Workbook
Name \0: #REF!
Name \1: #REF!
Name \a: #REF!
Name \b: #REF!
Name \c: #REF!
Name \d: #REF!
Name \e: #REF!
Name \i: #REF!
Name \J: #REF!
Name \k: #REF!
Name \l: #N/A
Name \m: #REF!
Name \o: #REF!
Name \p: #REF!
Name \r: #REF!
Name \T: #REF!
Name \z: #REF!
Name _: #REF!
Name _\0: #REF!
Name _\1: #REF!
Name _\a: #REF!
Name _\b: #REF!
Name _\c: #REF!
Name _\d: #REF!
Name _\e: #REF!
Name _\i: #REF!
Name _\J: #REF!
Name _\k: #REF!
Name _\l: #N/A
Name _\m: #REF!
Name _\o: #REF!
Name _\p: #REF!
Name _\r: #REF!
Name _\T: #REF!
Name _\z: #REF!
Name __: #REF!
Name ______ACR10: #REF!
Name ______ACR15: #REF!
Name ______acr20: #REF!
Name ______acr5: #REF!
Name ______ARQ1: #REF!
Name ______QT100: #REF!
Name ______QT2: #REF!
Name ______QT3: #REF!
Name ______QT4: #REF!
Name ______QT50: #REF!
Name ______QT75: #REF!
Name _____ACR10: #REF!
Name _____ACR15: #REF!
Name _____acr20: #REF!
Name _____acr5: #REF!
Name _____ARQ1: #REF!
Name _____key2: #REF!
Name _____QT100: #REF!
Name _____QT2: #REF!
Name _____QT3: #REF!
Name _____QT4: #REF!
Name _____QT50: #REF!
Name _____QT75: #REF!
Name ____key2: #REF!

Sheet CAPA
A1: DADOS DO EMPREENDIMENTO
B2: Projeto: | C2: Electra Towers | E2: ENDEREÇO DA OBRA: | F2: Rua 254, 215, Meia Praia, Itapema/SC
B3: Empresa: | C3: Thozen Empreendimentos | E3: Cidade/ES: | F3: Itapema, SC
B4: Revisão: | C4: R00 | E4: CNPJ: | F4: 43.339.082/0001-06
B6: Pazo de Obra: | C6: 48 | E6: Nº Unid. Residenciais: | F6: 192 | I6: Imagens
B8: Área do Terreno: | C8: 2095.43 | E8: Nº Unid. Comerciais: | F8: 7
B10: Área Construída: | C10: 37893.89 | E10: Nº Pavimentos: | F10: 57
B12: Área Privativa: | C12: 22778.64 | E12: Total de Dormitórios: | F12: 576
B14: Área de Lazer: | C14: 1736.27 | E14: Nº Subsolos: | F14: 0
B16: Área Comercial: | C16: 500.04 | E16: Nº Vagas: | F16: 399
B18: Torre | C18: Pavimento | D18: Área | E18: Área Privativa | F18: Perímetro | G18: Pé direito
B19: Embasamento | C19: Térreo | D19: 1565.91 | E19: 0 | G19: 4.3
B20: Embasamento | C20: Garagem 01 | D20: 1736.27 | E20: 0
B21: Embasamento | C21: Garagem 02 | D21: 1736.27 | E21: 0
B22: Embasamento | C22: Garagem 03 | D22: 1736.27 | E22: 0
B23: Embasamento | C23: Garagem 04 | D23: 1736.27 | E23: 0
B24: Embasamento | C24: Garagem 05 | D24: 1736.27 | E24: 0
B25: Embasamento | C25: Pavimento diferenciado — Lazer | D25: 1736.27 | E25: 0 | G25: 3.6
B26: Torre A | C26: Pavimento tipo — Torre A (×24) | D26: 12720.48 | E26: 11382.72 | G26: 3.24
B27: Torre B | C27: Pavimento tipo — Torre B (×24) | D27: 12892.32 | E27: 11397.12 | G27: 3.24
B28: Cobertura | C28: Casa de Máquinas | D28: 176.26 | E28: 0
B29: Cobertura | C29: Reservatórios | D29: 121.3 | E29: 0
B37: Torre | C37: Pavimento | D37: Descrição | E37: Área | I37: ETAPA
B38: Áreas Comuns | C38: =_xlfn.XLOOKUP(D38,MOBILIÁRIO!C:C,MOBILIÁRIO!B:B) -> TÉRREO | D38: {=_xlfn.UNIQUE(_xlfn._xlws.FILTER(MOBILIÁRIO!C7:C316,MOBILIÁRIO!C7:C316<>""))} -> Hall Externo | E38: =_xlfn.XLOOKUP(D38,MOBILIÁRIO!C:C,MOBILIÁRIO!F:F) -> 12.33 | I38: GERENCIAMENTO TÉCNICO E ADMINISTRATIVO
B39: Áreas Comuns | C39: =_xlfn.XLOOKUP(D39,MOBILIÁRIO!C:C,MOBILIÁRIO!B:B) -> TÉRREO | D39: Hall Térreo | E39: =_xlfn.XLOOKUP(D39,MOBILIÁRIO!C:C,MOBILIÁRIO!F:F) -> 35.27 | I39: MOVIMENTAÇÃO DE TERRA
B40: Áreas Comuns | C40: =_xlfn.XLOOKUP(D40,MOBILIÁRIO!C:C,MOBILIÁRIO!B:B) -> TÉRREO | D40: Guarita | E40: =_xlfn.XLOOKUP(D40,MOBILIÁRIO!C:C,MOBILIÁRIO!F:F) -> 4.72 | I40: CONTENÇÃO
B41: Áreas Comuns | C41: =_xlfn.XLOOKUP(D41,MOBILIÁRIO!C:C,MOBILIÁRIO!B:B) -> TÉRREO | D41: Lavapés | E41: =_xlfn.XLOOKUP(D41,MOBILIÁRIO!C:C,MOBILIÁRIO!F:F) -> 1 | I41: INFRAESTRUTURA
B42: Áreas Comuns | C42: =_xlfn.XLOOKUP(D42,MOBILIÁRIO!C:C,MOBILIÁRIO!B:B) -> TÉRREO | D42: Lavabo Pne - Térreo | E42: =_xlfn.XLOOKUP(D42,MOBILIÁRIO!C:C,MOBILIÁRIO!F:F) -> 3.77 | I42: SUPRAESTRUTURA
B43: Áreas Comuns | C43: =_xlfn.XLOOKUP(D43,MOBILIÁRIO!C:C,MOBILIÁRIO!B:B) -> TÉRREO | D43: Bicicletário/Box | E43: =_xlfn.XLOOKUP(D43,MOBILIÁRIO!C:C,MOBILIÁRIO!F:F) -> 87.33 | I43: ALVENARIAS E VEDAÇÕES
B44: Áreas Comuns | C44: =_xlfn.XLOOKUP(D44,MOBILIÁRIO!C:C,MOBILIÁRIO!B:B) -> TÉRREO | D44: Antecâmara - Térreo | E44: =_xlfn.XLOOKUP(D44,MOBILIÁRIO!C:C,MOBILIÁRIO!F:F) -> 8.07 | I44: SISTEMAS E INSTALAÇÕES ELÉTRICAS
B45: Áreas Comuns | C45: =_xlfn.XLOOKUP(D45,MOBILIÁRIO!C:C,MOBILIÁRIO!B:B) -> 2º AO 5º PAVIMENTO - GARAGENS (X5) | D45: Antecâmara - Garagens (x5) | E45: =_xlfn.XLOOKUP(D45,MOBILIÁRIO!C:C,MOBILIÁRIO!F:F) -> 33.6 | I45: SISTEMAS E INSTALAÇÕES HIDROSSANITÁRIAS E DRENAGEM
B46: Áreas Comuns | C46: =_xlfn.XLOOKUP(D46,MOBILIÁRIO!C:C,MOBILIÁRIO!B:B) -> 4º PAVIMENTO - LAZER/GARAGENS | D46: Sala de massagem | E46: =_xlfn.XLOOKUP(D46,MOBILIÁRIO!C:C,MOBILIÁRIO!F:F) -> 7.47 | I46: INSTALAÇÕES PREVENTIVAS
B47: Áreas Comuns | C47: =_xlfn.XLOOKUP(D47,MOBILIÁRIO!C:C,MOBILIÁRIO!B:B) -> 4º PAVIMENTO - LAZER/GARAGENS | D47: Banheiro - Lazer/Garagem | E47: =_xlfn.XLOOKUP(D47,MOBILIÁRIO!C:C,MOBILIÁRIO!F:F) -> 3.91 | I47: INSTALAÇÕES DE GÁS
B48: Áreas Comuns | C48: =_xlfn.XLOOKUP(D48,MOBILIÁRIO!C:C,MOBILIÁRIO!B:B) -> 4º PAVIMENTO - LAZER/GARAGENS | D48: Lavabo - Lazer/Garagem | E48: =_xlfn.XLOOKUP(D48,MOBILIÁRIO!C:C,MOBILIÁRIO!F:F) -> 2.61 | I48: EQUIPAMENTOS E SISTEMAS ESPECIAIS
B49: Áreas Comuns | C49: =_xlfn.XLOOKUP(D49,MOBILIÁRIO!C:C,MOBILIÁRIO!B:B) -> 4º PAVIMENTO - LAZER/GARAGENS | D49: Lavabo Pne - Lazer/Garagem | E49: =_xlfn.XLOOKUP(D49,MOBILIÁRIO!C:C,MOBILIÁRIO!F:F) -> 4.33 | I49: CLIMATIZAÇÃO, EXAUSTÃO MECÂNICA
B50: Áreas Comuns | C50: =_xlfn.XLOOKUP(D50,MOBILIÁRIO!C:C,MOBILIÁRIO!B:B) -> 4º PAVIMENTO - LAZER/GARAGENS | D50: Circulação - Lazer/garagem | E50: =_xlfn.XLOOKUP(D50,MOBILIÁRIO!C:C,MOBILIÁRIO!F:F) -> 30.85 | I50: INSTALAÇÕES ESPECIAIS
... B63: Áreas Comuns | C63: =_xlfn.XLOOKUP(D63,MOBILIÁRIO!C:C,MOBILIÁRIO!B:B) -> 5º PAVIMENTO - LAZER | D63: Laje Verde | E63: =_xlfn.XLOOKUP(D63,MOBILIÁRIO!C:C,MOBILIÁRIO!F:F) -> 269.95 | I63: CUB/SC
B64: Áreas Comuns | C64: =_xlfn.XLOOKUP(D64,MOBILIÁRIO!C:C,MOBILIÁRIO!B:B) -> 5º PAVIMENTO - LAZER | D64: Brinquedoteca | E64: =_xlfn.XLOOKUP(D64,MOBILIÁRIO!C:C,MOBILIÁRIO!F:F) -> 16.32
B65: Áreas Comuns | C65: =_xlfn.XLOOKUP(D65,MOBILIÁRIO!C:C,MOBILIÁRIO!B:B) -> 5º PAVIMENTO - LAZER | D65: Game Center | E65: =_xlfn.XLOOKUP(D65,MOBILIÁRIO!C:C,MOBILIÁRIO!F:F) -> 13.09 | I65: DESCRIÇÃO
B66: Áreas Comuns | C66: =_xlfn.XLOOKUP(D66,MOBILIÁRIO!C:C,MOBILIÁRIO!B:B) -> 5º PAVIMENTO - LAZER | D66: Sala de Festas | E66: =_xlfn.XLOOKUP(D66,MOBILIÁRIO!C:C,MOBILIÁRIO!F:F) -> 93.46 | I66: VALOR POR ÁREA PRIVATIVA (R$/m²)
...

Sheet EAP
A1: EAP DE ORÇAMENTO
A3: Contrutora - Obra
A5: UNIDADE CONSTRUTIVA | B5: 1 | C5: GERENCIAMENTO TÉCNICO E ADMINISTRATIVO
A6: CÉLULA CONSTRUTIVA | B6: 1 | C6: SERVIÇOS TÉCNICOS
A7: ETAPA | B7: 1.001 | C7: ESTUDOS, PROJETOS E CONSULTORIAS
A8: Subetapa | B8: 01.001.001 | C8: Estudos
A9: Subetapa | B9: 01.001.002 | C9: Projetos
A10: Subetapa | B10: 01.001.003 | C10: Consultorias
A11: Subetapa | B11: 01.001.004 | C11: Ensaios
A12: ETAPA | B12: 1.002 | C12: TAXAS E DOCUMENTOS
A13: Subetapa | B13: 01.002.001 | C13: Licenciamentos, Taxas, Impostos, Aprovações e Seguros
A14: Subetapa | B14: 01.002.002 | C14: Documentos
A15: CÉLULA CONSTRUTIVA | B15: 2 | C15: SERVIÇOS INICIAIS
A16: ETAPA | B16: 2.001 | C16: SEGURANÇA, MEIO AMBIENTE, SAÚDE
A17: Subetapa | B17: 02.001.001 | C17: Segurança do trabalho
A18: Subetapa | B18: 02.001.002 | C18: Equipamentos de proteção
A19: Subetapa | B19: 02.001.003 | C19: Meio ambiente
A20: Subetapa | B20: 02.001.004 | C20: Saúde ocupacional
A21: ETAPA | B21: 2.002 | C21: ADMINISTRAÇÃO E CANTEIRO DE OBRA
A22: Subetapa | B22: 02.002.001 | C22: Equipe de Gestão e Apoio
A23: Subetapa | B23: 02.002.002 | C23: Operação inicial de canteiro
A24: Subetapa | B24: 02.002.003 | C24: Despesas de consumo e manutenção
A25: Subetapa | B25: 02.002.004 | C25: Instalações provisórias
A26: Subetapa | B26: 02.002.005 | C26: Ligações Provisórias
A27: ETAPA | B27: 2.003 | C27: SERVIÇOS PRELIMINARES
... A29: Subetapa | B29: 02.003.002 | C29: Limpeza de terreno
A30: CÉLULA CONSTRUTIVA | B30: 3 | C30: EQUIPAMENTOS
A31: ETAPA | B31: 3.001 | C31: EQUIPAMENTOS
A32: Subetapa | B32: 03.001.001 | C32: Equipamentos de Carga e Transporte
A33: Subetapa | B33: 03.001.002 | C33: Equipamentos de obra
A34: Subetapa | B34: 03.001.003 | C34: Balancins e Andaimes
A35: UNIDADE CONSTRUTIVA | B35: 2 | C35: GERENCIAMENTO EXECUTIVO
A36: CÉLULA CONSTRUTIVA | B36: 1 | C36: INFRAESTRUTURA
A37: ETAPA | B37: 1.001 | C37: MOVIMENTAÇÃO DE TERRA
A38: Subetapa | B38: 01.001.001 | C38: Corte e aterro
A39: Subetapa | B39: 01.001.002 | C39: Rebaixamento de lençol
A40: Subetapa | B40: 01.001.003 | C40: Escavação e Reaterro de Valas
A41: Subetapa | B41: 01.001.004 | C41: Lastro de estrutura de concreto
A42: Subetapa | B42: 01.001.005 | C42: Movimentação de bota - fora
A43: ETAPA | B43: 1.002 | C43: FUNDAÇÃO PROFUNDA
...

Sheet IMPERMEABILIZAÇÃO
E1: DADOS
E2: Titulo
E3: Obra
E4: Cliente
E5: Cidade
E6: Endereço
E7: Descrição
E9: QUANTITATIVOS
A10: EAP | B10: Medição | C10: Pavimento | D10: Apoio | E10: Item | F10: Descrição | G10: Unid. | H10: Quantidade | I10: IMPER | J10: AMBIENTE | K10: Total | M10: Descrição | N10: 0 | O10: Tipo x8 | P10: Penthouse x22 | Q10: TOTAL | R10: OBSERVAÇÕES | T10: Descrição | U10: Referência
A12: =_xlfn.XLOOKUP(C12,$T$13:$T$58,$U$13:$U$58,"") -> 0 | B12: =UPPER(IF(F12="","",IF(IF(E12="","",LEN(E12)-LEN(SUBSTITUTE(E12,".","")))=2,(F12),B11))) | C12: =PROPER(IF(OR(F12="",C11="PAVIMENTO"),"",IF(AND(IF(E12="","",LEN(E12)-LEN(SUBSTITUTE(E12,".","")))=2,H12=""),F12,C11))) | D12: =IF(H12="","","SERVIÇO") | E12: 1. | F12: IMPERMEABILIZAÇÃO E TRATAMENTOS | I12: =IF(B12=F12,SUMIFS($H$12:$H$63964,$B$12:$B$63964,B12),"") | K12: =IF(C12=G12,SUMIFS($H$12:$H$63964,$B$12:$B$63964,C12),"") -> 0
A13: =_xlfn.XLOOKUP(C13,$T$13:$T$58,$U$13:$U$58,"") -> 0 | B13: =UPPER(IF(F13="","",IF(IF(E13="","",LEN(E13)-LEN(SUBSTITUTE(E13,".","")))=2,(F13),B12))) -> IMPERMEABILIZAÇAO E TRATAMENTOS | C13: =PROPER(IF(OR(F13="",C12="PAVIMENTO"),"",IF(AND(IF(E13="","",LEN(E13)-LEN(SUBSTITUTE(E13,".","")))=3,H13=""),F13,C12))) | D13: =IF(H13="","","SERVIÇO") | E13: 1.1. | F13: Impermeabilizaçao e tratamentos | I13: =IF(B13=F13,SUMIFS($H$12:$H$63964,$B$12:$B$63964,B13),"") -> 8265.06 | K13: =IF(C13=G13,SUMIFS($H$12:$H$63964,$B$12:$B$63964,C13),"") -> 0 | L13: TRUE | M13: =F13 -> Impermeabilizaçao e tratamentos | Q13: =SUM(Q14:Q63) -> 8265.06 | T13: {=_xlfn.UNIQUE(C12:C1840)}
A14: =_xlfn.XLOOKUP(C14,$T$13:$T$58,$U$13:$U$58,"") -> 0 | B14: =UPPER(IF(F14="","",IF(IF(E14="","",LEN(E14)-LEN(SUBSTITUTE(E14,".","")))=2,(F14),B13))) -> IMPERMEABILIZAÇAO E TRATAMENTOS | C14: =PROPER(IF(OR(F14="",C13="PAVIMENTO"),"",IF(AND(IF(E14="","",LEN(E14)-LEN(SUBSTITUTE(E14,".","")))=3,H14=""),F14,C13))) -> 01_1º Pav. (Térreo) | D14: =IF(H14="","","SERVIÇO") | E14: 1.1.1. | F14: 01_1º PAV. (TÉRREO) | I14: =IF(C14=F14,SUMIFS($H$12:$H$63964,$C$12:$C$63964,C14),"") -> 899.61 | M14: {=_xlfn.UNIQUE(_xlfn._xlws.FILTER($F$12:$F$10253,($D$12:$D$10253="serviço")*($B$12:$B$10253=M13)))} -> PAREDE: Sistema 2.5.3: Membrana de polímero acrílico com cimento e fibras sintéticas | Revestimento bicomponente à base de polímeros acrílicos com adição de cimento e fibras sintéticas (3,0 kg/m²) + Tela de poliéster nos pontos críticos - BANHEIRO | N14: =SUMIFS($H$13:$H$10253,$A$13:$A$10253,N$10,$F$13:$F$10253,$M14) -> 68.14 | O14: =SUMIFS($H$13:$H$10253,$A$13:$A$10253,O$10,$F$13:$F$10253,$M14) -> 0 | P14: =SUMIFS($H$13:$H$10253,$A$13:$A$10253,P$10,$F$13:$F$10253,$M14) -> 0 | Q14: =SUMIFS($H$13:$H$10253,$F$13:$F$10253,$M14) -> 68.14 | R14: PAREDE: Sistema 2.5.3: Membrana de polímero acrílico com cimento e fibras sintéticas | Revestimento bicomponente à base de polímeros acrílicos com adição de cimento e fibras sintéticas (3,0 kg/m²) + Tela de poliéster nos pontos críticos - BANHEIRO | T14: 01_1º Pav. (Térreo)
A15: =_xlfn.XLOOKUP(C15,$T$13:$T$58,$U$13:$U$58,"") -> 0 | B15: =UPPER(IF(F15="","",IF(IF(E15="","",LEN(E15)-LEN(SUBSTITUTE(E15,".","")))=2,(F15),B14))) -> IMPERMEABILIZAÇAO E TRATAMENTOS | C15: =PROPER(IF(OR(F15="",C14="PAVIMENTO"),"",IF(AND(IF(E15="","",LEN(E15)-LEN(SUBSTITUTE(E15,".","")))=3,H15=""),F15,C14))) -> 01_1º Pav. (Térreo) | D15: =IF(H15="","","SERVIÇO") -> SERVIÇO | E15: 1.1.1.1 | F15: PAREDE: Sistema 2.5.3: Membrana de polímero acrílico com cimento e fibras sintéticas | Revestimento bicomponente à base de polímeros acrílicos com adição de cimento e fibras sintéticas (3,0 kg/m²) + Tela de poliéster nos pontos críticos - BANHEIRO | G15: m² | H15: 39.3 | I15: =_xlfn.XLOOKUP($F15,$M$66:$M$115,$N$66:$N$115) -> 2.5.3 | J15: =TRIM(RIGHT(SUBSTITUTE(SUBSTITUTE(F15,CHAR(10)," ")," ",REPT(" ",100)),100)) -> BANHEIRO | K15: =TRIM(LEFT(SUBSTITUTE(SUBSTITUTE(F15,CHAR(10)," ")," ",REPT(" ",100)),100)) -> PAREDE: | M15: PISO: Sistema 2.5.3: Membrana de polímero acrílico com cimento e fibras sintéticas | Revestimento bicomponente à base de polímeros acrílicos com adição de cimento e fibras sintéticas (3,0 kg/m²) + Tela de poliéster nos pontos críticos - BANHEIRO | N15: =SUMIFS($H$13:$H$10253,$A$13:$A$10253,N$10,$F$13:$F$10253,$M15) -> 45.37 | O15: =SUMIFS($H$13:$H$10253,$A$13:$A$10253,O$10,$F$13:$F$10253,$M15) -> 0 | P15: =SUMIFS($H$13:$H$10253,$A$13:$A$10253,P$10,$F$13:$F$10253,$M15) -> 0 | Q15: =SUMIFS($H$13:$H$10253,$F$13:$F$10253,$M15) -> 45.37 | R15: PISO: Sistema 2.5.3: Membrana de polímero acrílico com cimento e fibras sintéticas | Revestimento bicomponente à base de polímeros acrílicos com adição de cimento e fibras sintéticas (3,0 kg/m²) + Tela de poliéster nos pontos críticos - BANHEIRO | T15: 02_Mez. 1º Pav. / G1
A16: =_xlfn.XLOOKUP(C16,$T$13:$T$58,$U$13:$U$58,"") -> 0 | B16: =UPPER(IF(F16="","",IF(IF(E16="","",LEN(E16)-LEN(SUBSTITUTE(E16,".","")))=2,(F16),B15))) -> IMPERMEABILIZAÇAO E TRATAMENTOS | C16: =PROPER(IF(OR(F16="",C15="PAVIMENTO"),"",IF(AND(IF(E16="","",LEN(E16)-LEN(SUBSTITUTE(E16,".","")))=3,H16=""),F16,C15))) -> 01_1º Pav. (Térreo) | D16: =IF(H16="","","SERVIÇO") -> SERVIÇO | E16: 1.1.1.2 | F16: PISO: Sistema 2.5.3: Membrana de polímero acrílico com cimento e fibras sintéticas | Revestimento bicomponente à base de polímeros acrílicos com adição de cimento e fibras sintéticas (3,0 kg/m²) + Tela de poliéster nos pontos críticos - BANHEIRO | G16: m² | H16: 26.46 | I16: =_xlfn.XLOOKUP($F16,$M$66:$M$115,$N$66:$N$115) -> 2.5.3 | J16: =TRIM(RIGHT(SUBSTITUTE(SUBSTITUTE(F16,CHAR(10)," ")," ",REPT(" ",100)),100)) -> BANHEIRO | K16: =TRIM(LEFT(SUBSTITUTE(SUBSTITUTE(F16,CHAR(10)," ")," ",REPT(" ",100)),100)) -> PISO: | M16: PAREDE: Sistema 2.1.4: Argamassa polimérica para impermeabilização - CASA DE BOMBAS | N16: =SUMIFS($H$13:$H$10253,$A$13:$A$10253,N$10,$F$13:$F$10253,$M16) -> 4.11 | O16: =SUMIFS($H$13:$H$10253,$A$13:$A$10253,O$10,$F$13:$F$10253,$M16) -> 0 | P16: =SUMIFS($H$13:$H$10253,$A$13:$A$10253,P$10,$F$13:$F$10253,$M16) -> 0 | Q16: =SUMIFS($H$13:$H$10253,$F$13:$F$10253,$M16) -> 4.11 | R16: PAREDE: Sistema 2.1.4: Argamassa polimérica para impermeabilização - CASA DE BOMBAS | T16: 03_2º Pav. / G2
A17: =_xlfn.XLOOKUP(C17,$T$13:$T$58,$U$13:$U$58,"") -> 0 | B17: =UPPER(IF(F17="","",IF(IF(E17="","",LEN(E17)-LEN(SUBSTITUTE(E17,".","")))=2,(F17),B16))) -> IMPERMEABILIZAÇAO E TRATAMENTOS | C17: =PROPER(IF(OR(F17="",C16="PAVIMENTO"),"",IF(AND(IF(E17="","",LEN(E17)-LEN(SUBSTITUTE(E17,".","")))=3,H17=""),F17,C16))) -> 01_1º Pav. (Térreo) | D17: =IF(H17="","","SERVIÇO") -> SERVIÇO | E17: 1.1.1.3 | F17: PAREDE: Sistema 2.1.4: Argamassa polimérica para impermeabilização - CASA DE BOMBAS | G17: m² | H17: 4.11 | I17: =_xlfn.XLOOKUP($F17,$M$66:$M$115,$N$66:$N$115) -> 2.1.4 | J17: =TRIM(RIGHT(SUBSTITUTE(SUBSTITUTE(F17,CHAR(10)," ")," ",REPT(" ",100)),100)) -> BOMBAS | K17: =TRIM(LEFT(SUBSTITUTE(SUBSTITUTE(F17,CHAR(10)," ")," ",REPT(" ",100)),100)) -> PAREDE: | M17: PISO: Sistema 2.1.4: Argamassa polimérica para impermeabilização | Argamassa impermeabilizante bicomponente à base de aditivos minerais e polímeros (4,0 kg/m²) + Tela de poliéster nos pontos críticos - CASA DE BOMBAS | N17: =SUMIFS($H$13:$H$10253,$A$13:$A$10253,N$10,$F$13:$F$10253,$M17) -> 7.01 | O17: =SUMIFS($H$13:$H$10253,$A$13:$A$10253,O$10,$F$13:$F$10253,$M17) -> 0 | P17: =SUMIFS($H$13:$H$10253,$A$13:$A$10253,P$10,$F$13:$F$10253,$M17) -> 0 | Q17: =SUMIFS($H$13:$H$10253,$F$13:$F$10253,$M17) -> 7.01 | R17: PISO: Sistema 2.1.4: Argamassa polimérica para impermeabilização | Argamassa impermeabilizante bicomponente à base de aditivos minerais e polímeros (4,0 kg/m²) + Tela de poliéster nos pontos críticos - CASA DE BOMBAS | T17: 04_Mez. 2º Pav. / G3
A18: =_xlfn.XLOOKUP(C18,$T$13:$T$58,$U$13:$U$58,"") -> 0 | B18: =UPPER(IF(F18="","",IF(IF(E18="","",LEN(E18)-LEN(SUBSTITUTE(E18,".","")))=2,(F18),B17))) -> IMPERMEABILIZAÇAO E TRATAMENTOS | C18: =PROPER(IF(OR(F18="",C17="PAVIMENTO"),"",IF(AND(IF(E18="","",LEN(E18)-LEN(SUBSTITUTE(E18,".","")))=3,H18=""),F18,C17))) -> 01_1º Pav. (Térreo) | D18: =IF(H18="","","SERVIÇO") -> SERVIÇO | E18: 1.1.1.4 | F18: PISO: Sistema 2.1.4: Argamassa polimérica para impermeabilização | Argamassa impermeabilizante bicomponente à base de aditivos minerais e polímeros (4,0 kg/m²) + Tela de poliéster nos pontos críticos - CASA DE BOMBAS | G18: m² | H18: 7.01 | I18: =_xlfn.XLOOKUP($F18,$M$66:$M$115,$N$66:$N$115) -> 2.1.4 | J18: =TRIM(RIGHT(SUBSTITUTE(SUBSTITUTE(F18,CHAR(10)," ")," ",REPT(" ",100)),100)) -> BOMBAS | K18: =TRIM(LEFT(SUBSTITUTE(SUBSTITUTE(F18,CHAR(10)," ")," ",REPT(" ",100)),100)) -> PISO: | M18: PISO: Sistema 2.5.3: Membrana de polímero acrílico com cimento e fibras sintéticas | Revestimento bicomponente à base de polímeros acrílicos com adição de cimento e fibras sintéticas (3,0 kg/m²) - ESQUADRIA | N18: =SUMIFS($H$13:$H$10253,$A$13:$A$10253,N$10,$F$13:$F$10253,$M18) -> 37.98 | O18: =SUMIFS($H$13:$H$10253,$A$13:$A$10253,O$10,$F$13:$F$10253,$M18) -> 0 | P18: =SUMIFS($H$13:$H$10253,$A$13:$A$10253,P$10,$F$13:$F$10253,$M18) -> 0 | Q18: =SUMIFS($H$13:$H$10253,$F$13:$F$10253,$M18) -> 37.98 | R18: PISO: Sistema 2.5.3: Membrana de polímero acrílico com cimento e fibras sintéticas | Revestimento bicomponente à base de polímeros acrílicos com adição de cimento e fibras sintéticas (3,0 kg/m²) - ESQUADRIA | T18: 05_3º Pav. / G4
A19: =_xlfn.XLOOKUP(C19,$T$13:$T$58,$U$13:$U$58,"") -> 0 | B19: =UPPER(IF(F19="","",IF(IF(E19="","",LEN(E19)-LEN(SUBSTITUTE(E19,".","")))=2,(F19),B18))) -> IMPERMEABILIZAÇAO E TRATAMENTOS | C19: =PROPER(IF(OR(F19="",C18="PAVIMENTO"),"",IF(AND(IF(E19="","",LEN(E19)-LEN(SUBSTITUTE(E19,".","")))=3,H19=""),F19,C18))) -> 01_1º Pav. (Térreo) | D19: =IF(H19="","","SERVIÇO") -> SERVIÇO | E19: 1.1.1.5 | F19: PISO: Sistema 2.5.3: Membrana de polímero acrílico com cimento e fibras sintéticas | Revestimento bicomponente à base de polímeros acrílicos com adição de cimento e fibras sintéticas (3,0 kg/m²) - ESQUADRIA | G19: m² | H19: 0.57 | I19: =_xlfn.XLOOKUP($F19,$M$66:$M$115,$N$66:$N$115) -> 2.5.3 | J19: =TRIM(RIGHT(SUBSTITUTE(SUBSTITUTE(F19,CHAR(10)," ")," ",REPT(" ",100)),100)) -> ESQUADRIA | K19: =TRIM(LEFT(SUBSTITUTE(SUBSTITUTE(F19,CHAR(10)," ")," ",REPT(" ",100)),100)) -> PISO: | M19: PISO: Argamassa polimérica para impermeabilizaçãoArgamassa impermeabilizante bicomponente à base de aditivos minerais e polímeros (4,0 kg/m²) + Tela depoliéster nos pontos críticos - CENTRAL DE GÁS/LIXEIRA | N19: =SUMIFS($H$13:$H$10253,$A$13:$A$10253,N$10,$F$13:$F$10253,$M19) -> 6.52 | O19: =SUMIFS($H$13:$H$10253,$A$13:$A$10253,O$10,$F$13:$F$10253,$M19) -> 0 | P19: =SUMIFS($H$13:$H$10253,$A$13:$A$10253,P$10,$F$13:$F$10253,$M19) -> 0 | Q19: =SUMIFS($H$13:$H$10253,$F$13:$F$10253,$M19) -> 6.52 | R19: PISO: Argamassa polimérica para impermeabilizaçãoArgamassa impermeabilizante bicomponente à base de aditivos minerais e polímeros (4,0 kg/m²) + Tela depoliéster nos pontos críticos - CENTRAL DE GÁS/LIXEIRA | T19: 06_Mez. 3º Pav. / G5
A20: =_xlfn.XLOOKUP(C20,$T$13:$T$58,$U$13:$U$58,"") -> 0 | B20: =UPPER(IF(F20="","",IF(IF(E20="","",LEN(E20)-LEN(SUBSTITUTE(E20,".","")))=2,(F20),B19))) -> IMPERMEABILIZAÇAO E TRATAMENTOS | C20: =PROPER(IF(OR(F20="",C19="PAVIMENTO"),"",IF(AND(IF(E20="","",LEN(E20)-LEN(SUBSTITUTE(E20,".","")))=3,H20=""),F20,C19))) -> 01_1º Pav. (Térreo) | D20: =IF(H20="","","SERVIÇO") -> SERVIÇO | E20: 1.1.1.6 | F20: PISO: Argamassa polimérica para impermeabilizaçãoArgamassa impermeabilizante bicomponente à base de aditivos minerais e polímeros (4,0 kg/m²) + Tela depoliéster nos pontos críticos - CENTRAL DE GÁS/LIXEIRA | G20: m² | H20: 6.52 | I20: =_xlfn.XLOOKUP($F20,$M$66:$M$115,$N$66:$N$115) -> 1 | J20: =TRIM(RIGHT(SUBSTITUTE(SUBSTITUTE(F20,CHAR(10)," ")," ",REPT(" ",100)),100)) -> GÁS/LIXEIRA | K20: =TRIM(LEFT(SUBSTITUTE(SUBSTITUTE(F20,CHAR(10)," ")," ",REPT(" ",100)),100)) -> PISO: | M20: PAREDE: Sistema 4.5.3: Manta asfáltica 4mm aderida com asfalto oxidado modificado + Emulsão asfáltica antiraiz | Primer asfáltico à base d'água (0,4 L/m²) + Asfalto oxidado modificado (2,5 kg/m²) + Manta asfáltica AA | N20: =SUMIFS($H$13:$H$10253,$A$13:$A$10253,N$10,$F$13:$F$10253,$M20) -> 70.68 | O20: =SUMIFS($H$13:$H$10253,$A$13:$A$10253,O$10,$F$13:$F$10253,$M20) -> 0 | P20: =SUMIFS($H$13:$H$10253,$A$13:$A$10253,P$10,$F$13:$F$10253,$M20) -> 0 | Q20: =SUMIFS($H$13:$H$10253,$F$13:$F$10253,$M20) -> 70.68 | R20: PAREDE: Sistema 4.5.3: Manta asfáltica 4mm aderida com asfalto oxidado modificado + Emulsão asfáltica antiraiz | Primer asfáltico à base d'água (0,4 L/m²) + Asfalto oxidado modificado (2,5 kg/m²) + Manta asfáltica AA 4mm Tipo III Classe B + Banho de asfalto oxidado modificado (2,5 kg/m²) + Emulsão asfáltica antiraiz sobre a proteção mecânica (0,8 L/m²) - FLOREIRA | T20: 07_4º Pav. - Lazer / G6
A21: =_xlfn.XLOOKUP(C21,$T$13:$T$58,$U$13:$U$58,"") -> 0 | B21: =UPPER(IF(F21="","",IF(IF(E21="","",LEN(E21)-LEN(SUBSTITUTE(E21,".","")))=2,(F21),B20))) -> IMPERMEABILIZAÇAO E TRATAMENTOS | C21: =PROPER(IF(OR(F21="",C20="PAVIMENTO"),"",IF(AND(IF(E21="","",LEN(E21)-LEN(SUBSTITUTE(E21,".","")))=3,H21=""),F21,C20))) -> 01_1º Pav. (Térreo) | D21: =IF(H21="","","SERVIÇO") -> SERVIÇO | E21: 1.1.1.7 | F21: PAREDE: Sistema 4.5.3: Manta asfáltica 4mm aderida com asfalto oxidado modificado + Emulsão asfáltica antiraiz | Primer asfáltico à base d'água (0,4 L/m²) + Asfalto oxidado modificado (2,5 kg/m²) + Manta asfáltica AA | G21: m² | H21: 29.9 | I21: 4.5.3 | J21: FLOREIRA | K21: =TRIM(LEFT(SUBSTITUTE(SUBSTITUTE(F21,CHAR(10)," ")," ",REPT(" ",100)),100)) -> PAREDE: | M21: PISO: Sistema 4.5.3: Manta asfáltica 4mm aderida com asfalto oxidado modificado + Emulsão asfáltica antiraiz | Primer asfáltico à base d'água (0,4 L/m²) + Asfalto oxidado modificado (2,5 kg/m²) + Manta asfáltica AA | N21: =SUMIFS($H$13:$H$10253,$A$13:$A$10253,N$10,$F$13:$F$10253,$M21) -> 271.44 | O21: =SUMIFS($H$13:$H$10253,$A$13:$A$10253,O$10,$F$13:$F$10253,$M21) -> 0 | P21: =SUMIFS($H$13:$H$10253,$A$13:$A$10253,P$10,$F$13:$F$10253,$M21) -> 0 | Q21: =SUMIFS($H$13:$H$10253,$F$13:$F$10253,$M21) -> 271.44 | R21: PISO: Sistema 4.5.3: Manta asfáltica 4mm aderida com asfalto oxidado modificado + Emulsão asfáltica antiraiz | Primer asfáltico à base d'água (0,4 L/m²) + Asfalto oxidado modificado (2,5 kg/m²) + Manta asfáltica AA 4mm Tipo III Classe B + Banho de asfalto oxidado modificado (2,5 kg/m²) + Emulsão asfáltica antiraiz sobre a proteção mecânica (0,8 L/m²) - FLOREIRA | T21: 08_5º Pav. - Lazer
A22: =_xlfn.XLOOKUP(C22,$T$13:$T$58,$U$13:$U$58,"") -> 0 | B22: =UPPER(IF(F22="","",IF(IF(E22="","",LEN(E22)-LEN(SUBSTITUTE(E22,".","")))=2,(F22),B21))) -> IMPERMEABILIZAÇAO E TRATAMENTOS | C22: =PROPER(IF(OR(F22="",C21="PAVIMENTO"),"",IF(AND(IF(E22="","",LEN(E22)-LEN(SUBSTITUTE(E22,".","")))=3,H22=""),F22,C21))) -> 01_1º Pav. (Térreo) | D22: =IF(H22="","","SERVIÇO") -> SERVIÇO | E22: 1.1.1.8 | F22: PISO: Sistema 4.5.3: Manta asfáltica 4mm aderida com asfalto oxidado modificado + Emulsão asfáltica antiraiz | Primer asfáltico à base d'água (0,4 L/m²) + Asfalto oxidado modificado (2,5 kg/m²) + Manta asfáltica AA | G22: m² | H22: 6.86 | I22: 4.5.3 | J22: FLOREIRA | K22: =TRIM(LEFT(SUBSTITUTE(SUBSTITUTE(F22,CHAR(10)," ")," ",REPT(" ",100)),100)) -> PISO: | L22: PROTEÇÃO MECANICA | M22: PAREDE: Sistema 2.1.4: Argamassa polimérica para impermeabilização | Argamassa impermeabilizante bicomponente à base de aditivos minerais e polímeros (4,0 kg/m²) + Tela de poliéster nos pontos críticos - FOSSO ELEVADOR | N22: =SUMIFS($H$13:$H$10253,$A$13:$A$10253,N$10,$F$13:$F$10253,$M22) -> 68.86 | O22: =SUMIFS($H$13:$H$10253,$A$13:$A$10253,O$10,$F$13:$F$10253,$M22) -> 0 | P22: =SUMIFS($H$13:$H$10253,$A$13:$A$10253,P$10,$F$13:$F$10253,$M22) -> 0 | Q22: =SUMIFS($H$13:$H$10253,$F$13:$F$10253,$M22) -> 68.86 | R22: PAREDE: Sistema 2.1.4: Argamassa polimérica para impermeabilização | Argamassa impermeabilizante bicomponente à base de aditivos minerais e polímeros (4,0 kg/m²) + Tela de poliéster nos pontos críticos - FOSSO ELEVADOR | T22: 09_6º Pav. - Tipo Dif.
A23: =_xlfn.XLOOKUP(C23,$T$13:$T$58,$U$13:$U$58,"") -> 0 | B23: =UPPER(IF(F23="","",IF(IF(E23="","",LEN(E23)-LEN(SUBSTITUTE(E23,".","")))=2,(F23),B22))) -> IMPERMEABILIZAÇAO E TRATAMENTOS | C23: =PROPER(IF(OR(F23="",C22="PAVIMENTO"),"",IF(AND(IF(E23="","",LEN(E23)-LEN(SUBSTITUTE(E23,".","")))=3,H23=""),F23,C22))) -> 01_1º Pav. (Térreo) | D23: =IF(H23="","","SERVIÇO") -> SERVIÇO | E23: 1.1.1.9 | F23: PAREDE: Sistema 2.1.4: Argamassa polimérica para impermeabilização | Argamassa impermeabilizante bicomponente à base de aditivos minerais e polímeros (4,0 kg/m²) + Tela de poliéster nos pontos críticos - FOSSO ELEVADOR | G23: m² | H23: 68.86 | I23: =_xlfn.XLOOKUP($F23,$M$66:$M$115,$N$66:$N$115) -> 2.1.4 | J23: =TRIM(RIGHT(SUBSTITUTE(SUBSTITUTE(F23,CHAR(10)," ")," ",REPT(" ",100)),100)) -> ELEVADOR | K23: =TRIM(LEFT(SUBSTITUTE(SUBSTITUTE(F23,CHAR(10)," ")," ",REPT(" ",100)),100)) -> PAREDE: | M23: PISO: Sistema 2.1.4: Argamassa polimérica para impermeabilização | Argamassa impermeabilizante bicomponente à base de aditivos minerais e polímeros (4,0 kg/m²) + Tela de poliéster nos pontos críticos - FOSSO ELEVADOR | N23: =SUMIFS($H$13:$H$10253,$A$13:$A$10253,N$10,$F$13:$F$10253,$M23) -> 11.17 | O23: =SUMIFS($H$13:$H$10253,$A$13:$A$10253,O$10,$F$13:$F$10253,$M23) -> 0 | P23: =SUMIFS($H$13:$H$10253,$A$13:$A$10253,P$10,$F$13:$F$10253,$M23) -> 0 | Q23: =SUMIFS($H$13:$H$10253,$F$13:$F$10253,$M23) -> 11.17 | R23: PISO: Sistema 2.1.4: Argamassa polimérica para impermeabilização | Argamassa impermeabilizante bicomponente à base de aditivos minerais e polímeros (4,0 kg/m²) + Tela de poliéster nos pontos críticos - FOSSO ELEVADOR | T23: 10_7º Pav. - Tipo | U23: Tipo x8
A24: =_xlfn.XLOOKUP(C24,$T$13:$T$58,$U$13:$U$58,"") -> 0 | B24: =UPPER(IF(F24="","",IF(IF(E24="","",LEN(E24)-LEN(SUBSTITUTE(E24,".","")))=2,(F24),B23))) -> IMPERMEABILIZAÇAO E TRATAMENTOS | C24: =PROPER(IF(OR(F24="",C23="PAVIMENTO"),"",IF(AND(IF(E24="","",LEN(E24)-LEN(SUBSTITUTE(E24,".","")))=3,H24=""),F24,C23))) -> 01_1º Pav. (Térreo) | D24: =IF(H24="","","SERVIÇO") -> SERVIÇO | E24: 1.1.1.10 | F24: PISO: Sistema 2.1.4: Argamassa polimérica para impermeabilização | Argamassa impermeabilizante bicomponente à base de aditivos minerais e polímeros (4,0 kg/m²) + Tela de poliéster nos pontos críticos - FOSSO ELEVADOR | G24: m² | H24: 11.17 | I24: =_xlfn.XLOOKUP($F24,$M$66:$M$115,$N$66:$N$115) -> 2.1.4 | J24: =TRIM(RIGHT(SUBSTITUTE(SUBSTITUTE(F24,CHAR(10)," ")," ",REPT(" ",100)),100)) -> ELEVADOR | K24: =TRIM(LEFT(SUBSTITUTE(SUBSTITUTE(F24,CHAR(10)," ")," ",REPT(" ",100)),100)) -> PISO: | M24: PAREDE: - VIGA BALDRAME | N24: =SUMIFS($H$13:$H$10253,$A$13:$A$10253,N$10,$F$13:$F$10253,$M24) -> 514.29 | O24: =SUMIFS($H$13:$H$10253,$A$13:$A$10253,O$10,$F$13:$F$10253,$M24) -> 0 | P24: =SUMIFS($H$13:$H$10253,$A$13:$A$10253,P$10,$F$13:$F$10253,$M24) -> 0 | Q24: =SUMIFS($H$13:$H$10253,$F$13:$F$10253,$M24) -> 514.29 | R24: PAREDE: - VIGA BALDRAME | T24: 11_8º Pav. - Tipo | U24: Tipo x8
A25: =_xlfn.XLOOKUP(C25,$T$13:$T$58,$U$13:$U$58,"") -> 0 | B25: =UPPER(IF(F25="","",IF(IF(E25="","",LEN(E25)-LEN(SUBSTITUTE(E25,".","")))=2,(F25),B24))) -> IMPERMEABILIZAÇAO E TRATAMENTOS | C25: =PROPER(IF(OR(F25="",C24="PAVIMENTO"),"",IF(AND(IF(E25="","",LEN(E25)-LEN(SUBSTITUTE(E25,".","")))=3,H25=""),F25,C24))) -> 01_1º Pav. (Térreo) | D25: =IF(H25="","","SERVIÇO") -> SERVIÇO | E25: 1.1.1.11 | F25: PAREDE: - VIGA BALDRAME | G25: m² | H25: 514.29 | I25: =_xlfn.XLOOKUP($F25,$M$66:$M$115,$N$66:$N$115) -> 3 | J25: =TRIM(RIGHT(SUBSTITUTE(SUBSTITUTE(F25,CHAR(10)," ")," ",REPT(" ",100)),100)) -> BALDRAME | K25: =TRIM(LEFT(SUBSTITUTE(SUBSTITUTE(F25,CHAR(10)," ")," ",REPT(" ",100)),100)) -> PAREDE: | M25: PISO: - VIGA BALDRAME | N25: =SUMIFS($H$13:$H$10253,$A$13:$A$10253,N$10,$F$13:$F$10253,$M25) -> 184.56 | O25: =SUMIFS($H$13:$H$10253,$A$13:$A$10253,O$10,$F$13:$F$10253,$M25) -> 0 | P25: =SUMIFS($H$13:$H$10253,$A$13:$A$10253,P$10,$F$13:$F$10253,$M25) -> 0 | Q25: =SUMIFS($H$13:$H$10253,$F$13:$F$10253,$M25) -> 184.56 | R25: PISO: - VIGA BALDRAME | T25: 12_9º Pav. - Tipo | U25: Tipo x8
A26: =_xlfn.XLOOKUP(C26,$T$13:$T$58,$U$13:$U$58,"") -> 0 | B26: =UPPER(IF(F26="","",IF(IF(E26="","",LEN(E26)-LEN(SUBSTITUTE(E26,".","")))=2,(F26),B25))) -> IMPERMEABILIZAÇAO E TRATAMENTOS | C26: =PROPER(IF(OR(F26="",C25="PAVIMENTO"),"",IF(AND(IF(E26="","",LEN(E26)-LEN(SUBSTITUTE(E26,".","")))=3,H26=""),F26,C25))) -> 01_1º Pav. (Térreo) | D26: =IF(H26="","","SERVIÇO") -> SERVIÇO | E26: 1.1.1.12 | F26: PISO: - VIGA BALDRAME | G26: m² | H26: 184.56 | I26: =_xlfn.XLOOKUP($F26,$M$66:$M$115,$N$66:$N$115) -> 3 | J26: =TRIM(RIGHT(SUBSTITUTE(SUBSTITUTE(F26,CHAR(10)," ")," ",REPT(" ",100)),100)) -> BALDRAME | K26: =TRIM(LEFT(SUBSTITUTE(SUBSTITUTE(F26,CHAR(10)," ")," ",REPT(" ",100)),100)) -> PISO: | M26: PAREDE: Sistema 2.5.3: Membrana de polímero acrílico com cimento e fibras sintéticas | Revestimento bicomponente à base de polímeros acrílicos com adição de cimento e fibras sintéticas (3,0 kg/m²) - ESQUADRIA | N26: =SUMIFS($H$13:$H$10253,$A$13:$A$10253,N$10,$F$13:$F$10253,$M26) -> 231.68 | O26: =SUMIFS($H$13:$H$10253,$A$13:$A$10253,O$10,$F$13:$F$10253,$M26) -> 273.44 | P26: =SUMIFS($H$13:$H$10253,$A$13:$A$10253,P$10,$F$13:$F$10253,$M26) -> 626.48 | Q26: =SUMIFS($H$13:$H$10253,$F$13:$F$10253,$M26) -> 1131.6 | R26: PAREDE: Sistema 2.5.3: Membrana de polímero acrílico com cimento e fibras sintéticas | Revestimento bicomponente à base de polímeros acrílicos com adição de cimento e fibras sintéticas (3,0 kg/m²) - ESQUADRIA | T26: 13_10º Pav. - Tipo | U26: Tipo x8
A27: =_xlfn.XLOOKUP(C27,$T$13:$T$58,$U$13:$U$58,"") -> 0 | B27: =UPPER(IF(F27="","",IF(IF(E27="","",LEN(E27)-LEN(SUBSTITUTE(E27,".","")))=2,(F27),B26))) -> IMPERMEABILIZAÇAO E TRATAMENTOS | C27: =PROPER(IF(OR(F27="",C26="PAVIMENTO"),"",IF(AND(IF(E27="","",LEN(E27)-LEN(SUBSTITUTE(E27,".","")))=3,H27=""),F27,C26))) -> 02_Mez. 1º Pav. / G1 | D27: =IF(H27="","","SERVIÇO") | E27: 1.1.2. | F27: 02_MEZ. 1º PAV. / G1 | I27: =IF(C27=F27,SUMIFS($H$12:$H$63964,$C$12:$C$63964,C27),"") -> 12.46 | M27: PAREDE: Sistema 2.8.6: Argamassa polimérica para impermeabilização + Membrana de polímero acrílico com cimento e fibras sintéticas | Argamassa impermeabilizante bicomponente à base de aditivos minerais e polímeros (2,0 kg/m²) + - CISTERNA | N27: =SUMIFS($H$13:$H$10253,$A$13:$A$10253,N$10,$F$13:$F$10253,$M27) -> 15.84 | O27: =SUMIFS($H$13:$H$10253,$A$13:$A$10253,O$10,$F$13:$F$10253,$M27) -> 0 | P27: =SUMIFS($H$13:$H$10253,$A$13:$A$10253,P$10,$F$13:$F$10253,$M27) -> 0 | Q27: =SUMIFS($H$13:$H$10253,$F$13:$F$10253,$M27) -> 15.84 | R27: PAREDE: Sistema 2.8.6: Argamassa polimérica para impermeabilização + Membrana de polímero acrílico com cimento e fibras sintéticas | Argamassa impermeabilizante bicomponente à base de aditivos minerais e polímeros (2,0 kg/m²) + Revestimento bicomponente à base de polímeros acrílicos com adição de cimento e fibras sintéticas (4,5 kg/m²) + Tela de poliéster nos pontos críticos - CISTERNA | T27: 14_11º Pav. - Tipo | U27: Tipo x8
A28: =_xlfn.XLOOKUP(C28,$T$13:$T$58,$U$13:$U$58,"") -> 0 | B28: =UPPER(IF(F28="","",IF(IF(E28="","",LEN(E28)-LEN(SUBSTITUTE(E28,".","")))=2,(F28),B27))) -> IMPERMEABILIZAÇAO E TRATAMENTOS | C28: =PROPER(IF(OR(F28="",C27="PAVIMENTO"),"",IF(AND(IF(E28="","",LEN(E28)-LEN(SUBSTITUTE(E28,".","")))=3,H28=""),F28,C27))) -> 02_Mez. 1º Pav. / G1 | D28: =IF(H28="","","SERVIÇO") -> SERVIÇO | E28: 1.1.2.1 | F28: PAREDE: Sistema 2.5.3: Membrana de polímero acrílico com cimento e fibras sintéticas | Revestimento bicomponente à base de polímeros acrílicos com adição de cimento e fibras sintéticas (3,0 kg/m²) - ESQUADRIA | G28: m² | H28: 7.93 | I28: =_xlfn.XLOOKUP($F28,$M$66:$M$115,$N$66:$N$115) -> 2.5.3 | J28: =TRIM(RIGHT(SUBSTITUTE(SUBSTITUTE(F28,CHAR(10)," ")," ",REPT(" ",100)),100)) -> ESQUADRIA | K28: =TRIM(LEFT(SUBSTITUTE(SUBSTITUTE(F28,CHAR(10)," ")," ",REPT(" ",100)),100)) -> PAREDE: | M28: PISO: Sistema 2.8.6: Argamassa polimérica para impermeabilização + Membrana de polímero acrílico com cimento e fibras sintéticas | Argamassa impermeabilizante bicomponente à base de aditivos minerais e polímeros (2,0 kg/m²) + - CISTERNA | N28: =SUMIFS($H$13:$H$10253,$A$13:$A$10253,N$10,$F$13:$F$10253,$M28) -> 4.99 | O28: =SUMIFS($H$13:$H$10253,$A$13:$A$10253,O$10,$F$13:$F$10253,$M28) -> 0 | P28: =SUMIFS($H$13:$H$10253,$A$13:$A$10253,P$10,$F$13:$F$10253,$M28) -> 0 | Q28: =SUMIFS($H$13:$H$10253,$F$13:$F$10253,$M28) -> 4.99 | R28: PISO: Sistema 2.8.6: Argamassa polimérica para impermeabilização + Membrana de polímero acrílico com cimento e fibras sintéticas | Argamassa impermeabilizante bicomponente à base de aditivos minerais e polímeros (2,0 kg/m²) + Revestimento bicomponente à base de polímeros acrílicos com adição de cimento e fibras sintéticas (4,5 kg/m²) + Tela de poliéster nos pontos críticos - CISTERNA | T28: 15_12º Pav. - Tipo | U28: Tipo x8
A29: =_xlfn.XLOOKUP(C29,$T$13:$T$58,$U$13:$U$58,"") -> 0 | B29: =UPPER(IF(F29="","",IF(IF(E29="","",LEN(E29)-LEN(SUBSTITUTE(E29,".","")))=2,(F29),B28))) -> IMPERMEABILIZAÇAO E TRATAMENTOS | C29: =PROPER(IF(OR(F29="",C28="PAVIMENTO"),"",IF(AND(IF(E29="","",LEN(E29)-LEN(SUBSTITUTE(E29,".","")))=3,H29=""),F29,C28))) -> 02_Mez. 1º Pav. / G1 | D29: =IF(H29="","","SERVIÇO") -> SERVIÇO | E29: 1.1.2.2 | F29: PISO: Sistema 2.5.3: Membrana de polímero acrílico com cimento e fibras sintéticas | Revestimento bicomponente à base de polímeros acrílicos com adição de cimento e fibras sintéticas (3,0 kg/m²) - ESQUADRIA | G29: m² | H29: 4.53 | I29: =_xlfn.XLOOKUP($F29,$M$66:$M$115,$N$66:$N$115) -> 2.5.3 | J29: =TRIM(RIGHT(SUBSTITUTE(SUBSTITUTE(F29,CHAR(10)," ")," ",REPT(" ",100)),100)) -> ESQUADRIA | K29: =TRIM(LEFT(SUBSTITUTE(SUBSTITUTE(F29,CHAR(10)," ")," ",REPT(" ",100)),100)) -> PISO: | M29: TETO: Sistema 7.1.2: Argamassa impermeabilizante sem cimento - MK-FEN 30 (F) | Argamassa não cimentícia com agentes incorporadores de ar (4,0 kg/m²) + Tela de poliéster nos pontos críticos - CISTERNA | N29: =SUMIFS($H$13:$H$10253,$A$13:$A$10253,N$10,$F$13:$F$10253,$M29) -> 4.99 | O29: =SUMIFS($H$13:$H$10253,$A$13:$A$10253,O$10,$F$13:$F$10253,$M29) -> 0 | P29: =SUMIFS($H$13:$H$10253,$A$13:$A$10253,P$10,$F$13:$F$10253,$M29) -> 0 | Q29: =SUMIFS($H$13:$H$10253,$F$13:$F$10253,$M29) -> 4.99 | R29: TETO: Sistema 7.1.2: Argamassa impermeabilizante sem cimento - MK-FEN 30 (F) | Argamassa não cimentícia com agentes incorporadores de ar (4,0 kg/m²) + Tela de poliéster nos pontos críticos - CISTERNA | T29: 16_13º Pav. - Tipo | U29: Tipo x8
A30: =_xlfn.XLOOKUP(C30,$T$13:$T$58,$U$13:$U$58,"") -> 0 | B30: =UPPER(IF(F30="","",IF(IF(E30="","",LEN(E30)-LEN(SUBSTITUTE(E30,".","")))=2,(F30),B29))) -> IMPERMEABILIZAÇAO E TRATAMENTOS | C30: =PROPER(IF(OR(F30="",C29="PAVIMENTO"),"",IF(AND(IF(E30="","",LEN(E30)-LEN(SUBSTITUTE(E30,".","")))=3,H30=""),F30,C29))) -> 03_2º Pav. / G2 | D30: =IF(H30="","","SERVIÇO") | E30: 1.1.3. | F30: 03_2º PAV. / G2 | I30: =IF(C30=F30,SUMIFS($H$12:$H$63964,$C$12:$C$63964,C30),"") -> 30.94 | M30: PAREDE: Sistema 4.2.4: Manta asfáltica 4mm aderida com asfalto oxidado modificado | Primer asfáltico à base d'água (0,4 L/m²) + Asfalto oxidado modificado (2,5 kg/m²) + Manta asfáltica AA 4mm Tipo III Classe B - CIRCULAÇÃO | N30: =SUMIFS($H$13:$H$10253,$A$13:$A$10253,N$10,$F$13:$F$10253,$M30) -> 27.38 | O30: =SUMIFS($H$13:$H$10253,$A$13:$A$10253,O$10,$F$13:$F$10253,$M30) -> 0 | P30: =SUMIFS($H$13:$H$10253,$A$13:$A$10253,P$10,$F$13:$F$10253,$M30) -> 0 | Q30: =SUMIFS($H$13:$H$10253,$F$13:$F$10253,$M30) -> 27.38 | R30: PAREDE: Sistema 4.2.4: Manta asfáltica 4mm aderida com asfalto oxidado modificado | Primer asfáltico à base d'água (0,4 L/m²) + Asfalto oxidado modificado (2,5 kg/m²) + Manta asfáltica AA 4mm Tipo III Classe B + Banho de asfalto oxidado modificado (2,5 kg/m²) - CIRCULAÇÃO | T30: 17_14º Pav. - Penthouse | U30: Tipo x8
A31: =_xlfn.XLOOKUP(C31,$T$13:$T$58,$U$13:$U$58,"") -> 0 | B31: =UPPER(IF(F31="","",IF(IF(E31="","",LEN(E31)-LEN(SUBSTITUTE(E31,".","")))=2,(F31),B30))) -> IMPERMEABILIZAÇAO E TRATAMENTOS | C31: =PROPER(IF(OR(F31="",C30="PAVIMENTO"),"",IF(AND(IF(E31="","",LEN(E31)-LEN(SUBSTITUTE(E31,".","")))=3,H31=""),F31,C30))) -> 03_2º Pav. / G2 | D31: =IF(H31="","","SERVIÇO") -> SERVIÇO | E31: 1.1.3.1 | F31: PAREDE: Sistema 2.5.3: Membrana de polímero acrílico com cimento e fibras sintéticas | Revestimento bicomponente à base de polímeros acrílicos com adição de cimento e fibras sintéticas (3,0 kg/m²) - ESQUADRIA | G31: m² | H31: 23.62 | I31: =_xlfn.XLOOKUP($F31,$M$66:$M$115,$N$66:$N$115) -> 2.5.3 | J31: =TRIM(RIGHT(SUBSTITUTE(SUBSTITUTE(F31,CHAR(10)," ")," ",REPT(" ",100)),100)) -> ESQUADRIA | K31: =TRIM(LEFT(SUBSTITUTE(SUBSTITUTE(F31,CHAR(10)," ")," ",REPT(" ",100)),100)) -> PAREDE: | M31: PISO: Sistema 4.2.4: Manta asfáltica 4mm aderida com asfalto oxidado modificado | Primer asfáltico à base d'água (0,4 L/m²) + Asfalto oxidado modificado (2,5 kg/m²) + Manta asfáltica AA 4mm Tipo III Classe B + - CIRCULAÇÃO | N31: =SUMIFS($H$13:$H$10253,$A$13:$A$10253,N$10,$F$13:$F$10253,$M31) -> 142.23 | O31: =SUMIFS($H$13:$H$10253,$A$13:$A$10253,O$10,$F$13:$F$10253,$M31) -> 0 | P31: =SUMIFS($H$13:$H$10253,$A$13:$A$10253,P$10,$F$13:$F$10253,$M31) -> 0 | Q31: =SUMIFS($H$13:$H$10253,$F$13:$F$10253,$M31) -> 142.23 | R31: PISO: Sistema 4.2.4: Manta asfáltica 4mm aderida com asfalto oxidado modificado | Primer asfáltico à base d'água (0,4 L/m²) + Asfalto oxidado modificado (2,5 kg/m²) + Manta asfáltica AA 4mm Tipo III Classe B + Banho de asfalto oxidado modificado (2,5 kg/m²) - CIRCULAÇÃO | T31: 18_15º Pav. - Penthouse | U31: Penthouse x22
A32: =_xlfn.XLOOKUP(C32,$T$13:$T$58,$U$13:$U$58,"") -> 0 | B32: =UPPER(IF(F32="","",IF(IF(E32="","",LEN(E32)-LEN(SUBSTITUTE(E32,".","")))=2,(F32),B31))) -> IMPERMEABILIZAÇAO E TRATAMENTOS | C32: =PROPER(IF(OR(F32="",C31="PAVIMENTO"),"",IF(AND(IF(E32="","",LEN(E32)-LEN(SUBSTITUTE(E32,".","")))=3,H32=""),F32,C31))) -> 03_2º Pav. / G2 | D32: =IF(H32="","","SERVIÇO") -> SERVIÇO | E32: 1.1.3.2 | F32: PISO: Sistema 2.5.3: Membrana de polímero acrílico com cimento e fibras sintéticas | Revestimento bicomponente à base de polímeros acrílicos com adição de cimento e fibras sintéticas (3,0 kg/m²) - ESQUADRIA | G32: m² | H32: 7.32 | I32: =_xlfn.XLOOKUP($F32,$M$66:$M$115,$N$66:$N$115) -> 2.5.3 | J32: =TRIM(RIGHT(SUBSTITUTE(SUBSTITUTE(F32,CHAR(10)," ")," ",REPT(" ",100)),100)) -> ESQUADRIA | K32: =TRIM(LEFT(SUBSTITUTE(SUBSTITUTE(F32,CHAR(10)," ")," ",REPT(" ",100)),100)) -> PISO: | M32: PAREDE: Sistema 4.9.2: Manta asfáltica 4+4mm aderida com asfalto oxidado modificado + Argamassa polimérica para impermeabilização | Primer asfáltico à base d'água (0,4 L/m²) + Asfalto oxidado modificado (2,5 kg/m² - PISCINA | N32: =SUMIFS($H$13:$H$10253,$A$13:$A$10253,N$10,$F$13:$F$10253,$M32) -> 99.14 | O32: =SUMIFS($H$13:$H$10253,$A$13:$A$10253,O$10,$F$13:$F$10253,$M32) -> 0 | P32: =SUMIFS($H$13:$H$10253,$A$13:$A$10253,P$10,$F$13:$F$10253,$M32) -> 0 | Q32: =SUMIFS($H$13:$H$10253,$F$13:$F$10253,$M32) -> 99.14 | R32: PAREDE: Sistema 4.9.2: Manta asfáltica 4+4mm aderida com asfalto oxidado modificado + Argamassa polimérica para impermeabilização | Primer asfáltico à base d'água (0,4 L/m²) + Asfalto oxidado modificado (2,5 kg/m²) + Manta asfáltica AA 3mm Tipo III Classe B + Asfalto oxidado modificado (2,5 kg/m²) + Manta asfáltica AA 4mm Tipo III Classe B + Argamassa polimérica para impermeabilização sobre a proteção mecânica (2,0 kg/m²) - PISCINA | T32: 19_16º Pav. - Penthouse | U32: Penthouse x22
A33: =_xlfn.XLOOKUP(C33,$T$13:$T$58,$U$13:$U$58,"") -> 0 | B33: =UPPER(IF(F33="","",IF(IF(E33="","",LEN(E33)-LEN(SUBSTITUTE(E33,".","")))=2,(F33),B32))) -> IMPERMEABILIZAÇAO E TRATAMENTOS | C33: =PROPER(IF(OR(F33="",C32="PAVIMENTO"),"",IF(AND(IF(E33="","",LEN(E33)-LEN(SUBSTITUTE(E33,".","")))=3,H33=""),F33,C32))) -> 04_Mez. 2º Pav. / G3 | D33: =IF(H33="","","SERVIÇO") | E33: 1.1.4. | F33: 04_MEZ. 2º PAV. / G3 | I33: =IF(C33=F33,SUMIFS($H$12:$H$63964,$C$12:$C$63964,C33),"") -> 25.3 | M33: PISO: Sistema 4.9.2: Manta asfáltica 4+4mm aderida com asfalto oxidado modificado + Argamassa polimérica para impermeabilização | Primer asfáltico à base d'água (0,4 L/m²) + Asfalto oxidado modificado (2,5 kg/m² - PISCINA | N33: =SUMIFS($H$13:$H$10253,$A$13:$A$10253,N$10,$F$13:$F$10253,$M33) -> 141.99 | O33: =SUMIFS($H$13:$H$10253,$A$13:$A$10253,O$10,$F$13:$F$10253,$M33) -> 0 | P33: =SUMIFS($H$13:$H$10253,$A$13:$A$10253,P$10,$F$13:$F$10253,$M33) -> 0 | Q33: =SUMIFS($H$13:$H$10253,$F$13:$F$10253,$M33) -> 141.99 | R33: PISO: Sistema 4.9.2: Manta asfáltica 4+4mm aderida com asfalto oxidado modificado + Argamassa polimérica para impermeabilização | Primer asfáltico à base d'água (0,4 L/m²) + Asfalto oxidado modificado (2,5 kg/m²) + Manta asfáltica AA 3mm Tipo III Classe B + Asfalto oxidado modificado (2,5 kg/m²) + Manta asfáltica AA 4mm Tipo III Classe B + Argamassa polimérica para impermeabilização sobre a proteção mecânica (2,0 kg/m²) - PISCINA | T33: 20_17º Pav. - Penthouse | U33: Penthouse x22
A34: =_xlfn.XLOOKUP(C34,$T$13:$T$58,$U$13:$U$58,"") -> 0 | B34: =UPPER(IF(F34="","",IF(IF(E34="","",LEN(E34)-LEN(SUBSTITUTE(E34,".","")))=2,(F34),B33))) -> IMPERMEABILIZAÇAO E TRATAMENTOS | C34: =PROPER(IF(OR(F34="",C33="PAVIMENTO"),"",IF(AND(IF(E34="","",LEN(E34)-LEN(SUBSTITUTE(E34,".","")))=3,H34=""),F34,C33))) -> 04_Mez. 2º Pav. / G3 | D34: =IF(H34="","","SERVIÇO") -> SERVIÇO | E34: 1.1.4.1 | F34: PAREDE: Sistema 2.5.3: Membrana de polímero acrílico com cimento e fibras sintéticas | Revestimento bicomponente à base de polímeros acrílicos com adição de cimento e fibras sintéticas (3,0 kg/m²) - ESQUADRIA | G34: m² | H34: 25.3 | I34: =_xlfn.XLOOKUP($F34,$M$66:$M$115,$N$66:$N$115) -> 2.5.3 | J34: =TRIM(RIGHT(SUBSTITUTE(SUBSTITUTE(F34,CHAR(10)," ")," ",REPT(" ",100)),100)) -> ESQUADRIA | K34: =TRIM(LEFT(SUBSTITUTE(SUBSTITUTE(F34,CHAR(10)," ")," ",REPT(" ",100)),100)) -> PAREDE: | M34: PAREDE: Sistema 7.1.6: Argamassa impermeabilizante sem cimento - MK-FEN 30 (F) | Argamassa não cimentícia com agentes incorporadores de ar (8,0 kg/m²) + Tela de poliéster nos pontos críticos - SAUNA | N34: =SUMIFS($H$13:$H$10253,$A$13:$A$10253,N$10,$F$13:$F$10253,$M34) -> 42.22 | O34: =SUMIFS($H$13:$H$10253,$A$13:$A$10253,O$10,$F$13:$F$10253,$M34) -> 0 | P34: =SUMIFS($H$13:$H$10253,$A$13:$A$10253,P$10,$F$13:$F$10253,$M34) -> 0 | Q34: =SUMIFS($H$13:$H$10253,$F$13:$F$10253,$M34) -> 42.22 | R34: PAREDE: Sistema 7.1.6: Argamassa impermeabilizante sem cimento - MK-FEN 30 (F) | Argamassa não cimentícia com agentes incorporadores de ar (8,0 kg/m²) + Tela de poliéster nos pontos críticos - SAUNA | T34: 21_18º Pav. - Penthouse | U34: Penthouse x22
A35: =_xlfn.XLOOKUP(C35,$T$13:$T$58,$U$13:$U$58,"") -> 0 | B35: =UPPER(IF(F35="","",IF(IF(E35="","",LEN(E35)-LEN(SUBSTITUTE(E35,".","")))=2,(F35),B34))) -> IMPERMEABILIZAÇAO E TRATAMENTOS | C35: =PROPER(IF(OR(F35="",C34="PAVIMENTO"),"",IF(AND(IF(E35="","",LEN(E35)-LEN(SUBSTITUTE(E35,".","")))=3,H35=""),F35,C34))) -> 05_3º Pav. / G4 | D35: =IF(H35="","","SERVIÇO") | E35: 1.1.5. | F35: 05_3º PAV. / G4 | I35: =IF(C35=F35,SUMIFS($H$12:$H$63964,$C$12:$C$63964,C35),"") -> 51.12 | M35: PISO: Sistema 7.1.6: Argamassa impermeabilizante sem cimento - MK-FEN 30 (F) | Argamassa não cimentícia com agentes incorporadores de ar (8,0 kg/m²) + Tela de poliéster nos pontos críticos - SAUNA | N35: =SUMIFS($H$13:$H$10253,$A$13:$A$10253,N$10,$F$13:$F$10253,$M35) -> 5.81 | O35: =SUMIFS($H$13:$H$10253,$A$13:$A$10253,O$10,$F$13:$F$10253,$M35) -> 0 | P35: =SUMIFS($H$13:$H$10253,$A$13:$A$10253,P$10,$F$13:$F$10253,$M35) -> 0 | Q35: =SUMIFS($H$13:$H$10253,$F$13:$F$10253,$M35) -> 5.81 | R35: PISO: Sistema 7.1.6: Argamassa impermeabilizante sem cimento - MK-FEN 30 (F) | Argamassa não cimentícia com agentes incorporadores de ar (8,0 kg/m²) + Tela de poliéster nos pontos críticos - SAUNA | T35: 22_19º Pav. - Penthouse | U35: Penthouse x22
A36: =_xlfn.XLOOKUP(C36,$T$13:$T$58,$U$13:$U$58,"") -> 0 | B36: =UPPER(IF(F36="","",IF(IF(E36="","",LEN(E36)-LEN(SUBSTITUTE(E36,".","")))=2,(F36),B35))) -> IMPERMEABILIZAÇAO E TRATAMENTOS | C36: =PROPER(IF(OR(F36="",C35="PAVIMENTO"),"",IF(AND(IF(E36="","",LEN(E36)-LEN(SUBSTITUTE(E36,".","")))=3,H36=""),F36,C35))) -> 05_3º Pav. / G4 | D36: =IF(H36="","","SERVIÇO") -> SERVIÇO | E36: 1.1.5.1 | F36: PAREDE: Sistema 2.8.6: Argamassa polimérica para impermeabilização + Membrana de polímero acrílico com cimento e fibras sintéticas | Argamassa impermeabilizante bicomponente à base de aditivos minerais e polímeros (2,0 kg/m²) + - CISTERNA | G36: m² | H36: 15.84 | I36: 2.8.6 | J36: =TRIM(RIGHT(SUBSTITUTE(SUBSTITUTE(F36,CHAR(10)," ")," ",REPT(" ",100)),100)) -> CISTERNA | K36: =TRIM(LEFT(SUBSTITUTE(SUBSTITUTE(F36,CHAR(10)," ")," ",REPT(" ",100)),100)) -> PAREDE: | M36: PAREDE: Sistema 4.2.4: Manta asfáltica 4mm aderida com asfalto oxidado modificado | Primer asfáltico à base d'água (0,4 L/m²) + Asfalto oxidado modificado (2,5 kg/m²) + Manta asfáltica AA 4mm Tipo III Classe - ESPAÇO CROSSFIT | N36: =SUMIFS($H$13:$H$10253,$A$13:$A$10253,N$10,$F$13:$F$10253,$M36) -> 32.09 | O36: =SUMIFS($H$13:$H$10253,$A$13:$A$10253,O$10,$F$13:$F$10253,$M36) -> 0 | P36: =SUMIFS($H$13:$H$10253,$A$13:$A$10253,P$10,$F$13:$F$10253,$M36) -> 0 | Q36: =SUMIFS($H$13:$H$10253,$F$13:$F$10253,$M36) -> 32.09 | R36: PAREDE: Sistema 4.2.4: Manta asfáltica 4mm aderida com asfalto oxidado modificado | Primer asfáltico à base d'água (0,4 L/m²) + Asfalto oxidado modificado (2,5 kg/m²) + Manta asfáltica AA 4mm Tipo III Classe B + Banho de asfalto oxidado modificado (2,5 kg/m²) - ESPAÇO CROSSFIT | T36: 23_20º Pav. - Penthouse | U36: Penthouse x22
A37: =_xlfn.XLOOKUP(C37,$T$13:$T$58,$U$13:$U$58,"") -> 0 | B37: =UPPER(IF(F37="","",IF(IF(E37="","",LEN(E37)-LEN(SUBSTITUTE(E37,".","")))=2,(F37),B36))) -> IMPERMEABILIZAÇAO E TRATAMENTOS | C37: =PROPER(IF(OR(F37="",C36="PAVIMENTO"),"",IF(AND(IF(E37="","",LEN(E37)-LEN(SUBSTITUTE(E37,".","")))=3,H37=""),F37,C36))) -> 05_3º Pav. / G4 | D37: =IF(H37="","","SERVIÇO") -> SERVIÇO | E37: 1.1.5.2 | F37: PISO: Sistema 2.8.6: Argamassa polimérica para impermeabilização + Membrana de polímero acrílico com cimento e fibras sintéticas | Argamassa impermeabilizante bicomponente à base de aditivos minerais e polímeros (2,0 kg/m²) + - CISTERNA | G37: m² | H37: 4.99 | I37: 2.8.6 | J37: =TRIM(RIGHT(SUBSTITUTE(SUBSTITUTE(F37,CHAR(10)," ")," ",REPT(" ",100)),100)) -> CISTERNA | K37: =TRIM(LEFT(SUBSTITUTE(SUBSTITUTE(F37,CHAR(10)," ")," ",REPT(" ",100)),100)) -> PISO: | M37: PISO: Sistema 4.2.4: Manta asfáltica 4mm aderida com asfalto oxidado modificado | Primer asfáltico à base d'água (0,4 L/m²) - ESPAÇO CROSSFIT | N37: =SUMIFS($H$13:$H$10253,$A$13:$A$10253,N$10,$F$13:$F$10253,$M37) -> 87.98 | O37: =SUMIFS($H$13:$H$10253,$A$13:$A$10253,O$10,$F$13:$F$10253,$M37) -> 0 | P37: =SUMIFS($H$13:$H$10253,$A$13:$A$10253,P$10,$F$13:$F$10253,$M37) -> 0 | Q37: =SUMIFS($H$13:$H$10253,$F$13:$F$10253,$M37) -> 87.98 | R37: PISO: Sistema 4.2.4: Manta asfáltica 4mm aderida com asfalto oxidado modificado | Primer asfáltico à base d'água (0,4 L/m²) - ESPAÇO CROSSFIT | T37: 24_21º Pav. - Penthouse | U37: Penthouse x22
A38: =_xlfn.XLOOKUP(C38,$T$13:$T$58,$U$13:$U$58,"") -> 0 | B38: =UPPER(IF(F38="","",IF(IF(E38="","",LEN(E38)-LEN(SUBSTITUTE(E38,".","")))=2,(F38),B37))) -> IMPERMEABILIZAÇAO E TRATAMENTOS | C38: =PROPER(IF(OR(F38="",C37="PAVIMENTO"),"",IF(AND(IF(E38="","",LEN(E38)-LEN(SUBSTITUTE(E38,".","")))=3,H38=""),F38,C37))) -> 05_3º Pav. / G4 | D38: =IF(H38="","","SERVIÇO") -> SERVIÇO | E38: 1.1.5.3 | F38: TETO: Sistema 7.1.2: Argamassa impermeabilizante sem cimento - MK-FEN 30 (F) | Argamassa não cimentícia com agentes incorporadores de ar (4,0 kg/m²) + Tela de poliéster nos pontos críticos - CISTERNA | G38: m² | H38: 4.99 | I38: =_xlfn.XLOOKUP($F38,$M$66:$M$115,$N$66:$N$115) -> 7.1.2 | J38: =TRIM(RIGHT(SUBSTITUTE(SUBSTITUTE(F38,CHAR(10)," ")," ",REPT(" ",100)),100)) -> CISTERNA | K38: =TRIM(LEFT(SUBSTITUTE(SUBSTITUTE(F38,CHAR(10)," ")," ",REPT(" ",100)),100)) -> TETO: | M38: PAREDE: Sistema 2.5.3: Membrana de polímero acrílico com cimento e fibras sintéticas - ÁREA DE SERVIÇO | N38: =SUMIFS($H$13:$H$10253,$A$13:$A$10253,N$10,$F$13:$F$10253,$M38) -> 27.65 | O38: =SUMIFS($H$13:$H$10253,$A$13:$A$10253,O$10,$F$13:$F$10253,$M38) -> 134.64 | P38: =SUMIFS($H$13:$H$10253,$A$13:$A$10253,P$10,$F$13:$F$10253,$M38) -> 219.87 | Q38: =SUMIFS($H$13:$H$10253,$F$13:$F$10253,$M38) -> 382.16 | R38: PAREDE: Sistema 2.5.3: Membrana de polímero acrílico com cimento e fibras sintéticas | Revestimento bicomponente à base de polímeros acrílicos com adição de cimento e fibras sintéticas (3,0 kg/m²)+ Tela de poliéster nos pontos críticos - ÁREA DE SERVIÇO | T38: 25_22º Pav. - Penthouse | U38: Penthouse x22
A39: =_xlfn.XLOOKUP(C39,$T$13:$T$58,$U$13:$U$58,"") -> 0 | B39: =UPPER(IF(F39="","",IF(IF(E39="","",LEN(E39)-LEN(SUBSTITUTE(E39,".","")))=2,(F39),B38))) -> IMPERMEABILIZAÇAO E TRATAMENTOS | C39: =PROPER(IF(OR(F39="",C38="PAVIMENTO"),"",IF(AND(IF(E39="","",LEN(E39)-LEN(SUBSTITUTE(E39,".","")))=3,H39=""),F39,C38))) -> 05_3º Pav. / G4 | D39: =IF(H39="","","SERVIÇO") -> SERVIÇO | E39: 1.1.5.4 | F39: PAREDE: Sistema 2.5.3: Membrana de polímero acrílico com cimento e fibras sintéticas | Revestimento bicomponente à base de polímeros acrílicos com adição de cimento e fibras sintéticas (3,0 kg/m²) - ESQUADRIA | G39: m² | H39: 25.3 | I39: =_xlfn.XLOOKUP($F39,$M$66:$M$115,$N$66:$N$115) -> 2.5.3 | J39: =TRIM(RIGHT(SUBSTITUTE(SUBSTITUTE(F39,CHAR(10)," ")," ",REPT(" ",100)),100)) -> ESQUADRIA | K39: =TRIM(LEFT(SUBSTITUTE(SUBSTITUTE(F39,CHAR(10)," ")," ",REPT(" ",100)),100)) -> PAREDE: | M39: PISO: Sistema 2.5.3: Membrana de polímero acrílico com cimento e fibras sintéticas | Revestimento bicomponente à base de polímeros acrílicos com adição de cimento e fibras sintéticas (3,0 kg/m²)+ Tela de poliéster nos pontos críticos - ÁREA DE SERVIÇO | N39: =SUMIFS($H$13:$H$10253,$A$13:$A$10253,N$10,$F$13:$F$10253,$M39) -> 12.95 | O39: =SUMIFS($H$13:$H$10253,$A$13:$A$10253,O$10,$F$13:$F$10253,$M39) -> 55.44 | P39: =SUMIFS($H$13:$H$10253,$A$13:$A$10253,P$10,$F$13:$F$10253,$M39) -> 95.76 | Q39: =SUMIFS($H$13:$H$10253,$F$13:$F$10253,$M39) -> 164.15 | R39: PISO: Sistema 2.5.3: Membrana de polímero acrílico com cimento e fibras sintéticas | Revestimento bicomponente à base de polímeros acrílicos com adição de cimento e fibras sintéticas (3,0 kg/m²)+ Tela de poliéster nos pontos críticos - ÁREA DE SERVIÇO | T39: 26_23º Pav. - Penthouse | U39: Penthouse x22
A40: =_xlfn.XLOOKUP(C40,$T$13:$T$58,$U$13:$U$58,"") -> 0 | B40: =UPPER(IF(F40="","",IF(IF(E40="","",LEN(E40)-LEN(SUBSTITUTE(E40,".","")))=2,(F40),B39))) -> IMPERMEABILIZAÇAO E TRATAMENTOS | C40: =PROPER(IF(OR(F40="",C39="PAVIMENTO"),"",IF(AND(IF(E40="","",LEN(E40)-LEN(SUBSTITUTE(E40,".","")))=3,H40=""),F40,C39))) -> 06_Mez. 3º Pav. / G5 | D40: =IF(H40="","","SERVIÇO") | E40: 1.1.6. | F40: 06_MEZ. 3º PAV. / G5 | I40: =IF(C40=F40,SUMIFS($H$12:$H$63964,$C$12:$C$63964,C40),"") -> 30.49 | M40: PAREDE: Sistema 7.1.6: Argamassa impermeabilizante sem cimento - MK-FEN 30 (F) | Argamassa não cimentícia com agentes incorporadores de ar (8,0 kg/m²) + Tela de poliéster nos pontos críticos - ÁREA TÉCNICA | N40: =SUMIFS($H$13:$H$10253,$A$13:$A$10253,N$10,$F$13:$F$10253,$M40) -> 6.08 | O40: =SUMIFS($H$13:$H$10253,$A$13:$A$10253,O$10,$F$13:$F$10253,$M40) -> 52.08 | P40: =SUMIFS($H$13:$H$10253,$A$13:$A$10253,P$10,$F$13:$F$10253,$M40) -> 71.79 | Q40: =SUMIFS($H$13:$H$10253,$F$13:$F$10253,$M40) -> 129.95 | R40: PAREDE: Sistema 7.1.6: Argamassa impermeabilizante sem cimento - MK-FEN 30 (F) | Argamassa não cimentícia com agentes incorporadores de ar (8,0 kg/m²) + Tela de poliéster nos pontos críticos - ÁREA TÉCNICA | T40: 27_24º Pav. - Penthouse | U40: Penthouse x22
A41: =_xlfn.XLOOKUP(C41,$T$13:$T$58,$U$13:$U$58,"") -> 0 | B41: =UPPER(IF(F41="","",IF(IF(E41="","",LEN(E41)-LEN(SUBSTITUTE(E41,".","")))=2,(F41),B40))) -> IMPERMEABILIZAÇAO E TRATAMENTOS | C41: =PROPER(IF(OR(F41="",C40="PAVIMENTO"),"",IF(AND(IF(E41="","",LEN(E41)-LEN(SUBSTITUTE(E41,".","")))=3,H41=""),F41,C40))) -> 06_Mez. 3º Pav. / G5 | D41: =IF(H41="","","SERVIÇO") -> SERVIÇO | E41: 1.1.6.1 | F41: PAREDE: Sistema 2.5.3: Membrana de polímero acrílico com cimento e fibras sintéticas | Revestimento bicomponente à base de polímeros acrílicos com adição de cimento e fibras sintéticas (3,0 kg/m²) - ESQUADRIA | G41: m² | H41: 24.05 | I41: =_xlfn.XLOOKUP($F41,$M$66:$M$115,$N$66:$N$115) -> 2.5.3 | J41: =TRIM(RIGHT(SUBSTITUTE(SUBSTITUTE(F41,CHAR(10)," ")," ",REPT(" ",100)),100)) -> ESQUADRIA | K41: =TRIM(LEFT(SUBSTITUTE(SUBSTITUTE(F41,CHAR(10)," ")," ",REPT(" ",100)),100)) -> PAREDE: | M41: PISO: Sistema 7.1.6: Argamassa impermeabilizante sem cimento - MK-FEN 30 (F) | Argamassa não cimentícia com agentes incorporadores de ar (8,0 kg/m²) + Tela de poliéster nos pontos críticos - ÁREA TÉCNICA | N41: =SUMIFS($H$13:$H$10253,$A$13:$A$10253,N$10,$F$13:$F$10253,$M41) -> 11.34 | O41: =SUMIFS($H$13:$H$10253,$A$13:$A$10253,O$10,$F$13:$F$10253,$M41) -> 86.4 | P41: =SUMIFS($H$13:$H$10253,$A$13:$A$10253,P$10,$F$13:$F$10253,$M41) -> 127.59 | Q41: =SUMIFS($H$13:$H$10253,$F$13:$F$10253,$M41) -> 225.33 | R41: PISO: Sistema 7.1.6: Argamassa impermeabilizante sem cimento - MK-FEN 30 (F) | Argamassa não cimentícia com agentes incorporadores de ar (8,0 kg/m²) + Tela de poliéster nos pontos críticos - ÁREA TÉCNICA | T41: 28_25º Pav. Penthouse | U41: Penthouse x22
A42: =_xlfn.XLOOKUP(C42,$T$13:$T$58,$U$13:$U$58,"") -> 0 | B42: =UPPER(IF(F42="","",IF(IF(E42="","",LEN(E42)-LEN(SUBSTITUTE(E42,".","")))=2,(F42),B41))) -> IMPERMEABILIZAÇAO E TRATAMENTOS | C42: =PROPER(IF(OR(F42="",C41="PAVIMENTO"),"",IF(AND(IF(E42="","",LEN(E42)-LEN(SUBSTITUTE(E42,".","")))=3,H42=""),F42,C41))) -> 06_Mez. 3º Pav. / G5 | D42: =IF(H42="","","SERVIÇO") -> SERVIÇO | E42: 1.1.6.2 | F42: PISO: Sistema 2.5.3: Membrana de polímero acrílico com cimento e fibras sintéticas | Revestimento bicomponente à base de polímeros acrílicos com adição de cimento e fibras sintéticas (3,0 kg/m²) - ESQUADRIA | G42: m² | H42: 6.44 | I42: =_xlfn.XLOOKUP($F42,$M$66:$M$115,$N$66:$N$115) -> 2.5.3 | J42: =TRIM(RIGHT(SUBSTITUTE(SUBSTITUTE(F42,CHAR(10)," ")," ",REPT(" ",100)),100)) -> ESQUADRIA | K42: =TRIM(LEFT(SUBSTITUTE(SUBSTITUTE(F42,CHAR(10)," ")," ",REPT(" ",100)),100)) -> PISO: | M42: PAREDE: Sistema 2.5.3: Membrana de polímero acrílico com cimento e fibras sintéticas | Revestimento bicomponente à base de polímeros acrílicos com adição de cimento e fibras sintéticas (3,0 kg/m²) - BANHEIRO | N42: =SUMIFS($H$13:$H$10253,$A$13:$A$10253,N$10,$F$13:$F$10253,$M42) -> 68.29 | O42: =SUMIFS($H$13:$H$10253,$A$13:$A$10253,O$10,$F$13:$F$10253,$M42) -> 216.48 | P42: =SUMIFS($H$13:$H$10253,$A$13:$A$10253,P$10,$F$13:$F$10253,$M42) -> 498.57 | Q42: =SUMIFS($H$13:$H$10253,$F$13:$F$10253,$M42) -> 783.34 | R42: PAREDE: Sistema 2.5.3: Membrana de polímero acrílico com cimento e fibras sintéticas | Revestimento bicomponente à base de polímeros acrílicos com adição de cimento e fibras sintéticas (3,0 kg/m²) - BANHEIRO | T42: 29_26º Pav. - Penthouse | U42: Penthouse x22
...

Sheet Ger_Executivo_Manual
H4: PROJETO: | I4: Electra Towers | O4: REVISÃO: | P4: DATA
H5: EMPRESA: | I5: Thozen | O5: R00
A6: Unidade Construtiva | B6: Célula Construtiva | C6: Etapa | D6: Subetapa | E6: Serviço | G6: GERENCIAMENTO EXECUTIVO
A7: 0 | B7: 0 | C7: 0 | D7: 0 | E7: 0 | G7: EAP | H7: NIVEL | I7: Item | J7: Descrição | K7: Unidade | L7: Quant. | M7: Preço un | N7: Total | O7: Considerações | P7: Situação
A8: 0 | B8: 1 | C8: 0 | D8: 0 | E8: 0 | H8: CÉLULA CONSTRUTIVA | I8: 01 | J8: MOVIMENTAÇÃO DE TERRA
A9: 0 | B9: 1 | C9: 1 | D9: 0 | E9: 0 | H9: ETAPA | I9: 01.001 | J9: DEMOLIÇÕES, LIMPEZA DE TERRENO E LOCAÇÃO DE OBRA | N9: 26235.314 | O9: 1.5663183
A10: 0 | B10: 1 | C10: 1 | D10: 1 | E10: 0 | H10: SUBETAPA | I10: 01.001.001 | J10: Locação e gabarito de obra | N10: 26235.314 | O10: 1.5663183
A11: 0 | B11: 1 | C11: 1 | D11: 1 | E11: 1 | G11: MOVIMENTAÇÃO DE TERRA | H11: SERVIÇO | I11: 01.001.001.001 | J11: Locação da obra | K11: m2 | N11: 26235.314 | P11: Pendente
A12: 0 | B12: 1 | C12: 2 | D12: 0 | E12: 1 | H12: ETAPA | I12: 01.002 | J12: SERVIÇOS PRELIMINARES
A13: 0 | B13: 1 | C13: 2 | D13: 1 | E13: 0 | H13: SUBETAPA | I13: 01.002.001 | J13: Limpeza Permanente e Remoção entulho
A14: 0 | B14: 1 | C14: 2 | D14: 1 | E14: 1 | G14: MOVIMENTAÇÃO DE TERRA | H14: SERVIÇO | I14: 01.002.001.001 | J14: Limpeza da camada vegetal | K14: m2 | P14: Pendente
A15: 0 | B15: 1 | C15: 2 | D15: 1 | E15: 2 | G15: MOVIMENTAÇÃO DE TERRA | H15: SERVIÇO | I15: 01.002.001.002 | J15: Remoção de entulhos e resíduos | P15: Pendente
A16: 0 | B16: 1 | C16: 2 | D16: 2 | E16: 0 | H16: SUBETAPA | I16: 01.002.002 | J16: Mão de Obra de Canteiro
A17: 0 | B17: 1 | C17: 2 | D17: 2 | E17: 1 | G17: MOVIMENTAÇÃO DE TERRA | H17: SERVIÇO | I17: 01.002.002.001 | J17: Mão de Obra de Canteiro | K17: vb | P17: Pendente
A18: 0 | B18: 1 | C18: 3 | D18: 0 | E18: 1 | H18: ETAPA | I18: 01.003 | J18: SERVIÇOS DE TERRAPLANAGEM | N18: 271126.19 | O18: 16.186957
A19: 0 | B19: 1 | C19: 3 | D19: 1 | E19: 0 | H19: SUBETAPA | I19: 01.003.001 | J19: Mao de obra - movimentações de terra | N19: 271126.19 | O19: 16.186957
A20: 0 | B20: 1 | C20: 3 | D20: 1 | E20: 1 | G20: MOVIMENTAÇÃO DE TERRA | H20: SERVIÇO | I20: 01.003.001.001 | J20: Mão de obra movimentação de terra | K20: vb | N20: 233000 | P20: Pendente
A21: 0 | B21: 1 | C21: 4 | D21: 0 | E21: 2 | H21: ETAPA | I21: 01.004 | J21: SERVIÇO DE DRENAGEM | N21: 80000 | O21: 4.7762135
A22: 0 | B22: 1 | C22: 4 | D22: 1 | E22: 0 | H22: SUBETAPA | I22: 01.004.001 | J22: Drenagem | N22: 80000 | O22: 4.7762135
A23: 0 | B23: 1 | C23: 4 | D23: 1 | E23: 1 | G23: MOVIMENTAÇÃO DE TERRA | H23: SERVIÇO | I23: 01.004.001.001 | J23: Rebaixamento de Lençol freático | K23: vb | N23: 80000 | P23: Pendente
A24: 0 | B24: 2 | C24: 0 | D24: 1 | E24: 1 | H24: CÉLULA CONSTRUTIVA | I24: 02 | J24: CONTENÇÃO | N24: 772006.63 | O24: 46.090856
A25: 0 | B25: 2 | C25: 1 | D25: 0 | E25: 1 | H25: ETAPA | I25: 02.001 | J25: MURETA GUIA | N25: 18739.389 | O25: 1.1187915
A26: 0 | B26: 2 | C26: 1 | D26: 1 | E26: 0 | H26: SUBETAPA | I26: 02.001.001 | J26: Forma | N26: 6673.9436 | O26: 0.39845225
A27: 0 | B27: 2 | C27: 1 | D27: 1 | E27: 1 | G27: CONTENÇÃO | H27: SERVIÇO | I27: 02.001.001.001 | J27: Forma para infraestrutura em Tábuas de Madeira Serrada 2x reaproveitamento | K27: m2 | L27: 111.3136 | M27: 59.956229 | N27: 6673.9436 | P27: Pendente
A28: 0 | B28: 2 | C28: 1 | D28: 2 | E28: 0 | H28: SUBETAPA | I28: 02.001.002 | J28: Armadura | N28: 4318.7306 | O28: 0.25783974
A29: 0 | B29: 2 | C29: 1 | D29: 2 | E29: 1 | G29: CONTENÇÃO | H29: SERVIÇO | I29: 02.001.002.001 | J29: Armação aço CA-50 ø 6,3mm para Contenções (corte e dobra em obra) | K29: un | L29: 670.32 | M29: 6.0795674 | N29: 4075.2556 | P29: Pendente
A30: 0 | B30: 2 | C30: 1 | D30: 2 | E30: 2 | G30: CONTENÇÃO | H30: SERVIÇO | I30: 02.001.002.002 | J30: Armação aço CA-50 ø 12,5mm para Contenções (corte e dobra em obra) | K30: un | L30: 41.6016 | M30: 5.8525391 | N30: 243.47499 | P30: Pendente
A31: 0 | B31: 2 | C31: 1 | D31: 3 | E31: 0 | H31: SUBETAPA | I31: 02.001.003 | J31: Concreto | N31: 7746.7147 | O31: 0.46249954
