Workbook

Sheet ORÇAMENTO_EXECUTIVO
A1: ETAPA | B1: VALOR ORÇADO | C1: % | D1: VALOR / m²
A2: GERENCIAMENTO TÉCNICO E ADMINISTRATIVO | B2: =[1]Relatório!$X$51 -> 2384931.9 | C2: =B2/B$19 -> 0.11233347 | D2: =B2/ORÇAMENTO_EXECUTIVO!H$2 -> 381.86527 | G2: ÁREA CONSTRUÍDA | H2: 6245.48 | I2: m²
A3: MOVIMENTAÇÃO DE TERRA | B3: =[1]Relatório!$X$15 -> 230869.63 | C3: =B3/B$19 -> 0.010874267 | D3: =B3/ORÇAMENTO_EXECUTIVO!H$2 -> 36.965875
A4: INFRAESTRUTURA | B4: =RELATÓRIO!X16 -> 933522.84 | C4: =B4/B$19 -> 0.043970168 | D4: =B4/ORÇAMENTO_EXECUTIVO!H$2 -> 149.47175
A5: SUPRAESTRUTURA | B5: =RELATÓRIO!X17 -> 4384787.1 | C5: =B5/B$19 -> 0.20652931 | D5: =B5/ORÇAMENTO_EXECUTIVO!H$2 -> 702.07367
A6: PAREDES E PAINEIS | B6: =RELATÓRIO!X18 -> 863630.83 | C6: =B6/B$19 -> 0.040678162 | D6: =B6/ORÇAMENTO_EXECUTIVO!H$2 -> 138.28094
A7: INSTALAÇÕES ELÉTRICAS, HIDRÁULICAS, GLP E PREVENTIVAS | B7: =RELATÓRIO!X20+RELATÓRIO!X21+RELATÓRIO!X22+RELATÓRIO!X23+RELATÓRIO!X24+RELATÓRIO!X32 -> 1935344.2 | C7: =B7/B$19 -> 0.091157289 | D7: =B7/ORÇAMENTO_EXECUTIVO!H$2 -> 309.87918
A8: EQUIPAMENTOS E SISTEMAS ESPECIAIS | B8: =RELATÓRIO!X25+RELATÓRIO!X26 -> 1404690.9 | C8: =B8/B$19 -> 0.066162811 | D8: =B8/ORÇAMENTO_EXECUTIVO!H$2 -> 224.9132
A9: IMPERMEABILIZAÇÃO | B9: =RELATÓRIO!X19 -> 420004.94 | C9: =B9/B$19 -> 0.019782792 | D9: =B9/ORÇAMENTO_EXECUTIVO!H$2 -> 67.249425
A10: REVESTIMENTOS INTERNOS DE PAREDE | B10: =RELATÓRIO!X27 -> 1030085.4 | C10: =B10/B$19 -> 0.048518394 | D10: =B10/ORÇAMENTO_EXECUTIVO!H$2 -> 164.93295
A11: REVESTIMENTOS E ACABAMENTOS INTERNOS EM TETO | B11: =RELATÓRIO!X28 -> 344380.88 | C11: =B11/B$19 -> 0.016220798 | D11: =B11/ORÇAMENTO_EXECUTIVO!H$2 -> 55.140819
A12: PISOS E PAVIMENTAÇÕES | B12: =RELATÓRIO!X29 -> 1388564.5 | C12: =B12/B$19 -> 0.065403238 | D12: =B12/ORÇAMENTO_EXECUTIVO!H$2 -> 222.33111
A13: PINTURA INTERNA | B13: =RELATÓRIO!X30 -> 712320.05 | C13: =B13/B$19 -> 0.033551222 | D13: =B13/ORÇAMENTO_EXECUTIVO!H$2 -> 114.05369
A14: ESQUADRIAS, VIDROS E FERRAGENS | B14: =RELATÓRIO!X31 -> 1623887.7 | C14: =B14/B$19 -> 0.076487273 | D14: =B14/ORÇAMENTO_EXECUTIVO!H$2 -> 260.01007
A15: COBERTURA | B15: =RELATÓRIO!X33 -> 17889.51 | C15: =B15/B$19 -> 0.00084261973 | D15: =B15/ORÇAMENTO_EXECUTIVO!H$2 -> 2.8643931
A16: REVESTIMENTOS E ACABAMENTOS DE FACHADA | B16: =RELATÓRIO!X34 -> 1579912.1 | C16: =B16/B$19 -> 0.074415963 | D16: =B16/ORÇAMENTO_EXECUTIVO!H$2 -> 252.96888
A17: SERVIÇOS COMPLEMENTARES | B17: =RELATÓRIO!X35 -> 1676000 | C17: =B17/B$19 -> 0.078941831 | D17: =B17/ORÇAMENTO_EXECUTIVO!H$2 -> 268.35407
A18: IMPREVISTOS E CONTINGENCIAS | B18: =RELATÓRIO!X36 -> 300000 | C18: =B18/B$19 -> 0.014130399 | D18: =B18/ORÇAMENTO_EXECUTIVO!H$2 -> 48.034739
A19: TOTAL | B19: =SUM(B2:B18) -> 21230823 | C19: =SUM(C2:C18) -> 1 | D19: =SUM(D2:D18) -> 3399.39
A20: CUB/SC | B20: 2793.27 | C20: 45474 | D20: =+D19/B20 -> 1.216993
A25: DESCRIÇÃO - 25 APARTAMENTOS (ÁREA TOTAL) | B25: ÁREA | C25: VALOR TOTAL
A26: VALOR POR UNIDADE PRIVATIVA (R$/m²) | B26: 3199.82 | C26: =B19/B26 -> 6635.0053
A27: VALOR POR UNIDADE TIPO 01 | B27: =121 -> 121 | C27: =C26*B27 -> 802835.64
A28: VALOR POR UNIDADE TIPO 02 | B28: =121 -> 121 | C28: =C26*B28 -> 802835.64
A29: VALOR POR UNIDADE DIFERENCIADO | B29: 245.7 | C29: =B29*C26 -> 1630220.8
A30: VALOR POR UNIDADE TIPO 03 | B30: =124.58 -> 124.58 | C30: =B30*C26 -> 826588.96
A33: ETAPA | B33: VALOR ORÇADO | C33: % | D33: VALOR / m² | G33: ÁREA PRIVATIVA | H33: 3199.82 | I33: m²
A34: GERENCIAMENTO TÉCNICO E ADMINISTRATIVO | B34: 2384931.9 | C34: =B34/B$19 -> 0.11233347 | D34: =B34/H33 -> 745.33314
A35: MOVIMENTAÇÃO DE TERRA | B35: 230869.63 | C35: =B35/B$19 -> 0.010874267 | D35: =B35/H33 -> 72.150818
A36: INFRAESTRUTURA | B36: 933522.84 | C36: =B36/B$19 -> 0.043970168 | D36: =B36/H33 -> 291.7423
A37: SUPRAESTRUTURA | B37: 4384787.1 | C37: =B37/B$19 -> 0.20652931 | D37: =B37/H33 -> 1370.323
A38: PAREDES E PAINEIS | B38: 863630.83 | C38: =B38/B$19 -> 0.040678162 | D38: =B38/H33 -> 269.89982
A39: INSTALAÇÕES ELÉTRICAS, HIDRÁULICAS, GLP E PREVENTIVAS | B39: 1935344.2 | C39: =B39/B$19 -> 0.091157289 | D39: =B39/H33 -> 604.82909
A40: EQUIPAMENTOS E SISTEMAS ESPECIAIS | B40: 1404690.9 | C40: =B40/B$19 -> 0.066162811 | D40: =B40/H33 -> 438.9906
A41: IMPERMEABILIZAÇÃO | B41: 420004.94 | C41: =B41/B$19 -> 0.019782792 | D41: =B41/H33 -> 131.25893
A42: REVESTIMENTOS INTERNOS DE PAREDE | B42: 1030085.4 | C42: =B42/B$19 -> 0.048518394 | D42: =B42/H33 -> 321.9198
A43: REVESTIMENTOS E ACABAMENTOS INTERNOS EM TETO | B43: 344380.88 | C43: =B43/B$19 -> 0.016220798 | D43: =B43/H33 -> 107.62508
A44: PISOS E PAVIMENTAÇÕES | B44: 1388564.5 | C44: =B44/B$19 -> 0.065403238 | D44: =B44/H33 -> 433.95083
A45: PINTURA INTERNA | B45: 712320.05 | C45: =B45/B$19 -> 0.033551222 | D45: =B45/H33 -> 222.61254
A46: ESQUADRIAS, VIDROS E FERRAGENS | B46: 1623887.7 | C46: =B46/B$19 -> 0.076487273 | D46: =B46/H33 -> 507.49346
...

Sheet ANÁLISE_CUSTOS
A1: ETAPA | B1: OBRA | D1: OBRA SIMILAR
B2: VALOR | C2: VALOR / m² | D2: VALOR / m²
A3: =ORÇAMENTO_EXECUTIVO!A3 -> MOVIMENTAÇÃO DE TERRA | B3: =RELATÓRIO!X15 -> 230869.63 | C3: =ORÇAMENTO_EXECUTIVO!D3 -> 36.965875 | D3: =FIXED(CÁLCULO_MÉDIAS!J9,2,FALSE)&" "&"-"&FIXED(CÁLCULO_MÉDIAS!K9,2,FALSE) -> 10,00 -15,00
A4: =ORÇAMENTO_EXECUTIVO!A4 -> INFRAESTRUTURA | B4: =RELATÓRIO!X16 -> 933522.84 | C4: =ORÇAMENTO_EXECUTIVO!D4 -> 149.47175 | D4: =FIXED(CÁLCULO_MÉDIAS!J10,2,FALSE)&" "&"-"&FIXED(CÁLCULO_MÉDIAS!K10,2,FALSE) -> 140,00 -190,00
A5: =ORÇAMENTO_EXECUTIVO!A5 -> SUPRAESTRUTURA | B5: =RELATÓRIO!X17 -> 4384787.1 | C5: =ORÇAMENTO_EXECUTIVO!D5 -> 702.07367 | D5: =FIXED(CÁLCULO_MÉDIAS!J11,2,FALSE)&" "&"-"&FIXED(CÁLCULO_MÉDIAS!K11,2,FALSE) -> 650,00 -695,00
A6: =ORÇAMENTO_EXECUTIVO!A6 -> PAREDES E PAINEIS | B6: =RELATÓRIO!X18 -> 863630.83 | C6: =ORÇAMENTO_EXECUTIVO!D6 -> 138.28094 | D6: =FIXED(CÁLCULO_MÉDIAS!J12,2,FALSE)&" "&"-"&FIXED(CÁLCULO_MÉDIAS!K12,2,FALSE) -> 120,00 -135,00
A7: =ORÇAMENTO_EXECUTIVO!A7 -> INSTALAÇÕES ELÉTRICAS, HIDRÁULICAS, GLP E PREVENTIVAS | B7: =RELATÓRIO!X20+RELATÓRIO!X21+RELATÓRIO!X22+RELATÓRIO!X23+RELATÓRIO!X24+RELATÓRIO!X32 -> 1935344.2 | C7: =ORÇAMENTO_EXECUTIVO!D7 -> 309.87918 | D7: =FIXED(CÁLCULO_MÉDIAS!J13,2,FALSE)&" "&"-"&FIXED(CÁLCULO_MÉDIAS!K13,2,FALSE) -> 270,00 -365,00
A8: =ORÇAMENTO_EXECUTIVO!A8 -> EQUIPAMENTOS E SISTEMAS ESPECIAIS | B8: =RELATÓRIO!X25+RELATÓRIO!X26 -> 1404690.9 | C8: =ORÇAMENTO_EXECUTIVO!D8 -> 224.9132 | D8: =FIXED(CÁLCULO_MÉDIAS!J14,2,FALSE)&" "&"-"&FIXED(CÁLCULO_MÉDIAS!K14,2,FALSE) -> 140,00 -170,00
A9: =ORÇAMENTO_EXECUTIVO!A9 -> IMPERMEABILIZAÇÃO | B9: =RELATÓRIO!X19 -> 420004.94 | C9: =ORÇAMENTO_EXECUTIVO!D9 -> 67.249425 | D9: =FIXED(CÁLCULO_MÉDIAS!J15,2,FALSE)&" "&"-"&FIXED(CÁLCULO_MÉDIAS!K15,2,FALSE) -> 45,00 -80,00
A10: =ORÇAMENTO_EXECUTIVO!A10 -> REVESTIMENTOS INTERNOS DE PAREDE | B10: =RELATÓRIO!X27 -> 1030085.4 | C10: =ORÇAMENTO_EXECUTIVO!D10 -> 164.93295 | D10: =FIXED(CÁLCULO_MÉDIAS!J16,2,FALSE)&" "&"-"&FIXED(CÁLCULO_MÉDIAS!K16,2,FALSE) -> 145,00 -190,00
A11: =ORÇAMENTO_EXECUTIVO!A11 -> REVESTIMENTOS E ACABAMENTOS INTERNOS EM TETO | B11: =RELATÓRIO!X28 -> 344380.88 | C11: =ORÇAMENTO_EXECUTIVO!D11 -> 55.140819 | D11: =FIXED(CÁLCULO_MÉDIAS!J17,2,FALSE)&" "&"-"&FIXED(CÁLCULO_MÉDIAS!K17,2,FALSE) -> 55,00 -70,00
A12: =ORÇAMENTO_EXECUTIVO!A12 -> PISOS E PAVIMENTAÇÕES | B12: =RELATÓRIO!X29 -> 1388564.5 | C12: =ORÇAMENTO_EXECUTIVO!D12 -> 222.33111 | D12: =FIXED(CÁLCULO_MÉDIAS!J18,2,FALSE)&" "&"-"&FIXED(CÁLCULO_MÉDIAS!K18,2,FALSE) -> 170,00 -210,00
A13: =ORÇAMENTO_EXECUTIVO!A13 -> PINTURA INTERNA | B13: =RELATÓRIO!X30 -> 712320.05 | C13: =ORÇAMENTO_EXECUTIVO!D13 -> 114.05369 | D13: =FIXED(CÁLCULO_MÉDIAS!J19,2,FALSE)&" "&"-"&FIXED(CÁLCULO_MÉDIAS!K19,2,FALSE) -> 100,00 -135,00
A14: =ORÇAMENTO_EXECUTIVO!A14 -> ESQUADRIAS, VIDROS E FERRAGENS | B14: =RELATÓRIO!X31 -> 1623887.7 | C14: =ORÇAMENTO_EXECUTIVO!D14 -> 260.01007 | D14: =FIXED(CÁLCULO_MÉDIAS!J20,2,FALSE)&" "&"-"&FIXED(CÁLCULO_MÉDIAS!K20,2,FALSE) -> 250,00 -290,00
A15: COBERTURA | B15: =RELATÓRIO!X33 -> 17889.51 | C15: =ORÇAMENTO_EXECUTIVO!D15 -> 2.8643931 | D15: =FIXED(CÁLCULO_MÉDIAS!J21,2,FALSE)&" "&"-"&FIXED(CÁLCULO_MÉDIAS!K21,2,FALSE) -> 15,00 -50,00
A16: =ORÇAMENTO_EXECUTIVO!A16 -> REVESTIMENTOS E ACABAMENTOS DE FACHADA | B16: =RELATÓRIO!X34 -> 1579912.1 | C16: =ORÇAMENTO_EXECUTIVO!D16 -> 252.96888 | D16: =FIXED(CÁLCULO_MÉDIAS!J22,2,FALSE)&" "&"-"&FIXED(CÁLCULO_MÉDIAS!K22,2,FALSE) -> 115,00 -130,00
A17: =ORÇAMENTO_EXECUTIVO!A17 -> SERVIÇOS COMPLEMENTARES | B17: =RELATÓRIO!X35 -> 1676000 | C17: =ORÇAMENTO_EXECUTIVO!D17 -> 268.35407 | D17: =FIXED(CÁLCULO_MÉDIAS!J23,2,FALSE)&" "&"-"&FIXED(CÁLCULO_MÉDIAS!K23,2,FALSE) -> 160,00 -220,00
A18: TOTAL | B18: =SUM(B3:B17) -> 18545891 | C18: =SUM(C3:C17) -> 2969.49 | D18: =FIXED(CÁLCULO_MÉDIAS!J24,2,FALSE)&" "&"-"&FIXED(CÁLCULO_MÉDIAS!K24,2,FALSE) -> 2.720,00 -3.365,00
B22: 2007.57
B23: 2461.35
B24: =B23/B22 -> 1.2260345
C27: 1.1023
A29: 900,00 - 1100 | B29: 900
A30: 25,00 - 30,00 | B30: 25
A31: 15,00 - 22,00 | B31: 15
A32: 150,00 - 200,00 | B32: 150
A33: 440,00 - 510,00 | B33: 440
A34: -
A35: 55,00 - 70,00 | B35: 55
A36: 170,00 - 200,00 | B36: 170
A37: 165,00 - 230,00 | B37: 165
A38: 40,00 - 70,00 | B38: 40
A39: 55,00 - 77,00 | B39: 55
A40: 35,00 - 50,00 | B40: 35
A41: 130,00 - 175,00 | B41: 130
A42: 35,00 - 65,00 | B42: 35
A43: 35,00 - 55,00 | B43: 35
A44: 430,00 - 550,00 | B44: 430
A45: 35,00 - 50,00 | B45: 35
A46: 150,00 - 220,00 | B46: 150

Sheet CÁLCULO_MÉDIAS
C3: DATA BASE | D3: 44896 | E3: DATA BASE | F3: 45108 | G3: DATA BASE | H3: 45383
C4: CUB | D4: 2651.17 | E4: CUB | F4: 2747.9 | G4: CUB | H4: 2757.56
C6: ÁGUAS DE MARÇO - INBRASUL | E6: MAIORI - AMALFI | G6: GRAN TORINO - MABREM | J6: MÉDIAS
C7: VALOR / M2 | D7: INDEXADO | E7: VALOR / M2 | F7: INDEXADO | G7: VALOR / M2 | H7: INDEXADO | J7: MÍNIMA | K7: MÁXIMA
B8: GERENCIAMENTO TECNICO E ADMINISTRATIVO | C8: 1198.23 | D8: =ORÇAMENTO_EXECUTIVO!$B$20/CÁLCULO_MÉDIAS!D$4*C8 -> 1262.4539 | E8: 419.37 | F8: =ORÇAMENTO_EXECUTIVO!$B$20/CÁLCULO_MÉDIAS!F$4*E8 -> 426.29413 | G8: 336.4 | H8: =ORÇAMENTO_EXECUTIVO!$B$20/CÁLCULO_MÉDIAS!H$4*G8 -> 340.75633 | J8: 335 | K8: 420
B9: MOVIMENTAÇÃO DE TERRA | C9: 5.17 | D9: =ORÇAMENTO_EXECUTIVO!$B$20/CÁLCULO_MÉDIAS!D$4*C9 -> 5.4471067 | E9: 7.37 | F9: =ORÇAMENTO_EXECUTIVO!$B$20/CÁLCULO_MÉDIAS!F$4*E9 -> 7.4916845 | G9: 0 | H9: =ORÇAMENTO_EXECUTIVO!$B$20/CÁLCULO_MÉDIAS!H$4*G9 -> 0 | J9: 10 | K9: 15
B10: INFRAESTRUTURA | C10: 144.25 | D10: =ORÇAMENTO_EXECUTIVO!$B$20/CÁLCULO_MÉDIAS!D$4*C10 -> 151.98165 | E10: 183.12 | F10: =ORÇAMENTO_EXECUTIVO!$B$20/CÁLCULO_MÉDIAS!F$4*E10 -> 186.14346 | G10: 162.9 | H10: =ORÇAMENTO_EXECUTIVO!$B$20/CÁLCULO_MÉDIAS!H$4*G10 -> 165.00953 | J10: 140 | K10: 190
B11: SUPRAESTRUTURA | C11: 613.07 | D11: =ORÇAMENTO_EXECUTIVO!$B$20/CÁLCULO_MÉDIAS!D$4*C11 -> 645.92992 | E11: 693.61 | F11: =ORÇAMENTO_EXECUTIVO!$B$20/CÁLCULO_MÉDIAS!F$4*E11 -> 705.06205 | G11: 655 | H11: =ORÇAMENTO_EXECUTIVO!$B$20/CÁLCULO_MÉDIAS!H$4*G11 -> 663.48215 | J11: 650 | K11: 695
B12: ALVENARIA | C12: 129.07 | D12: =ORÇAMENTO_EXECUTIVO!$B$20/CÁLCULO_MÉDIAS!D$4*C12 -> 135.98802 | E12: 124 | F12: =ORÇAMENTO_EXECUTIVO!$B$20/CÁLCULO_MÉDIAS!F$4*E12 -> 126.04734 | G12: 122.73 | H12: =ORÇAMENTO_EXECUTIVO!$B$20/CÁLCULO_MÉDIAS!H$4*G12 -> 124.31934 | J12: 120 | K12: 135
B13: INSTALAÇÕES ELÉTRICAS, HIDRÁULICAS, GLP E PREVENTIVAS | C13: 273.65 | D13: =ORÇAMENTO_EXECUTIVO!$B$20/CÁLCULO_MÉDIAS!D$4*C13 -> 288.31736 | E13: 304.39 | F13: =ORÇAMENTO_EXECUTIVO!$B$20/CÁLCULO_MÉDIAS!F$4*E13 -> 309.41572 | G13: 346.19 | H13: =ORÇAMENTO_EXECUTIVO!$B$20/CÁLCULO_MÉDIAS!H$4*G13 -> 350.67311 | J13: 270 | K13: 365
B14: EQUIPAMENTOS E SISTEMAS ESPECIAIS | C14: 131.86 | D14: =ORÇAMENTO_EXECUTIVO!$B$20/CÁLCULO_MÉDIAS!D$4*C14 -> 138.92756 | E14: 149.47 | F14: =ORÇAMENTO_EXECUTIVO!$B$20/CÁLCULO_MÉDIAS!F$4*E14 -> 151.93787 | G14: 163.3 | H14: =ORÇAMENTO_EXECUTIVO!$B$20/CÁLCULO_MÉDIAS!H$4*G14 -> 165.41471 | J14: 140 | K14: 170
B15: IMPERMEABILIZAÇÃO | C15: 41.71 | D15: =ORÇAMENTO_EXECUTIVO!$B$20/CÁLCULO_MÉDIAS!D$4*C15 -> 43.945613 | E15: 74.34 | F15: =ORÇAMENTO_EXECUTIVO!$B$20/CÁLCULO_MÉDIAS!F$4*E15 -> 75.567412 | G15: 43.36 | H15: =ORÇAMENTO_EXECUTIVO!$B$20/CÁLCULO_MÉDIAS!H$4*G15 -> 43.921506 | J15: 45 | K15: 80
B16: REVESTIMENTOS INTERNOS EM PISO E PAREDE | C16: 159.86 | D16: =ORÇAMENTO_EXECUTIVO!$B$20/CÁLCULO_MÉDIAS!D$4*C16 -> 168.42833 | E16: 190.23 | F16: =ORÇAMENTO_EXECUTIVO!$B$20/CÁLCULO_MÉDIAS!F$4*E16 -> 193.37085 | G16: 146.21 | H16: =ORÇAMENTO_EXECUTIVO!$B$20/CÁLCULO_MÉDIAS!H$4*G16 -> 148.1034 | J16: 145 | K16: 190
B17: REVESTIMENTOS E ACABAMENTOS INTERNOS EM TETO | C17: 68.43 | D17: =ORÇAMENTO_EXECUTIVO!$B$20/CÁLCULO_MÉDIAS!D$4*C17 -> 72.097778 | E17: 54.57 | F17: =ORÇAMENTO_EXECUTIVO!$B$20/CÁLCULO_MÉDIAS!F$4*E17 -> 55.470994 | G17: 60.1 | H17: =ORÇAMENTO_EXECUTIVO!$B$20/CÁLCULO_MÉDIAS!H$4*G17 -> 60.878286 | J17: 55 | K17: 70
B18: ACABAMENTOS EM PISO E PAREDE | C18: 199.49 | D18: =ORÇAMENTO_EXECUTIVO!$B$20/CÁLCULO_MÉDIAS!D$4*C18 -> 210.18246 | E18: 167.8 | F18: =ORÇAMENTO_EXECUTIVO!$B$20/CÁLCULO_MÉDIAS!F$4*E18 -> 170.57051 | G18: 153.35 | H18: =ORÇAMENTO_EXECUTIVO!$B$20/CÁLCULO_MÉDIAS!H$4*G18 -> 155.33586 | J18: 170 | K18: 210
B19: PINTURA INTERNA | C19: 104.47 | D19: =ORÇAMENTO_EXECUTIVO!$B$20/CÁLCULO_MÉDIAS!D$4*C19 -> 110.06949 | E19: 136.68 | F19: =ORÇAMENTO_EXECUTIVO!$B$20/CÁLCULO_MÉDIAS!F$4*E19 -> 138.93669 | G19: 149.59 | H19: =ORÇAMENTO_EXECUTIVO!$B$20/CÁLCULO_MÉDIAS!H$4*G19 -> 151.52717 | J19: 100 | K19: 135
... B23: SERVIÇOS COMPLEMENTARES | C23: 210.46 | D23: =ORÇAMENTO_EXECUTIVO!$B$20/CÁLCULO_MÉDIAS!D$4*C23 -> 221.74044 | E23: 125.12 | F23: =ORÇAMENTO_EXECUTIVO!$B$20/CÁLCULO_MÉDIAS!F$4*E23 -> 127.18583 | G23: 157.2 | H23: =ORÇAMENTO_EXECUTIVO!$B$20/CÁLCULO_MÉDIAS!H$4*G23 -> 159.23572 | J23: 160 | K23: 220
B24: TOTAL | C24: =SUM(C8:C23) -> 3722.92 | D24: =SUM(D8:D23) -> 3922.4647 | E24: =SUM(E8:E23) -> 3029.78 | F24: =SUM(F8:F23) -> 3079.8041 | G24: =SUM(G8:G23) -> 2901.94 | H24: =SUM(H8:H23) -> 2939.5197 | J24: =SUM(J8:J23) -> 2720 | K24: =SUM(K8:K23) -> 3365

Sheet RELATÓRIO
K2: Orçamento
K3: Resumo por Células Construtivas
A6: Obra | D6: 6 - Gran Tower - Custo direto
A7: Unidade construtiva | D7: 1 - GERENCIAMENTO EXECUTIVO
A8: Tipo de obra | D8: 1 - Construção Civil
A9: Endereço da obra | D9: Avenida Itapocorói, s/n - esquina com a Avenida Alfredo Brunetti - Armação - Penha/SC - 88385-000
A10: Versão do orçamento | D10: 2 - 28/07/2023 - 16:32:21 | L10: Data base | V10: 28/07/2023
A11: BDI | D11: não aplicado | L11: Encargos sociais | V11: não aplicado
A12: Preços expressos em | D12: R$ (REAL)
A14: Código | C14: Descrição | X14: Preço total | AE14: % Total
A15: 01 | C15: MOVIMENTAÇÃO DE TERRA | X15: 230869.63 | AE15: 0.21
A16: 02 | C16: INFRAESTRUTURA | X16: 933522.84 | AE16: 5.94
A17: 03 | C17: SUPRAESTRUTURA | X17: 4384787.1 | AE17: 20.74
A18: 04 | C18: PAREDES E PAINÉIS | X18: 863630.83 | AE18: 3.92
A19: 05 | C19: IMPERMEABILIZAÇÃO E TRATAMENTOS | X19: 420004.94 | AE19: 2.05
A20: 06 | C20: SISTEMAS E INSTALAÇÕES HIDROSSANITÁRIAS E DRENAGEM | X20: 581844.71 | AE20: 4.75
A21: 07 | C21: SISTEMAS E INSTALAÇÕES ELÉTRICAS | X21: 828826.45 | AE21: 3.93
A22: 08 | C22: INSTALAÇÕES PREVENTIVAS | X22: 99985.54 | AE22: 0.76
A23: 09 | C23: INSTALAÇÕES DE GÁS | X23: 89985.54 | AE23: 0.26
A24: 10 | C24: INSTALAÇÕES DE COMUNICAÇÕES | X24: 164481.09 | AE24: 0.83
A25: 11 | C25: EQUIPAMENTOS E SISTEMAS ESPECIAIS | X25: 1102590.9 | AE25: 5.55
A26: 12 | C26: CLIMATIZAÇÃO, EXAUSTÃO MECÂNICA E PRESSURIZAÇÃO | X26: 302100 | AE26: 0.24
... A36: 22 | C36: IMPREVISTOS E CONTINGÊNCIAS | X36: 300000 | AE36: 1.28
A37: Total da unidade construtiva | X37: =SUM(X15:AD36) -> 18845891 | AE37: 88.03
A39: Obra | D39: 6 - Gran Tower - Custo direto
A40: Unidade construtiva | D40: 2 - GERENCIAMENTO TÉCNICO E ADMINISTRATIVO
A41: Tipo de obra | D41: 1 - Construção Civil
A42: Endereço da obra | D42: Avenida Itapocorói, s/n - esquina com a Avenida Alfredo Brunetti - Armação - Penha/SC - 88385-000
A43: Versão do orçamento | D43: 2 - 28/07/2023 - 16:32:21 | L43: Data base | V43: 28/07/2023
A44: BDI | D44: não aplicado | L44: Encargos sociais | V44: não aplicado
A45: Preços expressos em | D45: R$ (REAL)
A47: Código | C47: Descrição | X47: Preço total | AE47: % Total
A48: 01 | C48: SERVIÇOS TÉCNICOS | X48: 704184.6 | AE48: 3.4
A49: 02 | C49: SERVIÇOS INICIAIS | X49: 957206.28 | AE49: 4.6
A50: 03 | C50: EQUIPAMENTOS | X50: 723541 | AE50: 3.49
A51: Total da unidade construtiva | X51: 2380921.4 | AE51: 11.97
A52: Total da obra | X52: 19882790 | AE52: 100
A54: 26/04/2024 - 11:39:46 | E54: SIENGE / SOFTPLAN
