Workbook
Name \0: #REF!
Name \0: #REF!
Name \a: #REF!
Name \a: #REF!
Name \m: #REF!
Name aa: #REF!
Name aa: #REF!
Name aaaa: '[1]M.O.'!#REF!
Name aaaa: '[1]M.O.'!#REF!
Name angelo: [2]Geral!#REF!
Name angelo: [2]Geral!#REF!
Name area: #REF!
Name Areaimpresso: #REF!
Name aux: #REF!
Name aux: #REF!
Name BDA: #REF!
Name BDA: #REF!
Name BDI: #REF!
Name ca: #REF!
Name Capa: #REF!
Name cronograma: #REF!
Name D: #REF!
Name direto: #REF!
Name DRE: #REF!
Name ea: #REF!
Name FFFFFFF: #REF!
Name FFFFFFF: #REF!
Name item_1: #REF!
Name LS: '[1]M.O.'!#REF!
Name MENU: #REF!
Name MENU: #REF!
Name MENU1: #REF!
Name MENU1: #REF!
Name MENU2: #REF!
Name MENU2: #REF!
Name MENU3: #REF!
Name MENU4: #REF!
Name MENU5: #REF!
Name MENU6: #REF!
Name mo: #REF!
Name OAE: #REF!
Name ParamValues1: [3]ParamValues!$A$1:$A$11
Name PAV: #REF!
Name pr: #REF!
Name PRE: #REF!
Name Print_Area: #REF!
Name Print_Area_MI: #REF!
Name Print_Titles: #REF!
Name qe: #REF!
Name qee: #REF!
Name reforsu: #REF!
Name ren: #REF!
Name REV: #REF!
Name sa: #REF!
Name SEG: #REF!
Name SIH: #REF!
Name SIV: #REF!
Name ss: #REF!
Name susref: #REF!
Name tania: #REF!

Sheet CAPA
A1: Obra | B1: GRAN TOWER
A2: Empresa | B2: GRANDEZZA EMPREENDIMENTOS
A3: Revisão | B3: R02
A4: Data | B4: 45503
A26: ORÇAMENTO EXECUTIVO
A28: GRANDEZZA - GRAN TOWER
A55: Itajaí, Julho de 2024

Sheet Resumo
A1: Obra | B1: GRAN TOWER
A2: Empresa | B2: GRANDEZZA EMPREENDIMENTOS
A3: Revisão | B3: R02
A4: Data | B4: 45503
A5: RESUMO
B7: ÁREA CONSTRUÍDA | D7: 6245.48 | E7: m²
B9: ETAPA | C9: VALOR ORÇADO | D9: % | E9: VALOR / m²
B10: GERENCIAMENTO TÉCNICO E ADMINISTRATIVO | C10: =ORÇAMENTO_EXECUTIVO!F13 -> 2384931.9 | D10: =C10/C$27 -> 0.11225506 | E10: =C10/$D$7 -> 381.86527
B11: MOVIMENTAÇÃO DE TERRA | C11: =ORÇAMENTO_EXECUTIVO!F108 -> 230869.63 | D11: =C11/C$27 -> 0.010866677 | E11: =C11/$D$7 -> 36.965875
B12: INFRAESTRUTURA | C12: =ORÇAMENTO_EXECUTIVO!F112 -> 933522.84 | D12: =C12/C$27 -> 0.04393948 | E12: =C12/$D$7 -> 149.47175
B13: SUPRAESTRUTURA | C13: =ORÇAMENTO_EXECUTIVO!F131 -> 4384787.1 | D13: =C13/C$27 -> 0.20638516 | E13: =C13/$D$7 -> 702.07367
B14: PAREDES E PAINEIS | C14: =ORÇAMENTO_EXECUTIVO!F150 -> 863630.83 | D14: =C14/C$27 -> 0.040649771 | E14: =C14/$D$7 -> 138.28094
B15: INSTALAÇÕES ELÉTRICAS, HIDRÁULICAS, GLP E PREVENTIVAS | C15: =ORÇAMENTO_EXECUTIVO!F199+ORÇAMENTO_EXECUTIVO!F214+ORÇAMENTO_EXECUTIVO!F230+ORÇAMENTO_EXECUTIVO!F244+ORÇAMENTO_EXECUTIVO!F254+ORÇAMENTO_EXECUTIVO!F385 -> 1935344.2 | D15: =C15/C$27 -> 0.091093667 | E15: =C15/$D$7 -> 309.87918
B16: EQUIPAMENTOS E SISTEMAS ESPECIAIS | C16: =ORÇAMENTO_EXECUTIVO!F263+ORÇAMENTO_EXECUTIVO!F270 -> 1404690.9 | D16: =C16/C$27 -> 0.066116634 | E16: =C16/$D$7 -> 224.9132
B17: IMPERMEABILIZAÇÃO | C17: =ORÇAMENTO_EXECUTIVO!F169 -> 420004.94 | D17: =C17/C$27 -> 0.019768985 | E17: =C17/$D$7 -> 67.249425
B18: REVESTIMENTOS INTERNOS DE PAREDE | C18: =ORÇAMENTO_EXECUTIVO!F277 -> 1030085.4 | D18: =C18/C$27 -> 0.048484531 | E18: =C18/$D$7 -> 164.93295
B19: REVESTIMENTOS E ACABAMENTOS INTERNOS EM TETO | C19: =ORÇAMENTO_EXECUTIVO!F293 -> 344380.88 | D19: =C19/C$27 -> 0.016209477 | E19: =C19/$D$7 -> 55.140819
B20: PISOS E PAVIMENTAÇÕES | C20: =ORÇAMENTO_EXECUTIVO!F305 -> 1388564.5 | D20: =C20/C$27 -> 0.065357591 | E20: =C20/$D$7 -> 222.33111
B21: PINTURA INTERNA | C21: =ORÇAMENTO_EXECUTIVO!F339 -> 712320.05 | D21: =C21/C$27 -> 0.033527806 | E21: =C21/$D$7 -> 114.05369
B22: ESQUADRIAS, VIDROS E FERRAGENS | C22: =ORÇAMENTO_EXECUTIVO!F358 -> 1623887.7 | D22: =C22/C$27 -> 0.07643389 | E22: =C22/$D$7 -> 260.01007
B23: COBERTURA | C23: =ORÇAMENTO_EXECUTIVO!F393 -> 32717.5 | D23: =C23/C$27 -> 0.0015399623 | E23: =C23/$D$7 -> 5.2385885
B24: REVESTIMENTOS E ACABAMENTOS DE FACHADA | C24: =ORÇAMENTO_EXECUTIVO!F404 -> 1579912.1 | D24: =C24/C$27 -> 0.074364026 | E24: =C24/$D$7 -> 252.96888
B25: SERVIÇOS COMPLEMENTARES | C25: =ORÇAMENTO_EXECUTIVO!F421 -> 1676000 | D25: =C25/C$27 -> 0.078886735 | E25: =C25/$D$7 -> 268.35407
B26: IMPREVISTOS E CONTINGENCIAS | C26: =ORÇAMENTO_EXECUTIVO!F431 -> 300000 | D26: =C26/C$27 -> 0.014120537 | E26: =C26/$D$7 -> 48.034739
B27: TOTAL | C27: =SUM(C10:C26) -> 21245651 | D27: =SUM(D10:D26) -> 1 | E27: =SUM(E10:E26) -> 3401.7642
B28: CUB/SC | C28: 2793.27 | D28: 45474 | E28: =+E27/C28 -> 1.217843
A30: Area privativa
B32: DESCRIÇÃO - 25 APARTAMENTOS (ÁREA TOTAL) | C32: ÁREA | D32: VALOR TOTAL
B33: VALOR POR UNIDADE PRIVATIVA (R$/m²) | C33: 3199.82 | D33: =C27/C33 -> 6639.6393
B34: VALOR POR UNIDADE TIPO 01 | C34: =121 -> 121 | D34: =D33*C34 -> 803396.35
B35: VALOR POR UNIDADE TIPO 02 | C35: =121 -> 121 | D35: =D33*C35 -> 803396.35
B36: VALOR POR UNIDADE DIFERENCIADO | C36: 245.7 | D36: =C36*D33 -> 1631359.4
B37: VALOR POR UNIDADE TIPO 03 | C37: =124.58 -> 124.58 | D37: =C37*D33 -> 827166.26
A39: Comparações
B41: ETAPA | C41: GRAN TOWER | E41: OBRAS DE REFERÊNCIA
C42: VALOR | D42: VALOR / m² | E42: VALOR / m²
B43: =B11 -> MOVIMENTAÇÃO DE TERRA | C43: =C11 -> 230869.63 | D43: =E11 -> 36.965875 | E43: 10,00 -15,00
B44: =B12 -> INFRAESTRUTURA | C44: =C12 -> 933522.84 | D44: =E12 -> 149.47175 | E44: 140,00 -190,00
B45: =B13 -> SUPRAESTRUTURA | C45: =C13 -> 4384787.1 | D45: =E13 -> 702.07367 | E45: 650,00 -695,00
B46: =B14 -> PAREDES E PAINEIS | C46: =C14 -> 863630.83 | D46: =E14 -> 138.28094 | E46: 120,00 -135,00
...

Sheet ORÇAMENTO_EXECUTIVO
A1: ORÇAMENTO EXECUTIVO
A7: Cliente | B7: GRANDEZZA
A8: Obra | B8: GRAN TOWER
A9: Data | B9: 45503
A10: Versão | B10: R02
A12: Código | B12: Descrição | C12: Un. | D12: Quantidade orçada | E12: Preço unitário | F12: Preço total | G12: Considerações
A13: 01 | B13: GERENCIAMENTO TÉCNICO E ADMINISTRATIVO | F13: 2384931.9
A14: 01.01 | B14: GERENCIAMENTO TÉCNICO | F14: =F15+F42 -> 704184.6
A15: 01.01.001 | B15: ESTUDOS | PROJETOS | CONSULTORIAS | F15: =SUM(F16+F23+F40) -> 511004.81
A16: 01.01.001.0001 | B16: Estudos | F16: =SUM(F17:F22) -> 65491
A17: 01.001.001.001 | B17: Memorial descrtivo | C17: VB | D17: 1 | E17: 6789 | F17: =E17*D17 -> 6789 | G17: Valor repassado pelo Grandezza, respondido no formulário de custos indiretos
A18: 01.001.001.002 | B18: Levantamento topográfico | C18: VB | D18: 1 | E18: 6789 | F18: =E18*D18 -> 6789 | G18: Valor repassado pelo Grandezza, respondido no formulário de custos indiretos
A19: 01.001.001.003 | B19: Estudo geológico | C19: VB | D19: 1 | E19: 6789 | F19: =E19*D19 -> 6789 | G19: Valor repassado pelo Grandezza, respondido no formulário de custos indiretos
A20: 01.001.001.004 | B20: Estudo ambiental | C20: VB | D20: 1 | E20: 16158 | F20: =E20*D20 -> 16158 | G20: Valor repassado pelo Grandezza, respondido no formulário de custos indiretos
A21: 01.001.001.005 | B21: Sondagem do terreno | C21: VB | D21: 1 | E21: 22177 | F21: =E21*D21 -> 22177 | G21: Valor repassado pelo Grandezza, respondido no formulário de custos indiretos
A22: 01.001.001.006 | B22: Projeto de canteiro | C22: VB | D22: 1 | E22: 6789 | F22: =E22*D22 -> 6789 | G22: Valor repassado pelo Grandezza, respondido no formulário de custos indiretos
A23: 01.01.001.0002 | B23: Projetos | F23: =SUM(F24:F39) -> 408226.81
A24: 01.01.001.0002.0001 | B24: Legalização de incorporação | C24: vb | D24: 1 | E24: 11611.7 | F24: 11611.7 | G24: Valor repassado pelo Grandezza, respondido no formulário de custos indiretos
A25: 01.01.001.0002.0002 | B25: Projeto arquitetônico legal | C25: vb | D25: 1 | E25: 79546 | F25: 79546 | G25: Valor repassado pelo Grandezza, respondido no formulário de custos indiretos
A26: 01.01.001.0002.0003 | B26: Projeto arquitetônico executivo | C26: vb | D26: 1 | E26: 50000 | F26: 50000 | G26: Valor repassado pelo Grandezza, respondido no formulário de custos indiretos
A27: 01.01.001.0002.0004 | B27: Projeto arquitetônico interiores | C27: vb | D27: 1 | E27: 67889 | F27: 67889 | G27: Valor repassado pelo Grandezza, respondido no formulário de custos indiretos
A28: 01.01.001.0002.0005 | B28: Projeto arquitetônico de fachada | C28: vb | D28: 1 | E28: 2187.34 | F28: 2187.34 | G28: Valor repassado pelo Grandezza, respondido no formulário de custos indiretos
A29: 01.01.001.0002.0006 | B29: Projeto de fundação | C29: vb | D29: 1 | E29: 3729 | F29: 3729 | G29: Valor repassado pelo Grandezza, respondido no formulário de custos indiretos
A30: 01.01.001.0002.0007 | B30: Projeto estrutural de concreto armado | C30: vb | D30: 1 | E30: 41587 | F30: 41587 | G30: Valor repassado pelo Grandezza, respondido no formulário de custos indiretos
A31: 01.01.001.0002.0008 | B31: Projeto de estrutura metálica | C31: vb | D31: 1 | E31: 30000 | F31: 30000 | G31: Valor repassado pelo Grandezza, respondido no formulário de custos indiretos
A32: 01.01.001.0002.0009 | B32: Projeto elétrico | C32: vb | D32: 1 | E32: 33310 | F32: 33310 | G32: Valor repassado pelo Grandezza, respondido no formulário de custos indiretos
A33: 01.01.001.0002.0010 | B33: Projeto de automação | C33: vb | D33: 1 | E33: 2000 | F33: 2000 | G33: Valor repassado pelo Grandezza, respondido no formulário de custos indiretos
A34: 01.01.001.0002.0011 | B34: Projeto hidrossanitário | C34: vb | D34: 1 | E34: 41016 | F34: 41016 | G34: Valor repassado pelo Grandezza, respondido no formulário de custos indiretos
A35: 01.01.001.0002.0012 | B35: Projeto preventivo | C35: vb | D35: 1 | E35: 4972 | F35: 4972 | G35: Valor repassado pelo Grandezza, respondido no formulário de custos indiretos
... A39: 01.01.001.0002.0016 | B39: Projeto de paisagismo | C39: vb | D39: 1 | E39: 1514.48 | F39: 1514.48 | G39: Valor repassado pelo Grandezza, respondido no formulário de custos indiretos
A40: 01.01.001.0003 | B40: Consultorias | F40: =SUM(F41:F41) -> 37287
A41: 01.01.001.0003.0001 | B41: Consultoria técnica de legalização | C41: VB | D41: 1 | E41: 37287 | F41: =E41*D41 -> 37287 | G41: Valor repassado pelo Grandezza, respondido no formulário de custos indiretos
A42: 01.01.002 | B42: TAXAS | DOCUMENTOS | F42: =F43 -> 193179.79
A43: 01.01.002.0001 | B43: Licenciamento - Taxas - Impostos | F43: =SUM(F44:F55) -> 193179.79
A44: 01.01.002.0001.0001 | B44: Despesas de seguro de obra | C44: VB | D44: 1 | E44: 37287 | F44: =E44*D44 -> 37287 | G44: Valor repassado pelo Grandezza, respondido no formulário de custos indiretos
A45: 01.01.002.0001.0003 | B45: Aprovação e legalização ambiental | C45: VB | D45: 1 | E45: 4972 | F45: =E45*D45 -> 4972 | G45: Valor repassado pelo Grandezza, respondido no formulário de custos indiretos
A46: 01.01.002.0001.0004 | B46: Aprovação e legalização prefeitura | C46: VB | D46: 1 | E46: 8883 | F46: =E46*D46 -> 8883 | G46: Valor repassado pelo Grandezza, respondido no formulário de custos indiretos
A47: 01.01.002.0001.0005 | B47: Aprovação e legalização água e esgoto | C47: VB | D47: 1 | E47: 1134 | F47: =E47*D47 -> 1134 | G47: Valor repassado pelo Grandezza, respondido no formulário de custos indiretos
A48: 01.01.002.0001.0006 | B48: Aprovação e legalização elétrico | C48: VB | D48: 1 | E48: 1134 | F48: =E48*D48 -> 1134 | G48: Valor repassado pelo Grandezza, respondido no formulário de custos indiretos
A49: 01.01.002.0001.0007 | B49: Aprovação e legalização bombeiros | C49: VB | D49: 1 | E49: 4972 | F49: =E49*D49 -> 4972 | G49: Valor repassado pelo Grandezza, respondido no formulário de custos indiretos
...
