Workbook
Name \0: #REF!
Name \1: #REF!
Name \a: #REF!
Name \b: #REF!
Name \c: #REF!
Name \d: #REF!
Name \e: #REF!
Name \i: #REF!
Name \J: #REF!
Name \k: #REF!
Name \l: #N/A
Name \m: #REF!
Name \o: #REF!
Name \p: #REF!
Name \r: #REF!
Name \T: #REF!
Name \z: #REF!
Name _: #REF!
Name _\0: #REF!
Name _\1: #REF!
Name _\a: #REF!
Name _\b: #REF!
Name _\c: #REF!
Name _\d: #REF!
Name _\e: #REF!
Name _\i: #REF!
Name _\J: #REF!
Name _\k: #REF!
Name _\l: #N/A
Name _\m: #REF!
Name _\o: #REF!
Name _\p: #REF!
Name _\r: #REF!
Name _\T: #REF!
Name _\z: #REF!
Name __: #REF!
Name ______ACR10: #REF!
Name ______ACR15: #REF!
Name ______acr20: #REF!
Name ______acr5: #REF!
Name ______ARQ1: #REF!
Name ______QT100: #REF!
Name ______QT2: #REF!
Name ______QT3: #REF!
Name ______QT4: #REF!
Name ______QT50: #REF!
Name ______QT75: #REF!
Name _____ACR10: #REF!
Name _____ACR15: #REF!
Name _____acr20: #REF!
Name _____acr5: #REF!
Name _____ARQ1: #REF!
Name _____key2: #REF!
Name _____QT100: #REF!
Name _____QT2: #REF!
Name _____QT3: #REF!
Name _____QT4: #REF!
Name _____QT50: #REF!
Name _____QT75: #REF!
Name ____key2: #REF!

Sheet CAPA
A1: DADOS DO EMPREENDIMENTO
B2: Projeto: | C2: Electra Towers | E2: ENDEREÇO DA OBRA: | F2: Rua 254, 215, Meia Praia, Itapema/SC
B3: Empresa: | C3: Thozen Empreendimentos | E3: Cidade/ES: | F3: Itapema, SC
B4: Revisão: | C4: R00 | E4: CNPJ: | F4: 43.339.082/0001-06
B6: Pazo de Obra: | C6: 48 | E6: Nº Unid. Residenciais: | F6: 192 | I6: Imagens
B8: Área do Terreno: | C8: 2095.43 | E8: Nº Unid. Comerciais: | F8: 7
B10: Área Construída: | C10: 37893.89 | E10: Nº Pavimentos: | F10: 57
B12: Área Privativa: | C12: 22778.64 | E12: Total de Dormitórios: | F12: 576
B14: Área de Lazer: | C14: 1736.27 | E14: Nº Subsolos: | F14: 0
B16: Área Comercial: | C16: 500.04 | E16: Nº Vagas: | F16: 399
B18: Torre | C18: Pavimento | D18: Área | E18: Área Privativa | F18: Perímetro | G18: Pé direito
B19: Embasamento | C19: Térreo | D19: 1565.91 | E19: 0 | G19: 4.3
B20: Embasamento | C20: Garagem 01 | D20: 1736.27 | E20: 0
B21: Embasamento | C21: Garagem 02 | D21: 1736.27 | E21: 0
B22: Embasamento | C22: Garagem 03 | D22: 1736.27 | E22: 0
B23: Embasamento | C23: Garagem 04 | D23: 1736.27 | E23: 0
B24: Embasamento | C24: Garagem 05 | D24: 1736.27 | E24: 0
B25: Embasamento | C25: Pavimento diferenciado — Lazer | D25: 1736.27 | E25: 0 | G25: 3.6
B26: Torre A | C26: Pavimento tipo — Torre A (×24) | D26: 12720.48 | E26: 11382.72 | G26: 3.24
B27: Torre B | C27: Pavimento tipo — Torre B (×24) | D27: 12892.32 | E27: 11397.12 | G27: 3.24
B28: Cobertura | C28: Casa de Máquinas | D28: 176.26 | E28: 0
B29: Cobertura | C29: Reservatórios | D29: 121.3 | E29: 0
B37: Torre | C37: Pavimento | D37: Descrição | E37: Área | I37: ETAPA
B38: Áreas Comuns | C38: =_xlfn.XLOOKUP(D38,MOBILIÁRIO!C:C,MOBILIÁRIO!B:B) -> TÉRREO | D38: {=_xlfn.UNIQUE(_xlfn._xlws.FILTER(MOBILIÁRIO!C7:C316,MOBILIÁRIO!C7:C316<>""))} -> Hall Externo | E38: =_xlfn.XLOOKUP(D38,MOBILIÁRIO!C:C,MOBILIÁRIO!F:F) -> 12.33 | I38: GERENCIAMENTO TÉCNICO E ADMINISTRATIVO
B39: Áreas Comuns | C39: =_xlfn.XLOOKUP(D39,MOBILIÁRIO!C:C,MOBILIÁRIO!B:B) -> TÉRREO | D39: Hall Térreo | E39: =_xlfn.XLOOKUP(D39,MOBILIÁRIO!C:C,MOBILIÁRIO!F:F) -> 35.27 | I39: MOVIMENTAÇÃO DE TERRA
B40: Áreas Comuns | C40: =_xlfn.XLOOKUP(D40,MOBILIÁRIO!C:C,MOBILIÁRIO!B:B) -> TÉRREO | D40: Guarita | E40: =_xlfn.XLOOKUP(D40,MOBILIÁRIO!C:C,MOBILIÁRIO!F:F) -> 4.72 | I40: CONTENÇÃO
B41: Áreas Comuns | C41: =_xlfn.XLOOKUP(D41,MOBILIÁRIO!C:C,MOBILIÁRIO!B:B) -> TÉRREO | D41: Lavapés | E41: =_xlfn.XLOOKUP(D41,MOBILIÁRIO!C:C,MOBILIÁRIO!F:F) -> 1 | I41: INFRAESTRUTURA
B42: Áreas Comuns | C42: =_xlfn.XLOOKUP(D42,MOBILIÁRIO!C:C,MOBILIÁRIO!B:B) -> TÉRREO | D42: Lavabo Pne - Térreo | E42: =_xlfn.XLOOKUP(D42,MOBILIÁRIO!C:C,MOBILIÁRIO!F:F) -> 3.77 | I42: SUPRAESTRUTURA
B43: Áreas Comuns | C43: =_xlfn.XLOOKUP(D43,MOBILIÁRIO!C:C,MOBILIÁRIO!B:B) -> TÉRREO | D43: Bicicletário/Box | E43: =_xlfn.XLOOKUP(D43,MOBILIÁRIO!C:C,MOBILIÁRIO!F:F) -> 87.33 | I43: ALVENARIAS E VEDAÇÕES
B44: Áreas Comuns | C44: =_xlfn.XLOOKUP(D44,MOBILIÁRIO!C:C,MOBILIÁRIO!B:B) -> TÉRREO | D44: Antecâmara - Térreo | E44: =_xlfn.XLOOKUP(D44,MOBILIÁRIO!C:C,MOBILIÁRIO!F:F) -> 8.07 | I44: SISTEMAS E INSTALAÇÕES ELÉTRICAS
B45: Áreas Comuns | C45: =_xlfn.XLOOKUP(D45,MOBILIÁRIO!C:C,MOBILIÁRIO!B:B) -> 2º AO 5º PAVIMENTO - GARAGENS (X5) | D45: Antecâmara - Garagens (x5) | E45: =_xlfn.XLOOKUP(D45,MOBILIÁRIO!C:C,MOBILIÁRIO!F:F) -> 33.6 | I45: SISTEMAS E INSTALAÇÕES HIDROSSANITÁRIAS E DRENAGEM
B46: Áreas Comuns | C46: =_xlfn.XLOOKUP(D46,MOBILIÁRIO!C:C,MOBILIÁRIO!B:B) -> 4º PAVIMENTO - LAZER/GARAGENS | D46: Sala de massagem | E46: =_xlfn.XLOOKUP(D46,MOBILIÁRIO!C:C,MOBILIÁRIO!F:F) -> 7.47 | I46: INSTALAÇÕES PREVENTIVAS
B47: Áreas Comuns | C47: =_xlfn.XLOOKUP(D47,MOBILIÁRIO!C:C,MOBILIÁRIO!B:B) -> 4º PAVIMENTO - LAZER/GARAGENS | D47: Banheiro - Lazer/Garagem | E47: =_xlfn.XLOOKUP(D47,MOBILIÁRIO!C:C,MOBILIÁRIO!F:F) -> 3.91 | I47: INSTALAÇÕES DE GÁS
B48: Áreas Comuns | C48: =_xlfn.XLOOKUP(D48,MOBILIÁRIO!C:C,MOBILIÁRIO!B:B) -> 4º PAVIMENTO - LAZER/GARAGENS | D48: Lavabo - Lazer/Garagem | E48: =_xlfn.XLOOKUP(D48,MOBILIÁRIO!C:C,MOBILIÁRIO!F:F) -> 2.61 | I48: EQUIPAMENTOS E SISTEMAS ESPECIAIS
B49: Áreas Comuns | C49: =_xlfn.XLOOKUP(D49,MOBILIÁRIO!C:C,MOBILIÁRIO!B:B) -> 4º PAVIMENTO - LAZER/GARAGENS | D49: Lavabo Pne - Lazer/Garagem | E49: =_xlfn.XLOOKUP(D49,MOBILIÁRIO!C:C,MOBILIÁRIO!F:F) -> 4.33 | I49: CLIMATIZAÇÃO, EXAUSTÃO MECÂNICA
B50: Áreas Comuns | C50: =_xlfn.XLOOKUP(D50,MOBILIÁRIO!C:C,MOBILIÁRIO!B:B) -> 4º PAVIMENTO - LAZER/GARAGENS | D50: Circulação - Lazer/garagem | E50: =_xlfn.XLOOKUP(D50,MOBILIÁRIO!C:C,MOBILIÁRIO!F:F) -> 30.85 | I50: INSTALAÇÕES ESPECIAIS
... B63: Áreas Comuns | C63: =_xlfn.XLOOKUP(D63,MOBILIÁRIO!C:C,MOBILIÁRIO!B:B) -> 5º PAVIMENTO - LAZER | D63: Laje Verde | E63: =_xlfn.XLOOKUP(D63,MOBILIÁRIO!C:C,MOBILIÁRIO!F:F) -> 269.95 | I63: CUB/SC
B64: Áreas Comuns | C64: =_xlfn.XLOOKUP(D64,MOBILIÁRIO!C:C,MOBILIÁRIO!B:B) -> 5º PAVIMENTO - LAZER | D64: Brinquedoteca | E64: =_xlfn.XLOOKUP(D64,MOBILIÁRIO!C:C,MOBILIÁRIO!F:F) -> 16.32
B65: Áreas Comuns | C65: =_xlfn.XLOOKUP(D65,MOBILIÁRIO!C:C,MOBILIÁRIO!B:B) -> 5º PAVIMENTO - LAZER | D65: Game Center | E65: =_xlfn.XLOOKUP(D65,MOBILIÁRIO!C:C,MOBILIÁRIO!F:F) -> 13.09 | I65: DESCRIÇÃO
B66: Áreas Comuns | C66: =_xlfn.XLOOKUP(D66,MOBILIÁRIO!C:C,MOBILIÁRIO!B:B) -> 5º PAVIMENTO - LAZER | D66: Sala de Festas | E66: =_xlfn.XLOOKUP(D66,MOBILIÁRIO!C:C,MOBILIÁRIO!F:F) -> 93.46 | I66: VALOR POR ÁREA PRIVATIVA (R$/m²)
...

Sheet EAP
A1: EAP DE ORÇAMENTO
A3: Contrutora - Obra
A5: UNIDADE CONSTRUTIVA | B5: 1 | C5: GERENCIAMENTO TÉCNICO E ADMINISTRATIVO
A6: CÉLULA CONSTRUTIVA | B6: 1 | C6: SERVIÇOS TÉCNICOS
A7: ETAPA | B7: 1.001 | C7: ESTUDOS, PROJETOS E CONSULTORIAS
A8: Subetapa | B8: 01.001.001 | C8: Estudos
A9: Subetapa | B9: 01.001.002 | C9: Projetos
A10: Subetapa | B10: 01.001.003 | C10: Consultorias
A11: Subetapa | B11: 01.001.004 | C11: Ensaios
A12: ETAPA | B12: 1.002 | C12: TAXAS E DOCUMENTOS
A13: Subetapa | B13: 01.002.001 | C13: Licenciamentos, Taxas, Impostos, Aprovações e Seguros
A14: Subetapa | B14: 01.002.002 | C14: Documentos
A15: CÉLULA CONSTRUTIVA | B15: 2 | C15: SERVIÇOS INICIAIS
A16: ETAPA | B16: 2.001 | C16: SEGURANÇA, MEIO AMBIENTE, SAÚDE
A17: Subetapa | B17: 02.001.001 | C17: Segurança do trabalho
A18: Subetapa | B18: 02.001.002 | C18: Equipamentos de proteção
A19: Subetapa | B19: 02.001.003 | C19: Meio ambiente
A20: Subetapa | B20: 02.001.004 | C20: Saúde ocupacional
A21: ETAPA | B21: 2.002 | C21: ADMINISTRAÇÃO E CANTEIRO DE OBRA
A22: Subetapa | B22: 02.002.001 | C22: Equipe de Gestão e Apoio
A23: Subetapa | B23: 02.002.002 | C23: Operação inicial de canteiro
A24: Subetapa | B24: 02.002.003 | C24: Despesas de consumo e manutenção
A25: Subetapa | B25: 02.002.004 | C25: Instalações provisórias
A26: Subetapa | B26: 02.002.005 | C26: Ligações Provisórias
A27: ETAPA | B27: 2.003 | C27: SERVIÇOS PRELIMINARES
... A29: Subetapa | B29: 02.003.002 | C29: Limpeza de terreno
A30: CÉLULA CONSTRUTIVA | B30: 3 | C30: EQUIPAMENTOS
A31: ETAPA | B31: 3.001 | C31: EQUIPAMENTOS
A32: Subetapa | B32: 03.001.001 | C32: Equipamentos de Carga e Transporte
A33: Subetapa | B33: 03.001.002 | C33: Equipamentos de obra
A34: Subetapa | B34: 03.001.003 | C34: Balancins e Andaimes
A35: UNIDADE CONSTRUTIVA | B35: 2 | C35: GERENCIAMENTO EXECUTIVO
A36: CÉLULA CONSTRUTIVA | B36: 1 | C36: INFRAESTRUTURA
A37: ETAPA | B37: 1.001 | C37: MOVIMENTAÇÃO DE TERRA
A38: Subetapa | B38: 01.001.001 | C38: Corte e aterro
A39: Subetapa | B39: 01.001.002 | C39: Rebaixamento de lençol
A40: Subetapa | B40: 01.001.003 | C40: Escavação e Reaterro de Valas
A41: Subetapa | B41: 01.001.004 | C41: Lastro de estrutura de concreto
A42: Subetapa | B42: 01.001.005 | C42: Movimentação de bota - fora
A43: ETAPA | B43: 1.002 | C43: FUNDAÇÃO PROFUNDA
...

Sheet AUTOMAÇÃO
B1: Projeto
B2: Empresa
B3: Origem | C3: Estimados
B4: Revisão | C4: R00 - Larissa
A6: PAVIMENTO | B6: GRUPO/EAP | C6: SUBGRUPO | D6: Descrição | E6: Quantidade | F6: Repetições | G6: Qte com perda | H6: Unidade | I6: Custo unitário | J6: Custo unitário - Mão de obra | K6: Custo Total | M6: GRUPO/EAP | N6: {=TRANSPOSE(_xlfn.UNIQUE(_xlfn._xlws.FILTER(A7:A1048576,A7:A1048576<>"")))} -> 01º - Térreo | O6: 07º - Lazer | Garagem | P6: 08º - Lazer | Q6: 09º - Tipo diferenciado | R6: 10º - Tipo x8 | S6: 11º - Penthouse x22 | T6: 12º - Duplex inferior | V6: TOTAL
K7: =IF(SUM(E7:I7)=0,SUMIFS($K8:$K$37,$A8:$A$37,$A7),(G7*I7)+(G7*J7)) -> 0 | M7: {=_xlfn.UNIQUE(_xlfn._xlws.FILTER(B8:B97,B8:B97<>""))} -> Sistema de interfone / controle de acesso | N7: =SUMIFS($K$7:$K$756,$B$7:$B$756,$M7,$A$7:$A$756,N$6) -> 2800 | O7: =SUMIFS($K$7:$K$756,$B$7:$B$756,$M7,$A$7:$A$756,O$6) -> 14910 | P7: =SUMIFS($K$7:$K$756,$B$7:$B$756,$M7,$A$7:$A$756,P$6) -> 13700 | Q7: =SUMIFS($K$7:$K$756,$B$7:$B$756,$M7,$A$7:$A$756,Q$6) -> 1720 | R7: =SUMIFS($K$7:$K$756,$B$7:$B$756,$M7,$A$7:$A$756,R$6) -> 2560 | S7: =SUMIFS($K$7:$K$756,$B$7:$B$756,$M7,$A$7:$A$756,S$6) -> 3520 | T7: =SUMIFS($K$7:$K$756,$B$7:$B$756,$M7,$A$7:$A$756,T$6) -> 320 | U7: =SUMIFS($K$7:$K$756,$B$7:$B$756,$M7,$A$7:$A$756,U$6) -> 0 | V7: =SUM(N7:U7) -> 39530
A8: 01º - Térreo | B8: Sistema de interfone / controle de acesso | C8: Botoeira | D8: Botoeira | E8: 8 | F8: 1 | G8: =E8*F8 -> 8 | H8: Unidade | J8: 90 | K8: =IF(SUM(E8:I8)=0,SUMIFS($K9:$K$37,$A9:$A$37,$A8),(G8*I8)+(G8*J8)) -> 720 | M8: Telefonia/lógica/internet | N8: =SUMIFS($K$7:$K$756,$B$7:$B$756,$M8,$A$7:$A$756,N$6) -> 900 | O8: =SUMIFS($K$7:$K$756,$B$7:$B$756,$M8,$A$7:$A$756,O$6) -> 1250 | P8: =SUMIFS($K$7:$K$756,$B$7:$B$756,$M8,$A$7:$A$756,P$6) -> 1250 | Q8: =SUMIFS($K$7:$K$756,$B$7:$B$756,$M8,$A$7:$A$756,Q$6) -> 5000 | R8: =SUMIFS($K$7:$K$756,$B$7:$B$756,$M8,$A$7:$A$756,R$6) -> 4800 | S8: =SUMIFS($K$7:$K$756,$B$7:$B$756,$M8,$A$7:$A$756,S$6) -> 3300 | T8: =SUMIFS($K$7:$K$756,$B$7:$B$756,$M8,$A$7:$A$756,T$6) -> 300 | U8: =SUMIFS($K$7:$K$756,$B$7:$B$756,$M8,$A$7:$A$756,U$6) -> 0 | V8: =SUM(N8:U8) -> 16800
A9: 01º - Térreo | B9: Sistema de interfone / controle de acesso | C9: Controle de Acesso | D9: Controle de Acesso | E9: 8 | F9: 1 | G9: =E9*F9 -> 8 | H9: Unidade | J9: 160 | K9: =IF(SUM(E9:I9)=0,SUMIFS($K10:$K$37,$A10:$A$37,$A9),(G9*I9)+(G9*J9)) -> 1280 | M9: Automação | N9: =SUMIFS($K$7:$K$756,$B$7:$B$756,$M9,$A$7:$A$756,N$6) -> 0 | O9: =SUMIFS($K$7:$K$756,$B$7:$B$756,$M9,$A$7:$A$756,O$6) -> 42992.696 | P9: =SUMIFS($K$7:$K$756,$B$7:$B$756,$M9,$A$7:$A$756,P$6) -> 42992.696 | Q9: =SUMIFS($K$7:$K$756,$B$7:$B$756,$M9,$A$7:$A$756,Q$6) -> 0 | R9: =SUMIFS($K$7:$K$756,$B$7:$B$756,$M9,$A$7:$A$756,R$6) -> 0 | S9: =SUMIFS($K$7:$K$756,$B$7:$B$756,$M9,$A$7:$A$756,S$6) -> 0 | T9: =SUMIFS($K$7:$K$756,$B$7:$B$756,$M9,$A$7:$A$756,T$6) -> 0 | U9: =SUMIFS($K$7:$K$756,$B$7:$B$756,$M9,$A$7:$A$756,U$6) -> 0 | V9: =SUM(N9:U9) -> 85985.392
A10: 01º - Térreo | B10: Sistema de interfone / controle de acesso | C10: Vídeo Porteiro/Interfone | D10: Vídeo Porteiro/Interfone | E10: 5 | F10: 1 | G10: =E10*F10 -> 5 | H10: Unidade | J10: 160 | K10: =IF(SUM(E10:I10)=0,SUMIFS($K11:$K$37,$A11:$A$37,$A10),(G10*I10)+(G10*J10)) -> 800 | M10: AUTOMAÇÃO LAZER**** | N10: =SUMIFS($K$7:$K$756,$B$7:$B$756,$M10,$A$7:$A$756,N$6) -> 0 | O10: =SUMIFS($K$7:$K$756,$B$7:$B$756,$M10,$A$7:$A$756,O$6) -> 0 | P10: =SUMIFS($K$7:$K$756,$B$7:$B$756,$M10,$A$7:$A$756,P$6) -> 0 | Q10: =SUMIFS($K$7:$K$756,$B$7:$B$756,$M10,$A$7:$A$756,Q$6) -> 0 | R10: =SUMIFS($K$7:$K$756,$B$7:$B$756,$M10,$A$7:$A$756,R$6) -> 0 | S10: =SUMIFS($K$7:$K$756,$B$7:$B$756,$M10,$A$7:$A$756,S$6) -> 0 | T10: =SUMIFS($K$7:$K$756,$B$7:$B$756,$M10,$A$7:$A$756,T$6) -> 0 | U10: =SUMIFS($K$7:$K$756,$B$7:$B$756,$M10,$A$7:$A$756,U$6) -> 0 | V10: =SUM(N10:U10) -> 0
A11: 01º - Térreo | B11: Telefonia/lógica/internet | C11: Wi‑Fi (AP) | D11: Wi‑Fi (AP) | E11: 6 | F11: 1 | G11: =E11*F11 -> 6 | H11: Unidade | J11: 150 | K11: =IF(SUM(E11:I11)=0,SUMIFS($K12:$K$37,$A12:$A$37,$A11),(G11*I11)+(G11*J11)) -> 900 | M11: AUTOMAÇÃO TIPOS**** | N11: =SUMIFS($K$7:$K$756,$B$7:$B$756,$M11,$A$7:$A$756,N$6) -> 0 | O11: =SUMIFS($K$7:$K$756,$B$7:$B$756,$M11,$A$7:$A$756,O$6) -> 0 | P11: =SUMIFS($K$7:$K$756,$B$7:$B$756,$M11,$A$7:$A$756,P$6) -> 0 | Q11: =SUMIFS($K$7:$K$756,$B$7:$B$756,$M11,$A$7:$A$756,Q$6) -> 0 | R11: =SUMIFS($K$7:$K$756,$B$7:$B$756,$M11,$A$7:$A$756,R$6) -> 0 | S11: =SUMIFS($K$7:$K$756,$B$7:$B$756,$M11,$A$7:$A$756,S$6) -> 0 | T11: =SUMIFS($K$7:$K$756,$B$7:$B$756,$M11,$A$7:$A$756,T$6) -> 0 | U11: =SUMIFS($K$7:$K$756,$B$7:$B$756,$M11,$A$7:$A$756,U$6) -> 0 | V11: =SUM(N11:U11) -> 0
A12: 07º - Lazer | Garagem | B12: Sistema de interfone / controle de acesso | C12: Botoeira | D12: Botoeira | E12: 5 | F12: 1 | G12: =E12*F12 -> 5 | H12: Unidade | I12: 60 | J12: 90 | K12: =IF(SUM(E12:I12)=0,SUMIFS($K13:$K$37,$A13:$A$37,$A12),(G12*I12)+(G12*J12)) -> 750 | N12: =SUMIFS($K$7:$K$756,$B$7:$B$756,$M12,$A$7:$A$756,N$6) -> 0 | O12: =SUMIFS($K$7:$K$756,$B$7:$B$756,$M12,$A$7:$A$756,O$6) -> 0 | P12: =SUMIFS($K$7:$K$756,$B$7:$B$756,$M12,$A$7:$A$756,P$6) -> 0 | Q12: =SUMIFS($K$7:$K$756,$B$7:$B$756,$M12,$A$7:$A$756,Q$6) -> 0 | R12: =SUMIFS($K$7:$K$756,$B$7:$B$756,$M12,$A$7:$A$756,R$6) -> 0 | S12: =SUMIFS($K$7:$K$756,$B$7:$B$756,$M12,$A$7:$A$756,S$6) -> 0 | T12: =SUMIFS($K$7:$K$756,$B$7:$B$756,$M12,$A$7:$A$756,T$6) -> 0 | U12: =SUMIFS($K$7:$K$756,$B$7:$B$756,$M12,$A$7:$A$756,U$6) -> 0 | V12: =SUM(N12:U12) -> 0
A13: 07º - Lazer | Garagem | B13: Sistema de interfone / controle de acesso | C13: Controle de Acesso | D13: Controle de Acesso | E13: 5 | F13: 1 | G13: =E13*F13 -> 5 | H13: Unidade | I13: 900 | J13: 160 | K13: =IF(SUM(E13:I13)=0,SUMIFS($K14:$K$37,$A14:$A$37,$A13),(G13*I13)+(G13*J13)) -> 5300 | N13: =SUMIFS($K$7:$K$756,$B$7:$B$756,$M13,$A$7:$A$756,N$6) -> 0 | O13: =SUMIFS($K$7:$K$756,$B$7:$B$756,$M13,$A$7:$A$756,O$6) -> 0 | P13: =SUMIFS($K$7:$K$756,$B$7:$B$756,$M13,$A$7:$A$756,P$6) -> 0 | Q13: =SUMIFS($K$7:$K$756,$B$7:$B$756,$M13,$A$7:$A$756,Q$6) -> 0 | R13: =SUMIFS($K$7:$K$756,$B$7:$B$756,$M13,$A$7:$A$756,R$6) -> 0 | S13: =SUMIFS($K$7:$K$756,$B$7:$B$756,$M13,$A$7:$A$756,S$6) -> 0 | T13: =SUMIFS($K$7:$K$756,$B$7:$B$756,$M13,$A$7:$A$756,T$6) -> 0 | U13: =SUMIFS($K$7:$K$756,$B$7:$B$756,$M13,$A$7:$A$756,U$6) -> 0 | V13: =SUM(N13:U13) -> 0
A14: 07º - Lazer | Garagem | B14: Sistema de interfone / controle de acesso | C14: Leitora de Tag Veicular | D14: Leitora de Tag Veicular | E14: 2 | F14: 1 | G14: =E14*F14 -> 2 | H14: Unidade | I14: 2500 | J14: 280 | K14: =IF(SUM(E14:I14)=0,SUMIFS($K15:$K$37,$A15:$A$37,$A14),(G14*I14)+(G14*J14)) -> 5560 | V14: =SUM(V7:V13) -> 142315.39
A15: 07º - Lazer | Garagem | B15: Sistema de interfone / controle de acesso | C15: Sensor Anti‑Esmagamento | D15: Sensor Anti‑Esmagamento | E15: 2 | F15: 1 | G15: =E15*F15 -> 2 | H15: Unidade | I15: 250 | J15: 110 | K15: =IF(SUM(E15:I15)=0,SUMIFS($K16:$K$37,$A16:$A$37,$A15),(G15*I15)+(G15*J15)) -> 720
A16: 07º - Lazer | Garagem | B16: Sistema de interfone / controle de acesso | C16: Vídeo Porteiro/Interfone | D16: Vídeo Porteiro/Interfone | E16: 3 | F16: 1 | G16: =E16*F16 -> 3 | H16: Unidade | I16: 700 | J16: 160 | K16: =IF(SUM(E16:I16)=0,SUMIFS($K18:$K$37,$A18:$A$37,$A16),(G16*I16)+(G16*J16)) -> 2580
A17: 07º - Lazer | Garagem | B17: Automação | C17: Automação | D17: Automação | E17: 1 | F17: 1 | G17: =E17*F17 -> 1 | H17: Unidade | I17: =39210.12*3019.26/2753.62 -> 42992.696 | K17: =IF(SUM(E17:I17)=0,SUMIFS($K19:$K$37,$A19:$A$37,$A17),(G17*I17)+(G17*J17)) -> 42992.696
A18: 07º - Lazer | Garagem | B18: Telefonia/lógica/internet | C18: Wi‑Fi (AP) | D18: Wi‑Fi (AP) | E18: 1 | F18: 1 | G18: =E18*F18 -> 1 | H18: Unidade | I18: 1100 | J18: 150 | K18: =IF(SUM(E18:I18)=0,SUMIFS($K26:$K$37,$A26:$A$37,$A18),(G18*I18)+(G18*J18)) -> 1250
A19: 08º - Lazer | B19: Sistema de interfone / controle de acesso | C19: Botoeira | D19: Botoeira | E19: 4 | F19: 1 | G19: =E19*F19 -> 4 | H19: Unidade | I19: 60 | J19: 90 | K19: =IF(SUM(E19:I19)=0,SUMIFS($K20:$K$37,$A20:$A$37,$A19),(G19*I19)+(G19*J19)) -> 600
A20: 08º - Lazer | B20: Sistema de interfone / controle de acesso | C20: Controle de Acesso | D20: Controle de Acesso | E20: 4 | F20: 1 | G20: =E20*F20 -> 4 | H20: Unidade | I20: 900 | J20: 160 | K20: =IF(SUM(E20:I20)=0,SUMIFS($K21:$K$37,$A21:$A$37,$A20),(G20*I20)+(G20*J20)) -> 4240
A21: 08º - Lazer | B21: Sistema de interfone / controle de acesso | C21: Leitora de Tag Veicular | D21: Leitora de Tag Veicular | E21: 2 | F21: 1 | G21: =E21*F21 -> 2 | H21: Unidade | I21: 2500 | J21: 280 | K21: =IF(SUM(E21:I21)=0,SUMIFS($K22:$K$37,$A22:$A$37,$A21),(G21*I21)+(G21*J21)) -> 5560
A22: 08º - Lazer | B22: Sistema de interfone / controle de acesso | C22: Sensor Anti‑Esmagamento | D22: Sensor Anti‑Esmagamento | E22: 2 | F22: 1 | G22: =E22*F22 -> 2 | H22: Unidade | I22: 250 | J22: 110 | K22: =IF(SUM(E22:I22)=0,SUMIFS($K23:$K$37,$A23:$A$37,$A22),(G22*I22)+(G22*J22)) -> 720
A23: 08º - Lazer | B23: Sistema de interfone / controle de acesso | C23: Vídeo Porteiro/Interfone | D23: Vídeo Porteiro/Interfone | E23: 3 | F23: 1 | G23: =E23*F23 -> 3 | H23: Unidade | I23: 700 | J23: 160 | K23: =IF(SUM(E23:I23)=0,SUMIFS($K25:$K$37,$A25:$A$37,$A23),(G23*I23)+(G23*J23)) -> 2580
A24: 08º - Lazer | B24: Automação | C24: Automação | D24: Automação | E24: 1 | F24: 1 | G24: =E24*F24 -> 1 | H24: Unidade | I24: =39210.12*3019.26/2753.62 -> 42992.696 | K24: =IF(SUM(E24:I24)=0,SUMIFS($K26:$K$37,$A26:$A$37,$A24),(G24*I24)+(G24*J24)) -> 42992.696
A25: 08º - Lazer | B25: Telefonia/lógica/internet | C25: Wi‑Fi (AP) | D25: Wi‑Fi (AP) | E25: 1 | F25: 1 | G25: =E25*F25 -> 1 | H25: Unidade | I25: 1100 | J25: 150 | K25: =IF(SUM(E25:I25)=0,SUMIFS(#REF!,#REF!,$A25),(G25*I25)+(G25*J25)) -> 1250
A26: 09º - Tipo diferenciado | B26: Automação | C26: Automação | D26: Automação | E26: 1 | F26: 1 | G26: =E26*F26 -> 1 | H26: Unidade | I26: =(599582.97/12)*3019.26/2753.62 -> 54785.364
A27: 09º - Tipo diferenciado | B27: Sistema de interfone / controle de acesso | C27: Vídeo Porteiro/Interfone | D27: Vídeo Porteiro/Interfone | E27: 2 | F27: 1 | G27: =E27*F27 -> 2 | H27: Unidade | I27: 700 | J27: 160 | K27: =IF(SUM(E27:I27)=0,SUMIFS($K28:$K$37,$A28:$A$37,$A27),(G27*I27)+(G27*J27)) -> 1720
A28: 09º - Tipo diferenciado | B28: Telefonia/lógica/internet | C28: Wi‑Fi (AP) | D28: Wi‑Fi (AP) | E28: 4 | F28: 1 | G28: =E28*F28 -> 4 | H28: Unidade | I28: 1100 | J28: 150 | K28: =IF(SUM(E28:I28)=0,SUMIFS(#REF!,#REF!,$A28),(G28*I28)+(G28*J28)) -> 5000
A29: 10º - Tipo x8 | B29: Automação | C29: Automação | D29: Automação | E29: 1 | F29: 8 | G29: =E29*F29 -> 8 | H29: Unidade | I29: =(599582.97/12)*3019.26/2753.62 -> 54785.364
A30: 10º - Tipo x8 | B30: Sistema de interfone / controle de acesso | C30: Vídeo Porteiro/Interfone | D30: Vídeo Porteiro/Interfone | E30: 2 | F30: 8 | G30: =E30*F30 -> 16 | H30: Unidade | J30: 160 | K30: =IF(SUM(E30:I30)=0,SUMIFS($K31:$K$37,$A31:$A$37,$A30),(G30*I30)+(G30*J30)) -> 2560
A31: 10º - Tipo x8 | B31: Telefonia/lógica/internet | C31: Wi‑Fi (AP) | D31: Wi‑Fi (AP) | E31: 4 | F31: 8 | G31: =E31*F31 -> 32 | H31: Unidade | J31: 150 | K31: =IF(SUM(E31:I31)=0,SUMIFS(#REF!,#REF!,$A31),(G31*I31)+(G31*J31)) -> 4800
A32: 11º - Penthouse x22 | B32: Automação | C32: Automação | D32: Automação | E32: 1 | F32: 22 | G32: =E32*F32 -> 22 | H32: Unidade | I32: =((599582.97/12)*3019.26/2753.62)/2 -> 27392.682
A33: 11º - Penthouse x22 | B33: Sistema de interfone / controle de acesso | C33: Vídeo Porteiro/Interfone | D33: Vídeo Porteiro/Interfone | E33: 1 | F33: 22 | G33: =E33*F33 -> 22 | H33: Unidade | J33: 160 | K33: =IF(SUM(E33:I33)=0,SUMIFS($K34:$K$37,$A34:$A$37,$A33),(G33*I33)+(G33*J33)) -> 3520
A34: 11º - Penthouse x22 | B34: Telefonia/lógica/internet | C34: Wi‑Fi (AP) | D34: Wi‑Fi (AP) | E34: 1 | F34: 22 | G34: =E34*F34 -> 22 | H34: Unidade | J34: 150 | K34: =IF(SUM(E34:I34)=0,SUMIFS($K36:$K$38,$A36:$A$38,$A34),(G34*I34)+(G34*J34)) -> 3300
A35: 12º - Duplex inferior | B35: Automação | C35: Automação | D35: Automação | E35: 1 | F35: 1 | G35: =E35*F35 -> 1 | H35: Unidade | I35: =(599582.97/12)*3019.26/2753.62 -> 54785.364 | J35: 140
A36: 12º - Duplex inferior | B36: Sistema de interfone / controle de acesso | C36: Vídeo Porteiro/Interfone | D36: Vídeo Porteiro/Interfone | E36: 2 | F36: 1 | G36: =E36*F36 -> 2 | H36: Unidade | J36: 160 | K36: =IF(SUM(E36:I36)=0,SUMIFS($K37:$K$37,$A37:$A$37,$A36),(G36*I36)+(G36*J36)) -> 320
A37: 12º - Duplex inferior | B37: Telefonia/lógica/internet | C37: Wi‑Fi (AP) | D37: Wi‑Fi (AP) | E37: 2 | F37: 1 | G37: =E37*F37 -> 2 | H37: Unidade | J37: 150 | K37: =IF(SUM(E37:I37)=0,SUMIFS($K$38:$K39,$A$38:$A39,$A37),(G37*I37)+(G37*J37)) -> 300
I38: TOTAL | J38: TOTAL | K38: =(SUMPRODUCT(G6:G37,J6:J37))+(SUMPRODUCT(G6:G37,I6:I37)) -> 1292948
B40: AUTOMAÇÃO LAZER**** | C40: Gateway GW3 – Protocolo TCP/IP – IR +RF + Central de Automação Yubii Home – Protocolo Z-Wave /RF / Wi-fi + Módulo Relé de 32ch cabeado Ethernet –32 entradas digitais, e 32 saídas (NO/NC), controle de equipamentos via protocolo TCP/HTTP. + Roteador gerenciador de Rede + Mini UPS Nobreak + Caixa 305m Cabo rede Cat5E + Material e Montagem Dos Quadros e Painéis – Materiais, Montagem, organização e interligação de equipamentos do Quadro de Automação e Rede + Instalação Automação – Instalação de retornos, pulsadores, configuração e integração Nice /MolSmart + Instalação elétrica – Passagem de cabeamento dos pulsadores + Material e Montagem Dos Quadros e Painéis – Materiais, Montagem, organização e interligação de equipamentos do Quadro de Automação e Rede + Instalação Automação – Instalação de retornos, pulsadores, configuração e integração Nice/ MolSmart + Instalação elétrica – Passagem de cabeamento dos pulsadores + Configuração de Rede – Instalação e Configuração de rede local e Mikrotik + omissos
B41: AUTOMAÇÃO TIPOS**** | C41: Central de Automação Yubii Home – Protocolo Z-Wave /RF / Wi-fi + Módulo Relé de 32ch cabeado Ethernet –32 entradas digitais, e 32 saídas (NO/NC), controle de equipamentos via protocolo TCP/HTTP. + Roteador gerenciador de Rede + Mini UPS Nobreak + Caixa 305m Cabo rede Cat5E + Material e Montagem Dos Quadros e Painéis – Materiais, Montagem, organização e interligação de equipamentos do Quadro de Automação e Rede + Instalação Automação – Instalação de retornos, pulsadores, configuração e integração Nice /MolSmart + Instalação elétrica – Passagem de cabeamento dos pulsadores + Material e Montagem Dos Quadros e Painéis – Materiais, Montagem, organização e interligação de equipamentos do Quadro de Automação e Rede + Instalação Automação – Instalação de retornos, pulsadores, configuração e integração Nice/ MolSmart + Instalação elétrica – Passagem de cabeamento dos pulsadores + Configuração de Rede – Instalação e Configuração de rede local e Mikrotik + omissos

Sheet Ger_Executivo_Manual
H4: PROJETO: | I4: Electra Towers | O4: REVISÃO: | P4: DATA
H5: EMPRESA: | I5: Thozen | O5: R00
A6: Unidade Construtiva | B6: Célula Construtiva | C6: Etapa | D6: Subetapa | E6: Serviço | G6: GERENCIAMENTO EXECUTIVO
A7: 0 | B7: 0 | C7: 0 | D7: 0 | E7: 0 | G7: EAP | H7: NIVEL | I7: Item | J7: Descrição | K7: Unidade | L7: Quant. | M7: Preço un | N7: Total | O7: Considerações | P7: Situação
A8: 0 | B8: 1 | C8: 0 | D8: 0 | E8: 0 | H8: CÉLULA CONSTRUTIVA | I8: 01 | J8: MOVIMENTAÇÃO DE TERRA
A9: 0 | B9: 1 | C9: 1 | D9: 0 | E9: 0 | H9: ETAPA | I9: 01.001 | J9: DEMOLIÇÕES, LIMPEZA DE TERRENO E LOCAÇÃO DE OBRA | N9: 26235.314 | O9: 1.5663183
A10: 0 | B10: 1 | C10: 1 | D10: 1 | E10: 0 | H10: SUBETAPA | I10: 01.001.001 | J10: Locação e gabarito de obra | N10: 26235.314 | O10: 1.5663183
A11: 0 | B11: 1 | C11: 1 | D11: 1 | E11: 1 | G11: MOVIMENTAÇÃO DE TERRA | H11: SERVIÇO | I11: 01.001.001.001 | J11: Locação da obra | K11: m2 | N11: 26235.314 | P11: Pendente
A12: 0 | B12: 1 | C12: 2 | D12: 0 | E12: 1 | H12: ETAPA | I12: 01.002 | J12: SERVIÇOS PRELIMINARES
A13: 0 | B13: 1 | C13: 2 | D13: 1 | E13: 0 | H13: SUBETAPA | I13: 01.002.001 | J13: Limpeza Permanente e Remoção entulho
A14: 0 | B14: 1 | C14: 2 | D14: 1 | E14: 1 | G14: MOVIMENTAÇÃO DE TERRA | H14: SERVIÇO | I14: 01.002.001.001 | J14: Limpeza da camada vegetal | K14: m2 | P14: Pendente
A15: 0 | B15: 1 | C15: 2 | D15: 1 | E15: 2 | G15: MOVIMENTAÇÃO DE TERRA | H15: SERVIÇO | I15: 01.002.001.002 | J15: Remoção de entulhos e resíduos | P15: Pendente
A16: 0 | B16: 1 | C16: 2 | D16: 2 | E16: 0 | H16: SUBETAPA | I16: 01.002.002 | J16: Mão de Obra de Canteiro
A17: 0 | B17: 1 | C17: 2 | D17: 2 | E17: 1 | G17: MOVIMENTAÇÃO DE TERRA | H17: SERVIÇO | I17: 01.002.002.001 | J17: Mão de Obra de Canteiro | K17: vb | P17: Pendente
A18: 0 | B18: 1 | C18: 3 | D18: 0 | E18: 1 | H18: ETAPA | I18: 01.003 | J18: SERVIÇOS DE TERRAPLANAGEM | N18: 271126.19 | O18: 16.186957
A19: 0 | B19: 1 | C19: 3 | D19: 1 | E19: 0 | H19: SUBETAPA | I19: 01.003.001 | J19: Mao de obra - movimentações de terra | N19: 271126.19 | O19: 16.186957
A20: 0 | B20: 1 | C20: 3 | D20: 1 | E20: 1 | G20: MOVIMENTAÇÃO DE TERRA | H20: SERVIÇO | I20: 01.003.001.001 | J20: Mão de obra movimentação de terra | K20: vb | N20: 233000 | P20: Pendente
A21: 0 | B21: 1 | C21: 4 | D21: 0 | E21: 2 | H21: ETAPA | I21: 01.004 | J21: SERVIÇO DE DRENAGEM | N21: 80000 | O21: 4.7762135
A22: 0 | B22: 1 | C22: 4 | D22: 1 | E22: 0 | H22: SUBETAPA | I22: 01.004.001 | J22: Drenagem | N22: 80000 | O22: 4.7762135
A23: 0 | B23: 1 | C23: 4 | D23: 1 | E23: 1 | G23: MOVIMENTAÇÃO DE TERRA | H23: SERVIÇO | I23: 01.004.001.001 | J23: Rebaixamento de Lençol freático | K23: vb | N23: 80000 | P23: Pendente
A24: 0 | B24: 2 | C24: 0 | D24: 1 | E24: 1 | H24: CÉLULA CONSTRUTIVA | I24: 02 | J24: CONTENÇÃO | N24: 772006.63 | O24: 46.090856
A25: 0 | B25: 2 | C25: 1 | D25: 0 | E25: 1 | H25: ETAPA | I25: 02.001 | J25: MURETA GUIA | N25: 18739.389 | O25: 1.1187915
A26: 0 | B26: 2 | C26: 1 | D26: 1 | E26: 0 | H26: SUBETAPA | I26: 02.001.001 | J26: Forma | N26: 6673.9436 | O26: 0.39845225
A27: 0 | B27: 2 | C27: 1 | D27: 1 | E27: 1 | G27: CONTENÇÃO | H27: SERVIÇO | I27: 02.001.001.001 | J27: Forma para infraestrutura em Tábuas de Madeira Serrada 2x reaproveitamento | K27: m2 | L27: 111.3136 | M27: 59.956229 | N27: 6673.9436 | P27: Pendente
A28: 0 | B28: 2 | C28: 1 | D28: 2 | E28: 0 | H28: SUBETAPA | I28: 02.001.002 | J28: Armadura | N28: 4318.7306 | O28: 0.25783974
A29: 0 | B29: 2 | C29: 1 | D29: 2 | E29: 1 | G29: CONTENÇÃO | H29: SERVIÇO | I29: 02.001.002.001 | J29: Armação aço CA-50 ø 6,3mm para Contenções (corte e dobra em obra) | K29: un | L29: 670.32 | M29: 6.0795674 | N29: 4075.2556 | P29: Pendente
A30: 0 | B30: 2 | C30: 1 | D30: 2 | E30: 2 | G30: CONTENÇÃO | H30: SERVIÇO | I30: 02.001.002.002 | J30: Armação aço CA-50 ø 12,5mm para Contenções (corte e dobra em obra) | K30: un | L30: 41.6016 | M30: 5.8525391 | N30: 243.47499 | P30: Pendente
A31: 0 | B31: 2 | C31: 1 | D31: 3 | E31: 0 | H31: SUBETAPA | I31: 02.001.003 | J31: Concreto | N31: 7746.7147 | O31: 0.46249954
A32: 0 | B32: 2 | C32: 1 | D32: 3 | E32: 1 | G32: CONTENÇÃO | H32: SERVIÇO | I32: 02.001.003.001 | J32: Concreto Usinado bombeável 50MPa para infraestrutura- incluindo serviço de bombeamento | K32: m3 | L32: 11.390452 | M32: 680.106 | N32: 7746.7147 | P32: Pendente
A33: 0 | B33: 2 | C33: 2 | D33: 0 | E33: 1 | H33: ETAPA | I33: 02.002 | J33: LAMELAS | PAREDE DIAFRAGMA | N33: 331865.23 | O33: 19.81324
A34: 0 | B34: 2 | C34: 2 | D34: 1 | E34: 0 | H34: SUBETAPA | I34: 02.002.001 | J34: Armadura | N34: 155967.97 | O34: 9.3117038
A35: 0 | B35: 2 | C35: 2 | D35: 1 | E35: 1 | G35: CONTENÇÃO | H35: SERVIÇO | I35: 02.002.001.001 | J35: Armação aço CA-50 ø 6,3mm para Contenções (corte e dobra em Indústria) | K35: un | L35: 2282 | M35: 8.964145 | N35: 20456.179 | P35: Pendente
A36: 0 | B36: 2 | C36: 2 | D36: 1 | E36: 2 | G36: CONTENÇÃO | H36: SERVIÇO | I36: 02.002.001.002 | J36: Armação aço CA-50 ø 8,0mm para Contenções (corte e dobra em Indústria) | K36: un | L36: 77 | M36: 8.964145 | N36: 690.23916 | P36: Pendente
A37: 0 | B37: 2 | C37: 2 | D37: 1 | E37: 3 | G37: CONTENÇÃO | H37: SERVIÇO | I37: 02.002.001.003 | J37: Armação aço CA-50 ø 12,5mm para Contenções (corte e dobra em Indústria) | K37: un | L37: 3884 | M37: 8.484145 | N37: 32952.419 | P37: Pendente
A38: 0 | B38: 2 | C38: 2 | D38: 1 | E38: 4 | G38: CONTENÇÃO | H38: SERVIÇO | I38: 02.002.001.004 | J38: Armação aço CA-50 ø 25,0mm para Contenções (corte e dobra em Indústria) | K38: un | L38: 12007 | M38: 8.484145 | N38: 101869.13 | P38: Pendente
A39: 0 | B39: 2 | C39: 2 | D39: 2 | E39: 0 | H39: SUBETAPA | I39: 02.002.002 | J39: Concreto | N39: 175897.26 | O39: 10.501536
A40: 0 | B40: 2 | C40: 2 | D40: 2 | E40: 1 | G40: CONTENÇÃO | H40: SERVIÇO | I40: 02.002.002.001 | J40: Concreto Usinado bombeável 50MPa com Penetron para infraestrutura- incluindo serviço de bombeamento | K40: m3 | L40: 210 | M40: 837.606 | N40: 175897.26 | P40: Pendente
A41: 0 | B41: 2 | C41: 3 | D41: 0 | E41: 1 | H41: ETAPA | I41: 02.003 | J41: VIGAS COROAMENTO | N41: 37645.991 | O41: 2.2475661
A42: 0 | B42: 2 | C42: 3 | D42: 1 | E42: 0 | H42: SUBETAPA | I42: 02.003.001 | J42: Forma | N42: 2482.1879 | O42: 0.14819324
A43: 0 | B43: 2 | C43: 3 | D43: 1 | E43: 1 | G43: CONTENÇÃO | H43: SERVIÇO | I43: 02.003.001.001 | J43: Forma para infraestrutura em Tábuas de Madeira Serrada 2x reaproveitamento | K43: m2 | L43: 41.4 | M43: 59.956229 | N43: 2482.1879 | P43: Pendente
...

Sheet Orçamento
A1: DADOS
A2: Titulo | B2: ORÇAMENTO
A3: Obra | B3: ELECTRA TOWERS
A4: Cliente | B4: THOZEN
A5: Cidade | B5: Porto Belo
A6: Endereço
A7: Descrição
A8: UF | B8: SC
A10: RESUMO
A11: Tipo | C11: Preço | E11: Observação
A12: Total | C12: 21718825 | E12: Geral da edificação
A13: Material | C13: 15467433
A14: Execução | C14: 6251392.4
A16: TABELA DE ORÇAMENTO
A17: Item | B17: Referência | C17: Tipo | D17: Código | E17: Descrição | F17: Unid. | G17: Quantidade | H17: Custo unitário | I17: Preço total | J17: % | K17: Observação
A19: 1. | E19: 03. PAREDES E PAINÉIS | I19: 1964071 | J19: 0.090431735
A20: 1.1. | E20: ARQ_Embasamento | I20: 228660.08 | J20: 0.010528198
A21: 1.1.1. | E21: 03.001. Alvenaria de vedação com blocos cerâmicos | I21: 133087.99 | J21: 0.006127771
A22: 1.1.1.1 | E22: BLOCO CERAMICO, 0,05 (Parede padrão) | F22: m² | G22: 35.77 | H22: 0 | I22: 0
A23: 1.1.1.2 | E23: BLOCO CERAMICO, 0,09 (Parede padrão) | F23: m² | G23: 171.98 | H23: 0 | I23: 0
A24: 1.1.1.3 | B24: Thozen - Electra | C24: COMPOSICAO | D24: 4825 | E24: Alvenaria de vedação de blocos cerâmicos furados na horizontal de 11,5x19x19cm (espessura 11,5cm) com argamassa industrializada de assentamento | F24: m2 | G24: 1262.88 | H24: 25.096 | I24: 31693.236 | J24: 0.0014592519
A25: 1.1.1.4 | B25: Thozen - Electra | C25: COMPOSICAO | D25: 4826 | E25: Alvenaria de vedação de blocos cerâmicos furados na horizontal de 14x19x19cm (espessura 14cm) com argamassa industrializada de assentamento | F25: m2 | G25: 1610.87 | H25: 40.7664 | I25: 65669.371 | J25: 0.0030236152
A26: 1.1.1.5 | B26: Thozen - Electra | C26: COMPOSICAO | D26: 90472 | E26: Alvenaria de vedação de blocos cerâmicos furados na horizontal de 19x19x19cm (espessura 19cm) com argamassa industrializada de assentamento | F26: m2 | G26: 631.36 | H26: 56.5848 | I26: 35725.379 | J26: 0.0016449039
A27: 1.1.2. | E27: 03.002. Alvenaria de vedação com blocos de concreto | I27: 0
A28: 1.1.2.1 | E28: BLOCO CONCRETO, 0,05 (Parede padrão) | F28: m² | G28: 1.49 | H28: 0 | I28: 0
A29: 1.1.2.2 | E29: BLOCO ANTI CHAMAS, 0,125 (Parede padrão) | F29: m² | G29: 252.44 | H29: 0 | I29: 0
A30: 1.1.2.3 | E30: BLOCO ANTI CHAMAS, 0,15 (Parede padrão) | F30: m² | G30: 774.4 | H30: 0 | I30: 0
A31: 1.1.3. | E31: 03.003. Serviços complementares para alvenaria de vedação | I31: 95572.097 | J31: 0.0044004266
A32: 1.1.3.1 | B32: Thozen - Electra | C32: COMPOSICAO | D32: 4831 | E32: Verga/contraverga de concreto, moldada in loco | F32: m | G32: 104.16 | H32: 43.712512 | I32: 4553.0952 | J32: 0.00020963819
A33: 1.1.3.2 | B33: Thozen - Electra | C33: COMPOSICAO | D33: 4828 | E33: Encunhamento de alvenaria de vedação com argamassa expansiva | F33: m | G33: 18470.23 | H33: 3.633798 | I33: 67117.085 | J33: 0.0030902724
A34: 1.1.3.3 | B34: Thozen - Electra | C34: COMPOSICAO | D34: 4829 | E34: Tela soldada para ligação alvenaria/estrutura | F34: m² | G34: 2370.59 | H34: 1.85 | I34: 4385.5915 | J34: 0.00020192582
A35: 1.1.3.4 | B35: Thozen - Electra | C35: COMPOSICAO | D35: 4831 | E35: Verga/contraverga de concreto, moldada in loco | F35: m | G35: 446.47 | H35: 43.712512 | I35: 19516.325 | J35: 0.00089859028
A36: 1.1.4. | E36: 03.005. Mão de obra | I36: 0
A37: 1.1.4.1 | E37: Mão de obra alvenaria cerâmica | F37: m² | G37: 4045.19 | H37: 0 | I37: 0
A38: 1.1.4.2 | E38: Mão de obra blocos sílico calcário (Parede padrão) | F38: m² | G38: 1028.33 | H38: 0 | I38: 0
A39: 1.1.5. | E39: Alvenaria de vedação com tijolo refratário | I39: 0
A40: 1.1.5.1 | E40: TIJOLO REFRATARIO, 0,016 (Parede padrão) | F40: m² | G40: 14.56 | H40: 0 | I40: 0
A41: 1.2. | E41: ARQ_Impermeab | I41: 45754.495 | J41: 0.0021066745
A42: 1.2.1. | E42: 03.003. Serviços complementares para alvenaria de vedação | I42: 45754.495 | J42: 0.0021066745
A43: 1.2.1.1 | B43: Thozen - Electra | C43: COMPOSICAO | D43: 4828 | E43: Encunhamento de alvenaria de vedação com argamassa expansiva | F43: m | G43: 12591.37 | H43: 3.633798 | I43: 45754.495 | J43: 0.0021066745
...

Sheet Composições
A1: DADOS
A2: Titulo | B2: ORÇAMENTO
A3: Obra | B3: ELECTRA TOWERS
A4: Cliente | B4: THOZEN
A5: Cidade | B5: Porto Belo
A6: Endereço
A7: Descrição
A8: UF | B8: SC
A11: TABELA DE COMPOSIÇÕES UTILIZADAS
A12: Código | B12: Referência | C12: Tipo | D12: Tipo | E12: Descrição | F12: Unid. | G12: Multiplicador | H12: Preço | J12: Ref. Tabela | K12: Ref. Código | L12: Justificativa | M12: Grupo de Serviço | N12: Serviço
H13: Unitário | I13: Total
A14: 4825 | B14: Thozen - Electra | D14: Original | E14: Alvenaria de vedação de blocos cerâmicos furados na horizontal de 11,5x19x19cm (espessura 11,5cm) com argamassa industrializada de assentamento | F14: m2 | I14: 25.096 | N14: BLOCOS | O14: =A14&B14&C14 -> 4825Thozen - Electra
A15: 194 | B15: Thozen - Electra | C15: INSUMO | D15: Original | E15: ARGAMASSA ESTABILIZADA PARA ASSENTAMENTO | F15: m3 | G15: 0.0125 | H15: 480 | I15: 6
A16: 228 | B16: Thozen - Electra | C16: INSUMO | D16: Original | E16: BLOCO CERÂMICO 11,5X19X19CM | F16: un | G16: 17.36 | H16: 1.1 | I16: 19.096
A17: 4826 | B17: Thozen - Electra | D17: Original | E17: Alvenaria de vedação de blocos cerâmicos furados na horizontal de 14x19x19cm (espessura 14cm) com argamassa industrializada de assentamento | F17: m2 | I17: 40.7664 | N17: BLOCOS | O17: =A17&B17&C17 -> 4826Thozen - Electra
A18: 194 | B18: Thozen - Electra | C18: INSUMO | D18: Original | E18: ARGAMASSA ESTABILIZADA PARA ASSENTAMENTO | F18: m3 | G18: 0.022 | H18: 480 | I18: 10.56
A19: 232 | B19: Thozen - Electra | C19: INSUMO | D19: Original | E19: BLOCO CERÂMICO 14X19X19CM | F19: un | G19: 17.36 | H19: 1.74 | I19: 30.2064
A20: 90472 | B20: Thozen - Electra | D20: Original | E20: Alvenaria de vedação de blocos cerâmicos furados na horizontal de 19x19x19cm (espessura 19cm) com argamassa industrializada de assentamento | F20: m2 | I20: 56.5848 | N20: BLOCOS | O20: =A20&B20&C20 -> 90472Thozen - Electra
A21: 194 | B21: Thozen - Electra | C21: INSUMO | D21: Original | E21: ARGAMASSA ESTABILIZADA PARA ASSENTAMENTO | F21: m3 | G21: 0.03 | H21: 480 | I21: 14.4
A22: 48433 | B22: Thozen - Electra | C22: INSUMO | D22: Original | E22: BLOCO CERÂMICO 19X19X19CM | F22: un | G22: 17.36 | H22: 2.43 | I22: 42.1848
A23: 4831 | B23: Thozen - Electra | D23: Original | E23: Verga/contraverga de concreto, moldada in loco | F23: m | I23: 43.712512 | O23: =A23&B23&C23 -> 4831Thozen - Electra
A24: 759 | B24: Thozen - Electra | C24: INSUMO | D24: Original | E24: CONCRETO USINADO FCK 20 MPA, SLUMP 14+/-2 | F24: m3 | G24: 0.0264 | H24: 450 | I24: 11.88
A25: 4800 | B25: Thozen - Electra | C25: INSUMO | D25: Original | E25: DESMOLDANTE DE FORMAS PARA CONCRETO | F25: l | G25: 0.007 | H25: 6.45 | I25: 0.04515
A26: 1412 | B26: Thozen - Electra | C26: INSUMO | D26: Original | E26: ESPAÇADOR PLÁSTICO | F26: un | G26: 6 | H26: 0.15 | I26: 0.9
A27: 2324 | B27: Thozen - Electra | C27: INSUMO | D27: Original | E27: PONTALETE 7,5X7,5 CM PINUS | F27: m3 | G27: 0.0012 | H27: 1310 | I27: 1.572
A28: 2362 | B28: Thozen - Electra | C28: INSUMO | D28: Original | E28: PREGO POLIDO COM CABEÇA 17X21 | F28: kg | G28: 0.0512 | H28: 10.91 | I28: 0.558592
A29: 2546 | B29: Thozen - Electra | C29: INSUMO | D29: Original | E29: SARRAFO 2,5X7,5 CM PINUS | F29: m3 | G29: 0.003171 | H29: 1300 | I29: 4.1223
A30: 2611 | B30: Thozen - Electra | C30: INSUMO | D30: Original | E30: TÁBUA 1"X12" 2,5X30CM PINUS | F30: m3 | G30: 0.011676 | H30: 1800 | I30: 21.0168
A31: 32 | B31: Thozen - Electra | C31: INSUMO | D31: Original | E31: AÇO CA-50 DIÂMETRO 6,30 MM | F31: kg | G31: 0.5243 | H31: 6.9 | I31: 3.61767
A32: 4828 | B32: Thozen - Electra | D32: Original | E32: Encunhamento de alvenaria de vedação com argamassa expansiva | F32: m | I32: 3.633798 | N32: ENCUNHAMENTO | O32: =A32&B32&C32 -> 4828Thozen - Electra
A33: 48435 | B33: Thozen - Electra | C33: INSUMO | D33: Original | E33: ARGAMASSA EXPANSIVA PARA ENCUNHAMENTO | F33: Kg | G33: 0.2154 | H33: 16.87 | I33: 3.633798
A34: 4829 | B34: Thozen - Electra | D34: Original | E34: Tela soldada para ligação alvenaria/estrutura | F34: m² | I34: 1.85 | O34: =A34&B34&C34 -> 4829Thozen - Electra
A35: 718 | B35: Thozen - Electra | C35: INSUMO | D35: Original | E35: CARTUCHO 22 - CARGA LEVE PARA FINCA PINO E POLVORA | F35: un | G35: 1 | H35: 0.3 | I35: 0.3
A36: 2260 | B36: Thozen - Electra | C36: INSUMO | D36: Original | E36: PINO LISO EM AÇO GALVANIZADO 1/2 X 22MM COM ARRUELA | F36: un | G36: 1 | H36: 0.3 | I36: 0.3
A37: 2901 | B37: Thozen - Electra | C37: INSUMO | D37: Original | E37: TELA DE ACO SOLDADA, FIO 1,24MM, MALHA 15X15MM | F37: m2 | G37: 0.5 | H37: 2.5 | I37: 1.25
A38: 4842 | B38: Thozen - Electra | D38: Original | E38: Impermeabilização com argamassa polimérica, 3 demãos | F38: m2 | I38: 36.225 | O38: =A38&B38&C38 -> 4842Thozen - Electra
A39: 202 | B39: Thozen - Electra | C39: INSUMO | D39: Original | E39: ARGAMASSA POLIMÉRICA IMPERMEABILIZANTE | F39: kg | G39: 3.15 | H39: 11.5 | I39: 36.225
A40: 90541 | B40: Thozen - Electra | D40: Original | E40: Chapisco adesivo aplicado em concreto, com desempenadeira dentada | F40: m2 | I40: 6.459 | N40: CHAPISCO | O40: =A40&B40&C40 -> 90541Thozen - Electra
A41: 197 | B41: Thozen - Electra | C41: INSUMO | D41: Original | E41: ARGAMASSA ESTABILIZADA PARA REBOCO | F41: m3 | G41: 0.0033 | H41: 480 | I41: 1.584
A42: 48481 | B42: Thozen - Electra | C42: INSUMO | D42: Original | E42: ADITIVO ADESIVO LÍQUIDO PARA ARGAMASSA | F42: L | G42: 0.625 | H42: 7.8 | I42: 4.875
...

Sheet Insumos (2)
A1: DADOS
A2: Titulo | B2: Tabela de insumos utilizados no projeto
A3: Obra | B3: ELECTRA TOWERS
A4: Cliente | B4: THOZEN
A5: Cidade | B5: Porto Belo
A6: Endereço
A7: Descrição
A8: UF | B8: SC
A11: INSUMOS UTILIZADOS
A12: Código | B12: Tabela | C12: Tipo | D12: Descrição | E12: Unid. | F12: Preço | G12: Origem custo | H12: Justificativa
A14: 194 | B14: Thozen - Electra | C14: Material | D14: ARGAMASSA ESTABILIZADA PARA ASSENTAMENTO | E14: m3 | F14: 480 | I14: =A14&B14 -> 194Thozen - Electra
A15: 228 | B15: Thozen - Electra | C15: Material | D15: BLOCO CERÂMICO 11,5X19X19CM | E15: un | F15: 1.1 | I15: =A15&B15 -> 228Thozen - Electra
A16: 232 | B16: Thozen - Electra | C16: Material | D16: BLOCO CERÂMICO 14X19X19CM | E16: un | F16: 1.74 | I16: =A16&B16 -> 232Thozen - Electra
A17: 48433 | B17: Thozen - Electra | C17: Material | D17: BLOCO CERÂMICO 19X19X19CM | E17: un | F17: 2.43 | I17: =A17&B17 -> 48433Thozen - Electra
A18: 759 | B18: Thozen - Electra | C18: Material | D18: CONCRETO USINADO FCK 20 MPA, SLUMP 14+/-2 | E18: m3 | F18: 450 | I18: =A18&B18 -> 759Thozen - Electra
A19: 4800 | B19: Thozen - Electra | C19: Material | D19: DESMOLDANTE DE FORMAS PARA CONCRETO | E19: l | F19: 6.45 | I19: =A19&B19 -> 4800Thozen - Electra
A20: 1412 | B20: Thozen - Electra | C20: Material | D20: ESPAÇADOR PLÁSTICO | E20: un | F20: 0.15 | I20: =A20&B20 -> 1412Thozen - Electra
A21: 2324 | B21: Thozen - Electra | C21: Material | D21: PONTALETE 7,5X7,5 CM PINUS | E21: m3 | F21: 1310 | I21: =A21&B21 -> 2324Thozen - Electra
A22: 2362 | B22: Thozen - Electra | C22: Material | D22: PREGO POLIDO COM CABEÇA 17X21 | E22: kg | F22: 10.91 | I22: =A22&B22 -> 2362Thozen - Electra
A23: 2546 | B23: Thozen - Electra | C23: Material | D23: SARRAFO 2,5X7,5 CM PINUS | E23: m3 | F23: 1300 | I23: =A23&B23 -> 2546Thozen - Electra
A24: 2611 | B24: Thozen - Electra | C24: Material | D24: TÁBUA 1"X12" 2,5X30CM PINUS | E24: m3 | F24: 1800 | I24: =A24&B24 -> 2611Thozen - Electra
A25: 32 | B25: Thozen - Electra | C25: Material | D25: AÇO CA-50 DIÂMETRO 6,30 MM | E25: kg | F25: 6.9 | G25: GERDAU | I25: =A25&B25 -> 32Thozen - Electra
A26: 48435 | B26: Thozen - Electra | C26: Material | D26: ARGAMASSA EXPANSIVA PARA ENCUNHAMENTO | E26: Kg | F26: 16.87 | I26: =A26&B26 -> 48435Thozen - Electra
A27: 718 | B27: Thozen - Electra | C27: Material | D27: CARTUCHO 22 - CARGA LEVE PARA FINCA PINO E POLVORA | E27: un | F27: 0.3 | I27: =A27&B27 -> 718Thozen - Electra
A28: 2260 | B28: Thozen - Electra | C28: Material | D28: PINO LISO EM AÇO GALVANIZADO 1/2 X 22MM COM ARRUELA | E28: un | F28: 0.3 | I28: =A28&B28 -> 2260Thozen - Electra
A29: 2901 | B29: Thozen - Electra | C29: Material | D29: TELA DE ACO SOLDADA, FIO 1,24MM, MALHA 15X15MM | E29: m2 | F29: 2.5 | I29: =A29&B29 -> 2901Thozen - Electra
A30: 202 | B30: Thozen - Electra | C30: Material | D30: ARGAMASSA POLIMÉRICA IMPERMEABILIZANTE | E30: kg | F30: 11.5 | I30: =A30&B30 -> 202Thozen - Electra
A31: 197 | B31: Thozen - Electra | C31: Material | D31: ARGAMASSA ESTABILIZADA PARA REBOCO | E31: m3 | F31: 480 | I31: =A31&B31 -> 197Thozen - Electra
A32: 48481 | B32: Thozen - Electra | C32: Material | D32: ADITIVO ADESIVO LÍQUIDO PARA ARGAMASSA | E32: L | F32: 7.8 | I32: =A32&B32 -> 48481Thozen - Electra
A33: 48373 | B33: Thozen - Electra | C33: Material | D33: CHAPISCO COLANTE 20KG | E33: Kg | F33: 1.31 | I33: =A33&B33 -> 48373Thozen - Electra
A34: 2154 | B34: Thozen - Electra | C34: Mao_obra | D34: MÃO DE OBRA PARA EXECUÇÃO DE CHAPISCO E REBOCO INTERNO EM PAREDES | E34: m2 | F34: 35 | I34: =A34&B34 -> 2154Thozen - Electra
A35: 193 | B35: Thozen - Electra | C35: Material | D35: ARGAMASSA COLANTE AC III | E35: kg | F35: 2.345 | I35: =A35&B35 -> 193Thozen - Electra
A36: 4881 | B36: Thozen - Electra | C36: Material | D36: ESPAÇADOR PARA REVESTIMENTO CERÂMICO TIPO CRUZETA 5 MM | E36: un | F36: 0.2 | I36: =A36&B36 -> 4881Thozen - Electra
A37: 4880 | B37: Thozen - Electra | C37: Material | D37: REJUNTE FLEXÍVEL | E37: m2 | F37: 2.0643 | I37: =A37&B37 -> 4880Thozen - Electra
... A61: 2552 | B61: Thozen - Electra | C61: Material | D61: SELADOR ACRÍLICO | E61: l | F61: 9.44 | I61: =A61&B61 -> 2552Thozen - Electra

Sheet PROJETOS
B1: GESTÃO DOS PROJETOS | J1: LEGENDA
A2: Obra | B2: Electra Towers (Rubens Alves) | J2: NÃO SE APLICA
A3: Empresa | B3: Thozen Empreendimentos | J3: PENDENTE
A4: Revisão | B4: R01 | J4: RECEBIDO
B5: PAVIMENTO | C5: DISCIPLINA | D5: PROJETOS | E5: CAMINHO | F5: STATUS | G5: OBSERVAÇÕES | J5: REVISADO
B7: ESTRUTURA
B8: TERRAPLENAGEM | C8: INFRAESTRUTURA | F8: NÃO SE APLICA
B9: MOVIMENTAÇÃO DE TERRA | C9: INFRAESTRUTURA | F9: PENDENTE
B10: FUNDAÇÃO PROFUNDA | C10: INFRAESTRUTURA | D10: 1203 - PREFORMAS - R20.DWG | E10: 01 ESTRUTURA/DWG | F10: RECEBIDO | G10: DWG Pré-formas Rev.20
B11: FUNDAÇÃO RASA | C11: INFRAESTRUTURA | D11: 1203 - THOZEN - RUBENS ALVES - BLOCOS+RAMPAS DE ACESSO - R26.ifc | E11: 01 ESTRUTURA/IFC | F11: RECEBIDO | G11: IFC Blocos + Rampas de Acesso Rev.26
B12: CONTENÇÃO | C12: INFRAESTRUTURA | F12: NÃO SE APLICA
B13: ÁREA – 1º PAVTO. (TÉRREO) | C13: SUPRAESTRUTURA | F13: RECEBIDO | G13: Coberto pelo IFC estrutural completo
B14: ÁREA – MEZANINO DO 1º PAVTO. | C14: SUPRAESTRUTURA | F14: RECEBIDO | G14: Coberto pelo IFC estrutural completo
B15: ÁREA – 2º PAVIMENTO | C15: SUPRAESTRUTURA | F15: RECEBIDO | G15: Coberto pelo IFC estrutural completo
B16: ÁREA – MEZANINO DO 2º PAVTO. | C16: SUPRAESTRUTURA | F16: RECEBIDO | G16: Coberto pelo IFC estrutural completo
B17: ÁREA – 3º PAVIMENTO | C17: SUPRAESTRUTURA | F17: RECEBIDO | G17: Coberto pelo IFC estrutural completo
B18: ÁREA – MEZANINO DO 3º PAVTO. | C18: SUPRAESTRUTURA | F18: RECEBIDO | G18: Coberto pelo IFC estrutural completo
B19: ÁREA – 4º PAVIMENTO GARAGEM/LAZER | C19: SUPRAESTRUTURA | F19: RECEBIDO | G19: Coberto pelo IFC estrutural completo
B20: ÁREA – 5º PAVIMENTO LAZER | C20: SUPRAESTRUTURA | F20: RECEBIDO | G20: Coberto pelo IFC estrutural completo
B21: ÁREA – 6º PAVIMENTO TIPO - DIFERENCIADO | C21: SUPRAESTRUTURA | F21: RECEBIDO | G21: Coberto pelo IFC estrutural completo
B22: ÁREA – 7º AO 14° PAVIMENTO TIPO - X8 | C22: SUPRAESTRUTURA | F22: RECEBIDO | G22: Coberto pelo IFC estrutural completo
B23: ÁREA – 15º AO 35° PAVIMENTO TIPO - X21 | C23: SUPRAESTRUTURA | F23: RECEBIDO | G23: Coberto pelo IFC estrutural completo
B24: ARQUITETURA
B25: TERRAPLENAGEM | C25: ARQUITETURA | F25: NÃO SE APLICA
B26: MOVIMENTAÇÃO DE TERRA | C26: ARQUITETURA | F26: NÃO SE APLICA
B27: FUNDAÇÃO PROFUNDA | C27: ARQUITETURA | F27: NÃO SE APLICA
B28: FUNDAÇÃO RASA | C28: ARQUITETURA | F28: NÃO SE APLICA
B29: CONTENÇÃO | C29: ARQUITETURA | F29: NÃO SE APLICA
B30: TÉRREO 01 | C30: ARQUITETURA | D30: RA_ARQ_EXE_01_TÉRREO_R02.dwg | E30: 02 ARQUITETURA/DWG | F30: RECEBIDO | G30: DWG Executivo Rev.02
B31: TÉRREO 02 | C31: ARQUITETURA | D31: RA_ARQ_EXE_10_CORTE1_R02.dwg + RA_ARQ_EXE_11_CORTE2_R02.dwg | E31: 02 ARQUITETURA/DWG | F31: RECEBIDO | G31: Cortes 1 e 2, Rev.02
B32: GARAGEM 01 | C32: ARQUITETURA | D32: RA_ARQ_EXE_02_G1_R02.dwg | E32: 02 ARQUITETURA/DWG | F32: RECEBIDO | G32: DWG Executivo Rev.02
B33: GARAGEM 02 | C33: ARQUITETURA | D33: RA_ARQ_EXE_03_G2_R02.dwg | E33: 02 ARQUITETURA/DWG | F33: RECEBIDO | G33: DWG Executivo Rev.02
B34: GARAGEM 03 | C34: ARQUITETURA | D34: RA_ARQ_EXE_04_G3_R02.dwg | E34: 02 ARQUITETURA/DWG | F34: RECEBIDO | G34: DWG Executivo Rev.02
B35: GARAGEM 04 | C35: ARQUITETURA | D35: RA_ARQ_EXE_05_G4_R02.dwg | E35: 02 ARQUITETURA/DWG | F35: RECEBIDO | G35: DWG Executivo Rev.02
B36: LAZER 01 | C36: ARQUITETURA | D36: RA_ARQ_EXE_06_G5_R02.dwg | E36: 02 ARQUITETURA/DWG | F36: RECEBIDO | G36: DWG Executivo Rev.02
B37: LAZER 02 | C37: ARQUITETURA | D37: RA_ARQ_EXE_07_LAZER_R02.dwg | E37: 02 ARQUITETURA/DWG | F37: RECEBIDO | G37: DWG Executivo Rev.02
B38: TIPO DIFERENCIADO 01 | C38: ARQUITETURA | D38: RA_ARQ_EXE_MODELAGEM EMBASAMENTO + COBERTURA_R08.ifc | E38: 02 ARQUITETURA/IFC | F38: RECEBIDO | G38: IFC Embasamento + Cobertura Rev.08
B39: TIPO DIFERENCIADO 02 | C39: ARQUITETURA | D39: RA_ARQ_EXE_MODELAGEM TIPO_R07.ifc | E39: 02 ARQUITETURA/IFC | F39: RECEBIDO | G39: IFC Tipo Rev.07
B40: TIPO (30x) | C40: ARQUITETURA | D40: RA_ARQ_EXE_08_TIPOS_R02.dwg | E40: 02 ARQUITETURA/DWG | F40: RECEBIDO | G40: DWG Executivo Rev.02
B41: DUPLEX INFERIOR (3x) | C41: ARQUITETURA | F41: NÃO SE APLICA
...

Sheet Ger_Tec e Adm
A4: PROJETO: | C4: Electra Towers | I4: REVISÃO: | J4: DATA
A5: EMPRESA: | C5: Thozen | I5: R00
A6: GERENCIAMENTO EXECUTIVO
A7: Atalho | B7: NIVEL | C7: Item | D7: Descrição | E7: Unidade | F7: Quant. | G7: Preço un | H7: Total | I7: Considerações | J7: Situação
B8: CÉLULA CONSTRUTIVA | C8: 01 | D8: SERVIÇOS TÉCNICOS | H8: =H9+H57 -> 3668982.5
B9: ETAPA | C9: 01.001 | D9: ESTUDOS, PROJETOS E CONSULTORIAS | H9: =H10+H20+H41+H46 -> 2273047.4 | J9: -
B10: SUBETAPA | C10: 01.001.001 | D10: Estudos | H10: =H11+H12+H13+H14+H15+H16+H17+H18+H19 -> 260925.31
B11: SERVIÇO | C11: 01.001.001.001 | D11: Memorial descritivo | E11: vb | F11: 1 | G11: 18386.35 | H11: =G11*F11 -> 18386.35 | I11: Estimado | J11: Lançado ERP
B12: SERVIÇO | C12: 01.001.001.002 | D12: Levantamento topográfico | E12: vb | F12: 1 | G12: 3000 | H12: =G12*F12 -> 3000 | I12: Recebido | J12: Lançado ERP
B13: SERVIÇO | C13: 01.001.001.003 | D13: Estudo geológico | E13: vb | F13: 1 | G13: 26930.408 | H13: =G13*F13 -> 26930.408 | I13: Estimado | J13: Lançado ERP
B14: SERVIÇO | C14: 01.001.001.004 | D14: Estudo ambiental | E14: vb | F14: 1 | G14: 4500 | H14: =G14*F14 -> 4500 | I14: Recebido | J14: Lançado ERP
B15: SERVIÇO | C15: 01.001.001.005 | D15: Sondagem do terreno | E15: vb | F15: 1 | G15: 7947.99 | H15: =G15*F15 -> 7947.99 | I15: Recebido | J15: Lançado ERP
B16: SERVIÇO | C16: 01.001.001.006 | D16: Projeto de canteiro | E16: vb | F16: 1 | G16: 11160.563 | H16: =G16*F16 -> 11160.563 | I16: Estimado | J16: Lançado ERP
B17: SERVIÇO | C17: 01.001.001.007 | D17: EFEG - Teste de Carga | E17: vb | F17: 1 | G17: 29000 | H17: =G17*F17 -> 29000 | I17: Recebido | J17: Lançado ERP
B18: SERVIÇO | C18: 01.001.001.008 | D18: Solugeot - Teste de Carga | E18: vb | F18: 1 | G18: 140000 | H18: =G18*F18 -> 140000 | I18: Recebido | J18: Lançado ERP
B19: SERVIÇO | C19: 01.001.001.009 | D19: Concreto - Teste de Carga | E19: vb | F19: 1 | G19: 20000 | H19: =G19*F19 -> 20000 | I19: Recebido | J19: Lançado ERP
B20: SUBETAPA | C20: 01.001.002 | D20: Projetos | H20: =H21+H22+H23+H24+H25+H26+H27+H28+H29+H30+H31+H32+H33+H34+H35+H36+H37+H38+H39+H40 -> 1205079.2
B21: SERVIÇO | C21: 01.001.002.001 | D21: Legalização de incorporação | E21: vb | F21: 1 | G21: 67351.993 | H21: =G21*F21 -> 67351.993 | I21: Estimado | J21: Lançado ERP
B22: SERVIÇO | C22: 01.001.002.002 | D22: Projeto arquitetônico legal | E22: vb | F22: 1 | G22: 237000 | H22: =G22*F22 -> 237000 | I22: Recebido - Considerado junto desse projeto os valores de projeto arquitetônico legal + hidráulico + preventivo + elétrico + arquitetônico | J22: Lançado ERP
B23: SERVIÇO | C23: 01.001.002.003 | D23: Projeto Arquitetônico interiores | E23: vb | F23: 1 | G23: 86773.378 | H23: =G23*F23 -> 86773.378 | I23: Estimado | J23: Lançado ERP
B24: SERVIÇO | C24: 01.001.002.004 | D24: Projeto arquitetônico de fachada | E24: vb | F24: 1 | G24: 58250 | H24: =G24*F24 -> 58250 | I24: Recebido | J24: Lançado ERP
B25: SERVIÇO | C25: 01.001.002.005 | D25: Projeto técnico de fachada | E25: vb | F25: 1 | G25: 75145.12 | H25: =G25*F25 -> 75145.12 | I25: Estimado | J25: Lançado ERP
B26: SERVIÇO | C26: 01.001.002.006 | D26: Projeto de terraplanagem | E26: vb | F26: 1 | G26: 6962.4358 | H26: =G26*F26 -> 6962.4358 | I26: Estimado | J26: Lançado ERP
B27: SERVIÇO | C27: 01.001.002.007 | D27: Projeto estrutural | E27: vb | F27: 1 | G27: 70000 | H27: =G27*F27 -> 70000 | I27: Recebido - Considerado junto desse projeto os valores de projeto estrutural e fundação | J27: Lançado ERP
B28: SERVIÇO | C28: 01.001.002.008 | D28: Projeto de automação | E28: vb | F28: 1 | G28: 96720.281 | H28: =G28*F28 -> 96720.281 | I28: Estimado | J28: Lançado ERP
B29: SERVIÇO | C29: 01.001.002.009 | D29: Projeto de irrigação | E29: vb | F29: 1 | G29: 39550.22 | H29: =G29*F29 -> 39550.22 | I29: Estimado | J29: Lançado ERP
B30: SERVIÇO | C30: 01.001.002.010 | D30: Projeto preventivo (PPCI - Plano de Prevenção e Proteção Contra Incêndios) e Gás | E30: vb | F30: 1 | G30: 27354.018 | H30: =G30*F30 -> 27354.018 | I30: Estimado - Considerado somente o projeto de gás, pois o ppci, conforme informado no formulario, esta nicluso no arquitetônico | J30: Lançado ERP
B31: SERVIÇO | C31: 01.001.002.011 | D31: Projeto de climatização/exaustão | E31: vb | F31: 1 | G31: 91124.893 | H31: =G31*F31 -> 91124.893 | I31: Estimado | J31: Lançado ERP
B32: SERVIÇO | C32: 01.001.002.012 | D32: Projeto de Segurança | E32: vb | F32: 1 | G32: 24827.001 | H32: =G32*F32 -> 24827.001 | I32: Estimado | J32: Lançado ERP
... B40: SERVIÇO | C40: 01.001.002.020 | D40: Projeto de Paisagismo | E40: vb | F40: 1 | G40: 36770.652 | H40: =G40*F40 -> 36770.652 | I40: Estimado | J40: Lançado ERP
B41: SUBETAPA | C41: 01.001.003 | D41: Consultorias | H41: =H42+H43+H44+H45 -> 206589.87
B42: SERVIÇO | C42: 01.001.003.001 | D42: Compatibilização de Projetos BIM | E42: vb | F42: 1 | G42: 144789.87 | H42: =G42*F42 -> 144789.87 | I42: Estimado | J42: Lançado ERP
B43: SERVIÇO | C43: 01.001.003.002 | D43: Tour Virtual | E43: vb | F43: 1 | G43: 11300 | H43: =G43*F43 -> 11300 | I43: Recebido | J43: Lançado ERP
B44: SERVIÇO | C44: 01.001.003.003 | D44: Consultoria técnica de legalização | E44: vb | F44: 1 | G44: 16000 | H44: =G44*F44 -> 16000 | I44: Recebido | J44: Lançado ERP
B45: SERVIÇO | C45: 01.001.003.004 | D45: Orçamento e planejamento | E45: vb | F45: 1 | G45: 34500 | H45: =G45*F45 -> 34500 | I45: Recebido | J45: Lançado ERP
B46: SUBETAPA | C46: 01.001.004 | D46: Ensaios | H46: =H47+H48+H49+H50+H51+H52+H53+H54+H55+H56 -> 600453
B47: SERVIÇO | C47: 01.001.004.001 | D47: Controle tecnológico do concreto | E47: vb | F47: 1 | G47: 238185 | H47: =G47*F47 -> 238185 | I47: Estimado | J47: Lançado ERP
B48: SERVIÇO | C48: 01.001.004.002 | D48: Ensaio de argamassa | E48: vb | F48: 1 | G48: 11200 | H48: =G48*F48 -> 11200 | I48: Estimado | J48: Lançado ERP
B49: SERVIÇO | C49: 01.001.004.003 | D49: Prova de carga | E49: vb | F49: 1 | G49: 5500 | H49: =G49*F49 -> 5500 | I49: Estimado | J49: Lançado ERP
B50: SERVIÇO | C50: 01.001.004.004 | D50: Ensaio de arrancamento de reboco | E50: vb | F50: 1 | G50: 6300 | H50: =G50*F50 -> 6300 | I50: Estimado | J50: Lançado ERP
...

Sheet Ger_Executivo_Cartesian
H4: PROJETO: | I4: Electra Towers | O4: REVISÃO: | P4: DATA
H5: EMPRESA: | I5: Thozen | O5: R00
A6: Unidade Construtiva | B6: Célula Construtiva | C6: Etapa | D6: Subetapa | E6: Serviço | G6: GERENCIAMENTO EXECUTIVO
A7: 0 | B7: 0 | C7: 0 | D7: 0 | E7: 0 | G7: EAP | H7: NIVEL | I7: Item | J7: Descrição | K7: Unidade | L7: Quant. | M7: Preço un | N7: Total | O7: Considerações | P7: Situação
A8: 0 | B8: 1 | C8: 0 | D8: 0 | E8: 0 | H8: CÉLULA CONSTRUTIVA | I8: 01 | J8: MOVIMENTAÇÃO DE TERRA
A9: 0 | B9: 1 | C9: 1 | D9: 0 | E9: 0 | H9: ETAPA | I9: 01.001 | J9: DEMOLIÇÕES, LIMPEZA DE TERRENO E LOCAÇÃO DE OBRA | N9: 26235.314 | O9: 1.5663183
A10: 0 | B10: 1 | C10: 1 | D10: 1 | E10: 0 | H10: SUBETAPA | I10: 01.001.001 | J10: Locação e gabarito de obra | N10: 26235.314 | O10: 1.5663183
A11: 0 | B11: 1 | C11: 1 | D11: 1 | E11: 1 | G11: MOVIMENTAÇÃO DE TERRA | H11: SERVIÇO | I11: 01.001.001.001 | J11: Locação da obra | K11: m2 | N11: 26235.314 | P11: Pendente
A12: 0 | B12: 1 | C12: 2 | D12: 0 | E12: 1 | H12: ETAPA | I12: 01.002 | J12: SERVIÇOS PRELIMINARES
A13: 0 | B13: 1 | C13: 2 | D13: 1 | E13: 0 | H13: SUBETAPA | I13: 01.002.001 | J13: Limpeza Permanente e Remoção entulho
A14: 0 | B14: 1 | C14: 2 | D14: 1 | E14: 1 | G14: MOVIMENTAÇÃO DE TERRA | H14: SERVIÇO | I14: 01.002.001.001 | J14: Limpeza da camada vegetal | K14: m2 | P14: Pendente
A15: 0 | B15: 1 | C15: 2 | D15: 1 | E15: 2 | G15: MOVIMENTAÇÃO DE TERRA | H15: SERVIÇO | I15: 01.002.001.002 | J15: Remoção de entulhos e resíduos | P15: Pendente
A16: 0 | B16: 1 | C16: 2 | D16: 2 | E16: 0 | H16: SUBETAPA | I16: 01.002.002 | J16: Mão de Obra de Canteiro
A17: 0 | B17: 1 | C17: 2 | D17: 2 | E17: 1 | G17: MOVIMENTAÇÃO DE TERRA | H17: SERVIÇO | I17: 01.002.002.001 | J17: Mão de Obra de Canteiro | K17: vb | P17: Pendente
A18: 0 | B18: 1 | C18: 3 | D18: 0 | E18: 1 | H18: ETAPA | I18: 01.003 | J18: SERVIÇOS DE TERRAPLANAGEM | N18: 271126.19 | O18: 16.186957
A19: 0 | B19: 1 | C19: 3 | D19: 1 | E19: 0 | H19: SUBETAPA | I19: 01.003.001 | J19: Mao de obra - movimentações de terra | N19: 271126.19 | O19: 16.186957
A20: 0 | B20: 1 | C20: 3 | D20: 1 | E20: 1 | G20: MOVIMENTAÇÃO DE TERRA | H20: SERVIÇO | I20: 01.003.001.001 | J20: Mão de obra movimentação de terra | K20: vb | N20: 233000 | P20: Pendente
A21: 0 | B21: 1 | C21: 4 | D21: 0 | E21: 2 | H21: ETAPA | I21: 01.004 | J21: SERVIÇO DE DRENAGEM | N21: 80000 | O21: 4.7762135
A22: 0 | B22: 1 | C22: 4 | D22: 1 | E22: 0 | H22: SUBETAPA | I22: 01.004.001 | J22: Drenagem | N22: 80000 | O22: 4.7762135
A23: 0 | B23: 1 | C23: 4 | D23: 1 | E23: 1 | G23: MOVIMENTAÇÃO DE TERRA | H23: SERVIÇO | I23: 01.004.001.001 | J23: Rebaixamento de Lençol freático | K23: vb | N23: 80000 | P23: Pendente
A24: 0 | B24: 2 | C24: 0 | D24: 1 | E24: 1 | H24: CÉLULA CONSTRUTIVA | I24: 02 | J24: CONTENÇÃO | N24: 772006.63 | O24: 46.090856
A25: 0 | B25: 2 | C25: 1 | D25: 0 | E25: 1 | H25: ETAPA | I25: 02.001 | J25: MURETA GUIA | N25: 18739.389 | O25: 1.1187915
A26: 0 | B26: 2 | C26: 1 | D26: 1 | E26: 0 | H26: SUBETAPA | I26: 02.001.001 | J26: Forma | N26: 6673.9436 | O26: 0.39845225
A27: 0 | B27: 2 | C27: 1 | D27: 1 | E27: 1 | G27: CONTENÇÃO | H27: SERVIÇO | I27: 02.001.001.001 | J27: Forma para infraestrutura em Tábuas de Madeira Serrada 2x reaproveitamento | K27: m2 | L27: 111.3136 | M27: 59.956229 | N27: 6673.9436 | P27: Pendente
A28: 0 | B28: 2 | C28: 1 | D28: 2 | E28: 0 | H28: SUBETAPA | I28: 02.001.002 | J28: Armadura | N28: 4318.7306 | O28: 0.25783974
A29: 0 | B29: 2 | C29: 1 | D29: 2 | E29: 1 | G29: CONTENÇÃO | H29: SERVIÇO | I29: 02.001.002.001 | J29: Armação aço CA-50 ø 6,3mm para Contenções (corte e dobra em obra) | K29: un | L29: 670.32 | M29: 6.0795674 | N29: 4075.2556 | P29: Pendente
A30: 0 | B30: 2 | C30: 1 | D30: 2 | E30: 2 | G30: CONTENÇÃO | H30: SERVIÇO | I30: 02.001.002.002 | J30: Armação aço CA-50 ø 12,5mm para Contenções (corte e dobra em obra) | K30: un | L30: 41.6016 | M30: 5.8525391 | N30: 243.47499 | P30: Pendente
A31: 0 | B31: 2 | C31: 1 | D31: 3 | E31: 0 | H31: SUBETAPA | I31: 02.001.003 | J31: Concreto | N31: 7746.7147 | O31: 0.46249954
A32: 0 | B32: 2 | C32: 1 | D32: 3 | E32: 1 | G32: CONTENÇÃO | H32: SERVIÇO | I32: 02.001.003.001 | J32: Concreto Usinado bombeável 50MPa para infraestrutura- incluindo serviço de bombeamento | K32: m3 | L32: 11.390452 | M32: 680.106 | N32: 7746.7147 | P32: Pendente
A33: 0 | B33: 2 | C33: 2 | D33: 0 | E33: 1 | H33: ETAPA | I33: 02.002 | J33: LAMELAS | PAREDE DIAFRAGMA | N33: 331865.23 | O33: 19.81324
A34: 0 | B34: 2 | C34: 2 | D34: 1 | E34: 0 | H34: SUBETAPA | I34: 02.002.001 | J34: Armadura | N34: 155967.97 | O34: 9.3117038
A35: 0 | B35: 2 | C35: 2 | D35: 1 | E35: 1 | G35: CONTENÇÃO | H35: SERVIÇO | I35: 02.002.001.001 | J35: Armação aço CA-50 ø 6,3mm para Contenções (corte e dobra em Indústria) | K35: un | L35: 2282 | M35: 8.964145 | N35: 20456.179 | P35: Pendente
A36: 0 | B36: 2 | C36: 2 | D36: 1 | E36: 2 | G36: CONTENÇÃO | H36: SERVIÇO | I36: 02.002.001.002 | J36: Armação aço CA-50 ø 8,0mm para Contenções (corte e dobra em Indústria) | K36: un | L36: 77 | M36: 8.964145 | N36: 690.23916 | P36: Pendente
A37: 0 | B37: 2 | C37: 2 | D37: 1 | E37: 3 | G37: CONTENÇÃO | H37: SERVIÇO | I37: 02.002.001.003 | J37: Armação aço CA-50 ø 12,5mm para Contenções (corte e dobra em Indústria) | K37: un | L37: 3884 | M37: 8.484145 | N37: 32952.419 | P37: Pendente
A38: 0 | B38: 2 | C38: 2 | D38: 1 | E38: 4 | G38: CONTENÇÃO | H38: SERVIÇO | I38: 02.002.001.004 | J38: Armação aço CA-50 ø 25,0mm para Contenções (corte e dobra em Indústria) | K38: un | L38: 12007 | M38: 8.484145 | N38: 101869.13 | P38: Pendente
A39: 0 | B39: 2 | C39: 2 | D39: 2 | E39: 0 | H39: SUBETAPA | I39: 02.002.002 | J39: Concreto | N39: 175897.26 | O39: 10.501536
