Workbook
Name \0: #REF!
Name \0: #REF!
Name \0: #REF!
Name \0: #REF!
Name \0: #REF!
Name \0: #REF!
Name \0: #REF!
Name \0: #REF!
Name \1: #REF!
Name \1: #REF!
Name \a: #REF!
Name \a: #REF!
Name \a: #REF!
Name \a: #REF!
Name \a: #REF!
Name \a: #REF!
Name \a: #REF!
Name \a: #REF!
Name \k: #REF!
Name \m: #REF!
Name \m: #REF!
Name \m: #REF!
Name \m: #REF!
Name \m: #REF!
Name \m: #REF!
Name \m: #REF!
Name \m: #REF!
Name \z: #REF!
Name _1: #REF!
Name _2: #REF!
Name aa: #REF!
Name aa: #REF!
Name aa: #REF!
Name aa: #REF!
Name aa: #REF!
Name aa: #REF!
Name aa: #REF!
Name aaaa: '[2]M.O.'!#REF!
Name aaaa: '[2]M.O.'!#REF!
Name aaaa: '[2]M.O.'!#REF!
Name aaaa: '[2]M.O.'!#REF!
Name AB: #REF!
Name AB: #REF!
Name ALUMÍNIO_2: #REF!
Name ALUMÍNIO_2: #REF!
Name angelo: [3]Geral!#REF!
Name angelo: [3]Geral!#REF!
Name angelo: [3]Geral!#REF!
Name angelo: [3]Geral!#REF!
Name angelo: [3]Geral!#REF!
Name angelo: [3]Geral!#REF!
Name angelo: [3]Geral!#REF!
Name area: #REF!
Name area: #REF!
Name area: #REF!
Name Área_Construída: #REF!
Name Área_Construída: #REF!
Name Área_Construída: #REF!
Name Área_impressão_IM: #REF!
Name Área_Privativa: #REF!

Sheet Obra
C1: Projeto | D1: =Ger_Executivo!C4 -> Playa Negra
C2: Empresa | D2: =Ger_Executivo!C5 -> GDI
C3: Revisão | D3: R00 - Patricia Bragato
A4: QUADRO DE ÁREAS
B6: Descrição | C6: Unidade | E6: Quantidade
B7: MESES DE OBRA | C7: MÊS | E7: 30
B8: ÁREA DO TERRENO | C8: M2 | E8: 1440.91
B9: ÁREA CONSTRUÍDA | C9: M2 | E9: =SUM(E10:E18) -> 8518.6
B10: SUBSOLO 2 | C10: M2 | E10: 1143.68
B11: SUBSOLO 1 | C11: M2 | E11: 1143.68
B12: TERREO | C12: M2 | E12: 1056.79
B13: SOBRELOJA | C13: M2 | E13: 174.32
B14: 2º PAVIMENTO | C14: M2 | E14: 612.42
B15: TIPO (X6) | C15: M2 | E15: =612.42*6 -> 3674.52
B16: ÁTICO | C16: M2 | E16: 633.25
B17: BARRILETE | C17: M2 | E17: 39.97
B18: RESERVATÓRIO | C18: M2 | E18: 39.97
B19: NÚMERO DE UNIDADES HABITACIONAIS | C19: UN | E19: 69
B20: ÁREA PRIVATIVA | C20: M2 | E20: =79.19+690.9+661.85+329.91+283.78+308.98+303.66+303.66+296.94+267.05+284.06 -> 3809.98
B21: ÁREA COMERCIAL | C21: M2 | E21: =166.88+149.33 -> 316.21
B22: NÚMERO DE PAVIMENTOS | C22: UN | E22: 12
B24: ETAPA | C24: VALOR ORÇADO | D24: % | E24: VALOR / m²
B25: GERENCIAMENTO TÉCNICO E ADMINISTRATIVO | C25: ='Ger_Tec e Adm'!H228 -> 12288227 | D25: =C25/C$46 -> 0.33187185 | E25: =C25/$E$9 -> 1442.5172
B26: MOVIMENTAÇÃO DE TERRA | C26: =Ger_Executivo!H33 -> 748566.23 | D26: =C26/C$46 -> 0.020216753 | E26: =C26/$E$9 -> 87.874325
B27: CONTENÇÃO | C27: =Ger_Executivo!H42 -> 785740.88 | D27: =C27/C$46 -> 0.02122074 | E27: =C27/$E$9 -> 92.238264
B28: INFRAESTRUTURA | C28: =Ger_Executivo!H69 -> 425508.35 | D28: =C28/C$46 -> 0.011491832 | E28: =C28/$E$9 -> 49.950502
B29: SUPRAESTRUTURA | C29: =Ger_Executivo!H83 -> 5968880.7 | D29: =C29/C$46 -> 0.16120335 | E29: =C29/$E$9 -> 700.68798
B30: ALVENARIA | C30: =Ger_Executivo!H286 -> 1143407.1 | D30: =C30/C$46 -> 0.030880339 | E30: =C30/$E$9 -> 134.22477
B31: INSTALAÇÕES ELÉTRICAS, HIDRÁULICAS, GLP E PREVENTIVAS | C31: =Ger_Executivo!H410+Ger_Executivo!H533+Ger_Executivo!H543+Ger_Executivo!H632 -> 2834254.8 | D31: =C31/C$46 -> 0.07654557 | E31: =C31/$E$9 -> 332.71368
B32: REVESTIMENTOS ARGAMASSADOS | C32: =Ger_Executivo!H670 -> 1844309.9 | D32: =C32/C$46 -> 0.049809833 | E32: =C32/$E$9 -> 216.50388
B33: IMPERMEABILIZAÇÃO E TRATAMENTOS | C33: =Ger_Executivo!H817 -> 855401.26 | D33: =C33/C$46 -> 0.023102079 | E33: =C33/$E$9 -> 100.41571
B34: ACABAMENTOS INETRNOS EM PAREDE | C34: =Ger_Executivo!H853 -> 834243.15 | D34: =C34/C$46 -> 0.022530655 | E34: =C34/$E$9 -> 97.931955
B35: ACABAMENTOS EM PISOS E PAVIMENTAÇÕES | C35: =Ger_Executivo!H917 -> 1691413.4 | D35: =C35/C$46 -> 0.045680509 | E35: =C35/$E$9 -> 198.55532
B36: ACABAMENTOS INTERNOS EM TETO | C36: =Ger_Executivo!H1040 -> 490056.09 | D36: =C36/C$46 -> 0.013235092 | E36: =C36/$E$9 -> 57.527773
B37: PINTURA INTERNA | C37: =Ger_Executivo!H1084 -> 997118.86 | D37: =C37/C$46 -> 0.026929489 | E37: =C37/$E$9 -> 117.05196
B38: REVESTIMENTOS E ACABAMENTOS DE FACHADA | C38: =Ger_Executivo!H1223 -> 1415697.1 | D38: =C38/C$46 -> 0.038234156 | E38: =C38/$E$9 -> 166.18893
B39: ESQUADRIAS, VIDROS E FERRAGENS | C39: =Ger_Executivo!H1320 -> 2272243 | D39: =C39/C$46 -> 0.061367148 | E39: =C39/$E$9 -> 266.73901
B40: LOUÇAS E METAIS | C40: =Ger_Executivo!H1356 -> 283803.98 | D40: =C40/C$46 -> 0.0076647793 | E40: =C40/$E$9 -> 33.3158
B41: CLIMATIZAÇÃO, EQUIPAMENTOS E SISTEMAS ESPECIAIS | C41: =Ger_Executivo!H658+Ger_Executivo!H1366 -> 847698.1 | D41: =C41/C$46 -> 0.022894037 | E41: =C41/$E$9 -> 99.511434
B42: COBERTURA | C42: =Ger_Executivo!H1375 -> 56125.701 | D42: =C42/C$46 -> 0.0015158037 | E42: =C42/$E$9 -> 6.5886062
...

Sheet Canteiro
C1: Projeto | D1: =Ger_Executivo!C4 -> Playa Negra
C2: Empresa | D2: =Ger_Executivo!C5 -> GDI
C3: Revisão | D3: R00 - Patricia Bragato
A4: INSTALAÇÕES DE CANTEIRO
A5: Instalações de canteiro
B7: Descrição | C7: Unidade | D7: Quantidade
B8: Produtividade média | C8: m2 / mês | D8: =Obra!E9/Obra!E7 -> 283.95333
B9: Pm | C9: h/m2 | D9: 48
B10: Numero de funcionários | C10: un | D10: 98
B11: Equipe administrativa | C11: un | D11: 4
B12: Ferramentas | C12: R$ | D12: =800*D10 -> 78400 | E12: 800,00/func.
B13: EPI | C13: R$ | D13: =500*(D10+D11) -> 51000 | E13: 500,00/func.
B14: Banheiro | C14: un | D14: =ROUNDUP(($D$10+D11)/20,0) -> 6 | E14: 1/20 func

Sheet EPC's
C1: Projeto | D1: =Ger_Executivo!C4 -> Playa Negra
C2: Empresa | D2: =Ger_Executivo!C5 -> GDI
C3: Revisão | D3: R00 - Patricia Bragato
A4: EQUIPAMENTOS DE PROTEÇÃO COLETIVA
A6: Bandejas de proteção
B8: Descrição | C8: Unidade | D8: Quantidade
B9: Perímetro de projeção torre | C9: m | D9: 104.43
B10: Bandeja de proteção primária | C10: m | D10: =D9 -> 104.43
B11: Bandeja de proteção secundária | C11: m | D11: =D9 -> 104.43
A13: Guarda - corpo de desforma
B15: Descrição | C15: Unidade | D15: Quantidade
B16: Perímetro de projeção da torre | C16: m | D16: =D9 -> 104.43
B17: Repetições de pavimentos** | C17: un | D17: 4
B18: Proteção de periferia pós desforma torre | C18: m | D18: =(D16*D17) -> 417.72
A20: Tela fachadeira
B22: Descrição | C22: Unidade | D22: Quantidade
B23: Perímetro de projeção da torre | C23: m | D23: =D9 -> 104.43
B24: Altura de cobrimento da tela | C24: m | D24: =27.36-5.94 -> 21.42
B25: Tela fachadeira | C25: m2 | D25: =D23*D24 -> 2236.8906 | E25: =D23/D25 -> 0.046685341
A27: Fechamento removível de vãos em madeira
B29: Descrição | C29: Unidade | D29: Quantidade
B30: Área das portas de elevadores | C30: m2 | D30: =1*2.4 -> 2.4
B31: Quantidade de elevadores | C31: un | D31: 2
B32: Quantidade de portas de elevadores | C32: un | D32: =D30*D31*Obra!E22 -> 57.6
B33: Fechamento removível de vãos em madeira | C33: m2 | D33: =D30*D32 -> 138.24
A35: Guarda - corpo de vãos
B37: Descrição | C37: Unidade | D37: Quantidade
B38: Perímetro de vãos | C38: m | D38: =Corrimão!E20 -> 909.25818
B39: Guarda - corpo de vãos | C39: m | D39: =D38 -> 909.25818
A41: Tapume
B43: Descrição | C43: Unidade | D43: Quantidade
B44: Perímetro de encontro com pavimentação | C44: m | D44: =31.07+26.65 -> 57.72
B45: Altura do tapume | C45: m | D45: 2.4
B46: Área de tapume | C46: m2 | D46: =D45*D44 -> 138.528
A48: Linha de vida
B50: Descrição | C50: Unidade | D50: Quantidade
B51: Perímetro de projeção da torre | C51: m | D51: =D9 -> 104.43
B52: Linha de vida | C52: m | D52: =D51 -> 104.43
A54: SQLA Leve
B56: Descrição | C56: Unidade | D56: Quantidade
...

Sheet Controle Tecnologico
E5: COND.01
A6: Item | B6: Descrição/Especificação | C6: Unid. | D6: V. Unit. (R$) | E6: Qtde. | F6: V. Total (R$) | G6: Observações
B7: CONTROLE TECNOLÓGICO - CONCRETO
A8: 1 | B8: Laudo e ART | C8: vb | D8: 1450 | E8: 1 | F8: =$D8*E8 -> 1450
A9: =A8+1 -> 2 | B9: Controle Tecnologico - Coleta materiais da obra | C9: unid. | D9: 20 | E9: =ROUNDUP(Estrutura!M98/8,0)*4 -> 1068 | F9: =$D9*E9 -> 21360 | G9: 4 CPs por caminhão betoneira de 8m³
A10: =A9+1 -> 3 | B10: Controle Tecnológico - Ensaio de concreto endurecido/grouth - compressão simples / Detalhe: Concreto | C10: cps | D10: 12.5 | E10: =E9 -> 1068 | F10: =$D10*E10 -> 13350 | G10: 4 CPs por caminhão betoneira de 8m³
A11: =A10+1 -> 4 | B11: Determinação do módulo de deformação tangente inicial (Eci) (módulo de elasticidade), Incluindo Avaliação Estática dos Resultados (NBR 8522 e NBR 12655) | C11: ensaio | D11: 480 | E11: 2 | F11: =$D11*E11 -> 960 | G11: A cada 5 pav. (e quando houver troca de fornecedor)
C12: SUBTOTAL: | F12: =SUM(F8:F11) -> 37120
C14: VALOR/M3 | F14: =F12/Estrutura!M98 -> 17.413169

Sheet Ger_Tec e Adm
B4: PROJETO: | C4: Playa Negra | I4: REVISÃO: | J4: DATA
B5: EMPRESA: | C5: GDI | I5: R00 - Patricia Bragato | J5: 45519
B6: GERENCIAMENTO TÉCNICO E ADMINISTRATIVO
B7: Atalho | C7: Item | D7: Descrição | E7: Unidade | F7: Quant. | G7: Preço un | H7: Total | I7: Considerações | J7: Situação
C8: 01 | D8: TERRENOS E SERVIÇOS TÉCNICOS | H8: =H9+H21+H59+H63+H75+H84+H87+H101 -> 10192608
C9: 01.001 | D9: TERRENO | H9: =H10+H17 -> 4048500 | J9: -
C10: 01.001.001 | D10: AQUISIÇÃO DO TERRENO | H10: =SUM(H11:H16) -> 3988000
C11: 01.001.001.001 | D11: Analise Jurídica da Documentação do Terreno | E11: vb | F11: 1 | G11: 16000 | H11: =F11*G11 -> 16000 | I11: Mantido conforme lançamento inicial pela GDI - SUGERIDO REAPROPRIAÇÃO | J11: N/A
C12: 01.001.001.002 | D12: TERRENO 3 - Jordan Martins e João Martins | E12: vb | F12: 1 | G12: 3300000 | H12: =F12*G12 -> 3300000 | I12: Mantido conforme lançamento inicial pela GDI - SUGERIDO REAPROPRIAÇÃO | J12: N/A
C13: 01.001.001.003 | D13: TERRENO 3 - Torna financeira - Jordan Martins e João Martins | E13: vb | F13: 1 | G13: 565000 | H13: =F13*G13 -> 565000 | I13: Mantido conforme lançamento inicial pela GDI - SUGERIDO REAPROPRIAÇÃO | J13: N/A
C14: 01.001.001.004 | D14: TERRENO 2 - Margarete Valli e Francisco Valli (permuta) | E14: vb | F14: 1 | G14: 2500 | H14: =F14*G14 -> 2500 | I14: Mantido conforme lançamento inicial pela GDI - SUGERIDO REAPROPRIAÇÃO | J14: N/A
C15: 01.001.001.005 | D15: TERRENO 2 - Margarete Valli e Francisco Valli (torna financeira) | E15: vb | F15: 1 | G15: 22000 | H15: =F15*G15 -> 22000 | I15: Mantido conforme lançamento inicial pela GDI - SUGERIDO REAPROPRIAÇÃO | J15: N/A
C16: 01.001.001.006 | D16: Corretagem Imobiliária pela intermeadiação do Terreno | E16: vb | F16: 1 | G16: 82500 | H16: =F16*G16 -> 82500 | I16: Mantido conforme lançamento inicial pela GDI - SUGERIDO REAPROPRIAÇÃO | J16: N/A
C17: 01.001.002 | D17: TRANSFERÊNCIA DE PROPRIEDADE DOS TERRENOS | H17: =SUM(H18:H20) -> 60500
C18: 01.001.002.001 | D18: ITBI / FRJ - Terreno 1 | E18: vb | F18: 1 | G18: 55500 | H18: =F18*G18 -> 55500 | I18: Mantido conforme lançamento inicial pela GDI - SUGERIDO REAPROPRIAÇÃO | J18: N/A
C19: 01.001.002.002 | D19: ITBI / FRJ - Terreno 2 | E19: vb | F19: 1 | G19: 3000 | H19: =F19*G19 -> 3000 | I19: Mantido conforme lançamento inicial pela GDI - SUGERIDO REAPROPRIAÇÃO | J19: N/A
C20: 01.001.002.003 | D20: Escritura - Terreno 1 | E20: vb | F20: 1 | G20: 2000 | H20: =F20*G20 -> 2000 | I20: Mantido conforme lançamento inicial pela GDI - SUGERIDO REAPROPRIAÇÃO | J20: N/A
C21: 01.002 | D21: PROJETOS E SERVICOS TECNICOS | H21: =H22+H30+H43 -> 1277956.6 | J21: -
C22: 01.002.001 | D22: LEVANTAMENTOS E ESTUDOS TÉCNICOS | H22: =SUM(H23:H29) -> 86622.901
C23: 01.002.001.001 | D23: Levantamento Topográfico | E23: m2 | F23: 8790.63 | G23: 1.97 | H23: =F23*G23 -> 17317.541 | I23: Mantido conforme lançamento inicial pela GDI | J23: Lançado ERP
C24: 01.002.001.002 | D24: Sondagem SPT | E24: m | F24: 200 | G24: 40 | H24: =F24*G24 -> 8000 | I24: Mantido conforme lançamento inicial pela GDI | J24: Lançado ERP
C25: 01.002.001.003 | D25: Imagens Aéreas - Drone | E25: vb | F25: 2 | G25: 600 | H25: =F25*G25 -> 1200 | I25: Mantido conforme lançamento inicial pela GDI | J25: Lançado ERP
C26: 01.002.001.004 | D26: Estudos de Impacto de Vizinhança | E26: m2 | F26: 8790 | G26: 3.95 | H26: =F26*G26 -> 34720.5 | I26: Mantido conforme lançamento inicial pela GDI | J26: Lançado ERP
C27: 01.002.001.005 | D27: Estudo de impactos ambientais | E27: m2 | F27: 1 | G27: 3.6 | H27: =F27*G27 -> 3.6 | I27: Mantido conforme lançamento inicial pela GDI | J27: Lançado ERP
C28: 01.002.001.006 | D28: Inventário Florestal | E28: vb | F28: 1 | G28: 7800 | H28: =F28*G28 -> 7800 | I28: Mantido conforme lançamento inicial pela GDI | J28: Lançado ERP
C29: 01.002.001.007 | D29: Sondagem Geofísica | E29: vb | F29: 8790.63 | G29: 2 | H29: =F29*G29 -> 17581.26 | I29: Mantido conforme lançamento inicial pela GDI | J29: Lançado ERP
C30: 01.002.002 | D30: PROJETO ARQUITETÔNICO E GERAÇÃO DE IMAGENS | H30: =SUM(H31:H42) -> 600480.37 | J30: -
C31: 01.002.002.001 | D31: Projeto Arquitetônico - Projeto Legal (4.573,24m²) | E31: m2 | F31: 8790.63 | G31: 40 | H31: =G31*F31 -> 351625.2 | I31: Mantido conforme lançamento inicial pela GDI | J31: Lançado ERP
C32: 01.002.002.002 | D32: Projeto Arquitetônico de Interiores - Áreas Comuns | E32: m2 | F32: 8790.63 | G32: 10 | H32: =F32*G32 -> 87906.3 | I32: Mantido conforme lançamento inicial pela GDI | J32: Lançado ERP
C33: 01.002.002.003 | D33: Projeto Arquitetônico de Interiores - Áreas Privativas | E33: m2 | F33: 0 | G33: 10 | H33: =F33*G33 -> 0 | I33: Mantido conforme lançamento inicial pela GDI | J33: Lançado ERP
C34: 01.002.002.004 | D34: Projeto Arquitetônico Áreas Externas/Paisagismo | E34: m2 | F34: 7 | G34: 12.175 | H34: =F34*G34 -> 85.225 | I34: Mantido conforme lançamento inicial pela GDI | J34: Lançado ERP
C35: 01.002.002.005 | D35: Cena extra - Bona Studio | E35: vb | F35: 1 | G35: 5000 | H35: =F35*G35 -> 5000 | I35: Mantido conforme lançamento inicial pela GDI | J35: Lançado ERP
C36: 01.002.002.006 | D36: Fotografia e cinematografia - R2 Imagens | E36: m2 | F36: 8790.63 | G36: 3.98 | H36: =F36*G36 -> 34986.707 | I36: Mantido conforme lançamento inicial pela GDI | J36: Lançado ERP
C37: 01.002.002.007 | D37: Adequação do Projeto Arquitetônico das fachadas e área de lazer | E37: m2 | F37: 8790.63 | G37: 3.95 | H37: =F37*G37 -> 34722.988 | I37: Mantido conforme lançamento inicial pela GDI | J37: Lançado ERP
C38: 01.002.002.008 | D38: Desenvolvimento de Imagens - Interiores e Paisagismo | E38: m2 | F38: 8790.63 | G38: 3.6 | H38: =F38*G38 -> 31646.268 | I38: Mantido conforme lançamento inicial pela GDI | J38: Lançado ERP
C39: 01.002.002.009 | D39: Serviços de arquitetura - Contrato Espaço Livre | E39: m2 | F39: 3939.28 | G39: 7.39 | H39: =F39*G39 -> 29111.279 | I39: Mantido conforme lançamento inicial pela GDI | J39: Lançado ERP
C40: 01.002.002.010 | D40: Impressão de Imagens e Plotagem de Projetos | E40: m2 | F40: 3939.28 | G40: 5 | H40: =F40*G40 -> 19696.4 | I40: Mantido conforme lançamento inicial pela GDI | J40: Lançado ERP
C41: 01.002.002.011 | D41: Evento de Apresentação do Projeto | E41: vb | F41: 1 | G41: 700 | H41: =F41*G41 -> 700 | I41: Mantido conforme lançamento inicial pela GDI | J41: Lançado ERP
C42: 01.002.002.012 | D42: Adequação do Projeto Arquitetônico das Fachadas | E42: m2 | F42: 1000 | G42: 5 | H42: =F42*G42 -> 5000 | I42: Mantido conforme lançamento inicial pela GDI | J42: Lançado ERP
C43: 01.002.003 | D43: PROJETOS COMPLEMENTARES DE ENGENHARIA | H43: =SUM(H44:H58) -> 590853.31
...

Sheet Ger_Executivo
B4: PROJETO: | C4: Playa Negra | I4: REVISÃO: | J4: DATA
B5: EMPRESA: | C5: GDI | I5: R00 - Patricia Bragato | J5: 45519
B6: GERENCIAMENTO EXECUTIVO
B7: Atalho | C7: Item | D7: Descrição | E7: Unidade | F7: Quant. | G7: Preço un | H7: Total | I7: Considerações | J7: Situação
C8: 01 | D8: EMPREITADA GLOBAL | H8: =H9 -> 9356622.6
C9: 01.001 | D9: EMPREITADA GLOBAL | H9: =H10 -> 9356622.6 | J9: -
C10: 01.002 | D10: EMPREITADA GLOBAL | H10: =H11 -> 9356622.6
C11: 01.002.000.001 | D11: Empreitada global | E11: vb | F11: 1 | G11: 9356622.6 | H11: =F11*G11 -> 9356622.6 | J11: Lançado ERP
C12: 02 | D12: SERVICOS PRELIMINARES | H12: =H13 -> 918379.52
C13: 02.001 | D13: SERVICOS PRELIMINARES | H13: =H14+H16+H28 -> 918379.52 | J13: -
C14: 02.001.001 | D14: SUPRESSAO VEGETAL | H14: =H15 -> 6000
C15: 02.001.001.001 | D15: Corte de Arvores conforme licenciamento ambiental | E15: vb | F15: 1 | G15: 6000 | H15: =F15*G15 -> 6000 | I15: Mantido conforme lançamento inicial pela GDI - SUGERIDO REAPROPRIAÇÃO | J15: Lançado ERP
C16: 02.001.002 | D16: IMPLANTACAO DO CANTEIRO DE OBRAS - FASE 1 - ESCAVACAO | H16: =SUM(H17:H27) -> 642473.95
C17: 02.001.002.001 | D17: Fornecimento de internet | E17: un | F17: 1 | G17: 5000 | H17: =F17*G17 -> 5000 | I17: Mantido conforme lançamento inicial pela GDI - SUGERIDO REAPROPRIAÇÃO | J17: Lançado ERP
C18: 02.001.002.002 | D18: Mão de Obra - Implantação do canteiros de Obras | E18: un | F18: 1 | G18: 449117.89 | H18: =F18*G18 -> 449117.89 | I18: Mantido conforme lançamento inicial pela GDI - SUGERIDO REAPROPRIAÇÃO | J18: Lançado ERP
C19: 02.001.002.003 | D19: Organização canteiro de obras | E19: vb | F19: 1 | G19: 15000 | H19: =F19*G19 -> 15000 | I19: Mantido conforme lançamento inicial pela GDI - SUGERIDO REAPROPRIAÇÃO | J19: Lançado ERP
C20: 02.001.002.004 | D20: Implantação do canteiro de obras | E20: un | F20: 1 | G20: 60000 | H20: =F20*G20 -> 60000 | I20: Mantido conforme lançamento inicial pela GDI - SUGERIDO REAPROPRIAÇÃO | J20: Lançado ERP
C21: 02.001.002.005 | D21: Container | E21: un | F21: 2 | G21: 24000 | H21: =F21*G21 -> 48000 | I21: Mantido conforme lançamento inicial pela GDI - SUGERIDO REAPROPRIAÇÃO | J21: Lançado ERP
C22: 02.001.002.006 | D22: Locação de sanitários químicos | E22: un | F22: 10 | G22: 4306.45 | H22: =F22*G22 -> 43064.5 | I22: Mantido conforme lançamento inicial pela GDI - SUGERIDO REAPROPRIAÇÃO | J22: Lançado ERP
C23: 02.001.002.007 | D23: Ligacao de Energia para o Canteiro de Obras | E23: vb | F23: 1 | G23: 0 | H23: =F23*G23 -> 0 | I23: Mantido conforme lançamento inicial pela GDI - SUGERIDO REAPROPRIAÇÃO | J23: Lançado ERP
C24: 02.001.002.008 | D24: Ligação de Água para o Canteiro de Obras | E24: vb | F24: 1 | G24: 0 | H24: =F24*G24 -> 0 | I24: Mantido conforme lançamento inicial pela GDI - SUGERIDO REAPROPRIAÇÃO | J24: Lançado ERP
C25: 02.001.002.009 | D25: Banheiros | E25: vb | F25: 1 | G25: 0 | H25: =F25*G25 -> 0 | I25: Mantido conforme lançamento inicial pela GDI - SUGERIDO REAPROPRIAÇÃO | J25: Lançado ERP
C26: 02.001.002.010 | D26: Refeitorio | E26: vb | F26: 1 | G26: 0 | H26: =F26*G26 -> 0 | I26: Mantido conforme lançamento inicial pela GDI - SUGERIDO REAPROPRIAÇÃO | J26: Lançado ERP
C27: 02.001.002.011 | D27: Instalações de Segurança para Canteiros de Obras | E27: un | F27: 36 | G27: 619.21 | H27: =F27*G27 -> 22291.56 | I27: Mantido conforme lançamento inicial pela GDI - SUGERIDO REAPROPRIAÇÃO | J27: Lançado ERP
C28: 02.001.003 | D28: SEGURANÇA DO TRABALHO | H28: =SUM(H29:H32) -> 269905.57
C29: 02.001.003.001 | D29: Acompanhamento Técnico em Segurança no Trabalho | E29: mes | F29: 30 | G29: 1200 | H29: =F29*G29 -> 36000 | I29: Mantido conforme lançamento inicial pela GDI - SUGERIDO REAPROPRIAÇÃO | J29: Lançado ERP
C30: 02.001.003.002 | D30: Mão de obra - itens de segurança | E30: vb | F30: 1 | G30: 46783.11 | H30: =F30*G30 -> 46783.11 | J30: Lançado ERP
C31: 02.001.003.003 | D31: Mão de obra - instalações provisórias | E31: vb | F31: 1 | G31: 93566.23 | H31: =F31*G31 -> 93566.23 | J31: Lançado ERP
C32: 02.001.003.004 | D32: Mão de obra - guarda corpo e proteções | E32: vb | F32: 1 | G32: 93556.23 | H32: =F32*G32 -> 93556.23 | J32: Lançado ERP
C33: 03 | D33: MOVIMENTAÇÃO DE TERRA | H33: =H34 -> 748566.23 | I33: Mantido conforme lançamento inicial pela GDI
C34: 03.001 | D34: MOVIMENTAÇÃO DE TERRA | H34: =H35+H37+H39 -> 748566.23 | J34: -
C35: 03.001.001 | D35: ESCAVAÇÃO | H35: =H36 -> 605000
C36: 03.001.001.001 | D36: Escavação dos Subsolos e Remoção do Solo | E36: un | F36: 1 | G36: 605000 | H36: =F36*G36 -> 605000 | J36: Lançado ERP
C37: 03.001.002 | D37: RETIRADA DE ENTULHO E LIMPEZA DA OBRA | H37: =H38 -> 50000
C38: 03.001.002.001 | D38: Caçamba para remoção de entulho | E38: un | F38: 1 | G38: 50000 | H38: =F38*G38 -> 50000 | J38: Lançado ERP
C39: 03.001.003 | D39: MÃO DE OBRA | H39: =SUM(H40:H41) -> 93566.226
C40: 03.001.003.001 | D40: Mão de obra - movimentação de terra | E40: vb | F40: 1 | G40: ='MÃO DE OBRA '!E25 -> 46783.113 | H40: =F40*G40 -> 46783.113 | J40: Lançado ERP
C41: 03.001.003.002 | D41: Mão de obra - locação | E41: vb | F41: 1 | G41: ='MÃO DE OBRA '!E27 -> 46783.113 | H41: =F41*G41 -> 46783.113 | J41: Lançado ERP
C42: 04 | D42: CONTENÇÕES | H42: =H43+H49 -> 785740.88 | I42: Mantido conforme lançamento inicial pela GDI
C43: 04.001 | D43: PAREDE CORTINA | H43: =H44 -> 275000 | J43: -
...

Sheet ORÇ MAO DE OBRA
B4: PROJETO: | C4: Playa Negra | I4: REVISÃO: | J4: DATA
B5: EMPRESA: | C5: GDI | I5: R00 - Patricia Bragato | J5: 45519
B6: Atalho | C6: Item | D6: Descrição | E6: Unidade | F6: Quant. | G6: Preço un | H6: Total | I6: Considerações | J6: Situação
B7: GERENCIAMENTO TECNICO E ADMINISTRATIVO
C8: 02 | D8: SERVIÇOS INICIAIS | H8: =H9 -> 449117.89
C9: 02.002 | D9: ADMINISTRAÇÃO E CANTEIRO DE OBRA | H9: =H10 -> 449117.89 | J9: -
C10: 02.002.004 | D10: Instalações provisórias | H10: =H11 -> 449117.89
C11: 02.002.004.007 | D11: Mão de Obra - Implantação do canteiros de Obras | E11: un | F11: 1 | G11: 449117.89 | H11: =F11*G11 -> 449117.89 | I11: Mantido conforme lançamento inicial pela GDI, ajuste de unidade e alocação na estrutura | J11: Lançado ERP
B12: GERENCIAMENTO EXECUTIVO
C13: 03 | D13: MOVIMENTAÇÃO DE TERRA | H13: =H14 -> 93566.226 | I13: Mantido conforme lançamento inicial pela GDI
C14: 03.001 | D14: MOVIMENTAÇÃO DE TERRA | H14: =H15 -> 93566.226 | J14: -
C15: 03.001.003 | D15: MÃO DE OBRA | H15: =SUM(H16:H17) -> 93566.226
C16: 03.001.003.001 | D16: Mão de obra - movimentação de terra | E16: vb | F16: 1 | G16: ='MÃO DE OBRA '!E25 -> 46783.113 | H16: =F16*G16 -> 46783.113 | J16: Lançado ERP
C17: 03.001.003.002 | D17: Mão de obra - locação | E17: vb | F17: 1 | G17: ='MÃO DE OBRA '!E27 -> 46783.113 | H17: =F17*G17 -> 46783.113 | J17: Lançado ERP
C18: 05 | D18: INFRAESTRUTURA | H18: =H19 -> 189918.48 | K18: =H21+H23 -> 2769560.3
C19: 05.001 | D19: INFRAESTRUTURA | H19: =H20 -> 189918.48
C20: 05.002.004 | D20: MÃO DE OBRA | H20: =SUM(H21:H22) -> 189918.48
C21: 05.002.004.001 | D21: Mão de obra - execução de infraestrutura | E21: vb | F21: 1 | G21: 181518.48 | H21: =F21*G21 -> 181518.48 | I21: Ajuste realizado conforme alinhamento da reunião do dia 18/12/2024. | J21: Lançado ERP
C22: 05.002.004.002 | D22: Acompanhamento topográfico para locação | E22: dia | F22: 6 | G22: 1400 | H22: =F22*G22 -> 8400 | J22: Lançado ERP
C23: 06 | D23: SUPRAESTRUTURA | H23: =H24+H27+H30+H33+H36+H39+H42+H45 -> 2588041.8
C24: 06.001 | D24: SUPRAESTRUTURA - SUBSOLO 2 | H24: =H25 -> 112279.47
C25: 06.001.005 | D25: MÃO DE OBRA | H25: =H26 -> 112279.47
C26: 06.001.005.001 | D26: Mão de obra - execução de supraestrutura | E26: vb | F26: 1 | G26: 112279.47 | H26: =F26*G26 -> 112279.47 | I26: Ajuste realizado conforme alinhamento da reunião do dia 18/12/2024. | J26: Lançado ERP
C27: 06.002 | D27: SUPRAESTRUTURA - SUBSOLO 1 | H27: =H28 -> 318125.17
C28: 06.002.005 | D28: MÃO DE OBRA | H28: =H29 -> 318125.17
C29: 06.002.005.001 | D29: Mão de obra - execução de supraestrutura | E29: vb | F29: 1 | G29: 318125.17 | H29: =F29*G29 -> 318125.17 | I29: Ajuste realizado conforme alinhamento da reunião do dia 18/12/2024. | J29: Lançado ERP
C30: 06.003 | D30: SUPRAESTRUTURA - TÉRREO | H30: =H31 -> 435082.95
C31: 06.003.005 | D31: MÃO DE OBRA | H31: =H32 -> 435082.95
C32: 06.003.005.001 | D32: Mão de obra - execução de supraestrutura | E32: vb | F32: 1 | G32: 435082.95 | H32: =F32*G32 -> 435082.95 | I32: Ajuste realizado conforme alinhamento da reunião do dia 18/12/2024. | J32: Lançado ERP
C33: 06.004 | D33: SUPRAESTRUTURA - SOBRELOJA | H33: =H34 -> 56139.74
C34: 06.004.005 | D34: MÃO DE OBRA | H34: =H35 -> 56139.74
C35: 06.004.005.001 | D35: Mão de obra - execução de supraestrutura | E35: vb | F35: 1 | G35: 56139.74 | H35: =F35*G35 -> 56139.74 | I35: Ajuste realizado conforme alinhamento da reunião do dia 18/12/2024. | J35: Lançado ERP
C36: 06.005 | D36: SUPRAESTRUTURA - TIPO 1 | H36: =H37 -> 182454.14
C37: 06.005.005 | D37: MÃO DE OBRA | H37: =H38 -> 182454.14
C38: 06.005.005.001 | D38: Mão de obra - execução de supraestrutura | E38: vb | F38: 1 | G38: 182454.14 | H38: =F38*G38 -> 182454.14 | I38: Ajuste realizado conforme alinhamento da reunião do dia 18/12/2024. | J38: Lançado ERP
C39: 06.006 | D39: SUPRAESTRUTURA - TIPO 2 (x6) | H39: =H40 -> 1094724.9
C40: 06.006.005 | D40: MÃO DE OBRA | H40: =H41 -> 1094724.9
C41: 06.006.005.001 | D41: Mão de obra - execução de supraestrutura | E41: vb | F41: 1 | G41: 1094724.9 | H41: =F41*G41 -> 1094724.9 | I41: Ajuste realizado conforme alinhamento da reunião do dia 18/12/2024. | J41: Lançado ERP
C42: 06.007 | D42: SUPRAESTRUTURA - ÁTICO | H42: =H43 -> 182454.14
C43: 06.007.005 | D43: MÃO DE OBRA | H43: =H44 -> 182454.14
...

Sheet MÃO DE OBRA 
A1: Obra | B1: Playa Negra
A2: Empresa | B2: GDI
A3: Revisão | B3: R00
A4: Data | B4: 45499
A5: Arquivo de origem
A6: DISTRIBUIÇÃO DE VERBAS
A8: MÃO DE OBRA
A10: Indiretos
C12: Etapa | D12: Porcentagem (%) | E12: Total
B13: Instalações provisórias | C13: Mão de Obra - Implantação do canteiros de Obras
B14: =B13 -> Instalações provisórias | C14: Garda corpo e proteções | D14: 0.01 | E14: =D14*$K$20 -> 93566.226
B15: =B14 -> Instalações provisórias | C15: instalações e ligações provisórias (barracos/banheiros/estações de trabalho/tapume/sinalizações/etc) | D15: 0.01 | E15: =D15*$K$20 -> 93566.226
B16: =B15 -> Instalações provisórias | C16: Itens de Segurança | D16: 0.005 | E16: =D16*$K$20 -> 46783.113
B17: =B16 -> Instalações provisórias | C17: LIMPEZA PERIÓDICA | D17: 0.023 | E17: =D17*$K$20 -> 215202.32
D18: Total (Vb) | E18: =SUM(E14:E17) -> 449117.89
A20: Movimentação de terra | J20: VALOR TOTAL | K20: 9356622.6
K22: =E18+E28+E39+E100+E162+E415+E302+E243+E270+E331+E322+E824+E858+E490+E569+E768+E686+E442+E878+E595 -> 9356622.6
C23: Etapa | D23: Porcentagem (%) | E23: Total | K23: =K22-K20 -> 0
B24: Movimentação de terra | C24: Mão de obra - movimentação de terra
B25: =B24 -> Movimentação de terra | C25: ESCAVAÇÃO E REATERRO | D25: 0.005 | E25: 46783.113 | J25: SOMA PROPORÇÕES | K25: =E18+E28+E39+E100+E162+E415+E302+E243+E270+E331+E322+E824+E858+E490+E569+E768+E686+E442+E878+E591 -> 9440846.3
B26: Movimentação de terra | C26: Mão de obra - locação
B27: =B26 -> Movimentação de terra | C27: FÔRMAS | D27: 0.005 | E27: 46783.113
D28: Total (Vb) | E28: =SUM(E25:E27) -> 93566.226
A30: Infraestrutura
C33: Etapa | D33: Porcentagem (%) | E33: Total
B34: Infraestrutura | C34: Mão de obra - execução de infraraestrutura
B35: =B34 -> Infraestrutura | C35: BLOCOS DE FUNDAÇÃO E PESCOÇOS | D35: 0.0087 | E35: =D35*$K$20 -> 81402.617 | F35: forma
B36: =B35 -> Infraestrutura | C36: BLOCOS DE FUNDAÇÃO E PESCOÇOS | D36: 0.003 | E36: =D36*$K$20 -> 28069.868 | F36: armadura
B37: =B36 -> Infraestrutura | C37: BLOCOS DE FUNDAÇÃO E PESCOÇOS | D37: 0.002 | E37: =D37*$K$20 -> 18713.245 | F37: laje
B38: =B37 -> Infraestrutura | C38: BLOCOS DE FUNDAÇÃO E PESCOÇOS | D38: 0.002 | E38: =D38*$K$20 -> 18713.245 | F38: concreto
D39: Total (Vb) | E39: =SUM(E35:E38) -> 146898.98
A41: Supraestrutura
B45: PAVIMENTO | C45: Etapa | D45: Porcentagem (%) | E45: Total
B46: Subsolo | C46: Mão de obra - execução de supraestrutura | E46: =SUM(E47:E50) -> 219880.63
B47: =B46 -> Subsolo | C47: SUBSOLO VIGAS BALDRAME E DESFÔRMA | D47: 0.01 | E47: =D47*$K$20 -> 93566.226 | F47: forma
B48: =B47 -> Subsolo | C48: SUBSOLO VIGAS BALDRAME E DESFÔRMA | D48: 0.0065 | E48: =D48*$K$20 -> 60818.047 | F48: armadura
B49: =B48 -> Subsolo | C49: SUBSOLO VIGAS BALDRAME E DESFÔRMA | D49: 0.003 | E49: =D49*$K$20 -> 28069.868 | F49: laje
B50: =B49 -> Subsolo | C50: SUBSOLO VIGAS BALDRAME E DESFÔRMA | D50: 0.004 | E50: =D50*$K$20 -> 37426.49 | F50: concreto
B51: Térreo | C51: Mão de obra - execução de supraestrutura | E51: =SUM(E52:E59) -> 407013.08
B52: =B51 -> Térreo | C52: TERREO VIGAS, PILARES MEZANINO, ESCORAMENTO E DESFORMA | D52: 0.014 | E52: =D52*$K$20 -> 130992.72
...

Sheet Planilha2
B2: Mão de obra para reboco interno | C2: m2 | D2: 14224.12 | E2: 734495.15
B3: Mão de obra - limpeza grossa - 2º pavimento | C3: vb | D3: 1 | E3: 6726.67
B4: Mão de obra - limpeza grossa - Ático | C4: vb | D4: 1 | E4: 6955.46
B5: Mão de obra - limpeza grossa - Barrilete | C5: vb | D5: 1 | E5: 878.04
B6: Mão de obra - limpeza grossa - Subsolo 1 | C6: vb | D6: 1 | E6: 12561.9
B7: Mão de obra - limpeza grossa - Subsolo 2 | C7: vb | D7: 1 | E7: 12561.9
B8: Mão de obra - limpeza grossa - Térreo | C8: vb | D8: 1 | E8: 11607.52
B9: Mão de obra - limpeza grossa - Tipo | C9: vb | D9: 1 | E9: 40360.03
B10: Mão d eobra para instalação de louças e metais | C10: vb | D10: 1 | E10: 93566.23
B11: Mão de obra - Entrada de energia | C11: vb | D11: 1 | E11: 9356.62
B12: Mão de obra - Execução de supraestrutura / Ático | C12: vb | D12: 1 | E12: 285376.99
B13: Mão de obra - Execução de supraestrutura / Barrilete | C13: vb | D13: 1 | E13: 668998.52
... B73: Mão de obra textura externa | C73: m2 | D73: 483.74 | E73: 93566.25

Sheet MO Infra
L6: =(92273.31+12957.46+45908+7494) -> 158632.77 | M6: =L6/(259.53*2+288.02) -> 196.55148

Sheet Composição forma blocos
A24: *composição mais próxima do serviço solicitado

Sheet Cotações
B1: Projeto | C1: =Ger_Executivo!C4 -> Playa Negra
B2: Empresa | C2: =Ger_Executivo!C5 -> GDI
B3: Revisão | C3: R00 - Michelle Furlan - 06/02/24
A4: CONTROLE DE COTAÇÕES
A5: INFORMAÇÕES IMPORTANTES: CNPJ XXXX / XXXXX / Endereço da obra: XXXX
A6: Item | B6: Data | C6: Site | D6: Status | E6: E-mail

Sheet Sapatas
B1: Projeto | C1: =Ger_Executivo!C4 -> Playa Negra
B2: Empresa | C2: =Ger_Executivo!C5 -> GDI
B3: Revisão | C3: R00 - Michelle Furlan -
A4: SAPATAS
A5: Peça | B5: Quant. | C5: Dimensões Unitárias - m | I5: Adição | J5: Adição | K5: Quantidade de Serviços
C6: A | D6: B | E6: H0 | F6: C | G6: D | H6: H1 | I6: largura | J6: altura | K6: Escav | L6: Apiloam | M6: Reaterro | N6: Bota-fora | O6: Lastro Concreto | Q6: Fôrma | R6: Concreto | S6: Imperm
C7: m | D7: m | E7: m | F7: m | G7: m | H7: m | I7: m | J7: m | K7: m3 | L7: m2 | M7: m3 | N7: m3 | O7: esp | P7: m3 | Q7: m2 | R7: m3 | S7: m2
A8: PROJETO: | K8: =(C8+I8)*(D8+I8)*(E8+H8+O8+J8)*B8 -> 0 | L8: =$C8*$D8*$B8 -> 0 | M8: =$K8-$R8-P8 -> 0 | N8: =(K8-M8)*1.3 -> 0 | P8: =($C8*$D8*$O8)*$B8 -> 0 | Q8: =(((($C8+$D8)*2)*$E8)*$B8)+(((J8-0.1)*4*F8)*B8) -> 0 | R8: =((($C8*$D8*$E8)+(($H8/6)*(($C8*$D8)+($F8*$G8)+(($C8+$F8)*($D8+$G8)))))*$B8)+((J8-0.1)*F8*G8*B8) -> 0
I9: =IF((C9+D9)<=1,0.6,1.2) -> 0.6 | K9: =(C9+I9)*(D9+I9)*(E9+H9+O9+J9)*B9 -> 0 | L9: =$C9*$D9*$B9 -> 0 | M9: =$K9-$R9-P9 -> 0 | N9: =(K9-M9)*1.3 -> 0 | O9: 0.1 | P9: =($C9*$D9*$O9)*$B9 -> 0 | Q9: =(((($C9+$D9)*2)*$E9)*$B9)+(((J9-0.1)*4*F9)*B9) -> 0 | R9: =((($C9*$D9*$E9)+(($H9/6)*(($C9*$D9)+($F9*$G9)+(($C9+$F9)*($D9+$G9)))))*$B9)+((J9-0.1)*F9*G9*B9) -> 0
I10: =IF((C10+D10)<=1,0.6,1.2) -> 0.6 | K10: =(C10+I10)*(D10+I10)*(E10+H10+O10+J10)*B10 -> 0 | L10: =$C10*$D10*$B10 -> 0 | M10: =$K10-$R10-P10 -> 0 | N10: =(K10-M10)*1.3 -> 0 | O10: 0.1 | P10: =($C10*$D10*$O10)*$B10 -> 0 | Q10: =(((($C10+$D10)*2)*$E10)*$B10)+(((J10-0.1)*4*F10)*B10) -> 0 | R10: =((($C10*$D10*$E10)+(($H10/6)*(($C10*$D10)+($F10*$G10)+(($C10+$F10)*($D10+$G10)))))*$B10)+((J10-0.1)*F10*G10*B10) -> 0
I11: =IF((C11+D11)<=1,0.6,1.2) -> 0.6 | K11: =(C11+I11)*(D11+I11)*(E11+H11+O11+J11)*B11 -> 0 | L11: =$C11*$D11*$B11 -> 0 | M11: =$K11-$R11-P11 -> 0 | N11: =(K11-M11)*1.3 -> 0 | O11: 0.1 | P11: =($C11*$D11*$O11)*$B11 -> 0 | Q11: =(((($C11+$D11)*2)*$E11)*$B11)+(((J11-0.1)*4*F11)*B11) -> 0 | R11: =((($C11*$D11*$E11)+(($H11/6)*(($C11*$D11)+($F11*$G11)+(($C11+$F11)*($D11+$G11)))))*$B11)+((J11-0.1)*F11*G11*B11) -> 0
I12: =IF((C12+D12)<=1,0.6,1.2) -> 0.6 | K12: =(C12+I12)*(D12+I12)*(E12+H12+O12+J12)*B12 -> 0 | L12: =$C12*$D12*$B12 -> 0 | M12: =$K12-$R12-P12 -> 0 | N12: =(K12-M12)*1.3 -> 0 | O12: 0.1 | P12: =($C12*$D12*$O12)*$B12 -> 0 | Q12: =(((($C12+$D12)*2)*$E12)*$B12)+(((J12-0.1)*4*F12)*B12) -> 0 | R12: =((($C12*$D12*$E12)+(($H12/6)*(($C12*$D12)+($F12*$G12)+(($C12+$F12)*($D12+$G12)))))*$B12)+((J12-0.1)*F12*G12*B12) -> 0
I13: =IF((C13+D13)<=1,0.6,1.2) -> 0.6 | K13: =(C13+I13)*(D13+I13)*(E13+H13+O13+J13)*B13 -> 0 | L13: =$C13*$D13*$B13 -> 0 | M13: =$K13-$R13-P13 -> 0 | N13: =(K13-M13)*1.3 -> 0 | O13: 0.1 | P13: =($C13*$D13*$O13)*$B13 -> 0 | Q13: =(((($C13+$D13)*2)*$E13)*$B13)+(((J13-0.1)*4*F13)*B13) -> 0 | R13: =((($C13*$D13*$E13)+(($H13/6)*(($C13*$D13)+($F13*$G13)+(($C13+$F13)*($D13+$G13)))))*$B13)+((J13-0.1)*F13*G13*B13) -> 0
I14: =IF((C14+D14)<=1,0.6,1.2) -> 0.6 | K14: =(C14+I14)*(D14+I14)*(E14+H14+O14+J14)*B14 -> 0 | L14: =$C14*$D14*$B14 -> 0 | M14: =$K14-$R14-P14 -> 0 | N14: =(K14-M14)*1.3 -> 0 | O14: 0.1 | P14: =($C14*$D14*$O14)*$B14 -> 0 | Q14: =(((($C14+$D14)*2)*$E14)*$B14)+(((J14-0.1)*4*F14)*B14) -> 0 | R14: =((($C14*$D14*$E14)+(($H14/6)*(($C14*$D14)+($F14*$G14)+(($C14+$F14)*($D14+$G14)))))*$B14)+((J14-0.1)*F14*G14*B14) -> 0
I15: =IF((C15+D15)<=1,0.6,1.2) -> 0.6 | K15: =(C15+I15)*(D15+I15)*(E15+H15+O15+J15)*B15 -> 0 | L15: =$C15*$D15*$B15 -> 0 | M15: =$K15-$R15-P15 -> 0 | N15: =(K15-M15)*1.3 -> 0 | O15: 0.1 | P15: =($C15*$D15*$O15)*$B15 -> 0 | Q15: =(((($C15+$D15)*2)*$E15)*$B15)+(((J15-0.1)*4*F15)*B15) -> 0 | R15: =((($C15*$D15*$E15)+(($H15/6)*(($C15*$D15)+($F15*$G15)+(($C15+$F15)*($D15+$G15)))))*$B15)+((J15-0.1)*F15*G15*B15) -> 0
I16: =IF((C16+D16)<=1,0.6,1.2) -> 0.6 | K16: =(C16+I16)*(D16+I16)*(E16+H16+O16+J16)*B16 -> 0 | L16: =$C16*$D16*$B16 -> 0 | M16: =$K16-$R16-P16 -> 0 | N16: =(K16-M16)*1.3 -> 0 | O16: 0.1 | P16: =($C16*$D16*$O16)*$B16 -> 0 | Q16: =(((($C16+$D16)*2)*$E16)*$B16)+(((J16-0.1)*4*F16)*B16) -> 0 | R16: =((($C16*$D16*$E16)+(($H16/6)*(($C16*$D16)+($F16*$G16)+(($C16+$F16)*($D16+$G16)))))*$B16)+((J16-0.1)*F16*G16*B16) -> 0
I17: =IF((C17+D17)<=1,0.6,1.2) -> 0.6 | K17: =(C17+I17)*(D17+I17)*(E17+H17+O17+J17)*B17 -> 0 | L17: =$C17*$D17*$B17 -> 0 | M17: =$K17-$R17-P17 -> 0 | N17: =(K17-M17)*1.3 -> 0 | O17: 0.1 | P17: =($C17*$D17*$O17)*$B17 -> 0 | Q17: =(((($C17+$D17)*2)*$E17)*$B17)+(((J17-0.1)*4*F17)*B17) -> 0 | R17: =((($C17*$D17*$E17)+(($H17/6)*(($C17*$D17)+($F17*$G17)+(($C17+$F17)*($D17+$G17)))))*$B17)+((J17-0.1)*F17*G17*B17) -> 0
I18: =IF((C18+D18)<=1,0.6,1.2) -> 0.6 | K18: =(C18+I18)*(D18+I18)*(E18+H18+O18+J18)*B18 -> 0 | L18: =$C18*$D18*$B18 -> 0 | M18: =$K18-$R18-P18 -> 0 | N18: =(K18-M18)*1.3 -> 0 | O18: 0.1 | P18: =($C18*$D18*$O18)*$B18 -> 0 | Q18: =(((($C18+$D18)*2)*$E18)*$B18)+(((J18-0.1)*4*F18)*B18) -> 0 | R18: =((($C18*$D18*$E18)+(($H18/6)*(($C18*$D18)+($F18*$G18)+(($C18+$F18)*($D18+$G18)))))*$B18)+((J18-0.1)*F18*G18*B18) -> 0
I19: =IF((C19+D19)<=1,0.6,1.2) -> 0.6 | K19: =(C19+I19)*(D19+I19)*(E19+H19+O19+J19)*B19 -> 0 | L19: =$C19*$D19*$B19 -> 0 | M19: =$K19-$R19-P19 -> 0 | N19: =(K19-M19)*1.3 -> 0 | O19: 0.1 | P19: =($C19*$D19*$O19)*$B19 -> 0 | Q19: =(((($C19+$D19)*2)*$E19)*$B19)+(((J19-0.1)*4*F19)*B19) -> 0 | R19: =((($C19*$D19*$E19)+(($H19/6)*(($C19*$D19)+($F19*$G19)+(($C19+$F19)*($D19+$G19)))))*$B19)+((J19-0.1)*F19*G19*B19) -> 0
I20: =IF((C20+D20)<=1,0.6,1.2) -> 0.6 | K20: =(C20+I20)*(D20+I20)*(E20+H20+O20+J20)*B20 -> 0 | L20: =$C20*$D20*$B20 -> 0 | M20: =$K20-$R20-P20 -> 0 | N20: =(K20-M20)*1.3 -> 0 | O20: 0.1 | P20: =($C20*$D20*$O20)*$B20 -> 0 | Q20: =(((($C20+$D20)*2)*$E20)*$B20)+(((J20-0.1)*4*F20)*B20) -> 0 | R20: =((($C20*$D20*$E20)+(($H20/6)*(($C20*$D20)+($F20*$G20)+(($C20+$F20)*($D20+$G20)))))*$B20)+((J20-0.1)*F20*G20*B20) -> 0
... I26: =IF((C26+D26)<=1,0.6,1.2) -> 0.6 | K26: =(C26+I26)*(D26+I26)*(E26+H26+O26+J26)*B26 -> 0 | L26: =$C26*$D26*$B26 -> 0 | M26: =$K26-$R26-P26 -> 0 | N26: =(K26-M26)*1.3 -> 0 | O26: 0.1 | P26: =($C26*$D26*$O26)*$B26 -> 0 | Q26: =(((($C26+$D26)*2)*$E26)*$B26)+(((J26-0.1)*4*F26)*B26) -> 0 | R26: =((($C26*$D26*$E26)+(($H26/6)*(($C26*$D26)+($F26*$G26)+(($C26+$F26)*($D26+$G26)))))*$B26)+((J26-0.1)*F26*G26*B26) -> 0
B27: TOTAL GERAL | K27: =SUM(K8:K26) -> 0 | L27: =SUM(L8:L26) -> 0 | M27: =SUM(M8:M26) -> 0 | N27: =SUM(N8:N26) -> 0 | P27: =SUM(P8:P26) -> 0 | Q27: =SUM(Q8:Q26) -> 0 | R27: =SUM(R8:R26) -> 0 | S27: =SUM(S8:S26) -> 0
K28: Vol. tronco pirâmide = (H2/6) * [ (A*B) + (C*D) + (A+C)*(B+D) ]

Sheet Tabela de Aço
A1: TABELA DE AÇO
A2: CA-50 | D2: CA-60
A3: Ø - mm | B3: kg/m | C3: pol | D3: Ø - mm | E3: kg/m
A4: 6.3 | B4: 0.245 | C4: 1/4" | D4: 3.4 | E4: 0.079
A5: 8 | B5: 0.395 | C5: 5/16" | D5: 4.2 | E5: 0.109
A6: 10 | B6: 0.617 | C6: 3/8" | D6: 5 | E6: 0.154
A7: 12.5 | B7: 0.963 | C7: 1/2" | D7: 6 | E7: 0.222
A8: 16 | B8: 1.578 | C8: 5/8" | D8: 7 | E8: 0.302
A9: 20 | B9: 2.466 | C9: 3/4" | D9: 8 | E9: 0.395
A10: 25 | B10: 3.853 | C10: 1" | D10: 9.5 | E10: 0.558
A11: 32 | B11: 6.313 | C11: 1 1/4" | D11: 0
A12: 40 | B12: 9.865 | C12: 1 5/8" | D12: 0

Sheet Estrutura
D1: Projeto | E1: =Obra!D1 -> Playa Negra
D2: Empresa | E2: =Obra!D2 -> GDI
D3: Origem | E3: PROJETO: PNEG-EST-PE-QUANTITATIVO-R00 (CTN & GDI - Pasta Compartilhada\04. GDI - PLAYA NEGRA (compartilhamento)\03. FN ESTRUTURAS)
D4: Revisão | E4: R00 - Patricia Bragato
A5: INFRAESTRUTURA
A6: ITEM | B6: 5 | C6: 6.3 | D6: 8 | E6: 10 | F6: 12.5 | G6: 16 | H6: 20 | I6: 25 | J6: Aço | K6: Q92 | L6: Q138 | M6: Concreto C40 | N6: Forma | O6: Area | P6: Enchimento EPS | R6: Cubetas Atex 800
B7: kgf | C7: kgf | D7: kgf | E7: kgf | F7: kgf | G7: kgf | H7: kgf | I7: kgf | J7: kgf | K7: kgf | L7: kgf | M7: (m³) | N7: (m²) | O7: (m²) | P7: 50x50x15 | Q7: 50x50x20 | R7: Forma Inteira 80x80x20 | S7: Meia Forma 40x80x20
A8: INFRAESTRUTURA
A9: Sapatas | B9: 0 | C9: 0 | D9: 0 | E9: 157 | F9: 1013 | G9: 7426 | H9: 2300 | I9: 0 | J9: =SUM(B9:I9) -> 10896 | K9: 0 | L9: 0 | M9: 240.8 | N9: 143.6 | O9: 0 | P9: 0 | Q9: 0 | R9: 0 | S9: 0
A10: TOTAL | B10: =SUM(B7:B9) -> 0 | C10: =SUM(C7:C9) -> 0 | D10: =SUM(D7:D9) -> 0 | E10: =SUM(E7:E9) -> 157 | F10: =SUM(F7:F9) -> 1013 | G10: =SUM(G7:G9) -> 7426 | H10: =SUM(H7:H9) -> 2300 | I10: =SUM(I7:I9) -> 0 | ... S10: =SUM(S7:S9) -> 0
A12: SUPRAESTRUTURA
A13: ITEM | B13: 5 | C13: 6.3 | D13: 8 | E13: 10 | F13: 12.5 | G13: 16 | H13: 20 | I13: 25 | J13: Aço | K13: Q92 | L13: Q138 | M13: Concreto C40 | N13: Forma | O13: Area | P13: Enchimento EPS | R13: Cubetas Atex 800
B14: kgf | C14: kgf | D14: kgf | E14: kgf | F14: kgf | G14: kgf | H14: kgf | I14: kgf | J14: kgf | K14: kgf | L14: kgf | M14: (m³) | N14: (m²) | O14: (m²) | P14: 50x50x15 | Q14: 50x50x20 | R14: Forma Inteira 80x80x20 | S14: Meia Forma 40x80x20
A15: SUBSOLO 2 | B15: =SUM(B16:B19) -> 236 | C15: =SUM(C16:C19) -> 660 | D15: =SUM(D16:D19) -> 175 | E15: =SUM(E16:E19) -> 1415 | F15: =SUM(F16:F19) -> 1119 | G15: =SUM(G16:G19) -> 990 | H15: =SUM(H16:H19) -> 1748 | I15: =SUM(I16:I19) -> 620 | ... N15: =SUM(N16:N19) -> 438.8024 | O15: 126.31 | P15: =SUM(P16:P19) -> 0
A16: Pilares | B16: 178 | C16: 173 | E16: 13 | F16: 257 | G16: 743 | H16: 1715 | I16: 620 | J16: 3699 | M16: 8.8 | N16: 89.1 | P16: 0 | Q16: 0 | R16: 0 | S16: 0
A17: Vigas | B17: 58 | C17: 472 | D17: 64 | E17: 620 | F17: 153 | G17: 247 | H17: 33 | J17: 1647 | M17: 27.3 | N17: 284.8 | P17: 0 | Q17: 0 | R17: 0 | S17: 0
A18: Lajes | D18: 106 | E18: 782 | F18: 610 | J18: 1498 | K18: 0 | L18: 4510 | M18: 12.7 | N18: 52 | P18: 0 | Q18: 0 | R18: 0 | S18: 0
A19: Escada | B19: =Escadas!K10 -> 0 | C19: =Escadas!L10 -> 15 | D19: =Escadas!M10 -> 5 | F19: =Escadas!N10 -> 99 | J19: =SUM(B19:I19) -> 119 | M19: =Escadas!P10 -> 1.650682 | N19: =Escadas!O10 -> 12.9024 | R19: 0 | S19: 0
A20: SUBSOLO 1 | B20: =SUM(B21:B24) -> 419 | C20: =SUM(C21:C24) -> 533 | D20: =SUM(D21:D24) -> 2086 | E20: =SUM(E21:E24) -> 2345 | F20: =SUM(F21:F24) -> 2813 | G20: =SUM(G21:G24) -> 3797 | H20: =SUM(H21:H24) -> 3150 | I20: =SUM(I21:I24) -> 1196 | ... N20: =SUM(N21:N24) -> 695.4256 | O20: 1111.93 | P20: =SUM(P21:P24) -> 0
A21: Pilares | B21: 264 | C21: 239 | E21: 20 | F21: 310 | G21: 1032 | H21: 1624 | I21: 670 | J21: 4159 | M21: 25.2 | N21: 256.7 | P21: 0 | Q21: 0 | R21: 0 | S21: 0
A22: Vigas | B22: 155 | C22: 21 | D22: 70 | E22: 178 | F22: 130 | G22: 219 | H22: 119 | J22: 892 | M22: 36.7 | N22: 331.2 | P22: 0 | Q22: 0 | R22: 0 | S22: 0
A23: Lajes | C23: 256 | D23: 2009 | E23: 2147 | F23: 2264 | G23: 2546 | H23: 1407 | I23: 526 | J23: 11155 | K23: 1460 | L23: 0 | M23: 156.8 | N23: 91.1 | P23: 0 | Q23: 0 | R23: 1185 | S23: 94
A24: Escada | B24: =Escadas!K11 -> 0 | C24: =Escadas!L11 -> 17 | D24: =Escadas!M11 -> 7 | F24: =Escadas!N11 -> 109 | J24: =SUM(B24:I24) -> 133 | M24: =Escadas!P11 -> 2.073698 | N24: =Escadas!O11 -> 16.4256 | R24: 0 | S24: 0
A25: TERREO | B25: =SUM(B26:B29) -> 469 | C25: =SUM(C26:C29) -> 667 | D25: =SUM(D26:D29) -> 6623 | E25: =SUM(E26:E29) -> 4592 | F25: =SUM(F26:F29) -> 6705 | G25: =SUM(G26:G29) -> 5015 | H25: =SUM(H26:H29) -> 5611 | I25: =SUM(I26:I29) -> 22149 | ... N25: =SUM(N26:N29) -> 1285.6262 | O25: 1111.85 | P25: =SUM(P26:P29) -> 0
A26: Pilares | B26: 330 | C26: 289 | E26: 54 | F26: 477 | G26: 717 | H26: 1808 | I26: 601 | J26: 4276 | M26: 32 | N26: 327 | P26: 0 | Q26: 0 | R26: 0 | S26: 0
A27: Vigas | B27: 129 | C27: 202 | D27: 5358 | E27: 2194 | F27: 4375 | G27: 2623 | H27: 2380 | I27: 21166 | J27: 38427 | M27: 229.2 | N27: 822.6 | P27: 0 | Q27: 0 | R27: 0 | S27: 0
A28: Lajes | B28: 8 | C28: 176 | D28: 1218 | E28: 2344 | F28: 1775 | G28: 1675 | H28: 1423 | I28: 382 | J28: 9001 | K28: 1123 | M28: 135.6 | N28: 107.2 | P28: 0 | Q28: 0 | R28: 806 | S28: 141
A29: Escada | B29: =Escadas!K12 -> 2 | C29: =Escadas!L12 -> 0 | D29: =Escadas!M12 -> 47 | F29: =Escadas!N12 -> 78 | J29: =SUM(B29:I29) -> 127 | M29: =Escadas!P12 -> 4.6170057 | N29: =Escadas!O12 -> 28.82623 | P29: 0 | Q29: 0 | R29: 0 | S29: 0
A30: SOBRELOJA | B30: =SUM(B31:B34) -> 306 | C30: =SUM(C31:C34) -> 299 | D30: =SUM(D31:D34) -> 525 | E30: =SUM(E31:E34) -> 631 | F30: =SUM(F31:F34) -> 736 | G30: =SUM(G31:G34) -> 1064 | H30: =SUM(H31:H34) -> 2834 | I30: =SUM(I31:I34) -> 662 | ... N30: =SUM(N31:N34) -> 508.00383 | O30: 180.29 | P30: =SUM(P31:P34) -> 183
A31: Pilares | B31: 124 | C31: 180 | E31: 67 | F31: 121 | G31: 194 | H31: 2373 | J31: 3059 | M31: 22.5 | N31: 236.1 | P31: 0 | Q31: 0 | R31: 0 | S31: 0
A32: Vigas | B32: 180 | C32: 36 | D32: 103 | E32: 62 | F32: 209 | G32: 344 | H32: 223 | I32: 477 | J32: 1634 | M32: 8.4 | N32: 88.5 | P32: 0 | Q32: 0 | R32: 0 | S32: 0
A33: Lajes | C33: 83 | D33: 365 | E33: 502 | F33: 349 | G33: 526 | H33: 238 | I33: 185 | J33: 2248 | K33: 152 | M33: 22.3 | N33: 153.7 | P33: 183 | Q33: 0 | R33: 0 | S33: 0
A34: Escada | B34: =Escadas!K13 -> 2 | C34: =Escadas!L13 -> 0 | D34: =Escadas!M13 -> 57 | F34: =Escadas!M13 -> 57 | J34: =SUM(B34:I34) -> 116 | M34: =Escadas!P13 -> 4.7223227 | N34: =Escadas!O13 -> 29.70383 | P34: 0 | Q34: 0 | R34: 0 | S34: 0
A35: 2º PAVIMENTO | B35: =SUM(B36:B39) -> 569 | C35: =SUM(C36:C39) -> 512 | D35: =SUM(D36:D39) -> 2286 | E35: =SUM(E36:E39) -> 1857 | F35: =SUM(F36:F39) -> 2367 | G35: =SUM(G36:G39) -> 3217 | H35: =SUM(H36:H39) -> 6014 | I35: =SUM(I36:I39) -> 2149 | ... N35: =SUM(N36:N39) -> 1107.9038 | O35: 615.06 | P35: =SUM(P36:P39) -> 942
A36: Pilares | B36: 418 | C36: 157 | F36: 160 | G36: 1121 | H36: 4510 | I36: 962 | J36: 7328 | M36: 22.8 | N36: 231.7 | P36: 0 | Q36: 0 | R36: 0 | S36: 0
A37: Vigas | B37: 149 | C37: 316 | D37: 527 | E37: 381 | F37: 237 | G37: 535 | H37: 410 | I37: 809 | J37: 3364 | M37: 25.6 | N37: 272 | P37: 0 | Q37: 0 | R37: 0 | S37: 0
A38: Lajes | C38: 39 | D38: 1702 | E38: 1476 | F38: 1884 | G38: 1561 | H38: 1094 | I38: 378 | J38: 8134 | K38: 787 | M38: 78.7 | N38: 574.5 | P38: 942 | Q38: 0 | R38: 0 | S38: 0
A39: Escada | B39: =Escadas!$K$14/6 -> 2 | C39: =Escadas!$L$14/6 -> 0 | D39: =Escadas!$M$14/6 -> 57 | F39: =Escadas!$N$14/6 -> 86 | J39: =SUM(B39:I39) -> 145 | M39: =Escadas!$P$14/6 -> 4.7223227 | N39: =Escadas!$O$14/6 -> 29.70383 | P39: 0 | Q39: 0 | R39: 0 | S39: 0
A40: 3º PAVIMENTO | B40: =SUM(B41:B44) -> 523 | C40: =SUM(C41:C44) -> 496 | D40: =SUM(D41:D44) -> 2419 | E40: =SUM(E41:E44) -> 1870 | F40: =SUM(F41:F44) -> 2614 | G40: =SUM(G41:G44) -> 2385 | H40: =SUM(H41:H44) -> 3124 | I40: =SUM(I41:I44) -> 803 | ... N40: =SUM(N41:N44) -> 1091.4038 | O40: 619.9 | P40: =SUM(P41:P44) -> 906
A41: Pilares | B41: 336 | C41: 16 | E41: 43 | F41: 405 | G41: 556 | H41: 1491 | I41: 219 | J41: 3066 | M41: 17.7 | N41: 218.7 | P41: 0 | Q41: 0 | R41: 0 | S41: 0
...

Sheet Escadas
D1: Projeto | E1: =Obra!D1 -> Playa Negra
D2: Empresa | E2: =Obra!D2 -> GDI
D3: Origem | E3: 04. GDI - PLAYA NEGRA (compartilhamento)\03. FN ESTRUTURAS\500 - DETALHES
D4: Revisão | E4: R00 - Patricia Bragato
A5: ESCADAS
A6: PAVIMENTO | B6: CÓDIGO DA ESCADA | C6: NÚMERO DE PATAMARES | D6: LADO 1 DO PATAMAR | E6: LADO 2 DO PATAMAR | F6: NÚMERO DE DEGRAUS | G6: COMPRIMENTO DO DEGRAU | H6: LARGURA DO DEGRAU | I6: ALTURA DO ESPELHO DO DEGRAU | J6: ESPESSURA MÉDIA DO DEGRAU | K6: Ø5,00 | L6: Ø6,30 | M6: Ø8,00 | N6: Ø12,00 | O6: FORMA DE COMPENSADO | P6: VOLUME DE CONCRETO | Q6: TAXA DE ARMADURA | R6: ESCORAMENTO
B7: COD. | C7: PATAMARES | F7: DEGRAUS | K7: F | L7: F | M7: C | N7: T | O7: F | P7: C | Q7: T | R7: Aesc
C8: NP | D8: L1 | E8: L2 | F8: ND | G8: D | H8: d | I8: e | J8: B | K8: kgf | L8: kgf | M8: kgf | N8: kgf | O8: (m²) | P8: (m³) | Q8: kg/m3 | R8: m2
A9: Projeto: PNEG-EST-PE-502-ESCA-R00 até PNEG-EST-PE-507-ESCA-R00
A10: Subsolo 02 | C10: 1 | D10: 1.21 | E10: 1.2 | F10: 13 | G10: 1.21 | H10: 0.28 | I10: 0.18 | J10: 0.19 | L10: 15 | M10: 5 | N10: 99 | O10: =C10*D10*E10+F10*G10*H10+G10*I10*F10*2+2*H10*F10*J10 -> 12.9024 | P10: =C10*D10*E10*J10+F10*G10*H10*J10+F10*G10*I10*J10 -> 1.650682 | Q10: =SUM(K10:N10)/P10 -> 72.091414 | R10: =C10*D10*E10+F10*G10*H10 -> 5.8564
A11: Subsolo 01 | C11: 1 | D11: 1.21 | E11: 1.2 | F11: 17 | G11: 1.21 | H11: 0.28 | I11: 0.18 | J11: 0.19 | L11: 17 | M11: 7 | N11: 109 | O11: =C11*D11*E11+F11*G11*H11+G11*I11*F11*2+2*H11*F11*J11 -> 16.4256 | P11: =C11*D11*E11*J11+F11*G11*H11*J11+F11*G11*I11*J11 -> 2.073698 | Q11: =SUM(K11:N11)/P11 -> 64.136629 | R11: =C11*D11*E11+F11*G11*H11 -> 7.2116
A12: Térreo | C12: 1 | D12: =2.2265+1.205 -> 3.4315 | E12: =(1.205*2)*2 -> 4.82 | F12: 14 | G12: 1.205 | H12: 0.28 | I12: 0.18 | J12: 0.19 | K12: 2 | M12: 47 | N12: 78 | O12: =C12*D12*E12+F12*G12*H12+G12*I12*F12*2+2*H12*F12*J12 -> 28.82623 | P12: =C12*D12*E12*J12+F12*G12*H12*J12+F12*G12*I12*J12 -> 4.6170057 | Q12: =SUM(K12:N12)/P12 -> 27.507005 | R12: =C12*D12*E12+F12*G12*H12 -> 21.26343
A13: Sobreloja | C13: 1 | D13: =2.2265+1.205 -> 3.4315 | E13: =(1.205*2)*2 -> 4.82 | F13: 15 | G13: 1.205 | H13: 0.28 | I13: 0.18 | J13: 0.19 | K13: 2 | M13: 57 | N13: 86 | O13: =C13*D13*E13+F13*G13*H13+G13*I13*F13*2+2*H13*F13*J13 -> 29.70383 | P13: =C13*D13*E13*J13+F13*G13*H13*J13+F13*G13*I13*J13 -> 4.7223227 | Q13: =SUM(K13:N13)/P13 -> 30.705229 | R13: =C13*D13*E13+F13*G13*H13 -> 21.60083
A14: Pav tipo x6 | C14: 1 | D14: =2.2265+1.205 -> 3.4315 | E14: =(1.205*2)*2 -> 4.82 | F14: 15 | G14: 1.205 | H14: 0.28 | I14: 0.18 | J14: 0.19 | K14: =2*6 -> 12 | M14: =57*6 -> 342 | N14: =86*6 -> 516 | O14: =(C14*D14*E14+F14*G14*H14+G14*I14*F14*2+2*H14*F14*J14)*6 -> 178.22298 | P14: =(C14*D14*E14*J14+F14*G14*H14*J14+F14*G14*I14*J14)*6 -> 28.333936 | Q14: =SUM(K14:N14)/P14 -> 30.705229 | R14: =(C14*D14*E14+F14*G14*H14)*6 -> 129.60498
A15: 8º Pavimento | C15: 1 | D15: =2.2265+1.205 -> 3.4315 | E15: =(1.205*2)*2 -> 4.82 | F15: 15 | G15: 1.205 | H15: 0.28 | I15: 0.18 | J15: 0.19 | K15: 2 | M15: 57 | N15: 86 | O15: =C15*D15*E15+F15*G15*H15+G15*I15*F15*2+2*H15*F15*J15 -> 29.70383 | P15: =C15*D15*E15*J15+F15*G15*H15*J15+F15*G15*I15*J15 -> 4.7223227 | Q15: =SUM(K15:N15)/P15 -> 30.705229 | R15: =C15*D15*E15+F15*G15*H15 -> 21.60083
A16: TOTAL | C16: =SUM(C10:C15) -> 6 | D16: =SUM(D10:D15) -> 16.146 | E16: =SUM(E10:E15) -> 21.68 | F16: =SUM(F10:F15) -> 89 | G16: =SUM(G10:G15) -> 7.24 | H16: =SUM(H10:H15) -> 1.68 | I16: =SUM(I10:I15) -> 1.08 | J16: =SUM(J10:J15) -> 1.14 | ... P16: =SUM(P10:P15) -> 46.119967 | Q16: =SUM(K16:N16)/P16 -> 33.369495 | R16: =SUM(R8:R15) -> 207.13807

Sheet ARQ
A1: DADOS
A2: Titulo | B2: QUANTITATIVO
A3: Obra | B3: PLAYA NEGRA
A4: Cliente | B4: GDI
A5: Cidade
A6: Endereço
A7: Descrição
A9: QUANTITATIVOS
A10: Item | B10: Descrição | C10: Unid. | D10: Quantidade
A12: 1. | B12: ALVENARIA E VEDAÇÕES
A13: 1.1. | B13: -2_SUB 2
A14: 1.1.1 | B14: BLOCO ANTI-CHAMAS, 15 cm | C14: m² | D14: 50.28
A15: 1.1.2 | B15: BLOCO CERAMICO, 09 cm | C15: m² | D15: 14.59
A16: 1.1.3 | B16: BLOCO CONCRETO, 14 cm | C16: m² | D16: 66.54
A17: 1.1.4 | B17: BLOCO DE COBOGO | C17: m² | D17: 12.65
A18: 1.1.5 | B18: ENCUNHAMENTO | C18: m | D18: 69.82
A19: 1.1.6. | B19: Porta
A20: 1.1.6.1 | B20: VERGAS+CONTRAVERGAS | C20: m | D20: 3.52
A21: 1.2. | B21: -1_SUB 1
A22: 1.2.1 | B22: BLOCO ANTI-CHAMAS, 15 cm | C22: m² | D22: 70.78
A23: 1.2.2 | B23: BLOCO CERAMICO, 09 cm | C23: m² | D23: 18.32
A24: 1.2.3 | B24: BLOCO CERAMICO, 11,5 cm | C24: m² | D24: 13.07
A25: 1.2.4 | B25: BLOCO CONCRETO, 14 cm | C25: m² | D25: 67.55
A26: 1.2.5 | B26: BLOCO DE COBOGO | C26: m² | D26: 19.1
A27: 1.2.6 | B27: DESCONSIDERAR | C27: m² | D27: 21.32
A28: 1.2.7 | B28: ENCUNHAMENTO | C28: m | D28: 62.31
A29: 1.2.8. | B29: Porta
A30: 1.2.8.1 | B30: VERGAS+CONTRAVERGAS | C30: m | D30: 2.44
A31: 1.3. | B31: 00_TER
A32: 1.3.1 | B32: BLOCO ANTI-CHAMAS, 15 cm | C32: m² | D32: 180.7
A33: 1.3.2 | B33: BLOCO CERAMICO, 09 cm | C33: m² | D33: 34.89
A34: 1.3.3 | B34: BLOCO CERAMICO, 11,5 cm | C34: m² | D34: 20.3
A35: 1.3.4 | B35: BLOCO CERAMICO, 14 cm | C35: m² | D35: 414.61
A36: 1.3.5 | B36: BLOCO CONCRETO, 15 cm | C36: m² | D36: 5.36
A37: 1.3.6 | B37: ENCUNHAMENTO | C37: m | D37: 147.24
A38: 1.3.7. | B38: Janela
A39: 1.3.7.1 | B39: VERGAS+CONTRAVERGAS | C39: m | D39: 1.6
A40: 1.3.8. | B40: Porta
A41: 1.3.8.1 | B41: VERGAS+CONTRAVERGAS | C41: m | D41: 11.4
A42: 1.4. | B42: 01_SLOJA
...

Sheet Tijolos refratários
D1: Projeto | E1: =Obra!D1 -> Playa Negra
D2: Empresa | E2: =Obra!D2 -> GDI
D3: Origem | E3: 04. GDI - PLAYA NEGRA (compartilhamento)\02. ARQUITETURA (GDI)\DWG\R09
D4: Revisão | E4: R00 - Patricia Bragato
A5: CHURRASQUERIA
A6: PAVIMENTO | B6: CÓDIGO DA CHURRASQUEIRA | C6: NUMERO DE CHURRASQUEIRAS | D6: LADO A | E6: LADO B | F6: PERIMETRO | G6: ALTURA | H6: AREA DE PISO | I6: AREA DA ABERTURA | J6: AREA DE REFRATÁRIO
B7: COD. | C7: NC | D7: L1 | E7: L2 | F7: P | G7: a | H7: AP | I7: AA | J7: AR
A8: Projeto: PN_REV09_ARQ_ANTEPROJETOo-Folha - 06-15 - PLANTA BAIXA - 2º PAVTO | J8: =SUM(J9:J11) -> 12.6915
A9: Tipo 1 | B9: A | C9: 1 | D9: 0.49 | E9: 0.7 | F9: =2*D9+2*E9 -> 2.38 | G9: 1.2 | H9: =E9*D9 -> 0.343 | I9: =0.6*0.6 -> 0.36 | J9: =(H9+F9*G9-I9)*C9 -> 2.839
A10: Tipo 1 | B10: B | C10: 2 | D10: 0.55 | E10: 0.65 | F10: =2*D10+2*E10 -> 2.4 | G10: 1.2 | H10: =E10*D10 -> 0.3575 | I10: =0.5*0.6 -> 0.3 | J10: =(H10+F10*G10-I10)*C10 -> 5.875
A11: Tipo 1 | B11: C | C11: 1 | D11: 0.95 | E11: 0.65 | F11: =2*D11+2*E11 -> 3.2 | G11: 1.2 | H11: =E11*D11 -> 0.6175 | I11: =0.8*0.6 -> 0.48 | J11: =(H11+F11*G11-I11)*C11 -> 3.9775
A12: Projeto: PN_REV09_ARQ_ANTEPROJETOo-Folha - 07-15 - PLANTA BAIXA - PAVTO TIPO (3º AO 8º) | J12: =SUM(J13:J15) -> 76.149
A13: Tipo (x6) | B13: A | C13: =1*6 -> 6 | D13: 0.49 | E13: 0.7 | F13: =2*D13+2*E13 -> 2.38 | G13: 1.2 | H13: =E13*D13 -> 0.343 | I13: =0.6*0.6 -> 0.36 | J13: =(H13+F13*G13-I13)*C13 -> 17.034
A14: Tipo (x6) | B14: B | C14: =2*6 -> 12 | D14: 0.55 | E14: 0.65 | F14: =2*D14+2*E14 -> 2.4 | G14: 1.2 | H14: =E14*D14 -> 0.3575 | I14: =0.5*0.6 -> 0.3 | J14: =(H14+F14*G14-I14)*C14 -> 35.25
A15: Tipo (x6) | B15: C | C15: =1*6 -> 6 | D15: 0.95 | E15: 0.65 | F15: =2*D15+2*E15 -> 3.2 | G15: 1.2 | H15: =E15*D15 -> 0.6175 | I15: =0.8*0.6 -> 0.48 | J15: =(H15+F15*G15-I15)*C15 -> 23.865
A16: TOTAL | C16: =SUM(C9:C15) -> 28 | J16: =J8+J12 -> 88.8405

Sheet Resumo impermeabilização
B1: Projeto | C1: =Obra!D1 -> Playa Negra
B2: Empresa | C2: =Obra!D2 -> GDI
B3: Origem | C3: PN_R0_IMP_PRANCHA 01 - PLANTA BAIXA SUBSOLO 2, DETALHES ELEVADOR, CISTERNA E ESCADA SS2; PN_R0_IMP_PRANCHA 02 - PLANTA BAIXA SUBSOLO 1 E DETALHES SUBSOLO 1 (1) ; PN_R0_IMP_PRANCHA 03 - PLANTA BAIXA TÉRREO, DETALHES CALÇADA EXTERNA E LAVABO PCD
B4: Revisão | C4: R00 - Patricia Bragato
A5: IMPERMEABILIZAÇÃO
A6: LOCAIS | B6: Descrição orçamento | D6: Area
D7: m2
A8: CISTERNAS | B8: Impermeabilizacao com argamassa polimerica impermeabilizante | D8: =Impermeabilização!$H$13+Impermeabilização!$H$41 -> 161.6
A9: PISCINAS E ESPELHOS DÁGUA | B9: Impermeabilizacao com aditivo cristalizante e membrana PU 2 camadas | D9: =SUMIF(Impermeabilização!$E$160:$E$174,B9,Impermeabilização!$H$160:$H$174) -> 123.975
A10: PISCINAS E ESPELHOS DÁGUA | B10: Impermeabilizacao com aditivo cristalizante e membrana PU potável 2 camadas | D10: =SUMIF(Impermeabilização!$E$160:$E$174,B10,Impermeabilização!$H$160:$H$174) -> 119.1
A11: BANHEIROS, COZINHAS E SACADAS | B11: Impermeabilizacao com argamassa polimerica impermeabilizante | D11: =SUMIF(Impermeabilização!$E$50:$E$158,B11,Impermeabilização!$H$50:$H$158)+Impermeabilização!$H$26 +Impermeabilização!H178+Impermeabilização!H181+Impermeabilização!H188+Impermeabilização!H191+Impermeabilização!H43 -> 2528.312
A12: FLOREIRAS | B12: Impermeabilizacao com aditivo cristalizante, com membrana antiraiz e geomembrana | D12: =SUMIF(Impermeabilização!$E$11:$E$224,B12,Impermeabilização!$H$11:$H$224) -> 80.91
A13: RESERVATÓRIO | B13: Impermeabilizacao com argamassa polimerica impermeabilizante | D13: =Impermeabilização!H212+Impermeabilização!H216 -> 63.889
A14: RESERVATÓRIO | B14: Impermeabilizacao com aditivo cristalizante e membrana PU híbrida | D14: =Impermeabilização!H221 -> 42.021
A15: RALOS | B15: Tratamento de ralo com manta de poliester | D15: =SUMIF(Impermeabilização!$E$11:$E$224,B15,Impermeabilização!$H$11:$H$224) -> 190.621
A16: JANELAS/PEITORIS | B16: Impermeabilização com membranas em peitoris | D16: =SUMIF(Impermeabilização!$E$11:$E$224,B16,Impermeabilização!$H$11:$H$224) -> 109.402
A17: LAJES E TERRAÇOS | B17: Impermeabilizacao com argamassa polimerica impermeabilizante | D17: 260.974
A18: LAJES E TERRAÇOS | B18: Impermeabilizacao com aditivo cristalizante e membrana PU 2 camadas | D18: 223.952
A19: LAJES E TERRAÇOS | B19: Impermeabilizacao com aditivo cristalizante e membrana PU híbrida | D19: 205.326
A20: LAJES E TERRAÇOS | B20: Impermeabilizacao com aditivo cristalizante e membrana PU | D20: 101.714
A21: LAJES E TERRAÇOS | B21: Impermeabilizacao com aditivo cristalizante e membrana PU de alto trânsito | D21: 1771.9984
A22: LAJES E TERRAÇOS | B22: Impermeabilizacao com aditivo cristalizante | D22: 35.725
A23: TOTAL | D23: =SUM(D8:D22) -> 6019.5194

Sheet Impermeabilização
B2: IMPERMEABILIZAÇÃO
B4: Obra | C4: Playa Negra
B5: Empresa | C5: GDI Empreendimentos
B6: Revisão | C6: R00
B7: Data | C7: 45526
B8: Acesso aos projetos | C8: PN_R0_IMP_PRANCHA 01 - PLANTA BAIXA SUBSOLO 2, DETALHES ELEVADOR, CISTERNA E ESCADA SS2; PN_R0_IMP_PRANCHA 02 - PLANTA BAIXA SUBSOLO 1 E DETALHES SUBSOLO 1 (1) ; PN_R0_IMP_PRANCHA 03 - PLANTA BAIXA TÉRREO, DETALHES CALÇADA EXTERNA E LAVABO PCD
B10: Pavimento | C10: Locais | D10: Descrição | E10: Descrição orçamento | F10: Area(m²) | G10: Repetições | H10: Total
B11: SUBSOLO 2 | C11: POÇO DO ELEVADOR | D11: Membrana cimentícia semiflexível | E11: Impermeabilizacao com aditivo cristalizante | F11: 35.725 | G11: 1 | H11: =G11*F11 -> 35.725
C12: Parede cobogó | D12: Cristalização + membrana PU alto trânsito | E12: Impermeabilizacao com aditivo cristalizante e membrana PU de alto trânsito | F12: =2.42*0.02 -> 0.0484 | G12: 1 | H12: =G12*F12 -> 0.0484
C13: CISTERNA | D13: Membrana cimentícia semiflexível | E13: Impermeabilizacao com argamassa polimerica impermeabilizante | F13: 114.118 | G13: 1 | H13: =G13*F13 -> 114.118
D14: Membrana cimentícia flexível | F14: 113.556 | G14: 1 | H14: =G14*F14 -> 113.556
D15: Reforço com tela poliester de 10cm | E15: Tratamento de ralo com manta de poliester | F15: 0.12 | G15: 1 | H15: =G15*F15 -> 0.12
C16: ESCADA | D16: Membrana cimentícia semiflexível | E16: Impermeabilizacao com argamassa polimerica impermeabilizante | F16: 6.583 | G16: 1 | H16: =G16*F16 -> 6.583
D17: Membrana cimentícia flexível | F17: 6.583 | G17: 1 | H17: =G17*F17 -> 6.583
C18: TOTAL | F18: =SUM(F11:F17) -> 276.7334
B19: SUBSOLO 1 | C19: GARAGEM | D19: Prime cimentício de correção de substrato | E19: Impermeabilizacao com aditivo cristalizante e membrana PU de alto trânsito | F19: =4.719+2.768+7.16+1034.31 -> 1048.957 | G19: 1 | H19: =G19*F19 -> 1048.957
D20: Membrana de alto trânsito | F20: =4.766+2.779+7.18+1033.9719 -> 1048.6969 | G20: 1 | H20: =G20*F20 -> 1048.6969
D21: Reforço com tela poliester de 10cm | E21: Tratamento de ralo com manta de poliester | F21: 0.72 | G21: 1 | H21: =G21*F21 -> 0.72
C22: TOTAL | F22: =SUM(F19:F21) -> 2098.3739
B23: TÉRREO | C23: Calçada externa | D23: Prime cimentício de correção de substrato | E23: Impermeabilizacao com aditivo cristalizante e membrana PU | F23: =56.363+1.771+1.673+0.217 -> 60.024 | G23: 1 | H23: =G23*F23 -> 60.024
D24: Membrana de PU | F24: =56.363+1.781+1.665+0.216 -> 60.025 | G24: 1 | H24: =G24*F24 -> 60.025
D25: Quartzo | F25: =53.777+1.241+1.657+0.224 -> 56.899 | G25: 1 | H25: =G25*F25 -> 56.899
C26: Lavabo PCD | D26: Membrana cimentícia semiflexível | E26: Impermeabilizacao com argamassa polimerica impermeabilizante | F26: =2*4.274 -> 8.548 | G26: 1 | H26: =G26*F26 -> 8.548
D27: Membrana cimentícia flexível | F27: =2*3.261 -> 6.522 | G27: 1 | H27: =G27*F27 -> 6.522
D28: Reforço com tela poliester de 10cm | E28: Tratamento de ralo com manta de poliester | F28: =2*0.169 -> 0.338 | G28: 1 | H28: =G28*F28 -> 0.338
C29: Garagem | D29: Prime cimentício de correção de substrato | E29: Impermeabilizacao com aditivo cristalizante e membrana PU de alto trânsito | F29: =720.886+2.107 -> 722.993 | G29: 1 | H29: =G29*F29 -> 722.993
D30: Membrana de alto trânsito | F30: =723.155+2.116 -> 725.271 | G30: 1 | H30: =G30*F30 -> 725.271
D31: Reforço com tela poliester de 10cm | E31: Tratamento de ralo com manta de poliester | F31: 0.174 | G31: 1 | H31: =G31*F31 -> 0.174
C32: Janela (dep. Int. lixo) | D32: Membrana Sikafill | E32: Impermeabilização com membranas em peitoris | F32: 1.07 | G32: 1 | H32: =G32*F32 -> 1.07
C33: Acesso ao subsolo | D33: Prime cimentício de correção de substrato | E33: Impermeabilizacao com aditivo cristalizante e membrana PU | F33: 41.69 | G33: 1 | H33: =G33*F33 -> 41.69
D34: Membrana de alto trânsito | F34: 41.679 | G34: 1 | H34: =G34*F34 -> 41.679
C35: Dep. Int. lixo | D35: Membrana cimentícia semiflexível | E35: Impermeabilizacao com argamassa polimerica impermeabilizante | F35: 43.852 | G35: 1 | H35: =G35*F35 -> 43.852
D36: Membrana cimentícia flexível | F36: 7.855 | G36: 1 | H36: =G36*F36 -> 7.855
D37: Reforço com tela poliester de 10cm | E37: Tratamento de ralo com manta de poliester | F37: 0.106 | G37: 1 | H37: =G37*F37 -> 0.106
C38: Dep. Tem. Lixo | D38: Membrana cimentícia semiflexível | E38: Impermeabilizacao com argamassa polimerica impermeabilizante | F38: 23.022 | G38: 1 | H38: =G38*F38 -> 23.022
D39: Membrana cimentícia flexível | F39: 4.458 | G39: 1 | H39: =G39*F39 -> 4.458
C40: TOTAL | F40: =SUM(F23:F39) -> 1804.526
B41: SOBRELOJA | C41: Cisterna pluvial | D41: Membrana cimentícia semiflexível | E41: Impermeabilizacao com argamassa polimerica impermeabilizante | F41: =47.159+0.323 -> 47.482 | G41: 1 | H41: =G41*F41 -> 47.482
D42: Membrana cimentícia flexível | F42: =17.376+0.323 -> 17.699 | G42: 1 | H42: =G42*F42 -> 17.699
C43: Lavabo Loja - sobreloja | D43: Membrana cimentícia semiflexível | E43: Impermeabilizacao com argamassa polimerica impermeabilizante | F43: =4.202 -> 4.202 | G43: 1 | H43: =G43*F43 -> 4.202
...

Sheet INTERFONIA
A1: Obra | B1: =Obra!D1 -> Playa Negra
A2: Empresa | B2: =Obra!D2 -> GDI
A3: Revisão | B3: =Obra!D3 -> R00 - Patricia Bragato
A4: QUANTIFICAÇÃO
A6: Interfonia
A8: Interfonia
B10: Descrição quantitativo | C10: Quantidade | D10: unidade | E10: Preço unitário | F10: Preço total
B11: Aparelho interfone | C11: =Obra!E19+3+4 -> 76 | D11: pç | E11: 72 | F11: =E11*C11 -> 5472
B12: Porteiro externo | C12: 1 | D12: pç | E12: 492 | F12: =E12*C12 -> 492
