Workbook
Name \0: #REF!
Name \0: #REF!
Name \a: #REF!
Name \a: #REF!
Name \m: #REF!
Name aa: #REF!
Name aa: #REF!
Name aaaa: '[1]M.O.'!#REF!
Name aaaa: '[1]M.O.'!#REF!
Name angelo: [2]Geral!#REF!
Name angelo: [2]Geral!#REF!
Name area: #REF!
Name Areaimpresso: #REF!
Name aux: #REF!
Name aux: #REF!
Name BDA: #REF!
Name BDA: #REF!
Name BDI: #REF!
Name ca: #REF!
Name Capa: #REF!
Name cronograma: #REF!
Name D: #REF!
Name direto: #REF!
Name DRE: #REF!
Name ea: #REF!
Name FFFFFFF: #REF!
Name item_1: #REF!
Name LS: '[1]M.O.'!#REF!
Name MENU: #REF!
Name MENU: #REF!
Name MENU1: #REF!
Name MENU1: #REF!
Name MENU2: #REF!
Name MENU2: #REF!
Name MENU3: #REF!
Name MENU4: #REF!
Name MENU5: #REF!
Name MENU6: #REF!
Name mo: #REF!
Name OAE: #REF!
Name ParamValues1: [3]ParamValues!$A$1:$A$39
Name PAV: #REF!
Name pr: #REF!
Name PRE: #REF!
Name Print_Area_MI: #REF!
Name qe: #REF!
Name qee: #REF!
Name reforsu: #REF!
Name ren: #REF!
Name REV: #REF!
Name sa: #REF!
Name SEG: #REF!
Name SIH: #REF!
Name SIV: #REF!
Name ss: #REF!
Name susref: #REF!
Name tania: #REF!
Name tc: #REF!
Name titulos: #REF!
Name TOT: #REF!

Sheet CAPA
A1: Obra | B1: AMARO
A2: Empresa | B2: TERRASSA
A3: Revisão | B3: R01
A4: Data | B4: 45426
A5: ORÇAMENTO EXECUTIVO
A26: ORÇAMENTO EXECUTIVO
A28: Construtora Terrassa - Amaro
A55: Itajaí, Maio de 2024

Sheet Resumo
A1: ETAPA | B1: VALOR ORÇADO | C1: % | D1: VALOR / m²
A2: GERENCIAMENTO TÉCNICO E ADMINISTRATIVO | B2: =ORÇAMENTO_EXECUTIVO!$F$8 -> 5614697 | C2: =B2/B$23 -> 0.16318534 | D2: =B2/Resumo!G$2 -> 535.78727 | F2: ÁREA CONSTRUÍDA | G2: 10479.34 | H2: m²
A3: CONTENÇÕES E FUNDAÇÕES | B3: =ORÇAMENTO_EXECUTIVO!$F$157 -> 1671216.1 | C3: =B3/B$23 -> 0.048572161 | D3: =B3/Resumo!G$2 -> 159.47723
A4: SUPRAESTRUTURA | B4: =ORÇAMENTO_EXECUTIVO!$F$195 -> 7557865.4 | C4: =B4/B$23 -> 0.21966152 | D4: =B4/Resumo!G$2 -> 721.21578
A5: ALVENARIA E VEDAÇÕES | B5: =ORÇAMENTO_EXECUTIVO!$F$386 -> 1849564.2 | C5: =B5/B$23 -> 0.053755665 | D5: =B5/Resumo!G$2 -> 176.49625
A6: INSTALAÇÕES ELÉTRICAS E TELEFÔNICAS | B6: =ORÇAMENTO_EXECUTIVO!$F$566 -> 1236715.3 | C6: =B6/B$23 -> 0.035943848 | D6: =B6/Resumo!G$2 -> 118.01462
A7: INSTALAÇÕES HIDROSSANITÁRIAS | B7: =ORÇAMENTO_EXECUTIVO!$F$594 -> 1535931.8 | C7: =B7/B$23 -> 0.044640264 | D7: =B7/Resumo!G$2 -> 146.56761
A8: INSTALAÇÕES PREVENTIVO (PCI | SPDA) | B8: =ORÇAMENTO_EXECUTIVO!$F$734 -> 309845.95 | C8: =B8/B$23 -> 0.0090053511 | D8: =B8/Resumo!G$2 -> 29.567315
A9: INSTALAÇÕES GLP | B9: =ORÇAMENTO_EXECUTIVO!$F$771 -> 44392.78 | C9: =B9/B$23 -> 0.0012902301 | D9: =B9/Resumo!G$2 -> 4.2362191
A10: INSTALAÇÕES CLIMATIZAÇÃO E EXAUSTÃO | B10: =ORÇAMENTO_EXECUTIVO!$F$779 -> 295942.08 | C10: =B10/B$23 -> 0.0086012495 | D10: =B10/Resumo!G$2 -> 28.240527
A11: REVESTIMENTOS DE ARGAMASSA | B11: =ORÇAMENTO_EXECUTIVO!$F$804 -> 2256448.8 | C11: =B11/B$23 -> 0.065581343 | D11: =B11/Resumo!G$2 -> 215.32356
A12: IMPERMEABILIZAÇÕES | B12: =ORÇAMENTO_EXECUTIVO!$F$995 -> 680287.38 | C12: =B12/B$23 -> 0.019771847 | D12: =B12/Resumo!G$2 -> 64.917006
A13: REVESTIMENTOS CERÂMICOS | B13: =ORÇAMENTO_EXECUTIVO!$F$1111 -> 1455299.5 | C13: =B13/B$23 -> 0.04229677 | D13: =B13/Resumo!G$2 -> 138.8732
A14: FORROS | B14: =ORÇAMENTO_EXECUTIVO!$F$1199 -> 968406.18 | C14: =B14/B$23 -> 0.028145721 | D14: =B14/Resumo!G$2 -> 92.41099
A15: ELEVADORES | B15: =ORÇAMENTO_EXECUTIVO!$F$1238 -> 1081743.1 | C15: =B15/B$23 -> 0.03143974 | D15: =B15/Resumo!G$2 -> 103.22626
A16: PINTURAS | B16: =ORÇAMENTO_EXECUTIVO!$F$1242 -> 1757382.5 | C16: =B16/B$23 -> 0.0510765 | D16: =B16/Resumo!G$2 -> 167.69974
A17: ESQUADRIAS (METÁLICAS, VIDRO E MADEIRA) | B17: =ORÇAMENTO_EXECUTIVO!$F$1434 -> 2995632.7 | C17: =B17/B$23 -> 0.087064957 | D17: =B17/Resumo!G$2 -> 285.86082
A18: REVESTIMENTOS COMPLEMENTARES | B18: =ORÇAMENTO_EXECUTIVO!$F$1565 -> 1486082.8 | C18: =B18/B$23 -> 0.043191456 | D18: =B18/Resumo!G$2 -> 141.81073
A19: INSTALAÇÕES COMPLEMENTARES | B19: =ORÇAMENTO_EXECUTIVO!$F$1705 -> 118382.63 | C19: =B19/B$23 -> 0.0034406684 | D19: =B19/Resumo!G$2 -> 11.296764
A20: LOUÇAS E METAIS | B20: =ORÇAMENTO_EXECUTIVO!$F$1711 -> 240314.9 | C20: =B20/B$23 -> 0.0069845033 | D20: =B20/Resumo!G$2 -> 22.932255
A21: LIMPEZA DE OBRA | B21: =ORÇAMENTO_EXECUTIVO!$F$1794 -> 157190.1 | C21: =B21/B$23 -> 0.0045685672 | D21: =B21/Resumo!G$2 -> 15
A22: INFRAESTRUTURA EXTERNA | MOBILIÁRIO ÁREAS COMUNS | DECORAÇÃO | PAISAGISMO | B22: =ORÇAMENTO_EXECUTIVO!$F$1816+ORÇAMENTO_EXECUTIVO!$F$1824 -> 1093529.5 | C22: =B22/B$23 -> 0.031782301 | D22: =B22/Resumo!G$2 -> 104.35099
A23: TOTAL | B23: =SUM(B2:B22) -> 34406871 | C23: =SUM(C2:C22) -> 1 | D23: =SUM(D2:D22) -> 3283.3051
A24: CUB/SC | B24: 2757.56 | C24: 45383 | D24: =ROUNDDOWN(D23/B24,2)&" CUB" -> 1,19 CUB
A27: Rótulos de Linha | B27: Soma de %
A28: SUPRAESTRUTURA | B28: 0.21910817
A29: GERENCIAMENTO TÉCNICO E ADMINISTRATIVO | B29: 0.12660285
A30: ESQUADRIAS (METÁLICAS, VIDRO E MADEIRA) | B30: 0.10195003
A31: REVESTIMENTOS DE ARGAMASSA | B31: 0.068628514
A32: ALVENARIA E VEDAÇÕES | B32: 0.056253368
A33: PINTURAS | B33: 0.053449719
A34: CONTENÇÕES E FUNDAÇÕES | B34: 0.048360425
A35: INSTALAÇÕES HIDROSSANITÁRIAS | B35: 0.04671443
A36: REVESTIMENTOS COMPLEMENTARES | B36: 0.045198303
A37: REVESTIMENTOS CERÂMICOS | B37: 0.044262047
A38: INSTALAÇÕES ELÉTRICAS E TELEFÔNICAS | B38: 0.037770192
A39: INFRAESTRUTURA EXTERNA | MOBILIÁRIO ÁREAS COMUNS | DECORAÇÃO | PAISAGISMO | B39: 0.033259034
... A49: Total Geral | B49: 1

Sheet Análise
A1: ETAPA | B1: AMARO | D1: OBRAS DE REFERÊNCIA
B2: VALOR | C2: VALOR / m² | D2: VALOR / m²
A3: INFRAESTRUTURA | B3: 1671216.1 | C3: 159.47723 | D3: 140,00 -180,00
A4: SUPRAESTRUTURA | B4: 7557865.4 | C4: 721.21578 | D4: 590,00 -670,00
A5: ALVENARIA | B5: 1849564.2 | C5: 176.49625 | D5: 130,00 -180,00
A6: INSTALAÇÕES ELÉTRICAS, HIDRÁULICAS, GLP E PREVENTIVAS | B6: 3367200.8 | C6: 321.31802 | D6: 260,00 -320,00
A7: EQUIPAMENTOS E SISTEMAS ESPECIAIS | B7: 1496067.8 | C7: 142.76355 | D7: 130,00 -200,00
A8: IMPERMEABILIZAÇÃO | B8: 680287.38 | C8: 64.917006 | D8: 30,00 -70,00
A9: REVESTIMENTOS INTERNOS EM PISO E PAREDE | B9: 1751905.6 | C9: 167.17709 | D9: 90,00 -170,00
A10: REVESTIMENTOS E ACABAMENTOS INTERNOS EM TETO | B10: 968406.18 | C10: 92.41099 | D10: 60,00 -90,00
A11: ACABAMENTOS EM PISO E PAREDE | B11: 2333301.1 | C11: 222.65726 | D11: 180,00 -220,00
A12: PINTURA INTERNA | B12: 1343221.3 | C12: 128.17804 | D12: 100,00 -140,00
A13: ESQUADRIAS, VIDROS E FERRAGENS | B13: 2995632.7 | C13: 285.86082 | D13: 280,00 -340,00
A14: REVESTIMENTOS E ACABAMENTOS DE FACHADA | B14: 1526785.7 | C14: 145.69483 | D14: 90,00 -140,00
A15: SERVIÇOS COMPLEMENTARES | B15: 1250719.6 | C15: 119.35099 | D15: 110,00 -160,00
A16: TOTAL | B16: =SUM(B3:B15) -> 28792174 | C16: =SUM(C3:C15) -> 2747.5179 | D16: 2.190,00 -2.880,00

Sheet Comparação Paramétrico
A1: ETAPA | B1: PARAMÉTRICO | E1: EXECUTIVO | G1: DIFERENÇA
B2: VALOR | C2: VALOR INDEXADO | D2: VALOR / m² | E2: VALOR | F2: VALOR / m² | G2: VALOR | H2: VALOR / m²
A3: GERENCIAMENTO TÉCNICO E ADMINISTRATIVO | B3: 3371440 | C3: =(Resumo!$B$24/'Comparação Paramétrico'!$B$18)*'Comparação Paramétrico'!B3 -> 3654216.5 | D3: =C3/$K$3 -> 348.70674 | E3: 5614697 | F3: =E3/$K$3 -> 535.78727 | G3: =E3-C3 -> 1960480.4 | H3: =F3-D3 -> 187.08053 | J3: ÁREA CONSTRUÍDA | K3: 10479.34 | L3: m²
A4: INFRAESTRUTURA | B4: 2411074.4 | C4: =(Resumo!$B$24/'Comparação Paramétrico'!$B$18)*'Comparação Paramétrico'!B4 -> 2613301.1 | D4: =C4/$K$3 -> 249.37649 | E4: 1671216.1 | F4: =E4/$K$3 -> 159.47723 | G4: =E4-C4 -> -942085.01 | H4: =F4-D4 -> -89.899269
A5: SUPRAESTRUTURA | B5: 6450527 | C5: =(Resumo!$B$24/'Comparação Paramétrico'!$B$18)*'Comparação Paramétrico'!B5 -> 6991559.2 | D5: =C5/$K$3 -> 667.17553 | E5: 7557865.4 | F5: =E5/$K$3 -> 721.21578 | G5: =E5-C5 -> 566306.16 | H5: =F5-D5 -> 54.040251
A6: ALVENARIA | B6: 1500998.1 | C6: =(Resumo!$B$24/'Comparação Paramétrico'!$B$18)*'Comparação Paramétrico'!B6 -> 1626893 | D6: =C6/$K$3 -> 155.24766 | E6: 1849564.2 | F6: =E6/$K$3 -> 176.49625 | G6: =E6-C6 -> 222671.21 | H6: =F6-D6 -> 21.248591
A7: INSTALAÇÕES ELÉTRICAS, HIDRÁULICAS, GLP E PREVENTIVAS | B7: 3873941.5 | C7: =(Resumo!$B$24/'Comparação Paramétrico'!$B$18)*'Comparação Paramétrico'!B7 -> 4198864.9 | D7: =C7/$K$3 -> 400.68028 | E7: 3367200.8 | F7: =E7/$K$3 -> 321.31802 | G7: =E7-C7 -> -831664.15 | H7: =F7-D7 -> -79.362264
A8: EQUIPAMENTOS E SISTEMAS ESPECIAIS | B8: 2736786.2 | C8: =(Resumo!$B$24/'Comparação Paramétrico'!$B$18)*'Comparação Paramétrico'!B8 -> 2966331.8 | D8: =C8/$K$3 -> 283.06475 | E8: 1496067.8 | F8: =E8/$K$3 -> 142.76355 | G8: =E8-C8 -> -1470264 | H8: =F8-D8 -> -140.3012
A9: IMPERMEABILIZAÇÃO | B9: 515307.1 | C9: =(Resumo!$B$24/'Comparação Paramétrico'!$B$18)*'Comparação Paramétrico'!B9 -> 558528.02 | D9: =C9/$K$3 -> 53.298015 | E9: 680287.38 | F9: =E9/$K$3 -> 64.917006 | G9: =E9-C9 -> 121759.36 | H9: =F9-D9 -> 11.618991
A10: REVESTIMENTOS INTERNOS EM PISO E PAREDE | B10: 1642622.1 | C10: =(Resumo!$B$24/'Comparação Paramétrico'!$B$18)*'Comparação Paramétrico'!B10 -> 1780395.6 | D10: =C10/$K$3 -> 169.89578 | E10: 1751905.6 | F10: =E10/$K$3 -> 167.17709 | G10: =E10-C10 -> -28489.992 | H10: =F10-D10 -> -2.7186819
A11: REVESTIMENTOS E ACABAMENTOS INTERNOS EM TETO | B11: 696735.86 | C11: =(Resumo!$B$24/'Comparação Paramétrico'!$B$18)*'Comparação Paramétrico'!B11 -> 755173.96 | D11: =C11/$K$3 -> 72.063123 | E11: 968406.18 | F11: =E11/$K$3 -> 92.41099 | G11: =E11-C11 -> 213232.22 | H11: =F11-D11 -> 20.347867
A12: ACABAMENTOS EM PISO E PAREDE | B12: 1818266.1 | C12: =(Resumo!$B$24/'Comparação Paramétrico'!$B$18)*'Comparação Paramétrico'!B12 -> 1970771.6 | D12: =C12/$K$3 -> 188.06256 | E12: 2333301.1 | F12: =E12/$K$3 -> 222.65726 | G12: =E12-C12 -> 362529.53 | H12: =F12-D12 -> 34.594691
A13: PINTURA INTERNA | B13: 1211611.2 | C13: =(Resumo!$B$24/'Comparação Paramétrico'!$B$18)*'Comparação Paramétrico'!B13 -> 1313234.1 | D13: =C13/$K$3 -> 125.31649 | E13: 1343221.3 | F13: =E13/$K$3 -> 128.17804 | G13: =E13-C13 -> 29987.184 | H13: =F13-D13 -> 2.8615527
A14: ESQUADRIAS, VIDROS E FERRAGENS | B14: 3573548.5 | C14: =(Resumo!$B$24/'Comparação Paramétrico'!$B$18)*'Comparação Paramétrico'!B14 -> 3873276.7 | D14: =C14/$K$3 -> 369.61075 | E14: 2995632.7 | F14: =E14/$K$3 -> 285.86082 | G14: =E14-C14 -> -877643.98 | H14: =F14-D14 -> -83.749929
A15: REVESTIMENTOS E ACABAMENTOS DE FACHADA | B15: 1460225.4 | C15: =(Resumo!$B$24/'Comparação Paramétrico'!$B$18)*'Comparação Paramétrico'!B15 -> 1582700.5 | D15: =C15/$K$3 -> 151.03055 | E15: 1526785.7 | F15: =E15/$K$3 -> 145.69483 | G15: =E15-C15 -> -55914.82 | H15: =F15-D15 -> -5.3357197
A16: SERVIÇOS COMPLEMENTARES | B16: 4154794.8 | C16: =(Resumo!$B$24/'Comparação Paramétrico'!$B$18)*'Comparação Paramétrico'!B16 -> 4503274.5 | D16: =C16/$K$3 -> 429.72883 | E16: 1250719.6 | F16: =E16/$K$3 -> 119.35099 | G16: =E16-C16 -> -3252554.8 | H16: =F16-D16 -> -310.37783
A17: TOTAL | B17: =SUM(B3:B16) -> 35417878 | C17: =SUM(C3:C16) -> 38388521 | D17: =SUM(D3:D16) -> 3663.2576 | E17: =SUM(E3:E16) -> 34406871 | F17: =SUM(F3:F16) -> 3283.3051 | G17: =SUM(G3:G16) -> -3981650.7 | H17: =SUM(H3:H16) -> -379.95243
B18: 2544.17 | G18: =G17/C17 -> -0.10371982
G20: VARIAÇÃO | H20: =G17/C17 -> -0.10371982

Sheet ORÇAMENTO_EXECUTIVO
A1: ORÇAMENTO EXECUTIVO
A2: Obra | B2: AMARO
A3: Empresa | B3: Terrazza
A4: Revisão | B4: =CAPA!B3 -> R01
A5: Data | B5: =CAPA!B4 -> 45426
A6: ORÇAMENTO EXECUTIVO AMARO - R00 | G6: OBSERVAÇÕES
A7: Código | B7: Descrição | C7: Un. | D7: Quantidade orçada | E7: Preço unitário | F7: Preço total | G7: Considerações | H7: Quantitativos
A8: 01 | B8: CUSTOS INDIRETOS | F8: =F9+F29+F65+F82 -> 5614697 | G8: OS CUSTOS INDIRETOS FORAM LANÇADOS SEGUINDO FORMULÁRIO DE CUSTOS INDIRETOS PREENCHIDO EM 24/11/2023 PELO FLÁVIO
A9: 01.01 | B9: TERRENO | F9: =F10+F12+F14+F16+F17+F19+F21+F24+F26 -> 1342700
A10: 01.01.001 | B10: TERRENO (ESTUDOS E VIABILIDADE) | F10: =F11 -> 10000
A11: 01.01.001.0001.00001 | B11: Terreno / Despesas com Estudos e Viabilidade | C11: vb | D11: 1 | E11: 10000 | F11: =E11*D11 -> 10000 | G11: Valor preenchido em formulário de custos indiretos, preenchido em 24/11/2023 pelo Flávio
A12: 01.01.002 | B12: TERRENO (LEVANTAMENTOS TOPOGRÁFICOS) | F12: =F13 -> 2000
A13: 01.01.002.0001.00001 | B13: Levantamento Topográfico | C13: vb | D13: 1 | E13: 2000 | F13: =E13*D13 -> 2000 | G13: Valor preenchido em formulário de custos indiretos, preenchido em 24/11/2023 pelo Flávio
A14: 01.01.003 | B14: SONDAGENS | F14: =F15 -> 6500
A15: 01.01.003.0001.00001 | B15: Sondagem de Percussão | C15: vb | D15: 1 | E15: 6500 | F15: =E15*D15 -> 6500 | G15: Valor preenchido em formulário de custos indiretos, preenchido em 24/11/2023 pelo Flávio
A16: 01.01.004 | B16: AQUISIÇÃO TERRENO | F16: 0
A17: 01.01.005 | B17: IPTU (IMPOSTO PREDIAL E TERRITORIAL URBANO) | F17: =F18 -> 54000
A18: 01.01.005.0001.00001 | B18: Impostos / IPTU | C18: mês | D18: 36 | E18: 1500 | F18: =E18*D18 -> 54000
A19: 01.01.006 | B19: INSS | F19: =F20 -> 11600
A20: 01.01.006.0001.00001 | B20: INSS | C20: vb | D20: 1 | E20: 11600 | F20: =E20*D20 -> 11600
A21: 01.01.007 | B21: SOLO CRIADO | OUTORGA ONEROSA | F21: =SUM(F22:F23) -> 1238000
A22: 01.01.007.0001.00001 | B22: TPC | C22: vb | D22: 1 | E22: 350000 | F22: =E22*D22 -> 350000
A23: 01.01.007.0001.00002 | B23: Solo criado / Outroga onerosa | C23: vb | D23: 1 | E23: 888000 | F23: =E23*D23 -> 888000
A24: 01.01.008 | B24: TERRENO (DESPESAS RETIFICAÇÃO, UNIFICAÇÃO E/OU DESMEMBRAMENTO) | F24: =F25 -> 10000
A25: 01.01.008.0001.00001 | B25: Compatibilização e aprovação em cartório | C25: vb | D25: 1 | E25: 10000 | F25: =E25*D25 -> 10000
A26: 01.01.009 | B26: DESPESAS COM REGISTRO DE INCORPORAÇÃO | F26: =F27+F28 -> 10600
A27: 01.01.009.0001.00001 | B27: Incorporação / Despesas Gerais | C27: vb | D27: 1 | E27: 5600 | F27: =E27*D27 -> 5600
A28: 01.01.009.0001.00002 | B28: Retificação do terreno | C28: vb | D28: 1 | E28: 5000 | F28: =E28*D28 -> 5000
A29: 01.02 | B29: PROJETOS | F29: =F30+F33+F35+F37+F40+F44+F49+F53+F55+F57+F60+F63 -> 834300
A30: 01.02.001 | B30: PROJETO ARQUITETÔNICO | F30: =F31+F32 -> 266000
A31: 01.02.001.0001.00001 | B31: Projeto Arquitetônico | C31: vb | D31: 1 | E31: 241000 | F31: =E31*D31 -> 241000 | G31: Valor preenchido em formulário de custos indiretos, preenchido em 24/11/2023 pelo Flávio
A32: 01.02.001.0001.00002 | B32: Projeto Interiores | C32: vb | D32: 1 | E32: 25000 | F32: =E32*D32 -> 25000
A33: 01.02.002 | B33: PROJETO TERRAPLANAGEM | F33: =F34 -> 1800
A34: 01.02.002.00001.00001 | B34: Projeto Terraplanagem | C34: vb | D34: 1 | E34: 1800 | F34: =E34*D34 -> 1800
A35: 01.02.003 | B35: PROJETO CANTEIRO | F35: =F36 -> 3000
A36: 01.02.003.00001.00001 | B36: Projeto Canteiro de Obras | C36: vb | D36: 1 | E36: 3000 | F36: =E36*D36 -> 3000 | G36: Valor preenchido em formulário de custos indiretos, preenchido em 24/11/2023 pelo Flávio
A37: 01.02.004 | B37: PROJETO FUNDAÇÕES | ESTRUTURAL | F37: =F38+F39 -> 71000
A38: 01.02.004.0001.00001 | B38: Projeto Estrutural | C38: vb | D38: 1 | E38: 50000 | F38: =E38*D38 -> 50000 | G38: Valor preenchido em formulário de custos indiretos, preenchido em 24/11/2023 pelo Flávio
A39: 01.02.005 | B39: Projeto Fundações | C39: vb | D39: 1 | E39: 21000 | F39: =E39*D39 -> 21000 | G39: Valor preenchido em formulário de custos indiretos, preenchido em 24/11/2023 pelo Flávio
A40: 01.02.005 | B40: PROJETO INST. COMPLEMENTARES (HIDROSSANITÁRIO, ELÉTRICO/TELECOM, PREVENTIVO, CLIMATIZAÇÃO/EXAUSTÃO) | F40: =F41+F42+F43 -> 86500
...

Sheet ABC Serviço
C2: Curva ABC de Serviços
A5: Obra | D5: 160 - OBRA | TRS Amaro - T4
A6: Unidade construtiva | D6: 3 - Custos Indiretos
A7: Tipo de obra | D7: 1 - Construção Civil
A8: BDI | D8: Não aplicado | G8: Encargos sociais | K8: Não aplicado
A10: Código | B10: Descrição | F10: Un. | H10: Quantidade | I10: Preço unitário | L10: Preço total | M10: %Part. | N10: %Acum.
A11: 9617 | B11: Solo criado / Outroga onerosa | F11: vb | H11: 1 | I11: 888000 | L11: 888000 | M11: 15.8156 | N11: 15.8156
A12: 9224 | B12: Equipe Técnica / Terceirizado | F12: mes | H12: 36 | I12: 15168.93 | L12: 546081.48 | M12: 9.7259 | N12: 25.5416
A13: 9043 | B13: Elevador Cremalheira (Locação) | F13: un | H13: 22 | I13: 22000 | L13: 484000 | M13: 8.6202 | N13: 34.1618
A14: 80034 | B14: Equipe Técnica / Engenheiro Civil (Rateio Obras) | F14: mês | H14: 36 | I14: 12000 | L14: 432000 | M14: 7.6941 | N14: 41.8559
A15: 9616 | B15: TPC | F15: vb | H15: 1 | I15: 350000 | L15: 350000 | M15: 6.2336 | N15: 48.0895
A16: 6388 | B16: Equipe Técnica / Mestre de Obras | F16: mês | H16: 36 | I16: 7380 | L16: 265680 | M16: 4.7319 | N16: 52.8214
A17: 6350 | B17: Projeto Arquitetônico | F17: vb | H17: 1 | I17: 241000 | L17: 241000 | M17: 4.2923 | N17: 57.1137
A18: 9621 | B18: Housi | F18: vb | H18: 1 | I18: 170000 | L18: 170000 | M18: 3.0278 | N18: 60.1415
A19: 9226 | B19: Equipe Técnica / Guincheiro | F19: mes | H19: 30 | I19: 4871.14 | L19: 146134.2 | M19: 2.6027 | N19: 62.7442
A20: 6382 | B20: Equipe Técnica / Almoxarife | F20: mês | H20: 30 | I20: 4305 | L20: 129150 | M20: 2.3002 | N20: 65.0444
A21: 80324 | B21: Bandeja de proteção secundária | F21: m | H21: 483.55 | I21: 237.5683 | L21: 114876.15 | M21: 2.046 | N21: 67.0904
A22: 6377 | B22: Gestão de Custos / Monitoramento/Acompanhamento de Obra | F22: mês | H22: 36 | I22: 2500 | L22: 90000 | M22: 1.6029 | N22: 68.6933
... A110: 8908 | B110: Taxas ART's e RRT's | F110: vb | H110: 1 | I110: 1680 | L110: 1680 | M110: 0.0299 | N110: 100
A111: Total da unidade construtiva | L111: 5614697
A113: Obra | D113: 160 - OBRA | TRS Amaro - T4
A114: Unidade construtiva | D114: 5 - Custos Diretos | Geral
A115: Tipo de obra | D115: 1 - Construção Civil
A116: BDI | D116: Não aplicado | G116: Encargos sociais | K116: Não aplicado
A118: Código | B118: Descrição | F118: Un. | H118: Quantidade | I118: Preço unitário | L118: Preço total | M118: %Part. | N118: %Acum.
A119: 6994 | B119: MOE - Supraestrutura / Execução Geral | F119: m2 | H119: 9218.23 | I119: 250 | L119: 2304557.5 | M119: 8.0041 | N119: 8.0041
A120: 9154 | B120: Esquadrias de alumínio | F120: m2 | H120: 2076.6395 | I120: 1049.07 | L120: 2178540.2 | M120: 7.5664 | N120: 15.5705
A121: 9278 | B121: Concreto Usinado (SUPRAESTRUTURA) - fck 40 MPa / Brita 0+1, slump 10+-2 | F121: m3 | H121: 2815.83 | I121: 605.851 | L121: 1705973.4 | M121: 5.9251 | N121: 21.4957
A122: 9090 | B122: Elevadores | F122: un | H122: 1 | I122: 1081743.1 | L122: 1081743.1 | M122: 3.7571 | N122: 25.2527
A123: 9153 | B123: MOE - Pinturas / Internas (Pintura Acrílica - Incluído Selador/Fundo e Massa) | F123: m2 | H123: 24591.14 | I123: 30 | L123: 737734.2 | M123: 2.5623 | N123: 27.815
A124: 7730 | B124: MOE - Revestimentos de Argamassa / Reboco Interno (com Desconto de Vãos) | F124: m2 | H124: 20484.07 | I124: 32 | L124: 655490.24 | M124: 2.2766 | N124: 30.0916
A125: 6971 | B125: Escoramento para Lajes e Vigas (Locação) | F125: m2 | H125: 9861.47 | I125: 60.93 | L125: 600859.36 | M125: 2.0869 | N125: 32.1785
A126: 9061 | B126: Alvenaria de vedação de blocos cerâmicos de 14x19x19cm (espessura 14cm) e argamassa industrializada de assentamento | F126: m2 | H126: 8463.75 | I126: 61.4093 | L126: 519752.97 | M126: 1.8052 | N126: 33.9837
A127: 6906 | B127: Armadura de Aço, incluso Corte e Dobra, (SUPRAESTRUTURA) - ø 6,3 mm | F127: kg | H127: 56586 | I127: 8.9924 | L127: 508843.95 | M127: 1.7673 | N127: 35.751
A128: 9020 | B128: MOE - Instalações Elétricas / Execução Geral | F128: m2 | H128: 10479.04 | I128: 47.53 | L128: 498068.77 | M128: 1.7299 | N128: 37.4809
A129: 6684 | B129: Concreto Usinado (ESTACAS) - fck 40 MPa / Brita 0+1, slump 24+-2 | F129: m3 | H129: 655.73 | I129: 715 | L129: 468846.95 | M129: 1.6284 | N129: 39.1093
A130: 7716 | B130: Reboco Interno com Argamassa Estabilizada - e=2,5 cm | F130: m2 | H130: 20484.07 | I130: 20.3071 | L130: 415972.06 | M130: 1.4447 | N130: 40.554
... A455: 8190 | B455: MOE - Revestimentos Complementares / Assentamentos e Acabamentos em Granito / Bocas/Vistas Churrasqueiras | F455: m2 | H455: 0.24 | I455: 32 | L455: 7.68 | M455: 0 | N455: 100
A456: Total da unidade construtiva | L456: 28792174
A457: Total da obra | L457: 34406871
...

Sheet ABC Insumos
C2: Curva ABC de Insumos
A5: Obra | D5: 160 - OBRA | TRS Amaro - T4
A6: Unidade construtiva | D6: 3 - Custos Indiretos
A7: Tipo de obra | D7: 1 - Construção Civil
A8: BDI | D8: Não aplicado | G8: Encargos sociais | K8: Não aplicado
A10: Código | B10: Descrição | F10: Un. | G10: Quantidade | H10: Preço unitário | L10: Preço total | M10: %Part. | N10: %Acum.
A11: 226 | B11: Terreno / Despesas com Outorga Onerosa | F11: vb | G11: 1 | I11: 888000 | L11: 888000 | M11: 15.8156 | N11: 15.8156
A12: 9225 | B12: Equipe Técnica / Terceirizado | F12: vb | G12: 36 | I12: 15168.93 | L12: 546081.48 | M12: 9.7259 | N12: 25.5416
A13: 9042 | B13: Elevador Cremalheira (Locação) | F13: un | G13: 22 | I13: 22000 | L13: 484000 | M13: 8.6202 | N13: 34.1618
A14: 116 | B14: Equipe Técnica / Engenheiro Civil | F14: mês | G14: 36 | I14: 12000 | L14: 432000 | M14: 7.6941 | N14: 41.8559
A15: 9618 | B15: TPC - Transf. Potencial Construtivo (Solo Oneroso) | F15: vb | G15: 1 | I15: 350000 | L15: 350000 | M15: 6.2336 | N15: 48.0895
A16: 118 | B16: Equipe Técnica / Mestre de Obras | F16: mês | G16: 36 | I16: 7380 | L16: 265680 | M16: 4.7319 | N16: 52.8214
A17: 185 | B17: Projeto Arquitetônico | F17: vb | G17: 1 | I17: 241000 | L17: 241000 | M17: 4.2923 | N17: 57.1137
A18: 9622 | B18: HOUSI | F18: vb | G18: 1 | I18: 170000 | L18: 170000 | M18: 3.0278 | N18: 60.1415
A19: 9227 | B19: Equipe Técnica / Guincheiro | F19: mes | G19: 30 | I19: 4871.14 | L19: 146134.2 | M19: 2.6027 | N19: 62.7442
A20: 112 | B20: Equipe Técnica / Almoxarife | F20: mês | G20: 30 | I20: 4305 | L20: 129150 | M20: 2.3002 | N20: 65.0444
A21: 21 | B21: Consultoria em Segurança do Trabalho | F21: mês | G21: 36 | I21: 2500 | L21: 90000 | M21: 1.6029 | N21: 66.6473
A22: 130 | B22: Gestão de Custos / Monitoramento/Acompanhamento de Obra | F22: mês | G22: 36 | I22: 2500 | L22: 90000 | M22: 1.6029 | N22: 68.2503
... A124: 1063 | B124: Aço CA-50 - 10,0 mm / sem Corte e Dobra | F124: kg | G124: 162.8307 | I124: 6.5822 | L124: 1071.78 | M124: 0.0191 | N124: 100
A125: Total da unidade construtiva | L125: 5614697
A127: Obra | D127: 160 - OBRA | TRS Amaro - T4
A128: Unidade construtiva | D128: 5 - Custos Diretos | Geral
A129: Tipo de obra | D129: 1 - Construção Civil
A130: BDI | D130: Não aplicado | G130: Encargos sociais | K130: Não aplicado
A132: Código | B132: Descrição | F132: Un. | G132: Quantidade | H132: Preço unitário | L132: Preço total | M132: %Part. | N132: %Acum.
A133: 515 | B133: MOE - Supraestrutura / Execução Geral | F133: m2 | G133: 10409.08 | I133: 250 | L133: 2602270 | M133: 9.0381 | N133: 9.0381
A134: 9155 | B134: Esquadrias de alumínio | F134: m2 | G134: 2076.6395 | I134: 1049.07 | L134: 2178540.2 | M134: 7.5664 | N134: 16.6045
A135: 1536 | B135: Concreto Usinado - fck 40 MPa | F135: m3 | G135: 4195.0605 | I135: 484.3806 | L135: 2032005.9 | M135: 7.0575 | N135: 23.662
A136: 9089 | B136: Elevadores | F136: un | G136: 1 | I136: 1081743.1 | L136: 1081743.1 | M136: 3.7571 | N136: 27.4191
A137: 9152 | B137: MOE - Pinturas / Internas | F137: m2 | G137: 24591.14 | I137: 30 | L137: 737734.2 | M137: 2.5623 | N137: 29.9814
A138: 594 | B138: MOE - Revestimentos de Argamassa / Reboco Interno / Paredes (com Desconto de Vãos) | F138: m2 | G138: 20484.07 | I138: 32 | L138: 655490.24 | M138: 2.2766 | N138: 32.258
A139: 2413 | B139: Escoramento para Lajes e Vigas (Locação) | F139: m2 | G139: 9861.47 | I139: 60.93 | L139: 600859.37 | M139: 2.0869 | N139: 34.3449
A140: 1035 | B140: Argamassa Estabilizada para Uso Geral | F140: m3 | G140: 1333.6223 | I140: 425 | L140: 566789.48 | M140: 1.9686 | N140: 36.3135
A141: 2545 | B141: Execução de Negativo em Gesso Liso | F141: m | G141: 22547.8 | I141: 25 | L141: 563695 | M141: 1.9578 | N141: 38.2713
A142: 721 | B142: Estimativas / Instalações Elétricas | F142: vb | G142: 10479.04 | I142: 47.53 | L142: 498068.77 | M142: 1.7299 | N142: 40.0011
A143: 584 | B143: MOE - Alvenarias e Vedações / Alvenaria de Vedação em Blocos Cerâmicos / incluso Vergas, Contravergas e Pilaretes (com Desconto de Vãos) | F143: m2 | G143: 13662.68 | I143: 34 | L143: 464531.12 | M143: 1.6134 | N143: 41.6145
A144: 1711 | B144: Bloco Cerâmico Vedação - 14x19x19 cm | F144: un | G144: 204399.56 | I144: 2.07 | L144: 423107.09 | M144: 1.4695 | N144: 43.0841
... A973: 3210 | B973: Tubo Aço Galvanizado - 2" | F973: m | G973: 0.01 | I973: 39 | L973: 0.39 | M973: 0 | N973: 100
A974: Total da unidade construtiva | L974: 28792172
A975: Total da obra | L975: 34406869
...

Sheet Insumos - grupos
C2: Insumos
A5: Obra | D5: 160 - OBRA | TRS Amaro - T4
A7: BDI | D7: Não aplicar | F7: Encargos sociais | I7: Não aplicar
A9: Grupo | D9: 01 - MÃO DE OBRA
A10: Família | D10: 01.001 - MÃO DE OBRA PRODUÇÃO
A11: Código | B11: Descrição | G11: Unidade | J11: Preço unitário | K11: Data do preço | L11: Ativo
A12: 257 | B12: Operador de Grua | G12: mês | J12: 6500 | K12: 10/11/2021 | L12: Sim
A13: 8963 | B13: * Servente (sem encargos) | G13: h | J13: 16.92 | K13: 15/09/2023 | L13: Sim
A15: Família | D15: 01.002 - MÃO DE OBRA EMPREITADA (GLOBAL)
A16: Código | B16: Descrição | G16: Unidade | J16: Preço unitário | K16: Data do preço | L16: Ativo
A17: 273 | B17: MOE - Alvenarias e Vedações / Mochetas/Shafts | G17: un | J17: 340 | K17: 15/09/2023 | L17: Sim
A18: 300 | B18: MOE - Esquadrias / Rodapés em Madeira, MDF e/ou Poliestireno | G18: m | J18: 13 | K18: 14/05/2024 | L18: Sim
A19: 345 | B19: MOE - Impermeabilizações / Áreas Externas e/ou Descobertas | G19: m2 | J19: 48 | K19: 29/01/2024 | L19: Sim
A20: 346 | B20: MOE - Impermeabilizações / Áreas Técnicas | G20: m2 | J20: 48 | K20: 29/01/2024 | L20: Sim
A21: 351 | B21: MOE - Impermeabilizações / Esquadrias | G21: m | J21: 30 | K21: 29/01/2024 | L21: Sim
A22: 354 | B22: MOE - Impermeabilizações / Piscinas | G22: m2 | J22: 60 | K22: 29/01/2024 | L22: Sim
A23: 355 | B23: MOE - Impermeabilizações / Poço Elevador | G23: m2 | J23: 25 | K23: 29/01/2024 | L23: Sim
A24: 356 | B24: MOE - Impermeabilizações / Proteção Mecânica | G24: m2 | J24: 45 | K24: 29/01/2024 | L24: Sim
A25: 357 | B25: MOE - Impermeabilizações / Reservatórios | G25: m2 | J25: 60 | K25: 29/01/2024 | L25: Sim
A26: 367 | B26: MOE - Infraestrutura-Implantação / Pavimentação em Blocos Intertravados (Paver) | G26: m2 | J26: 15 | K26: 10/11/2021 | L26: Sim
A27: 418 | B27: MOE - Pinturas / Externas (1ª Demão Tinta) | G27: m2 | J27: 11 | K27: 14/05/2024 | L27: Sim
A28: 423 | B28: MOE - Pinturas / Externas (Textura Acrílica) | G28: m2 | J28: 21 | K28: 14/05/2024 | L28: Sim
... A57: 9541 | B57: MOE - Revestimentos Arkwood / Assentamento de Revestimentos Arkwood Externos | G57: m2 | J57: 52 | K57: 15/04/2024 | L57: Sim
A59: Família | D59: 01.003 - MÃO DE OBRA TERCEIRIZADA
A60: Código | B60: Descrição | G60: Unidade | J60: Preço unitário | K60: Data do preço | L60: Ativo
A61: 6308 | B61: Mão de Obra para Pinturas Internas (2ª Demão Tinta) | G61: m2 | J61: 26.48 | K61: 10/10/2023 | L61: Sim
A62: 6313 | B62: Mão de Obra para Pinturas Internas (Fundo Preparador) | G62: m2 | J62: 9.86 | K62: 10/10/2023 | L62: Sim
A63: 6314 | B63: Mão de Obra para Pinturas Internas (Massa Corrida) | G63: m2 | J63: 46.61 | K63: 10/10/2023 | L63: Sim
A64: 6316 | B64: Mão de Obra para Pinturas Internas (Selador) | G64: m2 | J64: 9.86 | K64: 10/10/2023 | L64: Sim
A65: 9109 | B65: MOE - Instalações Hidrossanitárias / Execução Geral | G65: m2 | J65: 35.98 | K65: 14/05/2024 | L65: Sim
A66: 9123 | B66: MOE - Instalações Preventivo (PCI/SPDA) / Execução Geral | G66: m2 | J66: 11.4515 | K66: 10/10/2023 | L66: Sim
A67: 9152 | B67: MOE - Pinturas / Internas | G67: m2 | J67: 30 | K67: 22/04/2024 | L67: Sim
A68: 9470 | B68: Serviço de limpeza e remoção de excedente de solo durante a perfuração das estacas, blocos e baldrames | G68: m3 | J68: 32 | K68: 07/02/2024 | L68: Sim
A69: 9592 | B69: MOE - Revestimentos de Argamassa / Estucagem (com Desconto de Vãos) | G69: m2 | J69: 22 | K69: 22/04/2024 | L69: Sim
A70: 9595 | B70: MOE - Revestimentos de Argamassa / Polimento de Piso para Garagens | G70: m2 | J70: 16.5 | K70: 22/04/2024 | L70: Sim
A71: 9596 | B71: MOE - Pinturas / Internas (Pintura Epóxi em Piso - Incluído Demarcação Vagas Garagem) | G71: m2 | J71: 40 | K71: 22/04/2024 | L71: Sim
A72: 9601 | B72: MOE - Infraestrutura-Implantação / Pavimentação em Concreto Estampado | G72: m2 | J72: 45 | K72: 23/04/2024 | L72: Sim
A73: 9609 | B73: Estimativas / Prova de Carga | G73: vb | J73: 14350 | K73: 23/04/2024 | L73: Sim
A75: Grupo | D75: 02 - MATERIAIS
A76: Família | D76: 02.002 - AGLOMERANTES
...

Sheet Composições
C2: Composições de Serviços da Obra
A5: Obra | E5: 160 - OBRA | TRS Amaro - T4
A6: Unidade construtiva | E6: 3 - Custos Indiretos
A7: BDI | E7: não aplicado | J7: Encargos sociais | L7: não aplicado
A9: Etapa | E9: 001 - * DESPESAS INICIAIS
A10: Subetapa | E10: 001.001 - * TERRENO
A11: Serviço | E11: 9619 - Retificação do terreno | P11: Unidade | R11: vb
L12: Preço total por grupo
A13: Tipo | B13: Código | D13: Descrição | G13: Unidade | I13: Quantidade | K13: Preço unitário | L13: MÃO DE OBRA | N13: MATERIAIS | O13: Equipamentos de Obra | Q13: TERRENO, DESPESAS ADMINISTRATIVAS E CUSTOS INDIRETOS | S13: Preço total
A14: OU | B14: 229 | D14: Terreno / Despesas com Retificações | G14: vb | I14: 1 | K14: 5000 | Q14: 5000 | S14: 5000
A15: Total do serviço | L15: 0 | N15: 0 | O15: 0 | Q15: 5000 | S15: 5000
A16: Percentual por grupo | L16: 0 | N16: 0 | O16: 0 | Q16: 1 | S16: 1
A18: Serviço | E18: 9623 - Compatibilização e aprovação em cartório | P18: Unidade | R18: vb
L19: Preço total por grupo
A20: Tipo | B20: Código | D20: Descrição | G20: Unidade | I20: Quantidade | K20: Preço unitário | L20: MÃO DE OBRA | N20: MATERIAIS | O20: Equipamentos de Obra | Q20: TERRENO, DESPESAS ADMINISTRATIVAS E CUSTOS INDIRETOS | S20: Preço total
A21: OU | B21: 239 | D21: Despesas com Cartórios | G21: vb | I21: 1 | K21: 10000 | Q21: 10000 | S21: 10000
A22: Total do serviço | L22: 0 | N22: 0 | O22: 0 | Q22: 10000 | S22: 10000
A23: Percentual por grupo | L23: 0 | N23: 0 | O23: 0 | Q23: 1 | S23: 1
A25: Subetapa | E25: 001.003 - DOCUMENTAÇÃO REGISTRO DE IMÓVEIS
A26: Serviço | E26: 9616 - TPC | P26: Unidade | R26: vb
L27: Preço total por grupo
A28: Tipo | B28: Código | D28: Descrição | G28: Unidade | I28: Quantidade | K28: Preço unitário | L28: MÃO DE OBRA | N28: MATERIAIS | O28: Equipamentos de Obra | Q28: TERRENO, DESPESAS ADMINISTRATIVAS E CUSTOS INDIRETOS | S28: Preço total
A29: OU | B29: 9618 | D29: TPC - Transf. Potencial Construtivo (Solo Oneroso) | G29: vb | I29: 1 | K29: 350000 | Q29: 350000 | S29: 350000
A30: Total do serviço | L30: 0 | N30: 0 | O30: 0 | Q30: 350000 | S30: 350000
A31: Percentual por grupo | L31: 0 | N31: 0 | O31: 0 | Q31: 1 | S31: 1
A33: Etapa | E33: 003 - * SERVIÇOS TÉCNICOS
A34: Subetapa | E34: 003.004 - CONSULTORIA E ASSESSORIA TÉCNICA
A35: Serviço | E35: 9608 - Estimativas / Prova de Carga | P35: Unidade | R35: vb
L36: Preço total por grupo
A37: Tipo | B37: Código | D37: Descrição | G37: Unidade | I37: Quantidade | K37: Preço unitário | L37: MÃO DE OBRA | N37: MATERIAIS | O37: Equipamentos de Obra | Q37: TERRENO, DESPESAS ADMINISTRATIVAS E CUSTOS INDIRETOS | S37: Preço total
A38: MO | B38: 9609 | D38: Estimativas / Prova de Carga | G38: vb | I38: 1 | K38: 14350 | L38: 14350 | S38: 14350
A39: Total do serviço | L39: 14350 | N39: 0 | O39: 0 | Q39: 0 | S39: 14350
A40: Percentual por grupo | L40: 1 | N40: 0 | O40: 0 | Q40: 0 | S40: 1
A42: Serviço | E42: 9624 - Licenciamentos LAP e LAI | P42: Unidade | R42: vb
L43: Preço total por grupo
A44: Tipo | B44: Código | D44: Descrição | G44: Unidade | I44: Quantidade | K44: Preço unitário | L44: MÃO DE OBRA | N44: MATERIAIS | O44: Equipamentos de Obra | Q44: TERRENO, DESPESAS ADMINISTRATIVAS E CUSTOS INDIRETOS | S44: Preço total
A45: OU | B45: 162 | D45: Licença Ambiental Prévia (LAP) | G45: vb | I45: 1 | K45: 4000 | Q45: 4000 | S45: 4000
A46: Total do serviço | L46: 0 | N46: 0 | O46: 0 | Q46: 4000 | S46: 4000
A47: Percentual por grupo | L47: 0 | N47: 0 | O47: 0 | Q47: 1 | S47: 1
A49: Serviço | E49: 9625 - Impacto de Vizinhança | P49: Unidade | R49: vb
...
