Workbook
Name \0: #REF!
Name \0: #REF!
Name \0: #REF!
Name \0: #REF!
Name \0: #REF!
Name \0: #REF!
Name \0: #REF!
Name \0: #REF!
Name \0: #REF!
Name \0: #REF!
Name \1: #REF!
Name \1: #REF!
Name \1: #REF!
Name \1: #REF!
Name \1: #REF!
Name \a: #REF!
Name \a: #REF!
Name \a: #REF!
Name \a: #REF!
Name \a: #REF!
Name \a: #REF!
Name \a: #REF!
Name \a: #REF!
Name \a: #REF!
Name \a: #REF!
Name \b: #REF!
Name \b: #REF!
Name \b: #REF!
Name \b: #REF!
Name \c: #REF!
Name \c: #REF!
Name \c: #REF!
Name \c: #REF!
Name \d: #REF!
Name \d: #REF!
Name \d: #REF!
Name \d: #REF!
Name \e: #REF!
Name \e: #REF!
Name \e: #REF!
Name \e: #REF!
Name \i: #REF!
Name \i: #REF!
Name \i: #REF!
Name \i: #REF!
Name \J: #REF!
Name \J: #REF!
Name \J: #REF!
Name \J: #REF!
Name \k: #REF!
Name \k: #REF!
Name \k: #REF!
Name \k: #REF!
Name \l: #N/A
Name \m: #REF!
Name \m: #REF!
Name \m: #REF!
Name \m: #REF!
Name \m: #REF!
Name \m: #REF!

Sheet Obra 
C1: Projeto | D1: Marena
C2: Empresa | D2: XPCon
C3: Revisão | D3: R02 - 30/05/2025
A4: QUADRO DE ÁREAS
B6: Descrição | C6: Unidade | E6: Quantidade | G6: Imagens
B7: MESES DE OBRA | C7: MÊS | E7: 33
B8: ÁREA DO TERRENO | C8: M² | E8: 510.3
B9: ÁREA CONSTRUÍDA | C9: M² | E9: =SUM(E14:E22) -> 4174.83
B10: NÚMERO DE UNIDADES HABITACIONAIS | C10: UN | E10: 20
B11: NÚMERO DE UNIDADES COMERCIAIS | C11: UN | E11: 0
B12: ÁREA PRIVATIVA | C12: M² | E12: =(115.77+99.37)*9+196.59+98.64 -> 2231.49
B13: NÚMERO DE PAVIMENTOS | C13: UN | E13: 14
B14: Térreo | C14: M² | E14: 408.18
B15: Garagem G1 | C15: M² | E15: 416.94
B16: Garagem G2 | C16: M² | E16: 416.98
B17: Tipo Diferenciado | C17: M² | E17: 418.34
B18: Tipo (x9) | C18: M² | E18: 2183.13
B19: Rooftop | C19: M² | E19: 240.76
B20: Área Técnica | C20: M² | E20: 22.79
B21: Barrilete | C21: M² | E21: 34.64
B22: Reservatório Superior | C22: M² | E22: 33.07
B25: ETAPA | C25: VALOR ORÇADO | D25: % | E25: VALOR / m²
B26: GERENCIAMENTO TÉCNICO E ADMINISTRATIVO | C26: ='Ger_Tec e Adm'!N118 -> 1863691.2 | D26: =C26/C$44 -> 0.13424095 | E26: =C26/$E$9 -> 446.41128
B27: MOVIMENTAÇÃO DE TERRA | C27: =Ger_Executivo!N8 -> 96431.556 | D27: =C27/C$44 -> 0.0069459275 | E27: =C27/$E$9 -> 23.098319
B28: INFRAESTRUTURA | C28: =Ger_Executivo!N20 -> 1074827.1 | D28: =C28/C$44 -> 0.077419378 | E28: =C28/$E$9 -> 257.4541
B29: SUPRAESTRUTURA | C29: =Ger_Executivo!N48 -> 2805252.8 | D29: =C29/C$44 -> 0.20206127 | E29: =C29/$E$9 -> 671.94421
B30: PAREDES E PAINÉIS | C30: =Ger_Executivo!N230 -> 756309.89 | D30: =C30/C$44 -> 0.054476707 | E30: =C30/$E$9 -> 181.15945
B31: IMPERMEABILIZAÇÃO E TRATAMENTOS | C31: =Ger_Executivo!N349 -> 258270.51 | D31: =C31/C$44 -> 0.018603124 | E31: =C31/$E$9 -> 61.863718
B32: INSTALAÇÕES ELÉTRICAS, HIDRÁULICAS, GLP E PREVENTIVAS | C32: =Ger_Executivo!N440+Ger_Executivo!N521+Ger_Executivo!N647 -> 1561456.8 | D32: =C32/C$44 -> 0.11247113 | E32: =C32/$E$9 -> 374.01687
B33: EQUIPAMENTOS E SISTEMAS ESPECIAIS | C33: =Ger_Executivo!N746+Ger_Executivo!N752 -> 482585.96 | D33: =C33/C$44 -> 0.034760479 | E33: =C33/$E$9 -> 115.59416
B34: REVESTIMENTOS INTERNOS DE PAREDE | C34: =Ger_Executivo!N778 -> 558904.9 | D34: =C34/C$44 -> 0.040257703 | E34: =C34/$E$9 -> 133.87489
B35: REVESTIMENTOS E ACABAMENTOS INTERNOS EM TETO | C35: =Ger_Executivo!N879 -> 267746.82 | D35: =C35/C$44 -> 0.019285699 | E35: =C35/$E$9 -> 64.133585
B36: PISOS E PAVIMENTAÇÕES | C36: =Ger_Executivo!N935 -> 695036.52 | D36: =C36/C$44 -> 0.05006321 | E36: =C36/$E$9 -> 166.48259
B37: SISTEMAS DE PINTURA INTERNA | C37: =Ger_Executivo!N1048 -> 489145.93 | D37: =C37/C$44 -> 0.035232991 | E37: =C37/$E$9 -> 117.16547
B38: ESQUADRIAS, VIDROS E FERRAGENS | C38: =Ger_Executivo!N1190 -> 1270747.8 | D38: =C38/C$44 -> 0.091531469 | E38: =C38/$E$9 -> 304.38312
B39: LOUÇAS E METAIS | C39: =Ger_Executivo!N1310 -> 170550.25 | D39: =C39/C$44 -> 0.012284668 | E39: =C39/$E$9 -> 40.852023
B40: COBERTURA | C40: =Ger_Executivo!N1345 -> 108775.43 | D40: =C40/C$44 -> 0.007835052 | E40: =C40/$E$9 -> 26.055057
B41: REVESTIMENTOS E ACABAMENTOS DE FACHADA | C41: =Ger_Executivo!N1358 -> 561394.15 | D41: =C41/C$44 -> 0.040437002 | E41: =C41/$E$9 -> 134.47114
B42: SERVIÇOS COMPLEMENTARES | C42: =Ger_Executivo!N1381 -> 743046.77 | D42: =C42/C$44 -> 0.05352137 | E42: =C42/$E$9 -> 177.98252
B43: IMPREVISTOS E CONTINGÊNCIAS | C43: =Ger_Executivo!N1402 -> 119004.83 | D43: =C43/C$44 -> 0.0085718718 | E43: =C43/$E$9 -> 28.505312
...

Sheet Ger_Tec e Adm
G4: PROJETO: | I4: ='Obra '!D1 -> Marena | O4: REVISÃO: | P4: DATA
G5: EMPRESA: | I5: ='Obra '!D2 -> XPCon | O5: ='Obra '!D3 -> R02 - 30/05/2025 | P5: 45336
A6: Unidade Construtiva | B6: Célula Construtiva | C6: Etapa | D6: Subetapa | E6: Serviço | G6: GERENCIAMENTO EXECUTIVO
A7: 0 | B7: 0 | C7: 0 | D7: 0 | E7: 0 | G7: Atalho | H7: NIVEL | I7: Item | J7: Descrição | K7: Unidade | L7: Quant. | M7: Preço un | N7: Total | O7: Considerações | P7: Situação
A8: =IF($H8="UNIDADE CONSTRUTIVA",OFFSET(A8,-1,0)+1,LARGE(A$3:A7,1)) -> 0 | B8: =IF(H8="UNIDADE CONSTRUTIVA",0,IF(H8="CÉLULA CONSTRUTIVA",OFFSET(B8,-1,0)+1,OFFSET(B8,-1,0))) -> 1 | C8: =IF(H8="CÉLULA CONSTRUTIVA",0,IF(H8="ETAPA",OFFSET(C8,-1,0)+1,OFFSET(C8,-1,0))) -> 0 | D8: =IF(H8="ETAPA",0,IF(H8="SUBETAPA",OFFSET(D8,-1,0)+1,OFFSET(D8,-1,0))) -> 0 | E8: =IF(H8="Subetapa",0,IF(H8="serviço",OFFSET(E8,-1,0)+1,OFFSET(E8,-1,0))) -> 0 | H8: CÉLULA CONSTRUTIVA | I8: =IF(H8="Unidade Construtiva",TEXT(A8,"00"),IF(H8="Célula Construtiva",TEXT(B8,"00"),IF(H8="Etapa",CONCATENATE(TEXT(B8,"00"),".",TEXT(C8,"000")),IF(H8="Subetapa",CONCATENATE(TEXT(B8,"00"),".",TEXT(C8,"000"),".",TEXT(D8,"000")),IF(H8="Serviço",CONCATENATE(TEXT(B8,"00"),".",TEXT(C8,"000"),".",TEXT(D8,"000"),".",TEXT(E8,"000")),""))))) -> 01 | J8: SERVIÇOS TÉCNICOS | N8: =IF(H8="Serviço",M8*L8,IF(H8="CÉLULA CONSTRUTIVA",SUMIFS($N$8:$N$415,$B$8:$B$415,B8,$H$8:$H$415,"Serviço"),IF(H8="ETAPA",SUMIFS($N$8:$N$415,$B$8:$B$415,B8,$C$8:$C$415,C8,$H$8:$H$415,"Serviço"),IF(H8="SUBETAPA",SUMIFS($N$8:$N$415,$B$8:$B$415,B8,$C$8:$C$415,C8,$D$8:$D$415,D8,$H$8:$H$415,"Serviço"),0)))) -> 410864.82 | P8: -
A9: =IF($H9="UNIDADE CONSTRUTIVA",OFFSET(A9,-1,0)+1,LARGE(A$3:A8,1)) -> 0 | B9: =IF(H9="UNIDADE CONSTRUTIVA",0,IF(H9="CÉLULA CONSTRUTIVA",OFFSET(B9,-1,0)+1,OFFSET(B9,-1,0))) -> 1 | C9: =IF(H9="CÉLULA CONSTRUTIVA",0,IF(H9="ETAPA",OFFSET(C9,-1,0)+1,OFFSET(C9,-1,0))) -> 1 | D9: =IF(H9="ETAPA",0,IF(H9="SUBETAPA",OFFSET(D9,-1,0)+1,OFFSET(D9,-1,0))) -> 0 | E9: =IF(H9="Subetapa",0,IF(H9="serviço",OFFSET(E9,-1,0)+1,OFFSET(E9,-1,0))) -> 0 | H9: ETAPA | I9: =IF(H9="Unidade Construtiva",TEXT(A9,"00"),IF(H9="Célula Construtiva",TEXT(B9,"00"),IF(H9="Etapa",CONCATENATE(TEXT(B9,"00"),".",TEXT(C9,"000")),IF(H9="Subetapa",CONCATENATE(TEXT(B9,"00"),".",TEXT(C9,"000"),".",TEXT(D9,"000")),IF(H9="Serviço",CONCATENATE(TEXT(B9,"00"),".",TEXT(C9,"000"),".",TEXT(D9,"000"),".",TEXT(E9,"000")),""))))) -> 01.001 | J9: ESTUDOS, PROJETOS, CONSULTORIA E ENSAIOS | N9: =IF(H9="Serviço",M9*L9,IF(H9="CÉLULA CONSTRUTIVA",SUMIFS($N$8:$N$415,$B$8:$B$415,B9,$H$8:$H$415,"Serviço"),IF(H9="ETAPA",SUMIFS($N$8:$N$415,$B$8:$B$415,B9,$C$8:$C$415,C9,$H$8:$H$415,"Serviço"),IF(H9="SUBETAPA",SUMIFS($N$8:$N$415,$B$8:$B$415,B9,$C$8:$C$415,C9,$D$8:$D$415,D9,$H$8:$H$415,"Serviço"),0)))) -> 297869.38 | P9: -
A10: =IF($H10="UNIDADE CONSTRUTIVA",OFFSET(A10,-1,0)+1,LARGE(A$3:A9,1)) -> 0 | B10: =IF(H10="UNIDADE CONSTRUTIVA",0,IF(H10="CÉLULA CONSTRUTIVA",OFFSET(B10,-1,0)+1,OFFSET(B10,-1,0))) -> 1 | C10: =IF(H10="CÉLULA CONSTRUTIVA",0,IF(H10="ETAPA",OFFSET(C10,-1,0)+1,OFFSET(C10,-1,0))) -> 1 | D10: =IF(H10="ETAPA",0,IF(H10="SUBETAPA",OFFSET(D10,-1,0)+1,OFFSET(D10,-1,0))) -> 1 | E10: =IF(H10="Subetapa",0,IF(H10="serviço",OFFSET(E10,-1,0)+1,OFFSET(E10,-1,0))) -> 0 | H10: SUBETAPA | I10: =IF(H10="Unidade Construtiva",TEXT(A10,"00"),IF(H10="Célula Construtiva",TEXT(B10,"00"),IF(H10="Etapa",CONCATENATE(TEXT(B10,"00"),".",TEXT(C10,"000")),IF(H10="Subetapa",CONCATENATE(TEXT(B10,"00"),".",TEXT(C10,"000"),".",TEXT(D10,"000")),IF(H10="Serviço",CONCATENATE(TEXT(B10,"00"),".",TEXT(C10,"000"),".",TEXT(D10,"000"),".",TEXT(E10,"000")),""))))) -> 01.001.001 | J10: Estudos | N10: =IF(H10="Serviço",M10*L10,IF(H10="CÉLULA CONSTRUTIVA",SUMIFS($N$8:$N$415,$B$8:$B$415,B10,$H$8:$H$415,"Serviço"),IF(H10="ETAPA",SUMIFS($N$8:$N$415,$B$8:$B$415,B10,$C$8:$C$415,C10,$H$8:$H$415,"Serviço"),IF(H10="SUBETAPA",SUMIFS($N$8:$N$415,$B$8:$B$415,B10,$C$8:$C$415,C10,$D$8:$D$415,D10,$H$8:$H$415,"Serviço"),0)))) -> 34545.667
A11: =IF($H11="UNIDADE CONSTRUTIVA",OFFSET(A11,-1,0)+1,LARGE(A$3:A10,1)) -> 0 | B11: =IF(H11="UNIDADE CONSTRUTIVA",0,IF(H11="CÉLULA CONSTRUTIVA",OFFSET(B11,-1,0)+1,OFFSET(B11,-1,0))) -> 1 | C11: =IF(H11="CÉLULA CONSTRUTIVA",0,IF(H11="ETAPA",OFFSET(C11,-1,0)+1,OFFSET(C11,-1,0))) -> 1 | D11: =IF(H11="ETAPA",0,IF(H11="SUBETAPA",OFFSET(D11,-1,0)+1,OFFSET(D11,-1,0))) -> 1 | E11: =IF(H11="Subetapa",0,IF(H11="serviço",OFFSET(E11,-1,0)+1,OFFSET(E11,-1,0))) -> 1 | H11: SERVIÇO | I11: =IF(H11="Unidade Construtiva",TEXT(A11,"00"),IF(H11="Célula Construtiva",TEXT(B11,"00"),IF(H11="Etapa",CONCATENATE(TEXT(B11,"00"),".",TEXT(C11,"000")),IF(H11="Subetapa",CONCATENATE(TEXT(B11,"00"),".",TEXT(C11,"000"),".",TEXT(D11,"000")),IF(H11="Serviço",CONCATENATE(TEXT(B11,"00"),".",TEXT(C11,"000"),".",TEXT(D11,"000"),".",TEXT(E11,"000")),""))))) -> 01.001.001.001 | J11: Memorial descritivo | K11: vb | L11: 1 | M11: 2045.6667 | N11: =IF(H11="Serviço",M11*L11,IF(H11="CÉLULA CONSTRUTIVA",SUMIFS($N$8:$N$415,$B$8:$B$415,B11,$H$8:$H$415,"Serviço"),IF(H11="ETAPA",SUMIFS($N$8:$N$415,$B$8:$B$415,B11,$C$8:$C$415,C11,$H$8:$H$415,"Serviço"),IF(H11="SUBETAPA",SUMIFS($N$8:$N$415,$B$8:$B$415,B11,$C$8:$C$415,C11,$D$8:$D$415,D11,$H$8:$H$415,"Serviço"),0)))) -> 2045.6667 | O11: Estimado com base em índices históricos | P11: Finalizado
A12: =IF($H12="UNIDADE CONSTRUTIVA",OFFSET(A12,-1,0)+1,LARGE(A$3:A11,1)) -> 0 | B12: =IF(H12="UNIDADE CONSTRUTIVA",0,IF(H12="CÉLULA CONSTRUTIVA",OFFSET(B12,-1,0)+1,OFFSET(B12,-1,0))) -> 1 | C12: =IF(H12="CÉLULA CONSTRUTIVA",0,IF(H12="ETAPA",OFFSET(C12,-1,0)+1,OFFSET(C12,-1,0))) -> 1 | D12: =IF(H12="ETAPA",0,IF(H12="SUBETAPA",OFFSET(D12,-1,0)+1,OFFSET(D12,-1,0))) -> 1 | E12: =IF(H12="Subetapa",0,IF(H12="serviço",OFFSET(E12,-1,0)+1,OFFSET(E12,-1,0))) -> 2 | H12: SERVIÇO | I12: =IF(H12="Unidade Construtiva",TEXT(A12,"00"),IF(H12="Célula Construtiva",TEXT(B12,"00"),IF(H12="Etapa",CONCATENATE(TEXT(B12,"00"),".",TEXT(C12,"000")),IF(H12="Subetapa",CONCATENATE(TEXT(B12,"00"),".",TEXT(C12,"000"),".",TEXT(D12,"000")),IF(H12="Serviço",CONCATENATE(TEXT(B12,"00"),".",TEXT(C12,"000"),".",TEXT(D12,"000"),".",TEXT(E12,"000")),""))))) -> 01.001.001.002 | J12: Levantamento Topográfico | K12: vb | L12: 1 | M12: 3000 | N12: =IF(H12="Serviço",M12*L12,IF(H12="CÉLULA CONSTRUTIVA",SUMIFS($N$8:$N$415,$B$8:$B$415,B12,$H$8:$H$415,"Serviço"),IF(H12="ETAPA",SUMIFS($N$8:$N$415,$B$8:$B$415,B12,$C$8:$C$415,C12,$H$8:$H$415,"Serviço"),IF(H12="SUBETAPA",SUMIFS($N$8:$N$415,$B$8:$B$415,B12,$C$8:$C$415,C12,$D$8:$D$415,D12,$H$8:$H$415,"Serviço"),0)))) -> 3000 | O12: Valor informado em formulário | P12: Finalizado
A13: =IF($H13="UNIDADE CONSTRUTIVA",OFFSET(A13,-1,0)+1,LARGE(A$3:A12,1)) -> 0 | B13: =IF(H13="UNIDADE CONSTRUTIVA",0,IF(H13="CÉLULA CONSTRUTIVA",OFFSET(B13,-1,0)+1,OFFSET(B13,-1,0))) -> 1 | C13: =IF(H13="CÉLULA CONSTRUTIVA",0,IF(H13="ETAPA",OFFSET(C13,-1,0)+1,OFFSET(C13,-1,0))) -> 1 | D13: =IF(H13="ETAPA",0,IF(H13="SUBETAPA",OFFSET(D13,-1,0)+1,OFFSET(D13,-1,0))) -> 1 | E13: =IF(H13="Subetapa",0,IF(H13="serviço",OFFSET(E13,-1,0)+1,OFFSET(E13,-1,0))) -> 3 | H13: SERVIÇO | I13: =IF(H13="Unidade Construtiva",TEXT(A13,"00"),IF(H13="Célula Construtiva",TEXT(B13,"00"),IF(H13="Etapa",CONCATENATE(TEXT(B13,"00"),".",TEXT(C13,"000")),IF(H13="Subetapa",CONCATENATE(TEXT(B13,"00"),".",TEXT(C13,"000"),".",TEXT(D13,"000")),IF(H13="Serviço",CONCATENATE(TEXT(B13,"00"),".",TEXT(C13,"000"),".",TEXT(D13,"000"),".",TEXT(E13,"000")),""))))) -> 01.001.001.003 | J13: Estudo ambiental | K13: vb | L13: 1 | M13: 22000 | N13: =IF(H13="Serviço",M13*L13,IF(H13="CÉLULA CONSTRUTIVA",SUMIFS($N$8:$N$415,$B$8:$B$415,B13,$H$8:$H$415,"Serviço"),IF(H13="ETAPA",SUMIFS($N$8:$N$415,$B$8:$B$415,B13,$C$8:$C$415,C13,$H$8:$H$415,"Serviço"),IF(H13="SUBETAPA",SUMIFS($N$8:$N$415,$B$8:$B$415,B13,$C$8:$C$415,C13,$D$8:$D$415,D13,$H$8:$H$415,"Serviço"),0)))) -> 22000 | O13: Valor informado em formulário | P13: Finalizado
A14: =IF($H14="UNIDADE CONSTRUTIVA",OFFSET(A14,-1,0)+1,LARGE(A$3:A13,1)) -> 0 | B14: =IF(H14="UNIDADE CONSTRUTIVA",0,IF(H14="CÉLULA CONSTRUTIVA",OFFSET(B14,-1,0)+1,OFFSET(B14,-1,0))) -> 1 | C14: =IF(H14="CÉLULA CONSTRUTIVA",0,IF(H14="ETAPA",OFFSET(C14,-1,0)+1,OFFSET(C14,-1,0))) -> 1 | D14: =IF(H14="ETAPA",0,IF(H14="SUBETAPA",OFFSET(D14,-1,0)+1,OFFSET(D14,-1,0))) -> 1 | E14: =IF(H14="Subetapa",0,IF(H14="serviço",OFFSET(E14,-1,0)+1,OFFSET(E14,-1,0))) -> 4 | H14: SERVIÇO | I14: =IF(H14="Unidade Construtiva",TEXT(A14,"00"),IF(H14="Célula Construtiva",TEXT(B14,"00"),IF(H14="Etapa",CONCATENATE(TEXT(B14,"00"),".",TEXT(C14,"000")),IF(H14="Subetapa",CONCATENATE(TEXT(B14,"00"),".",TEXT(C14,"000"),".",TEXT(D14,"000")),IF(H14="Serviço",CONCATENATE(TEXT(B14,"00"),".",TEXT(C14,"000"),".",TEXT(D14,"000"),".",TEXT(E14,"000")),""))))) -> 01.001.001.004 | J14: Sondagem do terreno | K14: vb | L14: 1 | M14: 7500 | N14: =IF(H14="Serviço",M14*L14,IF(H14="CÉLULA CONSTRUTIVA",SUMIFS($N$8:$N$415,$B$8:$B$415,B14,$H$8:$H$415,"Serviço"),IF(H14="ETAPA",SUMIFS($N$8:$N$415,$B$8:$B$415,B14,$C$8:$C$415,C14,$H$8:$H$415,"Serviço"),IF(H14="SUBETAPA",SUMIFS($N$8:$N$415,$B$8:$B$415,B14,$C$8:$C$415,C14,$D$8:$D$415,D14,$H$8:$H$415,"Serviço"),0)))) -> 7500 | O14: Valor informado em formulário | P14: Finalizado
A15: =IF($H15="UNIDADE CONSTRUTIVA",OFFSET(A15,-1,0)+1,LARGE(A$3:A14,1)) -> 0 | B15: =IF(H15="UNIDADE CONSTRUTIVA",0,IF(H15="CÉLULA CONSTRUTIVA",OFFSET(B15,-1,0)+1,OFFSET(B15,-1,0))) -> 1 | C15: =IF(H15="CÉLULA CONSTRUTIVA",0,IF(H15="ETAPA",OFFSET(C15,-1,0)+1,OFFSET(C15,-1,0))) -> 1 | D15: =IF(H15="ETAPA",0,IF(H15="SUBETAPA",OFFSET(D15,-1,0)+1,OFFSET(D15,-1,0))) -> 2 | E15: =IF(H15="Subetapa",0,IF(H15="serviço",OFFSET(E15,-1,0)+1,OFFSET(E15,-1,0))) -> 0 | H15: SUBETAPA | I15: =IF(H15="Unidade Construtiva",TEXT(A15,"00"),IF(H15="Célula Construtiva",TEXT(B15,"00"),IF(H15="Etapa",CONCATENATE(TEXT(B15,"00"),".",TEXT(C15,"000")),IF(H15="Subetapa",CONCATENATE(TEXT(B15,"00"),".",TEXT(C15,"000"),".",TEXT(D15,"000")),IF(H15="Serviço",CONCATENATE(TEXT(B15,"00"),".",TEXT(C15,"000"),".",TEXT(D15,"000"),".",TEXT(E15,"000")),""))))) -> 01.001.002 | J15: Projetos | N15: =IF(H15="Serviço",M15*L15,IF(H15="CÉLULA CONSTRUTIVA",SUMIFS($N$8:$N$415,$B$8:$B$415,B15,$H$8:$H$415,"Serviço"),IF(H15="ETAPA",SUMIFS($N$8:$N$415,$B$8:$B$415,B15,$C$8:$C$415,C15,$H$8:$H$415,"Serviço"),IF(H15="SUBETAPA",SUMIFS($N$8:$N$415,$B$8:$B$415,B15,$C$8:$C$415,C15,$D$8:$D$415,D15,$H$8:$H$415,"Serviço"),0)))) -> 208968.66
A16: =IF($H16="UNIDADE CONSTRUTIVA",OFFSET(A16,-1,0)+1,LARGE(A$3:A15,1)) -> 0 | B16: =IF(H16="UNIDADE CONSTRUTIVA",0,IF(H16="CÉLULA CONSTRUTIVA",OFFSET(B16,-1,0)+1,OFFSET(B16,-1,0))) -> 1 | C16: =IF(H16="CÉLULA CONSTRUTIVA",0,IF(H16="ETAPA",OFFSET(C16,-1,0)+1,OFFSET(C16,-1,0))) -> 1 | D16: =IF(H16="ETAPA",0,IF(H16="SUBETAPA",OFFSET(D16,-1,0)+1,OFFSET(D16,-1,0))) -> 2 | E16: =IF(H16="Subetapa",0,IF(H16="serviço",OFFSET(E16,-1,0)+1,OFFSET(E16,-1,0))) -> 1 | H16: SERVIÇO | I16: =IF(H16="Unidade Construtiva",TEXT(A16,"00"),IF(H16="Célula Construtiva",TEXT(B16,"00"),IF(H16="Etapa",CONCATENATE(TEXT(B16,"00"),".",TEXT(C16,"000")),IF(H16="Subetapa",CONCATENATE(TEXT(B16,"00"),".",TEXT(C16,"000"),".",TEXT(D16,"000")),IF(H16="Serviço",CONCATENATE(TEXT(B16,"00"),".",TEXT(C16,"000"),".",TEXT(D16,"000"),".",TEXT(E16,"000")),""))))) -> 01.001.002.001 | J16: Legalização de incorporação | K16: vb | L16: 1 | M16: 6000 | N16: =IF(H16="Serviço",M16*L16,IF(H16="CÉLULA CONSTRUTIVA",SUMIFS($N$8:$N$415,$B$8:$B$415,B16,$H$8:$H$415,"Serviço"),IF(H16="ETAPA",SUMIFS($N$8:$N$415,$B$8:$B$415,B16,$C$8:$C$415,C16,$H$8:$H$415,"Serviço"),IF(H16="SUBETAPA",SUMIFS($N$8:$N$415,$B$8:$B$415,B16,$C$8:$C$415,C16,$D$8:$D$415,D16,$H$8:$H$415,"Serviço"),0)))) -> 6000 | O16: Valor informado em formulário | P16: Finalizado
A17: =IF($H17="UNIDADE CONSTRUTIVA",OFFSET(A17,-1,0)+1,LARGE(A$3:A16,1)) -> 0 | B17: =IF(H17="UNIDADE CONSTRUTIVA",0,IF(H17="CÉLULA CONSTRUTIVA",OFFSET(B17,-1,0)+1,OFFSET(B17,-1,0))) -> 1 | C17: =IF(H17="CÉLULA CONSTRUTIVA",0,IF(H17="ETAPA",OFFSET(C17,-1,0)+1,OFFSET(C17,-1,0))) -> 1 | D17: =IF(H17="ETAPA",0,IF(H17="SUBETAPA",OFFSET(D17,-1,0)+1,OFFSET(D17,-1,0))) -> 2 | E17: =IF(H17="Subetapa",0,IF(H17="serviço",OFFSET(E17,-1,0)+1,OFFSET(E17,-1,0))) -> 2 | H17: SERVIÇO | I17: =IF(H17="Unidade Construtiva",TEXT(A17,"00"),IF(H17="Célula Construtiva",TEXT(B17,"00"),IF(H17="Etapa",CONCATENATE(TEXT(B17,"00"),".",TEXT(C17,"000")),IF(H17="Subetapa",CONCATENATE(TEXT(B17,"00"),".",TEXT(C17,"000"),".",TEXT(D17,"000")),IF(H17="Serviço",CONCATENATE(TEXT(B17,"00"),".",TEXT(C17,"000"),".",TEXT(D17,"000"),".",TEXT(E17,"000")),""))))) -> 01.001.002.002 | J17: Projeto Arquitetônico legal | K17: vb | L17: 1 | M17: 26750 | N17: =IF(H17="Serviço",M17*L17,IF(H17="CÉLULA CONSTRUTIVA",SUMIFS($N$8:$N$415,$B$8:$B$415,B17,$H$8:$H$415,"Serviço"),IF(H17="ETAPA",SUMIFS($N$8:$N$415,$B$8:$B$415,B17,$C$8:$C$415,C17,$H$8:$H$415,"Serviço"),IF(H17="SUBETAPA",SUMIFS($N$8:$N$415,$B$8:$B$415,B17,$C$8:$C$415,C17,$D$8:$D$415,D17,$H$8:$H$415,"Serviço"),0)))) -> 26750 | O17: Valor informado em formulário | P17: Finalizado
A18: =IF($H18="UNIDADE CONSTRUTIVA",OFFSET(A18,-1,0)+1,LARGE(A$3:A17,1)) -> 0 | B18: =IF(H18="UNIDADE CONSTRUTIVA",0,IF(H18="CÉLULA CONSTRUTIVA",OFFSET(B18,-1,0)+1,OFFSET(B18,-1,0))) -> 1 | C18: =IF(H18="CÉLULA CONSTRUTIVA",0,IF(H18="ETAPA",OFFSET(C18,-1,0)+1,OFFSET(C18,-1,0))) -> 1 | D18: =IF(H18="ETAPA",0,IF(H18="SUBETAPA",OFFSET(D18,-1,0)+1,OFFSET(D18,-1,0))) -> 2 | E18: =IF(H18="Subetapa",0,IF(H18="serviço",OFFSET(E18,-1,0)+1,OFFSET(E18,-1,0))) -> 3 | H18: SERVIÇO | I18: =IF(H18="Unidade Construtiva",TEXT(A18,"00"),IF(H18="Célula Construtiva",TEXT(B18,"00"),IF(H18="Etapa",CONCATENATE(TEXT(B18,"00"),".",TEXT(C18,"000")),IF(H18="Subetapa",CONCATENATE(TEXT(B18,"00"),".",TEXT(C18,"000"),".",TEXT(D18,"000")),IF(H18="Serviço",CONCATENATE(TEXT(B18,"00"),".",TEXT(C18,"000"),".",TEXT(D18,"000"),".",TEXT(E18,"000")),""))))) -> 01.001.002.003 | J18: Projeto Arquitetônico Executivo | K18: vb | L18: 1 | M18: 26750 | N18: =IF(H18="Serviço",M18*L18,IF(H18="CÉLULA CONSTRUTIVA",SUMIFS($N$8:$N$415,$B$8:$B$415,B18,$H$8:$H$415,"Serviço"),IF(H18="ETAPA",SUMIFS($N$8:$N$415,$B$8:$B$415,B18,$C$8:$C$415,C18,$H$8:$H$415,"Serviço"),IF(H18="SUBETAPA",SUMIFS($N$8:$N$415,$B$8:$B$415,B18,$C$8:$C$415,C18,$D$8:$D$415,D18,$H$8:$H$415,"Serviço"),0)))) -> 26750 | O18: Valor informado em formulário | P18: Finalizado
A19: =IF($H19="UNIDADE CONSTRUTIVA",OFFSET(A19,-1,0)+1,LARGE(A$3:A18,1)) -> 0 | B19: =IF(H19="UNIDADE CONSTRUTIVA",0,IF(H19="CÉLULA CONSTRUTIVA",OFFSET(B19,-1,0)+1,OFFSET(B19,-1,0))) -> 1 | C19: =IF(H19="CÉLULA CONSTRUTIVA",0,IF(H19="ETAPA",OFFSET(C19,-1,0)+1,OFFSET(C19,-1,0))) -> 1 | D19: =IF(H19="ETAPA",0,IF(H19="SUBETAPA",OFFSET(D19,-1,0)+1,OFFSET(D19,-1,0))) -> 2 | E19: =IF(H19="Subetapa",0,IF(H19="serviço",OFFSET(E19,-1,0)+1,OFFSET(E19,-1,0))) -> 4 | H19: SERVIÇO | I19: =IF(H19="Unidade Construtiva",TEXT(A19,"00"),IF(H19="Célula Construtiva",TEXT(B19,"00"),IF(H19="Etapa",CONCATENATE(TEXT(B19,"00"),".",TEXT(C19,"000")),IF(H19="Subetapa",CONCATENATE(TEXT(B19,"00"),".",TEXT(C19,"000"),".",TEXT(D19,"000")),IF(H19="Serviço",CONCATENATE(TEXT(B19,"00"),".",TEXT(C19,"000"),".",TEXT(D19,"000"),".",TEXT(E19,"000")),""))))) -> 01.001.002.004 | J19: Projeto arquitetônico interiores/ambientação/fachada | K19: vb | L19: 1 | M19: 34000 | N19: =IF(H19="Serviço",M19*L19,IF(H19="CÉLULA CONSTRUTIVA",SUMIFS($N$8:$N$415,$B$8:$B$415,B19,$H$8:$H$415,"Serviço"),IF(H19="ETAPA",SUMIFS($N$8:$N$415,$B$8:$B$415,B19,$C$8:$C$415,C19,$H$8:$H$415,"Serviço"),IF(H19="SUBETAPA",SUMIFS($N$8:$N$415,$B$8:$B$415,B19,$C$8:$C$415,C19,$D$8:$D$415,D19,$H$8:$H$415,"Serviço"),0)))) -> 34000 | O19: Valor informado em formulário | P19: Finalizado
A20: =IF($H20="UNIDADE CONSTRUTIVA",OFFSET(A20,-1,0)+1,LARGE(A$3:A19,1)) -> 0 | B20: =IF(H20="UNIDADE CONSTRUTIVA",0,IF(H20="CÉLULA CONSTRUTIVA",OFFSET(B20,-1,0)+1,OFFSET(B20,-1,0))) -> 1 | C20: =IF(H20="CÉLULA CONSTRUTIVA",0,IF(H20="ETAPA",OFFSET(C20,-1,0)+1,OFFSET(C20,-1,0))) -> 1 | D20: =IF(H20="ETAPA",0,IF(H20="SUBETAPA",OFFSET(D20,-1,0)+1,OFFSET(D20,-1,0))) -> 2 | E20: =IF(H20="Subetapa",0,IF(H20="serviço",OFFSET(E20,-1,0)+1,OFFSET(E20,-1,0))) -> 5 | H20: SERVIÇO | I20: =IF(H20="Unidade Construtiva",TEXT(A20,"00"),IF(H20="Célula Construtiva",TEXT(B20,"00"),IF(H20="Etapa",CONCATENATE(TEXT(B20,"00"),".",TEXT(C20,"000")),IF(H20="Subetapa",CONCATENATE(TEXT(B20,"00"),".",TEXT(C20,"000"),".",TEXT(D20,"000")),IF(H20="Serviço",CONCATENATE(TEXT(B20,"00"),".",TEXT(C20,"000"),".",TEXT(D20,"000"),".",TEXT(E20,"000")),""))))) -> 01.001.002.005 | J20: Projeto de Fundação | K20: vb | L20: 1 | M20: 8500 | N20: =IF(H20="Serviço",M20*L20,IF(H20="CÉLULA CONSTRUTIVA",SUMIFS($N$8:$N$415,$B$8:$B$415,B20,$H$8:$H$415,"Serviço"),IF(H20="ETAPA",SUMIFS($N$8:$N$415,$B$8:$B$415,B20,$C$8:$C$415,C20,$H$8:$H$415,"Serviço"),IF(H20="SUBETAPA",SUMIFS($N$8:$N$415,$B$8:$B$415,B20,$C$8:$C$415,C20,$D$8:$D$415,D20,$H$8:$H$415,"Serviço"),0)))) -> 8500 | O20: Valor informado em formulário | P20: Finalizado
A21: =IF($H21="UNIDADE CONSTRUTIVA",OFFSET(A21,-1,0)+1,LARGE(A$3:A20,1)) -> 0 | B21: =IF(H21="UNIDADE CONSTRUTIVA",0,IF(H21="CÉLULA CONSTRUTIVA",OFFSET(B21,-1,0)+1,OFFSET(B21,-1,0))) -> 1 | C21: =IF(H21="CÉLULA CONSTRUTIVA",0,IF(H21="ETAPA",OFFSET(C21,-1,0)+1,OFFSET(C21,-1,0))) -> 1 | D21: =IF(H21="ETAPA",0,IF(H21="SUBETAPA",OFFSET(D21,-1,0)+1,OFFSET(D21,-1,0))) -> 2 | E21: =IF(H21="Subetapa",0,IF(H21="serviço",OFFSET(E21,-1,0)+1,OFFSET(E21,-1,0))) -> 6 | H21: SERVIÇO | I21: =IF(H21="Unidade Construtiva",TEXT(A21,"00"),IF(H21="Célula Construtiva",TEXT(B21,"00"),IF(H21="Etapa",CONCATENATE(TEXT(B21,"00"),".",TEXT(C21,"000")),IF(H21="Subetapa",CONCATENATE(TEXT(B21,"00"),".",TEXT(C21,"000"),".",TEXT(D21,"000")),IF(H21="Serviço",CONCATENATE(TEXT(B21,"00"),".",TEXT(C21,"000"),".",TEXT(D21,"000"),".",TEXT(E21,"000")),""))))) -> 01.001.002.006 | J21: Projeto Estrutura | K21: vb | L21: 1 | M21: 37600 | N21: =IF(H21="Serviço",M21*L21,IF(H21="CÉLULA CONSTRUTIVA",SUMIFS($N$8:$N$415,$B$8:$B$415,B21,$H$8:$H$415,"Serviço"),IF(H21="ETAPA",SUMIFS($N$8:$N$415,$B$8:$B$415,B21,$C$8:$C$415,C21,$H$8:$H$415,"Serviço"),IF(H21="SUBETAPA",SUMIFS($N$8:$N$415,$B$8:$B$415,B21,$C$8:$C$415,C21,$D$8:$D$415,D21,$H$8:$H$415,"Serviço"),0)))) -> 37600 | O21: Valor informado em formulário | P21: Finalizado
A22: =IF($H22="UNIDADE CONSTRUTIVA",OFFSET(A22,-1,0)+1,LARGE(A$3:A21,1)) -> 0 | B22: =IF(H22="UNIDADE CONSTRUTIVA",0,IF(H22="CÉLULA CONSTRUTIVA",OFFSET(B22,-1,0)+1,OFFSET(B22,-1,0))) -> 1 | C22: =IF(H22="CÉLULA CONSTRUTIVA",0,IF(H22="ETAPA",OFFSET(C22,-1,0)+1,OFFSET(C22,-1,0))) -> 1 | D22: =IF(H22="ETAPA",0,IF(H22="SUBETAPA",OFFSET(D22,-1,0)+1,OFFSET(D22,-1,0))) -> 2 | E22: =IF(H22="Subetapa",0,IF(H22="serviço",OFFSET(E22,-1,0)+1,OFFSET(E22,-1,0))) -> 7 | H22: SERVIÇO | I22: =IF(H22="Unidade Construtiva",TEXT(A22,"00"),IF(H22="Célula Construtiva",TEXT(B22,"00"),IF(H22="Etapa",CONCATENATE(TEXT(B22,"00"),".",TEXT(C22,"000")),IF(H22="Subetapa",CONCATENATE(TEXT(B22,"00"),".",TEXT(C22,"000"),".",TEXT(D22,"000")),IF(H22="Serviço",CONCATENATE(TEXT(B22,"00"),".",TEXT(C22,"000"),".",TEXT(D22,"000"),".",TEXT(E22,"000")),""))))) -> 01.001.002.007 | J22: Projeto elétrico/comunicação/telefonia/luminotécnico | K22: vb | L22: 1 | M22: 24600 | N22: =IF(H22="Serviço",M22*L22,IF(H22="CÉLULA CONSTRUTIVA",SUMIFS($N$8:$N$415,$B$8:$B$415,B22,$H$8:$H$415,"Serviço"),IF(H22="ETAPA",SUMIFS($N$8:$N$415,$B$8:$B$415,B22,$C$8:$C$415,C22,$H$8:$H$415,"Serviço"),IF(H22="SUBETAPA",SUMIFS($N$8:$N$415,$B$8:$B$415,B22,$C$8:$C$415,C22,$D$8:$D$415,D22,$H$8:$H$415,"Serviço"),0)))) -> 24600 | O22: Valor informado em formulário | P22: Finalizado
A23: =IF($H23="UNIDADE CONSTRUTIVA",OFFSET(A23,-1,0)+1,LARGE(A$3:A22,1)) -> 0 | B23: =IF(H23="UNIDADE CONSTRUTIVA",0,IF(H23="CÉLULA CONSTRUTIVA",OFFSET(B23,-1,0)+1,OFFSET(B23,-1,0))) -> 1 | C23: =IF(H23="CÉLULA CONSTRUTIVA",0,IF(H23="ETAPA",OFFSET(C23,-1,0)+1,OFFSET(C23,-1,0))) -> 1 | D23: =IF(H23="ETAPA",0,IF(H23="SUBETAPA",OFFSET(D23,-1,0)+1,OFFSET(D23,-1,0))) -> 2 | E23: =IF(H23="Subetapa",0,IF(H23="serviço",OFFSET(E23,-1,0)+1,OFFSET(E23,-1,0))) -> 8 | H23: SERVIÇO | I23: =IF(H23="Unidade Construtiva",TEXT(A23,"00"),IF(H23="Célula Construtiva",TEXT(B23,"00"),IF(H23="Etapa",CONCATENATE(TEXT(B23,"00"),".",TEXT(C23,"000")),IF(H23="Subetapa",CONCATENATE(TEXT(B23,"00"),".",TEXT(C23,"000"),".",TEXT(D23,"000")),IF(H23="Serviço",CONCATENATE(TEXT(B23,"00"),".",TEXT(C23,"000"),".",TEXT(D23,"000"),".",TEXT(E23,"000")),""))))) -> 01.001.002.008 | J23: Projeto hidrossanitário/drenagem/pluvial | K23: vb | L23: 1 | M23: 15810 | N23: =IF(H23="Serviço",M23*L23,IF(H23="CÉLULA CONSTRUTIVA",SUMIFS($N$8:$N$415,$B$8:$B$415,B23,$H$8:$H$415,"Serviço"),IF(H23="ETAPA",SUMIFS($N$8:$N$415,$B$8:$B$415,B23,$C$8:$C$415,C23,$H$8:$H$415,"Serviço"),IF(H23="SUBETAPA",SUMIFS($N$8:$N$415,$B$8:$B$415,B23,$C$8:$C$415,C23,$D$8:$D$415,D23,$H$8:$H$415,"Serviço"),0)))) -> 15810 | O23: Valor informado em formulário | P23: Finalizado
A24: =IF($H24="UNIDADE CONSTRUTIVA",OFFSET(A24,-1,0)+1,LARGE(A$3:A23,1)) -> 0 | B24: =IF(H24="UNIDADE CONSTRUTIVA",0,IF(H24="CÉLULA CONSTRUTIVA",OFFSET(B24,-1,0)+1,OFFSET(B24,-1,0))) -> 1 | C24: =IF(H24="CÉLULA CONSTRUTIVA",0,IF(H24="ETAPA",OFFSET(C24,-1,0)+1,OFFSET(C24,-1,0))) -> 1 | D24: =IF(H24="ETAPA",0,IF(H24="SUBETAPA",OFFSET(D24,-1,0)+1,OFFSET(D24,-1,0))) -> 2 | E24: =IF(H24="Subetapa",0,IF(H24="serviço",OFFSET(E24,-1,0)+1,OFFSET(E24,-1,0))) -> 9 | H24: SERVIÇO | I24: =IF(H24="Unidade Construtiva",TEXT(A24,"00"),IF(H24="Célula Construtiva",TEXT(B24,"00"),IF(H24="Etapa",CONCATENATE(TEXT(B24,"00"),".",TEXT(C24,"000")),IF(H24="Subetapa",CONCATENATE(TEXT(B24,"00"),".",TEXT(C24,"000"),".",TEXT(D24,"000")),IF(H24="Serviço",CONCATENATE(TEXT(B24,"00"),".",TEXT(C24,"000"),".",TEXT(D24,"000"),".",TEXT(E24,"000")),""))))) -> 01.001.002.009 | J24: Projeto preventivo (PPCI - Plano de Prevenção e Proteção Contra Incêndios) | K24: vb | L24: 1 | M24: 14720 | N24: =IF(H24="Serviço",M24*L24,IF(H24="CÉLULA CONSTRUTIVA",SUMIFS($N$8:$N$415,$B$8:$B$415,B24,$H$8:$H$415,"Serviço"),IF(H24="ETAPA",SUMIFS($N$8:$N$415,$B$8:$B$415,B24,$C$8:$C$415,C24,$H$8:$H$415,"Serviço"),IF(H24="SUBETAPA",SUMIFS($N$8:$N$415,$B$8:$B$415,B24,$C$8:$C$415,C24,$D$8:$D$415,D24,$H$8:$H$415,"Serviço"),0)))) -> 14720 | O24: Valor informado em formulário | P24: Finalizado
A25: =IF($H25="UNIDADE CONSTRUTIVA",OFFSET(A25,-1,0)+1,LARGE(A$3:A24,1)) -> 0 | B25: =IF(H25="UNIDADE CONSTRUTIVA",0,IF(H25="CÉLULA CONSTRUTIVA",OFFSET(B25,-1,0)+1,OFFSET(B25,-1,0))) -> 1 | C25: =IF(H25="CÉLULA CONSTRUTIVA",0,IF(H25="ETAPA",OFFSET(C25,-1,0)+1,OFFSET(C25,-1,0))) -> 1 | D25: =IF(H25="ETAPA",0,IF(H25="SUBETAPA",OFFSET(D25,-1,0)+1,OFFSET(D25,-1,0))) -> 2 | E25: =IF(H25="Subetapa",0,IF(H25="serviço",OFFSET(E25,-1,0)+1,OFFSET(E25,-1,0))) -> 10 | H25: SERVIÇO | I25: =IF(H25="Unidade Construtiva",TEXT(A25,"00"),IF(H25="Célula Construtiva",TEXT(B25,"00"),IF(H25="Etapa",CONCATENATE(TEXT(B25,"00"),".",TEXT(C25,"000")),IF(H25="Subetapa",CONCATENATE(TEXT(B25,"00"),".",TEXT(C25,"000"),".",TEXT(D25,"000")),IF(H25="Serviço",CONCATENATE(TEXT(B25,"00"),".",TEXT(C25,"000"),".",TEXT(D25,"000"),".",TEXT(E25,"000")),""))))) -> 01.001.002.010 | J25: Projeto de climatização/exaustão | K25: vb | L25: 1 | M25: 4741 | N25: =IF(H25="Serviço",M25*L25,IF(H25="CÉLULA CONSTRUTIVA",SUMIFS($N$8:$N$415,$B$8:$B$415,B25,$H$8:$H$415,"Serviço"),IF(H25="ETAPA",SUMIFS($N$8:$N$415,$B$8:$B$415,B25,$C$8:$C$415,C25,$H$8:$H$415,"Serviço"),IF(H25="SUBETAPA",SUMIFS($N$8:$N$415,$B$8:$B$415,B25,$C$8:$C$415,C25,$D$8:$D$415,D25,$H$8:$H$415,"Serviço"),0)))) -> 4741 | O25: Valor informado em formulário | P25: Finalizado
A26: =IF($H26="UNIDADE CONSTRUTIVA",OFFSET(A26,-1,0)+1,LARGE(A$3:A25,1)) -> 0 | B26: =IF(H26="UNIDADE CONSTRUTIVA",0,IF(H26="CÉLULA CONSTRUTIVA",OFFSET(B26,-1,0)+1,OFFSET(B26,-1,0))) -> 1 | C26: =IF(H26="CÉLULA CONSTRUTIVA",0,IF(H26="ETAPA",OFFSET(C26,-1,0)+1,OFFSET(C26,-1,0))) -> 1 | D26: =IF(H26="ETAPA",0,IF(H26="SUBETAPA",OFFSET(D26,-1,0)+1,OFFSET(D26,-1,0))) -> 2 | E26: =IF(H26="Subetapa",0,IF(H26="serviço",OFFSET(E26,-1,0)+1,OFFSET(E26,-1,0))) -> 11 | H26: SERVIÇO | I26: =IF(H26="Unidade Construtiva",TEXT(A26,"00"),IF(H26="Célula Construtiva",TEXT(B26,"00"),IF(H26="Etapa",CONCATENATE(TEXT(B26,"00"),".",TEXT(C26,"000")),IF(H26="Subetapa",CONCATENATE(TEXT(B26,"00"),".",TEXT(C26,"000"),".",TEXT(D26,"000")),IF(H26="Serviço",CONCATENATE(TEXT(B26,"00"),".",TEXT(C26,"000"),".",TEXT(D26,"000"),".",TEXT(E26,"000")),""))))) -> 01.001.002.011 | J26: Projeto de Segurança - Furações | K26: vb | L26: 1 | M26: 4741 | N26: =IF(H26="Serviço",M26*L26,IF(H26="CÉLULA CONSTRUTIVA",SUMIFS($N$8:$N$415,$B$8:$B$415,B26,$H$8:$H$415,"Serviço"),IF(H26="ETAPA",SUMIFS($N$8:$N$415,$B$8:$B$415,B26,$C$8:$C$415,C26,$H$8:$H$415,"Serviço"),IF(H26="SUBETAPA",SUMIFS($N$8:$N$415,$B$8:$B$415,B26,$C$8:$C$415,C26,$D$8:$D$415,D26,$H$8:$H$415,"Serviço"),0)))) -> 4741 | O26: Valor informado em formulário | P26: Finalizado
A27: =IF($H27="UNIDADE CONSTRUTIVA",OFFSET(A27,-1,0)+1,LARGE(A$3:A26,1)) -> 0 | B27: =IF(H27="UNIDADE CONSTRUTIVA",0,IF(H27="CÉLULA CONSTRUTIVA",OFFSET(B27,-1,0)+1,OFFSET(B27,-1,0))) -> 1 | C27: =IF(H27="CÉLULA CONSTRUTIVA",0,IF(H27="ETAPA",OFFSET(C27,-1,0)+1,OFFSET(C27,-1,0))) -> 1 | D27: =IF(H27="ETAPA",0,IF(H27="SUBETAPA",OFFSET(D27,-1,0)+1,OFFSET(D27,-1,0))) -> 2 | E27: =IF(H27="Subetapa",0,IF(H27="serviço",OFFSET(E27,-1,0)+1,OFFSET(E27,-1,0))) -> 12 | H27: SERVIÇO | I27: =IF(H27="Unidade Construtiva",TEXT(A27,"00"),IF(H27="Célula Construtiva",TEXT(B27,"00"),IF(H27="Etapa",CONCATENATE(TEXT(B27,"00"),".",TEXT(C27,"000")),IF(H27="Subetapa",CONCATENATE(TEXT(B27,"00"),".",TEXT(C27,"000"),".",TEXT(D27,"000")),IF(H27="Serviço",CONCATENATE(TEXT(B27,"00"),".",TEXT(C27,"000"),".",TEXT(D27,"000"),".",TEXT(E27,"000")),""))))) -> 01.001.002.012 | J27: Projeto de Impermeabilização | K27: vb | L27: 1 | M27: 4756.6602 | N27: =IF(H27="Serviço",M27*L27,IF(H27="CÉLULA CONSTRUTIVA",SUMIFS($N$8:$N$415,$B$8:$B$415,B27,$H$8:$H$415,"Serviço"),IF(H27="ETAPA",SUMIFS($N$8:$N$415,$B$8:$B$415,B27,$C$8:$C$415,C27,$H$8:$H$415,"Serviço"),IF(H27="SUBETAPA",SUMIFS($N$8:$N$415,$B$8:$B$415,B27,$C$8:$C$415,C27,$D$8:$D$415,D27,$H$8:$H$415,"Serviço"),0)))) -> 4756.6602 | O27: Estimado com base em índices históricos | P27: Finalizado
A28: =IF($H28="UNIDADE CONSTRUTIVA",OFFSET(A28,-1,0)+1,LARGE(A$3:A27,1)) -> 0 | B28: =IF(H28="UNIDADE CONSTRUTIVA",0,IF(H28="CÉLULA CONSTRUTIVA",OFFSET(B28,-1,0)+1,OFFSET(B28,-1,0))) -> 1 | C28: =IF(H28="CÉLULA CONSTRUTIVA",0,IF(H28="ETAPA",OFFSET(C28,-1,0)+1,OFFSET(C28,-1,0))) -> 1 | D28: =IF(H28="ETAPA",0,IF(H28="SUBETAPA",OFFSET(D28,-1,0)+1,OFFSET(D28,-1,0))) -> 3 | E28: =IF(H28="Subetapa",0,IF(H28="serviço",OFFSET(E28,-1,0)+1,OFFSET(E28,-1,0))) -> 0 | H28: SUBETAPA | I28: =IF(H28="Unidade Construtiva",TEXT(A28,"00"),IF(H28="Célula Construtiva",TEXT(B28,"00"),IF(H28="Etapa",CONCATENATE(TEXT(B28,"00"),".",TEXT(C28,"000")),IF(H28="Subetapa",CONCATENATE(TEXT(B28,"00"),".",TEXT(C28,"000"),".",TEXT(D28,"000")),IF(H28="Serviço",CONCATENATE(TEXT(B28,"00"),".",TEXT(C28,"000"),".",TEXT(D28,"000"),".",TEXT(E28,"000")),""))))) -> 01.001.003 | J28: Consultorias | N28: =IF(H28="Serviço",M28*L28,IF(H28="CÉLULA CONSTRUTIVA",SUMIFS($N$8:$N$415,$B$8:$B$415,B28,$H$8:$H$415,"Serviço"),IF(H28="ETAPA",SUMIFS($N$8:$N$415,$B$8:$B$415,B28,$C$8:$C$415,C28,$H$8:$H$415,"Serviço"),IF(H28="SUBETAPA",SUMIFS($N$8:$N$415,$B$8:$B$415,B28,$C$8:$C$415,C28,$D$8:$D$415,D28,$H$8:$H$415,"Serviço"),0)))) -> 22500
A29: =IF($H29="UNIDADE CONSTRUTIVA",OFFSET(A29,-1,0)+1,LARGE(A$3:A28,1)) -> 0 | B29: =IF(H29="UNIDADE CONSTRUTIVA",0,IF(H29="CÉLULA CONSTRUTIVA",OFFSET(B29,-1,0)+1,OFFSET(B29,-1,0))) -> 1 | C29: =IF(H29="CÉLULA CONSTRUTIVA",0,IF(H29="ETAPA",OFFSET(C29,-1,0)+1,OFFSET(C29,-1,0))) -> 1 | D29: =IF(H29="ETAPA",0,IF(H29="SUBETAPA",OFFSET(D29,-1,0)+1,OFFSET(D29,-1,0))) -> 3 | E29: =IF(H29="Subetapa",0,IF(H29="serviço",OFFSET(E29,-1,0)+1,OFFSET(E29,-1,0))) -> 1 | H29: SERVIÇO | I29: =IF(H29="Unidade Construtiva",TEXT(A29,"00"),IF(H29="Célula Construtiva",TEXT(B29,"00"),IF(H29="Etapa",CONCATENATE(TEXT(B29,"00"),".",TEXT(C29,"000")),IF(H29="Subetapa",CONCATENATE(TEXT(B29,"00"),".",TEXT(C29,"000"),".",TEXT(D29,"000")),IF(H29="Serviço",CONCATENATE(TEXT(B29,"00"),".",TEXT(C29,"000"),".",TEXT(D29,"000"),".",TEXT(E29,"000")),""))))) -> 01.001.003.001 | J29: Orçamento e planejamento | K29: vb | L29: 1 | M29: 22500 | N29: =IF(H29="Serviço",M29*L29,IF(H29="CÉLULA CONSTRUTIVA",SUMIFS($N$8:$N$415,$B$8:$B$415,B29,$H$8:$H$415,"Serviço"),IF(H29="ETAPA",SUMIFS($N$8:$N$415,$B$8:$B$415,B29,$C$8:$C$415,C29,$H$8:$H$415,"Serviço"),IF(H29="SUBETAPA",SUMIFS($N$8:$N$415,$B$8:$B$415,B29,$C$8:$C$415,C29,$D$8:$D$415,D29,$H$8:$H$415,"Serviço"),0)))) -> 22500 | O29: Custo de contratação Cartesian | P29: Finalizado
A30: =IF($H30="UNIDADE CONSTRUTIVA",OFFSET(A30,-1,0)+1,LARGE(A$3:A29,1)) -> 0 | B30: =IF(H30="UNIDADE CONSTRUTIVA",0,IF(H30="CÉLULA CONSTRUTIVA",OFFSET(B30,-1,0)+1,OFFSET(B30,-1,0))) -> 1 | C30: =IF(H30="CÉLULA CONSTRUTIVA",0,IF(H30="ETAPA",OFFSET(C30,-1,0)+1,OFFSET(C30,-1,0))) -> 1 | D30: =IF(H30="ETAPA",0,IF(H30="SUBETAPA",OFFSET(D30,-1,0)+1,OFFSET(D30,-1,0))) -> 4 | E30: =IF(H30="Subetapa",0,IF(H30="serviço",OFFSET(E30,-1,0)+1,OFFSET(E30,-1,0))) -> 0 | H30: SUBETAPA | I30: =IF(H30="Unidade Construtiva",TEXT(A30,"00"),IF(H30="Célula Construtiva",TEXT(B30,"00"),IF(H30="Etapa",CONCATENATE(TEXT(B30,"00"),".",TEXT(C30,"000")),IF(H30="Subetapa",CONCATENATE(TEXT(B30,"00"),".",TEXT(C30,"000"),".",TEXT(D30,"000")),IF(H30="Serviço",CONCATENATE(TEXT(B30,"00"),".",TEXT(C30,"000"),".",TEXT(D30,"000"),".",TEXT(E30,"000")),""))))) -> 01.001.004 | J30: Ensaios | N30: =IF(H30="Serviço",M30*L30,IF(H30="CÉLULA CONSTRUTIVA",SUMIFS($N$8:$N$415,$B$8:$B$415,B30,$H$8:$H$415,"Serviço"),IF(H30="ETAPA",SUMIFS($N$8:$N$415,$B$8:$B$415,B30,$C$8:$C$415,C30,$H$8:$H$415,"Serviço"),IF(H30="SUBETAPA",SUMIFS($N$8:$N$415,$B$8:$B$415,B30,$C$8:$C$415,C30,$D$8:$D$415,D30,$H$8:$H$415,"Serviço"),0)))) -> 31855.052
A31: =IF($H31="UNIDADE CONSTRUTIVA",OFFSET(A31,-1,0)+1,LARGE(A$3:A30,1)) -> 0 | B31: =IF(H31="UNIDADE CONSTRUTIVA",0,IF(H31="CÉLULA CONSTRUTIVA",OFFSET(B31,-1,0)+1,OFFSET(B31,-1,0))) -> 1 | C31: =IF(H31="CÉLULA CONSTRUTIVA",0,IF(H31="ETAPA",OFFSET(C31,-1,0)+1,OFFSET(C31,-1,0))) -> 1 | D31: =IF(H31="ETAPA",0,IF(H31="SUBETAPA",OFFSET(D31,-1,0)+1,OFFSET(D31,-1,0))) -> 4 | E31: =IF(H31="Subetapa",0,IF(H31="serviço",OFFSET(E31,-1,0)+1,OFFSET(E31,-1,0))) -> 1 | H31: SERVIÇO | I31: =IF(H31="Unidade Construtiva",TEXT(A31,"00"),IF(H31="Célula Construtiva",TEXT(B31,"00"),IF(H31="Etapa",CONCATENATE(TEXT(B31,"00"),".",TEXT(C31,"000")),IF(H31="Subetapa",CONCATENATE(TEXT(B31,"00"),".",TEXT(C31,"000"),".",TEXT(D31,"000")),IF(H31="Serviço",CONCATENATE(TEXT(B31,"00"),".",TEXT(C31,"000"),".",TEXT(D31,"000"),".",TEXT(E31,"000")),""))))) -> 01.001.004.001 | J31: Controle Tecnologico de Concreto | K31: vb | L31: 1 | M31: 23820 | N31: =IF(H31="Serviço",M31*L31,IF(H31="CÉLULA CONSTRUTIVA",SUMIFS($N$8:$N$415,$B$8:$B$415,B31,$H$8:$H$415,"Serviço"),IF(H31="ETAPA",SUMIFS($N$8:$N$415,$B$8:$B$415,B31,$C$8:$C$415,C31,$H$8:$H$415,"Serviço"),IF(H31="SUBETAPA",SUMIFS($N$8:$N$415,$B$8:$B$415,B31,$C$8:$C$415,C31,$D$8:$D$415,D31,$H$8:$H$415,"Serviço"),0)))) -> 23820 | O31: Estimado com base em índices históricos | P31: Finalizado
A32: =IF($H32="UNIDADE CONSTRUTIVA",OFFSET(A32,-1,0)+1,LARGE(A$3:A31,1)) -> 0 | B32: =IF(H32="UNIDADE CONSTRUTIVA",0,IF(H32="CÉLULA CONSTRUTIVA",OFFSET(B32,-1,0)+1,OFFSET(B32,-1,0))) -> 1 | C32: =IF(H32="CÉLULA CONSTRUTIVA",0,IF(H32="ETAPA",OFFSET(C32,-1,0)+1,OFFSET(C32,-1,0))) -> 1 | D32: =IF(H32="ETAPA",0,IF(H32="SUBETAPA",OFFSET(D32,-1,0)+1,OFFSET(D32,-1,0))) -> 4 | E32: =IF(H32="Subetapa",0,IF(H32="serviço",OFFSET(E32,-1,0)+1,OFFSET(E32,-1,0))) -> 2 | H32: SERVIÇO | I32: =IF(H32="Unidade Construtiva",TEXT(A32,"00"),IF(H32="Célula Construtiva",TEXT(B32,"00"),IF(H32="Etapa",CONCATENATE(TEXT(B32,"00"),".",TEXT(C32,"000")),IF(H32="Subetapa",CONCATENATE(TEXT(B32,"00"),".",TEXT(C32,"000"),".",TEXT(D32,"000")),IF(H32="Serviço",CONCATENATE(TEXT(B32,"00"),".",TEXT(C32,"000"),".",TEXT(D32,"000"),".",TEXT(E32,"000")),""))))) -> 01.001.004.002 | J32: Ensaio de argamassa | K32: vb | L32: 1 | M32: 1260 | N32: =IF(H32="Serviço",M32*L32,IF(H32="CÉLULA CONSTRUTIVA",SUMIFS($N$8:$N$415,$B$8:$B$415,B32,$H$8:$H$415,"Serviço"),IF(H32="ETAPA",SUMIFS($N$8:$N$415,$B$8:$B$415,B32,$C$8:$C$415,C32,$H$8:$H$415,"Serviço"),IF(H32="SUBETAPA",SUMIFS($N$8:$N$415,$B$8:$B$415,B32,$C$8:$C$415,C32,$D$8:$D$415,D32,$H$8:$H$415,"Serviço"),0)))) -> 1260 | O32: Estimado com base em índices históricos | P32: Finalizado
A33: =IF($H33="UNIDADE CONSTRUTIVA",OFFSET(A33,-1,0)+1,LARGE(A$3:A32,1)) -> 0 | B33: =IF(H33="UNIDADE CONSTRUTIVA",0,IF(H33="CÉLULA CONSTRUTIVA",OFFSET(B33,-1,0)+1,OFFSET(B33,-1,0))) -> 1 | C33: =IF(H33="CÉLULA CONSTRUTIVA",0,IF(H33="ETAPA",OFFSET(C33,-1,0)+1,OFFSET(C33,-1,0))) -> 1 | D33: =IF(H33="ETAPA",0,IF(H33="SUBETAPA",OFFSET(D33,-1,0)+1,OFFSET(D33,-1,0))) -> 4 | E33: =IF(H33="Subetapa",0,IF(H33="serviço",OFFSET(E33,-1,0)+1,OFFSET(E33,-1,0))) -> 3 | H33: SERVIÇO | I33: =IF(H33="Unidade Construtiva",TEXT(A33,"00"),IF(H33="Célula Construtiva",TEXT(B33,"00"),IF(H33="Etapa",CONCATENATE(TEXT(B33,"00"),".",TEXT(C33,"000")),IF(H33="Subetapa",CONCATENATE(TEXT(B33,"00"),".",TEXT(C33,"000"),".",TEXT(D33,"000")),IF(H33="Serviço",CONCATENATE(TEXT(B33,"00"),".",TEXT(C33,"000"),".",TEXT(D33,"000"),".",TEXT(E33,"000")),""))))) -> 01.001.004.003 | J33: Laudo de Vizinhança | K33: vb | L33: 1 | M33: 6775.0524 | N33: =IF(H33="Serviço",M33*L33,IF(H33="CÉLULA CONSTRUTIVA",SUMIFS($N$8:$N$415,$B$8:$B$415,B33,$H$8:$H$415,"Serviço"),IF(H33="ETAPA",SUMIFS($N$8:$N$415,$B$8:$B$415,B33,$C$8:$C$415,C33,$H$8:$H$415,"Serviço"),IF(H33="SUBETAPA",SUMIFS($N$8:$N$415,$B$8:$B$415,B33,$C$8:$C$415,C33,$D$8:$D$415,D33,$H$8:$H$415,"Serviço"),0)))) -> 6775.0524 | O33: Estimado com base em índices históricos | P33: Finalizado
A34: =IF($H34="UNIDADE CONSTRUTIVA",OFFSET(A34,-1,0)+1,LARGE(A$3:A33,1)) -> 0 | B34: =IF(H34="UNIDADE CONSTRUTIVA",0,IF(H34="CÉLULA CONSTRUTIVA",OFFSET(B34,-1,0)+1,OFFSET(B34,-1,0))) -> 1 | C34: =IF(H34="CÉLULA CONSTRUTIVA",0,IF(H34="ETAPA",OFFSET(C34,-1,0)+1,OFFSET(C34,-1,0))) -> 2 | D34: =IF(H34="ETAPA",0,IF(H34="SUBETAPA",OFFSET(D34,-1,0)+1,OFFSET(D34,-1,0))) -> 0 | E34: =IF(H34="Subetapa",0,IF(H34="serviço",OFFSET(E34,-1,0)+1,OFFSET(E34,-1,0))) -> 3 | H34: ETAPA | I34: =IF(H34="Unidade Construtiva",TEXT(A34,"00"),IF(H34="Célula Construtiva",TEXT(B34,"00"),IF(H34="Etapa",CONCATENATE(TEXT(B34,"00"),".",TEXT(C34,"000")),IF(H34="Subetapa",CONCATENATE(TEXT(B34,"00"),".",TEXT(C34,"000"),".",TEXT(D34,"000")),IF(H34="Serviço",CONCATENATE(TEXT(B34,"00"),".",TEXT(C34,"000"),".",TEXT(D34,"000"),".",TEXT(E34,"000")),""))))) -> 01.002 | J34: CONSUMOS, TAXAS E DOCUMENTOS | N34: =IF(H34="Serviço",M34*L34,IF(H34="CÉLULA CONSTRUTIVA",SUMIFS($N$8:$N$415,$B$8:$B$415,B34,$H$8:$H$415,"Serviço"),IF(H34="ETAPA",SUMIFS($N$8:$N$415,$B$8:$B$415,B34,$C$8:$C$415,C34,$H$8:$H$415,"Serviço"),IF(H34="SUBETAPA",SUMIFS($N$8:$N$415,$B$8:$B$415,B34,$C$8:$C$415,C34,$D$8:$D$415,D34,$H$8:$H$415,"Serviço"),0)))) -> 112995.44 | P34: -
A35: =IF($H35="UNIDADE CONSTRUTIVA",OFFSET(A35,-1,0)+1,LARGE(A$3:A34,1)) -> 0 | B35: =IF(H35="UNIDADE CONSTRUTIVA",0,IF(H35="CÉLULA CONSTRUTIVA",OFFSET(B35,-1,0)+1,OFFSET(B35,-1,0))) -> 1 | C35: =IF(H35="CÉLULA CONSTRUTIVA",0,IF(H35="ETAPA",OFFSET(C35,-1,0)+1,OFFSET(C35,-1,0))) -> 2 | D35: =IF(H35="ETAPA",0,IF(H35="SUBETAPA",OFFSET(D35,-1,0)+1,OFFSET(D35,-1,0))) -> 1 | E35: =IF(H35="Subetapa",0,IF(H35="serviço",OFFSET(E35,-1,0)+1,OFFSET(E35,-1,0))) -> 0 | H35: SUBETAPA | I35: =IF(H35="Unidade Construtiva",TEXT(A35,"00"),IF(H35="Célula Construtiva",TEXT(B35,"00"),IF(H35="Etapa",CONCATENATE(TEXT(B35,"00"),".",TEXT(C35,"000")),IF(H35="Subetapa",CONCATENATE(TEXT(B35,"00"),".",TEXT(C35,"000"),".",TEXT(D35,"000")),IF(H35="Serviço",CONCATENATE(TEXT(B35,"00"),".",TEXT(C35,"000"),".",TEXT(D35,"000"),".",TEXT(E35,"000")),""))))) -> 01.002.001 | J35: Licenciamentos, Taxas, Impostos, Aprovações e Seguros | N35: =IF(H35="Serviço",M35*L35,IF(H35="CÉLULA CONSTRUTIVA",SUMIFS($N$8:$N$415,$B$8:$B$415,B35,$H$8:$H$415,"Serviço"),IF(H35="ETAPA",SUMIFS($N$8:$N$415,$B$8:$B$415,B35,$C$8:$C$415,C35,$H$8:$H$415,"Serviço"),IF(H35="SUBETAPA",SUMIFS($N$8:$N$415,$B$8:$B$415,B35,$C$8:$C$415,C35,$D$8:$D$415,D35,$H$8:$H$415,"Serviço"),0)))) -> 95599.045
A36: =IF($H36="UNIDADE CONSTRUTIVA",OFFSET(A36,-1,0)+1,LARGE(A$3:A35,1)) -> 0 | B36: =IF(H36="UNIDADE CONSTRUTIVA",0,IF(H36="CÉLULA CONSTRUTIVA",OFFSET(B36,-1,0)+1,OFFSET(B36,-1,0))) -> 1 | C36: =IF(H36="CÉLULA CONSTRUTIVA",0,IF(H36="ETAPA",OFFSET(C36,-1,0)+1,OFFSET(C36,-1,0))) -> 2 | D36: =IF(H36="ETAPA",0,IF(H36="SUBETAPA",OFFSET(D36,-1,0)+1,OFFSET(D36,-1,0))) -> 1 | E36: =IF(H36="Subetapa",0,IF(H36="serviço",OFFSET(E36,-1,0)+1,OFFSET(E36,-1,0))) -> 1 | H36: SERVIÇO | I36: =IF(H36="Unidade Construtiva",TEXT(A36,"00"),IF(H36="Célula Construtiva",TEXT(B36,"00"),IF(H36="Etapa",CONCATENATE(TEXT(B36,"00"),".",TEXT(C36,"000")),IF(H36="Subetapa",CONCATENATE(TEXT(B36,"00"),".",TEXT(C36,"000"),".",TEXT(D36,"000")),IF(H36="Serviço",CONCATENATE(TEXT(B36,"00"),".",TEXT(C36,"000"),".",TEXT(D36,"000"),".",TEXT(E36,"000")),""))))) -> 01.002.001.001 | J36: Despesas de Seguros | K36: vb | L36: 1 | M36: 9200 | N36: =IF(H36="Serviço",M36*L36,IF(H36="CÉLULA CONSTRUTIVA",SUMIFS($N$8:$N$415,$B$8:$B$415,B36,$H$8:$H$415,"Serviço"),IF(H36="ETAPA",SUMIFS($N$8:$N$415,$B$8:$B$415,B36,$C$8:$C$415,C36,$H$8:$H$415,"Serviço"),IF(H36="SUBETAPA",SUMIFS($N$8:$N$415,$B$8:$B$415,B36,$C$8:$C$415,C36,$D$8:$D$415,D36,$H$8:$H$415,"Serviço"),0)))) -> 9200 | O36: Valor informado em formulário | P36: Lançado ERP
A37: =IF($H37="UNIDADE CONSTRUTIVA",OFFSET(A37,-1,0)+1,LARGE(A$3:A36,1)) -> 0 | B37: =IF(H37="UNIDADE CONSTRUTIVA",0,IF(H37="CÉLULA CONSTRUTIVA",OFFSET(B37,-1,0)+1,OFFSET(B37,-1,0))) -> 1 | C37: =IF(H37="CÉLULA CONSTRUTIVA",0,IF(H37="ETAPA",OFFSET(C37,-1,0)+1,OFFSET(C37,-1,0))) -> 2 | D37: =IF(H37="ETAPA",0,IF(H37="SUBETAPA",OFFSET(D37,-1,0)+1,OFFSET(D37,-1,0))) -> 1 | E37: =IF(H37="Subetapa",0,IF(H37="serviço",OFFSET(E37,-1,0)+1,OFFSET(E37,-1,0))) -> 2 | H37: SERVIÇO | I37: =IF(H37="Unidade Construtiva",TEXT(A37,"00"),IF(H37="Célula Construtiva",TEXT(B37,"00"),IF(H37="Etapa",CONCATENATE(TEXT(B37,"00"),".",TEXT(C37,"000")),IF(H37="Subetapa",CONCATENATE(TEXT(B37,"00"),".",TEXT(C37,"000"),".",TEXT(D37,"000")),IF(H37="Serviço",CONCATENATE(TEXT(B37,"00"),".",TEXT(C37,"000"),".",TEXT(D37,"000"),".",TEXT(E37,"000")),""))))) -> 01.002.001.002 | J37: Aprovação e legalização ambiental | K37: vb | L37: 1 | M37: 2628.5859 | N37: =IF(H37="Serviço",M37*L37,IF(H37="CÉLULA CONSTRUTIVA",SUMIFS($N$8:$N$415,$B$8:$B$415,B37,$H$8:$H$415,"Serviço"),IF(H37="ETAPA",SUMIFS($N$8:$N$415,$B$8:$B$415,B37,$C$8:$C$415,C37,$H$8:$H$415,"Serviço"),IF(H37="SUBETAPA",SUMIFS($N$8:$N$415,$B$8:$B$415,B37,$C$8:$C$415,C37,$D$8:$D$415,D37,$H$8:$H$415,"Serviço"),0)))) -> 2628.5859 | O37: Estimado com base em índices históricos | P37: Lançado ERP
A38: =IF($H38="UNIDADE CONSTRUTIVA",OFFSET(A38,-1,0)+1,LARGE(A$3:A37,1)) -> 0 | B38: =IF(H38="UNIDADE CONSTRUTIVA",0,IF(H38="CÉLULA CONSTRUTIVA",OFFSET(B38,-1,0)+1,OFFSET(B38,-1,0))) -> 1 | C38: =IF(H38="CÉLULA CONSTRUTIVA",0,IF(H38="ETAPA",OFFSET(C38,-1,0)+1,OFFSET(C38,-1,0))) -> 2 | D38: =IF(H38="ETAPA",0,IF(H38="SUBETAPA",OFFSET(D38,-1,0)+1,OFFSET(D38,-1,0))) -> 1 | E38: =IF(H38="Subetapa",0,IF(H38="serviço",OFFSET(E38,-1,0)+1,OFFSET(E38,-1,0))) -> 3 | H38: SERVIÇO | I38: =IF(H38="Unidade Construtiva",TEXT(A38,"00"),IF(H38="Célula Construtiva",TEXT(B38,"00"),IF(H38="Etapa",CONCATENATE(TEXT(B38,"00"),".",TEXT(C38,"000")),IF(H38="Subetapa",CONCATENATE(TEXT(B38,"00"),".",TEXT(C38,"000"),".",TEXT(D38,"000")),IF(H38="Serviço",CONCATENATE(TEXT(B38,"00"),".",TEXT(C38,"000"),".",TEXT(D38,"000"),".",TEXT(E38,"000")),""))))) -> 01.002.001.003 | J38: Aprovação e legalização prefeitura | K38: vb | L38: 1 | M38: 10990.118 | N38: =IF(H38="Serviço",M38*L38,IF(H38="CÉLULA CONSTRUTIVA",SUMIFS($N$8:$N$415,$B$8:$B$415,B38,$H$8:$H$415,"Serviço"),IF(H38="ETAPA",SUMIFS($N$8:$N$415,$B$8:$B$415,B38,$C$8:$C$415,C38,$H$8:$H$415,"Serviço"),IF(H38="SUBETAPA",SUMIFS($N$8:$N$415,$B$8:$B$415,B38,$C$8:$C$415,C38,$D$8:$D$415,D38,$H$8:$H$415,"Serviço"),0)))) -> 10990.118 | O38: Estimado com base em índices históricos | P38: Lançado ERP
A39: =IF($H39="UNIDADE CONSTRUTIVA",OFFSET(A39,-1,0)+1,LARGE(A$3:A38,1)) -> 0 | B39: =IF(H39="UNIDADE CONSTRUTIVA",0,IF(H39="CÉLULA CONSTRUTIVA",OFFSET(B39,-1,0)+1,OFFSET(B39,-1,0))) -> 1 | C39: =IF(H39="CÉLULA CONSTRUTIVA",0,IF(H39="ETAPA",OFFSET(C39,-1,0)+1,OFFSET(C39,-1,0))) -> 2 | D39: =IF(H39="ETAPA",0,IF(H39="SUBETAPA",OFFSET(D39,-1,0)+1,OFFSET(D39,-1,0))) -> 1 | E39: =IF(H39="Subetapa",0,IF(H39="serviço",OFFSET(E39,-1,0)+1,OFFSET(E39,-1,0))) -> 4 | H39: SERVIÇO | I39: =IF(H39="Unidade Construtiva",TEXT(A39,"00"),IF(H39="Célula Construtiva",TEXT(B39,"00"),IF(H39="Etapa",CONCATENATE(TEXT(B39,"00"),".",TEXT(C39,"000")),IF(H39="Subetapa",CONCATENATE(TEXT(B39,"00"),".",TEXT(C39,"000"),".",TEXT(D39,"000")),IF(H39="Serviço",CONCATENATE(TEXT(B39,"00"),".",TEXT(C39,"000"),".",TEXT(D39,"000"),".",TEXT(E39,"000")),""))))) -> 01.002.001.004 | J39: Aprovação e legalização água e esgoto | K39: vb | L39: 1 | M39: 822.7251 | N39: =IF(H39="Serviço",M39*L39,IF(H39="CÉLULA CONSTRUTIVA",SUMIFS($N$8:$N$415,$B$8:$B$415,B39,$H$8:$H$415,"Serviço"),IF(H39="ETAPA",SUMIFS($N$8:$N$415,$B$8:$B$415,B39,$C$8:$C$415,C39,$H$8:$H$415,"Serviço"),IF(H39="SUBETAPA",SUMIFS($N$8:$N$415,$B$8:$B$415,B39,$C$8:$C$415,C39,$D$8:$D$415,D39,$H$8:$H$415,"Serviço"),0)))) -> 822.7251 | O39: Estimado com base em índices históricos | P39: Lançado ERP
A40: =IF($H40="UNIDADE CONSTRUTIVA",OFFSET(A40,-1,0)+1,LARGE(A$3:A39,1)) -> 0 | B40: =IF(H40="UNIDADE CONSTRUTIVA",0,IF(H40="CÉLULA CONSTRUTIVA",OFFSET(B40,-1,0)+1,OFFSET(B40,-1,0))) -> 1 | C40: =IF(H40="CÉLULA CONSTRUTIVA",0,IF(H40="ETAPA",OFFSET(C40,-1,0)+1,OFFSET(C40,-1,0))) -> 2 | D40: =IF(H40="ETAPA",0,IF(H40="SUBETAPA",OFFSET(D40,-1,0)+1,OFFSET(D40,-1,0))) -> 1 | E40: =IF(H40="Subetapa",0,IF(H40="serviço",OFFSET(E40,-1,0)+1,OFFSET(E40,-1,0))) -> 5 | H40: SERVIÇO | I40: =IF(H40="Unidade Construtiva",TEXT(A40,"00"),IF(H40="Célula Construtiva",TEXT(B40,"00"),IF(H40="Etapa",CONCATENATE(TEXT(B40,"00"),".",TEXT(C40,"000")),IF(H40="Subetapa",CONCATENATE(TEXT(B40,"00"),".",TEXT(C40,"000"),".",TEXT(D40,"000")),IF(H40="Serviço",CONCATENATE(TEXT(B40,"00"),".",TEXT(C40,"000"),".",TEXT(D40,"000"),".",TEXT(E40,"000")),""))))) -> 01.002.001.005 | J40: Aprovação e legalização elétrico | K40: vb | L40: 1 | M40: 5859.118 | N40: =IF(H40="Serviço",M40*L40,IF(H40="CÉLULA CONSTRUTIVA",SUMIFS($N$8:$N$415,$B$8:$B$415,B40,$H$8:$H$415,"Serviço"),IF(H40="ETAPA",SUMIFS($N$8:$N$415,$B$8:$B$415,B40,$C$8:$C$415,C40,$H$8:$H$415,"Serviço"),IF(H40="SUBETAPA",SUMIFS($N$8:$N$415,$B$8:$B$415,B40,$C$8:$C$415,C40,$D$8:$D$415,D40,$H$8:$H$415,"Serviço"),0)))) -> 5859.118 | O40: Estimado com base em índices históricos | P40: Lançado ERP
A41: =IF($H41="UNIDADE CONSTRUTIVA",OFFSET(A41,-1,0)+1,LARGE(A$3:A40,1)) -> 0 | B41: =IF(H41="UNIDADE CONSTRUTIVA",0,IF(H41="CÉLULA CONSTRUTIVA",OFFSET(B41,-1,0)+1,OFFSET(B41,-1,0))) -> 1 | C41: =IF(H41="CÉLULA CONSTRUTIVA",0,IF(H41="ETAPA",OFFSET(C41,-1,0)+1,OFFSET(C41,-1,0))) -> 2 | D41: =IF(H41="ETAPA",0,IF(H41="SUBETAPA",OFFSET(D41,-1,0)+1,OFFSET(D41,-1,0))) -> 1 | E41: =IF(H41="Subetapa",0,IF(H41="serviço",OFFSET(E41,-1,0)+1,OFFSET(E41,-1,0))) -> 6 | H41: SERVIÇO | I41: =IF(H41="Unidade Construtiva",TEXT(A41,"00"),IF(H41="Célula Construtiva",TEXT(B41,"00"),IF(H41="Etapa",CONCATENATE(TEXT(B41,"00"),".",TEXT(C41,"000")),IF(H41="Subetapa",CONCATENATE(TEXT(B41,"00"),".",TEXT(C41,"000"),".",TEXT(D41,"000")),IF(H41="Serviço",CONCATENATE(TEXT(B41,"00"),".",TEXT(C41,"000"),".",TEXT(D41,"000"),".",TEXT(E41,"000")),""))))) -> 01.002.001.006 | J41: Aprovação e legalização bombeiros | K41: vb | L41: 1 | M41: 3607.9918 | N41: =IF(H41="Serviço",M41*L41,IF(H41="CÉLULA CONSTRUTIVA",SUMIFS($N$8:$N$415,$B$8:$B$415,B41,$H$8:$H$415,"Serviço"),IF(H41="ETAPA",SUMIFS($N$8:$N$415,$B$8:$B$415,B41,$C$8:$C$415,C41,$H$8:$H$415,"Serviço"),IF(H41="SUBETAPA",SUMIFS($N$8:$N$415,$B$8:$B$415,B41,$C$8:$C$415,C41,$D$8:$D$415,D41,$H$8:$H$415,"Serviço"),0)))) -> 3607.9918 | O41: Estimado com base em índices históricos | P41: Lançado ERP
A42: =IF($H42="UNIDADE CONSTRUTIVA",OFFSET(A42,-1,0)+1,LARGE(A$3:A41,1)) -> 0 | B42: =IF(H42="UNIDADE CONSTRUTIVA",0,IF(H42="CÉLULA CONSTRUTIVA",OFFSET(B42,-1,0)+1,OFFSET(B42,-1,0))) -> 1 | C42: =IF(H42="CÉLULA CONSTRUTIVA",0,IF(H42="ETAPA",OFFSET(C42,-1,0)+1,OFFSET(C42,-1,0))) -> 2 | D42: =IF(H42="ETAPA",0,IF(H42="SUBETAPA",OFFSET(D42,-1,0)+1,OFFSET(D42,-1,0))) -> 1 | E42: =IF(H42="Subetapa",0,IF(H42="serviço",OFFSET(E42,-1,0)+1,OFFSET(E42,-1,0))) -> 7 | H42: SERVIÇO | I42: =IF(H42="Unidade Construtiva",TEXT(A42,"00"),IF(H42="Célula Construtiva",TEXT(B42,"00"),IF(H42="Etapa",CONCATENATE(TEXT(B42,"00"),".",TEXT(C42,"000")),IF(H42="Subetapa",CONCATENATE(TEXT(B42,"00"),".",TEXT(C42,"000"),".",TEXT(D42,"000")),IF(H42="Serviço",CONCATENATE(TEXT(B42,"00"),".",TEXT(C42,"000"),".",TEXT(D42,"000"),".",TEXT(E42,"000")),""))))) -> 01.002.001.007 | J42: Taxas de ART | K42: vb | L42: 1 | M42: 1500 | N42: =IF(H42="Serviço",M42*L42,IF(H42="CÉLULA CONSTRUTIVA",SUMIFS($N$8:$N$415,$B$8:$B$415,B42,$H$8:$H$415,"Serviço"),IF(H42="ETAPA",SUMIFS($N$8:$N$415,$B$8:$B$415,B42,$C$8:$C$415,C42,$H$8:$H$415,"Serviço"),IF(H42="SUBETAPA",SUMIFS($N$8:$N$415,$B$8:$B$415,B42,$C$8:$C$415,C42,$D$8:$D$415,D42,$H$8:$H$415,"Serviço"),0)))) -> 1500 | O42: Valor informado em formulário | P42: Lançado ERP
A43: =IF($H43="UNIDADE CONSTRUTIVA",OFFSET(A43,-1,0)+1,LARGE(A$3:A42,1)) -> 0 | B43: =IF(H43="UNIDADE CONSTRUTIVA",0,IF(H43="CÉLULA CONSTRUTIVA",OFFSET(B43,-1,0)+1,OFFSET(B43,-1,0))) -> 1 | C43: =IF(H43="CÉLULA CONSTRUTIVA",0,IF(H43="ETAPA",OFFSET(C43,-1,0)+1,OFFSET(C43,-1,0))) -> 2 | D43: =IF(H43="ETAPA",0,IF(H43="SUBETAPA",OFFSET(D43,-1,0)+1,OFFSET(D43,-1,0))) -> 1 | E43: =IF(H43="Subetapa",0,IF(H43="serviço",OFFSET(E43,-1,0)+1,OFFSET(E43,-1,0))) -> 8 | H43: SERVIÇO | I43: =IF(H43="Unidade Construtiva",TEXT(A43,"00"),IF(H43="Célula Construtiva",TEXT(B43,"00"),IF(H43="Etapa",CONCATENATE(TEXT(B43,"00"),".",TEXT(C43,"000")),IF(H43="Subetapa",CONCATENATE(TEXT(B43,"00"),".",TEXT(C43,"000"),".",TEXT(D43,"000")),IF(H43="Serviço",CONCATENATE(TEXT(B43,"00"),".",TEXT(C43,"000"),".",TEXT(D43,"000"),".",TEXT(E43,"000")),""))))) -> 01.002.001.008 | J43: Alvará Construção | K43: vb | L43: 1 | M43: 13583.189 | N43: =IF(H43="Serviço",M43*L43,IF(H43="CÉLULA CONSTRUTIVA",SUMIFS($N$8:$N$415,$B$8:$B$415,B43,$H$8:$H$415,"Serviço"),IF(H43="ETAPA",SUMIFS($N$8:$N$415,$B$8:$B$415,B43,$C$8:$C$415,C43,$H$8:$H$415,"Serviço"),IF(H43="SUBETAPA",SUMIFS($N$8:$N$415,$B$8:$B$415,B43,$C$8:$C$415,C43,$D$8:$D$415,D43,$H$8:$H$415,"Serviço"),0)))) -> 13583.189 | O43: Estimado com base em índices históricos | P43: Lançado ERP
...

Sheet Ger_Executivo
G4: PROJETO: | I4: ='Ger_Tec e Adm'!I4 -> Marena | O4: REVISÃO: | P4: DATA
G5: EMPRESA: | I5: ='Ger_Tec e Adm'!I5 -> XPCon | O5: ='Obra '!D3 -> R02 - 30/05/2025 | P5: 45702
A6: Unidade Construtiva | B6: Célula Construtiva | C6: Etapa | D6: Subetapa | E6: Serviço | G6: GERENCIAMENTO EXECUTIVO
A7: 0 | B7: 0 | C7: 0 | D7: 0 | E7: 0 | G7: Atalho | H7: NIVEL | I7: Item | J7: Descrição | K7: Unidade | L7: Quant. | M7: Preço un | N7: Total | O7: Considerações | P7: Situação
A8: =IF($H8="UNIDADE CONSTRUTIVA",OFFSET(A8,-1,0)+1,LARGE(A$3:A7,1)) -> 0 | B8: =IF(H8="UNIDADE CONSTRUTIVA",0,IF(H8="CÉLULA CONSTRUTIVA",OFFSET(B8,-1,0)+1,OFFSET(B8,-1,0))) -> 1 | C8: =IF(H8="CÉLULA CONSTRUTIVA",0,IF(H8="ETAPA",OFFSET(C8,-1,0)+1,OFFSET(C8,-1,0))) -> 0 | D8: =IF(H8="ETAPA",0,IF(H8="SUBETAPA",OFFSET(D8,-1,0)+1,OFFSET(D8,-1,0))) -> 0 | E8: =IF(H8="Subetapa",0,IF(H8="serviço",OFFSET(E8,-1,0)+1,OFFSET(E8,-1,0))) -> 0 | H8: CÉLULA CONSTRUTIVA | I8: =IF(H8="Unidade Construtiva",TEXT(A8,"00"),IF(H8="Célula Construtiva",TEXT(B8,"00"),IF(H8="Etapa",CONCATENATE(TEXT(B8,"00"),".",TEXT(C8,"000")),IF(H8="Subetapa",CONCATENATE(TEXT(B8,"00"),".",TEXT(C8,"000"),".",TEXT(D8,"000")),IF(H8="Serviço",CONCATENATE(TEXT(B8,"00"),".",TEXT(C8,"000"),".",TEXT(D8,"000"),".",TEXT(E8,"000")),""))))) -> 01 | J8: MOVIMENTAÇÃO DE TERRA | N8: =IF(H8="Serviço",M8*L8,IF(H8="CÉLULA CONSTRUTIVA",SUMIFS($N$8:$N$1410,$B$8:$B$1410,B8,$H$8:$H$1410,"Serviço"),IF(H8="ETAPA",SUMIFS($N$8:$N$1410,$B$8:$B$1410,B8,$C$8:$C$1410,C8,$H$8:$H$1410,"Serviço"),IF(H8="SUBETAPA",SUMIFS($N$8:$N$1410,$B$8:$B$1410,B8,$C$8:$C$1410,C8,$D$8:$D$1410,D8,$H$8:$H$1410,"Serviço"),0)))) -> 96431.556
A9: =IF($H9="UNIDADE CONSTRUTIVA",OFFSET(A9,-1,0)+1,LARGE(A$3:A8,1)) -> 0 | B9: =IF(H9="UNIDADE CONSTRUTIVA",0,IF(H9="CÉLULA CONSTRUTIVA",OFFSET(B9,-1,0)+1,OFFSET(B9,-1,0))) -> 1 | C9: =IF(H9="CÉLULA CONSTRUTIVA",0,IF(H9="ETAPA",OFFSET(C9,-1,0)+1,OFFSET(C9,-1,0))) -> 1 | D9: =IF(H9="ETAPA",0,IF(H9="SUBETAPA",OFFSET(D9,-1,0)+1,OFFSET(D9,-1,0))) -> 0 | E9: =IF(H9="Subetapa",0,IF(H9="serviço",OFFSET(E9,-1,0)+1,OFFSET(E9,-1,0))) -> 0 | H9: ETAPA | I9: =IF(H9="Unidade Construtiva",TEXT(A9,"00"),IF(H9="Célula Construtiva",TEXT(B9,"00"),IF(H9="Etapa",CONCATENATE(TEXT(B9,"00"),".",TEXT(C9,"000")),IF(H9="Subetapa",CONCATENATE(TEXT(B9,"00"),".",TEXT(C9,"000"),".",TEXT(D9,"000")),IF(H9="Serviço",CONCATENATE(TEXT(B9,"00"),".",TEXT(C9,"000"),".",TEXT(D9,"000"),".",TEXT(E9,"000")),""))))) -> 01.001 | J9: MOVIMENTAÇÃO DE TERRA | N9: =IF(H9="Serviço",M9*L9,IF(H9="CÉLULA CONSTRUTIVA",SUMIFS($N$8:$N$1410,$B$8:$B$1410,B9,$H$8:$H$1410,"Serviço"),IF(H9="ETAPA",SUMIFS($N$8:$N$1410,$B$8:$B$1410,B9,$C$8:$C$1410,C9,$H$8:$H$1410,"Serviço"),IF(H9="SUBETAPA",SUMIFS($N$8:$N$1410,$B$8:$B$1410,B9,$C$8:$C$1410,C9,$D$8:$D$1410,D9,$H$8:$H$1410,"Serviço"),0)))) -> 96431.556
A10: =IF($H10="UNIDADE CONSTRUTIVA",OFFSET(A10,-1,0)+1,LARGE(A$3:A9,1)) -> 0 | B10: =IF(H10="UNIDADE CONSTRUTIVA",0,IF(H10="CÉLULA CONSTRUTIVA",OFFSET(B10,-1,0)+1,OFFSET(B10,-1,0))) -> 1 | C10: =IF(H10="CÉLULA CONSTRUTIVA",0,IF(H10="ETAPA",OFFSET(C10,-1,0)+1,OFFSET(C10,-1,0))) -> 1 | D10: =IF(H10="ETAPA",0,IF(H10="SUBETAPA",OFFSET(D10,-1,0)+1,OFFSET(D10,-1,0))) -> 1 | E10: =IF(H10="Subetapa",0,IF(H10="serviço",OFFSET(E10,-1,0)+1,OFFSET(E10,-1,0))) -> 0 | H10: SUBETAPA | I10: =IF(H10="Unidade Construtiva",TEXT(A10,"00"),IF(H10="Célula Construtiva",TEXT(B10,"00"),IF(H10="Etapa",CONCATENATE(TEXT(B10,"00"),".",TEXT(C10,"000")),IF(H10="Subetapa",CONCATENATE(TEXT(B10,"00"),".",TEXT(C10,"000"),".",TEXT(D10,"000")),IF(H10="Serviço",CONCATENATE(TEXT(B10,"00"),".",TEXT(C10,"000"),".",TEXT(D10,"000"),".",TEXT(E10,"000")),""))))) -> 01.001.001 | J10: Rebaixamento de Lençol Freático | N10: =IF(H10="Serviço",M10*L10,IF(H10="CÉLULA CONSTRUTIVA",SUMIFS($N$8:$N$1410,$B$8:$B$1410,B10,$H$8:$H$1410,"Serviço"),IF(H10="ETAPA",SUMIFS($N$8:$N$1410,$B$8:$B$1410,B10,$C$8:$C$1410,C10,$H$8:$H$1410,"Serviço"),IF(H10="SUBETAPA",SUMIFS($N$8:$N$1410,$B$8:$B$1410,B10,$C$8:$C$1410,C10,$D$8:$D$1410,D10,$H$8:$H$1410,"Serviço"),0)))) -> 5000
A11: =IF($H11="UNIDADE CONSTRUTIVA",OFFSET(A11,-1,0)+1,LARGE(A$3:A10,1)) -> 0 | B11: =IF(H11="UNIDADE CONSTRUTIVA",0,IF(H11="CÉLULA CONSTRUTIVA",OFFSET(B11,-1,0)+1,OFFSET(B11,-1,0))) -> 1 | C11: =IF(H11="CÉLULA CONSTRUTIVA",0,IF(H11="ETAPA",OFFSET(C11,-1,0)+1,OFFSET(C11,-1,0))) -> 1 | D11: =IF(H11="ETAPA",0,IF(H11="SUBETAPA",OFFSET(D11,-1,0)+1,OFFSET(D11,-1,0))) -> 1 | E11: =IF(H11="Subetapa",0,IF(H11="serviço",OFFSET(E11,-1,0)+1,OFFSET(E11,-1,0))) -> 1 | H11: SERVIÇO | I11: =IF(H11="Unidade Construtiva",TEXT(A11,"00"),IF(H11="Célula Construtiva",TEXT(B11,"00"),IF(H11="Etapa",CONCATENATE(TEXT(B11,"00"),".",TEXT(C11,"000")),IF(H11="Subetapa",CONCATENATE(TEXT(B11,"00"),".",TEXT(C11,"000"),".",TEXT(D11,"000")),IF(H11="Serviço",CONCATENATE(TEXT(B11,"00"),".",TEXT(C11,"000"),".",TEXT(D11,"000"),".",TEXT(E11,"000")),""))))) -> 01.001.001.001 | J11: Rebaixamento de Lençol Freático | K11: vb | L11: 1 | M11: 5000 | N11: =IF(H11="Serviço",M11*L11,IF(H11="CÉLULA CONSTRUTIVA",SUMIFS($N$8:$N$1410,$B$8:$B$1410,B11,$H$8:$H$1410,"Serviço"),IF(H11="ETAPA",SUMIFS($N$8:$N$1410,$B$8:$B$1410,B11,$C$8:$C$1410,C11,$H$8:$H$1410,"Serviço"),IF(H11="SUBETAPA",SUMIFS($N$8:$N$1410,$B$8:$B$1410,B11,$C$8:$C$1410,C11,$D$8:$D$1410,D11,$H$8:$H$1410,"Serviço"),0)))) -> 5000 | O11: Considerado informações passada pelo cliente em reunião com Glauber em 19/05/2025 | P11: Finalizado
A12: =IF($H12="UNIDADE CONSTRUTIVA",OFFSET(A12,-1,0)+1,LARGE(A$3:A11,1)) -> 0 | B12: =IF(H12="UNIDADE CONSTRUTIVA",0,IF(H12="CÉLULA CONSTRUTIVA",OFFSET(B12,-1,0)+1,OFFSET(B12,-1,0))) -> 1 | C12: =IF(H12="CÉLULA CONSTRUTIVA",0,IF(H12="ETAPA",OFFSET(C12,-1,0)+1,OFFSET(C12,-1,0))) -> 1 | D12: =IF(H12="ETAPA",0,IF(H12="SUBETAPA",OFFSET(D12,-1,0)+1,OFFSET(D12,-1,0))) -> 2 | E12: =IF(H12="Subetapa",0,IF(H12="serviço",OFFSET(E12,-1,0)+1,OFFSET(E12,-1,0))) -> 0 | H12: SUBETAPA | I12: =IF(H12="Unidade Construtiva",TEXT(A12,"00"),IF(H12="Célula Construtiva",TEXT(B12,"00"),IF(H12="Etapa",CONCATENATE(TEXT(B12,"00"),".",TEXT(C12,"000")),IF(H12="Subetapa",CONCATENATE(TEXT(B12,"00"),".",TEXT(C12,"000"),".",TEXT(D12,"000")),IF(H12="Serviço",CONCATENATE(TEXT(B12,"00"),".",TEXT(C12,"000"),".",TEXT(D12,"000"),".",TEXT(E12,"000")),""))))) -> 01.001.002 | J12: Escavação e Reaterro de Valas | N12: =IF(H12="Serviço",M12*L12,IF(H12="CÉLULA CONSTRUTIVA",SUMIFS($N$8:$N$1410,$B$8:$B$1410,B12,$H$8:$H$1410,"Serviço"),IF(H12="ETAPA",SUMIFS($N$8:$N$1410,$B$8:$B$1410,B12,$C$8:$C$1410,C12,$H$8:$H$1410,"Serviço"),IF(H12="SUBETAPA",SUMIFS($N$8:$N$1410,$B$8:$B$1410,B12,$C$8:$C$1410,C12,$D$8:$D$1410,D12,$H$8:$H$1410,"Serviço"),0)))) -> 49855.196
A13: =IF($H13="UNIDADE CONSTRUTIVA",OFFSET(A13,-1,0)+1,LARGE(A$3:A12,1)) -> 0 | B13: =IF(H13="UNIDADE CONSTRUTIVA",0,IF(H13="CÉLULA CONSTRUTIVA",OFFSET(B13,-1,0)+1,OFFSET(B13,-1,0))) -> 1 | C13: =IF(H13="CÉLULA CONSTRUTIVA",0,IF(H13="ETAPA",OFFSET(C13,-1,0)+1,OFFSET(C13,-1,0))) -> 1 | D13: =IF(H13="ETAPA",0,IF(H13="SUBETAPA",OFFSET(D13,-1,0)+1,OFFSET(D13,-1,0))) -> 2 | E13: =IF(H13="Subetapa",0,IF(H13="serviço",OFFSET(E13,-1,0)+1,OFFSET(E13,-1,0))) -> 1 | H13: SERVIÇO | I13: =IF(H13="Unidade Construtiva",TEXT(A13,"00"),IF(H13="Célula Construtiva",TEXT(B13,"00"),IF(H13="Etapa",CONCATENATE(TEXT(B13,"00"),".",TEXT(C13,"000")),IF(H13="Subetapa",CONCATENATE(TEXT(B13,"00"),".",TEXT(C13,"000"),".",TEXT(D13,"000")),IF(H13="Serviço",CONCATENATE(TEXT(B13,"00"),".",TEXT(C13,"000"),".",TEXT(D13,"000"),".",TEXT(E13,"000")),""))))) -> 01.001.002.001 | J13: Escavação mecanizada para blocos de fundação, vigas de fundação e poço de elevador, com retroescavadeira | K13: m3 | L13: ='Fundação Rasa'!F167 -> 1070.0809 | M13: 36.36 | N13: =IF(H13="Serviço",M13*L13,IF(H13="CÉLULA CONSTRUTIVA",SUMIFS($N$8:$N$1410,$B$8:$B$1410,B13,$H$8:$H$1410,"Serviço"),IF(H13="ETAPA",SUMIFS($N$8:$N$1410,$B$8:$B$1410,B13,$C$8:$C$1410,C13,$H$8:$H$1410,"Serviço"),IF(H13="SUBETAPA",SUMIFS($N$8:$N$1410,$B$8:$B$1410,B13,$C$8:$C$1410,C13,$D$8:$D$1410,D13,$H$8:$H$1410,"Serviço"),0)))) -> 38908.143 | P13: Finalizado
