Workbook
Name \0: #REF!
Name \0: #REF!
Name \0: #REF!
Name \0: #REF!
Name \0: #REF!
Name \1: #REF!
Name \1: #REF!
Name \1: #REF!
Name \a: #REF!
Name \a: #REF!
Name \a: #REF!
Name \a: #REF!
Name \a: #REF!
Name \b: #REF!
Name \b: #REF!
Name \b: #REF!
Name \c: #REF!
Name \c: #REF!
Name \c: #REF!
Name \d: #REF!
Name \d: #REF!
Name \d: #REF!
Name \e: #REF!
Name \e: #REF!
Name \e: #REF!
Name \i: #REF!
Name \i: #REF!
Name \i: #REF!
Name \J: #REF!
Name \J: #REF!
Name \J: #REF!
Name \k: #REF!
Name \k: #REF!
Name \k: #REF!
Name \l: #N/A
Name \m: #REF!
Name \m: #REF!
Name \m: #REF!
Name \m: #REF!
Name \m: #REF!
Name \o: #REF!
Name \o: #REF!
Name \o: #REF!
Name \p: #REF!
Name \p: #REF!
Name \p: #REF!
Name \r: #REF!
Name \r: #REF!
Name \r: #REF!
Name \T: #REF!
Name \T: #REF!
Name \T: #REF!
Name \z: #REF!
Name \z: #REF!
Name \z: #REF!
Name \z: #REF!
Name _\0: #REF!
Name _\1: #REF!
Name _\a: #REF!
Name _\b: #REF!

Sheet Obra 
C1: Projeto | D1: Porto Cerro
C2: Empresa | D2: XPCon Empreendimentos
C3: Revisão | D3: R01 - 03/09/2025
A4: QUADRO DE ÁREAS
B6: Descrição | C6: Unidade | E6: Quantidade | G6: Imagens
B7: MESES DE OBRA | C7: MÊS | E7: 36 | I7: PARA EAP CONSIDERADO TIPO X13 COMO QUADRO
B8: ÁREA DO TERRENO | C8: M² | E8: 894.13
B9: ÁREA CONSTRUÍDA | C9: M² | E9: 13188.75
B10: NÚMERO DE UNIDADES HABITACIONAIS | C10: UN | E10: 86
B11: NÚMERO DE UNIDADES COMERCIAIS | C11: UN | E11: 0
B12: ÁREA PRIVATIVA | C12: M² | E12: =SUM(E21:E23) -> 8125.79
B13: NÚMERO DE PAVIMENTOS | C13: UN | E13: 21
B15: Térreo - G01 | C15: M² | E15: 799.52
B16: 2º pavimento - G02 | C16: M² | E16: 803.5
B17: 3º pavimento - G03 | C17: M² | E17: 803.5
B18: 4º pavimento - G04 | C18: M² | E18: 803.5
B19: 5º pavimento - G05 | C19: M² | E19: 748.28
B20: 6º pavimento - Lazer | C20: M² | E20: 796.98
B21: 7º ao 19º pavimento - Tipo (x13) | C21: M² | E21: 7112.56
B22: 20º pavimento - Tipo Diferenciado | C22: M² | E22: 547.12
B23: 21º pavimento - Duplex Superior | C23: M² | E23: 466.11
B24: Área Técnica | C24: M² | E24: 250.06
B25: Reservatório Superior | C25: M² | E25: 57.62
B31: ETAPA | C31: VALOR ORÇADO | D31: % | E31: VALOR / m²
B32: GERENCIAMENTO TÉCNICO E ADMINISTRATIVO | C32: ='Ger_Tec e Adm'!N123 -> 4533686.5 | D32: =C32/C$51 -> 0.12280121 | E32: =C32/$E$9 -> 343.75407
B33: MOVIMENTAÇÃO DE TERRA | C33: =Ger_Executivo!N8 -> 201548.69 | D33: =C33/C$51 -> 0.005459227 | E33: =C33/$E$9 -> 15.281864
B34: INFRAESTRUTURA | C34: =Ger_Executivo!N21 -> 1971424.2 | D34: =C34/C$51 -> 0.05339877 | E34: =C34/$E$9 -> 149.47771
B35: SUPRAESTRUTURA | C35: =Ger_Executivo!N53 -> 6810042.5 | D35: =C35/C$51 -> 0.18445949 | E35: =C35/$E$9 -> 516.35239
B36: ALVENARIA ESTRUTURAL | C36: =Ger_Executivo!N220 -> 1867619.9 | D36: =C36/C$51 -> 0.050587087 | E36: =C36/$E$9 -> 141.60705
B37: ALVENARIA | C37: =Ger_Executivo!N275 -> 743245.34 | D37: =C37/C$51 -> 0.020131835 | E37: =C37/$E$9 -> 56.354495
B38: IMPERMEABILIZAÇÃO E TRATAMENTOS | C38: =Ger_Executivo!N329 -> 570028.95 | D38: =C38/C$51 -> 0.015440028 | E38: =C38/$E$9 -> 43.220848
B39: INSTALAÇÕES ELÉTRICAS, HIDRÁULICAS, GLP E PREVENTIVAS | C39: =Ger_Executivo!N431+Ger_Executivo!N470+Ger_Executivo!N609 -> 3848757 | D39: =C39/C$51 -> 0.10424894 | E39: =C39/$E$9 -> 291.82121
B40: EQUIPAMENTOS E SISTEMAS ESPECIAIS | C40: =Ger_Executivo!N708+Ger_Executivo!N718 -> 1709214.5 | D40: =C40/C$51 -> 0.046296455 | E40: =C40/$E$9 -> 129.5964
B41: REVESTIMENTOS INTERNOS DE PAREDE | C41: =Ger_Executivo!N747 -> 1655202.7 | D41: =C41/C$51 -> 0.044833469 | E41: =C41/$E$9 -> 125.5011
B42: REVESTIMENTOS E ACABAMENTOS EM TETO | C42: =Ger_Executivo!N865 -> 680621.57 | D42: =C42/C$51 -> 0.018435583 | E42: =C42/$E$9 -> 51.606223
B43: PISOS E PAVIMENTAÇÕES | C43: =Ger_Executivo!N912 -> 1992159.7 | D43: =C43/C$51 -> 0.053960421 | E43: =C43/$E$9 -> 151.04993
B44: SISTEMAS DE PINTURA INTERNA | C44: =Ger_Executivo!N1055 -> 2004994 | D44: =C44/C$51 -> 0.054308054 | E44: =C44/$E$9 -> 152.02305
B45: ESQUADRIAS, VIDROS E FERRAGENS | C45: =Ger_Executivo!N1185 -> 4314922.3 | D45: =C45/C$51 -> 0.11687568 | E45: =C45/$E$9 -> 327.16689
B46: LOUÇAS E METAIS | C46: =Ger_Executivo!N1308 -> 390783.28 | D46: =C46/C$51 -> 0.010584909 | E46: =C46/$E$9 -> 29.630047
B47: COBERTURA | C47: =Ger_Executivo!N1342 -> 163256.76 | D47: =C47/C$51 -> 0.0044220368 | E47: =C47/$E$9 -> 12.378486
...

Sheet Comparativo
B2: ETAPA | D2: PORTO CERRO R01 | G2: PORTO CERRO R00 | J2: PORTO CERRO - PRELIMINAR
D3: VALOR | E3: VALOR / m² | G3: VALOR | H3: VALOR / m² | J3: VALOR | K3: VALOR / m²
B4: GERENCIAMENTO TÉCNICO E ADMINISTRATIVO | D4: ='Obra '!C32 -> 4533686.5 | E4: ='Obra '!E32 -> 343.75407 | G4: 4060804.3 | H4: 307.89911 | J4: 3316841.3 | K4: 251.49019 | L4: Adicção de taxas e ajuste de equipamentos
B5: MOVIMENTAÇÃO DE TERRA | D5: ='Obra '!C33 -> 201548.69 | E5: ='Obra '!E33 -> 15.281864 | G5: 201548.69 | H5: 15.281864 | J5: 202605.16 | K5: 15.361969
B6: INFRAESTRUTURA | D6: ='Obra '!C34 -> 1971424.2 | E6: ='Obra '!E34 -> 149.47771 | G6: 1992929.8 | H6: 151.10831 | J6: 1836089.2 | K6: 139.21632 | L6: Retirada ede 1 jogo de forma
B7: SUPRAESTRUTURA | D7: ='Obra '!C35 -> 6810042.5 | E7: ='Obra '!E35 -> 516.35239 | G7: 6950469.5 | H7: 526.99987 | J7: 6497994.5 | K7: 492.69222
B8: ALVENARIA C/ ALVENARIA ESTRUTURAL | D8: ='Obra '!C36 -> 1867619.9 | E8: ='Obra '!E36 -> 141.60705 | G8: 2556087.3 | H8: 193.80815 | J8: 2378567.9 | K8: 180.34824
B9: ALVENARIA | D9: ='Obra '!C37 -> 743245.34 | E9: ='Obra '!E37 -> 56.354495
B10: INSTALAÇÕES ELÉTRICAS, HIDRÁULICAS, GLP, PREVENTIVAS | D10: ='Obra '!C39 -> 3848757 | E10: ='Obra '!E39 -> 291.82121 | G10: 3848757 | H10: 291.82121 | J10: 4956478.4 | K10: 375.81108
B11: EQUIPAMENTOS E SISTEMAS ESPECIAIS | D11: ='Obra '!C40 -> 1709214.5 | E11: ='Obra '!E40 -> 129.5964 | G11: 1528823 | H11: 115.91872 | J11: 1765339.5 | K11: 133.85192 | L11: Adição de sistemas keyless, camera, som, wi-fi e aquecimento de piscina
B12: IMPERMEABILIZAÇÃO | D12: ='Obra '!C38 -> 570028.95 | E12: ='Obra '!E38 -> 43.220848 | G12: 701038.53 | H12: 53.154282 | J12: 594137.8 | K12: 45.048834 | L12: Troca de laje impermeabilizada por telhado
B13: REVESTIMENTOS INTERNOS EM PAREDE | D13: ='Obra '!C41 -> 1655202.7 | E13: ='Obra '!E41 -> 125.5011 | G13: 1484604.3 | H13: 112.56596 | J13: 2016787.3 | K13: 152.91725 | L13: Adição de azulejo em parede dos banheiros e nichos
B14: REVESTIMENTOS E ACABAMENTOS INTERNOS EM TETO | D14: ='Obra '!C42 -> 680621.57 | E14: ='Obra '!E42 -> 51.606223 | G14: 680621.57 | H14: 51.606223 | J14: 862538.2 | K14: 65.399542
B15: PISOS E PAVIMENTAÇÕES | D15: ='Obra '!C43 -> 1992159.7 | E15: ='Obra '!E43 -> 151.04993 | G15: 1983338.7 | H15: 150.3811 | J15: 2353078.9 | K15: 178.41561 | L15: Adição de piso do elevador
B16: PINTURA INTERNA | D16: ='Obra '!C44 -> 2004994 | E16: ='Obra '!E44 -> 152.02305 | G16: 2133154.1 | H16: 161.74043 | J16: 2117102.7 | K16: 160.52338 | L16: Adição de azulejo em parede dos banheiros
B17: ESQUADRIAS, VIDROS E FERRAGENS | D17: ='Obra '!C45 -> 4314922.3 | E17: ='Obra '!E45 -> 327.16689 | G17: 4204046.3 | H17: 318.76002 | J17: 3224819 | K17: 244.51286 | L17: Adição de moldura churrasqueira
B18: COBERTURA | D18: ='Obra '!C47 -> 163256.76 | E18: ='Obra '!E47 -> 12.378486 | G18: 1798.7264 | H18: 0.13638339 | J18: 31796.941 | K18: 2.4109139 | L18: Troca de laje impermeabilizada por telhado
B19: LOUÇAS E METAIS | D19: ='Obra '!C46 -> 390783.28 | E19: ='Obra '!E46 -> 29.630047 | G19: 390783.28 | H19: 29.630047 | J19: 538815.72 | K19: 40.854192
B20: REVESTIMENTOS E ACABAMENTOS DE FACHADA | D20: ='Obra '!C48 -> 1305274.1 | E20: ='Obra '!E48 -> 98.968748 | G20: 1305247 | H20: 98.966695 | J20: 2253614.2 | K20: 170.87398
B21: SERVIÇOS COMPLEMENTARES | D21: ='Obra '!C49 -> 1521120.1 | E21: ='Obra '!E49 -> 115.33467 | G21: 1521120.1 | H21: 115.33467 | J21: 1016211.9 | K21: 77.051421
B22: IMPREVISTOS E CONTINGENCIAS | D22: ='Obra '!C50 -> 635004.31 | E22: ='Obra '!E50 -> 48.147422 | G22: 629687.36 | H22: 47.744279 | K22: 0
B23: TOTAL | D23: =SUM(D4:D22) -> 36918906 | E23: =SUM(E4:E22) -> 2799.2726 | G23: 36174859 | H23: 2742.8573 | J23: 35962819 | K23: 2726.7799

Sheet Ger_Tec e Adm
G4: PROJETO: | I4: Porto Cerro | O4: REVISÃO: | P4: DATA
G5: EMPRESA: | I5: XPCon | O5: ='Obra '!D3 -> R01 - 03/09/2025 | P5: 45860
A6: Unidade Construtiva | B6: Célula Construtiva | C6: Etapa | D6: Subetapa | E6: Serviço | G6: GERENCIAMENTO EXECUTIVO
A7: 0 | B7: 0 | C7: 0 | D7: 0 | E7: 0 | G7: Atalho | H7: NIVEL | I7: Item | J7: Descrição | K7: Unidade | L7: Quant. | M7: Preço un | N7: Total | O7: Considerações | P7: Situação
A8: =IF($H8="UNIDADE CONSTRUTIVA",OFFSET(A8,-1,0)+1,LARGE(A$3:A7,1)) -> 0 | B8: =IF(H8="UNIDADE CONSTRUTIVA",0,IF(H8="CÉLULA CONSTRUTIVA",OFFSET(B8,-1,0)+1,OFFSET(B8,-1,0))) -> 1 | C8: =IF(H8="CÉLULA CONSTRUTIVA",0,IF(H8="ETAPA",OFFSET(C8,-1,0)+1,OFFSET(C8,-1,0))) -> 0 | D8: =IF(H8="ETAPA",0,IF(H8="SUBETAPA",OFFSET(D8,-1,0)+1,OFFSET(D8,-1,0))) -> 0 | E8: =IF(H8="Subetapa",0,IF(H8="serviço",OFFSET(E8,-1,0)+1,OFFSET(E8,-1,0))) -> 0 | H8: CÉLULA CONSTRUTIVA | I8: =IF(H8="Unidade Construtiva",TEXT(A8,"00"),IF(H8="Célula Construtiva",TEXT(B8,"00"),IF(H8="Etapa",CONCATENATE(TEXT(B8,"00"),".",TEXT(C8,"000")),IF(H8="Subetapa",CONCATENATE(TEXT(B8,"00"),".",TEXT(C8,"000"),".",TEXT(D8,"000")),IF(H8="Serviço",CONCATENATE(TEXT(B8,"00"),".",TEXT(C8,"000"),".",TEXT(D8,"000"),".",TEXT(E8,"000")),""))))) -> 01 | J8: SERVIÇOS TÉCNICOS | N8: =IF(H8="Serviço",M8*L8,IF(H8="CÉLULA CONSTRUTIVA",SUMIFS($N$8:$N$420,$B$8:$B$420,B8,$H$8:$H$420,"Serviço"),IF(H8="ETAPA",SUMIFS($N$8:$N$420,$B$8:$B$420,B8,$C$8:$C$420,C8,$H$8:$H$420,"Serviço"),IF(H8="SUBETAPA",SUMIFS($N$8:$N$420,$B$8:$B$420,B8,$C$8:$C$420,C8,$D$8:$D$420,D8,$H$8:$H$420,"Serviço"),0)))) -> 1970733.8 | P8: - | R8: Adicionado/alterado em reivsao
A9: =IF($H9="UNIDADE CONSTRUTIVA",OFFSET(A9,-1,0)+1,LARGE(A$3:A8,1)) -> 0 | B9: =IF(H9="UNIDADE CONSTRUTIVA",0,IF(H9="CÉLULA CONSTRUTIVA",OFFSET(B9,-1,0)+1,OFFSET(B9,-1,0))) -> 1 | C9: =IF(H9="CÉLULA CONSTRUTIVA",0,IF(H9="ETAPA",OFFSET(C9,-1,0)+1,OFFSET(C9,-1,0))) -> 1 | D9: =IF(H9="ETAPA",0,IF(H9="SUBETAPA",OFFSET(D9,-1,0)+1,OFFSET(D9,-1,0))) -> 0 | E9: =IF(H9="Subetapa",0,IF(H9="serviço",OFFSET(E9,-1,0)+1,OFFSET(E9,-1,0))) -> 0 | H9: ETAPA | I9: =IF(H9="Unidade Construtiva",TEXT(A9,"00"),IF(H9="Célula Construtiva",TEXT(B9,"00"),IF(H9="Etapa",CONCATENATE(TEXT(B9,"00"),".",TEXT(C9,"000")),IF(H9="Subetapa",CONCATENATE(TEXT(B9,"00"),".",TEXT(C9,"000"),".",TEXT(D9,"000")),IF(H9="Serviço",CONCATENATE(TEXT(B9,"00"),".",TEXT(C9,"000"),".",TEXT(D9,"000"),".",TEXT(E9,"000")),""))))) -> 01.001 | J9: ESTUDOS, PROJETOS, CONSULTORIA E ENSAIOS | N9: =IF(H9="Serviço",M9*L9,IF(H9="CÉLULA CONSTRUTIVA",SUMIFS($N$8:$N$420,$B$8:$B$420,B9,$H$8:$H$420,"Serviço"),IF(H9="ETAPA",SUMIFS($N$8:$N$420,$B$8:$B$420,B9,$C$8:$C$420,C9,$H$8:$H$420,"Serviço"),IF(H9="SUBETAPA",SUMIFS($N$8:$N$420,$B$8:$B$420,B9,$C$8:$C$420,C9,$D$8:$D$420,D9,$H$8:$H$420,"Serviço"),0)))) -> 921014.53 | P9: -
A10: =IF($H10="UNIDADE CONSTRUTIVA",OFFSET(A10,-1,0)+1,LARGE(A$3:A9,1)) -> 0 | B10: =IF(H10="UNIDADE CONSTRUTIVA",0,IF(H10="CÉLULA CONSTRUTIVA",OFFSET(B10,-1,0)+1,OFFSET(B10,-1,0))) -> 1 | C10: =IF(H10="CÉLULA CONSTRUTIVA",0,IF(H10="ETAPA",OFFSET(C10,-1,0)+1,OFFSET(C10,-1,0))) -> 1 | D10: =IF(H10="ETAPA",0,IF(H10="SUBETAPA",OFFSET(D10,-1,0)+1,OFFSET(D10,-1,0))) -> 1 | E10: =IF(H10="Subetapa",0,IF(H10="serviço",OFFSET(E10,-1,0)+1,OFFSET(E10,-1,0))) -> 0 | H10: SUBETAPA | I10: =IF(H10="Unidade Construtiva",TEXT(A10,"00"),IF(H10="Célula Construtiva",TEXT(B10,"00"),IF(H10="Etapa",CONCATENATE(TEXT(B10,"00"),".",TEXT(C10,"000")),IF(H10="Subetapa",CONCATENATE(TEXT(B10,"00"),".",TEXT(C10,"000"),".",TEXT(D10,"000")),IF(H10="Serviço",CONCATENATE(TEXT(B10,"00"),".",TEXT(C10,"000"),".",TEXT(D10,"000"),".",TEXT(E10,"000")),""))))) -> 01.001.001 | J10: Estudos | N10: =IF(H10="Serviço",M10*L10,IF(H10="CÉLULA CONSTRUTIVA",SUMIFS($N$8:$N$420,$B$8:$B$420,B10,$H$8:$H$420,"Serviço"),IF(H10="ETAPA",SUMIFS($N$8:$N$420,$B$8:$B$420,B10,$C$8:$C$420,C10,$H$8:$H$420,"Serviço"),IF(H10="SUBETAPA",SUMIFS($N$8:$N$420,$B$8:$B$420,B10,$C$8:$C$420,C10,$D$8:$D$420,D10,$H$8:$H$420,"Serviço"),0)))) -> 109972.88
A11: =IF($H11="UNIDADE CONSTRUTIVA",OFFSET(A11,-1,0)+1,LARGE(A$3:A10,1)) -> 0 | B11: =IF(H11="UNIDADE CONSTRUTIVA",0,IF(H11="CÉLULA CONSTRUTIVA",OFFSET(B11,-1,0)+1,OFFSET(B11,-1,0))) -> 1 | C11: =IF(H11="CÉLULA CONSTRUTIVA",0,IF(H11="ETAPA",OFFSET(C11,-1,0)+1,OFFSET(C11,-1,0))) -> 1 | D11: =IF(H11="ETAPA",0,IF(H11="SUBETAPA",OFFSET(D11,-1,0)+1,OFFSET(D11,-1,0))) -> 1 | E11: =IF(H11="Subetapa",0,IF(H11="serviço",OFFSET(E11,-1,0)+1,OFFSET(E11,-1,0))) -> 1 | H11: SERVIÇO | I11: =IF(H11="Unidade Construtiva",TEXT(A11,"00"),IF(H11="Célula Construtiva",TEXT(B11,"00"),IF(H11="Etapa",CONCATENATE(TEXT(B11,"00"),".",TEXT(C11,"000")),IF(H11="Subetapa",CONCATENATE(TEXT(B11,"00"),".",TEXT(C11,"000"),".",TEXT(D11,"000")),IF(H11="Serviço",CONCATENATE(TEXT(B11,"00"),".",TEXT(C11,"000"),".",TEXT(D11,"000"),".",TEXT(E11,"000")),""))))) -> 01.001.001.001 | J11: Memorial descritivo | K11: vb | L11: 1 | M11: 6512.1875 | N11: =IF(H11="Serviço",M11*L11,IF(H11="CÉLULA CONSTRUTIVA",SUMIFS($N$8:$N$420,$B$8:$B$420,B11,$H$8:$H$420,"Serviço"),IF(H11="ETAPA",SUMIFS($N$8:$N$420,$B$8:$B$420,B11,$C$8:$C$420,C11,$H$8:$H$420,"Serviço"),IF(H11="SUBETAPA",SUMIFS($N$8:$N$420,$B$8:$B$420,B11,$C$8:$C$420,C11,$D$8:$D$420,D11,$H$8:$H$420,"Serviço"),0)))) -> 6512.1875 | O11: Estimado com base em índices históricos | P11: Lançado ERP
A12: =IF($H12="UNIDADE CONSTRUTIVA",OFFSET(A12,-1,0)+1,LARGE(A$3:A11,1)) -> 0 | B12: =IF(H12="UNIDADE CONSTRUTIVA",0,IF(H12="CÉLULA CONSTRUTIVA",OFFSET(B12,-1,0)+1,OFFSET(B12,-1,0))) -> 1 | C12: =IF(H12="CÉLULA CONSTRUTIVA",0,IF(H12="ETAPA",OFFSET(C12,-1,0)+1,OFFSET(C12,-1,0))) -> 1 | D12: =IF(H12="ETAPA",0,IF(H12="SUBETAPA",OFFSET(D12,-1,0)+1,OFFSET(D12,-1,0))) -> 1 | E12: =IF(H12="Subetapa",0,IF(H12="serviço",OFFSET(E12,-1,0)+1,OFFSET(E12,-1,0))) -> 2 | H12: SERVIÇO | I12: =IF(H12="Unidade Construtiva",TEXT(A12,"00"),IF(H12="Célula Construtiva",TEXT(B12,"00"),IF(H12="Etapa",CONCATENATE(TEXT(B12,"00"),".",TEXT(C12,"000")),IF(H12="Subetapa",CONCATENATE(TEXT(B12,"00"),".",TEXT(C12,"000"),".",TEXT(D12,"000")),IF(H12="Serviço",CONCATENATE(TEXT(B12,"00"),".",TEXT(C12,"000"),".",TEXT(D12,"000"),".",TEXT(E12,"000")),""))))) -> 01.001.001.002 | J12: Levantamento Topográfico | K12: vb | L12: 1 | M12: 9550.2178 | N12: =IF(H12="Serviço",M12*L12,IF(H12="CÉLULA CONSTRUTIVA",SUMIFS($N$8:$N$420,$B$8:$B$420,B12,$H$8:$H$420,"Serviço"),IF(H12="ETAPA",SUMIFS($N$8:$N$420,$B$8:$B$420,B12,$C$8:$C$420,C12,$H$8:$H$420,"Serviço"),IF(H12="SUBETAPA",SUMIFS($N$8:$N$420,$B$8:$B$420,B12,$C$8:$C$420,C12,$D$8:$D$420,D12,$H$8:$H$420,"Serviço"),0)))) -> 9550.2178 | O12: Estimado com base em índices históricos | P12: Lançado ERP
A13: =IF($H13="UNIDADE CONSTRUTIVA",OFFSET(A13,-1,0)+1,LARGE(A$3:A12,1)) -> 0 | B13: =IF(H13="UNIDADE CONSTRUTIVA",0,IF(H13="CÉLULA CONSTRUTIVA",OFFSET(B13,-1,0)+1,OFFSET(B13,-1,0))) -> 1 | C13: =IF(H13="CÉLULA CONSTRUTIVA",0,IF(H13="ETAPA",OFFSET(C13,-1,0)+1,OFFSET(C13,-1,0))) -> 1 | D13: =IF(H13="ETAPA",0,IF(H13="SUBETAPA",OFFSET(D13,-1,0)+1,OFFSET(D13,-1,0))) -> 1 | E13: =IF(H13="Subetapa",0,IF(H13="serviço",OFFSET(E13,-1,0)+1,OFFSET(E13,-1,0))) -> 3 | H13: SERVIÇO | I13: =IF(H13="Unidade Construtiva",TEXT(A13,"00"),IF(H13="Célula Construtiva",TEXT(B13,"00"),IF(H13="Etapa",CONCATENATE(TEXT(B13,"00"),".",TEXT(C13,"000")),IF(H13="Subetapa",CONCATENATE(TEXT(B13,"00"),".",TEXT(C13,"000"),".",TEXT(D13,"000")),IF(H13="Serviço",CONCATENATE(TEXT(B13,"00"),".",TEXT(C13,"000"),".",TEXT(D13,"000"),".",TEXT(E13,"000")),""))))) -> 01.001.001.003 | J13: Estudo ambiental | K13: vb | L13: 1 | M13: 70034.931 | N13: =IF(H13="Serviço",M13*L13,IF(H13="CÉLULA CONSTRUTIVA",SUMIFS($N$8:$N$420,$B$8:$B$420,B13,$H$8:$H$420,"Serviço"),IF(H13="ETAPA",SUMIFS($N$8:$N$420,$B$8:$B$420,B13,$C$8:$C$420,C13,$H$8:$H$420,"Serviço"),IF(H13="SUBETAPA",SUMIFS($N$8:$N$420,$B$8:$B$420,B13,$C$8:$C$420,C13,$D$8:$D$420,D13,$H$8:$H$420,"Serviço"),0)))) -> 70034.931 | O13: Estimado com base em índices históricos | P13: Lançado ERP
A14: =IF($H14="UNIDADE CONSTRUTIVA",OFFSET(A14,-1,0)+1,LARGE(A$3:A13,1)) -> 0 | B14: =IF(H14="UNIDADE CONSTRUTIVA",0,IF(H14="CÉLULA CONSTRUTIVA",OFFSET(B14,-1,0)+1,OFFSET(B14,-1,0))) -> 1 | C14: =IF(H14="CÉLULA CONSTRUTIVA",0,IF(H14="ETAPA",OFFSET(C14,-1,0)+1,OFFSET(C14,-1,0))) -> 1 | D14: =IF(H14="ETAPA",0,IF(H14="SUBETAPA",OFFSET(D14,-1,0)+1,OFFSET(D14,-1,0))) -> 1 | E14: =IF(H14="Subetapa",0,IF(H14="serviço",OFFSET(E14,-1,0)+1,OFFSET(E14,-1,0))) -> 4 | H14: SERVIÇO | I14: =IF(H14="Unidade Construtiva",TEXT(A14,"00"),IF(H14="Célula Construtiva",TEXT(B14,"00"),IF(H14="Etapa",CONCATENATE(TEXT(B14,"00"),".",TEXT(C14,"000")),IF(H14="Subetapa",CONCATENATE(TEXT(B14,"00"),".",TEXT(C14,"000"),".",TEXT(D14,"000")),IF(H14="Serviço",CONCATENATE(TEXT(B14,"00"),".",TEXT(C14,"000"),".",TEXT(D14,"000"),".",TEXT(E14,"000")),""))))) -> 01.001.001.004 | J14: Sondagem do terreno | K14: vb | L14: 1 | M14: 23875.545 | N14: =IF(H14="Serviço",M14*L14,IF(H14="CÉLULA CONSTRUTIVA",SUMIFS($N$8:$N$420,$B$8:$B$420,B14,$H$8:$H$420,"Serviço"),IF(H14="ETAPA",SUMIFS($N$8:$N$420,$B$8:$B$420,B14,$C$8:$C$420,C14,$H$8:$H$420,"Serviço"),IF(H14="SUBETAPA",SUMIFS($N$8:$N$420,$B$8:$B$420,B14,$C$8:$C$420,C14,$D$8:$D$420,D14,$H$8:$H$420,"Serviço"),0)))) -> 23875.545 | O14: Estimado com base em índices históricos | P14: Lançado ERP
A15: =IF($H15="UNIDADE CONSTRUTIVA",OFFSET(A15,-1,0)+1,LARGE(A$3:A14,1)) -> 0 | B15: =IF(H15="UNIDADE CONSTRUTIVA",0,IF(H15="CÉLULA CONSTRUTIVA",OFFSET(B15,-1,0)+1,OFFSET(B15,-1,0))) -> 1 | C15: =IF(H15="CÉLULA CONSTRUTIVA",0,IF(H15="ETAPA",OFFSET(C15,-1,0)+1,OFFSET(C15,-1,0))) -> 1 | D15: =IF(H15="ETAPA",0,IF(H15="SUBETAPA",OFFSET(D15,-1,0)+1,OFFSET(D15,-1,0))) -> 2 | E15: =IF(H15="Subetapa",0,IF(H15="serviço",OFFSET(E15,-1,0)+1,OFFSET(E15,-1,0))) -> 0 | H15: SUBETAPA | I15: =IF(H15="Unidade Construtiva",TEXT(A15,"00"),IF(H15="Célula Construtiva",TEXT(B15,"00"),IF(H15="Etapa",CONCATENATE(TEXT(B15,"00"),".",TEXT(C15,"000")),IF(H15="Subetapa",CONCATENATE(TEXT(B15,"00"),".",TEXT(C15,"000"),".",TEXT(D15,"000")),IF(H15="Serviço",CONCATENATE(TEXT(B15,"00"),".",TEXT(C15,"000"),".",TEXT(D15,"000"),".",TEXT(E15,"000")),""))))) -> 01.001.002 | J15: Projetos | N15: =IF(H15="Serviço",M15*L15,IF(H15="CÉLULA CONSTRUTIVA",SUMIFS($N$8:$N$420,$B$8:$B$420,B15,$H$8:$H$420,"Serviço"),IF(H15="ETAPA",SUMIFS($N$8:$N$420,$B$8:$B$420,B15,$C$8:$C$420,C15,$H$8:$H$420,"Serviço"),IF(H15="SUBETAPA",SUMIFS($N$8:$N$420,$B$8:$B$420,B15,$C$8:$C$420,C15,$D$8:$D$420,D15,$H$8:$H$420,"Serviço"),0)))) -> 556996.27
A16: =IF($H16="UNIDADE CONSTRUTIVA",OFFSET(A16,-1,0)+1,LARGE(A$3:A15,1)) -> 0 | B16: =IF(H16="UNIDADE CONSTRUTIVA",0,IF(H16="CÉLULA CONSTRUTIVA",OFFSET(B16,-1,0)+1,OFFSET(B16,-1,0))) -> 1 | C16: =IF(H16="CÉLULA CONSTRUTIVA",0,IF(H16="ETAPA",OFFSET(C16,-1,0)+1,OFFSET(C16,-1,0))) -> 1 | D16: =IF(H16="ETAPA",0,IF(H16="SUBETAPA",OFFSET(D16,-1,0)+1,OFFSET(D16,-1,0))) -> 2 | E16: =IF(H16="Subetapa",0,IF(H16="serviço",OFFSET(E16,-1,0)+1,OFFSET(E16,-1,0))) -> 1 | H16: SERVIÇO | I16: =IF(H16="Unidade Construtiva",TEXT(A16,"00"),IF(H16="Célula Construtiva",TEXT(B16,"00"),IF(H16="Etapa",CONCATENATE(TEXT(B16,"00"),".",TEXT(C16,"000")),IF(H16="Subetapa",CONCATENATE(TEXT(B16,"00"),".",TEXT(C16,"000"),".",TEXT(D16,"000")),IF(H16="Serviço",CONCATENATE(TEXT(B16,"00"),".",TEXT(C16,"000"),".",TEXT(D16,"000"),".",TEXT(E16,"000")),""))))) -> 01.001.002.001 | J16: Legalização de incorporação | K16: vb | L16: 1 | M16: 19100.436 | N16: =IF(H16="Serviço",M16*L16,IF(H16="CÉLULA CONSTRUTIVA",SUMIFS($N$8:$N$420,$B$8:$B$420,B16,$H$8:$H$420,"Serviço"),IF(H16="ETAPA",SUMIFS($N$8:$N$420,$B$8:$B$420,B16,$C$8:$C$420,C16,$H$8:$H$420,"Serviço"),IF(H16="SUBETAPA",SUMIFS($N$8:$N$420,$B$8:$B$420,B16,$C$8:$C$420,C16,$D$8:$D$420,D16,$H$8:$H$420,"Serviço"),0)))) -> 19100.436 | O16: Estimado com base em índices históricos | P16: Finalizado
A17: =IF($H17="UNIDADE CONSTRUTIVA",OFFSET(A17,-1,0)+1,LARGE(A$3:A16,1)) -> 0 | B17: =IF(H17="UNIDADE CONSTRUTIVA",0,IF(H17="CÉLULA CONSTRUTIVA",OFFSET(B17,-1,0)+1,OFFSET(B17,-1,0))) -> 1 | C17: =IF(H17="CÉLULA CONSTRUTIVA",0,IF(H17="ETAPA",OFFSET(C17,-1,0)+1,OFFSET(C17,-1,0))) -> 1 | D17: =IF(H17="ETAPA",0,IF(H17="SUBETAPA",OFFSET(D17,-1,0)+1,OFFSET(D17,-1,0))) -> 2 | E17: =IF(H17="Subetapa",0,IF(H17="serviço",OFFSET(E17,-1,0)+1,OFFSET(E17,-1,0))) -> 2 | H17: SERVIÇO | I17: =IF(H17="Unidade Construtiva",TEXT(A17,"00"),IF(H17="Célula Construtiva",TEXT(B17,"00"),IF(H17="Etapa",CONCATENATE(TEXT(B17,"00"),".",TEXT(C17,"000")),IF(H17="Subetapa",CONCATENATE(TEXT(B17,"00"),".",TEXT(C17,"000"),".",TEXT(D17,"000")),IF(H17="Serviço",CONCATENATE(TEXT(B17,"00"),".",TEXT(C17,"000"),".",TEXT(D17,"000"),".",TEXT(E17,"000")),""))))) -> 01.001.002.002 | J17: Projeto Arquitetônico legal | K17: vb | L17: 1 | M17: 85156.109 | N17: =IF(H17="Serviço",M17*L17,IF(H17="CÉLULA CONSTRUTIVA",SUMIFS($N$8:$N$420,$B$8:$B$420,B17,$H$8:$H$420,"Serviço"),IF(H17="ETAPA",SUMIFS($N$8:$N$420,$B$8:$B$420,B17,$C$8:$C$420,C17,$H$8:$H$420,"Serviço"),IF(H17="SUBETAPA",SUMIFS($N$8:$N$420,$B$8:$B$420,B17,$C$8:$C$420,C17,$D$8:$D$420,D17,$H$8:$H$420,"Serviço"),0)))) -> 85156.109 | O17: Estimado com base em índices históricos | P17: Finalizado
A18: =IF($H18="UNIDADE CONSTRUTIVA",OFFSET(A18,-1,0)+1,LARGE(A$3:A17,1)) -> 0 | B18: =IF(H18="UNIDADE CONSTRUTIVA",0,IF(H18="CÉLULA CONSTRUTIVA",OFFSET(B18,-1,0)+1,OFFSET(B18,-1,0))) -> 1 | C18: =IF(H18="CÉLULA CONSTRUTIVA",0,IF(H18="ETAPA",OFFSET(C18,-1,0)+1,OFFSET(C18,-1,0))) -> 1 | D18: =IF(H18="ETAPA",0,IF(H18="SUBETAPA",OFFSET(D18,-1,0)+1,OFFSET(D18,-1,0))) -> 2 | E18: =IF(H18="Subetapa",0,IF(H18="serviço",OFFSET(E18,-1,0)+1,OFFSET(E18,-1,0))) -> 3 | H18: SERVIÇO | I18: =IF(H18="Unidade Construtiva",TEXT(A18,"00"),IF(H18="Célula Construtiva",TEXT(B18,"00"),IF(H18="Etapa",CONCATENATE(TEXT(B18,"00"),".",TEXT(C18,"000")),IF(H18="Subetapa",CONCATENATE(TEXT(B18,"00"),".",TEXT(C18,"000"),".",TEXT(D18,"000")),IF(H18="Serviço",CONCATENATE(TEXT(B18,"00"),".",TEXT(C18,"000"),".",TEXT(D18,"000"),".",TEXT(E18,"000")),""))))) -> 01.001.002.003 | J18: Projeto Arquitetônico Executivo | K18: vb | L18: 1 | M18: 85156.109 | N18: =IF(H18="Serviço",M18*L18,IF(H18="CÉLULA CONSTRUTIVA",SUMIFS($N$8:$N$420,$B$8:$B$420,B18,$H$8:$H$420,"Serviço"),IF(H18="ETAPA",SUMIFS($N$8:$N$420,$B$8:$B$420,B18,$C$8:$C$420,C18,$H$8:$H$420,"Serviço"),IF(H18="SUBETAPA",SUMIFS($N$8:$N$420,$B$8:$B$420,B18,$C$8:$C$420,C18,$D$8:$D$420,D18,$H$8:$H$420,"Serviço"),0)))) -> 85156.109 | O18: Estimado com base em índices históricos | P18: Finalizado
A19: =IF($H19="UNIDADE CONSTRUTIVA",OFFSET(A19,-1,0)+1,LARGE(A$3:A18,1)) -> 0 | B19: =IF(H19="UNIDADE CONSTRUTIVA",0,IF(H19="CÉLULA CONSTRUTIVA",OFFSET(B19,-1,0)+1,OFFSET(B19,-1,0))) -> 1 | C19: =IF(H19="CÉLULA CONSTRUTIVA",0,IF(H19="ETAPA",OFFSET(C19,-1,0)+1,OFFSET(C19,-1,0))) -> 1 | D19: =IF(H19="ETAPA",0,IF(H19="SUBETAPA",OFFSET(D19,-1,0)+1,OFFSET(D19,-1,0))) -> 2 | E19: =IF(H19="Subetapa",0,IF(H19="serviço",OFFSET(E19,-1,0)+1,OFFSET(E19,-1,0))) -> 4 | H19: SERVIÇO | I19: =IF(H19="Unidade Construtiva",TEXT(A19,"00"),IF(H19="Célula Construtiva",TEXT(B19,"00"),IF(H19="Etapa",CONCATENATE(TEXT(B19,"00"),".",TEXT(C19,"000")),IF(H19="Subetapa",CONCATENATE(TEXT(B19,"00"),".",TEXT(C19,"000"),".",TEXT(D19,"000")),IF(H19="Serviço",CONCATENATE(TEXT(B19,"00"),".",TEXT(C19,"000"),".",TEXT(D19,"000"),".",TEXT(E19,"000")),""))))) -> 01.001.002.004 | J19: Projeto de Fundação | K19: vb | L19: 1 | M19: 27058.951 | N19: =IF(H19="Serviço",M19*L19,IF(H19="CÉLULA CONSTRUTIVA",SUMIFS($N$8:$N$420,$B$8:$B$420,B19,$H$8:$H$420,"Serviço"),IF(H19="ETAPA",SUMIFS($N$8:$N$420,$B$8:$B$420,B19,$C$8:$C$420,C19,$H$8:$H$420,"Serviço"),IF(H19="SUBETAPA",SUMIFS($N$8:$N$420,$B$8:$B$420,B19,$C$8:$C$420,C19,$D$8:$D$420,D19,$H$8:$H$420,"Serviço"),0)))) -> 27058.951 | O19: Estimado com base em índices históricos | P19: Finalizado
A20: =IF($H20="UNIDADE CONSTRUTIVA",OFFSET(A20,-1,0)+1,LARGE(A$3:A19,1)) -> 0 | B20: =IF(H20="UNIDADE CONSTRUTIVA",0,IF(H20="CÉLULA CONSTRUTIVA",OFFSET(B20,-1,0)+1,OFFSET(B20,-1,0))) -> 1 | C20: =IF(H20="CÉLULA CONSTRUTIVA",0,IF(H20="ETAPA",OFFSET(C20,-1,0)+1,OFFSET(C20,-1,0))) -> 1 | D20: =IF(H20="ETAPA",0,IF(H20="SUBETAPA",OFFSET(D20,-1,0)+1,OFFSET(D20,-1,0))) -> 2 | E20: =IF(H20="Subetapa",0,IF(H20="serviço",OFFSET(E20,-1,0)+1,OFFSET(E20,-1,0))) -> 5 | H20: SERVIÇO | I20: =IF(H20="Unidade Construtiva",TEXT(A20,"00"),IF(H20="Célula Construtiva",TEXT(B20,"00"),IF(H20="Etapa",CONCATENATE(TEXT(B20,"00"),".",TEXT(C20,"000")),IF(H20="Subetapa",CONCATENATE(TEXT(B20,"00"),".",TEXT(C20,"000"),".",TEXT(D20,"000")),IF(H20="Serviço",CONCATENATE(TEXT(B20,"00"),".",TEXT(C20,"000"),".",TEXT(D20,"000"),".",TEXT(E20,"000")),""))))) -> 01.001.002.005 | J20: Projeto Estrutura | K20: vb | L20: 1 | M20: 119696.06 | N20: =IF(H20="Serviço",M20*L20,IF(H20="CÉLULA CONSTRUTIVA",SUMIFS($N$8:$N$420,$B$8:$B$420,B20,$H$8:$H$420,"Serviço"),IF(H20="ETAPA",SUMIFS($N$8:$N$420,$B$8:$B$420,B20,$C$8:$C$420,C20,$H$8:$H$420,"Serviço"),IF(H20="SUBETAPA",SUMIFS($N$8:$N$420,$B$8:$B$420,B20,$C$8:$C$420,C20,$D$8:$D$420,D20,$H$8:$H$420,"Serviço"),0)))) -> 119696.06 | O20: Estimado com base em índices históricos | P20: Finalizado
A21: =IF($H21="UNIDADE CONSTRUTIVA",OFFSET(A21,-1,0)+1,LARGE(A$3:A20,1)) -> 0 | B21: =IF(H21="UNIDADE CONSTRUTIVA",0,IF(H21="CÉLULA CONSTRUTIVA",OFFSET(B21,-1,0)+1,OFFSET(B21,-1,0))) -> 1 | C21: =IF(H21="CÉLULA CONSTRUTIVA",0,IF(H21="ETAPA",OFFSET(C21,-1,0)+1,OFFSET(C21,-1,0))) -> 1 | D21: =IF(H21="ETAPA",0,IF(H21="SUBETAPA",OFFSET(D21,-1,0)+1,OFFSET(D21,-1,0))) -> 2 | E21: =IF(H21="Subetapa",0,IF(H21="serviço",OFFSET(E21,-1,0)+1,OFFSET(E21,-1,0))) -> 6 | H21: SERVIÇO | I21: =IF(H21="Unidade Construtiva",TEXT(A21,"00"),IF(H21="Célula Construtiva",TEXT(B21,"00"),IF(H21="Etapa",CONCATENATE(TEXT(B21,"00"),".",TEXT(C21,"000")),IF(H21="Subetapa",CONCATENATE(TEXT(B21,"00"),".",TEXT(C21,"000"),".",TEXT(D21,"000")),IF(H21="Serviço",CONCATENATE(TEXT(B21,"00"),".",TEXT(C21,"000"),".",TEXT(D21,"000"),".",TEXT(E21,"000")),""))))) -> 01.001.002.006 | J21: Projeto elétrico/comunicação/telefonia/luminotécnico | K21: vb | L21: 1 | M21: 78311.786 | N21: =IF(H21="Serviço",M21*L21,IF(H21="CÉLULA CONSTRUTIVA",SUMIFS($N$8:$N$420,$B$8:$B$420,B21,$H$8:$H$420,"Serviço"),IF(H21="ETAPA",SUMIFS($N$8:$N$420,$B$8:$B$420,B21,$C$8:$C$420,C21,$H$8:$H$420,"Serviço"),IF(H21="SUBETAPA",SUMIFS($N$8:$N$420,$B$8:$B$420,B21,$C$8:$C$420,C21,$D$8:$D$420,D21,$H$8:$H$420,"Serviço"),0)))) -> 78311.786 | O21: Estimado com base em índices históricos | P21: Finalizado
A22: =IF($H22="UNIDADE CONSTRUTIVA",OFFSET(A22,-1,0)+1,LARGE(A$3:A21,1)) -> 0 | B22: =IF(H22="UNIDADE CONSTRUTIVA",0,IF(H22="CÉLULA CONSTRUTIVA",OFFSET(B22,-1,0)+1,OFFSET(B22,-1,0))) -> 1 | C22: =IF(H22="CÉLULA CONSTRUTIVA",0,IF(H22="ETAPA",OFFSET(C22,-1,0)+1,OFFSET(C22,-1,0))) -> 1 | D22: =IF(H22="ETAPA",0,IF(H22="SUBETAPA",OFFSET(D22,-1,0)+1,OFFSET(D22,-1,0))) -> 2 | E22: =IF(H22="Subetapa",0,IF(H22="serviço",OFFSET(E22,-1,0)+1,OFFSET(E22,-1,0))) -> 7 | H22: SERVIÇO | I22: =IF(H22="Unidade Construtiva",TEXT(A22,"00"),IF(H22="Célula Construtiva",TEXT(B22,"00"),IF(H22="Etapa",CONCATENATE(TEXT(B22,"00"),".",TEXT(C22,"000")),IF(H22="Subetapa",CONCATENATE(TEXT(B22,"00"),".",TEXT(C22,"000"),".",TEXT(D22,"000")),IF(H22="Serviço",CONCATENATE(TEXT(B22,"00"),".",TEXT(C22,"000"),".",TEXT(D22,"000"),".",TEXT(E22,"000")),""))))) -> 01.001.002.007 | J22: Projeto hidrossanitário/drenagem/pluvial | K22: vb | L22: 1 | M22: 50329.648 | N22: =IF(H22="Serviço",M22*L22,IF(H22="CÉLULA CONSTRUTIVA",SUMIFS($N$8:$N$420,$B$8:$B$420,B22,$H$8:$H$420,"Serviço"),IF(H22="ETAPA",SUMIFS($N$8:$N$420,$B$8:$B$420,B22,$C$8:$C$420,C22,$H$8:$H$420,"Serviço"),IF(H22="SUBETAPA",SUMIFS($N$8:$N$420,$B$8:$B$420,B22,$C$8:$C$420,C22,$D$8:$D$420,D22,$H$8:$H$420,"Serviço"),0)))) -> 50329.648 | O22: Estimado com base em índices históricos | P22: Finalizado
A23: =IF($H23="UNIDADE CONSTRUTIVA",OFFSET(A23,-1,0)+1,LARGE(A$3:A22,1)) -> 0 | B23: =IF(H23="UNIDADE CONSTRUTIVA",0,IF(H23="CÉLULA CONSTRUTIVA",OFFSET(B23,-1,0)+1,OFFSET(B23,-1,0))) -> 1 | C23: =IF(H23="CÉLULA CONSTRUTIVA",0,IF(H23="ETAPA",OFFSET(C23,-1,0)+1,OFFSET(C23,-1,0))) -> 1 | D23: =IF(H23="ETAPA",0,IF(H23="SUBETAPA",OFFSET(D23,-1,0)+1,OFFSET(D23,-1,0))) -> 2 | E23: =IF(H23="Subetapa",0,IF(H23="serviço",OFFSET(E23,-1,0)+1,OFFSET(E23,-1,0))) -> 8 | H23: SERVIÇO | I23: =IF(H23="Unidade Construtiva",TEXT(A23,"00"),IF(H23="Célula Construtiva",TEXT(B23,"00"),IF(H23="Etapa",CONCATENATE(TEXT(B23,"00"),".",TEXT(C23,"000")),IF(H23="Subetapa",CONCATENATE(TEXT(B23,"00"),".",TEXT(C23,"000"),".",TEXT(D23,"000")),IF(H23="Serviço",CONCATENATE(TEXT(B23,"00"),".",TEXT(C23,"000"),".",TEXT(D23,"000"),".",TEXT(E23,"000")),""))))) -> 01.001.002.008 | J23: Projeto preventivo (PPCI - Plano de Prevenção e Proteção Contra Incêndios) | K23: vb | L23: 1 | M23: 46859.736 | N23: =IF(H23="Serviço",M23*L23,IF(H23="CÉLULA CONSTRUTIVA",SUMIFS($N$8:$N$420,$B$8:$B$420,B23,$H$8:$H$420,"Serviço"),IF(H23="ETAPA",SUMIFS($N$8:$N$420,$B$8:$B$420,B23,$C$8:$C$420,C23,$H$8:$H$420,"Serviço"),IF(H23="SUBETAPA",SUMIFS($N$8:$N$420,$B$8:$B$420,B23,$C$8:$C$420,C23,$D$8:$D$420,D23,$H$8:$H$420,"Serviço"),0)))) -> 46859.736 | O23: Estimado com base em índices históricos | P23: Finalizado
A24: =IF($H24="UNIDADE CONSTRUTIVA",OFFSET(A24,-1,0)+1,LARGE(A$3:A23,1)) -> 0 | B24: =IF(H24="UNIDADE CONSTRUTIVA",0,IF(H24="CÉLULA CONSTRUTIVA",OFFSET(B24,-1,0)+1,OFFSET(B24,-1,0))) -> 1 | C24: =IF(H24="CÉLULA CONSTRUTIVA",0,IF(H24="ETAPA",OFFSET(C24,-1,0)+1,OFFSET(C24,-1,0))) -> 1 | D24: =IF(H24="ETAPA",0,IF(H24="SUBETAPA",OFFSET(D24,-1,0)+1,OFFSET(D24,-1,0))) -> 2 | E24: =IF(H24="Subetapa",0,IF(H24="serviço",OFFSET(E24,-1,0)+1,OFFSET(E24,-1,0))) -> 9 | H24: SERVIÇO | I24: =IF(H24="Unidade Construtiva",TEXT(A24,"00"),IF(H24="Célula Construtiva",TEXT(B24,"00"),IF(H24="Etapa",CONCATENATE(TEXT(B24,"00"),".",TEXT(C24,"000")),IF(H24="Subetapa",CONCATENATE(TEXT(B24,"00"),".",TEXT(C24,"000"),".",TEXT(D24,"000")),IF(H24="Serviço",CONCATENATE(TEXT(B24,"00"),".",TEXT(C24,"000"),".",TEXT(D24,"000"),".",TEXT(E24,"000")),""))))) -> 01.001.002.009 | J24: Projeto de climatização/exaustão | K24: vb | L24: 1 | M24: 15092.528 | N24: =IF(H24="Serviço",M24*L24,IF(H24="CÉLULA CONSTRUTIVA",SUMIFS($N$8:$N$420,$B$8:$B$420,B24,$H$8:$H$420,"Serviço"),IF(H24="ETAPA",SUMIFS($N$8:$N$420,$B$8:$B$420,B24,$C$8:$C$420,C24,$H$8:$H$420,"Serviço"),IF(H24="SUBETAPA",SUMIFS($N$8:$N$420,$B$8:$B$420,B24,$C$8:$C$420,C24,$D$8:$D$420,D24,$H$8:$H$420,"Serviço"),0)))) -> 15092.528 | O24: Estimado com base em índices históricos | P24: Finalizado
A25: =IF($H25="UNIDADE CONSTRUTIVA",OFFSET(A25,-1,0)+1,LARGE(A$3:A24,1)) -> 0 | B25: =IF(H25="UNIDADE CONSTRUTIVA",0,IF(H25="CÉLULA CONSTRUTIVA",OFFSET(B25,-1,0)+1,OFFSET(B25,-1,0))) -> 1 | C25: =IF(H25="CÉLULA CONSTRUTIVA",0,IF(H25="ETAPA",OFFSET(C25,-1,0)+1,OFFSET(C25,-1,0))) -> 1 | D25: =IF(H25="ETAPA",0,IF(H25="SUBETAPA",OFFSET(D25,-1,0)+1,OFFSET(D25,-1,0))) -> 2 | E25: =IF(H25="Subetapa",0,IF(H25="serviço",OFFSET(E25,-1,0)+1,OFFSET(E25,-1,0))) -> 10 | H25: SERVIÇO | I25: =IF(H25="Unidade Construtiva",TEXT(A25,"00"),IF(H25="Célula Construtiva",TEXT(B25,"00"),IF(H25="Etapa",CONCATENATE(TEXT(B25,"00"),".",TEXT(C25,"000")),IF(H25="Subetapa",CONCATENATE(TEXT(B25,"00"),".",TEXT(C25,"000"),".",TEXT(D25,"000")),IF(H25="Serviço",CONCATENATE(TEXT(B25,"00"),".",TEXT(C25,"000"),".",TEXT(D25,"000"),".",TEXT(E25,"000")),""))))) -> 01.001.002.010 | J25: Projeto de Segurança - Furações | K25: vb | L25: 1 | M25: 15092.528 | N25: =IF(H25="Serviço",M25*L25,IF(H25="CÉLULA CONSTRUTIVA",SUMIFS($N$8:$N$420,$B$8:$B$420,B25,$H$8:$H$420,"Serviço"),IF(H25="ETAPA",SUMIFS($N$8:$N$420,$B$8:$B$420,B25,$C$8:$C$420,C25,$H$8:$H$420,"Serviço"),IF(H25="SUBETAPA",SUMIFS($N$8:$N$420,$B$8:$B$420,B25,$C$8:$C$420,C25,$D$8:$D$420,D25,$H$8:$H$420,"Serviço"),0)))) -> 15092.528 | O25: Estimado com base em índices históricos | P25: Finalizado
A26: =IF($H26="UNIDADE CONSTRUTIVA",OFFSET(A26,-1,0)+1,LARGE(A$3:A25,1)) -> 0 | B26: =IF(H26="UNIDADE CONSTRUTIVA",0,IF(H26="CÉLULA CONSTRUTIVA",OFFSET(B26,-1,0)+1,OFFSET(B26,-1,0))) -> 1 | C26: =IF(H26="CÉLULA CONSTRUTIVA",0,IF(H26="ETAPA",OFFSET(C26,-1,0)+1,OFFSET(C26,-1,0))) -> 1 | D26: =IF(H26="ETAPA",0,IF(H26="SUBETAPA",OFFSET(D26,-1,0)+1,OFFSET(D26,-1,0))) -> 2 | E26: =IF(H26="Subetapa",0,IF(H26="serviço",OFFSET(E26,-1,0)+1,OFFSET(E26,-1,0))) -> 11 | H26: SERVIÇO | I26: =IF(H26="Unidade Construtiva",TEXT(A26,"00"),IF(H26="Célula Construtiva",TEXT(B26,"00"),IF(H26="Etapa",CONCATENATE(TEXT(B26,"00"),".",TEXT(C26,"000")),IF(H26="Subetapa",CONCATENATE(TEXT(B26,"00"),".",TEXT(C26,"000"),".",TEXT(D26,"000")),IF(H26="Serviço",CONCATENATE(TEXT(B26,"00"),".",TEXT(C26,"000"),".",TEXT(D26,"000"),".",TEXT(E26,"000")),""))))) -> 01.001.002.011 | J26: Projeto de Impermeabilização | K26: vb | L26: 1 | M26: 15142.38 | N26: =IF(H26="Serviço",M26*L26,IF(H26="CÉLULA CONSTRUTIVA",SUMIFS($N$8:$N$420,$B$8:$B$420,B26,$H$8:$H$420,"Serviço"),IF(H26="ETAPA",SUMIFS($N$8:$N$420,$B$8:$B$420,B26,$C$8:$C$420,C26,$H$8:$H$420,"Serviço"),IF(H26="SUBETAPA",SUMIFS($N$8:$N$420,$B$8:$B$420,B26,$C$8:$C$420,C26,$D$8:$D$420,D26,$H$8:$H$420,"Serviço"),0)))) -> 15142.38 | O26: Estimado com base em índices históricos | P26: Finalizado
A27: =IF($H27="UNIDADE CONSTRUTIVA",OFFSET(A27,-1,0)+1,LARGE(A$3:A26,1)) -> 0 | B27: =IF(H27="UNIDADE CONSTRUTIVA",0,IF(H27="CÉLULA CONSTRUTIVA",OFFSET(B27,-1,0)+1,OFFSET(B27,-1,0))) -> 1 | C27: =IF(H27="CÉLULA CONSTRUTIVA",0,IF(H27="ETAPA",OFFSET(C27,-1,0)+1,OFFSET(C27,-1,0))) -> 1 | D27: =IF(H27="ETAPA",0,IF(H27="SUBETAPA",OFFSET(D27,-1,0)+1,OFFSET(D27,-1,0))) -> 3 | E27: =IF(H27="Subetapa",0,IF(H27="serviço",OFFSET(E27,-1,0)+1,OFFSET(E27,-1,0))) -> 0 | H27: SUBETAPA | I27: =IF(H27="Unidade Construtiva",TEXT(A27,"00"),IF(H27="Célula Construtiva",TEXT(B27,"00"),IF(H27="Etapa",CONCATENATE(TEXT(B27,"00"),".",TEXT(C27,"000")),IF(H27="Subetapa",CONCATENATE(TEXT(B27,"00"),".",TEXT(C27,"000"),".",TEXT(D27,"000")),IF(H27="Serviço",CONCATENATE(TEXT(B27,"00"),".",TEXT(C27,"000"),".",TEXT(D27,"000"),".",TEXT(E27,"000")),""))))) -> 01.001.003 | J27: Consultorias | N27: =IF(H27="Serviço",M27*L27,IF(H27="CÉLULA CONSTRUTIVA",SUMIFS($N$8:$N$420,$B$8:$B$420,B27,$H$8:$H$420,"Serviço"),IF(H27="ETAPA",SUMIFS($N$8:$N$420,$B$8:$B$420,B27,$C$8:$C$420,C27,$H$8:$H$420,"Serviço"),IF(H27="SUBETAPA",SUMIFS($N$8:$N$420,$B$8:$B$420,B27,$C$8:$C$420,C27,$D$8:$D$420,D27,$H$8:$H$420,"Serviço"),0)))) -> 76500
A28: =IF($H28="UNIDADE CONSTRUTIVA",OFFSET(A28,-1,0)+1,LARGE(A$3:A27,1)) -> 0 | B28: =IF(H28="UNIDADE CONSTRUTIVA",0,IF(H28="CÉLULA CONSTRUTIVA",OFFSET(B28,-1,0)+1,OFFSET(B28,-1,0))) -> 1 | C28: =IF(H28="CÉLULA CONSTRUTIVA",0,IF(H28="ETAPA",OFFSET(C28,-1,0)+1,OFFSET(C28,-1,0))) -> 1 | D28: =IF(H28="ETAPA",0,IF(H28="SUBETAPA",OFFSET(D28,-1,0)+1,OFFSET(D28,-1,0))) -> 3 | E28: =IF(H28="Subetapa",0,IF(H28="serviço",OFFSET(E28,-1,0)+1,OFFSET(E28,-1,0))) -> 1 | H28: SERVIÇO | I28: =IF(H28="Unidade Construtiva",TEXT(A28,"00"),IF(H28="Célula Construtiva",TEXT(B28,"00"),IF(H28="Etapa",CONCATENATE(TEXT(B28,"00"),".",TEXT(C28,"000")),IF(H28="Subetapa",CONCATENATE(TEXT(B28,"00"),".",TEXT(C28,"000"),".",TEXT(D28,"000")),IF(H28="Serviço",CONCATENATE(TEXT(B28,"00"),".",TEXT(C28,"000"),".",TEXT(D28,"000"),".",TEXT(E28,"000")),""))))) -> 01.001.003.001 | J28: Orçamento e planejamento | K28: vb | L28: 1 | M28: 22500 | N28: =IF(H28="Serviço",M28*L28,IF(H28="CÉLULA CONSTRUTIVA",SUMIFS($N$8:$N$420,$B$8:$B$420,B28,$H$8:$H$420,"Serviço"),IF(H28="ETAPA",SUMIFS($N$8:$N$420,$B$8:$B$420,B28,$C$8:$C$420,C28,$H$8:$H$420,"Serviço"),IF(H28="SUBETAPA",SUMIFS($N$8:$N$420,$B$8:$B$420,B28,$C$8:$C$420,C28,$D$8:$D$420,D28,$H$8:$H$420,"Serviço"),0)))) -> 22500 | O28: Custo de contratação Cartesian | P28: Finalizado
A29: =IF($H29="UNIDADE CONSTRUTIVA",OFFSET(A29,-1,0)+1,LARGE(A$3:A28,1)) -> 0 | B29: =IF(H29="UNIDADE CONSTRUTIVA",0,IF(H29="CÉLULA CONSTRUTIVA",OFFSET(B29,-1,0)+1,OFFSET(B29,-1,0))) -> 1 | C29: =IF(H29="CÉLULA CONSTRUTIVA",0,IF(H29="ETAPA",OFFSET(C29,-1,0)+1,OFFSET(C29,-1,0))) -> 1 | D29: =IF(H29="ETAPA",0,IF(H29="SUBETAPA",OFFSET(D29,-1,0)+1,OFFSET(D29,-1,0))) -> 3 | E29: =IF(H29="Subetapa",0,IF(H29="serviço",OFFSET(E29,-1,0)+1,OFFSET(E29,-1,0))) -> 2 | H29: SERVIÇO | I29: =IF(H29="Unidade Construtiva",TEXT(A29,"00"),IF(H29="Célula Construtiva",TEXT(B29,"00"),IF(H29="Etapa",CONCATENATE(TEXT(B29,"00"),".",TEXT(C29,"000")),IF(H29="Subetapa",CONCATENATE(TEXT(B29,"00"),".",TEXT(C29,"000"),".",TEXT(D29,"000")),IF(H29="Serviço",CONCATENATE(TEXT(B29,"00"),".",TEXT(C29,"000"),".",TEXT(D29,"000"),".",TEXT(E29,"000")),""))))) -> 01.001.003.002 | J29: Prevision | K29: mês | L29: 36 | M29: 1500 | N29: =IF(H29="Serviço",M29*L29,IF(H29="CÉLULA CONSTRUTIVA",SUMIFS($N$8:$N$420,$B$8:$B$420,B29,$H$8:$H$420,"Serviço"),IF(H29="ETAPA",SUMIFS($N$8:$N$420,$B$8:$B$420,B29,$C$8:$C$420,C29,$H$8:$H$420,"Serviço"),IF(H29="SUBETAPA",SUMIFS($N$8:$N$420,$B$8:$B$420,B29,$C$8:$C$420,C29,$D$8:$D$420,D29,$H$8:$H$420,"Serviço"),0)))) -> 54000 | O29: Fornecido pelo whatsapp | P29: Finalizado
A30: =IF($H30="UNIDADE CONSTRUTIVA",OFFSET(A30,-1,0)+1,LARGE(A$3:A28,1)) -> 0 | B30: =IF(H30="UNIDADE CONSTRUTIVA",0,IF(H30="CÉLULA CONSTRUTIVA",OFFSET(B30,-1,0)+1,OFFSET(B30,-1,0))) -> 1 | C30: =IF(H30="CÉLULA CONSTRUTIVA",0,IF(H30="ETAPA",OFFSET(C30,-1,0)+1,OFFSET(C30,-1,0))) -> 1 | D30: =IF(H30="ETAPA",0,IF(H30="SUBETAPA",OFFSET(D30,-1,0)+1,OFFSET(D30,-1,0))) -> 4 | E30: =IF(H30="Subetapa",0,IF(H30="serviço",OFFSET(E30,-1,0)+1,OFFSET(E30,-1,0))) -> 0 | H30: SUBETAPA | I30: =IF(H30="Unidade Construtiva",TEXT(A30,"00"),IF(H30="Célula Construtiva",TEXT(B30,"00"),IF(H30="Etapa",CONCATENATE(TEXT(B30,"00"),".",TEXT(C30,"000")),IF(H30="Subetapa",CONCATENATE(TEXT(B30,"00"),".",TEXT(C30,"000"),".",TEXT(D30,"000")),IF(H30="Serviço",CONCATENATE(TEXT(B30,"00"),".",TEXT(C30,"000"),".",TEXT(D30,"000"),".",TEXT(E30,"000")),""))))) -> 01.001.004 | J30: Ensaios | N30: =IF(H30="Serviço",M30*L30,IF(H30="CÉLULA CONSTRUTIVA",SUMIFS($N$8:$N$420,$B$8:$B$420,B30,$H$8:$H$420,"Serviço"),IF(H30="ETAPA",SUMIFS($N$8:$N$420,$B$8:$B$420,B30,$C$8:$C$420,C30,$H$8:$H$420,"Serviço"),IF(H30="SUBETAPA",SUMIFS($N$8:$N$420,$B$8:$B$420,B30,$C$8:$C$420,C30,$D$8:$D$420,D30,$H$8:$H$420,"Serviço"),0)))) -> 177545.38
A31: =IF($H31="UNIDADE CONSTRUTIVA",OFFSET(A31,-1,0)+1,LARGE(A$3:A30,1)) -> 0 | B31: =IF(H31="UNIDADE CONSTRUTIVA",0,IF(H31="CÉLULA CONSTRUTIVA",OFFSET(B31,-1,0)+1,OFFSET(B31,-1,0))) -> 1 | C31: =IF(H31="CÉLULA CONSTRUTIVA",0,IF(H31="ETAPA",OFFSET(C31,-1,0)+1,OFFSET(C31,-1,0))) -> 1 | D31: =IF(H31="ETAPA",0,IF(H31="SUBETAPA",OFFSET(D31,-1,0)+1,OFFSET(D31,-1,0))) -> 4 | E31: =IF(H31="Subetapa",0,IF(H31="serviço",OFFSET(E31,-1,0)+1,OFFSET(E31,-1,0))) -> 1 | H31: SERVIÇO | I31: =IF(H31="Unidade Construtiva",TEXT(A31,"00"),IF(H31="Célula Construtiva",TEXT(B31,"00"),IF(H31="Etapa",CONCATENATE(TEXT(B31,"00"),".",TEXT(C31,"000")),IF(H31="Subetapa",CONCATENATE(TEXT(B31,"00"),".",TEXT(C31,"000"),".",TEXT(D31,"000")),IF(H31="Serviço",CONCATENATE(TEXT(B31,"00"),".",TEXT(C31,"000"),".",TEXT(D31,"000"),".",TEXT(E31,"000")),""))))) -> 01.001.004.001 | J31: Controle Tecnologico de Concreto | K31: vb | L31: 1 | M31: 38456.656 | N31: =IF(H31="Serviço",M31*L31,IF(H31="CÉLULA CONSTRUTIVA",SUMIFS($N$8:$N$420,$B$8:$B$420,B31,$H$8:$H$420,"Serviço"),IF(H31="ETAPA",SUMIFS($N$8:$N$420,$B$8:$B$420,B31,$C$8:$C$420,C31,$H$8:$H$420,"Serviço"),IF(H31="SUBETAPA",SUMIFS($N$8:$N$420,$B$8:$B$420,B31,$C$8:$C$420,C31,$D$8:$D$420,D31,$H$8:$H$420,"Serviço"),0)))) -> 38456.656 | O31: Estimado com base em índices históricos | P31: Finalizado
A32: =IF($H32="UNIDADE CONSTRUTIVA",OFFSET(A32,-1,0)+1,LARGE(A$3:A31,1)) -> 0 | B32: =IF(H32="UNIDADE CONSTRUTIVA",0,IF(H32="CÉLULA CONSTRUTIVA",OFFSET(B32,-1,0)+1,OFFSET(B32,-1,0))) -> 1 | C32: =IF(H32="CÉLULA CONSTRUTIVA",0,IF(H32="ETAPA",OFFSET(C32,-1,0)+1,OFFSET(C32,-1,0))) -> 1 | D32: =IF(H32="ETAPA",0,IF(H32="SUBETAPA",OFFSET(D32,-1,0)+1,OFFSET(D32,-1,0))) -> 4 | E32: =IF(H32="Subetapa",0,IF(H32="serviço",OFFSET(E32,-1,0)+1,OFFSET(E32,-1,0))) -> 2 | H32: SERVIÇO | I32: =IF(H32="Unidade Construtiva",TEXT(A32,"00"),IF(H32="Célula Construtiva",TEXT(B32,"00"),IF(H32="Etapa",CONCATENATE(TEXT(B32,"00"),".",TEXT(C32,"000")),IF(H32="Subetapa",CONCATENATE(TEXT(B32,"00"),".",TEXT(C32,"000"),".",TEXT(D32,"000")),IF(H32="Serviço",CONCATENATE(TEXT(B32,"00"),".",TEXT(C32,"000"),".",TEXT(D32,"000"),".",TEXT(E32,"000")),""))))) -> 01.001.004.002 | J32: Laudo de Vizinhança | K32: vb | L32: 1 | M32: =13000+126088.72 -> 139088.72 | N32: =IF(H32="Serviço",M32*L32,IF(H32="CÉLULA CONSTRUTIVA",SUMIFS($N$8:$N$420,$B$8:$B$420,B32,$H$8:$H$420,"Serviço"),IF(H32="ETAPA",SUMIFS($N$8:$N$420,$B$8:$B$420,B32,$C$8:$C$420,C32,$H$8:$H$420,"Serviço"),IF(H32="SUBETAPA",SUMIFS($N$8:$N$420,$B$8:$B$420,B32,$C$8:$C$420,C32,$D$8:$D$420,D32,$H$8:$H$420,"Serviço"),0)))) -> 139088.72 | O32: Fornecido pelo whatsapp | P32: Finalizado
A33: =IF($H33="UNIDADE CONSTRUTIVA",OFFSET(A33,-1,0)+1,LARGE(A$3:A32,1)) -> 0 | B33: =IF(H33="UNIDADE CONSTRUTIVA",0,IF(H33="CÉLULA CONSTRUTIVA",OFFSET(B33,-1,0)+1,OFFSET(B33,-1,0))) -> 1 | C33: =IF(H33="CÉLULA CONSTRUTIVA",0,IF(H33="ETAPA",OFFSET(C33,-1,0)+1,OFFSET(C33,-1,0))) -> 2 | D33: =IF(H33="ETAPA",0,IF(H33="SUBETAPA",OFFSET(D33,-1,0)+1,OFFSET(D33,-1,0))) -> 0 | E33: =IF(H33="Subetapa",0,IF(H33="serviço",OFFSET(E33,-1,0)+1,OFFSET(E33,-1,0))) -> 2 | H33: ETAPA | I33: =IF(H33="Unidade Construtiva",TEXT(A33,"00"),IF(H33="Célula Construtiva",TEXT(B33,"00"),IF(H33="Etapa",CONCATENATE(TEXT(B33,"00"),".",TEXT(C33,"000")),IF(H33="Subetapa",CONCATENATE(TEXT(B33,"00"),".",TEXT(C33,"000"),".",TEXT(D33,"000")),IF(H33="Serviço",CONCATENATE(TEXT(B33,"00"),".",TEXT(C33,"000"),".",TEXT(D33,"000"),".",TEXT(E33,"000")),""))))) -> 01.002 | J33: CONSUMOS, TAXAS E DOCUMENTOS | N33: =IF(H33="Serviço",M33*L33,IF(H33="CÉLULA CONSTRUTIVA",SUMIFS($N$8:$N$420,$B$8:$B$420,B33,$H$8:$H$420,"Serviço"),IF(H33="ETAPA",SUMIFS($N$8:$N$420,$B$8:$B$420,B33,$C$8:$C$420,C33,$H$8:$H$420,"Serviço"),IF(H33="SUBETAPA",SUMIFS($N$8:$N$420,$B$8:$B$420,B33,$C$8:$C$420,C33,$D$8:$D$420,D33,$H$8:$H$420,"Serviço"),0)))) -> 1049719.3 | P33: -
A34: =IF($H34="UNIDADE CONSTRUTIVA",OFFSET(A34,-1,0)+1,LARGE(A$3:A33,1)) -> 0 | B34: =IF(H34="UNIDADE CONSTRUTIVA",0,IF(H34="CÉLULA CONSTRUTIVA",OFFSET(B34,-1,0)+1,OFFSET(B34,-1,0))) -> 1 | C34: =IF(H34="CÉLULA CONSTRUTIVA",0,IF(H34="ETAPA",OFFSET(C34,-1,0)+1,OFFSET(C34,-1,0))) -> 2 | D34: =IF(H34="ETAPA",0,IF(H34="SUBETAPA",OFFSET(D34,-1,0)+1,OFFSET(D34,-1,0))) -> 1 | E34: =IF(H34="Subetapa",0,IF(H34="serviço",OFFSET(E34,-1,0)+1,OFFSET(E34,-1,0))) -> 0 | H34: SUBETAPA | I34: =IF(H34="Unidade Construtiva",TEXT(A34,"00"),IF(H34="Célula Construtiva",TEXT(B34,"00"),IF(H34="Etapa",CONCATENATE(TEXT(B34,"00"),".",TEXT(C34,"000")),IF(H34="Subetapa",CONCATENATE(TEXT(B34,"00"),".",TEXT(C34,"000"),".",TEXT(D34,"000")),IF(H34="Serviço",CONCATENATE(TEXT(B34,"00"),".",TEXT(C34,"000"),".",TEXT(D34,"000"),".",TEXT(E34,"000")),""))))) -> 01.002.001 | J34: Licenciamentos, Taxas, Impostos, Aprovações e Seguros | N34: =IF(H34="Serviço",M34*L34,IF(H34="CÉLULA CONSTRUTIVA",SUMIFS($N$8:$N$420,$B$8:$B$420,B34,$H$8:$H$420,"Serviço"),IF(H34="ETAPA",SUMIFS($N$8:$N$420,$B$8:$B$420,B34,$C$8:$C$420,C34,$H$8:$H$420,"Serviço"),IF(H34="SUBETAPA",SUMIFS($N$8:$N$420,$B$8:$B$420,B34,$C$8:$C$420,C34,$D$8:$D$420,D34,$H$8:$H$420,"Serviço"),0)))) -> 516230.94
A35: =IF($H35="UNIDADE CONSTRUTIVA",OFFSET(A35,-1,0)+1,LARGE(A$3:A34,1)) -> 0 | B35: =IF(H35="UNIDADE CONSTRUTIVA",0,IF(H35="CÉLULA CONSTRUTIVA",OFFSET(B35,-1,0)+1,OFFSET(B35,-1,0))) -> 1 | C35: =IF(H35="CÉLULA CONSTRUTIVA",0,IF(H35="ETAPA",OFFSET(C35,-1,0)+1,OFFSET(C35,-1,0))) -> 2 | D35: =IF(H35="ETAPA",0,IF(H35="SUBETAPA",OFFSET(D35,-1,0)+1,OFFSET(D35,-1,0))) -> 1 | E35: =IF(H35="Subetapa",0,IF(H35="serviço",OFFSET(E35,-1,0)+1,OFFSET(E35,-1,0))) -> 1 | H35: SERVIÇO | I35: =IF(H35="Unidade Construtiva",TEXT(A35,"00"),IF(H35="Célula Construtiva",TEXT(B35,"00"),IF(H35="Etapa",CONCATENATE(TEXT(B35,"00"),".",TEXT(C35,"000")),IF(H35="Subetapa",CONCATENATE(TEXT(B35,"00"),".",TEXT(C35,"000"),".",TEXT(D35,"000")),IF(H35="Serviço",CONCATENATE(TEXT(B35,"00"),".",TEXT(C35,"000"),".",TEXT(D35,"000"),".",TEXT(E35,"000")),""))))) -> 01.002.001.001 | J35: Despesas de Seguros | K35: vb | L35: 1 | M35: 29287.335 | N35: =IF(H35="Serviço",M35*L35,IF(H35="CÉLULA CONSTRUTIVA",SUMIFS($N$8:$N$420,$B$8:$B$420,B35,$H$8:$H$420,"Serviço"),IF(H35="ETAPA",SUMIFS($N$8:$N$420,$B$8:$B$420,B35,$C$8:$C$420,C35,$H$8:$H$420,"Serviço"),IF(H35="SUBETAPA",SUMIFS($N$8:$N$420,$B$8:$B$420,B35,$C$8:$C$420,C35,$D$8:$D$420,D35,$H$8:$H$420,"Serviço"),0)))) -> 29287.335 | O35: Estimado com base em índices históricos | P35: Lançado ERP
A36: =IF($H36="UNIDADE CONSTRUTIVA",OFFSET(A36,-1,0)+1,LARGE(A$3:A35,1)) -> 0 | B36: =IF(H36="UNIDADE CONSTRUTIVA",0,IF(H36="CÉLULA CONSTRUTIVA",OFFSET(B36,-1,0)+1,OFFSET(B36,-1,0))) -> 1 | C36: =IF(H36="CÉLULA CONSTRUTIVA",0,IF(H36="ETAPA",OFFSET(C36,-1,0)+1,OFFSET(C36,-1,0))) -> 2 | D36: =IF(H36="ETAPA",0,IF(H36="SUBETAPA",OFFSET(D36,-1,0)+1,OFFSET(D36,-1,0))) -> 1 | E36: =IF(H36="Subetapa",0,IF(H36="serviço",OFFSET(E36,-1,0)+1,OFFSET(E36,-1,0))) -> 2 | H36: SERVIÇO | I36: =IF(H36="Unidade Construtiva",TEXT(A36,"00"),IF(H36="Célula Construtiva",TEXT(B36,"00"),IF(H36="Etapa",CONCATENATE(TEXT(B36,"00"),".",TEXT(C36,"000")),IF(H36="Subetapa",CONCATENATE(TEXT(B36,"00"),".",TEXT(C36,"000"),".",TEXT(D36,"000")),IF(H36="Serviço",CONCATENATE(TEXT(B36,"00"),".",TEXT(C36,"000"),".",TEXT(D36,"000"),".",TEXT(E36,"000")),""))))) -> 01.002.001.002 | J36: Aprovação e legalização ambiental | K36: vb | L36: 1 | M36: 8368.8559 | N36: =IF(H36="Serviço",M36*L36,IF(H36="CÉLULA CONSTRUTIVA",SUMIFS($N$8:$N$420,$B$8:$B$420,B36,$H$8:$H$420,"Serviço"),IF(H36="ETAPA",SUMIFS($N$8:$N$420,$B$8:$B$420,B36,$C$8:$C$420,C36,$H$8:$H$420,"Serviço"),IF(H36="SUBETAPA",SUMIFS($N$8:$N$420,$B$8:$B$420,B36,$C$8:$C$420,C36,$D$8:$D$420,D36,$H$8:$H$420,"Serviço"),0)))) -> 8368.8559 | O36: Estimado com base em índices históricos | P36: Lançado ERP
A37: =IF($H37="UNIDADE CONSTRUTIVA",OFFSET(A37,-1,0)+1,LARGE(A$3:A36,1)) -> 0 | B37: =IF(H37="UNIDADE CONSTRUTIVA",0,IF(H37="CÉLULA CONSTRUTIVA",OFFSET(B37,-1,0)+1,OFFSET(B37,-1,0))) -> 1 | C37: =IF(H37="CÉLULA CONSTRUTIVA",0,IF(H37="ETAPA",OFFSET(C37,-1,0)+1,OFFSET(C37,-1,0))) -> 2 | D37: =IF(H37="ETAPA",0,IF(H37="SUBETAPA",OFFSET(D37,-1,0)+1,OFFSET(D37,-1,0))) -> 1 | E37: =IF(H37="Subetapa",0,IF(H37="serviço",OFFSET(E37,-1,0)+1,OFFSET(E37,-1,0))) -> 3 | H37: SERVIÇO | I37: =IF(H37="Unidade Construtiva",TEXT(A37,"00"),IF(H37="Célula Construtiva",TEXT(B37,"00"),IF(H37="Etapa",CONCATENATE(TEXT(B37,"00"),".",TEXT(C37,"000")),IF(H37="Subetapa",CONCATENATE(TEXT(B37,"00"),".",TEXT(C37,"000"),".",TEXT(D37,"000")),IF(H37="Serviço",CONCATENATE(TEXT(B37,"00"),".",TEXT(C37,"000"),".",TEXT(D37,"000"),".",TEXT(E37,"000")),""))))) -> 01.002.001.003 | J37: Aprovação e legalização prefeitura | K37: vb | L37: 1 | M37: 32923.365 | N37: =IF(H37="Serviço",M37*L37,IF(H37="CÉLULA CONSTRUTIVA",SUMIFS($N$8:$N$420,$B$8:$B$420,B37,$H$8:$H$420,"Serviço"),IF(H37="ETAPA",SUMIFS($N$8:$N$420,$B$8:$B$420,B37,$C$8:$C$420,C37,$H$8:$H$420,"Serviço"),IF(H37="SUBETAPA",SUMIFS($N$8:$N$420,$B$8:$B$420,B37,$C$8:$C$420,C37,$D$8:$D$420,D37,$H$8:$H$420,"Serviço"),0)))) -> 32923.365 | O37: Estimado com base em índices históricos | P37: Lançado ERP
A38: =IF($H38="UNIDADE CONSTRUTIVA",OFFSET(A38,-1,0)+1,LARGE(A$3:A37,1)) -> 0 | B38: =IF(H38="UNIDADE CONSTRUTIVA",0,IF(H38="CÉLULA CONSTRUTIVA",OFFSET(B38,-1,0)+1,OFFSET(B38,-1,0))) -> 1 | C38: =IF(H38="CÉLULA CONSTRUTIVA",0,IF(H38="ETAPA",OFFSET(C38,-1,0)+1,OFFSET(C38,-1,0))) -> 2 | D38: =IF(H38="ETAPA",0,IF(H38="SUBETAPA",OFFSET(D38,-1,0)+1,OFFSET(D38,-1,0))) -> 1 | E38: =IF(H38="Subetapa",0,IF(H38="serviço",OFFSET(E38,-1,0)+1,OFFSET(E38,-1,0))) -> 4 | H38: SERVIÇO | I38: =IF(H38="Unidade Construtiva",TEXT(A38,"00"),IF(H38="Célula Construtiva",TEXT(B38,"00"),IF(H38="Etapa",CONCATENATE(TEXT(B38,"00"),".",TEXT(C38,"000")),IF(H38="Subetapa",CONCATENATE(TEXT(B38,"00"),".",TEXT(C38,"000"),".",TEXT(D38,"000")),IF(H38="Serviço",CONCATENATE(TEXT(B38,"00"),".",TEXT(C38,"000"),".",TEXT(D38,"000"),".",TEXT(E38,"000")),""))))) -> 01.002.001.004 | J38: Aprovação e legalização água e esgoto | K38: vb | L38: 1 | M38: 2619.0836 | N38: =IF(H38="Serviço",M38*L38,IF(H38="CÉLULA CONSTRUTIVA",SUMIFS($N$8:$N$420,$B$8:$B$420,B38,$H$8:$H$420,"Serviço"),IF(H38="ETAPA",SUMIFS($N$8:$N$420,$B$8:$B$420,B38,$C$8:$C$420,C38,$H$8:$H$420,"Serviço"),IF(H38="SUBETAPA",SUMIFS($N$8:$N$420,$B$8:$B$420,B38,$C$8:$C$420,C38,$D$8:$D$420,D38,$H$8:$H$420,"Serviço"),0)))) -> 2619.0836 | O38: Estimado com base em índices históricos | P38: Lançado ERP
A39: =IF($H39="UNIDADE CONSTRUTIVA",OFFSET(A39,-1,0)+1,LARGE(A$3:A38,1)) -> 0 | B39: =IF(H39="UNIDADE CONSTRUTIVA",0,IF(H39="CÉLULA CONSTRUTIVA",OFFSET(B39,-1,0)+1,OFFSET(B39,-1,0))) -> 1 | C39: =IF(H39="CÉLULA CONSTRUTIVA",0,IF(H39="ETAPA",OFFSET(C39,-1,0)+1,OFFSET(C39,-1,0))) -> 2 | D39: =IF(H39="ETAPA",0,IF(H39="SUBETAPA",OFFSET(D39,-1,0)+1,OFFSET(D39,-1,0))) -> 1 | E39: =IF(H39="Subetapa",0,IF(H39="serviço",OFFSET(E39,-1,0)+1,OFFSET(E39,-1,0))) -> 5 | H39: SERVIÇO | I39: =IF(H39="Unidade Construtiva",TEXT(A39,"00"),IF(H39="Célula Construtiva",TEXT(B39,"00"),IF(H39="Etapa",CONCATENATE(TEXT(B39,"00"),".",TEXT(C39,"000")),IF(H39="Subetapa",CONCATENATE(TEXT(B39,"00"),".",TEXT(C39,"000"),".",TEXT(D39,"000")),IF(H39="Serviço",CONCATENATE(TEXT(B39,"00"),".",TEXT(C39,"000"),".",TEXT(D39,"000"),".",TEXT(E39,"000")),""))))) -> 01.002.001.005 | J39: Aprovação e legalização elétrico | K39: vb | L39: 1 | M39: 18403.978 | N39: =IF(H39="Serviço",M39*L39,IF(H39="CÉLULA CONSTRUTIVA",SUMIFS($N$8:$N$420,$B$8:$B$420,B39,$H$8:$H$420,"Serviço"),IF(H39="ETAPA",SUMIFS($N$8:$N$420,$B$8:$B$420,B39,$C$8:$C$420,C39,$H$8:$H$420,"Serviço"),IF(H39="SUBETAPA",SUMIFS($N$8:$N$420,$B$8:$B$420,B39,$C$8:$C$420,C39,$D$8:$D$420,D39,$H$8:$H$420,"Serviço"),0)))) -> 18403.978 | O39: Estimado com base em índices históricos | P39: Lançado ERP
A40: =IF($H40="UNIDADE CONSTRUTIVA",OFFSET(A40,-1,0)+1,LARGE(A$3:A39,1)) -> 0 | B40: =IF(H40="UNIDADE CONSTRUTIVA",0,IF(H40="CÉLULA CONSTRUTIVA",OFFSET(B40,-1,0)+1,OFFSET(B40,-1,0))) -> 1 | C40: =IF(H40="CÉLULA CONSTRUTIVA",0,IF(H40="ETAPA",OFFSET(C40,-1,0)+1,OFFSET(C40,-1,0))) -> 2 | D40: =IF(H40="ETAPA",0,IF(H40="SUBETAPA",OFFSET(D40,-1,0)+1,OFFSET(D40,-1,0))) -> 1 | E40: =IF(H40="Subetapa",0,IF(H40="serviço",OFFSET(E40,-1,0)+1,OFFSET(E40,-1,0))) -> 6 | H40: SERVIÇO | I40: =IF(H40="Unidade Construtiva",TEXT(A40,"00"),IF(H40="Célula Construtiva",TEXT(B40,"00"),IF(H40="Etapa",CONCATENATE(TEXT(B40,"00"),".",TEXT(C40,"000")),IF(H40="Subetapa",CONCATENATE(TEXT(B40,"00"),".",TEXT(C40,"000"),".",TEXT(D40,"000")),IF(H40="Serviço",CONCATENATE(TEXT(B40,"00"),".",TEXT(C40,"000"),".",TEXT(D40,"000"),".",TEXT(E40,"000")),""))))) -> 01.002.001.006 | J40: Aprovação e legalização bombeiros | K40: vb | L40: 1 | M40: 11485.697 | N40: =IF(H40="Serviço",M40*L40,IF(H40="CÉLULA CONSTRUTIVA",SUMIFS($N$8:$N$420,$B$8:$B$420,B40,$H$8:$H$420,"Serviço"),IF(H40="ETAPA",SUMIFS($N$8:$N$420,$B$8:$B$420,B40,$C$8:$C$420,C40,$H$8:$H$420,"Serviço"),IF(H40="SUBETAPA",SUMIFS($N$8:$N$420,$B$8:$B$420,B40,$C$8:$C$420,C40,$D$8:$D$420,D40,$H$8:$H$420,"Serviço"),0)))) -> 11485.697 | O40: Estimado com base em índices históricos | P40: Lançado ERP
A41: =IF($H41="UNIDADE CONSTRUTIVA",OFFSET(A41,-1,0)+1,LARGE(A$3:A40,1)) -> 0 | B41: =IF(H41="UNIDADE CONSTRUTIVA",0,IF(H41="CÉLULA CONSTRUTIVA",OFFSET(B41,-1,0)+1,OFFSET(B41,-1,0))) -> 1 | C41: =IF(H41="CÉLULA CONSTRUTIVA",0,IF(H41="ETAPA",OFFSET(C41,-1,0)+1,OFFSET(C41,-1,0))) -> 2 | D41: =IF(H41="ETAPA",0,IF(H41="SUBETAPA",OFFSET(D41,-1,0)+1,OFFSET(D41,-1,0))) -> 1 | E41: =IF(H41="Subetapa",0,IF(H41="serviço",OFFSET(E41,-1,0)+1,OFFSET(E41,-1,0))) -> 7 | H41: SERVIÇO | I41: =IF(H41="Unidade Construtiva",TEXT(A41,"00"),IF(H41="Célula Construtiva",TEXT(B41,"00"),IF(H41="Etapa",CONCATENATE(TEXT(B41,"00"),".",TEXT(C41,"000")),IF(H41="Subetapa",CONCATENATE(TEXT(B41,"00"),".",TEXT(C41,"000"),".",TEXT(D41,"000")),IF(H41="Serviço",CONCATENATE(TEXT(B41,"00"),".",TEXT(C41,"000"),".",TEXT(D41,"000"),".",TEXT(E41,"000")),""))))) -> 01.002.001.007 | J41: Taxas de ART | K41: vb | L41: 1 | M41: 4775.1089 | N41: =IF(H41="Serviço",M41*L41,IF(H41="CÉLULA CONSTRUTIVA",SUMIFS($N$8:$N$420,$B$8:$B$420,B41,$H$8:$H$420,"Serviço"),IF(H41="ETAPA",SUMIFS($N$8:$N$420,$B$8:$B$420,B41,$C$8:$C$420,C41,$H$8:$H$420,"Serviço"),IF(H41="SUBETAPA",SUMIFS($N$8:$N$420,$B$8:$B$420,B41,$C$8:$C$420,C41,$D$8:$D$420,D41,$H$8:$H$420,"Serviço"),0)))) -> 4775.1089 | O41: Estimado com base em índices históricos | P41: Lançado ERP
A42: =IF($H42="UNIDADE CONSTRUTIVA",OFFSET(A42,-1,0)+1,LARGE(A$3:A41,1)) -> 0 | B42: =IF(H42="UNIDADE CONSTRUTIVA",0,IF(H42="CÉLULA CONSTRUTIVA",OFFSET(B42,-1,0)+1,OFFSET(B42,-1,0))) -> 1 | C42: =IF(H42="CÉLULA CONSTRUTIVA",0,IF(H42="ETAPA",OFFSET(C42,-1,0)+1,OFFSET(C42,-1,0))) -> 2 | D42: =IF(H42="ETAPA",0,IF(H42="SUBETAPA",OFFSET(D42,-1,0)+1,OFFSET(D42,-1,0))) -> 1 | E42: =IF(H42="Subetapa",0,IF(H42="serviço",OFFSET(E42,-1,0)+1,OFFSET(E42,-1,0))) -> 8 | H42: SERVIÇO | I42: =IF(H42="Unidade Construtiva",TEXT(A42,"00"),IF(H42="Célula Construtiva",TEXT(B42,"00"),IF(H42="Etapa",CONCATENATE(TEXT(B42,"00"),".",TEXT(C42,"000")),IF(H42="Subetapa",CONCATENATE(TEXT(B42,"00"),".",TEXT(C42,"000"),".",TEXT(D42,"000")),IF(H42="Serviço",CONCATENATE(TEXT(B42,"00"),".",TEXT(C42,"000"),".",TEXT(D42,"000"),".",TEXT(E42,"000")),""))))) -> 01.002.001.008 | J42: Alvará Construção | K42: vb | L42: 1 | M42: 51010.067 | N42: =IF(H42="Serviço",M42*L42,IF(H42="CÉLULA CONSTRUTIVA",SUMIFS($N$8:$N$420,$B$8:$B$420,B42,$H$8:$H$420,"Serviço"),IF(H42="ETAPA",SUMIFS($N$8:$N$420,$B$8:$B$420,B42,$C$8:$C$420,C42,$H$8:$H$420,"Serviço"),IF(H42="SUBETAPA",SUMIFS($N$8:$N$420,$B$8:$B$420,B42,$C$8:$C$420,C42,$D$8:$D$420,D42,$H$8:$H$420,"Serviço"),0)))) -> 51010.067 | O42: Estimado com base em índices históricos | P42: Lançado ERP
A43: =IF($H43="UNIDADE CONSTRUTIVA",OFFSET(A43,-1,0)+1,LARGE(A$3:A42,1)) -> 0 | B43: =IF(H43="UNIDADE CONSTRUTIVA",0,IF(H43="CÉLULA CONSTRUTIVA",OFFSET(B43,-1,0)+1,OFFSET(B43,-1,0))) -> 1 | C43: =IF(H43="CÉLULA CONSTRUTIVA",0,IF(H43="ETAPA",OFFSET(C43,-1,0)+1,OFFSET(C43,-1,0))) -> 2 | D43: =IF(H43="ETAPA",0,IF(H43="SUBETAPA",OFFSET(D43,-1,0)+1,OFFSET(D43,-1,0))) -> 1 | E43: =IF(H43="Subetapa",0,IF(H43="serviço",OFFSET(E43,-1,0)+1,OFFSET(E43,-1,0))) -> 9 | H43: SERVIÇO | I43: =IF(H43="Unidade Construtiva",TEXT(A43,"00"),IF(H43="Célula Construtiva",TEXT(B43,"00"),IF(H43="Etapa",CONCATENATE(TEXT(B43,"00"),".",TEXT(C43,"000")),IF(H43="Subetapa",CONCATENATE(TEXT(B43,"00"),".",TEXT(C43,"000"),".",TEXT(D43,"000")),IF(H43="Serviço",CONCATENATE(TEXT(B43,"00"),".",TEXT(C43,"000"),".",TEXT(D43,"000"),".",TEXT(E43,"000")),""))))) -> 01.002.001.009 | J43: Despesas cartório, licenças, certidões e jurídicas | K43: vb | L43: 1 | M43: 54830.62 | N43: =IF(H43="Serviço",M43*L43,IF(H43="CÉLULA CONSTRUTIVA",SUMIFS($N$8:$N$420,$B$8:$B$420,B43,$H$8:$H$420,"Serviço"),IF(H43="ETAPA",SUMIFS($N$8:$N$420,$B$8:$B$420,B43,$C$8:$C$420,C43,$H$8:$H$420,"Serviço"),IF(H43="SUBETAPA",SUMIFS($N$8:$N$420,$B$8:$B$420,B43,$C$8:$C$420,C43,$D$8:$D$420,D43,$H$8:$H$420,"Serviço"),0)))) -> 54830.62 | O43: Estimado com base em índices históricos | P43: Lançado ERP
...

Sheet Ger_Executivo
G4: PROJETO: | I4: ='Obra '!D1 -> Porto Cerro | O4: REVISÃO: | P4: DATA
G5: EMPRESA: | I5: ='Obra '!D2 -> XPCon Empreendimentos | O5: R01 | P5: 45887
A6: Unidade Construtiva | B6: Célula Construtiva | C6: Etapa | D6: Subetapa | E6: Serviço | G6: GERENCIAMENTO EXECUTIVO
A7: 0 | B7: 0 | C7: 0 | D7: 0 | E7: 0 | G7: Atalho | H7: NIVEL | I7: Item | J7: Descrição | K7: Unidade | L7: Quant. | M7: Preço un | N7: Total | O7: Considerações | P7: Situação
A8: =IF($H8="UNIDADE CONSTRUTIVA",OFFSET(A8,-1,0)+1,LARGE(A$3:A7,1)) -> 0 | B8: =IF(H8="UNIDADE CONSTRUTIVA",0,IF(H8="CÉLULA CONSTRUTIVA",OFFSET(B8,-1,0)+1,OFFSET(B8,-1,0))) -> 1 | C8: =IF(H8="CÉLULA CONSTRUTIVA",0,IF(H8="ETAPA",OFFSET(C8,-1,0)+1,OFFSET(C8,-1,0))) -> 0 | D8: =IF(H8="ETAPA",0,IF(H8="SUBETAPA",OFFSET(D8,-1,0)+1,OFFSET(D8,-1,0))) -> 0 | E8: =IF(H8="Subetapa",0,IF(H8="serviço",OFFSET(E8,-1,0)+1,OFFSET(E8,-1,0))) -> 0 | H8: CÉLULA CONSTRUTIVA | I8: =IF(H8="Unidade Construtiva",TEXT(A8,"00"),IF(H8="Célula Construtiva",TEXT(B8,"00"),IF(H8="Etapa",CONCATENATE(TEXT(B8,"00"),".",TEXT(C8,"000")),IF(H8="Subetapa",CONCATENATE(TEXT(B8,"00"),".",TEXT(C8,"000"),".",TEXT(D8,"000")),IF(H8="Serviço",CONCATENATE(TEXT(B8,"00"),".",TEXT(C8,"000"),".",TEXT(D8,"000"),".",TEXT(E8,"000")),""))))) -> 01 | J8: MOVIMENTAÇÃO DE TERRA | N8: =IF(H8="Serviço",M8*L8,IF(H8="CÉLULA CONSTRUTIVA",SUMIFS($N$8:$N$1393,$B$8:$B$1393,B8,$H$8:$H$1393,"Serviço"),IF(H8="ETAPA",SUMIFS($N$8:$N$1393,$B$8:$B$1393,B8,$C$8:$C$1393,C8,$H$8:$H$1393,"Serviço"),IF(H8="SUBETAPA",SUMIFS($N$8:$N$1393,$B$8:$B$1393,B8,$C$8:$C$1393,C8,$D$8:$D$1393,D8,$H$8:$H$1393,"Serviço"),0)))) -> 201548.69
A9: =IF($H9="UNIDADE CONSTRUTIVA",OFFSET(A9,-1,0)+1,LARGE(A$3:A8,1)) -> 0 | B9: =IF(H9="UNIDADE CONSTRUTIVA",0,IF(H9="CÉLULA CONSTRUTIVA",OFFSET(B9,-1,0)+1,OFFSET(B9,-1,0))) -> 1 | C9: =IF(H9="CÉLULA CONSTRUTIVA",0,IF(H9="ETAPA",OFFSET(C9,-1,0)+1,OFFSET(C9,-1,0))) -> 1 | D9: =IF(H9="ETAPA",0,IF(H9="SUBETAPA",OFFSET(D9,-1,0)+1,OFFSET(D9,-1,0))) -> 0 | E9: =IF(H9="Subetapa",0,IF(H9="serviço",OFFSET(E9,-1,0)+1,OFFSET(E9,-1,0))) -> 0 | H9: ETAPA | I9: =IF(H9="Unidade Construtiva",TEXT(A9,"00"),IF(H9="Célula Construtiva",TEXT(B9,"00"),IF(H9="Etapa",CONCATENATE(TEXT(B9,"00"),".",TEXT(C9,"000")),IF(H9="Subetapa",CONCATENATE(TEXT(B9,"00"),".",TEXT(C9,"000"),".",TEXT(D9,"000")),IF(H9="Serviço",CONCATENATE(TEXT(B9,"00"),".",TEXT(C9,"000"),".",TEXT(D9,"000"),".",TEXT(E9,"000")),""))))) -> 01.001 | J9: MOVIMENTAÇÃO DE TERRA | N9: =IF(H9="Serviço",M9*L9,IF(H9="CÉLULA CONSTRUTIVA",SUMIFS($N$8:$N$1393,$B$8:$B$1393,B9,$H$8:$H$1393,"Serviço"),IF(H9="ETAPA",SUMIFS($N$8:$N$1393,$B$8:$B$1393,B9,$C$8:$C$1393,C9,$H$8:$H$1393,"Serviço"),IF(H9="SUBETAPA",SUMIFS($N$8:$N$1393,$B$8:$B$1393,B9,$C$8:$C$1393,C9,$D$8:$D$1393,D9,$H$8:$H$1393,"Serviço"),0)))) -> 201548.69
A10: =IF($H10="UNIDADE CONSTRUTIVA",OFFSET(A10,-1,0)+1,LARGE(A$3:A9,1)) -> 0 | B10: =IF(H10="UNIDADE CONSTRUTIVA",0,IF(H10="CÉLULA CONSTRUTIVA",OFFSET(B10,-1,0)+1,OFFSET(B10,-1,0))) -> 1 | C10: =IF(H10="CÉLULA CONSTRUTIVA",0,IF(H10="ETAPA",OFFSET(C10,-1,0)+1,OFFSET(C10,-1,0))) -> 1 | D10: =IF(H10="ETAPA",0,IF(H10="SUBETAPA",OFFSET(D10,-1,0)+1,OFFSET(D10,-1,0))) -> 1 | E10: =IF(H10="Subetapa",0,IF(H10="serviço",OFFSET(E10,-1,0)+1,OFFSET(E10,-1,0))) -> 0 | H10: SUBETAPA | I10: =IF(H10="Unidade Construtiva",TEXT(A10,"00"),IF(H10="Célula Construtiva",TEXT(B10,"00"),IF(H10="Etapa",CONCATENATE(TEXT(B10,"00"),".",TEXT(C10,"000")),IF(H10="Subetapa",CONCATENATE(TEXT(B10,"00"),".",TEXT(C10,"000"),".",TEXT(D10,"000")),IF(H10="Serviço",CONCATENATE(TEXT(B10,"00"),".",TEXT(C10,"000"),".",TEXT(D10,"000"),".",TEXT(E10,"000")),""))))) -> 01.001.001 | J10: Rebaixamento de Lençol Freático | N10: =IF(H10="Serviço",M10*L10,IF(H10="CÉLULA CONSTRUTIVA",SUMIFS($N$8:$N$1393,$B$8:$B$1393,B10,$H$8:$H$1393,"Serviço"),IF(H10="ETAPA",SUMIFS($N$8:$N$1393,$B$8:$B$1393,B10,$C$8:$C$1393,C10,$H$8:$H$1393,"Serviço"),IF(H10="SUBETAPA",SUMIFS($N$8:$N$1393,$B$8:$B$1393,B10,$C$8:$C$1393,C10,$D$8:$D$1393,D10,$H$8:$H$1393,"Serviço"),0)))) -> 34800
