Workbook

Sheet Resumo
A1: PROPOSTA SENNA
A2: TIPOLOGIA | B2: DESCRIÇÃO | C2: ESTRUTURA | D2: UNIDADE | E2: TOTAL GERAL (M²) | F2: Preço material | G2: Preço MO | H2: Preço total | I2: Total | J2: Estimativa Marcio | K2: Total Marcio
A3: DW-B4 | B3: 2S / 70LP / 2S | C3: 400MSI | D3: M² | E3: 24432.7 | F3: =SUMIF(composições!A:A,Resumo!A3,composições!H:H) -> 144.3739 | G3: 120 | H3: =SUM(F3:G3) -> 264.3739 | I3: =E3*H3 -> 6459368.2 | J3: 200 | K3: =J3*E3 -> 4886540
A4: DW-B5 | B4: 2S / 70LP / SU | C4: 400MSI | D4: M² | E4: 20748.2 | F4: =SUMIF(composições!A:A,Resumo!A4,composições!H:H) -> 158.98954 | G4: 120 | H4: =SUM(F4:G4) -> 278.98954 | I4: =E4*H4 -> 5788530.8 | J4: 210 | K4: =J4*E4 -> 4357122
A5: DW-G5 | B5: 2S / 70 | C5: 400MDE-B-GL | D5: M² | E5: 35901.3 | F5: =SUMIF(composições!A:A,Resumo!A5,composições!H:H) -> 102.4394 | G5: 120 | H5: =SUM(F5:G5) -> 222.4394 | I5: =E5*H5 -> 7985863.7 | J5: 170 | K5: =J5*E5 -> 6103221
A6: DW-G11 | B6: US / 90 | C6: 400MDE-B-GL | D6: M² | E6: 12798.9 | F6: =SUMIF(composições!A:A,Resumo!A6,composições!H:H) -> 134.92796 | G6: 120 | H6: =SUM(F6:G6) -> 254.92796 | I6: =E6*H6 -> 3262797.5 | J6: 200 | K6: =J6*E6 -> 2559780
A7: DW-G6 | B7: US / 70 | C7: 400MDE-B-GL | D7: M² | E7: 10079 | F7: =SUMIF(composições!A:A,Resumo!A7,composições!H:H) -> 109.74722 | G7: 120 | H7: =SUM(F7:G7) -> 229.74722 | I7: =E7*H7 -> 2315622.3 | J7: 200 | K7: =J7*E7 -> 2015800
A8: DW-G8 | B8: 2S / 90(LSF) | C8: 400MDE-B-GL | D8: M² | E8: 4806 | F8: =SUMIF(composições!A:A,Resumo!A8,composições!H:H) -> 238.0105 | G8: 120 | H8: =SUM(F8:G8) -> 358.0105 | I8: =E8*H8 -> 1720598.4 | J8: 210 | K8: =J8*E8 -> 1009260
A9: DW-D2 | B9: 2S / 70LPe* | C9: 400MDE-B | D9: M² | E9: 6909 | F9: =SUMIF(composições!A:A,Resumo!A9,composições!H:H) -> 94.648698 | G9: 90 | H9: =SUM(F9:G9) -> 184.6487 | I9: =E9*H9 -> 1275737.9 | J9: 170 | K9: =J9*E9 -> 1174530
A10: DW-D3 | B10: US / 70LPe* | C10: 400MDE-B | D10: M² | E10: 3554.9 | F10: =SUMIF(composições!A:A,Resumo!A10,composições!H:H) -> 101.95652 | G10: 90 | H10: =SUM(F10:G10) -> 191.95652 | I10: =E10*H10 -> 682386.23 | J10: 170 | K10: =J10*E10 -> 604333
H12: Total | I12: =SUM(I3:I10) -> 29490905 | K12: =SUM(K3:K10) -> 22710586
A14: PADRÃO PDI
A15: TIPOLOGIA | B15: DESCRIÇÃO | C15: ESTRUTURA | D15: UNIDADE | E15: TOTAL GERAL (M²) | F15: Preço material | G15: Preço MO | H15: Preço total | I15: Total | J15: Estimativa Marcio | K15: Total Marcio
A16: PDI-DW-B4 | B16: PER/90LP/PER | C16: 400MSI | D16: M² | E16: 24432.7 | F16: =SUMIF(composições!A:A,Resumo!A16,composições!H:H) -> 121.44252 | G16: 120 | H16: =SUM(F16:G16) -> 241.44252 | I16: =E16*H16 -> 5899092.8 | J16: 200 | K16: =J16*E16 -> 4886540
A17: PDI-DW-B5 | B17: PEU/ 90LP / PER | C17: 400MSI | D17: M² | E17: 20748.2 | F17: =SUMIF(composições!A:A,Resumo!A17,composições!H:H) -> 131.67768 | G17: 120 | H17: =SUM(F17:G17) -> 251.67768 | I17: =E17*H17 -> 5221858.9 | J17: 210 | K17: =J17*E17 -> 4357122
A18: PDI-DW-G5 | B18: PER / 48 | C18: 400MSI | D18: M² | E18: 35901.3 | F18: =SUMIF(composições!A:A,Resumo!A18,composições!H:H) -> 63.177326 | G18: 120 | H18: =SUM(F18:G18) -> 183.17733 | I18: =E18*H18 -> 6576304.1 | J18: 170 | K18: =J18*E18 -> 6103221
A19: PDI-DW-G11 | B19: PEU / 48 | C19: 400MSI | D19: M² | E19: 12798.9 | F19: =SUMIF(composições!A:A,Resumo!A19,composições!H:H) -> 77.272088 | G19: 120 | H19: =SUM(F19:G19) -> 197.27209 | I19: =E19*H19 -> 2524865.7 | J19: 200 | K19: =J19*E19 -> 2559780
A20: PDI-DW-G6 | B20: PEU / 70 | C20: 400MSI | D20: M² | E20: 10079 | F20: =SUMIF(composições!A:A,Resumo!A20,composições!H:H) -> 77.272088 | G20: 120 | H20: =SUM(F20:G20) -> 197.27209 | I20: =E20*H20 -> 1988305.4 | J20: 200 | K20: =J20*E20 -> 2015800
A21: PDI-DW-G8 | B21: PER / 70 | C21: 400MSI | D21: M² | E21: 4806 | F21: =SUMIF(composições!A:A,Resumo!A21,composições!H:H) -> 67.036928 | G21: 120 | H21: =SUM(F21:G21) -> 187.03693 | I21: =E21*H21 -> 898899.48 | J21: 210 | K21: =J21*E21 -> 1009260
A22: PDI-DW-D2 | B22: PER / 70 | C22: 400MSI | D22: M² | E22: 6909 | F22: =SUMIF(composições!A:A,Resumo!A22,composições!H:H) -> 67.036928 | G22: 90 | H22: =SUM(F22:G22) -> 157.03693 | I22: =E22*H22 -> 1084968.1 | J22: 170 | K22: =J22*E22 -> 1174530
A23: PDI-DW-D3 | B23: PEU / 70 | C23: 400MSI | D23: M² | E23: 3554.9 | F23: =SUMIF(composições!A:A,Resumo!A23,composições!H:H) -> 77.272088 | G23: 90 | H23: =SUM(F23:G23) -> 167.27209 | I23: =E23*H23 -> 594635.55 | J23: 170 | K23: =J23*E23 -> 604333
H26: Total | I26: =SUM(I16:I23) -> 24788930
I27: =I12-I26 -> 4701974.9
I28: =I27/I12 -> 0.15943814
A29: PADRÃO BLUE VIEW
A30: TIPOLOGIA | B30: DESCRIÇÃO | C30: ESTRUTURA | D30: UNIDADE | E30: TOTAL GERAL (M²) | F30: Preço material | G30: Preço MO | H30: Preço total | I30: Total | J30: Estimativa Marcio | K30: Total Marcio
A31: BLUE-DW-B4 | B31: PER/90LP/ST | C31: 400MSI | D31: M² | E31: 24432.7 | F31: =SUMIF(composições!A:A,Resumo!A31,composições!H:H) -> 98.129104 | G31: 120 | H31: =SUM(F31:G31) -> 218.1291 | I31: =E31*H31 -> 5329483 | J31: 200 | K31: =J31*E31 -> 4886540
A32: BLUE-DW-B5 | B32: PEU/ 90LP / PER | C32: 400MSI | D32: M² | E32: 20748.2 | F32: =SUMIF(composições!A:A,Resumo!A32,composições!H:H) -> 105.43692 | G32: 120 | H32: =SUM(F32:G32) -> 225.43692 | I32: =E32*H32 -> 4677410.4 | J32: 210 | K32: =J32*E32 -> 4357122
A33: BLUE-DW-G5 | B33: PER / 48 | C33: 400MDE-B-GL | D33: M² | E33: 35901.3 | F33: =SUMIF(composições!A:A,Resumo!A33,composições!H:H) -> 72.749096 | G33: 120 | H33: =SUM(F33:G33) -> 192.7491 | I33: =E33*H33 -> 6919943.1 | J33: 170 | K33: =J33*E33 -> 6103221
A34: BLUE-DW-G11 | B34: PEU / 48 | C34: 400MDE-B-GL | D34: M² | E34: 12798.9 | F34: =SUMIF(composições!A:A,Resumo!A34,composições!H:H) -> 77.272088 | G34: 120 | H34: =SUM(F34:G34) -> 197.27209 | I34: =E34*H34 -> 2524865.7 | J34: 200 | K34: =J34*E34 -> 2559780
A35: BLUE-DW-G6 | B35: PEU / 70 | C35: 400MDE-B-GL | D35: M² | E35: 10079 | F35: =SUMIF(composições!A:A,Resumo!A35,composições!H:H) -> 77.272088 | G35: 120 | H35: =SUM(F35:G35) -> 197.27209 | I35: =E35*H35 -> 1988305.4 | J35: 200 | K35: =J35*E35 -> 2015800
A36: BLUE-DW-G8 | B36: PER / 70 | C36: 400MDE-B-GL | D36: M² | E36: 4806 | F36: =SUMIF(composições!A:A,Resumo!A36,composições!H:H) -> 72.749096 | G36: 120 | H36: =SUM(F36:G36) -> 192.7491 | I36: =E36*H36 -> 926352.16 | J36: 210 | K36: =J36*E36 -> 1009260
A37: BLUE-DW-D2 | B37: PER / 70 | C37: 400MDE-B | D37: M² | E37: 6909 | F37: =SUMIF(composições!A:A,Resumo!A37,composições!H:H) -> 76.608698 | G37: 90 | H37: =SUM(F37:G37) -> 166.6087 | I37: =E37*H37 -> 1151099.5 | J37: 170 | K37: =J37*E37 -> 1174530
A38: BLUE-DW-D3 | B38: PEU / 70 | C38: 400MDE-B | D38: M² | E38: 3554.9 | F38: =SUMIF(composições!A:A,Resumo!A38,composições!H:H) -> 62.688038 | G38: 90 | H38: =SUM(F38:G38) -> 152.68804 | I38: =E38*H38 -> 542790.71 | J38: 170 | K38: =J38*E38 -> 604333

Sheet Analise 
A1: TIPOLOGIA | B1: DESCRIÇÃO SENNA | C1: Preço material SENNA | D1: DESCRIÇÃO PDI | E1: Preço material PDI | F1: DIFERENÇA
A2: DW-B4 | B2: 2S / 70LP / 2S | C2: 133.99974 | D2: PER/90LP/PER | E2: 109.67026 | F2: =(C2-E2)/C2 -> 0.18156361
A3: DW-B5 | B3: 2S / 70LP / SU | C3: 146.31984 | D3: PEU/ 90LP / PER | E3: 118.15744 | F3: =(C3-E3)/C3 -> 0.19247148
A4: DW-G5 | B4: 2S / 70 | C4: 94.415823 | D4: PER / 48 | E4: 56.891196 | F4: =(C4-E4)/C4 -> 0.39744002
A5: DW-G11 | B5: US / 90 | C5: 125.75661 | D5: PEU / 48 | E5: 69.237978 | F5: =(C5-E5)/C5 -> 0.44942872
A6: DW-G6 | B6: US / 70 | C6: 100.57587 | D6: PEU / 70 | E6: 69.237978 | F6: =(C6-E6)/C6 -> 0.31158462
A7: DW-G8 | B7: 2S / 90(LSF) | C7: 229.98692 | D7: PER / 70 | E7: 60.750798 | F7: =(C7-E7)/C7 -> 0.73585107
A8: DW-D2 | B8: 2S / 70LPe* | C8: 82.906385 | D8: PER / 70 | E8: 60.750798 | F8: =(C8-E8)/C8 -> 0.26723619
A9: DW-D3 | B9: US / 70LPe* | C9: 89.066435 | D9: PEU / 70 | E9: 69.237978 | F9: =(C9-E9)/C9 -> 0.22262547

Sheet composições
A1: Codigo | B1: Tipo | C1: Descrição | D1: Descrição | E1: Und | F1: Quantidade | G1: Custo unit. | H1: Custo Total.
A2: DW-G11 | B2: Serviço | C2: Parede Com Sistema Em Chapas De Gesso Para Drywall, Uso Interno, Montante 90mm, Com Uma Face Dupla Standart e Resistente a Umidade e isolamento com Lã de PET Ensacada(US / 90LPe*) | D2: Parede Com Sistema Em Chapas De Gesso Para Drywall, Uso Interno, Montante 90mm, Com Uma Face Dupla Standart e Resistente a Umidade e isolamento com Lã de PET Ensacada(US / 90LPe*) | E2: M2 | H2: =SUM(H3:H16) -> 134.92796 | I2: OK
B3: Insumo | C3: Parede Com Sistema Em Chapas De Gesso Para Drywall, Uso Interno, Montante 90mm, Com Uma Face Dupla Standart e Resistente a Umidade e isolamento com Lã de PET Ensacada(US / 90LPe*) | D3: PLACA / CHAPA DE GESSO ACARTONADO, STANDARD (ST), COR BRANCA, E = 12,5 MM, 1200 X 2400 MM (L X C) | E3: M2 | F3: 1.053 | G3: 20.16 | H3: =G3*F3 -> 21.22848
B4: Insumo | C4: Parede Com Sistema Em Chapas De Gesso Para Drywall, Uso Interno, Montante 90mm, Com Uma Face Dupla Standart e Resistente a Umidade e isolamento com Lã de PET Ensacada(US / 90LPe*) | D4: PLACA / CHAPA DE GESSO ACARTONADO, RESISTENTE A UMIDADE (RU), COR VERDE, E = 12,5 MM, 1200 X 2400 MM (L X C) | E4: M2 | F4: 1.053 | G4: 27.1 | H4: =G4*F4 -> 28.5363
B5: Insumo | C5: Parede Com Sistema Em Chapas De Gesso Para Drywall, Uso Interno, Montante 90mm, Com Uma Face Dupla Standart e Resistente a Umidade e isolamento com Lã de PET Ensacada(US / 90LPe*) | D5: PINO DE ACO COM ARRUELA CONICA, DIAMETRO ARRUELA = *23* MM E COMP HASTE = *27* MM (ACAO INDIRETA) | E5: UN | F5: 2.48 | G5: 0.504 | H5: =G5*F5 -> 1.24992
B6: Insumo | C6: Parede Com Sistema Em Chapas De Gesso Para Drywall, Uso Interno, Montante 90mm, Com Uma Face Dupla Standart e Resistente a Umidade e isolamento com Lã de PET Ensacada(US / 90LPe*) | D6: PERFIL GUIA, FORMATO U, EM ACO ZINCADO, PARA ESTRUTURA PAREDE DRYWALL, E = 0,5 MM, 90 X 3000 MM (L X C) | E6: M | F6: 0.7624 | G6: 8.64 | H6: =G6*F6 -> 6.587136
B7: Insumo | C7: Parede Com Sistema Em Chapas De Gesso Para Drywall, Uso Interno, Montante 90mm, Com Uma Face Dupla Standart e Resistente a Umidade e isolamento com Lã de PET Ensacada(US / 90LPe*) | D7: PERFIL GUIA, FORMATO U, EM ACO ZINCADO, PARA BLOQUEADOR GUIA TRANSVERSAL E = 0,5 MM, 90 X 3000 MM (L X C) | E7: M | F7: =0.7624*1.2 -> 0.91488 | G7: 8.64 | H7: =G7*F7 -> 7.9045632
B8: Insumo | C8: Parede Com Sistema Em Chapas De Gesso Para Drywall, Uso Interno, Montante 90mm, Com Uma Face Dupla Standart e Resistente a Umidade e isolamento com Lã de PET Ensacada(US / 90LPe*) | D8: PERFIL MONTANTE DUPLOP, FORMATO C, EM ACO ZINCADO, PARA ESTRUTURA PAREDE DRYWALL, E = 0,5 MM, 90 X 3000 MM (L X C) | E8: M | F8: =2.0006*2 -> 4.0012 | G8: 10.79 | H8: =G8*F8 -> 43.172948
B9: Insumo | C9: Parede Com Sistema Em Chapas De Gesso Para Drywall, Uso Interno, Montante 90mm, Com Uma Face Dupla Standart e Resistente a Umidade e isolamento com Lã de PET Ensacada(US / 90LPe*) | D9: MASSA DE REJUNTE EM PO PARA DRYWALL, A BASE DE GESSO, SECAGEM RAPIDA, PARA TRATAMENTO DE JUNTAS DE CHAPA DE GESSO (NECESSITA ADICAO DE AGUA) | E9: KG | F9: 0.5489 | G9: 3.43 | H9: =G9*F9 -> 1.882727
B10: Insumo | C10: Parede Com Sistema Em Chapas De Gesso Para Drywall, Uso Interno, Montante 90mm, Com Uma Face Dupla Standart e Resistente a Umidade e isolamento com Lã de PET Ensacada(US / 90LPe*) | D10: FITA DE PAPEL MICROPERFURADO, 50 X 150 MM, PARA TRATAMENTO DE JUNTAS DE CHAPA DE GESSO PARA DRYWALL | E10: M | F10: 1.2513 | G10: 0.31 | H10: =G10*F10 -> 0.387903
B11: Insumo | C11: Parede Com Sistema Em Chapas De Gesso Para Drywall, Uso Interno, Montante 90mm, Com Uma Face Dupla Standart e Resistente a Umidade e isolamento com Lã de PET Ensacada(US / 90LPe*) | D11: FITA DE PAPEL REFORCADA COM LAMINA DE METAL PARA REFORCO DE CANTOS DE CHAPA DE GESSO PARA DRYWALL | E11: M | F11: 0.7407 | G11: 2.74 | H11: =G11*F11 -> 2.029518
B12: Insumo | C12: Parede Com Sistema Em Chapas De Gesso Para Drywall, Uso Interno, Montante 90mm, Com Uma Face Dupla Standart e Resistente a Umidade e isolamento com Lã de PET Ensacada(US / 90LPe*) | D12: LÃ DE PET ENSACADA | E12: M2 | F12: 1.1 | G12: 16.4 | H12: =G12*F12 -> 18.04
B13: Insumo | C13: Parede Com Sistema Em Chapas De Gesso Para Drywall, Uso Interno, Montante 90mm, Com Uma Face Dupla Standart e Resistente a Umidade e isolamento com Lã de PET Ensacada(US / 90LPe*) | D13: BANDA ACUSTICA | E13: M | F13: 0.8 | G13: 3 | H13: =G13*F13 -> 2.4
B14: Insumo | C14: Parede Com Sistema Em Chapas De Gesso Para Drywall, Uso Interno, Montante 90mm, Com Uma Face Dupla Standart e Resistente a Umidade e isolamento com Lã de PET Ensacada(US / 90LPe*) | D14: Aplicação de zarcão nas guias inferiores | E14: M | F14: 0.84 | G14: 0.6 | H14: =G14*F14 -> 0.504
B15: Insumo | C15: Parede Com Sistema Em Chapas De Gesso Para Drywall, Uso Interno, Montante 90mm, Com Uma Face Dupla Standart e Resistente a Umidade e isolamento com Lã de PET Ensacada(US / 90LPe*) | D15: PARAFUSO DRY WALL, EM ACO FOSFATIZADO, CABECA TROMBETA E PONTA AGULHA (TA), COMPRIMENTO 25 MM | E15: UN | F15: 10.0934 | G15: 0.09 | H15: =G15*F15 -> 0.908406
B16: Insumo | C16: Parede Com Sistema Em Chapas De Gesso Para Drywall, Uso Interno, Montante 90mm, Com Uma Face Dupla Standart e Resistente a Umidade e isolamento com Lã de PET Ensacada(US / 90LPe*) | D16: PARAFUSO DRY WALL, EM ACO ZINCADO, CABECA LENTILHA E PONTA BROCA (LB), LARGURA 4,2 MM, COMPRIMENTO 13 MM | E16: UN | F16: 0.4803 | G16: 0.2 | H16: =G16*F16 -> 0.09606
A17: DW-G5 | B17: Serviço | C17: Parede Com Sistema Em Chapas De Gesso Para Drywall, Uso Interno, Montante 70mm, Com Uma Face Dupla Standart (2S / 70) | D17: Parede Com Sistema Em Chapas De Gesso Para Drywall, Uso Interno, Montante 70mm, Com Uma Face Dupla Standart (2S / 70) | E17: M2 | H17: =SUM(H18:H29) -> 102.4394 | I17: OK
B18: Insumo | C18: =IF(B18="serviço",D18,C17) -> Parede Com Sistema Em Chapas De Gesso Para Drywall, Uso Interno, Montante 70mm, Com Uma Face Dupla Standart (2S / 70) | D18: PLACA / CHAPA DE GESSO ACARTONADO, STANDARD (ST), COR BRANCA, E = 12,5 MM, 1200 X 2400 MM (L X C) | E18: {=_xlfn.XLOOKUP(D18,[1]Insumos!B:B,[1]Insumos!C:$C)} -> M2 | F18: =1.053*2 -> 2.106 | G18: 20.16 | H18: =G18*F18 -> 42.45696
B19: Insumo | C19: =IF(B19="serviço",D19,C18) -> Parede Com Sistema Em Chapas De Gesso Para Drywall, Uso Interno, Montante 70mm, Com Uma Face Dupla Standart (2S / 70) | D19: PINO DE ACO COM ARRUELA CONICA, DIAMETRO ARRUELA = *23* MM E COMP HASTE = *27* MM (ACAO INDIRETA) | E19: {=_xlfn.XLOOKUP(D19,[1]Insumos!B:B,[1]Insumos!C:$C)} -> UN | F19: 2.48 | G19: {=IF(B19="insumo",_xlfn.XLOOKUP($D19,[1]Insumos!$B$1:$B$878,[1]Insumos!$D$1:$D$878),"")} -> 0.504 | H19: =G19*F19 -> 1.24992
B20: Insumo | C20: Parede Com Sistema Em Chapas De Gesso Para Drywall, Uso Interno, Montante 90mm, Com Uma Face Dupla Standart e Resistente a Umidade e isolamento com Lã de PET Ensacada(US / 90LPe*) | D20: PERFIL GUIA, FORMATO U, EM ACO ZINCADO, PARA BLOQUEADOR GUIA TRANSVERSAL | E20: M | F20: =0.7624*1.2 -> 0.91488 | G20: 7.46 | H20: =G20*F20 -> 6.8250048
B21: Insumo | C21: =IF(B21="serviço",D21,C19) -> Parede Com Sistema Em Chapas De Gesso Para Drywall, Uso Interno, Montante 70mm, Com Uma Face Dupla Standart (2S / 70) | D21: PERFIL GUIA, FORMATO U, EM ACO ZINCADO, PARA ESTRUTURA PAREDE DRYWALL, E = 0,5 MM, 70 X 3000 MM (L X C) | E21: {=_xlfn.XLOOKUP(D21,[1]Insumos!B:B,[1]Insumos!C:$C)} -> M | F21: 0.7624 | G21: 7.46 | H21: =G21*F21 -> 5.687504
B22: Insumo | C22: =IF(B22="serviço",D22,C21) -> Parede Com Sistema Em Chapas De Gesso Para Drywall, Uso Interno, Montante 70mm, Com Uma Face Dupla Standart (2S / 70) | D22: PERFIL MONTANTE DUPLO, FORMATO C, EM ACO ZINCADO, PARA ESTRUTURA PAREDE DRYWALL, E = 0,5 MM, 70 X 3000 MM (L X C) | E22: M | F22: =2.0006*2 -> 4.0012 | G22: 9.5 | H22: =G22*F22 -> 38.0114
B23: Insumo | C23: =IF(B23="serviço",D23,C22) -> Parede Com Sistema Em Chapas De Gesso Para Drywall, Uso Interno, Montante 70mm, Com Uma Face Dupla Standart (2S / 70) | D23: MASSA DE REJUNTE EM PO PARA DRYWALL, A BASE DE GESSO, SECAGEM RAPIDA, PARA TRATAMENTO DE JUNTAS DE CHAPA DE GESSO (NECESSITA ADICAO DE AGUA) | E23: {=_xlfn.XLOOKUP(D23,[1]Insumos!B:B,[1]Insumos!C:$C)} -> KG | F23: 0.5489 | G23: {=IF(B23="insumo",_xlfn.XLOOKUP($D23,[1]Insumos!$B$1:$B$878,[1]Insumos!$D$1:$D$878),"")} -> 3.43 | H23: =G23*F23 -> 1.882727
B24: Insumo | C24: =IF(B24="serviço",D24,C23) -> Parede Com Sistema Em Chapas De Gesso Para Drywall, Uso Interno, Montante 70mm, Com Uma Face Dupla Standart (2S / 70) | D24: FITA DE PAPEL MICROPERFURADO, 50 X 150 MM, PARA TRATAMENTO DE JUNTAS DE CHAPA DE GESSO PARA DRYWALL | E24: {=_xlfn.XLOOKUP(D24,[1]Insumos!B:B,[1]Insumos!C:$C)} -> M | F24: 1.2513 | G24: {=IF(B24="insumo",_xlfn.XLOOKUP($D24,[1]Insumos!$B$1:$B$878,[1]Insumos!$D$1:$D$878),"")} -> 0.31 | H24: =G24*F24 -> 0.387903
B25: Insumo | C25: =IF(B25="serviço",D25,C24) -> Parede Com Sistema Em Chapas De Gesso Para Drywall, Uso Interno, Montante 70mm, Com Uma Face Dupla Standart (2S / 70) | D25: FITA DE PAPEL REFORCADA COM LAMINA DE METAL PARA REFORCO DE CANTOS DE CHAPA DE GESSO PARA DRYWALL | E25: {=_xlfn.XLOOKUP(D25,[1]Insumos!B:B,[1]Insumos!C:$C)} -> M | F25: 0.7407 | G25: {=IF(B25="insumo",_xlfn.XLOOKUP($D25,[1]Insumos!$B$1:$B$878,[1]Insumos!$D$1:$D$878),"")} -> 2.74 | H25: =G25*F25 -> 2.029518
B26: Insumo | C26: =IF(B26="serviço",D26,C25) -> Parede Com Sistema Em Chapas De Gesso Para Drywall, Uso Interno, Montante 70mm, Com Uma Face Dupla Standart (2S / 70) | D26: PARAFUSO DRY WALL, EM ACO FOSFATIZADO, CABECA TROMBETA E PONTA AGULHA (TA), COMPRIMENTO 25 MM | E26: {=_xlfn.XLOOKUP(D26,[1]Insumos!B:B,[1]Insumos!C:$C)} -> UN | F26: 10.0934 | G26: {=IF(B26="insumo",_xlfn.XLOOKUP($D26,[1]Insumos!$B$1:$B$878,[1]Insumos!$D$1:$D$878),"")} -> 0.09 | H26: =G26*F26 -> 0.908406
B27: Insumo | C27: =IF(B27="serviço",D27,C26) -> Parede Com Sistema Em Chapas De Gesso Para Drywall, Uso Interno, Montante 70mm, Com Uma Face Dupla Standart (2S / 70) | D27: PARAFUSO DRY WALL, EM ACO ZINCADO, CABECA LENTILHA E PONTA BROCA (LB), LARGURA 4,2 MM, COMPRIMENTO 13 MM | E27: {=_xlfn.XLOOKUP(D27,[1]Insumos!B:B,[1]Insumos!C:$C)} -> UN | F27: 0.4803 | G27: {=IF(B27="insumo",_xlfn.XLOOKUP($D27,[1]Insumos!$B$1:$B$878,[1]Insumos!$D$1:$D$878),"")} -> 0.2 | H27: =G27*F27 -> 0.09606
B28: Insumo | C28: Parede Com Sistema Em Chapas De Gesso Para Drywall, Uso Interno, Montante 90mm, Com Uma Face Dupla Standart e Resistente a Umidade e isolamento com Lã de PET Ensacada(US / 90LPe*) | D28: BANDA ACUSTICA | E28: M | F28: 0.8 | G28: 3 | H28: =G28*F28 -> 2.4
B29: Insumo | C29: Parede Com Sistema Em Chapas De Gesso Para Drywall, Uso Interno, Montante 90mm, Com Uma Face Dupla Standart e Resistente a Umidade e isolamento com Lã de PET Ensacada(US / 90LPe*) | D29: Aplicação de zarcão nas guias inferiores | E29: M | F29: 0.84 | G29: 0.6 | H29: =G29*F29 -> 0.504
A30: DW-B4 | B30: Serviço | C30: =IF(B30="serviço",D30,#REF!) -> Parede Com Sistema Em Chapas De Gesso Para Drywall, Uso Interno, Montante 70mm, Com Duas Face Duplas Standart e Isolamento Lã de PET (2S / 70LP / 2S) | D30: Parede Com Sistema Em Chapas De Gesso Para Drywall, Uso Interno, Montante 70mm, Com Duas Face Duplas Standart e Isolamento Lã de PET (2S / 70LP / 2S) | E30: M2 | G30: {=IF(B30="insumo",_xlfn.XLOOKUP($D30,[1]Insumos!$B$1:$B$878,[1]Insumos!$D$1:$D$878),"")} | H30: =SUM(H31:H42) -> 144.3739 | I30: OK
B31: Insumo | C31: Parede Com Sistema Em Chapas De Gesso Para Drywall, Uso Interno, Montante 70mm, Com Duas Face Duplas Standart e Isolamento Lã de PET (2S / 70LP / 2S) | D31: PLACA / CHAPA DE GESSO ACARTONADO, STANDARD (ST), COR BRANCA, E = 12,5 MM, 1200 X 2400 MM (L X C) | E31: M2 | F31: 4.212 | G31: 20.16 | H31: =G31*F31 -> 84.91392
B32: Insumo | C32: Parede Com Sistema Em Chapas De Gesso Para Drywall, Uso Interno, Montante 70mm, Com Duas Face Duplas Standart e Isolamento Lã de PET (2S / 70LP / 2S) | D32: PINO DE ACO COM ARRUELA CONICA, DIAMETRO ARRUELA = *23* MM E COMP HASTE = *27* MM (ACAO INDIRETA) | E32: UN | F32: 4.95 | G32: 0.504 | H32: =G32*F32 -> 2.4948
B33: Insumo | C33: Parede Com Sistema Em Chapas De Gesso Para Drywall, Uso Interno, Montante 70mm, Com Duas Face Duplas Standart e Isolamento Lã de PET (2S / 70LP / 2S) | D33: PERFIL GUIA, FORMATO U, EM ACO ZINCADO, PARA ESTRUTURA PAREDE DRYWALL, E = 0,5 MM, 70 X 3000 MM (L X C) | E33: M | F33: 1.5248 | G33: 7.46 | H33: =G33*F33 -> 11.375008
B34: Insumo | C34: Parede Com Sistema Em Chapas De Gesso Para Drywall, Uso Interno, Montante 70mm, Com Duas Face Duplas Standart e Isolamento Lã de PET (2S / 70LP / 2S) | D34: PERFIL MONTANTE, FORMATO C, EM ACO ZINCADO, PARA ESTRUTURA PAREDE DRYWALL, E = 0,5 MM, 70 X 3000 MM (L X C) | E34: M | F34: =2.0006 -> 2.0006 | G34: 9.5 | H34: =G34*F34 -> 19.0057
B35: Insumo | C35: Parede Com Sistema Em Chapas De Gesso Para Drywall, Uso Interno, Montante 70mm, Com Duas Face Duplas Standart e Isolamento Lã de PET (2S / 70LP / 2S) | D35: MASSA DE REJUNTE EM PO PARA DRYWALL, A BASE DE GESSO, SECAGEM RAPIDA, PARA TRATAMENTO DE JUNTAS DE CHAPA DE GESSO (NECESSITA ADICAO DE AGUA) | E35: KG | F35: 1.0978 | G35: 3.43 | H35: =G35*F35 -> 3.765454
B36: Insumo | C36: Parede Com Sistema Em Chapas De Gesso Para Drywall, Uso Interno, Montante 70mm, Com Duas Face Duplas Standart e Isolamento Lã de PET (2S / 70LP / 2S) | D36: FITA DE PAPEL MICROPERFURADO, 50 X 150 MM, PARA TRATAMENTO DE JUNTAS DE CHAPA DE GESSO PARA DRYWALL | E36: M | F36: 2.5027 | G36: 0.31 | H36: =G36*F36 -> 0.775837
B37: Insumo | C37: Parede Com Sistema Em Chapas De Gesso Para Drywall, Uso Interno, Montante 70mm, Com Duas Face Duplas Standart e Isolamento Lã de PET (2S / 70LP / 2S) | D37: FITA DE PAPEL REFORCADA COM LAMINA DE METAL PARA REFORCO DE CANTOS DE CHAPA DE GESSO PARA DRYWALL | E37: M | F37: 1.4815 | G37: 2.74 | H37: =G37*F37 -> 4.05931
B38: Insumo | C38: Parede Com Sistema Em Chapas De Gesso Para Drywall, Uso Interno, Montante 70mm, Com Duas Face Duplas Standart e Isolamento Lã de PET (2S / 70LP / 2S) | D38: LÃ DE PET ENSACADA | E38: M2 | F38: 1.1 | G38: 11.97 | H38: =G38*F38 -> 13.167
B39: Insumo | C39: Parede Com Sistema Em Chapas De Gesso Para Drywall, Uso Interno, Montante 70mm, Com Duas Face Duplas Standart e Isolamento Lã de PET (2S / 70LP / 2S) | D39: PARAFUSO DRY WALL, EM ACO FOSFATIZADO, CABECA TROMBETA E PONTA AGULHA (TA), COMPRIMENTO 25 MM | E39: UN | F39: 20.1868 | G39: 0.09 | H39: =G39*F39 -> 1.816812
B40: Insumo | C40: Parede Com Sistema Em Chapas De Gesso Para Drywall, Uso Interno, Montante 70mm, Com Duas Face Duplas Standart e Isolamento Lã de PET (2S / 70LP / 2S) | D40: PARAFUSO DRY WALL, EM ACO ZINCADO, CABECA LENTILHA E PONTA BROCA (LB), LARGURA 4,2 MM, COMPRIMENTO 13 MM | E40: UN | F40: 0.4803 | G40: 0.2 | H40: =G40*F40 -> 0.09606
...

Sheet PROPOSTA VIGENTE
A1: PERFIS DRYWALL TODAS AS OBRAS
B2: CUSTO UN | C2: CUSTO ML
A3: GUIA DE 48 - 3 METROS | B3: 12.3 | C3: =B3/2 -> 6.15
A4: GUIA DE 70- 3 METROS | B4: 14.91 | C4: =B4/2 -> 7.455
A5: GUIA DE 90- 3 METROS | B5: 17.28 | C5: =B5/2 -> 8.64
A6: MONTANTE 48- 3 METROS | B6: 16.13 | C6: =B6/2 -> 8.065
A7: MONTANTE 70- 3 METROS | B7: 19.008 | C7: =B7/2 -> 9.504
A8: MONTANTE 90- 3 METROS | B8: 21.58 | C8: =B8/2 -> 10.79
A9: STTEL 95 MONT 140 - 6 METROS | B9: 125.66 | C9: =B9/6 -> 20.943333
A10: STTEL 95 MONT 90- 6 METROS | B10: 106.32 | C10: =B10/6 -> 17.72
A11: STTEL 95 GUIT 140 - 6 METROS | B11: 141.14 | C11: =B11/6 -> 23.523333
A15: MATERIAL | B15: CUSTO UN | C15: Real
A16: chapa st 12,5 mm - 1,20 x 2,90 | B16: 16.733001 | C16: 20.16
A17: chapa st 12,5 mm - 1,20 x 1,80 | B17: 16.733001 | C17: 20.16
A18: chapa ru 12,5 mm- 1,20 x 2,90 | B18: 22.581753 | C18: 27.098104
A19: chapa ru 12,5 mm- 1,20 x 1,80 | B19: 22.581753 | C19: 27.098104
A20: chapa performa st - 1,20 x 2,90 | B20: 26.024161 | C20: 31.228994
A21: chapa performa st - 1,20 x 1,80 | B21: 26.024161 | C21: 31.228994
A22: chapa performa ru - 1,20 x 2,90 | B22: 34.078728 | C22: 40.95
A23: chapa performa ru - 1,20 x 1,80 | B23: 34.078728 | C23: 40.894474
A24: chapa glasroc X 12,50mm - 1,20 x 2,40m | B24: 74.752621 | C24: 89.703145
A27: Lã de pet Ensacada M² | B27: 16.4
