Workbook

Sheet Orçamento
A1: Etapa | B1: Volume Total | D1: Duração Estimada (dias) | E1: m³/dia | F1: Custo equipamentos | G1: Bota fora - custo unitário | H1: Bota fora - custo total | I1: MO (Apoio a infra) | J1: CUSTO PARCIAL
A2: Escavação 1ª etapa - Setor C | B2: =5200*1.3 -> 6760 | C2: =B2/1.3 -> 5200 | D2: 30 | E2: =B2/D2 -> 225.33333 | F2: =Composições!E11 -> 280000 | G2: 40 | H2: =G2*B2 -> 270400 | I2: 75548.1 | J2: =SUM(H2,F2) -> 550400 | K2: =J2/B2 -> 81.420118
A3: Escavação 1ª etapa - Setor D | B3: =4151*1.3 -> 5396.3 | D3: 16 | E3: =B3/D3 -> 337.26875 | F3: =Composições!E22 -> 153600 | G3: 40 | H3: =G3*B3 -> 215852 | I3: =75548.1/2 -> 37774.05 | J3: =SUM(H3,F3) -> 369452 | K3: =J3/B3 -> 68.463948
A4: Escavação 1ª etapa - Setor B | B4: =3420*1.3 -> 4446 | D4: 14 | E4: =B4/D4 -> 317.57143 | F4: =Composições!E22 -> 153600 | G4: 40 | H4: =G4*B4 -> 177840 | I4: =75548.1/2 -> 37774.05 | J4: =SUM(H4,F4) -> 331440 | K4: =J4/B4 -> 74.547908
A5: Escavação 2ª etapa - Setor C | B5: =3600*1.3 -> 4680 | C5: =B5/1.3 -> 3600 | D5: 30 | E5: =B5/D5 -> 156 | F5: =Composições!E32 -> 342000 | G5: 40 | H5: =G5*B5 -> 187200 | I5: =75548.1*2 -> 151096.2 | J5: =SUM(H5,F5) -> 529200 | K5: =J5/B5 -> 113.07692
A6: Escavação 3ª etapa - Setor C | B6: =10144*1.3 -> 13187.2 | C6: =B6/1.3 -> 10144 | D6: 50 | E6: =B6/D6 -> 263.744 | F6: =Composições!E42 -> 680000 | G6: 40 | H6: =G6*B6 -> 527488 | I6: =I5*2.5 -> 377740.5 | J6: =SUM(H6,F6) -> 1207488 | K6: =J6/B6 -> 91.565154
I8: TOTAL | J8: =SUM(J2:J6) -> 2987980

Sheet Composições
A1: Modelo | B1: Capacidade do Balde (m³) | C1: Capacidade do Balde (m³) | D1: Volume Estimado por Hora (m³/h) | E1: média considerada (m³/h) | F1: m³ dia | G1: R$/m³
A2: R140W-9A | B2: 2500 | C2: 0,6 - 0,8 | D2: 12. - 30 | E2: 20 | F2: =E2*7 -> 140 | G2: =B2/F2 -> 17.857143
A3: R200LC-9A | B3: 3200 | C3: 1,0 - 1,2 | D3: 20 - 30 | E3: 25 | F3: =E3*7 -> 175 | G3: =B3/F3 -> 18.285714
A4: R220LC-9A | B4: 3500 | C4: 1,2 - 1,5 | D4: 25 - 40 | E4: 30 | F4: =E4*7 -> 210 | G4: =B4/F4 -> 16.666667
A5: R260LC-9A | B5: 4800 | C5: 1,5 - 1,7 (padrão; até 2,0 com opções) | D5: 35 - 50+ | E5: 40 | F5: =E5*7 -> 280 | G5: =B5/F5 -> 17.142857
A6: R35Z-9A | B6: 2200 | C6: 0,045 - 0,12 | D6: 1 - 3 m³/h | E6: 2 | F6: =E6*7 -> 14 | G6: =B6/F6 -> 157.14286
A7: R50-9A | B7: 2200 | C7: 0,13 - 0,16 | D7: 3 - 5 m³/h | E7: 4 | F7: =E7*7 -> 28 | G7: =B7/F7 -> 78.571429
A8: R80CR-9A | B8: 2200 | C8: 0,18 - 0,30 | D8: 5 - 8 m³/h | E8: 6.5 | F8: =E8*7 -> 45.5 | G8: =B8/F8 -> 48.351648
A9: R220LCR-9A (Long Reach) | B9: 7000 | C9: 1,2 - 1,5 | D9: 25 - 40 | E9: 30 | F9: =E9*7 -> 210 | G9: =B9/F9 -> 33.333333
A11: Composição 01 | B11: Capacidade diaria (m³/dia) | C11: =SUM(B19:C19) -> 700 | D11: total | E11: =SUM(B18:G18) -> 280000
A12: Volume Total | B12: =Orçamento!B2 -> 6760
A13: Duração Estimada (dias) | B13: 20
A14: m³/dia | B14: =Orçamento!E2 -> 225.33333
A15: QTD Equipamentos | B15: 1 | C15: 2 | D15: 1
A16: Equipamentos | B16: R260LC-9A | C16: R220LC-9A | D16: colar arrasador
A17: CUSTO DIARIO | B17: =$B$5 -> 4800 | C17: =$B$4 -> 3500 | D17: 2200
A18: Custo total | B18: =B17*B13*B15 -> 96000 | C18: =C17*B13*C15 -> 140000 | D18: =D17*B13*D15 -> 44000
A19: capcidade diaria | B19: =B15*$F$5 -> 280 | C19: =C15*$F$4 -> 420
A22: Composição 02 | B22: Capacidade diaria (m³/dia) | C22: =SUM(B30:B30) -> 420 | D22: total | E22: =SUM(B29:G29) -> 153600
A23: Volume Total | B23: =Orçamento!B3 -> 5396.3
A24: Duração Estimada (dias) | B24: =Orçamento!D3 -> 16
A25: m³/dia | B25: =Orçamento!E3 -> 337.26875
A26: QTD Equipamentos | B26: 2
A27: Equipamentos | B27: R260LC-9A
A28: CUSTO DIARIO | B28: =$B$5 -> 4800
A29: Custo total | B29: =B28*B24*B26 -> 153600
A30: capcidade diaria | B30: =B26*$F$4 -> 420
A32: Composição 03 | B32: Capacidade diaria (m³/dia) | C32: =SUM(B40:G40) -> 223 | D32: total | E32: =SUM(B39:G39) -> 342000
A33: Volume Total | B33: =Orçamento!B5 -> 4680
A34: Duração Estimada (dias) | B34: =Orçamento!D5 -> 30
A35: m³/dia | B35: =Orçamento!E5 -> 156
A36: QTD Equipamentos | B36: 1 | C36: 2 | D36: 1
A37: Equipamentos | B37: R260LC-9A | C37: R80CR-9A | D37: colar arrasador
A38: CUSTO DIARIO | B38: =$B$5 -> 4800 | C38: =B8 -> 2200 | D38: 2200
A39: Custo total | B39: =B38*B34*B36 -> 144000 | C39: =C38*C36*B34 -> 132000 | D39: =D38*B34*D36 -> 66000
A40: capcidade diaria | B40: =B36*$F$4 -> 210 | C40: =C36*E8 -> 13
A42: Composição 04 | B42: Capacidade diaria (m³/dia) | C42: =SUM(B50:G50) -> 218.5 | D42: total | E42: =SUM(B49:G49) -> 680000
A43: Volume Total | B43: =Orçamento!B6 -> 13187.2
A44: Duração Estimada (dias) | B44: =Orçamento!D6 -> 50
A45: m³/dia | B45: =Orçamento!E6 -> 263.744
...
