Workbook

Sheet PAINEL
A1: PAINEL DE CONTROLE
A4: Projeto: | B4: =DADOS_PROJETO!B2
A5: Área Construída: | B5: =DADOS_PROJETO!B6&" m²"
A6: Unidades: | B6: =DADOS_PROJETO!B7+DADOS_PROJETO!B8
A8: Custo Total: | B8: =CUSTOS_MACROGRUPO!G20
A9: Custo/m²: | B9: =CUSTOS_MACROGRUPO!G20/DADOS_PROJETO!B6
A10: Custo/Unidade: | B10: =CUSTOS_MACROGRUPO!G20/(DADOS_PROJETO!B7+DADOS_PROJETO!B8)
A12: CUB Atual: | B12: =DADOS_PROJETO!B19
A13: Fator CUB: | B13: =DADOS_PROJETO!B19/DADOS_PROJETO!B20
A15: Top 3 Macrogrupos:
A16: 1º | B16: =INDEX(CUSTOS_MACROGRUPO!B:B,MATCH(LARGE(CUSTOS_MACROGRUPO!H:H,1),CUSTOS_MACROGRUPO!H:H,0))&" ("&TEXT(LARGE(CUSTOS_MACROGRUPO!H:H,1),"0.0%")&")"
A17: 2º | B17: =INDEX(CUSTOS_MACROGRUPO!B:B,MATCH(LARGE(CUSTOS_MACROGRUPO!H:H,2),CUSTOS_MACROGRUPO!H:H,0))&" ("&TEXT(LARGE(CUSTOS_MACROGRUPO!H:H,2),"0.0%")&")"
A18: 3º | B18: =INDEX(CUSTOS_MACROGRUPO!B:B,MATCH(LARGE(CUSTOS_MACROGRUPO!H:H,3),CUSTOS_MACROGRUPO!H:H,0))&" ("&TEXT(LARGE(CUSTOS_MACROGRUPO!H:H,3),"0.0%")&")"

Sheet DADOS_PROJETO
A1: DADOS DO PROJETO
A2: Nome do Projeto | B2: Residencial Alípio Schirmann
A3: Código | B3: BCI-ALIPIO
A4: Cidade | B4: Itapema/SC
A6: Área Construída (m²) | B6: 12033.95
A7: Unidades Residenciais | B7: 43
A8: Unidades Comerciais | B8: 5
A9: Número de Pavimentos | B9: 26
A10: Pavimentos Tipo | B10: 21
A11: Pavimentos Garagem | B11: 3
A12: Elevadores | B12: 3
A13: Vagas | B13: 92
A14: Área Terreno (m²) | B14: 1029.39
A15: Número de Subsolos | B15: 0
A17: Prazo (meses) | B17: 36
A19: CUB Atual (R$/m²) | B19: 3019.26
A20: CUB Base dez/23 (R$/m²) | B20: 2752.67
A21: Data-base | B21: mar/2026

Sheet BRIEFING
A1: # | B1: Pergunta | C1: Resposta | D1: Macrogrupos Afetados
A2: Q1 | B2: Tipo de Fundação | C2: Hélice Contínua | D2: Infraestrutura
A3: Q2 | B3: Tipo de Laje | C3: Cubetas | D3: Supraestrutura
A4: Q3 | B4: Contenção | C4: Não | D4: Infraestrutura
A5: Q4 | B5: Subsolos | C5: 0 | D5: Mov. Terra, Infraestrutura, Impermeabilização
A6: Q5 | B6: Padrão | C6: Alto | D6: Rev. Int. Parede, Teto, Pisos, Pintura, Esquadrias, Fachada, Complementares
A7: Q6 | B7: Esquadria | C7: Pintura eletrostática | D7: Esquadrias
A8: Q7 | B8: Piso | C8: Porcelanato padrão | D8: Pisos
A9: Q8 | B9: Vedação | C9: Alvenaria | D9: Alvenaria
A10: Q9 | B10: Forro | C10: Gesso liso | D10: Teto
A11: Q10 | B11: Fachada | C11: Misto | D11: Fachada
A12: Q11 | B12: MO Fachada | C12: Empreitada | D12: Fachada
... A26: Q25 | B26: Pressurização | C26: Não | D26: Instalações

Sheet FATORES
A1: MATRIZ DE FATORES
A2: Macrogrupo | B2: Q1 | C2: Q2 | D2: Q3 | E2: Q4 | F2: Q5 | G2: Q6 | H2: Q7 | I2: Q8 | J2: Q9 | K2: Q10 | L2: Q11 | M2: Q12 | N2: Q13 | O2: Q14 | P2: Q15 | Q2: Q16 | R2: Q17 | S2: Q18 | T2: Q19 | U2: Q20 | V2: Q21 | W2: Q22 | X2: Q23 | Y2: Q24 | Z2: Q25 | AA2: Fator Briefing
A3: Gerenciamento | B3: =1 | C3: =1 | D3: =1 | E3: =1 | F3: =1 | G3: =1 | H3: =1 | I3: =1 | ... S3: =1 | T3: =IF(BRIEFING!$C$20="18",0.6,IF(BRIEFING!$C$20="24",0.75,IF(BRIEFING!$C$20="30",0.88,IF(BRIEFING!$C$20="36",1.0,IF(BRIEFING!$C$20="42",1.15,IF(BRIEFING!$C$20="48",1.3,1)))))) | U3: =IF(BRIEFING!$C$21="Interior SC",0.95,IF(BRIEFING!$C$21="Litoral SC",1.0,IF(BRIEFING!$C$21="Capital Floripa",1.05,IF(BRIEFING!$C$21="Litoral SP",1.15,IF(BRIEFING!$C$21="Capital SP-RJ",1.25,1))))) | V3: =1 | W3: =1 | X3: =1 | Y3: =1 | Z3: =1 | AA3: =PRODUCT(B3:Z3)
A4: Mov. Terra | B4: =1 | C4: =1 | D4: =1 | E4: =IF(BRIEFING!$C$5="0",1.0,IF(BRIEFING!$C$5="1",2.0,IF(BRIEFING!$C$5="2",3.5,IF(BRIEFING!$C$5="3+",5.0,1)))) | F4: =1 | G4: =1 | H4: =1 | I4: =1 | J4: =1 | K4: =1 | L4: =1 | M4: =1 | ... T4: =1 | U4: =IF(BRIEFING!$C$21="Interior SC",0.95,IF(BRIEFING!$C$21="Litoral SC",1.0,IF(BRIEFING!$C$21="Capital Floripa",1.05,IF(BRIEFING!$C$21="Litoral SP",1.15,IF(BRIEFING!$C$21="Capital SP-RJ",1.25,1))))) | V4: =1 | W4: =1 | X4: =1 | Y4: =1 | Z4: =1 | AA4: =PRODUCT(B4:Z4)
A5: Infraestrutura | B5: =IF(BRIEFING!$C$2="Hélice Contínua",1.0,IF(BRIEFING!$C$2="Estaca Franki",0.9,IF(BRIEFING!$C$2="Tubulão",1.15,IF(BRIEFING!$C$2="Sapata/Radier",0.75,IF(BRIEFING!$C$2="Estaca raiz",1.1,1))))) | C5: =1 | D5: =IF(BRIEFING!$C$4="Não",1.0,IF(BRIEFING!$C$4="Cortina de estacas",1.4,IF(BRIEFING!$C$4="Muro de arrimo",1.2,IF(BRIEFING!$C$4="Solo grampeado",1.3,IF(BRIEFING!$C$4="Tirantes",1.35,1))))) | E5: =IF(BRIEFING!$C$5="0",1.0,IF(BRIEFING!$C$5="1",1.2,IF(BRIEFING!$C$5="2",1.4,IF(BRIEFING!$C$5="3+",1.6,1)))) | F5: =1 | G5: =1 | H5: =1 | I5: =1 | J5: =1 | K5: =1 | L5: =1 | M5: =1 | ... T5: =1 | U5: =IF(BRIEFING!$C$21="Interior SC",0.95,IF(BRIEFING!$C$21="Litoral SC",1.0,IF(BRIEFING!$C$21="Capital Floripa",1.05,IF(BRIEFING!$C$21="Litoral SP",1.15,IF(BRIEFING!$C$21="Capital SP-RJ",1.25,1))))) | V5: =1 | W5: =1 | X5: =1 | Y5: =1 | Z5: =1 | AA5: =PRODUCT(B5:Z5)
A6: Supraestrutura | B6: =1 | C6: =IF(BRIEFING!$C$3="Cubetas",1.0,IF(BRIEFING!$C$3="Protendida",1.05,IF(BRIEFING!$C$3="Maciça",1.1,IF(BRIEFING!$C$3="Mista",1.03,IF(BRIEFING!$C$3="Treliçada",0.95,1))))) | D6: =1 | E6: =1 | F6: =1 | G6: =1 | H6: =1 | I6: =1 | J6: =1 | K6: =1 | ... T6: =1 | U6: =IF(BRIEFING!$C$21="Interior SC",0.95,IF(BRIEFING!$C$21="Litoral SC",1.0,IF(BRIEFING!$C$21="Capital Floripa",1.05,IF(BRIEFING!$C$21="Litoral SP",1.15,IF(BRIEFING!$C$21="Capital SP-RJ",1.25,1))))) | V6: =1 | W6: =1 | X6: =1 | Y6: =1 | Z6: =1 | AA6: =PRODUCT(B6:Z6)
A7: Alvenaria | B7: =1 | C7: =1 | D7: =1 | E7: =1 | F7: =1 | G7: =1 | H7: =1 | I7: =IF(BRIEFING!$C$9="Alvenaria",1.0,IF(BRIEFING!$C$9="Drywall",1.8,IF(BRIEFING!$C$9="Misto",1.3,1))) | J7: =1 | K7: =1 | L7: =1 | M7: =1 | N7: =1 | O7: =1 | P7: =1 | Q7: =1 | ... T7: =1 | U7: =IF(BRIEFING!$C$21="Interior SC",0.95,IF(BRIEFING!$C$21="Litoral SC",1.0,IF(BRIEFING!$C$21="Capital Floripa",1.05,IF(BRIEFING!$C$21="Litoral SP",1.15,IF(BRIEFING!$C$21="Capital SP-RJ",1.25,1))))) | V7: =1 | W7: =1 | X7: =1 | Y7: =1 | Z7: =1 | AA7: =PRODUCT(B7:Z7)
A8: Impermeabilização | B8: =1 | C8: =1 | D8: =1 | E8: =IF(BRIEFING!$C$5="0",1.0,IF(BRIEFING!$C$5="1",1.3,IF(BRIEFING!$C$5="2",1.6,IF(BRIEFING!$C$5="3+",1.9,1)))) | F8: =1 | G8: =1 | H8: =1 | I8: =1 | J8: =1 | K8: =1 | L8: =1 | M8: =1 | ... T8: =1 | U8: =IF(BRIEFING!$C$21="Interior SC",0.95,IF(BRIEFING!$C$21="Litoral SC",1.0,IF(BRIEFING!$C$21="Capital Floripa",1.05,IF(BRIEFING!$C$21="Litoral SP",1.15,IF(BRIEFING!$C$21="Capital SP-RJ",1.25,1))))) | V8: =1 | W8: =1 | X8: =1 | Y8: =1 | Z8: =1 | AA8: =PRODUCT(B8:Z8)
A9: Instalações | B9: =1 | C9: =1 | D9: =1 | E9: =1 | F9: =1 | G9: =1 | H9: =1 | I9: =1 | ... M9: =1 | N9: =IF(BRIEFING!$C$14="Gás individual",1.0,IF(BRIEFING!$C$14="Central",1.15,IF(BRIEFING!$C$14="Solar",1.2,IF(BRIEFING!$C$14="Bomba calor",1.25,IF(BRIEFING!$C$14="Sem",0.9,1))))) | O9: =1 | P9: =1 | Q9: =1 | R9: =1 | S9: =1 | T9: =1 | U9: =IF(BRIEFING!$C$21="Interior SC",0.95,IF(BRIEFING!$C$21="Litoral SC",1.0,IF(BRIEFING!$C$21="Capital Floripa",1.05,IF(BRIEFING!$C$21="Litoral SP",1.15,IF(BRIEFING!$C$21="Capital SP-RJ",1.25,1))))) | V9: =1 | W9: =1 | X9: =1 | Y9: =IF(BRIEFING!$C$25="Sim",1.05,IF(BRIEFING!$C$25="Não",1.0,1)) | Z9: =IF(BRIEFING!$C$26="Sim",1.08,IF(BRIEFING!$C$26="Não",1.0,1)) | AA9: =PRODUCT(B9:Z9)
A10: Sist. Especiais | B10: =1 | C10: =1 | D10: =1 | E10: =1 | F10: =1 | G10: =1 | H10: =1 | I10: =1 | ... N10: =1 | O10: =IF(BRIEFING!$C$15="Mínimo",0.85,IF(BRIEFING!$C$15="Básico",1.0,IF(BRIEFING!$C$15="Completo",1.3,IF(BRIEFING!$C$15="Premium",1.6,1)))) | P10: =IF(BRIEFING!$C$16="Sem",1.0,IF(BRIEFING!$C$16="Solar comum",1.1,IF(BRIEFING!$C$16="Solar completo",1.2,1))) | Q10: =1 | R10: =1 | S10: =1 | T10: =1 | U10: =IF(BRIEFING!$C$21="Interior SC",0.95,IF(BRIEFING!$C$21="Litoral SC",1.0,IF(BRIEFING!$C$21="Capital Floripa",1.05,IF(BRIEFING!$C$21="Litoral SP",1.15,IF(BRIEFING!$C$21="Capital SP-RJ",1.25,1))))) | V10: =IF(BRIEFING!$C$22="Sim",1.15,IF(BRIEFING!$C$22="Não",1.0,1)) | W10: =IF(BRIEFING!$C$23="Sim",1.1,IF(BRIEFING!$C$23="Não",1.0,1)) | X10: =IF(BRIEFING!$C$24="Sim",1.1,IF(BRIEFING!$C$24="Não",1.0,1)) | Y10: =1 | Z10: =1 | AA10: =PRODUCT(B10:Z10)
A11: Climatização | B11: =1 | C11: =1 | D11: =1 | E11: =1 | F11: =1 | G11: =1 | H11: =1 | I11: =1 | ... T11: =1 | U11: =IF(BRIEFING!$C$21="Interior SC",0.95,IF(BRIEFING!$C$21="Litoral SC",1.0,IF(BRIEFING!$C$21="Capital Floripa",1.05,IF(BRIEFING!$C$21="Litoral SP",1.15,IF(BRIEFING!$C$21="Capital SP-RJ",1.25,1))))) | V11: =1 | W11: =1 | X11: =1 | Y11: =1 | Z11: =1 | AA11: =PRODUCT(B11:Z11)
A12: Rev. Int. Parede | B12: =1 | C12: =1 | D12: =1 | E12: =1 | F12: =IF(BRIEFING!$C$6="Econômico",0.65,IF(BRIEFING!$C$6="Standard",0.8,IF(BRIEFING!$C$6="Alto",1.0,IF(BRIEFING!$C$6="Super Alto",1.2,IF(BRIEFING!$C$6="Luxo",1.45,1))))) | G12: =1 | H12: =1 | I12: =1 | J12: =1 | K12: =1 | L12: =1 | M12: =1 | N12: =1 | ... T12: =1 | U12: =IF(BRIEFING!$C$21="Interior SC",0.95,IF(BRIEFING!$C$21="Litoral SC",1.0,IF(BRIEFING!$C$21="Capital Floripa",1.05,IF(BRIEFING!$C$21="Litoral SP",1.15,IF(BRIEFING!$C$21="Capital SP-RJ",1.25,1))))) | V12: =1 | W12: =1 | X12: =1 | Y12: =1 | Z12: =1 | AA12: =PRODUCT(B12:Z12)
A13: Teto | B13: =1 | C13: =1 | D13: =1 | E13: =1 | F13: =IF(BRIEFING!$C$6="Econômico",0.7,IF(BRIEFING!$C$6="Standard",0.8,IF(BRIEFING!$C$6="Alto",1.0,IF(BRIEFING!$C$6="Super Alto",1.2,IF(BRIEFING!$C$6="Luxo",1.4,1))))) | G13: =1 | H13: =1 | I13: =1 | J13: =IF(BRIEFING!$C$10="Estucamento",0.8,IF(BRIEFING!$C$10="Gesso liso",1.0,IF(BRIEFING!$C$10="Gesso negativo",1.15,IF(BRIEFING!$C$10="Gesso sanca",1.2,IF(BRIEFING!$C$10="Mineral",1.1,1))))) | K13: =1 | L13: =1 | M13: =1 | N13: =1 | O13: =1 | P13: =1 | Q13: =1 | R13: =1 | ... T13: =1 | U13: =IF(BRIEFING!$C$21="Interior SC",0.95,IF(BRIEFING!$C$21="Litoral SC",1.0,IF(BRIEFING!$C$21="Capital Floripa",1.05,IF(BRIEFING!$C$21="Litoral SP",1.15,IF(BRIEFING!$C$21="Capital SP-RJ",1.25,1))))) | V13: =1 | W13: =1 | X13: =1 | Y13: =1 | Z13: =1 | AA13: =PRODUCT(B13:Z13)
A14: Pisos | B14: =1 | C14: =1 | D14: =1 | E14: =1 | F14: =IF(BRIEFING!$C$6="Econômico",0.6,IF(BRIEFING!$C$6="Standard",0.75,IF(BRIEFING!$C$6="Alto",1.0,IF(BRIEFING!$C$6="Super Alto",1.3,IF(BRIEFING!$C$6="Luxo",1.7,1))))) | G14: =1 | H14: =IF(BRIEFING!$C$8="Porcelanato padrão",1.0,IF(BRIEFING!$C$8="Cerâmica",0.75,IF(BRIEFING!$C$8="Vinílico",0.85,IF(BRIEFING!$C$8="Importado",1.5,IF(BRIEFING!$C$8="Mármore",2.0,1))))) | I14: =1 | J14: =1 | K14: =1 | L14: =1 | M14: =1 | N14: =1 | O14: =1 | P14: =1 | ... T14: =1 | U14: =IF(BRIEFING!$C$21="Interior SC",0.95,IF(BRIEFING!$C$21="Litoral SC",1.0,IF(BRIEFING!$C$21="Capital Floripa",1.05,IF(BRIEFING!$C$21="Litoral SP",1.15,IF(BRIEFING!$C$21="Capital SP-RJ",1.25,1))))) | V14: =1 | W14: =1 | X14: =1 | Y14: =1 | Z14: =1 | AA14: =PRODUCT(B14:Z14)
A15: Pintura | B15: =1 | C15: =1 | D15: =1 | E15: =1 | F15: =IF(BRIEFING!$C$6="Econômico",0.85,IF(BRIEFING!$C$6="Standard",0.9,IF(BRIEFING!$C$6="Alto",1.0,IF(BRIEFING!$C$6="Super Alto",1.1,IF(BRIEFING!$C$6="Luxo",1.2,1))))) | G15: =1 | H15: =1 | I15: =1 | J15: =1 | K15: =1 | L15: =1 | M15: =1 | N15: =1 | ... T15: =1 | U15: =IF(BRIEFING!$C$21="Interior SC",0.95,IF(BRIEFING!$C$21="Litoral SC",1.0,IF(BRIEFING!$C$21="Capital Floripa",1.05,IF(BRIEFING!$C$21="Litoral SP",1.15,IF(BRIEFING!$C$21="Capital SP-RJ",1.25,1))))) | V15: =1 | W15: =1 | X15: =1 | Y15: =1 | Z15: =1 | AA15: =PRODUCT(B15:Z15)
A16: Esquadrias | B16: =1 | C16: =1 | D16: =1 | E16: =1 | F16: =IF(BRIEFING!$C$6="Econômico",0.55,IF(BRIEFING!$C$6="Standard",0.7,IF(BRIEFING!$C$6="Alto",1.0,IF(BRIEFING!$C$6="Super Alto",1.35,IF(BRIEFING!$C$6="Luxo",1.6,1))))) | G16: =IF(BRIEFING!$C$7="Alumínio anodizado",1.0,IF(BRIEFING!$C$7="Pintura eletrostática",1.15,IF(BRIEFING!$C$7="PVC",0.9,IF(BRIEFING!$C$7="Alto desempenho",1.4,1)))) | H16: =1 | I16: =1 | J16: =1 | K16: =1 | L16: =1 | M16: =1 | N16: =1 | O16: =1 | ... T16: =1 | U16: =IF(BRIEFING!$C$21="Interior SC",0.95,IF(BRIEFING!$C$21="Litoral SC",1.0,IF(BRIEFING!$C$21="Capital Floripa",1.05,IF(BRIEFING!$C$21="Litoral SP",1.15,IF(BRIEFING!$C$21="Capital SP-RJ",1.25,1))))) | V16: =1 | W16: =1 | X16: =1 | Y16: =1 | Z16: =1 | AA16: =PRODUCT(B16:Z16)
A17: Louças e Metais | B17: =1 | C17: =1 | D17: =1 | E17: =1 | F17: =1 | G17: =1 | H17: =1 | I17: =1 | ... T17: =1 | U17: =IF(BRIEFING!$C$21="Interior SC",0.95,IF(BRIEFING!$C$21="Litoral SC",1.0,IF(BRIEFING!$C$21="Capital Floripa",1.05,IF(BRIEFING!$C$21="Litoral SP",1.15,IF(BRIEFING!$C$21="Capital SP-RJ",1.25,1))))) | V17: =1 | W17: =1 | X17: =1 | Y17: =1 | Z17: =1 | AA17: =PRODUCT(B17:Z17)
A18: Fachada | B18: =1 | C18: =1 | D18: =1 | E18: =1 | F18: =IF(BRIEFING!$C$6="Econômico",0.8,IF(BRIEFING!$C$6="Standard",0.85,IF(BRIEFING!$C$6="Alto",1.0,IF(BRIEFING!$C$6="Super Alto",1.25,IF(BRIEFING!$C$6="Luxo",1.5,1))))) | G18: =1 | H18: =1 | I18: =1 | J18: =1 | K18: =IF(BRIEFING!$C$11="Textura + pintura",1.0,IF(BRIEFING!$C$11="Cerâmica/Pastilha",1.4,IF(BRIEFING!$C$11="ACM",1.8,IF(BRIEFING!$C$11="Pele de vidro",2.5,IF(BRIEFING!$C$11="Misto",1.3,1))))) | L18: =IF(BRIEFING!$C$12="Equipe própria",1.0,IF(BRIEFING!$C$12="Empreitada",1.2,1)) | M18: =1 | N18: =1 | O18: =1 | P18: =1 | Q18: =1 | R18: =1 | S18: =1 | T18: =1 | U18: =IF(BRIEFING!$C$21="Interior SC",0.95,IF(BRIEFING!$C$21="Litoral SC",1.0,IF(BRIEFING!$C$21="Capital Floripa",1.05,IF(BRIEFING!$C$21="Litoral SP",1.15,IF(BRIEFING!$C$21="Capital SP-RJ",1.25,1))))) | V18: =1 | W18: =1 | X18: =1 | Y18: =1 | Z18: =1 | AA18: =PRODUCT(B18:Z18)
A19: Complementares | B19: =1 | C19: =1 | D19: =1 | E19: =1 | F19: =IF(BRIEFING!$C$6="Econômico",0.7,IF(BRIEFING!$C$6="Standard",0.85,IF(BRIEFING!$C$6="Alto",1.0,IF(BRIEFING!$C$6="Super Alto",1.2,IF(BRIEFING!$C$6="Luxo",1.5,1))))) | G19: =1 | H19: =1 | I19: =1 | J19: =1 | K19: =1 | L19: =1 | M19: =IF(BRIEFING!$C$13="Não",1.0,IF(BRIEFING!$C$13="Básica",1.1,IF(BRIEFING!$C$13="Completa",1.25,1))) | N19: =1 | O19: =1 | P19: =1 | Q19: =IF(BRIEFING!$C$17="Básico",0.7,IF(BRIEFING!$C$17="Completo",1.0,IF(BRIEFING!$C$17="Premium",1.4,1))) | R19: =IF(BRIEFING!$C$18="Sem",0.85,IF(BRIEFING!$C$18="Básico",1.0,IF(BRIEFING!$C$18="Elaborado",1.2,IF(BRIEFING!$C$18="Premium",1.5,1)))) | S19: =IF(BRIEFING!$C$19="Sem",0.85,IF(BRIEFING!$C$19="Básico",1.0,IF(BRIEFING!$C$19="Completo",1.25,IF(BRIEFING!$C$19="Decorado",1.5,1)))) | T19: =1 | U19: =IF(BRIEFING!$C$21="Interior SC",0.95,IF(BRIEFING!$C$21="Litoral SC",1.0,IF(BRIEFING!$C$21="Capital Floripa",1.05,IF(BRIEFING!$C$21="Litoral SP",1.15,IF(BRIEFING!$C$21="Capital SP-RJ",1.25,1))))) | V19: =1 | W19: =1 | X19: =1 | Y19: =1 | Z19: =1 | AA19: =PRODUCT(B19:Z19)
A20: Imprevistos | B20: =1 | C20: =1 | D20: =1 | E20: =1 | F20: =1 | G20: =1 | H20: =1 | I20: =1 | ... T20: =1 | U20: =IF(BRIEFING!$C$21="Interior SC",0.95,IF(BRIEFING!$C$21="Litoral SC",1.0,IF(BRIEFING!$C$21="Capital Floripa",1.05,IF(BRIEFING!$C$21="Litoral SP",1.15,IF(BRIEFING!$C$21="Capital SP-RJ",1.25,1))))) | V20: =1 | W20: =1 | X20: =1 | Y20: =1 | Z20: =1 | AA20: =PRODUCT(B20:Z20)

Sheet CUSTOS_MACROGRUPO
A1: # | B1: Macrogrupo | C1: Base R$/m² | D1: Fator CUB | E1: Fator Briefing | F1: R$/m² Ajustado | G1: Valor Total | H1: % | I1: Faixa Min | J1: Faixa Max | K1: Status
A2: 1 | B2: Gerenciamento | C2: 408.31 | D2: =DADOS_PROJETO!$B$19/DADOS_PROJETO!$B$20 | E2: =FATORES!$AA$3 | F2: =C2*D2*E2 | G2: =F2*DADOS_PROJETO!$B$6 | H2: =G2/SUM($G$2:$G$19) | I2: 200 | J2: 550 | K2: =IF(AND(F2>=I2,F2<=J2),"✓",IF(OR(F2<I2*0.8,F2>J2*1.2),"✗","⚠"))
A3: 2 | B3: Mov. Terra | C3: 12.4 | D3: =DADOS_PROJETO!$B$19/DADOS_PROJETO!$B$20 | E3: =FATORES!$AA$4 | F3: =C3*D3*E3 | G3: =F3*DADOS_PROJETO!$B$6 | H3: =G3/SUM($G$2:$G$19) | I3: 7 | J3: 60 | K3: =IF(AND(F3>=I3,F3<=J3),"✓",IF(OR(F3<I3*0.8,F3>J3*1.2),"✗","⚠"))
A4: 3 | B4: Infraestrutura | C4: 227.95 | D4: =DADOS_PROJETO!$B$19/DADOS_PROJETO!$B$20 | E4: =FATORES!$AA$5 | F4: =C4*D4*E4 | G4: =F4*DADOS_PROJETO!$B$6 | H4: =G4/SUM($G$2:$G$19) | I4: 120 | J4: 280 | K4: =IF(AND(F4>=I4,F4<=J4),"✓",IF(OR(F4<I4*0.8,F4>J4*1.2),"✗","⚠"))
A5: 4 | B5: Supraestrutura | C5: 726.18 | D5: =DADOS_PROJETO!$B$19/DADOS_PROJETO!$B$20 | E5: =FATORES!$AA$6 | F5: =C5*D5*E5 | G5: =F5*DADOS_PROJETO!$B$6 | H5: =G5/SUM($G$2:$G$19) | I5: 450 | J5: 950 | K5: =IF(AND(F5>=I5,F5<=J5),"✓",IF(OR(F5<I5*0.8,F5>J5*1.2),"✗","⚠"))
A6: 5 | B6: Alvenaria | C6: 147.73 | D6: =DADOS_PROJETO!$B$19/DADOS_PROJETO!$B$20 | E6: =FATORES!$AA$7 | F6: =C6*D6*E6 | G6: =F6*DADOS_PROJETO!$B$6 | H6: =G6/SUM($G$2:$G$19) | I6: 60 | J6: 300 | K6: =IF(AND(F6>=I6,F6<=J6),"✓",IF(OR(F6<I6*0.8,F6>J6*1.2),"✗","⚠"))
A7: 6 | B7: Impermeabilização | C7: 50 | D7: =DADOS_PROJETO!$B$19/DADOS_PROJETO!$B$20 | E7: =FATORES!$AA$8 | F7: =C7*D7*E7 | G7: =F7*DADOS_PROJETO!$B$6 | H7: =G7/SUM($G$2:$G$19) | I7: 36 | J7: 86 | K7: =IF(AND(F7>=I7,F7<=J7),"✓",IF(OR(F7<I7*0.8,F7>J7*1.2),"✗","⚠"))
A8: 7 | B8: Instalações | C8: 365.64 | D8: =DADOS_PROJETO!$B$19/DADOS_PROJETO!$B$20 | E8: =FATORES!$AA$9 | F8: =C8*D8*E8 | G8: =F8*DADOS_PROJETO!$B$6 | H8: =G8/SUM($G$2:$G$19) | I8: 315 | J8: 500 | K8: =IF(AND(F8>=I8,F8<=J8),"✓",IF(OR(F8<I8*0.8,F8>J8*1.2),"✗","⚠"))
A9: 8 | B9: Sist. Especiais | C9: 190.04 | D9: =DADOS_PROJETO!$B$19/DADOS_PROJETO!$B$20 | E9: =FATORES!$AA$10 | F9: =C9*D9*E9 | G9: =F9*DADOS_PROJETO!$B$6 | H9: =G9/SUM($G$2:$G$19) | I9: 100 | J9: 400 | K9: =IF(AND(F9>=I9,F9<=J9),"✓",IF(OR(F9<I9*0.8,F9>J9*1.2),"✗","⚠"))
A10: 9 | B10: Climatização | C10: 0 | D10: =DADOS_PROJETO!$B$19/DADOS_PROJETO!$B$20 | E10: =FATORES!$AA$11 | F10: =C10*D10*E10 | G10: =F10*DADOS_PROJETO!$B$6 | H10: =G10/SUM($G$2:$G$19) | I10: 0 | J10: 80 | K10: =IF(AND(F10>=I10,F10<=J10),"✓",IF(OR(F10<I10*0.8,F10>J10*1.2),"✗","⚠"))
A11: 10 | B11: Rev. Int. Parede | C11: 169.75 | D11: =DADOS_PROJETO!$B$19/DADOS_PROJETO!$B$20 | E11: =FATORES!$AA$12 | F11: =C11*D11*E11 | G11: =F11*DADOS_PROJETO!$B$6 | H11: =G11/SUM($G$2:$G$19) | I11: 100 | J11: 240 | K11: =IF(AND(F11>=I11,F11<=J11),"✓",IF(OR(F11<I11*0.8,F11>J11*1.2),"✗","⚠"))
A12: 11 | B12: Teto | C12: 67.43 | D12: =DADOS_PROJETO!$B$19/DADOS_PROJETO!$B$20 | E12: =FATORES!$AA$13 | F12: =C12*D12*E12 | G12: =F12*DADOS_PROJETO!$B$6 | H12: =G12/SUM($G$2:$G$19) | I12: 45 | J12: 140 | K12: =IF(AND(F12>=I12,F12<=J12),"✓",IF(OR(F12<I12*0.8,F12>J12*1.2),"✗","⚠"))
A13: 12 | B13: Pisos | C13: 189.36 | D13: =DADOS_PROJETO!$B$19/DADOS_PROJETO!$B$20 | E13: =FATORES!$AA$14 | F13: =C13*D13*E13 | G13: =F13*DADOS_PROJETO!$B$6 | H13: =G13/SUM($G$2:$G$19) | I13: 125 | J13: 350 | K13: =IF(AND(F13>=I13,F13<=J13),"✓",IF(OR(F13<I13*0.8,F13>J13*1.2),"✗","⚠"))
A14: 13 | B14: Pintura | C14: 131.49 | D14: =DADOS_PROJETO!$B$19/DADOS_PROJETO!$B$20 | E14: =FATORES!$AA$15 | F14: =C14*D14*E14 | G14: =F14*DADOS_PROJETO!$B$6 | H14: =G14/SUM($G$2:$G$19) | I14: 96 | J14: 200 | K14: =IF(AND(F14>=I14,F14<=J14),"✓",IF(OR(F14<I14*0.8,F14>J14*1.2),"✗","⚠"))
A15: 14 | B15: Esquadrias | C15: 366.05 | D15: =DADOS_PROJETO!$B$19/DADOS_PROJETO!$B$20 | E15: =FATORES!$AA$16 | F15: =C15*D15*E15 | G15: =F15*DADOS_PROJETO!$B$6 | H15: =G15/SUM($G$2:$G$19) | I15: 200 | J15: 700 | K15: =IF(AND(F15>=I15,F15<=J15),"✓",IF(OR(F15<I15*0.8,F15>J15*1.2),"✗","⚠"))
A16: 15 | B16: Louças e Metais | C16: 0 | D16: =DADOS_PROJETO!$B$19/DADOS_PROJETO!$B$20 | E16: =FATORES!$AA$17 | F16: =C16*D16*E16 | G16: =F16*DADOS_PROJETO!$B$6 | H16: =G16/SUM($G$2:$G$19) | I16: 30 | J16: 120 | K16: =IF(AND(F16>=I16,F16<=J16),"✓",IF(OR(F16<I16*0.8,F16>J16*1.2),"✗","⚠"))
A17: 16 | B17: Fachada | C17: 164.53 | D17: =DADOS_PROJETO!$B$19/DADOS_PROJETO!$B$20 | E17: =FATORES!$AA$18 | F17: =C17*D17*E17 | G17: =F17*DADOS_PROJETO!$B$6 | H17: =G17/SUM($G$2:$G$19) | I17: 55 | J17: 275 | K17: =IF(AND(F17>=I17,F17<=J17),"✓",IF(OR(F17<I17*0.8,F17>J17*1.2),"✗","⚠"))
A18: 17 | B18: Complementares | C18: 183.4 | D18: =DADOS_PROJETO!$B$19/DADOS_PROJETO!$B$20 | E18: =FATORES!$AA$19 | F18: =C18*D18*E18 | G18: =F18*DADOS_PROJETO!$B$6 | H18: =G18/SUM($G$2:$G$19) | I18: 100 | J18: 500 | K18: =IF(AND(F18>=I18,F18<=J18),"✓",IF(OR(F18<I18*0.8,F18>J18*1.2),"✗","⚠"))
A19: 18 | B19: Imprevistos | C19: 96.27 | D19: =DADOS_PROJETO!$B$19/DADOS_PROJETO!$B$20 | E19: =FATORES!$AA$20 | F19: =C19*D19*E19 | G19: =F19*DADOS_PROJETO!$B$6 | H19: =G19/SUM($G$2:$G$19) | I19: 35 | J19: 120 | K19: =IF(AND(F19>=I19,F19<=J19),"✓",IF(OR(F19<I19*0.8,F19>J19*1.2),"✗","⚠"))
B20: TOTAL | G20: =SUM(G2:G19) | H20: 100.0%

Sheet ÍNDICES
A1: ÍNDICES DE REFERÊNCIA
A3: A. ÍNDICES ESTRUTURAIS POR TIPO DE LAJE
A4: Parâmetro | B4: Cubetas | C4: Protendida | D4: Maciça | E4: Treliçada
A5: Concreto (m³/m² AC) | B5: 0.22 | C5: 0.2 | D5: 0.25 | E5: 0.19
A6: Aço (kg/m³) | B6: 90 | C6: 110 | D6: 85 | E6: 80
A7: Forma (m²/m³) | B7: 10 | C7: 9 | D7: 11 | E7: 12
A10: B. ÍNDICES DE ACABAMENTOS
A11: Item | B11: Índice (m²/m² AC) | C11: Referência
A12: Chapisco interno | B12: 1.8 | C12: Área de parede interna
A13: Reboco interno | B13: 1.8 | C13: Idem
A14: Estucamento | B14: 1.5 | C14: Área pintável
A15: Cerâmico parede | B15: 0.3 | C15: BWCs + cozinhas
A16: Porcelanato parede | B16: 0.15 | C16: BWCs padrão alto
A17: Contrapiso | B17: 0.85 | C17: Áreas internas
A18: Porcelanato piso | B18: 0.55 | C18: Áreas secas
A19: Cerâmico piso | B19: 0.15 | C19: BWCs + A. serviço
A20: Rodapé | B20: 0.4 | C20: m/m² AC
A21: Forro gesso | B21: 0.7 | C21: Área de teto
A22: Pintura interna | B22: 2.2 | C22: Paredes + teto
A23: Textura externa | B23: 0.45 | C23: Fachada
... A25: Reboco externo | B25: 0.45 | C25: Fachada
A28: C. ÍNDICES DE INSTALAÇÕES
A29: Disciplina | B29: R$/m² típico | C29: % do grupo
A30: Hidrossanitárias | B30: 120 | C30: 0.33
A31: Elétricas | B31: 110 | C31: 0.3
A32: Preventivas | B32: 60 | C32: 0.16
A33: Gás | B33: 35 | C33: 0.1
A34: Telecom | B34: 40 | C34: 0.11
A37: D. VERBAS PARAMÉTRICAS
A38: Item | B38: R$/m² | C38: Observação
A39: Elevadores | B39: 50-80 | C39: Por elevador: R$ 250-400k
A40: Gerador | B40: 15-25 | C40: Prédio alto
A41: Pressurização | B41: 10-18 | C41: Se aplicável
A42: Automação básica | B42: 8-15 | C42: CFTV + interfone

Sheet ESTRUTURAL
A1: DETALHAMENTO ESTRUTURAL — Nível Executivo
A2: Projeto: Residencial Alípio Schirmann — AC: 12,033.95 m²
A4: Item / Serviço | B4: Qtd | C4: Un | D4: Índice | E4: PU Material | F4: PU Mão de Obra | G4: Total Material | H4: Total Mão de Obra | I4: Total
A5: 1. FUNDAÇÕES
A6: Mobilização/desmobilização hélice contínua | B6: 1 | C6: vb | D6: — | E6: =IF(B6>0,G6/B6,0) | F6: =IF(B6>0,H6/B6,0) | G6: =I6*0.2 | H6: =I6*0.80 | I6: =CUSTOS_MACROGRUPO!$G$4*0.65*0.04
A7: Estaca hélice contínua ø40cm — L=14m | B7: =0.22*DADOS_PROJETO!$B$6 | C7: m | D7: 0.22 | E7: =IF(B7>0,G7/B7,0) | F7: =IF(B7>0,H7/B7,0) | G7: =I7*0.55 | H7: =I7*0.45 | I7: =CUSTOS_MACROGRUPO!$G$4*0.65*0.18
A8: Estaca hélice contínua ø50cm — L=16m | B8: =0.3*DADOS_PROJETO!$B$6 | C8: m | D8: 0.3 | E8: =IF(B8>0,G8/B8,0) | F8: =IF(B8>0,H8/B8,0) | G8: =I8*0.55 | H8: =I8*0.45 | I8: =CUSTOS_MACROGRUPO!$G$4*0.65*0.25
A9: Estaca hélice contínua ø60cm — L=18m | B9: =0.12*DADOS_PROJETO!$B$6 | C9: m | D9: 0.12 | E9: =IF(B9>0,G9/B9,0) | F9: =IF(B9>0,H9/B9,0) | G9: =I9*0.55 | H9: =I9*0.45 | I9: =CUSTOS_MACROGRUPO!$G$4*0.65*0.13
A10: Blocos de coroamento (concreto fck 30 MPa) | B10: =0.018*DADOS_PROJETO!$B$6 | C10: m³ | D10: 0.018 | E10: =IF(B10>0,G10/B10,0) | F10: =IF(B10>0,H10/B10,0) | G10: =I10*0.55 | H10: =I10*0.45 | I10: =CUSTOS_MACROGRUPO!$G$4*0.65*0.1
A11: Vigas baldrame (concreto fck 30 MPa) | B11: =0.012*DADOS_PROJETO!$B$6 | C11: m³ | D11: 0.012 | E11: =IF(B11>0,G11/B11,0) | F11: =IF(B11>0,H11/B11,0) | G11: =I11*0.55 | H11: =I11*0.45 | I11: =CUSTOS_MACROGRUPO!$G$4*0.65*0.08
A12: Armação blocos e baldrame (CA-50) | B12: =1.8*DADOS_PROJETO!$B$6 | C12: kg | D12: 1.8 | E12: =IF(B12>0,G12/B12,0) | F12: =IF(B12>0,H12/B12,0) | G12: =I12*0.7 | H12: =I12*0.30 | I12: =CUSTOS_MACROGRUPO!$G$4*0.65*0.08
A13: Forma blocos e baldrame (compensado) | B13: =0.12*DADOS_PROJETO!$B$6 | C13: m² | D13: 0.12 | E13: =IF(B13>0,G13/B13,0) | F13: =IF(B13>0,H13/B13,0) | G13: =I13*0.6 | H13: =I13*0.40 | I13: =CUSTOS_MACROGRUPO!$G$4*0.65*0.05
A14: Impermeabilização fundação | B14: =0.08*DADOS_PROJETO!$B$6 | C14: m² | D14: 0.08 | E14: =IF(B14>0,G14/B14,0) | F14: =IF(B14>0,H14/B14,0) | G14: =I14*0.65 | H14: =I14*0.35 | I14: =CUSTOS_MACROGRUPO!$G$4*0.65*0.03
A15: Escavação mecânica | B15: =0.05*DADOS_PROJETO!$B$6 | C15: m³ | D15: 0.05 | E15: =IF(B15>0,G15/B15,0) | F15: =IF(B15>0,H15/B15,0) | G15: =I15*0.3 | H15: =I15*0.70 | I15: =CUSTOS_MACROGRUPO!$G$4*0.65*0.03
A16: Reaterro compactado | B16: =0.03*DADOS_PROJETO!$B$6 | C16: m³ | D16: 0.03 | E16: =IF(B16>0,G16/B16,0) | F16: =IF(B16>0,H16/B16,0) | G16: =I16*0.4 | H16: =I16*0.60 | I16: =CUSTOS_MACROGRUPO!$G$4*0.65*0.02
A17: Lastro de brita e=5cm | B17: =0.005*DADOS_PROJETO!$B$6 | C17: m³ | D17: 0.005 | E17: =IF(B17>0,G17/B17,0) | F17: =IF(B17>0,H17/B17,0) | G17: =I17*0.8 | H17: =I17*0.20 | I17: =CUSTOS_MACROGRUPO!$G$4*0.65*0.01
A18: Subtotal 1. FUNDAÇÕES | G18: =SUM(G6:G17) | H18: =SUM(H6:H17) | I18: =SUM(I6:I17)
A20: 2. CONTENÇÕES
A21: Cortina de estacas / Perfil metálico | B21: =0.03*DADOS_PROJETO!$B$6 | C21: m² | D21: 0.03 | E21: =IF(B21>0,G21/B21,0) | F21: =IF(B21>0,H21/B21,0) | G21: =I21*0.6 | H21: =I21*0.40 | I21: =CUSTOS_MACROGRUPO!$G$4*0.35*0.35
A22: Tirantes protendidos | B22: =12 | C22: un | D22: 12 | E22: =IF(B22>0,G22/B22,0) | F22: =IF(B22>0,H22/B22,0) | G22: =I22*0.55 | H22: =I22*0.45 | I22: =CUSTOS_MACROGRUPO!$G$4*0.35*0.25
A23: Muro de arrimo concreto armado | B23: =0.008*DADOS_PROJETO!$B$6 | C23: m³ | D23: 0.008 | E23: =IF(B23>0,G23/B23,0) | F23: =IF(B23>0,H23/B23,0) | G23: =I23*0.55 | H23: =I23*0.45 | I23: =CUSTOS_MACROGRUPO!$G$4*0.35*0.15
A24: Drenagem subsuperficial (dreno) | B24: =0.02*DADOS_PROJETO!$B$6 | C24: m | D24: 0.02 | E24: =IF(B24>0,G24/B24,0) | F24: =IF(B24>0,H24/B24,0) | G24: =I24*0.65 | H24: =I24*0.35 | I24: =CUSTOS_MACROGRUPO!$G$4*0.35*0.08
A25: Chumbadores / grampos | B25: =20 | C25: un | D25: 20 | E25: =IF(B25>0,G25/B25,0) | F25: =IF(B25>0,H25/B25,0) | G25: =I25*0.6 | H25: =I25*0.40 | I25: =CUSTOS_MACROGRUPO!$G$4*0.35*0.07
A26: Concreto projetado (se aplicável) | B26: =0.005*DADOS_PROJETO!$B$6 | C26: m² | D26: 0.005 | E26: =IF(B26>0,G26/B26,0) | F26: =IF(B26>0,H26/B26,0) | G26: =I26*0.5 | H26: =I26*0.50 | I26: =CUSTOS_MACROGRUPO!$G$4*0.35*0.05
A27: Monitoramento geotécnico (inclinômetros) | B27: 1 | C27: vb | D27: — | E27: =IF(B27>0,G27/B27,0) | F27: =IF(B27>0,H27/B27,0) | G27: =I27*0.15 | H27: =I27*0.85 | I27: =CUSTOS_MACROGRUPO!$G$4*0.35*0.05
A28: Subtotal 2. CONTENÇÕES | G28: =SUM(G21:G27) | H28: =SUM(H21:H27) | I28: =SUM(I21:I27)
A30: 3. SUPRAESTRUTURA — CONCRETO
A31: Concreto fck 35 MPa — Pilares | B31: =0.047*DADOS_PROJETO!$B$6 | C31: m³ | D31: 0.047 | E31: =IF(B31>0,G31/B31,0) | F31: =IF(B31>0,H31/B31,0) | G31: =I31*0.6 | H31: =I31*0.40 | I31: =CUSTOS_MACROGRUPO!$G$5*0.42*0.24
A32: Concreto fck 30 MPa — Vigas | B32: =0.056*DADOS_PROJETO!$B$6 | C32: m³ | D32: 0.056 | E32: =IF(B32>0,G32/B32,0) | F32: =IF(B32>0,H32/B32,0) | G32: =I32*0.6 | H32: =I32*0.40 | I32: =CUSTOS_MACROGRUPO!$G$5*0.42*0.28
A33: Concreto fck 30 MPa — Lajes nervuradas (cubetas) | B33: =0.065*DADOS_PROJETO!$B$6 | C33: m³ | D33: 0.065 | E33: =IF(B33>0,G33/B33,0) | F33: =IF(B33>0,H33/B33,0) | G33: =I33*0.6 | H33: =I33*0.40 | I33: =CUSTOS_MACROGRUPO!$G$5*0.42*0.3
A34: Concreto fck 25 MPa — Escadas | B34: =0.008*DADOS_PROJETO!$B$6 | C34: m³ | D34: 0.008 | E34: =IF(B34>0,G34/B34,0) | F34: =IF(B34>0,H34/B34,0) | G34: =I34*0.55 | H34: =I34*0.45 | I34: =CUSTOS_MACROGRUPO!$G$5*0.42*0.05
A35: Concreto fck 30 MPa — Reservatórios | B35: =0.004*DADOS_PROJETO!$B$6 | C35: m³ | D35: 0.004 | E35: =IF(B35>0,G35/B35,0) | F35: =IF(B35>0,H35/B35,0) | G35: =I35*0.55 | H35: =I35*0.45 | I35: =CUSTOS_MACROGRUPO!$G$5*0.42*0.04
A36: Concreto fck 25 MPa — Muros/Muretas | B36: =0.003*DADOS_PROJETO!$B$6 | C36: m³ | D36: 0.003 | E36: =IF(B36>0,G36/B36,0) | F36: =IF(B36>0,H36/B36,0) | G36: =I36*0.55 | H36: =I36*0.45 | I36: =CUSTOS_MACROGRUPO!$G$5*0.42*0.02
A37: Bombeamento concreto | B37: =0.189*DADOS_PROJETO!$B$6 | C37: m³ | D37: 0.189 | E37: =IF(B37>0,G37/B37,0) | F37: =IF(B37>0,H37/B37,0) | G37: =I37*0.15 | H37: =I37*0.85 | I37: =CUSTOS_MACROGRUPO!$G$5*0.42*0.04
A38: Lançamento e adensamento | B38: =0.189*DADOS_PROJETO!$B$6 | C38: m³ | D38: 0.189 | E38: =IF(B38>0,G38/B38,0) | F38: =IF(B38>0,H38/B38,0) | G38: =I38*0.1 | H38: =I38*0.90 | I38: =CUSTOS_MACROGRUPO!$G$5*0.42*0.03
A39: Subtotal 3. SUPRAESTRUTURA — CONCRETO | G39: =SUM(G31:G38) | H39: =SUM(H31:H38) | I39: =SUM(I31:I38)
A41: 4. SUPRAESTRUTURA — AÇO
A42: Aço CA-50 — Pilares (taxa ~95 kg/m³) | B42: =4.47*DADOS_PROJETO!$B$6 | C42: kg | D42: 4.47 | E42: =IF(B42>0,G42/B42,0) | F42: =IF(B42>0,H42/B42,0) | G42: =I42*0.72 | H42: =I42*0.28 | I42: =CUSTOS_MACROGRUPO!$G$5*0.28*0.28
A43: Aço CA-50 — Vigas (taxa ~90 kg/m³) | B43: =5.04*DADOS_PROJETO!$B$6 | C43: kg | D43: 5.04 | E43: =IF(B43>0,G43/B43,0) | F43: =IF(B43>0,H43/B43,0) | G43: =I43*0.72 | H43: =I43*0.28 | I43: =CUSTOS_MACROGRUPO!$G$5*0.28*0.3
A44: Aço CA-50 — Lajes (taxa ~88 kg/m³) | B44: =5.72*DADOS_PROJETO!$B$6 | C44: kg | D44: 5.72 | E44: =IF(B44>0,G44/B44,0) | F44: =IF(B44>0,H44/B44,0) | G44: =I44*0.72 | H44: =I44*0.28 | I44: =CUSTOS_MACROGRUPO!$G$5*0.28*0.27
...

Sheet INSTALACOES
A1: DETALHAMENTO INSTALAÇÕES — Nível Executivo
A2: Projeto: Residencial Alípio Schirmann — AC: 12,033.95 m²
A4: Item / Serviço | B4: Qtd | C4: Un | D4: Índice | E4: PU Material | F4: PU Mão de Obra | G4: Total Material | H4: Total Mão de Obra | I4: Total
A5: 1. INSTALAÇÕES HIDRÁULICAS
A6: Tubulação água fria PVC soldável (ø20 a ø60) | B6: =2.0*DADOS_PROJETO!$B$6 | C6: m | D6: 2 | E6: =IF(B6>0,G6/B6,0) | F6: =IF(B6>0,H6/B6,0) | G6: =I6*0.5 | H6: =I6*0.50 | I6: =CUSTOS_MACROGRUPO!$G$8*0.33*0.12
A7: Tubulação água quente PPR (ø20 a ø32) | B7: =0.8*DADOS_PROJETO!$B$6 | C7: m | D7: 0.8 | E7: =IF(B7>0,G7/B7,0) | F7: =IF(B7>0,H7/B7,0) | G7: =I7*0.55 | H7: =I7*0.45 | I7: =CUSTOS_MACROGRUPO!$G$8*0.33*0.08
A8: Tubulação esgoto PVC (ø40 a ø150) | B8: =1.5*DADOS_PROJETO!$B$6 | C8: m | D8: 1.5 | E8: =IF(B8>0,G8/B8,0) | F8: =IF(B8>0,H8/B8,0) | G8: =I8*0.5 | H8: =I8*0.50 | I8: =CUSTOS_MACROGRUPO!$G$8*0.33*0.1
A9: Tubulação águas pluviais PVC (ø75 a ø150) | B9: =0.5*DADOS_PROJETO!$B$6 | C9: m | D9: 0.5 | E9: =IF(B9>0,G9/B9,0) | F9: =IF(B9>0,H9/B9,0) | G9: =I9*0.5 | H9: =I9*0.50 | I9: =CUSTOS_MACROGRUPO!$G$8*0.33*0.05
A10: Registros e válvulas (gaveta, pressão, esfera) | B10: =280 | C10: un | D10: 280 | E10: =IF(B10>0,G10/B10,0) | F10: =IF(B10>0,H10/B10,0) | G10: =I10*0.65 | H10: =I10*0.35 | I10: =CUSTOS_MACROGRUPO!$G$8*0.33*0.06
A11: Caixas sifonadas e ralos | B11: =240 | C11: un | D11: 240 | E11: =IF(B11>0,G11/B11,0) | F11: =IF(B11>0,H11/B11,0) | G11: =I11*0.6 | H11: =I11*0.40 | I11: =CUSTOS_MACROGRUPO!$G$8*0.33*0.04
A12: Caixas de inspeção / gordura | B12: =30 | C12: un | D12: 30 | E12: =IF(B12>0,G12/B12,0) | F12: =IF(B12>0,H12/B12,0) | G12: =I12*0.55 | H12: =I12*0.45 | I12: =CUSTOS_MACROGRUPO!$G$8*0.33*0.03
A13: Reservatório superior (fibra/concreto) | B13: =2 | C13: un | D13: 2 | E13: =IF(B13>0,G13/B13,0) | F13: =IF(B13>0,H13/B13,0) | G13: =I13*0.7 | H13: =I13*0.30 | I13: =CUSTOS_MACROGRUPO!$G$8*0.33*0.06
A14: Reservatório inferior | B14: =1 | C14: un | D14: 1 | E14: =IF(B14>0,G14/B14,0) | F14: =IF(B14>0,H14/B14,0) | G14: =I14*0.7 | H14: =I14*0.30 | I14: =CUSTOS_MACROGRUPO!$G$8*0.33*0.05
A15: Bombas de recalque (conjunto) | B15: =2 | C15: cj | D15: 2 | E15: =IF(B15>0,G15/B15,0) | F15: =IF(B15>0,H15/B15,0) | G15: =I15*0.75 | H15: =I15*0.25 | I15: =CUSTOS_MACROGRUPO!$G$8*0.33*0.06
A16: Medição individualizada (hidrômetros) | B16: =43 | C16: un | D16: 43 | E16: =IF(B16>0,G16/B16,0) | F16: =IF(B16>0,H16/B16,0) | G16: =I16*0.7 | H16: =I16*0.30 | I16: =CUSTOS_MACROGRUPO!$G$8*0.33*0.08
A17: Aquecedores de passagem (infraestrutura) | B17: =43 | C17: un | D17: 43 | E17: =IF(B17>0,G17/B17,0) | F17: =IF(B17>0,H17/B17,0) | G17: =I17*0.6 | H17: =I17*0.40 | I17: =CUSTOS_MACROGRUPO!$G$8*0.33*0.05
A18: Conexões, abraçadeiras e suportes | B18: 1 | C18: vb | D18: — | E18: =IF(B18>0,G18/B18,0) | F18: =IF(B18>0,H18/B18,0) | G18: =I18*0.75 | H18: =I18*0.25 | I18: =CUSTOS_MACROGRUPO!$G$8*0.33*0.08
A19: Louças sanitárias — Bacias c/ caixa acoplada | B19: =86 | C19: un | D19: 86 | E19: =IF(B19>0,G19/B19,0) | F19: =IF(B19>0,H19/B19,0) | G19: =I19*0.85 | H19: =I19*0.15 | I19: =CUSTOS_MACROGRUPO!$G$8*0.33*0.06
A20: Louças — Lavatórios e cubas | B20: =86 | C20: un | D20: 86 | E20: =IF(B20>0,G20/B20,0) | F20: =IF(B20>0,H20/B20,0) | G20: =I20*0.85 | H20: =I20*0.15 | I20: =CUSTOS_MACROGRUPO!$G$8*0.33*0.04
A21: Metais — Torneiras e misturadores | B21: =172 | C21: un | D21: 172 | E21: =IF(B21>0,G21/B21,0) | F21: =IF(B21>0,H21/B21,0) | G21: =I21*0.9 | H21: =I21*0.10 | I21: =CUSTOS_MACROGRUPO!$G$8*0.33*0.04
A22: Subtotal 1. INSTALAÇÕES HIDRÁULICAS | G22: =SUM(G6:G21) | H22: =SUM(H6:H21) | I22: =SUM(I6:I21)
A24: 2. INSTALAÇÕES ELÉTRICAS
A25: Quadros de distribuição (QDC apartamentos) | B25: =43 | C25: un | D25: 43 | E25: =IF(B25>0,G25/B25,0) | F25: =IF(B25>0,H25/B25,0) | G25: =I25*0.65 | H25: =I25*0.35 | I25: =CUSTOS_MACROGRUPO!$G$8*0.3*0.06
A26: Quadro geral de baixa tensão (QGBT) | B26: =1 | C26: un | D26: 1 | E26: =IF(B26>0,G26/B26,0) | F26: =IF(B26>0,H26/B26,0) | G26: =I26*0.7 | H26: =I26*0.30 | I26: =CUSTOS_MACROGRUPO!$G$8*0.3*0.04
A27: Fiação e cabos (ø1.5 a ø16mm²) | B27: =12.0*DADOS_PROJETO!$B$6 | C27: m | D27: 12 | E27: =IF(B27>0,G27/B27,0) | F27: =IF(B27>0,H27/B27,0) | G27: =I27*0.55 | H27: =I27*0.45 | I27: =CUSTOS_MACROGRUPO!$G$8*0.3*0.14
A28: Eletrodutos corrugados + rígidos | B28: =8.0*DADOS_PROJETO!$B$6 | C28: m | D28: 8 | E28: =IF(B28>0,G28/B28,0) | F28: =IF(B28>0,H28/B28,0) | G28: =I28*0.5 | H28: =I28*0.50 | I28: =CUSTOS_MACROGRUPO!$G$8*0.3*0.1
A29: Tomadas 2P+T (10A e 20A) | B29: =800 | C29: un | D29: 800 | E29: =IF(B29>0,G29/B29,0) | F29: =IF(B29>0,H29/B29,0) | G29: =I29*0.6 | H29: =I29*0.40 | I29: =CUSTOS_MACROGRUPO!$G$8*0.3*0.08
A30: Interruptores (simples, paralelo, intermediário) | B30: =400 | C30: un | D30: 400 | E30: =IF(B30>0,G30/B30,0) | F30: =IF(B30>0,H30/B30,0) | G30: =I30*0.6 | H30: =I30*0.40 | I30: =CUSTOS_MACROGRUPO!$G$8*0.3*0.05
A31: Luminárias áreas comuns (LED) | B31: =180 | C31: un | D31: 180 | E31: =IF(B31>0,G31/B31,0) | F31: =IF(B31>0,H31/B31,0) | G31: =I31*0.75 | H31: =I31*0.25 | I31: =CUSTOS_MACROGRUPO!$G$8*0.3*0.06
A32: Subestação / entrada de energia | B32: 1 | C32: vb | D32: — | E32: =IF(B32>0,G32/B32,0) | F32: =IF(B32>0,H32/B32,0) | G32: =I32*0.7 | H32: =I32*0.30 | I32: =CUSTOS_MACROGRUPO!$G$8*0.3*0.08
A33: SPDA (para-raios) | B33: 1 | C33: vb | D33: — | E33: =IF(B33>0,G33/B33,0) | F33: =IF(B33>0,H33/B33,0) | G33: =I33*0.55 | H33: =I33*0.45 | I33: =CUSTOS_MACROGRUPO!$G$8*0.3*0.05
A34: Medição individualizada (energia) | B34: =43 | C34: un | D34: 43 | E34: =IF(B34>0,G34/B34,0) | F34: =IF(B34>0,H34/B34,0) | G34: =I34*0.7 | H34: =I34*0.30 | I34: =CUSTOS_MACROGRUPO!$G$8*0.3*0.07
A35: Caixas de passagem e derivação | B35: =350 | C35: un | D35: 350 | E35: =IF(B35>0,G35/B35,0) | F35: =IF(B35>0,H35/B35,0) | G35: =I35*0.55 | H35: =I35*0.45 | I35: =CUSTOS_MACROGRUPO!$G$8*0.3*0.04
A36: Disjuntores e DRs | B36: =250 | C36: un | D36: 250 | E36: =IF(B36>0,G36/B36,0) | F36: =IF(B36>0,H36/B36,0) | G36: =I36*0.8 | H36: =I36*0.20 | I36: =CUSTOS_MACROGRUPO!$G$8*0.3*0.05
A37: Aterramento e equalização | B37: 1 | C37: vb | D37: — | E37: =IF(B37>0,G37/B37,0) | F37: =IF(B37>0,H37/B37,0) | G37: =I37*0.55 | H37: =I37*0.45 | I37: =CUSTOS_MACROGRUPO!$G$8*0.3*0.04
A38: Infraestrutura para ar-condicionado | B38: =86 | C38: pt | D38: 86 | E38: =IF(B38>0,G38/B38,0) | F38: =IF(B38>0,H38/B38,0) | G38: =I38*0.5 | H38: =I38*0.50 | I38: =CUSTOS_MACROGRUPO!$G$8*0.3*0.06
A39: Prumadas elétricas (shafts) | B39: 1 | C39: vb | D39: — | E39: =IF(B39>0,G39/B39,0) | F39: =IF(B39>0,H39/B39,0) | G39: =I39*0.45 | H39: =I39*0.55 | I39: =CUSTOS_MACROGRUPO!$G$8*0.3*0.04
A40: Iluminação de emergência | B40: =60 | C40: un | D40: 60 | E40: =IF(B40>0,G40/B40,0) | F40: =IF(B40>0,H40/B40,0) | G40: =I40*0.7 | H40: =I40*0.30 | I40: =CUSTOS_MACROGRUPO!$G$8*0.3*0.04
A41: Subtotal 2. INSTALAÇÕES ELÉTRICAS | G41: =SUM(G25:G40) | H41: =SUM(H25:H40) | I41: =SUM(I25:I40)
A43: 3. PREVENÇÃO CONTRA INCÊNDIO
...

Sheet ACABAMENTOS
A1: DETALHAMENTO ACABAMENTOS — Nível Executivo
A2: Projeto: Residencial Alípio Schirmann — AC: 12,033.95 m²
A4: Item / Serviço | B4: Qtd | C4: Un | D4: Índice | E4: PU Material | F4: PU Mão de Obra | G4: Total Material | H4: Total Mão de Obra | I4: Total
A5: 1. REVESTIMENTO INTERNO DE PAREDE
A6: Chapisco rolado (interno) | B6: =1.4*DADOS_PROJETO!$B$6 | C6: m² | D6: 1.4 | E6: =IF(B6>0,G6/B6,0) | F6: =IF(B6>0,H6/B6,0) | G6: =I6*0.4 | H6: =I6*0.60 | I6: =CUSTOS_MACROGRUPO!$G$11*1.0*0.06
A7: Emboço / massa única (espessura média 2cm) | B7: =1.4*DADOS_PROJETO!$B$6 | C7: m² | D7: 1.4 | E7: =IF(B7>0,G7/B7,0) | F7: =IF(B7>0,H7/B7,0) | G7: =I7*0.48 | H7: =I7*0.52 | I7: =CUSTOS_MACROGRUPO!$G$11*1.0*0.18
A8: Reboco fino (espessura 5mm) | B8: =0.8*DADOS_PROJETO!$B$6 | C8: m² | D8: 0.8 | E8: =IF(B8>0,G8/B8,0) | F8: =IF(B8>0,H8/B8,0) | G8: =I8*0.45 | H8: =I8*0.55 | I8: =CUSTOS_MACROGRUPO!$G$11*1.0*0.08
A9: Cerâmica parede — Banheiros (piso ao teto) | B9: =0.25*DADOS_PROJETO!$B$6 | C9: m² | D9: 0.25 | E9: =IF(B9>0,G9/B9,0) | F9: =IF(B9>0,H9/B9,0) | G9: =I9*0.52 | H9: =I9*0.48 | I9: =CUSTOS_MACROGRUPO!$G$11*1.0*0.12
A10: Cerâmica parede — Cozinha (meia-parede) | B10: =0.1*DADOS_PROJETO!$B$6 | C10: m² | D10: 0.1 | E10: =IF(B10>0,G10/B10,0) | F10: =IF(B10>0,H10/B10,0) | G10: =I10*0.52 | H10: =I10*0.48 | I10: =CUSTOS_MACROGRUPO!$G$11*1.0*0.06
A11: Cerâmica parede — Área de serviço | B11: =0.06*DADOS_PROJETO!$B$6 | C11: m² | D11: 0.06 | E11: =IF(B11>0,G11/B11,0) | F11: =IF(B11>0,H11/B11,0) | G11: =I11*0.52 | H11: =I11*0.48 | I11: =CUSTOS_MACROGRUPO!$G$11*1.0*0.04
A12: Porcelanato parede — Lavabos/banheiro suíte | B12: =0.08*DADOS_PROJETO!$B$6 | C12: m² | D12: 0.08 | E12: =IF(B12>0,G12/B12,0) | F12: =IF(B12>0,H12/B12,0) | G12: =I12*0.55 | H12: =I12*0.45 | I12: =CUSTOS_MACROGRUPO!$G$11*1.0*0.06
A13: Massa corrida PVA (paredes lisas) | B13: =0.9*DADOS_PROJETO!$B$6 | C13: m² | D13: 0.9 | E13: =IF(B13>0,G13/B13,0) | F13: =IF(B13>0,H13/B13,0) | G13: =I13*0.42 | H13: =I13*0.58 | I13: =CUSTOS_MACROGRUPO!$G$11*1.0*0.1
A14: Revestimento hall/circulação (porcelanato/pastilha) | B14: =0.05*DADOS_PROJETO!$B$6 | C14: m² | D14: 0.05 | E14: =IF(B14>0,G14/B14,0) | F14: =IF(B14>0,H14/B14,0) | G14: =I14*0.55 | H14: =I14*0.45 | I14: =CUSTOS_MACROGRUPO!$G$11*1.0*0.04
A15: Revestimento áreas comuns (lobby, salão festas) | B15: =0.04*DADOS_PROJETO!$B$6 | C15: m² | D15: 0.04 | E15: =IF(B15>0,G15/B15,0) | F15: =IF(B15>0,H15/B15,0) | G15: =I15*0.55 | H15: =I15*0.45 | I15: =CUSTOS_MACROGRUPO!$G$11*1.0*0.04
A16: Rejunte cerâmicas/porcelanatos | B16: =0.49*DADOS_PROJETO!$B$6 | C16: m² | D16: 0.49 | E16: =IF(B16>0,G16/B16,0) | F16: =IF(B16>0,H16/B16,0) | G16: =I16*0.65 | H16: =I16*0.35 | I16: =CUSTOS_MACROGRUPO!$G$11*1.0*0.04
A17: Cantoneiras e perfis de acabamento | B17: =0.15*DADOS_PROJETO!$B$6 | C17: m | D17: 0.15 | E17: =IF(B17>0,G17/B17,0) | F17: =IF(B17>0,H17/B17,0) | G17: =I17*0.7 | H17: =I17*0.30 | I17: =CUSTOS_MACROGRUPO!$G$11*1.0*0.02
A18: Argamassa colante ACIII (áreas molhadas) | B18: =0.49*DADOS_PROJETO!$B$6 | C18: m² | D18: 0.49 | E18: =IF(B18>0,G18/B18,0) | F18: =IF(B18>0,H18/B18,0) | G18: =I18*0.7 | H18: =I18*0.30 | I18: =CUSTOS_MACROGRUPO!$G$11*1.0*0.05
A19: Argamassa colante ACII (áreas secas) | B19: =0.3*DADOS_PROJETO!$B$6 | C19: m² | D19: 0.3 | E19: =IF(B19>0,G19/B19,0) | F19: =IF(B19>0,H19/B19,0) | G19: =I19*0.7 | H19: =I19*0.30 | I19: =CUSTOS_MACROGRUPO!$G$11*1.0*0.04
A20: Filete/rodameio decorativo | B20: =0.05*DADOS_PROJETO!$B$6 | C20: m | D20: 0.05 | E20: =IF(B20>0,G20/B20,0) | F20: =IF(B20>0,H20/B20,0) | G20: =I20*0.65 | H20: =I20*0.35 | I20: =CUSTOS_MACROGRUPO!$G$11*1.0*0.02
A21: Nicho banheiro (porcelanato) | B21: =86 | C21: un | D21: 86 | E21: =IF(B21>0,G21/B21,0) | F21: =IF(B21>0,H21/B21,0) | G21: =I21*0.55 | H21: =I21*0.45 | I21: =CUSTOS_MACROGRUPO!$G$11*1.0*0.03
A22: Tratamento de juntas (estruturais/dilatação) | B22: =0.02*DADOS_PROJETO!$B$6 | C22: m | D22: 0.02 | E22: =IF(B22>0,G22/B22,0) | F22: =IF(B22>0,H22/B22,0) | G22: =I22*0.5 | H22: =I22*0.50 | I22: =CUSTOS_MACROGRUPO!$G$11*1.0*0.02
A23: Subtotal 1. REVESTIMENTO INTERNO DE PAREDE | G23: =SUM(G6:G22) | H23: =SUM(H6:H22) | I23: =SUM(I6:I22)
A25: 2. TETO / FORRO
A26: Gesso liso — Apartamentos (teto, sancas) | B26: =0.65*DADOS_PROJETO!$B$6 | C26: m² | D26: 0.65 | E26: =IF(B26>0,G26/B26,0) | F26: =IF(B26>0,H26/B26,0) | G26: =I26*0.42 | H26: =I26*0.58 | I26: =CUSTOS_MACROGRUPO!$G$12*1.0*0.32
A27: Forro gesso acartonado — Áreas comuns | B27: =0.08*DADOS_PROJETO!$B$6 | C27: m² | D27: 0.08 | E27: =IF(B27>0,G27/B27,0) | F27: =IF(B27>0,H27/B27,0) | G27: =I27*0.48 | H27: =I27*0.52 | I27: =CUSTOS_MACROGRUPO!$G$12*1.0*0.1
A28: Forro gesso acartonado — Banheiros (resistente umidade) | B28: =0.06*DADOS_PROJETO!$B$6 | C28: m² | D28: 0.06 | E28: =IF(B28>0,G28/B28,0) | F28: =IF(B28>0,H28/B28,0) | G28: =I28*0.48 | H28: =I28*0.52 | I28: =CUSTOS_MACROGRUPO!$G$12*1.0*0.08
A29: Sanca/moldura gesso — Perímetro ambientes | B29: =0.3*DADOS_PROJETO!$B$6 | C29: m | D29: 0.3 | E29: =IF(B29>0,G29/B29,0) | F29: =IF(B29>0,H29/B29,0) | G29: =I29*0.4 | H29: =I29*0.60 | I29: =CUSTOS_MACROGRUPO!$G$12*1.0*0.1
A30: Forro PVC — Áreas técnicas/garagem | B30: =0.05*DADOS_PROJETO!$B$6 | C30: m² | D30: 0.05 | E30: =IF(B30>0,G30/B30,0) | F30: =IF(B30>0,H30/B30,0) | G30: =I30*0.55 | H30: =I30*0.45 | I30: =CUSTOS_MACROGRUPO!$G$12*1.0*0.05
A31: Tabica em gesso | B31: =0.2*DADOS_PROJETO!$B$6 | C31: m | D31: 0.2 | E31: =IF(B31>0,G31/B31,0) | F31: =IF(B31>0,H31/B31,0) | G31: =I31*0.38 | H31: =I31*0.62 | I31: =CUSTOS_MACROGRUPO!$G$12*1.0*0.06
A32: Rebaixo para iluminação (spots embutidos) | B32: =0.04*DADOS_PROJETO!$B$6 | C32: m² | D32: 0.04 | E32: =IF(B32>0,G32/B32,0) | F32: =IF(B32>0,H32/B32,0) | G32: =I32*0.45 | H32: =I32*0.55 | I32: =CUSTOS_MACROGRUPO!$G$12*1.0*0.05
A33: Forro mineral/metálico — Hall elevadores | B33: =0.02*DADOS_PROJETO!$B$6 | C33: m² | D33: 0.02 | E33: =IF(B33>0,G33/B33,0) | F33: =IF(B33>0,H33/B33,0) | G33: =I33*0.55 | H33: =I33*0.45 | I33: =CUSTOS_MACROGRUPO!$G$12*1.0*0.04
A34: Pintura de teto (1ª demão — incluída aqui) | B34: =0.7*DADOS_PROJETO!$B$6 | C34: m² | D34: 0.7 | E34: =IF(B34>0,G34/B34,0) | F34: =IF(B34>0,H34/B34,0) | G34: =I34*0.4 | H34: =I34*0.60 | I34: =CUSTOS_MACROGRUPO!$G$12*1.0*0.08
A35: Tratamento de trincas em teto (tela + massa) | B35: =0.1*DADOS_PROJETO!$B$6 | C35: m² | D35: 0.1 | E35: =IF(B35>0,G35/B35,0) | F35: =IF(B35>0,H35/B35,0) | G35: =I35*0.45 | H35: =I35*0.55 | I35: =CUSTOS_MACROGRUPO!$G$12*1.0*0.04
A36: Cortineiro em gesso | B36: =0.08*DADOS_PROJETO!$B$6 | C36: m | D36: 0.08 | E36: =IF(B36>0,G36/B36,0) | F36: =IF(B36>0,H36/B36,0) | G36: =I36*0.4 | H36: =I36*0.60 | I36: =CUSTOS_MACROGRUPO!$G$12*1.0*0.04
A37: Acabamento shaft/alçapão | B37: =43 | C37: un | D37: 43 | E37: =IF(B37>0,G37/B37,0) | F37: =IF(B37>0,H37/B37,0) | G37: =I37*0.5 | H37: =I37*0.50 | I37: =CUSTOS_MACROGRUPO!$G$12*1.0*0.04
A38: Subtotal 2. TETO / FORRO | G38: =SUM(G26:G37) | H38: =SUM(H26:H37) | I38: =SUM(I26:I37)
A40: 3. PISOS
A41: Contrapiso (argamassa e=4cm) | B41: =0.7*DADOS_PROJETO!$B$6 | C41: m² | D41: 0.7 | E41: =IF(B41>0,G41/B41,0) | F41: =IF(B41>0,H41/B41,0) | G41: =I41*0.48 | H41: =I41*0.52 | I41: =CUSTOS_MACROGRUPO!$G$13*1.0*0.12
A42: Porcelanato retificado — Salas/quartos (60×60 ou 80×80) | B42: =0.35*DADOS_PROJETO!$B$6 | C42: m² | D42: 0.35 | E42: =IF(B42>0,G42/B42,0) | F42: =IF(B42>0,H42/B42,0) | G42: =I42*0.55 | H42: =I42*0.45 | I42: =CUSTOS_MACROGRUPO!$G$13*1.0*0.16
A43: Porcelanato retificado — Áreas molhadas (antiderrapante) | B43: =0.12*DADOS_PROJETO!$B$6 | C43: m² | D43: 0.12 | E43: =IF(B43>0,G43/B43,0) | F43: =IF(B43>0,H43/B43,0) | G43: =I43*0.55 | H43: =I43*0.45 | I43: =CUSTOS_MACROGRUPO!$G$13*1.0*0.06
...

Sheet CI_DETALHADO
A1: CUSTOS INDIRETOS — Detalhamento Executivo
A2: Projeto: Residencial Alípio Schirmann — AC: 12,033.95 m²
A4: Item / Serviço | B4: Qtd | C4: Un | D4: Índice | E4: Preço Unitário | F4: Total | G4: R$/m² AC
A5: 1. PROJETOS E CONSULTORIAS
A6: Projeto Arquitetônico (legal + executivo) | B6: 1 | C6: vb | D6: — | E6: =IF(B6>0,F6/B6,0) | F6: =CUSTOS_MACROGRUPO!$G$2*0.22*0.15 | G6: =F6/DADOS_PROJETO!$B$6
A7: Projeto Estrutural | B7: 1 | C7: vb | D7: — | E7: =IF(B7>0,F7/B7,0) | F7: =CUSTOS_MACROGRUPO!$G$2*0.22*0.14 | G7: =F7/DADOS_PROJETO!$B$6
A8: Projeto Hidrossanitário | B8: 1 | C8: vb | D8: — | E8: =IF(B8>0,F8/B8,0) | F8: =CUSTOS_MACROGRUPO!$G$2*0.22*0.08 | G8: =F8/DADOS_PROJETO!$B$6
A9: Projeto Elétrico | B9: 1 | C9: vb | D9: — | E9: =IF(B9>0,F9/B9,0) | F9: =CUSTOS_MACROGRUPO!$G$2*0.22*0.08 | G9: =F9/DADOS_PROJETO!$B$6
A10: Projeto Preventivo Incêndio | B10: 1 | C10: vb | D10: — | E10: =IF(B10>0,F10/B10,0) | F10: =CUSTOS_MACROGRUPO!$G$2*0.22*0.06 | G10: =F10/DADOS_PROJETO!$B$6
A11: Projeto Fundações | B11: 1 | C11: vb | D11: — | E11: =IF(B11>0,F11/B11,0) | F11: =CUSTOS_MACROGRUPO!$G$2*0.22*0.07 | G11: =F11/DADOS_PROJETO!$B$6
A12: Projeto Ar Condicionado / Ventilação | B12: 1 | C12: vb | D12: — | E12: =IF(B12>0,F12/B12,0) | F12: =CUSTOS_MACROGRUPO!$G$2*0.22*0.05 | G12: =F12/DADOS_PROJETO!$B$6
A13: Projeto Luminotécnico | B13: 1 | C13: vb | D13: — | E13: =IF(B13>0,F13/B13,0) | F13: =CUSTOS_MACROGRUPO!$G$2*0.22*0.03 | G13: =F13/DADOS_PROJETO!$B$6
A14: Projeto Paisagístico | B14: 1 | C14: vb | D14: — | E14: =IF(B14>0,F14/B14,0) | F14: =CUSTOS_MACROGRUPO!$G$2*0.22*0.04 | G14: =F14/DADOS_PROJETO!$B$6
A15: Projeto Interiores (áreas comuns) | B15: 1 | C15: vb | D15: — | E15: =IF(B15>0,F15/B15,0) | F15: =CUSTOS_MACROGRUPO!$G$2*0.22*0.06 | G15: =F15/DADOS_PROJETO!$B$6
A16: Projeto Automação / CFTV / Telecom | B16: 1 | C16: vb | D16: — | E16: =IF(B16>0,F16/B16,0) | F16: =CUSTOS_MACROGRUPO!$G$2*0.22*0.04 | G16: =F16/DADOS_PROJETO!$B$6
A17: Projeto Gás | B17: 1 | C17: vb | D17: — | E17: =IF(B17>0,F17/B17,0) | F17: =CUSTOS_MACROGRUPO!$G$2*0.22*0.03 | G17: =F17/DADOS_PROJETO!$B$6
A18: Compatibilização BIM | B18: 1 | C18: vb | D18: — | E18: =IF(B18>0,F18/B18,0) | F18: =CUSTOS_MACROGRUPO!$G$2*0.22*0.06 | G18: =F18/DADOS_PROJETO!$B$6
A19: Consultoria Geotécnica (SPT + laudo) | B19: 1 | C19: vb | D19: — | E19: =IF(B19>0,F19/B19,0) | F19: =CUSTOS_MACROGRUPO!$G$2*0.22*0.05 | G19: =F19/DADOS_PROJETO!$B$6
A20: Topografia (levantamento + locação) | B20: 1 | C20: vb | D20: — | E20: =IF(B20>0,F20/B20,0) | F20: =CUSTOS_MACROGRUPO!$G$2*0.22*0.04 | G20: =F20/DADOS_PROJETO!$B$6
A21: As-built | B21: 1 | C21: vb | D21: — | E21: =IF(B21>0,F21/B21,0) | F21: =CUSTOS_MACROGRUPO!$G$2*0.22*0.02 | G21: =F21/DADOS_PROJETO!$B$6
A22: Subtotal 1. PROJETOS E CONSULTORIAS | F22: =SUM(F6:F21) | G22: =SUM(G6:G21)
A24: 2. TAXAS, LICENÇAS E SEGUROS
A25: Alvará de construção | B25: 1 | C25: vb | D25: — | E25: =IF(B25>0,F25/B25,0) | F25: =CUSTOS_MACROGRUPO!$G$2*0.05*0.15 | G25: =F25/DADOS_PROJETO!$B$6
A26: Habite-se / CND obra | B26: 1 | C26: vb | D26: — | E26: =IF(B26>0,F26/B26,0) | F26: =CUSTOS_MACROGRUPO!$G$2*0.05*0.12 | G26: =F26/DADOS_PROJETO!$B$6
A27: ART/RRT (acervo técnico) | B27: 1 | C27: vb | D27: — | E27: =IF(B27>0,F27/B27,0) | F27: =CUSTOS_MACROGRUPO!$G$2*0.05*0.08 | G27: =F27/DADOS_PROJETO!$B$6
A28: Licença ambiental (se aplicável) | B28: 1 | C28: vb | D28: — | E28: =IF(B28>0,F28/B28,0) | F28: =CUSTOS_MACROGRUPO!$G$2*0.05*0.08 | G28: =F28/DADOS_PROJETO!$B$6
A29: Seguro de obra (all risks) | B29: 1 | C29: vb | D29: — | E29: =IF(B29>0,F29/B29,0) | F29: =CUSTOS_MACROGRUPO!$G$2*0.05*0.2 | G29: =F29/DADOS_PROJETO!$B$6
A30: INSS obra (contribuição patronal) | B30: 1 | C30: vb | D30: — | E30: =IF(B30>0,F30/B30,0) | F30: =CUSTOS_MACROGRUPO!$G$2*0.05*0.15 | G30: =F30/DADOS_PROJETO!$B$6
A31: ISS sobre serviços | B31: 1 | C31: vb | D31: — | E31: =IF(B31>0,F31/B31,0) | F31: =CUSTOS_MACROGRUPO!$G$2*0.05*0.1 | G31: =F31/DADOS_PROJETO!$B$6
A32: Taxas de ligação (água, energia, gás) | B32: 1 | C32: vb | D32: — | E32: =IF(B32>0,F32/B32,0) | F32: =CUSTOS_MACROGRUPO!$G$2*0.05*0.07 | G32: =F32/DADOS_PROJETO!$B$6
A33: Registro de incorporação (cartório) | B33: 1 | C33: vb | D33: — | E33: =IF(B33>0,F33/B33,0) | F33: =CUSTOS_MACROGRUPO!$G$2*0.05*0.05 | G33: =F33/DADOS_PROJETO!$B$6
A34: Subtotal 2. TAXAS, LICENÇAS E SEGUROS | F34: =SUM(F25:F33) | G34: =SUM(G25:G33)
A36: 3. EQUIPE ADMINISTRATIVA
A37: Engenheiro Residente (36 meses × R$14.000/mês) | B37: =DADOS_PROJETO!$B$17 | C37: mês | D37: Prazo | E37: =IF(B37>0,F37/B37,0) | F37: =CUSTOS_MACROGRUPO!$G$2*0.2*0.25 | G37: =F37/DADOS_PROJETO!$B$6
A38: Mestre de Obras (36 meses × R$12.000/mês) | B38: =DADOS_PROJETO!$B$17 | C38: mês | D38: Prazo | E38: =IF(B38>0,F38/B38,0) | F38: =CUSTOS_MACROGRUPO!$G$2*0.2*0.22 | G38: =F38/DADOS_PROJETO!$B$6
A39: Técnico de Segurança (36 meses × R$7.500/mês) | B39: =DADOS_PROJETO!$B$17 | C39: mês | D39: Prazo | E39: =IF(B39>0,F39/B39,0) | F39: =CUSTOS_MACROGRUPO!$G$2*0.2*0.14 | G39: =F39/DADOS_PROJETO!$B$6
A40: Almoxarife (36 meses × R$5.000/mês) | B40: =DADOS_PROJETO!$B$17 | C40: mês | D40: Prazo | E40: =IF(B40>0,F40/B40,0) | F40: =CUSTOS_MACROGRUPO!$G$2*0.2*0.1 | G40: =F40/DADOS_PROJETO!$B$6
A41: Administrativo/Auxiliar (36 meses × R$4.500/mês) | B41: =DADOS_PROJETO!$B$17 | C41: mês | D41: Prazo | E41: =IF(B41>0,F41/B41,0) | F41: =CUSTOS_MACROGRUPO!$G$2*0.2*0.09 | G41: =F41/DADOS_PROJETO!$B$6
A42: Estagiário Engenharia (24 meses × R$2.500/mês) | B42: =24 | C42: mês | D42: 24 | E42: =IF(B42>0,F42/B42,0) | F42: =CUSTOS_MACROGRUPO!$G$2*0.2*0.05 | G42: =F42/DADOS_PROJETO!$B$6
A43: Apontador (36 meses × R$4.000/mês) | B43: =DADOS_PROJETO!$B$17 | C43: mês | D43: Prazo | E43: =IF(B43>0,F43/B43,0) | F43: =CUSTOS_MACROGRUPO!$G$2*0.2*0.08 | G43: =F43/DADOS_PROJETO!$B$6
...

Sheet BENCHMARK
A1: BENCHMARK — PROJETOS DE REFERÊNCIA
A3: Projeto | B3: Cidade | C3: AC (m²) | D3: NP | E3: Prazo (meses) | F3: CUB (R$/m²) | G3: R$/m² Original | H3: CUB Ratio | I3: R$/m² Atual
A4: Maison Beach | B4: Floripa | C4: 12880 | D4: 25 | E4: 36 | F4: 2753 | G4: 3291 | H4: 1.2 | I4: =H4*DADOS_PROJETO!$B$19
A5: Catena | B5: Floripa | C5: 9242 | D5: 20 | E5: 30 | F5: 3009 | G5: 3376 | H5: 1.12 | I5: =H5*DADOS_PROJETO!$B$19
A6: Connect | B6: Itajaí | C6: 13144 | D6: 28 | E6: 36 | F6: 2900 | G6: 3150 | H6: 1.09 | I6: =H6*DADOS_PROJETO!$B$19
A7: Dlohn | B7: Blumenau | C7: 8500 | D7: 18 | E7: 24 | F7: 2800 | G7: 3080 | H7: 1.1 | I7: =H7*DADOS_PROJETO!$B$19
A8: Eternity | B8: Itajaí | C8: 11200 | D8: 22 | E8: 30 | F8: 2850 | G8: 3420 | H8: 1.2 | I8: =H8*DADOS_PROJETO!$B$19
A9: Lorenzo | B9: Itajaí | C9: 9800 | D9: 20 | E9: 28 | F9: 2780 | G9: 3190 | H9: 1.15 | I9: =H9*DADOS_PROJETO!$B$19
A10: Monolyt | B10: Floripa | C10: 18500 | D10: 32 | E10: 42 | F10: 2900 | G10: 3480 | H10: 1.2 | I10: =H10*DADOS_PROJETO!$B$19
A11: Cota365 | B11: Floripa | C11: 10500 | D11: 24 | E11: 30 | F11: 2850 | G11: 3250 | H11: 1.14 | I11: =H11*DADOS_PROJETO!$B$19
A13: ESTE PROJETO | B13: =DADOS_PROJETO!B4 | C13: =DADOS_PROJETO!B6 | D13: =DADOS_PROJETO!B9 | E13: =DADOS_PROJETO!B17 | F13: =DADOS_PROJETO!B19 | G13: =CUSTOS_MACROGRUPO!G20/DADOS_PROJETO!B6 | H13: =(CUSTOS_MACROGRUPO!G20/DADOS_PROJETO!B6)/DADOS_PROJETO!B19 | I13: =CUSTOS_MACROGRUPO!G20/DADOS_PROJETO!B6
A15: COMPARATIVO POR MACROGRUPO (R$/m²)
A16: Macrogrupo | B16: Média Base | C16: Este Projeto | D16: Diferença %
A17: Gerenciamento | B17: 380 | C17: =CUSTOS_MACROGRUPO!F2 | D17: =(C17-B17)/B17
A18: Infraestrutura | B18: 210 | C18: =CUSTOS_MACROGRUPO!F4 | D18: =(C18-B18)/B18
A19: Supraestrutura | B19: 680 | C19: =CUSTOS_MACROGRUPO!F5 | D19: =(C19-B19)/B19
A20: Instalações | B20: 350 | C20: =CUSTOS_MACROGRUPO!F8 | D20: =(C20-B20)/B20
A21: Pisos | B21: 180 | C21: =CUSTOS_MACROGRUPO!F13 | D21: =(C21-B21)/B21
A22: Esquadrias | B22: 330 | C22: =CUSTOS_MACROGRUPO!F15 | D22: =(C22-B22)/B22
A23: Fachada | B23: 160 | C23: =CUSTOS_MACROGRUPO!F17 | D23: =(C23-B23)/B23

Sheet ANÁLISE_PRODUTO
A1: ANÁLISE DE PRODUTO
A3: Indicador | B3: Este Projeto | C3: Faixa Típica | D3: Status
A4: AC/UR (m²/UR) | B4: =DADOS_PROJETO!B6/DADOS_PROJETO!B7 | C4: 90-160 | D4: =IF(AND(B4>=90,B4<=160),"OK","ATENÇÃO")
A5: Custo/UR (R$) | B5: =CUSTOS_MACROGRUPO!G20/DADOS_PROJETO!B7 | C5: —
A6: R$/m² (R$/m²) | B6: =CUSTOS_MACROGRUPO!G20/DADOS_PROJETO!B6 | C6: —
A7: CUB Ratio | B7: =(CUSTOS_MACROGRUPO!G20/DADOS_PROJETO!B6)/DADOS_PROJETO!B19 | C7: 1.00-1.50 | D7: =IF(AND(B7>=1,B7<=1.5),"OK",IF(B7>1.5,"ALTO","BAIXO"))
A8: Vagas/UR | B8: =DADOS_PROJETO!B13/DADOS_PROJETO!B7 | C8: 1.0-2.0 | D8: =IF(AND(B8>=1,B8<=2),"OK","ATENÇÃO")
A9: % Tipo (NPT/NP) | B9: =DADOS_PROJETO!B10/DADOS_PROJETO!B9 | C9: 60-80% | D9: =IF(AND(B9>=0.6,B9<=0.8),"OK","ATENÇÃO")
A10: Elevador/UR | B10: =DADOS_PROJETO!B12/DADOS_PROJETO!B7 | C10: 0.015-0.030 | D10: =IF(AND(B10>=0.015,B10<=0.03),"OK","ATENÇÃO")

Sheet ALERTAS
A1: ALERTAS E VALIDAÇÕES
A2: Macrogrupo | B2: R$/m² Calculado | C2: Faixa Esperada | D2: Status
A3: =CUSTOS_MACROGRUPO!B2 | B3: =CUSTOS_MACROGRUPO!F2 | C3: =CUSTOS_MACROGRUPO!I2&" - "&CUSTOS_MACROGRUPO!J2 | D3: =CUSTOS_MACROGRUPO!K2
A4: =CUSTOS_MACROGRUPO!B3 | B4: =CUSTOS_MACROGRUPO!F3 | C4: =CUSTOS_MACROGRUPO!I3&" - "&CUSTOS_MACROGRUPO!J3 | D4: =CUSTOS_MACROGRUPO!K3
A5: =CUSTOS_MACROGRUPO!B4 | B5: =CUSTOS_MACROGRUPO!F4 | C5: =CUSTOS_MACROGRUPO!I4&" - "&CUSTOS_MACROGRUPO!J4 | D5: =CUSTOS_MACROGRUPO!K4
A6: =CUSTOS_MACROGRUPO!B5 | B6: =CUSTOS_MACROGRUPO!F5 | C6: =CUSTOS_MACROGRUPO!I5&" - "&CUSTOS_MACROGRUPO!J5 | D6: =CUSTOS_MACROGRUPO!K5
A7: =CUSTOS_MACROGRUPO!B6 | B7: =CUSTOS_MACROGRUPO!F6 | C7: =CUSTOS_MACROGRUPO!I6&" - "&CUSTOS_MACROGRUPO!J6 | D7: =CUSTOS_MACROGRUPO!K6
A8: =CUSTOS_MACROGRUPO!B7 | B8: =CUSTOS_MACROGRUPO!F7 | C8: =CUSTOS_MACROGRUPO!I7&" - "&CUSTOS_MACROGRUPO!J7 | D8: =CUSTOS_MACROGRUPO!K7
A9: =CUSTOS_MACROGRUPO!B8 | B9: =CUSTOS_MACROGRUPO!F8 | C9: =CUSTOS_MACROGRUPO!I8&" - "&CUSTOS_MACROGRUPO!J8 | D9: =CUSTOS_MACROGRUPO!K8
A10: =CUSTOS_MACROGRUPO!B9 | B10: =CUSTOS_MACROGRUPO!F9 | C10: =CUSTOS_MACROGRUPO!I9&" - "&CUSTOS_MACROGRUPO!J9 | D10: =CUSTOS_MACROGRUPO!K9
A11: =CUSTOS_MACROGRUPO!B10 | B11: =CUSTOS_MACROGRUPO!F10 | C11: =CUSTOS_MACROGRUPO!I10&" - "&CUSTOS_MACROGRUPO!J10 | D11: =CUSTOS_MACROGRUPO!K10
A12: =CUSTOS_MACROGRUPO!B11 | B12: =CUSTOS_MACROGRUPO!F11 | C12: =CUSTOS_MACROGRUPO!I11&" - "&CUSTOS_MACROGRUPO!J11 | D12: =CUSTOS_MACROGRUPO!K11
A13: =CUSTOS_MACROGRUPO!B12 | B13: =CUSTOS_MACROGRUPO!F12 | C13: =CUSTOS_MACROGRUPO!I12&" - "&CUSTOS_MACROGRUPO!J12 | D13: =CUSTOS_MACROGRUPO!K12
A14: =CUSTOS_MACROGRUPO!B13 | B14: =CUSTOS_MACROGRUPO!F13 | C14: =CUSTOS_MACROGRUPO!I13&" - "&CUSTOS_MACROGRUPO!J13 | D14: =CUSTOS_MACROGRUPO!K13
... A20: =CUSTOS_MACROGRUPO!B19 | B20: =CUSTOS_MACROGRUPO!F19 | C20: =CUSTOS_MACROGRUPO!I19&" - "&CUSTOS_MACROGRUPO!J19 | D20: =CUSTOS_MACROGRUPO!K19

Sheet NOTAS
A1: PREMISSAS E LIMITAÇÕES
A3: SOBRE ESTE TEMPLATE:
A4: Este orçamento paramétrico foi desenvolvido pela Cartesian Engenharia para estimativas rápidas de custos de obras residenciais/comerciais.
A6: BASE DE CALIBRAÇÃO:
A7: - Mediana calibrada com 18 projetos reais executados entre 2022-2024
A8: - CUB base: R$ 2.752,67 (dez/2023)
A9: - Faixas P10-P90 representam variação observada nos projetos da base
A11: COMO USAR:
A12: 1. Preencha DADOS_PROJETO com informações do empreendimento
A13: 2. Responda as 25 perguntas do BRIEFING (use os dropdowns)
A14: 3. Os custos em CUSTOS_MACROGRUPO são calculados automaticamente
A15: 4. Verifique ALERTAS para validar se os valores estão dentro das faixas esperadas
... A40: www.cartesianengenharia.com
