Workbook

Sheet DADOS
A1: ORÇAMENTO PARAMÉTRICO — DADOS DE ENTRADA
A3: 1. IDENTIFICAÇÃO DO PROJETO
A4: Nome do Projeto | B4: Maison Beach 2 Residence
A5: Construtora/Cliente | B5: Nobria Construtora LTDA
A6: Cidade | B6: Bombinhas
A7: Estado | B7: SC
A8: Data-base dos preços | C8: mês/ano | D8: Ex: mar/2026
A9: CUB Referência (R$/m²) | C9: R$/m² | D9: CUB-SC R8N do mês
A11: 2. DADOS DO PROGRAMA (ÁREAS E QUANTIDADES)
A12: Variável | B12: Valor | C12: Unidade | D12: Observação
A13: Área do Terreno (AT) | B13: 2723.26 | C13: m² | D13: Extraído do PDF
A14: Área Construída Total (AC) | B14: 12879.93 | C14: m² | D14: Extraído do PDF — DRIVER PRINCIPAL
A15: Nº Total Pavimentos (NP) | B15: 10 | C15: un | D15: Subsolo + Térreo + Mezanino + Lazer + 4 tipos + Cobertura + Barrilete
A16: Nº Pavimentos Tipo (NPT) | B16: 4 | C16: un | D16: 4°, 5°, 6° (iguais) + 7° (diferenciado)
A17: Nº Pav. Tipo Diferenciados (NPD) | B17: 1 | C17: un | D17: 7° pavimento com 8 apts
A18: Nº Pavimentos Duplex (ND) | B18: 0 | C18: un
A19: Unidades Residenciais (UR) | B19: 56 | C19: un | D19: 16+16+16+8 = 56 apts
A20: Unidades Comerciais | B20: 2 | C20: un | D20: Térreo
A21: Churrasqueiras (CHU) | B21: 0 | C21: un | D21: Preencher se houver nas unidades
A22: Área de Lazer (AL) | B22: 0 | C22: m² | D22: Preencher — 3° pav inteiro é lazer
A23: Área Projeção Torre (APT) | B23: 1795 | C23: m² | D23: Estimado: ~70.1m × 25.6m
A24: Perímetro Projeção Torre (PPT) | B24: 191.4 | C24: m | D24: Estimado: 2×(70.1+25.6)
A25: Área Projeção Embasamento (APE) | B25: 2400 | C25: m² | D25: Estimado: ~69m × ~35m (ajustar)
A26: Perímetro Projeção Embasamento (PPE) | B26: 208 | C26: m | D26: Estimado (ajustar)
A27: Nº de Subsolos (NS) | B27: 1 | C27: un | D27: Subsolo garagem
A28: Área Subsolos (AS) | B28: 0 | C28: m² | D28: Preencher
A29: Nº Pav. Embasamento (NPE) | B29: 3 | C29: un | D29: Subsolo + Térreo + Mezanino
A30: Área Embasamento (AE) | B30: 0 | C30: m² | D30: Preencher
... A33: Locação da Obra (LC) | B33: 0 | C33: m | D33: Perímetro da escavação
A35: 3. BRIEFING — PERGUNTAS DECISIVAS (❓ Maior impacto no resultado)
A36: Pergunta | B36: Resposta | C36: Impacto | D36: Observação | E36: Afeta qual Macrogrupo
A37: Tipo de Laje | B37: Cubetas | C37: ~15% supraestrutura | D37: Cubetas | Protendida | Maciça | Cub.Protendida | Treliçada | E37: → Supraestrutura (R$/m²)
A38: Padrão de Acabamento | B38: Standard | C38: 30-40% esquadrias | D38: Standard | Alto Padrão | Super Alto Padrão | E38: → Esquadrias, Rev.Int, Pisos, Teto, Pintura, Louças
A39: Tem Contenção? | B39: Não | C39: 5-8% do total | D39: Sim | Não | E39: → Infraestrutura (+/-40 R$/m²)
A40: Tipo Contenção (se sim) | D40: Cortina estacas, muro arrimo, etc.
A41: Extensão Contenção (m) | D41: Metros lineares
A42: Vedação Interna | B42: Alvenaria | C42: Drywall = 3x custo | D42: Alvenaria | Drywall | Misto | E42: → Alvenaria (Drywall=3x)
A43: MO Fachada | B43: Empreitada | C43: +50-60 R$/m² | D43: Empreitada | Equipe Própria | E43: → Fachada (-30% equipe própria)
A44: Cobertura Habitável? | B44: Não | C44: 5-10x cobertura simples | D44: Sim | Não | E44: → Complementares (+50 R$/m²)
A45: Descrição Cobertura (se sim) | D45: Pergolados, deck, piscina, etc.
...

Sheet PRODUTO
A1: ÍNDICES DE PRODUTO IMOBILIÁRIO — MAISON BEACH 2
A3: 1. EFICIÊNCIA DO TERRENO
A4: Índice | B4: Valor | C4: Unidade | D4: Fórmula | E4: Mín (Base) | F4: Mediana | G4: Máx (Base) | H4: Posição
A5: Coeficiente de Aproveitamento (CA) | B5: =DADOS!B14/DADOS!B13 -> 4.7295998 | C5: × | D5: AC / AT | E5: 1.5 | F5: 3.5 | G5: 14
A6: Área Construída por Unidade (AC/UR) | B6: =DADOS!B14/DADOS!B19 -> 229.99875 | C6: m²/un | D6: AC / UR | E6: 78.7 | F6: 198.2 | G6: 612.2
A7: Unidades por Terreno (UR/AT) | B7: =DADOS!B19/DADOS!B13 -> 0.020563589 | C7: un/m² | D7: UR / AT | E7: 0.003 | F7: 0.02 | G7: 0.1
A8: Área Projeção / Terreno | B8: =DADOS!B23/DADOS!B13 -> 0.65913648 | C8: × | D8: APT / AT
A10: 2. INFRAESTRUTURA DE APOIO
A11: Índice | B11: Valor | C11: Unidade | D11: Fórmula | E11: Mín (Base) | F11: Mediana | G11: Máx (Base) | H11: Posição
A12: Vagas por Unidade (VAG/UR) | B12: =DADOS!B32/DADOS!B19 -> 1.3571429 | C12: vag/un | D12: VAG / UR | E12: 0.67 | F12: 1.5 | G12: 2.45
A13: UR por Elevador | B13: =DADOS!B19/DADOS!B31 -> 28 | C13: un/elev | D13: UR / ELEV | E13: 12 | F13: 28 | G13: 47
A14: Elevadores por Pavimento | B14: =DADOS!B31/DADOS!B15 -> 0.2 | C14: elev/pav | D14: ELEV / NP | E14: 0.05 | F14: 0.15 | G14: 0.43
A15: Pavimentos Tipo / Total | B15: =DADOS!B16/DADOS!B15 -> 0.4 | C15: × | D15: NPT / NP | E15: 0.4 | F15: 0.6 | G15: 0.8
A16: UR por Pavimento Tipo | B16: =DADOS!B19/DADOS!B16 -> 14 | C16: un/pav | D16: UR / NPT | E16: 1.2 | F16: 5 | G16: 35.2
A18: 3. DENSIDADE E VERTICALIZAÇÃO
A19: Índice | B19: Valor | C19: Unidade | D19: Fórmula | E19: Mín (Base) | F19: Mediana | G19: Máx (Base) | H19: Posição
A20: Nº Total Pavimentos | B20: =DADOS!B15 -> 10 | C20: pav | D20: NP | E20: 4 | F20: 18 | G20: 43
A21: Nº Pavimentos Tipo | B21: =DADOS!B16 -> 4 | C21: pav | D21: NPT | E21: 3 | F21: 11 | G21: 32
A22: Nº Subsolos | B22: =DADOS!B27 -> 1 | C22: pav | D22: NS | E22: 0 | F22: 1 | G22: 3
A23: Nº Pav. Embasamento | B23: =DADOS!B29 -> 3 | C23: pav | D23: NPE | E23: 1 | F23: 3 | G23: 6
A24: AC por Pavimento | B24: =DADOS!B14/DADOS!B15 -> 1287.993 | C24: m²/pav | D24: AC / NP | E24: 200 | F24: 700 | G24: 1500
A25: Taxa de Ocupação (estimada) | B25: =DADOS!B23/DADOS!B13 -> 0.65913648 | C25: × | D25: APT / AT | E25: 0.3 | F25: 0.55 | G25: 0.8
A27: 4. CUSTO POR UNIDADE
A28: Índice | B28: Valor | C28: Unidade | D28: Fórmula | E28: Mín (Base) | F28: Mediana | G28: Máx (Base) | H28: Posição
A29: R$/m² AC (total) | B29: =RESUMO!B8 -> 0 | C29: R$/m² | D29: Total / AC | E29: 2370 | F29: 3600 | G29: 9534
A30: R$ Total por Unidade (R$/UR) | B30: =RESUMO!B10/DADOS!B19 -> 835401.46 | C30: R$/un | D30: Total / UR
A31: CUB Ratio | B31: =IF(DADOS!B9>0,RESUMO!B8/DADOS!B9,"Preencher CUB") -> Preencher CUB | C31: ×CUB | D31: R$/m² / CUB | E31: 0.94 | F31: 1.3 | G31: 3.39
A33: 5. BENCHMARK — PROJETOS COMPARÁVEIS (SC, 7.000-16.000 m², Alto Padrão)
A34: Projeto | B34: AC (m²) | C34: UR | D34: NP | E34: NPT | F34: AC/UR | G34: R$/m² | H34: Cidade
A35: Maison Beach 2 | B35: 12880 | C35: 56 | D35: 10 | E35: 4 | F35: =B35/C35 -> 230 | G35: =RESUMO!B8 -> 0 | H35: Bombinhas
A36: Kirchner West Village | B36: 10723 | C36: 44 | D36: 21 | E36: 15 | F36: =B36/C36 -> 243.70455 | G36: 2816 | H36: Itapema
A37: Meia Praia 298 | B37: 10618 | C37: 41 | D37: 26 | E37: 18 | F37: =B37/C37 -> 258.97561 | G37: 3535 | H37: Itapema
A38: Meia Praia Eternity | B38: 11893 | C38: 51 | D38: 28 | E38: 23 | F38: =B38/C38 -> 233.19608 | G38: 3482 | H38: Itapema
A39: Lorenzo Gabriel | B39: 8525 | C39: 73 | D39: 19 | E39: 14 | F39: =B39/C39 -> 116.78082 | G39: 3778 | H39: Itapema
A40: Amalfi Maiori | B40: 8367 | C40: 60 | D40: 18 | E40: 11 | F40: =B40/C40 -> 139.45 | G40: 3010 | H40: Itajaí
A41: Be Brave Meraki | B41: 22461 | C41: 110 | D41: 32 | E41: 25 | F41: =B41/C41 -> 204.19091 | G41: 3720 | H41: Itajaí
A42: Catena | B42: 9242 | C42: 48 | D42: 30 | F42: =B42/C42 -> 192.54167 | G42: 3376 | H42: SC
A43: Ferrazzo Perequê | B43: 5576 | C43: 38 | D43: 15 | E43: 8 | F43: =B43/C43 -> 146.73684 | G43: 4129 | H43: Porto Belo
A44: D'Lohn Estreito | B44: 13148 | C44: 89 | D44: 13 | E44: 8 | F44: =B44/C44 -> 147.73034 | G44: 3728 | H44: Florianópolis
A46: 6. MIX DE TIPOLOGIAS
...

Sheet ÍNDICES
A1: ÍNDICES PARAMÉTRICOS POR TIPO DE LAJE
A3: Parâmetro | B3: Maciça | C3: Cubetas | D3: Cub.Protend. | E3: Treliçada | F3: Protendida | G3: Unidade
A4: Jogos de Fôrma | B4: 1 | C4: 3 | D4: 3 | E4: 2 | F4: 3 | G4: jogos
A5: Montagem Fôrma (m²/AC) | B5: 1.2 | C5: 1.1 | D5: 1.1 | E5: 2.1 | F5: 2.1 | G5: m²/m²AC
A6: Concreto (m³/AC) | B6: 0.22 | C6: 0.23 | D6: 0.25 | E6: 0.25 | F6: 0.25 | G6: m³/m²AC
A7: Armadura (kg/m³) | B7: 78 | C7: 78 | D7: 100 | E7: 110 | F7: 90 | G7: kg/m³
A8: MO Estrutura (R$/AC) | B8: 240 | C8: 290 | D8: 280 | E8: 240 | F8: 240 | G8: R$/m²AC
A9: Supraestrutura R$/m² AC | B9: 580 | C9: 640 | D9: 700 | E9: 720 | F9: 670 | G9: R$/m²AC
A10: ÍNDICES GERAIS (independentes do tipo de laje)
A11: Serviço | B11: Índice | C11: Unidade | D11: Base | G11: Obs
A12: Nº Estacas (fundação) | B12: 0.14 | C12: un/m² | D12: APE
A13: Nº Estacas (cortina) | B13: 0.15 | C13: un/m² | D13: APE
A14: Forma Blocos/Baldrames | B14: 1.1 | C14: m²/m² | D14: APE
A15: Concreto Blocos/Baldrames | B15: 0.6 | C15: m³/m² | D15: APE
A16: Armação Blocos/Baldrames | B16: 70 | C16: kg/m³ | D16: Vol.concreto
A17: Forma Parede Contenção | B17: 2.1 | C17: m²/m² | D17: APE
A18: Concreto Parede Contenção | B18: 0.65 | C18: m³/m² | D18: APE
A19: Lastro Concreto Magro | B19: 0.8 | C19: m²/m² | D19: APE
A20: Escavação Valas | B20: 1.3 | C20: m³/m³ | D20: Vol.infra
A21: Alvenaria Externa | B21: 0.6 | C21: m²/m²AC | D21: AC
A22: Alvenaria Interna | B22: 0.8 | C22: m²/m²AC | D22: AC
A23: Contrapiso | B23: 0.62 | C23: m²/m²AC | D23: AC
... A32: Preventivas + GLP | B32: 41 | C32: R$/m²AC | D32: AC
A35: VERBAS PARAMÉTRICAS (R$/m² AC)
A36: Pintura Interna Geral | B36: 75
A37: Rev. Parede (acabamento) | B37: 45
A38: Rodapés | B38: 30
A39: Textura Escadas | B39: 25
A40: Soleiras e Peitoris | B40: 20
A41: Limpeza | B41: 15
A42: Paisagismo | B42: 11
A43: Comunicação Visual | B43: 10
A44: Serralheria | B44: 5
A45: Desmobilização | B45: 5
A46: Ligações Definitivas | B46: 4
A48: FATORES DE CUSTO
A49: BDI | B49: 1.1 | C49: Universal — todos os itens
A50: Perda Concreto (estacas) | B50: 1.3 | C50: Fundação profunda
A51: Perda Concreto (fund. rasa) | B51: 1.05 | C51: Blocos e baldrames
A52: Perda Concreto (supra) | B52: 1.05 | C52: Todas variantes de laje
...

Sheet PARAMÉTRICO
A1: ORÇAMENTO PARAMÉTRICO — CÁLCULO
A2: AC: | B2: =DADOS!B14 -> 12879.93 | C2: BDI: | D2: 1.1
A4: # | B4: Macrogrupo | C4: R$/m² AC | D4: Valor Total (R$) | E4: % do Total | F4: Benchmark Médio | G4: Status | H4: Fonte
A5: 1 | B5: Gerenciamento Técnico/Admin | C5: 450 | D5: =C5*$B$2*$D$2 -> 6375565.3 | E5: =IF($D$23=0,"",D5/$D$23) -> 0.13628104 | F5: 450 | G5: =IF(C5="","",IF(C5>F5*1.15,"⚠ ACIMA",IF(C5<F5*0.85,"↓ ABAIXO","✓ OK"))) -> ✓ OK | H5: Manual
A6: 2 | B6: Movimentação de Terra | C6: 15 | D6: =C6*$B$2*$D$2 -> 212518.85 | E6: =IF($D$23=0,"",D6/$D$23) -> 0.0045427014 | F6: 15 | G6: =IF(C6="","",IF(C6>F6*1.15,"⚠ ACIMA",IF(C6<F6*0.85,"↓ ABAIXO","✓ OK"))) -> ✓ OK | H6: Manual
A7: 3 | B7: Infraestrutura | C7: =IF(DADOS!B39="Sim",260,IF(DADOS!B39="Não",195,220)) -> 195 | D7: =C7*$B$2*$D$2 -> 2762745 | E7: =IF($D$23=0,"",D7/$D$23) -> 0.059055118 | F7: 220 | G7: =IF(C7="","",IF(C7>F7*1.15,"⚠ ACIMA",IF(C7<F7*0.85,"↓ ABAIXO","✓ OK"))) -> ✓ OK | H7: ← Contenção (DADOS!B39)
A8: 4 | B8: Supraestrutura | C8: =IF(DADOS!B37="Maciça",ÍNDICES!B9,IF(DADOS!B37="Cubetas",ÍNDICES!C9,IF(DADOS!B37="Cub.Protendida",ÍNDICES!D9,IF(DADOS!B37="Treliçada",ÍNDICES!E9,IF(DADOS!B37="Protendida",ÍNDICES!F9,670))))) -> 640 | D8: =C8*$B$2*$D$2 -> 9067470.7 | E8: =IF($D$23=0,"",D8/$D$23) -> 0.19382193 | F8: 670 | G8: =IF(C8="","",IF(C8>F8*1.15,"⚠ ACIMA",IF(C8<F8*0.85,"↓ ABAIXO","✓ OK"))) -> ✓ OK | H8: ← Tipo Laje (DADOS!B37)
A9: 5 | B9: Alvenaria | C9: =IF(DADOS!B42="Alvenaria",145,IF(DADOS!B42="Drywall",208,IF(DADOS!B42="Misto",185,160))) -> 145 | D9: =C9*$B$2*$D$2 -> 2054348.8 | E9: =IF($D$23=0,"",D9/$D$23) -> 0.04391278 | F9: 160 | G9: =IF(C9="","",IF(C9>F9*1.15,"⚠ ACIMA",IF(C9<F9*0.85,"↓ ABAIXO","✓ OK"))) -> ✓ OK | H9: ← Vedação (DADOS!B42)
A10: 6 | B10: Impermeabilização | C10: 75 | D10: =C10*$B$2*$D$2 -> 1062594.2 | E10: =IF($D$23=0,"",D10/$D$23) -> 0.022713507 | F10: 75 | G10: =IF(C10="","",IF(C10>F10*1.15,"⚠ ACIMA",IF(C10<F10*0.85,"↓ ABAIXO","✓ OK"))) -> ✓ OK | H10: Manual
A11: 7 | B11: Instalações | C11: 340 | D11: =C11*$B$2*$D$2 -> 4817093.8 | E11: =IF($D$23=0,"",D11/$D$23) -> 0.1029679 | F11: 340 | G11: =IF(C11="","",IF(C11>F11*1.15,"⚠ ACIMA",IF(C11<F11*0.85,"↓ ABAIXO","✓ OK"))) -> ✓ OK | H11: Manual
A12: 8 | B12: Sistemas Especiais | C12: 150 | D12: =C12*$B$2*$D$2 -> 2125188.5 | E12: =IF($D$23=0,"",D12/$D$23) -> 0.045427014 | F12: 150 | G12: =IF(C12="","",IF(C12>F12*1.15,"⚠ ACIMA",IF(C12<F12*0.85,"↓ ABAIXO","✓ OK"))) -> ✓ OK | H12: Manual
A13: 9 | B13: Climatização | C13: 45 | D13: =C13*$B$2*$D$2 -> 637556.54 | E13: =IF($D$23=0,"",D13/$D$23) -> 0.013628104 | F13: 45 | G13: =IF(C13="","",IF(C13>F13*1.15,"⚠ ACIMA",IF(C13<F13*0.85,"↓ ABAIXO","✓ OK"))) -> ✓ OK | H13: Manual
A14: 10 | B14: Rev. Internos Parede | C14: =IF(DADOS!B38="Standard",ÍNDICES!B59,IF(DADOS!B38="Alto Padrão",ÍNDICES!C59,IF(DADOS!B38="Super Alto Padrão",ÍNDICES!D59,200))) -> 140 | D14: =C14*$B$2*$D$2 -> 1983509.2 | E14: =IF($D$23=0,"",D14/$D$23) -> 0.042398546 | F14: 200 | G14: =IF(C14="","",IF(C14>F14*1.15,"⚠ ACIMA",IF(C14<F14*0.85,"↓ ABAIXO","✓ OK"))) -> ↓ ABAIXO | H14: ← Acabamento (DADOS!B38)
A15: 11 | B15: Teto | C15: =IF(DADOS!B38="Standard",ÍNDICES!B62,IF(DADOS!B38="Alto Padrão",ÍNDICES!C62,IF(DADOS!B38="Super Alto Padrão",ÍNDICES!D62,75))) -> 53 | D15: =C15*$B$2*$D$2 -> 750899.92 | E15: =IF($D$23=0,"",D15/$D$23) -> 0.016050878 | F15: 75 | G15: =IF(C15="","",IF(C15>F15*1.15,"⚠ ACIMA",IF(C15<F15*0.85,"↓ ABAIXO","✓ OK"))) -> ↓ ABAIXO | H15: ← Acabamento (DADOS!B38)
A16: 12 | B16: Pisos e Pavimentações | C16: =IF(DADOS!B38="Standard",ÍNDICES!B60,IF(DADOS!B38="Alto Padrão",ÍNDICES!C60,IF(DADOS!B38="Super Alto Padrão",ÍNDICES!D60,250))) -> 133 | D16: =C16*$B$2*$D$2 -> 1884333.8 | E16: =IF($D$23=0,"",D16/$D$23) -> 0.040278619 | F16: 250 | G16: =IF(C16="","",IF(C16>F16*1.15,"⚠ ACIMA",IF(C16<F16*0.85,"↓ ABAIXO","✓ OK"))) -> ↓ ABAIXO | H16: ← Acabamento (DADOS!B38)
A17: 13 | B17: Pintura | C17: =IF(DADOS!B38="Standard",ÍNDICES!B63,IF(DADOS!B38="Alto Padrão",ÍNDICES!C63,IF(DADOS!B38="Super Alto Padrão",ÍNDICES!D63,155))) -> 115 | D17: =C17*$B$2*$D$2 -> 1629311.1 | E17: =IF($D$23=0,"",D17/$D$23) -> 0.034827377 | F17: 155 | G17: =IF(C17="","",IF(C17>F17*1.15,"⚠ ACIMA",IF(C17<F17*0.85,"↓ ABAIXO","✓ OK"))) -> ↓ ABAIXO | H17: ← Acabamento (DADOS!B38)
A18: 14 | B18: Esquadrias | C18: =(IF(DADOS!B38="Standard",ÍNDICES!B58,IF(DADOS!B38="Alto Padrão",ÍNDICES!C58,IF(DADOS!B38="Super Alto Padrão",ÍNDICES!D58,300)))+IF(DADOS!B48="Sim",120,0))*IF(DADOS!B50="Alumínio Anodizado",ÍNDICES!B66,IF(DADOS!B50="Pintura Eletrostática",ÍNDICES!B67,IF(DADOS!B50="PVC",ÍNDICES!B68,1))) -> 211 | D18: =C18*$B$2*$D$2 -> 2989431.8 | E18: =IF($D$23=0,"",D18/$D$23) -> 0.063900666 | F18: 300 | G18: =IF(C18="","",IF(C18>F18*1.15,"⚠ ACIMA",IF(C18<F18*0.85,"↓ ABAIXO","✓ OK"))) -> ↓ ABAIXO | H18: ← Acabamento + Pele Vidro
A19: 15 | B19: Louças e Metais | C19: =IF(DADOS!B38="Standard",ÍNDICES!B61,IF(DADOS!B38="Alto Padrão",ÍNDICES!C61,IF(DADOS!B38="Super Alto Padrão",ÍNDICES!D61,30))) -> 25 | D19: =C19*$B$2*$D$2 -> 354198.08 | E19: =IF($D$23=0,"",D19/$D$23) -> 0.007571169 | F19: 30 | G19: =IF(C19="","",IF(C19>F19*1.15,"⚠ ACIMA",IF(C19<F19*0.85,"↓ ABAIXO","✓ OK"))) -> ↓ ABAIXO | H19: ← Acabamento (DADOS!B38)
A20: 16 | B20: Fachada | C20: =(IF(DADOS!B43="Empreitada",280,IF(DADOS!B43="Equipe Própria",220,250))+IF(DADOS!B49="Sim",25,0))*IF(DADOS!B51="Convencional",ÍNDICES!B71,IF(DADOS!B51="Neoclássica",ÍNDICES!B72,IF(DADOS!B51="Moderna",ÍNDICES!B73,IF(DADOS!B51="Minimalista",ÍNDICES!B74,1)))) -> 305 | D20: =C20*$B$2*$D$2 -> 4321216.5 | E20: =IF($D$23=0,"",D20/$D$23) -> 0.092368262 | F20: 140 | G20: =IF(C20="","",IF(C20>F20*1.15,"⚠ ACIMA",IF(C20<F20*0.85,"↓ ABAIXO","✓ OK"))) -> ⚠ ACIMA | H20: ← MO Fachada + Brises
A21: 17 | B21: Complementares | C21: =(IF(DADOS!B46="Básico",160,IF(DADOS!B46="Completo",200,IF(DADOS!B46="Premium",260,200))))+IF(DADOS!B44="Sim",50,0) -> 200 | D21: =C21*$B$2*$D$2 -> 2833584.6 | E21: =IF($D$23=0,"",D21/$D$23) -> 0.060569352 | F21: 200 | G21: =IF(C21="","",IF(C21>F21*1.15,"⚠ ACIMA",IF(C21<F21*0.85,"↓ ABAIXO","✓ OK"))) -> ✓ OK | H21: ← Lazer + Cobertura
A22: 18 | B22: Imprevistos | C22: 65 | D22: =C22*$B$2*$D$2 -> 920914.99 | E22: =IF($D$23=0,"",D22/$D$23) -> 0.019685039 | F22: 65 | G22: =IF(C22="","",IF(C22>F22*1.15,"⚠ ACIMA",IF(C22<F22*0.85,"↓ ABAIXO","✓ OK"))) -> ✓ OK | H22: Manual
A23: TOTAL GERAL | C23: =SUM(C5:C22) -> 3302 | D23: =SUM(D5:D22) -> 46782482 | E23: =SUM(E5:E22) -> 1 | F23: =SUM(F5:F22) -> 3540
A25: INDICADORES
A26: R$/m² AC Total | C26: =C23 -> 3302
A27: Custo Total (R$) | C27: =D23 -> 46782482
A28: CUBs Equivalentes | C28: =IF(DADOS!B9=0,"Preencher CUB",C23/DADOS!B9) -> Preencher CUB
A29: R$/UR | C29: =IF(DADOS!B19=0,"",D23/DADOS!B19) -> 835401.46
A30: AC/UR (m²/un) | C30: =IF(DADOS!B19=0,"",DADOS!B14/DADOS!B19) -> 229.99875

Sheet BENCHMARK
A1: BENCHMARK — FAIXAS DE REFERÊNCIA (R$/m² AC)
A2: Base: 6 projetos similares (7.000-12.900 m² AC) — Cartesian Engenharia
A4: # | B4: Macrogrupo | C4: Mín | D4: Mediana | E4: Máx | F4: Seu Projeto | G4: Posição
A5: 1 | B5: Gerenciamento Técnico/Admin | C5: 260 | D5: 450 | E5: 702 | F5: =PARAMÉTRICO!C5 -> 450 | G5: =IF(F5="","",IF(F5<C5,"↓ Abaixo Mín",IF(F5>E5,"⚠ Acima Máx",IF(F5<D5,"Abaixo Média","Acima Média")))) -> Acima Média
A6: 2 | B6: Movimentação de Terra | C6: 7 | D6: 15 | E6: 23 | F6: =PARAMÉTRICO!C6 -> 15 | G6: =IF(F6="","",IF(F6<C6,"↓ Abaixo Mín",IF(F6>E6,"⚠ Acima Máx",IF(F6<D6,"Abaixo Média","Acima Média")))) -> Acima Média
A7: 3 | B7: Infraestrutura | C7: 174 | D7: 220 | E7: 270 | F7: =PARAMÉTRICO!C7 -> 195 | G7: =IF(F7="","",IF(F7<C7,"↓ Abaixo Mín",IF(F7>E7,"⚠ Acima Máx",IF(F7<D7,"Abaixo Média","Acima Média")))) -> Abaixo Média
A8: 4 | B8: Supraestrutura | C8: 549 | D8: 670 | E8: 799 | F8: =PARAMÉTRICO!C8 -> 640 | G8: =IF(F8="","",IF(F8<C8,"↓ Abaixo Mín",IF(F8>E8,"⚠ Acima Máx",IF(F8<D8,"Abaixo Média","Acima Média")))) -> Abaixo Média
A9: 5 | B9: Alvenaria | C9: 114 | D9: 160 | E9: 208 | F9: =PARAMÉTRICO!C9 -> 145 | G9: =IF(F9="","",IF(F9<C9,"↓ Abaixo Mín",IF(F9>E9,"⚠ Acima Máx",IF(F9<D9,"Abaixo Média","Acima Média")))) -> Abaixo Média
A10: 6 | B10: Impermeabilização | C10: 64 | D10: 75 | E10: 86 | F10: =PARAMÉTRICO!C10 -> 75 | G10: =IF(F10="","",IF(F10<C10,"↓ Abaixo Mín",IF(F10>E10,"⚠ Acima Máx",IF(F10<D10,"Abaixo Média","Acima Média")))) -> Acima Média
A11: 7 | B11: Instalações | C11: 241 | D11: 340 | E11: 432 | F11: =PARAMÉTRICO!C11 -> 340 | G11: =IF(F11="","",IF(F11<C11,"↓ Abaixo Mín",IF(F11>E11,"⚠ Acima Máx",IF(F11<D11,"Abaixo Média","Acima Média")))) -> Acima Média
A12: 8 | B12: Sistemas Especiais | C12: 97 | D12: 150 | E12: 215 | F12: =PARAMÉTRICO!C12 -> 150 | G12: =IF(F12="","",IF(F12<C12,"↓ Abaixo Mín",IF(F12>E12,"⚠ Acima Máx",IF(F12<D12,"Abaixo Média","Acima Média")))) -> Acima Média
A13: 9 | B13: Climatização | C13: 25 | D13: 45 | E13: 72 | F13: =PARAMÉTRICO!C13 -> 45 | G13: =IF(F13="","",IF(F13<C13,"↓ Abaixo Mín",IF(F13>E13,"⚠ Acima Máx",IF(F13<D13,"Abaixo Média","Acima Média")))) -> Acima Média
A14: 10 | B14: Rev. Internos Parede | C14: 140 | D14: 200 | E14: 290 | F14: =PARAMÉTRICO!C14 -> 140 | G14: =IF(F14="","",IF(F14<C14,"↓ Abaixo Mín",IF(F14>E14,"⚠ Acima Máx",IF(F14<D14,"Abaixo Média","Acima Média")))) -> Abaixo Média
A15: 11 | B15: Teto | C15: 53 | D15: 75 | E15: 100 | F15: =PARAMÉTRICO!C15 -> 53 | G15: =IF(F15="","",IF(F15<C15,"↓ Abaixo Mín",IF(F15>E15,"⚠ Acima Máx",IF(F15<D15,"Abaixo Média","Acima Média")))) -> Abaixo Média
A16: 12 | B16: Pisos e Pavimentações | C16: 133 | D16: 250 | E16: 389 | F16: =PARAMÉTRICO!C16 -> 133 | G16: =IF(F16="","",IF(F16<C16,"↓ Abaixo Mín",IF(F16>E16,"⚠ Acima Máx",IF(F16<D16,"Abaixo Média","Acima Média")))) -> Abaixo Média
... A22: 18 | B22: Imprevistos | C22: 42 | D22: 65 | E22: 92 | F22: =PARAMÉTRICO!C22 -> 65 | G22: =IF(F22="","",IF(F22<C22,"↓ Abaixo Mín",IF(F22>E22,"⚠ Acima Máx",IF(F22<D22,"Abaixo Média","Acima Média")))) -> Acima Média
A23: TOTAL | C23: =SUM(C5:C22) -> 2485 | D23: =SUM(D5:D22) -> 3540 | E23: =SUM(E5:E22) -> 4795 | F23: =SUM(F5:F22) -> 3302
A26: PROJETOS DE REFERÊNCIA
B27: Projeto | C27: AC (m²) | D27: UR | E27: R$/m² AC | F27: CUBs | G27: Localização
A28: 1 | B28: Amalfi San Felice | C28: 7457 | D28: 30 | E28: 3292 | F28: 1.64 | G28: Itajaí/SC
A29: 2 | B29: Kirchner West Village | C29: 10723 | D29: 48 | E29: 2816 | F29: 1.39 | G29: Itajaí/SC
A30: 3 | B30: Adore Level UP | C30: 11103 | D30: 44 | E30: 3629 | F30: 1.8 | G30: Itajaí/SC
A31: 4 | B31: Amalfi Maiori | C31: 8367 | D31: 20 | E31: 3010 | F31: 1.5 | G31: Itajaí/SC
A32: 5 | B32: 2cinco4 Edition | C32: 7698 | D32: 28 | E32: 3063 | F32: 1.52 | G32: Itajaí/SC
A33: 6 | B33: BD Jardim Campeche | C33: 3633 | D33: 6 | E33: 0 | F33: 0 | G33: Florianópolis/SC

Sheet RESUMO
A1: RESUMO EXECUTIVO
A3: Projeto | B3: =DADOS!B4 -> Maison Beach 2 Residence
A4: Localização | B4: =DADOS!B6&"/"&DADOS!B7 -> Bombinhas/SC
A5: Área Construída (m²) | B5: =DADOS!B14 -> 12879.93
A6: Unidades Residenciais | B6: =DADOS!B19 -> 56
A8: RESULTADO
A9: R$/m² AC Total | B9: =PARAMÉTRICO!C23 -> 3302
A10: Custo Total (R$) | B10: =PARAMÉTRICO!D23 -> 46782482
A11: CUBs Equivalentes | B11: =PARAMÉTRICO!C26 -> 3302
A12: Custo por Unidade (R$/UR) | B12: =PARAMÉTRICO!C29 -> 835401.46
A13: AC/UR (m²/un) | B13: =PARAMÉTRICO!C30 -> 229.99875
A16: COMPOSIÇÃO DO CUSTO (TOP 5 MACROGRUPOS)
A17: Macrogrupo | B17: R$/m² | C17: % do Total | D17: Valor (R$)
A18: Supraestrutura | B18: =PARAMÉTRICO!C9 -> 145 | C18: =PARAMÉTRICO!E9 -> 0.04391278 | D18: =PARAMÉTRICO!D9 -> 2054348.8
A19: Gerenciamento | B19: =PARAMÉTRICO!C5 -> 450 | C19: =PARAMÉTRICO!E5 -> 0.13628104 | D19: =PARAMÉTRICO!D5 -> 6375565.3
A20: Instalações | B20: =PARAMÉTRICO!C11 -> 340 | C20: =PARAMÉTRICO!E11 -> 0.1029679 | D20: =PARAMÉTRICO!D11 -> 4817093.8
A21: Esquadrias | B21: =PARAMÉTRICO!C18 -> 211 | C21: =PARAMÉTRICO!E18 -> 0.063900666 | D21: =PARAMÉTRICO!D18 -> 2989431.8
A22: Pisos e Pavimentações | B22: =PARAMÉTRICO!C16 -> 133 | C22: =PARAMÉTRICO!E16 -> 0.040278619 | D22: =PARAMÉTRICO!D16 -> 1884333.8
A25: NOTAS
A26: • Valores em R$/m² AC incluem BDI de 10%
A27: • Benchmark baseado em 6 projetos similares (7.000-12.900 m² AC) em SC
A28: • Para ajustar: altere os R$/m² na aba PARAMÉTRICO (células azuis)
A29: • Perguntas do briefing (aba DADOS) impactam diretamente nos índices
A30: • Fórmula universal: Valor = R$/m² × AC × BDI
A31: • Status ⚠ indica valor >15% acima do benchmark; ↓ indica >15% abaixo
