Workbook

Sheet PAINEL
A1: PAINEL EXECUTIVO — ORÇAMENTO PARAMÉTRICO
A3: 1. RESUMO EXECUTIVO
A4: R$/m² (Custo/AC) | B4: =DADOS_PROJETO!B18
A5: Custo Total (R$) | B5: =DADOS_PROJETO!B17
A6: R$/UR | B6: =IF(DADOS_PROJETO!B8>0,DADOS_PROJETO!B17/DADOS_PROJETO!B8,0)
A7: Área Construída (m²) | B7: =DADOS_PROJETO!B7
A9: 2. CUSTO POR MACROGRUPO
A10: Macrogrupo | B10: R$/m² Param. | C10: Min Mercado | D10: Max Mercado | E10: Status/Ação
A11: Gerenciamento | B11: =CUSTOS_MACROGRUPO!D4 | C11: =CUSTOS_MACROGRUPO!F4 | D11: =CUSTOS_MACROGRUPO!G4 | E11: =IF(B11=0,"—",IF(B11>D11,"✗ Alto - Revisar escopo",IF(B11<C11,"⚠ Baixo - Verificar completude","✓ OK - Dentro da faixa")))
A12: Mov. Terra | B12: =CUSTOS_MACROGRUPO!D5 | C12: =CUSTOS_MACROGRUPO!F5 | D12: =CUSTOS_MACROGRUPO!G5 | E12: =IF(B12=0,"—",IF(B12>D12,"✗ Alto - Revisar escopo",IF(B12<C12,"⚠ Baixo - Verificar completude","✓ OK - Dentro da faixa")))
A13: Infraestrutura | B13: =CUSTOS_MACROGRUPO!D6 | C13: =CUSTOS_MACROGRUPO!F6 | D13: =CUSTOS_MACROGRUPO!G6 | E13: =IF(B13=0,"—",IF(B13>D13,"✗ Alto - Revisar escopo",IF(B13<C13,"⚠ Baixo - Verificar completude","✓ OK - Dentro da faixa")))
A14: Supraestrutura | B14: =CUSTOS_MACROGRUPO!D7 | C14: =CUSTOS_MACROGRUPO!F7 | D14: =CUSTOS_MACROGRUPO!G7 | E14: =IF(B14=0,"—",IF(B14>D14,"✗ Alto - Revisar escopo",IF(B14<C14,"⚠ Baixo - Verificar completude","✓ OK - Dentro da faixa")))
A15: Alvenaria | B15: =CUSTOS_MACROGRUPO!D8 | C15: =CUSTOS_MACROGRUPO!F8 | D15: =CUSTOS_MACROGRUPO!G8 | E15: =IF(B15=0,"—",IF(B15>D15,"✗ Alto - Revisar escopo",IF(B15<C15,"⚠ Baixo - Verificar completude","✓ OK - Dentro da faixa")))
A16: Instalações | B16: =CUSTOS_MACROGRUPO!D9 | C16: =CUSTOS_MACROGRUPO!F9 | D16: =CUSTOS_MACROGRUPO!G9 | E16: =IF(B16=0,"—",IF(B16>D16,"✗ Alto - Revisar escopo",IF(B16<C16,"⚠ Baixo - Verificar completude","✓ OK - Dentro da faixa")))
A17: Sist. Especiais | B17: =CUSTOS_MACROGRUPO!D10 | C17: =CUSTOS_MACROGRUPO!F10 | D17: =CUSTOS_MACROGRUPO!G10 | E17: =IF(B17=0,"—",IF(B17>D17,"✗ Alto - Revisar escopo",IF(B17<C17,"⚠ Baixo - Verificar completude","✓ OK - Dentro da faixa")))
A18: Impermeabilização | B18: =CUSTOS_MACROGRUPO!D11 | C18: =CUSTOS_MACROGRUPO!F11 | D18: =CUSTOS_MACROGRUPO!G11 | E18: =IF(B18=0,"—",IF(B18>D18,"✗ Alto - Revisar escopo",IF(B18<C18,"⚠ Baixo - Verificar completude","✓ OK - Dentro da faixa")))
A19: Rev. Int. Parede | B19: =CUSTOS_MACROGRUPO!D12 | C19: =CUSTOS_MACROGRUPO!F12 | D19: =CUSTOS_MACROGRUPO!G12 | E19: =IF(B19=0,"—",IF(B19>D19,"✗ Alto - Revisar escopo",IF(B19<C19,"⚠ Baixo - Verificar completude","✓ OK - Dentro da faixa")))
A20: Teto | B20: =CUSTOS_MACROGRUPO!D13 | C20: =CUSTOS_MACROGRUPO!F13 | D20: =CUSTOS_MACROGRUPO!G13 | E20: =IF(B20=0,"—",IF(B20>D20,"✗ Alto - Revisar escopo",IF(B20<C20,"⚠ Baixo - Verificar completude","✓ OK - Dentro da faixa")))
A21: Pisos | B21: =CUSTOS_MACROGRUPO!D14 | C21: =CUSTOS_MACROGRUPO!F14 | D21: =CUSTOS_MACROGRUPO!G14 | E21: =IF(B21=0,"—",IF(B21>D21,"✗ Alto - Revisar escopo",IF(B21<C21,"⚠ Baixo - Verificar completude","✓ OK - Dentro da faixa")))
A22: Pintura | B22: =CUSTOS_MACROGRUPO!D15 | C22: =CUSTOS_MACROGRUPO!F15 | D22: =CUSTOS_MACROGRUPO!G15 | E22: =IF(B22=0,"—",IF(B22>D22,"✗ Alto - Revisar escopo",IF(B22<C22,"⚠ Baixo - Verificar completude","✓ OK - Dentro da faixa")))
... A27: Imprevistos | B27: =CUSTOS_MACROGRUPO!D20 | C27: =CUSTOS_MACROGRUPO!F20 | D27: =CUSTOS_MACROGRUPO!G20 | E27: =IF(B27=0,"—",IF(B27>D27,"✗ Alto - Revisar escopo",IF(B27<C27,"⚠ Baixo - Verificar completude","✓ OK - Dentro da faixa")))
A29: 3. INDICADORES DE PRODUTO
A30: Indicador | B30: Valor | C30: Faixa Benchmark | D30: Status
A31: CA (Coef. Aproveitamento) | B31: =IF(DADOS_PROJETO!B14>0,DADOS_PROJETO!B7/DADOS_PROJETO!B14,0) | C31: 0.80 - 3.50 | D31: —
A32: AC/UR (m²) | B32: =IF(DADOS_PROJETO!B8>0,DADOS_PROJETO!B7/DADOS_PROJETO!B8,0) | C32: 60 - 150 | D32: —
A33: Vagas/UR | B33: =IF(DADOS_PROJETO!B8>0,DADOS_PROJETO!B13/DADOS_PROJETO!B8,0) | C33: 1.0 - 2.5 | D33: —
A34: UR/Elevador | B34: =IF(DADOS_PROJETO!B12>0,DADOS_PROJETO!B8/DADOS_PROJETO!B12,0) | C34: 20 - 40 | D34: —
A35: Pvtos Tipo/Total | B35: =IF(DADOS_PROJETO!B9>0,DADOS_PROJETO!B10/DADOS_PROJETO!B9,0) | C35: 0.30 - 0.60 | D35: —
A36: N° Pavimentos | B36: =DADOS_PROJETO!B9 | C36: 5 - 25 | D36: —
A37: R$/m² | B37: =DADOS_PROJETO!B18 | C37: 3500 - 5500 | D37: —
A38: R$/UR | B38: =IF(DADOS_PROJETO!B8>0,DADOS_PROJETO!B17/DADOS_PROJETO!B8,0) | C38: 250k - 650k | D38: —
A40: 4. DECISÕES DO BRIEFING
A41: Decisão | B41: Escolha | C41: Impacto | D41: Alternativa | E41: Economia Est.
A42: Tipo de Laje | B42: =BRIEFING!C6 | C42: Estrutura + Custo | D42: Ver ÍNDICES | E42: Variável
A43: Padrão Acabamento | B43: =BRIEFING!C10 | C43: Acabamentos | D43: Standard/Alto/Super Alto | E43: 10-30%
A44: Fachada | B44: =BRIEFING!C16 | C44: Estética + Custo | D44: Simples/Intermediária/Complexa | E44: 15-40%
A45: Pé Direito | B45: =BRIEFING!C14 | C45: Estrutura + Vedação | D45: 2.60m / 2.80m / 3.00m | E45: 5-10%
A46: Sistema de Elevadores | B46: =BRIEFING!C20 | C46: Instalações | D46: Convencional/Alta Performance | E46: 3-8%
A48: 5. POSICIONAMENTO (Projetos Referência)
A49: Projeto | B49: AC (m²) | C49: R$/m² | D49: CUB Ratio | E49: Status
...

Sheet BRIEFING
A1: BRIEFING — PARÂMETROS DE CALIBRAÇÃO
A2: Respostas ajustam automaticamente os custos via fatores multiplicadores
A3: # | B3: Parâmetro | C3: Resposta | D3: Impacto | E3: Macrogrupo(s) | F3: Fator | G3: Notas
A4: ESTRUTURA E FUNDAÇÃO
A5: 1 | B5: Tipo de Fundação | C5: Hélice contínua | D5: Profunda = base. Sapata ~30% menos | E5: 3-Infraestrutura | F5: =IF(C5="Hélice contínua",1.00,IF(C5="Estaca Franki",1.05,IF(C5="Tubulão",0.85,IF(C5="Sapata/Radier",0.70,IF(C5="Estaca raiz",1.15,1.00)))))
A6: 2 | B6: Tipo de Laje | C6: Cubetas (nervurada) | D6: ~15% na supraestrutura | E6: 4-Supraestrutura | F6: =IF(C6="Cubetas (nervurada)",1.00,IF(C6="Protendida",1.08,IF(C6="Maciça",1.15,IF(C6="Mista",1.03,1.00))))
A7: 3 | B7: Tem Contenção? | C7: Não | D7: 5-8% do custo total | E7: 3-Infraestrutura | F7: =IF(C7="Não",1.00,IF(C7="Cortina de estacas",1.50,IF(C7="Muro de arrimo",1.30,IF(C7="Solo grampeado",1.20,IF(C7="Tirantes",1.40,1.00)))))
A8: 4 | B8: Nº de Subsolos | C8: 0 | D8: +R$ 200-400/m² por subsolo | E8: 2-MovTerra + 3-Infra + 6-Impermeab | F8: =IF(C8="0",1.00,IF(C8="1",1.15,IF(C8="2",1.30,IF(C8="3 ou mais",1.50,1.00))))
A9: ACABAMENTOS E PADRÃO
A10: 5 | B10: Padrão de Acabamento Geral | C10: Alto Padrão | D10: 30-40% em acabamentos e esquadrias | E10: 10-Rev.Parede + 12-Pisos + 14-Esquadrias | F10: =IF(C10="Econômico",0.65,IF(C10="Standard",0.80,IF(C10="Alto Padrão",1.00,IF(C10="Super Alto Padrão",1.40,IF(C10="Luxo",1.80,1.00)))))
A11: 6 | B11: Tipo de Esquadria | C11: Alumínio anodizado | D11: Esquadrias = 8-12% do custo total | E11: 14-Esquadrias | F11: =IF(C11="Alumínio anodizado",1.00,IF(C11="Alumínio pintura eletrostática",1.10,IF(C11="PVC",1.15,IF(C11="Alto desempenho",1.35,1.00))))
A12: 7 | B12: Piso Predominante | C12: Porcelanato | D12: Mármore +60% vs porcelanato | E12: 12-Pisos | F12: =IF(C12="Porcelanato",1.00,IF(C12="Cerâmica",0.80,IF(C12="Vinílico",0.85,IF(C12="Porcelanato importado",1.25,IF(C12="Mármore/Granito",1.60,1.00)))))
A13: 8 | B13: Vedação Interna | C13: Alvenaria | D13: Drywall +80% no grupo | E13: 5-Alvenaria | F13: =IF(C13="Alvenaria",1.00,IF(C13="Drywall",1.80,IF(C13="Misto",1.35,1.00)))
A14: 9 | B14: Tipo de Forro | C14: Gesso com negativo | D14: Gesso trabalhado +40% | E14: 11-Teto | F14: =IF(C14="Estucamento simples",0.70,IF(C14="Gesso liso",0.85,IF(C14="Gesso com negativo",1.00,IF(C14="Gesso + sanca",1.25,IF(C14="Forro mineral",1.10,1.00)))))
A15: FACHADA E COBERTURA
A16: 10 | B16: Tipo de Fachada | C16: Textura + pintura | D16: Pele de vidro 2.5x mais cara | E16: 16-Fachada | F16: =IF(C16="Textura + pintura",1.00,IF(C16="Cerâmica/Pastilha",1.40,IF(C16="ACM",1.80,IF(C16="Pele de vidro",2.50,IF(C16="Misto (pintura + cerâmica)",1.25,1.00)))))
A17: 11 | B17: MO Fachada | C17: Empreitada | D17: +20% em empreitada | E17: 16-Fachada | F17: =IF(C17="Equipe própria",1.00,IF(C17="Empreitada",1.20,1.00))
A18: 12 | B18: Cobertura Habitável? | C18: Não | D18: Cobertura habitável 5-10x mais cara | E18: 17-Complementares | F18: =IF(C18="Não",1.00,IF(C18="Básica (deck e pergolado)",1.12,IF(C18="Completa (piscina e lazer)",1.35,1.00)))
A19: INSTALAÇÕES E SISTEMAS
A20: 13 | B20: Aquecimento de Água | C20: Individual gás | D20: Solar/bomba calor +12-15% | E20: 7-Instalações | F20: =IF(C20="Individual gás",1.00,IF(C20="Central gás",1.08,IF(C20="Solar",1.12,IF(C20="Bomba de calor",1.15,IF(C20="Sem aquecimento",0.95,1.00)))))
A21: 14 | B21: Nível de Automação | C21: Básico (interfonia + CFTV) | D21: Automação completa +R$ 80-150/m² | E21: 8-Sist. Especiais | F21: =IF(C21="Mínimo (só interfonia)",0.80,IF(C21="Básico (interfonia + CFTV)",1.00,IF(C21="Completo (automação + acesso)",1.30,IF(C21="Premium (smart building)",1.60,1.00))))
A22: 15 | B22: Geração de Energia | C22: Sem | D22: Painéis solares +R$ 50-120/m² | E22: 8-Sist. Especiais | F22: =IF(C22="Sem",1.00,IF(C22="Painéis solares (comum)",1.10,IF(C22="Painéis solares (completo)",1.20,1.00)))
A23: ÁREAS COMUNS E LAZER
A24: 16 | B24: Nível de Lazer | C24: Completo | D24: Premium: 2000-3500 R$/m² de lazer | E24: 17-Complementares + 8-Sist.Especiais | F24: =IF(C24="Básico (salão + churrasq.)",0.75,IF(C24="Completo (piscina + academia)",1.00,IF(C24="Premium (spa + rooftop)",1.30,1.00)))
A25: 17 | B25: Paisagismo | C25: Elaborado | D25: Premium: R$ 150-350/m² área externa | E25: 17-Complementares | F25: =IF(C25="Sem",0.90,IF(C25="Básico",0.95,IF(C25="Elaborado",1.00,IF(C25="Premium (autoral)",1.15,1.00))))
A26: 18 | B26: Mobiliário Áreas Comuns | C26: Completo | D26: Decoração autoral: R$ 800-2500/m² | E26: 17-Complementares | F26: =IF(C26="Sem (entrega bruta)",0.85,IF(C26="Básico",0.92,IF(C26="Completo",1.00,IF(C26="Decorado (autoral)",1.20,1.00))))
A27: GESTÃO E PRAZO
A28: 19 | B28: Prazo de Obra | C28: 42 meses | D28: +10-15% a cada 6 meses extras | E28: 1-Gerenciamento | F28: =IF(C28="18 meses",0.65,IF(C28="24 meses",0.82,IF(C28="30 meses",1.00,IF(C28="36 meses",1.12,IF(C28="42 meses",1.22,IF(C28="48 meses",1.40,1.00))))))
A29: 20 | B29: Região | C29: Litoral SC | D29: Capital +8-25% vs interior -10% | E29: 1-Gerenciamento (MO regional) | F29: =IF(C29="Interior SC",0.90,IF(C29="Litoral SC",1.00,IF(C29="Capital (Floripa)",1.08,IF(C29="Litoral SP",1.15,IF(C29="Capital (SP/RJ)",1.25,IF(C29="Outras capitais",1.10,1.00))))))
A30: INFRAESTRUTURA TÉCNICA
A31: 21 | B31: Gerador? | C31: Não | D31: Gerador +R$ 30-50/m² em sist. especiais | E31: 8-Sist. Especiais | F31: =IF(C31="Sim",1.15,1.00)
A32: 22 | B32: Subestação? | C32: Não | D32: Subestação +R$ 20-40/m² em sist. especiais | E32: 8-Sist. Especiais | F32: =IF(C32="Sim",1.10,1.00)
A33: 23 | B33: Placas Fotovoltaicas? | C33: Não | D33: Fotovoltaicas +R$ 50-120/m² em sist. especiais | E33: 8-Sist. Especiais | F33: =IF(C33="Sim",1.10,1.00)
A34: 24 | B34: Infra Carro Elétrico? | C34: Não | D34: Infraestrutura elétrica +R$ 15-25/m² | E34: 7-Instalações | F34: =IF(C34="Sim",1.05,1.00)
A35: 25 | B35: Pressurização Escada? | C35: Não | D35: Sistema pressurização +R$ 25-40/m² | E35: 7-Instalações | F35: =IF(C35="Sim",1.08,1.00)
A37: RESUMO DOS FATORES
A38: Fator Global Estimado (média dos 25 parâmetros) | F38: =AVERAGE(F5,F6,F7,F8,F10,F11,F12,F13,F14,F16,F17,F18,F20,F21,F22,F24,F25,F26,F28,F29,F31,F32,F33,F34,F35)
A39: R$/m² Estimado (R$/m² base × Fator Global) | F39: =CUSTOS_MACROGRUPO!D21*F38 | G39: R$/m²
A40: Custo Total Estimado (R$/m² × Área Construída) | F40: =F39*DADOS_PROJETO!B7 | G40: R$

Sheet ÍNDICES
A1: ÍNDICES PARAMÉTRICOS — REFERÊNCIA TÉCNICA
A3: ÍNDICES POR TIPO DE LAJE
A4: Parâmetro | B4: Maciça | C4: Cubetas | D4: Cub.Protendida | E4: Treliçada | F4: Protendida
A5: Jogos de Fôrma | B5: 12-15 | C5: 10-12 | D5: 9-11 | E5: 13-16 | F5: 8-10
A6: Montagem Fôrma (m²/AC) | B6: 3.2-3.8 | C6: 2.8-3.4 | D6: 2.5-3.0 | E6: 3.5-4.2 | F6: 2.3-2.8
A7: Concreto (m³/AC) | B7: 0.28-0.35 | C7: 0.22-0.28 | D7: 0.20-0.26 | E7: 0.30-0.38 | F7: 0.18-0.24
A8: Armadura (kg/m³) | B8: 100-130 | C8: 85-110 | D8: 75-95 | E8: 110-140 | F8: 65-85
A9: MO Estrutura (R$/AC) | B9: 280-350 | C9: 250-320 | D9: 230-300 | E9: 300-380 | F9: 210-280
A10: Supraestrutura R$/m² | B10: 750-950 | C10: 650-850 | D10: 600-800 | E10: 800-1000 | F10: 550-750
A12: ÍNDICES GERAIS
A13: Parâmetro | B13: Unidade | C13: Mín | D13: Típico | E13: Máx | F13: Observações
A14: Estacas | B14: m/m²AC | C14: 0.15 | D14: 0.20 | E14: 0.30 | F14: Varia por solo
A15: Alvenaria | B15: m²/m²AC | C15: 1.8 | D15: 2.2 | E15: 2.8 | F15: Inclui shafts
A16: Contrapiso | B16: m²/m²AC | C16: 0.85 | D16: 0.95 | E16: 1.05 | F16: Sobre laje
A17: Forro de Gesso | B17: m²/m²AC | C17: 0.70 | D17: 0.85 | E17: 0.95 | F17: Áreas nobres
A18: Esquadrias Alumínio | B18: m²/m²AC | C18: 0.15 | D18: 0.20 | E18: 0.30 | F18: Varanda aumenta
A19: Esquadrias PVC | B19: m²/m²AC | C19: 0.12 | D19: 0.18 | E19: 0.25 | F19: Alternativa
A20: Louças/Metais | B20: Jogo/UR | C20: 1.8 | D20: 2.2 | E20: 2.8 | F20: Padrão médio
A21: Ponto Elétrico | B21: Pts/m²AC | C21: 8 | D21: 10 | E21: 13 | F21: Inclui lógica
A22: Ponto Hidráulico | B22: Pts/m²AC | C22: 4 | D22: 5 | E22: 7 | F22: AF+AQ+ES+AG
A23: Elevador | B23: UR/Elev | C23: 20 | D23: 28 | E23: 40 | F23: Baixa: <25, Alta: >35
A25: VERBAS PARAMÉTRICAS (R$/m² AC)
A26: Item | B26: Standard | C26: Alto | D26: Super Alto | E26: Base | F26: Observações
A27: Pintura Interna | B27: 35-45 | C27: 50-65 | D27: 75-95 | E27: m²AC | F27: Látex/Acrílica
A28: Pintura Externa | B28: 25-35 | C28: 40-55 | D28: 60-80 | E28: m²AC | F28: Acrílica/Textura
A29: Rev. Parede Interna | B29: 120-150 | C29: 180-230 | D29: 280-350 | E29: m²AC | F29: Gesso/Porcelanato
A30: Rev. Parede Externa | B30: 80-110 | C30: 130-170 | D30: 200-260 | E30: m²AC | F30: Pastilha/ACM
A31: Rodapés | B31: 8-12 | C31: 15-20 | D31: 25-35 | E31: m²AC | F31: MDF/Porcelanato
A32: Soleiras | B32: 5-8 | C32: 10-15 | D32: 18-25 | E32: m²AC | F32: Mármore/Granito
A33: Paisagismo | B33: 15-25 | C33: 35-50 | D33: 65-90 | E33: m²AC | F33: Externo+Interno
A34: Sinalização | B34: 3-5 | C34: 8-12 | D34: 15-22 | E34: m²AC | F34: Placas+Numeração
A35: Playground | B35: 8-12 | C35: 18-25 | D35: 35-50 | E35: m²AC | F35: Se houver área lazer
A36: Deck/Pergolado | B36: 40-60 | C36: 80-110 | D36: 140-180 | E36: m²Deck | F36: Madeira/Composto
A38: FATORES DE CUSTO E AJUSTES
A39: Fator | B39: Valor Típico | C39: Faixa | D39: Aplicação | E39: Observações
A40: BDI | B40: 1.10 | C40: 1.08 - 1.15 | D40: Todos os custos | E40: Lucro + impostos + risco
A41: Perdas Concreto | B41: 1.05 | C41: 1.03 - 1.08 | D41: Volume concreto | E41: Sobra + geometria
A42: Perdas Argamassa | B42: 1.15 | C42: 1.10 - 1.25 | D42: Revestimentos | E42: Espessura irregular
A43: Empolamento Terra | B43: 1.25 | C43: 1.20 - 1.35 | D43: Movimento terra | E43: Solo solto vs compactado
A44: Fator Dificuldade | B44: 1.00-1.20 | C44: — | D44: MO difícil acesso | E44: Encosta, centro urbano
...

Sheet ANÁLISE_PRODUTO
A1: ANÁLISE DO PRODUTO — BENCHMARK E DIAGNÓSTICO
A3: Projeto | B3: Cidade | C3: AC m² | D3: UR | E3: NP | F3: VAG/UR | G3: AC/UR m² | H3: Padrão
A4: Maison Beach (ESTE) | B4: Bombinhas/SC | C4: =DADOS_PROJETO!B7 | D4: =DADOS_PROJETO!B8 | E4: =DADOS_PROJETO!B9 | F4: =IF(DADOS_PROJETO!B8>0,DADOS_PROJETO!B13/DADOS_PROJETO!B8,0) | G4: =IF(DADOS_PROJETO!B8>0,DADOS_PROJETO!B7/DADOS_PROJETO!B8,0) | H4: =DADOS_PROJETO!E11
A5: EZE Canto Grande | B5: Bombinhas/SC | C5: 1612 | D5: 8 | E5: 7 | F5: 2 | G5: 201.4 | H5: Alto
A6: EZE Eilat | B6: Bombinhas/SC | C6: 1767 | D6: 8 | E6: 7 | F6: 1.5 | G6: 220.9 | H6: Alto
A7: By Seasons | B7: Itapema/SC | C7: 6349 | D7: 54 | E7: 18 | F7: 1.2 | G7: 117.6 | H7: Alto
A8: ETR Mediterrâneo | B8: Itapema/SC | C8: 4617 | D8: 20 | E8: 13 | F8: 1.5 | G8: 230.9 | H8: Alto
A9: Meia Praia 298 | B9: Itapema/SC | C9: 10618 | D9: 41 | E9: 26 | F9: 1.5 | G9: 259 | H9: Alto
A10: Lorenzo Gabriel | B10: Itapema/SC | C10: 8525 | D10: 73 | E10: 19 | F10: 1.2 | G10: 116.8 | H10: Alto
A11: Ferrazzo Perequê | B11: Porto Belo/SC | C11: 5576 | D11: 38 | E11: 15 | F11: 1.3 | G11: 146.7 | H11: Alto
A12: Kirchner West | B12: Itapema/SC | C12: 10723 | D12: 44 | E12: 21 | F12: 2.5 | G12: 243.7 | H12: Alto
A13: MÉDIA REFERÊNCIAS | C13: =AVERAGE(C5:C12) | D13: =AVERAGE(D5:D12) | E13: =AVERAGE(E5:E12) | F13: =AVERAGE(F5:F12) | G13: =AVERAGE(G5:G12)
A16: Índice | B16: Este Projeto | C16: Média Mercado | D16: Faixa Min | E16: Faixa Max | F16: Status | G16: Comentário
A17: AC/UR (m²/un) | B17: =IF(DADOS_PROJETO!B8>0,DADOS_PROJETO!B7/DADOS_PROJETO!B8,0) | C17: =G13 | D17: 80 | E17: 260 | F17: =IF(B17>=D17,IF(B17<=E17,"✅ Dentro da faixa","⚠️ Acima da faixa"),"🔽 Abaixo da faixa")
A18: Vagas/UR | B18: =IF(DADOS_PROJETO!B8>0,DADOS_PROJETO!B13/DADOS_PROJETO!B8,0) | C18: =F13 | D18: 1 | E18: 2.5 | F18: =IF(B18>=D18,IF(B18<=E18,"✅ Dentro da faixa","⚠️ Acima da faixa"),"🔽 Abaixo da faixa")
A19: UR/Elevador | B19: =IF(DADOS_PROJETO!B12>0,DADOS_PROJETO!B8/DADOS_PROJETO!B12,0) | C19: =D13/AVERAGE(E5:E12)*AVERAGE(D5:D12) | D19: 15 | E19: 50 | F19: =IF(B19>=D19,IF(B19<=E19,"✅ Dentro da faixa","⚠️ Acima da faixa"),"🔽 Abaixo da faixa")
A20: CA (Coef. Aprov.) | B20: =IF(DADOS_PROJETO!B14>0,DADOS_PROJETO!B7/DADOS_PROJETO!B14,0) | C20: =AVERAGE(C5:C12)/1000 | D20: 2 | E20: 10 | F20: =IF(B20>=D20,IF(B20<=E20,"✅ Dentro da faixa","⚠️ Acima da faixa"),"🔽 Abaixo da faixa")
A21: Depósitos/UR | C21: 0.8 | D21: 0.5 | E21: 1 | F21: =IF(B21>=D21,IF(B21<=E21,"✅ Dentro da faixa","⚠️ Acima da faixa"),"🔽 Abaixo da faixa")
A22: % Área Privativa | C22: 0.45 | D22: 0.35 | E22: 0.55 | F22: =IF(B22>=D22,IF(B22<=E22,"✅ Dentro da faixa","⚠️ Acima da faixa"),"🔽 Abaixo da faixa")
A23: Área Média 2 Suítes | C23: 85 | D23: 60 | E23: 120 | F23: =IF(B23>=D23,IF(B23<=E23,"✅ Dentro da faixa","⚠️ Acima da faixa"),"🔽 Abaixo da faixa")
A24: Área Média 3 Suítes | C24: 110 | D24: 85 | E24: 160 | F24: =IF(B24>=D24,IF(B24<=E24,"✅ Dentro da faixa","⚠️ Acima da faixa"),"🔽 Abaixo da faixa")
A25: Área Média Cobertura | C25: 180 | D25: 130 | E25: 300 | F25: =IF(B25>=D25,IF(B25<=E25,"✅ Dentro da faixa","⚠️ Acima da faixa"),"🔽 Abaixo da faixa")
A28: DIAGNÓSTICO DO PRODUTO
A29: Posicionamento de mercado | B29: Alto
A30: Público-alvo | B30: Famílias 2ª moradia praia
A31: Diferencial competitivo | B31: Localização Canto Grande + lazer completo
A32: Risco principal | B32: Escala (56 UR em Bombinhas)
A33: Observações

Sheet DADOS_PROJETO
A1: DADOS DO PROJETO
A2: Cartesian Engenharia — Orçamento Paramétrico
A4: Nome do Projeto | B4: Maison Beach | D4: Prazo (meses) | E4: 42
A5: Código | B5: CTN-NOB-MSB | D5: Data-base | E5: Dez/2023
A6: Cidade / UF | B6: Bombinhas/SC | D6: CUB Data-base (R$/m²) | E6: 2752.67
A7: Área Construída - AC (m²) | B7: 12879.93 | D7: CUB Atual (R$/m²) | E7: 3050
A8: Unidades Residenciais (UR) | B8: 58 | D8: Fator de Atualização | E8: =E7/E6
A9: Nº Pavimentos (NP) | B9: 9 | D9: Tipo de Laje | E9: Nervurada
A10: Nº Pav. Tipo (NPT) | B10: 4 | D10: Tipo de Fundação | E10: Hélice contínua
A11: Nº Pav. Garagem (NPG) | B11: 2 | D11: Padrão de Acabamento | E11: Alto
A12: Elevadores | B12: 2
A13: Vagas de Garagem | B13: 92
A14: Área do Terreno - AT (m²) | B14: 3702.26
A16: RESUMO GERAL
A17: Custo Total Ajustado (R$) | B17: =CUSTOS_MACROGRUPO!J21
A18: R$/m² (Custo/AC) | B18: =IF(B7>0,B17/B7,0)
A19: CUB Ratio | B19: =IF(E7>0,B18/E7,0)
A21: DADOS COMPLEMENTARES
A22: APT - Área Projeção Torre (m²) | B22: 1795
A23: PPT - Perímetro Projeção Torre (m) | B23: 191.4
A24: APE - Área Projeção Embasamento (m²) | B24: 2400
A25: PPE - Perímetro Projeção Embasamento (m) | B25: 208
A26: NPD - Pav. Tipo Diferenciados | B26: 1
A27: Área de Lazer (m²)
A28: BDI - Bonif. Desp. Indiretas | B28: 1.1

Sheet CUSTOS_MACROGRUPO
A1: CUSTOS POR MACROGRUPO
A2: # | B2: Macrogrupo | C2: Valor Base Dez/23 (R$) | D2: R$/m² | E2: % | F2: Faixa Min (R$/m²) | G2: Faixa Max (R$/m²) | H2: Status | I2: Fator Briefing | J2: Valor Ajustado (R$)
A3: 1 | B3: Gerenciamento Técnico/Admin | C3: 4783063.3 | D3: =IF(DADOS_PROJETO!B7>0,J3/DADOS_PROJETO!B7,0) | E3: =IF(J$21>0,J3/J$21,0) | F3: 194 | G3: 475 | H3: =IF(C3=0,"",IF(AND(D3>=F3,D3<=G3),"✅ OK",IF(OR(D3<F3*0.85,D3>G3*1.15),"🔴 CRÍTICO","⚠️ ATENÇÃO"))) | I3: =BRIEFING!F28*BRIEFING!F29 | J3: =C3*DADOS_PROJETO!$E$8*I3
A4: 2 | B4: Movimentação de Terra | C4: 158777.73 | D4: =IF(DADOS_PROJETO!B7>0,J4/DADOS_PROJETO!B7,0) | E4: =IF(J$21>0,J4/J$21,0) | F4: 9 | G4: 76 | H4: =IF(C4=0,"",IF(AND(D4>=F4,D4<=G4),"✅ OK",IF(OR(D4<F4*0.85,D4>G4*1.15),"🔴 CRÍTICO","⚠️ ATENÇÃO"))) | I4: =BRIEFING!F8 | J4: =C4*DADOS_PROJETO!$E$8*I4
A5: 3 | B5: Infraestrutura | C5: 2904485 | D5: =IF(DADOS_PROJETO!B7>0,J5/DADOS_PROJETO!B7,0) | E5: =IF(J$21>0,J5/J$21,0) | F5: 172 | G5: 249 | H5: =IF(C5=0,"",IF(AND(D5>=F5,D5<=G5),"✅ OK",IF(OR(D5<F5*0.85,D5>G5*1.15),"🔴 CRÍTICO","⚠️ ATENÇÃO"))) | I5: =BRIEFING!F5*BRIEFING!F7*BRIEFING!F8 | J5: =C5*DADOS_PROJETO!$E$8*I5
A6: 4 | B6: Supraestrutura | C6: 8919704.7 | D6: =IF(DADOS_PROJETO!B7>0,J6/DADOS_PROJETO!B7,0) | E6: =IF(J$21>0,J6/J$21,0) | F6: 0 | G6: 766 | H6: =IF(C6=0,"",IF(AND(D6>=F6,D6<=G6),"✅ OK",IF(OR(D6<F6*0.85,D6>G6*1.15),"🔴 CRÍTICO","⚠️ ATENÇÃO"))) | I6: =BRIEFING!F6 | J6: =C6*DADOS_PROJETO!$E$8*I6
A7: 5 | B7: Alvenaria | C7: 1915290.1 | D7: =IF(DADOS_PROJETO!B7>0,J7/DADOS_PROJETO!B7,0) | E7: =IF(J$21>0,J7/J$21,0) | F7: 133 | G7: 262 | H7: =IF(C7=0,"",IF(AND(D7>=F7,D7<=G7),"✅ OK",IF(OR(D7<F7*0.85,D7>G7*1.15),"🔴 CRÍTICO","⚠️ ATENÇÃO"))) | I7: =BRIEFING!F13 | J7: =C7*DADOS_PROJETO!$E$8*I7
A8: 6 | B8: Impermeabilização | C8: 640539.77 | D8: =IF(DADOS_PROJETO!B7>0,J8/DADOS_PROJETO!B7,0) | E8: =IF(J$21>0,J8/J$21,0) | F8: 39 | G8: 73 | H8: =IF(C8=0,"",IF(AND(D8>=F8,D8<=G8),"✅ OK",IF(OR(D8<F8*0.85,D8>G8*1.15),"🔴 CRÍTICO","⚠️ ATENÇÃO"))) | I8: =AVERAGE(BRIEFING!F8,BRIEFING!F18) | J8: =C8*DADOS_PROJETO!$E$8*I8
A9: 7 | B9: Instalações (agrupado) | C9: 4594514.5 | D9: =IF(DADOS_PROJETO!B7>0,J9/DADOS_PROJETO!B7,0) | E9: =IF(J$21>0,J9/J$21,0) | F9: 335 | G9: 393 | H9: =IF(C9=0,"",IF(AND(D9>=F9,D9<=G9),"✅ OK",IF(OR(D9<F9*0.85,D9>G9*1.15),"🔴 CRÍTICO","⚠️ ATENÇÃO"))) | I9: =BRIEFING!F20*BRIEFING!F34*BRIEFING!F35 | J9: =C9*DADOS_PROJETO!$E$8*I9
A10: 8 | B10: Sistemas Especiais | C10: 2404559 | D10: =IF(DADOS_PROJETO!B7>0,J10/DADOS_PROJETO!B7,0) | E10: =IF(J$21>0,J10/J$21,0) | F10: 159 | G10: 237 | H10: =IF(C10=0,"",IF(AND(D10>=F10,D10<=G10),"✅ OK",IF(OR(D10<F10*0.85,D10>G10*1.15),"🔴 CRÍTICO","⚠️ ATENÇÃO"))) | I10: =AVERAGE(BRIEFING!F21,BRIEFING!F22,BRIEFING!F24)*BRIEFING!F31*BRIEFING!F32*BRIEFING!F33 | J10: =C10*DADOS_PROJETO!$E$8*I10
A11: 9 | B11: Climatização (incluso em Sist. Especiais) | C11: 0 | D11: =IF(DADOS_PROJETO!B7>0,J11/DADOS_PROJETO!B7,0) | E11: =IF(J$21>0,J11/J$21,0) | F11: 0 | G11: 0 | H11: =IF(C11=0,"",IF(AND(D11>=F11,D11<=G11),"✅ OK",IF(OR(D11<F11*0.85,D11>G11*1.15),"🔴 CRÍTICO","⚠️ ATENÇÃO"))) | I11: =1 | J11: =C11*DADOS_PROJETO!$E$8*I11
A12: 10 | B12: Rev. Internos Parede | C12: 2213445.7 | D12: =IF(DADOS_PROJETO!B7>0,J12/DADOS_PROJETO!B7,0) | E12: =IF(J$21>0,J12/J$21,0) | F12: 109 | G12: 217 | H12: =IF(C12=0,"",IF(AND(D12>=F12,D12<=G12),"✅ OK",IF(OR(D12<F12*0.85,D12>G12*1.15),"🔴 CRÍTICO","⚠️ ATENÇÃO"))) | I12: =BRIEFING!F10 | J12: =C12*DADOS_PROJETO!$E$8*I12
A13: 11 | B13: Teto | C13: 869940.82 | D13: =IF(DADOS_PROJETO!B7>0,J13/DADOS_PROJETO!B7,0) | E13: =IF(J$21>0,J13/J$21,0) | F13: 45 | G13: 112 | H13: =IF(C13=0,"",IF(AND(D13>=F13,D13<=G13),"✅ OK",IF(OR(D13<F13*0.85,D13>G13*1.15),"🔴 CRÍTICO","⚠️ ATENÇÃO"))) | I13: =BRIEFING!F14 | J13: =C13*DADOS_PROJETO!$E$8*I13
A14: 12 | B14: Pisos | C14: 2392311.1 | D14: =IF(DADOS_PROJETO!B7>0,J14/DADOS_PROJETO!B7,0) | E14: =IF(J$21>0,J14/J$21,0) | F14: 155 | G14: 211 | H14: =IF(C14=0,"",IF(AND(D14>=F14,D14<=G14),"✅ OK",IF(OR(D14<F14*0.85,D14>G14*1.15),"🔴 CRÍTICO","⚠️ ATENÇÃO"))) | I14: =BRIEFING!F10*BRIEFING!F12 | J14: =C14*DADOS_PROJETO!$E$8*I14
A15: 13 | B15: Pintura | C15: 1944390.8 | D15: =IF(DADOS_PROJETO!B7>0,J15/DADOS_PROJETO!B7,0) | E15: =IF(J$21>0,J15/J$21,0) | F15: 109 | G15: 180 | H15: =IF(C15=0,"",IF(AND(D15>=F15,D15<=G15),"✅ OK",IF(OR(D15<F15*0.85,D15>G15*1.15),"🔴 CRÍTICO","⚠️ ATENÇÃO"))) | I15: =1 | J15: =C15*DADOS_PROJETO!$E$8*I15
A16: 14 | B16: Esquadrias | C16: 4585715 | D16: =IF(DADOS_PROJETO!B7>0,J16/DADOS_PROJETO!B7,0) | E16: =IF(J$21>0,J16/J$21,0) | F16: 284 | G16: 518 | H16: =IF(C16=0,"",IF(AND(D16>=F16,D16<=G16),"✅ OK",IF(OR(D16<F16*0.85,D16>G16*1.15),"🔴 CRÍTICO","⚠️ ATENÇÃO"))) | I16: =BRIEFING!F10*BRIEFING!F11 | J16: =C16*DADOS_PROJETO!$E$8*I16
A17: 15 | B17: Louças e Metais (incluso em Complementares) | C17: 0 | D17: =IF(DADOS_PROJETO!B7>0,J17/DADOS_PROJETO!B7,0) | E17: =IF(J$21>0,J17/J$21,0) | F17: 0 | G17: 0 | H17: =IF(C17=0,"",IF(AND(D17>=F17,D17<=G17),"✅ OK",IF(OR(D17<F17*0.85,D17>G17*1.15),"🔴 CRÍTICO","⚠️ ATENÇÃO"))) | I17: =1 | J17: =C17*DADOS_PROJETO!$E$8*I17
A18: 16 | B18: Fachada | C18: 2075062.2 | D18: =IF(DADOS_PROJETO!B7>0,J18/DADOS_PROJETO!B7,0) | E18: =IF(J$21>0,J18/J$21,0) | F18: 70 | G18: 259 | H18: =IF(C18=0,"",IF(AND(D18>=F18,D18<=G18),"✅ OK",IF(OR(D18<F18*0.85,D18>G18*1.15),"🔴 CRÍTICO","⚠️ ATENÇÃO"))) | I18: =BRIEFING!F16*BRIEFING!F17 | J18: =C18*DADOS_PROJETO!$E$8*I18
A19: 17 | B19: Complementares + Cobertura | C19: 2585902.2 | D19: =IF(DADOS_PROJETO!B7>0,J19/DADOS_PROJETO!B7,0) | E19: =IF(J$21>0,J19/J$21,0) | F19: 157 | G19: 259 | H19: =IF(C19=0,"",IF(AND(D19>=F19,D19<=G19),"✅ OK",IF(OR(D19<F19*0.85,D19>G19*1.15),"🔴 CRÍTICO","⚠️ ATENÇÃO"))) | I19: =AVERAGE(BRIEFING!F18,BRIEFING!F24,BRIEFING!F25,BRIEFING!F26) | J19: =C19*DADOS_PROJETO!$E$8*I19
A20: 18 | B20: Imprevistos | C20: 1319154 | D20: =IF(DADOS_PROJETO!B7>0,J20/DADOS_PROJETO!B7,0) | E20: =IF(J$21>0,J20/J$21,0) | F20: 54 | G20: 118 | H20: =IF(C20=0,"",IF(AND(D20>=F20,D20<=G20),"✅ OK",IF(OR(D20<F20*0.85,D20>G20*1.15),"🔴 CRÍTICO","⚠️ ATENÇÃO"))) | I20: =1 | J20: =C20*DADOS_PROJETO!$E$8*I20
A21: TOTAL | C21: =SUM(C3:C20) | D21: =IF(DADOS_PROJETO!B7>0,J21/DADOS_PROJETO!B7,0) | E21: =SUM(E3:E20) | J21: =SUM(J3:J20)
A23: CUB Ratio (R$/m² ÷ CUB ref) | C23: =IF(DADOS_PROJETO!E7>0,D21/DADOS_PROJETO!E7,0)

Sheet ESTRUTURAL
A1: ANÁLISE ESTRUTURAL
A3: CONCRETO
A4: Elemento | B4: Volume (m³) | C4: % Vol. | D4: fck (MPa) | E4: PU (R$/m³) | F4: Total (R$) | G4: R$/m²
A5: Pilares | B5: 425.04 | C5: =IF(B$9>0,B5/B$9,0) | D5: 40 | E5: 680 | F5: =B5*E5 | G5: =IF(DADOS_PROJETO!B7>0,F5/DADOS_PROJETO!B7,0)
A6: Vigas | B6: 708.4 | C6: =IF(B$9>0,B6/B$9,0) | D6: 35 | E6: 620 | F6: =B6*E6 | G6: =IF(DADOS_PROJETO!B7>0,F6/DADOS_PROJETO!B7,0)
A7: Lajes | B7: 1558.47 | C7: =IF(B$9>0,B7/B$9,0) | D7: 30 | E7: 580 | F7: =B7*E7 | G7: =IF(DADOS_PROJETO!B7>0,F7/DADOS_PROJETO!B7,0)
A8: Escadas | B8: 141.68 | C8: =IF(B$9>0,B8/B$9,0) | D8: 30 | E8: 600 | F8: =B8*E8 | G8: =IF(DADOS_PROJETO!B7>0,F8/DADOS_PROJETO!B7,0)
A9: Total Concreto | B9: =SUM(B5:B8) | C9: =1 | F9: =SUM(F5:F8) | G9: =IF(DADOS_PROJETO!B7>0,F9/DADOS_PROJETO!B7,0)
A11: AÇO
A12: Elemento | B12: Peso (kg) | C12: % Peso | D12: Taxa (kg/m³)
A13: Pilares | B13: 51004.52 | C13: =IF(B$17>0,B13/B$17,0) | D13: =IF(ESTRUTURAL!B5>0,B13/ESTRUTURAL!B5,0)
A14: Vigas | B14: 76506.78 | C14: =IF(B$17>0,B14/B$17,0) | D14: =IF(ESTRUTURAL!B6>0,B14/ESTRUTURAL!B6,0)
A15: Lajes | B15: 114760.18 | C15: =IF(B$17>0,B15/B$17,0) | D15: =IF(ESTRUTURAL!B7>0,B15/ESTRUTURAL!B7,0)
A16: Escadas | B16: 12751.13 | C16: =IF(B$17>0,B16/B$17,0) | D16: =IF(ESTRUTURAL!B8>0,B16/ESTRUTURAL!B8,0)
A17: Total Aço | B17: =SUM(B13:B16) | C17: =1 | D17: =IF(B9>0,B17/B9,0)
A19: FORMA
A20: Tipo | B20: Área (m²) | C20: Reutilizações | D20: PU (R$/m²) | E20: Total (R$) | F20: R$/m²
A21: Madeira Serrada | B21: 6697.56 | C21: 3 | D21: 85 | E21: =B21*D21 | F21: =IF(DADOS_PROJETO!B7>0,E21/DADOS_PROJETO!B7,0)
A22: Compensado | B22: 10046.35 | C22: 5 | D22: 65 | E22: =B22*D22 | F22: =IF(DADOS_PROJETO!B7>0,E22/DADOS_PROJETO!B7,0)
A23: Total Forma | B23: =SUM(B21:B22) | E23: =SUM(E21:E22) | F23: =IF(DADOS_PROJETO!B7>0,E23/DADOS_PROJETO!B7,0)
A25: ÍNDICES ESTRUTURAIS
A26: Concreto / AC (m³/m²) | B26: =IF(DADOS_PROJETO!B7>0,B9/DADOS_PROJETO!B7,0)
A27: Taxa Aço Global (kg/m³) | B27: =IF(B9>0,B17/B9,0)
A28: Forma / AC (m²/m²) | B28: =IF(DADOS_PROJETO!B7>0,B23/DADOS_PROJETO!B7,0)

Sheet INSTALACOES
A1: INSTALAÇÕES
A2: Disciplina | B2: Valor (R$) | C2: R$/m² | D2: % Instalações | E2: MO (R$/m²) | F2: Material (R$/m²)
A3: Hidrossanitárias | B3: 1787412.3 | C3: =IF(DADOS_PROJETO!B7>0,B3/DADOS_PROJETO!B7,0) | D3: =IF(B$8>0,B3/B$8,0) | E3: 55.51 | F3: =IF(C3>0,C3-E3,0)
A4: Elétricas | B4: 1532067.7 | C4: =IF(DADOS_PROJETO!B7>0,B4/DADOS_PROJETO!B7,0) | D4: =IF(B$8>0,B4/B$8,0) | E4: 47.58 | F4: =IF(C4>0,C4-E4,0)
A5: Preventivas (Incêndio) | B5: 766033.84 | C5: =IF(DADOS_PROJETO!B7>0,B5/DADOS_PROJETO!B7,0) | D5: =IF(B$8>0,B5/B$8,0) | E5: 23.79 | F5: =IF(C5>0,C5-E5,0)
A6: Gás | B6: 510689.22 | C6: =IF(DADOS_PROJETO!B7>0,B6/DADOS_PROJETO!B7,0) | D6: =IF(B$8>0,B6/B$8,0) | E6: 15.86 | F6: =IF(C6>0,C6-E6,0)
A7: Comunicações / Telecom | B7: 510689.22 | C7: =IF(DADOS_PROJETO!B7>0,B7/DADOS_PROJETO!B7,0) | D7: =IF(B$8>0,B7/B$8,0) | E7: 15.86 | F7: =IF(C7>0,C7-E7,0)
A8: TOTAL INSTALAÇÕES | B8: =SUM(B3:B7) | C8: =IF(DADOS_PROJETO!B7>0,B8/DADOS_PROJETO!B7,0) | D8: =1 | E8: =SUM(E3:E7) | F8: =SUM(F3:F7)
A10: ÍNDICES DE INSTALAÇÕES
A11: MO Total / AC (R$/m²) | B11: =E8
A12: Material Total / AC (R$/m²) | B12: =F8
A13: Razão MO / Material | B13: =IF(F8>0,E8/F8,0)

Sheet ACABAMENTOS
A1: ACABAMENTOS DETALHADOS
A3: REVESTIMENTOS DE PAREDE
A4: Item | B4: Qtd | C4: Un | D4: PU Material (R$) | E4: PU MO (R$) | F4: Total Material (R$) | G4: Total MO (R$) | H4: Total (R$)
A5: Chapisco interno | B5: 23184 | C5: m² | D5: 8.5 | E5: 12 | F5: =B5*D5 | G5: =B5*E5 | H5: =F5+G5
A6: Reboco interno | B6: 23184 | C6: m² | D6: 15 | E6: 25 | F6: =B6*D6 | G6: =B6*E6 | H6: =F6+G6
A7: Estucamento / Massa corrida | B7: 19320 | C7: m² | D7: 12 | E7: 18 | F7: =B7*D7 | G7: =B7*E7 | H7: =F7+G7
A8: Cerâmico parede | B8: 3220 | C8: m² | D8: 65 | E8: 45 | F8: =B8*D8 | G8: =B8*E8 | H8: =F8+G8
A9: Porcelanato parede | B9: 1932 | C9: m² | D9: 120 | E9: 55 | F9: =B9*D9 | G9: =B9*E9 | H9: =F9+G9
A10: Pastilha interna | B10: 386 | C10: m² | D10: 180 | E10: 65 | F10: =B10*D10 | G10: =B10*E10 | H10: =F10+G10
A11: Subtotal Revestimentos De Parede | F11: =SUM(F5:F10) | G11: =SUM(G5:G10) | H11: =F11+G11
A13: PISOS
A14: Item | B14: Qtd | C14: Un | D14: PU Material (R$) | E14: PU MO (R$) | F14: Total Material (R$) | G14: Total MO (R$) | H14: Total (R$)
A15: Contrapiso | B15: 9660 | C15: m² | D15: 18 | E15: 22 | F15: =B15*D15 | G15: =B15*E15 | H15: =F15+G15
A16: Porcelanato piso | B16: 6440 | C16: m² | D16: 130 | E16: 50 | F16: =B16*D16 | G16: =B16*E16 | H16: =F16+G16
A17: Cerâmico piso | B17: 1288 | C17: m² | D17: 55 | E17: 40 | F17: =B17*D17 | G17: =B17*E17 | H17: =F17+G17
A18: Laminado | B18: 644 | C18: m² | D18: 85 | E18: 25 | F18: =B18*D18 | G18: =B18*E18 | H18: =F18+G18
A19: Vinílico | B19: 386 | C19: m² | D19: 95 | E19: 20 | F19: =B19*D19 | G19: =B19*E19 | H19: =F19+G19
A20: Rodapé | B20: 7728 | C20: m | D20: 35 | E20: 15 | F20: =B20*D20 | G20: =B20*E20 | H20: =F20+G20
A21: Soleira / Peitoril | B21: 696 | C21: m | D21: 90 | E21: 30 | F21: =B21*D21 | G21: =B21*E21 | H21: =F21+G21
A22: Subtotal Pisos | F22: =SUM(F15:F21) | G22: =SUM(G15:G21) | H22: =F22+G22
A24: TETO
A25: Item | B25: Qtd | C25: Un | D25: PU Material (R$) | E25: PU MO (R$) | F25: Total Material (R$) | G25: Total MO (R$) | H25: Total (R$)
A26: Forro gesso acartonado | B26: 7084 | C26: m² | D26: 45 | E26: 35 | F26: =B26*D26 | G26: =B26*E26 | H26: =F26+G26
A27: Forro gesso RU | B27: 1288 | C27: m² | D27: 55 | E27: 40 | F27: =B27*D27 | G27: =B27*E27 | H27: =F27+G27
A28: Forro madeira | B28: 386 | C28: m² | D28: 150 | E28: 45 | F28: =B28*D28 | G28: =B28*E28 | H28: =F28+G28
A29: Negativo / Tabica | B29: 3864 | C29: m | D29: 25 | E29: 20 | F29: =B29*D29 | G29: =B29*E29 | H29: =F29+G29
A30: Sanca | B30: 1030 | C30: m | D30: 35 | E30: 30 | F30: =B30*D30 | G30: =B30*E30 | H30: =F30+G30
A31: Subtotal Teto | F31: =SUM(F26:F30) | G31: =SUM(G26:G30) | H31: =F31+G31
A33: PINTURA
A34: Item | B34: Qtd | C34: Un | D34: PU Material (R$) | E34: PU MO (R$) | F34: Total Material (R$) | G34: Total MO (R$) | H34: Total (R$)
A35: Pintura parede (PVA/acrílica) | B35: 19320 | C35: m² | D35: 14 | E35: 12 | F35: =B35*D35 | G35: =B35*E35 | H35: =F35+G35
A36: Textura | B36: 1932 | C36: m² | D36: 22 | E36: 18 | F36: =B36*D36 | G36: =B36*E36 | H36: =F36+G36
A37: Pintura teto | B37: 8372 | C37: m² | D37: 12 | E37: 10 | F37: =B37*D37 | G37: =B37*E37 | H37: =F37+G37
A38: Epóxi | B38: 1546 | C38: m² | D38: 35 | E38: 20 | F38: =B38*D38 | G38: =B38*E38 | H38: =F38+G38
A39: Verniz | B39: 258 | C39: m² | D39: 28 | E39: 15 | F39: =B39*D39 | G39: =B39*E39 | H39: =F39+G39
A40: Subtotal Pintura | F40: =SUM(F35:F39) | G40: =SUM(G35:G39) | H40: =F40+G40
A42: FACHADA
A43: Item | B43: Qtd | C43: Un | D43: PU Material (R$) | E43: PU MO (R$) | F43: Total Material (R$) | G43: Total MO (R$) | H43: Total (R$)
A44: Chapisco externo | B44: 4875 | C44: m² | D44: 10 | E44: 15 | F44: =B44*D44 | G44: =B44*E44 | H44: =F44+G44
A45: Reboco externo | B45: 4875 | C45: m² | D45: 18 | E45: 30 | F45: =B45*D45 | G45: =B45*E45 | H45: =F45+G45
...

Sheet CI_DETALHADO
A1: CUSTOS INDIRETOS DETALHADOS
A3: PROJETOS E CONSULTORIAS
A4: Disciplina | B4: Valor (R$) | C4: R$/m²
A5: Arquitetônico | B5: 231838.74 | C5: =IF(DADOS_PROJETO!B7>0,B5/DADOS_PROJETO!B7,0)
A6: Estrutural | B6: 154559.16 | C6: =IF(DADOS_PROJETO!B7>0,B6/DADOS_PROJETO!B7,0)
A7: Elétrico | B7: 103039.44 | C7: =IF(DADOS_PROJETO!B7>0,B7/DADOS_PROJETO!B7,0)
A8: Hidrossanitário | B8: 90159.51 | C8: =IF(DADOS_PROJETO!B7>0,B8/DADOS_PROJETO!B7,0)
A9: Preventivo | B9: 64399.65 | C9: =IF(DADOS_PROJETO!B7>0,B9/DADOS_PROJETO!B7,0)
A10: Climatização | B10: 77279.58 | C10: =IF(DADOS_PROJETO!B7>0,B10/DADOS_PROJETO!B7,0)
A11: Paisagismo | B11: 51519.72 | C11: =IF(DADOS_PROJETO!B7>0,B11/DADOS_PROJETO!B7,0)
A12: Interiores | B12: 64399.65 | C12: =IF(DADOS_PROJETO!B7>0,B12/DADOS_PROJETO!B7,0)
A13: Fundações | B13: 77279.58 | C13: =IF(DADOS_PROJETO!B7>0,B13/DADOS_PROJETO!B7,0)
A14: Outros Projetos | B14: 51519.72 | C14: =IF(DADOS_PROJETO!B7>0,B14/DADOS_PROJETO!B7,0)
A15: Subtotal Projetos | B15: =SUM(B5:B14) | C15: =IF(DADOS_PROJETO!B7>0,B15/DADOS_PROJETO!B7,0)
A17: TAXAS E LICENÇAS
A18: Descrição | B18: Valor (R$) | C18: R$/m²
A19: Alvará de Construção | B19: 85000 | C19: =IF(DADOS_PROJETO!B7>0,B19/DADOS_PROJETO!B7,0)
A20: ARTs / RRTs | B20: 45000 | C20: =IF(DADOS_PROJETO!B7>0,B20/DADOS_PROJETO!B7,0)
A21: Corpo de Bombeiros | B21: 35000 | C21: =IF(DADOS_PROJETO!B7>0,B21/DADOS_PROJETO!B7,0)
A22: Habite-se | B22: 60000 | C22: =IF(DADOS_PROJETO!B7>0,B22/DADOS_PROJETO!B7,0)
A23: Registro de Incorporação | B23: 40000 | C23: =IF(DADOS_PROJETO!B7>0,B23/DADOS_PROJETO!B7,0)
A24: Outras Taxas | B24: 25000 | C24: =IF(DADOS_PROJETO!B7>0,B24/DADOS_PROJETO!B7,0)
A25: Subtotal Taxas | B25: =SUM(B19:B24) | C25: =IF(DADOS_PROJETO!B7>0,B25/DADOS_PROJETO!B7,0)
A27: EQUIPE ADMINISTRATIVA
A28: Função | B28: Qtd | C28: Custo/mês (R$) | D28: Meses | E28: Total (R$) | F28: R$/m²
A29: Engenheiro Residente | B29: 1 | C29: 18000 | D29: 30 | E29: =B29*C29*D29 | F29: =IF(DADOS_PROJETO!B7>0,E29/DADOS_PROJETO!B7,0)
A30: Mestre de Obras | B30: 1 | C30: 10000 | D30: 30 | E30: =B30*C30*D30 | F30: =IF(DADOS_PROJETO!B7>0,E30/DADOS_PROJETO!B7,0)
A31: Almoxarife | B31: 1 | C31: 5500 | D31: 28 | E31: =B31*C31*D31 | F31: =IF(DADOS_PROJETO!B7>0,E31/DADOS_PROJETO!B7,0)
A32: Técnico Segurança | B32: 1 | C32: 7000 | D32: 30 | E32: =B32*C32*D32 | F32: =IF(DADOS_PROJETO!B7>0,E32/DADOS_PROJETO!B7,0)
A33: Administrativo Obra | B33: 1 | C33: 5000 | D33: 30 | E33: =B33*C33*D33 | F33: =IF(DADOS_PROJETO!B7>0,E33/DADOS_PROJETO!B7,0)
A34: Estagiários | B34: 2 | C34: 2500 | D34: 24 | E34: =B34*C34*D34 | F34: =IF(DADOS_PROJETO!B7>0,E34/DADOS_PROJETO!B7,0)
A35: Subtotal Equipe ADM | E35: =SUM(E29:E34) | F35: =IF(DADOS_PROJETO!B7>0,E35/DADOS_PROJETO!B7,0)
A37: EPCs (PROTEÇÃO COLETIVA)
A38: Item | B38: Valor (R$) | C38: R$/m²
A39: Bandeja de Proteção | B39: 120000 | C39: =IF(DADOS_PROJETO!B7>0,B39/DADOS_PROJETO!B7,0)
A40: Guarda-corpo | B40: 85000 | C40: =IF(DADOS_PROJETO!B7>0,B40/DADOS_PROJETO!B7,0)
A41: Tela de Proteção | B41: 95000 | C41: =IF(DADOS_PROJETO!B7>0,B41/DADOS_PROJETO!B7,0)
A42: Linha de Vida | B42: 45000 | C42: =IF(DADOS_PROJETO!B7>0,B42/DADOS_PROJETO!B7,0)
A43: Sinalização | B43: 15000 | C43: =IF(DADOS_PROJETO!B7>0,B43/DADOS_PROJETO!B7,0)
A44: Outros EPCs | B44: 25000 | C44: =IF(DADOS_PROJETO!B7>0,B44/DADOS_PROJETO!B7,0)
...

Sheet BENCHMARK
A1: BENCHMARK — PROJETOS DE REFERÊNCIA
A3: Projeto | B3: Cidade | C3: AC (m²) | D3: NP | E3: Prazo (meses) | F3: CUB (R$/m²) | G3: R$/m² | H3: CUB Ratio
A4: By Seasons | B4: Itapema/SC | C4: 6348 | F4: 2839 | G4: 3520 | H4: =IF(F4>0,G4/F4,0)
A5: ETR Mediterrâneo | B5: Itapema/SC | C5: 4617 | F5: 2855 | G5: 4197 | H5: =IF(F5>0,G5/F5,0)
A6: Meia Praia 298 | B6: Itapema/SC | C6: 10618 | F6: 2719 | G6: 3535 | H6: =IF(F6>0,G6/F6,0)
A7: Meia Praia Eternity | B7: Itapema/SC | C7: 11893 | F7: 2720 | G7: 3482 | H7: =IF(F7>0,G7/F7,0)
A8: Lorenzo Gabriel | B8: Itapema/SC | C8: 8525 | F8: 2840 | G8: 3778 | H8: =IF(F8>0,G8/F8,0)
A9: Ferrazzo Viva Perequê | B9: Porto Belo/SC | C9: 5576 | F9: 2971 | G9: 4129 | H9: =IF(F9>0,G9/F9,0)
A10: EZE Canto Grande | B10: Bombinhas/SC | C10: 1611 | F10: 2467 | G10: 3627 | H10: =IF(F10>0,G10/F10,0)
A11: EZE Eilat | B11: Bombinhas/SC | C11: 1767 | F11: 2759 | G11: 3642 | H11: =IF(F11>0,G11/F11,0)
H12: =IF(F12>0,G12/F12,0)
H13: =IF(F13>0,G13/F13,0)
A14: MÉDIA | C14: =IF(COUNTA(C4:C13)>0,AVERAGE(C4:C13),0) | D14: =IF(COUNTA(D4:D13)>0,AVERAGE(D4:D13),0) | E14: =IF(COUNTA(E4:E13)>0,AVERAGE(E4:E13),0) | F14: =IF(COUNTA(F4:F13)>0,AVERAGE(F4:F13),0) | G14: =IF(COUNTA(G4:G13)>0,AVERAGE(G4:G13),0) | H14: =IF(COUNTA(H4:H13)>0,AVERAGE(H4:H13),0)
A17: COMPARATIVO R$/m² POR MACROGRUPO
A19: # | B19: Macrogrupo | C19: Este Projeto (R$/m²) | D19: Média Referências (R$/m²) | E19: Desvio (%)
A20: 1 | B20: Gerenciamento Técnico/Admin | C20: =CUSTOS_MACROGRUPO!D3 | D20: 448.65 | E20: =IF(D20>0,(C20-D20)/D20,0)
A21: 2 | B21: Movimentação de Terra | C21: =CUSTOS_MACROGRUPO!D4 | D21: 37.39 | E21: =IF(D21>0,(C21-D21)/D21,0)
A22: 3 | B22: Infraestrutura | C22: =CUSTOS_MACROGRUPO!D5 | D22: 186.94 | E22: =IF(D22>0,(C22-D22)/D22,0)
A23: 4 | B23: Supraestrutura | C23: =CUSTOS_MACROGRUPO!D6 | D23: 1046.85 | E23: =IF(D23>0,(C23-D23)/D23,0)
A24: 5 | B24: Alvenaria | C24: =CUSTOS_MACROGRUPO!D7 | D24: 186.94 | E24: =IF(D24>0,(C24-D24)/D24,0)
A25: 6 | B25: Impermeabilização | C25: =CUSTOS_MACROGRUPO!D8 | D25: 74.78 | E25: =IF(D25>0,(C25-D25)/D25,0)
A26: 7 | B26: Instalações (agrupado) | C26: =CUSTOS_MACROGRUPO!D9 | D26: 373.88 | E26: =IF(D26>0,(C26-D26)/D26,0)
A27: 8 | B27: Sistemas Especiais | C27: =CUSTOS_MACROGRUPO!D10 | D27: 149.55 | E27: =IF(D27>0,(C27-D27)/D27,0)
A28: 9 | B28: Climatização | C28: =CUSTOS_MACROGRUPO!D11 | D28: 74.78 | E28: =IF(D28>0,(C28-D28)/D28,0)
A29: 10 | B29: Rev. Internos Parede | C29: =CUSTOS_MACROGRUPO!D12 | D29: 224.32 | E29: =IF(D29>0,(C29-D29)/D29,0)
A30: 11 | B30: Teto | C30: =CUSTOS_MACROGRUPO!D13 | D30: 74.78 | E30: =IF(D30>0,(C30-D30)/D30,0)
A31: 12 | B31: Pisos | C31: =CUSTOS_MACROGRUPO!D14 | D31: 186.94 | E31: =IF(D31>0,(C31-D31)/D31,0)
... A37: 18 | B37: Imprevistos | C37: =CUSTOS_MACROGRUPO!D20 | D37: 0 | E37: =IF(D37>0,(C37-D37)/D37,0)
A40: FAIXAS TÍPICAS — BASE CARTESIAN
A41: Padrão Alto SC: R$/m² 3.000 – 4.500 | CUB ratio 1,05 – 1,50
A42: Supraestrutura: tipicamente 25% – 35% do custo total
A43: Instalações: tipicamente 8% – 15% do custo total
A44: Custos Indiretos: tipicamente 10% – 20% do custo total
A45: Base de referência: 40 projetos Cartesian Engenharia

Sheet ALERTAS
A1: PAINEL DE ALERTAS
A2: Resumo automático dos macrogrupos fora da faixa de benchmark
A4: # | B4: Macrogrupo | C4: R$/m² | D4: Faixa Min | E4: Faixa Max | F4: Situação
A5: 1 | B5: Gerenciamento Técnico/Admin | C5: =CUSTOS_MACROGRUPO!D3 | D5: =CUSTOS_MACROGRUPO!F3 | E5: =CUSTOS_MACROGRUPO!G3 | F5: =IF(C5=0,"—",IF(C5>E5,"⚠️ Acima da Faixa",IF(C5<D5,"🔽 Abaixo da Faixa","✅ Dentro da Faixa")))
A6: 2 | B6: Movimentação de Terra | C6: =CUSTOS_MACROGRUPO!D4 | D6: =CUSTOS_MACROGRUPO!F4 | E6: =CUSTOS_MACROGRUPO!G4 | F6: =IF(C6=0,"—",IF(C6>E6,"⚠️ Acima da Faixa",IF(C6<D6,"🔽 Abaixo da Faixa","✅ Dentro da Faixa")))
A7: 3 | B7: Infraestrutura | C7: =CUSTOS_MACROGRUPO!D5 | D7: =CUSTOS_MACROGRUPO!F5 | E7: =CUSTOS_MACROGRUPO!G5 | F7: =IF(C7=0,"—",IF(C7>E7,"⚠️ Acima da Faixa",IF(C7<D7,"🔽 Abaixo da Faixa","✅ Dentro da Faixa")))
A8: 4 | B8: Supraestrutura | C8: =CUSTOS_MACROGRUPO!D6 | D8: =CUSTOS_MACROGRUPO!F6 | E8: =CUSTOS_MACROGRUPO!G6 | F8: =IF(C8=0,"—",IF(C8>E8,"⚠️ Acima da Faixa",IF(C8<D8,"🔽 Abaixo da Faixa","✅ Dentro da Faixa")))
A9: 5 | B9: Alvenaria | C9: =CUSTOS_MACROGRUPO!D7 | D9: =CUSTOS_MACROGRUPO!F7 | E9: =CUSTOS_MACROGRUPO!G7 | F9: =IF(C9=0,"—",IF(C9>E9,"⚠️ Acima da Faixa",IF(C9<D9,"🔽 Abaixo da Faixa","✅ Dentro da Faixa")))
A10: 6 | B10: Impermeabilização | C10: =CUSTOS_MACROGRUPO!D8 | D10: =CUSTOS_MACROGRUPO!F8 | E10: =CUSTOS_MACROGRUPO!G8 | F10: =IF(C10=0,"—",IF(C10>E10,"⚠️ Acima da Faixa",IF(C10<D10,"🔽 Abaixo da Faixa","✅ Dentro da Faixa")))
A11: 7 | B11: Instalações (agrupado) | C11: =CUSTOS_MACROGRUPO!D9 | D11: =CUSTOS_MACROGRUPO!F9 | E11: =CUSTOS_MACROGRUPO!G9 | F11: =IF(C11=0,"—",IF(C11>E11,"⚠️ Acima da Faixa",IF(C11<D11,"🔽 Abaixo da Faixa","✅ Dentro da Faixa")))
A12: 8 | B12: Sistemas Especiais | C12: =CUSTOS_MACROGRUPO!D10 | D12: =CUSTOS_MACROGRUPO!F10 | E12: =CUSTOS_MACROGRUPO!G10 | F12: =IF(C12=0,"—",IF(C12>E12,"⚠️ Acima da Faixa",IF(C12<D12,"🔽 Abaixo da Faixa","✅ Dentro da Faixa")))
A13: 9 | B13: Climatização | C13: =CUSTOS_MACROGRUPO!D11 | D13: =CUSTOS_MACROGRUPO!F11 | E13: =CUSTOS_MACROGRUPO!G11 | F13: =IF(C13=0,"—",IF(C13>E13,"⚠️ Acima da Faixa",IF(C13<D13,"🔽 Abaixo da Faixa","✅ Dentro da Faixa")))
A14: 10 | B14: Rev. Internos Parede | C14: =CUSTOS_MACROGRUPO!D12 | D14: =CUSTOS_MACROGRUPO!F12 | E14: =CUSTOS_MACROGRUPO!G12 | F14: =IF(C14=0,"—",IF(C14>E14,"⚠️ Acima da Faixa",IF(C14<D14,"🔽 Abaixo da Faixa","✅ Dentro da Faixa")))
A15: 11 | B15: Teto | C15: =CUSTOS_MACROGRUPO!D13 | D15: =CUSTOS_MACROGRUPO!F13 | E15: =CUSTOS_MACROGRUPO!G13 | F15: =IF(C15=0,"—",IF(C15>E15,"⚠️ Acima da Faixa",IF(C15<D15,"🔽 Abaixo da Faixa","✅ Dentro da Faixa")))
A16: 12 | B16: Pisos | C16: =CUSTOS_MACROGRUPO!D14 | D16: =CUSTOS_MACROGRUPO!F14 | E16: =CUSTOS_MACROGRUPO!G14 | F16: =IF(C16=0,"—",IF(C16>E16,"⚠️ Acima da Faixa",IF(C16<D16,"🔽 Abaixo da Faixa","✅ Dentro da Faixa")))
... A22: 18 | B22: Imprevistos | C22: =CUSTOS_MACROGRUPO!D20 | D22: =CUSTOS_MACROGRUPO!F20 | E22: =CUSTOS_MACROGRUPO!G20 | F22: =IF(C22=0,"—",IF(C22>E22,"⚠️ Acima da Faixa",IF(C22<D22,"🔽 Abaixo da Faixa","✅ Dentro da Faixa")))
A25: RESUMO
A26: ⚠️ Acima da Faixa: | B26: =COUNTIF(F5:F22,"*Acima*")
A27: ✅ Dentro da Faixa: | B27: =COUNTIF(F5:F22,"*Dentro*")
A28: 🔽 Abaixo da Faixa: | B28: =COUNTIF(F5:F22,"*Abaixo*")
A29: — Sem dados: | B29: =COUNTIF(F5:F22,"—")

Sheet PRODUTO
A1: ANÁLISE DE PRODUTO
A2: Índices calculados a partir do orçamento paramétrico (17 projetos) e dados de mercado
A4: A. DADOS DO EMPREENDIMENTO
A5: Parâmetro | B5: Valor | C5: Unidade | D5: Fonte | E5: Observação
A6: Área Construída Total (AC) | B6: =DADOS_PROJETO!B7 | C6: m² | D6: Projeto
A7: Nº de Unidades Residenciais (UR) | B7: =DADOS_PROJETO!B8 | C7: un | D7: Projeto
A8: Nº de Vagas de Garagem | B8: =DADOS_PROJETO!B13 | C8: un | D8: Projeto
A9: Nº Pavimentos Tipo | B9: =DADOS_PROJETO!B10 | C9: un | D9: Projeto
A10: Área Privativa Média por UR | C10: m²/un | D10: Input | E10: Preencher
A11: Área Total do Terreno (AT) | B11: =DADOS_PROJETO!B14 | C11: m² | D11: Projeto
A12: Coef. Aproveitamento (CA) | B12: =IF(B11>0,B6/B11,0) | D12: Calculado | E12: AC / AT
A13: Preço Médio de Venda (VGV/UR) | C13: R$/un | D13: Mercado | E13: Pesquisa local
A14: VGV Total | B14: =B13*B7 | C14: R$ | D14: Calculado | E14: Preço × UR
A15: Custo Total Paramétrico | B15: =CUSTOS_MACROGRUPO!J21 | C15: R$ | D15: Paramétrico | E15: Soma macrogrupos
A16: Custo do Terreno | C16: R$ | D16: Input | E16: Valor pago pelo terreno
A19: B. ÍNDICES DE PRODUTO
A20: Índice | B20: Valor | C20: Unidade | D20: Fórmula | E20: Benchmark Mín | F20: Benchmark Máx | G20: Status | H20: Referência
A21: Custo por m² (R$/m²) | B21: =B15/B6 | C21: R$/m² | D21: Custo / AC | E21: 2800 | F21: 5000 | G21: =IF(B21<E21,"⬇ Abaixo",IF(B21>F21,"⬆ Acima","✅ OK")) | H21: Base: 17 projetos
A22: Custo por Unidade (R$/UR) | B22: =IF(B7>0,B15/B7,0) | C22: R$/un | D22: Custo / UR | E22: 400000 | F22: 900000 | G22: =IF(B22<E22,"⬇ Abaixo",IF(B22>F22,"⬆ Acima","✅ OK")) | H22: Base: 17 projetos
A23: CUB Ratio | B23: =IF(DADOS_PROJETO!E7>0,B21/DADOS_PROJETO!E7,0) | D23: R$/m² / CUB | E23: 1.05 | F23: 1.6 | G23: =IF(B23<E23,"⬇ Abaixo",IF(B23>F23,"⬆ Acima","✅ OK")) | H23: Base: 17 projetos
A24: Custo / VGV | B24: =IF(B14>0,B15/B14,0) | C24: % | D24: Custo / VGV | E24: 0.35 | F24: 0.55 | G24: =IF(B24<E24,"⬇ Abaixo",IF(B24>F24,"⬆ Acima","✅ OK")) | H24: Base: 17 projetos
A25: Margem Bruta Estimada | B25: =IF(B14>0,1-B24,0) | C25: % | D25: 1 - Custo/VGV | E25: 0.45 | F25: 0.65 | G25: =IF(B25<E25,"⬇ Abaixo",IF(B25>F25,"⬆ Acima","✅ OK")) | H25: Base: 17 projetos
A26: Custo por Vaga | B26: =IF(B8>0,B15/B8,0) | C26: R$/vaga | D26: Custo / Vagas | E26: 200000 | F26: 600000 | G26: =IF(B26<E26,"⬇ Abaixo",IF(B26>F26,"⬆ Acima","✅ OK")) | H26: Base: 17 projetos
A27: AC por UR | B27: =IF(B7>0,B6/B7,0) | C27: m²/un | D27: AC / UR | E27: 150 | F27: 350 | G27: =IF(B27<E27,"⬇ Abaixo",IF(B27>F27,"⬆ Acima","✅ OK")) | H27: Base: 17 projetos
A28: Vagas por UR | B28: =IF(B7>0,B8/B7,0) | C28: vagas/un | D28: Vagas / UR | E28: 1 | F28: 2.5 | G28: =IF(B28<E28,"⬇ Abaixo",IF(B28>F28,"⬆ Acima","✅ OK")) | H28: Base: 17 projetos
A29: Incidência Terreno | B29: =IF(B14>0,B16/B14,0) | C29: % | D29: Terreno / VGV | E29: 0.1 | F29: 0.25 | G29: =IF(B29<E29,"⬇ Abaixo",IF(B29>F29,"⬆ Acima","✅ OK")) | H29: Base: 17 projetos
A30: Custo Total / m² Privativo | B30: =IF(B10>0,B15/(B10*B7),0) | C30: R$/m²priv | D30: Custo / Área Priv. | E30: 4000 | F30: 8000 | G30: =IF(B30<E30,"⬇ Abaixo",IF(B30>F30,"⬆ Acima","✅ OK")) | H30: Base: 17 projetos
A33: C. COMPOSIÇÃO DE CUSTO POR UNIDADE
A34: Macrogrupo | B34: Custo Total | C34: % do Total | D34: R$/m² | E34: R$/UR | F34: Impacto
A35: Gerenciamento | B35: =CUSTOS_MACROGRUPO!J3 | C35: =IF(B35>0,B35/B15,0) | D35: =IF(B6>0,B35/B6,0) | E35: =IF(B7>0,B35/B7,0) | F35: =IF(C35>=0.1,"Alto impacto",IF(C35>=0.05,"Médio","Baixo impacto"))
A36: Mov. Terra | B36: =CUSTOS_MACROGRUPO!J4 | C36: =IF(B36>0,B36/B15,0) | D36: =IF(B6>0,B36/B6,0) | E36: =IF(B7>0,B36/B7,0) | F36: =IF(C36>=0.1,"Alto impacto",IF(C36>=0.05,"Médio","Baixo impacto"))
A37: Infraestrutura | B37: =CUSTOS_MACROGRUPO!J5 | C37: =IF(B37>0,B37/B15,0) | D37: =IF(B6>0,B37/B6,0) | E37: =IF(B7>0,B37/B7,0) | F37: =IF(C37>=0.1,"Alto impacto",IF(C37>=0.05,"Médio","Baixo impacto"))
A38: Supraestrutura | B38: =CUSTOS_MACROGRUPO!J6 | C38: =IF(B38>0,B38/B15,0) | D38: =IF(B6>0,B38/B6,0) | E38: =IF(B7>0,B38/B7,0) | F38: =IF(C38>=0.1,"Alto impacto",IF(C38>=0.05,"Médio","Baixo impacto"))
A39: Alvenaria | B39: =CUSTOS_MACROGRUPO!J7 | C39: =IF(B39>0,B39/B15,0) | D39: =IF(B6>0,B39/B6,0) | E39: =IF(B7>0,B39/B7,0) | F39: =IF(C39>=0.1,"Alto impacto",IF(C39>=0.05,"Médio","Baixo impacto"))
A40: Impermeabilização | B40: =CUSTOS_MACROGRUPO!J8 | C40: =IF(B40>0,B40/B15,0) | D40: =IF(B6>0,B40/B6,0) | E40: =IF(B7>0,B40/B7,0) | F40: =IF(C40>=0.1,"Alto impacto",IF(C40>=0.05,"Médio","Baixo impacto"))
A41: Instalações | B41: =CUSTOS_MACROGRUPO!J9 | C41: =IF(B41>0,B41/B15,0) | D41: =IF(B6>0,B41/B6,0) | E41: =IF(B7>0,B41/B7,0) | F41: =IF(C41>=0.1,"Alto impacto",IF(C41>=0.05,"Médio","Baixo impacto"))
A42: Sist. Especiais | B42: =CUSTOS_MACROGRUPO!J10 | C42: =IF(B42>0,B42/B15,0) | D42: =IF(B6>0,B42/B6,0) | E42: =IF(B7>0,B42/B7,0) | F42: =IF(C42>=0.1,"Alto impacto",IF(C42>=0.05,"Médio","Baixo impacto"))
A43: Climatização | B43: =CUSTOS_MACROGRUPO!J11 | C43: =IF(B43>0,B43/B15,0) | D43: =IF(B6>0,B43/B6,0) | E43: =IF(B7>0,B43/B7,0) | F43: =IF(C43>=0.1,"Alto impacto",IF(C43>=0.05,"Médio","Baixo impacto"))
A44: Rev. Int. Parede | B44: =CUSTOS_MACROGRUPO!J12 | C44: =IF(B44>0,B44/B15,0) | D44: =IF(B6>0,B44/B6,0) | E44: =IF(B7>0,B44/B7,0) | F44: =IF(C44>=0.1,"Alto impacto",IF(C44>=0.05,"Médio","Baixo impacto"))
A45: Teto | B45: =CUSTOS_MACROGRUPO!J13 | C45: =IF(B45>0,B45/B15,0) | D45: =IF(B6>0,B45/B6,0) | E45: =IF(B7>0,B45/B7,0) | F45: =IF(C45>=0.1,"Alto impacto",IF(C45>=0.05,"Médio","Baixo impacto"))
...

Sheet ANÁLISE_ÍNDICE_PRODUTO
A1: ANÁLISE DE ÍNDICE DE PRODUTO
A2: Base: 17 projetos executivos Cartesian | Valores normalizados CUB/SC dez/23 (R$ 2,752.67)
A4: A. BASE DE PROJETOS (normalizados CUB dez/23)
A5: Projeto | B5: AC (m²) | C5: CUB Ref | D5: Data Base | E5: R$/m² orig. | F5: R$/m² norm. | G5: CUB Ratio | H5: Gerenc. | I5: Supra | J5: Instal. | K5: Esquad. | L5: Fachada | M5: Compl. | N5: Classif.
A6: fasolo-vdf | B6: 20550 | C6: 2357.91 | E6: 2843.56 | F6: 3319.62 | G6: 1.21 | H6: 0 | I6: 0.24625485 | J6: 0.09984663 | K6: 0.12122639 | L6: 0.082441917 | M6: 0.046806263 | N6: Médio
A7: zapata | B7: 7533 | C7: 2993.04 | D7: 2025-09-01 | E7: 3192.61 | F7: 2936.21 | G7: 1.07 | H7: 0.10099878 | I7: 0.22900412 | J7: 0.11411936 | K7: 0.094109632 | L7: 0.05486937 | M7: 0.056001441 | N7: Econômico
A8: maison-beach | B8: 12880 | C8: 2752.67 | D8: 2023-12-01 | E8: 3290.71 | F8: 3290.71 | G8: 1.2 | H8: 0.13296146 | I8: 0.20035672 | J8: 0.13023629 | K8: 0.10819416 | L8: 0.02120093 | M8: 0.071127447 | N8: Médio
A9: cota365 | B9: 17473 | C9: 2846.12 | D9: 2024-10-01 | E9: 3366.88 | F9: 3256.33 | G9: 1.18 | H9: 0.059573914 | I9: 0.17683197 | J9: 0.10954642 | K9: 0.10145599 | L9: 0.032468835 | M9: 0.038134516 | N9: Médio
A10: catena | B10: 9242 | C10: 3008.84 | D10: 2025-11-01 | E10: 3376.01 | F10: 3088.58 | G10: 1.12 | H10: 0.1161002 | I10: 0.22422195 | J10: 0.10898959 | K10: 0.091842185 | L10: 0.04100292 | M10: 0.050942473 | N10: Médio
A11: eternity | B11: 11893 | C11: 2725.79 | D11: 2024-06-01 | E11: 3482.06 | F11: 3516.4 | G11: 1.28 | H11: 0.11576376 | I11: 0.21084691 | J11: 0.11009289 | K11: 0.099952678 | L11: 0.041055846 | M11: 0.050920489 | N11: Alto
A12: mp298 | B12: 10618 | C12: 2725.79 | D12: 2024-06-01 | E12: 3535.44 | F12: 3570.31 | G12: 1.3 | H12: 0.11470877 | I12: 0.21449431 | J12: 0.11014182 | K12: 0.10811977 | L12: 0.04920845 | M12: 0.049474186 | N12: Alto
A13: connect | B13: 13144 | C13: 2774.29 | D13: 2024-06-01 | E13: 3583.88 | F13: 3555.95 | G13: 1.29 | H13: 0.08534299 | I13: 4.0333262e-09 | J13: 0.095148204 | K13: 0.096875837 | L13: 0.047867066 | M13: 0.07002193 | N13: Alto
A14: dlohn | B14: 13148 | C14: 2907.85 | D14: 2025-02-01 | E14: 3728.08 | F14: 3529.13 | G14: 1.28 | H14: 0.078124692 | I14: 0.19258138 | J14: 0.10961396 | K14: 0.13698286 | L14: 0.015313092 | M14: 0.044679648 | N14: Alto
A15: lorenzo | B15: 8525 | C15: 2841.51 | D15: 2024-09-01 | E15: 3777.63 | F15: 3659.52 | G15: 1.33 | H15: 0.11641682 | I15: 0.20293992 | J15: 0.10235248 | K15: 0.10034956 | L15: 0.038811251 | M15: 0.048671304 | N15: Alto
A16: passione | B16: 6682 | C16: 2774.29 | D16: 2024-06-01 | E16: 3778.05 | F16: 3748.61 | G16: 1.36 | H16: 5.5460436e-09 | I16: 7.5267734e-09 | J16: 0.090258101 | K16: 0.10764632 | L16: 0.047466959 | M16: 0.061705813 | N16: Alto
A17: redentor | B17: 16728 | C17: 2671.09 | D17: 2752.32 | E17: 3923.38 | F17: 4043.21 | G17: 1.47 | H17: 0.091847341 | I17: 0.19659859 | J17: 0.090760213 | K17: 0.12808301 | L17: 0.068113275 | M17: 0.05300643 | N17: Alto
A18: viva | B18: 5576 | C18: 2965.54 | D18: 2025-07-01 | E18: 4128.8 | F18: 3832.43 | G18: 1.39 | H18: 0.12397491 | I18: 0.18700046 | J18: 0.081985097 | K18: 0.14193963 | L18: 0.067679084 | M18: 0.048985784 | N18: Alto
... A22: bd-campeche | B22: 3633 | C22: 3012.64 | D22: 2026-01-01 | E22: 5709.79 | F22: 5217.07 | G22: 1.9 | H22: 0.12298689 | I22: 0.13986903 | J22: 0.066175826 | K22: 0.066522046 | L22: 0.032190424 | M22: 0.046550632 | N22: Luxo
A24: ESTATÍSTICAS
A25: Média | F25: 3837.12 | G25: 1.39
A26: Mediana | F26: 3570.31 | G26: 1.3
A27: Mínimo | F27: 2936.21 | G27: 1.07
A28: Máximo | F28: 6192.47 | G28: 2.25
A31: B. PROJETO ATUAL vs BASE DE DADOS
A32: Macrogrupo | B32: Atual R$/m² | C32: Média Base | D32: Mediana Base | E32: Mín Base | F32: Máx Base | G32: Desvio vs Med. | H32: Análise
A33: Gerenciamento | B33: =CUSTOS_MACROGRUPO!D3 | C33: 378.37 | D33: 407.07 | E33: 0 | F33: 641.63 | G33: =IF(D33>0,(B33-D33)/D33,0) | H33: =IF(ABS(G33)<=0.1,"✅ Dentro",IF(G33>0.1,"⬆ Acima","⬇ Abaixo"))
A34: Mov. Terra | B34: =CUSTOS_MACROGRUPO!D4 | C34: 30.15 | D34: 12.47 | E34: 6.77 | F34: 100.79 | G34: =IF(D34>0,(B34-D34)/D34,0) | H34: =IF(ABS(G34)<=0.1,"✅ Dentro",IF(G34>0.1,"⬆ Acima","⬇ Abaixo"))
A35: Infraestrutura | B35: =CUSTOS_MACROGRUPO!D5 | C35: 218.07 | D35: 230.4 | E35: 117.39 | F35: 276.9 | G35: =IF(D35>0,(B35-D35)/D35,0) | H35: =IF(ABS(G35)<=0.1,"✅ Dentro",IF(G35>0.1,"⬆ Acima","⬇ Abaixo"))
A36: Supraestrutura | B36: =CUSTOS_MACROGRUPO!D6 | C36: 654.97 | D36: 722.66 | E36: 0 | F36: 965.07 | G36: =IF(D36>0,(B36-D36)/D36,0) | H36: =IF(ABS(G36)<=0.1,"✅ Dentro",IF(G36>0.1,"⬆ Acima","⬇ Abaixo"))
A37: Alvenaria | B37: =CUSTOS_MACROGRUPO!D7 | C37: 178.37 | D37: 148.7 | E37: 55.96 | F37: 431.99 | G37: =IF(D37>0,(B37-D37)/D37,0) | H37: =IF(ABS(G37)<=0.1,"✅ Dentro",IF(G37>0.1,"⬆ Acima","⬇ Abaixo"))
A38: Impermeabilização | B38: =CUSTOS_MACROGRUPO!D8 | C38: 58.3 | D38: 56.43 | E38: 35.79 | F38: 86.01 | G38: =IF(D38>0,(B38-D38)/D38,0) | H38: =IF(ABS(G38)<=0.1,"✅ Dentro",IF(G38>0.1,"⬆ Acima","⬇ Abaixo"))
A39: Instalações | B39: =CUSTOS_MACROGRUPO!D9 | C39: 378.14 | D39: 366.96 | E39: 314.2 | F39: 566.73 | G39: =IF(D39>0,(B39-D39)/D39,0) | H39: =IF(ABS(G39)<=0.1,"✅ Dentro",IF(G39>0.1,"⬆ Acima","⬇ Abaixo"))
A40: Sist. Especiais | B40: =CUSTOS_MACROGRUPO!D10 | C40: 214.98 | D40: 193.39 | E40: 151.55 | F40: 507.38 | G40: =IF(D40>0,(B40-D40)/D40,0) | H40: =IF(ABS(G40)<=0.1,"✅ Dentro",IF(G40>0.1,"⬆ Acima","⬇ Abaixo"))
A41: Rev. Int. Parede | B41: =CUSTOS_MACROGRUPO!D12 | C41: 167.05 | D41: 171.85 | E41: 98.77 | F41: 239.72 | G41: =IF(D41>0,(B41-D41)/D41,0) | H41: =IF(ABS(G41)<=0.1,"✅ Dentro",IF(G41>0.1,"⬆ Acima","⬇ Abaixo"))
A42: Teto | B42: =CUSTOS_MACROGRUPO!D13 | C42: 82.21 | D42: 68.65 | E42: 44.35 | F42: 141.94 | G42: =IF(D42>0,(B42-D42)/D42,0) | H42: =IF(ABS(G42)<=0.1,"✅ Dentro",IF(G42>0.1,"⬆ Acima","⬇ Abaixo"))
A43: Pisos | B43: =CUSTOS_MACROGRUPO!D14 | C43: 207.21 | D43: 193.69 | E43: 124.29 | F43: 458.04 | G43: =IF(D43>0,(B43-D43)/D43,0) | H43: =IF(ABS(G43)<=0.1,"✅ Dentro",IF(G43>0.1,"⬆ Acima","⬇ Abaixo"))
A44: Pintura | B44: =CUSTOS_MACROGRUPO!D15 | C44: 141.68 | D44: 133.12 | E44: 95.75 | F44: 199.04 | G44: =IF(D44>0,(B44-D44)/D44,0) | H44: =IF(ABS(G44)<=0.1,"✅ Dentro",IF(G44>0.1,"⬆ Acima","⬇ Abaixo"))
A45: Esquadrias | B45: =CUSTOS_MACROGRUPO!D16 | C45: 430.59 | D45: 367.23 | E45: 276.33 | F45: 1183.8 | G45: =IF(D45>0,(B45-D45)/D45,0) | H45: =IF(ABS(G45)<=0.1,"✅ Dentro",IF(G45>0.1,"⬆ Acima","⬇ Abaixo"))
A46: Fachada | B46: =CUSTOS_MACROGRUPO!D18 | C46: 170.87 | D46: 170.21 | E46: 54.04 | F46: 275.4 | G46: =IF(D46>0,(B46-D46)/D46,0) | H46: =IF(ABS(G46)<=0.1,"✅ Dentro",IF(G46>0.1,"⬆ Acima","⬇ Abaixo"))
A47: Complementares | B47: =CUSTOS_MACROGRUPO!D19 | C47: 278.11 | D47: 214.32 | E47: 145.75 | F47: 1098.59 | G47: =IF(D47>0,(B47-D47)/D47,0) | H47: =IF(ABS(G47)<=0.1,"✅ Dentro",IF(G47>0.1,"⬆ Acima","⬇ Abaixo"))
...
