Workbook

Sheet Premissas
A1: PREMISSAS DO RATEIO HIDROSSANITÁRIO — THOZEN ELECTRA
A3: ⚠ ESTE É UM RATEIO DERIVADO DO PRELIMINAR PARAMÉTRICO — NÃO É LEVANTAMENTO BIM. Use para sanity check e ordem de grandeza. Quantidades reais por pavimento virão do Visus/IFC quando o levantamento BIM estiver pronto. Células amarelas são editáveis — altere e o rateio recalcula.
A7: TOTAL HIDROSSANITÁRIO DO PRELIMINAR
A8: Total hidro (R$) | B8: 2583129.6
A9: % Material | B9: 0.35
A10: % Mão de obra | B10: 0.65
A11: Material calculado (R$) | B11: =Premissas!$B$8*Premissas!$B$9
A12: MO calculada (R$) | B12: =Premissas!$B$8*Premissas!$B$10
A14: ESTRUTURA DO EMPREENDIMENTO
A15: Número de torres | B15: 2
A16: Pavimentos totais por torre (np) | B16: 30
A17: Pavimentos tipo por torre (npt) | B17: 24
A18: Apartamentos totais (UR) | B18: 348
A19: Banheiros por apartamento | B19: 3
A20: AC total (m²) | B20: 37893.89
A21: Índice hidro (m tubulação / m² AC) | B21: 1.08
A23: DISTRIBUIÇÃO DE AC POR TIPO DE PAVIMENTO
A24: Tipo | B24: Qtd/torre | C24: % AC | D24: Fator hidro | E24: AC unit (m²)
A25: Subsolo | B25: 2 | C25: 0.08 | D25: 0.15 | E25: =IFERROR((Premissas!$B$20*C25)/(B25*Premissas!$B$15),0)
A26: Térreo | B26: 1 | C26: 0.02 | D26: 0.5 | E26: =IFERROR((Premissas!$B$20*C26)/(B26*Premissas!$B$15),0)
A27: Lazer | B27: 1 | C27: 0.03 | D27: 0.75 | E27: =IFERROR((Premissas!$B$20*C27)/(B27*Premissas!$B$15),0)
A28: Tipo | B28: 24 | C28: 0.85 | D28: 1 | E28: =IFERROR((Premissas!$B$20*C28)/(B28*Premissas!$B$15),0)
A29: Técnico | B29: 2 | C29: 0.02 | D29: 0.25 | E29: =IFERROR((Premissas!$B$20*C29)/(B29*Premissas!$B$15),0)
A30: TOTAL | B30: =SUM(B25:B29) | C30: =SUM(C25:C29) | E30: =SUMPRODUCT(B25:B29,E25:E29)*Premissas!$B$15

Sheet Pavimentos
A1: PAVIMENTOS — AC, FATOR, PESO, % PESO
A3: Torre | B3: Nº seq | C3: Pavimento | D3: Tipo | E3: AC (m²) | F3: Fator | G3: Peso
A4: 1 | B4: 1 | C4: Subsolo 1 | D4: Subsolo | E4: =Premissas!$E$25 | F4: =Premissas!$D$25 | G4: =E4*F4
A5: 1 | B5: 2 | C5: Subsolo 2 | D5: Subsolo | E5: =Premissas!$E$25 | F5: =Premissas!$D$25 | G5: =E5*F5
A6: 1 | B6: 3 | C6: Térreo | D6: Térreo | E6: =Premissas!$E$26 | F6: =Premissas!$D$26 | G6: =E6*F6
A7: 1 | B7: 4 | C7: Lazer | D7: Lazer | E7: =Premissas!$E$27 | F7: =Premissas!$D$27 | G7: =E7*F7
A8: 1 | B8: 5 | C8: Tipo 01 | D8: Tipo | E8: =Premissas!$E$28 | F8: =Premissas!$D$28 | G8: =E8*F8
A9: 1 | B9: 6 | C9: Tipo 02 | D9: Tipo | E9: =Premissas!$E$28 | F9: =Premissas!$D$28 | G9: =E9*F9
A10: 1 | B10: 7 | C10: Tipo 03 | D10: Tipo | E10: =Premissas!$E$28 | F10: =Premissas!$D$28 | G10: =E10*F10
A11: 1 | B11: 8 | C11: Tipo 04 | D11: Tipo | E11: =Premissas!$E$28 | F11: =Premissas!$D$28 | G11: =E11*F11
A12: 1 | B12: 9 | C12: Tipo 05 | D12: Tipo | E12: =Premissas!$E$28 | F12: =Premissas!$D$28 | G12: =E12*F12
A13: 1 | B13: 10 | C13: Tipo 06 | D13: Tipo | E13: =Premissas!$E$28 | F13: =Premissas!$D$28 | G13: =E13*F13
A14: 1 | B14: 11 | C14: Tipo 07 | D14: Tipo | E14: =Premissas!$E$28 | F14: =Premissas!$D$28 | G14: =E14*F14
A15: 1 | B15: 12 | C15: Tipo 08 | D15: Tipo | E15: =Premissas!$E$28 | F15: =Premissas!$D$28 | G15: =E15*F15
A16: 1 | B16: 13 | C16: Tipo 09 | D16: Tipo | E16: =Premissas!$E$28 | F16: =Premissas!$D$28 | G16: =E16*F16
A17: 1 | B17: 14 | C17: Tipo 10 | D17: Tipo | E17: =Premissas!$E$28 | F17: =Premissas!$D$28 | G17: =E17*F17
A18: 1 | B18: 15 | C18: Tipo 11 | D18: Tipo | E18: =Premissas!$E$28 | F18: =Premissas!$D$28 | G18: =E18*F18
A19: 1 | B19: 16 | C19: Tipo 12 | D19: Tipo | E19: =Premissas!$E$28 | F19: =Premissas!$D$28 | G19: =E19*F19
... A31: 1 | B31: 28 | C31: Tipo 24 | D31: Tipo | E31: =Premissas!$E$28 | F31: =Premissas!$D$28 | G31: =E31*F31
A32: 1 | B32: 29 | C32: Técnico 1 | D32: Técnico | E32: =Premissas!$E$29 | F32: =Premissas!$D$29 | G32: =E32*F32
A33: 1 | B33: 30 | C33: Técnico 2 | D33: Técnico | E33: =Premissas!$E$29 | F33: =Premissas!$D$29 | G33: =E33*F33
A34: 2 | B34: 31 | C34: Subsolo 1 | D34: Subsolo | E34: =Premissas!$E$25 | F34: =Premissas!$D$25 | G34: =E34*F34
A35: 2 | B35: 32 | C35: Subsolo 2 | D35: Subsolo | E35: =Premissas!$E$25 | F35: =Premissas!$D$25 | G35: =E35*F35
A36: 2 | B36: 33 | C36: Térreo | D36: Térreo | E36: =Premissas!$E$26 | F36: =Premissas!$D$26 | G36: =E36*F36
A37: 2 | B37: 34 | C37: Lazer | D37: Lazer | E37: =Premissas!$E$27 | F37: =Premissas!$D$27 | G37: =E37*F37
A38: 2 | B38: 35 | C38: Tipo 01 | D38: Tipo | E38: =Premissas!$E$28 | F38: =Premissas!$D$28 | G38: =E38*F38
A39: 2 | B39: 36 | C39: Tipo 02 | D39: Tipo | E39: =Premissas!$E$28 | F39: =Premissas!$D$28 | G39: =E39*F39
A40: 2 | B40: 37 | C40: Tipo 03 | D40: Tipo | E40: =Premissas!$E$28 | F40: =Premissas!$D$28 | G40: =E40*F40
A41: 2 | B41: 38 | C41: Tipo 04 | D41: Tipo | E41: =Premissas!$E$28 | F41: =Premissas!$D$28 | G41: =E41*F41
A42: 2 | B42: 39 | C42: Tipo 05 | D42: Tipo | E42: =Premissas!$E$28 | F42: =Premissas!$D$28 | G42: =E42*F42
A43: 2 | B43: 40 | C43: Tipo 06 | D43: Tipo | E43: =Premissas!$E$28 | F43: =Premissas!$D$28 | G43: =E43*F43
A44: 2 | B44: 41 | C44: Tipo 07 | D44: Tipo | E44: =Premissas!$E$28 | F44: =Premissas!$D$28 | G44: =E44*F44
A45: 2 | B45: 42 | C45: Tipo 08 | D45: Tipo | E45: =Premissas!$E$28 | F45: =Premissas!$D$28 | G45: =E45*F45
A46: 2 | B46: 43 | C46: Tipo 09 | D46: Tipo | E46: =Premissas!$E$28 | F46: =Premissas!$D$28 | G46: =E46*F46
A47: 2 | B47: 44 | C47: Tipo 10 | D47: Tipo | E47: =Premissas!$E$28 | F47: =Premissas!$D$28 | G47: =E47*F47
A48: 2 | B48: 45 | C48: Tipo 11 | D48: Tipo | E48: =Premissas!$E$28 | F48: =Premissas!$D$28 | G48: =E48*F48
A49: 2 | B49: 46 | C49: Tipo 12 | D49: Tipo | E49: =Premissas!$E$28 | F49: =Premissas!$D$28 | G49: =E49*F49
... A61: 2 | B61: 58 | C61: Tipo 24 | D61: Tipo | E61: =Premissas!$E$28 | F61: =Premissas!$D$28 | G61: =E61*F61
A62: 2 | B62: 59 | C62: Técnico 1 | D62: Técnico | E62: =Premissas!$E$29 | F62: =Premissas!$D$29 | G62: =E62*F62
A63: 2 | B63: 60 | C63: Técnico 2 | D63: Técnico | E63: =Premissas!$E$29 | F63: =Premissas!$D$29 | G63: =E63*F63
...

Sheet Rateio-valores
A1: RATEIO DE VALORES (R$) POR PAVIMENTO
A3: Torre | B3: Nº seq | C3: Pavimento | D3: Tipo | E3: % Peso | F3: R$ Material | G3: R$ MO | H3: R$ Total
A4: 1 | B4: 1 | C4: Subsolo 1 | D4: Subsolo | E4: =Pavimentos!$G$4/Pavimentos!$G$64 | F4: =E4*Premissas!$B$11 | G4: =E4*Premissas!$B$12 | H4: =F4+G4
A5: 1 | B5: 2 | C5: Subsolo 2 | D5: Subsolo | E5: =Pavimentos!$G$5/Pavimentos!$G$64 | F5: =E5*Premissas!$B$11 | G5: =E5*Premissas!$B$12 | H5: =F5+G5
A6: 1 | B6: 3 | C6: Térreo | D6: Térreo | E6: =Pavimentos!$G$6/Pavimentos!$G$64 | F6: =E6*Premissas!$B$11 | G6: =E6*Premissas!$B$12 | H6: =F6+G6
A7: 1 | B7: 4 | C7: Lazer | D7: Lazer | E7: =Pavimentos!$G$7/Pavimentos!$G$64 | F7: =E7*Premissas!$B$11 | G7: =E7*Premissas!$B$12 | H7: =F7+G7
A8: 1 | B8: 5 | C8: Tipo 01 | D8: Tipo | E8: =Pavimentos!$G$8/Pavimentos!$G$64 | F8: =E8*Premissas!$B$11 | G8: =E8*Premissas!$B$12 | H8: =F8+G8
A9: 1 | B9: 6 | C9: Tipo 02 | D9: Tipo | E9: =Pavimentos!$G$9/Pavimentos!$G$64 | F9: =E9*Premissas!$B$11 | G9: =E9*Premissas!$B$12 | H9: =F9+G9
A10: 1 | B10: 7 | C10: Tipo 03 | D10: Tipo | E10: =Pavimentos!$G$10/Pavimentos!$G$64 | F10: =E10*Premissas!$B$11 | G10: =E10*Premissas!$B$12 | H10: =F10+G10
A11: 1 | B11: 8 | C11: Tipo 04 | D11: Tipo | E11: =Pavimentos!$G$11/Pavimentos!$G$64 | F11: =E11*Premissas!$B$11 | G11: =E11*Premissas!$B$12 | H11: =F11+G11
A12: 1 | B12: 9 | C12: Tipo 05 | D12: Tipo | E12: =Pavimentos!$G$12/Pavimentos!$G$64 | F12: =E12*Premissas!$B$11 | G12: =E12*Premissas!$B$12 | H12: =F12+G12
A13: 1 | B13: 10 | C13: Tipo 06 | D13: Tipo | E13: =Pavimentos!$G$13/Pavimentos!$G$64 | F13: =E13*Premissas!$B$11 | G13: =E13*Premissas!$B$12 | H13: =F13+G13
A14: 1 | B14: 11 | C14: Tipo 07 | D14: Tipo | E14: =Pavimentos!$G$14/Pavimentos!$G$64 | F14: =E14*Premissas!$B$11 | G14: =E14*Premissas!$B$12 | H14: =F14+G14
A15: 1 | B15: 12 | C15: Tipo 08 | D15: Tipo | E15: =Pavimentos!$G$15/Pavimentos!$G$64 | F15: =E15*Premissas!$B$11 | G15: =E15*Premissas!$B$12 | H15: =F15+G15
A16: 1 | B16: 13 | C16: Tipo 09 | D16: Tipo | E16: =Pavimentos!$G$16/Pavimentos!$G$64 | F16: =E16*Premissas!$B$11 | G16: =E16*Premissas!$B$12 | H16: =F16+G16
A17: 1 | B17: 14 | C17: Tipo 10 | D17: Tipo | E17: =Pavimentos!$G$17/Pavimentos!$G$64 | F17: =E17*Premissas!$B$11 | G17: =E17*Premissas!$B$12 | H17: =F17+G17
A18: 1 | B18: 15 | C18: Tipo 11 | D18: Tipo | E18: =Pavimentos!$G$18/Pavimentos!$G$64 | F18: =E18*Premissas!$B$11 | G18: =E18*Premissas!$B$12 | H18: =F18+G18
A19: 1 | B19: 16 | C19: Tipo 12 | D19: Tipo | E19: =Pavimentos!$G$19/Pavimentos!$G$64 | F19: =E19*Premissas!$B$11 | G19: =E19*Premissas!$B$12 | H19: =F19+G19
A20: 1 | B20: 17 | C20: Tipo 13 | D20: Tipo | E20: =Pavimentos!$G$20/Pavimentos!$G$64 | F20: =E20*Premissas!$B$11 | G20: =E20*Premissas!$B$12 | H20: =F20+G20
A21: 1 | B21: 18 | C21: Tipo 14 | D21: Tipo | E21: =Pavimentos!$G$21/Pavimentos!$G$64 | F21: =E21*Premissas!$B$11 | G21: =E21*Premissas!$B$12 | H21: =F21+G21
A22: 1 | B22: 19 | C22: Tipo 15 | D22: Tipo | E22: =Pavimentos!$G$22/Pavimentos!$G$64 | F22: =E22*Premissas!$B$11 | G22: =E22*Premissas!$B$12 | H22: =F22+G22
A23: 1 | B23: 20 | C23: Tipo 16 | D23: Tipo | E23: =Pavimentos!$G$23/Pavimentos!$G$64 | F23: =E23*Premissas!$B$11 | G23: =E23*Premissas!$B$12 | H23: =F23+G23
A24: 1 | B24: 21 | C24: Tipo 17 | D24: Tipo | E24: =Pavimentos!$G$24/Pavimentos!$G$64 | F24: =E24*Premissas!$B$11 | G24: =E24*Premissas!$B$12 | H24: =F24+G24
A25: 1 | B25: 22 | C25: Tipo 18 | D25: Tipo | E25: =Pavimentos!$G$25/Pavimentos!$G$64 | F25: =E25*Premissas!$B$11 | G25: =E25*Premissas!$B$12 | H25: =F25+G25
A26: 1 | B26: 23 | C26: Tipo 19 | D26: Tipo | E26: =Pavimentos!$G$26/Pavimentos!$G$64 | F26: =E26*Premissas!$B$11 | G26: =E26*Premissas!$B$12 | H26: =F26+G26
A27: 1 | B27: 24 | C27: Tipo 20 | D27: Tipo | E27: =Pavimentos!$G$27/Pavimentos!$G$64 | F27: =E27*Premissas!$B$11 | G27: =E27*Premissas!$B$12 | H27: =F27+G27
A28: 1 | B28: 25 | C28: Tipo 21 | D28: Tipo | E28: =Pavimentos!$G$28/Pavimentos!$G$64 | F28: =E28*Premissas!$B$11 | G28: =E28*Premissas!$B$12 | H28: =F28+G28
A29: 1 | B29: 26 | C29: Tipo 22 | D29: Tipo | E29: =Pavimentos!$G$29/Pavimentos!$G$64 | F29: =E29*Premissas!$B$11 | G29: =E29*Premissas!$B$12 | H29: =F29+G29
A30: 1 | B30: 27 | C30: Tipo 23 | D30: Tipo | E30: =Pavimentos!$G$30/Pavimentos!$G$64 | F30: =E30*Premissas!$B$11 | G30: =E30*Premissas!$B$12 | H30: =F30+G30
A31: 1 | B31: 28 | C31: Tipo 24 | D31: Tipo | E31: =Pavimentos!$G$31/Pavimentos!$G$64 | F31: =E31*Premissas!$B$11 | G31: =E31*Premissas!$B$12 | H31: =F31+G31
A32: 1 | B32: 29 | C32: Técnico 1 | D32: Técnico | E32: =Pavimentos!$G$32/Pavimentos!$G$64 | F32: =E32*Premissas!$B$11 | G32: =E32*Premissas!$B$12 | H32: =F32+G32
A33: 1 | B33: 30 | C33: Técnico 2 | D33: Técnico | E33: =Pavimentos!$G$33/Pavimentos!$G$64 | F33: =E33*Premissas!$B$11 | G33: =E33*Premissas!$B$12 | H33: =F33+G33
A34: 2 | B34: 31 | C34: Subsolo 1 | D34: Subsolo | E34: =Pavimentos!$G$34/Pavimentos!$G$64 | F34: =E34*Premissas!$B$11 | G34: =E34*Premissas!$B$12 | H34: =F34+G34
A35: 2 | B35: 32 | C35: Subsolo 2 | D35: Subsolo | E35: =Pavimentos!$G$35/Pavimentos!$G$64 | F35: =E35*Premissas!$B$11 | G35: =E35*Premissas!$B$12 | H35: =F35+G35
A36: 2 | B36: 33 | C36: Térreo | D36: Térreo | E36: =Pavimentos!$G$36/Pavimentos!$G$64 | F36: =E36*Premissas!$B$11 | G36: =E36*Premissas!$B$12 | H36: =F36+G36
A37: 2 | B37: 34 | C37: Lazer | D37: Lazer | E37: =Pavimentos!$G$37/Pavimentos!$G$64 | F37: =E37*Premissas!$B$11 | G37: =E37*Premissas!$B$12 | H37: =F37+G37
A38: 2 | B38: 35 | C38: Tipo 01 | D38: Tipo | E38: =Pavimentos!$G$38/Pavimentos!$G$64 | F38: =E38*Premissas!$B$11 | G38: =E38*Premissas!$B$12 | H38: =F38+G38
A39: 2 | B39: 36 | C39: Tipo 02 | D39: Tipo | E39: =Pavimentos!$G$39/Pavimentos!$G$64 | F39: =E39*Premissas!$B$11 | G39: =E39*Premissas!$B$12 | H39: =F39+G39
A40: 2 | B40: 37 | C40: Tipo 03 | D40: Tipo | E40: =Pavimentos!$G$40/Pavimentos!$G$64 | F40: =E40*Premissas!$B$11 | G40: =E40*Premissas!$B$12 | H40: =F40+G40
A41: 2 | B41: 38 | C41: Tipo 04 | D41: Tipo | E41: =Pavimentos!$G$41/Pavimentos!$G$64 | F41: =E41*Premissas!$B$11 | G41: =E41*Premissas!$B$12 | H41: =F41+G41
...

Sheet Rateio-quantidades
A1: RATEIO DE QUANTIDADES FÍSICAS POR PAVIMENTO
A3: Torre | B3: Pavimento | C3: Tipo | D3: AC (m²) | E3: Tubulação (m) | F3: Vasos | G3: Lavatórios | H3: Chuveiros | I3: Pias cozinha | J3: Tanques AS
A4: 1 | B4: Subsolo 1 | C4: Subsolo | D4: =Pavimentos!$E$4 | E4: =D4*Premissas!$B$21*Pavimentos!$F$4 | F4: 0 | G4: 0 | H4: 0 | I4: 0 | J4: 0
A5: 1 | B5: Subsolo 2 | C5: Subsolo | D5: =Pavimentos!$E$5 | E5: =D5*Premissas!$B$21*Pavimentos!$F$5 | F5: 0 | G5: 0 | H5: 0 | I5: 0 | J5: 0
A6: 1 | B6: Térreo | C6: Térreo | D6: =Pavimentos!$E$6 | E6: =D6*Premissas!$B$21*Pavimentos!$F$6 | F6: 3 | G6: 3 | H6: 0 | I6: 1 | J6: 0
A7: 1 | B7: Lazer | C7: Lazer | D7: =Pavimentos!$E$7 | E7: =D7*Premissas!$B$21*Pavimentos!$F$7 | F7: 6 | G7: 6 | H7: 4 | I7: 2 | J7: 0
A8: 1 | B8: Tipo 01 | C8: Tipo | D8: =Pavimentos!$E$8 | E8: =D8*Premissas!$B$21*Pavimentos!$F$8 | F8: =ROUND(IFERROR(Premissas!$B$18/(Premissas!$B$28*Premissas!$B$15),0)*Premissas!$B$19,0) | G8: =ROUND(IFERROR(Premissas!$B$18/(Premissas!$B$28*Premissas!$B$15),0)*Premissas!$B$19,0) | H8: =ROUND(IFERROR(Premissas!$B$18/(Premissas!$B$28*Premissas!$B$15),0)*Premissas!$B$19,0) | I8: =ROUND(IFERROR(Premissas!$B$18/(Premissas!$B$28*Premissas!$B$15),0),0) | J8: =ROUND(IFERROR(Premissas!$B$18/(Premissas!$B$28*Premissas!$B$15),0),0)
A9: 1 | B9: Tipo 02 | C9: Tipo | D9: =Pavimentos!$E$9 | E9: =D9*Premissas!$B$21*Pavimentos!$F$9 | F9: =ROUND(IFERROR(Premissas!$B$18/(Premissas!$B$28*Premissas!$B$15),0)*Premissas!$B$19,0) | G9: =ROUND(IFERROR(Premissas!$B$18/(Premissas!$B$28*Premissas!$B$15),0)*Premissas!$B$19,0) | H9: =ROUND(IFERROR(Premissas!$B$18/(Premissas!$B$28*Premissas!$B$15),0)*Premissas!$B$19,0) | I9: =ROUND(IFERROR(Premissas!$B$18/(Premissas!$B$28*Premissas!$B$15),0),0) | J9: =ROUND(IFERROR(Premissas!$B$18/(Premissas!$B$28*Premissas!$B$15),0),0)
A10: 1 | B10: Tipo 03 | C10: Tipo | D10: =Pavimentos!$E$10 | E10: =D10*Premissas!$B$21*Pavimentos!$F$10 | F10: =ROUND(IFERROR(Premissas!$B$18/(Premissas!$B$28*Premissas!$B$15),0)*Premissas!$B$19,0) | G10: =ROUND(IFERROR(Premissas!$B$18/(Premissas!$B$28*Premissas!$B$15),0)*Premissas!$B$19,0) | H10: =ROUND(IFERROR(Premissas!$B$18/(Premissas!$B$28*Premissas!$B$15),0)*Premissas!$B$19,0) | I10: =ROUND(IFERROR(Premissas!$B$18/(Premissas!$B$28*Premissas!$B$15),0),0) | J10: =ROUND(IFERROR(Premissas!$B$18/(Premissas!$B$28*Premissas!$B$15),0),0)
A11: 1 | B11: Tipo 04 | C11: Tipo | D11: =Pavimentos!$E$11 | E11: =D11*Premissas!$B$21*Pavimentos!$F$11 | F11: =ROUND(IFERROR(Premissas!$B$18/(Premissas!$B$28*Premissas!$B$15),0)*Premissas!$B$19,0) | G11: =ROUND(IFERROR(Premissas!$B$18/(Premissas!$B$28*Premissas!$B$15),0)*Premissas!$B$19,0) | H11: =ROUND(IFERROR(Premissas!$B$18/(Premissas!$B$28*Premissas!$B$15),0)*Premissas!$B$19,0) | I11: =ROUND(IFERROR(Premissas!$B$18/(Premissas!$B$28*Premissas!$B$15),0),0) | J11: =ROUND(IFERROR(Premissas!$B$18/(Premissas!$B$28*Premissas!$B$15),0),0)
A12: 1 | B12: Tipo 05 | C12: Tipo | D12: =Pavimentos!$E$12 | E12: =D12*Premissas!$B$21*Pavimentos!$F$12 | F12: =ROUND(IFERROR(Premissas!$B$18/(Premissas!$B$28*Premissas!$B$15),0)*Premissas!$B$19,0) | G12: =ROUND(IFERROR(Premissas!$B$18/(Premissas!$B$28*Premissas!$B$15),0)*Premissas!$B$19,0) | H12: =ROUND(IFERROR(Premissas!$B$18/(Premissas!$B$28*Premissas!$B$15),0)*Premissas!$B$19,0) | I12: =ROUND(IFERROR(Premissas!$B$18/(Premissas!$B$28*Premissas!$B$15),0),0) | J12: =ROUND(IFERROR(Premissas!$B$18/(Premissas!$B$28*Premissas!$B$15),0),0)
A13: 1 | B13: Tipo 06 | C13: Tipo | D13: =Pavimentos!$E$13 | E13: =D13*Premissas!$B$21*Pavimentos!$F$13 | F13: =ROUND(IFERROR(Premissas!$B$18/(Premissas!$B$28*Premissas!$B$15),0)*Premissas!$B$19,0) | G13: =ROUND(IFERROR(Premissas!$B$18/(Premissas!$B$28*Premissas!$B$15),0)*Premissas!$B$19,0) | H13: =ROUND(IFERROR(Premissas!$B$18/(Premissas!$B$28*Premissas!$B$15),0)*Premissas!$B$19,0) | I13: =ROUND(IFERROR(Premissas!$B$18/(Premissas!$B$28*Premissas!$B$15),0),0) | J13: =ROUND(IFERROR(Premissas!$B$18/(Premissas!$B$28*Premissas!$B$15),0),0)
A14: 1 | B14: Tipo 07 | C14: Tipo | D14: =Pavimentos!$E$14 | E14: =D14*Premissas!$B$21*Pavimentos!$F$14 | F14: =ROUND(IFERROR(Premissas!$B$18/(Premissas!$B$28*Premissas!$B$15),0)*Premissas!$B$19,0) | G14: =ROUND(IFERROR(Premissas!$B$18/(Premissas!$B$28*Premissas!$B$15),0)*Premissas!$B$19,0) | H14: =ROUND(IFERROR(Premissas!$B$18/(Premissas!$B$28*Premissas!$B$15),0)*Premissas!$B$19,0) | I14: =ROUND(IFERROR(Premissas!$B$18/(Premissas!$B$28*Premissas!$B$15),0),0) | J14: =ROUND(IFERROR(Premissas!$B$18/(Premissas!$B$28*Premissas!$B$15),0),0)
A15: 1 | B15: Tipo 08 | C15: Tipo | D15: =Pavimentos!$E$15 | E15: =D15*Premissas!$B$21*Pavimentos!$F$15 | F15: =ROUND(IFERROR(Premissas!$B$18/(Premissas!$B$28*Premissas!$B$15),0)*Premissas!$B$19,0) | G15: =ROUND(IFERROR(Premissas!$B$18/(Premissas!$B$28*Premissas!$B$15),0)*Premissas!$B$19,0) | H15: =ROUND(IFERROR(Premissas!$B$18/(Premissas!$B$28*Premissas!$B$15),0)*Premissas!$B$19,0) | I15: =ROUND(IFERROR(Premissas!$B$18/(Premissas!$B$28*Premissas!$B$15),0),0) | J15: =ROUND(IFERROR(Premissas!$B$18/(Premissas!$B$28*Premissas!$B$15),0),0)
A16: 1 | B16: Tipo 09 | C16: Tipo | D16: =Pavimentos!$E$16 | E16: =D16*Premissas!$B$21*Pavimentos!$F$16 | F16: =ROUND(IFERROR(Premissas!$B$18/(Premissas!$B$28*Premissas!$B$15),0)*Premissas!$B$19,0) | G16: =ROUND(IFERROR(Premissas!$B$18/(Premissas!$B$28*Premissas!$B$15),0)*Premissas!$B$19,0) | H16: =ROUND(IFERROR(Premissas!$B$18/(Premissas!$B$28*Premissas!$B$15),0)*Premissas!$B$19,0) | I16: =ROUND(IFERROR(Premissas!$B$18/(Premissas!$B$28*Premissas!$B$15),0),0) | J16: =ROUND(IFERROR(Premissas!$B$18/(Premissas!$B$28*Premissas!$B$15),0),0)
A17: 1 | B17: Tipo 10 | C17: Tipo | D17: =Pavimentos!$E$17 | E17: =D17*Premissas!$B$21*Pavimentos!$F$17 | F17: =ROUND(IFERROR(Premissas!$B$18/(Premissas!$B$28*Premissas!$B$15),0)*Premissas!$B$19,0) | G17: =ROUND(IFERROR(Premissas!$B$18/(Premissas!$B$28*Premissas!$B$15),0)*Premissas!$B$19,0) | H17: =ROUND(IFERROR(Premissas!$B$18/(Premissas!$B$28*Premissas!$B$15),0)*Premissas!$B$19,0) | I17: =ROUND(IFERROR(Premissas!$B$18/(Premissas!$B$28*Premissas!$B$15),0),0) | J17: =ROUND(IFERROR(Premissas!$B$18/(Premissas!$B$28*Premissas!$B$15),0),0)
A18: 1 | B18: Tipo 11 | C18: Tipo | D18: =Pavimentos!$E$18 | E18: =D18*Premissas!$B$21*Pavimentos!$F$18 | F18: =ROUND(IFERROR(Premissas!$B$18/(Premissas!$B$28*Premissas!$B$15),0)*Premissas!$B$19,0) | G18: =ROUND(IFERROR(Premissas!$B$18/(Premissas!$B$28*Premissas!$B$15),0)*Premissas!$B$19,0) | H18: =ROUND(IFERROR(Premissas!$B$18/(Premissas!$B$28*Premissas!$B$15),0)*Premissas!$B$19,0) | I18: =ROUND(IFERROR(Premissas!$B$18/(Premissas!$B$28*Premissas!$B$15),0),0) | J18: =ROUND(IFERROR(Premissas!$B$18/(Premissas!$B$28*Premissas!$B$15),0),0)
A19: 1 | B19: Tipo 12 | C19: Tipo | D19: =Pavimentos!$E$19 | E19: =D19*Premissas!$B$21*Pavimentos!$F$19 | F19: =ROUND(IFERROR(Premissas!$B$18/(Premissas!$B$28*Premissas!$B$15),0)*Premissas!$B$19,0) | G19: =ROUND(IFERROR(Premissas!$B$18/(Premissas!$B$28*Premissas!$B$15),0)*Premissas!$B$19,0) | H19: =ROUND(IFERROR(Premissas!$B$18/(Premissas!$B$28*Premissas!$B$15),0)*Premissas!$B$19,0) | I19: =ROUND(IFERROR(Premissas!$B$18/(Premissas!$B$28*Premissas!$B$15),0),0) | J19: =ROUND(IFERROR(Premissas!$B$18/(Premissas!$B$28*Premissas!$B$15),0),0)
A20: 1 | B20: Tipo 13 | C20: Tipo | D20: =Pavimentos!$E$20 | E20: =D20*Premissas!$B$21*Pavimentos!$F$20 | F20: =ROUND(IFERROR(Premissas!$B$18/(Premissas!$B$28*Premissas!$B$15),0)*Premissas!$B$19,0) | G20: =ROUND(IFERROR(Premissas!$B$18/(Premissas!$B$28*Premissas!$B$15),0)*Premissas!$B$19,0) | H20: =ROUND(IFERROR(Premissas!$B$18/(Premissas!$B$28*Premissas!$B$15),0)*Premissas!$B$19,0) | I20: =ROUND(IFERROR(Premissas!$B$18/(Premissas!$B$28*Premissas!$B$15),0),0) | J20: =ROUND(IFERROR(Premissas!$B$18/(Premissas!$B$28*Premissas!$B$15),0),0)
A21: 1 | B21: Tipo 14 | C21: Tipo | D21: =Pavimentos!$E$21 | E21: =D21*Premissas!$B$21*Pavimentos!$F$21 | F21: =ROUND(IFERROR(Premissas!$B$18/(Premissas!$B$28*Premissas!$B$15),0)*Premissas!$B$19,0) | G21: =ROUND(IFERROR(Premissas!$B$18/(Premissas!$B$28*Premissas!$B$15),0)*Premissas!$B$19,0) | H21: =ROUND(IFERROR(Premissas!$B$18/(Premissas!$B$28*Premissas!$B$15),0)*Premissas!$B$19,0) | I21: =ROUND(IFERROR(Premissas!$B$18/(Premissas!$B$28*Premissas!$B$15),0),0) | J21: =ROUND(IFERROR(Premissas!$B$18/(Premissas!$B$28*Premissas!$B$15),0),0)
A22: 1 | B22: Tipo 15 | C22: Tipo | D22: =Pavimentos!$E$22 | E22: =D22*Premissas!$B$21*Pavimentos!$F$22 | F22: =ROUND(IFERROR(Premissas!$B$18/(Premissas!$B$28*Premissas!$B$15),0)*Premissas!$B$19,0) | G22: =ROUND(IFERROR(Premissas!$B$18/(Premissas!$B$28*Premissas!$B$15),0)*Premissas!$B$19,0) | H22: =ROUND(IFERROR(Premissas!$B$18/(Premissas!$B$28*Premissas!$B$15),0)*Premissas!$B$19,0) | I22: =ROUND(IFERROR(Premissas!$B$18/(Premissas!$B$28*Premissas!$B$15),0),0) | J22: =ROUND(IFERROR(Premissas!$B$18/(Premissas!$B$28*Premissas!$B$15),0),0)
A23: 1 | B23: Tipo 16 | C23: Tipo | D23: =Pavimentos!$E$23 | E23: =D23*Premissas!$B$21*Pavimentos!$F$23 | F23: =ROUND(IFERROR(Premissas!$B$18/(Premissas!$B$28*Premissas!$B$15),0)*Premissas!$B$19,0) | G23: =ROUND(IFERROR(Premissas!$B$18/(Premissas!$B$28*Premissas!$B$15),0)*Premissas!$B$19,0) | H23: =ROUND(IFERROR(Premissas!$B$18/(Premissas!$B$28*Premissas!$B$15),0)*Premissas!$B$19,0) | I23: =ROUND(IFERROR(Premissas!$B$18/(Premissas!$B$28*Premissas!$B$15),0),0) | J23: =ROUND(IFERROR(Premissas!$B$18/(Premissas!$B$28*Premissas!$B$15),0),0)
A24: 1 | B24: Tipo 17 | C24: Tipo | D24: =Pavimentos!$E$24 | E24: =D24*Premissas!$B$21*Pavimentos!$F$24 | F24: =ROUND(IFERROR(Premissas!$B$18/(Premissas!$B$28*Premissas!$B$15),0)*Premissas!$B$19,0) | G24: =ROUND(IFERROR(Premissas!$B$18/(Premissas!$B$28*Premissas!$B$15),0)*Premissas!$B$19,0) | H24: =ROUND(IFERROR(Premissas!$B$18/(Premissas!$B$28*Premissas!$B$15),0)*Premissas!$B$19,0) | I24: =ROUND(IFERROR(Premissas!$B$18/(Premissas!$B$28*Premissas!$B$15),0),0) | J24: =ROUND(IFERROR(Premissas!$B$18/(Premissas!$B$28*Premissas!$B$15),0),0)
A25: 1 | B25: Tipo 18 | C25: Tipo | D25: =Pavimentos!$E$25 | E25: =D25*Premissas!$B$21*Pavimentos!$F$25 | F25: =ROUND(IFERROR(Premissas!$B$18/(Premissas!$B$28*Premissas!$B$15),0)*Premissas!$B$19,0) | G25: =ROUND(IFERROR(Premissas!$B$18/(Premissas!$B$28*Premissas!$B$15),0)*Premissas!$B$19,0) | H25: =ROUND(IFERROR(Premissas!$B$18/(Premissas!$B$28*Premissas!$B$15),0)*Premissas!$B$19,0) | I25: =ROUND(IFERROR(Premissas!$B$18/(Premissas!$B$28*Premissas!$B$15),0),0) | J25: =ROUND(IFERROR(Premissas!$B$18/(Premissas!$B$28*Premissas!$B$15),0),0)
A26: 1 | B26: Tipo 19 | C26: Tipo | D26: =Pavimentos!$E$26 | E26: =D26*Premissas!$B$21*Pavimentos!$F$26 | F26: =ROUND(IFERROR(Premissas!$B$18/(Premissas!$B$28*Premissas!$B$15),0)*Premissas!$B$19,0) | G26: =ROUND(IFERROR(Premissas!$B$18/(Premissas!$B$28*Premissas!$B$15),0)*Premissas!$B$19,0) | H26: =ROUND(IFERROR(Premissas!$B$18/(Premissas!$B$28*Premissas!$B$15),0)*Premissas!$B$19,0) | I26: =ROUND(IFERROR(Premissas!$B$18/(Premissas!$B$28*Premissas!$B$15),0),0) | J26: =ROUND(IFERROR(Premissas!$B$18/(Premissas!$B$28*Premissas!$B$15),0),0)
A27: 1 | B27: Tipo 20 | C27: Tipo | D27: =Pavimentos!$E$27 | E27: =D27*Premissas!$B$21*Pavimentos!$F$27 | F27: =ROUND(IFERROR(Premissas!$B$18/(Premissas!$B$28*Premissas!$B$15),0)*Premissas!$B$19,0) | G27: =ROUND(IFERROR(Premissas!$B$18/(Premissas!$B$28*Premissas!$B$15),0)*Premissas!$B$19,0) | H27: =ROUND(IFERROR(Premissas!$B$18/(Premissas!$B$28*Premissas!$B$15),0)*Premissas!$B$19,0) | I27: =ROUND(IFERROR(Premissas!$B$18/(Premissas!$B$28*Premissas!$B$15),0),0) | J27: =ROUND(IFERROR(Premissas!$B$18/(Premissas!$B$28*Premissas!$B$15),0),0)
A28: 1 | B28: Tipo 21 | C28: Tipo | D28: =Pavimentos!$E$28 | E28: =D28*Premissas!$B$21*Pavimentos!$F$28 | F28: =ROUND(IFERROR(Premissas!$B$18/(Premissas!$B$28*Premissas!$B$15),0)*Premissas!$B$19,0) | G28: =ROUND(IFERROR(Premissas!$B$18/(Premissas!$B$28*Premissas!$B$15),0)*Premissas!$B$19,0) | H28: =ROUND(IFERROR(Premissas!$B$18/(Premissas!$B$28*Premissas!$B$15),0)*Premissas!$B$19,0) | I28: =ROUND(IFERROR(Premissas!$B$18/(Premissas!$B$28*Premissas!$B$15),0),0) | J28: =ROUND(IFERROR(Premissas!$B$18/(Premissas!$B$28*Premissas!$B$15),0),0)
A29: 1 | B29: Tipo 22 | C29: Tipo | D29: =Pavimentos!$E$29 | E29: =D29*Premissas!$B$21*Pavimentos!$F$29 | F29: =ROUND(IFERROR(Premissas!$B$18/(Premissas!$B$28*Premissas!$B$15),0)*Premissas!$B$19,0) | G29: =ROUND(IFERROR(Premissas!$B$18/(Premissas!$B$28*Premissas!$B$15),0)*Premissas!$B$19,0) | H29: =ROUND(IFERROR(Premissas!$B$18/(Premissas!$B$28*Premissas!$B$15),0)*Premissas!$B$19,0) | I29: =ROUND(IFERROR(Premissas!$B$18/(Premissas!$B$28*Premissas!$B$15),0),0) | J29: =ROUND(IFERROR(Premissas!$B$18/(Premissas!$B$28*Premissas!$B$15),0),0)
A30: 1 | B30: Tipo 23 | C30: Tipo | D30: =Pavimentos!$E$30 | E30: =D30*Premissas!$B$21*Pavimentos!$F$30 | F30: =ROUND(IFERROR(Premissas!$B$18/(Premissas!$B$28*Premissas!$B$15),0)*Premissas!$B$19,0) | G30: =ROUND(IFERROR(Premissas!$B$18/(Premissas!$B$28*Premissas!$B$15),0)*Premissas!$B$19,0) | H30: =ROUND(IFERROR(Premissas!$B$18/(Premissas!$B$28*Premissas!$B$15),0)*Premissas!$B$19,0) | I30: =ROUND(IFERROR(Premissas!$B$18/(Premissas!$B$28*Premissas!$B$15),0),0) | J30: =ROUND(IFERROR(Premissas!$B$18/(Premissas!$B$28*Premissas!$B$15),0),0)
A31: 1 | B31: Tipo 24 | C31: Tipo | D31: =Pavimentos!$E$31 | E31: =D31*Premissas!$B$21*Pavimentos!$F$31 | F31: =ROUND(IFERROR(Premissas!$B$18/(Premissas!$B$28*Premissas!$B$15),0)*Premissas!$B$19,0) | G31: =ROUND(IFERROR(Premissas!$B$18/(Premissas!$B$28*Premissas!$B$15),0)*Premissas!$B$19,0) | H31: =ROUND(IFERROR(Premissas!$B$18/(Premissas!$B$28*Premissas!$B$15),0)*Premissas!$B$19,0) | I31: =ROUND(IFERROR(Premissas!$B$18/(Premissas!$B$28*Premissas!$B$15),0),0) | J31: =ROUND(IFERROR(Premissas!$B$18/(Premissas!$B$28*Premissas!$B$15),0),0)
A32: 1 | B32: Técnico 1 | C32: Técnico | D32: =Pavimentos!$E$32 | E32: =D32*Premissas!$B$21*Pavimentos!$F$32 | F32: 0 | G32: 0 | H32: 0 | I32: 0 | J32: 0
A33: 1 | B33: Técnico 2 | C33: Técnico | D33: =Pavimentos!$E$33 | E33: =D33*Premissas!$B$21*Pavimentos!$F$33 | F33: 0 | G33: 0 | H33: 0 | I33: 0 | J33: 0
A34: 2 | B34: Subsolo 1 | C34: Subsolo | D34: =Pavimentos!$E$34 | E34: =D34*Premissas!$B$21*Pavimentos!$F$34 | F34: 0 | G34: 0 | H34: 0 | I34: 0 | J34: 0
A35: 2 | B35: Subsolo 2 | C35: Subsolo | D35: =Pavimentos!$E$35 | E35: =D35*Premissas!$B$21*Pavimentos!$F$35 | F35: 0 | G35: 0 | H35: 0 | I35: 0 | J35: 0
A36: 2 | B36: Térreo | C36: Térreo | D36: =Pavimentos!$E$36 | E36: =D36*Premissas!$B$21*Pavimentos!$F$36 | F36: 3 | G36: 3 | H36: 0 | I36: 1 | J36: 0
A37: 2 | B37: Lazer | C37: Lazer | D37: =Pavimentos!$E$37 | E37: =D37*Premissas!$B$21*Pavimentos!$F$37 | F37: 6 | G37: 6 | H37: 4 | I37: 2 | J37: 0
A38: 2 | B38: Tipo 01 | C38: Tipo | D38: =Pavimentos!$E$38 | E38: =D38*Premissas!$B$21*Pavimentos!$F$38 | F38: =ROUND(IFERROR(Premissas!$B$18/(Premissas!$B$28*Premissas!$B$15),0)*Premissas!$B$19,0) | G38: =ROUND(IFERROR(Premissas!$B$18/(Premissas!$B$28*Premissas!$B$15),0)*Premissas!$B$19,0) | H38: =ROUND(IFERROR(Premissas!$B$18/(Premissas!$B$28*Premissas!$B$15),0)*Premissas!$B$19,0) | I38: =ROUND(IFERROR(Premissas!$B$18/(Premissas!$B$28*Premissas!$B$15),0),0) | J38: =ROUND(IFERROR(Premissas!$B$18/(Premissas!$B$28*Premissas!$B$15),0),0)
A39: 2 | B39: Tipo 02 | C39: Tipo | D39: =Pavimentos!$E$39 | E39: =D39*Premissas!$B$21*Pavimentos!$F$39 | F39: =ROUND(IFERROR(Premissas!$B$18/(Premissas!$B$28*Premissas!$B$15),0)*Premissas!$B$19,0) | G39: =ROUND(IFERROR(Premissas!$B$18/(Premissas!$B$28*Premissas!$B$15),0)*Premissas!$B$19,0) | H39: =ROUND(IFERROR(Premissas!$B$18/(Premissas!$B$28*Premissas!$B$15),0)*Premissas!$B$19,0) | I39: =ROUND(IFERROR(Premissas!$B$18/(Premissas!$B$28*Premissas!$B$15),0),0) | J39: =ROUND(IFERROR(Premissas!$B$18/(Premissas!$B$28*Premissas!$B$15),0),0)
A40: 2 | B40: Tipo 03 | C40: Tipo | D40: =Pavimentos!$E$40 | E40: =D40*Premissas!$B$21*Pavimentos!$F$40 | F40: =ROUND(IFERROR(Premissas!$B$18/(Premissas!$B$28*Premissas!$B$15),0)*Premissas!$B$19,0) | G40: =ROUND(IFERROR(Premissas!$B$18/(Premissas!$B$28*Premissas!$B$15),0)*Premissas!$B$19,0) | H40: =ROUND(IFERROR(Premissas!$B$18/(Premissas!$B$28*Premissas!$B$15),0)*Premissas!$B$19,0) | I40: =ROUND(IFERROR(Premissas!$B$18/(Premissas!$B$28*Premissas!$B$15),0),0) | J40: =ROUND(IFERROR(Premissas!$B$18/(Premissas!$B$28*Premissas!$B$15),0),0)
A41: 2 | B41: Tipo 04 | C41: Tipo | D41: =Pavimentos!$E$41 | E41: =D41*Premissas!$B$21*Pavimentos!$F$41 | F41: =ROUND(IFERROR(Premissas!$B$18/(Premissas!$B$28*Premissas!$B$15),0)*Premissas!$B$19,0) | G41: =ROUND(IFERROR(Premissas!$B$18/(Premissas!$B$28*Premissas!$B$15),0)*Premissas!$B$19,0) | H41: =ROUND(IFERROR(Premissas!$B$18/(Premissas!$B$28*Premissas!$B$15),0)*Premissas!$B$19,0) | I41: =ROUND(IFERROR(Premissas!$B$18/(Premissas!$B$28*Premissas!$B$15),0),0) | J41: =ROUND(IFERROR(Premissas!$B$18/(Premissas!$B$28*Premissas!$B$15),0),0)
...

Sheet Resumo-por-tipo
A1: RESUMO POR TIPO DE PAVIMENTO
A3: Tipo | B3: Qtd total | C3: AC total (m²) | D3: R$ total | E3: % R$ | F3: Tubulação (m)
A4: Subsolo | B4: =Premissas!$B$25*Premissas!$B$15 | C4: =Premissas!$B$20*Premissas!$C$25 | D4: =SUMIF('Rateio-valores'!D:D,"Subsolo",'Rateio-valores'!H:H) | E4: =D4/Premissas!$B$8 | F4: =C4*Premissas!$B$21*Premissas!$D$25
A5: Térreo | B5: =Premissas!$B$26*Premissas!$B$15 | C5: =Premissas!$B$20*Premissas!$C$26 | D5: =SUMIF('Rateio-valores'!D:D,"Térreo",'Rateio-valores'!H:H) | E5: =D5/Premissas!$B$8 | F5: =C5*Premissas!$B$21*Premissas!$D$26
A6: Lazer | B6: =Premissas!$B$27*Premissas!$B$15 | C6: =Premissas!$B$20*Premissas!$C$27 | D6: =SUMIF('Rateio-valores'!D:D,"Lazer",'Rateio-valores'!H:H) | E6: =D6/Premissas!$B$8 | F6: =C6*Premissas!$B$21*Premissas!$D$27
A7: Tipo | B7: =Premissas!$B$28*Premissas!$B$15 | C7: =Premissas!$B$20*Premissas!$C$28 | D7: =SUMIF('Rateio-valores'!D:D,"Tipo",'Rateio-valores'!H:H) | E7: =D7/Premissas!$B$8 | F7: =C7*Premissas!$B$21*Premissas!$D$28
A8: Técnico | B8: =Premissas!$B$29*Premissas!$B$15 | C8: =Premissas!$B$20*Premissas!$C$29 | D8: =SUMIF('Rateio-valores'!D:D,"Técnico",'Rateio-valores'!H:H) | E8: =D8/Premissas!$B$8 | F8: =C8*Premissas!$B$21*Premissas!$D$29
A9: TOTAL | B9: =SUM(B4:B8) | C9: =SUM(C4:C8) | D9: =SUM(D4:D8) | E9: =SUM(E4:E8)
