Workbook

Sheet SEM IMPREVISTOS
A1: ETAPA | B1: VALOR ORÇADO | C1: % | D1: VALOR / m²
A2: GERENCIAMENTO TÉCNICO E ADMINISTRATIVO | B2: =[1]Obra!$C$33 -> 7713624.6 | C2: =B2/B$18 -> 0.12886234 | D2: =B2/'SEM IMPREVISTOS'!G$2 -> 494.3728 | F2: ÁREA CONSTRUÍDA | G2: 15602.85 | H2: m²
A3: MOVIMENTAÇÃO DE TERRA | B3: =B46 -> 1415598.8 | C3: =B3/B$18 -> 0.023648722 | D3: =B3/'SEM IMPREVISTOS'!G$2 -> 90.726936
A4: ESTRUTURA | B4: =C47 -> 18362172 | C4: =B4/B$18 -> 0.30675492 | D4: =B4/'SEM IMPREVISTOS'!G$2 -> 1176.8473
A5: PAREDES E PAINÉIS | B5: =C52 -> 3110673.8 | C5: =B5/B$18 -> 0.05196632 | D5: =B5/'SEM IMPREVISTOS'!G$2 -> 199.36574
A6: INSTALAÇÕES ELÉTRICAS, HIDRÁULICAS, GLP E PREVENTIVAS | B6: =C56+C58+C60+C62+C64 -> 6044697.4 | C6: =B6/B$18 -> 0.10098156 | D6: =B6/'SEM IMPREVISTOS'!G$2 -> 387.40982
A7: EQUIPAMENTOS E SISTEMAS ESPECIAIS | B7: =B66+C67 -> 2681510.5 | C7: =B7/B$18 -> 0.0447968 | D7: =B7/'SEM IMPREVISTOS'!G$2 -> 171.8603 | E7: Incluso climatização
A8: IMPERMEABILIZAÇÃO | B8: =C54 -> 802414.61 | C8: =B8/B$18 -> 0.013404985 | D8: =B8/'SEM IMPREVISTOS'!G$2 -> 51.427438
A9: REVESTIMENTOS INTERNOS DE PAREDE | B9: =B70+B72+C74 -> 1879566.7 | C9: =B9/B$18 -> 0.031399681 | D9: =B9/'SEM IMPREVISTOS'!G$2 -> 120.46304
A10: REVESTIMENTOS E ACABAMENTOS INTERNOS EM TETO | B10: =C76 -> 1650987.9 | C10: =B10/B$18 -> 0.027581087 | D10: =B10/'SEM IMPREVISTOS'!G$2 -> 105.81323
A11: PISOS E PAVIMENTAÇÕES | B11: =C78 -> 2503625 | C11: =B11/B$18 -> 0.04182508 | D11: =B11/'SEM IMPREVISTOS'!G$2 -> 160.45947
A12: PINTURA INTERNA | B12: =C88 -> 2472056.2 | C12: =B12/B$18 -> 0.041297697 | D12: =B12/'SEM IMPREVISTOS'!G$2 -> 158.43619
A13: ESQUADRIAS, VIDROS E FERRAGENS | B13: =C91 -> 4972981 | C13: =B13/B$18 -> 0.083077667 | D13: =B13/'SEM IMPREVISTOS'!G$2 -> 318.7226
A14: LOUÇAS E METAIS | B14: =C93 -> 280601.77 | C14: =B14/B$18 -> 0.0046876793 | D14: =B14/'SEM IMPREVISTOS'!G$2 -> 17.984007
A15: REVESTIMENTOS E ACABAMENTOS DE FACHADA | B15: =B71+B73+B90 -> 2575360 | C15: =B15/B$18 -> 0.04302347 | D15: =B15/'SEM IMPREVISTOS'!G$2 -> 165.05702
A16: SERVIÇOS COMPLEMENTARES | B16: =C95 -> 2465512.5 | C16: =B16/B$18 -> 0.041188379 | D16: =B16/'SEM IMPREVISTOS'!G$2 -> 158.0168
A17: IMPREVISTOS E CONTIGÊNCIAS | B17: =B51+B53+B55+B57+B59+B61+B63+B65+B68+B75+B77+B86+B89+B92+B94+B96 -> 928037.5 | C17: =B17/B$18 -> 0.015503617 | D17: =B17/'SEM IMPREVISTOS'!G$2 -> 59.478717
A18: TOTAL | B18: =SUM(B2:B17) -> 59859420 | C18: =SUM(C2:C17) -> 1 | D18: =SUM(D2:D17) -> 3836.4414
A19: CUB/SC | B19: 2934.53 | C19: 45809 | D19: =ROUNDDOWN(D18/B19,2)&" CUB" -> 1,3 CUB
A22: Rótulos de Linha | B22: Soma de %
A23: ESTRUTURA | B23: 0.31758611
A24: GERENCIAMENTO TÉCNICO E ADMINISTRATIVO | B24: 0.13135231
A25: INSTALAÇÕES ELÉTRICAS, HIDRÁULICAS, GLP E PREVENTIVAS | B25: 0.090635559
A26: ESQUADRIAS, VIDROS E FERRAGENS | B26: 0.080775089
A27: PAREDES E PAINÉIS | B27: 0.053801195
A28: EQUIPAMENTOS E SISTEMAS ESPECIAIS | B28: 0.04446455
A29: PINTURA INTERNA | B29: 0.042755874
A30: SERVIÇOS COMPLEMENTARES | B30: 0.041834177
A31: PISOS E PAVIMENTAÇÕES | B31: 0.039504046
A32: REVESTIMENTOS E ACABAMENTOS DE FACHADA | B32: 0.039035094
A33: REVESTIMENTOS INTERNOS DE PAREDE | B33: 0.031098469
A34: REVESTIMENTOS E ACABAMENTOS INTERNOS EM TETO | B34: 0.027974545
... A38: Total Geral | B38: 0.98296769
A44: GERENCIAMENTO TÉCNICO E ADMINISTRATIVO | B44: =[1]Ger_Administrativo!$N$127 -> 7713624.6
A45: MEGA
A46: MOVIMENTAÇÃO DE TERRA | B46: ='[1]Ger_Executivo MEGA'!$N$127 -> 1415598.8
A47: ESTRUTURA | B47: ='[1]Ger_Executivo MEGA'!$N$133 -> 18749747 | C47: =B47-B51 -> 18362172 | D47: SEM IMPREVISTO
A48: INFRAESTRUTURA | B48: ='[1]Ger_Executivo MEGA'!$N$134 -> 2368306.5
A49: SUPRAESTRUTURA | B49: ='[1]Ger_Executivo MEGA'!$N$152 -> 4417376.6
A50: ESTRUTURA GERAL | B50: ='[1]Ger_Executivo MEGA'!$N$169 -> 11964064 | C50: =B50-B51 -> 11576489
...

Sheet ORÇAMENTO_EXECUTIVO - IMPREVIST
A1: ETAPA | B1: VALOR ORÇADO | C1: % | D1: IMPREVISTOS | E1: TOTAL
A2: GERENCIAMENTO TÉCNICO E ADMINISTRATIVO | B2: ='SEM IMPREVISTOS'!B2 -> 7713624.6 | E2: =D2+B2 -> 7713624.6 | F2: =E2/$H$2 -> 494.3728 | G2: ÁREA CONSTRUÍDA | H2: =[1]Obra!$E$10 -> 15602.85 | I2: m²
A3: MOVIMENTAÇÃO DE TERRA | B3: ='SEM IMPREVISTOS'!B3 -> 1415598.8 | E3: =D3+B3 -> 1415598.8 | F3: =E3/$H$2 -> 90.726936
A4: INFRAESTRUTURA E SUPRAESTRUTURA | B4: ='SEM IMPREVISTOS'!B4 -> 18362172 | C4: =B4/$B$20 -> 0.40387355 | D4: =C4*$B$18 -> 413709.96 | E4: =D4+B4 -> 18775882 | F4: =E4/$H$2 -> 1203.3623
A5: PAREDES E PAINÉIS | B5: ='SEM IMPREVISTOS'!B5 -> 3110673.8 | C5: =B5/$B$20 -> 0.06841886 | D5: =C5*$B$18 -> 70085.212 | E5: =D5+B5 -> 3180759 | F5: =E5/$H$2 -> 203.85756
A6: INSTALAÇÕES ELÉTRICAS, HIDRÁULICAS, GLP E PREVENTIVAS E COMUNICAÇÃO E LOUÇAS E METAIS | B6: ='SEM IMPREVISTOS'!C56+'SEM IMPREVISTOS'!C58+'SEM IMPREVISTOS'!C60+'SEM IMPREVISTOS'!C62+'SEM IMPREVISTOS'!C64+'SEM IMPREVISTOS'!C93 -> 6325299.1 | C6: =B6/$B$20 -> 0.13912412 | D6: =C6*$B$18 -> 142512.51 | E6: =D6+B6 -> 6467811.6 | F6: =E6/$H$2 -> 414.52758 | H6: eletrica | I6: ='SEM IMPREVISTOS'!C58 -> 3081050.9 | J6: =I6/$B$6 -> 0.48709964 | K6: =J6*$D$6 -> 69417.793
A7: ELEVADOR | B7: ='SEM IMPREVISTOS'!B66 -> 1794333.1 | D7: =C7*$B$18 -> 0 | E7: =D7+B7 -> 1794333.1 | F7: =E7/$H$2 -> 115.00034 | H7: hidro | I7: ='SEM IMPREVISTOS'!C56 -> 2150552.2 | J7: =I7/$B$6 -> 0.33999218 | K7: =J7*$D$6 -> 48453.14
A8: CLIMATIZAÇÃO | B8: ='SEM IMPREVISTOS'!C67 -> 887177.39 | C8: =B8/$B$20 -> 0.01951335 | D8: =C8*$B$18 -> 19988.601 | E8: =D8+B8 -> 907165.99 | F8: =E8/$H$2 -> 58.141044 | H8: gas | I8: ='SEM IMPREVISTOS'!C62 -> 299263.85 | J8: =I8/$B$6 -> 0.047312204 | K8: =J8*$D$6 -> 6742.5811
A9: IMPERMEABILIZAÇÃO | B9: ='SEM IMPREVISTOS'!C54 -> 802414.61 | C9: =B9/$B$20 -> 0.017649004 | D9: =C9*$B$18 -> 18078.848 | E9: =D9+B9 -> 820493.45 | F9: =E9/$H$2 -> 52.586127 | H9: preventivo | I9: ='SEM IMPREVISTOS'!C60 -> 304981.48 | J9: =I9/$B$6 -> 0.048216136 | K9: =J9*$D$6 -> 6871.4026
A10: REVESTIMENTOS INTERNOS E EXTERNOS DE PAREDE | B10: ='SEM IMPREVISTOS'!B69 -> 2542675.7 | D10: =C10*$B$18 -> 0 | E10: =D10+B10 -> 2542675.7 | F10: =E10/$H$2 -> 162.96226 | H10: comunicação | I10: ='SEM IMPREVISTOS'!C64 -> 208848.89 | J10: =I10/$B$6 -> 0.033018026 | K10: =J10*$D$6 -> 4705.4819
A11: ACABAMENTOS INTERNOS DE PAREDE | B11: ='SEM IMPREVISTOS'!C74 -> 572185.25 | C11: =B11/$B$20 -> 0.012585139 | D11: =C11*$B$18 -> 12891.652 | E11: =D11+B11 -> 585076.91 | F11: =E11/$H$2 -> 37.498079 | H11: LOUÇAS | I11: ='SEM IMPREVISTOS'!C93 -> 280601.77 | J11: =I11/$B$6 -> 0.044361818 | K11: =J11*$D$6 -> 6322.1141
A12: REVESTIMENTOS E ACABAMENTOS INTERNOS EM TETO | B12: ='SEM IMPREVISTOS'!C76 -> 1650987.9 | C12: =B12/$B$20 -> 0.036313261 | D12: =C12*$B$18 -> 37197.676 | E12: =D12+B12 -> 1688185.6 | F12: =E12/$H$2 -> 108.19726
A13: PISOS E PAVIMENTAÇÕES | B13: ='SEM IMPREVISTOS'!C78 -> 2503625 | C13: =B13/$B$20 -> 0.055066903 | D13: =C13*$B$18 -> 56408.066 | E13: =D13+B13 -> 2560033.1 | F13: =E13/$H$2 -> 164.07471
A14: PINTURA INTERNA E EXTERNA | B14: ='SEM IMPREVISTOS'!C87 -> 3812121.9 | C14: =B14/$B$20 -> 0.083847121 | D14: =C14*$B$18 -> 85889.23 | E14: =D14+B14 -> 3898011.2 | F14: =E14/$H$2 -> 249.82687
A15: ESQUADRIAS, VIDROS E FERRAGENS | B15: ='SEM IMPREVISTOS'!C91 -> 4972981 | C15: =B15/$B$20 -> 0.10938006 | D15: =C15*$B$18 -> 112044.03 | E15: =D15+B15 -> 5085025 | F15: =E15/$H$2 -> 325.9036 | H15: especiais | I15: ='[1]Ger_Executivo MEGA'!$N$178 -> 3110673.8
A16: REVESTIMENTOS E ACABAMENTOS DE FACHADA | D16: =C16*$B$18 -> 0 | H16: climatização | I16: ='SEM IMPREVISTOS'!C67 -> 887177.39 | J16: 0 | K16: =D7 -> 0
A17: SERVIÇOS COMPLEMENTARES | B17: ='SEM IMPREVISTOS'!C95 -> 2465512.5 | C17: =B17/$B$20 -> 0.054228622 | D17: =C17*$B$18 -> 55549.369 | E17: =D17+B17 -> 2521061.8 | F17: =E17/$H$2 -> 161.57701
A18: IMPREVISTOS E CONTIGÊNCIAS | B18: =(SUM(B3:B17))*0.02 -> 1024355.2 | D18: 0 | E18: 0 | F18: =E18/$H$2 -> 0
A19: TOTAL | B19: =SUM(B3:B17) -> 51217758 | C19: =SUM(C2:C18) -> 1 | D19: =SUM(D3:D18) -> 1024355.2 | E19: =SUM(E2:E18) -> 59955738 | F19: =E19/H2 -> 3842.6145
B20: =B4+B5+B6+B8+B9+B11+B12+B13+B14+B15+B17 -> 45465150 | D20: 2934.53 | E20: 45809 | F20: =ROUNDDOWN(F19/D20,2)&" CUB" -> 1,3 CUB
B22: 49238640
B23: 44160347

Sheet ANÁLISE_CUSTOS
A1: ETAPA | B1: TRAMONTI | D1: OBRAS DE REFERÊNCIA
B2: VALOR SEM IMPREVISTOS | C2: VALOR / m² | D2: VALOR / m²
A3: MOVIMENTAÇÃO DE TERRA | B3: ='SEM IMPREVISTOS'!B46 -> 1415598.8 | C3: =B3/'GER_EXECUTIVO CART'!G$2 -> 90.726936 | D3: =FIXED(CÁLCULO_MÉDIAS!X11,2,FALSE)&" "&"-"&FIXED(CÁLCULO_MÉDIAS!Y11,2,FALSE) -> 30,00 -90,00 | E3: Valores praticados repassados pela amalfi
A4: ='SEM IMPREVISTOS'!A4 -> ESTRUTURA | B4: ='SEM IMPREVISTOS'!C47 -> 18362172 | C4: =B4/'GER_EXECUTIVO CART'!G$2 -> 1176.8473 | D4: =FIXED(CÁLCULO_MÉDIAS!X12,2,FALSE)&" "&"-"&FIXED(CÁLCULO_MÉDIAS!Y12,2,FALSE) -> 860,00 -1.090,00 | E4: custo de aço extremamente alto
A5: ='SEM IMPREVISTOS'!A5 -> PAREDES E PAINÉIS | B5: ='SEM IMPREVISTOS'!C52 -> 3110673.8 | C5: =B5/'GER_EXECUTIVO CART'!G$2 -> 199.36574 | D5: =FIXED(CÁLCULO_MÉDIAS!X14,2,FALSE)&" "&"-"&FIXED(CÁLCULO_MÉDIAS!Y14,2,FALSE) -> 110,00 -170,00 | E5: Valor da mão de obra é relativamente maior do que as demais obras | F5: =20*'GER_EXECUTIVO CART'!G2 -> 312057
A6: ='SEM IMPREVISTOS'!A6 -> INSTALAÇÕES ELÉTRICAS, HIDRÁULICAS, GLP E PREVENTIVAS | B6: ='SEM IMPREVISTOS'!C56+'SEM IMPREVISTOS'!C58+'SEM IMPREVISTOS'!C60+'SEM IMPREVISTOS'!C62+'SEM IMPREVISTOS'!C64+'SEM IMPREVISTOS'!C93 -> 6325299.1 | C6: =B6/'GER_EXECUTIVO CART'!G$2 -> 405.39383 | D6: =FIXED(CÁLCULO_MÉDIAS!X15,2,FALSE)&" "&"-"&FIXED(CÁLCULO_MÉDIAS!Y15,2,FALSE) -> 300,00 -360,00 | E6: Itens diferentes que normalmente não são considerados no resto do empreendimentos
A7: ='SEM IMPREVISTOS'!A7 -> EQUIPAMENTOS E SISTEMAS ESPECIAIS | B7: ='SEM IMPREVISTOS'!B66+'SEM IMPREVISTOS'!C67 -> 2681510.5 | C7: =B7/'GER_EXECUTIVO CART'!G$2 -> 171.8603 | D7: =FIXED(CÁLCULO_MÉDIAS!X16,2,FALSE)&" "&"-"&FIXED(CÁLCULO_MÉDIAS!Y16,2,FALSE) -> 150,00 -270,00 | E7: Okay
A8: ='SEM IMPREVISTOS'!A8 -> IMPERMEABILIZAÇÃO | B8: ='SEM IMPREVISTOS'!C54 -> 802414.61 | C8: =B8/'GER_EXECUTIVO CART'!G$2 -> 51.427438 | D8: =FIXED(CÁLCULO_MÉDIAS!X17,2,FALSE)&" "&"-"&FIXED(CÁLCULO_MÉDIAS!Y17,2,FALSE) -> 50,00 -80,00 | E8: Okay
A9: REVESTIMENTOS INTERNOS DE PISO E PAREDE | B9: ='SEM IMPREVISTOS'!B70+'SEM IMPREVISTOS'!B72+'SEM IMPREVISTOS'!B79+'SEM IMPREVISTOS'!B84 -> 2181983 | C9: =B9/'GER_EXECUTIVO CART'!G$2 -> 139.84516 | D9: =FIXED(CÁLCULO_MÉDIAS!X18,2,FALSE)&" "&"-"&FIXED(CÁLCULO_MÉDIAS!Y18,2,FALSE) -> 170,00 -205,00 | E9: Os revestimentos das áreas comuns foram movidos para serviços finais
A10: REVESTIMENTOS E ACABAMENTOS INTERNOS EM TETO | B10: ='SEM IMPREVISTOS'!C76 -> 1650987.9 | C10: =B10/'GER_EXECUTIVO CART'!G$2 -> 105.81323 | D10: =FIXED(CÁLCULO_MÉDIAS!X19,2,FALSE)&" "&"-"&FIXED(CÁLCULO_MÉDIAS!Y19,2,FALSE) -> 60,00 -95,00 | E10: Temos mais areas com forro acartonado, o qual o custo é mais elevado
A11: ACABAMENTOS EM PISO E PAREDE | B11: ='SEM IMPREVISTOS'!B85+'SEM IMPREVISTOS'!B83+'SEM IMPREVISTOS'!B82+'SEM IMPREVISTOS'!B81+'SEM IMPREVISTOS'!B80+'SEM IMPREVISTOS'!C74 -> 2201208.7 | C11: =B11/'GER_EXECUTIVO CART'!G$2 -> 141.07735 | D11: =FIXED(CÁLCULO_MÉDIAS!X20,2,FALSE)&" "&"-"&FIXED(CÁLCULO_MÉDIAS!Y20,2,FALSE) -> 150,00 -200,00 | E11: Okay
A12: ='SEM IMPREVISTOS'!A12 -> PINTURA INTERNA | B12: ='SEM IMPREVISTOS'!C88 -> 2472056.2 | C12: =B12/'GER_EXECUTIVO CART'!G$2 -> 158.43619 | D12: =FIXED(CÁLCULO_MÉDIAS!X21,2,FALSE)&" "&"-"&FIXED(CÁLCULO_MÉDIAS!Y21,2,FALSE) -> 140,00 -150,00 | E12: As pinturas das áreas comuns foram movidos para serviços finais
A13: ='SEM IMPREVISTOS'!A13 -> ESQUADRIAS, VIDROS E FERRAGENS | B13: ='SEM IMPREVISTOS'!C91 -> 4972981 | C13: =B13/'GER_EXECUTIVO CART'!G$2 -> 318.7226 | D13: =FIXED(CÁLCULO_MÉDIAS!X22,2,FALSE)&" "&"-"&FIXED(CÁLCULO_MÉDIAS!Y22,2,FALSE) -> 240,00 -350,00 | E13: Okay
A14: REVESTIMENTOS E ACABAMENTOS DE FACHADA | B14: ='SEM IMPREVISTOS'!B90+'SEM IMPREVISTOS'!B71+'SEM IMPREVISTOS'!B73 -> 2575360 | C14: =B14/'GER_EXECUTIVO CART'!G$2 -> 165.05702 | D14: =FIXED(CÁLCULO_MÉDIAS!X24,2,FALSE)&" "&"-"&FIXED(CÁLCULO_MÉDIAS!Y24,2,FALSE) -> 115,00 -180,00 | E14: Okay
A15: SERVIÇOS COMPLEMENTARES | B15: ='SEM IMPREVISTOS'!C95 -> 2465512.5 | C15: =B15/'GER_EXECUTIVO CART'!G$2 -> 158.0168 | D15: =FIXED(CÁLCULO_MÉDIAS!X25,2,FALSE)&" "&"-"&FIXED(CÁLCULO_MÉDIAS!Y25,2,FALSE) -> 120,00 -180,00 | E15: Okay
A16: TOTAL | B16: =SUM(B3:B15) -> 51217758 | C16: =SUM(C3:C15) -> 3282.5899 | D16: =FIXED(CÁLCULO_MÉDIAS!X26,2,FALSE)&" "&"-"&FIXED(CÁLCULO_MÉDIAS!Y26,2,FALSE) -> 3.175,00 -4.170,00
E17: =175+660 -> 835

Sheet Versões R01
A1: ETAPA | B1: EXECUTIVO R00 | D1: EXECUTIVO R01 | F1: DIFERENÇA
B2: VALOR | C2: VALOR / m² | D2: VALOR | E2: VALOR / m² | F2: VALOR | G2: VALOR / m² | H2: Observação
A3: GERENCIAMENTO TÉCNICO E ADMINISTRATIVO | B3: =[2]Versões!$D3 -> 7594518.6 | C3: =B3/'SEM IMPREVISTOS'!$G$2 -> 486.73919 | D3: ='GER_EXECUTIVO MEGA'!B2 -> 7713624.6 | E3: =D3/'SEM IMPREVISTOS'!$G$2 -> 494.3728 | F3: =D3-B3 -> 119106.04 | G3: =E3-C3 -> 7.6336078 | H3: Analises estão discretizadas no relatorio da revisão
A4: MOVIMENTAÇÃO DE TERRA | B4: =[2]Versões!$D4 -> 1354048.8 | C4: =B4/'SEM IMPREVISTOS'!$G$2 -> 86.782144 | D4: ='GER_EXECUTIVO MEGA'!B3 -> 1415598.8 | E4: =D4/'SEM IMPREVISTOS'!$G$2 -> 90.726936 | F4: =D4-B4 -> 61550 | G4: =E4-C4 -> 3.9447921 | H4: Analises estão discretizadas no relatorio da revisão
A5: INFRAESTRUTURA | B5: =[2]Versões!$D5 -> 0 | C5: =B5/'SEM IMPREVISTOS'!$G$2 -> 0 | E5: =D5/'SEM IMPREVISTOS'!$G$2 -> 0 | F5: =D5-B5 -> 0 | G5: =E5-C5 -> 0 | H5: Analises estão discretizadas no relatorio da revisão
A6: CONTENÇÕES | B6: =[2]Versões!$D6 -> 0 | C6: =B6/'SEM IMPREVISTOS'!$G$2 -> 0 | E6: =D6/'SEM IMPREVISTOS'!$G$2 -> 0 | F6: =D6-B6 -> 0 | G6: =E6-C6 -> 0 | H6: Analises estão discretizadas no relatorio da revisão
A7: SUPRAESTRUTURA + INFRA + CONTENÇÕES | B7: =[2]Versões!$D7 -> 18771638 | C7: =B7/'SEM IMPREVISTOS'!$G$2 -> 1203.0903 | D7: ='GER_EXECUTIVO MEGA'!B4 -> 18749747 | E7: =D7/'SEM IMPREVISTOS'!$G$2 -> 1201.6873 | F7: =D7-B7 -> -21891.248 | G7: =E7-C7 -> -1.4030288 | H7: Analises estão discretizadas no relatorio da revisão
A8: PAREDES E PAINÉIS | B8: =[2]Versões!$D8 -> 3180040.1 | C8: =B8/'SEM IMPREVISTOS'!$G$2 -> 203.81149 | D8: ='GER_EXECUTIVO MEGA'!B5 -> 3110673.8 | E8: =D8/'SEM IMPREVISTOS'!$G$2 -> 199.36574 | F8: =D8-B8 -> -69366.299 | G8: =E8-C8 -> -4.4457454 | H8: Analises estão discretizadas no relatorio da revisão
A9: INSTALAÇÕES ELÉTRICAS, HIDRÁULICAS, GLP E PREVENTIVAS E COMUNICAÇÃO E LOUÇAS E METAIS | B9: =[2]Versões!$D9 -> 5644076.7 | C9: =B9/'SEM IMPREVISTOS'!$G$2 -> 361.7337 | D9: ='GER_EXECUTIVO MEGA'!B6 -> 6469375.6 | E9: =D9/'SEM IMPREVISTOS'!$G$2 -> 414.62782 | F9: =D9-B9 -> 825298.96 | G9: =E9-C9 -> 52.894116 | H9: Analises estão discretizadas no relatorio da revisão
A10: EQUIPAMENTOS E SISTEMAS ESPECIAIS | B10: =[2]Versões!$D10 -> 2594727.6 | C10: =B10/'SEM IMPREVISTOS'!$G$2 -> 166.29831 | D10: ='GER_EXECUTIVO MEGA'!B7 -> 2701000.7 | E10: =D10/'SEM IMPREVISTOS'!$G$2 -> 173.10944 | F10: =D10-B10 -> 106273.07 | G10: =E10-C10 -> 6.8111321 | H10: Analises estão discretizadas no relatorio da revisão
A11: IMPERMEABILIZAÇÃO | B11: =[2]Versões!$D11 -> 820308.01 | C11: =B11/'SEM IMPREVISTOS'!$G$2 -> 52.574242 | D11: ='GER_EXECUTIVO MEGA'!B8 -> 820493.66 | E11: =D11/'SEM IMPREVISTOS'!$G$2 -> 52.58614 | F11: =D11-B11 -> 185.65287 | G11: =E11-C11 -> 0.011898651 | H11: Analises estão discretizadas no relatorio da revisão
A12: REVESTIMENTOS INTERNOS E EXTERNOS DE PAREDE | B12: =[2]Versões!$D12 -> 2224244.1 | C12: =B12/'SEM IMPREVISTOS'!$G$2 -> 142.5537 | D12: ='GER_EXECUTIVO MEGA'!B9 -> 2542675.7 | E12: =D12/'SEM IMPREVISTOS'!$G$2 -> 162.96226 | F12: =D12-B12 -> 318431.6 | G12: =E12-C12 -> 20.408553 | H12: Analises estão discretizadas no relatorio da revisão
A13: ACABAMENTOS INTERNOS DE PAREDE | B13: =[2]Versões!$D13 -> 501609.28 | C13: =B13/'SEM IMPREVISTOS'!$G$2 -> 32.148568 | D13: ='GER_EXECUTIVO MEGA'!B10 -> 585077.05 | E13: =D13/'SEM IMPREVISTOS'!$G$2 -> 37.498089 | F13: =D13-B13 -> 83467.772 | G13: =E13-C13 -> 5.3495209 | H13: Analises estão discretizadas no relatorio da revisão
A14: REVESTIMENTOS E ACABAMENTOS INTERNOS EM TETO | B14: =[2]Versões!$D14 -> 1653498.1 | C14: =B14/'SEM IMPREVISTOS'!$G$2 -> 105.97411 | D14: ='GER_EXECUTIVO MEGA'!B11 -> 1688186 | E14: =D14/'SEM IMPREVISTOS'!$G$2 -> 108.19728 | F14: =D14-B14 -> 34687.879 | G14: =E14-C14 -> 2.2231758 | H14: Analises estão discretizadas no relatorio da revisão
A15: PISOS E PAVIMENTAÇÕES | B15: =[2]Versões!$D15 -> 2334975.1 | C15: =B15/'SEM IMPREVISTOS'!$G$2 -> 149.65055 | D15: ='GER_EXECUTIVO MEGA'!B12 -> 2558866.3 | E15: =D15/'SEM IMPREVISTOS'!$G$2 -> 163.99993 | F15: =D15-B15 -> 223891.23 | G15: =E15-C15 -> 14.34938 | H15: Analises estão discretizadas no relatorio da revisão
A16: PINTURA INTERNA E EXTERNA | B16: =[2]Versões!$D16 -> 3897130.2 | C16: =B16/'SEM IMPREVISTOS'!$G$2 -> 249.7704 | D16: ='GER_EXECUTIVO MEGA'!B13 -> 3898012.2 | E16: =D16/'SEM IMPREVISTOS'!$G$2 -> 249.82693 | F16: =D16-B16 -> 882.00212 | G16: =E16-C16 -> 0.05652827 | H16: Analises estão discretizadas no relatorio da revisão
A17: ESQUADRIAS, VIDROS E FERRAGENS | B17: =[2]Versões!$D17 -> 4762411 | C17: =B17/'SEM IMPREVISTOS'!$G$2 -> 305.22699 | D17: ='GER_EXECUTIVO MEGA'!B14 -> 5085026.3 | E17: =D17/'SEM IMPREVISTOS'!$G$2 -> 325.90368 | F17: =D17-B17 -> 322615.33 | G17: =E17-C17 -> 20.676692 | H17: Analises estão discretizadas no relatorio da revisão
A18: REVESTIMENTOS E ACABAMENTOS DE FACHADA | B18: =[2]Versões!$D18 -> 0 | C18: =B18/'SEM IMPREVISTOS'!$G$2 -> 0 | E18: =D18/'SEM IMPREVISTOS'!$G$2 -> 0 | F18: =D18-B18 -> 0 | G18: =E18-C18 -> 0 | H18: Analises estão discretizadas no relatorio da revisão
A19: SERVIÇOS COMPLEMENTARES | B19: =[2]Versões!$D19 -> 2494269.7 | C19: =B19/'SEM IMPREVISTOS'!$G$2 -> 159.85988 | D19: ='GER_EXECUTIVO MEGA'!B15 -> 2521062.5 | E19: =D19/'SEM IMPREVISTOS'!$G$2 -> 161.57705 | F19: =D19-B19 -> 26792.769 | G19: =E19-C19 -> 1.7171715 | H19: Analises estão discretizadas no relatorio da revisão
A20: TOTAL | B20: =SUM(B3:B19) -> 57827495 | C20: =SUM(C3:C19) -> 3706.2136 | D20: =SUM(D3:D19) -> 59859420 | E20: =SUM(E3:E19) -> 3836.4414 | F20: =SUM(F3:F19) -> 2031924.7 | G20: =SUM(G3:G19) -> 130.22779

Sheet GER_EXECUTIVO MEGA
A1: ETAPA | B1: VALOR ORÇADO | C1: % | D1: VALOR / m²
A2: GERENCIAMENTO TÉCNICO E ADMINISTRATIVO | B2: ='SEM IMPREVISTOS'!B2 -> 7713624.6 | C2: =B2/B$16 -> 0.12886234 | D2: =B2/'GER_EXECUTIVO MEGA'!G$2 -> 494.3728 | F2: ÁREA CONSTRUÍDA | G2: =[1]Obra!$E$10 -> 15602.85 | H2: m²
A3: MOVIMENTAÇÃO DE TERRA | B3: =[1]Obra!$C34 -> 1415598.8 | C3: =B3/B$16 -> 0.023648722 | D3: =B3/'GER_EXECUTIVO MEGA'!G$2 -> 90.726936
A4: INFRAESTRUTURA E SUPRAESTRUTURA | B4: =[1]Obra!$C35 -> 18749747 | C4: =B4/B$16 -> 0.31322968 | D4: =B4/'GER_EXECUTIVO MEGA'!G$2 -> 1201.6873
A5: PAREDES E PAINÉIS | B5: =[1]Obra!$C36 -> 3110673.8 | C5: =B5/B$16 -> 0.05196632 | D5: =B5/'GER_EXECUTIVO MEGA'!G$2 -> 199.36574
A6: INSTALAÇÕES ELÉTRICAS, HIDRÁULICAS, GLP E PREVENTIVAS E COMUNICAÇÃO E LOUÇAS E METAIS | B6: =[1]Obra!$C37 -> 6469375.6 | C6: =B6/B$16 -> 0.10807615 | D6: =B6/'GER_EXECUTIVO MEGA'!G$2 -> 414.62782
A7: EQUIPAMENTOS E SISTEMAS ESPECIAIS | B7: =[1]Obra!$C38 -> 2701000.7 | C7: =B7/B$16 -> 0.0451224 | D7: =B7/'GER_EXECUTIVO MEGA'!G$2 -> 173.10944
A8: IMPERMEABILIZAÇÃO | B8: =[1]Obra!$C39 -> 820493.66 | C8: =B8/B$16 -> 0.01370701 | D8: =B8/'GER_EXECUTIVO MEGA'!G$2 -> 52.58614
A9: REVESTIMENTOS INTERNOS E EXTERNOS DE PAREDE | B9: =[1]Obra!$C40 -> 2542675.7 | C9: =B9/B$16 -> 0.042477453 | D9: =B9/'GER_EXECUTIVO MEGA'!G$2 -> 162.96226
A10: ACABAMENTOS INTERNOS DE PAREDE | B10: =[1]Obra!$C41 -> 585077.05 | C10: =B10/B$16 -> 0.0097741851 | D10: =B10/'GER_EXECUTIVO MEGA'!G$2 -> 37.498089
A11: REVESTIMENTOS E ACABAMENTOS INTERNOS EM TETO | B11: =[1]Obra!$C42 -> 1688186 | C11: =B11/B$16 -> 0.028202511 | D11: =B11/'GER_EXECUTIVO MEGA'!G$2 -> 108.19728
A12: PISOS E PAVIMENTAÇÕES | B12: =[1]Obra!$C43 -> 2558866.3 | C12: =B12/B$16 -> 0.042747931 | D12: =B12/'GER_EXECUTIVO MEGA'!G$2 -> 163.99993
A13: PINTURA INTERNA E EXTERNA | B13: =[1]Obra!$C44 -> 3898012.2 | C13: =B13/B$16 -> 0.065119444 | D13: =B13/'GER_EXECUTIVO MEGA'!G$2 -> 249.82693
A14: ESQUADRIAS, VIDROS E FERRAGENS | B14: =[1]Obra!$C45 -> 5085026.3 | C14: =B14/B$16 -> 0.084949475 | D14: =B14/'GER_EXECUTIVO MEGA'!G$2 -> 325.90368
A15: SERVIÇOS COMPLEMENTARES | B15: =[1]Obra!$C47 -> 2521062.5 | C15: =B15/B$16 -> 0.042116387 | D15: =B15/'GER_EXECUTIVO MEGA'!G$2 -> 161.57705
A16: TOTAL | B16: =SUM(B2:B15) -> 59859420 | C16: =SUM(C2:C15) -> 1 | D16: =SUM(D2:D15) -> 3836.4414
A17: CUB/SC | B17: 2934.53 | C17: 45809 | D17: =ROUNDUP(+D16/B17,2)&" CUB" -> 1,31 CUB
A20: Rótulos de Linha | B20: Soma de % | C20: Soma de VALOR ORÇADO | D20: Soma de VALOR / m²
A21: ESTRUTURA | B21: 0.31758611 | C21: 18362172 | D21: 1176.8473
A22: GERENCIAMENTO TÉCNICO E ADMINISTRATIVO | B22: 0.13135231 | C22: 7594518.6 | D22: 486.73919
A23: INSTALAÇÕES ELÉTRICAS, HIDRÁULICAS, GLP E PREVENTIVAS | B23: 0.090635559 | C23: 5240360.5 | D23: 335.85919
A24: ESQUADRIAS, VIDROS E FERRAGENS | B24: 0.080775089 | C24: 4670248.5 | D24: 299.32022
A25: PAREDES E PAINÉIS | B25: 0.053801195 | C25: 3110673.8 | D25: 199.36574
A26: EQUIPAMENTOS E SISTEMAS ESPECIAIS | B26: 0.04446455 | C26: 2570848.3 | D26: 164.76787
A27: PINTURA INTERNA | B27: 0.042755874 | C27: 2472056.2 | D27: 158.43619
A28: SERVIÇOS COMPLEMENTARES | B28: 0.041834177 | C28: 2418765.6 | D28: 155.02075
A29: PISOS E PAVIMENTAÇÕES | B29: 0.039504046 | C29: 2284042.2 | D29: 146.38622
A30: REVESTIMENTOS E ACABAMENTOS DE FACHADA | B30: 0.039035094 | C30: 2256928.4 | D30: 144.64847
A31: REVESTIMENTOS INTERNOS DE PAREDE | B31: 0.031098469 | C31: 1798049.1 | D31: 115.23851
A32: REVESTIMENTOS E ACABAMENTOS INTERNOS EM TETO | B32: 0.027974545 | C32: 1617430.3 | D32: 103.66249
... A36: Total Geral | B36: 0.98296769 | C36: 56833158 | D36: 3642.4857

Sheet Versões
A1: ETAPA | B1: PRELIMINAR - R01 | D1: EXECUTIVO R00 | F1: EXECUTIVO R01 | H1: DIFERENÇA
B2: VALOR | C2: VALOR / m² | D2: VALOR | E2: VALOR / m² | F2: VALOR | G2: VALOR / m² | H2: VALOR | I2: VALOR / m² | J2: Observação
A3: GERENCIAMENTO TÉCNICO E ADMINISTRATIVO | B3: =[3]GER_EXECUTIVO!$B$2 -> 7834981.6 | C3: =B3/'SEM IMPREVISTOS'!$G$2 -> 502.15067 | D3: =[2]Versões!$D3 -> 7594518.6 | E3: =D3/'SEM IMPREVISTOS'!$G$2 -> 486.73919 | F3: ='GER_EXECUTIVO MEGA'!B2 -> 7713624.6 | G3: =F3/'SEM IMPREVISTOS'!$G$2 -> 494.3728 | H3: =F3-B3 -> -121356.93 | I3: =G3-C3 -> -7.7778692 | J3: Ajustes dos custos solicitados, e adicionado bandejas
A4: MOVIMENTAÇÃO DE TERRA | B4: =[3]ANÁLISE_CUSTOS!$B3 -> 1346662.3 | C4: =B4/'SEM IMPREVISTOS'!$G$2 -> 86.308737 | D4: =[2]Versões!$D4 -> 1354048.8 | E4: =D4/'SEM IMPREVISTOS'!$G$2 -> 86.782144 | F4: ='GER_EXECUTIVO MEGA'!B3 -> 1415598.8 | G4: =F4/'SEM IMPREVISTOS'!$G$2 -> 90.726936 | H4: =F4-B4 -> 68936.497 | I4: =G4-C4 -> 4.418199 | J4: Informaram valores de contrato
A5: INFRAESTRUTURA | B5: =[3]ANÁLISE_CUSTOS!$B4 -> 0 | C5: =B5/'SEM IMPREVISTOS'!$G$2 -> 0 | D5: =[2]Versões!$D5 -> 0 | E5: =D5/'SEM IMPREVISTOS'!$G$2 -> 0 | G5: =F5/'SEM IMPREVISTOS'!$G$2 -> 0 | H5: =F5-B5 -> 0 | I5: =G5-C5 -> 0
A6: CONTENÇÕES | B6: =[3]ANÁLISE_CUSTOS!$B5 -> 0 | C6: =B6/'SEM IMPREVISTOS'!$G$2 -> 0 | D6: =[2]Versões!$D6 -> 0 | E6: =D6/'SEM IMPREVISTOS'!$G$2 -> 0 | G6: =F6/'SEM IMPREVISTOS'!$G$2 -> 0 | H6: =F6-B6 -> 0 | I6: =G6-C6 -> 0
A7: SUPRAESTRUTURA + INFRA + CONTENÇÕES | B7: =[3]ANÁLISE_CUSTOS!$B6 -> 17779417 | C7: =B7/'SEM IMPREVISTOS'!$G$2 -> 1139.4981 | D7: =[2]Versões!$D7 -> 18771638 | E7: =D7/'SEM IMPREVISTOS'!$G$2 -> 1203.0903 | F7: ='GER_EXECUTIVO MEGA'!B4 -> 18749747 | G7: =F7/'SEM IMPREVISTOS'!$G$2 -> 1201.6873 | H7: =F7-B7 -> 970329.33 | I7: =G7-C7 -> 62.189237 | J7: Aumento do valor do aço
A8: PAREDES E PAINÉIS | B8: =[3]ANÁLISE_CUSTOS!$B7 -> 3443813.4 | C8: =B8/'SEM IMPREVISTOS'!$G$2 -> 220.71695 | D8: =[2]Versões!$D8 -> 3180040.1 | E8: =D8/'SEM IMPREVISTOS'!$G$2 -> 203.81149 | F8: ='GER_EXECUTIVO MEGA'!B5 -> 3110673.8 | G8: =F8/'SEM IMPREVISTOS'!$G$2 -> 199.36574 | H8: =F8-B8 -> -333139.64 | I8: =G8-C8 -> -21.351204 | J8: Menos blocos silics calcarios (+barato); Menos drywall (+barato) Refino de quantidades e preços
A9: INSTALAÇÕES ELÉTRICAS, HIDRÁULICAS, GLP E PREVENTIVAS E COMUNICAÇÃO E LOUÇAS E METAIS | B9: =[3]ANÁLISE_CUSTOS!$B8 -> 5989392 | C9: =B9/'SEM IMPREVISTOS'!$G$2 -> 383.86525 | D9: =[2]Versões!$D9 -> 5644076.7 | E9: =D9/'SEM IMPREVISTOS'!$G$2 -> 361.7337 | F9: ='GER_EXECUTIVO MEGA'!B6 -> 6469375.6 | G9: =F9/'SEM IMPREVISTOS'!$G$2 -> 414.62782 | H9: =F9-B9 -> 479983.67 | I9: =G9-C9 -> 30.762564 | J9: Utilizado itens do projetista
A10: EQUIPAMENTOS E SISTEMAS ESPECIAIS | B10: =[3]ANÁLISE_CUSTOS!$B9 -> 2674089.8 | C10: =B10/'SEM IMPREVISTOS'!$G$2 -> 171.3847 | D10: =[2]Versões!$D10 -> 2594727.6 | E10: =D10/'SEM IMPREVISTOS'!$G$2 -> 166.29831 | F10: ='GER_EXECUTIVO MEGA'!B7 -> 2701000.7 | G10: =F10/'SEM IMPREVISTOS'!$G$2 -> 173.10944 | H10: =F10-B10 -> 26910.904 | I10: =G10-C10 -> 1.7247428 | J10: Retirada itens de piscina
A11: IMPERMEABILIZAÇÃO | B11: =[3]ANÁLISE_CUSTOS!$B10 -> 584238.34 | C11: =B11/'SEM IMPREVISTOS'!$G$2 -> 37.444335 | D11: =[2]Versões!$D11 -> 820308.01 | E11: =D11/'SEM IMPREVISTOS'!$G$2 -> 52.574242 | F11: ='GER_EXECUTIVO MEGA'!B8 -> 820493.66 | G11: =F11/'SEM IMPREVISTOS'!$G$2 -> 52.58614 | H11: =F11-B11 -> 236255.32 | I11: =G11-C11 -> 15.141805 | J11: Valor de combo material e mão de obra maiores
A12: REVESTIMENTOS INTERNOS E EXTERNOS DE PAREDE | B12: =[3]ANÁLISE_CUSTOS!$B11 -> 1770784.6 | C12: =B12/'SEM IMPREVISTOS'!$G$2 -> 113.4911 | D12: =[2]Versões!$D12 -> 2224244.1 | E12: =D12/'SEM IMPREVISTOS'!$G$2 -> 142.5537 | F12: ='GER_EXECUTIVO MEGA'!B9 -> 2542675.7 | G12: =F12/'SEM IMPREVISTOS'!$G$2 -> 162.96226 | H12: =F12-B12 -> 771891.06 | I12: =G12-C12 -> 49.471158 | J12: Refinamento de quantidade + aumento valor real do estucamento
A13: ACABAMENTOS INTERNOS DE PAREDE | B13: =[3]ANÁLISE_CUSTOS!$B12 -> 1322855.7 | C13: =B13/'SEM IMPREVISTOS'!$G$2 -> 84.782953 | D13: =[2]Versões!$D13 -> 501609.28 | E13: =D13/'SEM IMPREVISTOS'!$G$2 -> 32.148568 | F13: ='GER_EXECUTIVO MEGA'!B10 -> 585077.05 | G13: =F13/'SEM IMPREVISTOS'!$G$2 -> 37.498089 | H13: =F13-B13 -> -737778.64 | I13: =G13-C13 -> -47.284864 | J13: Acabamentos especiais para mobiliario
A14: REVESTIMENTOS E ACABAMENTOS INTERNOS EM TETO | B14: =[3]ANÁLISE_CUSTOS!$B13 -> 1139432.2 | C14: =B14/'SEM IMPREVISTOS'!$G$2 -> 73.027186 | D14: =[2]Versões!$D14 -> 1653498.1 | E14: =D14/'SEM IMPREVISTOS'!$G$2 -> 105.97411 | F14: ='GER_EXECUTIVO MEGA'!B11 -> 1688186 | G14: =F14/'SEM IMPREVISTOS'!$G$2 -> 108.19728 | H14: =F14-B14 -> 548753.75 | I14: =G14-C14 -> 35.170097 | J14: Valor atualizado com maior quantidade de forro acartonado do que anteriormente, que era somente mineral
A15: PISOS E PAVIMENTAÇÕES | B15: =[3]ANÁLISE_CUSTOS!$B14 -> 2973237.6 | C15: =B15/'SEM IMPREVISTOS'!$G$2 -> 190.55734 | D15: =[2]Versões!$D15 -> 2334975.1 | E15: =D15/'SEM IMPREVISTOS'!$G$2 -> 149.65055 | F15: ='GER_EXECUTIVO MEGA'!B12 -> 2558866.3 | G15: =F15/'SEM IMPREVISTOS'!$G$2 -> 163.99993 | H15: =F15-B15 -> -414371.22 | I15: =G15-C15 -> -26.557406 | J15: Valor mais barato de contrapiso e sem manta acustica no executivo
A16: PINTURA INTERNA E EXTERNA | B16: =[3]ANÁLISE_CUSTOS!$B15 -> 2806557.3 | C16: =B16/'SEM IMPREVISTOS'!$G$2 -> 179.87465 | D16: =[2]Versões!$D16 -> 3897130.2 | E16: =D16/'SEM IMPREVISTOS'!$G$2 -> 249.7704 | F16: ='GER_EXECUTIVO MEGA'!B13 -> 3898012.2 | G16: =F16/'SEM IMPREVISTOS'!$G$2 -> 249.82693 | H16: =F16-B16 -> 1091454.9 | I16: =G16-C16 -> 69.952278 | J16: Temos mais pintura, com valores maiores de mão de obra
A17: ESQUADRIAS, VIDROS E FERRAGENS | B17: =[3]ANÁLISE_CUSTOS!$B16 -> 3656203.9 | C17: =B17/'SEM IMPREVISTOS'!$G$2 -> 234.32923 | D17: =[2]Versões!$D17 -> 4762411 | E17: =D17/'SEM IMPREVISTOS'!$G$2 -> 305.22699 | F17: ='GER_EXECUTIVO MEGA'!B14 -> 5085026.3 | G17: =F17/'SEM IMPREVISTOS'!$G$2 -> 325.90368 | H17: =F17-B17 -> 1428822.4 | I17: =G17-C17 -> 91.574452 | J17: Valores de mercado aumentaram, como pele de vidro, brise e guarda-corpo
A18: REVESTIMENTOS E ACABAMENTOS DE FACHADA | B18: =[3]ANÁLISE_CUSTOS!$B17 -> 0 | C18: =B18/'SEM IMPREVISTOS'!$G$2 -> 0 | D18: =[2]Versões!$D18 -> 0 | E18: =D18/'SEM IMPREVISTOS'!$G$2 -> 0 | G18: =F18/'SEM IMPREVISTOS'!$G$2 -> 0 | H18: =F18-B18 -> 0 | I18: =G18-C18 -> 0
A19: SERVIÇOS COMPLEMENTARES | B19: =[3]ANÁLISE_CUSTOS!$B18 -> 2711159.5 | C19: =B19/'SEM IMPREVISTOS'!$G$2 -> 173.76053 | D19: =[2]Versões!$D19 -> 2494269.7 | E19: =D19/'SEM IMPREVISTOS'!$G$2 -> 159.85988 | F19: ='GER_EXECUTIVO MEGA'!B15 -> 2521062.5 | G19: =F19/'SEM IMPREVISTOS'!$G$2 -> 161.57705 | H19: =F19-B19 -> -190097.04 | I19: =G19-C19 -> -12.183482 | J19: Retirada de ligação definitiva + valor atualizado ao da amalfi de desmobilização + mobiliario e paisagismo valor mais barato
A20: TOTAL | B20: =SUM(B3:B19) -> 56032826 | C20: =SUM(C3:C19) -> 3591.1917 | D20: =SUM(D3:D19) -> 57827495 | E20: =SUM(E3:E19) -> 3706.2136 | F20: =SUM(F3:F19) -> 59859420 | G20: =SUM(G3:G19) -> 3836.4414 | H20: =SUM(H3:H19) -> 3826594.4 | I20: =SUM(I3:I19) -> 245.24971

Sheet GER_EXECUTIVO CART
A1: ETAPA | B1: VALOR ORÇADO | C1: % | D1: VALOR / m²
A2: GERENCIAMENTO TÉCNICO E ADMINISTRATIVO | B2: ='GER_EXECUTIVO MEGA'!B2 -> 7713624.6 | C2: =B2/B$18 -> 0.12886234 | D2: =B2/'GER_EXECUTIVO CART'!G$2 -> 494.3728 | E2: =D2-Amalfi!C3 -> 0 | F2: ÁREA CONSTRUÍDA | G2: =[1]Obra!$E$10 -> 15602.85 | H2: m²
A3: MOVIMENTAÇÃO DE TERRA | B3: ='SEM IMPREVISTOS'!B46 -> 1415598.8 | C3: =B3/B$18 -> 0.023648722 | D3: =B3/'GER_EXECUTIVO CART'!G$2 -> 90.726936 | E3: =D3-Amalfi!C4 -> 0
A4: INFRAESTRUTURA | B4: ='SEM IMPREVISTOS'!B48 -> 2368306.5 | C4: =B4/B$18 -> 0.039564475 | D4: =B4/'GER_EXECUTIVO CART'!G$2 -> 151.78679 | E4: =D4-Amalfi!C5 -> 0
A5: SUPRAESTRUTURA | B5: ='SEM IMPREVISTOS'!B49+'SEM IMPREVISTOS'!B50 -> 16381440 | C5: =B5/B$18 -> 0.2736652 | D5: =B5/'GER_EXECUTIVO CART'!G$2 -> 1049.9005 | E5: =D5-Amalfi!C6 -> 0
A6: PAREDES E PAINÉIS | B6: ='SEM IMPREVISTOS'!B52 -> 3110673.8 | C6: =B6/B$18 -> 0.05196632 | D6: =B6/'GER_EXECUTIVO CART'!G$2 -> 199.36574 | E6: =D6-Amalfi!C7 -> 0
A7: INSTALAÇÕES ELÉTRICAS, HIDRÁULICAS, GLP E PREVENTIVAS | B7: ='SEM IMPREVISTOS'!B56+'SEM IMPREVISTOS'!B58+'SEM IMPREVISTOS'!B60+'SEM IMPREVISTOS'!B62+'SEM IMPREVISTOS'!B64 -> 6182451.7 | C7: =B7/B$18 -> 0.10328285 | D7: =B7/'GER_EXECUTIVO CART'!G$2 -> 396.23861 | E7: =D7-Amalfi!C8 -> -18.389201
A8: EQUIPAMENTOS E SISTEMAS ESPECIAIS | B8: ='SEM IMPREVISTOS'!B66+'SEM IMPREVISTOS'!B67 -> 2701000.7 | C8: =B8/B$18 -> 0.0451224 | D8: =B8/'GER_EXECUTIVO CART'!G$2 -> 173.10944 | E8: =D8-Amalfi!C9 -> 0
A9: IMPERMEABILIZAÇÃO | B9: ='SEM IMPREVISTOS'!B54 -> 820493.66 | C9: =B9/B$18 -> 0.01370701 | D9: =B9/'GER_EXECUTIVO CART'!G$2 -> 52.58614 | E9: =D9-Amalfi!C10 -> 0
A10: REVESTIMENTOS INTERNOS DE PAREDE | B10: ='SEM IMPREVISTOS'!B70+'SEM IMPREVISTOS'!B72+'SEM IMPREVISTOS'!B74 -> 1892458.5 | C10: =B10/B$18 -> 0.031615049 | D10: =B10/'GER_EXECUTIVO CART'!G$2 -> 121.28928 | E10: =D10-Amalfi!C11 -> 0
A11: REVESTIMENTOS E ACABAMENTOS INTERNOS EM TETO | B11: ='SEM IMPREVISTOS'!B76 -> 1688186 | C11: =B11/B$18 -> 0.028202511 | D11: =B11/'GER_EXECUTIVO CART'!G$2 -> 108.19728 | E11: =D11-Amalfi!C12 -> 0
A12: PISOS E PAVIMENTAÇÕES | B12: ='SEM IMPREVISTOS'!B78 -> 2558866.3 | C12: =B12/B$18 -> 0.042747931 | D12: =B12/'GER_EXECUTIVO CART'!G$2 -> 163.99993 | E12: =D12-Amalfi!C13 -> 0
A13: PINTURA INTERNA | B13: ='SEM IMPREVISTOS'!B88 -> 2557946.4 | C13: =B13/B$18 -> 0.042732562 | D13: =B13/'GER_EXECUTIVO CART'!G$2 -> 163.94097 | E13: =D13-Amalfi!C14 -> 0
A14: ESQUADRIAS, VIDROS E FERRAGENS | B14: ='SEM IMPREVISTOS'!B91 -> 5085026.3 | C14: =B14/B$18 -> 0.084949475 | D14: =B14/'GER_EXECUTIVO CART'!G$2 -> 325.90368 | E14: =D14-Amalfi!C15 -> 0
A15: LOUÇAS E METAIS | B15: ='SEM IMPREVISTOS'!B93 -> 286923.95 | C15: =B15/B$18 -> 0.0047932966 | D15: =B15/'GER_EXECUTIVO CART'!G$2 -> 18.389201 | E15: =D15-Amalfi!C16 -> 18.389201
A16: REVESTIMENTOS E ACABAMENTOS DE FACHADA | B16: ='SEM IMPREVISTOS'!B90+'SEM IMPREVISTOS'!B71+'SEM IMPREVISTOS'!B73 -> 2575360 | C16: =B16/B$18 -> 0.04302347 | D16: =B16/'GER_EXECUTIVO CART'!G$2 -> 165.05702 | E16: =D16-Amalfi!C17 -> 0
A17: SERVIÇOS COMPLEMENTARES | B17: ='SEM IMPREVISTOS'!B95 -> 2521062.5 | C17: =B17/B$18 -> 0.042116387 | D17: =B17/'GER_EXECUTIVO CART'!G$2 -> 161.57705 | E17: =D17-Amalfi!C18 -> 0
A18: TOTAL | B18: =SUM(B2:B17) -> 59859420 | C18: =SUM(C2:C17) -> 1 | D18: =SUM(D2:D17) -> 3836.4414
A19: CUB/SC | B19: 2934.53 | C19: 45809 | D19: =ROUNDDOWN(D18/B19,2)&" CUB" -> 1,3 CUB
A22: Rótulos de Linha | B22: Soma de %
A23: ESTRUTURA | B23: 0.31758611
A24: GERENCIAMENTO TÉCNICO E ADMINISTRATIVO | B24: 0.13135231
A25: INSTALAÇÕES ELÉTRICAS, HIDRÁULICAS, GLP E PREVENTIVAS | B25: 0.090635559
A26: ESQUADRIAS, VIDROS E FERRAGENS | B26: 0.080775089
A27: PAREDES E PAINÉIS | B27: 0.053801195
A28: EQUIPAMENTOS E SISTEMAS ESPECIAIS | B28: 0.04446455
A29: PINTURA INTERNA | B29: 0.042755874
A30: SERVIÇOS COMPLEMENTARES | B30: 0.041834177
A31: PISOS E PAVIMENTAÇÕES | B31: 0.039504046
A32: REVESTIMENTOS E ACABAMENTOS DE FACHADA | B32: 0.039035094
A33: REVESTIMENTOS INTERNOS DE PAREDE | B33: 0.031098469
A34: REVESTIMENTOS E ACABAMENTOS INTERNOS EM TETO | B34: 0.027974545
... A38: Total Geral | B38: 0.98296769

Sheet Amalfi
A1: ETAPA | B1: TRAMONTI | D1: RAVELLO | F1: MARINE | H1: MAIORI
B2: VALOR SEM IMPREVISTOS | C2: VALOR / m² | D2: VALOR | E2: VALOR / m² | F2: VALOR | G2: VALOR / m² | H2: VALOR | I2: VALOR / m² | K2: ETAPA | L2: MARINE | M2: MAIORI | N2: RAVELLO | O2: TRAMONTI
A3: GERENCIAMENTO TÉCNICO E ADMINISTRATIVO | B3: ='SEM IMPREVISTOS'!B2 -> 7713624.6 | C3: ='GER_EXECUTIVO CART'!D2 -> 494.3728 | D3: 5210393.6 | E3: 387.84287 | F3: 2346985.5 | G3: 521.7077 | H3: 3318913.6 | I3: 396.6908 | J3: =[4]Ravello!$G$9/N3 -> 360.62846 | K3: ÁREA CONSTRUÍDA | L3: =[5]ORÇAMENTO_EXECUTIVO!G2 -> 4498.66 | M3: ='[6]ORÇAMENTO_EXECUTIVO-IMPREVISTOS'!$G$2 -> 8366.5 | N3: 13434.29 | O3: =[1]Obra!$E$10 -> 15602.85
A4: =[5]ORÇAMENTO_EXECUTIVO!A3 -> MOVIMENTAÇÃO DE TERRA | B4: =ANÁLISE_CUSTOS!B3 -> 1415598.8 | C4: ='GER_EXECUTIVO CART'!D3 -> 90.726936 | D4: 91928.48 | E4: 6.8428238 | F4: 75751.4 | G4: 16.838659 | H4: 61666.64 | I4: 7.3706615 | K4: PAVIMENTOS | L4: 12 | M4: 17 | N4: 21 | O4: =[1]Obra!$E$14 -> 28
A5: =[5]ORÇAMENTO_EXECUTIVO!A4 -> INFRAESTRUTURA | B5: =ANÁLISE_CUSTOS!B4 -> 18362172 | C5: ='GER_EXECUTIVO CART'!D4 -> 151.78679 | D5: 2274308.4 | E5: 169.2913 | F5: 1547469.9 | G5: 343.98464 | H5: 1477672.4 | I5: 176.61774 | K5: UNIDADES PRIVATIVAS | L5: 27 | M5: 60 | N5: =15*5 -> 75 | O5: =[1]Obra!$E$11 -> 90
A6: =[5]ORÇAMENTO_EXECUTIVO!A5 -> SUPRAESTRUTURA | B6: =ANÁLISE_CUSTOS!#REF! -> #REF! | C6: ='GER_EXECUTIVO CART'!D5 -> 1049.9005 | D6: 8582605 | E6: 638.8581 | F6: 2140197.9 | G6: 475.7412 | H6: 4867206.8 | I6: 581.74946 | K6: ÁREA PRIVATIVA | L6: ='[5]AREAS PRIVATIVAS'!H2 -> 2651.04 | M6: ='[6]AREAS PRIVATIVAS'!$H$2 -> 4969.86 | N6: 6651.9 | O6: =[1]Obra!$E$13 -> 7934.94
A7: =[5]ORÇAMENTO_EXECUTIVO!A6 -> PAREDES E PAINÉIS | B7: =ANÁLISE_CUSTOS!B5 -> 3110673.8 | C7: ='GER_EXECUTIVO CART'!D6 -> 199.36574 | D7: 1579258.5 | E7: 117.5543 | F7: 518491.15 | G7: 115.25458 | H7: 957804.21 | I7: 114.48087 | L7: =L6/L3 -> 0.58929548 | M7: =M6/M3 -> 0.594019 | N7: =N6/N3 -> 0.4951434 | O7: =O6/O3 -> 0.50855709
A8: =[5]ORÇAMENTO_EXECUTIVO!A7 -> INSTALAÇÕES ELÉTRICAS, HIDRÁULICAS, GLP E PREVENTIVAS | B8: =ANÁLISE_CUSTOS!B6 -> 6325299.1 | C8: ='GER_EXECUTIVO CART'!D7+'GER_EXECUTIVO CART'!D15 -> 414.62782 | D8: 4475688.7 | E8: 333.1541 | F8: 1360169.8 | G8: 302.34998 | H8: 2677326.4 | I8: 295.45929 | K8: DESCRIÇÃO | L8: ÁREA (m²) | M8: VALOR POR ÁREA PRIVATIVA (R$/m²)
A9: =[5]ORÇAMENTO_EXECUTIVO!A8 -> EQUIPAMENTOS E SISTEMAS ESPECIAIS | B9: =ANÁLISE_CUSTOS!B7 -> 2681510.5 | C9: ='GER_EXECUTIVO CART'!D8 -> 173.10944 | D9: 1588014.3 | E9: 118.20604 | F9: 762092.57 | G9: 169.40435 | H9: 1127279.8 | I9: 159.28357 | K9: RAVELLO | L9: 6651.9 | M9: 5907.0751
A10: =[5]ORÇAMENTO_EXECUTIVO!A9 -> IMPERMEABILIZAÇÃO | B10: =ANÁLISE_CUSTOS!B8 -> 802414.61 | C10: ='GER_EXECUTIVO CART'!D9 -> 52.58614 | D10: 803986.98 | E10: 59.845885 | F10: 294041.8 | G10: 65.362085 | H10: 530681.65 | I10: 64.527967 | K10: MARINE | L10: 2651.04 | M10: 5321.4146 | N10: =133674/N3 -> 9.9502095
A11: REVESTIMENTOS INTERNOS DE PISO E PAREDE | B11: =ANÁLISE_CUSTOS!B9 -> 2181983 | C11: ='GER_EXECUTIVO CART'!D10 -> 121.28928 | D11: 2222306.6 | E11: 165.42047 | F11: 723689.27 | G11: 160.86774 | H11: 1640085 | I11: 196.03001 | K11: MAIORI | L11: 4969.86 | M11: 5067.6946
A12: =[5]ORÇAMENTO_EXECUTIVO!A11 -> REVESTIMENTOS E ACABAMENTOS INTERNOS EM TETO | B12: =ANÁLISE_CUSTOS!B10 -> 1650987.9 | C12: ='GER_EXECUTIVO CART'!D11 -> 108.19728 | D12: 761518.52 | E12: 56.684687 | F12: 186134.37 | G12: 41.375514 | H12: 482761.18 | I12: 57.701689 | K12: TRAMONTI | L12: =[1]Obra!$E$13 -> 7934.94 | M12: ='GER_EXECUTIVO CART'!B18/Amalfi!L12 -> 7543.7773
A13: ACABAMENTOS EM PISO E PAREDE | B13: =ANÁLISE_CUSTOS!B11 -> 2201208.7 | C13: ='GER_EXECUTIVO CART'!D12 -> 163.99993 | D13: 1875621.2 | E13: 139.61446 | F13: 629165.16 | G13: 139.85613 | H13: 1116639.8 | I13: 133.46558
A14: =[5]ORÇAMENTO_EXECUTIVO!A13 -> PINTURA INTERNA | B14: =ANÁLISE_CUSTOS!B12 -> 2472056.2 | C14: ='GER_EXECUTIVO CART'!D13 -> 163.94097 | D14: 1833810.4 | E14: 136.50222 | F14: 632045.41 | G14: 140.49637 | H14: 1143520.2 | I14: 136.67845
A15: =[5]ORÇAMENTO_EXECUTIVO!A14 -> ESQUADRIAS, VIDROS E FERRAGENS | B15: =ANÁLISE_CUSTOS!B13 -> 4972981 | C15: ='GER_EXECUTIVO CART'!D14 -> 325.90368 | D15: 3007096.1 | E15: 223.83737 | F15: 1052268.9 | G15: 233.90719 | H15: 2795225.8 | I15: 334.09739
A16: COBERTURA | B16: 0 | C16: 0 | D16: 0 | E16: 0 | F16: 66484.628 | G16: 14.778763 | H16: 123462.33 | I16: 14.756748
A17: REVESTIMENTOS E ACABAMENTOS DE FACHADA | B17: =ANÁLISE_CUSTOS!B14 -> 2575360 | C17: ='GER_EXECUTIVO CART'!D16 -> 165.05702 | D17: 2182960 | E17: 162.49166 | F17: 547328.18 | G17: 121.66471 | H17: 1248713.7 | I17: 149.25162
A18: SERVIÇOS COMPLEMENTARES | B18: =ANÁLISE_CUSTOS!B15 -> 2465512.5 | C18: ='GER_EXECUTIVO CART'!D17 -> 161.57705 | D18: 2223087.2 | E18: 165.47857 | F18: 1085298.8 | G18: 241.24936 | H18: 1521821.9 | I18: 181.89468
A19: TOTAL | B19: =SUM(B3:B18) -> #REF! | C19: =SUM(C3:C18) -> 3836.4414 | D19: =SUM(D3:D18) -> 38712584 | E19: =SUM(E3:E18) -> 2881.6249 | F19: =SUM(F4:F18) -> 11620629 | G19: =SUM(G3:G18) -> 3104.839 | H19: =SUM(H4:H18) -> 21771868 | I19: =SUM(I3:I18) -> 3000.0565

Sheet Planilha1
B4: AMBIENTE | C4: PAREDE | D4: PISO
B6: DELIVERY | C6: TINTA CAFÉ EXPRESSO | D6: PORCELANATO ELIANE 60X60 BOLD ACETINADO BLEND PLUS
B7: ZELADORIA | C7: TINTA MADEIRA ESFUMAÇADA | D7: PORCELANATO ELIANE 60X60 BOLD ACETINADO BLEND PLUS
B8: BWC ZELADORIA | C8: REVESTIMENTO REALCE 32X56 BRANCO BRILHANTE | D8: PORCELANATO ELIANE 60X60 BOLD ACETINADO BLEND PLUS | E8: =UPPER(C8) -> REVESTIMENTO REALCE 32X56 BRANCO BRILHANTE
B9: MARKETPLACE | C9: TINTA BEGE | D9: PORCELANATO ELIANE 60X60 BOLD ACETINADO BLEND PLUS | E9: =UPPER(D9) -> PORCELANATO ELIANE 60X60 BOLD ACETINADO BLEND PLUS
B10: HALL | C10: TEXTURA VELVET QUEIMADO + PORCELANATO BIANCOGRES RIPA SENSE 45X90 ACETINADO + TINTA PORCELANA | D10: PISO VINILICO | E10: =UPPER(C10) -> TEXTURA VELVET QUEIMADO + PORCELANATO BIANCOGRES RIPA SENSE 45X90 ACETINADO + TINTA PORCELANA
B11: BANHEIRO HALL | C11: TINTA PORCELANA | D11: PISO VINILICO | E11: PORCELANATO BIANCOGRES RIPA SENSE 45X90 ACETINADO
B12: CIRCULAÇÃO HALL | C12: TINTA MADEIRA ESFUMAÇADA + PORCELANA | D12: PISO PORCELANATO | E12: =UPPER(C12) -> TINTA MADEIRA ESFUMAÇADA + PORCELANA
B13: MONITORAMENTO | C13: TINTA MADEIRA ESFUMAÇADA | D13: PORCELANATO ELIANE 60X60 BOLD ACETINADO BLEND PLUS | E13: =UPPER(D13) -> PORCELANATO ELIANE 60X60 BOLD ACETINADO BLEND PLUS
B14: CIRCULAÇÃO G2 | C14: TINTA CAFÉ EXPRESSO E BEGE | D14: PORCELANATO BLEND PLUS GREY RETIFICADO ACETINADO 60X60 ELIANE | E14: =UPPER(D14) -> PORCELANATO BLEND PLUS GREY RETIFICADO ACETINADO 60X60 ELIANE
B15: BICICLETÁRIO | C15: TINTA CINZA ELEFANTE | D15: PISO RETIFICADO EMBRAMACO 76X76CM ACETINADO | E15: =UPPER(D15) -> PISO RETIFICADO EMBRAMACO 76X76CM ACETINADO
B16: ACADEMIA FUNCIONAL EXTERNA | C16: - | D16: PORCELANATO AMADEIRADO | E16: =UPPER(D16) -> PORCELANATO AMADEIRADO
B17: ÁREA PISCINA | C17: - | D17: PORCELANATO AMADEIRADO | E17: =UPPER(D17) -> PORCELANATO AMADEIRADO
B18: TERRAÇO SALÃO DE FESTAS + FIRE PLACE | C18: - | D18: PORCELANATO DELTA 73X73 RETIFICADO ACETINADO JUA CLARO 2280-A | E18: =UPPER(D18) -> PORCELANATO DELTA 73X73 RETIFICADO ACETINADO JUA CLARO 2280-A
B19: AMBIENTE | C19: PAREDE | D19: PISO
B21: HORTA | C21: - | D21: PORCELANATO ELIANE 60X60 BOLD ACETINADO BLEND PLUS | E21: =UPPER(D21) -> PORCELANATO ELIANE 60X60 BOLD ACETINADO BLEND PLUS
B22: ÁREA CHURRASCO EXTERNO | C22: - | D22: PORCELANATO PRO CONCRETE ABS 89,5X89,5CM | E22: =UPPER(D22) -> PORCELANATO PRO CONCRETE ABS 89,5X89,5CM
B23: ESPAÇO ZEN | C23: - | D23: PORCELANATO VILLAGRES 71X71 RETIFICADO ACETINADO MONTREAL FENDI | E23: =UPPER(D23) -> PORCELANATO VILLAGRES 71X71 RETIFICADO ACETINADO MONTREAL FENDI
B24: QUIOSQUE PISCINA | C24: TINTA BABOSA | D24: PORCELANATO TIPO ARGILA | PORTOBELLO | E24: =UPPER(D24) -> PORCELANATO TIPO ARGILA | PORTOBELLO
B25: CIRCULAÇÃO + BANHEIROS | C25: PISO 75X75CM CEDASA RETIFICADO EVIDENCE POLIDO + TINTA BRANCA | D25: PISO 75X75CM CEDASA RETIFICADO EVIDENCE POLIDO | E25: =UPPER(D25) -> PISO 75X75CM CEDASA RETIFICADO EVIDENCE POLIDO
B26: QUIOSQUE SPORT | C26: PORCELANATO TIJOLINHO + TEXTURA CIMENTO QUEIMADO COR CINZA ELEFANTE | D26: PORCELANATO BIANCOGRES 20X120 SCALA BEIGE-A RET | E26: =UPPER(D26) -> PORCELANATO BIANCOGRES 20X120 SCALA BEIGE-A RET
B27: SALA DE JOGOS | C27: TINTA MADEIRA ESFUMAÇADA | D27: PORCELANATO BIANCOGRES 20X120 SCALA BEIGE-A RET | E27: =UPPER(D27) -> PORCELANATO BIANCOGRES 20X120 SCALA BEIGE-A RET
B28: SALÃO DE FESTAS | C28: PORCELANATO MARMORIZADO POLIDO BORDA RETA INTERNO 90X90CM AVORIO DI BRESCIA PORTOBELLO | D28: PORCELANATO CIMENTÍCIO ACETINADO BORDA RETA INTERNO 120X120CM MUNARI BRANCO ELIANE | E28: =UPPER(C28) -> PORCELANATO MARMORIZADO POLIDO BORDA RETA INTERNO 90X90CM AVORIO DI BRESCIA PORTOBELLO
B29: BANHEIROS | C29: TINTA MADEIRA ESFUMAÇADA | D29: PORCELANATO ELIANE 60X60 BOLD ACETINADO BLEND PLUS | E29: =UPPER(D29) -> PORCELANATO ELIANE 60X60 BOLD ACETINADO BLEND PLUS
B30: CIRCULAÇÃO | C30: TINTA MADEIRA ESFUMAÇADA + CAFÉ EXPRESSO | D30: PORCELANATO ELIZABETH EGEU SAND 74x74 A | E30: =UPPER(D30) -> PORCELANATO ELIZABETH EGEU SAND 74X74 A
B31: ESPAÇO TEEN | C31: TINTA AREIA + SALMÃO | D31: PISO VINILICO | E31: =UPPER(D31) -> PISO VINILICO
B32: LAVANDERIA | C32: TINTA BEGE | D32: PISO VINILICO | E32: =UPPER(D32) -> PISO VINILICO
B33: ACADEMIA | C33: TINTA PATATIVA | D33: PISO VINILICO | E33: =UPPER(D33) -> PISO VINILICO
B34: BRINQUEDOTECA | C34: TINTA BEGE + BABOSA | D34: PISO MONOLITICO | E34: =UPPER(D34) -> PISO MONOLITICO

Sheet Versões (2)
A1: ETAPA | B1: PRELIMINAR - R01 | D1: EXECUTIVO | F1: DIFERENÇA | H1: DOM | L1: LIBERATO | P1: PAESSAGIO | T1: MAIORI | X1: RAVELLO | Z1: DIFERENÇA
B2: VALOR | C2: VALOR / m² | D2: VALOR | E2: VALOR / m² | H2: VALOR | I2: VALOR / m² | L2: VALOR | M2: VALOR / m² | P2: VALOR | Q2: VALOR / m² | T2: VALOR | U2: VALOR / m² | X2: VALOR | Y2: VALOR / m² | AD2: OPUS | AF2: MAIORI | AH2: RAVELLO
A3: GERENCIAMENTO TÉCNICO E ADMINISTRATIVO | B3: =[3]GER_EXECUTIVO!$B$2 -> 7834981.6 | C3: =B3/'SEM IMPREVISTOS'!$G$2 -> 502.15067 | D3: ='ORÇAMENTO_EXECUTIVO - IMPREVIST'!E2 -> 7713624.6 | E3: =D3/'SEM IMPREVISTOS'!$G$2 -> 494.3728 | F3: =D3-B3 -> -121356.93 | G3: =E3-C3 -> -7.7778692 | J3: =D3-H3 -> 7713624.6 | K3: =E3-I3 -> 494.3728 | L3: 2434594.8 | M3: 231.41678 | N3: =L3-D3 -> -5279029.8 | O3: =M3-E3 -> -262.95602 | P3: 1755488.7 | Q3: 107.38182 | R3: =P3-D3 -> -5958136 | S3: =Q3-E3 -> -386.99098 | T3: 3687674.5 | U3: 440.76669 | V3: =T3-D3 -> -4025950.1 | W3: =U3-E3 -> -53.606107 | X3: 5163084.8 | Y3: 384.32137 | Z3: =X3-D3 -> -2550539.8 | AA3: =Y3-E3 -> -110.05143 | AC3: INDEXADO | AD3: VALOR / M2 | AE3: INDEXADO | AF3: VALOR / M2 | AG3: INDEXADO | AH3: VALOR / M2 | AI3: INDEXADO
A4: MOVIMENTAÇÃO DE TERRA | B4: =[3]ANÁLISE_CUSTOS!$B3 -> 1346662.3 | C4: =B4/'SEM IMPREVISTOS'!$G$2 -> 86.308737 | D4: ='[1]Ger_Executivo MEGA'!$N$8 -> 1744878.4 | E4: =D4/'SEM IMPREVISTOS'!$G$2 -> 111.83075 | F4: =D4-B4 -> 398216.13 | G4: =E4-C4 -> 25.522013 | J4: =D4-H4 -> 1744878.4 | K4: =E4-I4 -> 111.83075 | L4: 0 | M4: 0 | N4: =L4-D4 -> -1744878.4 | O4: =M4-E4 -> -111.83075 | P4: 474494.57 | Q4: 29.024447 | R4: =P4-D4 -> -1270383.9 | S4: =Q4-E4 -> -82.806303 | T4: 108650.81 | U4: 12.986411 | V4: =T4-D4 -> -1636227.6 | W4: =U4-E4 -> -98.844339 | X4: 274980.69 | Y4: 20.468569 | Z4: =X4-D4 -> -1469897.7 | AA4: =Y4-E4 -> -91.362181 | AC4: 1013.5594 | AD4: 515.91027 | AE4: 564.73127 | AF4: 419.36861 | AG4: 447.851 | AH4: 387.84287 | AI4: 413.32375
A5: INFRAESTRUTURA | B5: =[3]ANÁLISE_CUSTOS!$B4 -> 0 | C5: =B5/'SEM IMPREVISTOS'!$G$2 -> 0 | E5: =D5/'SEM IMPREVISTOS'!$G$2 -> 0 | F5: =D5-B5 -> 0 | G5: =E5-C5 -> 0 | J5: =D5-H5 -> 0 | K5: =E5-I5 -> 0 | L5: 0 | M5: 0 | N5: =L5-D5 -> 0 | O5: =M5-E5 -> 0 | P5: 0 | Q5: 0 | R5: =P5-D5 -> 0 | S5: =Q5-E5 -> 0 | T5: 6755554.8 | U5: 0 | V5: =T5-D5 -> 6755554.8 | W5: =U5-E5 -> 0 | X5: 0 | Y5: 0 | Z5: =X5-D5 -> 0 | AA5: =Y5-E5 -> 0 | AC5: 2.8778817 | AE5: 0 | AF5: 7.3706628 | AG5: 7.8712584 | AH5: 6.8428238 | AI5: 7.2923903
A6: CONTENÇÕES | B6: =[3]ANÁLISE_CUSTOS!$B5 -> 0 | C6: =B6/'SEM IMPREVISTOS'!$G$2 -> 0 | E6: =D6/'SEM IMPREVISTOS'!$G$2 -> 0 | F6: =D6-B6 -> 0 | G6: =E6-C6 -> 0 | J6: =D6-H6 -> 0 | K6: =E6-I6 -> 0 | L6: 0 | M6: 0 | N6: =L6-D6 -> 0 | O6: =M6-E6 -> 0 | P6: 0 | Q6: 0 | R6: =P6-D6 -> 0 | S6: =Q6-E6 -> 0 | T6: 0 | U6: 0 | V6: =T6-D6 -> 0 | W6: =U6-E6 -> 0 | X6: 0 | Y6: 0 | Z6: =X6-D6 -> 0 | AA6: =Y6-E6 -> 0 | AC6: 173.92814 | AD6: 112.98609 | AE6: 123.67805 | AF6: 183.12103 | AG6: 195.55812 | AH6: 169.2913 | AI6: 180.41356
A7: SUPRAESTRUTURA + INFRA + CONTENÇÕES | B7: =[3]ANÁLISE_CUSTOS!$B6 -> 17779417 | C7: =B7/'SEM IMPREVISTOS'!$G$2 -> 1139.4981 | D7: ='[1]Ger_Executivo MEGA'!$N$14 -> 10000 | E7: =D7/'SEM IMPREVISTOS'!$G$2 -> 0.64090855 | F7: =D7-B7 -> -17769417 | G7: =E7-C7 -> -1138.8572 | J7: =D7-H7 -> 10000 | K7: =E7-I7 -> 0.64090855 | L7: 9420328.7 | M7: 895.43531 | N7: =L7-D7 -> 9410328.7 | O7: =M7-E7 -> 894.7944 | P7: 9366782.2 | Q7: 572.95846 | R7: =P7-D7 -> 9356782.2 | S7: =Q7-E7 -> 572.31755 | T7: 6755554.8 | U7: 807.45292 | V7: =T7-D7 -> 6745554.8 | W7: =U7-E7 -> 806.81201 | X7: 12426123 | Y7: 924.9557 | Z7: =X7-D7 -> 12416123 | AA7: =Y7-E7 -> 924.31479 | AC7: 602.02119 | AD7: 624.69265 | AE7: 683.80781 | AF7: 683.35962 | AG7: 729.77157 | AH7: 638.8581 | AI7: 680.83042
A8: PAREDES E PAINÉIS | B8: =[3]ANÁLISE_CUSTOS!$B7 -> 3443813.4 | C8: =B8/'SEM IMPREVISTOS'!$G$2 -> 220.71695 | D8: ='[1]Ger_Executivo MEGA'!$N$58 -> 140936.17 | E8: =D8/'SEM IMPREVISTOS'!$G$2 -> 9.0327199 | F8: =D8-B8 -> -3302877.2 | G8: =E8-C8 -> -211.68423 | J8: =D8-H8 -> 140936.17 | K8: =E8-I8 -> 9.0327199 | L8: 1679390.1 | M8: 159.63192 | N8: =L8-D8 -> 1538453.9 | O8: =M8-E8 -> 150.5992 | P8: 821712.57 | Q8: 50.26349 | R8: =P8-D8 -> 680776.39 | S8: =Q8-E8 -> 41.230771 | T8: 1543964.2 | U8: 184.54123 | V8: =T8-D8 -> 1403028 | W8: =U8-E8 -> 175.50851 | X8: 2854366.4 | Y8: 212.46872 | Z8: =X8-D8 -> 2713430.2 | AA8: =Y8-E8 -> 203.436 | AC8: 148.69852 | AD8: 98.954851 | AE8: 108.31903 | AF8: 122.17231 | AG8: 130.46992 | AH8: 117.5543 | AI8: 125.2775
A9: INSTALAÇÕES ELÉTRICAS, HIDRÁULICAS, GLP E PREVENTIVAS E COMUNICAÇÃO E LOUÇAS E METAIS | B9: =[3]ANÁLISE_CUSTOS!$B8 -> 5989392 | C9: =B9/'SEM IMPREVISTOS'!$G$2 -> 383.86525 | D9: ='[1]Ger_Executivo MEGA'!$N$99+'[1]Ger_Executivo MEGA'!$N$123+'[1]Ger_Executivo MEGA'!$N$147+'[1]Ger_Executivo MEGA'!$N$161+'[1]Ger_Executivo MEGA'!$N$168+'[1]Ger_Executivo MEGA'!$N$328 -> 944605.9 | E9: =D9/'SEM IMPREVISTOS'!$G$2 -> 60.5406 | F9: =D9-B9 -> -5044786.1 | G9: =E9-C9 -> -323.32465 | J9: =D9-H9 -> 944605.9 | K9: =E9-I9 -> 60.5406 | L9: 3782057.4 | M9: 359.49784 | N9: =L9-D9 -> 2837451.6 | O9: =M9-E9 -> 298.95724 | P9: 2366895.9 | Q9: 144.7811 | R9: =P9-D9 -> 1422290 | S9: =Q9-E9 -> 84.240503 | T9: 2891998 | U9: 345.66401 | V9: =T9-D9 -> 1947392.1 | W9: =U9-E9 -> 285.12341 | X9: 5242188.4 | Y9: 390.20956 | Z9: =X9-D9 -> 4297582.5 | AA9: =Y9-E9 -> 329.66896 | AC9: 436.32006 | AD9: 338.5 | AE9: 370.53252 | AF9: 330.15727 | AG9: 352.58067 | AH9: 333.1541 | AI9: 355.04198
A10: EQUIPAMENTOS E SISTEMAS ESPECIAIS | B10: =[3]ANÁLISE_CUSTOS!$B9 -> 2674089.8 | C10: =B10/'SEM IMPREVISTOS'!$G$2 -> 171.3847 | D10: ='[1]Ger_Executivo MEGA'!$N$178+'[1]Ger_Executivo MEGA'!$N$182 -> 3137657.8 | E10: =D10/'SEM IMPREVISTOS'!$G$2 -> 201.09517 | F10: =D10-B10 -> 463567.96 | G10: =E10-C10 -> 29.710467 | J10: =D10-H10 -> 3137657.8 | K10: =E10-I10 -> 201.09517 | L10: 1799763.4 | M10: 171.07383 | N10: =L10-D10 -> -1337894.4 | O10: =M10-E10 -> -30.02134 | P10: 4096799.4 | Q10: 250.59789 | R10: =P10-D10 -> 959141.64 | S10: =Q10-E10 -> 49.502723 | T10: 973244.48 | U10: 116.32636 | V10: =T10-D10 -> -2164413.3 | W10: =U10-E10 -> -84.76881 | X10: 1544387.2 | Y10: 114.9586 | Z10: =X10-D10 -> -1593270.5 | AA10: =Y10-E10 -> -86.136564 | AC10: 347.92521 | AD10: 195.68218 | AE10: 214.19974 | AF10: 147.25896 | AG10: 157.2604 | AH10: 118.20604 | AI10: 125.97206
A11: IMPERMEABILIZAÇÃO | B11: =[3]ANÁLISE_CUSTOS!$B10 -> 584238.34 | C11: =B11/'SEM IMPREVISTOS'!$G$2 -> 37.444335 | D11: ='[1]Ger_Executivo MEGA'!$N$77 -> 130000 | E11: =D11/'SEM IMPREVISTOS'!$G$2 -> 8.3318112 | F11: =D11-B11 -> -454238.34 | G11: =E11-C11 -> -29.112524 | J11: =D11-H11 -> 130000 | K11: =E11-I11 -> 8.3318112 | L11: 800333.36 | M11: 76.074495 | N11: =L11-D11 -> 670333.36 | O11: =M11-E11 -> 67.742684 | P11: 378634.57 | Q11: 23.160769 | R11: =P11-D11 -> 248634.57 | S11: =Q11-E11 -> 14.828958 | T11: 267167.91 | U11: 31.933056 | V11: =T11-D11 -> 137167.91 | W11: =U11-E11 -> 23.601245 | X11: 762863.95 | Y11: 56.784836 | Z11: =X11-D11 -> 632863.95 | AA11: =Y11-E11 -> 48.453025 | AC11: 58.231973 | AD11: 43.49527 | AE11: 47.611262 | AF11: 73.241233 | AG11: 78.215582 | AH11: 59.845885 | AI11: 63.777698
A12: REVESTIMENTOS INTERNOS E EXTERNOS DE PAREDE | B12: =[3]ANÁLISE_CUSTOS!$B11 -> 1770784.6 | C12: =B12/'SEM IMPREVISTOS'!$G$2 -> 113.4911 | D12: ='[1]Ger_Executivo MEGA'!$N$195 -> 0 | E12: =D12/'SEM IMPREVISTOS'!$G$2 -> 0 | F12: =D12-B12 -> -1770784.6 | G12: =E12-C12 -> -113.4911 | J12: =D12-H12 -> 0 | K12: =E12-I12 -> 0 | L12: 2026265.9 | M12: 192.60369 | N12: =L12-D12 -> 2026265.9 | O12: =M12-E12 -> 192.60369 | P12: 0 | Q12: 0 | R12: =P12-D12 -> 0 | S12: =Q12-E12 -> 0 | T12: 2836010.1 | U12: 338.9721 | V12: =T12-D12 -> 2836010.1 | W12: =U12-E12 -> 338.9721 | X12: 2921450.8 | Y12: 217.46224 | Z12: =X12-D12 -> 2921450.8 | AA12: =Y12-E12 -> 217.46224 | AC12: 212.9003 | AD12: 140.41605 | AE12: 153.70373 | AF12: 163.65373 | AG12: 174.76865 | AH12: 165.42047 | AI12: 176.28843
A13: ACABAMENTOS INTERNOS DE PAREDE | B13: =[3]ANÁLISE_CUSTOS!$B12 -> 1322855.7 | C13: =B13/'SEM IMPREVISTOS'!$G$2 -> 84.782953 | D13: ='[1]Ger_Executivo MEGA'!$N$210 -> 20914.87 | E13: =D13/'SEM IMPREVISTOS'!$G$2 -> 1.3404519 | F13: =D13-B13 -> -1301940.8 | G13: =E13-C13 -> -83.442501 | J13: =D13-H13 -> 20914.87 | K13: =E13-I13 -> 1.3404519 | L13: 612037.06 | M13: 58.176271 | N13: =L13-D13 -> 591122.19 | O13: =M13-E13 -> 56.83582 | P13: 0 | Q13: 0 | R13: =P13-D13 -> -20914.87 | S13: =Q13-E13 -> -1.3404519 | T13: 589277.61 | U13: 70.43299 | V13: =T13-D13 -> 568362.74 | W13: =U13-E13 -> 69.092538 | X13: 707200.64 | Y13: 52.64146 | Z13: =X13-D13 -> 686285.77 | AA13: =Y13-E13 -> 51.301008 | AC13: 136.25722 | AD13: 43.38056 | AE13: 47.485697 | AF13: 53.764127 | AG13: 57.415643 | AH13: 56.684687 | AI13: 60.408813
A14: REVESTIMENTOS E ACABAMENTOS INTERNOS EM TETO | B14: =[3]ANÁLISE_CUSTOS!$B13 -> 1139432.2 | C14: =B14/'SEM IMPREVISTOS'!$G$2 -> 73.027186 | D14: ='[1]Ger_Executivo MEGA'!$N$220 -> 358428.64 | E14: =D14/'SEM IMPREVISTOS'!$G$2 -> 22.971998 | F14: =D14-B14 -> -781003.59 | G14: =E14-C14 -> -50.055188 | J14: =D14-H14 -> 358428.64 | K14: =E14-I14 -> 22.971998 | L14: 629386.67 | M14: 59.825412 | N14: =L14-D14 -> 270958.03 | O14: =M14-E14 -> 36.853414 | P14: 862904.82 | Q14: 52.783187 | R14: =P14-D14 -> 504476.18 | S14: =Q14-E14 -> 29.811189 | T14: 556545.35 | U14: 66.52069 | V14: =T14-D14 -> 198116.71 | W14: =U14-E14 -> 43.548692 | X14: 862572.94 | Y14: 64.206813 | Z14: =X14-D14 -> 504144.31 | AA14: =Y14-E14 -> 41.234815 | AC14: 220.51995 | AD14: 235.68857 | AE14: 257.99196 | AF14: 189.08185 | AG14: 201.92378 | AH14: 139.61446 | AI14: 148.78699
A15: PISOS E PAVIMENTAÇÕES | B15: =[3]ANÁLISE_CUSTOS!$B14 -> 2973237.6 | C15: =B15/'SEM IMPREVISTOS'!$G$2 -> 190.55734 | D15: ='[1]Ger_Executivo MEGA'!$N$235 -> 52103.948 | E15: =D15/'SEM IMPREVISTOS'!$G$2 -> 3.3393866 | F15: =D15-B15 -> -2921133.6 | G15: =E15-C15 -> -187.21795 | J15: =D15-H15 -> 52103.948 | K15: =E15-I15 -> 3.3393866 | L15: 542621.15 | M15: 51.578045 | N15: =L15-D15 -> 490517.2 | O15: =M15-E15 -> 48.238659 | P15: 0 | Q15: 0 | R15: =P15-D15 -> -52103.948 | S15: =Q15-E15 -> -3.3393866 | T15: 1496779 | U15: 178.90146 | V15: =T15-D15 -> 1444675.1 | W15: =U15-E15 -> 175.56207 | X15: 2193634.7 | Y15: 163.28624 | Z15: =X15-D15 -> 2141530.8 | AA15: =Y15-E15 -> 159.94686 | AC15: 175.5593 | AD15: 17.510173 | AE15: 19.167175 | AF15: 134.65857 | AG15: 143.80422 | AH15: 136.50222 | AI15: 145.47028
A16: PINTURA INTERNA E EXTERNA | B16: =[3]ANÁLISE_CUSTOS!$B15 -> 2806557.3 | C16: =B16/'SEM IMPREVISTOS'!$G$2 -> 179.87465 | D16: ='[1]Ger_Executivo MEGA'!$N$267 -> 312741.32 | E16: =D16/'SEM IMPREVISTOS'!$G$2 -> 20.043859 | F16: =D16-B16 -> -2493815.9 | G16: =E16-C16 -> -159.8308 | J16: =D16-H16 -> 312741.32 | K16: =E16-I16 -> 20.043859 | L16: 1439529.6 | M16: 136.83235 | N16: =L16-D16 -> 1126788.3 | O16: =M16-E16 -> 116.78849 | P16: 0 | Q16: 0 | R16: =P16-D16 -> -312741.32 | S16: =Q16-E16 -> -20.043859 | T16: 1249969.5 | U16: 149.40172 | V16: =T16-D16 -> 937228.16 | W16: =U16-E16 -> 129.35786 | X16: 3018741.9 | Y16: 224.70424 | Z16: =X16-D16 -> 2706000.6 | AA16: =Y16-E16 -> 204.66038 | AC16: 785.01399 | AD16: 73.435461 | AE16: 80.384716 | AF16: 246.44936 | AG16: 263.18754 | AH16: 223.83737 | AI16: 238.54326
A17: ESQUADRIAS, VIDROS E FERRAGENS | B17: =[3]ANÁLISE_CUSTOS!$B16 -> 3656203.9 | C17: =B17/'SEM IMPREVISTOS'!$G$2 -> 234.32923 | D17: ='[1]Ger_Executivo MEGA'!$N$293 -> 124889.96 | E17: =D17/'SEM IMPREVISTOS'!$G$2 -> 8.0043042 | F17: =D17-B17 -> -3531313.9 | G17: =E17-C17 -> -226.32493 | J17: =D17-H17 -> 124889.96 | K17: =E17-I17 -> 8.0043042 | L17: 2367640.5 | M17: 225.05254 | N17: =L17-D17 -> 2242750.5 | O17: =M17-E17 -> 217.04823 | P17: 4464254.4 | Q17: 273.07481 | R17: =P17-D17 -> 4339364.4 | S17: =Q17-E17 -> 265.07051 | T17: 2132929.3 | U17: 254.93687 | V17: =T17-D17 -> 2008039.3 | W17: =U17-E17 -> 246.93256 | X17: 3537375.2 | Y17: 263.30943 | Z17: =X17-D17 -> 3412485.2 | AA17: =Y17-E17 -> 255.30512 | AC17: 19.720233 | AD17: 289.35719 | AE17: 316.73929 | AF17: 14.67023 | AG17: 15.666593 | AH17: 0 | AI17: 0
A18: REVESTIMENTOS E ACABAMENTOS DE FACHADA | B18: =[3]ANÁLISE_CUSTOS!$B17 -> 0 | C18: =B18/'SEM IMPREVISTOS'!$G$2 -> 0 | D18: ='[1]Ger_Executivo MEGA'!$N$338 -> 932576.07 | E18: =D18/'SEM IMPREVISTOS'!$G$2 -> 59.769598 | F18: =D18-B18 -> 932576.07 | G18: =E18-C18 -> 59.769598 | J18: =D18-H18 -> 932576.07 | K18: =E18-I18 -> 59.769598 | L18: 440509.46 | M18: 41.87197 | N18: =L18-D18 -> -492066.61 | O18: =M18-E18 -> -17.897628 | P18: 0 | Q18: 0 | R18: =P18-D18 -> -932576.07 | S18: =Q18-E18 -> -59.769598 | T18: 333415.47 | U18: 39.851248 | V18: =T18-D18 -> -599160.6 | W18: =U18-E18 -> -19.918349 | X18: 6623.3191 | Y18: 0.49301594 | Z18: =X18-D18 -> -925952.75 | AA18: =Y18-E18 -> -59.276582 | AC18: 159.4358 | AD18: 93.244353 | AE18: 102.06814 | AF18: 132.67687 | AG18: 141.68793 | AH18: 162.49166 | AI18: 173.16719
A19: SERVIÇOS COMPLEMENTARES | B19: =[3]ANÁLISE_CUSTOS!$B18 -> 2711159.5 | C19: =B19/'SEM IMPREVISTOS'!$G$2 -> 173.76053 | D19: ='[1]Ger_Executivo MEGA'!$N$346 -> 203841 | E19: =D19/'SEM IMPREVISTOS'!$G$2 -> 13.064344 | F19: =D19-B19 -> -2507318.5 | G19: =E19-C19 -> -160.69619 | J19: =D19-H19 -> 203841 | K19: =E19-I19 -> 13.064344 | L19: 2117620.7 | M19: 201.28728 | N19: =L19-D19 -> 1913779.7 | O19: =M19-E19 -> 188.22294 | P19: 1902989 | Q19: 116.40429 | R19: =P19-D19 -> 1699148 | S19: =Q19-E19 -> 103.33995 | T19: 1511748 | U19: 180.69062 | V19: =T19-D19 -> 1307907 | W19: =U19-E19 -> 167.62627 | X19: 2538432.1 | Y19: 188.95171 | Z19: =X19-D19 -> 2334591.1 | AA19: =Y19-E19 -> 175.88737 | AC19: 263.83653 | AD19: 217.60741 | AE19: 238.19978 | AF19: 123.27583 | AG19: 131.64839 | AH19: 165.47857 | AI19: 176.35035
A20: TOTAL | B20: =SUM(B3:B19) -> 56032826 | C20: =SUM(C3:C19) -> 3591.1917 | D20: =SUM(D3:D19) -> 15827199 | E20: =SUM(E3:E19) -> 1014.3787 | F20: =SUM(F3:F19) -> -40205627 | G20: =SUM(G3:G19) -> -2576.813 | H20: =SUM(H3:H19) -> 0 | I20: =SUM(I3:I19) -> 0 | ... AA20: =SUM(AA3:AA19) -> 2264.8438

Sheet CÁLCULO_MÉDIAS
D1: =7000/D5 -> 1.1660817
C3: DATA BASE | D3: 44958 | E3: DATA BASE | F3: 45047 | G3: DATA BASE | H3: 45017 | I3: DATA BASE | J3: 44896 | K3: DATA BASE | L3: 45017 | M3: DATA BASE | N3: 44927 | O3: DATA BASE | P3: 44682 | Q3: DATA BASE | R3: 45017 | S3: DATA BASE | T3: 45108 | U3: DATA BASE | V3: 45108
C4: CUB | D4: 2662.47 | E4: CUB | F4: 2688.94 | G4: CUB | H4: 2680.84 | I4: CUB | J4: 2643.16 | K4: CUB | L4: 2680.84 | M4: CUB | N4: 2651.17 | O4: CUB | P4: 2470.83 | Q4: CUB | R4: 2680.84 | S4: CUB | T4: 2747.9 | U4: CUB | V4: 2753.62
C5: M2 | D5: 6003.01 | F5: 10520.39 | H5: 16348.1 | T5: =Amalfi!M3 -> 8366.5 | V5: =Amalfi!N3 -> 13434.29
C6: PAVIMENTOS | H6: 33 PAV
H7: 55 UNI
C8: DOM | E8: LIBERATO | G8: PAESSAGGIO | I8: M VILLAGE | K8: LA VIE - MG3 | M8: NM | O8: CANTO GRANDE | Q8: OPUS | S8: MAIORI | U8: RAVELLO | X8: MÉDIAS
C9: VALOR / M2 | D9: INDEXADO | E9: VALOR / M2 | F9: INDEXADO | G9: VALOR / M2 | H9: INDEXADO | I9: VALOR / M2 | J9: INDEXADO | K9: VALOR / M2 | L9: INDEXADO | M9: VALOR / M2 | N9: INDEXADO | O9: VALOR / M2 | P9: INDEXADO | Q9: VALOR / M2 | R9: INDEXADO | S9: VALOR / M2 | T9: INDEXADO | U9: VALOR / M2 | V9: INDEXADO | X9: MÍNIMA | Y9: MÁXIMA | Z9: ATUAL
B10: GERENCIAMENTO TÉCNICO E ADMINISTRATIVO | C10: 425.96974 | D10: =('SEM IMPREVISTOS'!$B$19/CÁLCULO_MÉDIAS!D$4)*C10 -> 469.49673 | E10: 283.33076 | F10: =('SEM IMPREVISTOS'!$B$19/CÁLCULO_MÉDIAS!F$4)*E10 -> 309.20832 | G10: =306.853550565509+12.39 -> 319.24355 | H10: =('SEM IMPREVISTOS'!$B$19/CÁLCULO_MÉDIAS!H$4)*G10 -> 349.45382 | I10: 400.33 | J10: =('SEM IMPREVISTOS'!$B$19/CÁLCULO_MÉDIAS!J$4)*I10 -> 444.46057 | K10: 351.39718 | L10: =('SEM IMPREVISTOS'!$B$19/CÁLCULO_MÉDIAS!L$4)*K10 -> 384.65017 | M10: 507.7761 | N10: =('SEM IMPREVISTOS'!$B$19/CÁLCULO_MÉDIAS!N$4)*M10 -> 562.04778 | O10: 853.40172 | P10: =('SEM IMPREVISTOS'!$B$19/CÁLCULO_MÉDIAS!P$4)*O10 -> 1013.5594 | Q10: 515.91027 | R10: =('SEM IMPREVISTOS'!$B$19/CÁLCULO_MÉDIAS!R$4)*Q10 -> 564.73127 | S10: 419.36861 | T10: =('SEM IMPREVISTOS'!$B$19/CÁLCULO_MÉDIAS!T$4)*S10 -> 447.851 | U10: 387.84287 | V10: =('SEM IMPREVISTOS'!$B$19/CÁLCULO_MÉDIAS!V$4)*U10 -> 413.32375 | X10: 320 | Y10: 470
