Workbook
Name \0: #REF!
Name \0: #REF!
Name \1: #REF!
Name \a: #REF!
Name \a: #REF!
Name \b: #REF!
Name \c: #REF!
Name \d: #REF!
Name \e: #REF!
Name \i: #REF!
Name \J: #REF!
Name \k: #REF!
Name \l: #N/A
Name \m: #REF!
Name \m: #REF!
Name \o: #REF!
Name \p: #REF!
Name \r: #REF!
Name \T: #REF!
Name \z: #REF!
Name _: #REF!
Name _\0: #REF!
Name _\1: #REF!
Name _\a: #REF!
Name _\b: #REF!
Name _\c: #REF!
Name _\d: #REF!
Name _\e: #REF!
Name _\i: #REF!
Name _\J: #REF!
Name _\k: #REF!
Name _\l: #N/A
Name _\m: #REF!
Name _\m: #REF!
Name _\o: #REF!
Name _\p: #REF!
Name _\r: #REF!
Name _\T: #REF!
Name _\z: #REF!
Name _\z: #REF!
Name __: #REF!
Name ______ACR10: #REF!
Name ______ACR15: #REF!
Name ______acr20: #REF!
Name ______acr5: #REF!
Name ______ARQ1: #REF!
Name ______QT100: #REF!
Name ______QT2: #REF!
Name ______QT3: #REF!
Name ______QT4: #REF!
Name ______QT50: #REF!
Name ______QT75: #REF!
Name _____ACR10: #REF!
Name _____ACR15: #REF!
Name _____acr20: #REF!
Name _____acr5: #REF!
Name _____ARQ1: #REF!
Name _____key2: #REF!
Name _____QT100: #REF!
Name _____QT2: #REF!

Sheet CAPA
C1: DADOS DO EMPREENDIMENTO
B2: Projeto: | C2: RESIDENCIAL ALIPIO SCHIRMANN | E2: ENDEREÇO DA OBRA: | F2: Rua : 298 E RUA 300, lotes 131, 132, 133 e 134, Jardim Guarani- Nº XX | CEP: 88220-971
B3: Empresa: | C3: Borscheid | E3: Cidade/ES: | F3: Meia Praia/SC
B4: Revisão: | C4: R00 | E4: CNPJ: | F4: 03.893.978/0001-18
B6: Pazo de Obra: | C6: 48 | E6: Nº Unid. Residenciais: | F6: =E96 -> 43 | I6: Imagens
B8: Área do Terreno: | C8: 1029.39 | E8: Nº Unid. Comerciais: | F8: 5
B10: Área Construída: | C10: =SUM($D$19:$D$48) -> 12033.96 | E10: Nº Pavimentos: | F10: 29
B12: Área Privativa: | C12: =SUM($E$19:$E$76) -> 6188.34 | E12: Total de Dormitórios: | F12: =G96 -> 130
B14: Área de Lazer: | C14: =SUM(D51:D84) -> 919.1218 | E14: Nº Subsolos: | F14: 0
B16: Área Comercial: | C16: =D105 -> 488.34 | E16: Nº Vagas: | F16: =F96 -> 48
B18: Torre | C18: Pavimento | D18: Área | E18: Área Privativa | F18: Perímetro | G18: Pé direito
B19: Torre 1 | C19: TÉRREO 01 | D19: 935.13 | F19: =[1]EPCs!M5 -> 126.01 | G19: =[1]EPCs!N5 -> 3.6
B20: Torre 1 | C20: MEZANINO DO 01 PAV | D20: 906.99 | F20: =[1]EPCs!M6 -> 131.834 | G20: =[1]EPCs!N6 -> 3.24
B21: Torre 1 | C21: 2º PAV - GARAGEM | D21: 906.99 | F21: =[1]EPCs!M7 -> 131.834 | G21: =[1]EPCs!N7 -> 2.88
B22: Torre 1 | C22: MEZANINO DO 02 PAV | D22: 906.99 | F22: =[1]EPCs!M8 -> 131.834 | G22: =[1]EPCs!N8 -> 4.86
B23: Torre 1 | C23: 3º PAVTO - LAZER | D23: 906.99 | F23: =[1]EPCs!M9 -> 85.37 | G23: =[1]EPCs!N9 -> 3.6
B24: Torre 1 | C24: 4º PAVTO - TIPO | D24: 320.81 | E24: =5906.88/21 -> 281.28 | F24: =[1]EPCs!M10 -> 81.91 | G24: =[1]EPCs!N10 -> 3.24
B25: Torre 1 | C25: 5º PAVTO - TIPO | D25: 320.81 | E25: =5906.88/21 -> 281.28 | F25: =[1]EPCs!M11 -> 81.91 | G25: =[1]EPCs!N11 -> 3.24
B26: Torre 1 | C26: 6º PAVTO - TIPO | D26: 320.81 | E26: =5906.88/21 -> 281.28 | F26: =[1]EPCs!M12 -> 81.91 | G26: =[1]EPCs!N12 -> 3.24
B27: Torre 1 | C27: 7º PAVTO - TIPO | D27: 320.81 | E27: =5906.88/21 -> 281.28 | F27: =[1]EPCs!M13 -> 81.91 | G27: =[1]EPCs!N13 -> 3.24
B28: Torre 1 | C28: 8º PAVTO - TIPO | D28: 320.81 | E28: =5906.88/21 -> 281.28 | F28: =[1]EPCs!M14 -> 81.91 | G28: =[1]EPCs!N14 -> 3.24
B29: Torre 1 | C29: 9º PAVTO - TIPO | D29: 320.81 | E29: =5906.88/21 -> 281.28 | F29: =[1]EPCs!M15 -> 81.91 | G29: =[1]EPCs!N15 -> 3.24
B30: Torre 1 | C30: 10º PAVTO - TIPO | D30: 320.81 | E30: =5906.88/21 -> 281.28 | F30: =[1]EPCs!M16 -> 81.91 | G30: =[1]EPCs!N16 -> 3.24
B31: Torre 1 | C31: 11º PAVTO - TIPO | D31: 320.81 | E31: =5906.88/21 -> 281.28 | F31: =[1]EPCs!M17 -> 81.91 | G31: =[1]EPCs!N17 -> 3.24
B32: Torre 1 | C32: 12º PAVTO - TIPO | D32: 320.81 | E32: =5906.88/21 -> 281.28 | F32: =[1]EPCs!M18 -> 81.91 | G32: =[1]EPCs!N18 -> 3.24
B33: Torre 1 | C33: 13º PAVTO - TIPO | D33: 320.81 | E33: =5906.88/21 -> 281.28 | F33: =[1]EPCs!M19 -> 81.91 | G33: =[1]EPCs!N19 -> 3.24
B34: Torre 1 | C34: 14º PAVTO - TIPO | D34: 320.81 | E34: =5906.88/21 -> 281.28 | F34: =[1]EPCs!M20 -> 81.91 | G34: =[1]EPCs!N20 -> 3.24
B35: Torre 1 | C35: 15º PAVTO - TIPO | D35: 320.81 | E35: =5906.88/21 -> 281.28 | F35: =[1]EPCs!M21 -> 81.91 | G35: =[1]EPCs!N21 -> 3.24
... B44: Torre 1 | C44: 24º PAVTO - TIPO | D44: 320.81 | E44: =5906.88/21 -> 281.28 | F44: =[1]EPCs!M30 -> 81.91 | G44: =[1]EPCs!N30 -> 3.24
B45: Torre 1 | C45: 25º PVTO - PENTHOUSE X1 | D45: 320.99 | E45: 281.46 | F45: =[1]EPCs!M31 -> 81.91 | G45: =[1]EPCs!N31 -> 3.24
B46: Torre 1 | C46: 26º PVTO - ROOFTOP | D46: 295.17 | F46: =[1]EPCs!M32 -> 77.48 | G46: =[1]EPCs!N32 -> 3.4
B47: Torre 1 | C47: PAVIMENTO DE COBERTURA / CASA DE MÁQUINAS | D47: 60.38 | F47: =[1]EPCs!M33 -> 43.22 | G47: =[1]EPCs!N33 -> 3
B48: Torre 1 | C48: RESERVATÓRIOS | D48: 57.32 | F48: =[1]EPCs!M34 -> 31.64 | G48: =[1]EPCs!N34 -> 4
B50: Pavimento | C50: Descrição | D50: Área
B51: =[1]MOBILIÁRIO!B7 -> Térreo | C51: =[1]MOBILIÁRIO!C7 -> Hall de acesso | D51: =SUMIFS([1]MOBILIÁRIO!F:F,[1]MOBILIÁRIO!C:C,CAPA!C51,[1]MOBILIÁRIO!E:E,[1]MOBILIÁRIO!$E$7) -> 56.53 | I51: ETAPA | J51: VALOR ORÇADO | K51: % | L51: VALOR / m²
B52: =[1]MOBILIÁRIO!B21 -> Térreo | C52: =[1]MOBILIÁRIO!C21 -> Lavabo - Lobby | D52: =SUMIFS([1]MOBILIÁRIO!F:F,[1]MOBILIÁRIO!C:C,CAPA!C52,[1]MOBILIÁRIO!E:E,[1]MOBILIÁRIO!$E$7) -> 2.32 | I52: TERRENO | J52: =[1]Terreno!$N$25 -> 12463690 | K52: =J52/J$75 -> 0.1902211 | L52: =J52/$C$10 -> 1035.7098
B53: =[1]MOBILIÁRIO!B26 -> Térreo | C53: =[1]MOBILIÁRIO!C26 -> Hall Praia | D53: =SUMIFS([1]MOBILIÁRIO!F:F,[1]MOBILIÁRIO!C:C,CAPA!C53,[1]MOBILIÁRIO!E:E,[1]MOBILIÁRIO!$E$7) -> 44.83 | I53: GERENCIAMENTO TÉCNICO E ADMINISTRATIVO | J53: ='[1]Ger_Tec e Adm'!$N$171 -> 7647984.9 | K53: =J53/J$75 -> 0.11672371 | L53: =J53/$C$10 -> 635.53351
B54: =[1]MOBILIÁRIO!B34 -> Térreo | C54: =[1]MOBILIÁRIO!C34 -> Zelador | D54: =SUMIFS([1]MOBILIÁRIO!F:F,[1]MOBILIÁRIO!C:C,CAPA!C54,[1]MOBILIÁRIO!E:E,[1]MOBILIÁRIO!$E$7) -> 3.89 | I54: =[1]Ger_Executivo!$J$8 -> MOVIMENTAÇÃO DE TERRA | J54: =[1]Ger_Executivo!$N$8 -> 399006.27 | K54: =J54/J$75 -> 0.0060896423 | L54: =J54/$C$10 -> 33.156689
B55: =[1]MOBILIÁRIO!B41 -> Lazer | C55: =[1]MOBILIÁRIO!C41 -> Deck + Prainha | D55: =SUMIFS([1]MOBILIÁRIO!F:F,[1]MOBILIÁRIO!C:C,CAPA!C55,[1]MOBILIÁRIO!E:E,[1]MOBILIÁRIO!$E$7) -> 44.82 | I55: =[1]Ger_Executivo!$J$23 -> INFRAESTRUTURA | J55: =[1]Ger_Executivo!$N$23 -> 3161953.3 | K55: =J55/J$75 -> 0.048257799 | L55: =J55/$C$10 -> 262.75252
B56: =[1]MOBILIÁRIO!B46 -> Lazer | C56: =[1]MOBILIÁRIO!C46 -> WC Deck 1 | D56: =SUMIFS([1]MOBILIÁRIO!F:F,[1]MOBILIÁRIO!C:C,CAPA!C56,[1]MOBILIÁRIO!E:E,[1]MOBILIÁRIO!$E$7) -> 3.77 | I56: =[1]Ger_Executivo!$J$55 -> SUPRAESTRUTURA | J56: =[1]Ger_Executivo!$N$55 -> 10108557 | K56: =J56/J$75 -> 0.15427702 | L56: =J56/$C$10 -> 840.00257
...
