Workbook
Name \0: #REF!
Name \1: #REF!
Name \a: #REF!
Name \b: #REF!
Name \c: #REF!
Name \d: #REF!
Name \e: #REF!
Name \i: #REF!
Name \J: #REF!
Name \k: #REF!
Name \l: #N/A
Name \m: #REF!
Name \o: #REF!
Name \p: #REF!
Name \r: #REF!
Name \T: #REF!
Name \z: #REF!
Name ______ACR10: #REF!
Name ______ACR15: #REF!
Name ______acr20: #REF!
Name ______acr5: #REF!
Name ______ARQ1: #REF!
Name ______QT100: #REF!
Name ______QT2: #REF!
Name ______QT3: #REF!
Name ______QT4: #REF!
Name ______QT50: #REF!
Name ______QT75: #REF!
Name _____ACR10: #REF!
Name _____ACR15: #REF!
Name _____acr20: #REF!
Name _____acr5: #REF!
Name _____ARQ1: #REF!
Name _____QT100: #REF!
Name _____QT2: #REF!
Name _____QT3: #REF!
Name _____QT4: #REF!
Name _____QT50: #REF!
Name _____QT75: #REF!
Name ___ACR10: #REF!
Name ___ACR15: #REF!
Name ___acr20: #REF!
Name ___acr5: #REF!
Name ___ARQ1: #REF!
Name ___QT100: #REF!
Name ___QT2: #REF!
Name ___QT3: #REF!
Name ___QT4: #REF!
Name ___QT50: #REF!
Name ___QT75: #REF!
Name __ACR10: #REF!
Name __ACR15: #REF!
Name __acr20: #REF!
Name __acr5: #REF!
Name __ARQ1: #REF!
Name __Axe3: #REF!
Name __Axe4: #REF!
Name __htm2: #REF!
Name __htn2: #REF!
Name __iss2: #REF!

Sheet OBRA
A1: ORÇAMENTO PARAMÉTRICO
A5: Obra | B5: NOW Residence
A6: Cliente | B6: Cambert Engenharia
A7: Data | B7: 46107
A8: Versão | B8: R00
B10: Descrição | C10: Unidade | D10: Quantidade
B11: ÁREA DO TERRENO | C11: M2 | D11: 1210.5
B12: ÁREA CONSTRUÍDA | C12: M2 | D12: 13275.29
B13: NÚMERO DE APARTAMENTOS | C13: UN | D13: 144
B14: MESES DE OBRA | C14: MÊS | D14: 48
B15: NÚMERO DE PAVIMENTOS | C15: UN | D15: 24
B17: ETAPA | C17: VALOR ORÇADO | D17: % | E17: VALOR / m²
B18: GERENCIAMENTO TÉCNICO E ADMINISTRATIVO | C18: =ORÇAMENTO!N48 | D18: =C18/C$20 | E18: =C18/OBRA!$D$12
B19: MOVIMENTAÇÃO DE TERRA | C19: =ORÇAMENTO!N107 | D19: =C19/C$20 | E19: =C19/OBRA!$D$12
B20: INFRAESTRUTURA + CONTENÇÃO | C20: =ORÇAMENTO!N117+ORÇAMENTO!N135 | D20: =C20/C$20 | E20: =C20/OBRA!$D$12
B21: SUPRAESTRUTURA | C21: =ORÇAMENTO!N144 | D21: =C21/C$20 | E21: =C21/OBRA!$D$12
B22: ALVENARIA | C22: =ORÇAMENTO!N159 | D22: =C22/C$20 | E22: =C22/OBRA!$D$12
B23: INSTALAÇÕES ELÉTRICAS, HIDRÁULICAS, GLP E PREVENTIVAS | C23: =ORÇAMENTO!N182 | D23: =C23/C$20 | E23: =C23/OBRA!$D$12
B24: EQUIPAMENTOS E SISTEMAS ESPECIAIS | C24: =ORÇAMENTO!N207 | D24: =C24/C$20 | E24: =C24/OBRA!$D$12
B25: IMPERMEABILIZAÇÃO | C25: =ORÇAMENTO!N169 | D25: =C25/C$20 | E25: =C25/OBRA!$D$12
B26: REVESTIMENTOS E ACABAMENTOS INTERNOS EM PAREDE | C26: =ORÇAMENTO!N230 | D26: =C26/C$20 | E26: =C26/OBRA!$D$12
B27: REVESTIMENTOS E ACABAMENTOS INTERNOS EM TETO | C27: =ORÇAMENTO!N241 | D27: =C27/C$20 | E27: =C27/OBRA!$D$12
B28: REVESTIMENTOS E ACABAMENTOS INTERNOS EM PISO | C28: =ORÇAMENTO!N250 | D28: =C28/C$20 | E28: =C28/OBRA!$D$12
B29: PINTURA INTERNA | C29: =ORÇAMENTO!N265 | D29: =C29/C$20 | E29: =C29/OBRA!$D$12
B30: ESQUADRIAS, VIDROS E FERRAGENS | C30: =ORÇAMENTO!N274 | D30: =C30/C$20 | E30: =C30/OBRA!$D$12
B31: COBERTURA | D31: =C31/C$20 | E31: =C31/OBRA!$D$12
B32: REVESTIMENTOS E ACABAMENTOS DE FACHADA | C32: =ORÇAMENTO!N291 | D32: =C32/C$20 | E32: =C32/OBRA!$D$12
B33: SERVIÇOS COMPLEMENTARES | C33: =ORÇAMENTO!N300 | D33: =C33/C$20 | E33: =C33/OBRA!$D$12
B34: IMPREVISTOS E CONTINGENCIAS | C34: =ORÇAMENTO!N309 | D34: =C34/C$20 | E34: =C34/OBRA!$D$12
B35: TOTAL | C35: =SUM(C18:C34) | D35: =SUM(D18:D34) | E35: =SUM(E18:E34)
B36: CUB/SC | C36: 2907.85 | D36: 45689 | E36: =+E35/C36

Sheet EPC's
A1: Obra | B1: =OBRA!B5
A2: Empresa | B2: =OBRA!B6
A3: Revisão | B3: R00
A4: LEVANTAMENTO QUANTITATIVO
A6: Equipamentos de proteção coletiva
A8: Bandejas de proteção
B10: Descrição | C10: Unidade | D10: Quantidade
B11: Perímetro de projeção embasamneto | C11: m | D11: 157.96
B12: Perímetro de projeção torre | C12: m | D12: 132.16
B13: Bandeja de proteção primária | C13: m | D13: =D11+D12
B14: Bandeja de proteção secundária | C14: m | D14: =D12
A16: Guarda - corpo de desforma
B18: Descrição | C18: Unidade | D18: Quantidade
B19: Perímetro de projeção da torre | C19: m | D19: =D12
B20: Repetições de pavimentos** | C20: un | D20: 4
B21: Proteção de periferia pós desforma torre | C21: m | D21: =(D19*D20)
A23: Tela fachadeira
B25: Descrição | C25: Unidade | D25: Quantidade
B26: Perimetro da torre | C26: m | D26: =D12
B27: Altura da torre | C27: m | D27: 44.78
B28: Tela fachadeira | C28: m2 | D28: =D26*D27
A30: Fechamento removível de vãos em madeira
B32: Descrição | C32: Unidade | D32: Quantidade
B33: Área das portas de elevadores | C33: m2 | D33: =0.9*2.4
B34: Quantidade de elevadores | C34: un | D34: 2
B35: Quantidade de portas de elevadores | C35: un | D35: 26
B36: Fechamento removível de vãos em madeira | C36: m2 | D36: =D33*D35
A38: Guarda - corpo de vãos
B40: Descrição | C40: Unidade | D40: Quantidade
B41: Perímetro de vãos | C41: m | D41: 632.2144
B42: Guarda - corpo de vãos | C42: m | D42: =D41
A44: Tapume
B46: Descrição | C46: Unidade | D46: Quantidade
B47: Perímetro de encontro com pavimentação | C47: m | D47: 31
B48: Altura do tapume | C48: m | D48: 2.4
B49: Cobertura para proteção de pedestres | C49: m2 | D49: =D48*D47

Sheet ORÇAMENTO
G1: ORÇAMENTO PRELIMINAR
A4: Unidade Construtiva | B4: Célula Construtiva | C4: Etapa | D4: Subetapa | E4: Serviço | M4: ESCOLHA UMA OPÇÃO:
A5: 0 | B5: 0 | C5: 0 | D5: 0 | E5: 0 | G5: CLIENTE | I5: =OBRA!B6 | M5: FORRO VINILICO
A6: =IF(G6="UNIDADE CONSTRUTIVA",OFFSET(A6,-1,0)+1,LARGE(A$4:A5,1)) | B6: =IF(G6="UNIDADE CONSTRUTIVA",0,IF(G6="CÉLULA CONSTRUTIVA",OFFSET(B6,-1,0)+1,OFFSET(B6,-1,0))) | C6: =IF(G6="CÉLULA CONSTRUTIVA",0,IF(G6="ETAPA",OFFSET(C6,-1,0)+1,OFFSET(C6,-1,0))) | D6: =IF(G6="ETAPA",0,IF(G6="SUBETAPA",OFFSET(D6,-1,0)+1,OFFSET(D6,-1,0))) | E6: =IF(G6="Subetapa",0,IF(G6="serviço",OFFSET(E6,-1,0)+1,OFFSET(E6,-1,0))) | G6: OBRA | I6: =OBRA!B5 | M6: REBOCO
A7: =IF(G7="UNIDADE CONSTRUTIVA",OFFSET(A7,-1,0)+1,LARGE(A$4:A6,1)) | B7: =IF(G7="UNIDADE CONSTRUTIVA",0,IF(G7="CÉLULA CONSTRUTIVA",OFFSET(B7,-1,0)+1,OFFSET(B7,-1,0))) | C7: =IF(G7="CÉLULA CONSTRUTIVA",0,IF(G7="ETAPA",OFFSET(C7,-1,0)+1,OFFSET(C7,-1,0))) | D7: =IF(G7="ETAPA",0,IF(G7="SUBETAPA",OFFSET(D7,-1,0)+1,OFFSET(D7,-1,0))) | E7: =IF(G7="Subetapa",0,IF(G7="serviço",OFFSET(E7,-1,0)+1,OFFSET(E7,-1,0))) | G7: DATA | I7: =OBRA!B7 | M7: BRISE TOTAL
H8: VERSÃO | I8: =OBRA!B8
M9: ESQUADRIAS MAIORES
B10: =IF(G10="UNIDADE CONSTRUTIVA",0,IF(G10="CÉLULA CONSTRUTIVA",OFFSET(B10,-1,0)+1,OFFSET(B10,-1,0))) | C10: =IF(G10="CÉLULA CONSTRUTIVA",0,IF(G10="ETAPA",OFFSET(C10,-1,0)+1,OFFSET(C10,-1,0))) | D10: =IF(G10="ETAPA",0,IF(G10="SUBETAPA",OFFSET(D10,-1,0)+1,OFFSET(D10,-1,0))) | E10: =IF(G10="Subetapa",0,IF(G10="serviço",OFFSET(E10,-1,0)+1,OFFSET(E10,-1,0))) | H10: * IMPORTANTE: Os custos unitários apresentados nessa página possuem majoração ao custo real buscando contemplar aproximações de quantidades, perdas e outras situações previstas através de índices e indexadores no orçamento
A11: =IF(G11="UNIDADE CONSTRUTIVA",OFFSET(A11,-1,0)+1,LARGE(A$4:A10,1)) | B11: =IF(G11="UNIDADE CONSTRUTIVA",0,IF(G11="CÉLULA CONSTRUTIVA",OFFSET(B11,-1,0)+1,OFFSET(B11,-1,0))) | C11: =IF(G11="CÉLULA CONSTRUTIVA",0,IF(G11="ETAPA",OFFSET(C11,-1,0)+1,OFFSET(C11,-1,0))) | D11: =IF(G11="ETAPA",0,IF(G11="SUBETAPA",OFFSET(D11,-1,0)+1,OFFSET(D11,-1,0))) | E11: =IF(G11="Subetapa",0,IF(G11="serviço",OFFSET(E11,-1,0)+1,OFFSET(E11,-1,0))) | G11: Nivel | H11: Código | I11: Descrição | J11: Un. | K11: Quantidade | L11: Preço unitário | M11: Preço total | N11: % | O11: R$/m² | P11: Observação
A12: =IF(G12="UNIDADE CONSTRUTIVA",OFFSET(A12,-1,0)+1,LARGE(A$4:A11,1)) | B12: =IF(G12="UNIDADE CONSTRUTIVA",0,IF(G12="CÉLULA CONSTRUTIVA",OFFSET(B12,-1,0)+1,OFFSET(B12,-1,0))) | C12: =IF(G12="CÉLULA CONSTRUTIVA",0,IF(G12="ETAPA",OFFSET(C12,-1,0)+1,OFFSET(C12,-1,0))) | D12: =IF(G12="ETAPA",0,IF(G12="SUBETAPA",OFFSET(D12,-1,0)+1,OFFSET(D12,-1,0))) | E12: =IF(G12="Subetapa",0,IF(G12="serviço",OFFSET(E12,-1,0)+1,OFFSET(E12,-1,0)))
A13: =IF(G13="UNIDADE CONSTRUTIVA",OFFSET(A13,-1,0)+1,LARGE(A$4:A12,1)) | B13: =IF(G13="UNIDADE CONSTRUTIVA",0,IF(G13="CÉLULA CONSTRUTIVA",OFFSET(B13,-1,0)+1,OFFSET(B13,-1,0))) | C13: =IF(G13="CÉLULA CONSTRUTIVA",0,IF(G13="ETAPA",OFFSET(C13,-1,0)+1,OFFSET(C13,-1,0))) | D13: =IF(G13="ETAPA",0,IF(G13="SUBETAPA",OFFSET(D13,-1,0)+1,OFFSET(D13,-1,0))) | E13: =IF(G13="Subetapa",0,IF(G13="serviço",OFFSET(E13,-1,0)+1,OFFSET(E13,-1,0))) | G13: UNIDADE CONSTRUTIVA | H13: =IF(G13="Unidade Construtiva",CONCATENATE("UC ",TEXT(A13,"00")),IF(G13="Célula Construtiva",TEXT(B13,"00"),IF(G13="Etapa",CONCATENATE(TEXT(B13,"00"),".",TEXT(C13,"000")),IF(G13="Subetapa",CONCATENATE(TEXT(B13,"00"),".",TEXT(C13,"000"),".",TEXT(D13,"000")),IF(G13="Serviço",CONCATENATE(TEXT(B13,"00"),".",TEXT(C13,"000"),".",TEXT(D13,"000"),".",TEXT(E13,"000")),""))))) | I13: DESPESAS INDIRETAS | M13: =M14+M44 | N13: =M13/$M$298 | O13: =M13/OBRA!$D$12
A14: =IF(G14="UNIDADE CONSTRUTIVA",OFFSET(A14,-1,0)+1,LARGE(A$4:A13,1)) | B14: =IF(G14="UNIDADE CONSTRUTIVA",0,IF(G14="CÉLULA CONSTRUTIVA",OFFSET(B14,-1,0)+1,OFFSET(B14,-1,0))) | C14: =IF(G14="CÉLULA CONSTRUTIVA",0,IF(G14="ETAPA",OFFSET(C14,-1,0)+1,OFFSET(C14,-1,0))) | D14: =IF(G14="ETAPA",0,IF(G14="SUBETAPA",OFFSET(D14,-1,0)+1,OFFSET(D14,-1,0))) | E14: =IF(G14="Subetapa",0,IF(G14="serviço",OFFSET(E14,-1,0)+1,OFFSET(E14,-1,0))) | G14: CÉLULA CONSTRUTIVA | H14: =IF(G14="Unidade Construtiva",CONCATENATE("UC ",TEXT(A14,"00")),IF(G14="Célula Construtiva",TEXT(B14,"00"),IF(G14="Etapa",CONCATENATE(TEXT(B14,"00"),".",TEXT(C14,"000")),IF(G14="Subetapa",CONCATENATE(TEXT(B14,"00"),".",TEXT(C14,"000"),".",TEXT(D14,"000")),IF(G14="Serviço",CONCATENATE(TEXT(B14,"00"),".",TEXT(C14,"000"),".",TEXT(D14,"000"),".",TEXT(E14,"000")),""))))) | I14: GERENCIAMENTO TÉCNICO | M14: =M15+M34 | N14: =M14/$M$298 | O14: =M14/OBRA!$D$12
A15: =IF(G15="UNIDADE CONSTRUTIVA",OFFSET(A15,-1,0)+1,LARGE(A$4:A14,1)) | B15: =IF(G15="UNIDADE CONSTRUTIVA",0,IF(G15="CÉLULA CONSTRUTIVA",OFFSET(B15,-1,0)+1,OFFSET(B15,-1,0))) | C15: =IF(G15="CÉLULA CONSTRUTIVA",0,IF(G15="ETAPA",OFFSET(C15,-1,0)+1,OFFSET(C15,-1,0))) | D15: =IF(G15="ETAPA",0,IF(G15="SUBETAPA",OFFSET(D15,-1,0)+1,OFFSET(D15,-1,0))) | E15: =IF(G15="Subetapa",0,IF(G15="serviço",OFFSET(E15,-1,0)+1,OFFSET(E15,-1,0))) | G15: ETAPA | H15: =IF(G15="Unidade Construtiva",CONCATENATE("UC ",TEXT(A15,"00")),IF(G15="Célula Construtiva",TEXT(B15,"00"),IF(G15="Etapa",CONCATENATE(TEXT(B15,"00"),".",TEXT(C15,"000")),IF(G15="Subetapa",CONCATENATE(TEXT(B15,"00"),".",TEXT(C15,"000"),".",TEXT(D15,"000")),IF(G15="Serviço",CONCATENATE(TEXT(B15,"00"),".",TEXT(C15,"000"),".",TEXT(D15,"000"),".",TEXT(E15,"000")),""))))) | I15: SEGURANÇA, MEIO AMBIENTE, SAÚDE | M15: =SUM(M16:M33)/2 | N15: =M15/$M$298 | O15: =M15/OBRA!$D$12
A16: =IF(G16="UNIDADE CONSTRUTIVA",OFFSET(A16,-1,0)+1,LARGE(A$4:A15,1)) | B16: =IF(G16="UNIDADE CONSTRUTIVA",0,IF(G16="CÉLULA CONSTRUTIVA",OFFSET(B16,-1,0)+1,OFFSET(B16,-1,0))) | C16: =IF(G16="CÉLULA CONSTRUTIVA",0,IF(G16="ETAPA",OFFSET(C16,-1,0)+1,OFFSET(C16,-1,0))) | D16: =IF(G16="ETAPA",0,IF(G16="SUBETAPA",OFFSET(D16,-1,0)+1,OFFSET(D16,-1,0))) | E16: =IF(G16="Subetapa",0,IF(G16="serviço",OFFSET(E16,-1,0)+1,OFFSET(E16,-1,0))) | G16: Subetapa | H16: =IF(G16="Unidade Construtiva",CONCATENATE("UC ",TEXT(A16,"00")),IF(G16="Célula Construtiva",TEXT(B16,"00"),IF(G16="Etapa",CONCATENATE(TEXT(B16,"00"),".",TEXT(C16,"000")),IF(G16="Subetapa",CONCATENATE(TEXT(B16,"00"),".",TEXT(C16,"000"),".",TEXT(D16,"000")),IF(G16="Serviço",CONCATENATE(TEXT(B16,"00"),".",TEXT(C16,"000"),".",TEXT(D16,"000"),".",TEXT(E16,"000")),""))))) | I16: Estudos | N16: =M16/$M$298 | O16: =M16/OBRA!$D$12
A17: =IF(G17="UNIDADE CONSTRUTIVA",OFFSET(A17,-1,0)+1,LARGE(A$4:A16,1)) | B17: =IF(G17="UNIDADE CONSTRUTIVA",0,IF(G17="CÉLULA CONSTRUTIVA",OFFSET(B17,-1,0)+1,OFFSET(B17,-1,0))) | C17: =IF(G17="CÉLULA CONSTRUTIVA",0,IF(G17="ETAPA",OFFSET(C17,-1,0)+1,OFFSET(C17,-1,0))) | D17: =IF(G17="ETAPA",0,IF(G17="SUBETAPA",OFFSET(D17,-1,0)+1,OFFSET(D17,-1,0))) | E17: =IF(G17="Subetapa",0,IF(G17="serviço",OFFSET(E17,-1,0)+1,OFFSET(E17,-1,0))) | G17: Subetapa | H17: =IF(G17="Unidade Construtiva",CONCATENATE("UC ",TEXT(A17,"00")),IF(G17="Célula Construtiva",TEXT(B17,"00"),IF(G17="Etapa",CONCATENATE(TEXT(B17,"00"),".",TEXT(C17,"000")),IF(G17="Subetapa",CONCATENATE(TEXT(B17,"00"),".",TEXT(C17,"000"),".",TEXT(D17,"000")),IF(G17="Serviço",CONCATENATE(TEXT(B17,"00"),".",TEXT(C17,"000"),".",TEXT(D17,"000"),".",TEXT(E17,"000")),""))))) | I17: Projetos | M17: =SUM(M18:M27) | N17: =M17/$M$298 | O17: =M17/OBRA!$D$12
A18: =IF(G18="UNIDADE CONSTRUTIVA",OFFSET(A18,-1,0)+1,LARGE(A$4:A17,1)) | B18: =IF(G18="UNIDADE CONSTRUTIVA",0,IF(G18="CÉLULA CONSTRUTIVA",OFFSET(B18,-1,0)+1,OFFSET(B18,-1,0))) | C18: =IF(G18="CÉLULA CONSTRUTIVA",0,IF(G18="ETAPA",OFFSET(C18,-1,0)+1,OFFSET(C18,-1,0))) | D18: =IF(G18="ETAPA",0,IF(G18="SUBETAPA",OFFSET(D18,-1,0)+1,OFFSET(D18,-1,0))) | E18: =IF(G18="Subetapa",0,IF(G18="serviço",OFFSET(E18,-1,0)+1,OFFSET(E18,-1,0))) | G18: Serviço | H18: =IF(G18="Unidade Construtiva",CONCATENATE("UC ",TEXT(A18,"00")),IF(G18="Célula Construtiva",TEXT(B18,"00"),IF(G18="Etapa",CONCATENATE(TEXT(B18,"00"),".",TEXT(C18,"000")),IF(G18="Subetapa",CONCATENATE(TEXT(B18,"00"),".",TEXT(C18,"000"),".",TEXT(D18,"000")),IF(G18="Serviço",CONCATENATE(TEXT(B18,"00"),".",TEXT(C18,"000"),".",TEXT(D18,"000"),".",TEXT(E18,"000")),""))))) | I18: Projeto Arquitetônico | J18: vb | K18: 1 | L18: 412743.05 | M18: =K18*L18 | N18: =M18/$M$298 | O18: =M18/OBRA!$D$12
A19: =IF(G19="UNIDADE CONSTRUTIVA",OFFSET(A19,-1,0)+1,LARGE(A$4:A18,1)) | B19: =IF(G19="UNIDADE CONSTRUTIVA",0,IF(G19="CÉLULA CONSTRUTIVA",OFFSET(B19,-1,0)+1,OFFSET(B19,-1,0))) | C19: =IF(G19="CÉLULA CONSTRUTIVA",0,IF(G19="ETAPA",OFFSET(C19,-1,0)+1,OFFSET(C19,-1,0))) | D19: =IF(G19="ETAPA",0,IF(G19="SUBETAPA",OFFSET(D19,-1,0)+1,OFFSET(D19,-1,0))) | E19: =IF(G19="Subetapa",0,IF(G19="serviço",OFFSET(E19,-1,0)+1,OFFSET(E19,-1,0))) | G19: Serviço | H19: =IF(G19="Unidade Construtiva",CONCATENATE("UC ",TEXT(A19,"00")),IF(G19="Célula Construtiva",TEXT(B19,"00"),IF(G19="Etapa",CONCATENATE(TEXT(B19,"00"),".",TEXT(C19,"000")),IF(G19="Subetapa",CONCATENATE(TEXT(B19,"00"),".",TEXT(C19,"000"),".",TEXT(D19,"000")),IF(G19="Serviço",CONCATENATE(TEXT(B19,"00"),".",TEXT(C19,"000"),".",TEXT(D19,"000"),".",TEXT(E19,"000")),""))))) | I19: Projeto Estrutural | J19: vb | K19: 1 | L19: 343952.54 | M19: =K19*L19 | N19: =M19/$M$298 | O19: =M19/OBRA!$D$12
A20: =IF(G20="UNIDADE CONSTRUTIVA",OFFSET(A20,-1,0)+1,LARGE(A$4:A18,1)) | B20: =IF(G20="UNIDADE CONSTRUTIVA",0,IF(G20="CÉLULA CONSTRUTIVA",OFFSET(B20,-1,0)+1,OFFSET(B20,-1,0))) | C20: =IF(G20="CÉLULA CONSTRUTIVA",0,IF(G20="ETAPA",OFFSET(C20,-1,0)+1,OFFSET(C20,-1,0))) | D20: =IF(G20="ETAPA",0,IF(G20="SUBETAPA",OFFSET(D20,-1,0)+1,OFFSET(D20,-1,0))) | E20: =IF(G20="Subetapa",0,IF(G20="serviço",OFFSET(E20,-1,0)+1,OFFSET(E20,-1,0))) | G20: Serviço | H20: =IF(G20="Unidade Construtiva",CONCATENATE("UC ",TEXT(A20,"00")),IF(G20="Célula Construtiva",TEXT(B20,"00"),IF(G20="Etapa",CONCATENATE(TEXT(B20,"00"),".",TEXT(C20,"000")),IF(G20="Subetapa",CONCATENATE(TEXT(B20,"00"),".",TEXT(C20,"000"),".",TEXT(D20,"000")),IF(G20="Serviço",CONCATENATE(TEXT(B20,"00"),".",TEXT(C20,"000"),".",TEXT(D20,"000"),".",TEXT(E20,"000")),""))))) | I20: Projeto Elétrico | J20: vb | K20: 1 | L20: 206371.52 | M20: =K20*L20 | N20: =M20/$M$298 | O20: =M20/OBRA!$D$12
A21: =IF(G21="UNIDADE CONSTRUTIVA",OFFSET(A21,-1,0)+1,LARGE(A$4:A19,1)) | B21: =IF(G21="UNIDADE CONSTRUTIVA",0,IF(G21="CÉLULA CONSTRUTIVA",OFFSET(B21,-1,0)+1,OFFSET(B21,-1,0))) | C21: =IF(G21="CÉLULA CONSTRUTIVA",0,IF(G21="ETAPA",OFFSET(C21,-1,0)+1,OFFSET(C21,-1,0))) | D21: =IF(G21="ETAPA",0,IF(G21="SUBETAPA",OFFSET(D21,-1,0)+1,OFFSET(D21,-1,0))) | E21: =IF(G21="Subetapa",0,IF(G21="serviço",OFFSET(E21,-1,0)+1,OFFSET(E21,-1,0))) | G21: Serviço | H21: =IF(G21="Unidade Construtiva",CONCATENATE("UC ",TEXT(A21,"00")),IF(G21="Célula Construtiva",TEXT(B21,"00"),IF(G21="Etapa",CONCATENATE(TEXT(B21,"00"),".",TEXT(C21,"000")),IF(G21="Subetapa",CONCATENATE(TEXT(B21,"00"),".",TEXT(C21,"000"),".",TEXT(D21,"000")),IF(G21="Serviço",CONCATENATE(TEXT(B21,"00"),".",TEXT(C21,"000"),".",TEXT(D21,"000"),".",TEXT(E21,"000")),""))))) | I21: Projeto Hidrossanitário | J21: vb | K21: 1 | L21: 206371.52 | M21: =K21*L21 | N21: =M21/$M$298 | O21: =M21/OBRA!$D$12
A22: =IF(G22="UNIDADE CONSTRUTIVA",OFFSET(A22,-1,0)+1,LARGE(A$4:A19,1)) | B22: =IF(G22="UNIDADE CONSTRUTIVA",0,IF(G22="CÉLULA CONSTRUTIVA",OFFSET(B22,-1,0)+1,OFFSET(B22,-1,0))) | C22: =IF(G22="CÉLULA CONSTRUTIVA",0,IF(G22="ETAPA",OFFSET(C22,-1,0)+1,OFFSET(C22,-1,0))) | D22: =IF(G22="ETAPA",0,IF(G22="SUBETAPA",OFFSET(D22,-1,0)+1,OFFSET(D22,-1,0))) | E22: =IF(G22="Subetapa",0,IF(G22="serviço",OFFSET(E22,-1,0)+1,OFFSET(E22,-1,0))) | G22: Serviço | H22: =IF(G22="Unidade Construtiva",CONCATENATE("UC ",TEXT(A22,"00")),IF(G22="Célula Construtiva",TEXT(B22,"00"),IF(G22="Etapa",CONCATENATE(TEXT(B22,"00"),".",TEXT(C22,"000")),IF(G22="Subetapa",CONCATENATE(TEXT(B22,"00"),".",TEXT(C22,"000"),".",TEXT(D22,"000")),IF(G22="Serviço",CONCATENATE(TEXT(B22,"00"),".",TEXT(C22,"000"),".",TEXT(D22,"000"),".",TEXT(E22,"000")),""))))) | I22: Projeto Preventivo | J22: vb | K22: 1 | L22: 110064.81 | M22: =K22*L22 | N22: =M22/$M$298 | O22: =M22/OBRA!$D$12
A23: =IF(G23="UNIDADE CONSTRUTIVA",OFFSET(A23,-1,0)+1,LARGE(A$4:A20,1)) | B23: =IF(G23="UNIDADE CONSTRUTIVA",0,IF(G23="CÉLULA CONSTRUTIVA",OFFSET(B23,-1,0)+1,OFFSET(B23,-1,0))) | C23: =IF(G23="CÉLULA CONSTRUTIVA",0,IF(G23="ETAPA",OFFSET(C23,-1,0)+1,OFFSET(C23,-1,0))) | D23: =IF(G23="ETAPA",0,IF(G23="SUBETAPA",OFFSET(D23,-1,0)+1,OFFSET(D23,-1,0))) | E23: =IF(G23="Subetapa",0,IF(G23="serviço",OFFSET(E23,-1,0)+1,OFFSET(E23,-1,0))) | G23: Serviço | H23: =IF(G23="Unidade Construtiva",CONCATENATE("UC ",TEXT(A23,"00")),IF(G23="Célula Construtiva",TEXT(B23,"00"),IF(G23="Etapa",CONCATENATE(TEXT(B23,"00"),".",TEXT(C23,"000")),IF(G23="Subetapa",CONCATENATE(TEXT(B23,"00"),".",TEXT(C23,"000"),".",TEXT(D23,"000")),IF(G23="Serviço",CONCATENATE(TEXT(B23,"00"),".",TEXT(C23,"000"),".",TEXT(D23,"000"),".",TEXT(E23,"000")),""))))) | I23: Projeto Climatização | J23: vb | K23: 1 | L23: 55032.41 | M23: =K23*L23 | N23: =M23/$M$298 | O23: =M23/OBRA!$D$12
A24: =IF(G24="UNIDADE CONSTRUTIVA",OFFSET(A24,-1,0)+1,LARGE(A$4:A23,1)) | B24: =IF(G24="UNIDADE CONSTRUTIVA",0,IF(G24="CÉLULA CONSTRUTIVA",OFFSET(B24,-1,0)+1,OFFSET(B24,-1,0))) | C24: =IF(G24="CÉLULA CONSTRUTIVA",0,IF(G24="ETAPA",OFFSET(C24,-1,0)+1,OFFSET(C24,-1,0))) | D24: =IF(G24="ETAPA",0,IF(G24="SUBETAPA",OFFSET(D24,-1,0)+1,OFFSET(D24,-1,0))) | E24: =IF(G24="Subetapa",0,IF(G24="serviço",OFFSET(E24,-1,0)+1,OFFSET(E24,-1,0))) | G24: Serviço | H24: =IF(G24="Unidade Construtiva",CONCATENATE("UC ",TEXT(A24,"00")),IF(G24="Célula Construtiva",TEXT(B24,"00"),IF(G24="Etapa",CONCATENATE(TEXT(B24,"00"),".",TEXT(C24,"000")),IF(G24="Subetapa",CONCATENATE(TEXT(B24,"00"),".",TEXT(C24,"000"),".",TEXT(D24,"000")),IF(G24="Serviço",CONCATENATE(TEXT(B24,"00"),".",TEXT(C24,"000"),".",TEXT(D24,"000"),".",TEXT(E24,"000")),""))))) | I24: Projeto Paisagismo | J24: vb | K24: 1 | L24: 31690.77 | M24: =K24*L24 | N24: =M24/$M$298 | O24: =M24/OBRA!$D$12
A25: =IF(G25="UNIDADE CONSTRUTIVA",OFFSET(A25,-1,0)+1,LARGE(A$4:A22,1)) | B25: =IF(G25="UNIDADE CONSTRUTIVA",0,IF(G25="CÉLULA CONSTRUTIVA",OFFSET(B25,-1,0)+1,OFFSET(B25,-1,0))) | C25: =IF(G25="CÉLULA CONSTRUTIVA",0,IF(G25="ETAPA",OFFSET(C25,-1,0)+1,OFFSET(C25,-1,0))) | D25: =IF(G25="ETAPA",0,IF(G25="SUBETAPA",OFFSET(D25,-1,0)+1,OFFSET(D25,-1,0))) | E25: =IF(G25="Subetapa",0,IF(G25="serviço",OFFSET(E25,-1,0)+1,OFFSET(E25,-1,0))) | G25: Serviço | H25: =IF(G25="Unidade Construtiva",CONCATENATE("UC ",TEXT(A25,"00")),IF(G25="Célula Construtiva",TEXT(B25,"00"),IF(G25="Etapa",CONCATENATE(TEXT(B25,"00"),".",TEXT(C25,"000")),IF(G25="Subetapa",CONCATENATE(TEXT(B25,"00"),".",TEXT(C25,"000"),".",TEXT(D25,"000")),IF(G25="Serviço",CONCATENATE(TEXT(B25,"00"),".",TEXT(C25,"000"),".",TEXT(D25,"000"),".",TEXT(E25,"000")),""))))) | I25: Projeto Interiores | J25: vb | K25: 1 | L25: 79226.93 | M25: =K25*L25 | N25: =M25/$M$298 | O25: =M25/OBRA!$D$12
A26: =IF(G26="UNIDADE CONSTRUTIVA",OFFSET(A26,-1,0)+1,LARGE(A$4:A25,1)) | B26: =IF(G26="UNIDADE CONSTRUTIVA",0,IF(G26="CÉLULA CONSTRUTIVA",OFFSET(B26,-1,0)+1,OFFSET(B26,-1,0))) | C26: =IF(G26="CÉLULA CONSTRUTIVA",0,IF(G26="ETAPA",OFFSET(C26,-1,0)+1,OFFSET(C26,-1,0))) | D26: =IF(G26="ETAPA",0,IF(G26="SUBETAPA",OFFSET(D26,-1,0)+1,OFFSET(D26,-1,0))) | E26: =IF(G26="Subetapa",0,IF(G26="serviço",OFFSET(E26,-1,0)+1,OFFSET(E26,-1,0))) | G26: Serviço | H26: =IF(G26="Unidade Construtiva",CONCATENATE("UC ",TEXT(A26,"00")),IF(G26="Célula Construtiva",TEXT(B26,"00"),IF(G26="Etapa",CONCATENATE(TEXT(B26,"00"),".",TEXT(C26,"000")),IF(G26="Subetapa",CONCATENATE(TEXT(B26,"00"),".",TEXT(C26,"000"),".",TEXT(D26,"000")),IF(G26="Serviço",CONCATENATE(TEXT(B26,"00"),".",TEXT(C26,"000"),".",TEXT(D26,"000"),".",TEXT(E26,"000")),""))))) | I26: Projeto Fundações | J26: vb | K26: 1 | L26: 41274.3 | M26: =K26*L26 | N26: =M26/$M$298 | O26: =M26/OBRA!$D$12
A27: =IF(G27="UNIDADE CONSTRUTIVA",OFFSET(A27,-1,0)+1,LARGE(A$4:A26,1)) | B27: =IF(G27="UNIDADE CONSTRUTIVA",0,IF(G27="CÉLULA CONSTRUTIVA",OFFSET(B27,-1,0)+1,OFFSET(B27,-1,0))) | C27: =IF(G27="CÉLULA CONSTRUTIVA",0,IF(G27="ETAPA",OFFSET(C27,-1,0)+1,OFFSET(C27,-1,0))) | D27: =IF(G27="ETAPA",0,IF(G27="SUBETAPA",OFFSET(D27,-1,0)+1,OFFSET(D27,-1,0))) | E27: =IF(G27="Subetapa",0,IF(G27="serviço",OFFSET(E27,-1,0)+1,OFFSET(E27,-1,0))) | G27: Serviço | H27: =IF(G27="Unidade Construtiva",CONCATENATE("UC ",TEXT(A27,"00")),IF(G27="Célula Construtiva",TEXT(B27,"00"),IF(G27="Etapa",CONCATENATE(TEXT(B27,"00"),".",TEXT(C27,"000")),IF(G27="Subetapa",CONCATENATE(TEXT(B27,"00"),".",TEXT(C27,"000"),".",TEXT(D27,"000")),IF(G27="Serviço",CONCATENATE(TEXT(B27,"00"),".",TEXT(C27,"000"),".",TEXT(D27,"000"),".",TEXT(E27,"000")),""))))) | I27: Outros projetos | J27: vb | K27: 1 | L27: 79226.93 | M27: =K27*L27 | N27: =M27/$M$298 | O27: =M27/OBRA!$D$12
A28: =IF(G28="UNIDADE CONSTRUTIVA",OFFSET(A28,-1,0)+1,LARGE(A$4:A17,1)) | B28: =IF(G28="UNIDADE CONSTRUTIVA",0,IF(G28="CÉLULA CONSTRUTIVA",OFFSET(B28,-1,0)+1,OFFSET(B28,-1,0))) | C28: =IF(G28="CÉLULA CONSTRUTIVA",0,IF(G28="ETAPA",OFFSET(C28,-1,0)+1,OFFSET(C28,-1,0))) | D28: =IF(G28="ETAPA",0,IF(G28="SUBETAPA",OFFSET(D28,-1,0)+1,OFFSET(D28,-1,0))) | E28: =IF(G28="Subetapa",0,IF(G28="serviço",OFFSET(E28,-1,0)+1,OFFSET(E28,-1,0))) | G28: Subetapa | H28: =IF(G28="Unidade Construtiva",CONCATENATE("UC ",TEXT(A28,"00")),IF(G28="Célula Construtiva",TEXT(B28,"00"),IF(G28="Etapa",CONCATENATE(TEXT(B28,"00"),".",TEXT(C28,"000")),IF(G28="Subetapa",CONCATENATE(TEXT(B28,"00"),".",TEXT(C28,"000"),".",TEXT(D28,"000")),IF(G28="Serviço",CONCATENATE(TEXT(B28,"00"),".",TEXT(C28,"000"),".",TEXT(D28,"000"),".",TEXT(E28,"000")),""))))) | I28: Consultorias | N28: =M28/$M$298 | O28: =M28/OBRA!$D$12
A29: =IF(G29="UNIDADE CONSTRUTIVA",OFFSET(A29,-1,0)+1,LARGE(A$4:A28,1)) | B29: =IF(G29="UNIDADE CONSTRUTIVA",0,IF(G29="CÉLULA CONSTRUTIVA",OFFSET(B29,-1,0)+1,OFFSET(B29,-1,0))) | C29: =IF(G29="CÉLULA CONSTRUTIVA",0,IF(G29="ETAPA",OFFSET(C29,-1,0)+1,OFFSET(C29,-1,0))) | D29: =IF(G29="ETAPA",0,IF(G29="SUBETAPA",OFFSET(D29,-1,0)+1,OFFSET(D29,-1,0))) | E29: =IF(G29="Subetapa",0,IF(G29="serviço",OFFSET(E29,-1,0)+1,OFFSET(E29,-1,0))) | G29: Subetapa | H29: =IF(G29="Unidade Construtiva",CONCATENATE("UC ",TEXT(A29,"00")),IF(G29="Célula Construtiva",TEXT(B29,"00"),IF(G29="Etapa",CONCATENATE(TEXT(B29,"00"),".",TEXT(C29,"000")),IF(G29="Subetapa",CONCATENATE(TEXT(B29,"00"),".",TEXT(C29,"000"),".",TEXT(D29,"000")),IF(G29="Serviço",CONCATENATE(TEXT(B29,"00"),".",TEXT(C29,"000"),".",TEXT(D29,"000"),".",TEXT(E29,"000")),""))))) | I29: Ensaios e Laudos | M29: =SUM(M30:M33) | N29: =M29/$M$298 | O29: =M29/OBRA!$D$12
A30: =IF(G30="UNIDADE CONSTRUTIVA",OFFSET(A30,-1,0)+1,LARGE(A$4:A29,1)) | B30: =IF(G30="UNIDADE CONSTRUTIVA",0,IF(G30="CÉLULA CONSTRUTIVA",OFFSET(B30,-1,0)+1,OFFSET(B30,-1,0))) | C30: =IF(G30="CÉLULA CONSTRUTIVA",0,IF(G30="ETAPA",OFFSET(C30,-1,0)+1,OFFSET(C30,-1,0))) | D30: =IF(G30="ETAPA",0,IF(G30="SUBETAPA",OFFSET(D30,-1,0)+1,OFFSET(D30,-1,0))) | E30: =IF(G30="Subetapa",0,IF(G30="serviço",OFFSET(E30,-1,0)+1,OFFSET(E30,-1,0))) | G30: Serviço | H30: =IF(G30="Unidade Construtiva",CONCATENATE("UC ",TEXT(A30,"00")),IF(G30="Célula Construtiva",TEXT(B30,"00"),IF(G30="Etapa",CONCATENATE(TEXT(B30,"00"),".",TEXT(C30,"000")),IF(G30="Subetapa",CONCATENATE(TEXT(B30,"00"),".",TEXT(C30,"000"),".",TEXT(D30,"000")),IF(G30="Serviço",CONCATENATE(TEXT(B30,"00"),".",TEXT(C30,"000"),".",TEXT(D30,"000"),".",TEXT(E30,"000")),""))))) | I30: Concreto (CP) | J30: vb | K30: 1 | L30: 412743.05 | M30: =K30*L30 | N30: =M30/$M$298 | O30: =M30/OBRA!$D$12
A31: =IF(G31="UNIDADE CONSTRUTIVA",OFFSET(A31,-1,0)+1,LARGE(A$4:A28,1)) | B31: =IF(G31="UNIDADE CONSTRUTIVA",0,IF(G31="CÉLULA CONSTRUTIVA",OFFSET(B31,-1,0)+1,OFFSET(B31,-1,0))) | C31: =IF(G31="CÉLULA CONSTRUTIVA",0,IF(G31="ETAPA",OFFSET(C31,-1,0)+1,OFFSET(C31,-1,0))) | D31: =IF(G31="ETAPA",0,IF(G31="SUBETAPA",OFFSET(D31,-1,0)+1,OFFSET(D31,-1,0))) | E31: =IF(G31="Subetapa",0,IF(G31="serviço",OFFSET(E31,-1,0)+1,OFFSET(E31,-1,0))) | G31: Serviço | H31: =IF(G31="Unidade Construtiva",CONCATENATE("UC ",TEXT(A31,"00")),IF(G31="Célula Construtiva",TEXT(B31,"00"),IF(G31="Etapa",CONCATENATE(TEXT(B31,"00"),".",TEXT(C31,"000")),IF(G31="Subetapa",CONCATENATE(TEXT(B31,"00"),".",TEXT(C31,"000"),".",TEXT(D31,"000")),IF(G31="Serviço",CONCATENATE(TEXT(B31,"00"),".",TEXT(C31,"000"),".",TEXT(D31,"000"),".",TEXT(E31,"000")),""))))) | I31: Solo/Fundações | J31: vb | K31: 1 | L31: 247645.83 | M31: =K31*L31 | N31: =M31/$M$298 | O31: =M31/OBRA!$D$12
A32: =IF(G32="UNIDADE CONSTRUTIVA",OFFSET(A32,-1,0)+1,LARGE(A$4:A31,1)) | B32: =IF(G32="UNIDADE CONSTRUTIVA",0,IF(G32="CÉLULA CONSTRUTIVA",OFFSET(B32,-1,0)+1,OFFSET(B32,-1,0))) | C32: =IF(G32="CÉLULA CONSTRUTIVA",0,IF(G32="ETAPA",OFFSET(C32,-1,0)+1,OFFSET(C32,-1,0))) | D32: =IF(G32="ETAPA",0,IF(G32="SUBETAPA",OFFSET(D32,-1,0)+1,OFFSET(D32,-1,0))) | E32: =IF(G32="Subetapa",0,IF(G32="serviço",OFFSET(E32,-1,0)+1,OFFSET(E32,-1,0))) | G32: Serviço | H32: =IF(G32="Unidade Construtiva",CONCATENATE("UC ",TEXT(A32,"00")),IF(G32="Célula Construtiva",TEXT(B32,"00"),IF(G32="Etapa",CONCATENATE(TEXT(B32,"00"),".",TEXT(C32,"000")),IF(G32="Subetapa",CONCATENATE(TEXT(B32,"00"),".",TEXT(C32,"000"),".",TEXT(D32,"000")),IF(G32="Serviço",CONCATENATE(TEXT(B32,"00"),".",TEXT(C32,"000"),".",TEXT(D32,"000"),".",TEXT(E32,"000")),""))))) | I32: Estanqueidade | J32: vb | K32: 1 | L32: 12676.31 | M32: =K32*L32 | N32: =M32/$M$298 | O32: =M32/OBRA!$D$12
A33: =IF(G33="UNIDADE CONSTRUTIVA",OFFSET(A33,-1,0)+1,LARGE(A$4:A32,1)) | B33: =IF(G33="UNIDADE CONSTRUTIVA",0,IF(G33="CÉLULA CONSTRUTIVA",OFFSET(B33,-1,0)+1,OFFSET(B33,-1,0))) | C33: =IF(G33="CÉLULA CONSTRUTIVA",0,IF(G33="ETAPA",OFFSET(C33,-1,0)+1,OFFSET(C33,-1,0))) | D33: =IF(G33="ETAPA",0,IF(G33="SUBETAPA",OFFSET(D33,-1,0)+1,OFFSET(D33,-1,0))) | E33: =IF(G33="Subetapa",0,IF(G33="serviço",OFFSET(E33,-1,0)+1,OFFSET(E33,-1,0))) | G33: Serviço | H33: =IF(G33="Unidade Construtiva",CONCATENATE("UC ",TEXT(A33,"00")),IF(G33="Célula Construtiva",TEXT(B33,"00"),IF(G33="Etapa",CONCATENATE(TEXT(B33,"00"),".",TEXT(C33,"000")),IF(G33="Subetapa",CONCATENATE(TEXT(B33,"00"),".",TEXT(C33,"000"),".",TEXT(D33,"000")),IF(G33="Serviço",CONCATENATE(TEXT(B33,"00"),".",TEXT(C33,"000"),".",TEXT(D33,"000"),".",TEXT(E33,"000")),""))))) | I33: Outros ensaios | J33: vb | K33: 1 | L33: 12676.31 | M33: =K33*L33 | N33: =M33/$M$298 | O33: =M33/OBRA!$D$12
A34: =IF(G34="UNIDADE CONSTRUTIVA",OFFSET(A34,-1,0)+1,LARGE(A$4:A29,1)) | B34: =IF(G34="UNIDADE CONSTRUTIVA",0,IF(G34="CÉLULA CONSTRUTIVA",OFFSET(B34,-1,0)+1,OFFSET(B34,-1,0))) | C34: =IF(G34="CÉLULA CONSTRUTIVA",0,IF(G34="ETAPA",OFFSET(C34,-1,0)+1,OFFSET(C34,-1,0))) | D34: =IF(G34="ETAPA",0,IF(G34="SUBETAPA",OFFSET(D34,-1,0)+1,OFFSET(D34,-1,0))) | E34: =IF(G34="Subetapa",0,IF(G34="serviço",OFFSET(E34,-1,0)+1,OFFSET(E34,-1,0))) | G34: ETAPA | H34: =IF(G34="Unidade Construtiva",CONCATENATE("UC ",TEXT(A34,"00")),IF(G34="Célula Construtiva",TEXT(B34,"00"),IF(G34="Etapa",CONCATENATE(TEXT(B34,"00"),".",TEXT(C34,"000")),IF(G34="Subetapa",CONCATENATE(TEXT(B34,"00"),".",TEXT(C34,"000"),".",TEXT(D34,"000")),IF(G34="Serviço",CONCATENATE(TEXT(B34,"00"),".",TEXT(C34,"000"),".",TEXT(D34,"000"),".",TEXT(E34,"000")),""))))) | I34: TAXAS E DOCUMENTOS | M34: =M35+M36+M43 | N34: =M34/$M$298 | O34: =M34/OBRA!$D$12
A35: =IF(G35="UNIDADE CONSTRUTIVA",OFFSET(A35,-1,0)+1,LARGE(A$4:A34,1)) | B35: =IF(G35="UNIDADE CONSTRUTIVA",0,IF(G35="CÉLULA CONSTRUTIVA",OFFSET(B35,-1,0)+1,OFFSET(B35,-1,0))) | C35: =IF(G35="CÉLULA CONSTRUTIVA",0,IF(G35="ETAPA",OFFSET(C35,-1,0)+1,OFFSET(C35,-1,0))) | D35: =IF(G35="ETAPA",0,IF(G35="SUBETAPA",OFFSET(D35,-1,0)+1,OFFSET(D35,-1,0))) | E35: =IF(G35="Subetapa",0,IF(G35="serviço",OFFSET(E35,-1,0)+1,OFFSET(E35,-1,0))) | G35: Subetapa | H35: =IF(G35="Unidade Construtiva",CONCATENATE("UC ",TEXT(A35,"00")),IF(G35="Célula Construtiva",TEXT(B35,"00"),IF(G35="Etapa",CONCATENATE(TEXT(B35,"00"),".",TEXT(C35,"000")),IF(G35="Subetapa",CONCATENATE(TEXT(B35,"00"),".",TEXT(C35,"000"),".",TEXT(D35,"000")),IF(G35="Serviço",CONCATENATE(TEXT(B35,"00"),".",TEXT(C35,"000"),".",TEXT(D35,"000"),".",TEXT(E35,"000")),""))))) | I35: Seguros | M35: 27131.405 | N35: =M35/$M$298 | O35: =M35/OBRA!$D$12
A36: =IF(G36="UNIDADE CONSTRUTIVA",OFFSET(A36,-1,0)+1,LARGE(A$4:A35,1)) | B36: =IF(G36="UNIDADE CONSTRUTIVA",0,IF(G36="CÉLULA CONSTRUTIVA",OFFSET(B36,-1,0)+1,OFFSET(B36,-1,0))) | C36: =IF(G36="CÉLULA CONSTRUTIVA",0,IF(G36="ETAPA",OFFSET(C36,-1,0)+1,OFFSET(C36,-1,0))) | D36: =IF(G36="ETAPA",0,IF(G36="SUBETAPA",OFFSET(D36,-1,0)+1,OFFSET(D36,-1,0))) | E36: =IF(G36="Subetapa",0,IF(G36="serviço",OFFSET(E36,-1,0)+1,OFFSET(E36,-1,0))) | G36: Subetapa | H36: =IF(G36="Unidade Construtiva",CONCATENATE("UC ",TEXT(A36,"00")),IF(G36="Célula Construtiva",TEXT(B36,"00"),IF(G36="Etapa",CONCATENATE(TEXT(B36,"00"),".",TEXT(C36,"000")),IF(G36="Subetapa",CONCATENATE(TEXT(B36,"00"),".",TEXT(C36,"000"),".",TEXT(D36,"000")),IF(G36="Serviço",CONCATENATE(TEXT(B36,"00"),".",TEXT(C36,"000"),".",TEXT(D36,"000"),".",TEXT(E36,"000")),""))))) | I36: Licenciamentos, Taxas, Impostos | M36: =SUM(M37:M42) | N36: =M36/$M$298 | O36: =M36/OBRA!$D$12
A37: =IF(G37="UNIDADE CONSTRUTIVA",OFFSET(A37,-1,0)+1,LARGE(A$4:A36,1)) | B37: =IF(G37="UNIDADE CONSTRUTIVA",0,IF(G37="CÉLULA CONSTRUTIVA",OFFSET(B37,-1,0)+1,OFFSET(B37,-1,0))) | C37: =IF(G37="CÉLULA CONSTRUTIVA",0,IF(G37="ETAPA",OFFSET(C37,-1,0)+1,OFFSET(C37,-1,0))) | D37: =IF(G37="ETAPA",0,IF(G37="SUBETAPA",OFFSET(D37,-1,0)+1,OFFSET(D37,-1,0))) | E37: =IF(G37="Subetapa",0,IF(G37="serviço",OFFSET(E37,-1,0)+1,OFFSET(E37,-1,0))) | G37: Serviço | H37: =IF(G37="Unidade Construtiva",CONCATENATE("UC ",TEXT(A37,"00")),IF(G37="Célula Construtiva",TEXT(B37,"00"),IF(G37="Etapa",CONCATENATE(TEXT(B37,"00"),".",TEXT(C37,"000")),IF(G37="Subetapa",CONCATENATE(TEXT(B37,"00"),".",TEXT(C37,"000"),".",TEXT(D37,"000")),IF(G37="Serviço",CONCATENATE(TEXT(B37,"00"),".",TEXT(C37,"000"),".",TEXT(D37,"000"),".",TEXT(E37,"000")),""))))) | I37: Alvará | J37: vb | K37: 1 | L37: 110064.81 | M37: =K37*L37 | N37: =M37/$M$298 | O37: =M37/OBRA!$D$12
A38: =IF(G38="UNIDADE CONSTRUTIVA",OFFSET(A38,-1,0)+1,LARGE(A$4:A33,1)) | B38: =IF(G38="UNIDADE CONSTRUTIVA",0,IF(G38="CÉLULA CONSTRUTIVA",OFFSET(B38,-1,0)+1,OFFSET(B38,-1,0))) | C38: =IF(G38="CÉLULA CONSTRUTIVA",0,IF(G38="ETAPA",OFFSET(C38,-1,0)+1,OFFSET(C38,-1,0))) | D38: =IF(G38="ETAPA",0,IF(G38="SUBETAPA",OFFSET(D38,-1,0)+1,OFFSET(D38,-1,0))) | E38: =IF(G38="Subetapa",0,IF(G38="serviço",OFFSET(E38,-1,0)+1,OFFSET(E38,-1,0))) | G38: Serviço | H38: =IF(G38="Unidade Construtiva",CONCATENATE("UC ",TEXT(A38,"00")),IF(G38="Célula Construtiva",TEXT(B38,"00"),IF(G38="Etapa",CONCATENATE(TEXT(B38,"00"),".",TEXT(C38,"000")),IF(G38="Subetapa",CONCATENATE(TEXT(B38,"00"),".",TEXT(C38,"000"),".",TEXT(D38,"000")),IF(G38="Serviço",CONCATENATE(TEXT(B38,"00"),".",TEXT(C38,"000"),".",TEXT(D38,"000"),".",TEXT(E38,"000")),""))))) | I38: ARTs/RRTs | J38: vb | K38: 1 | L38: 55032.41 | M38: =K38*L38 | N38: =M38/$M$298 | O38: =M38/OBRA!$D$12
A39: =IF(G39="UNIDADE CONSTRUTIVA",OFFSET(A39,-1,0)+1,LARGE(A$4:A38,1)) | B39: =IF(G39="UNIDADE CONSTRUTIVA",0,IF(G39="CÉLULA CONSTRUTIVA",OFFSET(B39,-1,0)+1,OFFSET(B39,-1,0))) | C39: =IF(G39="CÉLULA CONSTRUTIVA",0,IF(G39="ETAPA",OFFSET(C39,-1,0)+1,OFFSET(C39,-1,0))) | D39: =IF(G39="ETAPA",0,IF(G39="SUBETAPA",OFFSET(D39,-1,0)+1,OFFSET(D39,-1,0))) | E39: =IF(G39="Subetapa",0,IF(G39="serviço",OFFSET(E39,-1,0)+1,OFFSET(E39,-1,0))) | G39: Serviço | H39: =IF(G39="Unidade Construtiva",CONCATENATE("UC ",TEXT(A39,"00")),IF(G39="Célula Construtiva",TEXT(B39,"00"),IF(G39="Etapa",CONCATENATE(TEXT(B39,"00"),".",TEXT(C39,"000")),IF(G39="Subetapa",CONCATENATE(TEXT(B39,"00"),".",TEXT(C39,"000"),".",TEXT(D39,"000")),IF(G39="Serviço",CONCATENATE(TEXT(B39,"00"),".",TEXT(C39,"000"),".",TEXT(D39,"000"),".",TEXT(E39,"000")),""))))) | I39: Bombeiros | J39: vb | K39: 1 | L39: 63381.54 | M39: =K39*L39 | N39: =M39/$M$298 | O39: =M39/OBRA!$D$12
A40: =IF(G40="UNIDADE CONSTRUTIVA",OFFSET(A40,-1,0)+1,LARGE(A$4:A35,1)) | B40: =IF(G40="UNIDADE CONSTRUTIVA",0,IF(G40="CÉLULA CONSTRUTIVA",OFFSET(B40,-1,0)+1,OFFSET(B40,-1,0))) | C40: =IF(G40="CÉLULA CONSTRUTIVA",0,IF(G40="ETAPA",OFFSET(C40,-1,0)+1,OFFSET(C40,-1,0))) | D40: =IF(G40="ETAPA",0,IF(G40="SUBETAPA",OFFSET(D40,-1,0)+1,OFFSET(D40,-1,0))) | E40: =IF(G40="Subetapa",0,IF(G40="serviço",OFFSET(E40,-1,0)+1,OFFSET(E40,-1,0))) | G40: Serviço | H40: =IF(G40="Unidade Construtiva",CONCATENATE("UC ",TEXT(A40,"00")),IF(G40="Célula Construtiva",TEXT(B40,"00"),IF(G40="Etapa",CONCATENATE(TEXT(B40,"00"),".",TEXT(C40,"000")),IF(G40="Subetapa",CONCATENATE(TEXT(B40,"00"),".",TEXT(C40,"000"),".",TEXT(D40,"000")),IF(G40="Serviço",CONCATENATE(TEXT(B40,"00"),".",TEXT(C40,"000"),".",TEXT(D40,"000"),".",TEXT(E40,"000")),""))))) | I40: Habite-se | J40: vb | K40: 1 | L40: 47536.16 | M40: =K40*L40 | N40: =M40/$M$298 | O40: =M40/OBRA!$D$12
A41: =IF(G41="UNIDADE CONSTRUTIVA",OFFSET(A41,-1,0)+1,LARGE(A$4:A40,1)) | B41: =IF(G41="UNIDADE CONSTRUTIVA",0,IF(G41="CÉLULA CONSTRUTIVA",OFFSET(B41,-1,0)+1,OFFSET(B41,-1,0))) | C41: =IF(G41="CÉLULA CONSTRUTIVA",0,IF(G41="ETAPA",OFFSET(C41,-1,0)+1,OFFSET(C41,-1,0))) | D41: =IF(G41="ETAPA",0,IF(G41="SUBETAPA",OFFSET(D41,-1,0)+1,OFFSET(D41,-1,0))) | E41: =IF(G41="Subetapa",0,IF(G41="serviço",OFFSET(E41,-1,0)+1,OFFSET(E41,-1,0))) | G41: Serviço | H41: =IF(G41="Unidade Construtiva",CONCATENATE("UC ",TEXT(A41,"00")),IF(G41="Célula Construtiva",TEXT(B41,"00"),IF(G41="Etapa",CONCATENATE(TEXT(B41,"00"),".",TEXT(C41,"000")),IF(G41="Subetapa",CONCATENATE(TEXT(B41,"00"),".",TEXT(C41,"000"),".",TEXT(D41,"000")),IF(G41="Serviço",CONCATENATE(TEXT(B41,"00"),".",TEXT(C41,"000"),".",TEXT(D41,"000"),".",TEXT(E41,"000")),""))))) | I41: Registro Incorporação | J41: vb | K41: 1 | L41: 31690.77 | M41: =K41*L41 | N41: =M41/$M$298 | O41: =M41/OBRA!$D$12
A42: =IF(G42="UNIDADE CONSTRUTIVA",OFFSET(A42,-1,0)+1,LARGE(A$4:A41,1)) | B42: =IF(G42="UNIDADE CONSTRUTIVA",0,IF(G42="CÉLULA CONSTRUTIVA",OFFSET(B42,-1,0)+1,OFFSET(B42,-1,0))) | C42: =IF(G42="CÉLULA CONSTRUTIVA",0,IF(G42="ETAPA",OFFSET(C42,-1,0)+1,OFFSET(C42,-1,0))) | D42: =IF(G42="ETAPA",0,IF(G42="SUBETAPA",OFFSET(D42,-1,0)+1,OFFSET(D42,-1,0))) | E42: =IF(G42="Subetapa",0,IF(G42="serviço",OFFSET(E42,-1,0)+1,OFFSET(E42,-1,0))) | G42: Serviço | H42: =IF(G42="Unidade Construtiva",CONCATENATE("UC ",TEXT(A42,"00")),IF(G42="Célula Construtiva",TEXT(B42,"00"),IF(G42="Etapa",CONCATENATE(TEXT(B42,"00"),".",TEXT(C42,"000")),IF(G42="Subetapa",CONCATENATE(TEXT(B42,"00"),".",TEXT(C42,"000"),".",TEXT(D42,"000")),IF(G42="Serviço",CONCATENATE(TEXT(B42,"00"),".",TEXT(C42,"000"),".",TEXT(D42,"000"),".",TEXT(E42,"000")),""))))) | I42: Outras taxas | J42: vb | K42: 1 | L42: 31690.77 | M42: =K42*L42 | N42: =M42/$M$298 | O42: =M42/OBRA!$D$12
...

Sheet Planilha1
C3: Descrição | D3: Quantidade | E3: Custo
B4: COMPRA CUBETAS
B5: LOCAÇÃO DE CUBETAS | C5: FORRO MADEIRA | D5: 369.9 | E5: 636.9
C6: FORRO PVC IMITA MADEIRA | D6: 369.9 | E6: 81.576
C7: FORRO VINILICO | D7: 369.9 | E7: 253
C8: DECK MADEIRA | D8: 96.22 | E8: 888.8
C9: PORCELANATO QUE IMITA MADEIRA | D9: 96.22 | E9: 324.5
C10: PISO EMBORRACHADO | D10: 126.98 | E10: 385
C11: PISO VINILICO | D11: 126.98 | E11: 165
C12: PISO POLIDO + EPOXI | D12: 2485.44 | E12: 55
C13: PISO LAPIDADO | D13: 2485.44 | E13: 172.7
C14: PINTURA EPOXI | D14: 2485.44 | E14: 132
C15: ESQUADRIAS MAIORES | D15: 2110.7751 | E15: 1375
C16: ESQUADRIAS MENORES | D16: 1649.9751 | E16: 1265
C17: FACHADA ESQ MAIORES | D17: 2854.67
C18: FACHADA ESQ MENORES | D18: 3315.47
C19: CHAPISCO | D19: ='[2]Rev. Internos Piso e Parede'!$B$20 | E19: ='[2]Rev. Internos Piso e Parede'!$G$20/'[2]Rev. Internos Piso e Parede'!$B$20
C20: REBOCO | D20: ='[2]Rev. Internos Piso e Parede'!$B$20 | E20: ='[2]Rev. Internos Piso e Parede'!$G$21/'[2]Rev. Internos Piso e Parede'!$B$21
C21: GESSO SARRAFEADO | D21: ='[2]Rev. Internos Piso e Parede'!$B$20 | E21: ='[2]Rev. Internos Piso e Parede'!$G$38/'[2]Rev. Internos Piso e Parede'!$B$38
C22: BRISE TOTAL | D22: 345.254 | E22: 2310
C23: BRISE FACHADA NORTE | D23: =(2.52*2+3.52+0.89)*(2.8/2)*8 | E23: 2310
