Workbook

Sheet Gerência Consolidada
G4: PROJETO: | I4: =[4]CAPA!C2 | O4: REVISÃO:
G5: EMPRESA: | I5: =[4]CAPA!C3 | O5: =[4]CAPA!C4
A6: Unidade Construtiva | B6: Célula Construtiva | C6: Etapa | D6: Subetapa | E6: Serviço | G6: GERENCIAMENTO TÉCNICO E ADMINISTRATIVO
A7: 0 | B7: 0 | C7: 0 | D7: 0 | E7: 0 | G7: Atalho | H7: NIVEL | I7: Item | J7: Descrição | K7: Unidade | L7: Quant. | M7: Preço un | N7: Total | O7: Considerações
A8: =IF($H8="UNIDADE CONSTRUTIVA",OFFSET(A8,-1,0)+1,LARGE(A$3:A7,1)) | B8: =IF(H8="UNIDADE CONSTRUTIVA",0,IF(H8="CÉLULA CONSTRUTIVA",OFFSET(B8,-1,0)+1,OFFSET(B8,-1,0))) | C8: =IF(H8="CÉLULA CONSTRUTIVA",0,IF(H8="ETAPA",OFFSET(C8,-1,0)+1,OFFSET(C8,-1,0))) | D8: =IF(H8="ETAPA",0,IF(H8="SUBETAPA",OFFSET(D8,-1,0)+1,OFFSET(D8,-1,0))) | E8: =IF(H8="Subetapa",0,IF(H8="serviço",OFFSET(E8,-1,0)+1,OFFSET(E8,-1,0))) | H8: CÉLULA CONSTRUTIVA | I8: =IF(H8="Unidade Construtiva",TEXT(A8,"00"),IF(H8="Célula Construtiva",TEXT(B8,"00"),IF(H8="Etapa",CONCATENATE(TEXT(B8,"00"),".",TEXT(C8,"000")),IF(H8="Subetapa",CONCATENATE(TEXT(B8,"00"),".",TEXT(C8,"000"),".",TEXT(D8,"000")),IF(H8="Serviço",CONCATENATE(TEXT(B8,"00"),".",TEXT(C8,"000"),".",TEXT(D8,"000"),".",TEXT(E8,"000")),""))))) | J8: SERVIÇOS TÉCNICOS | N8: =IF(H8="Serviço",M8*L8,IF(H8="CÉLULA CONSTRUTIVA",SUMIFS($N$8:$N$442,$B$8:$B$442,B8,$H$8:$H$442,"Serviço"),IF(H8="ETAPA",SUMIFS($N$8:$N$442,$B$8:$B$442,B8,$C$8:$C$442,C8,$H$8:$H$442,"Serviço"),IF(H8="SUBETAPA",SUMIFS($N$8:$N$442,$B$8:$B$442,B8,$C$8:$C$442,C8,$D$8:$D$442,D8,$H$8:$H$442,"Serviço"),0))))
A9: =IF($H9="UNIDADE CONSTRUTIVA",OFFSET(A9,-1,0)+1,LARGE(A$3:A8,1)) | B9: =IF(H9="UNIDADE CONSTRUTIVA",0,IF(H9="CÉLULA CONSTRUTIVA",OFFSET(B9,-1,0)+1,OFFSET(B9,-1,0))) | C9: =IF(H9="CÉLULA CONSTRUTIVA",0,IF(H9="ETAPA",OFFSET(C9,-1,0)+1,OFFSET(C9,-1,0))) | D9: =IF(H9="ETAPA",0,IF(H9="SUBETAPA",OFFSET(D9,-1,0)+1,OFFSET(D9,-1,0))) | E9: =IF(H9="Subetapa",0,IF(H9="serviço",OFFSET(E9,-1,0)+1,OFFSET(E9,-1,0))) | H9: ETAPA | I9: =IF(H9="Unidade Construtiva",TEXT(A9,"00"),IF(H9="Célula Construtiva",TEXT(B9,"00"),IF(H9="Etapa",CONCATENATE(TEXT(B9,"00"),".",TEXT(C9,"000")),IF(H9="Subetapa",CONCATENATE(TEXT(B9,"00"),".",TEXT(C9,"000"),".",TEXT(D9,"000")),IF(H9="Serviço",CONCATENATE(TEXT(B9,"00"),".",TEXT(C9,"000"),".",TEXT(D9,"000"),".",TEXT(E9,"000")),""))))) | J9: ESTUDOS, PROJETOS, CONSULTORIA E ENSAIOS | N9: =IF(H9="Serviço",M9*L9,IF(H9="CÉLULA CONSTRUTIVA",SUMIFS($N$8:$N$442,$B$8:$B$442,B9,$H$8:$H$442,"Serviço"),IF(H9="ETAPA",SUMIFS($N$8:$N$442,$B$8:$B$442,B9,$C$8:$C$442,C9,$H$8:$H$442,"Serviço"),IF(H9="SUBETAPA",SUMIFS($N$8:$N$442,$B$8:$B$442,B9,$C$8:$C$442,C9,$D$8:$D$442,D9,$H$8:$H$442,"Serviço"),0))))
A10: =IF($H10="UNIDADE CONSTRUTIVA",OFFSET(A10,-1,0)+1,LARGE(A$3:A9,1)) | B10: =IF(H10="UNIDADE CONSTRUTIVA",0,IF(H10="CÉLULA CONSTRUTIVA",OFFSET(B10,-1,0)+1,OFFSET(B10,-1,0))) | C10: =IF(H10="CÉLULA CONSTRUTIVA",0,IF(H10="ETAPA",OFFSET(C10,-1,0)+1,OFFSET(C10,-1,0))) | D10: =IF(H10="ETAPA",0,IF(H10="SUBETAPA",OFFSET(D10,-1,0)+1,OFFSET(D10,-1,0))) | E10: =IF(H10="Subetapa",0,IF(H10="serviço",OFFSET(E10,-1,0)+1,OFFSET(E10,-1,0))) | H10: SUBETAPA | I10: =IF(H10="Unidade Construtiva",TEXT(A10,"00"),IF(H10="Célula Construtiva",TEXT(B10,"00"),IF(H10="Etapa",CONCATENATE(TEXT(B10,"00"),".",TEXT(C10,"000")),IF(H10="Subetapa",CONCATENATE(TEXT(B10,"00"),".",TEXT(C10,"000"),".",TEXT(D10,"000")),IF(H10="Serviço",CONCATENATE(TEXT(B10,"00"),".",TEXT(C10,"000"),".",TEXT(D10,"000"),".",TEXT(E10,"000")),""))))) | J10: Estudos | N10: =IF(H10="Serviço",M10*L10,IF(H10="CÉLULA CONSTRUTIVA",SUMIFS($N$8:$N$442,$B$8:$B$442,B10,$H$8:$H$442,"Serviço"),IF(H10="ETAPA",SUMIFS($N$8:$N$442,$B$8:$B$442,B10,$C$8:$C$442,C10,$H$8:$H$442,"Serviço"),IF(H10="SUBETAPA",SUMIFS($N$8:$N$442,$B$8:$B$442,B10,$C$8:$C$442,C10,$D$8:$D$442,D10,$H$8:$H$442,"Serviço"),0))))
A11: =IF($H11="UNIDADE CONSTRUTIVA",OFFSET(A11,-1,0)+1,LARGE(A$3:A10,1)) | B11: =IF(H11="UNIDADE CONSTRUTIVA",0,IF(H11="CÉLULA CONSTRUTIVA",OFFSET(B11,-1,0)+1,OFFSET(B11,-1,0))) | C11: =IF(H11="CÉLULA CONSTRUTIVA",0,IF(H11="ETAPA",OFFSET(C11,-1,0)+1,OFFSET(C11,-1,0))) | D11: =IF(H11="ETAPA",0,IF(H11="SUBETAPA",OFFSET(D11,-1,0)+1,OFFSET(D11,-1,0))) | E11: =IF(H11="Subetapa",0,IF(H11="serviço",OFFSET(E11,-1,0)+1,OFFSET(E11,-1,0))) | H11: SERVIÇO | I11: =IF(H11="Unidade Construtiva",TEXT(A11,"00"),IF(H11="Célula Construtiva",TEXT(B11,"00"),IF(H11="Etapa",CONCATENATE(TEXT(B11,"00"),".",TEXT(C11,"000")),IF(H11="Subetapa",CONCATENATE(TEXT(B11,"00"),".",TEXT(C11,"000"),".",TEXT(D11,"000")),IF(H11="Serviço",CONCATENATE(TEXT(B11,"00"),".",TEXT(C11,"000"),".",TEXT(D11,"000"),".",TEXT(E11,"000")),""))))) | J11: Levantamento topográfico | K11: =_xlfn.XLOOKUP($J11,BASES!$A$12:$A$392,BASES!$C$12:$C$392) | L11: =_xlfn.XLOOKUP($J11,BASES!$A$12:$A$392,BASES!$D$12:$D$392) | M11: =_xlfn.XLOOKUP($J11,BASES!$A$1:$A$2289,BASES!$E$1:$E$2289) | N11: =IF(H11="Serviço",M11*L11,IF(H11="CÉLULA CONSTRUTIVA",SUMIFS($N$8:$N$442,$B$8:$B$442,B11,$H$8:$H$442,"Serviço"),IF(H11="ETAPA",SUMIFS($N$8:$N$442,$B$8:$B$442,B11,$C$8:$C$442,C11,$H$8:$H$442,"Serviço"),IF(H11="SUBETAPA",SUMIFS($N$8:$N$442,$B$8:$B$442,B11,$C$8:$C$442,C11,$D$8:$D$442,D11,$H$8:$H$442,"Serviço"),0)))) | O11: =_xlfn.XLOOKUP($J11,BASES!$A$12:$A$392,BASES!$F$12:$F$392)
A12: =IF($H12="UNIDADE CONSTRUTIVA",OFFSET(A12,-1,0)+1,LARGE(A$3:A11,1)) | B12: =IF(H12="UNIDADE CONSTRUTIVA",0,IF(H12="CÉLULA CONSTRUTIVA",OFFSET(B12,-1,0)+1,OFFSET(B12,-1,0))) | C12: =IF(H12="CÉLULA CONSTRUTIVA",0,IF(H12="ETAPA",OFFSET(C12,-1,0)+1,OFFSET(C12,-1,0))) | D12: =IF(H12="ETAPA",0,IF(H12="SUBETAPA",OFFSET(D12,-1,0)+1,OFFSET(D12,-1,0))) | E12: =IF(H12="Subetapa",0,IF(H12="serviço",OFFSET(E12,-1,0)+1,OFFSET(E12,-1,0))) | H12: SERVIÇO | I12: =IF(H12="Unidade Construtiva",TEXT(A12,"00"),IF(H12="Célula Construtiva",TEXT(B12,"00"),IF(H12="Etapa",CONCATENATE(TEXT(B12,"00"),".",TEXT(C12,"000")),IF(H12="Subetapa",CONCATENATE(TEXT(B12,"00"),".",TEXT(C12,"000"),".",TEXT(D12,"000")),IF(H12="Serviço",CONCATENATE(TEXT(B12,"00"),".",TEXT(C12,"000"),".",TEXT(D12,"000"),".",TEXT(E12,"000")),""))))) | J12: Estudo ambiental | K12: =_xlfn.XLOOKUP($J12,BASES!$A$12:$A$392,BASES!$C$12:$C$392) | L12: =_xlfn.XLOOKUP($J12,BASES!$A$12:$A$392,BASES!$D$12:$D$392) | M12: =_xlfn.XLOOKUP($J12,BASES!$A$1:$A$2289,BASES!$E$1:$E$2289) | N12: =IF(H12="Serviço",M12*L12,IF(H12="CÉLULA CONSTRUTIVA",SUMIFS($N$8:$N$442,$B$8:$B$442,B12,$H$8:$H$442,"Serviço"),IF(H12="ETAPA",SUMIFS($N$8:$N$442,$B$8:$B$442,B12,$C$8:$C$442,C12,$H$8:$H$442,"Serviço"),IF(H12="SUBETAPA",SUMIFS($N$8:$N$442,$B$8:$B$442,B12,$C$8:$C$442,C12,$D$8:$D$442,D12,$H$8:$H$442,"Serviço"),0)))) | O12: =_xlfn.XLOOKUP($J12,BASES!$A$12:$A$392,BASES!$F$12:$F$392)
A13: =IF($H13="UNIDADE CONSTRUTIVA",OFFSET(A13,-1,0)+1,LARGE(A$3:A12,1)) | B13: =IF(H13="UNIDADE CONSTRUTIVA",0,IF(H13="CÉLULA CONSTRUTIVA",OFFSET(B13,-1,0)+1,OFFSET(B13,-1,0))) | C13: =IF(H13="CÉLULA CONSTRUTIVA",0,IF(H13="ETAPA",OFFSET(C13,-1,0)+1,OFFSET(C13,-1,0))) | D13: =IF(H13="ETAPA",0,IF(H13="SUBETAPA",OFFSET(D13,-1,0)+1,OFFSET(D13,-1,0))) | E13: =IF(H13="Subetapa",0,IF(H13="serviço",OFFSET(E13,-1,0)+1,OFFSET(E13,-1,0))) | H13: SERVIÇO | I13: =IF(H13="Unidade Construtiva",TEXT(A13,"00"),IF(H13="Célula Construtiva",TEXT(B13,"00"),IF(H13="Etapa",CONCATENATE(TEXT(B13,"00"),".",TEXT(C13,"000")),IF(H13="Subetapa",CONCATENATE(TEXT(B13,"00"),".",TEXT(C13,"000"),".",TEXT(D13,"000")),IF(H13="Serviço",CONCATENATE(TEXT(B13,"00"),".",TEXT(C13,"000"),".",TEXT(D13,"000"),".",TEXT(E13,"000")),""))))) | J13: Sondagem do terreno | K13: =_xlfn.XLOOKUP($J13,BASES!$A$12:$A$392,BASES!$C$12:$C$392) | L13: =_xlfn.XLOOKUP($J13,BASES!$A$12:$A$392,BASES!$D$12:$D$392) | M13: =_xlfn.XLOOKUP($J13,BASES!$A$1:$A$2289,BASES!$E$1:$E$2289) | N13: =IF(H13="Serviço",M13*L13,IF(H13="CÉLULA CONSTRUTIVA",SUMIFS($N$8:$N$442,$B$8:$B$442,B13,$H$8:$H$442,"Serviço"),IF(H13="ETAPA",SUMIFS($N$8:$N$442,$B$8:$B$442,B13,$C$8:$C$442,C13,$H$8:$H$442,"Serviço"),IF(H13="SUBETAPA",SUMIFS($N$8:$N$442,$B$8:$B$442,B13,$C$8:$C$442,C13,$D$8:$D$442,D13,$H$8:$H$442,"Serviço"),0)))) | O13: =_xlfn.XLOOKUP($J13,BASES!$A$12:$A$392,BASES!$F$12:$F$392)
A14: =IF($H14="UNIDADE CONSTRUTIVA",OFFSET(A14,-1,0)+1,LARGE(A$3:A13,1)) | B14: =IF(H14="UNIDADE CONSTRUTIVA",0,IF(H14="CÉLULA CONSTRUTIVA",OFFSET(B14,-1,0)+1,OFFSET(B14,-1,0))) | C14: =IF(H14="CÉLULA CONSTRUTIVA",0,IF(H14="ETAPA",OFFSET(C14,-1,0)+1,OFFSET(C14,-1,0))) | D14: =IF(H14="ETAPA",0,IF(H14="SUBETAPA",OFFSET(D14,-1,0)+1,OFFSET(D14,-1,0))) | E14: =IF(H14="Subetapa",0,IF(H14="serviço",OFFSET(E14,-1,0)+1,OFFSET(E14,-1,0))) | H14: SUBETAPA | I14: =IF(H14="Unidade Construtiva",TEXT(A14,"00"),IF(H14="Célula Construtiva",TEXT(B14,"00"),IF(H14="Etapa",CONCATENATE(TEXT(B14,"00"),".",TEXT(C14,"000")),IF(H14="Subetapa",CONCATENATE(TEXT(B14,"00"),".",TEXT(C14,"000"),".",TEXT(D14,"000")),IF(H14="Serviço",CONCATENATE(TEXT(B14,"00"),".",TEXT(C14,"000"),".",TEXT(D14,"000"),".",TEXT(E14,"000")),""))))) | J14: Projetos | N14: =IF(H14="Serviço",M14*L14,IF(H14="CÉLULA CONSTRUTIVA",SUMIFS($N$8:$N$442,$B$8:$B$442,B14,$H$8:$H$442,"Serviço"),IF(H14="ETAPA",SUMIFS($N$8:$N$442,$B$8:$B$442,B14,$C$8:$C$442,C14,$H$8:$H$442,"Serviço"),IF(H14="SUBETAPA",SUMIFS($N$8:$N$442,$B$8:$B$442,B14,$C$8:$C$442,C14,$D$8:$D$442,D14,$H$8:$H$442,"Serviço"),0))))
A15: =IF($H15="UNIDADE CONSTRUTIVA",OFFSET(A15,-1,0)+1,LARGE(A$3:A14,1)) | B15: =IF(H15="UNIDADE CONSTRUTIVA",0,IF(H15="CÉLULA CONSTRUTIVA",OFFSET(B15,-1,0)+1,OFFSET(B15,-1,0))) | C15: =IF(H15="CÉLULA CONSTRUTIVA",0,IF(H15="ETAPA",OFFSET(C15,-1,0)+1,OFFSET(C15,-1,0))) | D15: =IF(H15="ETAPA",0,IF(H15="SUBETAPA",OFFSET(D15,-1,0)+1,OFFSET(D15,-1,0))) | E15: =IF(H15="Subetapa",0,IF(H15="serviço",OFFSET(E15,-1,0)+1,OFFSET(E15,-1,0))) | H15: SERVIÇO | I15: =IF(H15="Unidade Construtiva",TEXT(A15,"00"),IF(H15="Célula Construtiva",TEXT(B15,"00"),IF(H15="Etapa",CONCATENATE(TEXT(B15,"00"),".",TEXT(C15,"000")),IF(H15="Subetapa",CONCATENATE(TEXT(B15,"00"),".",TEXT(C15,"000"),".",TEXT(D15,"000")),IF(H15="Serviço",CONCATENATE(TEXT(B15,"00"),".",TEXT(C15,"000"),".",TEXT(D15,"000"),".",TEXT(E15,"000")),""))))) | J15: Legalização de incorporação | K15: =_xlfn.XLOOKUP($J15,BASES!$A$12:$A$392,BASES!$C$12:$C$392) | L15: =_xlfn.XLOOKUP($J15,BASES!$A$12:$A$392,BASES!$D$12:$D$392) | M15: =_xlfn.XLOOKUP($J15,BASES!$A$1:$A$2289,BASES!$E$1:$E$2289) | N15: =IF(H15="Serviço",M15*L15,IF(H15="CÉLULA CONSTRUTIVA",SUMIFS($N$8:$N$442,$B$8:$B$442,B15,$H$8:$H$442,"Serviço"),IF(H15="ETAPA",SUMIFS($N$8:$N$442,$B$8:$B$442,B15,$C$8:$C$442,C15,$H$8:$H$442,"Serviço"),IF(H15="SUBETAPA",SUMIFS($N$8:$N$442,$B$8:$B$442,B15,$C$8:$C$442,C15,$D$8:$D$442,D15,$H$8:$H$442,"Serviço"),0)))) | O15: =_xlfn.XLOOKUP($J15,BASES!$A$12:$A$392,BASES!$F$12:$F$392)
A16: =IF($H16="UNIDADE CONSTRUTIVA",OFFSET(A16,-1,0)+1,LARGE(A$3:A15,1)) | B16: =IF(H16="UNIDADE CONSTRUTIVA",0,IF(H16="CÉLULA CONSTRUTIVA",OFFSET(B16,-1,0)+1,OFFSET(B16,-1,0))) | C16: =IF(H16="CÉLULA CONSTRUTIVA",0,IF(H16="ETAPA",OFFSET(C16,-1,0)+1,OFFSET(C16,-1,0))) | D16: =IF(H16="ETAPA",0,IF(H16="SUBETAPA",OFFSET(D16,-1,0)+1,OFFSET(D16,-1,0))) | E16: =IF(H16="Subetapa",0,IF(H16="serviço",OFFSET(E16,-1,0)+1,OFFSET(E16,-1,0))) | H16: SERVIÇO | I16: =IF(H16="Unidade Construtiva",TEXT(A16,"00"),IF(H16="Célula Construtiva",TEXT(B16,"00"),IF(H16="Etapa",CONCATENATE(TEXT(B16,"00"),".",TEXT(C16,"000")),IF(H16="Subetapa",CONCATENATE(TEXT(B16,"00"),".",TEXT(C16,"000"),".",TEXT(D16,"000")),IF(H16="Serviço",CONCATENATE(TEXT(B16,"00"),".",TEXT(C16,"000"),".",TEXT(D16,"000"),".",TEXT(E16,"000")),""))))) | J16: Projeto Arquitetônico Legal | K16: =_xlfn.XLOOKUP($J16,BASES!$A$12:$A$392,BASES!$C$12:$C$392) | L16: =_xlfn.XLOOKUP($J16,BASES!$A$12:$A$392,BASES!$D$12:$D$392) | M16: =_xlfn.XLOOKUP($J16,BASES!$A$1:$A$2289,BASES!$E$1:$E$2289) | N16: =IF(H16="Serviço",M16*L16,IF(H16="CÉLULA CONSTRUTIVA",SUMIFS($N$8:$N$442,$B$8:$B$442,B16,$H$8:$H$442,"Serviço"),IF(H16="ETAPA",SUMIFS($N$8:$N$442,$B$8:$B$442,B16,$C$8:$C$442,C16,$H$8:$H$442,"Serviço"),IF(H16="SUBETAPA",SUMIFS($N$8:$N$442,$B$8:$B$442,B16,$C$8:$C$442,C16,$D$8:$D$442,D16,$H$8:$H$442,"Serviço"),0)))) | O16: =_xlfn.XLOOKUP($J16,BASES!$A$12:$A$392,BASES!$F$12:$F$392)
A17: =IF($H17="UNIDADE CONSTRUTIVA",OFFSET(A17,-1,0)+1,LARGE(A$3:A16,1)) | B17: =IF(H17="UNIDADE CONSTRUTIVA",0,IF(H17="CÉLULA CONSTRUTIVA",OFFSET(B17,-1,0)+1,OFFSET(B17,-1,0))) | C17: =IF(H17="CÉLULA CONSTRUTIVA",0,IF(H17="ETAPA",OFFSET(C17,-1,0)+1,OFFSET(C17,-1,0))) | D17: =IF(H17="ETAPA",0,IF(H17="SUBETAPA",OFFSET(D17,-1,0)+1,OFFSET(D17,-1,0))) | E17: =IF(H17="Subetapa",0,IF(H17="serviço",OFFSET(E17,-1,0)+1,OFFSET(E17,-1,0))) | H17: SERVIÇO | I17: =IF(H17="Unidade Construtiva",TEXT(A17,"00"),IF(H17="Célula Construtiva",TEXT(B17,"00"),IF(H17="Etapa",CONCATENATE(TEXT(B17,"00"),".",TEXT(C17,"000")),IF(H17="Subetapa",CONCATENATE(TEXT(B17,"00"),".",TEXT(C17,"000"),".",TEXT(D17,"000")),IF(H17="Serviço",CONCATENATE(TEXT(B17,"00"),".",TEXT(C17,"000"),".",TEXT(D17,"000"),".",TEXT(E17,"000")),""))))) | J17: Projeto Arquitetônico Executivo | K17: =_xlfn.XLOOKUP($J17,BASES!$A$12:$A$392,BASES!$C$12:$C$392) | L17: =_xlfn.XLOOKUP($J17,BASES!$A$12:$A$392,BASES!$D$12:$D$392) | M17: =_xlfn.XLOOKUP($J17,BASES!$A$1:$A$2289,BASES!$E$1:$E$2289) | N17: =IF(H17="Serviço",M17*L17,IF(H17="CÉLULA CONSTRUTIVA",SUMIFS($N$8:$N$442,$B$8:$B$442,B17,$H$8:$H$442,"Serviço"),IF(H17="ETAPA",SUMIFS($N$8:$N$442,$B$8:$B$442,B17,$C$8:$C$442,C17,$H$8:$H$442,"Serviço"),IF(H17="SUBETAPA",SUMIFS($N$8:$N$442,$B$8:$B$442,B17,$C$8:$C$442,C17,$D$8:$D$442,D17,$H$8:$H$442,"Serviço"),0)))) | O17: =_xlfn.XLOOKUP($J17,BASES!$A$12:$A$392,BASES!$F$12:$F$392)
A18: =IF($H18="UNIDADE CONSTRUTIVA",OFFSET(A18,-1,0)+1,LARGE(A$3:A17,1)) | B18: =IF(H18="UNIDADE CONSTRUTIVA",0,IF(H18="CÉLULA CONSTRUTIVA",OFFSET(B18,-1,0)+1,OFFSET(B18,-1,0))) | C18: =IF(H18="CÉLULA CONSTRUTIVA",0,IF(H18="ETAPA",OFFSET(C18,-1,0)+1,OFFSET(C18,-1,0))) | D18: =IF(H18="ETAPA",0,IF(H18="SUBETAPA",OFFSET(D18,-1,0)+1,OFFSET(D18,-1,0))) | E18: =IF(H18="Subetapa",0,IF(H18="serviço",OFFSET(E18,-1,0)+1,OFFSET(E18,-1,0))) | H18: SERVIÇO | I18: =IF(H18="Unidade Construtiva",TEXT(A18,"00"),IF(H18="Célula Construtiva",TEXT(B18,"00"),IF(H18="Etapa",CONCATENATE(TEXT(B18,"00"),".",TEXT(C18,"000")),IF(H18="Subetapa",CONCATENATE(TEXT(B18,"00"),".",TEXT(C18,"000"),".",TEXT(D18,"000")),IF(H18="Serviço",CONCATENATE(TEXT(B18,"00"),".",TEXT(C18,"000"),".",TEXT(D18,"000"),".",TEXT(E18,"000")),""))))) | J18: Projeto arquitetônico de fachada | K18: =_xlfn.XLOOKUP($J18,BASES!$A$12:$A$392,BASES!$C$12:$C$392) | L18: =_xlfn.XLOOKUP($J18,BASES!$A$12:$A$392,BASES!$D$12:$D$392) | M18: =_xlfn.XLOOKUP($J18,BASES!$A$1:$A$2289,BASES!$E$1:$E$2289) | N18: =IF(H18="Serviço",M18*L18,IF(H18="CÉLULA CONSTRUTIVA",SUMIFS($N$8:$N$442,$B$8:$B$442,B18,$H$8:$H$442,"Serviço"),IF(H18="ETAPA",SUMIFS($N$8:$N$442,$B$8:$B$442,B18,$C$8:$C$442,C18,$H$8:$H$442,"Serviço"),IF(H18="SUBETAPA",SUMIFS($N$8:$N$442,$B$8:$B$442,B18,$C$8:$C$442,C18,$D$8:$D$442,D18,$H$8:$H$442,"Serviço"),0)))) | O18: =_xlfn.XLOOKUP($J18,BASES!$A$12:$A$392,BASES!$F$12:$F$392)
A19: =IF($H19="UNIDADE CONSTRUTIVA",OFFSET(A19,-1,0)+1,LARGE(A$3:A18,1)) | B19: =IF(H19="UNIDADE CONSTRUTIVA",0,IF(H19="CÉLULA CONSTRUTIVA",OFFSET(B19,-1,0)+1,OFFSET(B19,-1,0))) | C19: =IF(H19="CÉLULA CONSTRUTIVA",0,IF(H19="ETAPA",OFFSET(C19,-1,0)+1,OFFSET(C19,-1,0))) | D19: =IF(H19="ETAPA",0,IF(H19="SUBETAPA",OFFSET(D19,-1,0)+1,OFFSET(D19,-1,0))) | E19: =IF(H19="Subetapa",0,IF(H19="serviço",OFFSET(E19,-1,0)+1,OFFSET(E19,-1,0))) | H19: SERVIÇO | I19: =IF(H19="Unidade Construtiva",TEXT(A19,"00"),IF(H19="Célula Construtiva",TEXT(B19,"00"),IF(H19="Etapa",CONCATENATE(TEXT(B19,"00"),".",TEXT(C19,"000")),IF(H19="Subetapa",CONCATENATE(TEXT(B19,"00"),".",TEXT(C19,"000"),".",TEXT(D19,"000")),IF(H19="Serviço",CONCATENATE(TEXT(B19,"00"),".",TEXT(C19,"000"),".",TEXT(D19,"000"),".",TEXT(E19,"000")),""))))) | J19: Projeto estrutural | K19: =_xlfn.XLOOKUP($J19,BASES!$A$12:$A$392,BASES!$C$12:$C$392) | L19: =_xlfn.XLOOKUP($J19,BASES!$A$12:$A$392,BASES!$D$12:$D$392) | M19: =_xlfn.XLOOKUP($J19,BASES!$A$1:$A$2289,BASES!$E$1:$E$2289) | N19: =IF(H19="Serviço",M19*L19,IF(H19="CÉLULA CONSTRUTIVA",SUMIFS($N$8:$N$442,$B$8:$B$442,B19,$H$8:$H$442,"Serviço"),IF(H19="ETAPA",SUMIFS($N$8:$N$442,$B$8:$B$442,B19,$C$8:$C$442,C19,$H$8:$H$442,"Serviço"),IF(H19="SUBETAPA",SUMIFS($N$8:$N$442,$B$8:$B$442,B19,$C$8:$C$442,C19,$D$8:$D$442,D19,$H$8:$H$442,"Serviço"),0)))) | O19: =_xlfn.XLOOKUP($J19,BASES!$A$12:$A$392,BASES!$F$12:$F$392)
A20: =IF($H20="UNIDADE CONSTRUTIVA",OFFSET(A20,-1,0)+1,LARGE(A$3:A19,1)) | B20: =IF(H20="UNIDADE CONSTRUTIVA",0,IF(H20="CÉLULA CONSTRUTIVA",OFFSET(B20,-1,0)+1,OFFSET(B20,-1,0))) | C20: =IF(H20="CÉLULA CONSTRUTIVA",0,IF(H20="ETAPA",OFFSET(C20,-1,0)+1,OFFSET(C20,-1,0))) | D20: =IF(H20="ETAPA",0,IF(H20="SUBETAPA",OFFSET(D20,-1,0)+1,OFFSET(D20,-1,0))) | E20: =IF(H20="Subetapa",0,IF(H20="serviço",OFFSET(E20,-1,0)+1,OFFSET(E20,-1,0))) | H20: SERVIÇO | I20: =IF(H20="Unidade Construtiva",TEXT(A20,"00"),IF(H20="Célula Construtiva",TEXT(B20,"00"),IF(H20="Etapa",CONCATENATE(TEXT(B20,"00"),".",TEXT(C20,"000")),IF(H20="Subetapa",CONCATENATE(TEXT(B20,"00"),".",TEXT(C20,"000"),".",TEXT(D20,"000")),IF(H20="Serviço",CONCATENATE(TEXT(B20,"00"),".",TEXT(C20,"000"),".",TEXT(D20,"000"),".",TEXT(E20,"000")),""))))) | J20: Projeto elétrico/comunicação/telefonia/luminotécnico | K20: =_xlfn.XLOOKUP($J20,BASES!$A$12:$A$392,BASES!$C$12:$C$392) | L20: =_xlfn.XLOOKUP($J20,BASES!$A$12:$A$392,BASES!$D$12:$D$392) | M20: =_xlfn.XLOOKUP($J20,BASES!$A$1:$A$2289,BASES!$E$1:$E$2289) | N20: =IF(H20="Serviço",M20*L20,IF(H20="CÉLULA CONSTRUTIVA",SUMIFS($N$8:$N$442,$B$8:$B$442,B20,$H$8:$H$442,"Serviço"),IF(H20="ETAPA",SUMIFS($N$8:$N$442,$B$8:$B$442,B20,$C$8:$C$442,C20,$H$8:$H$442,"Serviço"),IF(H20="SUBETAPA",SUMIFS($N$8:$N$442,$B$8:$B$442,B20,$C$8:$C$442,C20,$D$8:$D$442,D20,$H$8:$H$442,"Serviço"),0)))) | O20: =_xlfn.XLOOKUP($J20,BASES!$A$12:$A$392,BASES!$F$12:$F$392)
A21: =IF($H21="UNIDADE CONSTRUTIVA",OFFSET(A21,-1,0)+1,LARGE(A$3:A20,1)) | B21: =IF(H21="UNIDADE CONSTRUTIVA",0,IF(H21="CÉLULA CONSTRUTIVA",OFFSET(B21,-1,0)+1,OFFSET(B21,-1,0))) | C21: =IF(H21="CÉLULA CONSTRUTIVA",0,IF(H21="ETAPA",OFFSET(C21,-1,0)+1,OFFSET(C21,-1,0))) | D21: =IF(H21="ETAPA",0,IF(H21="SUBETAPA",OFFSET(D21,-1,0)+1,OFFSET(D21,-1,0))) | E21: =IF(H21="Subetapa",0,IF(H21="serviço",OFFSET(E21,-1,0)+1,OFFSET(E21,-1,0))) | H21: SERVIÇO | I21: =IF(H21="Unidade Construtiva",TEXT(A21,"00"),IF(H21="Célula Construtiva",TEXT(B21,"00"),IF(H21="Etapa",CONCATENATE(TEXT(B21,"00"),".",TEXT(C21,"000")),IF(H21="Subetapa",CONCATENATE(TEXT(B21,"00"),".",TEXT(C21,"000"),".",TEXT(D21,"000")),IF(H21="Serviço",CONCATENATE(TEXT(B21,"00"),".",TEXT(C21,"000"),".",TEXT(D21,"000"),".",TEXT(E21,"000")),""))))) | J21: Projeto de Paisagismo | K21: =_xlfn.XLOOKUP($J21,BASES!$A$12:$A$392,BASES!$C$12:$C$392) | L21: =_xlfn.XLOOKUP($J21,BASES!$A$12:$A$392,BASES!$D$12:$D$392) | M21: =_xlfn.XLOOKUP($J21,BASES!$A$1:$A$2289,BASES!$E$1:$E$2289) | N21: =IF(H21="Serviço",M21*L21,IF(H21="CÉLULA CONSTRUTIVA",SUMIFS($N$8:$N$442,$B$8:$B$442,B21,$H$8:$H$442,"Serviço"),IF(H21="ETAPA",SUMIFS($N$8:$N$442,$B$8:$B$442,B21,$C$8:$C$442,C21,$H$8:$H$442,"Serviço"),IF(H21="SUBETAPA",SUMIFS($N$8:$N$442,$B$8:$B$442,B21,$C$8:$C$442,C21,$D$8:$D$442,D21,$H$8:$H$442,"Serviço"),0)))) | O21: =_xlfn.XLOOKUP($J21,BASES!$A$12:$A$392,BASES!$F$12:$F$392)
A22: =IF($H22="UNIDADE CONSTRUTIVA",OFFSET(A22,-1,0)+1,LARGE(A$3:A21,1)) | B22: =IF(H22="UNIDADE CONSTRUTIVA",0,IF(H22="CÉLULA CONSTRUTIVA",OFFSET(B22,-1,0)+1,OFFSET(B22,-1,0))) | C22: =IF(H22="CÉLULA CONSTRUTIVA",0,IF(H22="ETAPA",OFFSET(C22,-1,0)+1,OFFSET(C22,-1,0))) | D22: =IF(H22="ETAPA",0,IF(H22="SUBETAPA",OFFSET(D22,-1,0)+1,OFFSET(D22,-1,0))) | E22: =IF(H22="Subetapa",0,IF(H22="serviço",OFFSET(E22,-1,0)+1,OFFSET(E22,-1,0))) | H22: SUBETAPA | I22: =IF(H22="Unidade Construtiva",TEXT(A22,"00"),IF(H22="Célula Construtiva",TEXT(B22,"00"),IF(H22="Etapa",CONCATENATE(TEXT(B22,"00"),".",TEXT(C22,"000")),IF(H22="Subetapa",CONCATENATE(TEXT(B22,"00"),".",TEXT(C22,"000"),".",TEXT(D22,"000")),IF(H22="Serviço",CONCATENATE(TEXT(B22,"00"),".",TEXT(C22,"000"),".",TEXT(D22,"000"),".",TEXT(E22,"000")),""))))) | J22: Consultorias | N22: =IF(H22="Serviço",M22*L22,IF(H22="CÉLULA CONSTRUTIVA",SUMIFS($N$8:$N$442,$B$8:$B$442,B22,$H$8:$H$442,"Serviço"),IF(H22="ETAPA",SUMIFS($N$8:$N$442,$B$8:$B$442,B22,$C$8:$C$442,C22,$H$8:$H$442,"Serviço"),IF(H22="SUBETAPA",SUMIFS($N$8:$N$442,$B$8:$B$442,B22,$C$8:$C$442,C22,$D$8:$D$442,D22,$H$8:$H$442,"Serviço"),0))))
A23: =IF($H23="UNIDADE CONSTRUTIVA",OFFSET(A23,-1,0)+1,LARGE(A$3:A22,1)) | B23: =IF(H23="UNIDADE CONSTRUTIVA",0,IF(H23="CÉLULA CONSTRUTIVA",OFFSET(B23,-1,0)+1,OFFSET(B23,-1,0))) | C23: =IF(H23="CÉLULA CONSTRUTIVA",0,IF(H23="ETAPA",OFFSET(C23,-1,0)+1,OFFSET(C23,-1,0))) | D23: =IF(H23="ETAPA",0,IF(H23="SUBETAPA",OFFSET(D23,-1,0)+1,OFFSET(D23,-1,0))) | E23: =IF(H23="Subetapa",0,IF(H23="serviço",OFFSET(E23,-1,0)+1,OFFSET(E23,-1,0))) | H23: SERVIÇO | I23: =IF(H23="Unidade Construtiva",TEXT(A23,"00"),IF(H23="Célula Construtiva",TEXT(B23,"00"),IF(H23="Etapa",CONCATENATE(TEXT(B23,"00"),".",TEXT(C23,"000")),IF(H23="Subetapa",CONCATENATE(TEXT(B23,"00"),".",TEXT(C23,"000"),".",TEXT(D23,"000")),IF(H23="Serviço",CONCATENATE(TEXT(B23,"00"),".",TEXT(C23,"000"),".",TEXT(D23,"000"),".",TEXT(E23,"000")),""))))) | J23: Consultorias Técnicas de esquadrias | K23: =_xlfn.XLOOKUP($J23,BASES!$A$12:$A$392,BASES!$C$12:$C$392) | L23: =_xlfn.XLOOKUP($J23,BASES!$A$12:$A$392,BASES!$D$12:$D$392) | M23: =_xlfn.XLOOKUP($J23,BASES!$A$1:$A$2289,BASES!$E$1:$E$2289) | N23: =IF(H23="Serviço",M23*L23,IF(H23="CÉLULA CONSTRUTIVA",SUMIFS($N$8:$N$442,$B$8:$B$442,B23,$H$8:$H$442,"Serviço"),IF(H23="ETAPA",SUMIFS($N$8:$N$442,$B$8:$B$442,B23,$C$8:$C$442,C23,$H$8:$H$442,"Serviço"),IF(H23="SUBETAPA",SUMIFS($N$8:$N$442,$B$8:$B$442,B23,$C$8:$C$442,C23,$D$8:$D$442,D23,$H$8:$H$442,"Serviço"),0)))) | O23: =_xlfn.XLOOKUP($J23,BASES!$A$12:$A$392,BASES!$F$12:$F$392)
A24: =IF($H24="UNIDADE CONSTRUTIVA",OFFSET(A24,-1,0)+1,LARGE(A$3:A23,1)) | B24: =IF(H24="UNIDADE CONSTRUTIVA",0,IF(H24="CÉLULA CONSTRUTIVA",OFFSET(B24,-1,0)+1,OFFSET(B24,-1,0))) | C24: =IF(H24="CÉLULA CONSTRUTIVA",0,IF(H24="ETAPA",OFFSET(C24,-1,0)+1,OFFSET(C24,-1,0))) | D24: =IF(H24="ETAPA",0,IF(H24="SUBETAPA",OFFSET(D24,-1,0)+1,OFFSET(D24,-1,0))) | E24: =IF(H24="Subetapa",0,IF(H24="serviço",OFFSET(E24,-1,0)+1,OFFSET(E24,-1,0))) | H24: SERVIÇO | I24: =IF(H24="Unidade Construtiva",TEXT(A24,"00"),IF(H24="Célula Construtiva",TEXT(B24,"00"),IF(H24="Etapa",CONCATENATE(TEXT(B24,"00"),".",TEXT(C24,"000")),IF(H24="Subetapa",CONCATENATE(TEXT(B24,"00"),".",TEXT(C24,"000"),".",TEXT(D24,"000")),IF(H24="Serviço",CONCATENATE(TEXT(B24,"00"),".",TEXT(C24,"000"),".",TEXT(D24,"000"),".",TEXT(E24,"000")),""))))) | J24: Consultoria técnica de legalização | K24: =_xlfn.XLOOKUP($J24,BASES!$A$12:$A$392,BASES!$C$12:$C$392) | L24: =_xlfn.XLOOKUP($J24,BASES!$A$12:$A$392,BASES!$D$12:$D$392) | M24: =_xlfn.XLOOKUP($J24,BASES!$A$1:$A$2289,BASES!$E$1:$E$2289) | N24: =IF(H24="Serviço",M24*L24,IF(H24="CÉLULA CONSTRUTIVA",SUMIFS($N$8:$N$442,$B$8:$B$442,B24,$H$8:$H$442,"Serviço"),IF(H24="ETAPA",SUMIFS($N$8:$N$442,$B$8:$B$442,B24,$C$8:$C$442,C24,$H$8:$H$442,"Serviço"),IF(H24="SUBETAPA",SUMIFS($N$8:$N$442,$B$8:$B$442,B24,$C$8:$C$442,C24,$D$8:$D$442,D24,$H$8:$H$442,"Serviço"),0)))) | O24: =_xlfn.XLOOKUP($J24,BASES!$A$12:$A$392,BASES!$F$12:$F$392)
A25: =IF($H25="UNIDADE CONSTRUTIVA",OFFSET(A25,-1,0)+1,LARGE(A$3:A24,1)) | B25: =IF(H25="UNIDADE CONSTRUTIVA",0,IF(H25="CÉLULA CONSTRUTIVA",OFFSET(B25,-1,0)+1,OFFSET(B25,-1,0))) | C25: =IF(H25="CÉLULA CONSTRUTIVA",0,IF(H25="ETAPA",OFFSET(C25,-1,0)+1,OFFSET(C25,-1,0))) | D25: =IF(H25="ETAPA",0,IF(H25="SUBETAPA",OFFSET(D25,-1,0)+1,OFFSET(D25,-1,0))) | E25: =IF(H25="Subetapa",0,IF(H25="serviço",OFFSET(E25,-1,0)+1,OFFSET(E25,-1,0))) | H25: SERVIÇO | I25: =IF(H25="Unidade Construtiva",TEXT(A25,"00"),IF(H25="Célula Construtiva",TEXT(B25,"00"),IF(H25="Etapa",CONCATENATE(TEXT(B25,"00"),".",TEXT(C25,"000")),IF(H25="Subetapa",CONCATENATE(TEXT(B25,"00"),".",TEXT(C25,"000"),".",TEXT(D25,"000")),IF(H25="Serviço",CONCATENATE(TEXT(B25,"00"),".",TEXT(C25,"000"),".",TEXT(D25,"000"),".",TEXT(E25,"000")),""))))) | J25: Orçamento e planejamento | K25: =_xlfn.XLOOKUP($J25,BASES!$A$12:$A$392,BASES!$C$12:$C$392) | L25: =_xlfn.XLOOKUP($J25,BASES!$A$12:$A$392,BASES!$D$12:$D$392) | M25: =_xlfn.XLOOKUP($J25,BASES!$A$1:$A$2289,BASES!$E$1:$E$2289) | N25: =IF(H25="Serviço",M25*L25,IF(H25="CÉLULA CONSTRUTIVA",SUMIFS($N$8:$N$442,$B$8:$B$442,B25,$H$8:$H$442,"Serviço"),IF(H25="ETAPA",SUMIFS($N$8:$N$442,$B$8:$B$442,B25,$C$8:$C$442,C25,$H$8:$H$442,"Serviço"),IF(H25="SUBETAPA",SUMIFS($N$8:$N$442,$B$8:$B$442,B25,$C$8:$C$442,C25,$D$8:$D$442,D25,$H$8:$H$442,"Serviço"),0)))) | O25: =_xlfn.XLOOKUP($J25,BASES!$A$12:$A$392,BASES!$F$12:$F$392)
A26: =IF($H26="UNIDADE CONSTRUTIVA",OFFSET(A26,-1,0)+1,LARGE(A$3:A25,1)) | B26: =IF(H26="UNIDADE CONSTRUTIVA",0,IF(H26="CÉLULA CONSTRUTIVA",OFFSET(B26,-1,0)+1,OFFSET(B26,-1,0))) | C26: =IF(H26="CÉLULA CONSTRUTIVA",0,IF(H26="ETAPA",OFFSET(C26,-1,0)+1,OFFSET(C26,-1,0))) | D26: =IF(H26="ETAPA",0,IF(H26="SUBETAPA",OFFSET(D26,-1,0)+1,OFFSET(D26,-1,0))) | E26: =IF(H26="Subetapa",0,IF(H26="serviço",OFFSET(E26,-1,0)+1,OFFSET(E26,-1,0))) | H26: SERVIÇO | I26: =IF(H26="Unidade Construtiva",TEXT(A26,"00"),IF(H26="Célula Construtiva",TEXT(B26,"00"),IF(H26="Etapa",CONCATENATE(TEXT(B26,"00"),".",TEXT(C26,"000")),IF(H26="Subetapa",CONCATENATE(TEXT(B26,"00"),".",TEXT(C26,"000"),".",TEXT(D26,"000")),IF(H26="Serviço",CONCATENATE(TEXT(B26,"00"),".",TEXT(C26,"000"),".",TEXT(D26,"000"),".",TEXT(E26,"000")),""))))) | J26: Consultoria em Licenciamento Ambiental | K26: =_xlfn.XLOOKUP($J26,BASES!$A$12:$A$392,BASES!$C$12:$C$392) | L26: =_xlfn.XLOOKUP($J26,BASES!$A$12:$A$392,BASES!$D$12:$D$392) | M26: =_xlfn.XLOOKUP($J26,BASES!$A$1:$A$2289,BASES!$E$1:$E$2289) | N26: =IF(H26="Serviço",M26*L26,IF(H26="CÉLULA CONSTRUTIVA",SUMIFS($N$8:$N$442,$B$8:$B$442,B26,$H$8:$H$442,"Serviço"),IF(H26="ETAPA",SUMIFS($N$8:$N$442,$B$8:$B$442,B26,$C$8:$C$442,C26,$H$8:$H$442,"Serviço"),IF(H26="SUBETAPA",SUMIFS($N$8:$N$442,$B$8:$B$442,B26,$C$8:$C$442,C26,$D$8:$D$442,D26,$H$8:$H$442,"Serviço"),0)))) | O26: =_xlfn.XLOOKUP($J26,BASES!$A$12:$A$392,BASES!$F$12:$F$392)
A27: =IF($H27="UNIDADE CONSTRUTIVA",OFFSET(A27,-1,0)+1,LARGE(A$3:A26,1)) | B27: =IF(H27="UNIDADE CONSTRUTIVA",0,IF(H27="CÉLULA CONSTRUTIVA",OFFSET(B27,-1,0)+1,OFFSET(B27,-1,0))) | C27: =IF(H27="CÉLULA CONSTRUTIVA",0,IF(H27="ETAPA",OFFSET(C27,-1,0)+1,OFFSET(C27,-1,0))) | D27: =IF(H27="ETAPA",0,IF(H27="SUBETAPA",OFFSET(D27,-1,0)+1,OFFSET(D27,-1,0))) | E27: =IF(H27="Subetapa",0,IF(H27="serviço",OFFSET(E27,-1,0)+1,OFFSET(E27,-1,0))) | H27: SUBETAPA | I27: =IF(H27="Unidade Construtiva",TEXT(A27,"00"),IF(H27="Célula Construtiva",TEXT(B27,"00"),IF(H27="Etapa",CONCATENATE(TEXT(B27,"00"),".",TEXT(C27,"000")),IF(H27="Subetapa",CONCATENATE(TEXT(B27,"00"),".",TEXT(C27,"000"),".",TEXT(D27,"000")),IF(H27="Serviço",CONCATENATE(TEXT(B27,"00"),".",TEXT(C27,"000"),".",TEXT(D27,"000"),".",TEXT(E27,"000")),""))))) | J27: Ensaios | N27: =IF(H27="Serviço",M27*L27,IF(H27="CÉLULA CONSTRUTIVA",SUMIFS($N$8:$N$442,$B$8:$B$442,B27,$H$8:$H$442,"Serviço"),IF(H27="ETAPA",SUMIFS($N$8:$N$442,$B$8:$B$442,B27,$C$8:$C$442,C27,$H$8:$H$442,"Serviço"),IF(H27="SUBETAPA",SUMIFS($N$8:$N$442,$B$8:$B$442,B27,$C$8:$C$442,C27,$D$8:$D$442,D27,$H$8:$H$442,"Serviço"),0))))
A28: =IF($H28="UNIDADE CONSTRUTIVA",OFFSET(A28,-1,0)+1,LARGE(A$3:A27,1)) | B28: =IF(H28="UNIDADE CONSTRUTIVA",0,IF(H28="CÉLULA CONSTRUTIVA",OFFSET(B28,-1,0)+1,OFFSET(B28,-1,0))) | C28: =IF(H28="CÉLULA CONSTRUTIVA",0,IF(H28="ETAPA",OFFSET(C28,-1,0)+1,OFFSET(C28,-1,0))) | D28: =IF(H28="ETAPA",0,IF(H28="SUBETAPA",OFFSET(D28,-1,0)+1,OFFSET(D28,-1,0))) | E28: =IF(H28="Subetapa",0,IF(H28="serviço",OFFSET(E28,-1,0)+1,OFFSET(E28,-1,0))) | H28: SERVIÇO | I28: =IF(H28="Unidade Construtiva",TEXT(A28,"00"),IF(H28="Célula Construtiva",TEXT(B28,"00"),IF(H28="Etapa",CONCATENATE(TEXT(B28,"00"),".",TEXT(C28,"000")),IF(H28="Subetapa",CONCATENATE(TEXT(B28,"00"),".",TEXT(C28,"000"),".",TEXT(D28,"000")),IF(H28="Serviço",CONCATENATE(TEXT(B28,"00"),".",TEXT(C28,"000"),".",TEXT(D28,"000"),".",TEXT(E28,"000")),""))))) | J28: Controle tecnológico do concreto | K28: =_xlfn.XLOOKUP($J28,BASES!$A$12:$A$392,BASES!$C$12:$C$392) | L28: =_xlfn.XLOOKUP($J28,BASES!$A$12:$A$392,BASES!$D$12:$D$392) | M28: ='Cont.Tecnol.'!F6+'Cont.Tecnol.'!F11+'Cont.Tecnol.'!F16+'Cont.Tecnol.'!F21+'Cont.Tecnol.'!F26 | N28: =IF(H28="Serviço",M28*L28,IF(H28="CÉLULA CONSTRUTIVA",SUMIFS($N$8:$N$442,$B$8:$B$442,B28,$H$8:$H$442,"Serviço"),IF(H28="ETAPA",SUMIFS($N$8:$N$442,$B$8:$B$442,B28,$C$8:$C$442,C28,$H$8:$H$442,"Serviço"),IF(H28="SUBETAPA",SUMIFS($N$8:$N$442,$B$8:$B$442,B28,$C$8:$C$442,C28,$D$8:$D$442,D28,$H$8:$H$442,"Serviço"),0)))) | O28: Estimado conrfome aba "Cont. Tecnol."
A29: =IF($H29="UNIDADE CONSTRUTIVA",OFFSET(A29,-1,0)+1,LARGE(A$3:A28,1)) | B29: =IF(H29="UNIDADE CONSTRUTIVA",0,IF(H29="CÉLULA CONSTRUTIVA",OFFSET(B29,-1,0)+1,OFFSET(B29,-1,0))) | C29: =IF(H29="CÉLULA CONSTRUTIVA",0,IF(H29="ETAPA",OFFSET(C29,-1,0)+1,OFFSET(C29,-1,0))) | D29: =IF(H29="ETAPA",0,IF(H29="SUBETAPA",OFFSET(D29,-1,0)+1,OFFSET(D29,-1,0))) | E29: =IF(H29="Subetapa",0,IF(H29="serviço",OFFSET(E29,-1,0)+1,OFFSET(E29,-1,0))) | H29: SERVIÇO | I29: =IF(H29="Unidade Construtiva",TEXT(A29,"00"),IF(H29="Célula Construtiva",TEXT(B29,"00"),IF(H29="Etapa",CONCATENATE(TEXT(B29,"00"),".",TEXT(C29,"000")),IF(H29="Subetapa",CONCATENATE(TEXT(B29,"00"),".",TEXT(C29,"000"),".",TEXT(D29,"000")),IF(H29="Serviço",CONCATENATE(TEXT(B29,"00"),".",TEXT(C29,"000"),".",TEXT(D29,"000"),".",TEXT(E29,"000")),""))))) | J29: Prova de carga | K29: =_xlfn.XLOOKUP($J29,BASES!$A$12:$A$392,BASES!$C$12:$C$392) | L29: =_xlfn.XLOOKUP($J29,BASES!$A$12:$A$392,BASES!$D$12:$D$392) | M29: =_xlfn.XLOOKUP($J29,BASES!$A$1:$A$2289,BASES!$E$1:$E$2289) | N29: =IF(H29="Serviço",M29*L29,IF(H29="CÉLULA CONSTRUTIVA",SUMIFS($N$8:$N$442,$B$8:$B$442,B29,$H$8:$H$442,"Serviço"),IF(H29="ETAPA",SUMIFS($N$8:$N$442,$B$8:$B$442,B29,$C$8:$C$442,C29,$H$8:$H$442,"Serviço"),IF(H29="SUBETAPA",SUMIFS($N$8:$N$442,$B$8:$B$442,B29,$C$8:$C$442,C29,$D$8:$D$442,D29,$H$8:$H$442,"Serviço"),0)))) | O29: =_xlfn.XLOOKUP($J29,BASES!$A$12:$A$392,BASES!$F$12:$F$392)
A30: =IF($H30="UNIDADE CONSTRUTIVA",OFFSET(A30,-1,0)+1,LARGE(A$3:A29,1)) | B30: =IF(H30="UNIDADE CONSTRUTIVA",0,IF(H30="CÉLULA CONSTRUTIVA",OFFSET(B30,-1,0)+1,OFFSET(B30,-1,0))) | C30: =IF(H30="CÉLULA CONSTRUTIVA",0,IF(H30="ETAPA",OFFSET(C30,-1,0)+1,OFFSET(C30,-1,0))) | D30: =IF(H30="ETAPA",0,IF(H30="SUBETAPA",OFFSET(D30,-1,0)+1,OFFSET(D30,-1,0))) | E30: =IF(H30="Subetapa",0,IF(H30="serviço",OFFSET(E30,-1,0)+1,OFFSET(E30,-1,0))) | H30: SERVIÇO | I30: =IF(H30="Unidade Construtiva",TEXT(A30,"00"),IF(H30="Célula Construtiva",TEXT(B30,"00"),IF(H30="Etapa",CONCATENATE(TEXT(B30,"00"),".",TEXT(C30,"000")),IF(H30="Subetapa",CONCATENATE(TEXT(B30,"00"),".",TEXT(C30,"000"),".",TEXT(D30,"000")),IF(H30="Serviço",CONCATENATE(TEXT(B30,"00"),".",TEXT(C30,"000"),".",TEXT(D30,"000"),".",TEXT(E30,"000")),""))))) | J30: Ensaio de arrancamento de reboco | K30: =_xlfn.XLOOKUP($J30,BASES!$A$12:$A$392,BASES!$C$12:$C$392) | L30: =_xlfn.XLOOKUP($J30,BASES!$A$12:$A$392,BASES!$D$12:$D$392) | M30: =_xlfn.XLOOKUP($J30,BASES!$A$1:$A$2289,BASES!$E$1:$E$2289) | N30: =IF(H30="Serviço",M30*L30,IF(H30="CÉLULA CONSTRUTIVA",SUMIFS($N$8:$N$442,$B$8:$B$442,B30,$H$8:$H$442,"Serviço"),IF(H30="ETAPA",SUMIFS($N$8:$N$442,$B$8:$B$442,B30,$C$8:$C$442,C30,$H$8:$H$442,"Serviço"),IF(H30="SUBETAPA",SUMIFS($N$8:$N$442,$B$8:$B$442,B30,$C$8:$C$442,C30,$D$8:$D$442,D30,$H$8:$H$442,"Serviço"),0)))) | O30: =_xlfn.XLOOKUP($J30,BASES!$A$12:$A$392,BASES!$F$12:$F$392)
A31: =IF($H31="UNIDADE CONSTRUTIVA",OFFSET(A31,-1,0)+1,LARGE(A$3:A30,1)) | B31: =IF(H31="UNIDADE CONSTRUTIVA",0,IF(H31="CÉLULA CONSTRUTIVA",OFFSET(B31,-1,0)+1,OFFSET(B31,-1,0))) | C31: =IF(H31="CÉLULA CONSTRUTIVA",0,IF(H31="ETAPA",OFFSET(C31,-1,0)+1,OFFSET(C31,-1,0))) | D31: =IF(H31="ETAPA",0,IF(H31="SUBETAPA",OFFSET(D31,-1,0)+1,OFFSET(D31,-1,0))) | E31: =IF(H31="Subetapa",0,IF(H31="serviço",OFFSET(E31,-1,0)+1,OFFSET(E31,-1,0))) | H31: SERVIÇO | I31: =IF(H31="Unidade Construtiva",TEXT(A31,"00"),IF(H31="Célula Construtiva",TEXT(B31,"00"),IF(H31="Etapa",CONCATENATE(TEXT(B31,"00"),".",TEXT(C31,"000")),IF(H31="Subetapa",CONCATENATE(TEXT(B31,"00"),".",TEXT(C31,"000"),".",TEXT(D31,"000")),IF(H31="Serviço",CONCATENATE(TEXT(B31,"00"),".",TEXT(C31,"000"),".",TEXT(D31,"000"),".",TEXT(E31,"000")),""))))) | J31: Laudo de Vizinhança | K31: =_xlfn.XLOOKUP($J31,BASES!$A$12:$A$392,BASES!$C$12:$C$392) | L31: =_xlfn.XLOOKUP($J31,BASES!$A$12:$A$392,BASES!$D$12:$D$392) | M31: =_xlfn.XLOOKUP($J31,BASES!$A$1:$A$2289,BASES!$E$1:$E$2289) | N31: =IF(H31="Serviço",M31*L31,IF(H31="CÉLULA CONSTRUTIVA",SUMIFS($N$8:$N$442,$B$8:$B$442,B31,$H$8:$H$442,"Serviço"),IF(H31="ETAPA",SUMIFS($N$8:$N$442,$B$8:$B$442,B31,$C$8:$C$442,C31,$H$8:$H$442,"Serviço"),IF(H31="SUBETAPA",SUMIFS($N$8:$N$442,$B$8:$B$442,B31,$C$8:$C$442,C31,$D$8:$D$442,D31,$H$8:$H$442,"Serviço"),0)))) | O31: =_xlfn.XLOOKUP($J31,BASES!$A$12:$A$392,BASES!$F$12:$F$392)
A32: =IF($H32="UNIDADE CONSTRUTIVA",OFFSET(A32,-1,0)+1,LARGE(A$3:A31,1)) | B32: =IF(H32="UNIDADE CONSTRUTIVA",0,IF(H32="CÉLULA CONSTRUTIVA",OFFSET(B32,-1,0)+1,OFFSET(B32,-1,0))) | C32: =IF(H32="CÉLULA CONSTRUTIVA",0,IF(H32="ETAPA",OFFSET(C32,-1,0)+1,OFFSET(C32,-1,0))) | D32: =IF(H32="ETAPA",0,IF(H32="SUBETAPA",OFFSET(D32,-1,0)+1,OFFSET(D32,-1,0))) | E32: =IF(H32="Subetapa",0,IF(H32="serviço",OFFSET(E32,-1,0)+1,OFFSET(E32,-1,0))) | H32: ETAPA | I32: =IF(H32="Unidade Construtiva",TEXT(A32,"00"),IF(H32="Célula Construtiva",TEXT(B32,"00"),IF(H32="Etapa",CONCATENATE(TEXT(B32,"00"),".",TEXT(C32,"000")),IF(H32="Subetapa",CONCATENATE(TEXT(B32,"00"),".",TEXT(C32,"000"),".",TEXT(D32,"000")),IF(H32="Serviço",CONCATENATE(TEXT(B32,"00"),".",TEXT(C32,"000"),".",TEXT(D32,"000"),".",TEXT(E32,"000")),""))))) | J32: CONSUMOS, TAXAS E DOCUMENTOS | N32: =IF(H32="Serviço",M32*L32,IF(H32="CÉLULA CONSTRUTIVA",SUMIFS($N$8:$N$442,$B$8:$B$442,B32,$H$8:$H$442,"Serviço"),IF(H32="ETAPA",SUMIFS($N$8:$N$442,$B$8:$B$442,B32,$C$8:$C$442,C32,$H$8:$H$442,"Serviço"),IF(H32="SUBETAPA",SUMIFS($N$8:$N$442,$B$8:$B$442,B32,$C$8:$C$442,C32,$D$8:$D$442,D32,$H$8:$H$442,"Serviço"),0))))
A33: =IF($H33="UNIDADE CONSTRUTIVA",OFFSET(A33,-1,0)+1,LARGE(A$3:A32,1)) | B33: =IF(H33="UNIDADE CONSTRUTIVA",0,IF(H33="CÉLULA CONSTRUTIVA",OFFSET(B33,-1,0)+1,OFFSET(B33,-1,0))) | C33: =IF(H33="CÉLULA CONSTRUTIVA",0,IF(H33="ETAPA",OFFSET(C33,-1,0)+1,OFFSET(C33,-1,0))) | D33: =IF(H33="ETAPA",0,IF(H33="SUBETAPA",OFFSET(D33,-1,0)+1,OFFSET(D33,-1,0))) | E33: =IF(H33="Subetapa",0,IF(H33="serviço",OFFSET(E33,-1,0)+1,OFFSET(E33,-1,0))) | H33: SUBETAPA | I33: =IF(H33="Unidade Construtiva",TEXT(A33,"00"),IF(H33="Célula Construtiva",TEXT(B33,"00"),IF(H33="Etapa",CONCATENATE(TEXT(B33,"00"),".",TEXT(C33,"000")),IF(H33="Subetapa",CONCATENATE(TEXT(B33,"00"),".",TEXT(C33,"000"),".",TEXT(D33,"000")),IF(H33="Serviço",CONCATENATE(TEXT(B33,"00"),".",TEXT(C33,"000"),".",TEXT(D33,"000"),".",TEXT(E33,"000")),""))))) | J33: Licenciamentos, Taxas, Impostos, Aprovações e Seguros | N33: =IF(H33="Serviço",M33*L33,IF(H33="CÉLULA CONSTRUTIVA",SUMIFS($N$8:$N$467,$B$8:$B$467,B33,$H$8:$H$467,"Serviço"),IF(H33="ETAPA",SUMIFS($N$8:$N$467,$B$8:$B$467,B33,$C$8:$C$467,C33,$H$8:$H$467,"Serviço"),IF(H33="SUBETAPA",SUMIFS($N$8:$N$467,$B$8:$B$467,B33,$C$8:$C$467,C33,$D$8:$D$467,D33,$H$8:$H$467,"Serviço"),0))))
A34: =IF($H34="UNIDADE CONSTRUTIVA",OFFSET(A34,-1,0)+1,LARGE(A$3:A33,1)) | B34: =IF(H34="UNIDADE CONSTRUTIVA",0,IF(H34="CÉLULA CONSTRUTIVA",OFFSET(B34,-1,0)+1,OFFSET(B34,-1,0))) | C34: =IF(H34="CÉLULA CONSTRUTIVA",0,IF(H34="ETAPA",OFFSET(C34,-1,0)+1,OFFSET(C34,-1,0))) | D34: =IF(H34="ETAPA",0,IF(H34="SUBETAPA",OFFSET(D34,-1,0)+1,OFFSET(D34,-1,0))) | E34: =IF(H34="Subetapa",0,IF(H34="serviço",OFFSET(E34,-1,0)+1,OFFSET(E34,-1,0))) | H34: SERVIÇO | I34: =IF(H34="Unidade Construtiva",TEXT(A34,"00"),IF(H34="Célula Construtiva",TEXT(B34,"00"),IF(H34="Etapa",CONCATENATE(TEXT(B34,"00"),".",TEXT(C34,"000")),IF(H34="Subetapa",CONCATENATE(TEXT(B34,"00"),".",TEXT(C34,"000"),".",TEXT(D34,"000")),IF(H34="Serviço",CONCATENATE(TEXT(B34,"00"),".",TEXT(C34,"000"),".",TEXT(D34,"000"),".",TEXT(E34,"000")),""))))) | J34: Despesas de Seguros | K34: =_xlfn.XLOOKUP($J34,BASES!$A$12:$A$392,BASES!$C$12:$C$392) | L34: =_xlfn.XLOOKUP($J34,BASES!$A$12:$A$392,BASES!$D$12:$D$392) | M34: =_xlfn.XLOOKUP($J34,BASES!$A$1:$A$2289,BASES!$E$1:$E$2289) | N34: =IF(H34="Serviço",M34*L34,IF(H34="CÉLULA CONSTRUTIVA",SUMIFS($N$8:$N$467,$B$8:$B$467,B34,$H$8:$H$467,"Serviço"),IF(H34="ETAPA",SUMIFS($N$8:$N$467,$B$8:$B$467,B34,$C$8:$C$467,C34,$H$8:$H$467,"Serviço"),IF(H34="SUBETAPA",SUMIFS($N$8:$N$467,$B$8:$B$467,B34,$C$8:$C$467,C34,$D$8:$D$467,D34,$H$8:$H$467,"Serviço"),0)))) | O34: =_xlfn.XLOOKUP($J34,BASES!$A$12:$A$392,BASES!$F$12:$F$392)
A35: =IF($H35="UNIDADE CONSTRUTIVA",OFFSET(A35,-1,0)+1,LARGE(A$3:A34,1)) | B35: =IF(H35="UNIDADE CONSTRUTIVA",0,IF(H35="CÉLULA CONSTRUTIVA",OFFSET(B35,-1,0)+1,OFFSET(B35,-1,0))) | C35: =IF(H35="CÉLULA CONSTRUTIVA",0,IF(H35="ETAPA",OFFSET(C35,-1,0)+1,OFFSET(C35,-1,0))) | D35: =IF(H35="ETAPA",0,IF(H35="SUBETAPA",OFFSET(D35,-1,0)+1,OFFSET(D35,-1,0))) | E35: =IF(H35="Subetapa",0,IF(H35="serviço",OFFSET(E35,-1,0)+1,OFFSET(E35,-1,0))) | H35: SERVIÇO | I35: =IF(H35="Unidade Construtiva",TEXT(A35,"00"),IF(H35="Célula Construtiva",TEXT(B35,"00"),IF(H35="Etapa",CONCATENATE(TEXT(B35,"00"),".",TEXT(C35,"000")),IF(H35="Subetapa",CONCATENATE(TEXT(B35,"00"),".",TEXT(C35,"000"),".",TEXT(D35,"000")),IF(H35="Serviço",CONCATENATE(TEXT(B35,"00"),".",TEXT(C35,"000"),".",TEXT(D35,"000"),".",TEXT(E35,"000")),""))))) | J35: Taxas de consulta de viabilidade | K35: =_xlfn.XLOOKUP($J35,BASES!$A$12:$A$392,BASES!$C$12:$C$392) | L35: =_xlfn.XLOOKUP($J35,BASES!$A$12:$A$392,BASES!$D$12:$D$392) | M35: =_xlfn.XLOOKUP($J35,BASES!$A$1:$A$2289,BASES!$E$1:$E$2289) | N35: =IF(H35="Serviço",M35*L35,IF(H35="CÉLULA CONSTRUTIVA",SUMIFS($N$8:$N$467,$B$8:$B$467,B35,$H$8:$H$467,"Serviço"),IF(H35="ETAPA",SUMIFS($N$8:$N$467,$B$8:$B$467,B35,$C$8:$C$467,C35,$H$8:$H$467,"Serviço"),IF(H35="SUBETAPA",SUMIFS($N$8:$N$467,$B$8:$B$467,B35,$C$8:$C$467,C35,$D$8:$D$467,D35,$H$8:$H$467,"Serviço"),0)))) | O35: =_xlfn.XLOOKUP($J35,BASES!$A$12:$A$392,BASES!$F$12:$F$392)
A36: =IF($H36="UNIDADE CONSTRUTIVA",OFFSET(A36,-1,0)+1,LARGE(A$3:A35,1)) | B36: =IF(H36="UNIDADE CONSTRUTIVA",0,IF(H36="CÉLULA CONSTRUTIVA",OFFSET(B36,-1,0)+1,OFFSET(B36,-1,0))) | C36: =IF(H36="CÉLULA CONSTRUTIVA",0,IF(H36="ETAPA",OFFSET(C36,-1,0)+1,OFFSET(C36,-1,0))) | D36: =IF(H36="ETAPA",0,IF(H36="SUBETAPA",OFFSET(D36,-1,0)+1,OFFSET(D36,-1,0))) | E36: =IF(H36="Subetapa",0,IF(H36="serviço",OFFSET(E36,-1,0)+1,OFFSET(E36,-1,0))) | H36: SERVIÇO | I36: =IF(H36="Unidade Construtiva",TEXT(A36,"00"),IF(H36="Célula Construtiva",TEXT(B36,"00"),IF(H36="Etapa",CONCATENATE(TEXT(B36,"00"),".",TEXT(C36,"000")),IF(H36="Subetapa",CONCATENATE(TEXT(B36,"00"),".",TEXT(C36,"000"),".",TEXT(D36,"000")),IF(H36="Serviço",CONCATENATE(TEXT(B36,"00"),".",TEXT(C36,"000"),".",TEXT(D36,"000"),".",TEXT(E36,"000")),""))))) | J36: Avaliação e Legalização ambiental | K36: =_xlfn.XLOOKUP($J36,BASES!$A$12:$A$392,BASES!$C$12:$C$392) | L36: =_xlfn.XLOOKUP($J36,BASES!$A$12:$A$392,BASES!$D$12:$D$392) | M36: =_xlfn.XLOOKUP($J36,BASES!$A$1:$A$2289,BASES!$E$1:$E$2289) | N36: =IF(H36="Serviço",M36*L36,IF(H36="CÉLULA CONSTRUTIVA",SUMIFS($N$8:$N$467,$B$8:$B$467,B36,$H$8:$H$467,"Serviço"),IF(H36="ETAPA",SUMIFS($N$8:$N$467,$B$8:$B$467,B36,$C$8:$C$467,C36,$H$8:$H$467,"Serviço"),IF(H36="SUBETAPA",SUMIFS($N$8:$N$467,$B$8:$B$467,B36,$C$8:$C$467,C36,$D$8:$D$467,D36,$H$8:$H$467,"Serviço"),0)))) | O36: =_xlfn.XLOOKUP($J36,BASES!$A$12:$A$392,BASES!$F$12:$F$392)
A37: =IF($H37="UNIDADE CONSTRUTIVA",OFFSET(A37,-1,0)+1,LARGE(A$3:A36,1)) | B37: =IF(H37="UNIDADE CONSTRUTIVA",0,IF(H37="CÉLULA CONSTRUTIVA",OFFSET(B37,-1,0)+1,OFFSET(B37,-1,0))) | C37: =IF(H37="CÉLULA CONSTRUTIVA",0,IF(H37="ETAPA",OFFSET(C37,-1,0)+1,OFFSET(C37,-1,0))) | D37: =IF(H37="ETAPA",0,IF(H37="SUBETAPA",OFFSET(D37,-1,0)+1,OFFSET(D37,-1,0))) | E37: =IF(H37="Subetapa",0,IF(H37="serviço",OFFSET(E37,-1,0)+1,OFFSET(E37,-1,0))) | H37: SERVIÇO | I37: =IF(H37="Unidade Construtiva",TEXT(A37,"00"),IF(H37="Célula Construtiva",TEXT(B37,"00"),IF(H37="Etapa",CONCATENATE(TEXT(B37,"00"),".",TEXT(C37,"000")),IF(H37="Subetapa",CONCATENATE(TEXT(B37,"00"),".",TEXT(C37,"000"),".",TEXT(D37,"000")),IF(H37="Serviço",CONCATENATE(TEXT(B37,"00"),".",TEXT(C37,"000"),".",TEXT(D37,"000"),".",TEXT(E37,"000")),""))))) | J37: Aprovação e legalização prefeitura | K37: =_xlfn.XLOOKUP($J37,BASES!$A$12:$A$392,BASES!$C$12:$C$392) | L37: =_xlfn.XLOOKUP($J37,BASES!$A$12:$A$392,BASES!$D$12:$D$392) | M37: =_xlfn.XLOOKUP($J37,BASES!$A$1:$A$2289,BASES!$E$1:$E$2289) | N37: =IF(H37="Serviço",M37*L37,IF(H37="CÉLULA CONSTRUTIVA",SUMIFS($N$8:$N$467,$B$8:$B$467,B37,$H$8:$H$467,"Serviço"),IF(H37="ETAPA",SUMIFS($N$8:$N$467,$B$8:$B$467,B37,$C$8:$C$467,C37,$H$8:$H$467,"Serviço"),IF(H37="SUBETAPA",SUMIFS($N$8:$N$467,$B$8:$B$467,B37,$C$8:$C$467,C37,$D$8:$D$467,D37,$H$8:$H$467,"Serviço"),0)))) | O37: =_xlfn.XLOOKUP($J37,BASES!$A$12:$A$392,BASES!$F$12:$F$392)
A38: =IF($H38="UNIDADE CONSTRUTIVA",OFFSET(A38,-1,0)+1,LARGE(A$3:A37,1)) | B38: =IF(H38="UNIDADE CONSTRUTIVA",0,IF(H38="CÉLULA CONSTRUTIVA",OFFSET(B38,-1,0)+1,OFFSET(B38,-1,0))) | C38: =IF(H38="CÉLULA CONSTRUTIVA",0,IF(H38="ETAPA",OFFSET(C38,-1,0)+1,OFFSET(C38,-1,0))) | D38: =IF(H38="ETAPA",0,IF(H38="SUBETAPA",OFFSET(D38,-1,0)+1,OFFSET(D38,-1,0))) | E38: =IF(H38="Subetapa",0,IF(H38="serviço",OFFSET(E38,-1,0)+1,OFFSET(E38,-1,0))) | H38: SERVIÇO | I38: =IF(H38="Unidade Construtiva",TEXT(A38,"00"),IF(H38="Célula Construtiva",TEXT(B38,"00"),IF(H38="Etapa",CONCATENATE(TEXT(B38,"00"),".",TEXT(C38,"000")),IF(H38="Subetapa",CONCATENATE(TEXT(B38,"00"),".",TEXT(C38,"000"),".",TEXT(D38,"000")),IF(H38="Serviço",CONCATENATE(TEXT(B38,"00"),".",TEXT(C38,"000"),".",TEXT(D38,"000"),".",TEXT(E38,"000")),""))))) | J38: Aprovação e legalização água e esgoto | K38: =_xlfn.XLOOKUP($J38,BASES!$A$12:$A$392,BASES!$C$12:$C$392) | L38: =_xlfn.XLOOKUP($J38,BASES!$A$12:$A$392,BASES!$D$12:$D$392) | M38: =_xlfn.XLOOKUP($J38,BASES!$A$1:$A$2289,BASES!$E$1:$E$2289) | N38: =IF(H38="Serviço",M38*L38,IF(H38="CÉLULA CONSTRUTIVA",SUMIFS($N$8:$N$467,$B$8:$B$467,B38,$H$8:$H$467,"Serviço"),IF(H38="ETAPA",SUMIFS($N$8:$N$467,$B$8:$B$467,B38,$C$8:$C$467,C38,$H$8:$H$467,"Serviço"),IF(H38="SUBETAPA",SUMIFS($N$8:$N$467,$B$8:$B$467,B38,$C$8:$C$467,C38,$D$8:$D$467,D38,$H$8:$H$467,"Serviço"),0)))) | O38: =_xlfn.XLOOKUP($J38,BASES!$A$12:$A$392,BASES!$F$12:$F$392)
A39: =IF($H39="UNIDADE CONSTRUTIVA",OFFSET(A39,-1,0)+1,LARGE(A$3:A38,1)) | B39: =IF(H39="UNIDADE CONSTRUTIVA",0,IF(H39="CÉLULA CONSTRUTIVA",OFFSET(B39,-1,0)+1,OFFSET(B39,-1,0))) | C39: =IF(H39="CÉLULA CONSTRUTIVA",0,IF(H39="ETAPA",OFFSET(C39,-1,0)+1,OFFSET(C39,-1,0))) | D39: =IF(H39="ETAPA",0,IF(H39="SUBETAPA",OFFSET(D39,-1,0)+1,OFFSET(D39,-1,0))) | E39: =IF(H39="Subetapa",0,IF(H39="serviço",OFFSET(E39,-1,0)+1,OFFSET(E39,-1,0))) | H39: SERVIÇO | I39: =IF(H39="Unidade Construtiva",TEXT(A39,"00"),IF(H39="Célula Construtiva",TEXT(B39,"00"),IF(H39="Etapa",CONCATENATE(TEXT(B39,"00"),".",TEXT(C39,"000")),IF(H39="Subetapa",CONCATENATE(TEXT(B39,"00"),".",TEXT(C39,"000"),".",TEXT(D39,"000")),IF(H39="Serviço",CONCATENATE(TEXT(B39,"00"),".",TEXT(C39,"000"),".",TEXT(D39,"000"),".",TEXT(E39,"000")),""))))) | J39: Aprovação e legalização elétrico | K39: =_xlfn.XLOOKUP($J39,BASES!$A$12:$A$392,BASES!$C$12:$C$392) | L39: =_xlfn.XLOOKUP($J39,BASES!$A$12:$A$392,BASES!$D$12:$D$392) | M39: =_xlfn.XLOOKUP($J39,BASES!$A$1:$A$2289,BASES!$E$1:$E$2289) | N39: =IF(H39="Serviço",M39*L39,IF(H39="CÉLULA CONSTRUTIVA",SUMIFS($N$8:$N$467,$B$8:$B$467,B39,$H$8:$H$467,"Serviço"),IF(H39="ETAPA",SUMIFS($N$8:$N$467,$B$8:$B$467,B39,$C$8:$C$467,C39,$H$8:$H$467,"Serviço"),IF(H39="SUBETAPA",SUMIFS($N$8:$N$467,$B$8:$B$467,B39,$C$8:$C$467,C39,$D$8:$D$467,D39,$H$8:$H$467,"Serviço"),0)))) | O39: =_xlfn.XLOOKUP($J39,BASES!$A$12:$A$392,BASES!$F$12:$F$392)
A40: =IF($H40="UNIDADE CONSTRUTIVA",OFFSET(A40,-1,0)+1,LARGE(A$3:A39,1)) | B40: =IF(H40="UNIDADE CONSTRUTIVA",0,IF(H40="CÉLULA CONSTRUTIVA",OFFSET(B40,-1,0)+1,OFFSET(B40,-1,0))) | C40: =IF(H40="CÉLULA CONSTRUTIVA",0,IF(H40="ETAPA",OFFSET(C40,-1,0)+1,OFFSET(C40,-1,0))) | D40: =IF(H40="ETAPA",0,IF(H40="SUBETAPA",OFFSET(D40,-1,0)+1,OFFSET(D40,-1,0))) | E40: =IF(H40="Subetapa",0,IF(H40="serviço",OFFSET(E40,-1,0)+1,OFFSET(E40,-1,0))) | H40: SERVIÇO | I40: =IF(H40="Unidade Construtiva",TEXT(A40,"00"),IF(H40="Célula Construtiva",TEXT(B40,"00"),IF(H40="Etapa",CONCATENATE(TEXT(B40,"00"),".",TEXT(C40,"000")),IF(H40="Subetapa",CONCATENATE(TEXT(B40,"00"),".",TEXT(C40,"000"),".",TEXT(D40,"000")),IF(H40="Serviço",CONCATENATE(TEXT(B40,"00"),".",TEXT(C40,"000"),".",TEXT(D40,"000"),".",TEXT(E40,"000")),""))))) | J40: Aprovação e legalização bombeiros | K40: =_xlfn.XLOOKUP($J40,BASES!$A$12:$A$392,BASES!$C$12:$C$392) | L40: =_xlfn.XLOOKUP($J40,BASES!$A$12:$A$392,BASES!$D$12:$D$392) | M40: =_xlfn.XLOOKUP($J40,BASES!$A$1:$A$2289,BASES!$E$1:$E$2289) | N40: =IF(H40="Serviço",M40*L40,IF(H40="CÉLULA CONSTRUTIVA",SUMIFS($N$8:$N$467,$B$8:$B$467,B40,$H$8:$H$467,"Serviço"),IF(H40="ETAPA",SUMIFS($N$8:$N$467,$B$8:$B$467,B40,$C$8:$C$467,C40,$H$8:$H$467,"Serviço"),IF(H40="SUBETAPA",SUMIFS($N$8:$N$467,$B$8:$B$467,B40,$C$8:$C$467,C40,$D$8:$D$467,D40,$H$8:$H$467,"Serviço"),0)))) | O40: =_xlfn.XLOOKUP($J40,BASES!$A$12:$A$392,BASES!$F$12:$F$392)
A41: =IF($H41="UNIDADE CONSTRUTIVA",OFFSET(A41,-1,0)+1,LARGE(A$3:A40,1)) | B41: =IF(H41="UNIDADE CONSTRUTIVA",0,IF(H41="CÉLULA CONSTRUTIVA",OFFSET(B41,-1,0)+1,OFFSET(B41,-1,0))) | C41: =IF(H41="CÉLULA CONSTRUTIVA",0,IF(H41="ETAPA",OFFSET(C41,-1,0)+1,OFFSET(C41,-1,0))) | D41: =IF(H41="ETAPA",0,IF(H41="SUBETAPA",OFFSET(D41,-1,0)+1,OFFSET(D41,-1,0))) | E41: =IF(H41="Subetapa",0,IF(H41="serviço",OFFSET(E41,-1,0)+1,OFFSET(E41,-1,0))) | H41: SERVIÇO | I41: =IF(H41="Unidade Construtiva",TEXT(A41,"00"),IF(H41="Célula Construtiva",TEXT(B41,"00"),IF(H41="Etapa",CONCATENATE(TEXT(B41,"00"),".",TEXT(C41,"000")),IF(H41="Subetapa",CONCATENATE(TEXT(B41,"00"),".",TEXT(C41,"000"),".",TEXT(D41,"000")),IF(H41="Serviço",CONCATENATE(TEXT(B41,"00"),".",TEXT(C41,"000"),".",TEXT(D41,"000"),".",TEXT(E41,"000")),""))))) | J41: Taxas ART | K41: =_xlfn.XLOOKUP($J41,BASES!$A$12:$A$392,BASES!$C$12:$C$392) | L41: =_xlfn.XLOOKUP($J41,BASES!$A$12:$A$392,BASES!$D$12:$D$392) | M41: =_xlfn.XLOOKUP($J41,BASES!$A$1:$A$2289,BASES!$E$1:$E$2289) | N41: =IF(H41="Serviço",M41*L41,IF(H41="CÉLULA CONSTRUTIVA",SUMIFS($N$8:$N$467,$B$8:$B$467,B41,$H$8:$H$467,"Serviço"),IF(H41="ETAPA",SUMIFS($N$8:$N$467,$B$8:$B$467,B41,$C$8:$C$467,C41,$H$8:$H$467,"Serviço"),IF(H41="SUBETAPA",SUMIFS($N$8:$N$467,$B$8:$B$467,B41,$C$8:$C$467,C41,$D$8:$D$467,D41,$H$8:$H$467,"Serviço"),0)))) | O41: =_xlfn.XLOOKUP($J41,BASES!$A$12:$A$392,BASES!$F$12:$F$392)
A42: =IF($H42="UNIDADE CONSTRUTIVA",OFFSET(A42,-1,0)+1,LARGE(A$3:A41,1)) | B42: =IF(H42="UNIDADE CONSTRUTIVA",0,IF(H42="CÉLULA CONSTRUTIVA",OFFSET(B42,-1,0)+1,OFFSET(B42,-1,0))) | C42: =IF(H42="CÉLULA CONSTRUTIVA",0,IF(H42="ETAPA",OFFSET(C42,-1,0)+1,OFFSET(C42,-1,0))) | D42: =IF(H42="ETAPA",0,IF(H42="SUBETAPA",OFFSET(D42,-1,0)+1,OFFSET(D42,-1,0))) | E42: =IF(H42="Subetapa",0,IF(H42="serviço",OFFSET(E42,-1,0)+1,OFFSET(E42,-1,0))) | H42: SERVIÇO | I42: =IF(H42="Unidade Construtiva",TEXT(A42,"00"),IF(H42="Célula Construtiva",TEXT(B42,"00"),IF(H42="Etapa",CONCATENATE(TEXT(B42,"00"),".",TEXT(C42,"000")),IF(H42="Subetapa",CONCATENATE(TEXT(B42,"00"),".",TEXT(C42,"000"),".",TEXT(D42,"000")),IF(H42="Serviço",CONCATENATE(TEXT(B42,"00"),".",TEXT(C42,"000"),".",TEXT(D42,"000"),".",TEXT(E42,"000")),""))))) | J42: Taxas alvará | K42: =_xlfn.XLOOKUP($J42,BASES!$A$12:$A$392,BASES!$C$12:$C$392) | L42: =_xlfn.XLOOKUP($J42,BASES!$A$12:$A$392,BASES!$D$12:$D$392) | M42: =_xlfn.XLOOKUP($J42,BASES!$A$1:$A$2289,BASES!$E$1:$E$2289) | N42: =IF(H42="Serviço",M42*L42,IF(H42="CÉLULA CONSTRUTIVA",SUMIFS($N$8:$N$467,$B$8:$B$467,B42,$H$8:$H$467,"Serviço"),IF(H42="ETAPA",SUMIFS($N$8:$N$467,$B$8:$B$467,B42,$C$8:$C$467,C42,$H$8:$H$467,"Serviço"),IF(H42="SUBETAPA",SUMIFS($N$8:$N$467,$B$8:$B$467,B42,$C$8:$C$467,C42,$D$8:$D$467,D42,$H$8:$H$467,"Serviço"),0)))) | O42: =_xlfn.XLOOKUP($J42,BASES!$A$12:$A$392,BASES!$F$12:$F$392)
A43: =IF($H43="UNIDADE CONSTRUTIVA",OFFSET(A43,-1,0)+1,LARGE(A$3:A42,1)) | B43: =IF(H43="UNIDADE CONSTRUTIVA",0,IF(H43="CÉLULA CONSTRUTIVA",OFFSET(B43,-1,0)+1,OFFSET(B43,-1,0))) | C43: =IF(H43="CÉLULA CONSTRUTIVA",0,IF(H43="ETAPA",OFFSET(C43,-1,0)+1,OFFSET(C43,-1,0))) | D43: =IF(H43="ETAPA",0,IF(H43="SUBETAPA",OFFSET(D43,-1,0)+1,OFFSET(D43,-1,0))) | E43: =IF(H43="Subetapa",0,IF(H43="serviço",OFFSET(E43,-1,0)+1,OFFSET(E43,-1,0))) | H43: SERVIÇO | I43: =IF(H43="Unidade Construtiva",TEXT(A43,"00"),IF(H43="Célula Construtiva",TEXT(B43,"00"),IF(H43="Etapa",CONCATENATE(TEXT(B43,"00"),".",TEXT(C43,"000")),IF(H43="Subetapa",CONCATENATE(TEXT(B43,"00"),".",TEXT(C43,"000"),".",TEXT(D43,"000")),IF(H43="Serviço",CONCATENATE(TEXT(B43,"00"),".",TEXT(C43,"000"),".",TEXT(D43,"000"),".",TEXT(E43,"000")),""))))) | J43: Taxa Renovação Alvará de Construção | K43: =_xlfn.XLOOKUP($J43,BASES!$A$12:$A$392,BASES!$C$12:$C$392) | L43: =_xlfn.XLOOKUP($J43,BASES!$A$12:$A$392,BASES!$D$12:$D$392) | M43: =_xlfn.XLOOKUP($J43,BASES!$A$1:$A$2289,BASES!$E$1:$E$2289) | N43: =IF(H43="Serviço",M43*L43,IF(H43="CÉLULA CONSTRUTIVA",SUMIFS($N$8:$N$467,$B$8:$B$467,B43,$H$8:$H$467,"Serviço"),IF(H43="ETAPA",SUMIFS($N$8:$N$467,$B$8:$B$467,B43,$C$8:$C$467,C43,$H$8:$H$467,"Serviço"),IF(H43="SUBETAPA",SUMIFS($N$8:$N$467,$B$8:$B$467,B43,$C$8:$C$467,C43,$D$8:$D$467,D43,$H$8:$H$467,"Serviço"),0)))) | O43: =_xlfn.XLOOKUP($J43,BASES!$A$12:$A$392,BASES!$F$12:$F$392)
...
