Workbook
Name \0: #REF!
Name \0: #REF!
Name \0: #REF!
Name \0: #REF!
Name \0: #REF!
Name \0: #REF!
Name \0: #REF!
Name \0: #REF!
Name \0: #REF!
Name \0: #REF!
Name \1: #REF!
Name \1: #REF!
Name \1: #REF!
Name \1: #REF!
Name \1: #REF!
Name \1: #REF!
Name \a: #REF!
Name \a: #REF!
Name \a: #REF!
Name \a: #REF!
Name \a: #REF!
Name \a: #REF!
Name \a: #REF!
Name \a: #REF!
Name \a: #REF!
Name \b: #REF!
Name \b: #REF!
Name \b: #REF!
Name \b: #REF!
Name \c: #REF!
Name \c: #REF!
Name \c: #REF!
Name \c: #REF!
Name \d: #REF!
Name \d: #REF!
Name \d: #REF!
Name \d: #REF!
Name \e: #REF!
Name \e: #REF!
Name \e: #REF!
Name \e: #REF!
Name \i: #REF!
Name \i: #REF!
Name \i: #REF!
Name \i: #REF!
Name \J: #REF!
Name \J: #REF!
Name \J: #REF!
Name \J: #REF!
Name \k: #REF!
Name \k: #REF!
Name \k: #REF!
Name \k: #REF!
Name \k: #REF!
Name \l: #N/A
Name \m: #REF!
Name \m: #REF!
Name \m: #REF!
Name \m: #REF!
Name \m: #REF!

Sheet Obra 
C1: Projeto | D1: Brisa da armação
C2: Empresa | D2: HACASA
C3: Revisão | D3: R00 - Letícia
A4: QUADRO DE ÁREAS
B6: Descrição | C6: Unidade | E6: Quantidade | G6: Imagens
B7: MESES DE OBRA | C7: MÊS | E7: 48
B8: ÁREA DO TERRENO | C8: M² | E8: 1410.3
B9: ÁREA CONSTRUÍDA | C9: M² | E9: =SUM($E$15:$E$25) -> 12828.33
B10: NÚMERO DE UNIDADES HABITACIONAIS | C10: UN | E10: 117
B11: NÚMERO DE UNIDADES COMERCIAIS | C11: UN | E11: 4
B12: ÁREA PRIVATIVA | C12: M² | E12: 7101.75
B13: NÚMERO DE PAVIMENTOS | C13: UN | E13: 20
B15: Térreo | C15: M² | E15: 918.44
B16: Garagem G1 | C16: M² | E16: 1045.47
B17: Garagem G2 | C17: M² | E17: 1045.47
B18: Garagem G3 | C18: M² | E18: 1045.47
B19: Garagem G4 | C19: M² | E19: 1051.41
B20: Tipo 01 (1x) | C20: M² | E20: 545.33
B21: Tipo 02 (11x) | C21: M² | E21: 5998.63
B22: Tipo 03 (01x) | C22: M² | E22: 557.79
... B25: Caixa D'água | C25: M² | E25: 40.32
B31: ETAPA | C31: VALOR ORÇADO | D31: % | E31: VALOR / m²
B32: GERENCIAMENTO TÉCNICO E ADMINISTRATIVO | C32: 4609930 | D32: =C32/C$53 -> 0.10902428 | E32: =C32/$E$9 -> 359.35543
B33: MOVIMENTAÇÃO DE TERRA | C33: 231016.84 | D33: =C33/C$53 -> 0.0054635201 | E33: =C33/$E$9 -> 18.008333
B34: INFRAESTRUTURA | C34: 2489515.3 | D34: =C34/C$53 -> 0.058876733 | E34: =C34/$E$9 -> 194.06386
B35: SUPRAESTRUTURA | C35: 8183443.8 | D35: =C35/C$53 -> 0.19353745 | E35: =C35/$E$9 -> 637.91965
B36: ALVENARIA | C36: 1838976.9 | D36: =C36/C$53 -> 0.04349158 | E36: =C36/$E$9 -> 143.35279
B37: INSTALAÇÕES ELÉTRICAS, HIDRÁULICAS, GLP E PREVENTIVAS | C37: 2423175.5 | D37: =C37/C$53 -> 0.057307806 | E37: =C37/$E$9 -> 188.89252
B38: CLIMATIZAÇÃO, EXAUSTÃO MECÂNICA E PRESSURIZAÇÃO | C38: 874867.45 | D38: =C38/C$53 -> 0.020690509 | E38: =C38/$E$9 -> 68.198078
B39: REVESTIMENTOS ARGAMASSADOS PISO E PAREDE | C39: 2123455.5 | D39: =C39/C$53 -> 0.050219464 | E39: =C39/$E$9 -> 165.5286
B40: REVESTIMENTOS ARGAMASSADOS TETO | C40: 767.25885 | D40: =C40/C$53 -> 1.8145579e-05 | E40: =C40/$E$9 -> 0.059809722
B41: IMPERMEABILIZAÇÃO | C41: 1217962.5 | D41: =C41/C$53 -> 0.028804666 | E41: =C41/$E$9 -> 94.943187
B42: ACABAMENTOS INTERNOS EM PAREDE | C42: 421316.73 | D42: =C42/C$53 -> 0.0099640894 | E42: =C42/$E$9 -> 32.842679
B43: ACABAMENTOS EM PISOS E PAVIMENTAÇÕES | C43: 1609363.8 | D43: =C43/C$53 -> 0.038061258 | E43: =C43/$E$9 -> 125.45388
... B52: IMPREVISTOS | C52: 738697.75 | D52: =C52/C$53 -> 0.017470112 | E52: =C52/$E$9 -> 57.583314
B53: TOTAL | C53: =SUM(C32:C52) -> 42283515 | D53: =SUM(D32:D52) -> 1 | E53: =SUM(E32:E52) -> 3296.1044
B54: CUB/SC | C54: 2863.73 | D54: 45597 | E54: =ROUNDUP(+E53/C54,2)&" CUB" -> 1,16 CUB

Sheet EPCs
A1: Obra | B1: ='Obra '!D1 -> Brisa da armação
A2: Empresa | B2: ='Obra '!D2 -> HACASA
A3: Revisão | B3: ='Obra '!D3 -> R00 - Letícia | K3: Guia pavimentos
A4: Equipamentos de proteção coletiva | K4: Pavimento | L4: Área | M4: Perímetro | N4: Pé Direito
A5: Bandejas de proteção
B7: Descrição | C7: Unidade | D7: Quantidade | F7: Imagem formulário
B8: Perímetro de projeção embasamento | C8: m
B9: Perímetro de projeção Primária tipo 1 | C9: m
B10: Perímetro de projeção torre tipo 1 | C10: m
B11: Bandeja de proteção primária | C11: m | D11: =D8+D9 -> 0
B12: Bandeja de proteção secundária | C12: m | D12: =D10 -> 0
B13: * Considerado as informações do Projeto de Segurança
A14: Guarda - corpo de vãos
B16: Descrição | C16: Unidade | D16: Quantidade | F16: Imagem formulário
B17: Perímetro de vãos | C17: m
B18: Guarda - corpo de vãos | C18: m | D18: =D17 -> 0
A20: Guarda - corpo de desforma
B22: Descrição | C22: Unidade | D22: Quantidade | F22: Imagem formulário
B23: Perímetro de projeção da torre | C23: m | D23: =M22 -> 0
B24: Repetições de pavimentos** | C24: un | D24: 4
B25: Proteção de periferia pós desforma torre | C25: m | D25: =(D23*D24) -> 0
A27: Fechamento removível de vãos em madeira
B29: Descrição | C29: Unidade | D29: Quantidade | F29: Imagem formulário
B30: Área das portas de elevadores | C30: m2
B31: Quantidade de elevadores | C31: un
B32: Quantidade de portas de elevadores | C32: un
B33: Fechamento removível de vãos em madeira | C33: m2 | D33: =D30*D32 -> 0
B34: Área das portas de aptos | C34: m2
B35: Quantidade de aptos | C35: un
B36: =A27 -> Fechamento removível de vãos em madeira | C36: m2 | D36: =D34*D35 -> 0
A38: Tela fachadeira
B40: Descrição | C40: Unidade | D40: Quantidade | F40: Imagem formulário
B41: Area da fachada | C41: m² | D41: =SUMPRODUCT($M$9:$M$22,$N$9:$N$22) -> 0
B42: =A38 -> Tela fachadeira | C42: m2 | D42: =D41 -> 0
A44: SLQA
B46: Descrição | C46: Unidade | D46: Quantidade | F46: Imagem formulário
B47: Perímetro de projeção da torre 1 | C47: m | D47: =$M$22 -> 0
B48: Altura de cobrimento da tela | C48: un | D48: 1
B49: =A44 -> SLQA | C49: m | D49: =D47*D48 -> 0
A52: Tapume
...

Sheet CANTEIRO
A1: Obra | B1: ='Obra '!D1 -> Brisa da armação
A2: Empresa | B2: ='Obra '!D2 -> HACASA
A3: Revisão | B3: ='Obra '!D3 -> R00 - Letícia | O3: Número de funcionários | S3: Produtividade média (h/m2)
A4: Instalações de canteiro | O4: Área construída | P4: 6601.277 | S4: A.C/prazo | T4: =P4/P5 -> 235.75989
A5: Instalações de canteiro | O5: Prazo da obra | P5: 28 | Q5: meses | S5: Pm | T5: 49 | U5: h/m2
O6: NF | P6: =ROUNDUP((P4*T5)/P5/180,) -> 65 | Q6: funcionários
B7: Descrição | C7: Unidade | D7: Quantidade | O7: Pavimentos | P7: 10
B8: Produtividade média | C8: m2 / mês | D8: ='Obra '!$E$9/'Obra '!$E$7 -> 267.25688 | O8: Equipe administrativa | P8: 5 | Q8: funcionários
B9: Pm | C9: h/m2 | D9: 41
B10: Numero de funcionários | C10: un | D10: =ROUNDUP((D9*'Obra '!$E$9)/'Obra '!$E$7/180,) -> 61
B11: Equipe administrativa | C11: un | D11: 5 | O11: Barracão interno | P11: =450+(P4-13000)/1000*16 -> 347.62043
B12: Pontos de água e esgoto | C12: un | D12: =ROUNDUP($D$10/20,0) -> 4 | E12: 20 funcionários/ponto | O12: Externo | P12: =P11*0.4 -> 139.04817
B13: Bebedouro | C13: un | D13: =ROUNDUP('Obra '!$E$13/5,0) -> 4 | E13: 1 / 5 pav.
B14: Ferramentas | C14: R$ | D14: =800*D10 -> 48800 | E14: 800,00/func. | P14: =SUM(P11:P13) -> 486.6686
B15: EPI | C15: R$ | D15: =500*D10 -> 30500 | E15: 500,00/func.
B16: Banheiro | C16: un | D16: =ROUNDUP($D$10/20,0) -> 4 | E16: 1/20 func | O16: Área refeitório | P16: 1 | Q16: m²/funcionários
P17: =P16*P6 -> 65 | Q17: m²
A18: Mobiliário de canteiro
O19: Área de vestiário | P19: 1.5 | Q19: m²/funcionários
B20: Descrição | C20: Unidade | D20: Quantidade | E20: Custo unitário | F20: Custo total | P20: =P19*P6 -> 97.5 | Q20: m²
B21: Cadeira | C21: un | D21: =ROUNDUP(D11*1.5,) -> 8 | E21: 200 | F21: =D21*E21 -> 1600
B22: Mesa | C22: un | D22: 1 | E22: 1000 | F22: =E22*D22 -> 1000
B23: Ar condicionado | C23: un | D23: 2 | E23: 5000 | F23: =E23*D23 -> 10000
B24: Armário | C24: m | D24: 4 | E24: 900 | F24: =E24*D24 -> 3600
B25: Escrivaninha | C25: un | D25: =D11 -> 5 | E25: 800 | F25: =E25*D25 -> 4000
B26: TOTAL | F26: =F23+F24+F25+F22+F21 -> 20200
B27: Descrição | C27: Unidade | D27: Quantidade | E27: Custo unitário | F27: Custo total
B28: Computador pessoal | C28: un | D28: =D11 -> 5 | E28: 6500 | F28: =D28*E28 -> 32500
B29: Impressora | C29: un | D29: 1 | E29: 2000 | F29: =E29*D29 -> 2000
B30: Roteador | C30: un | D30: 2 | E30: 500 | F30: =E30*D30 -> 1000
B31: TOTAL | F31: =+F28+F29+F30 -> 35500 | O31: Área sanitários | P31: =1*ROUNDUP(P6/20,) -> 4 | Q31: m²
A33: Instalações Provisórias (central de aço, formas, argamassa, almoxarifado geral, construções temporárias) | O33: área lavatório | P33: =0.6*ROUNDUP(P6/20,) -> 2.4 | Q33: m²
O34: Área de chuveiros | P34: =0.8*ROUNDUP(P6/10,) -> 5.6 | Q34: m²
B35: Descrição | C35: Unidade | D35: Será utilizado | E35: Quantidade | F35: Custo unitário | G35: Custo total
B36: Central de aço | C36: m2 | D36: Sim | E36: =IF(D36="Sim",15,0) -> 15 | F36: 115.4849 | G36: =IF(D36="sim",E36*F36,0) -> 1732.2735
B37: Central de fôrmas | C37: m2 | D37: Sim | E37: =IF(D37="Sim",15,0) -> 15 | F37: 115.4849 | G37: =IF(D37="sim",E37*F37,0) -> 1732.2735
B38: Central de Argamassa | C38: m2 | D38: Sim | E38: =IF(D38="Sim",15,0) -> 15 | F38: 115.4849 | G38: =IF(D38="sim",E38*F38,0) -> 1732.2735
B39: Armazenamento de cerâmicas* | C39: m2 | D39: Sim | E39: =IF(D39="não",0,ROUNDUP(3*'Obra '!$E$10/COUNTIFS($D$39:$D$47,"Sim"),)) -> 51 | F39: 201.22489 | G39: =IF(D39="sim",E39*F39,0) -> 10262.469
B40: Armazenamento de placas degesso* | C40: m2 | D40: Não | E40: =IF(D40="não",0,ROUNDUP(3*'Obra '!$E$10/COUNTIFS($D$39:$D$47,"Sim"),)) -> 0 | F40: 201.22489 | G40: =IF(D40="sim",E40*F40,0) -> 0
B41: Armazenamento de blocos* | C41: m2 | D41: Sim | E41: =IF(D41="não",0,ROUNDUP(3*'Obra '!$E$10/COUNTIFS($D$39:$D$47,"Sim"),)) -> 51 | F41: 201.22489 | G41: =IF(D41="sim",E41*F41,0) -> 10262.469
...

Sheet Ensaios 
C1: Projeto | D1: ='Obra '!D1 -> Brisa da armação
C2: Empresa | D2: ='Obra '!D2 -> HACASA
C3: Revisão | D3: ='Obra '!D3 -> R00 - Letícia
A4: ENSAIOS
A5: Item | B5: Descrição/Especificação | C5: Unid. | D5: V. Unit. (R$) | E5: Qtde. | F5: V. Total (R$) | G5: Observações
B6: CONTROLE TECNOLÓGICO - CONCRETO | F6: =SUM(F7:F12) -> 261480
A7: 1 | B7: Laudo e ART | C7: vb | D7: 1450 | E7: 1 | F7: =$D7*E7 -> 1450
A8: =A7+1 -> 2 | B8: Controle Tecnologico Infraestrutura - Coleta materiais da obra | C8: unid. | D8: 20 | E8: =ROUNDUP(([4]Resumo!L181+[4]Resumo!L182+[4]Resumo!L218)/8,0)*4 -> 1444 | F8: =$D8*E8 -> 28880 | G8: 4 CPs por caminhão betoneira de 8m³
A9: =A8+1 -> 3 | B9: Controle Tecnologico Contenção - Coleta materiais da obra | C9: unid. | D9: 20 | E9: =ROUNDUP(([4]Resumo!L200+[4]Resumo!L201)/8,0)*4 -> 452 | F9: =$D9*E9 -> 9040 | G9: 4 CPs por caminhão betoneira de 8m³
A10: =A9+1 -> 4 | B10: Controle Tecnologico Supraestrutura - Coleta materiais da obra | C10: unid. | D10: 20 | E10: =ROUNDUP(([4]Resumo!L242+[4]Resumo!L243+[4]Resumo!L271+[4]Resumo!L272+[4]Resumo!L294+[4]Resumo!L295)/8,0)*4 -> 5972 | F10: =$D10*E10 -> 119440 | G10: 4 CPs por caminhão betoneira de 8m³
A11: =A8+1 -> 3 | B11: Controle Tecnológico - Ensaio de concreto endurecido/grouth - compressão simples / Detalhe: Concreto | C11: cps | D11: 12.5 | E11: =E8+E9+E10 -> 7868 | F11: =$D11*E11 -> 98350
A12: =A11+1 -> 4 | B12: Determinação do módulo de deformação tangente inicial (Eci) (módulo de elasticidade), Incluindo Avaliação Estática dos Resultados (NBR 8522 e NBR 12655) | C12: ensaio | D12: 480 | E12: =[4]Obra!E56/5 -> 9 | F12: =$D12*E12 -> 4320 | G12: A cada 5 pav. (e quando houver troca de fornecedor)
B13: ACUSTICA - ENSAIO DE RUIDOS ( PISO + FACHADA) | F13: =SUM(F14:F15) -> 9000
A14: 1 | B14: Ensaio de Desempenho Acustico para piso Ensaio de ruído aéreo e ruído de impacto em Laje de dorm. | C14: ensaios | D14: 7500 | E14: 1 | F14: =$D14*E14 -> 7500 | G14: 1 ensaio
A15: =A14+1 -> 2 | B15: Ensaio de Desempenho Acustico para vedação externa Ensaio de isolamento a ruído aéreo em Fachada de dorm. | C15: ensaios | D15: 1500 | E15: 1 | F15: =$D15*E15 -> 1500 | G15: 1 ensaio
B16: ENSAIO PARA CAIXILHOS | F16: =SUM(F17:F19) -> 9968
A17: 1 | B17: Permeabilidade ao ar Estanqueidade a agua Resistencias a cargas uniformes distribuidas | C17: ensaios | D17: 3174 | E17: 1 | F17: =$D17*E17 -> 3174 | G17: 1 ensaio por tipo de caixilho (dormitório, sala, área de serviço e banheiro e terraço, se houver)
A18: =A17+1 -> 2 | B18: Resistencia as operações de manuseio com manutenção SEM persiana integrada | C18: ensaios | D18: 2774 | E18: 1 | F18: =$D18*E18 -> 2774 | G18: 1 ensaio por tipo de caixilho (dormitório, sala, área de serviço e banheiro e terraço, se houver)
A19: =A18+1 -> 3 | B19: Resistencia as operações de manuseio com manutenção COM persiana integrada | C19: ensaios | D19: 4020 | E19: 1 | F19: =$D19*E19 -> 4020 | G19: 1 ensaio por tipo de caixilho (dormitório, sala, área de serviço e banheiro e terraço, se houver)
B20: ENSAIO PARA GUARDA-CORPO | F20: =F21 -> 4210
A21: 1 | B21: Ensaio de guarda-corpo Determinação do esforço horizontal, esforço vertical e Resistencia a impactos | C21: ensaios | D21: 4210 | E21: 1 | F21: =$D21*E21 -> 4210 | G21: 1 prototipo por projeto
B22: ENSAIOS PARA ARGAMASSA DE REVESTIMENTO (FACHADA) | F22: =F23 -> 1260
A23: 1 | B23: Ensaio de arrancamento de argamassa de revestimento Determinação da aderencia a tração | C23: ensaios | D23: 1260 | E23: 1 | F23: =$D23*E23 -> 1260 | G23: 1 ensaio por torre
B24: ENSAIO PARA REVESTIMENTOS CERÂMICOS | F24: =F25 -> 664.44444
A25: 1 | B25: Aderência em Revestimento Cerâmico Determinação da aderência a tração (NBR 13754) | C25: ensaios | D25: 664.44444 | E25: 1 | F25: =$D25*E25 -> 664.44444 | G25: Torre Alta: 1 ensaio por torre, por referência de produto
B26: ENSAIO PARA ANCORAGEM (GANHOS DA COBERTURA) | F26: =SUM(F27:F28) -> 3165
A27: 1 | B27: Arrancamento de ganchos da cobertura Ensaio de Arrancamento | C27: ensaios | D27: 1680 | E27: 1 | F27: =$D27*E27 -> 1680 | G27: 1 ensaio por torre
A28: =A27+1 -> 2 | B28: Arrancamento de ganchos da cobertura Emissão de Relatorio e Laudos, incluindo Mobilização/ Desmobilização | C28: ensaios | D28: 1485 | E28: 1 | F28: =$D28*E28 -> 1485 | G28: 1 por tipo de torre
B29: ENSAIOS PARA ALVENARIA ESTRUTURAL | F29: =SUM(F30:F35) -> 81801
A30: 1 | B30: Controle Tecnológico - Ensaio de concreto endurecido/grouth - compressão simples / Detalhe: Groute | C30: unid. | D30: 8.5 | F30: 2805 | G30: ≥ 12Mpa: 6 CP's x núm pav x núm torres + ANEXOS (CONSIDERAR +6 CPs PARA CADA PAVIMENTO DE ANEXOS - INCLUINDO EMBASAMENTO E PLATIBANDA - SE HOUVER) Torre alta: 6CPs por pavimento
A31: =A30+1 -> 2 | B31: Ensaio de Argamassa - Determinação da resistência a compressão - no cubo (NBR 15961-2/2011) | C31: unid. | D31: 18 | F31: 11556 | G31: ≥ 12Mpa: 6 CP's x núm pav x núm torres + ANEXOS (CONSIDERAR +6 CPs PARA CADA PAVIMENTO DE ANEXOS - INCLUINDO EMBASAMENTO E PLATIBANDA - SE HOUVER) Torre alta: 6CPs por pavimento P/ pavimento > 600m²: 12 CPs
A32: =A31+1 -> 3 | B32: Ensaio Prisma - Determinação da resistência a compressão - Oco (NBR 15961-2/2011) | C32: unid. | D32: 50 | F32: 27600 | G32: 12 CP's x núm pav x núm torres Torre alta: 12CPs por pavimento P/ pavimento > 600m²: 12 CPs
A33: =A32+1 -> 4 | B33: Ensaio Prisma - Determinação da resistência a compressão - Cheio (NBR 15961-2/2011) | C33: unid. | D33: 65 | F33: 35880 | G33: 12 CP's x núm pav x núm torres Torre alta: 12CPs por pavimento P/ pavimento > 600m²: 12 CPs
A34: =A33+1 -> 5 | B34: Ensaio de Bloco - Determinação da resistência a compressão com dimensionamento (NBR 12118) | C34: cps | D34: 40 | F34: 2640 | G34: 6 cps x núm classes de resistencia
A35: =A34+1 -> 6 | B35: Ensaio de Bloco - Determinação da absorção e área liquida (NBR 12118) | C35: unid | D35: 40 | F35: 1320 | G35: 3 cps x núm classe de resistencia
C36: SUBTOTAL: | F36: =F29+F26+F24+F22+F20+F16+F13+F6 -> 371548.44

Sheet BASES
A1: Estimativas Custos Indiretos
A2: Empresa | B2: ='Obra '!$D$1 -> Brisa da armação | H2: CN empreendimentos | J2: CN empreendimentos | L2: Amalfi Construções e Incorporações | N2: Amalfi Construções e Incorporações | P2: Amalfi Construções e Incorporações | R2: Amalfi Construções e Incorporações | T2: AS Ramos | V2: Mabrem Maiochi Empreendimentos | X2: All Empreendimentos | Z2: All Empreendimentos | AB2: ASPEN TOWERS | AD2: Barra 4 | AF2: Atlantia | AH2: Modelo
A3: Obra | B3: ='Obra '!$D$2 -> HACASA | H3: Brava Ocean | J3: BRAVA VALLEY | L3: Tramonti | N3: MARINE | P3: MAIORI | R3: Ravello | T3: PAESAGGIO | V3: LIBERATO | X3: Acacias JK | Z3: Lago di Garda Residenciale | AB3: JTA EMPREENDIMENTOS E URBANISMO | AD3: Viva 4 | AF3: H empreendimentos | AH3: Modelo
A4: Prazo de Obra | B4: ='Obra '!$E$7 -> 48 | AB4: 56 | AD4: 33 | AF4: 65 | AH4: Modelo
A5: Cidade/Estado | H5: Itajaí - SC | J5: Itajaí - SC | L5: Itajaí - SC | N5: Navegantes - SC | P5: Itajaí - SC | R5: Itajaí - SC | T5: Balneáreo Camboriú - SC | V5: Itajaí - SC | X5: Florianópolis – SC | Z5: Porto Belo - SC | AB5: Porto Belo - SC | AD5: Florianópolis - SC | AF5: Porto Belo - SC | AH5: Modelo
A6: R$/m² | B6: =$E$11/$B$8 -> 294.52801 | H6: 360.73572 | J6: 219.31773 | L6: 380.09457 | N6: 419.37 | P6: 396.69 | R6: 353.33 | T6: 263.26 | V6: 200.45074 | X6: 374.84 | Z6: 583.04 | AB6: 437.74041 | AD6: 311.85511 | AF6: 291.75097
A7: Área de Terreno | B7: ='Obra '!$E$8 -> 1410.3 | H7: 6060 | J7: 2713.9 | L7: 1224.03 | N7: 600 | P7: 914.4 | R7: 1412.41 | T7: 1734.23 | V7: 1634.37 | X7: 460.03 | Z7: 675 | AB7: 1473.45 | AD7: 3794.1 | AF7: 1410.3 | AH7: Modelo
A8: Área Construída | B8: ='Obra '!$E$9 -> 12828.33 | H8: 61763.96 | J8: 23497.71 | L8: 15602.89 | N8: 4498.68 | P8: 8366.5 | R8: 13434.29 | T8: 19144.43 | V8: 10520.39 | X8: 1943.23 | Z8: 7055.73 | AB8: 22087.95 | AD8: 13223.26 | AF8: 12828.33 | AH8: Modelo
A9: N° pavimentos | B9: ='Obra '!$E$13 -> 20 | H9: 31 | J9: 46 | L9: 28 | N9: 12 | P9: 20 | R9: 21 | T9: 35 | V9: 18 | X9: 8 | Z9: 19 | AB9: 34 | AD9: 6 | AF9: 20 | AH9: Modelo
A10: Cub | B10: 2863.73 | H10: 2662.47 | J10: 2470.83 | L10: 2863.73 | N10: 2750.52 | P10: 2747.9 | R10: 2753.62 | T10: 2680.84 | V10: 2754.98 | X10: 2758.46 | Z10: 2846.12 | AB10: 2846.12 | AD10: 2863.73 | AF10: 2863.73 | AJ10: =SUM(AJ13:AJ338) -> 3778302.5
A11: Data Cub | B11: 45616 | D11: Total | E11: =SUMPRODUCT($D$12:$D$341,$E$12:$E$341) -> 3778302.5 | H11: 44958 | J11: 44682 | L11: 45536 | N11: 45139 | P11: 45108 | R11: 45323 | T11: 45017 | V11: 45231 | X11: 45413 | Z11: 45566 | AB11: 45586 | AD11: 45616 | AF11: 45616 | AJ11: =SUM(AJ14:AJ339) -> 3778302.5
A12: Descrição | C12: Unidade | D12: Quantidade | E12: Valor (R$) | F12: Status do Custo | G12: Indice Médio | H12: Valor | I12: Referência | J12: Valor | K12: Referência | L12: Valor | M12: Referência | N12: Valor | O12: Referência | P12: Valor | Q12: Referência | R12: Valor | S12: Referência | T12: Valor | U12: Referência | V12: Valor | W12: Referência | X12: Valor | Y12: Referência | Z12: Valor | AA12: Referência | AB12: Valor | AC12: Referência | AD12: Valor | AE12: Referência | AF12: Valor | AG12: Referência | AH12: Valor | AI12: Referência | AJ12: =SUM(AJ15:AJ340) -> 3778302.5
A13: TEC 01 – ESTUDOS, PROJETOS, CONSULTORIAS, ENSAIOS E LAUDOS
A14: ESTUDOS | E14: =SUMPRODUCT(D15:D23,E15:E23) -> 47208.254
A15: Memorial descritivo | C15: vb | D15: 1 | E15: =$B$8*0.49 -> 6285.8817 | F15: Estimado | G15: =IFERROR(AVERAGEIFS($H15:$AI15,H$12:AI$12,"Referência"),"") -> 0.39071743 | H15: 17220 | I15: =IF(H15=0,"",($B$10/H$10)*H15/H$8) -> 0.29987852 | J15: 1532.0642 | K15: =IF(J15=0,"",($B$10/J$10)*J15/J$8) -> 0.075568469 | L15: 0 | M15: =IF(L15=0,"",($B$10/L$10)*L15/L$8) | N15: 2138.0766 | O15: =IF(N15=0,"",($B$10/N$10)*N15/N$8) -> 0.49482932 | P15: 0 | Q15: =IF(P15=0,"",($B$10/P$10)*P15/P$8) | R15: 0 | S15: =IF(R15=0,"",($B$10/R$10)*R15/R$8) | T15: 0 | U15: =IF(T15=0,"",($B$10/T$10)*T15/T$8) | V15: 5000 | W15: =IF(V15=0,"",($B$10/V$10)*V15/V$8) -> 0.49402825 | X15: 0 | Y15: =IF(X15=0,"",($B$10/X$10)*X15/X$8) | Z15: 0 | AA15: =IF(Z15=0,"",($B$10/Z$10)*Z15/Z$8) | AB15: 0 | AC15: =IF(AB15=0,"",($B$10/AB$10)*AB15/AB$8) | AD15: 6479.3974 | AE15: =IF(AD15=0,"",($B$10/AD$10)*AD15/AD$8) -> 0.49 | AF15: 6285.8817 | AG15: =IF(AF15=0,"",($B$10/AF$10)*AF15/AF$8) -> 0.49 | AI15: =IF(AH15=0,"",($B$10/AH$10)*AH15/AH$8) | AJ15: =E15*D15 -> 6285.8817 | AK15: 1
A16: Levantamento topográfico | C16: vb | D16: 1 | E16: =$B$8*0.46 -> 5901.0318 | F16: Estimado | G16: =IFERROR(AVERAGEIFS($H16:$AI16,H$12:AI$12,"Referência"),"") -> 0.99743036 | H16: 14207 | I16: =IF(H16=0,"",($B$10/H$10)*H16/H$8) -> 0.24740849 | J16: 0 | K16: =IF(J16=0,"",($B$10/J$10)*J16/J$8) | L16: 6709.2427 | M16: =IF(L16=0,"",($B$10/L$10)*L16/L$8) -> 0.43 | N16: 0 | O16: =IF(N16=0,"",($B$10/N$10)*N16/N$8) | P16: 3500 | Q16: =IF(P16=0,"",($B$10/P$10)*P16/P$8) -> 0.43596876 | R16: 0 | S16: =IF(R16=0,"",($B$10/R$10)*R16/R$8) | T16: 0 | U16: =IF(T16=0,"",($B$10/T$10)*T16/T$8) | V16: 4750 | W16: =IF(V16=0,"",($B$10/V$10)*V16/V$8) -> 0.46932684 | X16: 10000 | Y16: =IF(X16=0,"",($B$10/X$10)*X16/X$8) -> 5.3424587 | Z16: 5000 | AA16: =IF(Z16=0,"",($B$10/Z$10)*Z16/Z$8) -> 0.71302854 | AB16: 9630 | AC16: =IF(AB16=0,"",($B$10/AB$10)*AB16/AB$8) -> 0.43868192 | AD16: 5818.2344 | AE16: =IF(AD16=0,"",($B$10/AD$10)*AD16/AD$8) -> 0.44 | AF16: 5901.0318 | AG16: =IF(AF16=0,"",($B$10/AF$10)*AF16/AF$8) -> 0.46 | AI16: =IF(AH16=0,"",($B$10/AH$10)*AH16/AH$8) | AJ16: =E16*D16 -> 5901.0318 | AK16: 1
A17: Estudo geológico | C17: vb | F17: Não Solicitado | G17: =IFERROR(AVERAGEIFS($H17:$AI17,H$12:AI$12,"Referência"),"") -> 0.36998069 | H17: 12048 | I17: =IF(H17=0,"",($B$10/H$10)*H17/H$8) -> 0.20981048 | J17: 0 | K17: =IF(J17=0,"",($B$10/J$10)*J17/J$8) | L17: 0 | M17: =IF(L17=0,"",($B$10/L$10)*L17/L$8) | N17: 0 | O17: =IF(N17=0,"",($B$10/N$10)*N17/N$8) | P17: 0 | Q17: =IF(P17=0,"",($B$10/P$10)*P17/P$8) | R17: 0 | S17: =IF(R17=0,"",($B$10/R$10)*R17/R$8) | T17: 8067.1619 | U17: =IF(T17=0,"",($B$10/T$10)*T17/T$8) -> 0.45013161 | V17: 0 | W17: =IF(V17=0,"",($B$10/V$10)*V17/V$8) | X17: 0 | Y17: =IF(X17=0,"",($B$10/X$10)*X17/X$8) | Z17: 0 | AA17: =IF(Z17=0,"",($B$10/Z$10)*Z17/Z$8) | AB17: 0 | AC17: =IF(AB17=0,"",($B$10/AB$10)*AB17/AB$8) | AD17: 5950.467 | AE17: =IF(AD17=0,"",($B$10/AD$10)*AD17/AD$8) -> 0.45 | AF17: 0 | AG17: =IF(AF17=0,"",($B$10/AF$10)*AF17/AF$8) | AI17: =IF(AH17=0,"",($B$10/AH$10)*AH17/AH$8) | AJ17: =E17*D17 -> 0 | AK17: 0
A18: Estudo ambiental | C18: vb | D18: 1 | E18: =$B$8*1.24 -> 15907.129 | F18: Estimado | G18: =IFERROR(AVERAGEIFS($H18:$AI18,H$12:AI$12,"Referência"),"") -> 1.6056752 | H18: 16064 | I18: =IF(H18=0,"",($B$10/H$10)*H18/H$8) -> 0.2797473 | J18: 0 | K18: =IF(J18=0,"",($B$10/J$10)*J18/J$8) | L18: 15000 | M18: =IF(L18=0,"",($B$10/L$10)*L18/L$8) -> 0.96136036 | N18: 0 | O18: =IF(N18=0,"",($B$10/N$10)*N18/N$8) | P18: 11964.095 | Q18: =IF(P18=0,"",($B$10/P$10)*P18/P$8) -> 1.4902776 | R18: 0 | S18: =IF(R18=0,"",($B$10/R$10)*R18/R$8) | T18: 27426.591 | U18: =IF(T18=0,"",($B$10/T$10)*T18/T$8) -> 1.5303493 | V18: 49892.2 | W18: =IF(V18=0,"",($B$10/V$10)*V18/V$8) -> 4.9296312 | X18: 0 | Y18: =IF(X18=0,"",($B$10/X$10)*X18/X$8) | Z18: 4000 | AA18: =IF(Z18=0,"",($B$10/Z$10)*Z18/Z$8) -> 0.57042283 | AB18: 26765.958 | AC18: =IF(AB18=0,"",($B$10/AB$10)*AB18/AB$8) -> 1.2192879 | AD18: 29487.87 | AE18: =IF(AD18=0,"",($B$10/AD$10)*AD18/AD$8) -> 2.23 | AF18: 15907.129 | AG18: =IF(AF18=0,"",($B$10/AF$10)*AF18/AF$8) -> 1.24 | AI18: =IF(AH18=0,"",($B$10/AH$10)*AH18/AH$8) | AJ18: =E18*D18 -> 15907.129 | AK18: 1
A19: Sondagem do terreno | C19: vb | D19: 1 | E19: =$B$8*1.1 -> 14111.163 | F19: Estimado | G19: =IFERROR(AVERAGEIFS($H19:$AI19,H$12:AI$12,"Referência"),"") -> 0.93154156 | H19: 48270 | I19: =IF(H19=0,"",($B$10/H$10)*H19/H$8) -> 0.84060024 | J19: 0 | K19: =IF(J19=0,"",($B$10/J$10)*J19/J$8) | L19: 14364 | M19: =IF(L19=0,"",($B$10/L$10)*L19/L$8) -> 0.92059868 | N19: 0 | O19: =IF(N19=0,"",($B$10/N$10)*N19/N$8) | P19: 5500 | Q19: =IF(P19=0,"",($B$10/P$10)*P19/P$8) -> 0.68509377 | R19: 0 | S19: =IF(R19=0,"",($B$10/R$10)*R19/R$8) | T19: 0 | U19: =IF(T19=0,"",($B$10/T$10)*T19/T$8) | V19: 8830 | W19: =IF(V19=0,"",($B$10/V$10)*V19/V$8) -> 0.87245389 | X19: 0 | Y19: =IF(X19=0,"",($B$10/X$10)*X19/X$8) | Z19: 4800 | AA19: =IF(Z19=0,"",($B$10/Z$10)*Z19/Z$8) -> 0.6845074 | AB19: 33347 | AC19: =IF(AB19=0,"",($B$10/AB$10)*AB19/AB$8) -> 1.5190785 | AD19: 10975.306 | AE19: =IF(AD19=0,"",($B$10/AD$10)*AD19/AD$8) -> 0.83 | AF19: 14111.163 | AG19: =IF(AF19=0,"",($B$10/AF$10)*AF19/AF$8) -> 1.1 | AI19: =IF(AH19=0,"",($B$10/AH$10)*AH19/AH$8) | AJ19: =E19*D19 -> 14111.163 | AK19: 1
A20: Projeto de canteiro | C20: vb | D20: 1 | E20: =$B$8*0.39 -> 5003.0487 | F20: Estimado | G20: =IFERROR(AVERAGEIFS($H20:$AI20,H$12:AI$12,"Referência"),"") -> 0.38632166 | H20: 14056 | I20: =IF(H20=0,"",($B$10/H$10)*H20/H$8) -> 0.24477889 | J20: 3778.8344 | K20: =IF(J20=0,"",($B$10/J$10)*J20/J$8) -> 0.18638953 | L20: 0 | M20: =IF(L20=0,"",($B$10/L$10)*L20/L$8) | N20: 0 | O20: =IF(N20=0,"",($B$10/N$10)*N20/N$8) | P20: 0 | Q20: =IF(P20=0,"",($B$10/P$10)*P20/P$8) | R20: 0 | S20: =IF(R20=0,"",($B$10/R$10)*R20/R$8) | T20: 0 | U20: =IF(T20=0,"",($B$10/T$10)*T20/T$8) | V20: 3950 | W20: =IF(V20=0,"",($B$10/V$10)*V20/V$8) -> 0.39028232 | X20: 0 | Y20: =IF(X20=0,"",($B$10/X$10)*X20/X$8) | Z20: 5000 | AA20: =IF(Z20=0,"",($B$10/Z$10)*Z20/Z$8) -> 0.71302854 | AB20: 8556.3309 | AC20: =IF(AB20=0,"",($B$10/AB$10)*AB20/AB$8) -> 0.38977235 | AD20: 5157.0714 | AE20: =IF(AD20=0,"",($B$10/AD$10)*AD20/AD$8) -> 0.39 | AF20: 5003.0487 | AG20: =IF(AF20=0,"",($B$10/AF$10)*AF20/AF$8) -> 0.39 | AI20: =IF(AH20=0,"",($B$10/AH$10)*AH20/AH$8) | AJ20: =E20*D20 -> 5003.0487 | AK20: 1
A21: Estudo de Análise Técnica de Projeto | C21: vb | F21: Não Solicitado | G21: =IFERROR(AVERAGEIFS($H21:$AI21,H$12:AI$12,"Referência"),"") -> 2.6909045 | H21: 0 | I21: =IF(H21=0,"",($B$10/H$10)*H21/H$8) | J21: 0 | K21: =IF(J21=0,"",($B$10/J$10)*J21/J$8) | L21: 42000 | M21: =IF(L21=0,"",($B$10/L$10)*L21/L$8) -> 2.691809 | N21: 0 | O21: =IF(N21=0,"",($B$10/N$10)*N21/N$8) | P21: 0 | Q21: =IF(P21=0,"",($B$10/P$10)*P21/P$8) | R21: 0 | S21: =IF(R21=0,"",($B$10/R$10)*R21/R$8) | T21: 0 | U21: =IF(T21=0,"",($B$10/T$10)*T21/T$8) | V21: 0 | W21: =IF(V21=0,"",($B$10/V$10)*V21/V$8) | X21: 0 | Y21: =IF(X21=0,"",($B$10/X$10)*X21/X$8) | Z21: 0 | AA21: =IF(Z21=0,"",($B$10/Z$10)*Z21/Z$8) | AB21: 0 | AC21: =IF(AB21=0,"",($B$10/AB$10)*AB21/AB$8) | AD21: 35570.569 | AE21: =IF(AD21=0,"",($B$10/AD$10)*AD21/AD$8) -> 2.69 | AF21: 0 | AG21: =IF(AF21=0,"",($B$10/AF$10)*AF21/AF$8) | AI21: =IF(AH21=0,"",($B$10/AH$10)*AH21/AH$8) | AJ21: =E21*D21 -> 0 | AK21: 0
A22: Estudo Rebaixamento de Lençol Freático | C22: vb | F22: Não Solicitado | G22: =IFERROR(AVERAGEIFS($H22:$AI22,H$12:AI$12,"Referência"),"") -> 0.64090691 | H22: 0 | I22: =IF(H22=0,"",($B$10/H$10)*H22/H$8) | J22: 0 | K22: =IF(J22=0,"",($B$10/J$10)*J22/J$8) | L22: 10000 | M22: =IF(L22=0,"",($B$10/L$10)*L22/L$8) -> 0.64090691 | N22: 0 | O22: =IF(N22=0,"",($B$10/N$10)*N22/N$8) | P22: 0 | Q22: =IF(P22=0,"",($B$10/P$10)*P22/P$8) | R22: 0 | S22: =IF(R22=0,"",($B$10/R$10)*R22/R$8) | T22: 0 | U22: =IF(T22=0,"",($B$10/T$10)*T22/T$8) | V22: 0 | W22: =IF(V22=0,"",($B$10/V$10)*V22/V$8) | X22: 0 | Y22: =IF(X22=0,"",($B$10/X$10)*X22/X$8) | Z22: 0 | AA22: =IF(Z22=0,"",($B$10/Z$10)*Z22/Z$8) | AB22: 0 | AC22: =IF(AB22=0,"",($B$10/AB$10)*AB22/AB$8) | AD22: 0 | AE22: =IF(AD22=0,"",($B$10/AD$10)*AD22/AD$8) | AF22: 0 | AG22: =IF(AF22=0,"",($B$10/AF$10)*AF22/AF$8) | AI22: =IF(AH22=0,"",($B$10/AH$10)*AH22/AH$8) | AJ22: =E22*D22 -> 0 | AK22: 0
A23: Informações complementares de Estudos | C23: vb | F23: Não Solicitado | G23: =IFERROR(AVERAGEIFS($H23:$AI23,H$12:AI$12,"Referência"),"") | H23: 0 | I23: =IF(H23=0,"",($B$10/H$10)*H23/H$8) | J23: 0 | K23: =IF(J23=0,"",($B$10/J$10)*J23/J$8) | L23: 0 | M23: =IF(L23=0,"",($B$10/L$10)*L23/L$8) | N23: 0 | O23: =IF(N23=0,"",($B$10/N$10)*N23/N$8) | P23: 0 | Q23: =IF(P23=0,"",($B$10/P$10)*P23/P$8) | R23: 0 | S23: =IF(R23=0,"",($B$10/R$10)*R23/R$8) | T23: 0 | U23: =IF(T23=0,"",($B$10/T$10)*T23/T$8) | V23: 0 | W23: =IF(V23=0,"",($B$10/V$10)*V23/V$8) | X23: 0 | Y23: =IF(X23=0,"",($B$10/X$10)*X23/X$8) | Z23: 0 | AA23: =IF(Z23=0,"",($B$10/Z$10)*Z23/Z$8) | AB23: 0 | AC23: =IF(AB23=0,"",($B$10/AB$10)*AB23/AB$8) | AD23: 0 | AE23: =IF(AD23=0,"",($B$10/AD$10)*AD23/AD$8) | AF23: 0 | AG23: =IF(AF23=0,"",($B$10/AF$10)*AF23/AF$8) | AI23: =IF(AH23=0,"",($B$10/AH$10)*AH23/AH$8) | AJ23: =E23*D23 -> 0 | AK23: 0
A24: Projetos - Arquitetonico | E24: =SUMPRODUCT(D25:D31,E25:E31) -> 174465.29 | I24: =IF(H24=0,"",($B$10/H$10)*H24/H$8) | K24: =IF(J24=0,"",($B$10/J$10)*J24/J$8) | M24: =IF(L24=0,"",($B$10/L$10)*L24/L$8) | O24: =IF(N24=0,"",($B$10/N$10)*N24/N$8) | Q24: =IF(P24=0,"",($B$10/P$10)*P24/P$8) | S24: =IF(R24=0,"",($B$10/R$10)*R24/R$8) | U24: =IF(T24=0,"",($B$10/T$10)*T24/T$8) | W24: =IF(V24=0,"",($B$10/V$10)*V24/V$8) | Y24: =IF(X24=0,"",($B$10/X$10)*X24/X$8) | AA24: =IF(Z24=0,"",($B$10/Z$10)*Z24/Z$8) | AC24: =IF(AB24=0,"",($B$10/AB$10)*AB24/AB$8) | AE24: =IF(AD24=0,"",($B$10/AD$10)*AD24/AD$8) | AG24: =IF(AF24=0,"",($B$10/AF$10)*AF24/AF$8) | AI24: =IF(AH24=0,"",($B$10/AH$10)*AH24/AH$8) | AK24: 0
A25: Legalização de incorporação | C25: vb | D25: 1 | E25: =$B$8*1.62 -> 20781.895 | F25: Estimado | G25: =IFERROR(AVERAGEIFS($H25:$AI25,H$12:AI$12,"Referência"),"") -> 1.547038 | H25: 48190 | I25: =IF(H25=0,"",($B$10/H$10)*H25/H$8) -> 0.83920708 | J25: 0 | K25: =IF(J25=0,"",($B$10/J$10)*J25/J$8) | L25: 28553.289 | M25: =IF(L25=0,"",($B$10/L$10)*L25/L$8) -> 1.83 | N25: 0 | O25: =IF(N25=0,"",($B$10/N$10)*N25/N$8) | P25: 0 | Q25: =IF(P25=0,"",($B$10/P$10)*P25/P$8) | R25: 24583.635 | S25: =IF(R25=0,"",($B$10/R$10)*R25/R$8) -> 1.9030905 | T25: 35080.523 | U25: =IF(T25=0,"",($B$10/T$10)*T25/T$8) -> 1.9574235 | V25: 0 | W25: =IF(V25=0,"",($B$10/V$10)*V25/V$8) | X25: 0 | Y25: =IF(X25=0,"",($B$10/X$10)*X25/X$8) | Z25: 0 | AA25: =IF(Z25=0,"",($B$10/Z$10)*Z25/Z$8) | AB25: 17112.662 | AC25: =IF(AB25=0,"",($B$10/AB$10)*AB25/AB$8) -> 0.77954469 | AD25: 25124.194 | AE25: =IF(AD25=0,"",($B$10/AD$10)*AD25/AD$8) -> 1.9 | AF25: 20781.895 | AG25: =IF(AF25=0,"",($B$10/AF$10)*AF25/AF$8) -> 1.62 | AI25: =IF(AH25=0,"",($B$10/AH$10)*AH25/AH$8) | AJ25: =E25*D25 -> 20781.895 | AK25: 1
A26: Projeto Arquitetônico | C26: vb | F26: Não Solicitado | G26: =IFERROR(AVERAGEIFS($H26:$AI26,H$12:AI$12,"Referência"),"") -> 7.203173 | H26: 0 | I26: =IF(H26=0,"",($B$10/H$10)*H26/H$8) | J26: 0 | K26: =IF(J26=0,"",($B$10/J$10)*J26/J$8) | L26: 0 | M26: =IF(L26=0,"",($B$10/L$10)*L26/L$8) | N26: 0 | O26: =IF(N26=0,"",($B$10/N$10)*N26/N$8) | P26: 74000 | Q26: =IF(P26=0,"",($B$10/P$10)*P26/P$8) -> 9.2176253 | R26: 0 | S26: =IF(R26=0,"",($B$10/R$10)*R26/R$8) | T26: 0 | U26: =IF(T26=0,"",($B$10/T$10)*T26/T$8) | V26: 82118 | W26: =IF(V26=0,"",($B$10/V$10)*V26/V$8) -> 8.1137224 | X26: 0 | Y26: =IF(X26=0,"",($B$10/X$10)*X26/X$8) | Z26: 30000 | AA26: =IF(Z26=0,"",($B$10/Z$10)*Z26/Z$8) -> 4.2781712 | AB26: 0 | AC26: =IF(AB26=0,"",($B$10/AB$10)*AB26/AB$8) | AD26: 0 | AE26: =IF(AD26=0,"",($B$10/AD$10)*AD26/AD$8) | AF26: 0 | AG26: =IF(AF26=0,"",($B$10/AF$10)*AF26/AF$8) | AI26: =IF(AH26=0,"",($B$10/AH$10)*AH26/AH$8) | AJ26: =E26*D26 -> 0 | AK26: 0
A27: Projeto Arquitetônico Legal | C27: vb | D27: 1 | E27: =$B$8*6.98 -> 89541.743 | F27: Estimado | G27: =IFERROR(AVERAGEIFS($H27:$AI27,H$12:AI$12,"Referência"),"") -> 9.3722888 | H27: 0 | I27: =IF(H27=0,"",($B$10/H$10)*H27/H$8) | J27: 0 | K27: =IF(J27=0,"",($B$10/J$10)*J27/J$8) | L27: 140000 | M27: =IF(L27=0,"",($B$10/L$10)*L27/L$8) -> 8.9726967 | N27: 0 | O27: =IF(N27=0,"",($B$10/N$10)*N27/N$8) | P27: 0 | Q27: =IF(P27=0,"",($B$10/P$10)*P27/P$8) | R27: 0 | S27: =IF(R27=0,"",($B$10/R$10)*R27/R$8) | T27: 0 | U27: =IF(T27=0,"",($B$10/T$10)*T27/T$8) | V27: 0 | W27: =IF(V27=0,"",($B$10/V$10)*V27/V$8) | X27: 40816 | Y27: =IF(X27=0,"",($B$10/X$10)*X27/X$8) -> 21.805779 | Z27: 31725 | AA27: =IF(Z27=0,"",($B$10/Z$10)*Z27/Z$8) -> 4.5241661 | AB27: 109345.52 | AC27: =IF(AB27=0,"",($B$10/AB$10)*AB27/AB$8) -> 4.9810907 | AD27: 118612.64 | AE27: =IF(AD27=0,"",($B$10/AD$10)*AD27/AD$8) -> 8.97 | AF27: 89541.743 | AG27: =IF(AF27=0,"",($B$10/AF$10)*AF27/AF$8) -> 6.98 | AI27: =IF(AH27=0,"",($B$10/AH$10)*AH27/AH$8) | AJ27: =E27*D27 -> 89541.743 | AK27: 1
A28: Projeto Arquitetônico Executivo | C28: vb | F28: Não Solicitado | G28: =IFERROR(AVERAGEIFS($H28:$AI28,H$12:AI$12,"Referência"),"") -> 5.9981799 | H28: 305000 | I28: =IF(H28=0,"",($B$10/H$10)*H28/H$8) -> 5.3114372 | J28: 0 | K28: =IF(J28=0,"",($B$10/J$10)*J28/J$8) | L28: 0 | M28: =IF(L28=0,"",($B$10/L$10)*L28/L$8) | N28: 0 | O28: =IF(N28=0,"",($B$10/N$10)*N28/N$8) | P28: 0 | Q28: =IF(P28=0,"",($B$10/P$10)*P28/P$8) | R28: 0 | S28: =IF(R28=0,"",($B$10/R$10)*R28/R$8) | T28: 0 | U28: =IF(T28=0,"",($B$10/T$10)*T28/T$8) | V28: 0 | W28: =IF(V28=0,"",($B$10/V$10)*V28/V$8) | X28: 0 | Y28: =IF(X28=0,"",($B$10/X$10)*X28/X$8) | Z28: 31725 | AA28: =IF(Z28=0,"",($B$10/Z$10)*Z28/Z$8) -> 4.5241661 | AB28: 108380.19 | AC28: =IF(AB28=0,"",($B$10/AB$10)*AB28/AB$8) -> 4.9371164 | AD28: 121918.46 | AE28: =IF(AD28=0,"",($B$10/AD$10)*AD28/AD$8) -> 9.22 | AF28: 0 | AG28: =IF(AF28=0,"",($B$10/AF$10)*AF28/AF$8) | AI28: =IF(AH28=0,"",($B$10/AH$10)*AH28/AH$8) | AJ28: =E28*D28 -> 0 | AK28: 0
A29: Projeto Arquitetônico interiores | C29: vb | D29: 1 | E29: =$B$8*5 -> 64141.65 | F29: Estimado | G29: =IFERROR(AVERAGEIFS($H29:$AI29,H$12:AI$12,"Referência"),"") -> 6.5208551 | H29: 660000 | I29: =IF(H29=0,"",($B$10/H$10)*H29/H$8) -> 11.493602 | J29: 0 | K29: =IF(J29=0,"",($B$10/J$10)*J29/J$8) | L29: 77500 | M29: =IF(L29=0,"",($B$10/L$10)*L29/L$8) -> 4.9670285 | N29: 0 | O29: =IF(N29=0,"",($B$10/N$10)*N29/N$8) | P29: 0 | Q29: =IF(P29=0,"",($B$10/P$10)*P29/P$8) | R29: 0 | S29: =IF(R29=0,"",($B$10/R$10)*R29/R$8) | T29: 0 | U29: =IF(T29=0,"",($B$10/T$10)*T29/T$8) | V29: 0 | W29: =IF(V29=0,"",($B$10/V$10)*V29/V$8) | X29: 0 | Y29: =IF(X29=0,"",($B$10/X$10)*X29/X$8) | Z29: 14100 | AA29: =IF(Z29=0,"",($B$10/Z$10)*Z29/Z$8) -> 2.0107405 | AB29: 234531.22 | AC29: =IF(AB29=0,"",($B$10/AB$10)*AB29/AB$8) -> 10.68376 | AD29: 65719.602 | AE29: =IF(AD29=0,"",($B$10/AD$10)*AD29/AD$8) -> 4.97 | AF29: 64141.65 | AG29: =IF(AF29=0,"",($B$10/AF$10)*AF29/AF$8) -> 5 | AI29: =IF(AH29=0,"",($B$10/AH$10)*AH29/AH$8) | AJ29: =E29*D29 -> 64141.65 | AK29: 1
A30: Projeto arquitetônico de fachada | C30: vb | F30: Não Solicitado | G30: =IFERROR(AVERAGEIFS($H30:$AI30,H$12:AI$12,"Referência"),"") -> 1.1427206 | H30: 0 | I30: =IF(H30=0,"",($B$10/H$10)*H30/H$8) | J30: 11513.878 | K30: =IF(J30=0,"",($B$10/J$10)*J30/J$8) -> 0.56791754 | L30: 0 | M30: =IF(L30=0,"",($B$10/L$10)*L30/L$8) | N30: 0 | O30: =IF(N30=0,"",($B$10/N$10)*N30/N$8) | P30: 0 | Q30: =IF(P30=0,"",($B$10/P$10)*P30/P$8) | R30: 0 | S30: =IF(R30=0,"",($B$10/R$10)*R30/R$8) | T30: 0 | U30: =IF(T30=0,"",($B$10/T$10)*T30/T$8) | V30: 0 | W30: =IF(V30=0,"",($B$10/V$10)*V30/V$8) | X30: 0 | Y30: =IF(X30=0,"",($B$10/X$10)*X30/X$8) | Z30: 14100 | AA30: =IF(Z30=0,"",($B$10/Z$10)*Z30/Z$8) -> 2.0107405 | AB30: 18648.414 | AC30: =IF(AB30=0,"",($B$10/AB$10)*AB30/AB$8) -> 0.84950383 | AD30: 0 | AE30: =IF(AD30=0,"",($B$10/AD$10)*AD30/AD$8) | AF30: 0 | AG30: =IF(AF30=0,"",($B$10/AF$10)*AF30/AF$8) | AI30: =IF(AH30=0,"",($B$10/AH$10)*AH30/AH$8) | AJ30: =E30*D30 -> 0 | AK30: 0
A31: Projeto técnico de fachada | C31: vb | F31: Não Solicitado | G31: =IFERROR(AVERAGEIFS($H31:$AI31,H$12:AI$12,"Referência"),"") -> 0.80753011 | H31: 0 | I31: =IF(H31=0,"",($B$10/H$10)*H31/H$8) | J31: 4500 | K31: =IF(J31=0,"",($B$10/J$10)*J31/J$8) -> 0.22196075 | L31: 0 | M31: =IF(L31=0,"",($B$10/L$10)*L31/L$8) | N31: 0 | O31: =IF(N31=0,"",($B$10/N$10)*N31/N$8) | P31: 0 | Q31: =IF(P31=0,"",($B$10/P$10)*P31/P$8) | R31: 0 | S31: =IF(R31=0,"",($B$10/R$10)*R31/R$8) | T31: 0 | U31: =IF(T31=0,"",($B$10/T$10)*T31/T$8) | V31: 0 | W31: =IF(V31=0,"",($B$10/V$10)*V31/V$8) | X31: 0 | Y31: =IF(X31=0,"",($B$10/X$10)*X31/X$8) | Z31: 14100 | AA31: =IF(Z31=0,"",($B$10/Z$10)*Z31/Z$8) -> 2.0107405 | AB31: 4168.4689 | AC31: =IF(AB31=0,"",($B$10/AB$10)*AB31/AB$8) -> 0.18988909 | AD31: 0 | AE31: =IF(AD31=0,"",($B$10/AD$10)*AD31/AD$8) | AF31: 0 | AG31: =IF(AF31=0,"",($B$10/AF$10)*AF31/AF$8) | AI31: =IF(AH31=0,"",($B$10/AH$10)*AH31/AH$8) | AJ31: =E31*D31 -> 0 | AK31: 0
A32: Projetos - Estrutural | E32: =SUMPRODUCT(D33:D37,E33:E37) -> 104294.32 | I32: =IF(H32=0,"",($B$10/H$10)*H32/H$8) | K32: =IF(J32=0,"",($B$10/J$10)*J32/J$8) | M32: =IF(L32=0,"",($B$10/L$10)*L32/L$8) | O32: =IF(N32=0,"",($B$10/N$10)*N32/N$8) | Q32: =IF(P32=0,"",($B$10/P$10)*P32/P$8) | S32: =IF(R32=0,"",($B$10/R$10)*R32/R$8) | U32: =IF(T32=0,"",($B$10/T$10)*T32/T$8) | W32: =IF(V32=0,"",($B$10/V$10)*V32/V$8) | Y32: =IF(X32=0,"",($B$10/X$10)*X32/X$8) | AA32: =IF(Z32=0,"",($B$10/Z$10)*Z32/Z$8) | AC32: =IF(AB32=0,"",($B$10/AB$10)*AB32/AB$8) | AE32: =IF(AD32=0,"",($B$10/AD$10)*AD32/AD$8) | AG32: =IF(AF32=0,"",($B$10/AF$10)*AF32/AF$8) | AI32: =IF(AH32=0,"",($B$10/AH$10)*AH32/AH$8) | AK32: 0
A33: Projeto de terraplanagem | C33: vb | F33: Não Solicitado | G33: =IFERROR(AVERAGEIFS($H33:$AI33,H$12:AI$12,"Referência"),"") -> 0.16602333 | H33: 0 | I33: =IF(H33=0,"",($B$10/H$10)*H33/H$8) | J33: 1532.0642 | K33: =IF(J33=0,"",($B$10/J$10)*J33/J$8) -> 0.075568469 | L33: 0 | M33: =IF(L33=0,"",($B$10/L$10)*L33/L$8) | N33: 984.25197 | O33: =IF(N33=0,"",($B$10/N$10)*N33/N$8) -> 0.22779199 | P33: 1500 | Q33: =IF(P33=0,"",($B$10/P$10)*P33/P$8) -> 0.18684376 | R33: 0 | S33: =IF(R33=0,"",($B$10/R$10)*R33/R$8) | T33: 0 | U33: =IF(T33=0,"",($B$10/T$10)*T33/T$8) | V33: 0 | W33: =IF(V33=0,"",($B$10/V$10)*V33/V$8) | X33: 0 | Y33: =IF(X33=0,"",($B$10/X$10)*X33/X$8) | Z33: 0 | AA33: =IF(Z33=0,"",($B$10/Z$10)*Z33/Z$8) | AB33: 3290.8965 | AC33: =IF(AB33=0,"",($B$10/AB$10)*AB33/AB$8) -> 0.14991244 | AD33: 2512.4194 | AE33: =IF(AD33=0,"",($B$10/AD$10)*AD33/AD$8) -> 0.19 | AF33: 0 | AG33: =IF(AF33=0,"",($B$10/AF$10)*AF33/AF$8) | AI33: =IF(AH33=0,"",($B$10/AH$10)*AH33/AH$8) | AJ33: =E33*D33 -> 0 | AK33: 0
A34: Projeto de Fundação | C34: vb | D34: 1 | E34: =$B$8*1.9 -> 24373.827 | F34: Estimado | G34: =IFERROR(AVERAGEIFS($H34:$AI34,H$12:AI$12,"Referência"),"") -> 1.8759971 | H34: 61396 | I34: =IF(H34=0,"",($B$10/H$10)*H34/H$8) -> 1.0691836 | J34: 46064.489 | K34: =IF(J34=0,"",($B$10/J$10)*J34/J$8) -> 2.272113 | L34: 44600 | M34: =IF(L34=0,"",($B$10/L$10)*L34/L$8) -> 2.8584448 | N34: 0 | O34: =IF(N34=0,"",($B$10/N$10)*N34/N$8) | P34: 0 | Q34: =IF(P34=0,"",($B$10/P$10)*P34/P$8) | R34: 0 | S34: =IF(R34=0,"",($B$10/R$10)*R34/R$8) | T34: 0 | U34: =IF(T34=0,"",($B$10/T$10)*T34/T$8) | V34: 9600 | W34: =IF(V34=0,"",($B$10/V$10)*V34/V$8) -> 0.94853424 | X34: 0 | Y34: =IF(X34=0,"",($B$10/X$10)*X34/X$8) | Z34: 8000 | AA34: =IF(Z34=0,"",($B$10/Z$10)*Z34/Z$8) -> 1.1408457 | AB34: 43001.048 | AC34: =IF(AB34=0,"",($B$10/AB$10)*AB34/AB$8) -> 1.9588559 | AD34: 37818.524 | AE34: =IF(AD34=0,"",($B$10/AD$10)*AD34/AD$8) -> 2.86 | AF34: 24373.827 | AG34: =IF(AF34=0,"",($B$10/AF$10)*AF34/AF$8) -> 1.9 | AI34: =IF(AH34=0,"",($B$10/AH$10)*AH34/AH$8) | AJ34: =E34*D34 -> 24373.827 | AK34: 1
A35: Projeto estrutural | C35: vb | D35: 1 | E35: =$B$8*6.23 -> 79920.496 | F35: Estimado | G35: =IFERROR(AVERAGEIFS($H35:$AI35,H$12:AI$12,"Referência"),"") -> 6.8526819 | H35: 230000 | I35: =IF(H35=0,"",($B$10/H$10)*H35/H$8) -> 4.0053461 | J35: 0 | K35: =IF(J35=0,"",($B$10/J$10)*J35/J$8) | L35: 109543.5 | M35: =IF(L35=0,"",($B$10/L$10)*L35/L$8) -> 7.0207186 | N35: 0 | O35: =IF(N35=0,"",($B$10/N$10)*N35/N$8) | P35: 41100 | Q35: =IF(P35=0,"",($B$10/P$10)*P35/P$8) -> 5.1195189 | R35: 0 | S35: =IF(R35=0,"",($B$10/R$10)*R35/R$8) | T35: 287022.46 | U35: =IF(T35=0,"",($B$10/T$10)*T35/T$8) -> 16.015283 | V35: 55000 | W35: =IF(V35=0,"",($B$10/V$10)*V35/V$8) -> 5.4343107 | X35: 0 | Y35: =IF(X35=0,"",($B$10/X$10)*X35/X$8) | Z35: 58000 | AA35: =IF(Z35=0,"",($B$10/Z$10)*Z35/Z$8) -> 8.2711311 | AB35: 81614.233 | AC35: =IF(AB35=0,"",($B$10/AB$10)*AB35/AB$8) -> 3.7178285 | AD35: 77488.304 | AE35: =IF(AD35=0,"",($B$10/AD$10)*AD35/AD$8) -> 5.86 | AF35: 79920.496 | AG35: =IF(AF35=0,"",($B$10/AF$10)*AF35/AF$8) -> 6.23 | AI35: =IF(AH35=0,"",($B$10/AH$10)*AH35/AH$8) | AJ35: =E35*D35 -> 79920.496 | AK35: 1
A36: Projeto de estrutura metálica | C36: vb | F36: Não Solicitado | G36: =IFERROR(AVERAGEIFS($H36:$AI36,H$12:AI$12,"Referência"),"") | H36: 0 | I36: =IF(H36=0,"",($B$10/H$10)*H36/H$8) | J36: 0 | K36: =IF(J36=0,"",($B$10/J$10)*J36/J$8) | L36: 0 | M36: =IF(L36=0,"",($B$10/L$10)*L36/L$8) | N36: 0 | O36: =IF(N36=0,"",($B$10/N$10)*N36/N$8) | P36: 0 | Q36: =IF(P36=0,"",($B$10/P$10)*P36/P$8) | R36: 0 | S36: =IF(R36=0,"",($B$10/R$10)*R36/R$8) | T36: 0 | U36: =IF(T36=0,"",($B$10/T$10)*T36/T$8) | V36: 0 | W36: =IF(V36=0,"",($B$10/V$10)*V36/V$8) | X36: 0 | Y36: =IF(X36=0,"",($B$10/X$10)*X36/X$8) | Z36: 0 | AA36: =IF(Z36=0,"",($B$10/Z$10)*Z36/Z$8) | AB36: 0 | AC36: =IF(AB36=0,"",($B$10/AB$10)*AB36/AB$8) | AD36: 0 | AE36: =IF(AD36=0,"",($B$10/AD$10)*AD36/AD$8) | AF36: 0 | AG36: =IF(AF36=0,"",($B$10/AF$10)*AF36/AF$8) | AI36: =IF(AH36=0,"",($B$10/AH$10)*AH36/AH$8) | AJ36: =E36*D36 -> 0 | AK36: 0
A37: Projeto de alvenaria estrutural | C37: vb | F37: Não Solicitado | G37: =IFERROR(AVERAGEIFS($H37:$AI37,H$12:AI$12,"Referência"),"") | H37: 0 | I37: =IF(H37=0,"",($B$10/H$10)*H37/H$8) | J37: 0 | K37: =IF(J37=0,"",($B$10/J$10)*J37/J$8) | L37: 0 | M37: =IF(L37=0,"",($B$10/L$10)*L37/L$8) | N37: 0 | O37: =IF(N37=0,"",($B$10/N$10)*N37/N$8) | P37: 0 | Q37: =IF(P37=0,"",($B$10/P$10)*P37/P$8) | R37: 0 | S37: =IF(R37=0,"",($B$10/R$10)*R37/R$8) | T37: 0 | U37: =IF(T37=0,"",($B$10/T$10)*T37/T$8) | V37: 0 | W37: =IF(V37=0,"",($B$10/V$10)*V37/V$8) | X37: 0 | Y37: =IF(X37=0,"",($B$10/X$10)*X37/X$8) | Z37: 0 | AA37: =IF(Z37=0,"",($B$10/Z$10)*Z37/Z$8) | AB37: 0 | AC37: =IF(AB37=0,"",($B$10/AB$10)*AB37/AB$8) | AD37: 0 | AE37: =IF(AD37=0,"",($B$10/AD$10)*AD37/AD$8) | AF37: 0 | AG37: =IF(AF37=0,"",($B$10/AF$10)*AF37/AF$8) | AI37: =IF(AH37=0,"",($B$10/AH$10)*AH37/AH$8) | AJ37: =E37*D37 -> 0 | AK37: 0
A38: Projetos - Complementares | E38: =SUMPRODUCT(D39:D58,E39:E58) -> 85244.253 | I38: =IF(H38=0,"",($B$10/H$10)*H38/H$8) | K38: =IF(J38=0,"",($B$10/J$10)*J38/J$8) | M38: =IF(L38=0,"",($B$10/L$10)*L38/L$8) | O38: =IF(N38=0,"",($B$10/N$10)*N38/N$8) | Q38: =IF(P38=0,"",($B$10/P$10)*P38/P$8) | S38: =IF(R38=0,"",($B$10/R$10)*R38/R$8) | U38: =IF(T38=0,"",($B$10/T$10)*T38/T$8) | W38: =IF(V38=0,"",($B$10/V$10)*V38/V$8) | Y38: =IF(X38=0,"",($B$10/X$10)*X38/X$8) | AA38: =IF(Z38=0,"",($B$10/Z$10)*Z38/Z$8) | AC38: =IF(AB38=0,"",($B$10/AB$10)*AB38/AB$8) | AE38: =IF(AD38=0,"",($B$10/AD$10)*AD38/AD$8) | AG38: =IF(AF38=0,"",($B$10/AF$10)*AF38/AF$8) | AI38: =IF(AH38=0,"",($B$10/AH$10)*AH38/AH$8) | AK38: 0
A39: Projeto elétrico/comunicação/telefonia/luminotécnico | C39: vb | F39: Não Solicitado | G39: =IFERROR(AVERAGEIFS($H39:$AI39,H$12:AI$12,"Referência"),"") -> 5.339256 | H39: 440000 | I39: =IF(H39=0,"",($B$10/H$10)*H39/H$8) -> 7.6624012 | J39: 0 | K39: =IF(J39=0,"",($B$10/J$10)*J39/J$8) | L39: 0 | M39: =IF(L39=0,"",($B$10/L$10)*L39/L$8) | N39: 0 | O39: =IF(N39=0,"",($B$10/N$10)*N39/N$8) | P39: 0 | Q39: =IF(P39=0,"",($B$10/P$10)*P39/P$8) | R39: 0 | S39: =IF(R39=0,"",($B$10/R$10)*R39/R$8) | T39: 0 | U39: =IF(T39=0,"",($B$10/T$10)*T39/T$8) | V39: 0 | W39: =IF(V39=0,"",($B$10/V$10)*V39/V$8) | X39: 0 | Y39: =IF(X39=0,"",($B$10/X$10)*X39/X$8) | Z39: 21150 | AA39: =IF(Z39=0,"",($B$10/Z$10)*Z39/Z$8) -> 3.0161107 | AB39: 0 | AC39: =IF(AB39=0,"",($B$10/AB$10)*AB39/AB$8) | AD39: 0 | AE39: =IF(AD39=0,"",($B$10/AD$10)*AD39/AD$8) | AF39: 0 | AG39: =IF(AF39=0,"",($B$10/AF$10)*AF39/AF$8) | AI39: =IF(AH39=0,"",($B$10/AH$10)*AH39/AH$8) | AJ39: =E39*D39 -> 0 | AK39: 0
A40: Projeto elétrico/comunicação/telefonia | C40: vb | D40: 1 | E40: =$B$8*2.49 -> 31942.542 | F40: Estimado | G40: =IFERROR(AVERAGEIFS($H40:$AI40,H$12:AI$12,"Referência"),"") -> 3.630328 | H40: 440000 | I40: =IF(H40=0,"",($B$10/H$10)*H40/H$8) -> 7.6624012 | J40: 0 | K40: =IF(J40=0,"",($B$10/J$10)*J40/J$8) | L40: 38900 | M40: =IF(L40=0,"",($B$10/L$10)*L40/L$8) -> 2.4931279 | N40: 0 | O40: =IF(N40=0,"",($B$10/N$10)*N40/N$8) | P40: 0 | Q40: =IF(P40=0,"",($B$10/P$10)*P40/P$8) | R40: 0 | S40: =IF(R40=0,"",($B$10/R$10)*R40/R$8) | T40: 0 | U40: =IF(T40=0,"",($B$10/T$10)*T40/T$8) | V40: 0 | W40: =IF(V40=0,"",($B$10/V$10)*V40/V$8) | X40: 0 | Y40: =IF(X40=0,"",($B$10/X$10)*X40/X$8) | Z40: 21150 | AA40: =IF(Z40=0,"",($B$10/Z$10)*Z40/Z$8) -> 3.0161107 | AB40: 0 | AC40: =IF(AB40=0,"",($B$10/AB$10)*AB40/AB$8) | AD40: 32925.917 | AE40: =IF(AD40=0,"",($B$10/AD$10)*AD40/AD$8) -> 2.49 | AF40: 31942.542 | AG40: =IF(AF40=0,"",($B$10/AF$10)*AF40/AF$8) -> 2.49 | AI40: =IF(AH40=0,"",($B$10/AH$10)*AH40/AH$8) | AJ40: =E40*D40 -> 31942.542 | AK40: 1
...

Sheet ESQUADRIAS
A1: Obra | B1: ='Obra '!D1 -> Brisa da armação
A2: Empresa | B2: ='Obra '!D2 -> HACASA
A3: Revisão | B3: ='Obra '!D3 -> R00 - Letícia
A4: LEVANTAMENTO ESQUADRIAS
A5: Aplicação | B5: Descrição do Material | C5: Largura (Cm) | D5: Altura (Cm) | E5: Total m2/m | F5: Total un | H5: Pavimentos | R5: Visus | V5: Fornecedor 1 | Y5: Fornecedor 2
H6: Térreo | I6: Garagem G1 | J6: Garagem G2 | K6: Garagem G3 | L6: Garagem G4 | M6: Tipo 01 (1x) | N6: Tipo 02 (11x) | O6: Tipo 03 (01x) | P6: Rooftop | R6: Largura (Cm) | S6: Altura (Cm) | T6: Total m2/m | V6: Custo Unitário | W6: Cuto Total | Y6: Custo Unitário | Z6: Cuto Total
H7: 1 | I7: 1 | J7: 1 | K7: 1 | L7: 1 | M7: 1 | N7: 11 | O7: 1 | P7: 1
A8: Porta Madeira | B8: P1 - PORTA DE ABRIR, 1 FOLHA, MADEIRA MACICA, 90 x 210 cm | C8: 0.9 | D8: 2.1 | E8: =IF(D8=0,SUMPRODUCT($H$7:$P$7,$H8:$P8)*(C8),SUMPRODUCT($H$7:$P$7,$H8:$P8)*(C8*D8)) -> 0 | F8: =SUMPRODUCT($H$7:$P$7,$H8:$P8) -> 0 | T8: 0 | W8: =V8*F8 -> 0 | Z8: =Y8*I8 -> 0
A9: Porta Madeira | B9: P2 - PORTA DE ABRIR, 1 FOLHA, MADEIRA SEMI-OCA, 80 x 210 cm | C9: 0.8 | D9: 2.1 | E9: =IF(D9=0,SUMPRODUCT($H$7:$P$7,$H9:$P9)*(C9),SUMPRODUCT($H$7:$P$7,$H9:$P9)*(C9*D9)) -> 0 | F9: =SUMPRODUCT($H$7:$P$7,$H9:$P9) -> 0 | T9: 0 | W9: =V9*F9 -> 0 | Z9: =Y9*I9 -> 0
A10: Porta Madeira | B10: P3 - PORTA DE ABRIR, 1 FOLHA, MADEIRA SEMI-OCA, 70 x 210 cm | C10: 0.7 | D10: 2.1 | E10: =IF(D10=0,SUMPRODUCT($H$7:$P$7,$H10:$P10)*(C10),SUMPRODUCT($H$7:$P$7,$H10:$P10)*(C10*D10)) -> 0 | F10: =SUMPRODUCT($H$7:$P$7,$H10:$P10) -> 0 | T10: 0 | W10: =V10*F10 -> 0 | Z10: =Y10*I10 -> 0
A11: Porta Madeira | B11: PORTA DE CORRER, 1 FOLHA, MADEIRA, 80 x 210 cm | C11: 0.8 | D11: 2.1 | E11: =IF(D11=0,SUMPRODUCT($H$7:$P$7,$H11:$P11)*(C11),SUMPRODUCT($H$7:$P$7,$H11:$P11)*(C11*D11)) -> 0 | F11: =SUMPRODUCT($H$7:$P$7,$H11:$P11) -> 0 | T11: 0 | W11: =V11*F11 -> 0 | Z11: =Y11*I11 -> 0
A12: Porta Madeira | E12: =IF(D12=0,SUMPRODUCT($H$7:$P$7,$H12:$P12)*(C12),SUMPRODUCT($H$7:$P$7,$H12:$P12)*(C12*D12)) -> 0 | F12: =SUMPRODUCT($H$7:$P$7,$H12:$P12) -> 0 | T12: 0 | W12: =V12*F12 -> 0 | Z12: =Y12*I12 -> 0
A13: Porta Madeira | E13: =IF(D13=0,SUMPRODUCT($H$7:$P$7,$H13:$P13)*(C13),SUMPRODUCT($H$7:$P$7,$H13:$P13)*(C13*D13)) -> 0 | F13: =SUMPRODUCT($H$7:$P$7,$H13:$P13) -> 0 | T13: 0 | W13: =V13*F13 -> 0 | Z13: =Y13*I13 -> 0
A14: Corrimão Madeira (m) | B14: CORRIMÃO ESCADA_PAREDE - MADEIRA | E14: =IF(D14=0,SUMPRODUCT($H$7:$P$7,$H14:$P14)*(C14),SUMPRODUCT($H$7:$P$7,$H14:$P14)*(C14*D14)) -> 0 | F14: =SUMPRODUCT($H$7:$P$7,$H14:$P14) -> 0 | T14: 0 | W14: =V14*F14 -> 0 | Z14: =Y14*I14 -> 0
A15: Corrimão Madeira (m) | E15: =IF(D15=0,SUMPRODUCT($H$7:$P$7,$H15:$P15)*(C15),SUMPRODUCT($H$7:$P$7,$H15:$P15)*(C15*D15)) -> 0 | F15: =SUMPRODUCT($H$7:$P$7,$H15:$P15) -> 0 | T15: 0 | W15: =V15*F15 -> 0 | Z15: =Y15*I15 -> 0
A16: Corrimão Madeira (m) | E16: =IF(D16=0,SUMPRODUCT($H$7:$P$7,$H16:$P16)*(C16),SUMPRODUCT($H$7:$P$7,$H16:$P16)*(C16*D16)) -> 0 | F16: =SUMPRODUCT($H$7:$P$7,$H16:$P16) -> 0 | T16: 0 | W16: =V16*F16 -> 0 | Z16: =Y16*I16 -> 0
A17: Corrimão Madeira (m) | E17: =IF(D17=0,SUMPRODUCT($H$7:$P$7,$H17:$P17)*(C17),SUMPRODUCT($H$7:$P$7,$H17:$P17)*(C17*D17)) -> 0 | F17: =SUMPRODUCT($H$7:$P$7,$H17:$P17) -> 0 | T17: 0 | W17: =V17*F17 -> 0 | Z17: =Y17*I17 -> 0
A18: Corrimão Madeira (m) | E18: =IF(D18=0,SUMPRODUCT($H$7:$P$7,$H18:$P18)*(C18),SUMPRODUCT($H$7:$P$7,$H18:$P18)*(C18*D18)) -> 0 | F18: =SUMPRODUCT($H$7:$P$7,$H18:$P18) -> 0 | T18: 0 | W18: =V18*F18 -> 0 | Z18: =Y18*I18 -> 0
A19: Corrimão Madeira (m) | E19: =IF(D19=0,SUMPRODUCT($H$7:$P$7,$H19:$P19)*(C19),SUMPRODUCT($H$7:$P$7,$H19:$P19)*(C19*D19)) -> 0 | F19: =SUMPRODUCT($H$7:$P$7,$H19:$P19) -> 0 | T19: 0 | W19: =V19*F19 -> 0 | Z19: =Y19*I19 -> 0
A20: Corrimão Madeira (m) | E20: =IF(D20=0,SUMPRODUCT($H$7:$P$7,$H20:$P20)*(C20),SUMPRODUCT($H$7:$P$7,$H20:$P20)*(C20*D20)) -> 0 | F20: =SUMPRODUCT($H$7:$P$7,$H20:$P20) -> 0 | T20: 0 | W20: =V20*F20 -> 0 | Z20: =Y20*I20 -> 0
A21: Brise de Madeira (m) | B21: BRISE DE MADEIRA VERTICAL - 140 cm | C21: 1.4 | E21: =IF(D21=0,SUMPRODUCT($H$7:$P$7,$H21:$P21)*(C21),SUMPRODUCT($H$7:$P$7,$H21:$P21)*(C21*D21)) -> 0 | F21: =SUMPRODUCT($H$7:$P$7,$H21:$P21) -> 0 | W21: =V21*E21 -> 0 | Z21: =Y21*I21 -> 0
A22: Brise de Madeira (m) | B22: BRISE DE MADEIRA VERTICAL - 156 cm | C22: 1.56 | E22: =IF(D22=0,SUMPRODUCT($H$7:$P$7,$H22:$P22)*(C22),SUMPRODUCT($H$7:$P$7,$H22:$P22)*(C22*D22)) -> 0 | F22: =SUMPRODUCT($H$7:$P$7,$H22:$P22) -> 0 | W22: =V22*E22 -> 0 | Z22: =Y22*I22 -> 0
A23: Brise de Madeira (m) | B23: BRISE DE MADEIRA VERTICAL - 282 cm | C23: 2.82 | E23: =IF(D23=0,SUMPRODUCT($H$7:$P$7,$H23:$P23)*(C23),SUMPRODUCT($H$7:$P$7,$H23:$P23)*(C23*D23)) -> 0 | F23: =SUMPRODUCT($H$7:$P$7,$H23:$P23) -> 0 | W23: =V23*E23 -> 0 | Z23: =Y23*I23 -> 0
A24: Brise de Madeira (m) | B24: BRISE DE MADEIRA VERTICAL - 291 cm | C24: 2.91 | E24: =IF(D24=0,SUMPRODUCT($H$7:$P$7,$H24:$P24)*(C24),SUMPRODUCT($H$7:$P$7,$H24:$P24)*(C24*D24)) -> 0 | F24: =SUMPRODUCT($H$7:$P$7,$H24:$P24) -> 0 | W24: =V24*E24 -> 0 | Z24: =Y24*I24 -> 0
A25: Brise de Madeira (m) | B25: BRISE DE MADEIRA VERTICAL - 396 cm | C25: 3.96 | E25: =IF(D25=0,SUMPRODUCT($H$7:$P$7,$H25:$P25)*(C25),SUMPRODUCT($H$7:$P$7,$H25:$P25)*(C25*D25)) -> 0 | F25: =SUMPRODUCT($H$7:$P$7,$H25:$P25) -> 0 | W25: =V25*E25 -> 0 | Z25: =Y25*I25 -> 0
A26: Brise de Madeira (m) | B26: BRISE DE MADEIRA VERTICAL - 406 cm | C26: 4.06 | E26: =IF(D26=0,SUMPRODUCT($H$7:$P$7,$H26:$P26)*(C26),SUMPRODUCT($H$7:$P$7,$H26:$P26)*(C26*D26)) -> 0 | F26: =SUMPRODUCT($H$7:$P$7,$H26:$P26) -> 0 | W26: =V26*E26 -> 0 | Z26: =Y26*I26 -> 0
A27: Brise de Madeira (m) | B27: BRISE DE MADEIRA VERTICAL - 71 cm | C27: 71 | E27: =IF(D27=0,SUMPRODUCT($H$7:$P$7,$H27:$P27)*(C27),SUMPRODUCT($H$7:$P$7,$H27:$P27)*(C27*D27)) -> 0 | F27: =SUMPRODUCT($H$7:$P$7,$H27:$P27) -> 0 | W27: =V27*E27 -> 0 | Z27: =Y27*I27 -> 0
A28: Brise de Madeira (m) | B28: BRISE DE MADEIRA VERTICAL - 96 cm | C28: 0.96 | E28: =IF(D28=0,SUMPRODUCT($H$7:$P$7,$H28:$P28)*(C28),SUMPRODUCT($H$7:$P$7,$H28:$P28)*(C28*D28)) -> 0 | F28: =SUMPRODUCT($H$7:$P$7,$H28:$P28) -> 0 | W28: =V28*E28 -> 0 | Z28: =Y28*I28 -> 0
A29: Brise de Madeira (m) | E29: =IF(D29=0,SUMPRODUCT($H$7:$P$7,$H29:$P29)*(C29),SUMPRODUCT($H$7:$P$7,$H29:$P29)*(C29*D29)) -> 0 | F29: =SUMPRODUCT($H$7:$P$7,$H29:$P29) -> 0 | W29: =V29*E29 -> 0 | Z29: =Y29*I29 -> 0
A30: ContraMarco | B30: CONTRAMARCO | E30: =IF(D30=0,SUMPRODUCT($H$7:$P$7,$H30:$P30)*(C30),SUMPRODUCT($H$7:$P$7,$H30:$P30)*(C30*D30)) -> 0 | F30: =SUMPRODUCT($H$7:$P$7,$H30:$P30) -> 0 | W30: =V30*F30 -> 0 | Z30: =Y30*I30 -> 0
A31: ContraMarco | E31: =IF(D31=0,SUMPRODUCT($H$7:$P$7,$H31:$P31)*(C31),SUMPRODUCT($H$7:$P$7,$H31:$P31)*(C31*D31)) -> 0 | F31: =SUMPRODUCT($H$7:$P$7,$H31:$P31) -> 0 | W31: =V31*F31 -> 0 | Z31: =Y31*I31 -> 0
A32: ContraMarco | E32: =IF(D32=0,SUMPRODUCT($H$7:$P$7,$H32:$P32)*(C32),SUMPRODUCT($H$7:$P$7,$H32:$P32)*(C32*D32)) -> 0 | F32: =SUMPRODUCT($H$7:$P$7,$H32:$P32) -> 0 | W32: =V32*F32 -> 0 | Z32: =Y32*I32 -> 0
A33: ContraMarco | E33: =IF(D33=0,SUMPRODUCT($H$7:$P$7,$H33:$P33)*(C33),SUMPRODUCT($H$7:$P$7,$H33:$P33)*(C33*D33)) -> 0 | F33: =SUMPRODUCT($H$7:$P$7,$H33:$P33) -> 0 | W33: =V33*F33 -> 0 | Z33: =Y33*I33 -> 0
A34: ContraMarco | E34: =IF(D34=0,SUMPRODUCT($H$7:$P$7,$H34:$P34)*(C34),SUMPRODUCT($H$7:$P$7,$H34:$P34)*(C34*D34)) -> 0 | F34: =SUMPRODUCT($H$7:$P$7,$H34:$P34) -> 0 | W34: =V34*F34 -> 0 | Z34: =Y34*I34 -> 0
A35: Portões Alumínio | E35: =IF(D35=0,SUMPRODUCT($H$7:$P$7,$H35:$P35)*(C35),SUMPRODUCT($H$7:$P$7,$H35:$P35)*(C35*D35)) -> 0 | F35: =SUMPRODUCT($H$7:$P$7,$H35:$P35) -> 0 | W35: =V35*F35 -> 0 | Z35: =Y35*F35 -> 0
A36: Portões Alumínio | E36: =IF(D36=0,SUMPRODUCT($H$7:$P$7,$H36:$P36)*(C36),SUMPRODUCT($H$7:$P$7,$H36:$P36)*(C36*D36)) -> 0 | F36: =SUMPRODUCT($H$7:$P$7,$H36:$P36) -> 0 | W36: =V36*F36 -> 0 | Z36: =Y36*F36 -> 0
A37: Portões Alumínio | E37: =IF(D37=0,SUMPRODUCT($H$7:$P$7,$H37:$P37)*(C37),SUMPRODUCT($H$7:$P$7,$H37:$P37)*(C37*D37)) -> 0 | F37: =SUMPRODUCT($H$7:$P$7,$H37:$P37) -> 0 | W37: =V37*F37 -> 0 | Z37: =Y37*F37 -> 0
A38: Portões Alumínio | E38: =IF(D38=0,SUMPRODUCT($H$7:$P$7,$H38:$P38)*(C38),SUMPRODUCT($H$7:$P$7,$H38:$P38)*(C38*D38)) -> 0 | F38: =SUMPRODUCT($H$7:$P$7,$H38:$P38) -> 0 | W38: =V38*F38 -> 0 | Z38: =Y38*F38 -> 0
A39: Portas Alumínio | B39: P5 - PORTA DE ABRIR, 1 FOLHA, VIDRO E ALUMINIO, 80 x 210 cm | C39: 0.8 | D39: 2.1 | E39: =IF(D39=0,SUMPRODUCT($H$7:$P$7,$H39:$P39)*(C39),SUMPRODUCT($H$7:$P$7,$H39:$P39)*(C39*D39)) -> 0 | F39: =SUMPRODUCT($H$7:$P$7,$H39:$P39) -> 0 | W39: =V39*F39 -> 0 | Z39: =Y39*F39 -> 0
A40: Portas Alumínio | B40: P6 - PORTA DE ABRIR, 1 FOLHA, ALUMINIO VENEZIANA, 60 x 210 cm | C40: 0.6 | D40: 2.1 | E40: =IF(D40=0,SUMPRODUCT($H$7:$P$7,$H40:$P40)*(C40),SUMPRODUCT($H$7:$P$7,$H40:$P40)*(C40*D40)) -> 0 | F40: =SUMPRODUCT($H$7:$P$7,$H40:$P40) -> 0 | W40: =V40*F40 -> 0 | Z40: =Y40*F40 -> 0
...

Sheet MOBILIÁRIO
B1: Obra | C1: ='Obra '!D1 -> Brisa da armação
B2: Empresa | C2: ='Obra '!D2 -> HACASA
B3: Revisão | C3: ='Obra '!D3 -> R00 - Letícia
B4: LEVANTAMENTO MOBILIÁRIOS E EQUIPAMENTOS DE LAZER
B6: TOTAL PAVIMENTOS: | C6: =SUMPRODUCT($E$12:$E$163,$F$12:$F$163) -> 1669247.2
B7: ÁREA TOTAL: | C7: =SUMIFS($E$11:$E$163,$D$11:$D$163,"Área: ") -> 956.51
B8: CUSTO ACABAMENTOS ESPECIAIS: | C8: =SUMIFS($G$11:$G$163,$D$11:$D$163,"Acabamentos Especiais") -> 419472
B9: CUSTO/ M2 | C9: =C6/C7 -> 1745.1434
B11: Pavimento | C11: Ambiente | D11: Descrição | E11: Quantidade (un) | F11: Preço Unitário | G11: Preço Total | H11: Observações
B12: TERREO | G12: =SUM(G13:G18)/2 -> 56703
B13: =B12 -> TERREO | C13: Hall Principal | D13: Área: | E13: 30.5 | G13: =SUM(G14:G18) -> 56703
B14: =B13 -> TERREO | C14: =C13 -> Hall Principal | D14: Acabamentos Especiais | E14: =E13 -> 30.5 | F14: 450 | G14: =E14*F14 -> 13725
B15: =B14 -> TERREO | C15: =C14 -> Hall Principal | D15: Poltrona Corda Estofada Algodão Estrutura em Madeira Amêndoa | E15: 6 | F15: 2033 | G15: =E15*F15 -> 12198
B16: =B15 -> TERREO | C16: =C15 -> Hall Principal | D16: Espelhos | E16: 1 | F16: 4800 | G16: =E16*F16 -> 4800
B17: =B16 -> TERREO | C17: =C16 -> Hall Principal | D17: Pendente Luminaria de trilho para teto | E17: 1 | F17: 980 | G17: =E17*F17 -> 980
B18: =B17 -> TERREO | C18: =C17 -> Hall Principal | D18: Marcenaria | E18: 1 | F18: 25000 | G18: =E18*F18 -> 25000
B19: =B18 -> TERREO | C19: Bike Share | D19: Área: | E19: 19.48 | G19: =SUM(G20:G23) -> 18450
B20: =B19 -> TERREO | C20: =C19 -> Bike Share | D20: Suporte de parede para bicicletas, gancho vertical, resistente suporta até 30 kg | E20: 7 | F20: 150 | G20: =E20*F20 -> 1050
B21: =B20 -> TERREO | C21: =C20 -> Bike Share | D21: Estação de Carregamento de Bike Elétrica, Carregador EV | E21: 1 | F21: 7500 | G21: =E21*F21 -> 7500
B22: =B21 -> TERREO | C22: =C21 -> Bike Share | D22: Divisória Aramada decoração | E22: 4 | F22: 1250 | G22: =E22*F22 -> 5000
B23: =B22 -> TERREO | C23: =C22 -> Bike Share | D23: Pendente Luminaria de trilho para teto | E23: 5 | F23: 980 | G23: =E23*F23 -> 4900
B24: =B23 -> TERREO | C24: Pranchário | D24: Área: | E24: 4.87 | G24: =SUM(G25:G25) -> 7890
B25: =B24 -> TERREO | C25: =C24 -> Pranchário | D25: Suporte de para Pranchas | E25: 1 | F25: 7890 | G25: =E25*F25 -> 7890
B26: =B25 -> TERREO | C26: Academia | D26: Área: | E26: 43.41 | G26: =SUM(G27:G41) -> 178255.5
B27: =B26 -> TERREO | C27: =C26 -> Academia | D27: Acabamentos Especiais | E27: =E26 -> 43.41 | F27: 450 | G27: =E27*F27 -> 19534.5
B28: =B27 -> TERREO | C28: =C27 -> Academia | D28: ESTEIRA ERGOMÉTRICA ATHLETIC NEW EXTREME 18 KM/H | E28: 3 | F28: 9000 | G28: =E28*F28 -> 27000
B29: =B28 -> TERREO | C29: =C28 -> Academia | D29: SPINNING ATHLETIC ADVANCED 2200BS | E29: 2 | F29: 3245 | G29: =E29*F29 -> 6490
B30: =B29 -> TERREO | C30: =C29 -> Academia | D30: ESTAÇÃO DE MUSCULAÇÃO ATHLETIC POWER PLUS | E30: 1 | F30: 62000 | G30: =E30*F30 -> 62000
B31: =B30 -> TERREO | C31: =C30 -> Academia | D31: Kit Banco Supino Reto Inclinado + 2x Barras 40cm + Barra 1,50m + 80kg anilhas em PVC | E31: 1 | F31: 3250 | G31: =E31*F31 -> 3250
B32: =B31 -> TERREO | C32: =C31 -> Academia | D32: Estação de Musculação e Banco Supino Gallant GBS1H03A-PT | E32: 1 | F32: 859 | G32: =E32*F32 -> 859
B33: =B32 -> TERREO | C33: =C32 -> Academia | D33: Kit Ketleball + suporte | E33: 1 | F33: 2650 | G33: =E33*F33 -> 2650
B34: =B33 -> TERREO | C34: =C33 -> Academia | D34: Tapete de yoga Asana - 4.5mm PVC ecológico - Ameixa | E34: 6 | F34: 150 | G34: =E34*F34 -> 900
B35: =B34 -> TERREO | C35: =C34 -> Academia | D35: Espelho | E35: 1 | F35: 3500 | G35: =E35*F35 -> 3500
B36: =B35 -> TERREO | C36: =C35 -> Academia | D36: Marcenaria | E36: 1 | F36: 35500 | G36: =E36*F36 -> 35500
B37: =B36 -> TERREO | C37: =C36 -> Academia | D37: Purificador Electrolux Água Gelada, Fria e Natural com Painel Easy Touch Cinza (PE11X) - Bivolt | E37: 1 | F37: 1250 | G37: =E37*F37 -> 1250
B38: =B37 -> TERREO | C38: =C37 -> Academia | D38: Kit Fitness 20kg + 2 Barras 40cm Rosca + 1 Barra 120cm Presilhas | E38: 2 | F38: 1200 | G38: =E38*F38 -> 2400
B39: =B38 -> TERREO | C39: =C38 -> Academia | D39: Kit Halteres Ajustáveis Com Rosca 20kg - Top! | E39: 10 | F39: 450 | G39: =E39*F39 -> 4500
... B41: =B40 -> TERREO | C41: =C40 -> Academia | D41: SUPORTE TORRE EXPOSITOR PARA 20 HALTERES DE 01KG A 10KG | E41: 1 | F41: 1562 | G41: =E41*F41 -> 1562
B42: =B41 -> TERREO | C42: Lavanderia | D42: Área: | E42: 14.42 | G42: =SUM(G43:G48) -> 105846.03
B43: =B42 -> TERREO | C43: =C42 -> Lavanderia | D43: Acabamentos Especiais | E43: =E42 -> 14.42 | F43: 450 | G43: =E43*F43 -> 6489
...

Sheet Ger_Tec e Adm
G4: PROJETO: | I4: ='Obra '!D1 -> Brisa da armação | O4: REVISÃO: | P4: DATA
G5: EMPRESA: | I5: ='Obra '!D2 -> HACASA | O5: ='Obra '!D3 -> R00 - Letícia | P5: 45728
A6: Unidade Construtiva | B6: Célula Construtiva | C6: Etapa | D6: Subetapa | E6: Serviço | G6: GERENCIAMENTO EXECUTIVO
A7: 0 | B7: 0 | C7: 0 | D7: 0 | E7: 0 | G7: Atalho | H7: NIVEL | I7: Item | J7: Descrição | K7: Unidade | L7: Quant. | M7: Preço un | N7: Total | O7: Considerações | P7: Situação
A8: =IF($H8="UNIDADE CONSTRUTIVA",OFFSET(A8,-1,0)+1,LARGE(A$3:A7,1)) -> 0 | B8: =IF(H8="UNIDADE CONSTRUTIVA",0,IF(H8="CÉLULA CONSTRUTIVA",OFFSET(B8,-1,0)+1,OFFSET(B8,-1,0))) -> 1 | C8: =IF(H8="CÉLULA CONSTRUTIVA",0,IF(H8="ETAPA",OFFSET(C8,-1,0)+1,OFFSET(C8,-1,0))) -> 0 | D8: =IF(H8="ETAPA",0,IF(H8="SUBETAPA",OFFSET(D8,-1,0)+1,OFFSET(D8,-1,0))) -> 0 | E8: =IF(H8="Subetapa",0,IF(H8="serviço",OFFSET(E8,-1,0)+1,OFFSET(E8,-1,0))) -> 0 | H8: CÉLULA CONSTRUTIVA | I8: =IF(H8="Unidade Construtiva",TEXT(A8,"00"),IF(H8="Célula Construtiva",TEXT(B8,"00"),IF(H8="Etapa",CONCATENATE(TEXT(B8,"00"),".",TEXT(C8,"000")),IF(H8="Subetapa",CONCATENATE(TEXT(B8,"00"),".",TEXT(C8,"000"),".",TEXT(D8,"000")),IF(H8="Serviço",CONCATENATE(TEXT(B8,"00"),".",TEXT(C8,"000"),".",TEXT(D8,"000"),".",TEXT(E8,"000")),""))))) -> 01 | J8: SERVIÇOS TÉCNICOS | N8: =IF(H8="Serviço",M8*L8,IF(H8="CÉLULA CONSTRUTIVA",SUMIFS($N$8:$N$417,$B$8:$B$417,B8,$H$8:$H$417,"Serviço"),IF(H8="ETAPA",SUMIFS($N$8:$N$417,$B$8:$B$417,B8,$C$8:$C$417,C8,$H$8:$H$417,"Serviço"),IF(H8="SUBETAPA",SUMIFS($N$8:$N$417,$B$8:$B$417,B8,$C$8:$C$417,C8,$D$8:$D$417,D8,$H$8:$H$417,"Serviço"),0)))) -> 586319.4 | P8: -
