Workbook

Sheet Orçamento Resumo
A1: Etapa | B1: Valor Orçado | C1: % | D1: Valor / m²
A2: GERENCIAMENTO TÉCNICO E ADMINISTRATIVO | B2: 1356858.9 | C2: =+B2/$B$20 -> 0.094639055 | D2: =B2/$H$5 -> 305.56444
A3: MOVIMENTAÇÃO DE TERRA | B3: ='Planilha2 (2)'!K7 -> 19982.12 | C3: =+B3/$B$20 -> 0.0013937256 | D3: =B3/$H$5 -> 4.4999707
A4: INFRAESTRUTURA | B4: ='Planilha2 (2)'!K8 -> 1068053.1 | C4: =+B4/$B$20 -> 0.074495247 | D4: =B4/$H$5 -> 240.52542
A5: SUPRAESTRUTURA | B5: ='Planilha2 (2)'!K9 -> 1410081.3 | C5: =+B5/$B$20 -> 0.098351243 | D5: =B5/$H$5 -> 317.55012 | H5: 4440.5
A6: ALVENARIA, VEDAÇÕES E DIVISÓRIAS | B6: ='Planilha2 (2)'!K10 -> 1423157.3 | C6: =+B6/$B$20 -> 0.099263275 | D6: =B6/$H$5 -> 320.49482
A7: INSTALAÇÕES ELÉTRICAS, HIDROSSANITÁRIAS, PREVENTIVAS E GLP | B7: ='Planilha2 (2)'!K11+'Planilha2 (2)'!K12+'Planilha2 (2)'!K14 -> 1826248.5 | C7: =+B7/$B$20 -> 0.12737834 | D7: =B7/$H$5 -> 411.27092 | H7: 64
A8: LOUÇAS E METAIS | B8: ='Planilha2 (2)'!K13 -> 106062.57 | C8: =+B8/$B$20 -> 0.0073977193 | D8: =B8/$H$5 -> 23.885276
A9: SISTEMAS ESPECIAIS E EQUIPAMENTOS | B9: ='Planilha2 (2)'!K15+'Planilha2 (2)'!K16 -> 1078142.8 | C9: =+B9/$B$20 -> 0.075198984 | D9: =B9/$H$5 -> 242.7976
A10: IMPERMEABILIZAÇÃO | B10: ='Planilha2 (2)'!K17 -> 322448.32 | C10: =+B10/$B$20 -> 0.02249033 | D10: =B10/$H$5 -> 72.615318
A11: REVESTIMENTOS INTERNOS EM PISO E PAREDE | B11: ='Planilha2 (2)'!K18 -> 1247304.6 | C11: =+B11/$B$20 -> 0.086997795 | D11: =B11/$H$5 -> 280.89284 | H11: área de ap | I11: 57.65
A12: REVESTIMENTOS E ACABAMENTOS INTERNOS EM TETO | B12: ='Planilha2 (2)'!K19 -> 456659.62 | C12: =+B12/$B$20 -> 0.031851385 | D12: =B12/$H$5 -> 102.83968
A13: ACABAMENTOS EM PISO E PAREDE | B13: ='Planilha2 (2)'!K20 -> 1194226.7 | C13: =+B13/$B$20 -> 0.083295681 | D13: =B13/$H$5 -> 268.93969 | F13: =180*1.1 -> 198
A14: PINTURA INTERNA | B14: ='Planilha2 (2)'!K21 -> 460055.52 | C14: =+B14/$B$20 -> 0.032088244 | D14: =B14/$H$5 -> 103.60444 | F14: =220*1.1 -> 242
A15: ESQUADRIAS | B15: ='Planilha2 (2)'!K22 -> 1041740 | C15: =+B15/$B$20 -> 0.072659944 | D15: =B15/$H$5 -> 234.59972
A16: REVESTIMENTOS E ACABAMENTOS DE FACHADA | B16: ='Planilha2 (2)'!K23 -> 534054.65 | C16: =+B16/$B$20 -> 0.037249582 | D16: =B16/$H$5 -> 120.26904
A17: MÃO DE OBRA PRÓPRIA | B17: ='Planilha2 (2)'!K6 -> 363462 | C17: =+B17/$B$20 -> 0.025350978 | D17: =B17/$H$5 -> 81.851593
A18: SERVIÇOS COMPLEMENTARES | B18: ='Planilha2 (2)'!K24-B19 -> 210941.5 | C18: =+B18/$B$20 -> 0.014712881 | D18: =B18/$H$5 -> 47.503997
A19: IMPREVISTOS E CONTINGÊNCIAS | B19: 217718.87 | C19: =+B19/$B$20 -> 0.015185594 | D19: =B19/$H$5 -> 49.03026
A20: TOTAL | B20: =SUM(B2:B19) -> 14337198 | C20: =SUM(C2:C19) -> 1 | D20: =SUM(D2:D19) -> 3228.7351
A21: CUB/MT | B21: 2591.01 | C21: 44991 | D21: =+D20/B21 -> 1.2461299

Sheet Análise custos
A1: Etapa | B1: Guanabara (R$/m²) | C1: Obras Similares
A2: ='Orçamento Resumo'!A3 -> MOVIMENTAÇÃO DE TERRA | B2: ='Orçamento Resumo'!D3 -> 4.4999707 | C2: 10,00 - 50,00 | D2: 10 | E2: 50
A3: ='Orçamento Resumo'!A4 -> INFRAESTRUTURA | B3: ='Orçamento Resumo'!D4 -> 240.52542 | C3: 170,00 - 250,00 | D3: 170 | E3: 250
A4: ='Orçamento Resumo'!A5 -> SUPRAESTRUTURA | B4: ='Orçamento Resumo'!D5 -> 317.55012 | C4: 320,00 - 380,00 | D4: 320 | E4: 380
A5: ='Orçamento Resumo'!A6 -> ALVENARIA, VEDAÇÕES E DIVISÓRIAS | B5: ='Orçamento Resumo'!D6 -> 320.49482 | C5: 200,00 - 300,00 | D5: 200 | E5: 300
A6: ='Orçamento Resumo'!A7 -> INSTALAÇÕES ELÉTRICAS, HIDROSSANITÁRIAS, PREVENTIVAS E GLP | B6: ='Orçamento Resumo'!D7 -> 411.27092 | C6: 300,00 - 400,00 | D6: 300 | E6: 400
A7: LOUÇAS E METAIS | B7: ='Orçamento Resumo'!D8 -> 23.885276 | C7: 15,00 - 30,00 | D7: 15 | E7: 30
A8: ='Orçamento Resumo'!A9 -> SISTEMAS ESPECIAIS E EQUIPAMENTOS | B8: ='Orçamento Resumo'!D9 -> 242.7976 | C8: 110,00 - 170,00 | D8: 110 | E8: 170
A9: ='Orçamento Resumo'!A10 -> IMPERMEABILIZAÇÃO | B9: ='Orçamento Resumo'!D10 -> 72.615318 | C9: 75,00 - 85,00 | D9: 75 | E9: 85
A10: ='Orçamento Resumo'!A11 -> REVESTIMENTOS INTERNOS EM PISO E PAREDE | B10: ='Orçamento Resumo'!D11 -> 280.89284 | C10: 160,00 - 270,00 | D10: 160 | E10: 270
A11: ='Orçamento Resumo'!A12 -> REVESTIMENTOS E ACABAMENTOS INTERNOS EM TETO | B11: ='Orçamento Resumo'!D12 -> 102.83968 | C11: 50,00 - 100,00 | D11: 50 | E11: 100
A12: ='Orçamento Resumo'!A13 -> ACABAMENTOS EM PISO E PAREDE | B12: ='Orçamento Resumo'!D13 -> 268.93969 | C12: 160,00 - 250,00 | D12: 160 | E12: 250
A13: ='Orçamento Resumo'!A14 -> PINTURA INTERNA | B13: ='Orçamento Resumo'!D14 -> 103.60444 | C13: 80,00 - 120,00 | D13: 80 | E13: 120
A14: ='Orçamento Resumo'!A15 -> ESQUADRIAS | B14: ='Orçamento Resumo'!D15 -> 234.59972 | C14: 180,00 - 270,00 | D14: 180 | E14: 270
A15: ='Orçamento Resumo'!A16 -> REVESTIMENTOS E ACABAMENTOS DE FACHADA | B15: ='Orçamento Resumo'!D16 -> 120.26904 | C15: 85,00 - 110,00 | D15: 85 | E15: 110
A16: ='Orçamento Resumo'!A17 -> MÃO DE OBRA PRÓPRIA | B16: ='Orçamento Resumo'!D17 -> 81.851593 | C16: 50,00 - 80,00 | D16: 50 | E16: 80
A17: ='Orçamento Resumo'!A18 -> SERVIÇOS COMPLEMENTARES | B17: ='Orçamento Resumo'!D18+'Orçamento Resumo'!D19 -> 96.534257 | C17: 120,00 - 210,00 | D17: 120 | E17: 210
A18: TOTAL | B18: =SUM(B2:B17) -> 2923.1707 | C18: 2100,00 - 3100,00 | D18: =SUM(D2:D17) -> 2085 | E18: =SUM(E2:E17) -> 3075

Sheet Planilha1
C2: BELISSIMO | D2: HOMESET | E2: CARRARO | G2: Guanabara
C3: 44835 | D3: 44896 | E3: 44805 | H3: 2643.16
B4: GERENCIAMENTO | C4: =228.97*B24 -> 225.37155 | D4: =384.24*D24 -> 376.65888 | E4: =185.03*E24 -> 251.40517 | G4: 230 | H4: 380
B5: MOVIMENTAÇÃO DE TERRA | C5: =10.06*B24 -> 9.9018989 | D5: =13.74*D24 -> 13.468907 | E5: =38.04*E24 -> 51.685958 | G5: 10 | H5: 50
B6: INFRAESTRUTURA | C6: =167.14*B24 -> 164.51326 | D6: =326.81*D24 -> 320.36198 | E6: =222.62*E24 -> 302.4797 | G6: 170 | H6: 250
B7: SUPRAESTRUTURA | C7: =350.59*B24 -> 345.08019 | D7: =213.27*D24 -> 209.06215 | E7: =697.81*E24 -> 948.13297 | G7: 320 | H7: 380
B8: ALVENARIA, VEDAÇÕES E DIVISÓRIAS | C8: =180.14*B24 -> 177.30895 | D8: =340.65*D24 -> 333.92892 | E8: =233.95*E24 -> 317.87408 | G8: 200 | H8: 300
B9: INSTALAÇÕES ELÉTRICAS, HIDROSSANITÁRIAS, PREVENTIVAS E GLP | C9: =208.77*B24 -> 205.48901 | D9: =344.24*D24 -> 337.44809 | E9: =787.22*E24 -> 1069.6167 | G9: 330 | H9: 400
B10: SISTEMAS ESPECIAIS E EQUIPAMENTOS | C10: =111.63*B24 -> 109.87564 | D10: =111.13*D24 -> 108.93739 | E10: =126.32*E24 -> 171.63434 | G10: 110 | H10: 170
B11: IMPERMEABILIZAÇÃO | C11: =16.63*B24 -> 16.368646 | D11: =89.56*D24 -> 87.792966 | E11: =91.99*E24 -> 124.98925 | G11: 75 | H11: 85
B12: REVESTIMENTOS INTERNOS EM PISO E PAREDE | C12: =99.62*B24 -> 98.05439 | D12: =137.62*D24 -> 134.90473 | E12: =162.02*E24 -> 220.14088 | G12: 100 | H12: 220
B13: REVESTIMENTOS E ACABAMENTOS INTERNOS EM TETO | C13: =25.64*B24 -> 25.237046 | D13: =33.42*D24 -> 32.760618 | E13: =74.69*E24 -> 101.48329 | G13: 40 | H13: 100
B14: ACABAMENTOS EM PISO E PAREDE | C14: =143.31*B24 -> 141.05777 | D14: =258.2*D24 -> 253.10567 | E14: =178.08*E24 -> 241.96202 | G14: 140 | H14: 250
B15: PINTURA INTERNA | C15: =78.87*B24 -> 77.630494 | D15: =120.94*D24 -> 118.55383 | E15: =79.38*E24 -> 107.85571 | G15: 80 | H15: 120
B16: ESQUADRIAS | C16: =135.31*B24 -> 133.18349 | D16: =204.3*D24 -> 200.26913 | E16: =195.99*E24 -> 266.29682 | G16: 130 | H16: 270
B17: REVESTIMENTOS E ACABAMENTOS DE FACHADA | C17: =87.43*B24 -> 86.055966 | D17: =105.37*D24 -> 103.29103 | E17: =78.02*E24 -> 106.00785 | G17: 85 | H17: 110
B18: SERVIÇOS COMPLEMENTARES | C18: =105.35*B24 -> 103.69434 | D18: =60.06*D24 -> 58.875006 | E18: =201.17*E24 -> 273.33502 | G18: 60 | H18: 270
C19: =SUM(C5:C18) -> 1693.4511 | D19: =SUM(D5:D18) -> 2312.7604 | E19: =SUM(E5:E18) -> 4303.4946
B22: 2632.38 | D22: 2643.16 | E22: 1906.94
B23: 2591.01 | D23: 2591.01 | E23: 2591.01
B24: =B23/B22 -> 0.98428418 | D24: =D23/D22 -> 0.98026983 | E24: =E23/E22 -> 1.3587265
B27: DESPESAS INDIRETAS | C27: 1223.46

Sheet Planilha2
C2: Obra | F2: 18 - RESIDENCIAL GUANABARA
C3: Unidade construtiva | F3: 2 - GERENCIAMENTO EXECUTIVO - EMBASAMENTO
C4: Código | E4: Descrição | G4: Preço total | H4: % Total
C5: 01 | E5: MÃO DE OBRA TERCEIRIZADA | G5: 3819542.4 | H5: 26.73
C6: 02 | E6: MÃO DE OBRA PRÓPRIA | G6: 363462 | H6: 2.54
C7: 03 | E7: MOVIMENTAÇÃO DE TERRA | G7: 9030.44 | H7: 0.06
C8: 04 | E8: INFRAESTRUTURA | G8: 44507.37 | H8: 0.31
C9: 05 | E9: SUPRAESTRUTURA | G9: 40467.57 | H9: 0.28
C10: 06 | E10: ALVENARIA, VEDAÇÕES E DIVISÓRIAS | G10: 61225.95 | H10: 0.43
C11: 07 | E11: SISTEMAS E INSTALAÇÕES ELÉTRICAS | G11: 61315.12 | H11: 0.43
C12: 08 | E12: SISTEMAS E INSTALAÇÕES HIDROSSANITÁRIAS E DRENAGEM | G12: 75165.48 | H12: 0.53
C13: 09 | E13: LOUÇAS E METAIS | G13: 11518.19 | H13: 0.08
C14: 10 | E14: INSTALAÇÕES PREVENTIVAS E GLP | G14: 383.08 | H14: 0
C15: 11 | E15: EQUIPAMENTOS E SISTEMAS ESPECIAIS | G15: 100389.19 | H15: 0.7
C16: 12 | E16: CLIMATIZAÇÃO, EXAUSTÃO MECÂNICA E PRESSURIZAÇÃO | G16: 15229.02 | H16: 0.11
... C24: 20 | E24: SERVIÇOS COMPLEMENTARES E FINAIS | G24: 428660.37 | H24: 3
C25: Total da unidade construtiva | G25: 5292990.1 | H25: 37.05
C27: Unidade construtiva | F27: 3 - GERENCIAMENTO EXECUTIVO - TORRE A
C28: Código | E28: Descrição | G28: Preço total | H28: % Total
C29: 01 | E29: MOVIMENTAÇÃO DE TERRA | G29: 5475.84 | H29: 0.04
C30: 02 | E30: INFRAESTRUTURA | G30: 402817.08 | H30: 2.82
C31: 03 | E31: SUPRAESTRUTURA | G31: 418376.86 | H31: 2.93
C32: 04 | E32: ALVENARIA, VEDAÇÕES E DIVISÓRIAS | G32: 487495.09 | H32: 3.41
C33: 05 | E33: SISTEMAS E INSTALAÇÕES ELÉTRICAS | G33: 215220.16 | H33: 1.51
C34: 06 | E34: SISTEMAS E INSTALAÇÕES HIDROSSANITÁRIAS E DRENAGEM | G34: 298080.39 | H34: 2.09
C35: 07 | E35: LOUÇAS E METAIS | G35: 47272.19 | H35: 0.33
C36: 08 | E36: INSTALAÇÕES PREVENTIVAS E GLP | G36: 61991.86 | H36: 0.43
C37: 09 | E37: EQUIPAMENTOS E SISTEMAS ESPECIAIS | G37: 451772.36 | H37: 3.16
C38: 10 | E38: CLIMATIZAÇÃO, EXAUSTÃO MECÂNICA E PRESSURIZAÇÃO | G38: 15649.91 | H38: 0.11
C39: 11 | E39: IMPERMEABILIZAÇÃO E TRATAMENTOS | G39: 92500.05 | H39: 0.65
C40: 12 | E40: REVESTIMENTOS INTERNOS EM PISO E PAREDE | G40: 258270.29 | H40: 1.81
... C45: 17 | E45: REVESTIMENTOS E ACABAMENTOS EM FACHADA | G45: 95765.8 | H45: 0.67
C46: Total da unidade construtiva | G46: 3843674.7 | H46: 26.9
C48: Obra | F48: 18 - RESIDENCIAL GUANABARA
C49: Unidade construtiva | F49: 4 - GERENCIAMENTO EXECUTIVO - TORRE B
C50: Código | E50: Descrição | G50: Preço total | H50: % Total
C51: 01 | E51: MOVIMENTAÇÃO DE TERRA | G51: 5475.84 | H51: 0.04
C52: 02 | E52: INFRAESTRUTURA | G52: 402817.08 | H52: 2.82
C53: 03 | E53: SUPRAESTRUTURA | G53: 418376.86 | H53: 2.93
C54: 04 | E54: ALVENARIA, VEDAÇÕES E DIVISÓRIAS | G54: 487495.09 | H54: 3.41
...

Sheet Planilha2 (2)
C2: Obra | F2: 18 - RESIDENCIAL GUANABARA
C3: Unidade construtiva | F3: 2 - GERENCIAMENTO EXECUTIVO - EMBASAMENTO
C4: Código | E4: Descrição | G4: EMBASAMENTO | H4: TORRE A | I4: TORRE B | J4: MO | K4: TOTAL
C5: 01 | E5: GERENCIAMENTO TÉCNICO E ADIMINISTRATIVO | G5: 1306858.9 | K5: =G5 -> 1306858.9
C6: 02 | E6: MÃO DE OBRA PRÓPRIA | G6: 363462 | K6: =SUM(G6:J6) -> 363462
C7: 03 | E7: MOVIMENTAÇÃO DE TERRA | G7: 9030.44 | H7: 5475.84 | I7: 5475.84 | K7: =SUM(G7:J7) -> 19982.12
C8: 04 | E8: INFRAESTRUTURA | G8: 44507.37 | H8: 402817.08 | I8: 402817.08 | J8: 217911.6 | K8: =SUM(G8:J8) -> 1068053.1
C9: 05 | E9: SUPRAESTRUTURA | G9: 40467.57 | H9: 418376.86 | I9: 418376.86 | J9: 532860 | K9: =SUM(G9:J9) -> 1410081.3
C10: 06 | E10: ALVENARIA, VEDAÇÕES E DIVISÓRIAS | G10: 61225.95 | H10: 487495.09 | I10: 487495.09 | J10: 386941.14 | K10: =SUM(G10:J10) -> 1423157.3
C11: 07 | E11: SISTEMAS E INSTALAÇÕES ELÉTRICAS | G11: 61315.12 | H11: 215220.16 | I11: 215220.16 | J11: 252000 | K11: =SUM(G11:J11) -> 743755.44
C12: 08 | E12: SISTEMAS E INSTALAÇÕES HIDROSSANITÁRIAS E DRENAGEM | G12: 75165.48 | H12: 298080.39 | I12: 298080.39 | J12: 252000 | K12: =SUM(G12:J12) -> 923326.26
C13: 09 | E13: LOUÇAS E METAIS | G13: 11518.19 | H13: 47272.19 | I13: 47272.19 | K13: =SUM(G13:J13) -> 106062.57
C14: 10 | E14: INSTALAÇÕES PREVENTIVAS E GLP | G14: 383.08 | H14: 61991.86 | I14: 61991.86 | J14: 34800 | K14: =SUM(G14:J14) -> 159166.8
C15: 11 | E15: EQUIPAMENTOS E SISTEMAS ESPECIAIS | G15: 100389.19 | H15: 451772.36 | I15: 451772.36 | K15: =SUM(G15:J15) -> 1003933.9
C16: 12 | E16: CLIMATIZAÇÃO, EXAUSTÃO MECÂNICA E PRESSURIZAÇÃO | G16: 15229.02 | H16: 15649.91 | I16: 15649.91 | J16: 27680 | K16: =SUM(G16:J16) -> 74208.84
C17: 13 | E17: IMPERMEABILIZAÇÃO E TRATAMENTOS | G17: 8468.88 | H17: 92500.05 | I17: 92500.05 | J17: 128979.34 | K17: =SUM(G17:J17) -> 322448.32
C18: 14 | E18: REVESTIMENTOS INTERNOS EM PISO E PAREDE | G18: 42280.56 | H18: 258270.29 | I18: 258270.29 | J18: 688483.51 | K18: =SUM(G18:J18) -> 1247304.6
C19: 15 | E19: REVESTIMENTOS E ACABAMENTOS INTERNOS EM TETO | G19: 4030.94 | H19: 149341.37 | I19: 149341.37 | J19: 153945.94 | K19: =SUM(G19:J19) -> 456659.62
C20: 16 | E20: ACABAMENTOS EM PISO E PAREDE | G20: 84575.65 | H20: 347804.67 | I20: 347804.67 | J20: 414041.71 | K20: =SUM(G20:J20) -> 1194226.7
C21: 17 | E21: SISTEMAS DE PINTURA INTERNA | G21: 6579.54 | H21: 52545.75 | I21: 52545.75 | J21: 348384.48 | K21: =SUM(G21:J21) -> 460055.52
C22: 18 | E22: ESQUADRIAS, VIDROS E FERRAGENS | G22: 87890.48 | H22: 443295.03 | I22: 443295.03 | J22: 67259.5 | K22: =SUM(G22:J22) -> 1041740
C23: 19 | E23: REVESTIMENTOS E ACABAMENTOS EM FACHADA | G23: 28267.85 | H23: 95765.8 | I23: 95765.8 | J23: 314255.2 | K23: =SUM(G23:J23) -> 534054.65
C24: 20 | E24: SERVIÇOS COMPLEMENTARES E FINAIS | G24: 428660.37 | K24: =SUM(G24:J24) -> 428660.37
C25: Total da unidade construtiva | G25: 5292990.1 | H25: =SUM(H7:H23) -> 3843674.7 | I25: =SUM(I7:I23) -> 3843674.7 | J25: =SUM(J7:J23) -> 3819542.4 | K25: =SUM(K5:K24) -> 14287198
