Workbook
Name \0: #REF!
Name \0: #REF!
Name \0: #REF!
Name \1: #REF!
Name \a: #REF!
Name \a: #REF!
Name \a: #REF!
Name \b: #REF!
Name \c: #REF!
Name \d: #REF!
Name \e: #REF!
Name \i: #REF!
Name \J: #REF!
Name \k: #REF!
Name \l: #N/A
Name \m: #REF!
Name \m: #REF!
Name \m: #REF!
Name \o: #REF!
Name \p: #REF!
Name \r: #REF!
Name \T: #REF!
Name \z: #REF!
Name _\0: #REF!
Name _\1: #REF!
Name _\a: #REF!
Name _\b: #REF!
Name _\c: #REF!
Name _\d: #REF!
Name _\e: #REF!
Name _\i: #REF!
Name _\J: #REF!
Name _\k: #REF!
Name _\l: #N/A
Name _\m: #REF!
Name _\o: #REF!
Name _\p: #REF!
Name _\r: #REF!
Name _\T: #REF!
Name _\z: #REF!
Name ______ACR10: #REF!
Name ______ACR15: #REF!
Name ______acr20: #REF!
Name ______acr5: #REF!
Name ______ARQ1: #REF!
Name ______QT100: #REF!
Name ______QT2: #REF!
Name ______QT3: #REF!
Name ______QT4: #REF!
Name ______QT50: #REF!
Name ______QT75: #REF!
Name _____ACR10: #REF!
Name _____ACR15: #REF!
Name _____acr20: #REF!
Name _____acr5: #REF!
Name _____ARQ1: #REF!
Name _____QT100: #REF!
Name _____QT2: #REF!
Name _____QT3: #REF!
Name _____QT4: #REF!

Sheet PREÇO
B1: Projeto | C1: ='CLIMATIZAÇÃO E EXAUSTÃO'!D1 -> Senna Tower
B2: Empresa | C2: ='CLIMATIZAÇÃO E EXAUSTÃO'!D2 -> FG
B3: Revisão | C3: ='CLIMATIZAÇÃO E EXAUSTÃO'!D3 -> R00 - Letícia
A4: ='CLIMATIZAÇÃO E EXAUSTÃO'!A4 -> CLIMATIZAÇÃO E EXAUSTÃO
C5: Descrição | D5: Unidade | E5: Custo unitário

Sheet CLIMATIZAÇÃO E EXAUSTÃO
C1: Projeto | D1: Senna Tower
C2: Empresa | D2: FG
C3: Revisão | D3: R00 - Letícia
A4: CLIMATIZAÇÃO E EXAUSTÃO
A5: TORRE | B5: PAVIMENTO | C5: GRUPO/EAP | D5: Arquivo | E5: Descrição | F5: Referência | G5: Modelo | H5: Quantidade | I5: Repetição | J5: Perda | K5: Qte com perda | L5: Unidade | M5: Custo unitário | N5: Custo Total | P5: Torre | Q5: EAP | R5: Exaustão forçada e renovação de ar (material) | S5: Exaustão forçada - Ventokit apartamentos (material) | T5: Desumidificador (material | U5: Ventilação garagem (material) | V5: Exaustor para coifa | W5: Infraestrutura de climatização área comum (material) | X5: Infraestrutura de climatização embasamento (material) | Y5: Infraestrutura de climatização torre (material) | Z5: TOTAL
A6: GERAL | B6: SUBSOLO | N6: =IF(SUM(H6:M6)=0,SUMIFS($N7:$N$759,$B7:$B$759,$B6,$A7:$A$759,$A6),K6*M6) -> #N/A | P6: GERAL | Q6: {=_xlfn.UNIQUE(_xlfn._xlws.FILTER($E$6:$E$1048576,$E$6:$E$1048576<>""))} -> Controlador com sensor de monóxido de carbono. Interligado por wifi integrado ao sistema de ventilação do subsolo. | R6: =SUMIFS($K$6:$K$426,$E$6:$E$426,$Q6,$C$6:$C$426,R$5,$A$6:$A$426,$P6) -> 0 | S6: =SUMIFS($K$6:$K$426,$E$6:$E$426,$Q6,$C$6:$C$426,S$5,$A$6:$A$426,$P6) -> 0 | T6: =SUMIFS($K$6:$K$426,$E$6:$E$426,$Q6,$C$6:$C$426,T$5,$A$6:$A$426,$P6) -> 0 | U6: =SUMIFS($K$6:$K$426,$E$6:$E$426,$Q6,$C$6:$C$426,U$5,$A$6:$A$426,$P6) -> 384 | V6: =SUMIFS($K$6:$K$426,$E$6:$E$426,$Q6,$C$6:$C$426,V$5,$A$6:$A$426,$P6) -> 0 | W6: =SUMIFS($K$6:$K$426,$E$6:$E$426,$Q6,$C$6:$C$426,W$5,$A$6:$A$426,$P6) -> 0 | X6: =SUMIFS($K$6:$K$426,$E$6:$E$426,$Q6,$C$6:$C$426,X$5,$A$6:$A$426,$P6) -> 0 | Y6: =SUMIFS($K$6:$K$426,$E$6:$E$426,$Q6,$C$6:$C$426,Y$5,$A$6:$A$426,$P6) -> 0 | Z6: =SUM(R6:Y6) -> 384
A7: =A6 -> GERAL | B7: =B6 -> SUBSOLO | C7: Ventilação garagem (material) | D7: SEN-AP-EXT-001-SUB-R00.pdf | E7: Controlador com sensor de monóxido de carbono. Interligado por wifi integrado ao sistema de ventilação do subsolo. | F7: Storge | G7: STG02-MINI | H7: 48 | I7: 1 | J7: 0 | K7: =(H7+J7*H7)*I7 -> 48 | L7: un | M7: =_xlfn.XLOOKUP($E7,PREÇO!$C$6:$C$89,PREÇO!$E$6:$E$89) -> #N/A | N7: =IF(SUM(H7:M7)=0,SUMIFS($N8:$N$759,$B8:$B$759,$B7,$A8:$A$759,$A7),K7*M7) -> #N/A | P7: GERAL | Q7: Ventilador de indução direcionador de ar compacto com motor eletrônico, com drive STG02-DRV, comunicação por wifi integrado. | R7: =SUMIFS($K$6:$K$426,$E$6:$E$426,$Q7,$C$6:$C$426,R$5,$A$6:$A$426,$P7) -> 0 | S7: =SUMIFS($K$6:$K$426,$E$6:$E$426,$Q7,$C$6:$C$426,S$5,$A$6:$A$426,$P7) -> 0 | T7: =SUMIFS($K$6:$K$426,$E$6:$E$426,$Q7,$C$6:$C$426,T$5,$A$6:$A$426,$P7) -> 0 | U7: =SUMIFS($K$6:$K$426,$E$6:$E$426,$Q7,$C$6:$C$426,U$5,$A$6:$A$426,$P7) -> 920 | V7: =SUMIFS($K$6:$K$426,$E$6:$E$426,$Q7,$C$6:$C$426,V$5,$A$6:$A$426,$P7) -> 0 | W7: =SUMIFS($K$6:$K$426,$E$6:$E$426,$Q7,$C$6:$C$426,W$5,$A$6:$A$426,$P7) -> 0 | X7: =SUMIFS($K$6:$K$426,$E$6:$E$426,$Q7,$C$6:$C$426,X$5,$A$6:$A$426,$P7) -> 0 | Y7: =SUMIFS($K$6:$K$426,$E$6:$E$426,$Q7,$C$6:$C$426,Y$5,$A$6:$A$426,$P7) -> 0 | Z7: =SUM(R7:Y7) -> 920
A8: =A7 -> GERAL | B8: =B7 -> SUBSOLO | C8: Ventilação garagem (material) | D8: SEN-AP-EXT-001-SUB-R00.pdf | E8: Ventilador de indução direcionador de ar compacto com motor eletrônico, com drive STG02-DRV, comunicação por wifi integrado. | F8: Storge | G8: STG-SJF 3000EC | H8: 115 | I8: 1 | J8: 0 | K8: =(H8+J8*H8)*I8 -> 115 | L8: un | M8: =_xlfn.XLOOKUP($E8,PREÇO!$C$6:$C$89,PREÇO!$E$6:$E$89) -> #N/A | N8: =IF(SUM(H8:M8)=0,SUMIFS($N9:$N$759,$B9:$B$759,$B8,$A9:$A$759,$A8),K8*M8) -> #N/A | P8: GERAL | Q8: Ventilador tubo axial com motor eletrônico, vazão máxima de 11.000 m³/h, ruído máximo 76 dB(A) livre, com drive STG02-DRV, comunicação por wifi integrado. | R8: =SUMIFS($K$6:$K$426,$E$6:$E$426,$Q8,$C$6:$C$426,R$5,$A$6:$A$426,$P8) -> 0 | S8: =SUMIFS($K$6:$K$426,$E$6:$E$426,$Q8,$C$6:$C$426,S$5,$A$6:$A$426,$P8) -> 0 | T8: =SUMIFS($K$6:$K$426,$E$6:$E$426,$Q8,$C$6:$C$426,T$5,$A$6:$A$426,$P8) -> 0 | U8: =SUMIFS($K$6:$K$426,$E$6:$E$426,$Q8,$C$6:$C$426,U$5,$A$6:$A$426,$P8) -> 80 | V8: =SUMIFS($K$6:$K$426,$E$6:$E$426,$Q8,$C$6:$C$426,V$5,$A$6:$A$426,$P8) -> 0 | W8: =SUMIFS($K$6:$K$426,$E$6:$E$426,$Q8,$C$6:$C$426,W$5,$A$6:$A$426,$P8) -> 0 | X8: =SUMIFS($K$6:$K$426,$E$6:$E$426,$Q8,$C$6:$C$426,X$5,$A$6:$A$426,$P8) -> 0 | Y8: =SUMIFS($K$6:$K$426,$E$6:$E$426,$Q8,$C$6:$C$426,Y$5,$A$6:$A$426,$P8) -> 0 | Z8: =SUM(R8:Y8) -> 80
A9: =A8 -> GERAL | B9: =B8 -> SUBSOLO | C9: Ventilação garagem (material) | D9: SEN-AP-EXT-001-SUB-R00.pdf | E9: Ventilador tubo axial com motor eletrônico, vazão máxima de 11.000 m³/h, ruído máximo 76 dB(A) livre, com drive STG02-DRV, comunicação por wifi integrado. | F9: Storge | G9: STG-AFSW500 EC | H9: 10 | I9: 1 | J9: 0 | K9: =(H9+J9*H9)*I9 -> 10 | L9: un | M9: =_xlfn.XLOOKUP($E9,PREÇO!$C$6:$C$89,PREÇO!$E$6:$E$89) -> #N/A | N9: =IF(SUM(H9:M9)=0,SUMIFS($N10:$N$759,$B10:$B$759,$B9,$A10:$A$759,$A9),K9*M9) -> #N/A | P9: GERAL | Q9: Ventilador tubo axial com motor eletrônico, vazão máxima de 19.300 m³/h, ruído máximo 81 dB(A) livre, com drive STG02-DRV, comunicação por wifi integrado. | R9: =SUMIFS($K$6:$K$426,$E$6:$E$426,$Q9,$C$6:$C$426,R$5,$A$6:$A$426,$P9) -> 0 | S9: =SUMIFS($K$6:$K$426,$E$6:$E$426,$Q9,$C$6:$C$426,S$5,$A$6:$A$426,$P9) -> 0 | T9: =SUMIFS($K$6:$K$426,$E$6:$E$426,$Q9,$C$6:$C$426,T$5,$A$6:$A$426,$P9) -> 0 | U9: =SUMIFS($K$6:$K$426,$E$6:$E$426,$Q9,$C$6:$C$426,U$5,$A$6:$A$426,$P9) -> 96 | V9: =SUMIFS($K$6:$K$426,$E$6:$E$426,$Q9,$C$6:$C$426,V$5,$A$6:$A$426,$P9) -> 0 | W9: =SUMIFS($K$6:$K$426,$E$6:$E$426,$Q9,$C$6:$C$426,W$5,$A$6:$A$426,$P9) -> 0 | X9: =SUMIFS($K$6:$K$426,$E$6:$E$426,$Q9,$C$6:$C$426,X$5,$A$6:$A$426,$P9) -> 0 | Y9: =SUMIFS($K$6:$K$426,$E$6:$E$426,$Q9,$C$6:$C$426,Y$5,$A$6:$A$426,$P9) -> 0 | Z9: =SUM(R9:Y9) -> 96
A10: =A9 -> GERAL | B10: =B9 -> SUBSOLO | C10: Ventilação garagem (material) | D10: SEN-AP-EXT-001-SUB-R00.pdf | E10: Ventilador tubo axial com motor eletrônico, vazão máxima de 19.300 m³/h, ruído máximo 81 dB(A) livre, com drive STG02-DRV, comunicação por wifi integrado. | F10: Storge | G10: STG-AFSW800 EC | H10: 12 | I10: 1 | J10: 0 | K10: =(H10+J10*H10)*I10 -> 12 | L10: un | M10: =_xlfn.XLOOKUP($E10,PREÇO!$C$6:$C$89,PREÇO!$E$6:$E$89) -> #N/A | N10: =IF(SUM(H10:M10)=0,SUMIFS($N11:$N$759,$B11:$B$759,$B10,$A11:$A$759,$A10),K10*M10) -> #N/A | P10: GERAL | Q10: Ventilador helicocentrífugo, baixo nível de ruído, com elementos acústicos, junta de borracha na sucção e descarga. | R10: =SUMIFS($K$6:$K$426,$E$6:$E$426,$Q10,$C$6:$C$426,R$5,$A$6:$A$426,$P10) -> 45 | S10: =SUMIFS($K$6:$K$426,$E$6:$E$426,$Q10,$C$6:$C$426,S$5,$A$6:$A$426,$P10) -> 2226 | T10: =SUMIFS($K$6:$K$426,$E$6:$E$426,$Q10,$C$6:$C$426,T$5,$A$6:$A$426,$P10) -> 0 | U10: =SUMIFS($K$6:$K$426,$E$6:$E$426,$Q10,$C$6:$C$426,U$5,$A$6:$A$426,$P10) -> 16 | V10: =SUMIFS($K$6:$K$426,$E$6:$E$426,$Q10,$C$6:$C$426,V$5,$A$6:$A$426,$P10) -> 0 | W10: =SUMIFS($K$6:$K$426,$E$6:$E$426,$Q10,$C$6:$C$426,W$5,$A$6:$A$426,$P10) -> 0 | X10: =SUMIFS($K$6:$K$426,$E$6:$E$426,$Q10,$C$6:$C$426,X$5,$A$6:$A$426,$P10) -> 0 | Y10: =SUMIFS($K$6:$K$426,$E$6:$E$426,$Q10,$C$6:$C$426,Y$5,$A$6:$A$426,$P10) -> 0 | Z10: =SUM(R10:Y10) -> 2287
A11: =A10 -> GERAL | B11: =B10 -> SUBSOLO | C11: Exaustão forçada e renovação de ar (material) | D11: SEN-AP-CLI-101-SUB-R01.pdf | E11: Ventilador helicocentrífugo, baixo nível de ruído, com elementos acústicos, junta de borracha na sucção e descarga. | F11: Soler & Palau | G11: TD-160/100 N SILENT | H11: 1 | I11: 1 | J11: 0 | K11: =(H11+J11*H11)*I11 -> 1 | L11: un | M11: =_xlfn.XLOOKUP($E11,PREÇO!$C$6:$C$89,PREÇO!$E$6:$E$89) -> #N/A | N11: =IF(SUM(H11:M11)=0,SUMIFS($N12:$N$759,$B12:$B$759,$B11,$A12:$A$759,$A11),K11*M11) -> #N/A | P11: GERAL | Q11: Ventilador helicocentrífugo com caixa de bornes externa, motor regulável, duas velocidades. | R11: =SUMIFS($K$6:$K$426,$E$6:$E$426,$Q11,$C$6:$C$426,R$5,$A$6:$A$426,$P11) -> 10 | S11: =SUMIFS($K$6:$K$426,$E$6:$E$426,$Q11,$C$6:$C$426,S$5,$A$6:$A$426,$P11) -> 0 | T11: =SUMIFS($K$6:$K$426,$E$6:$E$426,$Q11,$C$6:$C$426,T$5,$A$6:$A$426,$P11) -> 0 | U11: =SUMIFS($K$6:$K$426,$E$6:$E$426,$Q11,$C$6:$C$426,U$5,$A$6:$A$426,$P11) -> 0 | V11: =SUMIFS($K$6:$K$426,$E$6:$E$426,$Q11,$C$6:$C$426,V$5,$A$6:$A$426,$P11) -> 0 | W11: =SUMIFS($K$6:$K$426,$E$6:$E$426,$Q11,$C$6:$C$426,W$5,$A$6:$A$426,$P11) -> 0 | X11: =SUMIFS($K$6:$K$426,$E$6:$E$426,$Q11,$C$6:$C$426,X$5,$A$6:$A$426,$P11) -> 0 | Y11: =SUMIFS($K$6:$K$426,$E$6:$E$426,$Q11,$C$6:$C$426,Y$5,$A$6:$A$426,$P11) -> 0 | Z11: =SUM(R11:Y11) -> 10
A12: =A11 -> GERAL | B12: =B11 -> SUBSOLO | C12: Exaustão forçada e renovação de ar (material) | D12: SEN-AP-CLI-101-SUB-R01.pdf | E12: Ventilador helicocentrífugo com caixa de bornes externa, motor regulável, duas velocidades. | F12: Soler & Palau | G12: TD-250/100 | H12: 1 | I12: 1 | J12: 0 | K12: =(H12+J12*H12)*I12 -> 1 | L12: un | M12: =_xlfn.XLOOKUP($E12,PREÇO!$C$6:$C$89,PREÇO!$E$6:$E$89) -> #N/A | N12: =IF(SUM(H12:M12)=0,SUMIFS($N13:$N$759,$B13:$B$759,$B12,$A13:$A$759,$A12),K12*M12) -> #N/A | P12: GERAL | Q12: Unidade evaporadora tipo Hi-wall, capacidade 12.300 Btu/h, linha VRV, ciclo Q/F. | R12: =SUMIFS($K$6:$K$426,$E$6:$E$426,$Q12,$C$6:$C$426,R$5,$A$6:$A$426,$P12) -> 0 | S12: =SUMIFS($K$6:$K$426,$E$6:$E$426,$Q12,$C$6:$C$426,S$5,$A$6:$A$426,$P12) -> 0 | T12: =SUMIFS($K$6:$K$426,$E$6:$E$426,$Q12,$C$6:$C$426,T$5,$A$6:$A$426,$P12) -> 0 | U12: =SUMIFS($K$6:$K$426,$E$6:$E$426,$Q12,$C$6:$C$426,U$5,$A$6:$A$426,$P12) -> 0 | V12: =SUMIFS($K$6:$K$426,$E$6:$E$426,$Q12,$C$6:$C$426,V$5,$A$6:$A$426,$P12) -> 0 | W12: =SUMIFS($K$6:$K$426,$E$6:$E$426,$Q12,$C$6:$C$426,W$5,$A$6:$A$426,$P12) -> 9 | X12: =SUMIFS($K$6:$K$426,$E$6:$E$426,$Q12,$C$6:$C$426,X$5,$A$6:$A$426,$P12) -> 2 | Y12: =SUMIFS($K$6:$K$426,$E$6:$E$426,$Q12,$C$6:$C$426,Y$5,$A$6:$A$426,$P12) -> 0 | Z12: =SUM(R12:Y12) -> 11
A13: =A12 -> GERAL | B13: =B12 -> SUBSOLO | C13: Infraestrutura de climatização embasamento (material) | D13: SEN-AP-CLI-101-SUB-R01.pdf | E13: Unidade evaporadora tipo Hi-wall, capacidade 12.300 Btu/h, linha VRV, ciclo Q/F. | F13: Daikin | G13: FXAQ32AVM | H13: 2 | I13: 1 | J13: 0 | K13: =(H13+J13*H13)*I13 -> 2 | L13: un | M13: =_xlfn.XLOOKUP($E13,PREÇO!$C$6:$C$89,PREÇO!$E$6:$E$89) -> #N/A | N13: =IF(SUM(H13:M13)=0,SUMIFS($N14:$N$759,$B14:$B$759,$B13,$A14:$A$759,$A13),K13*M13) -> #N/A | P13: GERAL | Q13: Unidade evaporadora tipo Hi-wall, capacidade 24.200 Btu/h, linha VRV, ciclo Q/F. | R13: =SUMIFS($K$6:$K$426,$E$6:$E$426,$Q13,$C$6:$C$426,R$5,$A$6:$A$426,$P13) -> 0 | S13: =SUMIFS($K$6:$K$426,$E$6:$E$426,$Q13,$C$6:$C$426,S$5,$A$6:$A$426,$P13) -> 0 | T13: =SUMIFS($K$6:$K$426,$E$6:$E$426,$Q13,$C$6:$C$426,T$5,$A$6:$A$426,$P13) -> 0 | U13: =SUMIFS($K$6:$K$426,$E$6:$E$426,$Q13,$C$6:$C$426,U$5,$A$6:$A$426,$P13) -> 0 | V13: =SUMIFS($K$6:$K$426,$E$6:$E$426,$Q13,$C$6:$C$426,V$5,$A$6:$A$426,$P13) -> 0 | W13: =SUMIFS($K$6:$K$426,$E$6:$E$426,$Q13,$C$6:$C$426,W$5,$A$6:$A$426,$P13) -> 1 | X13: =SUMIFS($K$6:$K$426,$E$6:$E$426,$Q13,$C$6:$C$426,X$5,$A$6:$A$426,$P13) -> 2 | Y13: =SUMIFS($K$6:$K$426,$E$6:$E$426,$Q13,$C$6:$C$426,Y$5,$A$6:$A$426,$P13) -> 0 | Z13: =SUM(R13:Y13) -> 3
A14: =A13 -> GERAL | B14: =B13 -> SUBSOLO | C14: Infraestrutura de climatização embasamento (material) | D14: SEN-AP-CLI-101-SUB-R01.pdf | E14: Unidade evaporadora tipo Hi-wall, capacidade 24.200 Btu/h, linha VRV, ciclo Q/F. | F14: Daikin | G14: FXAQ63AVM | H14: 2 | I14: 1 | J14: 0 | K14: =(H14+J14*H14)*I14 -> 2 | L14: un | M14: =_xlfn.XLOOKUP($E14,PREÇO!$C$6:$C$89,PREÇO!$E$6:$E$89) -> #N/A | N14: =IF(SUM(H14:M14)=0,SUMIFS($N15:$N$759,$B15:$B$759,$B14,$A15:$A$759,$A14),K14*M14) -> #N/A | P14: GERAL | Q14: Grelha redonda fixa com colarinho de DN Ø100 mm. | R14: =SUMIFS($K$6:$K$426,$E$6:$E$426,$Q14,$C$6:$C$426,R$5,$A$6:$A$426,$P14) -> 3 | S14: =SUMIFS($K$6:$K$426,$E$6:$E$426,$Q14,$C$6:$C$426,S$5,$A$6:$A$426,$P14) -> 0 | T14: =SUMIFS($K$6:$K$426,$E$6:$E$426,$Q14,$C$6:$C$426,T$5,$A$6:$A$426,$P14) -> 0 | U14: =SUMIFS($K$6:$K$426,$E$6:$E$426,$Q14,$C$6:$C$426,U$5,$A$6:$A$426,$P14) -> 0 | V14: =SUMIFS($K$6:$K$426,$E$6:$E$426,$Q14,$C$6:$C$426,V$5,$A$6:$A$426,$P14) -> 0 | W14: =SUMIFS($K$6:$K$426,$E$6:$E$426,$Q14,$C$6:$C$426,W$5,$A$6:$A$426,$P14) -> 0 | X14: =SUMIFS($K$6:$K$426,$E$6:$E$426,$Q14,$C$6:$C$426,X$5,$A$6:$A$426,$P14) -> 0 | Y14: =SUMIFS($K$6:$K$426,$E$6:$E$426,$Q14,$C$6:$C$426,Y$5,$A$6:$A$426,$P14) -> 0 | Z14: =SUM(R14:Y14) -> 3
A15: =A14 -> GERAL | B15: =B14 -> SUBSOLO | C15: Exaustão forçada e renovação de ar (material) | D15: SEN-AP-CLI-101-SUB-R01.pdf | E15: Grelha redonda fixa com colarinho de DN Ø100 mm. | F15: Sicflux | G15: S 100 | H15: 2 | I15: 1 | J15: 0 | K15: =(H15+J15*H15)*I15 -> 2 | L15: un | M15: =_xlfn.XLOOKUP($E15,PREÇO!$C$6:$C$89,PREÇO!$E$6:$E$89) -> #N/A | N15: =IF(SUM(H15:M15)=0,SUMIFS($N16:$N$759,$B16:$B$759,$B15,$A16:$A$759,$A15),K15*M15) -> #N/A | P15: GERAL | Q15: Grelha redonda fixa com colarinho de DN Ø200 mm. | R15: =SUMIFS($K$6:$K$426,$E$6:$E$426,$Q15,$C$6:$C$426,R$5,$A$6:$A$426,$P15) -> 4 | S15: =SUMIFS($K$6:$K$426,$E$6:$E$426,$Q15,$C$6:$C$426,S$5,$A$6:$A$426,$P15) -> 0 | T15: =SUMIFS($K$6:$K$426,$E$6:$E$426,$Q15,$C$6:$C$426,T$5,$A$6:$A$426,$P15) -> 0 | U15: =SUMIFS($K$6:$K$426,$E$6:$E$426,$Q15,$C$6:$C$426,U$5,$A$6:$A$426,$P15) -> 0 | V15: =SUMIFS($K$6:$K$426,$E$6:$E$426,$Q15,$C$6:$C$426,V$5,$A$6:$A$426,$P15) -> 0 | W15: =SUMIFS($K$6:$K$426,$E$6:$E$426,$Q15,$C$6:$C$426,W$5,$A$6:$A$426,$P15) -> 0 | X15: =SUMIFS($K$6:$K$426,$E$6:$E$426,$Q15,$C$6:$C$426,X$5,$A$6:$A$426,$P15) -> 0 | Y15: =SUMIFS($K$6:$K$426,$E$6:$E$426,$Q15,$C$6:$C$426,Y$5,$A$6:$A$426,$P15) -> 0 | Z15: =SUM(R15:Y15) -> 4
A16: =A15 -> GERAL | B16: =B15 -> SUBSOLO | C16: Exaustão forçada e renovação de ar (material) | D16: SEN-AP-CLI-101-SUB-R01.pdf | E16: Grelha redonda fixa com colarinho de DN Ø200 mm. | F16: Sicflux | G16: S 200 | H16: 4 | I16: 1 | J16: 0 | K16: =(H16+J16*H16)*I16 -> 4 | L16: un | M16: =_xlfn.XLOOKUP($E16,PREÇO!$C$6:$C$89,PREÇO!$E$6:$E$89) -> #N/A | N16: =IF(SUM(H16:M16)=0,SUMIFS($N17:$N$759,$B17:$B$759,$B16,$A17:$A$759,$A16),K16*M16) -> #N/A | P16: GERAL | Q16: Boca com regulador de vazão, em plástico ABS, diâmetro nominal de Ø100mm. | R16: =SUMIFS($K$6:$K$426,$E$6:$E$426,$Q16,$C$6:$C$426,R$5,$A$6:$A$426,$P16) -> 332 | S16: =SUMIFS($K$6:$K$426,$E$6:$E$426,$Q16,$C$6:$C$426,S$5,$A$6:$A$426,$P16) -> 0 | T16: =SUMIFS($K$6:$K$426,$E$6:$E$426,$Q16,$C$6:$C$426,T$5,$A$6:$A$426,$P16) -> 0 | U16: =SUMIFS($K$6:$K$426,$E$6:$E$426,$Q16,$C$6:$C$426,U$5,$A$6:$A$426,$P16) -> 9 | V16: =SUMIFS($K$6:$K$426,$E$6:$E$426,$Q16,$C$6:$C$426,V$5,$A$6:$A$426,$P16) -> 0 | W16: =SUMIFS($K$6:$K$426,$E$6:$E$426,$Q16,$C$6:$C$426,W$5,$A$6:$A$426,$P16) -> 0 | X16: =SUMIFS($K$6:$K$426,$E$6:$E$426,$Q16,$C$6:$C$426,X$5,$A$6:$A$426,$P16) -> 0 | Y16: =SUMIFS($K$6:$K$426,$E$6:$E$426,$Q16,$C$6:$C$426,Y$5,$A$6:$A$426,$P16) -> 2 | Z16: =SUM(R16:Y16) -> 343
A17: =A16 -> GERAL | B17: =B16 -> SUBSOLO | C17: Exaustão forçada e renovação de ar (material) | D17: SEN-AP-CLI-101-SUB-R01.pdf | E17: Boca com regulador de vazão, em plástico ABS, diâmetro nominal de Ø100mm. | F17: Sicflux | G17: RVA 100 | H17: 3 | I17: 1 | J17: 0 | K17: =(H17+J17*H17)*I17 -> 3 | L17: un | M17: =_xlfn.XLOOKUP($E17,PREÇO!$C$6:$C$89,PREÇO!$E$6:$E$89) -> #N/A | N17: =IF(SUM(H17:M17)=0,SUMIFS($N18:$N$759,$B18:$B$759,$B17,$A18:$A$759,$A17),K17*M17) -> #N/A | P17: GERAL | Q17: Unidade condensadora linha VRV 6, Série R, Quente e Frio. | R17: =SUMIFS($K$6:$K$426,$E$6:$E$426,$Q17,$C$6:$C$426,R$5,$A$6:$A$426,$P17) -> 0 | S17: =SUMIFS($K$6:$K$426,$E$6:$E$426,$Q17,$C$6:$C$426,S$5,$A$6:$A$426,$P17) -> 0 | T17: =SUMIFS($K$6:$K$426,$E$6:$E$426,$Q17,$C$6:$C$426,T$5,$A$6:$A$426,$P17) -> 0 | U17: =SUMIFS($K$6:$K$426,$E$6:$E$426,$Q17,$C$6:$C$426,U$5,$A$6:$A$426,$P17) -> 0 | V17: =SUMIFS($K$6:$K$426,$E$6:$E$426,$Q17,$C$6:$C$426,V$5,$A$6:$A$426,$P17) -> 0 | W17: =SUMIFS($K$6:$K$426,$E$6:$E$426,$Q17,$C$6:$C$426,W$5,$A$6:$A$426,$P17) -> 10 | X17: =SUMIFS($K$6:$K$426,$E$6:$E$426,$Q17,$C$6:$C$426,X$5,$A$6:$A$426,$P17) -> 0 | Y17: =SUMIFS($K$6:$K$426,$E$6:$E$426,$Q17,$C$6:$C$426,Y$5,$A$6:$A$426,$P17) -> 0 | Z17: =SUM(R17:Y17) -> 10
A18: GERAL | B18: 1° PAV. TÉRREO | N18: =IF(SUM(H18:M18)=0,SUMIFS($N19:$N$759,$B19:$B$759,$B18,$A19:$A$759,$A18),K18*M18) -> #N/A | P18: GERAL | Q18: Unidade evaporadora tipo Teto, capacidade 12.300 Btu/h, linha VRV, ciclo Q/F. | R18: =SUMIFS($K$6:$K$426,$E$6:$E$426,$Q18,$C$6:$C$426,R$5,$A$6:$A$426,$P18) -> 0 | S18: =SUMIFS($K$6:$K$426,$E$6:$E$426,$Q18,$C$6:$C$426,S$5,$A$6:$A$426,$P18) -> 0 | T18: =SUMIFS($K$6:$K$426,$E$6:$E$426,$Q18,$C$6:$C$426,T$5,$A$6:$A$426,$P18) -> 0 | U18: =SUMIFS($K$6:$K$426,$E$6:$E$426,$Q18,$C$6:$C$426,U$5,$A$6:$A$426,$P18) -> 0 | V18: =SUMIFS($K$6:$K$426,$E$6:$E$426,$Q18,$C$6:$C$426,V$5,$A$6:$A$426,$P18) -> 0 | W18: =SUMIFS($K$6:$K$426,$E$6:$E$426,$Q18,$C$6:$C$426,W$5,$A$6:$A$426,$P18) -> 5 | X18: =SUMIFS($K$6:$K$426,$E$6:$E$426,$Q18,$C$6:$C$426,X$5,$A$6:$A$426,$P18) -> 0 | Y18: =SUMIFS($K$6:$K$426,$E$6:$E$426,$Q18,$C$6:$C$426,Y$5,$A$6:$A$426,$P18) -> 0 | Z18: =SUM(R18:Y18) -> 5
A19: =A18 -> GERAL | B19: =B18 -> 1° PAV. TÉRREO | C19: Ventilação garagem (material) | D19: SEN-AP-EXT-002-TER-R00.pdf | E19: Controlador com sensor de monóxido de carbono. Interligado por wifi integrado ao sistema de ventilação do subsolo. | F19: Storge | G19: STG02-MINI | H19: 48 | I19: 1 | J19: 0 | K19: =(H19+J19*H19)*I19 -> 48 | L19: un | M19: =_xlfn.XLOOKUP($E19,PREÇO!$C$6:$C$89,PREÇO!$E$6:$E$89) -> #N/A | N19: =IF(SUM(H19:M19)=0,SUMIFS($N20:$N$759,$B20:$B$759,$B19,$A20:$A$759,$A19),K19*M19) -> #N/A | P19: GERAL | Q19: Unidade evaporadora tipo Teto, capacidade 24.200 Btu/h, linha VRV, ciclo Q/F. | R19: =SUMIFS($K$6:$K$426,$E$6:$E$426,$Q19,$C$6:$C$426,R$5,$A$6:$A$426,$P19) -> 0 | S19: =SUMIFS($K$6:$K$426,$E$6:$E$426,$Q19,$C$6:$C$426,S$5,$A$6:$A$426,$P19) -> 0 | T19: =SUMIFS($K$6:$K$426,$E$6:$E$426,$Q19,$C$6:$C$426,T$5,$A$6:$A$426,$P19) -> 0 | U19: =SUMIFS($K$6:$K$426,$E$6:$E$426,$Q19,$C$6:$C$426,U$5,$A$6:$A$426,$P19) -> 0 | V19: =SUMIFS($K$6:$K$426,$E$6:$E$426,$Q19,$C$6:$C$426,V$5,$A$6:$A$426,$P19) -> 0 | W19: =SUMIFS($K$6:$K$426,$E$6:$E$426,$Q19,$C$6:$C$426,W$5,$A$6:$A$426,$P19) -> 5 | X19: =SUMIFS($K$6:$K$426,$E$6:$E$426,$Q19,$C$6:$C$426,X$5,$A$6:$A$426,$P19) -> 0 | Y19: =SUMIFS($K$6:$K$426,$E$6:$E$426,$Q19,$C$6:$C$426,Y$5,$A$6:$A$426,$P19) -> 0 | Z19: =SUM(R19:Y19) -> 5
A20: =A19 -> GERAL | B20: =B19 -> 1° PAV. TÉRREO | C20: Ventilação garagem (material) | D20: SEN-AP-EXT-002-TER-R00.pdf | E20: Ventilador de indução direcionador de ar compacto com motor eletrônico, com drive STG02-DRV, comunicação por wifi integrado. | F20: Storge | G20: STG-SJF 3000EC | H20: 115 | I20: 1 | J20: 0 | K20: =(H20+J20*H20)*I20 -> 115 | L20: un | M20: =_xlfn.XLOOKUP($E20,PREÇO!$C$6:$C$89,PREÇO!$E$6:$E$89) -> #N/A | N20: =IF(SUM(H20:M20)=0,SUMIFS($N21:$N$759,$B21:$B$759,$B20,$A21:$A$759,$A20),K20*M20) -> #N/A | P20: GERAL | Q20: Unidade evaporadora tipo Teto, capacidade 38.200 Btu/h, linha VRV, ciclo Q/F. | R20: =SUMIFS($K$6:$K$426,$E$6:$E$426,$Q20,$C$6:$C$426,R$5,$A$6:$A$426,$P20) -> 0 | S20: =SUMIFS($K$6:$K$426,$E$6:$E$426,$Q20,$C$6:$C$426,S$5,$A$6:$A$426,$P20) -> 0 | T20: =SUMIFS($K$6:$K$426,$E$6:$E$426,$Q20,$C$6:$C$426,T$5,$A$6:$A$426,$P20) -> 0 | U20: =SUMIFS($K$6:$K$426,$E$6:$E$426,$Q20,$C$6:$C$426,U$5,$A$6:$A$426,$P20) -> 0 | V20: =SUMIFS($K$6:$K$426,$E$6:$E$426,$Q20,$C$6:$C$426,V$5,$A$6:$A$426,$P20) -> 0 | W20: =SUMIFS($K$6:$K$426,$E$6:$E$426,$Q20,$C$6:$C$426,W$5,$A$6:$A$426,$P20) -> 11 | X20: =SUMIFS($K$6:$K$426,$E$6:$E$426,$Q20,$C$6:$C$426,X$5,$A$6:$A$426,$P20) -> 0 | Y20: =SUMIFS($K$6:$K$426,$E$6:$E$426,$Q20,$C$6:$C$426,Y$5,$A$6:$A$426,$P20) -> 0 | Z20: =SUM(R20:Y20) -> 11
A21: =A20 -> GERAL | B21: =B20 -> 1° PAV. TÉRREO | C21: Ventilação garagem (material) | D21: SEN-AP-EXT-002-TER-R00.pdf | E21: Ventilador tubo axial com motor eletrônico, vazão máxima de 11.000 m³/h, ruído máximo 76 dB(A) livre, com drive STG02-DRV, comunicação por wifi integrado. | F21: Storge | G21: STG-AFSW500 EC | H21: 10 | I21: 1 | J21: 0 | K21: =(H21+J21*H21)*I21 -> 10 | L21: un | M21: =_xlfn.XLOOKUP($E21,PREÇO!$C$6:$C$89,PREÇO!$E$6:$E$89) -> #N/A | N21: =IF(SUM(H21:M21)=0,SUMIFS($N22:$N$759,$B22:$B$759,$B21,$A22:$A$759,$A21),K21*M21) -> #N/A | P21: GERAL | Q21: Unidade evaporadora tipo cassete Round Flow, capacidade 38.200 Btu/h, linha VRV, ciclo Q/F. | R21: =SUMIFS($K$6:$K$426,$E$6:$E$426,$Q21,$C$6:$C$426,R$5,$A$6:$A$426,$P21) -> 0 | S21: =SUMIFS($K$6:$K$426,$E$6:$E$426,$Q21,$C$6:$C$426,S$5,$A$6:$A$426,$P21) -> 0 | T21: =SUMIFS($K$6:$K$426,$E$6:$E$426,$Q21,$C$6:$C$426,T$5,$A$6:$A$426,$P21) -> 0 | U21: =SUMIFS($K$6:$K$426,$E$6:$E$426,$Q21,$C$6:$C$426,U$5,$A$6:$A$426,$P21) -> 0 | V21: =SUMIFS($K$6:$K$426,$E$6:$E$426,$Q21,$C$6:$C$426,V$5,$A$6:$A$426,$P21) -> 0 | W21: =SUMIFS($K$6:$K$426,$E$6:$E$426,$Q21,$C$6:$C$426,W$5,$A$6:$A$426,$P21) -> 114 | X21: =SUMIFS($K$6:$K$426,$E$6:$E$426,$Q21,$C$6:$C$426,X$5,$A$6:$A$426,$P21) -> 0 | Y21: =SUMIFS($K$6:$K$426,$E$6:$E$426,$Q21,$C$6:$C$426,Y$5,$A$6:$A$426,$P21) -> 0 | Z21: =SUM(R21:Y21) -> 114
A22: =A21 -> GERAL | B22: =B21 -> 1° PAV. TÉRREO | C22: Ventilação garagem (material) | D22: SEN-AP-EXT-002-TER-R00.pdf | E22: Ventilador tubo axial com motor eletrônico, vazão máxima de 19.300 m³/h, ruído máximo 81 dB(A) livre, com drive STG02-DRV, comunicação por wifi integrado. | F22: Storge | G22: STG-AFSW800 EC | H22: 12 | I22: 1 | J22: 0 | K22: =(H22+J22*H22)*I22 -> 12 | L22: un | M22: =_xlfn.XLOOKUP($E22,PREÇO!$C$6:$C$89,PREÇO!$E$6:$E$89) -> #N/A | N22: =IF(SUM(H22:M22)=0,SUMIFS($N23:$N$759,$B23:$B$759,$B22,$A23:$A$759,$A22),K22*M22) -> #N/A | P22: GERAL | Q22: Unidade evaporadora tipo cassete Round Flow, capacidade 47.800 Btu/h, linha VRV, ciclo Q/F. | R22: =SUMIFS($K$6:$K$426,$E$6:$E$426,$Q22,$C$6:$C$426,R$5,$A$6:$A$426,$P22) -> 0 | S22: =SUMIFS($K$6:$K$426,$E$6:$E$426,$Q22,$C$6:$C$426,S$5,$A$6:$A$426,$P22) -> 0 | T22: =SUMIFS($K$6:$K$426,$E$6:$E$426,$Q22,$C$6:$C$426,T$5,$A$6:$A$426,$P22) -> 0 | U22: =SUMIFS($K$6:$K$426,$E$6:$E$426,$Q22,$C$6:$C$426,U$5,$A$6:$A$426,$P22) -> 0 | V22: =SUMIFS($K$6:$K$426,$E$6:$E$426,$Q22,$C$6:$C$426,V$5,$A$6:$A$426,$P22) -> 0 | W22: =SUMIFS($K$6:$K$426,$E$6:$E$426,$Q22,$C$6:$C$426,W$5,$A$6:$A$426,$P22) -> 129 | X22: =SUMIFS($K$6:$K$426,$E$6:$E$426,$Q22,$C$6:$C$426,X$5,$A$6:$A$426,$P22) -> 0 | Y22: =SUMIFS($K$6:$K$426,$E$6:$E$426,$Q22,$C$6:$C$426,Y$5,$A$6:$A$426,$P22) -> 0 | Z22: =SUM(R22:Y22) -> 129
A23: =A22 -> GERAL | B23: =B22 -> 1° PAV. TÉRREO | C23: Exaustão forçada e renovação de ar (material) | D23: SEN-AP-CLI-BLA-001-R01.pdf | E23: Ventilador helicocentrífugo, baixo nível de ruído, com elementos acústicos, junta de borracha na sucção e descarga. | F23: Soler & Palau | G23: TD-160/100 N SILENT | H23: 4 | I23: 1 | J23: 0 | K23: =(H23+J23*H23)*I23 -> 4 | L23: un | M23: =_xlfn.XLOOKUP($E23,PREÇO!$C$6:$C$89,PREÇO!$E$6:$E$89) -> #N/A | N23: =IF(SUM(H23:M23)=0,SUMIFS($N24:$N$759,$B24:$B$759,$B23,$A24:$A$759,$A23),K23*M23) -> #N/A | P23: GERAL | Q23: Gabinete de ventilação, com filtro G4+M5, paineis isolados | R23: =SUMIFS($K$6:$K$426,$E$6:$E$426,$Q23,$C$6:$C$426,R$5,$A$6:$A$426,$P23) -> 2 | S23: =SUMIFS($K$6:$K$426,$E$6:$E$426,$Q23,$C$6:$C$426,S$5,$A$6:$A$426,$P23) -> 0 | T23: =SUMIFS($K$6:$K$426,$E$6:$E$426,$Q23,$C$6:$C$426,T$5,$A$6:$A$426,$P23) -> 0 | U23: =SUMIFS($K$6:$K$426,$E$6:$E$426,$Q23,$C$6:$C$426,U$5,$A$6:$A$426,$P23) -> 8 | V23: =SUMIFS($K$6:$K$426,$E$6:$E$426,$Q23,$C$6:$C$426,V$5,$A$6:$A$426,$P23) -> 0 | W23: =SUMIFS($K$6:$K$426,$E$6:$E$426,$Q23,$C$6:$C$426,W$5,$A$6:$A$426,$P23) -> 0 | X23: =SUMIFS($K$6:$K$426,$E$6:$E$426,$Q23,$C$6:$C$426,X$5,$A$6:$A$426,$P23) -> 0 | Y23: =SUMIFS($K$6:$K$426,$E$6:$E$426,$Q23,$C$6:$C$426,Y$5,$A$6:$A$426,$P23) -> 0 | Z23: =SUM(R23:Y23) -> 10
A24: =A23 -> GERAL | B24: =B23 -> 1° PAV. TÉRREO | C24: Infraestrutura de climatização área comum (material) | D24: SEN-AP-CLI-BLA-001-R01.pdf | E24: Unidade condensadora linha VRV 6, Série R, Quente e Frio. | F24: Daikin | G24: REYQ26BYM | H24: 1 | I24: 1 | J24: 0 | K24: =(H24+J24*H24)*I24 -> 1 | L24: un | M24: =_xlfn.XLOOKUP($E24,PREÇO!$C$6:$C$89,PREÇO!$E$6:$E$89) -> #N/A | N24: =IF(SUM(H24:M24)=0,SUMIFS($N25:$N$759,$B25:$B$759,$B24,$A25:$A$759,$A24),K24*M24) -> #N/A | P24: GERAL | Q24: Grelha redonda fixa com colarinho, em plástico ABS, colarinho de Ø100m. | R24: =SUMIFS($K$6:$K$426,$E$6:$E$426,$Q24,$C$6:$C$426,R$5,$A$6:$A$426,$P24) -> 8 | S24: =SUMIFS($K$6:$K$426,$E$6:$E$426,$Q24,$C$6:$C$426,S$5,$A$6:$A$426,$P24) -> 0 | T24: =SUMIFS($K$6:$K$426,$E$6:$E$426,$Q24,$C$6:$C$426,T$5,$A$6:$A$426,$P24) -> 0 | U24: =SUMIFS($K$6:$K$426,$E$6:$E$426,$Q24,$C$6:$C$426,U$5,$A$6:$A$426,$P24) -> 12 | V24: =SUMIFS($K$6:$K$426,$E$6:$E$426,$Q24,$C$6:$C$426,V$5,$A$6:$A$426,$P24) -> 0 | W24: =SUMIFS($K$6:$K$426,$E$6:$E$426,$Q24,$C$6:$C$426,W$5,$A$6:$A$426,$P24) -> 0 | X24: =SUMIFS($K$6:$K$426,$E$6:$E$426,$Q24,$C$6:$C$426,X$5,$A$6:$A$426,$P24) -> 0 | Y24: =SUMIFS($K$6:$K$426,$E$6:$E$426,$Q24,$C$6:$C$426,Y$5,$A$6:$A$426,$P24) -> 0 | Z24: =SUM(R24:Y24) -> 20
A25: =A24 -> GERAL | B25: =B24 -> 1° PAV. TÉRREO | C25: Infraestrutura de climatização área comum (material) | D25: SEN-AP-CLI-BLA-001-R01.pdf | E25: Unidade condensadora linha VRV 6, Série R, Quente e Frio. | F25: Daikin | G25: REYQ20BYM | H25: 1 | I25: 1 | J25: 0 | K25: =(H25+J25*H25)*I25 -> 1 | L25: un | M25: =_xlfn.XLOOKUP($E25,PREÇO!$C$6:$C$89,PREÇO!$E$6:$E$89) -> #N/A | N25: =IF(SUM(H25:M25)=0,SUMIFS($N26:$N$759,$B26:$B$759,$B25,$A26:$A$759,$A25),K25*M25) -> #N/A | P25: GERAL | Q25: Grelha metálica retangular, com registro de lâminas convergentes. | R25: =SUMIFS($K$6:$K$426,$E$6:$E$426,$Q25,$C$6:$C$426,R$5,$A$6:$A$426,$P25) -> 169 | S25: =SUMIFS($K$6:$K$426,$E$6:$E$426,$Q25,$C$6:$C$426,S$5,$A$6:$A$426,$P25) -> 0 | T25: =SUMIFS($K$6:$K$426,$E$6:$E$426,$Q25,$C$6:$C$426,T$5,$A$6:$A$426,$P25) -> 0 | U25: =SUMIFS($K$6:$K$426,$E$6:$E$426,$Q25,$C$6:$C$426,U$5,$A$6:$A$426,$P25) -> 29 | V25: =SUMIFS($K$6:$K$426,$E$6:$E$426,$Q25,$C$6:$C$426,V$5,$A$6:$A$426,$P25) -> 0 | W25: =SUMIFS($K$6:$K$426,$E$6:$E$426,$Q25,$C$6:$C$426,W$5,$A$6:$A$426,$P25) -> 0 | X25: =SUMIFS($K$6:$K$426,$E$6:$E$426,$Q25,$C$6:$C$426,X$5,$A$6:$A$426,$P25) -> 0 | Y25: =SUMIFS($K$6:$K$426,$E$6:$E$426,$Q25,$C$6:$C$426,Y$5,$A$6:$A$426,$P25) -> 0 | Z25: =SUM(R25:Y25) -> 198
A26: =A25 -> GERAL | B26: =B25 -> 1° PAV. TÉRREO | C26: Infraestrutura de climatização área comum (material) | D26: SEN-AP-CLI-BLA-001-R01.pdf | E26: Unidade evaporadora tipo Teto, capacidade 12.300 Btu/h, linha VRV, ciclo Q/F. | F26: Daikin | G26: FXHQ32MAVE | H26: 1 | I26: 1 | J26: 0 | K26: =(H26+J26*H26)*I26 -> 1 | L26: un | M26: =_xlfn.XLOOKUP($E26,PREÇO!$C$6:$C$89,PREÇO!$E$6:$E$89) -> #N/A | N26: =IF(SUM(H26:M26)=0,SUMIFS($N27:$N$759,$B27:$B$759,$B26,$A27:$A$759,$A26),K26*M26) -> #N/A | P26: GERAL | Q26: Coifa Lavadora tipo Ilha com 5 Estágios de Filtragem. Vazão de 5.760 m³/h. | R26: =SUMIFS($K$6:$K$426,$E$6:$E$426,$Q26,$C$6:$C$426,R$5,$A$6:$A$426,$P26) -> 0 | S26: =SUMIFS($K$6:$K$426,$E$6:$E$426,$Q26,$C$6:$C$426,S$5,$A$6:$A$426,$P26) -> 0 | T26: =SUMIFS($K$6:$K$426,$E$6:$E$426,$Q26,$C$6:$C$426,T$5,$A$6:$A$426,$P26) -> 0 | U26: =SUMIFS($K$6:$K$426,$E$6:$E$426,$Q26,$C$6:$C$426,U$5,$A$6:$A$426,$P26) -> 0 | V26: =SUMIFS($K$6:$K$426,$E$6:$E$426,$Q26,$C$6:$C$426,V$5,$A$6:$A$426,$P26) -> 1 | W26: =SUMIFS($K$6:$K$426,$E$6:$E$426,$Q26,$C$6:$C$426,W$5,$A$6:$A$426,$P26) -> 0 | X26: =SUMIFS($K$6:$K$426,$E$6:$E$426,$Q26,$C$6:$C$426,X$5,$A$6:$A$426,$P26) -> 0 | Y26: =SUMIFS($K$6:$K$426,$E$6:$E$426,$Q26,$C$6:$C$426,Y$5,$A$6:$A$426,$P26) -> 0 | Z26: =SUM(R26:Y26) -> 1
A27: =A26 -> GERAL | B27: =B26 -> 1° PAV. TÉRREO | C27: Infraestrutura de climatização área comum (material) | D27: SEN-AP-CLI-BLA-001-R01.pdf | E27: Unidade evaporadora tipo Teto, capacidade 24.200 Btu/h, linha VRV, ciclo Q/F. | F27: Daikin | G27: FXHQ63MAVE | H27: 1 | I27: 1 | J27: 0 | K27: =(H27+J27*H27)*I27 -> 1 | L27: un | M27: =_xlfn.XLOOKUP($E27,PREÇO!$C$6:$C$89,PREÇO!$E$6:$E$89) -> #N/A | N27: =IF(SUM(H27:M27)=0,SUMIFS($N28:$N$759,$B28:$B$759,$B27,$A28:$A$759,$A27),K27*M27) -> #N/A | P27: GERAL | Q27: Unidade condensadora VRF de 4 HP, Só Frio, retangular de descarga horizontal. | R27: =SUMIFS($K$6:$K$426,$E$6:$E$426,$Q27,$C$6:$C$426,R$5,$A$6:$A$426,$P27) -> 0 | S27: =SUMIFS($K$6:$K$426,$E$6:$E$426,$Q27,$C$6:$C$426,S$5,$A$6:$A$426,$P27) -> 0 | T27: =SUMIFS($K$6:$K$426,$E$6:$E$426,$Q27,$C$6:$C$426,T$5,$A$6:$A$426,$P27) -> 0 | U27: =SUMIFS($K$6:$K$426,$E$6:$E$426,$Q27,$C$6:$C$426,U$5,$A$6:$A$426,$P27) -> 0 | V27: =SUMIFS($K$6:$K$426,$E$6:$E$426,$Q27,$C$6:$C$426,V$5,$A$6:$A$426,$P27) -> 0 | W27: =SUMIFS($K$6:$K$426,$E$6:$E$426,$Q27,$C$6:$C$426,W$5,$A$6:$A$426,$P27) -> 2 | X27: =SUMIFS($K$6:$K$426,$E$6:$E$426,$Q27,$C$6:$C$426,X$5,$A$6:$A$426,$P27) -> 0 | Y27: =SUMIFS($K$6:$K$426,$E$6:$E$426,$Q27,$C$6:$C$426,Y$5,$A$6:$A$426,$P27) -> 0 | Z27: =SUM(R27:Y27) -> 2
A28: =A27 -> GERAL | B28: =B27 -> 1° PAV. TÉRREO | C28: Infraestrutura de climatização área comum (material) | D28: SEN-AP-CLI-BLA-001-R01.pdf | E28: Unidade evaporadora tipo Teto, capacidade 38.200 Btu/h, linha VRV, ciclo Q/F. | F28: Daikin | G28: FXHQ100MAVE | H28: 1 | I28: 1 | J28: 0 | K28: =(H28+J28*H28)*I28 -> 1 | L28: un | M28: =_xlfn.XLOOKUP($E28,PREÇO!$C$6:$C$89,PREÇO!$E$6:$E$89) -> #N/A | N28: =IF(SUM(H28:M28)=0,SUMIFS($N29:$N$759,$B29:$B$759,$B28,$A29:$A$759,$A28),K28*M28) -> #N/A | P28: GERAL | Q28: Unidade Condensadora Linha VRV 6, Série R, Quente e Frio Simultaneo 10 HP, 231 kg | R28: =SUMIFS($K$6:$K$426,$E$6:$E$426,$Q28,$C$6:$C$426,R$5,$A$6:$A$426,$P28) -> 0 | S28: =SUMIFS($K$6:$K$426,$E$6:$E$426,$Q28,$C$6:$C$426,S$5,$A$6:$A$426,$P28) -> 0 | T28: =SUMIFS($K$6:$K$426,$E$6:$E$426,$Q28,$C$6:$C$426,T$5,$A$6:$A$426,$P28) -> 0 | U28: =SUMIFS($K$6:$K$426,$E$6:$E$426,$Q28,$C$6:$C$426,U$5,$A$6:$A$426,$P28) -> 0 | V28: =SUMIFS($K$6:$K$426,$E$6:$E$426,$Q28,$C$6:$C$426,V$5,$A$6:$A$426,$P28) -> 0 | W28: =SUMIFS($K$6:$K$426,$E$6:$E$426,$Q28,$C$6:$C$426,W$5,$A$6:$A$426,$P28) -> 1 | X28: =SUMIFS($K$6:$K$426,$E$6:$E$426,$Q28,$C$6:$C$426,X$5,$A$6:$A$426,$P28) -> 0 | Y28: =SUMIFS($K$6:$K$426,$E$6:$E$426,$Q28,$C$6:$C$426,Y$5,$A$6:$A$426,$P28) -> 0 | Z28: =SUM(R28:Y28) -> 1
A29: =A28 -> GERAL | B29: =B28 -> 1° PAV. TÉRREO | C29: Infraestrutura de climatização área comum (material) | D29: SEN-AP-CLI-BLA-001-R01.pdf | E29: Unidade evaporadora tipo cassete Round Flow, capacidade 38.200 Btu/h, linha VRV, ciclo Q/F. | F29: Daikin | G29: FXFQ100AVM | H29: 3 | I29: 1 | J29: 0 | K29: =(H29+J29*H29)*I29 -> 3 | L29: un | M29: =_xlfn.XLOOKUP($E29,PREÇO!$C$6:$C$89,PREÇO!$E$6:$E$89) -> #N/A | N29: =IF(SUM(H29:M29)=0,SUMIFS($N30:$N$759,$B30:$B$759,$B29,$A30:$A$759,$A29),K29*M29) -> #N/A | P29: GERAL | Q29: Unidade evaporadora tipo Hi-wall, capacidade 7.500 Btu/h, linha VRV, ciclo Q/F. | R29: =SUMIFS($K$6:$K$426,$E$6:$E$426,$Q29,$C$6:$C$426,R$5,$A$6:$A$426,$P29) -> 0 | S29: =SUMIFS($K$6:$K$426,$E$6:$E$426,$Q29,$C$6:$C$426,S$5,$A$6:$A$426,$P29) -> 0 | T29: =SUMIFS($K$6:$K$426,$E$6:$E$426,$Q29,$C$6:$C$426,T$5,$A$6:$A$426,$P29) -> 0 | U29: =SUMIFS($K$6:$K$426,$E$6:$E$426,$Q29,$C$6:$C$426,U$5,$A$6:$A$426,$P29) -> 0 | V29: =SUMIFS($K$6:$K$426,$E$6:$E$426,$Q29,$C$6:$C$426,V$5,$A$6:$A$426,$P29) -> 0 | W29: =SUMIFS($K$6:$K$426,$E$6:$E$426,$Q29,$C$6:$C$426,W$5,$A$6:$A$426,$P29) -> 2 | X29: =SUMIFS($K$6:$K$426,$E$6:$E$426,$Q29,$C$6:$C$426,X$5,$A$6:$A$426,$P29) -> 0 | Y29: =SUMIFS($K$6:$K$426,$E$6:$E$426,$Q29,$C$6:$C$426,Y$5,$A$6:$A$426,$P29) -> 0 | Z29: =SUM(R29:Y29) -> 2
A30: =A29 -> GERAL | B30: =B29 -> 1° PAV. TÉRREO | C30: Infraestrutura de climatização área comum (material) | D30: SEN-AP-CLI-BLA-001-R01.pdf | E30: Unidade evaporadora tipo cassete Round Flow, capacidade 47.800 Btu/h, linha VRV, ciclo Q/F. | F30: Daikin | G30: FXFQ125AVM | H30: 6 | I30: 1 | J30: 0 | K30: =(H30+J30*H30)*I30 -> 6 | L30: un | M30: =_xlfn.XLOOKUP($E30,PREÇO!$C$6:$C$89,PREÇO!$E$6:$E$89) -> #N/A | N30: =IF(SUM(H30:M30)=0,SUMIFS($N31:$N$759,$B31:$B$759,$B30,$A31:$A$759,$A30),K30*M30) -> #N/A | P30: GERAL | Q30: Unidade evaporadora tipo Hi-wall, capacidade 15.400 Btu/h, linha VRV, ciclo Q/F. | R30: =SUMIFS($K$6:$K$426,$E$6:$E$426,$Q30,$C$6:$C$426,R$5,$A$6:$A$426,$P30) -> 0 | S30: =SUMIFS($K$6:$K$426,$E$6:$E$426,$Q30,$C$6:$C$426,S$5,$A$6:$A$426,$P30) -> 0 | T30: =SUMIFS($K$6:$K$426,$E$6:$E$426,$Q30,$C$6:$C$426,T$5,$A$6:$A$426,$P30) -> 0 | U30: =SUMIFS($K$6:$K$426,$E$6:$E$426,$Q30,$C$6:$C$426,U$5,$A$6:$A$426,$P30) -> 0 | V30: =SUMIFS($K$6:$K$426,$E$6:$E$426,$Q30,$C$6:$C$426,V$5,$A$6:$A$426,$P30) -> 0 | W30: =SUMIFS($K$6:$K$426,$E$6:$E$426,$Q30,$C$6:$C$426,W$5,$A$6:$A$426,$P30) -> 1 | X30: =SUMIFS($K$6:$K$426,$E$6:$E$426,$Q30,$C$6:$C$426,X$5,$A$6:$A$426,$P30) -> 0 | Y30: =SUMIFS($K$6:$K$426,$E$6:$E$426,$Q30,$C$6:$C$426,Y$5,$A$6:$A$426,$P30) -> 0 | Z30: =SUM(R30:Y30) -> 1
... A34: =A33 -> GERAL | B34: =B33 -> 1° PAV. TÉRREO | C34: Exaustão forçada e renovação de ar (material) | D34: SEN-AP-CLI-BLA-001-R01.pdf | E34: Grelha metálica retangular, com registro de lâminas convergentes. | F34: TROX | G34: AT-AG/225x125 | H34: 5 | I34: 1 | J34: 0 | K34: =(H34+J34*H34)*I34 -> 5 | L34: un | M34: =_xlfn.XLOOKUP($E34,PREÇO!$C$6:$C$89,PREÇO!$E$6:$E$89) -> #N/A | N34: =IF(SUM(H34:M34)=0,SUMIFS($N35:$N$759,$B35:$B$759,$B34,$A35:$A$759,$A34),K34*M34) -> #N/A | P34: GERAL | Q34: Unidade evaporadora inverter Hi-Wall, capacidade de 12.000 BTU/h, linha split, ciclo Q/F. Alimentação elétrica pela condensadora. | R34: =SUMIFS($K$6:$K$426,$E$6:$E$426,$Q34,$C$6:$C$426,R$5,$A$6:$A$426,$P34) -> 0 | S34: =SUMIFS($K$6:$K$426,$E$6:$E$426,$Q34,$C$6:$C$426,S$5,$A$6:$A$426,$P34) -> 0 | T34: =SUMIFS($K$6:$K$426,$E$6:$E$426,$Q34,$C$6:$C$426,T$5,$A$6:$A$426,$P34) -> 0 | U34: =SUMIFS($K$6:$K$426,$E$6:$E$426,$Q34,$C$6:$C$426,U$5,$A$6:$A$426,$P34) -> 0 | V34: =SUMIFS($K$6:$K$426,$E$6:$E$426,$Q34,$C$6:$C$426,V$5,$A$6:$A$426,$P34) -> 0 | W34: =SUMIFS($K$6:$K$426,$E$6:$E$426,$Q34,$C$6:$C$426,W$5,$A$6:$A$426,$P34) -> 2 | X34: =SUMIFS($K$6:$K$426,$E$6:$E$426,$Q34,$C$6:$C$426,X$5,$A$6:$A$426,$P34) -> 0 | Y34: =SUMIFS($K$6:$K$426,$E$6:$E$426,$Q34,$C$6:$C$426,Y$5,$A$6:$A$426,$P34) -> 0 | Z34: =SUM(R34:Y34) -> 2
A35: =A34 -> GERAL | B35: =B34 -> 1° PAV. TÉRREO | C35: Exaustão forçada e renovação de ar (material) | D35: SEN-AP-CLI-BLA-001-R01.pdf | E35: Grelha metálica retangular, com registro de lâminas convergentes. | F35: TROX | G35: AT-AG/225x165 | H35: 4 | I35: 1 | J35: 0 | K35: =(H35+J35*H35)*I35 -> 4 | L35: un | M35: =_xlfn.XLOOKUP($E35,PREÇO!$C$6:$C$89,PREÇO!$E$6:$E$89) -> #N/A | N35: =IF(SUM(H35:M35)=0,SUMIFS($N70:$N$759,$B70:$B$759,$B35,$A70:$A$759,$A35),K35*M35) -> #N/A | P35: GERAL | Q35: Gabinete de ventilação com filtro G4, para reposição de ar do sistema de exaustão de cozinha, vazão de 2.920 m³/h. | R35: =SUMIFS($K$6:$K$426,$E$6:$E$426,$Q35,$C$6:$C$426,R$5,$A$6:$A$426,$P35) -> 0 | S35: =SUMIFS($K$6:$K$426,$E$6:$E$426,$Q35,$C$6:$C$426,S$5,$A$6:$A$426,$P35) -> 0 | T35: =SUMIFS($K$6:$K$426,$E$6:$E$426,$Q35,$C$6:$C$426,T$5,$A$6:$A$426,$P35) -> 0 | U35: =SUMIFS($K$6:$K$426,$E$6:$E$426,$Q35,$C$6:$C$426,U$5,$A$6:$A$426,$P35) -> 0 | V35: =SUMIFS($K$6:$K$426,$E$6:$E$426,$Q35,$C$6:$C$426,V$5,$A$6:$A$426,$P35) -> 1 | W35: =SUMIFS($K$6:$K$426,$E$6:$E$426,$Q35,$C$6:$C$426,W$5,$A$6:$A$426,$P35) -> 0 | X35: =SUMIFS($K$6:$K$426,$E$6:$E$426,$Q35,$C$6:$C$426,X$5,$A$6:$A$426,$P35) -> 0 | Y35: =SUMIFS($K$6:$K$426,$E$6:$E$426,$Q35,$C$6:$C$426,Y$5,$A$6:$A$426,$P35) -> 0 | Z35: =SUM(R35:Y35) -> 1
A36: =A35 -> GERAL | B36: =B35 -> 1° PAV. TÉRREO | C36: Exaustor para coifa | D36: SEN-AP-CLI-102-TER-R01.pdf | E36: Coifa Lavadora tipo Ilha com 5 Estágios de Filtragem. Vazão de 5.760 m³/h. | F36: Melting | G36: Multi Vortex | H36: 1 | I36: 1 | J36: 0 | K36: =(H36+J36*H36)*I36 -> 1 | L36: un | P36: GERAL | Q36: Gabinete de ventilação, com filtro G4+M5, paineis isolados. | R36: =SUMIFS($K$6:$K$426,$E$6:$E$426,$Q36,$C$6:$C$426,R$5,$A$6:$A$426,$P36) -> 0 | S36: =SUMIFS($K$6:$K$426,$E$6:$E$426,$Q36,$C$6:$C$426,S$5,$A$6:$A$426,$P36) -> 0 | T36: =SUMIFS($K$6:$K$426,$E$6:$E$426,$Q36,$C$6:$C$426,T$5,$A$6:$A$426,$P36) -> 0 | U36: =SUMIFS($K$6:$K$426,$E$6:$E$426,$Q36,$C$6:$C$426,U$5,$A$6:$A$426,$P36) -> 0 | V36: =SUMIFS($K$6:$K$426,$E$6:$E$426,$Q36,$C$6:$C$426,V$5,$A$6:$A$426,$P36) -> 2 | W36: =SUMIFS($K$6:$K$426,$E$6:$E$426,$Q36,$C$6:$C$426,W$5,$A$6:$A$426,$P36) -> 0 | X36: =SUMIFS($K$6:$K$426,$E$6:$E$426,$Q36,$C$6:$C$426,X$5,$A$6:$A$426,$P36) -> 0 | Y36: =SUMIFS($K$6:$K$426,$E$6:$E$426,$Q36,$C$6:$C$426,Y$5,$A$6:$A$426,$P36) -> 0 | Z36: =SUM(R36:Y36) -> 2
A37: =A36 -> GERAL | B37: =B36 -> 1° PAV. TÉRREO | C37: Exaustão forçada e renovação de ar (material) | D37: SEN-AP-CLI-102-TER-R01.pdf | E37: Ventilador helicocentrífugo, baixo nível de ruído, com elementos acústicos, junta de borracha na sucção e descarga. | F37: Soler & Palau | G37: TD-160/100 N SILENT | H37: 4 | I37: 1 | J37: 0 | K37: =(H37+J37*H37)*I37 -> 4 | L37: un | P37: GERAL | Q37: Grelha redonda fixa com colarinho de DN Ø150 mm. | R37: =SUMIFS($K$6:$K$426,$E$6:$E$426,$Q37,$C$6:$C$426,R$5,$A$6:$A$426,$P37) -> 1 | S37: =SUMIFS($K$6:$K$426,$E$6:$E$426,$Q37,$C$6:$C$426,S$5,$A$6:$A$426,$P37) -> 0 | T37: =SUMIFS($K$6:$K$426,$E$6:$E$426,$Q37,$C$6:$C$426,T$5,$A$6:$A$426,$P37) -> 0 | U37: =SUMIFS($K$6:$K$426,$E$6:$E$426,$Q37,$C$6:$C$426,U$5,$A$6:$A$426,$P37) -> 0 | V37: =SUMIFS($K$6:$K$426,$E$6:$E$426,$Q37,$C$6:$C$426,V$5,$A$6:$A$426,$P37) -> 0 | W37: =SUMIFS($K$6:$K$426,$E$6:$E$426,$Q37,$C$6:$C$426,W$5,$A$6:$A$426,$P37) -> 0 | X37: =SUMIFS($K$6:$K$426,$E$6:$E$426,$Q37,$C$6:$C$426,X$5,$A$6:$A$426,$P37) -> 0 | Y37: =SUMIFS($K$6:$K$426,$E$6:$E$426,$Q37,$C$6:$C$426,Y$5,$A$6:$A$426,$P37) -> 0 | Z37: =SUM(R37:Y37) -> 1
A38: =A37 -> GERAL | B38: =B37 -> 1° PAV. TÉRREO | C38: Exaustão forçada e renovação de ar (material) | D38: SEN-AP-CLI-102-TER-R01.pdf | E38: Ventilador helicocentrífugo com caixa de bornes externa, motor regulável, duas velocidades. | F38: Soler & Palau | G38: TD-350/125 | H38: 2 | I38: 1 | J38: 0 | K38: =(H38+J38*H38)*I38 -> 2 | L38: un | P38: GERAL | Q38: Boca com regulador de vazão, em plástico ABS, diâmetro nominal de Ø150mm. | R38: =SUMIFS($K$6:$K$426,$E$6:$E$426,$Q38,$C$6:$C$426,R$5,$A$6:$A$426,$P38) -> 2 | S38: =SUMIFS($K$6:$K$426,$E$6:$E$426,$Q38,$C$6:$C$426,S$5,$A$6:$A$426,$P38) -> 0 | T38: =SUMIFS($K$6:$K$426,$E$6:$E$426,$Q38,$C$6:$C$426,T$5,$A$6:$A$426,$P38) -> 0 | U38: =SUMIFS($K$6:$K$426,$E$6:$E$426,$Q38,$C$6:$C$426,U$5,$A$6:$A$426,$P38) -> 0 | V38: =SUMIFS($K$6:$K$426,$E$6:$E$426,$Q38,$C$6:$C$426,V$5,$A$6:$A$426,$P38) -> 0 | W38: =SUMIFS($K$6:$K$426,$E$6:$E$426,$Q38,$C$6:$C$426,W$5,$A$6:$A$426,$P38) -> 0 | X38: =SUMIFS($K$6:$K$426,$E$6:$E$426,$Q38,$C$6:$C$426,X$5,$A$6:$A$426,$P38) -> 0 | Y38: =SUMIFS($K$6:$K$426,$E$6:$E$426,$Q38,$C$6:$C$426,Y$5,$A$6:$A$426,$P38) -> 0 | Z38: =SUM(R38:Y38) -> 2
A39: =A38 -> GERAL | B39: =B38 -> 1° PAV. TÉRREO | C39: Exaustão forçada e renovação de ar (material) | D39: SEN-AP-CLI-102-TER-R01.pdf | E39: Ventilador helicocentrífugo com caixa de bornes externa, motor regulável, duas velocidades. | F39: Soler & Palau | G39: TD-500/150 | H39: 3 | I39: 1 | J39: 0 | K39: =(H39+J39*H39)*I39 -> 3 | L39: un | P39: GERAL | Q39: Difusor de uma via de alumínio. | R39: =SUMIFS($K$6:$K$426,$E$6:$E$426,$Q39,$C$6:$C$426,R$5,$A$6:$A$426,$P39) -> 2 | S39: =SUMIFS($K$6:$K$426,$E$6:$E$426,$Q39,$C$6:$C$426,S$5,$A$6:$A$426,$P39) -> 0 | T39: =SUMIFS($K$6:$K$426,$E$6:$E$426,$Q39,$C$6:$C$426,T$5,$A$6:$A$426,$P39) -> 0 | U39: =SUMIFS($K$6:$K$426,$E$6:$E$426,$Q39,$C$6:$C$426,U$5,$A$6:$A$426,$P39) -> 0 | V39: =SUMIFS($K$6:$K$426,$E$6:$E$426,$Q39,$C$6:$C$426,V$5,$A$6:$A$426,$P39) -> 0 | W39: =SUMIFS($K$6:$K$426,$E$6:$E$426,$Q39,$C$6:$C$426,W$5,$A$6:$A$426,$P39) -> 0 | X39: =SUMIFS($K$6:$K$426,$E$6:$E$426,$Q39,$C$6:$C$426,X$5,$A$6:$A$426,$P39) -> 0 | Y39: =SUMIFS($K$6:$K$426,$E$6:$E$426,$Q39,$C$6:$C$426,Y$5,$A$6:$A$426,$P39) -> 0 | Z39: =SUM(R39:Y39) -> 2
A40: =A39 -> GERAL | B40: =B39 -> 1° PAV. TÉRREO | C40: Exaustão forçada e renovação de ar (material) | D40: SEN-AP-CLI-102-TER-R01.pdf | E40: Ventilador helicocentrífugo com caixa de bornes externa, motor regulável, duas velocidades. | F40: Soler & Palau | G40: TD-800/200 | H40: 4 | I40: 1 | J40: 0 | K40: =(H40+J40*H40)*I40 -> 4 | L40: un | P40: GERAL | Q40: Difusor de uma via de alumínio, com registro de lâminas convergentes. | R40: =SUMIFS($K$6:$K$426,$E$6:$E$426,$Q40,$C$6:$C$426,R$5,$A$6:$A$426,$P40) -> 4 | S40: =SUMIFS($K$6:$K$426,$E$6:$E$426,$Q40,$C$6:$C$426,S$5,$A$6:$A$426,$P40) -> 0 | T40: =SUMIFS($K$6:$K$426,$E$6:$E$426,$Q40,$C$6:$C$426,T$5,$A$6:$A$426,$P40) -> 0 | U40: =SUMIFS($K$6:$K$426,$E$6:$E$426,$Q40,$C$6:$C$426,U$5,$A$6:$A$426,$P40) -> 0 | V40: =SUMIFS($K$6:$K$426,$E$6:$E$426,$Q40,$C$6:$C$426,V$5,$A$6:$A$426,$P40) -> 0 | W40: =SUMIFS($K$6:$K$426,$E$6:$E$426,$Q40,$C$6:$C$426,W$5,$A$6:$A$426,$P40) -> 0 | X40: =SUMIFS($K$6:$K$426,$E$6:$E$426,$Q40,$C$6:$C$426,X$5,$A$6:$A$426,$P40) -> 0 | Y40: =SUMIFS($K$6:$K$426,$E$6:$E$426,$Q40,$C$6:$C$426,Y$5,$A$6:$A$426,$P40) -> 0 | Z40: =SUM(R40:Y40) -> 4
A41: =A40 -> GERAL | B41: =B40 -> 1° PAV. TÉRREO | C41: Infraestrutura de climatização área comum (material) | D41: SEN-AP-CLI-102-TER-R01.pdf | E41: Unidade condensadora VRF de 4 HP, Só Frio, retangular de descarga horizontal. | F41: Daikin | G41: RXMQ4AVE | H41: 1 | I41: 1 | J41: 0 | K41: =(H41+J41*H41)*I41 -> 1 | L41: un | P41: GERAL | Q41: Veneziana externa de alumínio com tela de insetos | R41: =SUMIFS($K$6:$K$426,$E$6:$E$426,$Q41,$C$6:$C$426,R$5,$A$6:$A$426,$P41) -> 3 | S41: =SUMIFS($K$6:$K$426,$E$6:$E$426,$Q41,$C$6:$C$426,S$5,$A$6:$A$426,$P41) -> 0 | T41: =SUMIFS($K$6:$K$426,$E$6:$E$426,$Q41,$C$6:$C$426,T$5,$A$6:$A$426,$P41) -> 0 | U41: =SUMIFS($K$6:$K$426,$E$6:$E$426,$Q41,$C$6:$C$426,U$5,$A$6:$A$426,$P41) -> 1 | V41: =SUMIFS($K$6:$K$426,$E$6:$E$426,$Q41,$C$6:$C$426,V$5,$A$6:$A$426,$P41) -> 1 | W41: =SUMIFS($K$6:$K$426,$E$6:$E$426,$Q41,$C$6:$C$426,W$5,$A$6:$A$426,$P41) -> 0 | X41: =SUMIFS($K$6:$K$426,$E$6:$E$426,$Q41,$C$6:$C$426,X$5,$A$6:$A$426,$P41) -> 0 | Y41: =SUMIFS($K$6:$K$426,$E$6:$E$426,$Q41,$C$6:$C$426,Y$5,$A$6:$A$426,$P41) -> 0 | Z41: =SUM(R41:Y41) -> 5
A42: =A41 -> GERAL | B42: =B41 -> 1° PAV. TÉRREO | C42: Infraestrutura de climatização área comum (material) | D42: SEN-AP-CLI-102-TER-R01.pdf | E42: Unidade Condensadora Linha VRV 6, Série R, Quente e Frio Simultaneo 10 HP, 231 kg | F42: Daikin | G42: REYQ10BYM9 | H42: 1 | I42: 1 | J42: 0 | K42: =(H42+J42*H42)*I42 -> 1 | L42: un | P42: GERAL | Q42: Grelha autofechante em plástico ABS com anti-UV, com colarinho de Ø100mm. | R42: =SUMIFS($K$6:$K$426,$E$6:$E$426,$Q42,$C$6:$C$426,R$5,$A$6:$A$426,$P42) -> 3 | S42: =SUMIFS($K$6:$K$426,$E$6:$E$426,$Q42,$C$6:$C$426,S$5,$A$6:$A$426,$P42) -> 0 | T42: =SUMIFS($K$6:$K$426,$E$6:$E$426,$Q42,$C$6:$C$426,T$5,$A$6:$A$426,$P42) -> 0 | U42: =SUMIFS($K$6:$K$426,$E$6:$E$426,$Q42,$C$6:$C$426,U$5,$A$6:$A$426,$P42) -> 0 | V42: =SUMIFS($K$6:$K$426,$E$6:$E$426,$Q42,$C$6:$C$426,V$5,$A$6:$A$426,$P42) -> 0 | W42: =SUMIFS($K$6:$K$426,$E$6:$E$426,$Q42,$C$6:$C$426,W$5,$A$6:$A$426,$P42) -> 0 | X42: =SUMIFS($K$6:$K$426,$E$6:$E$426,$Q42,$C$6:$C$426,X$5,$A$6:$A$426,$P42) -> 0 | Y42: =SUMIFS($K$6:$K$426,$E$6:$E$426,$Q42,$C$6:$C$426,Y$5,$A$6:$A$426,$P42) -> 0 | Z42: =SUM(R42:Y42) -> 3
A43: =A42 -> GERAL | B43: =B42 -> 1° PAV. TÉRREO | C43: Infraestrutura de climatização área comum (material) | D43: SEN-AP-CLI-102-TER-R01.pdf | E43: Unidade evaporadora tipo Hi-wall, capacidade 7.500 Btu/h, linha VRV, ciclo Q/F. | F43: Daikin | G43: FXAQ20AVM | H43: 2 | I43: 1 | J43: 0 | K43: =(H43+J43*H43)*I43 -> 2 | L43: un | P43: GERAL | Q43: Grelha autofechante em plástico ABS com anti-UV, com colarinho de Ø150mm. | R43: =SUMIFS($K$6:$K$426,$E$6:$E$426,$Q43,$C$6:$C$426,R$5,$A$6:$A$426,$P43) -> 1 | S43: =SUMIFS($K$6:$K$426,$E$6:$E$426,$Q43,$C$6:$C$426,S$5,$A$6:$A$426,$P43) -> 0 | T43: =SUMIFS($K$6:$K$426,$E$6:$E$426,$Q43,$C$6:$C$426,T$5,$A$6:$A$426,$P43) -> 0 | U43: =SUMIFS($K$6:$K$426,$E$6:$E$426,$Q43,$C$6:$C$426,U$5,$A$6:$A$426,$P43) -> 1 | V43: =SUMIFS($K$6:$K$426,$E$6:$E$426,$Q43,$C$6:$C$426,V$5,$A$6:$A$426,$P43) -> 0 | W43: =SUMIFS($K$6:$K$426,$E$6:$E$426,$Q43,$C$6:$C$426,W$5,$A$6:$A$426,$P43) -> 0 | X43: =SUMIFS($K$6:$K$426,$E$6:$E$426,$Q43,$C$6:$C$426,X$5,$A$6:$A$426,$P43) -> 0 | Y43: =SUMIFS($K$6:$K$426,$E$6:$E$426,$Q43,$C$6:$C$426,Y$5,$A$6:$A$426,$P43) -> 0 | Z43: =SUM(R43:Y43) -> 2
...

Sheet Planilha1
F1: Projeto
F2: Empresa
F3: Revisão
F5: GRUPO/EAP
F6: Ventilação garagem (material)
F7: Exaustão forçada e renovação de ar (material)
F8: Infraestrutura de climatização embasamento (material)
F9: Infraestrutura de climatização área comum (material)
F10: Exaustor para coifa
F11: Exaustão forçada - Ventokit apartamentos (material)
F12: Infraestrutura de climatização torre (material)
F13: Desumidificador (material
