Workbook
Name _: #REF!
Name _: #REF!
Name _: #REF!
Name _: #REF!
Name _: #REF!
Name __: #REF!
Name __: #REF!
Name __: #REF!
Name ______ACR10: #REF!
Name ______ACR10: #REF!
Name ______ACR10: #REF!
Name ______ACR10: #REF!
Name ______ACR10: #REF!
Name ______ACR15: #REF!
Name ______ACR15: #REF!
Name ______ACR15: #REF!
Name ______ACR15: #REF!
Name ______ACR15: #REF!
Name ______acr20: #REF!
Name ______acr20: #REF!
Name ______acr20: #REF!
Name ______acr20: #REF!
Name ______acr20: #REF!
Name ______acr5: #REF!
Name ______acr5: #REF!
Name ______acr5: #REF!
Name ______acr5: #REF!
Name ______acr5: #REF!
Name ______ARQ1: #REF!
Name ______ARQ1: #REF!
Name ______ARQ1: #REF!
Name ______ARQ1: #REF!
Name ______ARQ1: #REF!
Name ______QT100: #REF!
Name ______QT100: #REF!
Name ______QT100: #REF!
Name ______QT100: #REF!
Name ______QT100: #REF!
Name ______QT2: #REF!
Name ______QT2: #REF!
Name ______QT2: #REF!
Name ______QT2: #REF!
Name ______QT2: #REF!
Name ______QT3: #REF!
Name ______QT3: #REF!
Name ______QT3: #REF!
Name ______QT3: #REF!
Name ______QT3: #REF!
Name ______QT4: #REF!
Name ______QT4: #REF!
Name ______QT4: #REF!
Name ______QT4: #REF!
Name ______QT4: #REF!
Name ______QT50: #REF!
Name ______QT50: #REF!
Name ______QT50: #REF!
Name ______QT50: #REF!
Name ______QT50: #REF!
Name ______QT75: #REF!
Name ______QT75: #REF!

Sheet Obra 
C1: Projeto | D1: Mosaico
C2: Empresa | D2: Grupo DUO
C3: Revisão | D3: R00
A4: QUADRO DE ÁREAS
B6: Descrição | C6: Unidade | E6: Quantidade | G6: Imagens
B7: MESES DE OBRA | C7: MÊS | E7: 42
B8: ÁREA DO TERRENO | C8: M² | E8: 1140
B9: ÁREA CONSTRUÍDA | C9: M² | E9: 7672.04
B10: NÚMERO DE UNIDADES HABITACIONAIS | C10: UN | E10: 81
B11: NÚMERO DE UNIDADES COMERCIAIS | C11: UN | E11: 2
B12: ÁREA PRIVATIVA | C12: M² | E12: 4782.91
B13: NÚMERO DE PAVIMENTOS | C13: UN | E13: 16
B15: 1º Pavimento | C15: M² | E15: 787.31
B16: 2º Pavimento | C16: M² | E16: 785.88
B17: 3º Pavimento | C17: M² | E17: 808.07
B18: 4º Pavimento | C18: M² | E18: 506.35
B19: 5º Pavimento | C19: M² | E19: 506.35
... B30: Reservatórios | C30: M² | E30: 27.75
B34: ETAPA | C34: VALOR ORÇADO | D34: % | E34: VALOR / m²
B35: GERENCIAMENTO TÉCNICO E ADMINISTRATIVO | C35: ='Ger_Tec e Adm'!N121 -> 5188435.6 | D35: =C35/C$53 -> 0.1677078 | E35: =C35/$E$9 -> 676.27849
B36: MOVIMENTAÇÃO DE TERRA | C36: =Ger_Executivo!N8 -> 96602.73 | D36: =C36/C$53 -> 0.0031225272 | E36: =C36/$E$9 -> 12.591531
B37: INFRAESTRUTURA | C37: =Ger_Executivo!N18 -> 1590820.8 | D37: =C37/C$53 -> 0.051420712 | E37: =C37/$E$9 -> 207.35304
B38: SUPRAESTRUTURA | C38: =Ger_Executivo!N51 -> 5123650 | D38: =C38/C$53 -> 0.16561371 | E38: =C38/$E$9 -> 667.83411
B39: ALVENARIA | C39: =Ger_Executivo!N76 -> 1312845.6 | D39: =C39/C$53 -> 0.042435612 | E39: =C39/$E$9 -> 171.12079
B40: IMPERMEABILIZAÇÃO E TRATAMENTOS | C40: =Ger_Executivo!N92 -> 674300.8 | D40: =C40/C$53 -> 0.021795684 | E40: =C40/$E$9 -> 87.890679
B41: INSTALAÇÕES ELÉTRICAS, HIDRÁULICAS, GLP E PREVENTIVAS | C41: =Ger_Executivo!N116+Ger_Executivo!N128+Ger_Executivo!N144+Ger_Executivo!N156 -> 2428838.7 | D41: =C41/C$53 -> 0.078508289 | E41: =C41/$E$9 -> 316.58317
B42: EQUIPAMENTOS E SISTEMAS ESPECIAIS | C42: =Ger_Executivo!N162+Ger_Executivo!N169 -> 865640.05 | D42: =C42/C$53 -> 0.027980417 | E42: =C42/$E$9 -> 112.83049
B43: CLIMATIZAÇÃO, EXAUSTÃO MECÂNICA E PRESSURIZAÇÃO | C43: =Ger_Executivo!N176 -> 229561 | D43: =C43/C$53 -> 0.0074201885 | E43: =C43/$E$9 -> 29.921768
B44: REVESTIMENTOS INTERNOS DE PAREDE | C44: =Ger_Executivo!N184 -> 1510715.5 | D44: =C44/C$53 -> 0.048831437 | E44: =C44/$E$9 -> 196.91183
B45: REVESTIMENTOS INTERNOS DE TETO | C45: =Ger_Executivo!N204 -> 557998.01 | D45: =C45/C$53 -> 0.018036384 | E45: =C45/$E$9 -> 72.731373
B46: PISOS E PAVIMENTAÇÕES | C46: =Ger_Executivo!N212 -> 2160927.4 | D46: =C46/C$53 -> 0.069848488 | E46: =C46/$E$9 -> 281.66269
B47: SISTEMAS DE PINTURA INTERNA | C47: =Ger_Executivo!N237 -> 1247040.6 | D47: =C47/C$53 -> 0.040308573 | E47: =C47/$E$9 -> 162.54355
B48: ESQUADRIAS, VIDROS E FERRAGENS | C48: =Ger_Executivo!N259 -> 3562144.1 | D48: =C48/C$53 -> 0.11514055 | E48: =C48/$E$9 -> 464.30208
B49: LOUÇAS E METAIS | C49: =Ger_Executivo!N296 -> 251275.31 | D49: =C49/C$53 -> 0.0081220685 | E49: =C49/$E$9 -> 32.752085
B50: REVESTIMENTOS E ACABAMENTOS EM FACHADA | C50: =Ger_Executivo!N306 -> 2820993 | D50: =C50/C$53 -> 0.091184043 | E50: =C50/$E$9 -> 367.6979
B51: SERVIÇOS COMPLEMENTARES E FINAIS | C51: =Ger_Executivo!N326 -> 935038.96 | D51: =C51/C$53 -> 0.030223624 | E51: =C51/$E$9 -> 121.87618
B52: IMPREVISTOS | C52: =Ger_Executivo!N344 -> 380525.89 | D52: =C52/C$53 -> 0.012299885 | E52: =C52/$E$9 -> 49.599049
B53: TOTAL | C53: =SUM(C35:C52) -> 30937354 | D53: =SUM(D35:D52) -> 1 | E53: =SUM(E35:E52) -> 4032.4808
B54: CUB/SC | C54: 2999.38 | D54: 45931 | E54: =ROUND(+E53/C54,2)&" CUB" -> 1,34 CUB
B63: MOVIMENTAÇÃO DE TERRA
...

Sheet EPCs
A1: Obra | B1: ='Obra '!D1 -> Mosaico
A2: Empresa | B2: ='Obra '!D2 -> Grupo DUO
A3: Revisão | B3: ='Obra '!D3 -> R00 | K3: Guia pavimentos
A4: Equipamentos de proteção coletiva | K4: Pavimento | L4: Área | M4: Perímetro | N4: Pé Direito
A5: Bandejas de proteção
K6: ='Obra '!B15 -> 1º Pavimento | L6: ='Obra '!E15 -> 787.31 | M6: 135.43 | N6: 3.24
B7: Descrição | C7: Unidade | D7: Quantidade | F7: Imagem formulário | K7: ='Obra '!B16 -> 2º Pavimento | L7: ='Obra '!E16 -> 785.88 | M7: 120.85 | N7: 3.96 | O7: 15.95
B8: Perímetro de projeção embasamento - primária | C8: m | D8: 135.43 | K8: ='Obra '!B17 -> 3º Pavimento | L8: ='Obra '!E17 -> 808.07 | M8: 125.95 | N8: 3.24 | O8: 15.95
B9: Perímetro de projeção embasamento - secundária | C9: m | D9: 290.49 | K9: ='Obra '!B18 -> 4º Pavimento | L9: ='Obra '!E18 -> 506.35 | M9: 96.83 | N9: 3.24 | O9: 15.95
K10: ='Obra '!B19 -> 5º Pavimento | L10: ='Obra '!E19 -> 506.35 | M10: 96.83 | N10: 3.24 | O10: 15.95
K11: ='Obra '!B20 -> 6º Pavimento | L11: ='Obra '!E20 -> 506.35 | M11: 96.83 | N11: 3.24 | O11: 15.95
B12: Bandeja de proteção primária | C12: m | D12: =D8+D10 -> 135.43 | K12: ='Obra '!B21 -> 7º Pavimento | L12: ='Obra '!E21 -> 506.35 | M12: 96.83 | N12: 3.24 | O12: 37.075
B13: Bandeja de proteção secundária | C13: m | D13: =D9+D11 -> 290.49 | K13: ='Obra '!B22 -> 8º Pavimento | L13: ='Obra '!E22 -> 506.35 | M13: 96.83 | N13: 3.24 | O13: =29.4*24 -> 705.6
K14: ='Obra '!B23 -> 9º Pavimento | L14: ='Obra '!E23 -> 506.35 | M14: 96.83 | N14: 3.24
A15: Guarda - corpo de vãos | K15: ='Obra '!B24 -> 10º Pavimento | L15: ='Obra '!E24 -> 506.35 | M15: 96.83 | N15: 3.24
K16: ='Obra '!B25 -> 11º Pavimento | L16: ='Obra '!E25 -> 506.35 | M16: 96.83 | N16: 3.24 | O16: =SUM(O6:O15) -> 822.425
B17: Descrição | C17: Unidade | D17: Quantidade | F17: Imagem formulário | K17: ='Obra '!B26 -> 12º Pavimento | L17: ='Obra '!E26 -> 506.35 | M17: 96.83 | N17: 2.88
B18: Perímetro de vãos | C18: m | D18: 530.19 | K18: ='Obra '!B27 -> Mezanino | L18: ='Obra '!E27 -> 194.44 | M18: 96.83 | N18: 2.88
B19: Guarda - corpo de vãos | C19: m | D19: =D18 -> 530.19 | K19: ='Obra '!B28 -> Cobertura | L19: ='Obra '!E28 -> 483.01 | M19: 89.08 | N19: 4.32
K20: ='Obra '!B29 -> Barrilete | L20: ='Obra '!E29 -> 27.75 | M20: 60.35 | N20: 3
A21: Guarda - corpo de desforma | K21: ='Obra '!B30 -> Reservatórios | L21: ='Obra '!E30 -> 27.75 | M21: 27.92 | N21: 3.32
K22: ='Obra '!B31 -> 0 | M22: =SUM(M6:M21) -> 1527.88
B23: Descrição | C23: Unidade | D23: Quantidade | F23: Imagem formulário
B24: Perímetro de projeção da torre | C24: m | D24: 96.83
B25: Repetições de pavimentos** | C25: un | D25: 4
B26: Proteção de periferia pós desforma torre | C26: m | D26: =(D24*D25) -> 387.32
A28: Fechamento removível de vãos em madeira
B30: Descrição | C30: Unidade | D30: Quantidade | F30: Imagem formulário
B31: Área das portas de elevadores | C31: m2 | D31: =0.9*2.1 -> 1.89
B32: Quantidade de elevadores | C32: un | D32: 2
B33: Quantidade de portas de elevadores | C33: un | D33: 28
B34: Fechamento removível de vãos em madeira | C34: m2 | D34: =D31*D33 -> 52.92
A36: Fechamento removível de vãos de portas de entrada de apto em madeira
B38: Descrição | C38: Unidade | D38: Quantidade | F38: Imagem formulário
B39: Área das portas de entrada | C39: m2 | D39: =0.9*2.1 -> 1.89
B40: Quantidade de portas de entrada | C40: un | D40: 81
B41: Fechamento removível de vãos em madeira | C41: m2 | D41: =D39*D40 -> 153.09
A43: Tela fachadeira
B45: Descrição | C45: Unidade | D45: Quantidade | F45: Imagem formulário
B46: Area da fachada | C46: m² | D46: =SUMPRODUCT($M$7:$M$21,$N$7:$N$21) -> 4612.7884
...

Sheet CANTEIRO
A1: Obra | B1: ='Obra '!D1 -> Mosaico
A2: Empresa | B2: ='Obra '!D2 -> Grupo DUO
A3: Revisão | B3: ='Obra '!D3 -> R00
A4: Instalações de canteiro
A5: Instalações de canteiro
B7: Descrição | C7: Unidade | D7: Quantidade
B8: Produtividade média | C8: m2 / mês | D8: ='Obra '!$E$9/'Obra '!$E$7 -> 182.66762
B9: Pm | C9: h/m2 | D9: 49
B10: Numero de funcionários | C10: un | D10: =ROUNDUP((D9*'Obra '!$E$9)/'Obra '!$E$7/180,) -> 50
B11: Equipe administrativa | C11: un | D11: 2
B12: Pontos de água e esgoto | C12: un | D12: =ROUNDUP($D$10/20,0) -> 3 | E12: 20 funcionários/ponto
B13: Bebedouro | C13: un | D13: =ROUNDUP('Obra '!$E$13/5,0) -> 4 | E13: 1 / 5 pav.
B14: Ferramentas | C14: R$ | D14: =800*D10 -> 40000 | E14: 800,00/func.
B15: EPI | C15: R$ | D15: =500*(D10+D11) -> 26000 | E15: 500,00/func.
B16: Banheiro | C16: un | D16: =ROUNDUP($D$10/20,0) -> 3 | E16: 1/20 func
A18: Mobiliário de canteiro
B20: Descrição | C20: Unidade | D20: Quantidade | E20: Custo unitário | F20: Custo total
B21: Cadeira | C21: un | D21: =ROUNDUP(D11*1.5,) -> 3 | E21: 200 | F21: =D21*E21 -> 600
B22: Mesa | C22: un | D22: 1 | E22: 1000 | F22: =E22*D22 -> 1000
B23: Ar condicionado | C23: un | D23: 1 | E23: 5000 | F23: =E23*D23 -> 5000
B24: Armário | C24: m | D24: 4 | E24: 900 | F24: =E24*D24 -> 3600
B25: Escrivaninha | C25: un | D25: 5 | E25: 800 | F25: =E25*D25 -> 4000
B26: TOTAL | F26: =F23+F24+F25+F22+F21 -> 14200
B27: Descrição | C27: Unidade | D27: Quantidade | E27: Custo unitário | F27: Custo total
B28: Computador pessoal | C28: un | D28: 5 | E28: 6500 | F28: =D28*E28 -> 32500
B29: Impressora | C29: un | D29: 1 | E29: 2000 | F29: =E29*D29 -> 2000
B30: Roteador | C30: un | D30: 2 | E30: 500 | F30: =E30*D30 -> 1000
B31: TOTAL | F31: =+F28+F29+F30 -> 35500
A33: Instalações Provisórias (central de aço, formas, argamassa, almoxarifado geral, construções temporárias)
B35: Descrição | C35: Unidade | D35: Será utilizado | E35: Quantidade | F35: Custo unitário | G35: Custo total
B36: Central de aço | C36: m2 | D36: Sim | E36: =IF(D36="Sim",15,0) -> 15 | F36: 115.4849 | G36: =IF(D36="sim",E36*F36,0) -> 1732.2735
B37: Central de fôrmas | C37: m2 | D37: Sim | E37: =IF(D37="Sim",15,0) -> 15 | F37: 115.4849 | G37: =IF(D37="sim",E37*F37,0) -> 1732.2735
B38: Central de Argamassa | C38: m2 | D38: Sim | E38: =IF(D38="Sim",15,0) -> 15 | F38: 115.4849 | G38: =IF(D38="sim",E38*F38,0) -> 1732.2735
B39: Armazenamento de cerâmicas* | C39: m2 | D39: Sim | E39: =IF(D39="não",0,ROUNDUP(3*'Obra '!$E$10/COUNTIFS($D$39:$D$47,"Sim"),)) -> 35 | F39: 201.22489 | G39: =IF(D39="sim",E39*F39,0) -> 7042.8712
B40: Armazenamento de placas degesso* | C40: m2 | D40: Não | E40: =IF(D40="não",0,ROUNDUP(3*'Obra '!$E$10/COUNTIFS($D$39:$D$47,"Sim"),)) -> 0 | F40: 201.22489 | G40: =IF(D40="sim",E40*F40,0) -> 0
B41: Armazenamento de blocos* | C41: m2 | D41: Sim | E41: =IF(D41="não",0,ROUNDUP(3*'Obra '!$E$10/COUNTIFS($D$39:$D$47,"Sim"),)) -> 35 | F41: 201.22489 | G41: =IF(D41="sim",E41*F41,0) -> 7042.8712
B42: Armazenamento de contramarcos* | C42: m2 | D42: Sim | E42: =IF(D42="não",0,ROUNDUP(3*'Obra '!$E$10/COUNTIFS($D$39:$D$47,"Sim"),)) -> 35 | F42: 201.22489 | G42: =IF(D42="sim",E42*F42,0) -> 7042.8712
B43: Armazenamento de portas e rodapés* | C43: m2 | D43: Sim | E43: =IF(D43="não",0,ROUNDUP(3*'Obra '!$E$10/COUNTIFS($D$39:$D$47,"Sim"),)) -> 35 | F43: 201.22489 | G43: =IF(D43="sim",E43*F43,0) -> 7042.8712
B44: Armazenamento de esquadrias* | C44: m2 | D44: Não | E44: =IF(D44="não",0,ROUNDUP(3*'Obra '!$E$10/COUNTIFS($D$39:$D$47,"Sim"),)) -> 0 | F44: 201.22489 | G44: =IF(D44="sim",E44*F44,0) -> 0
B45: Armazenamento de instalações complementares* | C45: m2 | D45: Sim | E45: =IF(D45="não",0,ROUNDUP(3*'Obra '!$E$10/COUNTIFS($D$39:$D$47,"Sim"),)) -> 35 | F45: 201.22489 | G45: =IF(D45="sim",E45*F45,0) -> 7042.8712
...

Sheet Ensaios 
C1: Projeto | D1: ='Obra '!D1 -> Mosaico
C2: Empresa | D2: ='Obra '!D2 -> Grupo DUO
C3: Revisão | D3: ='Obra '!D3 -> R00
A4: ENSAIOS
A5: Item | B5: Descrição/Especificação | C5: Unid. | D5: V. Unit. (R$) | E5: Qtde. | F5: V. Total (R$) | G5: Observações
B6: CONTROLE TECNOLÓGICO - CONCRETO | F6: =SUM(F7:F12) -> 39640
A7: 1 | B7: Laudo e ART | C7: vb | D7: 1450 | E7: 1 | F7: =$D7*E7 -> 1450
A8: =A7+1 -> 2 | B8: Controle Tecnologico Infraestrutura - Coleta materiais da obra | C8: unid. | D8: 20 | E8: =ROUNDUP((Aço_Infraestrutura!P23)/8,0)*4 -> 188 | F8: =$D8*E8 -> 3760 | G8: 4 CPs por caminhão betoneira de 8m³
A9: =A8+1 -> 3 | B9: Controle Tecnologico Contenção - Coleta materiais da obra | C9: unid. | D9: 20 | E9: =ROUNDUP((Estacas!K13)/8,0)*4 -> 64 | F9: =$D9*E9 -> 1280 | G9: 4 CPs por caminhão betoneira de 8m³
A10: =A9+1 -> 4 | B10: Controle Tecnologico Supraestrutura - Coleta materiais da obra | C10: unid. | D10: 20 | E10: =ROUNDUP((Supraestrutura!P97)/8,0)*4 -> 864 | F10: =$D10*E10 -> 17280 | G10: 4 CPs por caminhão betoneira de 8m³
A11: =A8+1 -> 3 | B11: Controle Tecnológico - Ensaio de concreto endurecido/grouth - compressão simples / Detalhe: Concreto | C11: cps | D11: 12.5 | E11: =E8+E9+E10 -> 1116 | F11: =$D11*E11 -> 13950
A12: =A11+1 -> 4 | B12: Determinação do módulo de deformação tangente inicial (Eci) (módulo de elasticidade), Incluindo Avaliação Estática dos Resultados (NBR 8522 e NBR 12655) | C12: ensaio | D12: 480 | E12: =ROUNDUP('Obra '!E13/5,0) -> 4 | F12: =$D12*E12 -> 1920 | G12: A cada 5 pav. (e quando houver troca de fornecedor)
B13: ACUSTICA - ENSAIO DE RUIDOS ( PISO + FACHADA) | F13: =SUM(F14:F15) -> 0
A14: 1 | B14: Ensaio de Desempenho Acustico para piso Ensaio de ruído aéreo e ruído de impacto em Laje de dorm. | C14: ensaios | D14: 7500 | F14: =$D14*E14 -> 0 | G14: 1 ensaio
A15: =A14+1 -> 2 | B15: Ensaio de Desempenho Acustico para vedação externa Ensaio de isolamento a ruído aéreo em Fachada de dorm. | C15: ensaios | D15: 1500 | F15: =$D15*E15 -> 0 | G15: 1 ensaio
B16: ENSAIO PARA CAIXILHOS | F16: =SUM(F17:F19) -> 0
A17: 1 | B17: Permeabilidade ao ar Estanqueidade a agua Resistencias a cargas uniformes distribuidas | C17: ensaios | D17: 3174 | F17: =$D17*E17 -> 0 | G17: 1 ensaio por tipo de caixilho (dormitório, sala, área de serviço e banheiro e terraço, se houver)
A18: =A17+1 -> 2 | B18: Resistencia as operações de manuseio com manutenção SEM persiana integrada | C18: ensaios | D18: 2774 | F18: =$D18*E18 -> 0 | G18: 1 ensaio por tipo de caixilho (dormitório, sala, área de serviço e banheiro e terraço, se houver)
A19: =A18+1 -> 3 | B19: Resistencia as operações de manuseio com manutenção COM persiana integrada | C19: ensaios | D19: 4020 | F19: =$D19*E19 -> 0 | G19: 1 ensaio por tipo de caixilho (dormitório, sala, área de serviço e banheiro e terraço, se houver)
B20: ENSAIO PARA GUARDA-CORPO | F20: =F21 -> 4210
A21: 1 | B21: Ensaio de guarda-corpo Determinação do esforço horizontal, esforço vertical e Resistencia a impactos | C21: ensaios | D21: 4210 | E21: 1 | F21: =$D21*E21 -> 4210 | G21: 1 prototipo por projeto
B22: ENSAIOS PARA ARGAMASSA DE REVESTIMENTO (FACHADA) | F22: =F23 -> 1260
A23: 1 | B23: Ensaio de arrancamento de argamassa de revestimento Determinação da aderencia a tração | C23: ensaios | D23: 1260 | E23: 1 | F23: =$D23*E23 -> 1260 | G23: 1 ensaio por torre
B24: ENSAIO ARRANCAMENTO DE REBOCO | F24: =F25 -> 1260
A25: 1 | B25: Ensaio de arrancamento de argamassa de reboco Determinação da aderencia a tração | C25: ensaios | D25: 1260 | E25: 1 | F25: =$D25*E25 -> 1260 | G25: 1 ensaio por torre
B26: ENSAIO PARA REVESTIMENTOS CERÂMICOS | F26: =F27 -> 664.44444
A27: 1 | B27: Aderência em Revestimento Cerâmico Determinação da aderência a tração (NBR 13754) | C27: ensaios | D27: 664.44444 | E27: 1 | F27: =$D27*E27 -> 664.44444 | G27: Torre Alta: 1 ensaio por torre, por referência de produto
B28: ENSAIO PARA ANCORAGEM (GANHOS DA COBERTURA) | F28: =SUM(F29) -> 1680
A29: 1 | B29: Arrancamento de ganchos da cobertura Ensaio de Arrancamento | C29: ensaios | D29: 1680 | E29: 1 | F29: =$D29*E29 -> 1680 | G29: 1 ensaio por torre
B30: ENSAIOS PARA ALVENARIA ESTRUTURAL | F30: =SUM(F31:F36) -> 1728
A31: 1 | B31: Controle Tecnológico - Ensaio de concreto endurecido/grouth - compressão simples / Detalhe: Groute | C31: unid. | D31: 8.5 | G31: ≥ 12Mpa: 6 CP's x núm pav x núm torres + ANEXOS (CONSIDERAR +6 CPs PARA CADA PAVIMENTO DE ANEXOS - INCLUINDO EMBASAMENTO E PLATIBANDA - SE HOUVER) Torre alta: 6CPs por pavimento
A32: =A31+1 -> 2 | B32: Ensaio de Argamassa - Determinação da resistência a compressão - no cubo (NBR 15961-2/2011) | C32: unid. | D32: 18 | E32: =6*'Obra '!E13 -> 96 | F32: =E32*D32 -> 1728 | G32: ≥ 12Mpa: 6 CP's x núm pav x núm torres + ANEXOS (CONSIDERAR +6 CPs PARA CADA PAVIMENTO DE ANEXOS - INCLUINDO EMBASAMENTO E PLATIBANDA - SE HOUVER) Torre alta: 6CPs por pavimento P/ pavimento > 600m²: 12 CPs
A33: =A32+1 -> 3 | B33: Ensaio Prisma - Determinação da resistência a compressão - Oco (NBR 15961-2/2011) | C33: unid. | D33: 50 | G33: 12 CP's x núm pav x núm torres Torre alta: 12CPs por pavimento P/ pavimento > 600m²: 12 CPs
A34: =A33+1 -> 4 | B34: Ensaio Prisma - Determinação da resistência a compressão - Cheio (NBR 15961-2/2011) | C34: unid. | D34: 65 | G34: 12 CP's x núm pav x núm torres Torre alta: 12CPs por pavimento P/ pavimento > 600m²: 12 CPs
A35: =A34+1 -> 5 | B35: Ensaio de Bloco - Determinação da resistência a compressão com dimensionamento (NBR 12118) | C35: cps | D35: 40 | G35: 6 cps x núm classes de resistencia
A36: =A35+1 -> 6 | B36: Ensaio de Bloco - Determinação da absorção e área liquida (NBR 12118) | C36: unid | D36: 40 | G36: 3 cps x núm classe de resistencia
C37: SUBTOTAL: | F37: =F30+F28+F26+F22+F20+F16+F13+F6 -> 49182.444

Sheet Ger_Tec e Adm
G4: PROJETO: | I4: ='Obra '!D1 -> Mosaico | O4: REVISÃO: | P4: DATA
G5: EMPRESA: | I5: ='Obra '!D2 -> Grupo DUO | O5: ='Obra '!D3 -> R00 | P5: 45877
A6: Unidade Construtiva | B6: Célula Construtiva | C6: Etapa | D6: Subetapa | E6: Serviço | G6: GERENCIAMENTO EXECUTIVO
A7: 0 | B7: 0 | C7: 0 | D7: 0 | E7: 0 | G7: Atalho | H7: NIVEL | I7: Item | J7: Descrição | K7: Unidade | L7: Quant. | M7: Preço un | N7: Total | O7: Considerações | P7: Situação
A8: =IF($H8="UNIDADE CONSTRUTIVA",OFFSET(A8,-1,0)+1,LARGE(A$3:A7,1)) -> 0 | B8: =IF(H8="UNIDADE CONSTRUTIVA",0,IF(H8="CÉLULA CONSTRUTIVA",OFFSET(B8,-1,0)+1,OFFSET(B8,-1,0))) -> 1 | C8: =IF(H8="CÉLULA CONSTRUTIVA",0,IF(H8="ETAPA",OFFSET(C8,-1,0)+1,OFFSET(C8,-1,0))) -> 0 | D8: =IF(H8="ETAPA",0,IF(H8="SUBETAPA",OFFSET(D8,-1,0)+1,OFFSET(D8,-1,0))) -> 0 | E8: =IF(H8="Subetapa",0,IF(H8="serviço",OFFSET(E8,-1,0)+1,OFFSET(E8,-1,0))) -> 0 | H8: CÉLULA CONSTRUTIVA | I8: =IF(H8="Unidade Construtiva",TEXT(A8,"00"),IF(H8="Célula Construtiva",TEXT(B8,"00"),IF(H8="Etapa",CONCATENATE(TEXT(B8,"00"),".",TEXT(C8,"000")),IF(H8="Subetapa",CONCATENATE(TEXT(B8,"00"),".",TEXT(C8,"000"),".",TEXT(D8,"000")),IF(H8="Serviço",CONCATENATE(TEXT(B8,"00"),".",TEXT(C8,"000"),".",TEXT(D8,"000"),".",TEXT(E8,"000")),""))))) -> 01 | J8: SERVIÇOS TÉCNICOS | N8: =IF(H8="Serviço",M8*L8,IF(H8="CÉLULA CONSTRUTIVA",SUMIFS($N$8:$N$418,$B$8:$B$418,B8,$H$8:$H$418,"Serviço"),IF(H8="ETAPA",SUMIFS($N$8:$N$418,$B$8:$B$418,B8,$C$8:$C$418,C8,$H$8:$H$418,"Serviço"),IF(H8="SUBETAPA",SUMIFS($N$8:$N$418,$B$8:$B$418,B8,$C$8:$C$418,C8,$D$8:$D$418,D8,$H$8:$H$418,"Serviço"),0)))) -> 2526660.3
A9: =IF($H9="UNIDADE CONSTRUTIVA",OFFSET(A9,-1,0)+1,LARGE(A$3:A8,1)) -> 0 | B9: =IF(H9="UNIDADE CONSTRUTIVA",0,IF(H9="CÉLULA CONSTRUTIVA",OFFSET(B9,-1,0)+1,OFFSET(B9,-1,0))) -> 1 | C9: =IF(H9="CÉLULA CONSTRUTIVA",0,IF(H9="ETAPA",OFFSET(C9,-1,0)+1,OFFSET(C9,-1,0))) -> 1 | D9: =IF(H9="ETAPA",0,IF(H9="SUBETAPA",OFFSET(D9,-1,0)+1,OFFSET(D9,-1,0))) -> 0 | E9: =IF(H9="Subetapa",0,IF(H9="serviço",OFFSET(E9,-1,0)+1,OFFSET(E9,-1,0))) -> 0 | H9: ETAPA | I9: =IF(H9="Unidade Construtiva",TEXT(A9,"00"),IF(H9="Célula Construtiva",TEXT(B9,"00"),IF(H9="Etapa",CONCATENATE(TEXT(B9,"00"),".",TEXT(C9,"000")),IF(H9="Subetapa",CONCATENATE(TEXT(B9,"00"),".",TEXT(C9,"000"),".",TEXT(D9,"000")),IF(H9="Serviço",CONCATENATE(TEXT(B9,"00"),".",TEXT(C9,"000"),".",TEXT(D9,"000"),".",TEXT(E9,"000")),""))))) -> 01.001 | J9: ESTUDOS, PROJETOS, CONSULTORIA E ENSAIOS | N9: =IF(H9="Serviço",M9*L9,IF(H9="CÉLULA CONSTRUTIVA",SUMIFS($N$8:$N$418,$B$8:$B$418,B9,$H$8:$H$418,"Serviço"),IF(H9="ETAPA",SUMIFS($N$8:$N$418,$B$8:$B$418,B9,$C$8:$C$418,C9,$H$8:$H$418,"Serviço"),IF(H9="SUBETAPA",SUMIFS($N$8:$N$418,$B$8:$B$418,B9,$C$8:$C$418,C9,$D$8:$D$418,D9,$H$8:$H$418,"Serviço"),0)))) -> 852669.77
A10: =IF($H10="UNIDADE CONSTRUTIVA",OFFSET(A10,-1,0)+1,LARGE(A$3:A9,1)) -> 0 | B10: =IF(H10="UNIDADE CONSTRUTIVA",0,IF(H10="CÉLULA CONSTRUTIVA",OFFSET(B10,-1,0)+1,OFFSET(B10,-1,0))) -> 1 | C10: =IF(H10="CÉLULA CONSTRUTIVA",0,IF(H10="ETAPA",OFFSET(C10,-1,0)+1,OFFSET(C10,-1,0))) -> 1 | D10: =IF(H10="ETAPA",0,IF(H10="SUBETAPA",OFFSET(D10,-1,0)+1,OFFSET(D10,-1,0))) -> 1 | E10: =IF(H10="Subetapa",0,IF(H10="serviço",OFFSET(E10,-1,0)+1,OFFSET(E10,-1,0))) -> 0 | H10: SUBETAPA | I10: =IF(H10="Unidade Construtiva",TEXT(A10,"00"),IF(H10="Célula Construtiva",TEXT(B10,"00"),IF(H10="Etapa",CONCATENATE(TEXT(B10,"00"),".",TEXT(C10,"000")),IF(H10="Subetapa",CONCATENATE(TEXT(B10,"00"),".",TEXT(C10,"000"),".",TEXT(D10,"000")),IF(H10="Serviço",CONCATENATE(TEXT(B10,"00"),".",TEXT(C10,"000"),".",TEXT(D10,"000"),".",TEXT(E10,"000")),""))))) -> 01.001.001 | J10: Estudos | N10: =IF(H10="Serviço",M10*L10,IF(H10="CÉLULA CONSTRUTIVA",SUMIFS($N$8:$N$418,$B$8:$B$418,B10,$H$8:$H$418,"Serviço"),IF(H10="ETAPA",SUMIFS($N$8:$N$418,$B$8:$B$418,B10,$C$8:$C$418,C10,$H$8:$H$418,"Serviço"),IF(H10="SUBETAPA",SUMIFS($N$8:$N$418,$B$8:$B$418,B10,$C$8:$C$418,C10,$D$8:$D$418,D10,$H$8:$H$418,"Serviço"),0)))) -> 45800
A11: =IF($H11="UNIDADE CONSTRUTIVA",OFFSET(A11,-1,0)+1,LARGE(A$3:A10,1)) -> 0 | B11: =IF(H11="UNIDADE CONSTRUTIVA",0,IF(H11="CÉLULA CONSTRUTIVA",OFFSET(B11,-1,0)+1,OFFSET(B11,-1,0))) -> 1 | C11: =IF(H11="CÉLULA CONSTRUTIVA",0,IF(H11="ETAPA",OFFSET(C11,-1,0)+1,OFFSET(C11,-1,0))) -> 1 | D11: =IF(H11="ETAPA",0,IF(H11="SUBETAPA",OFFSET(D11,-1,0)+1,OFFSET(D11,-1,0))) -> 1 | E11: =IF(H11="Subetapa",0,IF(H11="serviço",OFFSET(E11,-1,0)+1,OFFSET(E11,-1,0))) -> 1 | H11: SERVIÇO | I11: =IF(H11="Unidade Construtiva",TEXT(A11,"00"),IF(H11="Célula Construtiva",TEXT(B11,"00"),IF(H11="Etapa",CONCATENATE(TEXT(B11,"00"),".",TEXT(C11,"000")),IF(H11="Subetapa",CONCATENATE(TEXT(B11,"00"),".",TEXT(C11,"000"),".",TEXT(D11,"000")),IF(H11="Serviço",CONCATENATE(TEXT(B11,"00"),".",TEXT(C11,"000"),".",TEXT(D11,"000"),".",TEXT(E11,"000")),""))))) -> 01.001.001.001 | J11: Levantamento topográfico | K11: vb | L11: 1 | M11: 1800 | N11: =IF(H11="Serviço",M11*L11,IF(H11="CÉLULA CONSTRUTIVA",SUMIFS($N$8:$N$418,$B$8:$B$418,B11,$H$8:$H$418,"Serviço"),IF(H11="ETAPA",SUMIFS($N$8:$N$418,$B$8:$B$418,B11,$C$8:$C$418,C11,$H$8:$H$418,"Serviço"),IF(H11="SUBETAPA",SUMIFS($N$8:$N$418,$B$8:$B$418,B11,$C$8:$C$418,C11,$D$8:$D$418,D11,$H$8:$H$418,"Serviço"),0)))) -> 1800 | O11: Valor informado em formulário | P11: Lançado ERP
A12: =IF($H12="UNIDADE CONSTRUTIVA",OFFSET(A12,-1,0)+1,LARGE(A$3:A11,1)) -> 0 | B12: =IF(H12="UNIDADE CONSTRUTIVA",0,IF(H12="CÉLULA CONSTRUTIVA",OFFSET(B12,-1,0)+1,OFFSET(B12,-1,0))) -> 1 | C12: =IF(H12="CÉLULA CONSTRUTIVA",0,IF(H12="ETAPA",OFFSET(C12,-1,0)+1,OFFSET(C12,-1,0))) -> 1 | D12: =IF(H12="ETAPA",0,IF(H12="SUBETAPA",OFFSET(D12,-1,0)+1,OFFSET(D12,-1,0))) -> 1 | E12: =IF(H12="Subetapa",0,IF(H12="serviço",OFFSET(E12,-1,0)+1,OFFSET(E12,-1,0))) -> 2 | H12: SERVIÇO | I12: =IF(H12="Unidade Construtiva",TEXT(A12,"00"),IF(H12="Célula Construtiva",TEXT(B12,"00"),IF(H12="Etapa",CONCATENATE(TEXT(B12,"00"),".",TEXT(C12,"000")),IF(H12="Subetapa",CONCATENATE(TEXT(B12,"00"),".",TEXT(C12,"000"),".",TEXT(D12,"000")),IF(H12="Serviço",CONCATENATE(TEXT(B12,"00"),".",TEXT(C12,"000"),".",TEXT(D12,"000"),".",TEXT(E12,"000")),""))))) -> 01.001.001.002 | J12: Sondagem do terreno | K12: vb | L12: 1 | M12: 44000 | N12: =IF(H12="Serviço",M12*L12,IF(H12="CÉLULA CONSTRUTIVA",SUMIFS($N$8:$N$418,$B$8:$B$418,B12,$H$8:$H$418,"Serviço"),IF(H12="ETAPA",SUMIFS($N$8:$N$418,$B$8:$B$418,B12,$C$8:$C$418,C12,$H$8:$H$418,"Serviço"),IF(H12="SUBETAPA",SUMIFS($N$8:$N$418,$B$8:$B$418,B12,$C$8:$C$418,C12,$D$8:$D$418,D12,$H$8:$H$418,"Serviço"),0)))) -> 44000 | O12: Valor informado em formulário | P12: Lançado ERP
A13: =IF($H13="UNIDADE CONSTRUTIVA",OFFSET(A13,-1,0)+1,LARGE(A$3:A12,1)) -> 0 | B13: =IF(H13="UNIDADE CONSTRUTIVA",0,IF(H13="CÉLULA CONSTRUTIVA",OFFSET(B13,-1,0)+1,OFFSET(B13,-1,0))) -> 1 | C13: =IF(H13="CÉLULA CONSTRUTIVA",0,IF(H13="ETAPA",OFFSET(C13,-1,0)+1,OFFSET(C13,-1,0))) -> 1 | D13: =IF(H13="ETAPA",0,IF(H13="SUBETAPA",OFFSET(D13,-1,0)+1,OFFSET(D13,-1,0))) -> 2 | E13: =IF(H13="Subetapa",0,IF(H13="serviço",OFFSET(E13,-1,0)+1,OFFSET(E13,-1,0))) -> 0 | H13: SUBETAPA | I13: =IF(H13="Unidade Construtiva",TEXT(A13,"00"),IF(H13="Célula Construtiva",TEXT(B13,"00"),IF(H13="Etapa",CONCATENATE(TEXT(B13,"00"),".",TEXT(C13,"000")),IF(H13="Subetapa",CONCATENATE(TEXT(B13,"00"),".",TEXT(C13,"000"),".",TEXT(D13,"000")),IF(H13="Serviço",CONCATENATE(TEXT(B13,"00"),".",TEXT(C13,"000"),".",TEXT(D13,"000"),".",TEXT(E13,"000")),""))))) -> 01.001.002 | J13: Projetos | N13: =IF(H13="Serviço",M13*L13,IF(H13="CÉLULA CONSTRUTIVA",SUMIFS($N$8:$N$418,$B$8:$B$418,B13,$H$8:$H$418,"Serviço"),IF(H13="ETAPA",SUMIFS($N$8:$N$418,$B$8:$B$418,B13,$C$8:$C$418,C13,$H$8:$H$418,"Serviço"),IF(H13="SUBETAPA",SUMIFS($N$8:$N$418,$B$8:$B$418,B13,$C$8:$C$418,C13,$D$8:$D$418,D13,$H$8:$H$418,"Serviço"),0)))) -> 614822.41
A14: =IF($H14="UNIDADE CONSTRUTIVA",OFFSET(A14,-1,0)+1,LARGE(A$3:A13,1)) -> 0 | B14: =IF(H14="UNIDADE CONSTRUTIVA",0,IF(H14="CÉLULA CONSTRUTIVA",OFFSET(B14,-1,0)+1,OFFSET(B14,-1,0))) -> 1 | C14: =IF(H14="CÉLULA CONSTRUTIVA",0,IF(H14="ETAPA",OFFSET(C14,-1,0)+1,OFFSET(C14,-1,0))) -> 1 | D14: =IF(H14="ETAPA",0,IF(H14="SUBETAPA",OFFSET(D14,-1,0)+1,OFFSET(D14,-1,0))) -> 2 | E14: =IF(H14="Subetapa",0,IF(H14="serviço",OFFSET(E14,-1,0)+1,OFFSET(E14,-1,0))) -> 1 | H14: SERVIÇO | I14: =IF(H14="Unidade Construtiva",TEXT(A14,"00"),IF(H14="Célula Construtiva",TEXT(B14,"00"),IF(H14="Etapa",CONCATENATE(TEXT(B14,"00"),".",TEXT(C14,"000")),IF(H14="Subetapa",CONCATENATE(TEXT(B14,"00"),".",TEXT(C14,"000"),".",TEXT(D14,"000")),IF(H14="Serviço",CONCATENATE(TEXT(B14,"00"),".",TEXT(C14,"000"),".",TEXT(D14,"000"),".",TEXT(E14,"000")),""))))) -> 01.001.002.001 | J14: Projeto Arquitetônico legal - incluindo: executivo + interiores + fachada | K14: vb | L14: 1 | M14: 320000 | N14: =IF(H14="Serviço",M14*L14,IF(H14="CÉLULA CONSTRUTIVA",SUMIFS($N$8:$N$418,$B$8:$B$418,B14,$H$8:$H$418,"Serviço"),IF(H14="ETAPA",SUMIFS($N$8:$N$418,$B$8:$B$418,B14,$C$8:$C$418,C14,$H$8:$H$418,"Serviço"),IF(H14="SUBETAPA",SUMIFS($N$8:$N$418,$B$8:$B$418,B14,$C$8:$C$418,C14,$D$8:$D$418,D14,$H$8:$H$418,"Serviço"),0)))) -> 320000 | O14: Valor informado em formulário | P14: Lançado ERP
A15: =IF($H15="UNIDADE CONSTRUTIVA",OFFSET(A15,-1,0)+1,LARGE(A$3:A14,1)) -> 0 | B15: =IF(H15="UNIDADE CONSTRUTIVA",0,IF(H15="CÉLULA CONSTRUTIVA",OFFSET(B15,-1,0)+1,OFFSET(B15,-1,0))) -> 1 | C15: =IF(H15="CÉLULA CONSTRUTIVA",0,IF(H15="ETAPA",OFFSET(C15,-1,0)+1,OFFSET(C15,-1,0))) -> 1 | D15: =IF(H15="ETAPA",0,IF(H15="SUBETAPA",OFFSET(D15,-1,0)+1,OFFSET(D15,-1,0))) -> 2 | E15: =IF(H15="Subetapa",0,IF(H15="serviço",OFFSET(E15,-1,0)+1,OFFSET(E15,-1,0))) -> 2 | H15: SERVIÇO | I15: =IF(H15="Unidade Construtiva",TEXT(A15,"00"),IF(H15="Célula Construtiva",TEXT(B15,"00"),IF(H15="Etapa",CONCATENATE(TEXT(B15,"00"),".",TEXT(C15,"000")),IF(H15="Subetapa",CONCATENATE(TEXT(B15,"00"),".",TEXT(C15,"000"),".",TEXT(D15,"000")),IF(H15="Serviço",CONCATENATE(TEXT(B15,"00"),".",TEXT(C15,"000"),".",TEXT(D15,"000"),".",TEXT(E15,"000")),""))))) -> 01.001.002.002 | J15: Projeto técnico de fachada | K15: vb | L15: 1 | M15: 9933.5054 | N15: =IF(H15="Serviço",M15*L15,IF(H15="CÉLULA CONSTRUTIVA",SUMIFS($N$8:$N$418,$B$8:$B$418,B15,$H$8:$H$418,"Serviço"),IF(H15="ETAPA",SUMIFS($N$8:$N$418,$B$8:$B$418,B15,$C$8:$C$418,C15,$H$8:$H$418,"Serviço"),IF(H15="SUBETAPA",SUMIFS($N$8:$N$418,$B$8:$B$418,B15,$C$8:$C$418,C15,$D$8:$D$418,D15,$H$8:$H$418,"Serviço"),0)))) -> 9933.5054 | O15: Estimado com base em índices históricos | P15: Lançado ERP
A16: =IF($H16="UNIDADE CONSTRUTIVA",OFFSET(A16,-1,0)+1,LARGE(A$3:A15,1)) -> 0 | B16: =IF(H16="UNIDADE CONSTRUTIVA",0,IF(H16="CÉLULA CONSTRUTIVA",OFFSET(B16,-1,0)+1,OFFSET(B16,-1,0))) -> 1 | C16: =IF(H16="CÉLULA CONSTRUTIVA",0,IF(H16="ETAPA",OFFSET(C16,-1,0)+1,OFFSET(C16,-1,0))) -> 1 | D16: =IF(H16="ETAPA",0,IF(H16="SUBETAPA",OFFSET(D16,-1,0)+1,OFFSET(D16,-1,0))) -> 2 | E16: =IF(H16="Subetapa",0,IF(H16="serviço",OFFSET(E16,-1,0)+1,OFFSET(E16,-1,0))) -> 3 | H16: SERVIÇO | I16: =IF(H16="Unidade Construtiva",TEXT(A16,"00"),IF(H16="Célula Construtiva",TEXT(B16,"00"),IF(H16="Etapa",CONCATENATE(TEXT(B16,"00"),".",TEXT(C16,"000")),IF(H16="Subetapa",CONCATENATE(TEXT(B16,"00"),".",TEXT(C16,"000"),".",TEXT(D16,"000")),IF(H16="Serviço",CONCATENATE(TEXT(B16,"00"),".",TEXT(C16,"000"),".",TEXT(D16,"000"),".",TEXT(E16,"000")),""))))) -> 01.001.002.003 | J16: Projeto de Estrutural/Fundações/ Elétrico/Hidro/PPCI/Gás | K16: vb | L16: 1 | M16: 170000 | N16: =IF(H16="Serviço",M16*L16,IF(H16="CÉLULA CONSTRUTIVA",SUMIFS($N$8:$N$418,$B$8:$B$418,B16,$H$8:$H$418,"Serviço"),IF(H16="ETAPA",SUMIFS($N$8:$N$418,$B$8:$B$418,B16,$C$8:$C$418,C16,$H$8:$H$418,"Serviço"),IF(H16="SUBETAPA",SUMIFS($N$8:$N$418,$B$8:$B$418,B16,$C$8:$C$418,C16,$D$8:$D$418,D16,$H$8:$H$418,"Serviço"),0)))) -> 170000 | O16: Valor informado em formulário | P16: Lançado ERP
A17: =IF($H17="UNIDADE CONSTRUTIVA",OFFSET(A17,-1,0)+1,LARGE(A$3:A16,1)) -> 0 | B17: =IF(H17="UNIDADE CONSTRUTIVA",0,IF(H17="CÉLULA CONSTRUTIVA",OFFSET(B17,-1,0)+1,OFFSET(B17,-1,0))) -> 1 | C17: =IF(H17="CÉLULA CONSTRUTIVA",0,IF(H17="ETAPA",OFFSET(C17,-1,0)+1,OFFSET(C17,-1,0))) -> 1 | D17: =IF(H17="ETAPA",0,IF(H17="SUBETAPA",OFFSET(D17,-1,0)+1,OFFSET(D17,-1,0))) -> 2 | E17: =IF(H17="Subetapa",0,IF(H17="serviço",OFFSET(E17,-1,0)+1,OFFSET(E17,-1,0))) -> 4 | H17: SERVIÇO | I17: =IF(H17="Unidade Construtiva",TEXT(A17,"00"),IF(H17="Célula Construtiva",TEXT(B17,"00"),IF(H17="Etapa",CONCATENATE(TEXT(B17,"00"),".",TEXT(C17,"000")),IF(H17="Subetapa",CONCATENATE(TEXT(B17,"00"),".",TEXT(C17,"000"),".",TEXT(D17,"000")),IF(H17="Serviço",CONCATENATE(TEXT(B17,"00"),".",TEXT(C17,"000"),".",TEXT(D17,"000"),".",TEXT(E17,"000")),""))))) -> 01.001.002.004 | J17: Projeto de Impermeabilização | K17: vb | L17: 1 | M17: 17221.491 | N17: =IF(H17="Serviço",M17*L17,IF(H17="CÉLULA CONSTRUTIVA",SUMIFS($N$8:$N$418,$B$8:$B$418,B17,$H$8:$H$418,"Serviço"),IF(H17="ETAPA",SUMIFS($N$8:$N$418,$B$8:$B$418,B17,$C$8:$C$418,C17,$H$8:$H$418,"Serviço"),IF(H17="SUBETAPA",SUMIFS($N$8:$N$418,$B$8:$B$418,B17,$C$8:$C$418,C17,$D$8:$D$418,D17,$H$8:$H$418,"Serviço"),0)))) -> 17221.491 | O17: Estimado com base em índices históricos | P17: Lançado ERP
A18: =IF($H18="UNIDADE CONSTRUTIVA",OFFSET(A18,-1,0)+1,LARGE(A$3:A17,1)) -> 0 | B18: =IF(H18="UNIDADE CONSTRUTIVA",0,IF(H18="CÉLULA CONSTRUTIVA",OFFSET(B18,-1,0)+1,OFFSET(B18,-1,0))) -> 1 | C18: =IF(H18="CÉLULA CONSTRUTIVA",0,IF(H18="ETAPA",OFFSET(C18,-1,0)+1,OFFSET(C18,-1,0))) -> 1 | D18: =IF(H18="ETAPA",0,IF(H18="SUBETAPA",OFFSET(D18,-1,0)+1,OFFSET(D18,-1,0))) -> 2 | E18: =IF(H18="Subetapa",0,IF(H18="serviço",OFFSET(E18,-1,0)+1,OFFSET(E18,-1,0))) -> 5 | H18: SERVIÇO | I18: =IF(H18="Unidade Construtiva",TEXT(A18,"00"),IF(H18="Célula Construtiva",TEXT(B18,"00"),IF(H18="Etapa",CONCATENATE(TEXT(B18,"00"),".",TEXT(C18,"000")),IF(H18="Subetapa",CONCATENATE(TEXT(B18,"00"),".",TEXT(C18,"000"),".",TEXT(D18,"000")),IF(H18="Serviço",CONCATENATE(TEXT(B18,"00"),".",TEXT(C18,"000"),".",TEXT(D18,"000"),".",TEXT(E18,"000")),""))))) -> 01.001.002.005 | J18: Projeto de segurança | K18: vb | L18: 1 | M18: 4998.6149 | N18: =IF(H18="Serviço",M18*L18,IF(H18="CÉLULA CONSTRUTIVA",SUMIFS($N$8:$N$418,$B$8:$B$418,B18,$H$8:$H$418,"Serviço"),IF(H18="ETAPA",SUMIFS($N$8:$N$418,$B$8:$B$418,B18,$C$8:$C$418,C18,$H$8:$H$418,"Serviço"),IF(H18="SUBETAPA",SUMIFS($N$8:$N$418,$B$8:$B$418,B18,$C$8:$C$418,C18,$D$8:$D$418,D18,$H$8:$H$418,"Serviço"),0)))) -> 4998.6149 | O18: Estimado com base em índices históricos | P18: Lançado ERP
A19: =IF($H19="UNIDADE CONSTRUTIVA",OFFSET(A19,-1,0)+1,LARGE(A$3:A18,1)) -> 0 | B19: =IF(H19="UNIDADE CONSTRUTIVA",0,IF(H19="CÉLULA CONSTRUTIVA",OFFSET(B19,-1,0)+1,OFFSET(B19,-1,0))) -> 1 | C19: =IF(H19="CÉLULA CONSTRUTIVA",0,IF(H19="ETAPA",OFFSET(C19,-1,0)+1,OFFSET(C19,-1,0))) -> 1 | D19: =IF(H19="ETAPA",0,IF(H19="SUBETAPA",OFFSET(D19,-1,0)+1,OFFSET(D19,-1,0))) -> 2 | E19: =IF(H19="Subetapa",0,IF(H19="serviço",OFFSET(E19,-1,0)+1,OFFSET(E19,-1,0))) -> 6 | H19: SERVIÇO | I19: =IF(H19="Unidade Construtiva",TEXT(A19,"00"),IF(H19="Célula Construtiva",TEXT(B19,"00"),IF(H19="Etapa",CONCATENATE(TEXT(B19,"00"),".",TEXT(C19,"000")),IF(H19="Subetapa",CONCATENATE(TEXT(B19,"00"),".",TEXT(C19,"000"),".",TEXT(D19,"000")),IF(H19="Serviço",CONCATENATE(TEXT(B19,"00"),".",TEXT(C19,"000"),".",TEXT(D19,"000"),".",TEXT(E19,"000")),""))))) -> 01.001.002.006 | J19: Projeto de climatização/exaustão | K19: vb | L19: 1 | M19: 29000 | N19: =IF(H19="Serviço",M19*L19,IF(H19="CÉLULA CONSTRUTIVA",SUMIFS($N$8:$N$418,$B$8:$B$418,B19,$H$8:$H$418,"Serviço"),IF(H19="ETAPA",SUMIFS($N$8:$N$418,$B$8:$B$418,B19,$C$8:$C$418,C19,$H$8:$H$418,"Serviço"),IF(H19="SUBETAPA",SUMIFS($N$8:$N$418,$B$8:$B$418,B19,$C$8:$C$418,C19,$D$8:$D$418,D19,$H$8:$H$418,"Serviço"),0)))) -> 29000 | O19: Valor informado em formulário | P19: Lançado ERP
A20: =IF($H20="UNIDADE CONSTRUTIVA",OFFSET(A20,-1,0)+1,LARGE(A$3:A19,1)) -> 0 | B20: =IF(H20="UNIDADE CONSTRUTIVA",0,IF(H20="CÉLULA CONSTRUTIVA",OFFSET(B20,-1,0)+1,OFFSET(B20,-1,0))) -> 1 | C20: =IF(H20="CÉLULA CONSTRUTIVA",0,IF(H20="ETAPA",OFFSET(C20,-1,0)+1,OFFSET(C20,-1,0))) -> 1 | D20: =IF(H20="ETAPA",0,IF(H20="SUBETAPA",OFFSET(D20,-1,0)+1,OFFSET(D20,-1,0))) -> 2 | E20: =IF(H20="Subetapa",0,IF(H20="serviço",OFFSET(E20,-1,0)+1,OFFSET(E20,-1,0))) -> 7 | H20: SERVIÇO | I20: =IF(H20="Unidade Construtiva",TEXT(A20,"00"),IF(H20="Célula Construtiva",TEXT(B20,"00"),IF(H20="Etapa",CONCATENATE(TEXT(B20,"00"),".",TEXT(C20,"000")),IF(H20="Subetapa",CONCATENATE(TEXT(B20,"00"),".",TEXT(C20,"000"),".",TEXT(D20,"000")),IF(H20="Serviço",CONCATENATE(TEXT(B20,"00"),".",TEXT(C20,"000"),".",TEXT(D20,"000"),".",TEXT(E20,"000")),""))))) -> 01.001.002.007 | J20: Projeto de irrigação | K20: vb | L20: 1 | M20: 5447.1484 | N20: =IF(H20="Serviço",M20*L20,IF(H20="CÉLULA CONSTRUTIVA",SUMIFS($N$8:$N$418,$B$8:$B$418,B20,$H$8:$H$418,"Serviço"),IF(H20="ETAPA",SUMIFS($N$8:$N$418,$B$8:$B$418,B20,$C$8:$C$418,C20,$H$8:$H$418,"Serviço"),IF(H20="SUBETAPA",SUMIFS($N$8:$N$418,$B$8:$B$418,B20,$C$8:$C$418,C20,$D$8:$D$418,D20,$H$8:$H$418,"Serviço"),0)))) -> 5447.1484 | O20: Estimado com base em índices históricos | P20: Lançado ERP
A21: =IF($H21="UNIDADE CONSTRUTIVA",OFFSET(A21,-1,0)+1,LARGE(A$3:A20,1)) -> 0 | B21: =IF(H21="UNIDADE CONSTRUTIVA",0,IF(H21="CÉLULA CONSTRUTIVA",OFFSET(B21,-1,0)+1,OFFSET(B21,-1,0))) -> 1 | C21: =IF(H21="CÉLULA CONSTRUTIVA",0,IF(H21="ETAPA",OFFSET(C21,-1,0)+1,OFFSET(C21,-1,0))) -> 1 | D21: =IF(H21="ETAPA",0,IF(H21="SUBETAPA",OFFSET(D21,-1,0)+1,OFFSET(D21,-1,0))) -> 2 | E21: =IF(H21="Subetapa",0,IF(H21="serviço",OFFSET(E21,-1,0)+1,OFFSET(E21,-1,0))) -> 8 | H21: SERVIÇO | I21: =IF(H21="Unidade Construtiva",TEXT(A21,"00"),IF(H21="Célula Construtiva",TEXT(B21,"00"),IF(H21="Etapa",CONCATENATE(TEXT(B21,"00"),".",TEXT(C21,"000")),IF(H21="Subetapa",CONCATENATE(TEXT(B21,"00"),".",TEXT(C21,"000"),".",TEXT(D21,"000")),IF(H21="Serviço",CONCATENATE(TEXT(B21,"00"),".",TEXT(C21,"000"),".",TEXT(D21,"000"),".",TEXT(E21,"000")),""))))) -> 01.001.002.008 | J21: Projeto de furações | K21: vb | L21: 1 | M21: 34500 | N21: =IF(H21="Serviço",M21*L21,IF(H21="CÉLULA CONSTRUTIVA",SUMIFS($N$8:$N$418,$B$8:$B$418,B21,$H$8:$H$418,"Serviço"),IF(H21="ETAPA",SUMIFS($N$8:$N$418,$B$8:$B$418,B21,$C$8:$C$418,C21,$H$8:$H$418,"Serviço"),IF(H21="SUBETAPA",SUMIFS($N$8:$N$418,$B$8:$B$418,B21,$C$8:$C$418,C21,$D$8:$D$418,D21,$H$8:$H$418,"Serviço"),0)))) -> 34500 | O21: Valor informado em formulário | P21: Lançado ERP
A22: =IF($H22="UNIDADE CONSTRUTIVA",OFFSET(A22,-1,0)+1,LARGE(A$3:A21,1)) -> 0 | B22: =IF(H22="UNIDADE CONSTRUTIVA",0,IF(H22="CÉLULA CONSTRUTIVA",OFFSET(B22,-1,0)+1,OFFSET(B22,-1,0))) -> 1 | C22: =IF(H22="CÉLULA CONSTRUTIVA",0,IF(H22="ETAPA",OFFSET(C22,-1,0)+1,OFFSET(C22,-1,0))) -> 1 | D22: =IF(H22="ETAPA",0,IF(H22="SUBETAPA",OFFSET(D22,-1,0)+1,OFFSET(D22,-1,0))) -> 2 | E22: =IF(H22="Subetapa",0,IF(H22="serviço",OFFSET(E22,-1,0)+1,OFFSET(E22,-1,0))) -> 9 | H22: SERVIÇO | I22: =IF(H22="Unidade Construtiva",TEXT(A22,"00"),IF(H22="Célula Construtiva",TEXT(B22,"00"),IF(H22="Etapa",CONCATENATE(TEXT(B22,"00"),".",TEXT(C22,"000")),IF(H22="Subetapa",CONCATENATE(TEXT(B22,"00"),".",TEXT(C22,"000"),".",TEXT(D22,"000")),IF(H22="Serviço",CONCATENATE(TEXT(B22,"00"),".",TEXT(C22,"000"),".",TEXT(D22,"000"),".",TEXT(E22,"000")),""))))) -> 01.001.002.009 | J22: Projeto de Piscina | K22: vb | L22: 1 | M22: 5703.7202 | N22: =IF(H22="Serviço",M22*L22,IF(H22="CÉLULA CONSTRUTIVA",SUMIFS($N$8:$N$418,$B$8:$B$418,B22,$H$8:$H$418,"Serviço"),IF(H22="ETAPA",SUMIFS($N$8:$N$418,$B$8:$B$418,B22,$C$8:$C$418,C22,$H$8:$H$418,"Serviço"),IF(H22="SUBETAPA",SUMIFS($N$8:$N$418,$B$8:$B$418,B22,$C$8:$C$418,C22,$D$8:$D$418,D22,$H$8:$H$418,"Serviço"),0)))) -> 5703.7202 | O22: Estimado com base em índices históricos | P22: Lançado ERP
A23: =IF($H23="UNIDADE CONSTRUTIVA",OFFSET(A23,-1,0)+1,LARGE(A$3:A22,1)) -> 0 | B23: =IF(H23="UNIDADE CONSTRUTIVA",0,IF(H23="CÉLULA CONSTRUTIVA",OFFSET(B23,-1,0)+1,OFFSET(B23,-1,0))) -> 1 | C23: =IF(H23="CÉLULA CONSTRUTIVA",0,IF(H23="ETAPA",OFFSET(C23,-1,0)+1,OFFSET(C23,-1,0))) -> 1 | D23: =IF(H23="ETAPA",0,IF(H23="SUBETAPA",OFFSET(D23,-1,0)+1,OFFSET(D23,-1,0))) -> 2 | E23: =IF(H23="Subetapa",0,IF(H23="serviço",OFFSET(E23,-1,0)+1,OFFSET(E23,-1,0))) -> 10 | H23: SERVIÇO | I23: =IF(H23="Unidade Construtiva",TEXT(A23,"00"),IF(H23="Célula Construtiva",TEXT(B23,"00"),IF(H23="Etapa",CONCATENATE(TEXT(B23,"00"),".",TEXT(C23,"000")),IF(H23="Subetapa",CONCATENATE(TEXT(B23,"00"),".",TEXT(C23,"000"),".",TEXT(D23,"000")),IF(H23="Serviço",CONCATENATE(TEXT(B23,"00"),".",TEXT(C23,"000"),".",TEXT(D23,"000"),".",TEXT(E23,"000")),""))))) -> 01.001.002.010 | J23: Projeto de Paisagismo | K23: vb | L23: 1 | M23: 18017.931 | N23: =IF(H23="Serviço",M23*L23,IF(H23="CÉLULA CONSTRUTIVA",SUMIFS($N$8:$N$418,$B$8:$B$418,B23,$H$8:$H$418,"Serviço"),IF(H23="ETAPA",SUMIFS($N$8:$N$418,$B$8:$B$418,B23,$C$8:$C$418,C23,$H$8:$H$418,"Serviço"),IF(H23="SUBETAPA",SUMIFS($N$8:$N$418,$B$8:$B$418,B23,$C$8:$C$418,C23,$D$8:$D$418,D23,$H$8:$H$418,"Serviço"),0)))) -> 18017.931 | O23: Estimado com base em índices históricos | P23: Lançado ERP
A24: =IF($H24="UNIDADE CONSTRUTIVA",OFFSET(A24,-1,0)+1,LARGE(A$3:A23,1)) -> 0 | B24: =IF(H24="UNIDADE CONSTRUTIVA",0,IF(H24="CÉLULA CONSTRUTIVA",OFFSET(B24,-1,0)+1,OFFSET(B24,-1,0))) -> 1 | C24: =IF(H24="CÉLULA CONSTRUTIVA",0,IF(H24="ETAPA",OFFSET(C24,-1,0)+1,OFFSET(C24,-1,0))) -> 1 | D24: =IF(H24="ETAPA",0,IF(H24="SUBETAPA",OFFSET(D24,-1,0)+1,OFFSET(D24,-1,0))) -> 3 | E24: =IF(H24="Subetapa",0,IF(H24="serviço",OFFSET(E24,-1,0)+1,OFFSET(E24,-1,0))) -> 0 | H24: SUBETAPA | I24: =IF(H24="Unidade Construtiva",TEXT(A24,"00"),IF(H24="Célula Construtiva",TEXT(B24,"00"),IF(H24="Etapa",CONCATENATE(TEXT(B24,"00"),".",TEXT(C24,"000")),IF(H24="Subetapa",CONCATENATE(TEXT(B24,"00"),".",TEXT(C24,"000"),".",TEXT(D24,"000")),IF(H24="Serviço",CONCATENATE(TEXT(B24,"00"),".",TEXT(C24,"000"),".",TEXT(D24,"000"),".",TEXT(E24,"000")),""))))) -> 01.001.003 | J24: Consultorias | N24: =IF(H24="Serviço",M24*L24,IF(H24="CÉLULA CONSTRUTIVA",SUMIFS($N$8:$N$418,$B$8:$B$418,B24,$H$8:$H$418,"Serviço"),IF(H24="ETAPA",SUMIFS($N$8:$N$418,$B$8:$B$418,B24,$C$8:$C$418,C24,$H$8:$H$418,"Serviço"),IF(H24="SUBETAPA",SUMIFS($N$8:$N$418,$B$8:$B$418,B24,$C$8:$C$418,C24,$D$8:$D$418,D24,$H$8:$H$418,"Serviço"),0)))) -> 141604.91
A25: =IF($H25="UNIDADE CONSTRUTIVA",OFFSET(A25,-1,0)+1,LARGE(A$3:A24,1)) -> 0 | B25: =IF(H25="UNIDADE CONSTRUTIVA",0,IF(H25="CÉLULA CONSTRUTIVA",OFFSET(B25,-1,0)+1,OFFSET(B25,-1,0))) -> 1 | C25: =IF(H25="CÉLULA CONSTRUTIVA",0,IF(H25="ETAPA",OFFSET(C25,-1,0)+1,OFFSET(C25,-1,0))) -> 1 | D25: =IF(H25="ETAPA",0,IF(H25="SUBETAPA",OFFSET(D25,-1,0)+1,OFFSET(D25,-1,0))) -> 3 | E25: =IF(H25="Subetapa",0,IF(H25="serviço",OFFSET(E25,-1,0)+1,OFFSET(E25,-1,0))) -> 1 | H25: SERVIÇO | I25: =IF(H25="Unidade Construtiva",TEXT(A25,"00"),IF(H25="Célula Construtiva",TEXT(B25,"00"),IF(H25="Etapa",CONCATENATE(TEXT(B25,"00"),".",TEXT(C25,"000")),IF(H25="Subetapa",CONCATENATE(TEXT(B25,"00"),".",TEXT(C25,"000"),".",TEXT(D25,"000")),IF(H25="Serviço",CONCATENATE(TEXT(B25,"00"),".",TEXT(C25,"000"),".",TEXT(D25,"000"),".",TEXT(E25,"000")),""))))) -> 01.001.003.001 | J25: Compatibilização de Projetos BIM | K25: vb | L25: 1 | M25: 68700 | N25: =IF(H25="Serviço",M25*L25,IF(H25="CÉLULA CONSTRUTIVA",SUMIFS($N$8:$N$418,$B$8:$B$418,B25,$H$8:$H$418,"Serviço"),IF(H25="ETAPA",SUMIFS($N$8:$N$418,$B$8:$B$418,B25,$C$8:$C$418,C25,$H$8:$H$418,"Serviço"),IF(H25="SUBETAPA",SUMIFS($N$8:$N$418,$B$8:$B$418,B25,$C$8:$C$418,C25,$D$8:$D$418,D25,$H$8:$H$418,"Serviço"),0)))) -> 68700 | O25: Valor informado em formulário | P25: Lançado ERP
A26: =IF($H26="UNIDADE CONSTRUTIVA",OFFSET(A26,-1,0)+1,LARGE(A$3:A25,1)) -> 0 | B26: =IF(H26="UNIDADE CONSTRUTIVA",0,IF(H26="CÉLULA CONSTRUTIVA",OFFSET(B26,-1,0)+1,OFFSET(B26,-1,0))) -> 1 | C26: =IF(H26="CÉLULA CONSTRUTIVA",0,IF(H26="ETAPA",OFFSET(C26,-1,0)+1,OFFSET(C26,-1,0))) -> 1 | D26: =IF(H26="ETAPA",0,IF(H26="SUBETAPA",OFFSET(D26,-1,0)+1,OFFSET(D26,-1,0))) -> 3 | E26: =IF(H26="Subetapa",0,IF(H26="serviço",OFFSET(E26,-1,0)+1,OFFSET(E26,-1,0))) -> 2 | H26: SERVIÇO | I26: =IF(H26="Unidade Construtiva",TEXT(A26,"00"),IF(H26="Célula Construtiva",TEXT(B26,"00"),IF(H26="Etapa",CONCATENATE(TEXT(B26,"00"),".",TEXT(C26,"000")),IF(H26="Subetapa",CONCATENATE(TEXT(B26,"00"),".",TEXT(C26,"000"),".",TEXT(D26,"000")),IF(H26="Serviço",CONCATENATE(TEXT(B26,"00"),".",TEXT(C26,"000"),".",TEXT(D26,"000"),".",TEXT(E26,"000")),""))))) -> 01.001.003.002 | J26: Orçamento e planejamento | K26: vb | L26: 1 | M26: 43209.164 | N26: =IF(H26="Serviço",M26*L26,IF(H26="CÉLULA CONSTRUTIVA",SUMIFS($N$8:$N$418,$B$8:$B$418,B26,$H$8:$H$418,"Serviço"),IF(H26="ETAPA",SUMIFS($N$8:$N$418,$B$8:$B$418,B26,$C$8:$C$418,C26,$H$8:$H$418,"Serviço"),IF(H26="SUBETAPA",SUMIFS($N$8:$N$418,$B$8:$B$418,B26,$C$8:$C$418,C26,$D$8:$D$418,D26,$H$8:$H$418,"Serviço"),0)))) -> 43209.164 | O26: Valor informado em formulário | P26: Lançado ERP
A27: =IF($H27="UNIDADE CONSTRUTIVA",OFFSET(A27,-1,0)+1,LARGE(A$3:A26,1)) -> 0 | B27: =IF(H27="UNIDADE CONSTRUTIVA",0,IF(H27="CÉLULA CONSTRUTIVA",OFFSET(B27,-1,0)+1,OFFSET(B27,-1,0))) -> 1 | C27: =IF(H27="CÉLULA CONSTRUTIVA",0,IF(H27="ETAPA",OFFSET(C27,-1,0)+1,OFFSET(C27,-1,0))) -> 1 | D27: =IF(H27="ETAPA",0,IF(H27="SUBETAPA",OFFSET(D27,-1,0)+1,OFFSET(D27,-1,0))) -> 3 | E27: =IF(H27="Subetapa",0,IF(H27="serviço",OFFSET(E27,-1,0)+1,OFFSET(E27,-1,0))) -> 3 | H27: SERVIÇO | I27: =IF(H27="Unidade Construtiva",TEXT(A27,"00"),IF(H27="Célula Construtiva",TEXT(B27,"00"),IF(H27="Etapa",CONCATENATE(TEXT(B27,"00"),".",TEXT(C27,"000")),IF(H27="Subetapa",CONCATENATE(TEXT(B27,"00"),".",TEXT(C27,"000"),".",TEXT(D27,"000")),IF(H27="Serviço",CONCATENATE(TEXT(B27,"00"),".",TEXT(C27,"000"),".",TEXT(D27,"000"),".",TEXT(E27,"000")),""))))) -> 01.001.003.003 | J27: Consultoria técnica de fachada | K27: vb | L27: 1 | M27: 29695.746 | N27: =IF(H27="Serviço",M27*L27,IF(H27="CÉLULA CONSTRUTIVA",SUMIFS($N$8:$N$418,$B$8:$B$418,B27,$H$8:$H$418,"Serviço"),IF(H27="ETAPA",SUMIFS($N$8:$N$418,$B$8:$B$418,B27,$C$8:$C$418,C27,$H$8:$H$418,"Serviço"),IF(H27="SUBETAPA",SUMIFS($N$8:$N$418,$B$8:$B$418,B27,$C$8:$C$418,C27,$D$8:$D$418,D27,$H$8:$H$418,"Serviço"),0)))) -> 29695.746 | O27: Estimado com base em índices históricos | P27: Lançado ERP
A28: =IF($H28="UNIDADE CONSTRUTIVA",OFFSET(A28,-1,0)+1,LARGE(A$3:A27,1)) -> 0 | B28: =IF(H28="UNIDADE CONSTRUTIVA",0,IF(H28="CÉLULA CONSTRUTIVA",OFFSET(B28,-1,0)+1,OFFSET(B28,-1,0))) -> 1 | C28: =IF(H28="CÉLULA CONSTRUTIVA",0,IF(H28="ETAPA",OFFSET(C28,-1,0)+1,OFFSET(C28,-1,0))) -> 1 | D28: =IF(H28="ETAPA",0,IF(H28="SUBETAPA",OFFSET(D28,-1,0)+1,OFFSET(D28,-1,0))) -> 4 | E28: =IF(H28="Subetapa",0,IF(H28="serviço",OFFSET(E28,-1,0)+1,OFFSET(E28,-1,0))) -> 0 | H28: SUBETAPA | I28: =IF(H28="Unidade Construtiva",TEXT(A28,"00"),IF(H28="Célula Construtiva",TEXT(B28,"00"),IF(H28="Etapa",CONCATENATE(TEXT(B28,"00"),".",TEXT(C28,"000")),IF(H28="Subetapa",CONCATENATE(TEXT(B28,"00"),".",TEXT(C28,"000"),".",TEXT(D28,"000")),IF(H28="Serviço",CONCATENATE(TEXT(B28,"00"),".",TEXT(C28,"000"),".",TEXT(D28,"000"),".",TEXT(E28,"000")),""))))) -> 01.001.004 | J28: Ensaios | N28: =IF(H28="Serviço",M28*L28,IF(H28="CÉLULA CONSTRUTIVA",SUMIFS($N$8:$N$418,$B$8:$B$418,B28,$H$8:$H$418,"Serviço"),IF(H28="ETAPA",SUMIFS($N$8:$N$418,$B$8:$B$418,B28,$C$8:$C$418,C28,$H$8:$H$418,"Serviço"),IF(H28="SUBETAPA",SUMIFS($N$8:$N$418,$B$8:$B$418,B28,$C$8:$C$418,C28,$D$8:$D$418,D28,$H$8:$H$418,"Serviço"),0)))) -> 50442.444
A29: =IF($H29="UNIDADE CONSTRUTIVA",OFFSET(A29,-1,0)+1,LARGE(A$3:A28,1)) -> 0 | B29: =IF(H29="UNIDADE CONSTRUTIVA",0,IF(H29="CÉLULA CONSTRUTIVA",OFFSET(B29,-1,0)+1,OFFSET(B29,-1,0))) -> 1 | C29: =IF(H29="CÉLULA CONSTRUTIVA",0,IF(H29="ETAPA",OFFSET(C29,-1,0)+1,OFFSET(C29,-1,0))) -> 1 | D29: =IF(H29="ETAPA",0,IF(H29="SUBETAPA",OFFSET(D29,-1,0)+1,OFFSET(D29,-1,0))) -> 4 | E29: =IF(H29="Subetapa",0,IF(H29="serviço",OFFSET(E29,-1,0)+1,OFFSET(E29,-1,0))) -> 1 | H29: SERVIÇO | I29: =IF(H29="Unidade Construtiva",TEXT(A29,"00"),IF(H29="Célula Construtiva",TEXT(B29,"00"),IF(H29="Etapa",CONCATENATE(TEXT(B29,"00"),".",TEXT(C29,"000")),IF(H29="Subetapa",CONCATENATE(TEXT(B29,"00"),".",TEXT(C29,"000"),".",TEXT(D29,"000")),IF(H29="Serviço",CONCATENATE(TEXT(B29,"00"),".",TEXT(C29,"000"),".",TEXT(D29,"000"),".",TEXT(E29,"000")),""))))) -> 01.001.004.001 | J29: Controle Tecnologico de Concreto | K29: vb | L29: 1 | M29: ='Ensaios '!F6 -> 39640 | N29: =IF(H29="Serviço",M29*L29,IF(H29="CÉLULA CONSTRUTIVA",SUMIFS($N$8:$N$418,$B$8:$B$418,B29,$H$8:$H$418,"Serviço"),IF(H29="ETAPA",SUMIFS($N$8:$N$418,$B$8:$B$418,B29,$C$8:$C$418,C29,$H$8:$H$418,"Serviço"),IF(H29="SUBETAPA",SUMIFS($N$8:$N$418,$B$8:$B$418,B29,$C$8:$C$418,C29,$D$8:$D$418,D29,$H$8:$H$418,"Serviço"),0)))) -> 39640 | O29: Estimado com base em índices históricos | P29: Lançado ERP
A30: =IF($H30="UNIDADE CONSTRUTIVA",OFFSET(A30,-1,0)+1,LARGE(A$3:A29,1)) -> 0 | B30: =IF(H30="UNIDADE CONSTRUTIVA",0,IF(H30="CÉLULA CONSTRUTIVA",OFFSET(B30,-1,0)+1,OFFSET(B30,-1,0))) -> 1 | C30: =IF(H30="CÉLULA CONSTRUTIVA",0,IF(H30="ETAPA",OFFSET(C30,-1,0)+1,OFFSET(C30,-1,0))) -> 1 | D30: =IF(H30="ETAPA",0,IF(H30="SUBETAPA",OFFSET(D30,-1,0)+1,OFFSET(D30,-1,0))) -> 4 | E30: =IF(H30="Subetapa",0,IF(H30="serviço",OFFSET(E30,-1,0)+1,OFFSET(E30,-1,0))) -> 2 | H30: SERVIÇO | I30: =IF(H30="Unidade Construtiva",TEXT(A30,"00"),IF(H30="Célula Construtiva",TEXT(B30,"00"),IF(H30="Etapa",CONCATENATE(TEXT(B30,"00"),".",TEXT(C30,"000")),IF(H30="Subetapa",CONCATENATE(TEXT(B30,"00"),".",TEXT(C30,"000"),".",TEXT(D30,"000")),IF(H30="Serviço",CONCATENATE(TEXT(B30,"00"),".",TEXT(C30,"000"),".",TEXT(D30,"000"),".",TEXT(E30,"000")),""))))) -> 01.001.004.002 | J30: Ensaio de argamassa | K30: vb | L30: 1 | M30: 1728 | N30: =IF(H30="Serviço",M30*L30,IF(H30="CÉLULA CONSTRUTIVA",SUMIFS($N$8:$N$418,$B$8:$B$418,B30,$H$8:$H$418,"Serviço"),IF(H30="ETAPA",SUMIFS($N$8:$N$418,$B$8:$B$418,B30,$C$8:$C$418,C30,$H$8:$H$418,"Serviço"),IF(H30="SUBETAPA",SUMIFS($N$8:$N$418,$B$8:$B$418,B30,$C$8:$C$418,C30,$D$8:$D$418,D30,$H$8:$H$418,"Serviço"),0)))) -> 1728 | O30: Estimado com base em índices históricos | P30: Lançado ERP
A31: =IF($H31="UNIDADE CONSTRUTIVA",OFFSET(A31,-1,0)+1,LARGE(A$3:A30,1)) -> 0 | B31: =IF(H31="UNIDADE CONSTRUTIVA",0,IF(H31="CÉLULA CONSTRUTIVA",OFFSET(B31,-1,0)+1,OFFSET(B31,-1,0))) -> 1 | C31: =IF(H31="CÉLULA CONSTRUTIVA",0,IF(H31="ETAPA",OFFSET(C31,-1,0)+1,OFFSET(C31,-1,0))) -> 1 | D31: =IF(H31="ETAPA",0,IF(H31="SUBETAPA",OFFSET(D31,-1,0)+1,OFFSET(D31,-1,0))) -> 4 | E31: =IF(H31="Subetapa",0,IF(H31="serviço",OFFSET(E31,-1,0)+1,OFFSET(E31,-1,0))) -> 3 | H31: SERVIÇO | I31: =IF(H31="Unidade Construtiva",TEXT(A31,"00"),IF(H31="Célula Construtiva",TEXT(B31,"00"),IF(H31="Etapa",CONCATENATE(TEXT(B31,"00"),".",TEXT(C31,"000")),IF(H31="Subetapa",CONCATENATE(TEXT(B31,"00"),".",TEXT(C31,"000"),".",TEXT(D31,"000")),IF(H31="Serviço",CONCATENATE(TEXT(B31,"00"),".",TEXT(C31,"000"),".",TEXT(D31,"000"),".",TEXT(E31,"000")),""))))) -> 01.001.004.003 | J31: Ensaio de guarda-corpo | K31: vb | L31: 1 | M31: 4210 | N31: =IF(H31="Serviço",M31*L31,IF(H31="CÉLULA CONSTRUTIVA",SUMIFS($N$8:$N$418,$B$8:$B$418,B31,$H$8:$H$418,"Serviço"),IF(H31="ETAPA",SUMIFS($N$8:$N$418,$B$8:$B$418,B31,$C$8:$C$418,C31,$H$8:$H$418,"Serviço"),IF(H31="SUBETAPA",SUMIFS($N$8:$N$418,$B$8:$B$418,B31,$C$8:$C$418,C31,$D$8:$D$418,D31,$H$8:$H$418,"Serviço"),0)))) -> 4210 | O31: Estimado com base em índices históricos | P31: Lançado ERP
A32: =IF($H32="UNIDADE CONSTRUTIVA",OFFSET(A32,-1,0)+1,LARGE(A$3:A31,1)) -> 0 | B32: =IF(H32="UNIDADE CONSTRUTIVA",0,IF(H32="CÉLULA CONSTRUTIVA",OFFSET(B32,-1,0)+1,OFFSET(B32,-1,0))) -> 1 | C32: =IF(H32="CÉLULA CONSTRUTIVA",0,IF(H32="ETAPA",OFFSET(C32,-1,0)+1,OFFSET(C32,-1,0))) -> 1 | D32: =IF(H32="ETAPA",0,IF(H32="SUBETAPA",OFFSET(D32,-1,0)+1,OFFSET(D32,-1,0))) -> 4 | E32: =IF(H32="Subetapa",0,IF(H32="serviço",OFFSET(E32,-1,0)+1,OFFSET(E32,-1,0))) -> 4 | H32: SERVIÇO | I32: =IF(H32="Unidade Construtiva",TEXT(A32,"00"),IF(H32="Célula Construtiva",TEXT(B32,"00"),IF(H32="Etapa",CONCATENATE(TEXT(B32,"00"),".",TEXT(C32,"000")),IF(H32="Subetapa",CONCATENATE(TEXT(B32,"00"),".",TEXT(C32,"000"),".",TEXT(D32,"000")),IF(H32="Serviço",CONCATENATE(TEXT(B32,"00"),".",TEXT(C32,"000"),".",TEXT(D32,"000"),".",TEXT(E32,"000")),""))))) -> 01.001.004.004 | J32: Ensaio de arrancamento de reboco | K32: vb | L32: 1 | M32: 1260 | N32: =IF(H32="Serviço",M32*L32,IF(H32="CÉLULA CONSTRUTIVA",SUMIFS($N$8:$N$418,$B$8:$B$418,B32,$H$8:$H$418,"Serviço"),IF(H32="ETAPA",SUMIFS($N$8:$N$418,$B$8:$B$418,B32,$C$8:$C$418,C32,$H$8:$H$418,"Serviço"),IF(H32="SUBETAPA",SUMIFS($N$8:$N$418,$B$8:$B$418,B32,$C$8:$C$418,C32,$D$8:$D$418,D32,$H$8:$H$418,"Serviço"),0)))) -> 1260 | O32: Estimado com base em índices históricos | P32: Lançado ERP
A33: =IF($H33="UNIDADE CONSTRUTIVA",OFFSET(A33,-1,0)+1,LARGE(A$3:A32,1)) -> 0 | B33: =IF(H33="UNIDADE CONSTRUTIVA",0,IF(H33="CÉLULA CONSTRUTIVA",OFFSET(B33,-1,0)+1,OFFSET(B33,-1,0))) -> 1 | C33: =IF(H33="CÉLULA CONSTRUTIVA",0,IF(H33="ETAPA",OFFSET(C33,-1,0)+1,OFFSET(C33,-1,0))) -> 1 | D33: =IF(H33="ETAPA",0,IF(H33="SUBETAPA",OFFSET(D33,-1,0)+1,OFFSET(D33,-1,0))) -> 4 | E33: =IF(H33="Subetapa",0,IF(H33="serviço",OFFSET(E33,-1,0)+1,OFFSET(E33,-1,0))) -> 5 | H33: SERVIÇO | I33: =IF(H33="Unidade Construtiva",TEXT(A33,"00"),IF(H33="Célula Construtiva",TEXT(B33,"00"),IF(H33="Etapa",CONCATENATE(TEXT(B33,"00"),".",TEXT(C33,"000")),IF(H33="Subetapa",CONCATENATE(TEXT(B33,"00"),".",TEXT(C33,"000"),".",TEXT(D33,"000")),IF(H33="Serviço",CONCATENATE(TEXT(B33,"00"),".",TEXT(C33,"000"),".",TEXT(D33,"000"),".",TEXT(E33,"000")),""))))) -> 01.001.004.005 | J33: Ensaio de arrancamento revestimento cerâmico | K33: vb | L33: 1 | M33: 664.44444 | N33: =IF(H33="Serviço",M33*L33,IF(H33="CÉLULA CONSTRUTIVA",SUMIFS($N$8:$N$418,$B$8:$B$418,B33,$H$8:$H$418,"Serviço"),IF(H33="ETAPA",SUMIFS($N$8:$N$418,$B$8:$B$418,B33,$C$8:$C$418,C33,$H$8:$H$418,"Serviço"),IF(H33="SUBETAPA",SUMIFS($N$8:$N$418,$B$8:$B$418,B33,$C$8:$C$418,C33,$D$8:$D$418,D33,$H$8:$H$418,"Serviço"),0)))) -> 664.44444 | O33: Estimado com base em índices históricos | P33: Lançado ERP
A34: =IF($H34="UNIDADE CONSTRUTIVA",OFFSET(A34,-1,0)+1,LARGE(A$3:A33,1)) -> 0 | B34: =IF(H34="UNIDADE CONSTRUTIVA",0,IF(H34="CÉLULA CONSTRUTIVA",OFFSET(B34,-1,0)+1,OFFSET(B34,-1,0))) -> 1 | C34: =IF(H34="CÉLULA CONSTRUTIVA",0,IF(H34="ETAPA",OFFSET(C34,-1,0)+1,OFFSET(C34,-1,0))) -> 1 | D34: =IF(H34="ETAPA",0,IF(H34="SUBETAPA",OFFSET(D34,-1,0)+1,OFFSET(D34,-1,0))) -> 4 | E34: =IF(H34="Subetapa",0,IF(H34="serviço",OFFSET(E34,-1,0)+1,OFFSET(E34,-1,0))) -> 6 | H34: SERVIÇO | I34: =IF(H34="Unidade Construtiva",TEXT(A34,"00"),IF(H34="Célula Construtiva",TEXT(B34,"00"),IF(H34="Etapa",CONCATENATE(TEXT(B34,"00"),".",TEXT(C34,"000")),IF(H34="Subetapa",CONCATENATE(TEXT(B34,"00"),".",TEXT(C34,"000"),".",TEXT(D34,"000")),IF(H34="Serviço",CONCATENATE(TEXT(B34,"00"),".",TEXT(C34,"000"),".",TEXT(D34,"000"),".",TEXT(E34,"000")),""))))) -> 01.001.004.006 | J34: Ensaio de arrancamento fachada | K34: vb | L34: 1 | M34: 1260 | N34: =IF(H34="Serviço",M34*L34,IF(H34="CÉLULA CONSTRUTIVA",SUMIFS($N$8:$N$418,$B$8:$B$418,B34,$H$8:$H$418,"Serviço"),IF(H34="ETAPA",SUMIFS($N$8:$N$418,$B$8:$B$418,B34,$C$8:$C$418,C34,$H$8:$H$418,"Serviço"),IF(H34="SUBETAPA",SUMIFS($N$8:$N$418,$B$8:$B$418,B34,$C$8:$C$418,C34,$D$8:$D$418,D34,$H$8:$H$418,"Serviço"),0)))) -> 1260 | O34: Estimado com base em índices históricos | P34: Lançado ERP
A35: =IF($H35="UNIDADE CONSTRUTIVA",OFFSET(A35,-1,0)+1,LARGE(A$3:A34,1)) -> 0 | B35: =IF(H35="UNIDADE CONSTRUTIVA",0,IF(H35="CÉLULA CONSTRUTIVA",OFFSET(B35,-1,0)+1,OFFSET(B35,-1,0))) -> 1 | C35: =IF(H35="CÉLULA CONSTRUTIVA",0,IF(H35="ETAPA",OFFSET(C35,-1,0)+1,OFFSET(C35,-1,0))) -> 1 | D35: =IF(H35="ETAPA",0,IF(H35="SUBETAPA",OFFSET(D35,-1,0)+1,OFFSET(D35,-1,0))) -> 4 | E35: =IF(H35="Subetapa",0,IF(H35="serviço",OFFSET(E35,-1,0)+1,OFFSET(E35,-1,0))) -> 7 | H35: SERVIÇO | I35: =IF(H35="Unidade Construtiva",TEXT(A35,"00"),IF(H35="Célula Construtiva",TEXT(B35,"00"),IF(H35="Etapa",CONCATENATE(TEXT(B35,"00"),".",TEXT(C35,"000")),IF(H35="Subetapa",CONCATENATE(TEXT(B35,"00"),".",TEXT(C35,"000"),".",TEXT(D35,"000")),IF(H35="Serviço",CONCATENATE(TEXT(B35,"00"),".",TEXT(C35,"000"),".",TEXT(D35,"000"),".",TEXT(E35,"000")),""))))) -> 01.001.004.007 | J35: Ensaio de arrancamento de gancho da cobertura | K35: vb | L35: 1 | M35: 1680 | N35: =IF(H35="Serviço",M35*L35,IF(H35="CÉLULA CONSTRUTIVA",SUMIFS($N$8:$N$418,$B$8:$B$418,B35,$H$8:$H$418,"Serviço"),IF(H35="ETAPA",SUMIFS($N$8:$N$418,$B$8:$B$418,B35,$C$8:$C$418,C35,$H$8:$H$418,"Serviço"),IF(H35="SUBETAPA",SUMIFS($N$8:$N$418,$B$8:$B$418,B35,$C$8:$C$418,C35,$D$8:$D$418,D35,$H$8:$H$418,"Serviço"),0)))) -> 1680 | O35: Estimado com base em índices históricos | P35: Lançado ERP
A36: =IF($H36="UNIDADE CONSTRUTIVA",OFFSET(A36,-1,0)+1,LARGE(A$3:A35,1)) -> 0 | B36: =IF(H36="UNIDADE CONSTRUTIVA",0,IF(H36="CÉLULA CONSTRUTIVA",OFFSET(B36,-1,0)+1,OFFSET(B36,-1,0))) -> 1 | C36: =IF(H36="CÉLULA CONSTRUTIVA",0,IF(H36="ETAPA",OFFSET(C36,-1,0)+1,OFFSET(C36,-1,0))) -> 2 | D36: =IF(H36="ETAPA",0,IF(H36="SUBETAPA",OFFSET(D36,-1,0)+1,OFFSET(D36,-1,0))) -> 0 | E36: =IF(H36="Subetapa",0,IF(H36="serviço",OFFSET(E36,-1,0)+1,OFFSET(E36,-1,0))) -> 7 | H36: ETAPA | I36: =IF(H36="Unidade Construtiva",TEXT(A36,"00"),IF(H36="Célula Construtiva",TEXT(B36,"00"),IF(H36="Etapa",CONCATENATE(TEXT(B36,"00"),".",TEXT(C36,"000")),IF(H36="Subetapa",CONCATENATE(TEXT(B36,"00"),".",TEXT(C36,"000"),".",TEXT(D36,"000")),IF(H36="Serviço",CONCATENATE(TEXT(B36,"00"),".",TEXT(C36,"000"),".",TEXT(D36,"000"),".",TEXT(E36,"000")),""))))) -> 01.002 | J36: CONSUMOS, TAXAS E DOCUMENTOS | N36: =IF(H36="Serviço",M36*L36,IF(H36="CÉLULA CONSTRUTIVA",SUMIFS($N$8:$N$418,$B$8:$B$418,B36,$H$8:$H$418,"Serviço"),IF(H36="ETAPA",SUMIFS($N$8:$N$418,$B$8:$B$418,B36,$C$8:$C$418,C36,$H$8:$H$418,"Serviço"),IF(H36="SUBETAPA",SUMIFS($N$8:$N$418,$B$8:$B$418,B36,$C$8:$C$418,C36,$D$8:$D$418,D36,$H$8:$H$418,"Serviço"),0)))) -> 1673990.5 | P36: -
A37: =IF($H37="UNIDADE CONSTRUTIVA",OFFSET(A37,-1,0)+1,LARGE(A$3:A36,1)) -> 0 | B37: =IF(H37="UNIDADE CONSTRUTIVA",0,IF(H37="CÉLULA CONSTRUTIVA",OFFSET(B37,-1,0)+1,OFFSET(B37,-1,0))) -> 1 | C37: =IF(H37="CÉLULA CONSTRUTIVA",0,IF(H37="ETAPA",OFFSET(C37,-1,0)+1,OFFSET(C37,-1,0))) -> 2 | D37: =IF(H37="ETAPA",0,IF(H37="SUBETAPA",OFFSET(D37,-1,0)+1,OFFSET(D37,-1,0))) -> 1 | E37: =IF(H37="Subetapa",0,IF(H37="serviço",OFFSET(E37,-1,0)+1,OFFSET(E37,-1,0))) -> 0 | H37: SUBETAPA | I37: =IF(H37="Unidade Construtiva",TEXT(A37,"00"),IF(H37="Célula Construtiva",TEXT(B37,"00"),IF(H37="Etapa",CONCATENATE(TEXT(B37,"00"),".",TEXT(C37,"000")),IF(H37="Subetapa",CONCATENATE(TEXT(B37,"00"),".",TEXT(C37,"000"),".",TEXT(D37,"000")),IF(H37="Serviço",CONCATENATE(TEXT(B37,"00"),".",TEXT(C37,"000"),".",TEXT(D37,"000"),".",TEXT(E37,"000")),""))))) -> 01.002.001 | J37: Licenciamentos, Taxas, Impostos, Aprovações e Seguros | N37: =IF(H37="Serviço",M37*L37,IF(H37="CÉLULA CONSTRUTIVA",SUMIFS($N$8:$N$418,$B$8:$B$418,B37,$H$8:$H$418,"Serviço"),IF(H37="ETAPA",SUMIFS($N$8:$N$418,$B$8:$B$418,B37,$C$8:$C$418,C37,$H$8:$H$418,"Serviço"),IF(H37="SUBETAPA",SUMIFS($N$8:$N$418,$B$8:$B$418,B37,$C$8:$C$418,C37,$D$8:$D$418,D37,$H$8:$H$418,"Serviço"),0)))) -> 1645252.2
A38: =IF($H38="UNIDADE CONSTRUTIVA",OFFSET(A38,-1,0)+1,LARGE(A$3:A37,1)) -> 0 | B38: =IF(H38="UNIDADE CONSTRUTIVA",0,IF(H38="CÉLULA CONSTRUTIVA",OFFSET(B38,-1,0)+1,OFFSET(B38,-1,0))) -> 1 | C38: =IF(H38="CÉLULA CONSTRUTIVA",0,IF(H38="ETAPA",OFFSET(C38,-1,0)+1,OFFSET(C38,-1,0))) -> 2 | D38: =IF(H38="ETAPA",0,IF(H38="SUBETAPA",OFFSET(D38,-1,0)+1,OFFSET(D38,-1,0))) -> 1 | E38: =IF(H38="Subetapa",0,IF(H38="serviço",OFFSET(E38,-1,0)+1,OFFSET(E38,-1,0))) -> 1 | H38: SERVIÇO | I38: =IF(H38="Unidade Construtiva",TEXT(A38,"00"),IF(H38="Célula Construtiva",TEXT(B38,"00"),IF(H38="Etapa",CONCATENATE(TEXT(B38,"00"),".",TEXT(C38,"000")),IF(H38="Subetapa",CONCATENATE(TEXT(B38,"00"),".",TEXT(C38,"000"),".",TEXT(D38,"000")),IF(H38="Serviço",CONCATENATE(TEXT(B38,"00"),".",TEXT(C38,"000"),".",TEXT(D38,"000"),".",TEXT(E38,"000")),""))))) -> 01.002.001.001 | J38: Despesas de Seguros | K38: vb | L38: 1 | M38: 23000 | N38: =IF(H38="Serviço",M38*L38,IF(H38="CÉLULA CONSTRUTIVA",SUMIFS($N$8:$N$418,$B$8:$B$418,B38,$H$8:$H$418,"Serviço"),IF(H38="ETAPA",SUMIFS($N$8:$N$418,$B$8:$B$418,B38,$C$8:$C$418,C38,$H$8:$H$418,"Serviço"),IF(H38="SUBETAPA",SUMIFS($N$8:$N$418,$B$8:$B$418,B38,$C$8:$C$418,C38,$D$8:$D$418,D38,$H$8:$H$418,"Serviço"),0)))) -> 23000 | O38: Valor informado em formulário | P38: Lançado ERP
A39: =IF($H39="UNIDADE CONSTRUTIVA",OFFSET(A39,-1,0)+1,LARGE(A$3:A38,1)) -> 0 | B39: =IF(H39="UNIDADE CONSTRUTIVA",0,IF(H39="CÉLULA CONSTRUTIVA",OFFSET(B39,-1,0)+1,OFFSET(B39,-1,0))) -> 1 | C39: =IF(H39="CÉLULA CONSTRUTIVA",0,IF(H39="ETAPA",OFFSET(C39,-1,0)+1,OFFSET(C39,-1,0))) -> 2 | D39: =IF(H39="ETAPA",0,IF(H39="SUBETAPA",OFFSET(D39,-1,0)+1,OFFSET(D39,-1,0))) -> 1 | E39: =IF(H39="Subetapa",0,IF(H39="serviço",OFFSET(E39,-1,0)+1,OFFSET(E39,-1,0))) -> 2 | H39: SERVIÇO | I39: =IF(H39="Unidade Construtiva",TEXT(A39,"00"),IF(H39="Célula Construtiva",TEXT(B39,"00"),IF(H39="Etapa",CONCATENATE(TEXT(B39,"00"),".",TEXT(C39,"000")),IF(H39="Subetapa",CONCATENATE(TEXT(B39,"00"),".",TEXT(C39,"000"),".",TEXT(D39,"000")),IF(H39="Serviço",CONCATENATE(TEXT(B39,"00"),".",TEXT(C39,"000"),".",TEXT(D39,"000"),".",TEXT(E39,"000")),""))))) -> 01.002.001.002 | J39: Outorga, aprovação e demais taxas | K39: vb | L39: 1 | M39: 1500000 | N39: =IF(H39="Serviço",M39*L39,IF(H39="CÉLULA CONSTRUTIVA",SUMIFS($N$8:$N$418,$B$8:$B$418,B39,$H$8:$H$418,"Serviço"),IF(H39="ETAPA",SUMIFS($N$8:$N$418,$B$8:$B$418,B39,$C$8:$C$418,C39,$H$8:$H$418,"Serviço"),IF(H39="SUBETAPA",SUMIFS($N$8:$N$418,$B$8:$B$418,B39,$C$8:$C$418,C39,$D$8:$D$418,D39,$H$8:$H$418,"Serviço"),0)))) -> 1500000 | O39: Valor informado em formulário | P39: Lançado ERP
