Workbook

Sheet Versões
A1: ETAPA | B1: ORÇAMENTO EXECUTIVO R00 | C1: ORÇAMENTO EXECUTIVO R00 INDEXADO | D1: VALOR / m² | E1: ORÇAMENTO EXECUTIVO R01 AUDITORIA | F1: % | G1: VALOR / m² | H1: Diferença R$ | I1: Diferença R$/M2 | J1: Diferença %
A2: CUSTOS PRELIMINARES, ADMINISTRATIVOS E OPERAÇÕES | B2: ='[1]ORÇ. SINTÉTICO'!C11 -> 4093306.9 | C2: =($E$19/$C$19)*B2 -> 5654314.6 | D2: =C2/Versões!$N$2 -> 338.01842 | E2: ='[2]Obra '!C34 -> 8753722.9 | F2: =E2/E$18 -> 0.12134433 | G2: =E2/Versões!N$2 -> 523.30295 | H2: =E2-C2 -> 3099408.2 | I2: =H2/$N$2 -> 185.28454 | J2: =H2/C2 -> 0.54814924 | M2: ÁREA CONSTRUÍDA | N2: 16727.83
A3: EQUIPAMENTOS DE GRANDE PORTE | B3: ='[1]ORÇ. SINTÉTICO'!C12 -> 902031.98 | C3: =($E$19/$C$19)*B3 -> 1246027.4 | D3: =C3/Versões!$N$2 -> 74.488287 | E3: ='[2]Obra '!C35 -> 1428510 | F3: =E3/E$18 -> 0.019802043 | G3: =E3/Versões!N$2 -> 85.397211 | H3: =E3-C3 -> 182482.63 | I3: =H3/$N$2 -> 10.908924 | J3: =H3/C3 -> 0.14645154 | K3: *Considerar com o mercado
A4: INFRA ESTRUTURA | B4: ='[1]ORÇ. SINTÉTICO'!C13 -> 3476955.1 | C4: =($E$19/$C$19)*B4 -> 4802913.2 | D4: =C4/Versões!$N$2 -> 287.12111 | E4: ='[2]Obra '!C36 -> 4472521.3 | F4: =E4/E$18 -> 0.061998206 | G4: =E4/Versões!N$2 -> 267.37008 | H4: =E4-C4 -> -330391.9 | I4: =H4/$N$2 -> -19.751031 | J4: =H4/C4 -> -0.068789896
A5: SUPRA ESTRUTURA | B5: ='[1]ORÇ. SINTÉTICO'!C14 -> 13952879 | C5: =($E$19/$C$19)*B5 -> 19273895 | D5: =C5/Versões!$N$2 -> 1152.2053 | E5: ='[2]Obra '!C37 -> 16569702 | F5: =E5/E$18 -> 0.22968964 | G5: =E5/Versões!N$2 -> 990.54702 | H5: =E5-C5 -> -2704192.5 | I5: =H5/$N$2 -> -161.6583 | J5: =H5/C5 -> -0.14030338
A6: PAREDES E DIVISÓRIAS | B6: ='[1]ORÇ. SINTÉTICO'!C15 -> 2048262 | C6: =($E$19/$C$19)*B6 -> 2829379.2 | D6: =C6/Versões!$N$2 -> 169.14203 | E6: ='[2]Obra '!C38 -> 4429172.2 | F6: =E6/E$18 -> 0.0613973 | G6: =E6/Versões!N$2 -> 264.77864 | H6: =E6-C6 -> 1599793 | I6: =H6/$N$2 -> 95.63661 | J6: =H6/C6 -> 0.56542189 | K6: *O Drywall orçamento anteriormente está com custo muito abaixo do praticado do mercado e quantidade está inferior ao modelado atualmente
A7: INSTALAÇÕES HIDROSSANITÁRIAS | B7: ='[1]ORÇ. SINTÉTICO'!C16 -> 1193599.8 | C7: =($E$19/$C$19)*B7 -> 1648786.4 | D7: =C7/Versões!$N$2 -> 98.565466 | E7: ='[2]Obra '!C39 -> 1649879.2 | F7: =E7/E$18 -> 0.022870669 | G7: =E7/Versões!N$2 -> 98.630798 | H7: =E7-C7 -> 1092.8623 | I7: =H7/$N$2 -> 0.065331982 | J7: =H7/C7 -> 0.00066282831
A8: INSTALAÇÕES ELÉTRICAS, LÓGICAS E TELEFÔNICAS | B8: ='[1]ORÇ. SINTÉTICO'!C17 -> 1897027.1 | C8: =($E$19/$C$19)*B8 -> 2620469.9 | D8: =C8/Versões!$N$2 -> 156.65331 | E8: ='[2]Obra '!C40 -> 2108723.1 | F8: =E8/E$18 -> 0.029231174 | G8: =E8/Versões!N$2 -> 126.06077 | H8: =E8-C8 -> -511746.87 | I8: =H8/$N$2 -> -30.592544 | J8: =H8/C8 -> -0.1952882
A9: REVESTIMENTOS EM ARGAMASSA DE PISO, PAREDE E TETO | B9: ='[1]ORÇ. SINTÉTICO'!C18 -> 1208325.3 | C9: =($E$19/$C$19)*B9 -> 1669127.5 | D9: =C9/Versões!$N$2 -> 99.781473 | E9: ='[2]Obra '!C41 -> 1898258.5 | F9: =E9/E$18 -> 0.026313708 | G9: =E9/Versões!N$2 -> 113.47906 | H9: =E9-C9 -> 229130.95 | I9: =H9/$N$2 -> 13.697589 | J9: =H9/C9 -> 0.13727588
A10: FORRO | B10: ='[1]ORÇ. SINTÉTICO'!C19 -> 660504.85 | C10: =($E$19/$C$19)*B10 -> 912392.42 | D10: =C10/Versões!$N$2 -> 54.543382 | E10: ='[2]Obra '!C42 -> 736663.3 | F10: =E10/E$18 -> 0.010211646 | G10: =E10/Versões!N$2 -> 44.038186 | H10: =E10-C10 -> -175729.12 | I10: =H10/$N$2 -> -10.505195 | J10: =H10/C10 -> -0.19260257
A11: IMPERMEABILIZAÇÕES | B11: ='[1]ORÇ. SINTÉTICO'!C20 -> 409814.65 | C11: =($E$19/$C$19)*B11 -> 566099.98 | D11: =C11/Versões!$N$2 -> 33.841806 | E11: ='[2]Obra '!C43 -> 1214123.3 | F11: =E11/E$18 -> 0.016830209 | G11: =E11/Versões!N$2 -> 72.581042 | H11: =E11-C11 -> 648023.34 | I11: =H11/$N$2 -> 38.739235 | J11: =H11/C11 -> 1.1447154
A12: PINTURA | B12: ='[1]ORÇ. SINTÉTICO'!C21 -> 1359989.1 | C12: =($E$19/$C$19)*B12 -> 1878629.2 | D12: =C12/Versões!$N$2 -> 112.30561 | E12: ='[2]Obra '!C44 -> 2370480 | F12: =E12/E$18 -> 0.032859656 | G12: =E12/Versões!N$2 -> 141.70876 | H12: =E12-C12 -> 491850.81 | I12: =H12/$N$2 -> 29.403145 | J12: =H12/C12 -> 0.26181367
A13: ACABAMENTOS DE PISO E PAREDE | B13: ='[1]ORÇ. SINTÉTICO'!C22 -> 6140827.6 | C13: =($E$19/$C$19)*B13 -> 8482669.9 | D13: =C13/Versões!$N$2 -> 507.09924 | E13: ='[2]Obra '!C45 -> 7112920.9 | F13: =E13/E$18 -> 0.098599494 | G13: =E13/Versões!N$2 -> 425.2148 | H13: =E13-C13 -> -1369749 | I13: =H13/$N$2 -> -81.884439 | J13: =H13/C13 -> -0.16147616
A14: ESQUADRIAS | B14: ='[1]ORÇ. SINTÉTICO'!C23 -> 5702498.5 | C14: =($E$19/$C$19)*B14 -> 7877181.2 | D14: =C14/Versões!$N$2 -> 470.90275 | E14: ='[2]Obra '!C46 -> 8730804.6 | F14: =E14/E$18 -> 0.12102664 | G14: =E14/Versões!N$2 -> 521.93289 | H14: =E14-C14 -> 853623.44 | I14: =H14/$N$2 -> 51.030136 | J14: =H14/C14 -> 0.10836661
A15: SISTEMAS E INSTALAÇÕES ESPECIAIS | B15: ='[1]ORÇ. SINTÉTICO'!C24 -> 3876049.6 | C15: =($E$19/$C$19)*B15 -> 5354204.9 | D15: =C15/Versões!$N$2 -> 320.07767 | E15: ='[2]Obra '!C47 -> 6911114.4 | F15: =E15/E$18 -> 0.095802048 | G15: =E15/Versões!N$2 -> 413.15069 | H15: =E15-C15 -> 1556909.6 | I15: =H15/$N$2 -> 93.073014 | J15: =H15/C15 -> 0.29078259 | K15: Custo de PPCI tem Sprinclers que eleca o custo geral dessa etapa
A16: SERVIÇOS COMPLEMENTARES | B16: ='[1]ORÇ. SINTÉTICO'!C25 -> 1993733.5 | C16: =($E$19/$C$19)*B16 -> 2754056 | D16: =C16/Versões!$N$2 -> 164.63917 | E16: ='[2]Obra '!C48 -> 1932915.9 | F16: =E16/E$18 -> 0.02679413 | G16: =E16/Versões!N$2 -> 115.5509 | H16: =E16-C16 -> -821140.16 | I16: =H16/$N$2 -> -49.088265 | J16: =H16/C16 -> -0.29815667
A17: DECORAÇÃO E MOBILIÁRIO ÁREA COMUM | B17: ='[1]ORÇ. SINTÉTICO'!C26 -> 1625998 | C17: =($E$19/$C$19)*B17 -> 2246082.3 | D17: =C17/Versões!$N$2 -> 134.27219 | E17: ='[2]Obra '!C49 -> 1820015.3 | F17: =E17/E$18 -> 0.0252291 | G17: =E17/Versões!N$2 -> 108.80164 | H17: =E17-C17 -> -426067.01 | I17: =H17/$N$2 -> -25.470549 | J17: =H17/C17 -> -0.18969341
A18: TOTAL | B18: =SUM(B2:B17) -> 50541803 | C18: =SUM(C2:C17) -> 69816229 | D18: =SUM(D2:D17) -> 4173.6572 | E18: =SUM(E2:E17) -> 72139527 | F18: =SUM(F2:F17) -> 1 | G18: =SUM(G2:G17) -> 4312.5454 | H18: =SUM(H2:H17) -> 2323298.3 | I18: =SUM(I2:I17) -> 138.8882 | J18: =H18/C18 -> 0.033277338
A19: CUB/SC | B19: 2171.33 | C19: 2171.33 | D19: =ROUNDUP(+D18/B19,2)&" CUB" -> 1,93 CUB | E19: 2999.38 | G19: =ROUNDUP(+G18/E19,2)&" CUB" -> 1,44 CUB
A20: Mês Referência | B20: 44287 | C20: 44287 | E20: 45931
E21: =E19/C19-1 -> 0.38135613

Sheet ORÇAMENTO_COMPARATIVO
A1: ETAPA | B1: ORÇAMENTO R00 | F1: ORÇAMENTO R00 INDEXADO | J1: ORÇAMENTO CARTESIAN R01 | N1: CUSTO APROPRIADO | P1: OBSERVAÇÕES
B2: VALOR ORÇADO | C2: % | D2: VALOR / M² | E2: VALOR / CUB | F2: VALOR ORÇADO | G2: % | H2: VALOR / M² | I2: VALOR / CUB | J2: VALOR ORÇADO | K2: % | L2: VALOR / M² | M2: VALOR / CUB | N2: VALOR / CUB | R2: ÁREA CONSTRUÍDA | S2: 13131.85
A3: CUSTOS PRELIMINARES, ADMINISTRATIVOS E OPERAÇÕES | B3: =[3]ORÇAMENTO!$J$13 -> 4923771.2 | C3: =B3/B$19 -> 0.093252316 | D3: =B3/ORÇAMENTO_COMPARATIVO!S$2 -> 374.94878 | E3: =B3/ORÇAMENTO_COMPARATIVO!S$2/$B$20 -> 0.17268162 | F3: =B3/$F$20*$J$20 -> 6801481.5 | G3: =F3/F$19 -> 0.093252316 | H3: =F3/ORÇAMENTO_COMPARATIVO!S$2 -> 517.9378 | I3: =F3/ORÇAMENTO_COMPARATIVO!S$2/$B$20 -> 0.23853481 | J3: ='[2]Obra '!C34 -> 8753722.9 | K3: =J3/J$19 -> 0.12134433 | L3: =J3/ORÇAMENTO_COMPARATIVO!S$2 -> 666.60241 | M3: =J3/ORÇAMENTO_COMPARATIVO!S$2/$J$20 -> 0.22224673 | N3: =[4]Relatório!$T$13 -> 3312.54 | O3: =N3/$S$2 -> 0.25225235 | P3: *Para considerações para Custos indiretos o Orçamento Cartesian considerou a premisas alinhadas no Senarium para elaboração, divergindo em alguns pontos do Orçamento R00
A4: EQUIPAMENTOS DE GRANDE PORTE | B4: =[3]ORÇAMENTO!$J$74 -> 902031.98 | C4: =B4/B$19 -> 0.017083769 | D4: =B4/ORÇAMENTO_COMPARATIVO!S$2 -> 68.690396 | E4: =B4/ORÇAMENTO_COMPARATIVO!S$2/$B$20 -> 0.031635171 | F4: =B4/$F$20*$J$20 -> 1246027.4 | G4: =F4/F$19 -> 0.017083769 | H4: =F4/ORÇAMENTO_COMPARATIVO!S$2 -> 94.8859 | I4: =F4/ORÇAMENTO_COMPARATIVO!S$2/$B$20 -> 0.043699438 | J4: ='[2]Obra '!C35 -> 1428510 | K4: =J4/J$19 -> 0.019802043 | L4: =J4/ORÇAMENTO_COMPARATIVO!S$2 -> 108.78209 | M4: =J4/ORÇAMENTO_COMPARATIVO!S$2/$J$20 -> 0.036268191 | N4: =[4]Relatório!$T$31 -> 581.16 | O4: =N4/$S$2 -> 0.04425576 | P4: *Orçamento Cartesian considerou temnpo dos equipamentos de orbras de mesmo porte e para os custo de locação consideramos o que tem praticado atualmente no mercado
A5: INFRAESTRUTURA | B5: =[3]ORÇAMENTO!$J$82 -> 3374468.3 | C5: =B5/B$19 -> 0.063909749 | D5: =B5/ORÇAMENTO_COMPARATIVO!S$2 -> 256.96823 | E5: =B5/ORÇAMENTO_COMPARATIVO!S$2/$B$20 -> 0.11834601 | F5: =B5/$F$20*$J$20 -> 4661342.4 | G5: =F5/F$19 -> 0.063909749 | H5: =F5/ORÇAMENTO_COMPARATIVO!S$2 -> 354.96464 | I5: =F5/ORÇAMENTO_COMPARATIVO!S$2/$B$20 -> 0.16347798 | J5: ='[2]Obra '!C36 -> 4472521.3 | K5: =J5/J$19 -> 0.061998206 | L5: =J5/ORÇAMENTO_COMPARATIVO!S$2 -> 340.58577 | M5: =J5/ORÇAMENTO_COMPARATIVO!S$2/$J$20 -> 0.11355206 | N5: =[4]Relatório!$T$36 -> 1555.51 | O5: =N5/$S$2 -> 0.11845323 | P5: *Consideração do orçamento R01 levou em contra quantitativos de projetos e cotações recentes do mercado. Observamos que Mão de Obra para execução da infra estava mais elevada que o praticado arualmente
A6: SUPRAESTRUTURA | B6: =[3]ORÇAMENTO!$J$126 -> 14553688 | C6: =B6/B$19 -> 0.27563529 | D6: =B6/ORÇAMENTO_COMPARATIVO!S$2 -> 1108.274 | E6: =B6/ORÇAMENTO_COMPARATIVO!S$2/$B$20 -> 0.51041251 | F6: =B6/$F$20*$J$20 -> 20103826 | G6: =F6/F$19 -> 0.27563529 | H6: =F6/ORÇAMENTO_COMPARATIVO!S$2 -> 1530.9211 | I6: =F6/ORÇAMENTO_COMPARATIVO!S$2/$B$20 -> 0.70506145 | J6: ='[2]Obra '!C37 -> 16569702 | K6: =J6/J$19 -> 0.22968964 | L6: =J6/ORÇAMENTO_COMPARATIVO!S$2 -> 1261.795 | M6: =J6/ORÇAMENTO_COMPARATIVO!S$2/$J$20 -> 0.42068526 | N6: =[4]Relatório!$T$46 -> 8693.73 | O6: =N6/$S$2 -> 0.66203391 | P6: * Consideração do orçamento Cartesian, utilizou quantidades extraídas dos projetos e com preços cotados recentemente no mercado inclusive a mão de obra para execução da Supraestrutura, observando que alguns itens como os de mão de obra e aço foram apropriados com um custo muito mais elevado, dos empreendimentos de mesmo porte.
A7: ALVENARIAS E VEDAÇÕES | B7: =[3]ORÇAMENTO!$J$172 -> 2260687.9 | C7: =B7/B$19 -> 0.042815634 | D7: =B7/ORÇAMENTO_COMPARATIVO!S$2 -> 172.15304 | E7: =B7/ORÇAMENTO_COMPARATIVO!S$2/$B$20 -> 0.079284605 | F7: =B7/$F$20*$J$20 -> 3122815.1 | G7: =F7/F$19 -> 0.042815634 | H7: =F7/ORÇAMENTO_COMPARATIVO!S$2 -> 237.80466 | I7: =F7/ORÇAMENTO_COMPARATIVO!S$2/$B$20 -> 0.10952028 | J7: ='[2]Obra '!C38 -> 4429172.2 | K7: =J7/J$19 -> 0.0613973 | L7: =J7/ORÇAMENTO_COMPARATIVO!S$2 -> 337.28471 | M7: =J7/ORÇAMENTO_COMPARATIVO!S$2/$J$20 -> 0.11245148 | N7: =[4]Relatório!$T$63 -> 1434.95 | O7: =N7/$S$2 -> 0.10927249 | P7: * O orçamento R00 não traz detalhamentos da extração de quantidades para confrontarmos as considerações, porém no orçamento R01 consideramos as quantidades do modelo elaborado e vinculamos as quantidades a composições consolidadas com preços praticados atualmente e ficou equivalente ao custo apropriado nesta etapa.
A8: SISTEMAS E INSTALAÇÕES HIDROSSANITÁRIAS E DRENAGEM | B8: =[3]ORÇAMENTO!$J$256 -> 1824838.5 | C8: =B8/B$19 -> 0.034560991 | D8: =B8/ORÇAMENTO_COMPARATIVO!S$2 -> 138.96279 | E8: =B8/ORÇAMENTO_COMPARATIVO!S$2/$B$20 -> 0.063998926 | F8: =B8/$F$20*$J$20 -> 2520751.8 | G8: =F8/F$19 -> 0.034560991 | H8: =F8/ORÇAMENTO_COMPARATIVO!S$2 -> 191.9571 | I8: =F8/ORÇAMENTO_COMPARATIVO!S$2/$B$20 -> 0.088405308 | J8: ='[2]Obra '!C39 -> 1649879.2 | K8: =J8/J$19 -> 0.022870669 | L8: =J8/ORÇAMENTO_COMPARATIVO!S$2 -> 125.63951 | M8: =J8/ORÇAMENTO_COMPARATIVO!S$2/$J$20 -> 0.041888494 | N8: =[4]Relatório!$T$79 -> 1110.26 | O8: =N8/$S$2 -> 0.084547113 | P8: *O orçamento R01 considerou a lista de quantidades fornecidas para precificação do Material, considerando custos praticados na atualidade, não foi possível identificar as diferenças do orçamento R00, nem do apropriado.
A9: SISTEMAS E INSTALAÇÕES ELÉTRICAS | B9: =[3]ORÇAMENTO!$J$272 -> 2301980.5 | C9: =B9/B$19 -> 0.043597682 | D9: =B9/ORÇAMENTO_COMPARATIVO!S$2 -> 175.2975 | E9: =B9/ORÇAMENTO_COMPARATIVO!S$2/$B$20 -> 0.080732777 | F9: =B9/$F$20*$J$20 -> 3179854.8 | G9: =F9/F$19 -> 0.043597682 | H9: =F9/ORÇAMENTO_COMPARATIVO!S$2 -> 242.14828 | I9: =F9/ORÇAMENTO_COMPARATIVO!S$2/$B$20 -> 0.11152072 | J9: ='[2]Obra '!C40 -> 2108723.1 | K9: =J9/J$19 -> 0.029231174 | L9: =J9/ORÇAMENTO_COMPARATIVO!S$2 -> 160.58081 | M9: =J9/ORÇAMENTO_COMPARATIVO!S$2/$J$20 -> 0.053538 | N9: =[4]Relatório!$T$86 -> 1474.67 | O9: =N9/$S$2 -> 0.1122972 | P9: *O orçamento R01 considerou a lista de quantidades fornecidas para precificação do Material, considerando custos praticados na atualidade, não foi possível identificar as diferenças do orçamento R00, nem do apropriado.
A10: REVESTIMENTOS EM ARGAMASSA DE PISO, PAREDE E TETO | B10: =[3]ORÇAMENTO!$J$289 -> 1514636.6 | C10: =B10/B$19 -> 0.028686014 | D10: =B10/ORÇAMENTO_COMPARATIVO!S$2 -> 115.34069 | E10: =B10/ORÇAMENTO_COMPARATIVO!S$2/$B$20 -> 0.053119833 | F10: =B10/$F$20*$J$20 -> 2092252.6 | G10: =F10/F$19 -> 0.028686014 | H10: =F10/ORÇAMENTO_COMPARATIVO!S$2 -> 159.32657 | I10: =F10/ORÇAMENTO_COMPARATIVO!S$2/$B$20 -> 0.073377407 | J10: ='[2]Obra '!C41 -> 1898258.5 | K10: =J10/J$19 -> 0.026313708 | L10: =J10/ORÇAMENTO_COMPARATIVO!S$2 -> 144.55377 | M10: =J10/ORÇAMENTO_COMPARATIVO!S$2/$J$20 -> 0.048194551 | N10: =[4]Relatório!$T$93 -> 760.67 | O10: =N10/$S$2 -> 0.057925578 | P10: *Os quantitativos considerados no orçamento R01 foram extraídos do modelo elaborado considerando as premissas que validamos em conjunto, consideramos também os cunstos praticados recentemente no mercado.
A11: FORRO | B11: =[3]ORÇAMENTO!$J$355 -> 660504.85 | C11: =B11/B$19 -> 0.012509437 | D11: =B11/ORÇAMENTO_COMPARATIVO!S$2 -> 50.297928 | E11: =B11/ORÇAMENTO_COMPARATIVO!S$2/$B$20 -> 0.023164571 | F11: =B11/$F$20*$J$20 -> 912392.42 | G11: =F11/F$19 -> 0.012509437 | H11: =F11/ORÇAMENTO_COMPARATIVO!S$2 -> 69.479351 | I11: =F11/ORÇAMENTO_COMPARATIVO!S$2/$B$20 -> 0.031998522 | J11: ='[2]Obra '!C42 -> 736663.3 | K11: =J11/J$19 -> 0.010211646 | L11: =J11/ORÇAMENTO_COMPARATIVO!S$2 -> 56.09745 | M11: =J11/ORÇAMENTO_COMPARATIVO!S$2/$J$20 -> 0.018703015 | N11: =[4]Relatório!$T$109 -> 380.82 | O11: =N11/$S$2 -> 0.028999722 | P11: *Considerações de quantidades foam validadas com o modelo e os custos cotados atualmente
A12: IMPERMEABILIZAÇÃO E TRATAMENTOS | B12: =[3]ORÇAMENTO!$J$400 -> 459516.61 | C12: =B12/B$19 -> 0.0087028797 | D12: =B12/ORÇAMENTO_COMPARATIVO!S$2 -> 34.992527 | E12: =B12/ORÇAMENTO_COMPARATIVO!S$2/$B$20 -> 0.016115711 | F12: =B12/$F$20*$J$20 -> 634756.09 | G12: =F12/F$19 -> 0.0087028797 | H12: =F12/ORÇAMENTO_COMPARATIVO!S$2 -> 48.337141 | I12: =F12/ORÇAMENTO_COMPARATIVO!S$2/$B$20 -> 0.022261536 | J12: ='[2]Obra '!C43 -> 1214123.3 | K12: =J12/J$19 -> 0.016830209 | L12: =J12/ORÇAMENTO_COMPARATIVO!S$2 -> 92.456381 | M12: =J12/ORÇAMENTO_COMPARATIVO!S$2/$J$20 -> 0.030825164 | N12: =[4]Relatório!$T$119 -> 191.96 | O12: =N12/$S$2 -> 0.014617895 | P12: *O orçamento R01 considerou praticas atuais no mercado considerando as quantidades extraídas do modelo eleraborado, não sendo possível confrontar com o orçamento anterior as práticas devido ausência de alguns detalhamentos
A13: PINTURA | B13: =[3]ORÇAMENTO!$J$440 -> 1359989.1 | C13: =B13/B$19 -> 0.025757113 | D13: =B13/ORÇAMENTO_COMPARATIVO!S$2 -> 103.56416 | E13: =B13/ORÇAMENTO_COMPARATIVO!S$2/$B$20 -> 0.047696188 | F13: =B13/$F$20*$J$20 -> 1878629.2 | G13: =F13/F$19 -> 0.025757113 | H13: =F13/ORÇAMENTO_COMPARATIVO!S$2 -> 143.05899 | I13: =F13/ORÇAMENTO_COMPARATIVO!S$2/$B$20 -> 0.065885421 | J13: ='[2]Obra '!C44 -> 2370480 | K13: =J13/J$19 -> 0.032859656 | L13: =J13/ORÇAMENTO_COMPARATIVO!S$2 -> 180.51379 | M13: =J13/ORÇAMENTO_COMPARATIVO!S$2/$J$20 -> 0.060183702 | N13: =[4]Relatório!$T$129 -> 656.83 | O13: =N13/$S$2 -> 0.050018086 | P13: *Orçamento Cartesian considerou quantidades do modelo elaborado e os custos considerados são praticados atualmente.
A14: ACABAMENTOS EM PISO E PAREDE | B14: =[3]ORÇAMENTO!$J$520 -> 5475281.6 | C14: =B14/B$19 -> 0.10369749 | D14: =B14/ORÇAMENTO_COMPARATIVO!S$2 -> 416.94671 | E14: =B14/ORÇAMENTO_COMPARATIVO!S$2/$B$20 -> 0.19202365 | F14: =B14/$F$20*$J$20 -> 7563313.8 | G14: =F14/F$19 -> 0.10369749 | H14: =F14/ORÇAMENTO_COMPARATIVO!S$2 -> 575.95189 | I14: =F14/ORÇAMENTO_COMPARATIVO!S$2/$B$20 -> 0.26525304 | J14: ='[2]Obra '!C45 -> 7112920.9 | K14: =J14/J$19 -> 0.098599494 | L14: =J14/ORÇAMENTO_COMPARATIVO!S$2 -> 541.65414 | M14: =J14/ORÇAMENTO_COMPARATIVO!S$2/$J$20 -> 0.1805887 | N14: =[4]Relatório!$T$139 -> 2875.58 | O14: =N14/$S$2 -> 0.21897752 | P14: *O orçamento R00 tem algumas incompatibilidades com o Orçamento Cartesian, acreditamos que possa ser divido alinhamento dos acabamentos. Ná análise de apropriações tem alguns custos localizados que não condiz com a etapa apropriada.
A15: ESQUADRIAS, VIDROS E FERRAGENS | B15: =[3]ORÇAMENTO!$J$737 -> 5717398.7 | C15: =B15/B$19 -> 0.10828299 | D15: =B15/ORÇAMENTO_COMPARATIVO!S$2 -> 435.3841 | E15: =B15/ORÇAMENTO_COMPARATIVO!S$2/$B$20 -> 0.20051494 | F15: =B15/$F$20*$J$20 -> 7897763.8 | G15: =F15/F$19 -> 0.10828299 | H15: =F15/ORÇAMENTO_COMPARATIVO!S$2 -> 601.4205 | I15: =F15/ORÇAMENTO_COMPARATIVO!S$2/$B$20 -> 0.27698254 | J15: ='[2]Obra '!C46 -> 8730804.6 | K15: =J15/J$19 -> 0.12102664 | L15: =J15/ORÇAMENTO_COMPARATIVO!S$2 -> 664.85717 | M15: =J15/ORÇAMENTO_COMPARATIVO!S$2/$J$20 -> 0.22166487 | N15: =[4]Relatório!$T$152 -> 1819.66 | O15: =N15/$S$2 -> 0.13856844 | P15: *Orçamento Cartesian considerou proprostas recentes coletadas no mercado, verificamos que o custo orçado Cartesian e o custo apropriado está próximo.
A16: EQUIPAMENTOS E SISTEMAS ESPECIAIS | B16: =[3]ORÇAMENTO!$J$859 -> 3839958.5 | C16: =B16/B$19 -> 0.072725765 | D16: =B16/ORÇAMENTO_COMPARATIVO!S$2 -> 292.41566 | E16: =B16/ORÇAMENTO_COMPARATIVO!S$2/$B$20 -> 0.13467122 | F16: =B16/$F$20*$J$20 -> 5304350.2 | G16: =F16/F$19 -> 0.072725765 | H16: =F16/ORÇAMENTO_COMPARATIVO!S$2 -> 403.93016 | I16: =F16/ORÇAMENTO_COMPARATIVO!S$2/$B$20 -> 0.18602891 | J16: ='[2]Obra '!C47 -> 6911114.4 | K16: =J16/J$19 -> 0.095802048 | L16: =J16/ORÇAMENTO_COMPARATIVO!S$2 -> 526.28643 | M16: =J16/ORÇAMENTO_COMPARATIVO!S$2/$J$20 -> 0.17546507 | N16: =[4]Relatório!$T$166 -> 3255.6 | O16: =N16/$S$2 -> 0.24791633
A17: SERVIÇOS COMPLEMENTARES E FINAIS | B17: =[3]ORÇAMENTO!$J$904 -> 2005774.3 | C17: =B17/B$19 -> 0.037987773 | D17: =B17/ORÇAMENTO_COMPARATIVO!S$2 -> 152.74119 | E17: =B17/ORÇAMENTO_COMPARATIVO!S$2/$B$20 -> 0.070344529 | F17: =B17/$F$20*$J$20 -> 2770688.7 | G17: =F17/F$19 -> 0.037987773 | H17: =F17/ORÇAMENTO_COMPARATIVO!S$2 -> 210.98997 | I17: =F17/ORÇAMENTO_COMPARATIVO!S$2/$B$20 -> 0.097170846 | J17: ='[2]Obra '!C48 -> 1932915.9 | K17: =J17/J$19 -> 0.02679413 | L17: =J17/ORÇAMENTO_COMPARATIVO!S$2 -> 147.19296 | M17: =J17/ORÇAMENTO_COMPARATIVO!S$2/$J$20 -> 0.049074462 | N17: =[4]Relatório!$T$183 -> 2128.77 | O17: =N17/$S$2 -> 0.1621074
A18: DECORAÇÃO E MOBILIÁRIO ÁREA COMUM | B18: =[3]ORÇAMENTO!$J$993 -> 1625998 | C18: =B18/B$19 -> 0.030795111 | D18: =B18/ORÇAMENTO_COMPARATIVO!S$2 -> 123.82094 | E18: =B18/ORÇAMENTO_COMPARATIVO!S$2/$B$20 -> 0.057025391 | F18: =B18/$F$20*$J$20 -> 2246082.3 | G18: =F18/F$19 -> 0.030795111 | H18: =F18/ORÇAMENTO_COMPARATIVO!S$2 -> 171.04082 | I18: =F18/ORÇAMENTO_COMPARATIVO!S$2/$B$20 -> 0.078772373 | J18: ='[2]Obra '!C49 -> 1820015.3 | K18: =J18/J$19 -> 0.0252291 | L18: =J18/ORÇAMENTO_COMPARATIVO!S$2 -> 138.5955 | M18: =J18/ORÇAMENTO_COMPARATIVO!S$2/$J$20 -> 0.04620805 | N18: =[4]Relatório!$T$202 -> 917.54 | O18: =N18/$S$2 -> 0.069871343 | P18: *Os custos de mobiliários foram detalhado no Orçamento Cartesian de acordo com material recebido. O custo aproproado condiz com o orçado Cartesian e não sendo possível analisar o orçamento R00 | O apropriado tem apenas um item que não condiz com a Etapa apropriada.
A19: TOTAL | B19: =SUM(B3:B18) -> 52800525 | C19: =SUM(C3:C18) -> 1 | D19: =SUM(D3:D18) -> 4020.7986 | E19: =SUM(E3:E18) -> 1.8517676 | F19: =SUM(F3:F18) -> 72936328 | G19: =SUM(G3:G18) -> 1 | H19: =SUM(H3:H18) -> 5554.1548 | I19: =SUM(I3:I18) -> 2.5579506 | ... M19: =SUM(M3:M18) -> 1.8315378 | O19: =SUM(O3:O18) -> 2.3721144
A20: CUB/SC | B20: 2171.33 | C20: 44287 | D20: =ROUNDUP(+D19/B20,3)&" CUB" -> 1,852 CUB | F20: 2171.33 | G20: 44287 | H20: =ROUNDUP(+H19/F20,3)&" CUB" -> 2,558 CUB | J20: 2999.38 | K20: 45931 | L20: =ROUNDUP(+L19/J20,2)&" CUB" -> 1,84 CUB

Sheet ORÇAMENTO_EXECUTIVO
A1: ETAPA | B1: VALOR ORÇADO | C1: % | D1: VALOR / m²
A2: GERENCIAMENTO TÉCNICO E ADMINISTRATIVO | B2: =[5]Versões!$B$3 -> 10189226 | C2: =B2/B$18 -> 0.12758663 | D2: =B2/ORÇAMENTO_EXECUTIVO!G$2 -> 775.91699 | F2: ÁREA CONSTRUÍDA | G2: 13131.85
A3: MOVIMENTAÇÃO DE TERRA | B3: =[5]Versões!$B$4 -> 242339.35 | C3: =B3/B$18 -> 0.0030345055 | D3: =B3/ORÇAMENTO_EXECUTIVO!G$2 -> 18.454319
A4: INFRAESTRUTURA | B4: =[5]Versões!$B$5 -> 4343181.9 | C4: =B4/B$18 -> 0.054384107 | D4: =B4/ORÇAMENTO_EXECUTIVO!G$2 -> 330.73649
A5: SUPRAESTRUTURA | B5: =[5]Versões!$B$6 -> 16234650 | C5: =B5/B$18 -> 0.20328574 | D5: =B5/ORÇAMENTO_EXECUTIVO!G$2 -> 1236.2805
A6: ALVENARIA | B6: =[5]Versões!$B$7 -> 3717189.5 | C6: =B6/B$18 -> 0.046545606 | D6: =B6/ORÇAMENTO_EXECUTIVO!G$2 -> 283.06671
A7: INSTALAÇÕES ELÉTRICAS, HIDRÁULICAS, GLP E PREVENTIVAS | B7: =[5]Versões!$B$8 -> 10773485 | C7: =B7/B$18 -> 0.13490256 | D7: =B7/ORÇAMENTO_EXECUTIVO!G$2 -> 820.4088
A8: EQUIPAMENTOS E SISTEMAS ESPECIAIS | B8: =[5]Versões!$B$9 -> 4512186.8 | C8: =B8/B$18 -> 0.056500339 | D8: =B8/ORÇAMENTO_EXECUTIVO!G$2 -> 343.60633
A9: IMPERMEABILIZAÇÃO | B9: =[5]Versões!$B$13 -> 1211404.1 | C9: =B9/B$18 -> 0.015168862 | D9: =B9/ORÇAMENTO_EXECUTIVO!G$2 -> 92.249308
A10: REVESTIMENTOS INTERNOS EM PISO E PAREDE | B10: =[5]Versões!$B$10+[5]Versões!$B$11 -> 1757066.4 | C10: =B10/B$18 -> 0.022001493 | D10: =B10/ORÇAMENTO_EXECUTIVO!G$2 -> 133.80189
A11: REVESTIMENTOS E ACABAMENTOS INTERNOS EM TETO | B11: =[5]Versões!$B$12+[5]Versões!$B$16 -> 950215.8 | C11: =B11/B$18 -> 0.011898336 | D11: =B11/ORÇAMENTO_EXECUTIVO!G$2 -> 72.359629
A12: ACABAMENTOS EM PISO E PAREDE | B12: =[5]Versões!$B$14+[5]Versões!$B$15 -> 3740842.9 | C12: =B12/B$18 -> 0.046841786 | D12: =B12/ORÇAMENTO_EXECUTIVO!G$2 -> 284.86792
A13: PINTURA INTERNA | B13: =[5]Versões!$B$17 -> 2553763.5 | C13: =B13/B$18 -> 0.031977511 | D13: =B13/ORÇAMENTO_EXECUTIVO!G$2 -> 194.47096
A14: ESQUADRIAS, VIDROS E FERRAGENS | B14: =[5]Versões!$B$20 -> 12643362 | C14: =B14/B$18 -> 0.15831664 | D14: =B14/ORÇAMENTO_EXECUTIVO!G$2 -> 962.80131
A15: REVESTIMENTOS E ACABAMENTOS DE FACHADA | B15: =[5]Versões!$B$18+[5]Versões!$B$19 -> 4178126.9 | C15: =B15/B$18 -> 0.052317334 | D15: =B15/ORÇAMENTO_EXECUTIVO!G$2 -> 318.16743
A16: SERVIÇOS COMPLEMENTARES | B16: =[5]Versões!$B$22+[5]Versões!$B$21 -> 2814194.2 | C16: =B16/B$18 -> 0.035238551 | D16: =B16/ORÇAMENTO_EXECUTIVO!G$2 -> 214.30295
A17: IMPREVISTOS E CONTINGENCIAS | C17: =B17/B$18 -> 0 | D17: =B17/ORÇAMENTO_EXECUTIVO!G$2 -> 0
A18: TOTAL | B18: =SUM(B2:B17) -> 79861234 | C18: =SUM(C2:C17) -> 1 | D18: =SUM(D2:D17) -> 6081.4915
A19: CUB/SC | B19: 2999.38 | C19: 45931 | D19: =ROUNDUP(+D18/B19,2)&" CUB" -> 2,03 CUB

Sheet ANÁLISE_CUSTOS
A1: ETAPA | B1: OBRA | D1: OBRA SIMILAR
B2: VALOR DIRETO | C2: VALOR / m² | D2: VALOR / m²
A3: =ORÇAMENTO_COMPARATIVO!A3 -> CUSTOS PRELIMINARES, ADMINISTRATIVOS E OPERAÇÕES | B3: =ORÇAMENTO_COMPARATIVO!J3 -> 8753722.9 | C3: =ORÇAMENTO_COMPARATIVO!L3 -> 666.60241 | D3: =FIXED(CÁLCULO_MÉDIAS!R10,2,FALSE)&" "&"-"&FIXED(CÁLCULO_MÉDIAS!S10,2,FALSE) -> 530,00 -650,00
A4: =ORÇAMENTO_COMPARATIVO!A4 -> EQUIPAMENTOS DE GRANDE PORTE | B4: =ORÇAMENTO_COMPARATIVO!J4 -> 1428510 | C4: =ORÇAMENTO_COMPARATIVO!L4 -> 108.78209 | D4: =FIXED(CÁLCULO_MÉDIAS!R11,2,FALSE)&" "&"-"&FIXED(CÁLCULO_MÉDIAS!S11,2,FALSE) -> 16,00 -27,00
A5: =ORÇAMENTO_COMPARATIVO!A5 -> INFRAESTRUTURA | B5: =ORÇAMENTO_COMPARATIVO!J5 -> 4472521.3 | C5: =ORÇAMENTO_COMPARATIVO!L5 -> 340.58577 | D5: =FIXED(CÁLCULO_MÉDIAS!R12,2,FALSE)&" "&"-"&FIXED(CÁLCULO_MÉDIAS!S12,2,FALSE) -> 220,00 -370,00
A6: =ORÇAMENTO_COMPARATIVO!A6 -> SUPRAESTRUTURA | B6: =ORÇAMENTO_COMPARATIVO!J6 -> 16569702 | C6: =ORÇAMENTO_COMPARATIVO!L6 -> 1261.795 | D6: =FIXED(CÁLCULO_MÉDIAS!R13,2,FALSE)&" "&"-"&FIXED(CÁLCULO_MÉDIAS!S13,2,FALSE) -> 730,00 -810,00 | E6: Relação do aço por m3 de concreto está acima das obras de mesmo porte Cerca de 139kg/m2 sendo que o Scenarium deu 55kg/m3. 32% do Custo da Supra é somente para o aço.
A7: =ORÇAMENTO_COMPARATIVO!A7 -> ALVENARIAS E VEDAÇÕES | B7: =ORÇAMENTO_COMPARATIVO!J7 -> 4429172.2 | C7: =ORÇAMENTO_COMPARATIVO!L7 -> 337.28471 | D7: =FIXED(CÁLCULO_MÉDIAS!R14,2,FALSE)&" "&"-"&FIXED(CÁLCULO_MÉDIAS!S14,2,FALSE) -> 100,00 -170,00
A8: =ORÇAMENTO_COMPARATIVO!A8 -> SISTEMAS E INSTALAÇÕES HIDROSSANITÁRIAS E DRENAGEM | B8: =ORÇAMENTO_COMPARATIVO!J8 -> 1649879.2 | C8: =ORÇAMENTO_COMPARATIVO!L8 -> 125.63951 | D8: =FIXED(CÁLCULO_MÉDIAS!R15,2,FALSE)&" "&"-"&FIXED(CÁLCULO_MÉDIAS!S15,2,FALSE) -> 480,00 -600,00
A9: =ORÇAMENTO_COMPARATIVO!A9 -> SISTEMAS E INSTALAÇÕES ELÉTRICAS | B9: =ORÇAMENTO_COMPARATIVO!J9 -> 2108723.1 | C9: =ORÇAMENTO_COMPARATIVO!L9 -> 160.58081 | D9: =FIXED(CÁLCULO_MÉDIAS!R16,2,FALSE)&" "&"-"&FIXED(CÁLCULO_MÉDIAS!S16,2,FALSE) -> 230,00 -265,00
A10: =ORÇAMENTO_COMPARATIVO!A10 -> REVESTIMENTOS EM ARGAMASSA DE PISO, PAREDE E TETO | B10: =ORÇAMENTO_COMPARATIVO!J10 -> 1898258.5 | C10: =ORÇAMENTO_COMPARATIVO!L10 -> 144.55377 | D10: =FIXED(CÁLCULO_MÉDIAS!R17,2,FALSE)&" "&"-"&FIXED(CÁLCULO_MÉDIAS!S17,2,FALSE) -> 65,00 -100,00
A11: =ORÇAMENTO_COMPARATIVO!A11 -> FORRO | B11: =ORÇAMENTO_COMPARATIVO!J11 -> 736663.3 | C11: =ORÇAMENTO_COMPARATIVO!L11 -> 56.09745 | D11: =FIXED(CÁLCULO_MÉDIAS!R18,2,FALSE)&" "&"-"&FIXED(CÁLCULO_MÉDIAS!S18,2,FALSE) -> 160,00 -210,00 | E11: * Quase não tem argamassados de Parede
A12: =ORÇAMENTO_COMPARATIVO!A12 -> IMPERMEABILIZAÇÃO E TRATAMENTOS | B12: =ORÇAMENTO_COMPARATIVO!J12 -> 1214123.3 | C12: =ORÇAMENTO_COMPARATIVO!L12 -> 92.456381 | D12: =FIXED(CÁLCULO_MÉDIAS!R19,2,FALSE)&" "&"-"&FIXED(CÁLCULO_MÉDIAS!S19,2,FALSE) -> 55,00 -90,00
A13: =ORÇAMENTO_COMPARATIVO!A13 -> PINTURA | B13: =ORÇAMENTO_COMPARATIVO!J13 -> 2370480 | C13: =ORÇAMENTO_COMPARATIVO!L13 -> 180.51379 | D13: =FIXED(CÁLCULO_MÉDIAS!R20,2,FALSE)&" "&"-"&FIXED(CÁLCULO_MÉDIAS!S20,2,FALSE) -> 200,00 -280,00 | E13: *Detalhamento bem específico dos acabamentos com peças bem diversificadas
A14: =ORÇAMENTO_COMPARATIVO!A14 -> ACABAMENTOS EM PISO E PAREDE | B14: =ORÇAMENTO_COMPARATIVO!J14 -> 7112920.9 | C14: =ORÇAMENTO_COMPARATIVO!L14 -> 541.65414 | D14: =FIXED(CÁLCULO_MÉDIAS!R21,2,FALSE)&" "&"-"&FIXED(CÁLCULO_MÉDIAS!S21,2,FALSE) -> 100,00 -150,00 | E14: *Considerando nuances de cores e textura e pintura
A15: =ORÇAMENTO_COMPARATIVO!A15 -> ESQUADRIAS, VIDROS E FERRAGENS | B15: =ORÇAMENTO_COMPARATIVO!J15 -> 8730804.6 | C15: =ORÇAMENTO_COMPARATIVO!L15 -> 664.85717 | D15: =FIXED(CÁLCULO_MÉDIAS!R22,2,FALSE)&" "&"-"&FIXED(CÁLCULO_MÉDIAS!S22,2,FALSE) -> 630,00 -700,00 | E15: *Fachabada muito imponete com muita esquadria
A16: =ORÇAMENTO_COMPARATIVO!A16 -> EQUIPAMENTOS E SISTEMAS ESPECIAIS | B16: =ORÇAMENTO_COMPARATIVO!J16 -> 6911114.4 | C16: =ORÇAMENTO_COMPARATIVO!L16 -> 526.28643 | D16: =FIXED(CÁLCULO_MÉDIAS!R24,2,FALSE)&" "&"-"&FIXED(CÁLCULO_MÉDIAS!S24,2,FALSE) -> 170,00 -200,00 | E16: * Os empreendimentos de mesmo porte não utilizaram facahada ventilada tem o Redentor que tem ACM e alguns detalhaes, mas nada perto de fachada Ventilada
A17: =ORÇAMENTO_COMPARATIVO!A17 -> SERVIÇOS COMPLEMENTARES E FINAIS | B17: =ORÇAMENTO_COMPARATIVO!J17 -> 1932915.9 | C17: =ORÇAMENTO_COMPARATIVO!L17 -> 147.19296 | D17: =FIXED(CÁLCULO_MÉDIAS!R25,2,FALSE)&" "&"-"&FIXED(CÁLCULO_MÉDIAS!S25,2,FALSE) -> 190,00 -250,00
A18: =ORÇAMENTO_COMPARATIVO!A18 -> DECORAÇÃO E MOBILIÁRIO ÁREA COMUM | B18: =ORÇAMENTO_COMPARATIVO!J18 -> 1820015.3 | C18: =ORÇAMENTO_COMPARATIVO!L18 -> 138.5955
A19: TOTAL | B19: =SUM(B3:B17) -> 70319512 | C19: =SUM(C3:C18) -> 5493.4778 | D19: =FIXED(CÁLCULO_MÉDIAS!R26,2,FALSE)&" "&"-"&FIXED(CÁLCULO_MÉDIAS!S26,2,FALSE) -> 3.876,00 -4.872,00
B23: 2007.57
B24: 2461.35
B25: =B24/B23 -> 1.2260345
C28: 1.1023
A30: 900,00 - 1100 | B30: 900
A31: 25,00 - 30,00 | B31: 25
A32: 15,00 - 22,00 | B32: 15
A33: 150,00 - 200,00 | B33: 150
A34: 440,00 - 510,00 | B34: 440
A35: -
A36: 55,00 - 70,00 | B36: 55
A37: 170,00 - 200,00 | B37: 170
A38: 165,00 - 230,00 | B38: 165
A39: 40,00 - 70,00 | B39: 40
A40: 55,00 - 77,00 | B40: 55
A41: 35,00 - 50,00 | B41: 35
A42: 130,00 - 175,00 | B42: 130
A43: 35,00 - 65,00 | B43: 35
A44: 35,00 - 55,00 | B44: 35
A45: 430,00 - 550,00 | B45: 430
A46: 35,00 - 50,00 | B46: 35
...

Sheet AREAS PRIVATIVAS
A1: ETAPA | B1: VALOR ORÇADO | C1: % | D1: VALOR / AP
A2: GERENCIAMENTO TÉCNICO E ADMINISTRATIVO | B2: =ORÇAMENTO_COMPARATIVO!J3 -> 8753722.9 | C2: =B2/B$18 -> 0.12134433 | D2: =B2/'AREAS PRIVATIVAS'!G$2 -> 1108.0157 | F2: ÁREA PRIVATIVA | G2: 7900.36 | H2: m²
A3: MOVIMENTAÇÃO DE TERRA | B3: =ORÇAMENTO_COMPARATIVO!J4 -> 1428510 | C3: =B3/B$18 -> 0.019802043 | D3: =B3/'AREAS PRIVATIVAS'!G$2 -> 180.81582
A4: INFRAESTRUTURA | B4: =ORÇAMENTO_COMPARATIVO!J5 -> 4472521.3 | C4: =B4/B$18 -> 0.061998206 | D4: =B4/'AREAS PRIVATIVAS'!G$2 -> 566.11614
A5: SUPRAESTRUTURA | B5: =ORÇAMENTO_COMPARATIVO!J6 -> 16569702 | C5: =B5/B$18 -> 0.22968964 | D5: =B5/'AREAS PRIVATIVAS'!G$2 -> 2097.3351
A6: ALVENARIA | B6: =ORÇAMENTO_COMPARATIVO!J7 -> 4429172.2 | C6: =B6/B$18 -> 0.0613973 | D6: =B6/'AREAS PRIVATIVAS'!G$2 -> 560.62916
A7: INSTALAÇÕES ELÉTRICAS, HIDRÁULICAS, GLP E PREVENTIVAS | B7: =ORÇAMENTO_COMPARATIVO!J8 -> 1649879.2 | C7: =B7/B$18 -> 0.022870669 | D7: =B7/'AREAS PRIVATIVAS'!G$2 -> 208.83595
A8: EQUIPAMENTOS E SISTEMAS ESPECIAIS | B8: =ORÇAMENTO_COMPARATIVO!J9 -> 2108723.1 | C8: =B8/B$18 -> 0.029231174 | D8: =B8/'AREAS PRIVATIVAS'!G$2 -> 266.91481
A9: IMPERMEABILIZAÇÃO | B9: =ORÇAMENTO_COMPARATIVO!J10 -> 1898258.5 | C9: =B9/B$18 -> 0.026313708 | D9: =B9/'AREAS PRIVATIVAS'!G$2 -> 240.27493
A10: REVESTIMENTOS INTERNOS EM PISO E PAREDE | B10: =ORÇAMENTO_COMPARATIVO!J11 -> 736663.3 | C10: =B10/B$18 -> 0.010211646 | D10: =B10/'AREAS PRIVATIVAS'!G$2 -> 93.244269
A11: REVESTIMENTOS E ACABAMENTOS INTERNOS EM TETO | B11: =ORÇAMENTO_COMPARATIVO!J12 -> 1214123.3 | C11: =B11/B$18 -> 0.016830209 | D11: =B11/'AREAS PRIVATIVAS'!G$2 -> 153.67949
A12: ACABAMENTOS EM PISO E PAREDE | B12: =ORÇAMENTO_COMPARATIVO!J13 -> 2370480 | C12: =B12/B$18 -> 0.032859656 | D12: =B12/'AREAS PRIVATIVAS'!G$2 -> 300.04709
A13: PINTURA INTERNA | B13: =ORÇAMENTO_COMPARATIVO!J14 -> 7112920.9 | C13: =B13/B$18 -> 0.098599494 | D13: =B13/'AREAS PRIVATIVAS'!G$2 -> 900.3287
A14: ESQUADRIAS, VIDROS E FERRAGENS | B14: =ORÇAMENTO_COMPARATIVO!J15 -> 8730804.6 | C14: =B14/B$18 -> 0.12102664 | D14: =B14/'AREAS PRIVATIVAS'!G$2 -> 1105.1148
... A16: SERVIÇOS COMPLEMENTARES | B16: =ORÇAMENTO_COMPARATIVO!J17 -> 1932915.9 | C16: =B16/B$18 -> 0.02679413 | D16: =B16/'AREAS PRIVATIVAS'!G$2 -> 244.66174
A17: IMPREVISTOS E CONTINGENCIAS | B17: =ORÇAMENTO_COMPARATIVO!J18 -> 1820015.3 | C17: 0.03 | D17: =B17/'AREAS PRIVATIVAS'!G$2 -> 230.37119
A18: TOTAL | B18: =SUM(B2:B17) -> 72139527 | C18: =SUM(C2:C17) -> 1.0047709 | D18: =SUM(D2:D17) -> 9131.1696

Sheet CÁLCULO_MÉDIAS
C3: DATA BASE | D3: 44958 | E3: DATA BASE | G3: DATA BASE | H3: 44958 | I3: DATA BASE | J3: 44378 | K3: DATA BASE | L3: 44713 | M3: DATA BASE | N3: 45839 | O3: DATA BASE | P3: 44805
C4: CUB | D4: 2662.47 | E4: CUB | F4: 2643.16 | G4: CUB | H4: 2662.47 | I4: CUB | J4: 2307.92 | K4: CUB | L4: 2544.17 | M4: CUB | N4: 2965.54 | O4: CUB | P4: 2623.42
C5: M2 | M5: AREA CONSTRUÍDA | N5: 16727.83 | O5: AREA CONSTRUÍDA | P5: 8275
C6: PAVIMENTOS | M6: Nº PAVIMENTOS | N6: 43 | O6: Nº PAVIMENTOS | P6: 20 | Q6: 13 TIPO
C8: DOM | E8: M VILLAGE | G8: LUMIS | I8: NAUTILUS | K8: SANTORINI | M8: Redentor | O8: MARIO LAGO | R8: MÉDIAS
C9: VALOR / M2 | D9: INDEXADO | E9: VALOR / M2 | F9: INDEXADO | G9: VALOR / M2 | H9: INDEXADO | I9: VALOR / M2 | J9: INDEXADO | K9: VALOR / M2 | L9: INDEXADO | M9: VALOR / M2 | N9: INDEXADO | O9: VALOR / M2 | P9: INDEXADO | R9: MÍNIMA | S9: MÁXIMA
B10: GERENCIAMENTO TECNICO E ADMINISTRATIVO | C10: 438.31354 | D10: =(ORÇAMENTO_COMPARATIVO!$J$20/CÁLCULO_MÉDIAS!D$4)*C10 -> 493.77791 | E10: 400.33 | F10: =(ORÇAMENTO_COMPARATIVO!$J$20/CÁLCULO_MÉDIAS!F$4)*E10 -> 454.28268 | G10: 192.5376 | H10: =(ORÇAMENTO_COMPARATIVO!$J$20/CÁLCULO_MÉDIAS!H$4)*G10 -> 216.90139 | I10: 376.08378 | J10: =(ORÇAMENTO_COMPARATIVO!$J$20/CÁLCULO_MÉDIAS!J$4)*I10 -> 488.75965 | K10: 441.31552 | L10: =(ORÇAMENTO_COMPARATIVO!$J$20/CÁLCULO_MÉDIAS!L$4)*K10 -> 520.27693 | M10: 640.8743 | N10: =(ORÇAMENTO_COMPARATIVO!$J$20/CÁLCULO_MÉDIAS!N$4)*M10 -> 648.18736 | O10: 275.54996 | P10: =(ORÇAMENTO_COMPARATIVO!$J$20/CÁLCULO_MÉDIAS!P$4)*O10 -> 315.03879 | R10: 530 | S10: 650
B11: MOVIMENTAÇÃO DE TERRA | C11: 19.58779 | D11: =(ORÇAMENTO_COMPARATIVO!$J$20/CÁLCULO_MÉDIAS!D$4)*C11 -> 22.066437 | E11: 73.6 | F11: =(ORÇAMENTO_COMPARATIVO!$J$20/CÁLCULO_MÉDIAS!F$4)*E11 -> 83.519109 | G11: 131.35298 | H11: =(ORÇAMENTO_COMPARATIVO!$J$20/CÁLCULO_MÉDIAS!H$4)*G11 -> 147.97444 | I11: 19.639226 | J11: =(ORÇAMENTO_COMPARATIVO!$J$20/CÁLCULO_MÉDIAS!J$4)*I11 -> 25.523199 | K11: 23.672459 | L11: =(ORÇAMENTO_COMPARATIVO!$J$20/CÁLCULO_MÉDIAS!L$4)*K11 -> 27.908002 | M11: 20.474934 | N11: =(ORÇAMENTO_COMPARATIVO!$J$20/CÁLCULO_MÉDIAS!N$4)*M11 -> 20.708575 | O11: 11.354068 | P11: =(ORÇAMENTO_COMPARATIVO!$J$20/CÁLCULO_MÉDIAS!P$4)*O11 -> 12.981209 | R11: 16 | S11: 27
B12: INFRAESTRUTURA | C12: 195.5904 | D12: =(ORÇAMENTO_COMPARATIVO!$J$20/CÁLCULO_MÉDIAS!D$4)*C12 -> 220.34048 | E12: 475.12 | F12: =(ORÇAMENTO_COMPARATIVO!$J$20/CÁLCULO_MÉDIAS!F$4)*E12 -> 539.15216 | G12: 99.325701 | H12: =(ORÇAMENTO_COMPARATIVO!$J$20/CÁLCULO_MÉDIAS!H$4)*G12 -> 111.89441 | I12: 175.47897 | J12: =(ORÇAMENTO_COMPARATIVO!$J$20/CÁLCULO_MÉDIAS!J$4)*I12 -> 228.05301 | K12: 194.20763 | L12: =(ORÇAMENTO_COMPARATIVO!$J$20/CÁLCULO_MÉDIAS!L$4)*K12 -> 228.9558 | M12: 378.99947 | N12: =(ORÇAMENTO_COMPARATIVO!$J$20/CÁLCULO_MÉDIAS!N$4)*M12 -> 383.32426 | O12: 177.84796 | P12: =(ORÇAMENTO_COMPARATIVO!$J$20/CÁLCULO_MÉDIAS!P$4)*O12 -> 203.33519 | R12: 220 | S12: 370
B13: SUPRAESTRUTURA | C13: 633.1943 | D13: =(ORÇAMENTO_COMPARATIVO!$J$20/CÁLCULO_MÉDIAS!D$4)*C13 -> 713.31896 | E13: 724.14 | F13: =(ORÇAMENTO_COMPARATIVO!$J$20/CÁLCULO_MÉDIAS!F$4)*E13 -> 821.73271 | G13: 670.8352 | H13: =(ORÇAMENTO_COMPARATIVO!$J$20/CÁLCULO_MÉDIAS!H$4)*G13 -> 755.72295 | I13: 462.68058 | J13: =(ORÇAMENTO_COMPARATIVO!$J$20/CÁLCULO_MÉDIAS!J$4)*I13 -> 601.30112 | K13: 472.2289 | L13: =(ORÇAMENTO_COMPARATIVO!$J$20/CÁLCULO_MÉDIAS!L$4)*K13 -> 556.72142 | M13: 1062.4018 | N13: =(ORÇAMENTO_COMPARATIVO!$J$20/CÁLCULO_MÉDIAS!N$4)*M13 -> 1074.525 | O13: 698.9 | P13: =(ORÇAMENTO_COMPARATIVO!$J$20/CÁLCULO_MÉDIAS!P$4)*O13 -> 799.05874 | R13: 730 | S13: 810
B14: ALVENARIA | C14: 119.11837 | D14: =(ORÇAMENTO_COMPARATIVO!$J$20/CÁLCULO_MÉDIAS!D$4)*C14 -> 134.19166 | E14: 168.14 | F14: =(ORÇAMENTO_COMPARATIVO!$J$20/CÁLCULO_MÉDIAS!F$4)*E14 -> 190.80031 | G14: 151.38702 | H14: =(ORÇAMENTO_COMPARATIVO!$J$20/CÁLCULO_MÉDIAS!H$4)*G14 -> 170.54359 | I14: 57.004854 | J14: =(ORÇAMENTO_COMPARATIVO!$J$20/CÁLCULO_MÉDIAS!J$4)*I14 -> 74.083685 | K14: 56.465243 | L14: =(ORÇAMENTO_COMPARATIVO!$J$20/CÁLCULO_MÉDIAS!L$4)*K14 -> 66.568162 | M14: 176.75348 | N14: =(ORÇAMENTO_COMPARATIVO!$J$20/CÁLCULO_MÉDIAS!N$4)*M14 -> 178.77043 | O14: 100.27283 | P14: =(ORÇAMENTO_COMPARATIVO!$J$20/CÁLCULO_MÉDIAS!P$4)*O14 -> 114.64284 | R14: 100 | S14: 170
B15: INSTALAÇÕES ELÉTRICAS, HIDRÁULICAS, GLP E PREVENTIVAS | C15: 298.34419 | D15: =(ORÇAMENTO_COMPARATIVO!$J$20/CÁLCULO_MÉDIAS!D$4)*C15 -> 336.09678 | E15: 325.69 | F15: =(ORÇAMENTO_COMPARATIVO!$J$20/CÁLCULO_MÉDIAS!F$4)*E15 -> 369.5834 | G15: 301.65243 | H15: =(ORÇAMENTO_COMPARATIVO!$J$20/CÁLCULO_MÉDIAS!H$4)*G15 -> 339.82364 | I15: =163.356244433727+44.67 -> 208.02624 | J15: =(ORÇAMENTO_COMPARATIVO!$J$20/CÁLCULO_MÉDIAS!J$4)*I15 -> 270.35155 | K15: =206.000001468319+48.36 -> 254.36 | L15: =(ORÇAMENTO_COMPARATIVO!$J$20/CÁLCULO_MÉDIAS!L$4)*K15 -> 299.8708 | M15: 591.33991 | N15: =(ORÇAMENTO_COMPARATIVO!$J$20/CÁLCULO_MÉDIAS!N$4)*M15 -> 598.08774 | O15: 217.23158 | P15: =(ORÇAMENTO_COMPARATIVO!$J$20/CÁLCULO_MÉDIAS!P$4)*O15 -> 248.36285 | R15: 480 | S15: 600
B16: EQUIPAMENTOS E SISTEMAS ESPECIAIS | C16: 234.95757 | D16: =(ORÇAMENTO_COMPARATIVO!$J$20/CÁLCULO_MÉDIAS!D$4)*C16 -> 264.68919 | E16: 126.03 | F16: =(ORÇAMENTO_COMPARATIVO!$J$20/CÁLCULO_MÉDIAS!F$4)*E16 -> 143.01513 | G16: 121.62815 | H16: =(ORÇAMENTO_COMPARATIVO!$J$20/CÁLCULO_MÉDIAS!H$4)*G16 -> 137.01902 | I16: 193.52138 | J16: =(ORÇAMENTO_COMPARATIVO!$J$20/CÁLCULO_MÉDIAS!J$4)*I16 -> 251.50098 | K16: 221.95225 | L16: =(ORÇAMENTO_COMPARATIVO!$J$20/CÁLCULO_MÉDIAS!L$4)*K16 -> 261.66456 | M16: 335.79661 | N16: =(ORÇAMENTO_COMPARATIVO!$J$20/CÁLCULO_MÉDIAS!N$4)*M16 -> 339.62841 | O16: 207.7874 | P16: =(ORÇAMENTO_COMPARATIVO!$J$20/CÁLCULO_MÉDIAS!P$4)*O16 -> 237.56522 | R16: 230 | S16: 265
B17: IMPERMEABILIZAÇÃO | C17: 40.38554 | D17: =(ORÇAMENTO_COMPARATIVO!$J$20/CÁLCULO_MÉDIAS!D$4)*C17 -> 45.495942 | E17: 88.82 | F17: =(ORÇAMENTO_COMPARATIVO!$J$20/CÁLCULO_MÉDIAS!F$4)*E17 -> 100.79032 | G17: 61.191658 | H17: =(ORÇAMENTO_COMPARATIVO!$J$20/CÁLCULO_MÉDIAS!H$4)*G17 -> 68.934874 | I17: 67.011431 | J17: =(ORÇAMENTO_COMPARATIVO!$J$20/CÁLCULO_MÉDIAS!J$4)*I17 -> 87.088264 | K17: 77.826887 | L17: =(ORÇAMENTO_COMPARATIVO!$J$20/CÁLCULO_MÉDIAS!L$4)*K17 -> 91.751891 | M17: 46.008199 | N17: =(ORÇAMENTO_COMPARATIVO!$J$20/CÁLCULO_MÉDIAS!N$4)*M17 -> 46.533202 | O17: 52.877814 | P17: =(ORÇAMENTO_COMPARATIVO!$J$20/CÁLCULO_MÉDIAS!P$4)*O17 -> 60.455687 | R17: 65 | S17: 100
B18: REVESTIMENTOS INTERNOS EM PISO E PAREDE | C18: 171.46501 | D18: =(ORÇAMENTO_COMPARATIVO!$J$20/CÁLCULO_MÉDIAS!D$4)*C18 -> 193.16226 | E18: 208.78 | F18: =(ORÇAMENTO_COMPARATIVO!$J$20/CÁLCULO_MÉDIAS!F$4)*E18 -> 236.91739 | G18: 161.7371 | H18: =(ORÇAMENTO_COMPARATIVO!$J$20/CÁLCULO_MÉDIAS!H$4)*G18 -> 182.20338 | I18: 50.803601 | J18: =(ORÇAMENTO_COMPARATIVO!$J$20/CÁLCULO_MÉDIAS!J$4)*I18 -> 66.024518 | K18: 58.908295 | L18: =(ORÇAMENTO_COMPARATIVO!$J$20/CÁLCULO_MÉDIAS!L$4)*K18 -> 69.448331 | M18: 242.30051 | N18: =(ORÇAMENTO_COMPARATIVO!$J$20/CÁLCULO_MÉDIAS!N$4)*M18 -> 245.06542 | O18: 183.80825 | P18: =(ORÇAMENTO_COMPARATIVO!$J$20/CÁLCULO_MÉDIAS!P$4)*O18 -> 210.14965 | R18: 160 | S18: 210
B19: REVESTIMENTOS E ACABAMENTOS INTERNOS EM TETO | C19: 82.252956 | D19: =(ORÇAMENTO_COMPARATIVO!$J$20/CÁLCULO_MÉDIAS!D$4)*C19 -> 92.661278 | E19: 69.87 | F19: =(ORÇAMENTO_COMPARATIVO!$J$20/CÁLCULO_MÉDIAS!F$4)*E19 -> 79.286415 | G19: 38.140863 | H19: =(ORÇAMENTO_COMPARATIVO!$J$20/CÁLCULO_MÉDIAS!H$4)*G19 -> 42.967223 | I19: 40.348692 | J19: =(ORÇAMENTO_COMPARATIVO!$J$20/CÁLCULO_MÉDIAS!J$4)*I19 -> 52.437286 | K19: 43.752635 | L19: =(ORÇAMENTO_COMPARATIVO!$J$20/CÁLCULO_MÉDIAS!L$4)*K19 -> 51.580979 | M19: 59.184931 | N19: =(ORÇAMENTO_COMPARATIVO!$J$20/CÁLCULO_MÉDIAS!N$4)*M19 -> 59.860294 | O19: 55.024017 | P19: =(ORÇAMENTO_COMPARATIVO!$J$20/CÁLCULO_MÉDIAS!P$4)*O19 -> 62.90946 | R19: 55 | S19: 90
B20: ACABAMENTOS EM PISO E PAREDE | C20: 171.08275 | D20: =(ORÇAMENTO_COMPARATIVO!$J$20/CÁLCULO_MÉDIAS!D$4)*C20 -> 192.73163 | E20: 169.91 | F20: =(ORÇAMENTO_COMPARATIVO!$J$20/CÁLCULO_MÉDIAS!F$4)*E20 -> 192.80886 | G20: 233.49804 | H20: =(ORÇAMENTO_COMPARATIVO!$J$20/CÁLCULO_MÉDIAS!H$4)*G20 -> 263.04497 | I20: 142.87754 | J20: =(ORÇAMENTO_COMPARATIVO!$J$20/CÁLCULO_MÉDIAS!J$4)*I20 -> 185.68409 | K20: 211.45217 | L20: =(ORÇAMENTO_COMPARATIVO!$J$20/CÁLCULO_MÉDIAS!L$4)*K20 -> 249.28578 | M20: 201.06525 | N20: =(ORÇAMENTO_COMPARATIVO!$J$20/CÁLCULO_MÉDIAS!N$4)*M20 -> 203.35962 | O20: 163.81515 | P20: =(ORÇAMENTO_COMPARATIVO!$J$20/CÁLCULO_MÉDIAS!P$4)*O20 -> 187.29136 | R20: 200 | S20: 280
B21: PINTURA INTERNA | C21: 131.71985 | D21: =(ORÇAMENTO_COMPARATIVO!$J$20/CÁLCULO_MÉDIAS!D$4)*C21 -> 148.38773 | E21: 91.97 | F21: =(ORÇAMENTO_COMPARATIVO!$J$20/CÁLCULO_MÉDIAS!F$4)*E21 -> 104.36484 | G21: 60.245257 | H21: =(ORÇAMENTO_COMPARATIVO!$J$20/CÁLCULO_MÉDIAS!H$4)*G21 -> 67.868715 | I21: 33.009396 | J21: =(ORÇAMENTO_COMPARATIVO!$J$20/CÁLCULO_MÉDIAS!J$4)*I21 -> 42.899113 | K21: 34.336878 | L21: =(ORÇAMENTO_COMPARATIVO!$J$20/CÁLCULO_MÉDIAS!L$4)*K21 -> 40.480528 | M21: 139.35201 | N21: =(ORÇAMENTO_COMPARATIVO!$J$20/CÁLCULO_MÉDIAS!N$4)*M21 -> 140.94217 | O21: 108.33293 | P21: =(ORÇAMENTO_COMPARATIVO!$J$20/CÁLCULO_MÉDIAS!P$4)*O21 -> 123.85803 | R21: 100 | S21: 150
B22: ESQUADRIAS, VIDROS E FERRAGENS | C22: 323.47432 | D22: =(ORÇAMENTO_COMPARATIVO!$J$20/CÁLCULO_MÉDIAS!D$4)*C22 -> 364.40688 | E22: 334.99 | F22: =(ORÇAMENTO_COMPARATIVO!$J$20/CÁLCULO_MÉDIAS!F$4)*E22 -> 380.13677 | G22: 393.73193 | H22: =(ORÇAMENTO_COMPARATIVO!$J$20/CÁLCULO_MÉDIAS!H$4)*G22 -> 443.55492 | I22: 544.38783 | J22: =(ORÇAMENTO_COMPARATIVO!$J$20/CÁLCULO_MÉDIAS!J$4)*I22 -> 707.48812 | K22: 549.13098 | L22: =(ORÇAMENTO_COMPARATIVO!$J$20/CÁLCULO_MÉDIAS!L$4)*K22 -> 647.38302 | M22: 747.75539 | N22: =(ORÇAMENTO_COMPARATIVO!$J$20/CÁLCULO_MÉDIAS!N$4)*M22 -> 756.28809 | O22: 309.45411 | P22: =(ORÇAMENTO_COMPARATIVO!$J$20/CÁLCULO_MÉDIAS!P$4)*O22 -> 353.80171 | R22: 630 | S22: 700
B23: COBERTURA | C23: 5.0049675 | D23: =(ORÇAMENTO_COMPARATIVO!$J$20/CÁLCULO_MÉDIAS!D$4)*C23 -> 5.6382981 | E23: 42.32 | F23: =(ORÇAMENTO_COMPARATIVO!$J$20/CÁLCULO_MÉDIAS!F$4)*E23 -> 48.023488 | G23: 18.057176 | H23: =(ORÇAMENTO_COMPARATIVO!$J$20/CÁLCULO_MÉDIAS!H$4)*G23 -> 20.342138 | I23: 0 | J23: =(ORÇAMENTO_COMPARATIVO!$J$20/CÁLCULO_MÉDIAS!J$4)*I23 -> 0 | K23: 0 | L23: =(ORÇAMENTO_COMPARATIVO!$J$20/CÁLCULO_MÉDIAS!L$4)*K23 -> 0 | M23: 405.1942 | N23: =(ORÇAMENTO_COMPARATIVO!$J$20/CÁLCULO_MÉDIAS!N$4)*M23 -> 409.8179 | O23: 0.59741266 | P23: =(ORÇAMENTO_COMPARATIVO!$J$20/CÁLCULO_MÉDIAS!P$4)*O23 -> 0.68302734
B24: REVESTIMENTOS E ACABAMENTOS DE FACHADA | C24: 165.68145 | D24: =(ORÇAMENTO_COMPARATIVO!$J$20/CÁLCULO_MÉDIAS!D$4)*C24 -> 186.64685 | E24: 128.59 | F24: =(ORÇAMENTO_COMPARATIVO!$J$20/CÁLCULO_MÉDIAS!F$4)*E24 -> 145.92014 | G24: 152.18185 | H24: =(ORÇAMENTO_COMPARATIVO!$J$20/CÁLCULO_MÉDIAS!H$4)*G24 -> 171.439 | I24: 33.346303 | J24: =(ORÇAMENTO_COMPARATIVO!$J$20/CÁLCULO_MÉDIAS!J$4)*I24 -> 43.336959 | K24: 35.477947 | L24: =(ORÇAMENTO_COMPARATIVO!$J$20/CÁLCULO_MÉDIAS!L$4)*K24 -> 41.82576 | M24: 198.23788 | N24: =(ORÇAMENTO_COMPARATIVO!$J$20/CÁLCULO_MÉDIAS!N$4)*M24 -> 200.49999 | O24: 112.08422 | P24: =(ORÇAMENTO_COMPARATIVO!$J$20/CÁLCULO_MÉDIAS!P$4)*O24 -> 128.14691 | R24: 170 | S24: 200
B25: SERVIÇOS COMPLEMENTARES | C25: 142.84172 | D25: =(ORÇAMENTO_COMPARATIVO!$J$20/CÁLCULO_MÉDIAS!D$4)*C25 -> 160.91696 | E25: 206.87 | F25: =(ORÇAMENTO_COMPARATIVO!$J$20/CÁLCULO_MÉDIAS!F$4)*E25 -> 234.74997 | G25: 152.5097 | H25: =(ORÇAMENTO_COMPARATIVO!$J$20/CÁLCULO_MÉDIAS!H$4)*G25 -> 171.80833 | I25: 143.24654 | J25: =(ORÇAMENTO_COMPARATIVO!$J$20/CÁLCULO_MÉDIAS!J$4)*I25 -> 186.16365 | K25: =147.331110298641+157.55 -> 304.88111 | L25: =(ORÇAMENTO_COMPARATIVO!$J$20/CÁLCULO_MÉDIAS!L$4)*K25 -> 359.43129 | M25: 92.097292 | N25: =(ORÇAMENTO_COMPARATIVO!$J$20/CÁLCULO_MÉDIAS!N$4)*M25 -> 93.148221 | O25: 167.97572 | P25: =(ORÇAMENTO_COMPARATIVO!$J$20/CÁLCULO_MÉDIAS!P$4)*O25 -> 192.04817 | R25: 190 | S25: 250
B26: TOTAL | C26: =SUM(C10:C25) -> 3173.0147 | D26: =SUM(D10:D25) -> 3574.5293 | E26: =SUM(E10:E25) -> 3635.17 | F26: =SUM(F10:F25) -> 4125.0837 | G26: =SUM(G10:G25) -> 2940.0127 | H26: =SUM(H10:H25) -> 3312.043 | I26: =SUM(I10:I25) -> 2547.4664 | J26: =SUM(J10:J25) -> 3310.6952 | ... P26: =SUM(P10:P25) -> 3250.3289 | R26: =SUM(R10:R25) -> 3876 | S26: =SUM(S10:S25) -> 4872
