Workbook
Name \0: #REF!
Name \0: #REF!
Name \0: #REF!
Name \1: #REF!
Name \a: #REF!
Name \a: #REF!
Name \a: #REF!
Name \b: #REF!
Name \c: #REF!
Name \d: #REF!
Name \e: #REF!
Name \i: #REF!
Name \J: #REF!
Name \k: #REF!
Name \l: #N/A
Name \m: #REF!
Name \m: #REF!
Name \m: #REF!
Name \o: #REF!
Name \p: #REF!
Name \r: #REF!
Name \T: #REF!
Name \z: #REF!
Name _\0: #REF!
Name _\1: #REF!
Name _\a: #REF!
Name _\b: #REF!
Name _\c: #REF!
Name _\d: #REF!
Name _\e: #REF!
Name _\i: #REF!
Name _\J: #REF!
Name _\k: #REF!
Name _\l: #N/A
Name _\m: #REF!
Name _\o: #REF!
Name _\p: #REF!
Name _\r: #REF!
Name _\T: #REF!
Name _\z: #REF!
Name ______ACR10: #REF!
Name ______ACR15: #REF!
Name ______acr20: #REF!
Name ______acr5: #REF!
Name ______ARQ1: #REF!
Name ______QT100: #REF!
Name ______QT2: #REF!
Name ______QT3: #REF!
Name ______QT4: #REF!
Name ______QT50: #REF!
Name ______QT75: #REF!
Name _____ACR10: #REF!
Name _____ACR15: #REF!
Name _____acr20: #REF!
Name _____acr5: #REF!
Name _____ARQ1: #REF!
Name _____QT100: #REF!
Name _____QT2: #REF!
Name _____QT3: #REF!
Name _____QT4: #REF!

Sheet PREÇO
B1: Projeto | C1: =Aspiração!D1 -> Senna Tower
B2: Empresa | C2: =Aspiração!D2 -> FG
B3: Revisão | C3: =Aspiração!D3 -> R00 - Letícia
A4: =Aspiração!A4 -> ASPIRAÇÃO
C5: Descrição | D5: Unidade | E5: Custo unitário
D6: =_xlfn.XLOOKUP(PREÇO!C6,Aspiração!$E$7:$E$61,Aspiração!$J$7:$J$61) -> 0
D7: =_xlfn.XLOOKUP(PREÇO!C7,Aspiração!$E$7:$E$61,Aspiração!$J$7:$J$61) -> 0
D8: =_xlfn.XLOOKUP(PREÇO!C8,Aspiração!$E$7:$E$61,Aspiração!$J$7:$J$61) -> 0
D9: =_xlfn.XLOOKUP(PREÇO!C9,Aspiração!$E$7:$E$61,Aspiração!$J$7:$J$61) -> 0
D10: =_xlfn.XLOOKUP(PREÇO!C10,Aspiração!$E$7:$E$61,Aspiração!$J$7:$J$61) -> 0
D11: =_xlfn.XLOOKUP(PREÇO!C11,Aspiração!$E$7:$E$61,Aspiração!$J$7:$J$61) -> 0
D12: =_xlfn.XLOOKUP(PREÇO!C12,Aspiração!$E$7:$E$61,Aspiração!$J$7:$J$61) -> 0
D13: =_xlfn.XLOOKUP(PREÇO!C13,Aspiração!$E$7:$E$61,Aspiração!$J$7:$J$61) -> 0
D14: =_xlfn.XLOOKUP(PREÇO!C14,Aspiração!$E$7:$E$61,Aspiração!$J$7:$J$61) -> 0
D15: =_xlfn.XLOOKUP(PREÇO!C15,Aspiração!$E$7:$E$61,Aspiração!$J$7:$J$61) -> 0
D16: =_xlfn.XLOOKUP(PREÇO!C16,Aspiração!$E$7:$E$61,Aspiração!$J$7:$J$61) -> 0
D17: =_xlfn.XLOOKUP(PREÇO!C17,Aspiração!$E$7:$E$61,Aspiração!$J$7:$J$61) -> 0
... D58: =_xlfn.XLOOKUP(PREÇO!C58,Aspiração!$E$7:$E$61,Aspiração!$J$7:$J$61) -> 0

Sheet Aspiração
C1: Projeto | D1: Senna Tower
C2: Empresa | D2: FG
C3: Revisão | D3: R00 - Letícia
A4: ASPIRAÇÃO
A5: TORRE | B5: PAVIMENTO | C5: GRUPO/EAP | D5: SUBGRUPO | E5: Descrição | F5: Quantidade | G5: Repetições do pavimento | H5: Apartamentos por pavimento | I5: Qte total | J5: Unidade | K5: Custo unitário | L5: Custo Total | N5: Torre | O5: EAP | P5: Tomada de aspiração chumbada na alvenaria/draywall | Q5: Tomada 220V Central de aspiração | R5: TOTAL
A6: GERAL | B6: TIPO 01 | L6: =IF(SUM(F6:K6)=0,SUMIFS($L7:$L$394,$B7:$B$394,$B6,$A7:$A$394,$A6),I6*K6) -> #N/A | N6: GERAL | O6: {=_xlfn.UNIQUE(_xlfn._xlws.FILTER($B$6:$B$1048576,$B$6:$B$1048576<>""))} -> TIPO 01 | P6: =SUMIFS($I$6:$I$61,$E$6:$E$61,P$5,$B$6:$B$61,$O6,$A$6:$A$61,$N6) -> 84 | Q6: =SUMIFS($I$6:$I$61,$E$6:$E$61,Q$5,$B$6:$B$61,$O6,$A$6:$A$61,$N6) -> 12 | R6: =SUM(Q6:Q6) -> 12
A7: =A6 -> GERAL | B7: =B6 -> TIPO 01 | C7: Sistema de aspiração central | D7: Aspiração | E7: Tomada de aspiração chumbada na alvenaria/draywall | F7: 7 | G7: 6 | H7: 2 | I7: =F7*G7*H7 -> 84 | J7: un | K7: =_xlfn.XLOOKUP($E7,PREÇO!$C$6:$C$89,PREÇO!$E$6:$E$89) -> #N/A | L7: =IF(SUM(F7:K7)=0,SUMIFS($L9:$L$394,$B9:$B$394,$B7,$A9:$A$394,$A7),I7*K7) -> #N/A | N7: GERAL | O7: TIPO 02 | P7: =SUMIFS($I$6:$I$61,$E$6:$E$61,P$5,$B$6:$B$61,$O7,$A$6:$A$61,$N7) -> 42 | Q7: =SUMIFS($I$6:$I$61,$E$6:$E$61,Q$5,$B$6:$B$61,$O7,$A$6:$A$61,$N7) -> 6 | R7: =SUM(Q7:Q7) -> 6
A8: =A7 -> GERAL | B8: =B7 -> TIPO 01 | C8: Sistema de aspiração central | D8: Aspiração | E8: Tomada 220V Central de aspiração | F8: 1 | G8: 6 | H8: 2 | I8: =F8*G8*H8 -> 12 | J8: un | K8: =_xlfn.XLOOKUP($E8,PREÇO!$C$6:$C$89,PREÇO!$E$6:$E$89) -> #N/A | L8: =IF(SUM(F8:K8)=0,SUMIFS($L10:$L$394,$B10:$B$394,$B8,$A10:$A$394,$A8),I8*K8) -> #N/A | N8: GERAL | O8: TIPO 03 A | P8: =SUMIFS($I$6:$I$61,$E$6:$E$61,P$5,$B$6:$B$61,$O8,$A$6:$A$61,$N8) -> 132 | Q8: =SUMIFS($I$6:$I$61,$E$6:$E$61,Q$5,$B$6:$B$61,$O8,$A$6:$A$61,$N8) -> 22 | R8: =SUM(Q8:Q8) -> 22
A9: GERAL | B9: TIPO 02 | L9: =IF(SUM(F9:K9)=0,SUMIFS($L10:$L$394,$B10:$B$394,$B9,$A10:$A$394,$A9),I9*K9) -> #N/A | N9: GERAL | O9: TIPO 03 B | P9: =SUMIFS($I$6:$I$61,$E$6:$E$61,P$5,$B$6:$B$61,$O9,$A$6:$A$61,$N9) -> 96 | Q9: =SUMIFS($I$6:$I$61,$E$6:$E$61,Q$5,$B$6:$B$61,$O9,$A$6:$A$61,$N9) -> 16 | R9: =SUM(Q9:Q9) -> 16
A10: =A9 -> GERAL | B10: =B9 -> TIPO 02 | C10: Sistema de aspiração central | D10: Aspiração | E10: Tomada de aspiração chumbada na alvenaria/draywall | F10: 7 | G10: 3 | H10: 2 | I10: =F10*G10*H10 -> 42 | J10: un | K10: =_xlfn.XLOOKUP($E10,PREÇO!$C$6:$C$89,PREÇO!$E$6:$E$89) -> #N/A | L10: =IF(SUM(F10:K10)=0,SUMIFS($L12:$L$394,$B12:$B$394,$B10,$A12:$A$394,$A10),I10*K10) -> #N/A | N10: GERAL | O10: TIPO 03 C | P10: =SUMIFS($I$6:$I$61,$E$6:$E$61,P$5,$B$6:$B$61,$O10,$A$6:$A$61,$N10) -> 108 | Q10: =SUMIFS($I$6:$I$61,$E$6:$E$61,Q$5,$B$6:$B$61,$O10,$A$6:$A$61,$N10) -> 18 | R10: =SUM(Q10:Q10) -> 18
A11: =A10 -> GERAL | B11: =B10 -> TIPO 02 | C11: Sistema de aspiração central | D11: Aspiração | E11: Tomada 220V Central de aspiração | F11: 1 | G11: 3 | H11: 2 | I11: =F11*G11*H11 -> 6 | J11: un | K11: =_xlfn.XLOOKUP($E11,PREÇO!$C$6:$C$89,PREÇO!$E$6:$E$89) -> #N/A | L11: =IF(SUM(F11:K11)=0,SUMIFS($L13:$L$394,$B13:$B$394,$B11,$A13:$A$394,$A11),I11*K11) -> #N/A | N11: GERAL | O11: TIPO 04 A | P11: =SUMIFS($I$6:$I$61,$E$6:$E$61,P$5,$B$6:$B$61,$O11,$A$6:$A$61,$N11) -> 120 | Q11: =SUMIFS($I$6:$I$61,$E$6:$E$61,Q$5,$B$6:$B$61,$O11,$A$6:$A$61,$N11) -> 20 | R11: =SUM(Q11:Q11) -> 20
A12: GERAL | B12: TIPO 03 A | L12: =IF(SUM(F12:K12)=0,SUMIFS($L13:$L$394,$B13:$B$394,$B12,$A13:$A$394,$A12),I12*K12) -> #N/A | N12: GERAL | O12: TIPO 04 B | P12: =SUMIFS($I$6:$I$61,$E$6:$E$61,P$5,$B$6:$B$61,$O12,$A$6:$A$61,$N12) -> 432 | Q12: =SUMIFS($I$6:$I$61,$E$6:$E$61,Q$5,$B$6:$B$61,$O12,$A$6:$A$61,$N12) -> 72 | R12: =SUM(Q12:Q12) -> 72
A13: =A12 -> GERAL | B13: =B12 -> TIPO 03 A | C13: Sistema de aspiração central | D13: Aspiração | E13: Tomada de aspiração chumbada na alvenaria/draywall | F13: 6 | G13: 11 | H13: 2 | I13: =F13*G13*H13 -> 132 | J13: un | K13: =_xlfn.XLOOKUP($E13,PREÇO!$C$6:$C$89,PREÇO!$E$6:$E$89) -> #N/A | L13: =IF(SUM(F13:K13)=0,SUMIFS($L21:$L$394,$B21:$B$394,$B13,$A21:$A$394,$A13),I13*K13) -> #N/A | N13: GERAL | O13: TIPO 04 C | P13: =SUMIFS($I$6:$I$61,$E$6:$E$61,P$5,$B$6:$B$61,$O13,$A$6:$A$61,$N13) -> 228 | Q13: =SUMIFS($I$6:$I$61,$E$6:$E$61,Q$5,$B$6:$B$61,$O13,$A$6:$A$61,$N13) -> 38 | R13: =SUM(Q13:Q13) -> 38
A14: =A13 -> GERAL | B14: =B13 -> TIPO 03 A | C14: Sistema de aspiração central | D14: Aspiração | E14: Tomada 220V Central de aspiração | F14: 1 | G14: 11 | H14: 2 | I14: =F14*G14*H14 -> 22 | J14: un | K14: =_xlfn.XLOOKUP($E14,PREÇO!$C$6:$C$89,PREÇO!$E$6:$E$89) -> #N/A | L14: =IF(SUM(F14:K14)=0,SUMIFS($L16:$L$394,$B16:$B$394,$B14,$A16:$A$394,$A14),I14*K14) -> #N/A | N14: GERAL | O14: TIPO 04 D | P14: =SUMIFS($I$6:$I$61,$E$6:$E$61,P$5,$B$6:$B$61,$O14,$A$6:$A$61,$N14) -> 108 | Q14: =SUMIFS($I$6:$I$61,$E$6:$E$61,Q$5,$B$6:$B$61,$O14,$A$6:$A$61,$N14) -> 18 | R14: =SUM(Q14:Q14) -> 18
A15: GERAL | B15: TIPO 03 B | L15: =IF(SUM(F15:K15)=0,SUMIFS($L16:$L$394,$B16:$B$394,$B15,$A16:$A$394,$A15),I15*K15) -> #N/A | N15: GERAL | O15: DUPLEX INFERIOR | P15: =SUMIFS($I$6:$I$61,$E$6:$E$61,P$5,$B$6:$B$61,$O15,$A$6:$A$61,$N15) -> 12 | Q15: =SUMIFS($I$6:$I$61,$E$6:$E$61,Q$5,$B$6:$B$61,$O15,$A$6:$A$61,$N15) -> 4 | R15: =SUM(Q15:Q15) -> 4
A16: =A15 -> GERAL | B16: =B15 -> TIPO 03 B | C16: Sistema de aspiração central | D16: Aspiração | E16: Tomada de aspiração chumbada na alvenaria/draywall | F16: 6 | G16: 8 | H16: 2 | I16: =F16*G16*H16 -> 96 | J16: un | K16: =_xlfn.XLOOKUP($E16,PREÇO!$C$6:$C$89,PREÇO!$E$6:$E$89) -> #N/A | L16: =IF(SUM(F16:K16)=0,SUMIFS($L33:$L$394,$B33:$B$394,$B16,$A33:$A$394,$A16),I16*K16) -> #N/A | N16: GERAL | O16: DUPLEX SUPERIOR | P16: =SUMIFS($I$6:$I$61,$E$6:$E$61,P$5,$B$6:$B$61,$O16,$A$6:$A$61,$N16) -> 20 | Q16: =SUMIFS($I$6:$I$61,$E$6:$E$61,Q$5,$B$6:$B$61,$O16,$A$6:$A$61,$N16) -> 0 | R16: =SUM(Q16:Q16) -> 0
A17: =A16 -> GERAL | B17: =B16 -> TIPO 03 B | C17: Sistema de aspiração central | D17: Aspiração | E17: Tomada 220V Central de aspiração | F17: 1 | G17: 8 | H17: 2 | I17: =F17*G17*H17 -> 16 | J17: un | K17: =_xlfn.XLOOKUP($E17,PREÇO!$C$6:$C$89,PREÇO!$E$6:$E$89) -> #N/A | L17: =IF(SUM(F17:K17)=0,SUMIFS($L19:$L$394,$B19:$B$394,$B17,$A19:$A$394,$A17),I17*K17) -> #N/A | N17: GERAL | O17: TRIPLEX INFERIOR | P17: =SUMIFS($I$6:$I$61,$E$6:$E$61,P$5,$B$6:$B$61,$O17,$A$6:$A$61,$N17) -> 4 | Q17: =SUMIFS($I$6:$I$61,$E$6:$E$61,Q$5,$B$6:$B$61,$O17,$A$6:$A$61,$N17) -> 0 | R17: =SUM(Q17:Q17) -> 0
A18: GERAL | B18: TIPO 03 C | L18: =IF(SUM(F18:K18)=0,SUMIFS($L19:$L$394,$B19:$B$394,$B18,$A19:$A$394,$A18),I18*K18) -> #N/A | N18: GERAL | O18: TRIPLEX INTERMEDIÁRIO | P18: =SUMIFS($I$6:$I$61,$E$6:$E$61,P$5,$B$6:$B$61,$O18,$A$6:$A$61,$N18) -> 6 | Q18: =SUMIFS($I$6:$I$61,$E$6:$E$61,Q$5,$B$6:$B$61,$O18,$A$6:$A$61,$N18) -> 2 | R18: =SUM(Q18:Q18) -> 2
A19: =A18 -> GERAL | B19: =B18 -> TIPO 03 C | C19: Sistema de aspiração central | D19: Aspiração | E19: Tomada de aspiração chumbada na alvenaria/draywall | F19: 6 | G19: 9 | H19: 2 | I19: =F19*G19*H19 -> 108 | J19: un | K19: =_xlfn.XLOOKUP($E19,PREÇO!$C$6:$C$89,PREÇO!$E$6:$E$89) -> #N/A | L19: =IF(SUM(F19:K19)=0,SUMIFS($L36:$L$394,$B36:$B$394,$B19,$A36:$A$394,$A19),I19*K19) -> #N/A | N19: GERAL | O19: TRIPLEX SUPERIOR | P19: =SUMIFS($I$6:$I$61,$E$6:$E$61,P$5,$B$6:$B$61,$O19,$A$6:$A$61,$N19) -> 8 | Q19: =SUMIFS($I$6:$I$61,$E$6:$E$61,Q$5,$B$6:$B$61,$O19,$A$6:$A$61,$N19) -> 0 | R19: =SUM(Q19:Q19) -> 0
A20: =A19 -> GERAL | B20: =B19 -> TIPO 03 C | C20: Sistema de aspiração central | D20: Aspiração | E20: Tomada 220V Central de aspiração | F20: 1 | G20: 9 | H20: 2 | I20: =F20*G20*H20 -> 18 | J20: un | K20: =_xlfn.XLOOKUP($E20,PREÇO!$C$6:$C$89,PREÇO!$E$6:$E$89) -> #N/A | L20: =IF(SUM(F20:K20)=0,SUMIFS($L22:$L$394,$B22:$B$394,$B20,$A22:$A$394,$A20),I20*K20) -> #N/A | N20: GERAL | O20: LAZER RESIDENCIAL 01 | P20: =SUMIFS($I$6:$I$61,$E$6:$E$61,P$5,$B$6:$B$61,$O20,$A$6:$A$61,$N20) -> 10 | Q20: =SUMIFS($I$6:$I$61,$E$6:$E$61,Q$5,$B$6:$B$61,$O20,$A$6:$A$61,$N20) -> 1 | R20: =SUM(Q20:Q20) -> 1
A21: GERAL | B21: TIPO 04 A | L21: =IF(SUM(F21:K21)=0,SUMIFS($L22:$L$394,$B22:$B$394,$B21,$A22:$A$394,$A21),I21*K21) -> #N/A | N21: GERAL | O21: LAZER RESIDENCIAL 02 | P21: =SUMIFS($I$6:$I$61,$E$6:$E$61,P$5,$B$6:$B$61,$O21,$A$6:$A$61,$N21) -> 7 | Q21: =SUMIFS($I$6:$I$61,$E$6:$E$61,Q$5,$B$6:$B$61,$O21,$A$6:$A$61,$N21) -> 1 | R21: =SUM(Q21:Q21) -> 1
A22: =A21 -> GERAL | B22: =B21 -> TIPO 04 A | C22: Sistema de aspiração central | D22: Aspiração | E22: Tomada de aspiração chumbada na alvenaria/draywall | F22: 6 | G22: 10 | H22: 2 | I22: =F22*G22*H22 -> 120 | J22: un | K22: =_xlfn.XLOOKUP($E22,PREÇO!$C$6:$C$89,PREÇO!$E$6:$E$89) -> #N/A | L22: =IF(SUM(F22:K22)=0,SUMIFS($L33:$L$394,$B33:$B$394,$B22,$A33:$A$394,$A22),I22*K22) -> #N/A | N22: GERAL | O22: LAZER RESIDENCIAL 03 | P22: =SUMIFS($I$6:$I$61,$E$6:$E$61,P$5,$B$6:$B$61,$O22,$A$6:$A$61,$N22) -> 5 | Q22: =SUMIFS($I$6:$I$61,$E$6:$E$61,Q$5,$B$6:$B$61,$O22,$A$6:$A$61,$N22) -> 1 | R22: =SUM(Q22:Q22) -> 1
A23: =A22 -> GERAL | B23: =B22 -> TIPO 04 A | C23: Sistema de aspiração central | D23: Aspiração | E23: Tomada 220V Central de aspiração | F23: 1 | G23: 10 | H23: 2 | I23: =F23*G23*H23 -> 20 | J23: un | K23: =_xlfn.XLOOKUP($E23,PREÇO!$C$6:$C$89,PREÇO!$E$6:$E$89) -> #N/A | L23: =IF(SUM(F23:K23)=0,SUMIFS($L25:$L$394,$B25:$B$394,$B23,$A25:$A$394,$A23),I23*K23) -> #N/A | N23: GERAL | O23: LAZER RESIDENCIAL 04 | P23: =SUMIFS($I$6:$I$61,$E$6:$E$61,P$5,$B$6:$B$61,$O23,$A$6:$A$61,$N23) -> 7 | Q23: =SUMIFS($I$6:$I$61,$E$6:$E$61,Q$5,$B$6:$B$61,$O23,$A$6:$A$61,$N23) -> 1 | R23: =SUM(Q23:Q23) -> 1
A24: GERAL | B24: TIPO 04 B | L24: =IF(SUM(F24:K24)=0,SUMIFS($L25:$L$394,$B25:$B$394,$B24,$A25:$A$394,$A24),I24*K24) -> #N/A | N24: GERAL | O24: LAZER RESIDENCIAL 05 | P24: =SUMIFS($I$6:$I$61,$E$6:$E$61,P$5,$B$6:$B$61,$O24,$A$6:$A$61,$N24) -> 8 | Q24: =SUMIFS($I$6:$I$61,$E$6:$E$61,Q$5,$B$6:$B$61,$O24,$A$6:$A$61,$N24) -> 1 | R24: =SUM(Q24:Q24) -> 1
A25: =A24 -> GERAL | B25: =B24 -> TIPO 04 B | C25: Sistema de aspiração central | D25: Aspiração | E25: Tomada de aspiração chumbada na alvenaria/draywall | F25: 6 | G25: 36 | H25: 2 | I25: =F25*G25*H25 -> 432 | J25: un | K25: =_xlfn.XLOOKUP($E25,PREÇO!$C$6:$C$89,PREÇO!$E$6:$E$89) -> #N/A | L25: =IF(SUM(F25:K25)=0,SUMIFS($L36:$L$394,$B36:$B$394,$B25,$A36:$A$394,$A25),I25*K25) -> #N/A | N25: GERAL | O25: LAZER RESIDENCIAL 06 | P25: =SUMIFS($I$6:$I$61,$E$6:$E$61,P$5,$B$6:$B$61,$O25,$A$6:$A$61,$N25) -> 6 | Q25: =SUMIFS($I$6:$I$61,$E$6:$E$61,Q$5,$B$6:$B$61,$O25,$A$6:$A$61,$N25) -> 0 | R25: =SUM(Q25:Q25) -> 0
A26: =A25 -> GERAL | B26: =B25 -> TIPO 04 B | C26: Sistema de aspiração central | D26: Aspiração | E26: Tomada 220V Central de aspiração | F26: 1 | G26: 36 | H26: 2 | I26: =F26*G26*H26 -> 72 | J26: un | K26: =_xlfn.XLOOKUP($E26,PREÇO!$C$6:$C$89,PREÇO!$E$6:$E$89) -> #N/A | L26: =IF(SUM(F26:K26)=0,SUMIFS($L28:$L$394,$B28:$B$394,$B26,$A28:$A$394,$A26),I26*K26) -> #N/A
A27: GERAL | B27: TIPO 04 C | L27: =IF(SUM(F27:K27)=0,SUMIFS($L28:$L$394,$B28:$B$394,$B27,$A28:$A$394,$A27),I27*K27) -> #N/A
A28: =A27 -> GERAL | B28: =B27 -> TIPO 04 C | C28: Sistema de aspiração central | D28: Aspiração | E28: Tomada de aspiração chumbada na alvenaria/draywall | F28: 6 | G28: 19 | H28: 2 | I28: =F28*G28*H28 -> 228 | J28: un | K28: =_xlfn.XLOOKUP($E28,PREÇO!$C$6:$C$89,PREÇO!$E$6:$E$89) -> #N/A | L28: =IF(SUM(F28:K28)=0,SUMIFS($L38:$L$394,$B38:$B$394,$B28,$A38:$A$394,$A28),I28*K28) -> #N/A
A29: =A28 -> GERAL | B29: =B28 -> TIPO 04 C | C29: Sistema de aspiração central | D29: Aspiração | E29: Tomada 220V Central de aspiração | F29: 1 | G29: 19 | H29: 2 | I29: =F29*G29*H29 -> 38 | J29: un | K29: =_xlfn.XLOOKUP($E29,PREÇO!$C$6:$C$89,PREÇO!$E$6:$E$89) -> #N/A | L29: =IF(SUM(F29:K29)=0,SUMIFS($L31:$L$394,$B31:$B$394,$B29,$A31:$A$394,$A29),I29*K29) -> #N/A
A30: GERAL | B30: TIPO 04 D | L30: =IF(SUM(F30:K30)=0,SUMIFS($L31:$L$394,$B31:$B$394,$B30,$A31:$A$394,$A30),I30*K30) -> #N/A
A31: =A30 -> GERAL | B31: =B30 -> TIPO 04 D | C31: Sistema de aspiração central | D31: Aspiração | E31: Tomada de aspiração chumbada na alvenaria/draywall | F31: 6 | G31: 9 | H31: 2 | I31: =F31*G31*H31 -> 108 | J31: un | K31: =_xlfn.XLOOKUP($E31,PREÇO!$C$6:$C$89,PREÇO!$E$6:$E$89) -> #N/A | L31: =IF(SUM(F31:K31)=0,SUMIFS($L40:$L$394,$B40:$B$394,$B31,$A40:$A$394,$A31),I31*K31) -> #N/A
A32: =A31 -> GERAL | B32: =B31 -> TIPO 04 D | C32: Sistema de aspiração central | D32: Aspiração | E32: Tomada 220V Central de aspiração | F32: 1 | G32: 9 | H32: 2 | I32: =F32*G32*H32 -> 18 | J32: un | K32: =_xlfn.XLOOKUP($E32,PREÇO!$C$6:$C$89,PREÇO!$E$6:$E$89) -> #N/A | L32: =IF(SUM(F32:K32)=0,SUMIFS($L34:$L$394,$B34:$B$394,$B32,$A34:$A$394,$A32),I32*K32) -> #N/A
A33: GERAL | B33: DUPLEX INFERIOR | L33: =IF(SUM(F33:K33)=0,SUMIFS($L34:$L$394,$B34:$B$394,$B33,$A34:$A$394,$A33),I33*K33) -> #N/A
A34: =A33 -> GERAL | B34: =B33 -> DUPLEX INFERIOR | C34: Sistema de aspiração central | D34: Aspiração | E34: Tomada de aspiração chumbada na alvenaria/draywall | F34: 3 | G34: 2 | H34: 2 | I34: =F34*G34*H34 -> 12 | J34: un | K34: =_xlfn.XLOOKUP($E34,PREÇO!$C$6:$C$89,PREÇO!$E$6:$E$89) -> #N/A | L34: =IF(SUM(F34:K34)=0,SUMIFS($L36:$L$394,$B36:$B$394,$B34,$A36:$A$394,$A34),I34*K34) -> #N/A
A35: =A34 -> GERAL | B35: =B34 -> DUPLEX INFERIOR | C35: Sistema de aspiração central | D35: Aspiração | E35: Tomada 220V Central de aspiração | F35: 1 | G35: 2 | H35: 2 | I35: =F35*G35*H35 -> 4 | J35: un | K35: =_xlfn.XLOOKUP($E35,PREÇO!$C$6:$C$89,PREÇO!$E$6:$E$89) -> #N/A | L35: =IF(SUM(F35:K35)=0,SUMIFS($L37:$L$394,$B37:$B$394,$B35,$A37:$A$394,$A35),I35*K35) -> #N/A
A36: GERAL | B36: DUPLEX SUPERIOR | L36: =IF(SUM(F36:K36)=0,SUMIFS($L37:$L$394,$B37:$B$394,$B36,$A37:$A$394,$A36),I36*K36) -> #N/A
A37: =A36 -> GERAL | B37: =B36 -> DUPLEX SUPERIOR | C37: Sistema de aspiração central | D37: Aspiração | E37: Tomada de aspiração chumbada na alvenaria/draywall | F37: 5 | G37: 2 | H37: 2 | I37: =F37*G37*H37 -> 20 | J37: un | K37: =_xlfn.XLOOKUP($E37,PREÇO!$C$6:$C$89,PREÇO!$E$6:$E$89) -> #N/A | L37: =IF(SUM(F37:K37)=0,SUMIFS($L38:$L$394,$B38:$B$394,$B37,$A38:$A$394,$A37),I37*K37) -> #N/A
A38: GERAL | B38: TRIPLEX INFERIOR | L38: =IF(SUM(F38:K38)=0,SUMIFS($L39:$L$394,$B39:$B$394,$B38,$A39:$A$394,$A38),I38*K38) -> #N/A
A39: =A38 -> GERAL | B39: =B38 -> TRIPLEX INFERIOR | C39: Sistema de aspiração central | D39: Aspiração | E39: Tomada de aspiração chumbada na alvenaria/draywall | F39: 2 | G39: 1 | H39: 2 | I39: =F39*G39*H39 -> 4 | J39: un | K39: =_xlfn.XLOOKUP($E39,PREÇO!$C$6:$C$89,PREÇO!$E$6:$E$89) -> #N/A | L39: =IF(SUM(F39:K39)=0,SUMIFS($L40:$L$394,$B40:$B$394,$B39,$A40:$A$394,$A39),I39*K39) -> #N/A
A40: GERAL | B40: TRIPLEX INTERMEDIÁRIO | L40: =IF(SUM(F40:K40)=0,SUMIFS($L41:$L$394,$B41:$B$394,$B40,$A41:$A$394,$A40),I40*K40) -> #N/A
...

Sheet Arquivos Utilizados
B1: Projeto: | C1: =[4]CAPA!$C$2 -> Senna Tower
B2: Empresa: | C2: =[4]CAPA!$C$3 -> FG
B3: Revisão: | C3: R00
A4: Discplina | B4: Pavimento | C4: Arquivos
A5: Aspiração | B5: TIPO 01 | C5: SEN-AP-ASP-001-TP1-R00.pdf
A6: Aspiração | B6: TIPO 02 | C6: SEN-AP-ASP-002-TP2-R00.pdf
A7: Aspiração | B7: TIPO 03 A | C7: SEN-AP-ASP-003-TP3-R00.pdf
A8: Aspiração | B8: TIPO 03 B | C8: SEN-AP-ASP-004-TP3-R00.pdf
A9: Aspiração | B9: TIPO 03 C | C9: SEN-AP-ASP-005-TP3-R00.pdf
A10: Aspiração | B10: TIPO 04 A | C10: SEN-AP-ASP-006-TP4-R00.pdf
A11: Aspiração | B11: TIPO 04 B | C11: SEN-AP-ASP-007-TP4-R00.pdf
A12: Aspiração | B12: TIPO 04 C | C12: SEN-AP-ASP-008-TP4-R00.pdf
A13: Aspiração | B13: TIPO 04 D | C13: SEN-AP-ASP-009-TP4-R00.pdf
A14: Aspiração | B14: DUPLEX INFERIOR | C14: SEN-AP-ASP-010-DUP-R00.pdf
A15: Aspiração | B15: DUPLEX SUPERIOR | C15: SEN-AP-ASP-011-DUP-R00.pdf
... A24: Aspiração | B24: LAZER RESIDENCIAL 06 | C24: SEN-AP-ASP-020-LZ6-R00.pdf
