Workbook
Name \0: #REF!
Name \1: #REF!
Name \a: #REF!
Name \b: #REF!
Name \c: #REF!
Name \d: #REF!
Name \e: #REF!
Name \i: #REF!
Name \J: #REF!
Name \k: #REF!
Name \l: #N/A
Name \m: #REF!
Name \o: #REF!
Name \p: #REF!
Name \r: #REF!
Name \T: #REF!
Name \z: #REF!
Name _: #REF!
Name _\0: #REF!
Name _\1: #REF!
Name _\a: #REF!
Name _\b: #REF!
Name _\c: #REF!
Name _\d: #REF!
Name _\e: #REF!
Name _\i: #REF!
Name _\J: #REF!
Name _\k: #REF!
Name _\l: #N/A
Name _\m: #REF!
Name _\o: #REF!
Name _\p: #REF!
Name _\r: #REF!
Name _\T: #REF!
Name _\z: #REF!
Name __: #REF!
Name ______ACR10: #REF!
Name ______ACR15: #REF!
Name ______acr20: #REF!
Name ______acr5: #REF!
Name ______ARQ1: #REF!
Name ______QT100: #REF!
Name ______QT2: #REF!
Name ______QT3: #REF!
Name ______QT4: #REF!
Name ______QT50: #REF!
Name ______QT75: #REF!
Name _____ACR10: #REF!
Name _____ACR15: #REF!
Name _____acr20: #REF!
Name _____acr5: #REF!
Name _____ARQ1: #REF!
Name _____key2: #REF!
Name _____QT100: #REF!
Name _____QT2: #REF!
Name _____QT3: #REF!
Name _____QT4: #REF!
Name _____QT50: #REF!
Name _____QT75: #REF!
Name ____key2: #REF!

Sheet CAPA
A1: DADOS DO EMPREENDIMENTO
B2: Projeto: | C2: Electra Towers | E2: ENDEREÇO DA OBRA: | F2: Rua 254, 215, Meia Praia, Itapema/SC
B3: Empresa: | C3: Thozen Empreendimentos | E3: Cidade/ES: | F3: Itapema, SC
B4: Revisão: | C4: R00 | E4: CNPJ: | F4: 43.339.082/0001-06
B6: Pazo de Obra: | C6: 48 | E6: Nº Unid. Residenciais: | F6: 192 | I6: Imagens
B8: Área do Terreno: | C8: 2095.43 | E8: Nº Unid. Comerciais: | F8: 7
B10: Área Construída: | C10: 37893.89 | E10: Nº Pavimentos: | F10: 57
B12: Área Privativa: | C12: 22778.64 | E12: Total de Dormitórios: | F12: 576
B14: Área de Lazer: | C14: 1736.27 | E14: Nº Subsolos: | F14: 0
B16: Área Comercial: | C16: 500.04 | E16: Nº Vagas: | F16: 399
B18: Torre | C18: Pavimento | D18: Área | E18: Área Privativa | F18: Perímetro | G18: Pé direito
B19: Embasamento | C19: Térreo | D19: 1565.91 | E19: 0 | G19: 4.3
B20: Embasamento | C20: Garagem 01 | D20: 1736.27 | E20: 0
B21: Embasamento | C21: Garagem 02 | D21: 1736.27 | E21: 0
B22: Embasamento | C22: Garagem 03 | D22: 1736.27 | E22: 0
B23: Embasamento | C23: Garagem 04 | D23: 1736.27 | E23: 0
B24: Embasamento | C24: Garagem 05 | D24: 1736.27 | E24: 0
B25: Embasamento | C25: Pavimento diferenciado — Lazer | D25: 1736.27 | E25: 0 | G25: 3.6
B26: Torre A | C26: Pavimento tipo — Torre A (×24) | D26: 12720.48 | E26: 11382.72 | G26: 3.24
B27: Torre B | C27: Pavimento tipo — Torre B (×24) | D27: 12892.32 | E27: 11397.12 | G27: 3.24
B28: Cobertura | C28: Casa de Máquinas | D28: 176.26 | E28: 0
B29: Cobertura | C29: Reservatórios | D29: 121.3 | E29: 0
B37: Torre | C37: Pavimento | D37: Descrição | E37: Área | I37: ETAPA
B38: Áreas Comuns | C38: =_xlfn.XLOOKUP(D38,MOBILIÁRIO!C:C,MOBILIÁRIO!B:B) -> TÉRREO | D38: {=_xlfn.UNIQUE(_xlfn._xlws.FILTER(MOBILIÁRIO!C7:C316,MOBILIÁRIO!C7:C316<>""))} -> Hall Externo | E38: =_xlfn.XLOOKUP(D38,MOBILIÁRIO!C:C,MOBILIÁRIO!F:F) -> 12.33 | I38: GERENCIAMENTO TÉCNICO E ADMINISTRATIVO
B39: Áreas Comuns | C39: =_xlfn.XLOOKUP(D39,MOBILIÁRIO!C:C,MOBILIÁRIO!B:B) -> TÉRREO | D39: Hall Térreo | E39: =_xlfn.XLOOKUP(D39,MOBILIÁRIO!C:C,MOBILIÁRIO!F:F) -> 35.27 | I39: MOVIMENTAÇÃO DE TERRA
B40: Áreas Comuns | C40: =_xlfn.XLOOKUP(D40,MOBILIÁRIO!C:C,MOBILIÁRIO!B:B) -> TÉRREO | D40: Guarita | E40: =_xlfn.XLOOKUP(D40,MOBILIÁRIO!C:C,MOBILIÁRIO!F:F) -> 4.72 | I40: CONTENÇÃO
B41: Áreas Comuns | C41: =_xlfn.XLOOKUP(D41,MOBILIÁRIO!C:C,MOBILIÁRIO!B:B) -> TÉRREO | D41: Lavapés | E41: =_xlfn.XLOOKUP(D41,MOBILIÁRIO!C:C,MOBILIÁRIO!F:F) -> 1 | I41: INFRAESTRUTURA
B42: Áreas Comuns | C42: =_xlfn.XLOOKUP(D42,MOBILIÁRIO!C:C,MOBILIÁRIO!B:B) -> TÉRREO | D42: Lavabo Pne - Térreo | E42: =_xlfn.XLOOKUP(D42,MOBILIÁRIO!C:C,MOBILIÁRIO!F:F) -> 3.77 | I42: SUPRAESTRUTURA
B43: Áreas Comuns | C43: =_xlfn.XLOOKUP(D43,MOBILIÁRIO!C:C,MOBILIÁRIO!B:B) -> TÉRREO | D43: Bicicletário/Box | E43: =_xlfn.XLOOKUP(D43,MOBILIÁRIO!C:C,MOBILIÁRIO!F:F) -> 87.33 | I43: ALVENARIAS E VEDAÇÕES
B44: Áreas Comuns | C44: =_xlfn.XLOOKUP(D44,MOBILIÁRIO!C:C,MOBILIÁRIO!B:B) -> TÉRREO | D44: Antecâmara - Térreo | E44: =_xlfn.XLOOKUP(D44,MOBILIÁRIO!C:C,MOBILIÁRIO!F:F) -> 8.07 | I44: SISTEMAS E INSTALAÇÕES ELÉTRICAS
B45: Áreas Comuns | C45: =_xlfn.XLOOKUP(D45,MOBILIÁRIO!C:C,MOBILIÁRIO!B:B) -> 2º AO 5º PAVIMENTO - GARAGENS (X5) | D45: Antecâmara - Garagens (x5) | E45: =_xlfn.XLOOKUP(D45,MOBILIÁRIO!C:C,MOBILIÁRIO!F:F) -> 33.6 | I45: SISTEMAS E INSTALAÇÕES HIDROSSANITÁRIAS E DRENAGEM
B46: Áreas Comuns | C46: =_xlfn.XLOOKUP(D46,MOBILIÁRIO!C:C,MOBILIÁRIO!B:B) -> 4º PAVIMENTO - LAZER/GARAGENS | D46: Sala de massagem | E46: =_xlfn.XLOOKUP(D46,MOBILIÁRIO!C:C,MOBILIÁRIO!F:F) -> 7.47 | I46: INSTALAÇÕES PREVENTIVAS
B47: Áreas Comuns | C47: =_xlfn.XLOOKUP(D47,MOBILIÁRIO!C:C,MOBILIÁRIO!B:B) -> 4º PAVIMENTO - LAZER/GARAGENS | D47: Banheiro - Lazer/Garagem | E47: =_xlfn.XLOOKUP(D47,MOBILIÁRIO!C:C,MOBILIÁRIO!F:F) -> 3.91 | I47: INSTALAÇÕES DE GÁS
B48: Áreas Comuns | C48: =_xlfn.XLOOKUP(D48,MOBILIÁRIO!C:C,MOBILIÁRIO!B:B) -> 4º PAVIMENTO - LAZER/GARAGENS | D48: Lavabo - Lazer/Garagem | E48: =_xlfn.XLOOKUP(D48,MOBILIÁRIO!C:C,MOBILIÁRIO!F:F) -> 2.61 | I48: EQUIPAMENTOS E SISTEMAS ESPECIAIS
B49: Áreas Comuns | C49: =_xlfn.XLOOKUP(D49,MOBILIÁRIO!C:C,MOBILIÁRIO!B:B) -> 4º PAVIMENTO - LAZER/GARAGENS | D49: Lavabo Pne - Lazer/Garagem | E49: =_xlfn.XLOOKUP(D49,MOBILIÁRIO!C:C,MOBILIÁRIO!F:F) -> 4.33 | I49: CLIMATIZAÇÃO, EXAUSTÃO MECÂNICA
B50: Áreas Comuns | C50: =_xlfn.XLOOKUP(D50,MOBILIÁRIO!C:C,MOBILIÁRIO!B:B) -> 4º PAVIMENTO - LAZER/GARAGENS | D50: Circulação - Lazer/garagem | E50: =_xlfn.XLOOKUP(D50,MOBILIÁRIO!C:C,MOBILIÁRIO!F:F) -> 30.85 | I50: INSTALAÇÕES ESPECIAIS
... B63: Áreas Comuns | C63: =_xlfn.XLOOKUP(D63,MOBILIÁRIO!C:C,MOBILIÁRIO!B:B) -> 5º PAVIMENTO - LAZER | D63: Laje Verde | E63: =_xlfn.XLOOKUP(D63,MOBILIÁRIO!C:C,MOBILIÁRIO!F:F) -> 269.95 | I63: CUB/SC
B64: Áreas Comuns | C64: =_xlfn.XLOOKUP(D64,MOBILIÁRIO!C:C,MOBILIÁRIO!B:B) -> 5º PAVIMENTO - LAZER | D64: Brinquedoteca | E64: =_xlfn.XLOOKUP(D64,MOBILIÁRIO!C:C,MOBILIÁRIO!F:F) -> 16.32
B65: Áreas Comuns | C65: =_xlfn.XLOOKUP(D65,MOBILIÁRIO!C:C,MOBILIÁRIO!B:B) -> 5º PAVIMENTO - LAZER | D65: Game Center | E65: =_xlfn.XLOOKUP(D65,MOBILIÁRIO!C:C,MOBILIÁRIO!F:F) -> 13.09 | I65: DESCRIÇÃO
B66: Áreas Comuns | C66: =_xlfn.XLOOKUP(D66,MOBILIÁRIO!C:C,MOBILIÁRIO!B:B) -> 5º PAVIMENTO - LAZER | D66: Sala de Festas | E66: =_xlfn.XLOOKUP(D66,MOBILIÁRIO!C:C,MOBILIÁRIO!F:F) -> 93.46 | I66: VALOR POR ÁREA PRIVATIVA (R$/m²)
...

Sheet EAP
A1: EAP DE ORÇAMENTO
A3: Contrutora - Obra
A5: UNIDADE CONSTRUTIVA | B5: 1 | C5: GERENCIAMENTO TÉCNICO E ADMINISTRATIVO
A6: CÉLULA CONSTRUTIVA | B6: 1 | C6: SERVIÇOS TÉCNICOS
A7: ETAPA | B7: 1.001 | C7: ESTUDOS, PROJETOS E CONSULTORIAS
A8: Subetapa | B8: 01.001.001 | C8: Estudos
A9: Subetapa | B9: 01.001.002 | C9: Projetos
A10: Subetapa | B10: 01.001.003 | C10: Consultorias
A11: Subetapa | B11: 01.001.004 | C11: Ensaios
A12: ETAPA | B12: 1.002 | C12: TAXAS E DOCUMENTOS
A13: Subetapa | B13: 01.002.001 | C13: Licenciamentos, Taxas, Impostos, Aprovações e Seguros
A14: Subetapa | B14: 01.002.002 | C14: Documentos
A15: CÉLULA CONSTRUTIVA | B15: 2 | C15: SERVIÇOS INICIAIS
A16: ETAPA | B16: 2.001 | C16: SEGURANÇA, MEIO AMBIENTE, SAÚDE
A17: Subetapa | B17: 02.001.001 | C17: Segurança do trabalho
A18: Subetapa | B18: 02.001.002 | C18: Equipamentos de proteção
A19: Subetapa | B19: 02.001.003 | C19: Meio ambiente
A20: Subetapa | B20: 02.001.004 | C20: Saúde ocupacional
A21: ETAPA | B21: 2.002 | C21: ADMINISTRAÇÃO E CANTEIRO DE OBRA
A22: Subetapa | B22: 02.002.001 | C22: Equipe de Gestão e Apoio
A23: Subetapa | B23: 02.002.002 | C23: Operação inicial de canteiro
A24: Subetapa | B24: 02.002.003 | C24: Despesas de consumo e manutenção
A25: Subetapa | B25: 02.002.004 | C25: Instalações provisórias
A26: Subetapa | B26: 02.002.005 | C26: Ligações Provisórias
A27: ETAPA | B27: 2.003 | C27: SERVIÇOS PRELIMINARES
... A29: Subetapa | B29: 02.003.002 | C29: Limpeza de terreno
A30: CÉLULA CONSTRUTIVA | B30: 3 | C30: EQUIPAMENTOS
A31: ETAPA | B31: 3.001 | C31: EQUIPAMENTOS
A32: Subetapa | B32: 03.001.001 | C32: Equipamentos de Carga e Transporte
A33: Subetapa | B33: 03.001.002 | C33: Equipamentos de obra
A34: Subetapa | B34: 03.001.003 | C34: Balancins e Andaimes
A35: UNIDADE CONSTRUTIVA | B35: 2 | C35: GERENCIAMENTO EXECUTIVO
A36: CÉLULA CONSTRUTIVA | B36: 1 | C36: INFRAESTRUTURA
A37: ETAPA | B37: 1.001 | C37: MOVIMENTAÇÃO DE TERRA
A38: Subetapa | B38: 01.001.001 | C38: Corte e aterro
A39: Subetapa | B39: 01.001.002 | C39: Rebaixamento de lençol
A40: Subetapa | B40: 01.001.003 | C40: Escavação e Reaterro de Valas
A41: Subetapa | B41: 01.001.004 | C41: Lastro de estrutura de concreto
A42: Subetapa | B42: 01.001.005 | C42: Movimentação de bota - fora
A43: ETAPA | B43: 1.002 | C43: FUNDAÇÃO PROFUNDA
...

Sheet Fund. Rasa | Contenção
B1: Projeto: | C1: =CAPA!C2 -> Elizabeth II Royal Home
B2: Empresa: | C2: =CAPA!C3 -> Gessele
B3: Revisão: | C3: =CAPA!C4 -> R00
A5: ITEM | B5: Projetos | C5: Projetos | D5: Projetos | E5: Descição | F5: Validação | G5: Quantidade | H5: Largura | I5: Largura | J5: Comprimento | K5: Comprimento | L5: Comprimento | M5: Altura | N5: Altura | O5: Altura | P5: Área Externa | Q5: Perímetro Externo | R5: Forma | S5: Largura Adicional | T5: Profundidade | U5: Escavação | V5: Apiolamento | W5: Reaterro | X5: Bota-fora | Y5: Lastro | Z5: Lastro Brita | AA5: Lastro Concreto | AB5: Alvenaria | AC5: Grount | AD5: Fôrma | AE5: Imperm | AF5: Lona | AG5: Concreto | AH5: Tipo | AI5: Detalhe Típico
G6: Und. | H6: A - a1+ a2 | I6: a2 | J6: B | K6: b2 | L6: b1 | M6: H | N6: H0 | O6: H1 | P6: A | Q6: B | R6: lados | S6: m | T6: m | U6: m3 | V6: m2 | W6: m3 | X6: m3 | Y6: esp | Z6: m3 | AA6: m3 | AB6: m2 | AC6: m3 | AD6: m2 | AE6: m2 | AF6: m2 | AG6: m3
A7: TORRE 1 | B7: FUNDAÇÃO RASA | C7: BLOCOS QUADRADOS RETANGULARES
A8: =A7 -> TORRE 1 | B8: =B7 -> FUNDAÇÃO RASA | C8: =C7 -> BLOCOS QUADRADOS RETANGULARES | E8: P12, P18, P25a, P26a, P27a, P28a, P29a | G8: 7 | H8: 1 | J8: 1 | M8: 1.1 | S8: =IF(M8<=1,0.6,1.2) -> 1.2 | T8: 0.85 | U8: =(H8+S8)*(T8+Y8)*(J8+S8)*G8 -> 32.186 | V8: =(H8)*(J8)*G8 -> 7 | W8: =+U8-AG8 -> 24.486 | X8: =(U8-W8)*1.3 -> 10.01 | Y8: 0.1 | Z8: =V8*$Y$8 -> 0.7 | AA8: =V8*$Y$8 -> 0.7 | AD8: =(2*H8+J8*2)*M8*G8 -> 30.8 | AE8: =(V8/G8+((H8+J8)*M8)*2)*G8 -> 37.8 | AG8: =H8*M8*J8*G8 -> 7.7 | AH8: 50
A9: =A8 -> TORRE 1 | B9: =B8 -> FUNDAÇÃO RASA | C9: =C8 -> BLOCOS QUADRADOS RETANGULARES | E9: P30a, P31a, P32a | G9: 3 | H9: 1 | J9: 1 | M9: 1.1 | S9: =IF(M9<=1,0.6,1.2) -> 1.2 | T9: 1.15 | U9: =(H9+S9)*(T9+Y9)*(J9+S9)*G9 -> 18.15 | V9: =(H9)*(J9)*G9 -> 3 | W9: =+U9-AG9 -> 14.85 | X9: =(U9-W9)*1.3 -> 4.29 | Y9: 0.1 | Z9: =V9*$Y$8 -> 0.3 | AA9: =V9*$Y$8 -> 0.3 | AD9: =(2*H9+J9*2)*M9*G9 -> 13.2 | AE9: =(V9/G9+((H9+J9)*M9)*2)*G9 -> 16.2 | AG9: =H9*M9*J9*G9 -> 3.3 | AH9: 50
A10: =A9 -> TORRE 1 | B10: =B9 -> FUNDAÇÃO RASA | C10: =C9 -> BLOCOS QUADRADOS RETANGULARES | E10: P1 | G10: 1 | H10: 1 | J10: 1 | M10: 1.1 | S10: =IF(M10<=1,0.6,1.2) -> 1.2 | T10: 1.65 | U10: =(H10+S10)*(T10+Y10)*(J10+S10)*G10 -> 8.47 | V10: =(H10)*(J10)*G10 -> 1 | W10: =+U10-AG10 -> 7.37 | X10: =(U10-W10)*1.3 -> 1.43 | Y10: 0.1 | Z10: =V10*$Y$8 -> 0.1 | AA10: =V10*$Y$8 -> 0.1 | AD10: =(2*H10+J10*2)*M10*G10 -> 4.4 | AE10: =(V10/G10+((H10+J10)*M10)*2)*G10 -> 5.4 | AG10: =H10*M10*J10*G10 -> 1.1 | AH10: 50
A11: =A10 -> TORRE 1 | B11: =B10 -> FUNDAÇÃO RASA | C11: =C10 -> BLOCOS QUADRADOS RETANGULARES | E11: P9, P10, P11a, P17, P23, P24a, P33a, P34a, P35a, P36a | G11: 10 | H11: 1 | J11: 1 | M11: 1.1 | S11: =IF(M11<=1,0.6,1.2) -> 1.2 | T11: 1.68 | U11: =(H11+S11)*(T11+Y11)*(J11+S11)*G11 -> 86.152 | V11: =(H11)*(J11)*G11 -> 10 | W11: =+U11-AG11 -> 75.152 | X11: =(U11-W11)*1.3 -> 14.3 | Y11: 0.1 | Z11: =V11*$Y$8 -> 1 | AA11: =V11*$Y$8 -> 1 | AD11: =(2*H11+J11*2)*M11*G11 -> 44 | AE11: =(V11/G11+((H11+J11)*M11)*2)*G11 -> 54 | AG11: =H11*M11*J11*G11 -> 11 | AH11: 50
A12: =A11 -> TORRE 1 | B12: =B11 -> FUNDAÇÃO RASA | C12: =C11 -> BLOCOS QUADRADOS RETANGULARES | E12: P37 | G12: 1 | H12: 2.4 | J12: 3.9 | M12: 1.7 | S12: =IF(M12<=1,0.6,1.2) -> 1.2 | T12: 2.58 | U12: =(H12+S12)*(T12+Y12)*(J12+S12)*G12 -> 49.2048 | V12: =(H12)*(J12)*G12 -> 9.36 | W12: =+U12-AG12 -> 33.2928 | X12: =(U12-W12)*1.3 -> 20.6856 | Y12: 0.1 | Z12: =V12*$Y$8 -> 0.936 | AA12: =V12*$Y$8 -> 0.936 | AD12: =(2*H12+J12*2)*M12*G12 -> 21.42 | AE12: =(V12/G12+((H12+J12)*M12)*2)*G12 -> 30.78 | AG12: =H12*M12*J12*G12 -> 15.912 | AH12: 50
A13: =A12 -> TORRE 1 | B13: =B12 -> FUNDAÇÃO RASA | C13: =C12 -> BLOCOS QUADRADOS RETANGULARES | E13: P16, P22 | G13: 2 | H13: 2.7 | J13: 0.9 | M13: 1.1 | S13: =IF(M13<=1,0.6,1.2) -> 1.2 | T13: 1.68 | U13: =(H13+S13)*(T13+Y13)*(J13+S13)*G13 -> 29.1564 | V13: =(H13)*(J13)*G13 -> 4.86 | W13: =+U13-AG13 -> 23.8104 | X13: =(U13-W13)*1.3 -> 6.9498 | Y13: 0.1 | Z13: =V13*$Y$8 -> 0.486 | AA13: =V13*$Y$8 -> 0.486 | AD13: =(2*H13+J13*2)*M13*G13 -> 15.84 | AE13: =(V13/G13+((H13+J13)*M13)*2)*G13 -> 20.7 | AG13: =H13*M13*J13*G13 -> 5.346 | AH13: 50
A14: =A13 -> TORRE 1 | B14: =B13 -> FUNDAÇÃO RASA | C14: =C13 -> BLOCOS QUADRADOS RETANGULARES | E14: P38 | G14: 1 | H14: 3.02 | J14: 3.02 | M14: 1.65 | S14: =IF(M14<=1,0.6,1.2) -> 1.2 | T14: 2.53 | U14: =(H14+S14)*(T14+Y14)*(J14+S14)*G14 -> 46.836092 | V14: =(H14)*(J14)*G14 -> 9.1204 | W14: =+U14-AG14 -> 31.787432 | X14: =(U14-W14)*1.3 -> 19.563258 | Y14: 0.1 | Z14: =V14*$Y$8 -> 0.91204 | AA14: =V14*$Y$8 -> 0.91204 | AD14: =(2*H14+J14*2)*M14*G14 -> 19.932 | AE14: =(V14/G14+((H14+J14)*M14)*2)*G14 -> 29.0524 | AG14: =H14*M14*J14*G14 -> 15.04866 | AH14: 50
A15: =A11 -> TORRE 1 | B15: =B11 -> FUNDAÇÃO RASA | C15: =C11 -> BLOCOS QUADRADOS RETANGULARES | E15: P3 | G15: 1 | H15: 3.9 | J15: 3.5 | M15: 1.6 | S15: =IF(M15<=1,0.6,1.2) -> 1.2 | T15: 2.45 | U15: =(H15+S15)*(T15+Y15)*(J15+S15)*G15 -> 61.1235 | V15: =(H15)*(J15)*G15 -> 13.65 | W15: =+U15-AG15 -> 39.2835 | X15: =(U15-W15)*1.3 -> 28.392 | Y15: 0.1 | Z15: =V15*$Y$8 -> 1.365 | AA15: =V15*$Y$8 -> 1.365 | AD15: =(2*H15+J15*2)*M15*G15 -> 23.68 | AE15: =(V15/G15+((H15+J15)*M15)*2)*G15 -> 37.33 | AG15: =H15*M15*J15*G15 -> 21.84 | AH15: 50
A16: =A15 -> TORRE 1 | B16: =B15 -> FUNDAÇÃO RASA | C16: =C15 -> BLOCOS QUADRADOS RETANGULARES | E16: P8 | G16: 1 | H16: 3.9 | J16: 3.9 | M16: 1.65 | S16: =IF(M16<=1,0.6,1.2) -> 1.2 | T16: 2.23 | U16: =(H16+S16)*(T16+Y16)*(J16+S16)*G16 -> 60.6033 | V16: =(H16)*(J16)*G16 -> 15.21 | W16: =+U16-AG16 -> 35.5068 | X16: =(U16-W16)*1.3 -> 32.62545 | Y16: 0.1 | Z16: =V16*$Y$8 -> 1.521 | AA16: =V16*$Y$8 -> 1.521 | AD16: =(2*H16+J16*2)*M16*G16 -> 25.74 | AE16: =(V16/G16+((H16+J16)*M16)*2)*G16 -> 40.95 | AG16: =H16*M16*J16*G16 -> 25.0965 | AH16: 50
A17: =A16 -> TORRE 1 | B17: =B16 -> FUNDAÇÃO RASA | C17: =C16 -> BLOCOS QUADRADOS RETANGULARES | E17: P40 | G17: 1 | H17: 3.9 | J17: 3.9 | M17: 1.65 | S17: =IF(M17<=1,0.6,1.2) -> 1.2 | T17: 2.48 | U17: =(H17+S17)*(T17+Y17)*(J17+S17)*G17 -> 67.1058 | V17: =(H17)*(J17)*G17 -> 15.21 | W17: =+U17-AG17 -> 42.0093 | X17: =(U17-W17)*1.3 -> 32.62545 | Y17: 0.1 | Z17: =V17*$Y$8 -> 1.521 | AA17: =V17*$Y$8 -> 1.521 | AD17: =(2*H17+J17*2)*M17*G17 -> 25.74 | AE17: =(V17/G17+((H17+J17)*M17)*2)*G17 -> 40.95 | AG17: =H17*M17*J17*G17 -> 25.0965 | AH17: 50
A18: =A17 -> TORRE 1 | B18: =B17 -> FUNDAÇÃO RASA | C18: =C17 -> BLOCOS QUADRADOS RETANGULARES | E18: P20 | G18: 1 | H18: 3.9 | J18: 6.4 | M18: 2 | S18: =IF(M18<=1,0.6,1.2) -> 1.2 | T18: 1.75 | U18: =(H18+S18)*(T18+Y18)*(J18+S18)*G18 -> 71.706 | V18: =(H18)*(J18)*G18 -> 24.96 | W18: =+U18-AG18 -> 21.786 | X18: =(U18-W18)*1.3 -> 64.896 | Y18: 0.1 | Z18: =V18*$Y$8 -> 2.496 | AA18: =V18*$Y$8 -> 2.496 | AD18: =(2*H18+J18*2)*M18*G18 -> 41.2 | AE18: =(V18/G18+((H18+J18)*M18)*2)*G18 -> 66.16 | AG18: =H18*M18*J18*G18 -> 49.92 | AH18: 50
A19: =A18 -> TORRE 1 | B19: =B18 -> FUNDAÇÃO RASA | C19: =C18 -> BLOCOS QUADRADOS RETANGULARES | E19: P20 | G19: 1 | H19: 5.4 | J19: 2.4 | M19: 1.7 | S19: =IF(M19<=1,0.6,1.2) -> 1.2 | T19: 2.25 | U19: =(H19+S19)*(T19+Y19)*(J19+S19)*G19 -> 55.836 | V19: =(H19)*(J19)*G19 -> 12.96 | W19: =+U19-AG19 -> 33.804 | X19: =(U19-W19)*1.3 -> 28.6416 | Y19: 0.1 | Z19: =V19*$Y$8 -> 1.296 | AA19: =V19*$Y$8 -> 1.296 | AD19: =(2*H19+J19*2)*M19*G19 -> 26.52 | AE19: =(V19/G19+((H19+J19)*M19)*2)*G19 -> 39.48 | AG19: =H19*M19*J19*G19 -> 22.032 | AH19: 50
A20: =A19 -> TORRE 1 | B20: =B19 -> FUNDAÇÃO RASA | C20: =C19 -> BLOCOS QUADRADOS RETANGULARES | E20: P13 | G20: 1 | H20: 6.9 | J20: 2.4 | M20: 1.9 | S20: =IF(M20<=1,0.6,1.2) -> 1.2 | T20: 1.65 | U20: =(H20+S20)*(T20+Y20)*(J20+S20)*G20 -> 51.03 | V20: =(H20)*(J20)*G20 -> 16.56 | W20: =+U20-AG20 -> 19.566 | X20: =(U20-W20)*1.3 -> 40.9032 | Y20: 0.1 | Z20: =V20*$Y$8 -> 1.656 | AA20: =V20*$Y$8 -> 1.656 | AD20: =(2*H20+J20*2)*M20*G20 -> 35.34 | AE20: =(V20/G20+((H20+J20)*M20)*2)*G20 -> 51.9 | AG20: =H20*M20*J20*G20 -> 31.464 | AH20: 50
A21: =A20 -> TORRE 1 | B21: =B20 -> FUNDAÇÃO RASA | C21: =C20 -> BLOCOS QUADRADOS RETANGULARES | E21: P19 | G21: 1 | H21: 6.9 | J21: 2.4 | M21: 1.9 | S21: =IF(M21<=1,0.6,1.2) -> 1.2 | T21: 1.65 | U21: =(H21+S21)*(T21+Y21)*(J21+S21)*G21 -> 51.03 | V21: =(H21)*(J21)*G21 -> 16.56 | W21: =+U21-AG21 -> 19.566 | X21: =(U21-W21)*1.3 -> 40.9032 | Y21: 0.1 | Z21: =V21*$Y$8 -> 1.656 | AA21: =V21*$Y$8 -> 1.656 | AD21: =(2*H21+J21*2)*M21*G21 -> 35.34 | AE21: =(V21/G21+((H21+J21)*M21)*2)*G21 -> 51.9 | AG21: =H21*M21*J21*G21 -> 31.464 | AH21: 50
A22: =A18 -> TORRE 1 | B22: =B18 -> FUNDAÇÃO RASA | C22: =C18 -> BLOCOS QUADRADOS RETANGULARES | E22: P4+P14+P15 | G22: 1 | H22: 12.9 | J22: 11.29 | M22: 2.3 | S22: =IF(M22<=1,0.6,1.2) -> 1.2 | T22: 4.13 | U22: =(H22+S22)*(T22+Y22)*(J22+S22)*G22 -> 744.94107 | V22: =(H22)*(J22)*G22 -> 145.641 | W22: =+U22-AG22 -> 409.96677 | X22: =(U22-W22)*1.3 -> 435.46659 | Y22: 0.1 | Z22: =V22*$Y$8 -> 14.5641 | AA22: =V22*$Y$8 -> 14.5641 | AD22: =(2*H22+J22*2)*M22*G22 -> 111.274 | AE22: =(V22/G22+((H22+J22)*M22)*2)*G22 -> 256.915 | AG22: =H22*M22*J22*G22 -> 334.9743 | AH22: 50
A24: =A7 -> TORRE 1 | B24: =B7 -> FUNDAÇÃO RASA | C24: BLOCOS HEXAGONAIS
A25: =A24 -> TORRE 1 | B25: =B24 -> FUNDAÇÃO RASA | C25: =C24 -> BLOCOS HEXAGONAIS | E25: P21 | G25: 1 | H25: - | I25: - | J25: - | K25: - | L25: - | M25: 1.8 | S25: 0.6 | T25: 2.38 | U25: =38.97*T25*G25 -> 92.7486 | V25: =15.84 -> 15.84 | W25: =U25-AG25 -> 64.2366 | X25: =(U25-W25)*1.3 -> 37.0656 | Y25: 0.1 | Z25: =V25*$Y$8 -> 1.584 | AA25: =V25*Y25 -> 1.584 | AD25: =15.12*M25*G25 -> 27.216 | AE25: =(V25/G25+15.12*M25)*G25 -> 43.056 | AG25: =15.84*M25*G25 -> 28.512 | AH25: 50
A26: =A25 -> TORRE 1 | B26: =B25 -> FUNDAÇÃO RASA | C26: =C25 -> BLOCOS HEXAGONAIS | E26: P39 | G26: 1 | H26: - | I26: - | J26: - | K26: - | L26: - | M26: 1.8 | S26: 0.6 | T26: 3.63 | U26: =38.97*T26*G26 -> 141.4611 | V26: 15.84 | W26: =U26-AG26 -> 112.9491 | X26: =(U26-W26)*1.3 -> 37.0656 | Y26: 0.1 | Z26: =V26*$Y$8 -> 1.584 | AA26: =V26*Y26 -> 1.584 | AD26: =15.12*M26*G26 -> 27.216 | AE26: =(V26/G26+15.12*M26)*G26 -> 43.056 | AG26: =15.84*M26*G26 -> 28.512 | AH26: 50
A28: =A7 -> TORRE 1 | B28: =B7 -> FUNDAÇÃO RASA | C28: VIGAS FUNDAÇÃO
A29: =A28 -> TORRE 1 | B29: =B28 -> FUNDAÇÃO RASA | C29: =C28 -> VIGAS FUNDAÇÃO | R29: 2 | S29: =IF(M29<=1,0.6,1.2) -> 0.6 | U29: =((H29+S29)*(M29+T29)*J29)*G29 -> 0 | V29: =(H29)*(J29)*G29 -> 0 | W29: =U29-AG29 -> 0 | X29: =(U29-W29)*1.3 -> 0 | Y29: 0.1 | Z29: =V29*$Y$8 -> 0 | AA29: =V29*$Y29 -> 0 | AD29: =((J29*M29*R29))*G29 -> 0 | AE29: =AD29+J29*H29 -> 0 | AG29: =H29*M29*J29*G29 -> 0 | AH29: 30
A30: =A29 -> TORRE 1 | B30: =B29 -> FUNDAÇÃO RASA | C30: =C29 -> VIGAS FUNDAÇÃO | R30: 2 | S30: =IF(M30<=1,0.6,1.2) -> 0.6 | U30: =((H30+S30)*(M30+T30)*J30)*G30 -> 0 | V30: =(H30)*(J30)*G30 -> 0 | W30: =U30-AG30 -> 0 | X30: =(U30-W30)*1.3 -> 0 | Y30: 0.1 | Z30: =V30*$Y$8 -> 0 | AA30: =V30*$Y30 -> 0 | AD30: =((J30*M30*R30))*G30 -> 0 | AE30: =AD30+J30*H30 -> 0 | AG30: =H30*M30*J30*G30 -> 0 | AH30: 30
A31: =A30 -> TORRE 1 | B31: =B30 -> FUNDAÇÃO RASA | C31: =C30 -> VIGAS FUNDAÇÃO | R31: 2 | S31: =IF(M31<=1,0.6,1.2) -> 0.6 | U31: =((H31+S31)*(M31+T31)*J31)*G31 -> 0 | V31: =(H31)*(J31)*G31 -> 0 | W31: =U31-AG31 -> 0 | X31: =(U31-W31)*1.3 -> 0 | Y31: 0.1 | Z31: =V31*$Y$8 -> 0 | AA31: =V31*$Y31 -> 0 | AD31: =((J31*M31*R31))*G31 -> 0 | AE31: =AD31+J31*H31 -> 0 | AG31: =H31*M31*J31*G31 -> 0 | AH31: 30
A32: =A31 -> TORRE 1 | B32: =B31 -> FUNDAÇÃO RASA | C32: =C31 -> VIGAS FUNDAÇÃO | R32: 2 | S32: =IF(M32<=1,0.6,1.2) -> 0.6 | U32: =((H32+S32)*(M32+T32)*J32)*G32 -> 0 | V32: =(H32)*(J32)*G32 -> 0 | W32: =U32-AG32 -> 0 | X32: =(U32-W32)*1.3 -> 0 | Y32: 0.1 | Z32: =V32*$Y$8 -> 0 | AA32: =V32*$Y32 -> 0 | AD32: =((J32*M32*R32))*G32 -> 0 | AE32: =AD32+J32*H32 -> 0 | AG32: =H32*M32*J32*G32 -> 0 | AH32: 30
A33: =A32 -> TORRE 1 | B33: =B32 -> FUNDAÇÃO RASA | C33: =C32 -> VIGAS FUNDAÇÃO | R33: 2 | S33: =IF(M33<=1,0.6,1.2) -> 0.6 | U33: =((H33+S33)*(M33+T33)*J33)*G33 -> 0 | V33: =(H33)*(J33)*G33 -> 0 | W33: =U33-AG33 -> 0 | X33: =(U33-W33)*1.3 -> 0 | Y33: 0.1 | Z33: =V33*$Y$8 -> 0 | AA33: =V33*$Y33 -> 0 | AD33: =((J33*M33*R33))*G33 -> 0 | AE33: =AD33+J33*H33 -> 0 | AG33: =H33*M33*J33*G33 -> 0 | AH33: 30
A34: =A33 -> TORRE 1 | B34: =B33 -> FUNDAÇÃO RASA | C34: =C33 -> VIGAS FUNDAÇÃO | R34: 2 | S34: =IF(M34<=1,0.6,1.2) -> 0.6 | U34: =((H34+S34)*(M34+T34)*J34)*G34 -> 0 | V34: =(H34)*(J34)*G34 -> 0 | W34: =U34-AG34 -> 0 | X34: =(U34-W34)*1.3 -> 0 | Y34: 0.1 | Z34: =V34*$Y$8 -> 0 | AA34: =V34*$Y34 -> 0 | AD34: =((J34*M34*R34))*G34 -> 0 | AE34: =AD34+J34*H34 -> 0 | AG34: =H34*M34*J34*G34 -> 0 | AH34: 30
A35: =A34 -> TORRE 1 | B35: =B34 -> FUNDAÇÃO RASA | C35: =C34 -> VIGAS FUNDAÇÃO | R35: 2 | S35: =IF(M35<=1,0.6,1.2) -> 0.6 | U35: =((H35+S35)*(M35+T35)*J35)*G35 -> 0 | V35: =(H35)*(J35)*G35 -> 0 | W35: =U35-AG35 -> 0 | X35: =(U35-W35)*1.3 -> 0 | Y35: 0.1 | Z35: =V35*$Y$8 -> 0 | AA35: =V35*$Y35 -> 0 | AD35: =((J35*M35*R35))*G35 -> 0 | AE35: =AD35+J35*H35 -> 0 | AG35: =H35*M35*J35*G35 -> 0 | AH35: 30
A36: =A35 -> TORRE 1 | B36: =B35 -> FUNDAÇÃO RASA | C36: =C35 -> VIGAS FUNDAÇÃO | R36: 2 | S36: =IF(M36<=1,0.6,1.2) -> 0.6 | U36: =((H36+S36)*(M36+T36)*J36)*G36 -> 0 | V36: =(H36)*(J36)*G36 -> 0 | W36: =U36-AG36 -> 0 | X36: =(U36-W36)*1.3 -> 0 | Y36: 0.1 | Z36: =V36*$Y$8 -> 0 | AA36: =V36*$Y36 -> 0 | AD36: =((J36*M36*R36))*G36 -> 0 | AE36: =AD36+J36*H36 -> 0 | AG36: =H36*M36*J36*G36 -> 0 | AH36: 30
A37: =A36 -> TORRE 1 | B37: =B36 -> FUNDAÇÃO RASA | C37: =C36 -> VIGAS FUNDAÇÃO | R37: 2 | S37: =IF(M37<=1,0.6,1.2) -> 0.6 | U37: =((H37+S37)*(M37+T37)*J37)*G37 -> 0 | V37: =(H37)*(J37)*G37 -> 0 | W37: =U37-AG37 -> 0 | X37: =(U37-W37)*1.3 -> 0 | Y37: 0.1 | Z37: =V37*$Y$8 -> 0 | AA37: =V37*$Y37 -> 0 | AD37: =((J37*M37*R37))*G37 -> 0 | AE37: =AD37+J37*H37 -> 0 | AG37: =H37*M37*J37*G37 -> 0 | AH37: 30
A38: =A37 -> TORRE 1 | B38: =B37 -> FUNDAÇÃO RASA | C38: =C37 -> VIGAS FUNDAÇÃO | R38: 2 | S38: =IF(M38<=1,0.6,1.2) -> 0.6 | U38: =((H38+S38)*(M38+T38)*J38)*G38 -> 0 | V38: =(H38)*(J38)*G38 -> 0 | W38: =U38-AG38 -> 0 | X38: =(U38-W38)*1.3 -> 0 | Y38: 0.1 | Z38: =V38*$Y$8 -> 0 | AA38: =V38*$Y38 -> 0 | AD38: =((J38*M38*R38))*G38 -> 0 | AE38: =AD38+J38*H38 -> 0 | AG38: =H38*M38*J38*G38 -> 0 | AH38: 30
A39: =A38 -> TORRE 1 | B39: =B38 -> FUNDAÇÃO RASA | C39: =C38 -> VIGAS FUNDAÇÃO | R39: 2 | S39: =IF(M39<=1,0.6,1.2) -> 0.6 | U39: =((H39+S39)*(M39+T39)*J39)*G39 -> 0 | V39: =(H39)*(J39)*G39 -> 0 | W39: =U39-AG39 -> 0 | X39: =(U39-W39)*1.3 -> 0 | Y39: 0.1 | Z39: =V39*$Y$8 -> 0 | AA39: =V39*$Y39 -> 0 | AD39: =((J39*M39*R39))*G39 -> 0 | AE39: =AD39+J39*H39 -> 0 | AG39: =H39*M39*J39*G39 -> 0 | AH39: 30
A40: =A39 -> TORRE 1 | B40: =B39 -> FUNDAÇÃO RASA | C40: =C39 -> VIGAS FUNDAÇÃO | R40: 2 | S40: =IF(M40<=1,0.6,1.2) -> 0.6 | U40: =((H40+S40)*(M40+T40)*J40)*G40 -> 0 | V40: =(H40)*(J40)*G40 -> 0 | W40: =U40-AG40 -> 0 | X40: =(U40-W40)*1.3 -> 0 | Y40: 0.1 | Z40: =V40*$Y$8 -> 0 | AA40: =V40*$Y40 -> 0 | AD40: =((J40*M40*R40))*G40 -> 0 | AE40: =AD40+J40*H40 -> 0 | AG40: =H40*M40*J40*G40 -> 0 | AH40: 30
... A49: =A48 -> TORRE 1 | B49: =B48 -> FUNDAÇÃO RASA | C49: =C48 -> VIGAS FUNDAÇÃO | R49: 2 | S49: =IF(M49<=1,0.6,1.2) -> 0.6 | U49: =((H49+S49)*(M49+T49)*J49)*G49 -> 0 | V49: =(H49)*(J49)*G49 -> 0 | W49: =U49-AG49 -> 0 | X49: =(U49-W49)*1.3 -> 0 | Y49: 0.1 | Z49: =V49*$Y$8 -> 0 | AA49: =V49*$Y49 -> 0 | AD49: =((J49*M49*R49))*G49 -> 0 | AE49: =AD49+J49*H49 -> 0 | AG49: =H49*M49*J49*G49 -> 0 | AH49: 30
A51: =A7 -> TORRE 1 | B51: =B7 -> FUNDAÇÃO RASA | C51: PILARES FUNDAÇÃO
A52: =A51 -> TORRE 1 | B52: =B51 -> FUNDAÇÃO RASA | C52: =C51 -> PILARES FUNDAÇÃO | R52: 4 | S52: =IF(M52<=1,0.6,1.2) -> 0.6 | U52: =((H52+S52)*(M52+T52)*J52)*G52 -> 0 | V52: =(H52)*(J52)*G52 -> 0 | W52: =U52-AG52 -> 0 | X52: =(U52-W52)*1.3 -> 0 | Y52: 0.1 | Z52: =V52*$Y$8 -> 0 | AA52: =V52*$Y52 -> 0 | AD52: =((J52*M52*R52))*G52 -> 0 | AE52: =AD52+J52*H52 -> 0 | AG52: =H52*M52*J52*G52 -> 0 | AH52: 30
...

Sheet Ger_Executivo_Manual
H4: PROJETO: | I4: Electra Towers | O4: REVISÃO: | P4: DATA
H5: EMPRESA: | I5: Thozen | O5: R00
A6: Unidade Construtiva | B6: Célula Construtiva | C6: Etapa | D6: Subetapa | E6: Serviço | G6: GERENCIAMENTO EXECUTIVO
A7: 0 | B7: 0 | C7: 0 | D7: 0 | E7: 0 | G7: EAP | H7: NIVEL | I7: Item | J7: Descrição | K7: Unidade | L7: Quant. | M7: Preço un | N7: Total | O7: Considerações | P7: Situação
A8: 0 | B8: 1 | C8: 0 | D8: 0 | E8: 0 | H8: CÉLULA CONSTRUTIVA | I8: 01 | J8: MOVIMENTAÇÃO DE TERRA
A9: 0 | B9: 1 | C9: 1 | D9: 0 | E9: 0 | H9: ETAPA | I9: 01.001 | J9: DEMOLIÇÕES, LIMPEZA DE TERRENO E LOCAÇÃO DE OBRA | N9: 26235.314 | O9: 1.5663183
A10: 0 | B10: 1 | C10: 1 | D10: 1 | E10: 0 | H10: SUBETAPA | I10: 01.001.001 | J10: Locação e gabarito de obra | N10: 26235.314 | O10: 1.5663183
A11: 0 | B11: 1 | C11: 1 | D11: 1 | E11: 1 | G11: MOVIMENTAÇÃO DE TERRA | H11: SERVIÇO | I11: 01.001.001.001 | J11: Locação da obra | K11: m2 | N11: 26235.314 | P11: Pendente
A12: 0 | B12: 1 | C12: 2 | D12: 0 | E12: 1 | H12: ETAPA | I12: 01.002 | J12: SERVIÇOS PRELIMINARES
A13: 0 | B13: 1 | C13: 2 | D13: 1 | E13: 0 | H13: SUBETAPA | I13: 01.002.001 | J13: Limpeza Permanente e Remoção entulho
A14: 0 | B14: 1 | C14: 2 | D14: 1 | E14: 1 | G14: MOVIMENTAÇÃO DE TERRA | H14: SERVIÇO | I14: 01.002.001.001 | J14: Limpeza da camada vegetal | K14: m2 | P14: Pendente
A15: 0 | B15: 1 | C15: 2 | D15: 1 | E15: 2 | G15: MOVIMENTAÇÃO DE TERRA | H15: SERVIÇO | I15: 01.002.001.002 | J15: Remoção de entulhos e resíduos | P15: Pendente
A16: 0 | B16: 1 | C16: 2 | D16: 2 | E16: 0 | H16: SUBETAPA | I16: 01.002.002 | J16: Mão de Obra de Canteiro
A17: 0 | B17: 1 | C17: 2 | D17: 2 | E17: 1 | G17: MOVIMENTAÇÃO DE TERRA | H17: SERVIÇO | I17: 01.002.002.001 | J17: Mão de Obra de Canteiro | K17: vb | P17: Pendente
A18: 0 | B18: 1 | C18: 3 | D18: 0 | E18: 1 | H18: ETAPA | I18: 01.003 | J18: SERVIÇOS DE TERRAPLANAGEM | N18: 271126.19 | O18: 16.186957
A19: 0 | B19: 1 | C19: 3 | D19: 1 | E19: 0 | H19: SUBETAPA | I19: 01.003.001 | J19: Mao de obra - movimentações de terra | N19: 271126.19 | O19: 16.186957
A20: 0 | B20: 1 | C20: 3 | D20: 1 | E20: 1 | G20: MOVIMENTAÇÃO DE TERRA | H20: SERVIÇO | I20: 01.003.001.001 | J20: Mão de obra movimentação de terra | K20: vb | N20: 233000 | P20: Pendente
A21: 0 | B21: 1 | C21: 4 | D21: 0 | E21: 2 | H21: ETAPA | I21: 01.004 | J21: SERVIÇO DE DRENAGEM | N21: 80000 | O21: 4.7762135
A22: 0 | B22: 1 | C22: 4 | D22: 1 | E22: 0 | H22: SUBETAPA | I22: 01.004.001 | J22: Drenagem | N22: 80000 | O22: 4.7762135
A23: 0 | B23: 1 | C23: 4 | D23: 1 | E23: 1 | G23: MOVIMENTAÇÃO DE TERRA | H23: SERVIÇO | I23: 01.004.001.001 | J23: Rebaixamento de Lençol freático | K23: vb | N23: 80000 | P23: Pendente
A24: 0 | B24: 2 | C24: 0 | D24: 1 | E24: 1 | H24: CÉLULA CONSTRUTIVA | I24: 02 | J24: CONTENÇÃO | N24: 772006.63 | O24: 46.090856
A25: 0 | B25: 2 | C25: 1 | D25: 0 | E25: 1 | H25: ETAPA | I25: 02.001 | J25: MURETA GUIA | N25: 18739.389 | O25: 1.1187915
A26: 0 | B26: 2 | C26: 1 | D26: 1 | E26: 0 | H26: SUBETAPA | I26: 02.001.001 | J26: Forma | N26: 6673.9436 | O26: 0.39845225
A27: 0 | B27: 2 | C27: 1 | D27: 1 | E27: 1 | G27: CONTENÇÃO | H27: SERVIÇO | I27: 02.001.001.001 | J27: Forma para infraestrutura em Tábuas de Madeira Serrada 2x reaproveitamento | K27: m2 | L27: 111.3136 | M27: 59.956229 | N27: 6673.9436 | P27: Pendente
A28: 0 | B28: 2 | C28: 1 | D28: 2 | E28: 0 | H28: SUBETAPA | I28: 02.001.002 | J28: Armadura | N28: 4318.7306 | O28: 0.25783974
A29: 0 | B29: 2 | C29: 1 | D29: 2 | E29: 1 | G29: CONTENÇÃO | H29: SERVIÇO | I29: 02.001.002.001 | J29: Armação aço CA-50 ø 6,3mm para Contenções (corte e dobra em obra) | K29: un | L29: 670.32 | M29: 6.0795674 | N29: 4075.2556 | P29: Pendente
A30: 0 | B30: 2 | C30: 1 | D30: 2 | E30: 2 | G30: CONTENÇÃO | H30: SERVIÇO | I30: 02.001.002.002 | J30: Armação aço CA-50 ø 12,5mm para Contenções (corte e dobra em obra) | K30: un | L30: 41.6016 | M30: 5.8525391 | N30: 243.47499 | P30: Pendente
A31: 0 | B31: 2 | C31: 1 | D31: 3 | E31: 0 | H31: SUBETAPA | I31: 02.001.003 | J31: Concreto | N31: 7746.7147 | O31: 0.46249954
A32: 0 | B32: 2 | C32: 1 | D32: 3 | E32: 1 | G32: CONTENÇÃO | H32: SERVIÇO | I32: 02.001.003.001 | J32: Concreto Usinado bombeável 50MPa para infraestrutura- incluindo serviço de bombeamento | K32: m3 | L32: 11.390452 | M32: 680.106 | N32: 7746.7147 | P32: Pendente
A33: 0 | B33: 2 | C33: 2 | D33: 0 | E33: 1 | H33: ETAPA | I33: 02.002 | J33: LAMELAS | PAREDE DIAFRAGMA | N33: 331865.23 | O33: 19.81324
A34: 0 | B34: 2 | C34: 2 | D34: 1 | E34: 0 | H34: SUBETAPA | I34: 02.002.001 | J34: Armadura | N34: 155967.97 | O34: 9.3117038
A35: 0 | B35: 2 | C35: 2 | D35: 1 | E35: 1 | G35: CONTENÇÃO | H35: SERVIÇO | I35: 02.002.001.001 | J35: Armação aço CA-50 ø 6,3mm para Contenções (corte e dobra em Indústria) | K35: un | L35: 2282 | M35: 8.964145 | N35: 20456.179 | P35: Pendente
A36: 0 | B36: 2 | C36: 2 | D36: 1 | E36: 2 | G36: CONTENÇÃO | H36: SERVIÇO | I36: 02.002.001.002 | J36: Armação aço CA-50 ø 8,0mm para Contenções (corte e dobra em Indústria) | K36: un | L36: 77 | M36: 8.964145 | N36: 690.23916 | P36: Pendente
A37: 0 | B37: 2 | C37: 2 | D37: 1 | E37: 3 | G37: CONTENÇÃO | H37: SERVIÇO | I37: 02.002.001.003 | J37: Armação aço CA-50 ø 12,5mm para Contenções (corte e dobra em Indústria) | K37: un | L37: 3884 | M37: 8.484145 | N37: 32952.419 | P37: Pendente
A38: 0 | B38: 2 | C38: 2 | D38: 1 | E38: 4 | G38: CONTENÇÃO | H38: SERVIÇO | I38: 02.002.001.004 | J38: Armação aço CA-50 ø 25,0mm para Contenções (corte e dobra em Indústria) | K38: un | L38: 12007 | M38: 8.484145 | N38: 101869.13 | P38: Pendente
A39: 0 | B39: 2 | C39: 2 | D39: 2 | E39: 0 | H39: SUBETAPA | I39: 02.002.002 | J39: Concreto | N39: 175897.26 | O39: 10.501536
A40: 0 | B40: 2 | C40: 2 | D40: 2 | E40: 1 | G40: CONTENÇÃO | H40: SERVIÇO | I40: 02.002.002.001 | J40: Concreto Usinado bombeável 50MPa com Penetron para infraestrutura- incluindo serviço de bombeamento | K40: m3 | L40: 210 | M40: 837.606 | N40: 175897.26 | P40: Pendente
A41: 0 | B41: 2 | C41: 3 | D41: 0 | E41: 1 | H41: ETAPA | I41: 02.003 | J41: VIGAS COROAMENTO | N41: 37645.991 | O41: 2.2475661
A42: 0 | B42: 2 | C42: 3 | D42: 1 | E42: 0 | H42: SUBETAPA | I42: 02.003.001 | J42: Forma | N42: 2482.1879 | O42: 0.14819324
A43: 0 | B43: 2 | C43: 3 | D43: 1 | E43: 1 | G43: CONTENÇÃO | H43: SERVIÇO | I43: 02.003.001.001 | J43: Forma para infraestrutura em Tábuas de Madeira Serrada 2x reaproveitamento | K43: m2 | L43: 41.4 | M43: 59.956229 | N43: 2482.1879 | P43: Pendente
...

Sheet Orçamento
A1: DADOS
A2: Titulo | B2: ORÇAMENTO
A3: Obra | B3: ELECTRA TOWERS
A4: Cliente | B4: THOZEN
A5: Cidade | B5: Porto Belo
A6: Endereço
A7: Descrição
A8: UF | B8: SC
A10: RESUMO
A11: Tipo | C11: Preço | E11: Observação
A12: Total | C12: 21718825 | E12: Geral da edificação
A13: Material | C13: 15467433
A14: Execução | C14: 6251392.4
A16: TABELA DE ORÇAMENTO
A17: Item | B17: Referência | C17: Tipo | D17: Código | E17: Descrição | F17: Unid. | G17: Quantidade | H17: Custo unitário | I17: Preço total | J17: % | K17: Observação
A19: 1. | E19: 03. PAREDES E PAINÉIS | I19: 1964071 | J19: 0.090431735
A20: 1.1. | E20: ARQ_Embasamento | I20: 228660.08 | J20: 0.010528198
A21: 1.1.1. | E21: 03.001. Alvenaria de vedação com blocos cerâmicos | I21: 133087.99 | J21: 0.006127771
A22: 1.1.1.1 | E22: BLOCO CERAMICO, 0,05 (Parede padrão) | F22: m² | G22: 35.77 | H22: 0 | I22: 0
A23: 1.1.1.2 | E23: BLOCO CERAMICO, 0,09 (Parede padrão) | F23: m² | G23: 171.98 | H23: 0 | I23: 0
A24: 1.1.1.3 | B24: Thozen - Electra | C24: COMPOSICAO | D24: 4825 | E24: Alvenaria de vedação de blocos cerâmicos furados na horizontal de 11,5x19x19cm (espessura 11,5cm) com argamassa industrializada de assentamento | F24: m2 | G24: 1262.88 | H24: 25.096 | I24: 31693.236 | J24: 0.0014592519
A25: 1.1.1.4 | B25: Thozen - Electra | C25: COMPOSICAO | D25: 4826 | E25: Alvenaria de vedação de blocos cerâmicos furados na horizontal de 14x19x19cm (espessura 14cm) com argamassa industrializada de assentamento | F25: m2 | G25: 1610.87 | H25: 40.7664 | I25: 65669.371 | J25: 0.0030236152
A26: 1.1.1.5 | B26: Thozen - Electra | C26: COMPOSICAO | D26: 90472 | E26: Alvenaria de vedação de blocos cerâmicos furados na horizontal de 19x19x19cm (espessura 19cm) com argamassa industrializada de assentamento | F26: m2 | G26: 631.36 | H26: 56.5848 | I26: 35725.379 | J26: 0.0016449039
A27: 1.1.2. | E27: 03.002. Alvenaria de vedação com blocos de concreto | I27: 0
A28: 1.1.2.1 | E28: BLOCO CONCRETO, 0,05 (Parede padrão) | F28: m² | G28: 1.49 | H28: 0 | I28: 0
A29: 1.1.2.2 | E29: BLOCO ANTI CHAMAS, 0,125 (Parede padrão) | F29: m² | G29: 252.44 | H29: 0 | I29: 0
A30: 1.1.2.3 | E30: BLOCO ANTI CHAMAS, 0,15 (Parede padrão) | F30: m² | G30: 774.4 | H30: 0 | I30: 0
A31: 1.1.3. | E31: 03.003. Serviços complementares para alvenaria de vedação | I31: 95572.097 | J31: 0.0044004266
A32: 1.1.3.1 | B32: Thozen - Electra | C32: COMPOSICAO | D32: 4831 | E32: Verga/contraverga de concreto, moldada in loco | F32: m | G32: 104.16 | H32: 43.712512 | I32: 4553.0952 | J32: 0.00020963819
A33: 1.1.3.2 | B33: Thozen - Electra | C33: COMPOSICAO | D33: 4828 | E33: Encunhamento de alvenaria de vedação com argamassa expansiva | F33: m | G33: 18470.23 | H33: 3.633798 | I33: 67117.085 | J33: 0.0030902724
A34: 1.1.3.3 | B34: Thozen - Electra | C34: COMPOSICAO | D34: 4829 | E34: Tela soldada para ligação alvenaria/estrutura | F34: m² | G34: 2370.59 | H34: 1.85 | I34: 4385.5915 | J34: 0.00020192582
A35: 1.1.3.4 | B35: Thozen - Electra | C35: COMPOSICAO | D35: 4831 | E35: Verga/contraverga de concreto, moldada in loco | F35: m | G35: 446.47 | H35: 43.712512 | I35: 19516.325 | J35: 0.00089859028
A36: 1.1.4. | E36: 03.005. Mão de obra | I36: 0
A37: 1.1.4.1 | E37: Mão de obra alvenaria cerâmica | F37: m² | G37: 4045.19 | H37: 0 | I37: 0
A38: 1.1.4.2 | E38: Mão de obra blocos sílico calcário (Parede padrão) | F38: m² | G38: 1028.33 | H38: 0 | I38: 0
A39: 1.1.5. | E39: Alvenaria de vedação com tijolo refratário | I39: 0
A40: 1.1.5.1 | E40: TIJOLO REFRATARIO, 0,016 (Parede padrão) | F40: m² | G40: 14.56 | H40: 0 | I40: 0
A41: 1.2. | E41: ARQ_Impermeab | I41: 45754.495 | J41: 0.0021066745
A42: 1.2.1. | E42: 03.003. Serviços complementares para alvenaria de vedação | I42: 45754.495 | J42: 0.0021066745
A43: 1.2.1.1 | B43: Thozen - Electra | C43: COMPOSICAO | D43: 4828 | E43: Encunhamento de alvenaria de vedação com argamassa expansiva | F43: m | G43: 12591.37 | H43: 3.633798 | I43: 45754.495 | J43: 0.0021066745
...

Sheet Composições
A1: DADOS
A2: Titulo | B2: ORÇAMENTO
A3: Obra | B3: ELECTRA TOWERS
A4: Cliente | B4: THOZEN
A5: Cidade | B5: Porto Belo
A6: Endereço
A7: Descrição
A8: UF | B8: SC
A11: TABELA DE COMPOSIÇÕES UTILIZADAS
A12: Código | B12: Referência | C12: Tipo | D12: Tipo | E12: Descrição | F12: Unid. | G12: Multiplicador | H12: Preço | J12: Ref. Tabela | K12: Ref. Código | L12: Justificativa | M12: Grupo de Serviço | N12: Serviço
H13: Unitário | I13: Total
A14: 4825 | B14: Thozen - Electra | D14: Original | E14: Alvenaria de vedação de blocos cerâmicos furados na horizontal de 11,5x19x19cm (espessura 11,5cm) com argamassa industrializada de assentamento | F14: m2 | I14: 25.096 | N14: BLOCOS | O14: =A14&B14&C14 -> 4825Thozen - Electra
A15: 194 | B15: Thozen - Electra | C15: INSUMO | D15: Original | E15: ARGAMASSA ESTABILIZADA PARA ASSENTAMENTO | F15: m3 | G15: 0.0125 | H15: 480 | I15: 6
A16: 228 | B16: Thozen - Electra | C16: INSUMO | D16: Original | E16: BLOCO CERÂMICO 11,5X19X19CM | F16: un | G16: 17.36 | H16: 1.1 | I16: 19.096
A17: 4826 | B17: Thozen - Electra | D17: Original | E17: Alvenaria de vedação de blocos cerâmicos furados na horizontal de 14x19x19cm (espessura 14cm) com argamassa industrializada de assentamento | F17: m2 | I17: 40.7664 | N17: BLOCOS | O17: =A17&B17&C17 -> 4826Thozen - Electra
A18: 194 | B18: Thozen - Electra | C18: INSUMO | D18: Original | E18: ARGAMASSA ESTABILIZADA PARA ASSENTAMENTO | F18: m3 | G18: 0.022 | H18: 480 | I18: 10.56
A19: 232 | B19: Thozen - Electra | C19: INSUMO | D19: Original | E19: BLOCO CERÂMICO 14X19X19CM | F19: un | G19: 17.36 | H19: 1.74 | I19: 30.2064
A20: 90472 | B20: Thozen - Electra | D20: Original | E20: Alvenaria de vedação de blocos cerâmicos furados na horizontal de 19x19x19cm (espessura 19cm) com argamassa industrializada de assentamento | F20: m2 | I20: 56.5848 | N20: BLOCOS | O20: =A20&B20&C20 -> 90472Thozen - Electra
A21: 194 | B21: Thozen - Electra | C21: INSUMO | D21: Original | E21: ARGAMASSA ESTABILIZADA PARA ASSENTAMENTO | F21: m3 | G21: 0.03 | H21: 480 | I21: 14.4
A22: 48433 | B22: Thozen - Electra | C22: INSUMO | D22: Original | E22: BLOCO CERÂMICO 19X19X19CM | F22: un | G22: 17.36 | H22: 2.43 | I22: 42.1848
A23: 4831 | B23: Thozen - Electra | D23: Original | E23: Verga/contraverga de concreto, moldada in loco | F23: m | I23: 43.712512 | O23: =A23&B23&C23 -> 4831Thozen - Electra
A24: 759 | B24: Thozen - Electra | C24: INSUMO | D24: Original | E24: CONCRETO USINADO FCK 20 MPA, SLUMP 14+/-2 | F24: m3 | G24: 0.0264 | H24: 450 | I24: 11.88
A25: 4800 | B25: Thozen - Electra | C25: INSUMO | D25: Original | E25: DESMOLDANTE DE FORMAS PARA CONCRETO | F25: l | G25: 0.007 | H25: 6.45 | I25: 0.04515
A26: 1412 | B26: Thozen - Electra | C26: INSUMO | D26: Original | E26: ESPAÇADOR PLÁSTICO | F26: un | G26: 6 | H26: 0.15 | I26: 0.9
A27: 2324 | B27: Thozen - Electra | C27: INSUMO | D27: Original | E27: PONTALETE 7,5X7,5 CM PINUS | F27: m3 | G27: 0.0012 | H27: 1310 | I27: 1.572
A28: 2362 | B28: Thozen - Electra | C28: INSUMO | D28: Original | E28: PREGO POLIDO COM CABEÇA 17X21 | F28: kg | G28: 0.0512 | H28: 10.91 | I28: 0.558592
A29: 2546 | B29: Thozen - Electra | C29: INSUMO | D29: Original | E29: SARRAFO 2,5X7,5 CM PINUS | F29: m3 | G29: 0.003171 | H29: 1300 | I29: 4.1223
A30: 2611 | B30: Thozen - Electra | C30: INSUMO | D30: Original | E30: TÁBUA 1"X12" 2,5X30CM PINUS | F30: m3 | G30: 0.011676 | H30: 1800 | I30: 21.0168
A31: 32 | B31: Thozen - Electra | C31: INSUMO | D31: Original | E31: AÇO CA-50 DIÂMETRO 6,30 MM | F31: kg | G31: 0.5243 | H31: 6.9 | I31: 3.61767
A32: 4828 | B32: Thozen - Electra | D32: Original | E32: Encunhamento de alvenaria de vedação com argamassa expansiva | F32: m | I32: 3.633798 | N32: ENCUNHAMENTO | O32: =A32&B32&C32 -> 4828Thozen - Electra
A33: 48435 | B33: Thozen - Electra | C33: INSUMO | D33: Original | E33: ARGAMASSA EXPANSIVA PARA ENCUNHAMENTO | F33: Kg | G33: 0.2154 | H33: 16.87 | I33: 3.633798
A34: 4829 | B34: Thozen - Electra | D34: Original | E34: Tela soldada para ligação alvenaria/estrutura | F34: m² | I34: 1.85 | O34: =A34&B34&C34 -> 4829Thozen - Electra
A35: 718 | B35: Thozen - Electra | C35: INSUMO | D35: Original | E35: CARTUCHO 22 - CARGA LEVE PARA FINCA PINO E POLVORA | F35: un | G35: 1 | H35: 0.3 | I35: 0.3
A36: 2260 | B36: Thozen - Electra | C36: INSUMO | D36: Original | E36: PINO LISO EM AÇO GALVANIZADO 1/2 X 22MM COM ARRUELA | F36: un | G36: 1 | H36: 0.3 | I36: 0.3
A37: 2901 | B37: Thozen - Electra | C37: INSUMO | D37: Original | E37: TELA DE ACO SOLDADA, FIO 1,24MM, MALHA 15X15MM | F37: m2 | G37: 0.5 | H37: 2.5 | I37: 1.25
A38: 4842 | B38: Thozen - Electra | D38: Original | E38: Impermeabilização com argamassa polimérica, 3 demãos | F38: m2 | I38: 36.225 | O38: =A38&B38&C38 -> 4842Thozen - Electra
A39: 202 | B39: Thozen - Electra | C39: INSUMO | D39: Original | E39: ARGAMASSA POLIMÉRICA IMPERMEABILIZANTE | F39: kg | G39: 3.15 | H39: 11.5 | I39: 36.225
A40: 90541 | B40: Thozen - Electra | D40: Original | E40: Chapisco adesivo aplicado em concreto, com desempenadeira dentada | F40: m2 | I40: 6.459 | N40: CHAPISCO | O40: =A40&B40&C40 -> 90541Thozen - Electra
A41: 197 | B41: Thozen - Electra | C41: INSUMO | D41: Original | E41: ARGAMASSA ESTABILIZADA PARA REBOCO | F41: m3 | G41: 0.0033 | H41: 480 | I41: 1.584
A42: 48481 | B42: Thozen - Electra | C42: INSUMO | D42: Original | E42: ADITIVO ADESIVO LÍQUIDO PARA ARGAMASSA | F42: L | G42: 0.625 | H42: 7.8 | I42: 4.875
...

Sheet Insumos (2)
A1: DADOS
A2: Titulo | B2: Tabela de insumos utilizados no projeto
A3: Obra | B3: ELECTRA TOWERS
A4: Cliente | B4: THOZEN
A5: Cidade | B5: Porto Belo
A6: Endereço
A7: Descrição
A8: UF | B8: SC
A11: INSUMOS UTILIZADOS
A12: Código | B12: Tabela | C12: Tipo | D12: Descrição | E12: Unid. | F12: Preço | G12: Origem custo | H12: Justificativa
A14: 194 | B14: Thozen - Electra | C14: Material | D14: ARGAMASSA ESTABILIZADA PARA ASSENTAMENTO | E14: m3 | F14: 480 | I14: =A14&B14 -> 194Thozen - Electra
A15: 228 | B15: Thozen - Electra | C15: Material | D15: BLOCO CERÂMICO 11,5X19X19CM | E15: un | F15: 1.1 | I15: =A15&B15 -> 228Thozen - Electra
A16: 232 | B16: Thozen - Electra | C16: Material | D16: BLOCO CERÂMICO 14X19X19CM | E16: un | F16: 1.74 | I16: =A16&B16 -> 232Thozen - Electra
A17: 48433 | B17: Thozen - Electra | C17: Material | D17: BLOCO CERÂMICO 19X19X19CM | E17: un | F17: 2.43 | I17: =A17&B17 -> 48433Thozen - Electra
A18: 759 | B18: Thozen - Electra | C18: Material | D18: CONCRETO USINADO FCK 20 MPA, SLUMP 14+/-2 | E18: m3 | F18: 450 | I18: =A18&B18 -> 759Thozen - Electra
A19: 4800 | B19: Thozen - Electra | C19: Material | D19: DESMOLDANTE DE FORMAS PARA CONCRETO | E19: l | F19: 6.45 | I19: =A19&B19 -> 4800Thozen - Electra
A20: 1412 | B20: Thozen - Electra | C20: Material | D20: ESPAÇADOR PLÁSTICO | E20: un | F20: 0.15 | I20: =A20&B20 -> 1412Thozen - Electra
A21: 2324 | B21: Thozen - Electra | C21: Material | D21: PONTALETE 7,5X7,5 CM PINUS | E21: m3 | F21: 1310 | I21: =A21&B21 -> 2324Thozen - Electra
A22: 2362 | B22: Thozen - Electra | C22: Material | D22: PREGO POLIDO COM CABEÇA 17X21 | E22: kg | F22: 10.91 | I22: =A22&B22 -> 2362Thozen - Electra
A23: 2546 | B23: Thozen - Electra | C23: Material | D23: SARRAFO 2,5X7,5 CM PINUS | E23: m3 | F23: 1300 | I23: =A23&B23 -> 2546Thozen - Electra
A24: 2611 | B24: Thozen - Electra | C24: Material | D24: TÁBUA 1"X12" 2,5X30CM PINUS | E24: m3 | F24: 1800 | I24: =A24&B24 -> 2611Thozen - Electra
A25: 32 | B25: Thozen - Electra | C25: Material | D25: AÇO CA-50 DIÂMETRO 6,30 MM | E25: kg | F25: 6.9 | G25: GERDAU | I25: =A25&B25 -> 32Thozen - Electra
A26: 48435 | B26: Thozen - Electra | C26: Material | D26: ARGAMASSA EXPANSIVA PARA ENCUNHAMENTO | E26: Kg | F26: 16.87 | I26: =A26&B26 -> 48435Thozen - Electra
A27: 718 | B27: Thozen - Electra | C27: Material | D27: CARTUCHO 22 - CARGA LEVE PARA FINCA PINO E POLVORA | E27: un | F27: 0.3 | I27: =A27&B27 -> 718Thozen - Electra
A28: 2260 | B28: Thozen - Electra | C28: Material | D28: PINO LISO EM AÇO GALVANIZADO 1/2 X 22MM COM ARRUELA | E28: un | F28: 0.3 | I28: =A28&B28 -> 2260Thozen - Electra
A29: 2901 | B29: Thozen - Electra | C29: Material | D29: TELA DE ACO SOLDADA, FIO 1,24MM, MALHA 15X15MM | E29: m2 | F29: 2.5 | I29: =A29&B29 -> 2901Thozen - Electra
A30: 202 | B30: Thozen - Electra | C30: Material | D30: ARGAMASSA POLIMÉRICA IMPERMEABILIZANTE | E30: kg | F30: 11.5 | I30: =A30&B30 -> 202Thozen - Electra
A31: 197 | B31: Thozen - Electra | C31: Material | D31: ARGAMASSA ESTABILIZADA PARA REBOCO | E31: m3 | F31: 480 | I31: =A31&B31 -> 197Thozen - Electra
A32: 48481 | B32: Thozen - Electra | C32: Material | D32: ADITIVO ADESIVO LÍQUIDO PARA ARGAMASSA | E32: L | F32: 7.8 | I32: =A32&B32 -> 48481Thozen - Electra
A33: 48373 | B33: Thozen - Electra | C33: Material | D33: CHAPISCO COLANTE 20KG | E33: Kg | F33: 1.31 | I33: =A33&B33 -> 48373Thozen - Electra
A34: 2154 | B34: Thozen - Electra | C34: Mao_obra | D34: MÃO DE OBRA PARA EXECUÇÃO DE CHAPISCO E REBOCO INTERNO EM PAREDES | E34: m2 | F34: 35 | I34: =A34&B34 -> 2154Thozen - Electra
A35: 193 | B35: Thozen - Electra | C35: Material | D35: ARGAMASSA COLANTE AC III | E35: kg | F35: 2.345 | I35: =A35&B35 -> 193Thozen - Electra
A36: 4881 | B36: Thozen - Electra | C36: Material | D36: ESPAÇADOR PARA REVESTIMENTO CERÂMICO TIPO CRUZETA 5 MM | E36: un | F36: 0.2 | I36: =A36&B36 -> 4881Thozen - Electra
A37: 4880 | B37: Thozen - Electra | C37: Material | D37: REJUNTE FLEXÍVEL | E37: m2 | F37: 2.0643 | I37: =A37&B37 -> 4880Thozen - Electra
... A61: 2552 | B61: Thozen - Electra | C61: Material | D61: SELADOR ACRÍLICO | E61: l | F61: 9.44 | I61: =A61&B61 -> 2552Thozen - Electra

Sheet PROJETOS
B1: GESTÃO DOS PROJETOS | J1: LEGENDA
A2: Obra | B2: Electra Towers (Rubens Alves) | J2: NÃO SE APLICA
A3: Empresa | B3: Thozen Empreendimentos | J3: PENDENTE
A4: Revisão | B4: R01 | J4: RECEBIDO
B5: PAVIMENTO | C5: DISCIPLINA | D5: PROJETOS | E5: CAMINHO | F5: STATUS | G5: OBSERVAÇÕES | J5: REVISADO
B7: ESTRUTURA
B8: TERRAPLENAGEM | C8: INFRAESTRUTURA | F8: NÃO SE APLICA
B9: MOVIMENTAÇÃO DE TERRA | C9: INFRAESTRUTURA | F9: PENDENTE
B10: FUNDAÇÃO PROFUNDA | C10: INFRAESTRUTURA | D10: 1203 - PREFORMAS - R20.DWG | E10: 01 ESTRUTURA/DWG | F10: RECEBIDO | G10: DWG Pré-formas Rev.20
B11: FUNDAÇÃO RASA | C11: INFRAESTRUTURA | D11: 1203 - THOZEN - RUBENS ALVES - BLOCOS+RAMPAS DE ACESSO - R26.ifc | E11: 01 ESTRUTURA/IFC | F11: RECEBIDO | G11: IFC Blocos + Rampas de Acesso Rev.26
B12: CONTENÇÃO | C12: INFRAESTRUTURA | F12: NÃO SE APLICA
B13: ÁREA – 1º PAVTO. (TÉRREO) | C13: SUPRAESTRUTURA | F13: RECEBIDO | G13: Coberto pelo IFC estrutural completo
B14: ÁREA – MEZANINO DO 1º PAVTO. | C14: SUPRAESTRUTURA | F14: RECEBIDO | G14: Coberto pelo IFC estrutural completo
B15: ÁREA – 2º PAVIMENTO | C15: SUPRAESTRUTURA | F15: RECEBIDO | G15: Coberto pelo IFC estrutural completo
B16: ÁREA – MEZANINO DO 2º PAVTO. | C16: SUPRAESTRUTURA | F16: RECEBIDO | G16: Coberto pelo IFC estrutural completo
B17: ÁREA – 3º PAVIMENTO | C17: SUPRAESTRUTURA | F17: RECEBIDO | G17: Coberto pelo IFC estrutural completo
B18: ÁREA – MEZANINO DO 3º PAVTO. | C18: SUPRAESTRUTURA | F18: RECEBIDO | G18: Coberto pelo IFC estrutural completo
B19: ÁREA – 4º PAVIMENTO GARAGEM/LAZER | C19: SUPRAESTRUTURA | F19: RECEBIDO | G19: Coberto pelo IFC estrutural completo
B20: ÁREA – 5º PAVIMENTO LAZER | C20: SUPRAESTRUTURA | F20: RECEBIDO | G20: Coberto pelo IFC estrutural completo
B21: ÁREA – 6º PAVIMENTO TIPO - DIFERENCIADO | C21: SUPRAESTRUTURA | F21: RECEBIDO | G21: Coberto pelo IFC estrutural completo
B22: ÁREA – 7º AO 14° PAVIMENTO TIPO - X8 | C22: SUPRAESTRUTURA | F22: RECEBIDO | G22: Coberto pelo IFC estrutural completo
B23: ÁREA – 15º AO 35° PAVIMENTO TIPO - X21 | C23: SUPRAESTRUTURA | F23: RECEBIDO | G23: Coberto pelo IFC estrutural completo
B24: ARQUITETURA
B25: TERRAPLENAGEM | C25: ARQUITETURA | F25: NÃO SE APLICA
B26: MOVIMENTAÇÃO DE TERRA | C26: ARQUITETURA | F26: NÃO SE APLICA
B27: FUNDAÇÃO PROFUNDA | C27: ARQUITETURA | F27: NÃO SE APLICA
B28: FUNDAÇÃO RASA | C28: ARQUITETURA | F28: NÃO SE APLICA
B29: CONTENÇÃO | C29: ARQUITETURA | F29: NÃO SE APLICA
B30: TÉRREO 01 | C30: ARQUITETURA | D30: RA_ARQ_EXE_01_TÉRREO_R02.dwg | E30: 02 ARQUITETURA/DWG | F30: RECEBIDO | G30: DWG Executivo Rev.02
B31: TÉRREO 02 | C31: ARQUITETURA | D31: RA_ARQ_EXE_10_CORTE1_R02.dwg + RA_ARQ_EXE_11_CORTE2_R02.dwg | E31: 02 ARQUITETURA/DWG | F31: RECEBIDO | G31: Cortes 1 e 2, Rev.02
B32: GARAGEM 01 | C32: ARQUITETURA | D32: RA_ARQ_EXE_02_G1_R02.dwg | E32: 02 ARQUITETURA/DWG | F32: RECEBIDO | G32: DWG Executivo Rev.02
B33: GARAGEM 02 | C33: ARQUITETURA | D33: RA_ARQ_EXE_03_G2_R02.dwg | E33: 02 ARQUITETURA/DWG | F33: RECEBIDO | G33: DWG Executivo Rev.02
B34: GARAGEM 03 | C34: ARQUITETURA | D34: RA_ARQ_EXE_04_G3_R02.dwg | E34: 02 ARQUITETURA/DWG | F34: RECEBIDO | G34: DWG Executivo Rev.02
B35: GARAGEM 04 | C35: ARQUITETURA | D35: RA_ARQ_EXE_05_G4_R02.dwg | E35: 02 ARQUITETURA/DWG | F35: RECEBIDO | G35: DWG Executivo Rev.02
B36: LAZER 01 | C36: ARQUITETURA | D36: RA_ARQ_EXE_06_G5_R02.dwg | E36: 02 ARQUITETURA/DWG | F36: RECEBIDO | G36: DWG Executivo Rev.02
B37: LAZER 02 | C37: ARQUITETURA | D37: RA_ARQ_EXE_07_LAZER_R02.dwg | E37: 02 ARQUITETURA/DWG | F37: RECEBIDO | G37: DWG Executivo Rev.02
B38: TIPO DIFERENCIADO 01 | C38: ARQUITETURA | D38: RA_ARQ_EXE_MODELAGEM EMBASAMENTO + COBERTURA_R08.ifc | E38: 02 ARQUITETURA/IFC | F38: RECEBIDO | G38: IFC Embasamento + Cobertura Rev.08
B39: TIPO DIFERENCIADO 02 | C39: ARQUITETURA | D39: RA_ARQ_EXE_MODELAGEM TIPO_R07.ifc | E39: 02 ARQUITETURA/IFC | F39: RECEBIDO | G39: IFC Tipo Rev.07
B40: TIPO (30x) | C40: ARQUITETURA | D40: RA_ARQ_EXE_08_TIPOS_R02.dwg | E40: 02 ARQUITETURA/DWG | F40: RECEBIDO | G40: DWG Executivo Rev.02
B41: DUPLEX INFERIOR (3x) | C41: ARQUITETURA | F41: NÃO SE APLICA
...

Sheet Ger_Tec e Adm
A4: PROJETO: | C4: Electra Towers | I4: REVISÃO: | J4: DATA
A5: EMPRESA: | C5: Thozen | I5: R00
A6: GERENCIAMENTO EXECUTIVO
A7: Atalho | B7: NIVEL | C7: Item | D7: Descrição | E7: Unidade | F7: Quant. | G7: Preço un | H7: Total | I7: Considerações | J7: Situação
B8: CÉLULA CONSTRUTIVA | C8: 01 | D8: SERVIÇOS TÉCNICOS | H8: =H9+H57 -> 3668982.5
B9: ETAPA | C9: 01.001 | D9: ESTUDOS, PROJETOS E CONSULTORIAS | H9: =H10+H20+H41+H46 -> 2273047.4 | J9: -
B10: SUBETAPA | C10: 01.001.001 | D10: Estudos | H10: =H11+H12+H13+H14+H15+H16+H17+H18+H19 -> 260925.31
B11: SERVIÇO | C11: 01.001.001.001 | D11: Memorial descritivo | E11: vb | F11: 1 | G11: 18386.35 | H11: =G11*F11 -> 18386.35 | I11: Estimado | J11: Lançado ERP
B12: SERVIÇO | C12: 01.001.001.002 | D12: Levantamento topográfico | E12: vb | F12: 1 | G12: 3000 | H12: =G12*F12 -> 3000 | I12: Recebido | J12: Lançado ERP
B13: SERVIÇO | C13: 01.001.001.003 | D13: Estudo geológico | E13: vb | F13: 1 | G13: 26930.408 | H13: =G13*F13 -> 26930.408 | I13: Estimado | J13: Lançado ERP
B14: SERVIÇO | C14: 01.001.001.004 | D14: Estudo ambiental | E14: vb | F14: 1 | G14: 4500 | H14: =G14*F14 -> 4500 | I14: Recebido | J14: Lançado ERP
B15: SERVIÇO | C15: 01.001.001.005 | D15: Sondagem do terreno | E15: vb | F15: 1 | G15: 7947.99 | H15: =G15*F15 -> 7947.99 | I15: Recebido | J15: Lançado ERP
B16: SERVIÇO | C16: 01.001.001.006 | D16: Projeto de canteiro | E16: vb | F16: 1 | G16: 11160.563 | H16: =G16*F16 -> 11160.563 | I16: Estimado | J16: Lançado ERP
B17: SERVIÇO | C17: 01.001.001.007 | D17: EFEG - Teste de Carga | E17: vb | F17: 1 | G17: 29000 | H17: =G17*F17 -> 29000 | I17: Recebido | J17: Lançado ERP
B18: SERVIÇO | C18: 01.001.001.008 | D18: Solugeot - Teste de Carga | E18: vb | F18: 1 | G18: 140000 | H18: =G18*F18 -> 140000 | I18: Recebido | J18: Lançado ERP
B19: SERVIÇO | C19: 01.001.001.009 | D19: Concreto - Teste de Carga | E19: vb | F19: 1 | G19: 20000 | H19: =G19*F19 -> 20000 | I19: Recebido | J19: Lançado ERP
B20: SUBETAPA | C20: 01.001.002 | D20: Projetos | H20: =H21+H22+H23+H24+H25+H26+H27+H28+H29+H30+H31+H32+H33+H34+H35+H36+H37+H38+H39+H40 -> 1205079.2
B21: SERVIÇO | C21: 01.001.002.001 | D21: Legalização de incorporação | E21: vb | F21: 1 | G21: 67351.993 | H21: =G21*F21 -> 67351.993 | I21: Estimado | J21: Lançado ERP
B22: SERVIÇO | C22: 01.001.002.002 | D22: Projeto arquitetônico legal | E22: vb | F22: 1 | G22: 237000 | H22: =G22*F22 -> 237000 | I22: Recebido - Considerado junto desse projeto os valores de projeto arquitetônico legal + hidráulico + preventivo + elétrico + arquitetônico | J22: Lançado ERP
B23: SERVIÇO | C23: 01.001.002.003 | D23: Projeto Arquitetônico interiores | E23: vb | F23: 1 | G23: 86773.378 | H23: =G23*F23 -> 86773.378 | I23: Estimado | J23: Lançado ERP
B24: SERVIÇO | C24: 01.001.002.004 | D24: Projeto arquitetônico de fachada | E24: vb | F24: 1 | G24: 58250 | H24: =G24*F24 -> 58250 | I24: Recebido | J24: Lançado ERP
B25: SERVIÇO | C25: 01.001.002.005 | D25: Projeto técnico de fachada | E25: vb | F25: 1 | G25: 75145.12 | H25: =G25*F25 -> 75145.12 | I25: Estimado | J25: Lançado ERP
B26: SERVIÇO | C26: 01.001.002.006 | D26: Projeto de terraplanagem | E26: vb | F26: 1 | G26: 6962.4358 | H26: =G26*F26 -> 6962.4358 | I26: Estimado | J26: Lançado ERP
B27: SERVIÇO | C27: 01.001.002.007 | D27: Projeto estrutural | E27: vb | F27: 1 | G27: 70000 | H27: =G27*F27 -> 70000 | I27: Recebido - Considerado junto desse projeto os valores de projeto estrutural e fundação | J27: Lançado ERP
B28: SERVIÇO | C28: 01.001.002.008 | D28: Projeto de automação | E28: vb | F28: 1 | G28: 96720.281 | H28: =G28*F28 -> 96720.281 | I28: Estimado | J28: Lançado ERP
B29: SERVIÇO | C29: 01.001.002.009 | D29: Projeto de irrigação | E29: vb | F29: 1 | G29: 39550.22 | H29: =G29*F29 -> 39550.22 | I29: Estimado | J29: Lançado ERP
B30: SERVIÇO | C30: 01.001.002.010 | D30: Projeto preventivo (PPCI - Plano de Prevenção e Proteção Contra Incêndios) e Gás | E30: vb | F30: 1 | G30: 27354.018 | H30: =G30*F30 -> 27354.018 | I30: Estimado - Considerado somente o projeto de gás, pois o ppci, conforme informado no formulario, esta nicluso no arquitetônico | J30: Lançado ERP
B31: SERVIÇO | C31: 01.001.002.011 | D31: Projeto de climatização/exaustão | E31: vb | F31: 1 | G31: 91124.893 | H31: =G31*F31 -> 91124.893 | I31: Estimado | J31: Lançado ERP
B32: SERVIÇO | C32: 01.001.002.012 | D32: Projeto de Segurança | E32: vb | F32: 1 | G32: 24827.001 | H32: =G32*F32 -> 24827.001 | I32: Estimado | J32: Lançado ERP
... B40: SERVIÇO | C40: 01.001.002.020 | D40: Projeto de Paisagismo | E40: vb | F40: 1 | G40: 36770.652 | H40: =G40*F40 -> 36770.652 | I40: Estimado | J40: Lançado ERP
B41: SUBETAPA | C41: 01.001.003 | D41: Consultorias | H41: =H42+H43+H44+H45 -> 206589.87
B42: SERVIÇO | C42: 01.001.003.001 | D42: Compatibilização de Projetos BIM | E42: vb | F42: 1 | G42: 144789.87 | H42: =G42*F42 -> 144789.87 | I42: Estimado | J42: Lançado ERP
B43: SERVIÇO | C43: 01.001.003.002 | D43: Tour Virtual | E43: vb | F43: 1 | G43: 11300 | H43: =G43*F43 -> 11300 | I43: Recebido | J43: Lançado ERP
B44: SERVIÇO | C44: 01.001.003.003 | D44: Consultoria técnica de legalização | E44: vb | F44: 1 | G44: 16000 | H44: =G44*F44 -> 16000 | I44: Recebido | J44: Lançado ERP
B45: SERVIÇO | C45: 01.001.003.004 | D45: Orçamento e planejamento | E45: vb | F45: 1 | G45: 34500 | H45: =G45*F45 -> 34500 | I45: Recebido | J45: Lançado ERP
B46: SUBETAPA | C46: 01.001.004 | D46: Ensaios | H46: =H47+H48+H49+H50+H51+H52+H53+H54+H55+H56 -> 600453
B47: SERVIÇO | C47: 01.001.004.001 | D47: Controle tecnológico do concreto | E47: vb | F47: 1 | G47: 238185 | H47: =G47*F47 -> 238185 | I47: Estimado | J47: Lançado ERP
B48: SERVIÇO | C48: 01.001.004.002 | D48: Ensaio de argamassa | E48: vb | F48: 1 | G48: 11200 | H48: =G48*F48 -> 11200 | I48: Estimado | J48: Lançado ERP
B49: SERVIÇO | C49: 01.001.004.003 | D49: Prova de carga | E49: vb | F49: 1 | G49: 5500 | H49: =G49*F49 -> 5500 | I49: Estimado | J49: Lançado ERP
B50: SERVIÇO | C50: 01.001.004.004 | D50: Ensaio de arrancamento de reboco | E50: vb | F50: 1 | G50: 6300 | H50: =G50*F50 -> 6300 | I50: Estimado | J50: Lançado ERP
...

Sheet Ger_Executivo_Cartesian
H4: PROJETO: | I4: Electra Towers | O4: REVISÃO: | P4: DATA
H5: EMPRESA: | I5: Thozen | O5: R00
A6: Unidade Construtiva | B6: Célula Construtiva | C6: Etapa | D6: Subetapa | E6: Serviço | G6: GERENCIAMENTO EXECUTIVO
A7: 0 | B7: 0 | C7: 0 | D7: 0 | E7: 0 | G7: EAP | H7: NIVEL | I7: Item | J7: Descrição | K7: Unidade | L7: Quant. | M7: Preço un | N7: Total | O7: Considerações | P7: Situação
A8: 0 | B8: 1 | C8: 0 | D8: 0 | E8: 0 | H8: CÉLULA CONSTRUTIVA | I8: 01 | J8: MOVIMENTAÇÃO DE TERRA
A9: 0 | B9: 1 | C9: 1 | D9: 0 | E9: 0 | H9: ETAPA | I9: 01.001 | J9: DEMOLIÇÕES, LIMPEZA DE TERRENO E LOCAÇÃO DE OBRA | N9: 26235.314 | O9: 1.5663183
A10: 0 | B10: 1 | C10: 1 | D10: 1 | E10: 0 | H10: SUBETAPA | I10: 01.001.001 | J10: Locação e gabarito de obra | N10: 26235.314 | O10: 1.5663183
A11: 0 | B11: 1 | C11: 1 | D11: 1 | E11: 1 | G11: MOVIMENTAÇÃO DE TERRA | H11: SERVIÇO | I11: 01.001.001.001 | J11: Locação da obra | K11: m2 | N11: 26235.314 | P11: Pendente
A12: 0 | B12: 1 | C12: 2 | D12: 0 | E12: 1 | H12: ETAPA | I12: 01.002 | J12: SERVIÇOS PRELIMINARES
A13: 0 | B13: 1 | C13: 2 | D13: 1 | E13: 0 | H13: SUBETAPA | I13: 01.002.001 | J13: Limpeza Permanente e Remoção entulho
A14: 0 | B14: 1 | C14: 2 | D14: 1 | E14: 1 | G14: MOVIMENTAÇÃO DE TERRA | H14: SERVIÇO | I14: 01.002.001.001 | J14: Limpeza da camada vegetal | K14: m2 | P14: Pendente
A15: 0 | B15: 1 | C15: 2 | D15: 1 | E15: 2 | G15: MOVIMENTAÇÃO DE TERRA | H15: SERVIÇO | I15: 01.002.001.002 | J15: Remoção de entulhos e resíduos | P15: Pendente
A16: 0 | B16: 1 | C16: 2 | D16: 2 | E16: 0 | H16: SUBETAPA | I16: 01.002.002 | J16: Mão de Obra de Canteiro
A17: 0 | B17: 1 | C17: 2 | D17: 2 | E17: 1 | G17: MOVIMENTAÇÃO DE TERRA | H17: SERVIÇO | I17: 01.002.002.001 | J17: Mão de Obra de Canteiro | K17: vb | P17: Pendente
A18: 0 | B18: 1 | C18: 3 | D18: 0 | E18: 1 | H18: ETAPA | I18: 01.003 | J18: SERVIÇOS DE TERRAPLANAGEM | N18: 271126.19 | O18: 16.186957
A19: 0 | B19: 1 | C19: 3 | D19: 1 | E19: 0 | H19: SUBETAPA | I19: 01.003.001 | J19: Mao de obra - movimentações de terra | N19: 271126.19 | O19: 16.186957
A20: 0 | B20: 1 | C20: 3 | D20: 1 | E20: 1 | G20: MOVIMENTAÇÃO DE TERRA | H20: SERVIÇO | I20: 01.003.001.001 | J20: Mão de obra movimentação de terra | K20: vb | N20: 233000 | P20: Pendente
A21: 0 | B21: 1 | C21: 4 | D21: 0 | E21: 2 | H21: ETAPA | I21: 01.004 | J21: SERVIÇO DE DRENAGEM | N21: 80000 | O21: 4.7762135
A22: 0 | B22: 1 | C22: 4 | D22: 1 | E22: 0 | H22: SUBETAPA | I22: 01.004.001 | J22: Drenagem | N22: 80000 | O22: 4.7762135
A23: 0 | B23: 1 | C23: 4 | D23: 1 | E23: 1 | G23: MOVIMENTAÇÃO DE TERRA | H23: SERVIÇO | I23: 01.004.001.001 | J23: Rebaixamento de Lençol freático | K23: vb | N23: 80000 | P23: Pendente
A24: 0 | B24: 2 | C24: 0 | D24: 1 | E24: 1 | H24: CÉLULA CONSTRUTIVA | I24: 02 | J24: CONTENÇÃO | N24: 772006.63 | O24: 46.090856
A25: 0 | B25: 2 | C25: 1 | D25: 0 | E25: 1 | H25: ETAPA | I25: 02.001 | J25: MURETA GUIA | N25: 18739.389 | O25: 1.1187915
A26: 0 | B26: 2 | C26: 1 | D26: 1 | E26: 0 | H26: SUBETAPA | I26: 02.001.001 | J26: Forma | N26: 6673.9436 | O26: 0.39845225
A27: 0 | B27: 2 | C27: 1 | D27: 1 | E27: 1 | G27: CONTENÇÃO | H27: SERVIÇO | I27: 02.001.001.001 | J27: Forma para infraestrutura em Tábuas de Madeira Serrada 2x reaproveitamento | K27: m2 | L27: 111.3136 | M27: 59.956229 | N27: 6673.9436 | P27: Pendente
A28: 0 | B28: 2 | C28: 1 | D28: 2 | E28: 0 | H28: SUBETAPA | I28: 02.001.002 | J28: Armadura | N28: 4318.7306 | O28: 0.25783974
A29: 0 | B29: 2 | C29: 1 | D29: 2 | E29: 1 | G29: CONTENÇÃO | H29: SERVIÇO | I29: 02.001.002.001 | J29: Armação aço CA-50 ø 6,3mm para Contenções (corte e dobra em obra) | K29: un | L29: 670.32 | M29: 6.0795674 | N29: 4075.2556 | P29: Pendente
A30: 0 | B30: 2 | C30: 1 | D30: 2 | E30: 2 | G30: CONTENÇÃO | H30: SERVIÇO | I30: 02.001.002.002 | J30: Armação aço CA-50 ø 12,5mm para Contenções (corte e dobra em obra) | K30: un | L30: 41.6016 | M30: 5.8525391 | N30: 243.47499 | P30: Pendente
A31: 0 | B31: 2 | C31: 1 | D31: 3 | E31: 0 | H31: SUBETAPA | I31: 02.001.003 | J31: Concreto | N31: 7746.7147 | O31: 0.46249954
A32: 0 | B32: 2 | C32: 1 | D32: 3 | E32: 1 | G32: CONTENÇÃO | H32: SERVIÇO | I32: 02.001.003.001 | J32: Concreto Usinado bombeável 50MPa para infraestrutura- incluindo serviço de bombeamento | K32: m3 | L32: 11.390452 | M32: 680.106 | N32: 7746.7147 | P32: Pendente
A33: 0 | B33: 2 | C33: 2 | D33: 0 | E33: 1 | H33: ETAPA | I33: 02.002 | J33: LAMELAS | PAREDE DIAFRAGMA | N33: 331865.23 | O33: 19.81324
A34: 0 | B34: 2 | C34: 2 | D34: 1 | E34: 0 | H34: SUBETAPA | I34: 02.002.001 | J34: Armadura | N34: 155967.97 | O34: 9.3117038
