Workbook

Sheet ANÁLISE_CUSTOS
A1: ETAPA | B1: OBRA | D1: OBRA SIMILAR
B2: VALOR | C2: VALOR / m² | D2: VALOR / m²
A3: =ORÇAMENTO_EXECUTIVO!A3 -> MOVIMENTAÇÃO DE TERRA | B3: =ORÇAMENTO_EXECUTIVO!B3 -> 76735.27 | C3: =ORÇAMENTO_EXECUTIVO!D3 -> 24.594244 | D3: =FIXED(CÁLCULO_MÉDIAS!L9,2,FALSE)&" "&"-"&FIXED(CÁLCULO_MÉDIAS!M9,2,FALSE) -> 10,00 -25,00
A4: =ORÇAMENTO_EXECUTIVO!A4 -> INFRAESTRUTURA | B4: =ORÇAMENTO_EXECUTIVO!B4 -> 783900.64 | C4: =ORÇAMENTO_EXECUTIVO!D4 -> 251.24618 | D4: =FIXED(CÁLCULO_MÉDIAS!L10,2,FALSE)&" "&"-"&FIXED(CÁLCULO_MÉDIAS!M10,2,FALSE) -> 65,00 -100,00
A5: =ORÇAMENTO_EXECUTIVO!A5 -> SUPRAESTRUTURA | B5: =ORÇAMENTO_EXECUTIVO!B5 -> 2467160.8 | C5: =ORÇAMENTO_EXECUTIVO!D5 -> 790.74399 | D5: =FIXED(CÁLCULO_MÉDIAS!L11,2,FALSE)&" "&"-"&FIXED(CÁLCULO_MÉDIAS!M11,2,FALSE) -> 515,00 -670,00
A6: =ORÇAMENTO_EXECUTIVO!A6 -> ALVENARIA | B6: =ORÇAMENTO_EXECUTIVO!B6 -> 348134.35 | C6: =ORÇAMENTO_EXECUTIVO!D6 -> 111.57973 | D6: =FIXED(CÁLCULO_MÉDIAS!L12,2,FALSE)&" "&"-"&FIXED(CÁLCULO_MÉDIAS!M12,2,FALSE) -> 70,00 -120,00
A7: =ORÇAMENTO_EXECUTIVO!A7 -> INSTALAÇÕES ELÉTRICAS, HIDRÁULICAS, GLP E PREVENTIVAS | B7: =ORÇAMENTO_EXECUTIVO!B7 -> 1164752.4 | C7: =ORÇAMENTO_EXECUTIVO!D7 -> 373.3121 | D7: =FIXED(CÁLCULO_MÉDIAS!L13,2,FALSE)&" "&"-"&FIXED(CÁLCULO_MÉDIAS!M13,2,FALSE) -> 290,00 -335,00
A8: =ORÇAMENTO_EXECUTIVO!A8 -> EQUIPAMENTOS E SISTEMAS ESPECIAIS | B8: =ORÇAMENTO_EXECUTIVO!B8 -> 334750 | C8: =ORÇAMENTO_EXECUTIVO!D8 -> 107.28995 | D8: =FIXED(CÁLCULO_MÉDIAS!L14,2,FALSE)&" "&"-"&FIXED(CÁLCULO_MÉDIAS!M14,2,FALSE) -> 125,00 -255,00
A9: =ORÇAMENTO_EXECUTIVO!A9 -> IMPERMEABILIZAÇÃO | B9: =ORÇAMENTO_EXECUTIVO!B9 -> 249600.14 | C9: =ORÇAMENTO_EXECUTIVO!D9 -> 79.998763 | D9: =FIXED(CÁLCULO_MÉDIAS!L15,2,FALSE)&" "&"-"&FIXED(CÁLCULO_MÉDIAS!M15,2,FALSE) -> 35,00 -65,00
A10: =ORÇAMENTO_EXECUTIVO!A10 -> REVESTIMENTOS INTERNOS DE PAREDE | B10: =ORÇAMENTO_EXECUTIVO!B10 -> 605982.32 | C10: =ORÇAMENTO_EXECUTIVO!D10 -> 194.22199 | D10: =FIXED(CÁLCULO_MÉDIAS!L16,2,FALSE)&" "&"-"&FIXED(CÁLCULO_MÉDIAS!M16,2,FALSE) -> 65,00 -165,00
A11: =ORÇAMENTO_EXECUTIVO!A11 -> REVESTIMENTOS E ACABAMENTOS INTERNOS EM TETO | B11: =ORÇAMENTO_EXECUTIVO!B11 -> 119794.21 | C11: =ORÇAMENTO_EXECUTIVO!D11 -> 38.394965 | D11: =FIXED(CÁLCULO_MÉDIAS!L17,2,FALSE)&" "&"-"&FIXED(CÁLCULO_MÉDIAS!M17,2,FALSE) -> 38,00 -60,00
A12: =ORÇAMENTO_EXECUTIVO!A12 -> PISOS E PAVIMENTAÇÕES | B12: =ORÇAMENTO_EXECUTIVO!B12 -> 515781.63 | C12: =ORÇAMENTO_EXECUTIVO!D12 -> 165.31198 | D12: =FIXED(CÁLCULO_MÉDIAS!L18,2,FALSE)&" "&"-"&FIXED(CÁLCULO_MÉDIAS!M18,2,FALSE) -> 220,00 -235,00
A13: =ORÇAMENTO_EXECUTIVO!A13 -> PINTURA INTERNA | B13: =ORÇAMENTO_EXECUTIVO!B13 -> 237376.62 | C13: =ORÇAMENTO_EXECUTIVO!D13 -> 76.081031 | D13: =FIXED(CÁLCULO_MÉDIAS!L19,2,FALSE)&" "&"-"&FIXED(CÁLCULO_MÉDIAS!M19,2,FALSE) -> 65,00 -70,00
A14: =ORÇAMENTO_EXECUTIVO!A14 -> ESQUADRIAS, VIDROS E FERRAGENS | B14: =ORÇAMENTO_EXECUTIVO!B14 -> 1067596.6 | C14: =ORÇAMENTO_EXECUTIVO!D14 -> 342.17292 | D14: =FIXED(CÁLCULO_MÉDIAS!L20,2,FALSE)&" "&"-"&FIXED(CÁLCULO_MÉDIAS!M20,2,FALSE) -> 360,00 -400,00
A15: =ORÇAMENTO_EXECUTIVO!A15 -> REVESTIMENTOS E ACABAMENTOS DE FACHADA | B15: =ORÇAMENTO_EXECUTIVO!B15 -> 506232.01 | C15: =ORÇAMENTO_EXECUTIVO!D15 -> 162.25125 | D15: =FIXED(CÁLCULO_MÉDIAS!L22,2,FALSE)&" "&"-"&FIXED(CÁLCULO_MÉDIAS!M22,2,FALSE) -> 150,00 -190,00
A16: =ORÇAMENTO_EXECUTIVO!A16 -> SERVIÇOS COMPLEMENTARES | B16: =ORÇAMENTO_EXECUTIVO!B16 -> 86568.1 | C16: =ORÇAMENTO_EXECUTIVO!D16 -> 27.745741 | D16: =FIXED(CÁLCULO_MÉDIAS!L23,2,FALSE)&" "&"-"&FIXED(CÁLCULO_MÉDIAS!M23,2,FALSE) -> 80,00 -150,00
A17: TOTAL | B17: =SUM(B3:B16) -> 8564365.1 | C17: =SUM(C3:C16) -> 2744.9448 | D17: =FIXED(CÁLCULO_MÉDIAS!L24,2,FALSE)&" "&"-"&FIXED(CÁLCULO_MÉDIAS!M24,2,FALSE) -> 2.091,00 -2.848,00
A22: DESCRIÇÃO - 27 APARTAMENTOS (ÁREA TOTAL) | B22: ÁREA | C22: VALOR | D22: =ORÇAMENTO_EXECUTIVO!B18 -> 10446495
A23: VALOR POR UNIDADE PRIVATIVA (R$/m²) | B23: 1729.84 | C23: =D22/B23 -> 6038.9947
A24: VALOR POR UNIDADE TIPO 01 | B24: 75.56 | C24: =D22/B24 -> 138254.3
A25: VALOR POR UNIDADE TIPO 02 | B25: 74.56 | C25: =D22/B25 -> 140108.56
A26: VALOR POR UNIDADE TIPO 03 | B26: 69.18 | C26: =D22/B26 -> 151004.55
A27: VALOR POR UNIDADE TIPO 04 | B27: 72.53 | C27: =D22/B27 -> 144029.98
A28: VALOR POR UNIDADE TIPO 05 | B28: 72.91 | C28: =D22/B28 -> 143279.31
A29: VALOR POR UNIDADE TIPO 06 | B29: 74.81 | C29: =D22/B29 -> 139640.35
A30: VALOR POR UNIDADE TIPO 07 | B30: 72.78 | C30: =D22/B30 -> 143535.24

Sheet ORÇAMENTO_EXECUTIVO
A1: ETAPA | B1: VALOR ORÇADO | C1: % | D1: VALOR / m² | F1: MÍNIMA | G1: MÁXIMA
A2: GERENCIAMENTO TÉCNICO E ADMINISTRATIVO | B2: =RELATÓRIO!X52 -> 1757024.4 | C2: =B2/B$18 -> 0.16819273 | D2: =B2/ORÇAMENTO_EXECUTIVO!I$2 -> 563.13983 | F2: 460 | G2: 530 | H2: ÁREA CONSTRUÍDA | I2: 3120.05 | J2: m²
A3: MOVIMENTAÇÃO DE TERRA | B3: =RELATÓRIO!X15 -> 76735.27 | C3: =B3/B$18 -> 0.0073455521 | D3: =B3/ORÇAMENTO_EXECUTIVO!I$2 -> 24.594244 | F3: 35 | G3: 135
A4: INFRAESTRUTURA | B4: =RELATÓRIO!X16 -> 783900.64 | C4: =B4/B$18 -> 0.075039587 | D4: =B4/ORÇAMENTO_EXECUTIVO!I$2 -> 251.24618 | F4: 65 | G4: 100
A5: SUPRAESTRUTURA | B5: =RELATÓRIO!X17 -> 2467160.8 | C5: =B5/B$18 -> 0.23617117 | D5: =B5/ORÇAMENTO_EXECUTIVO!I$2 -> 790.74399 | F5: 440 | G5: 515
A6: ALVENARIA | B6: =RELATÓRIO!X18 -> 348134.35 | C6: =B6/B$18 -> 0.033325471 | D6: =B6/ORÇAMENTO_EXECUTIVO!I$2 -> 111.57973 | F6: 70 | G6: 120
A7: INSTALAÇÕES ELÉTRICAS, HIDRÁULICAS, GLP E PREVENTIVAS | B7: =RELATÓRIO!AF20 -> 1164752.4 | C7: =B7/B$18 -> 0.11149696 | D7: =B7/ORÇAMENTO_EXECUTIVO!I$2 -> 373.3121 | F7: 290 | G7: 335
A8: EQUIPAMENTOS E SISTEMAS ESPECIAIS | B8: =RELATÓRIO!AF25 -> 334750 | C8: =B8/B$18 -> 0.032044242 | D8: =B8/ORÇAMENTO_EXECUTIVO!I$2 -> 107.28995 | F8: 125 | G8: 255
A9: IMPERMEABILIZAÇÃO | B9: =RELATÓRIO!X19 -> 249600.14 | C9: =B9/B$18 -> 0.023893196 | D9: =B9/ORÇAMENTO_EXECUTIVO!I$2 -> 79.998763 | F9: 35 | G9: 65
A10: REVESTIMENTOS INTERNOS DE PAREDE | B10: =RELATÓRIO!X27 -> 605982.32 | C10: =B10/B$18 -> 0.058008198 | D10: =B10/ORÇAMENTO_EXECUTIVO!I$2 -> 194.22199 | F10: 65 | G10: 110
A11: REVESTIMENTOS E ACABAMENTOS INTERNOS EM TETO | B11: =RELATÓRIO!X28 -> 119794.21 | C11: =B11/B$18 -> 0.011467408 | D11: =B11/ORÇAMENTO_EXECUTIVO!I$2 -> 38.394965 | F11: 38 | G11: 60
A12: PISOS E PAVIMENTAÇÕES | B12: =RELATÓRIO!X29 -> 515781.63 | C12: =B12/B$18 -> 0.049373656 | D12: =B12/ORÇAMENTO_EXECUTIVO!I$2 -> 165.31198 | F12: 220 | G12: 235
A13: PINTURA INTERNA | B13: =RELATÓRIO!X30 -> 237376.62 | C13: =B13/B$18 -> 0.022723089 | D13: =B13/ORÇAMENTO_EXECUTIVO!I$2 -> 76.081031 | F13: 65 | G13: 70
A14: ESQUADRIAS, VIDROS E FERRAGENS | B14: =RELATÓRIO!X31+RELATÓRIO!X32+RELATÓRIO!X33 -> 1067596.6 | C14: =B14/B$18 -> 0.10219664 | D14: =B14/ORÇAMENTO_EXECUTIVO!I$2 -> 342.17292 | F14: 360 | G14: 400
A15: REVESTIMENTOS E ACABAMENTOS DE FACHADA | B15: =RELATÓRIO!X35 -> 506232.01 | C15: =B15/B$18 -> 0.04845951 | D15: =B15/ORÇAMENTO_EXECUTIVO!I$2 -> 162.25125 | F15: 150 | G15: 190
A16: SERVIÇOS COMPLEMENTARES | B16: =RELATÓRIO!X36 -> 86568.1 | C16: =B16/B$18 -> 0.0082868085 | D16: =B16/ORÇAMENTO_EXECUTIVO!I$2 -> 27.745741 | F16: 80 | G16: 150
A17: IMPREVISTOS E CONTINGENCIAS | B17: =RELATÓRIO!X37 -> 125105 | C17: =B17/B$18 -> 0.011975788 | D17: =B17/ORÇAMENTO_EXECUTIVO!I$2 -> 40.097114
A18: TOTAL | B18: =SUM(B2:B17) -> 10446495 | C18: =SUM(C2:C17) -> 1 | D18: =SUM(D2:D17) -> 3348.1818
A19: CUB/BA | B19: 1889.47 | C19: 45323 | D19: =+D18/B19 -> 1.7720217
E21: =10446494.54-B18 -> 0
A23: JUSTIFICATIVAS E COMENTÁRIOS
A24: GERENCIAMENTO TÉCNICO E ADMINISTRATIVO | B24: Valor fornecido pelo cliente
A25: MOVIMENTAÇÃO DE TERRA | B25: Corrigido os quantitativos
A26: INFRAESTRUTURA | B26: Correção de formas e concreto
A27: SUPRAESTRUTURA | B27: Correção de formas e concreto
A28: ALVENARIA | B28: Ficou acima porque consideramos gesso (Drywall) e lã de vidro
A29: INSTALAÇÕES ELÉTRICAS, HIDRÁULICAS, GLP E PREVENTIVAS | B29: Foi feito através de verba (elétrica), porque os quantitativos fornecidos não batiam com o projeto
A30: EQUIPAMENTOS E SISTEMAS ESPECIAIS | B30: não temos gerador e subsestação
A31: IMPERMEABILIZAÇÃO | B31: temos uma área a ser impermeabilizada superior (toda cobertura, abas do empreendimento e fachada/parede verde)
A32: REVESTIMENTOS INTERNOS DE PAREDE | B32: corrigimos os quantitativos e os valores de alguns insumos e mão de obra
A33: REVESTIMENTOS E ACABAMENTOS INTERNOS EM TETO | B33: corrigimos os quantitativos e os valores de alguns insumos e mão de obra
A34: PISOS E PAVIMENTAÇÕES | B34: corrigimos os quantitativos e os valores de alguns insumos e mão de obra
A35: PINTURA INTERNA | B35: corrigimos os quantitativos e os valores de alguns insumos e mão de obra
... A40: IMPREVISTOS E CONTINGENCIAS | B40: fornecido pelo cliente
A44: Movimentação de terra e Infra
A45: Soberano | B45: Foi considerado verba (estimativa)
B46: No Soberano temos o caso em que na sondagem, todos os furos tinham acúmulo de água (1,54m aprox.)
B47: 12 Estacas com 3,0 e 16m + estacas com 7,5m ou 12m
B48: Não tem subsolo
B49: Rebaixamento lençol freático
...

Sheet CÁLCULO_MÉDIAS
C3: DATA BASE | D3: 44682 | E3: DATA BASE | F3: 44682 | G3: DATA BASE | H3: 44958 | I3: DATA BASE | J3: 44805
C4: CUB | D4: 2470.83 | E4: CUB | F4: 2770.83 | G4: CUB | H4: 14888.46 | I4: CUB | J4: 2623.42
C6: F NOGUEIRA - WPR | E6: F NOGUEIRA - SOBERANO | G6: LUMIS - LIVE | I6: PAVITEC - SIENA | L6: MÉDIAS
C7: VALOR / M2 | D7: INDEXADO | E7: VALOR / M2 | F7: INDEXADO | I7: VALOR / M2 | J7: INDEXADO | L7: MÍNIMA | M7: MÁXIMA
B8: GERENCIAMENTO TECNICO E ADMINISTRATIVO | C8: 526.31 | D8: =ORÇAMENTO_EXECUTIVO!$B$19/CÁLCULO_MÉDIAS!D$4*C8 -> 402.47486 | E8: 504.2 | F8: =ORÇAMENTO_EXECUTIVO!$B$19/CÁLCULO_MÉDIAS!F$4*E8 -> 343.82144 | G8: 192.54 | H8: =ORÇAMENTO_EXECUTIVO!$B$19/CÁLCULO_MÉDIAS!H$4*G8 -> 24.434935 | I8: 466.94 | J8: =ORÇAMENTO_EXECUTIVO!$B$19/CÁLCULO_MÉDIAS!J$4*I8 -> 336.30495 | L8: 460 | M8: 530
B9: MOVIMENTAÇÃO DE TERRA | C9: 5.47 | D9: =ORÇAMENTO_EXECUTIVO!$B$19/CÁLCULO_MÉDIAS!D$4*C9 -> 4.1829672 | E9: 14.78 | F9: =ORÇAMENTO_EXECUTIVO!$B$19/CÁLCULO_MÉDIAS!F$4*E9 -> 10.078701 | G9: 131.35 | H9: =ORÇAMENTO_EXECUTIVO!$B$19/CÁLCULO_MÉDIAS!H$4*G9 -> 16.669413 | I9: 32.65 | J9: =ORÇAMENTO_EXECUTIVO!$B$19/CÁLCULO_MÉDIAS!J$4*I9 -> 23.515562 | L9: 10 | M9: 25
B10: INFRAESTRUTURA | C10: 95.87 | D10: =ORÇAMENTO_EXECUTIVO!$B$19/CÁLCULO_MÉDIAS!D$4*C10 -> 73.312809 | E10: 66.71 | F10: =ORÇAMENTO_EXECUTIVO!$B$19/CÁLCULO_MÉDIAS!F$4*E10 -> 45.490537 | G10: 99.33 | H10: =ORÇAMENTO_EXECUTIVO!$B$19/CÁLCULO_MÉDIAS!H$4*G10 -> 12.605807 | I10: 43.56 | J10: =ORÇAMENTO_EXECUTIVO!$B$19/CÁLCULO_MÉDIAS!J$4*I10 -> 31.373289 | L10: 65 | M10: 100
B11: SUPRAESTRUTURA | C11: 310.02 | D11: =ORÇAMENTO_EXECUTIVO!$B$19/CÁLCULO_MÉDIAS!D$4*C11 -> 237.07559 | E11: 440.86 | F11: =ORÇAMENTO_EXECUTIVO!$B$19/CÁLCULO_MÉDIAS!F$4*E11 -> 300.62896 | G11: 670.84 | H11: =ORÇAMENTO_EXECUTIVO!$B$19/CÁLCULO_MÉDIAS!H$4*G11 -> 85.135202 | I11: 515.43 | J11: =ORÇAMENTO_EXECUTIVO!$B$19/CÁLCULO_MÉDIAS!J$4*I11 -> 371.22898 | L11: 515 | M11: 670
B12: ALVENARIA | C12: 113.35 | D12: =ORÇAMENTO_EXECUTIVO!$B$19/CÁLCULO_MÉDIAS!D$4*C12 -> 86.679951 | E12: 59.84 | F12: =ORÇAMENTO_EXECUTIVO!$B$19/CÁLCULO_MÉDIAS!F$4*E12 -> 40.805782 | G12: 151.39 | H12: =ORÇAMENTO_EXECUTIVO!$B$19/CÁLCULO_MÉDIAS!H$4*G12 -> 19.212656 | I12: 72.44 | J12: =ORÇAMENTO_EXECUTIVO!$B$19/CÁLCULO_MÉDIAS!J$4*I12 -> 52.173578 | L12: 70 | M12: 120
B13: INSTALAÇÕES ELÉTRICAS, HIDRÁULICAS, GLP E PREVENTIVAS | C13: 332.12 | D13: =ORÇAMENTO_EXECUTIVO!$B$19/CÁLCULO_MÉDIAS!D$4*C13 -> 253.9757 | E13: 296.6 | F13: =ORÇAMENTO_EXECUTIVO!$B$19/CÁLCULO_MÉDIAS!F$4*E13 -> 202.25593 | G13: 301.65 | H13: =ORÇAMENTO_EXECUTIVO!$B$19/CÁLCULO_MÉDIAS!H$4*G13 -> 38.281906 | I13: 300.71 | J13: =ORÇAMENTO_EXECUTIVO!$B$19/CÁLCULO_MÉDIAS!J$4*I13 -> 216.58085 | L13: 290 | M13: 335
B14: EQUIPAMENTOS E SISTEMAS ESPECIAIS | C14: 254.78 | D14: =ORÇAMENTO_EXECUTIVO!$B$19/CÁLCULO_MÉDIAS!D$4*C14 -> 194.83298 | E14: 194.51 | F14: =ORÇAMENTO_EXECUTIVO!$B$19/CÁLCULO_MÉDIAS!F$4*E14 -> 132.63925 | G14: 121.63 | H14: =ORÇAMENTO_EXECUTIVO!$B$19/CÁLCULO_MÉDIAS!H$4*G14 -> 15.435863 | I14: 125.08 | J14: =ORÇAMENTO_EXECUTIVO!$B$19/CÁLCULO_MÉDIAS!J$4*I14 -> 90.086569 | L14: 125 | M14: 255
B15: IMPERMEABILIZAÇÃO | C15: 34.01 | D15: =ORÇAMENTO_EXECUTIVO!$B$19/CÁLCULO_MÉDIAS!D$4*C15 -> 26.007809 | E15: 23.16 | F15: =ORÇAMENTO_EXECUTIVO!$B$19/CÁLCULO_MÉDIAS!F$4*E15 -> 15.793147 | G15: 61.19 | H15: =ORÇAMENTO_EXECUTIVO!$B$19/CÁLCULO_MÉDIAS!H$4*G15 -> 7.7655224 | I15: 33.56 | J15: =ORÇAMENTO_EXECUTIVO!$B$19/CÁLCULO_MÉDIAS!J$4*I15 -> 24.170973 | L15: 35 | M15: 65
B16: REVESTIMENTOS INTERNOS EM PISO E PAREDE | C16: 65.18 | D16: =ORÇAMENTO_EXECUTIVO!$B$19/CÁLCULO_MÉDIAS!D$4*C16 -> 49.84384 | E16: 109.14 | F16: =ORÇAMENTO_EXECUTIVO!$B$19/CÁLCULO_MÉDIAS!F$4*E16 -> 74.424182 | G16: 161.74 | H16: =ORÇAMENTO_EXECUTIVO!$B$19/CÁLCULO_MÉDIAS!H$4*G16 -> 20.526158 | I16: 89.84 | J16: =ORÇAMENTO_EXECUTIVO!$B$19/CÁLCULO_MÉDIAS!J$4*I16 -> 64.705607 | L16: 65 | M16: 165
B17: REVESTIMENTOS E ACABAMENTOS INTERNOS EM TETO | C17: 69.4 | D17: =ORÇAMENTO_EXECUTIVO!$B$19/CÁLCULO_MÉDIAS!D$4*C17 -> 53.070919 | E17: 68.79 | F17: =ORÇAMENTO_EXECUTIVO!$B$19/CÁLCULO_MÉDIAS!F$4*E17 -> 46.908919 | G17: 38.14 | H17: =ORÇAMENTO_EXECUTIVO!$B$19/CÁLCULO_MÉDIAS!H$4*G17 -> 4.8402847 | I17: 69.99 | J17: =ORÇAMENTO_EXECUTIVO!$B$19/CÁLCULO_MÉDIAS!J$4*I17 -> 50.40901 | L17: 38 | M17: 60
B18: ACABAMENTOS EM PISO E PAREDE | C18: 231.88 | D18: =ORÇAMENTO_EXECUTIVO!$B$19/CÁLCULO_MÉDIAS!D$4*C18 -> 177.3211 | E18: 226.88 | F18: =ORÇAMENTO_EXECUTIVO!$B$19/CÁLCULO_MÉDIAS!F$4*E18 -> 154.71283 | G18: 233.5 | H18: =ORÇAMENTO_EXECUTIVO!$B$19/CÁLCULO_MÉDIAS!H$4*G18 -> 29.633101 | I18: 78.12 | J18: =ORÇAMENTO_EXECUTIVO!$B$19/CÁLCULO_MÉDIAS!J$4*I18 -> 56.264493 | L18: 220 | M18: 235
B19: PINTURA INTERNA | C19: 62.33 | D19: =ORÇAMENTO_EXECUTIVO!$B$19/CÁLCULO_MÉDIAS!D$4*C19 -> 47.664414 | E19: 69.71 | F19: =ORÇAMENTO_EXECUTIVO!$B$19/CÁLCULO_MÉDIAS!F$4*E19 -> 47.536281 | G19: 60.25 | H19: =ORÇAMENTO_EXECUTIVO!$B$19/CÁLCULO_MÉDIAS!H$4*G19 -> 7.6462285 | I19: 65.03 | J19: =ORÇAMENTO_EXECUTIVO!$B$19/CÁLCULO_MÉDIAS!J$4*I19 -> 46.836661 | L19: 65 | M19: 70 | Q19: 116.72 | R19: m3
B20: ESQUADRIAS, VIDROS E FERRAGENS | C20: 200.81 | D20: =ORÇAMENTO_EXECUTIVO!$B$19/CÁLCULO_MÉDIAS!D$4*C20 -> 153.56154 | E20: 361.82 | F20: =ORÇAMENTO_EXECUTIVO!$B$19/CÁLCULO_MÉDIAS!F$4*E20 -> 246.73041 | G20: 393.73 | H20: =ORÇAMENTO_EXECUTIVO!$B$19/CÁLCULO_MÉDIAS!H$4*G20 -> 49.967627 | I20: 401.96 | J20: =ORÇAMENTO_EXECUTIVO!$B$19/CÁLCULO_MÉDIAS!J$4*I20 -> 289.5043 | L20: 360 | M20: 400
B21: COBERTURA | C21: 3.62 | D21: =ORÇAMENTO_EXECUTIVO!$B$19/CÁLCULO_MÉDIAS!D$4*C21 -> 2.7682525 | E21: 3.43 | F21: =ORÇAMENTO_EXECUTIVO!$B$19/CÁLCULO_MÉDIAS!F$4*E21 -> 2.3389678 | G21: 18.06 | H21: =ORÇAMENTO_EXECUTIVO!$B$19/CÁLCULO_MÉDIAS!H$4*G21 -> 2.2919649 | I21: 0 | J21: =ORÇAMENTO_EXECUTIVO!$B$19/CÁLCULO_MÉDIAS!J$4*I21 -> 0 | L21: 3 | M21: 8
B22: REVESTIMENTOS E ACABAMENTOS DE FACHADA | C22: 81.12 | D22: =ORÇAMENTO_EXECUTIVO!$B$19/CÁLCULO_MÉDIAS!D$4*C22 -> 62.033327 | E22: 70.04 | F22: =ORÇAMENTO_EXECUTIVO!$B$19/CÁLCULO_MÉDIAS!F$4*E22 -> 47.761313 | G22: 152.18 | H22: =ORÇAMENTO_EXECUTIVO!$B$19/CÁLCULO_MÉDIAS!H$4*G22 -> 19.312914 | I22: 190.5 | J22: =ORÇAMENTO_EXECUTIVO!$B$19/CÁLCULO_MÉDIAS!J$4*I22 -> 137.20412 | L22: 150 | M22: 190
B23: SERVIÇOS COMPLEMENTARES | C23: 112.85 | D23: =ORÇAMENTO_EXECUTIVO!$B$19/CÁLCULO_MÉDIAS!D$4*C23 -> 86.297596 | E23: 84.68 | F23: =ORÇAMENTO_EXECUTIVO!$B$19/CÁLCULO_MÉDIAS!F$4*E23 -> 57.744546 | G23: 152.51 | H23: =ORÇAMENTO_EXECUTIVO!$B$19/CÁLCULO_MÉDIAS!H$4*G23 -> 19.354794 | I23: 85.44 | J23: =ORÇAMENTO_EXECUTIVO!$B$19/CÁLCULO_MÉDIAS!J$4*I23 -> 61.536588 | L23: 80 | M23: 150
B24: TOTAL | C24: =SUM(C8:C23) -> 2499.12 | D24: =SUM(D8:D23) -> 1911.1037 | E24: =SUM(E8:E23) -> 2595.15 | F24: =SUM(F8:F23) -> 1769.6712 | G24: =SUM(G8:G23) -> 2940.03 | H24: =SUM(H8:H23) -> 373.11438 | I24: =SUM(I8:I23) -> 2571.25 | J24: =SUM(J8:J23) -> 1851.8955 | L24: =SUM(L9:L23) -> 2091 | M24: =SUM(M9:M23) -> 2848
C26: CUB DE SC | E26: CUB DE SC | G26: CUB DE SC | I26: CUB DA BA

Sheet Planilha2
C4: GERENCIAMENTO TÉCNICO E ADMINISTRATIVO - Faltam os itens:
C5: Locação da obra
C6: Sondagem
C7: Levantamento Planialtimetrico
C8: Controle tecnológico
C9: Ensaios de controle tecnológico
C10: Seguro de vida coletivo
C11: Seguro de risco de engenharia e responsabilidade civil
C13: Supra - Pavitec
C14: 8645.48
C15: 30185.13
C16: 8112.23
C17: 23715.3
C18: 19218.72
C19: 11031.98
C20: 11407.23
C21: 9383.25
C22: =24638.61/2 -> 12319.305
C23: =29675.88/2 -> 14837.94
C24: =39848.85/2 -> 19924.425
C25: =29918.64/2 -> 14959.32
C26: =70119.9/2 -> 35059.95
C27: =21920.82/2 -> 10960.41
C28: =20985.48/2 -> 10492.74
C29: =23443.68/2 -> 11721.84
C30: =SUM(C14:C29) -> 251975.25 | D30: valor total supra MO
C31: 2373.64 | D31: área
C32: =C30/C31 -> 106.15563 | D32: valor/m²
C37: 23676.88 | D37: 2373.64
D38: 4309.77
C39: =C37*D38 -> 1.0204191e+08
C40: =C39/D37 -> 42989.631
C42: ACM LUMIS - LIVE estimativa de custo estrutura ACM
C43: ÁREA | D43: 14888.46
C44: VALOR | D44: 422100
C45: Valor m² de área do empreendimento | D45: =D44/D43 -> 28.350817
C46: ÁREA | D46: 4309.77
C47: VALOR | D47: =D45*D46 -> 122185.5 | E47: =D47/224.24 -> 544.88717
C48: Valor m² de área do empreendimento | D48: =D47/D46 -> 28.350817

Sheet RELATÓRIO
D2: Orçamento
D3: Resumo por Células Construtivas
A6: Obra | E6: 2031 - MARAVISTA RESIDENCE (CONSTRUÇÃO)
A7: Unidade construtiva | E7: 1 - CUSTOS DIRETOS
A8: Tipo de obra | E8: 4 - Construção Civil
A9: Endereço da obra | E9: Rua dos Tucanos - Lote 33 Quadra 34 - Nossa Senhora da Vitoria - Ilhéus/BA - 45655-738
A10: Versão do orçamento | E10: 1 - 18/04/2023 - 08:26:18 | L10: Data base | V10: 18/04/2023
A11: BDI | E11: não aplicado | L11: Encargos sociais | V11: não aplicado
A12: Preços expressos em | E12: R$ (REAL)
A14: Código | C14: Descrição | X14: Preço total | AE14: % Total
A15: 01 | C15: MOVIMENTAÇÃO DE TERRA | X15: 76735.27 | AE15: 0.74
A16: 02 | C16: INFRAESTRUTURA | X16: 783900.64 | AE16: 7.42
A17: 03 | C17: SUPRAESTRUTURA | X17: 2467160.8 | AE17: 23.64
A18: 04 | C18: ALVENARIA | X18: 348134.35 | AE18: 3.34
A19: 05 | C19: IMPERMEABILIZAÇÃO E TRATAMENTOS | X19: 249600.14 | AE19: 2.39
A20: 06 | C20: INSTALAÇÕES ELÉTRICAS | X20: 328992.26 | AE20: 3.15 | AF20: =X20+X21+X22+X23+X24+X34 -> 1164752.4
A21: 07 | C21: INSTALAÇÕES HIDROSSANITÁRIAS E DRENAGEM | X21: 263670.32 | AE21: 2.53
A22: 08 | C22: INSTALAÇÕES PREVENTIVAS | X22: 49156.19 | AE22: 0.47
A23: 09 | C23: INSTALAÇÕES DE GÁS | X23: 151855.37 | AE23: 1.45
A24: 10 | C24: INSTALAÇÕES DE COMUNICAÇÃO E DADOS | X24: 249943.24 | AE24: 2.39
A25: 11 | C25: EQUIPAMENTOS E SISTEMAS ESPECIAIS | X25: 275000 | AE25: 2.63 | AF25: =X25+X26 -> 334750
A26: 12 | C26: CLIMATIZAÇÃO, EXAUSTÃO MECÂNICA E PRESSURIZAÇÃO | X26: 59750 | AE26: 0.57
A27: 13 | C27: REVESTIMENTOS INTERNOS DE PAREDE | X27: 605982.32 | AE27: 5.81
A28: 14 | C28: REVESTIMENTOS E ACABAMENTOS INTERNOS EM TETO | X28: 119794.21 | AE28: 1.15
A29: 15 | C29: PISOS E PAVIMENTAÇÕES | X29: 515781.63 | AE29: 4.94
A30: 16 | C30: SISTEMAS DE PINTURA INTERNA | X30: 237376.62 | AE30: 2.27
A31: 17 | C31: ESQUADRIAS DE ALUMÍNIO | X31: 601239.89 | AE31: 5.76
A32: 18 | C32: ESQUADRIAS DE MADEIRA | X32: 137244.22 | AE32: 1.31
A33: 19 | C33: ESQUADRIAS METÁLICAS | X33: 329112.5 | AE33: 3.15
A34: 20 | C34: LOUÇAS E METAIS | X34: 121135.05 | AE34: 1.16 | AF34: =X34/3120 -> 38.825337
A35: 21 | C35: REVESTIMENTOS E ACABAMENTOS EM FACHADA | X35: 506232.01 | AE35: 4.85
A36: 22 | C36: SERVIÇOS COMPLEMENTARES | X36: 86568.1 | AE36: 0.83
A37: 23 | C37: IMPERVISTOS E CONTINGÊNCIAS | X37: 125105 | AE37: 1.2
A38: Total da unidade construtiva | X38: =SUM(X15:AD37) -> 8689470.1 | AE38: 86.58
A40: Obra | E40: 2031 - MARAVISTA RESIDENCE (CONSTRUÇÃO)
A41: Unidade construtiva | E41: 2 - CUSTOS INDIRETOS
A42: Tipo de obra | E42: 4 - Construção Civil
A43: Endereço da obra | E43: Rua dos Tucanos - Lote 33 Quadra 34 - Nossa Senhora da Vitoria - Ilhéus/BA - 45655-738
A44: Versão do orçamento | E44: 1 - 18/04/2023 - 08:26:18 | L44: Data base | V44: 18/04/2023
A45: BDI | E45: não aplicado | L45: Encargos sociais | V45: não aplicado
...
