Workbook

Sheet FLOW_RESUMO
A1: FLOW DA LAGOA - RESUMO DE ENQUADRAMENTO
A3: Data da versão | B3: 2026-06-09 | C3: Fonte | D3: Pacote v01
A4: Área construída | B4: 15000.62 | C4: m² | D4: Quadro ARQ
A5: Área computável | B5: 8122.55 | C5: m² | D5: Quadro ARQ
A6: Área privativa | B6: 8343.9 | C6: m² | D6: Quadro ARQ
A7: UR | B7: 236 | C7: un | D7: Premissa por área média
A8: Área construída/UR | B8: 63.561949 | C8: m²/UR | D8: Controle
A9: Área privativa/UR | B9: 35.355508 | C9: m²/UR | D9: Controle
A10: Vagas automóveis | B10: 161 | C10: un | D10: Quadro ARQ
A11: Vagas bicicletas | B11: 213 | C11: un | D11: Quadro ARQ
A12: Elevadores | B12: 4 | C12: un | D12: Premissa visual
A13: Prazo | B13: 24 | C13: meses | D13: Premissa V1
A14: CUB-SC ref. maio/2026 | B14: 3096.25 | C14: R$/m² | D14: Sinduscon-Fpolis
A15: Supabase médio-alto mediana | B15: 3348.65 | C15: R$/m² | D15: Soma macrogrupos
... A20: R$/m² / CUB | B20: 1.1885345 | C20: x CUB | D20: Controle

Sheet PAINEL
A1: FLOW DA LAGOA — PARAMÉTRICO V2
A2: Bottom-up + Dropdowns interativos | 75 executivos calibrados
A4: Custo Total | B4: =CUSTOS_MACROGRUPO!D22
A5: R$/m² AC | B5: =CUSTOS_MACROGRUPO!D22/DADOS_PROJETO!B5
A6: CUB Ratio | B6: =B5/DADOS_PROJETO!B12
A7: Custo/UR | B7: =CUSTOS_MACROGRUPO!D22/DADOS_PROJETO!B6
A8: AC | B8: =DADOS_PROJETO!B5
A9: UR | B9: =DADOS_PROJETO!B6
A10: CUB | B10: =DADOS_PROJETO!B12
A11: Laje | B11: =BRIEFING!B4
A12: Subsolos | B12: =BRIEFING!B5
A13: Padrão | B13: =BRIEFING!B7
A14: Fachada | B14: =BRIEFING!B8

Sheet DADOS_PROJETO
A1: FLOW DA LAGOA — ORÇAMENTO PARAMÉTRICO V2
A3: Projeto | B3: Flow da Lagoa
A4: Cidade/UF | B4: Florianópolis
A5: AC Total (m²) | B5: 15000.62
A6: UR | B6: 236
A7: Pavimentos | B7: 6
A8: Pav. Tipo | B8: 3
A9: Elevadores | B9: 4
A10: Vagas | B10: 161
A11: Prazo (meses) | B11: 24
A12: CUB Atual (R$) | B12: 3096.25

Sheet BRIEFING
A1: BRIEFING — ALTERE OS DROPDOWNS PARA RECALCULAR
A2: Cada alteração muda automaticamente os índices e custos nas abas de detalhe
A3: Pergunta | B3: Resposta | C3: Impacto
A4: Tipo de Laje | B4: Convencional | C4: Muda: concreto, aço, forma, escoramento, cordoalha
A5: Subsolos | B5: 0 | C5: Muda: contenção, mov.terra, impermeabilização, fundação
A6: Fundação | B6: Hélice | C6: Muda: custo infraestrutura, tipo de perfuração
A7: Padrão Acabamento | B7: Médio-Alto | C7: Muda: pisos, rev.parede, esquadrias, louças, fachada
A8: Fachada | B8: Textura | C8: Muda: custo fachada (R$/m²)
A9: Pressurização | B9: Não | C9: Muda: custo sist.especiais (+R$ 80k)
A10: Nº Torres | B10: 3 | C10: Muda: gerador, elevadores, equipamentos
A11: Gerador Dedicado | B11: Não | C11: Muda: sist.especiais (R$ 120-350k)
A12: Entrega | B12: Completa | C12: Shell desconta ~R$ 200/m² (pisos, pintura, rev.parede, louças, alvenaria)
A13: Tipologia | B13: 1-2 Dormitórios | C13: Muda: pontos elétricos, louças, alvenaria interna
A14: Pé-Direito | B14: Padrão (3.00) | C14: Muda: fachada, alvenaria, estrutura (+2-8%)
... A17: Piscina | B17: Sim | C17: Muda: sist.especiais (R$ 0 / R$ 220k / R$ 320k)

Sheet INDICES
A1: ÍNDICES CALIBRADOS — HÍBRIDO: BRIEFING + OVERRIDE MANUAL
A2: B=calculado via BRIEFING (não editar) | C=override manual (edite para sobrescrever) | D=valor efetivo usado nas abas de macrogrupo (= Override se preenchido, senão B)
A4: Índice | B4: Valor calc | C4: Override | D4: Efetivo | E4: Unidade | F4: Fonte
A5: Concreto (m³/m² AC) | B5: =IF(BRIEFING!B4="Protendida",0.22,IF(BRIEFING!B4="Nervurada",0.20,0.25)) | D5: =IF(C5="",B5,C5) | E5: m³/m² | F5: Master 7p exec | IF Laje
A6: Aço convenc. (kg/m³) | B6: =IF(BRIEFING!B4="Protendida",70,IF(BRIEFING!B4="Nervurada",90,106)) | D6: =IF(C6="",B6,C6) | E6: kg/m³ | F6: Master 7p+11p narr | IF Laje
A7: Cordoalha (kg/m² laje) | B7: =IF(BRIEFING!B4="Protendida",8,0) | D7: =IF(C7="",B7,C7) | E7: kg/m² | F7: Master protendida | IF Laje=Protendida
A8: Forma (m²/m³) | B8: =IF(BRIEFING!B4="Protendida",6.05,IF(BRIEFING!B4="Nervurada",6.5,7.12)) | D8: =IF(C8="",B8,C8) | E8: m²/m³ | F8: Master 7p exec | IF Laje
A9: Escoramento (R$/m²) | B9: =IF(BRIEFING!B4="Protendida",50,IF(BRIEFING!B4="Nervurada",35,0)) | D9: =IF(C9="",B9,C9) | E9: R$/m² | F9: PU base 7p | IF Laje
A10: fck Laje | B10: =IF(BRIEFING!B4="Protendida",40,30) | D10: =IF(C10="",B10,C10) | E10: MPa | F10: IF Laje
A11: Nº estacas (base AC) | B11: =ROUND(DADOS_PROJETO!B5/75,0)*(1+VALUE(BRIEFING!B5)*0.15) | D11: =IF(C11="",B11,C11) | E11: un | F11: ~1 est/75m² + sub | AC/75 × (1+sub×15%)
A12: Comp. estaca (m) | B12: =IF(BRIEFING!B6="Hélice",18,IF(BRIEFING!B6="Tubulão",12,0))+VALUE(BRIEFING!B5)*2 | D12: =IF(C12="",B12,C12) | E12: m | F12: Tipo + prof.sub | IF Fundação + sub×2m
A13: Alvenaria (m²/m² AC) | B13: =2.25*IF(BRIEFING!B12="Shell",0.75,1)*IF(BRIEFING!B14="Duplo",1.15,IF(BRIEFING!B14="Alto (3.20)",1.05,1)) | D13: =IF(C13="",B13,C13) | E13: m²/m² | F13: 2,25 × shell × pé-dir | IF Entrega + Pé-Direito
A14: Pisos (m²/m² AC) | B14: =1.70*IF(BRIEFING!B12="Shell",0.40,1) | D14: =IF(C14="",B14,C14) | E14: m²/m² | F14: 1,70 × shell | IF Entrega (shell = 40%)
A15: Rev. Parede (m²/m² AC) | B15: =2.85*IF(BRIEFING!B12="Shell",0.50,1)*IF(VALUE(BRIEFING!B15)>=2,1.15,IF(VALUE(BRIEFING!B15)>=1,1.0,0.85)) | D15: =IF(C15="",B15,C15) | E15: m²/m² | F15: 2,85 × shell × bwc | IF Entrega + BWC/apto
A16: Forro (m²/m² AC) | B16: =1.16*IF(BRIEFING!B12="Shell",0.45,1) | D16: =IF(C16="",B16,C16) | E16: m²/m² | F16: 1,16 × shell | IF Entrega (shell = 45%)
A17: Pintura (m² sup/m² AC) | B17: =5.65*IF(BRIEFING!B12="Shell",0.40,1) | D17: =IF(C17="",B17,C17) | E17: m²/m² | F17: 5,65 × shell | IF Entrega (shell = 40%)
A18: Fachada (m²/m² AC) | B18: =IF(BRIEFING!B8="Pele de vidro",1.8,IF(BRIEFING!B8="ACM",1.7,1.55))*IF(BRIEFING!B14="Duplo",1.12,IF(BRIEFING!B14="Alto (3.20)",1.05,1)) | D18: =IF(C18="",B18,C18) | E18: m²/m² | F18: Tipo fachada × pé-dir | IF Fachada + Pé-Direito
A19: Impermeab. (m²/m² AC) | B19: =0.37+VALUE(BRIEFING!B5)*0.05+IF(VALUE(BRIEFING!B15)>=3,0.04,IF(VALUE(BRIEFING!B15)>=2,0.03,0)) | D19: =IF(C19="",B19,C19) | E19: m²/m² | F19: Base + sub + bwc | IF Sub + BWC
A20: Fator padrão acabamento | B20: =IF(BRIEFING!B7="Luxo",1.35,IF(BRIEFING!B7="Alto",1.15,IF(BRIEFING!B7="Médio-Alto",1.0,0.85))) | D20: =IF(C20="",B20,C20) | E20: fator | F20: IF Padrão
A21: PU fachada (R$/m²) | B21: =IF(BRIEFING!B8="Pele de vidro",350,IF(BRIEFING!B8="ACM",280,IF(BRIEFING!B8="Cerâmica",180,100))) | D21: =IF(C21="",B21,C21) | E21: R$/m² | F21: PU base + briefing | IF Fachada tipo
A22: Pressurização (R$) | B22: =IF(BRIEFING!B9="Sim",80000,0) | D22: =IF(C22="",B22,C22) | E22: R$ | F22: Param. base | IF Sim
A23: Gerador (R$) | B23: =IF(BRIEFING!B11="Não",0,IF(BRIEFING!B10="3",350000,IF(BRIEFING!B10="2",250000,180000))) | D23: =IF(C23="",B23,C23) | E23: R$ | F23: IF Gerador Sim + Torres | IF Gerador + Torres
A24: Contenção (R$) | B24: =IF(VALUE(BRIEFING!B5)>0,VALUE(BRIEFING!B5)*3.5*120*350,0) | D24: =IF(C24="",B24,C24) | E24: R$ | F24: Sub×prof×perim×R$ | IF Sub>0
A25: Mov. Terra PU (R$/m²) | B25: =IF(VALUE(BRIEFING!B5)>0,17+VALUE(BRIEFING!B5)*15,17) | D25: =IF(C25="",B25,C25) | E25: R$/m² | F25: Base + sub×15 | IF Sub>0
A26: Fator tipologia louças | B26: =IF(BRIEFING!B13="Studios",0.65,IF(BRIEFING!B13="1-2 Dormitórios",0.85,IF(BRIEFING!B13="3-4 Dormitórios",1.20,1.0))) | D26: =IF(C26="",B26,C26) | E26: fator | F26: Studios menos louças | IF Tipologia
A27: Fator tipologia elétrica | B27: =IF(BRIEFING!B13="Studios",0.80,IF(BRIEFING!B13="3-4 Dormitórios",1.15,1.0)) | D27: =IF(C27="",B27,C27) | E27: fator | F27: Studios menos pontos | IF Tipologia
A28: Fator entrega (shell) | B28: =IF(BRIEFING!B12="Shell",0.85,1.0) | D28: =IF(C28="",B28,C28) | E28: fator | F28: Shell desconta ~15% total | IF Entrega
A29: PU piso predominante | B29: =IF(BRIEFING!B16="Porcelanato",81.21,IF(BRIEFING!B16="Laminado",65,73))*INDICES!D20 | D29: =IF(C29="",B29,C29) | E29: R$/m² | F29: Tipo piso × padrão | IF Tipo Piso × Padrão (usa D20=efetivo)
A30: Piscina (R$) | B30: =IF(BRIEFING!B17="Aquecida",320000,IF(BRIEFING!B17="Sim",220000,0)) | D30: =IF(C30="",B30,C30) | E30: R$ | F30: Param. base | IF Piscina
A31: Fator pé-direito estrutura | B31: =IF(BRIEFING!B14="Duplo",1.12,IF(BRIEFING!B14="Alto (3.20)",1.05,IF(BRIEFING!B14="Baixo (2.80)",0.97,1.0))) | D31: =IF(C31="",B31,C31) | E31: fator | F31: Pé-dir afeta estrutura | IF Pé-Direito
A32: Fator BWC louças | B32: =IF(VALUE(BRIEFING!B15)>=4,1.80,IF(VALUE(BRIEFING!B15)>=3,1.50,IF(VALUE(BRIEFING!B15)>=2,1.20,1.0))) | D32: =IF(C32="",B32,C32) | E32: fator | F32: Mais bwc = mais louças | IF BWC/apto
A33: Fator viga protendida | B33: =IF(BRIEFING!B4="Protendida",0.08,0.30) | D33: =IF(C33="",B33,C33) | E33: fator | F33: Peso viga/m² conforme laje | IF Laje (0.08 prot / 0.30 conv)
A34: Fator laje protendida | B34: =IF(BRIEFING!B4="Protendida",0.60,0.35) | D34: =IF(C34="",B34,C34) | E34: fator | F34: Peso laje/m² conforme tipo | IF Laje (0.60 prot / 0.35 conv)
A35: Fator hidro BWC | B35: =IF(VALUE(BRIEFING!B15)>=2,1.15,1) | D35: =IF(C35="",B35,C35) | E35: fator | F35: Mais bwc = mais hidro | IF BWC>=2 (1.15 / 1.0)

Sheet CUSTOS_MACROGRUPO
A1: CUSTOS POR MACROGRUPO — BOTTOM-UP COM BRIEFING
A3: Macrogrupo | B3: R$/m² | C3: % Total | D3: Custo Total (R$) | E3: Aba
A4: Gerenciamento | B4: =D4/DADOS_PROJETO!B5 | C4: =D4/D22 | D4: ='Gerenciamento'!G2 | E4: Gerenciamento
A5: Mov. Terra | B5: =D5/DADOS_PROJETO!B5 | C5: =D5/D22 | D5: ='Mov. Terra'!G2 | E5: Mov. Terra
A6: Infraestrutura | B6: =D6/DADOS_PROJETO!B5 | C6: =D6/D22 | D6: ='Infraestrutura'!G2 | E6: Infraestrutura
A7: Supraestrutura | B7: =D7/DADOS_PROJETO!B5 | C7: =D7/D22 | D7: ='Supraestrutura'!G2 | E7: Supraestrutura
A8: Alvenaria | B8: =D8/DADOS_PROJETO!B5 | C8: =D8/D22 | D8: ='Alvenaria'!G2 | E8: Alvenaria
A9: Impermeabilização | B9: =D9/DADOS_PROJETO!B5 | C9: =D9/D22 | D9: ='Impermeabilização'!G2 | E9: Impermeabilização
A10: Instalações | B10: =D10/DADOS_PROJETO!B5 | C10: =D10/D22 | D10: ='Instalações'!G2 | E10: Instalações
A11: Sist. Especiais | B11: =D11/DADOS_PROJETO!B5 | C11: =D11/D22 | D11: ='Sist. Especiais'!G2 | E11: Sist. Especiais
A12: Climatização | B12: =D12/DADOS_PROJETO!B5 | C12: =D12/D22 | D12: ='Climatização'!G2 | E12: Climatização
A13: Rev. Int. Parede | B13: =D13/DADOS_PROJETO!B5 | C13: =D13/D22 | D13: ='Rev. Int. Parede'!G2 | E13: Rev. Int. Parede
A14: Teto | B14: =D14/DADOS_PROJETO!B5 | C14: =D14/D22 | D14: ='Teto'!G2 | E14: Teto
A15: Pisos | B15: =D15/DADOS_PROJETO!B5 | C15: =D15/D22 | D15: ='Pisos'!G2 | E15: Pisos
A16: Pintura | B16: =D16/DADOS_PROJETO!B5 | C16: =D16/D22 | D16: ='Pintura'!G2 | E16: Pintura
A17: Esquadrias | B17: =D17/DADOS_PROJETO!B5 | C17: =D17/D22 | D17: ='Esquadrias'!G2 | E17: Esquadrias
A18: Louças e Metais | B18: =D18/DADOS_PROJETO!B5 | C18: =D18/D22 | D18: ='Louças e Metais'!G2 | E18: Louças e Metais
A19: Fachada | B19: =D19/DADOS_PROJETO!B5 | C19: =D19/D22 | D19: ='Fachada'!G2 | E19: Fachada
A20: Complementares | B20: =D20/DADOS_PROJETO!B5 | C20: =D20/D22 | D20: ='Complementares'!G2 | E20: Complementares
A21: Imprevistos | B21: =D21/DADOS_PROJETO!B5 | C21: =D21/D22 | D21: ='Imprevistos'!G2 | E21: Imprevistos
A22: TOTAL | B22: =D22/DADOS_PROJETO!B5 | D22: =SUM(D4:D21)

Sheet Supraestrutura
A1: SUPRAESTRUTURA | G1: Total:
G2: =F14
A3: Item | B3: Descrição | C3: Qtd | D3: Un | E3: PU (R$) | F3: Total (R$) | G3: Fonte
A4: Concreto Pilares | B4: fck30 | C4: =ROUND(INDICES!D5*DADOS_PROJETO!B5*0.22*INDICES!D31,0) | D4: m³ | E4: 590 | F4: =C4*E4 | G4: Índ×AC×22% × pé-dir (7p)
A5: Concreto Vigas | B5: fck30 | C5: =ROUND(INDICES!D5*DADOS_PROJETO!B5*INDICES!D33,0) | D5: m³ | E5: 590 | F5: =C5*E5 | G5: Índ conc × AC × fator viga (D33)
A6: Concreto Lajes | B6: fck conforme laje | C6: =ROUND(INDICES!D5*DADOS_PROJETO!B5*INDICES!D34,0) | D6: m³ | E6: =IF(INDICES!D10=40,690,590) | F6: =C6*E6 | G6: Índ conc × AC × fator laje (D34)
A7: Concreto Escadas | B7: fck30 | C7: =ROUND(INDICES!D5*DADOS_PROJETO!B5*0.05,0) | D7: m³ | E7: 590 | F7: =C7*E7 | G7: Índ×AC×5%
A8: Concreto Blocos | B8: Baldrame fck30 | C8: =ROUND(INDICES!D5*DADOS_PROJETO!B5*0.05,0) | D8: m³ | E8: 590 | F8: =C8*E8 | G8: Índ×AC×5%
A9: Aço CA-50 | B9: Convencional | C9: =ROUND(INDICES!D6*INDICES!D5*DADOS_PROJETO!B5,0) | D9: kg | E9: 8.67 | F9: =C9*E9 | G9: Índ aço×conc×AC
A10: Cordoalha CP-190 | B10: Protensão | C10: =ROUND(INDICES!D7*DADOS_PROJETO!B5*0.65,0) | D10: kg | E10: 22 | F10: =C10*E10 | G10: IF Prot→8kg/m² laje
A11: Forma | B11: Compensado plastif. | C11: =ROUND(INDICES!D8*INDICES!D5*DADOS_PROJETO!B5,0) | D11: m² | E11: 88.07 | F11: =C11*E11 | G11: Índ forma×conc×AC
A12: Escoramento | B12: Metálico | C12: =ROUND(DADOS_PROJETO!B5*0.65,0) | D12: m² | E12: =INDICES!D9 | F12: =C12*E12 | G12: IF Laje→PU escor
A13: MO Estrutura | B13: Empreitada (32,6%) | C13: =DADOS_PROJETO!B5 | D13: m² | E13: =ROUND((SUM(F4:F12)*0.326/0.674)/DADOS_PROJETO!B5,2) | F13: =C13*E13 | G13: Split 32,6% MO (10p)
A14: TOTAL | F14: =SUM(F4:F13)

Sheet Infraestrutura
A1: INFRAESTRUTURA | G1: Total:
G2: =F13
A3: Item | B3: Descrição | C3: Qtd | D3: Un | E3: PU (R$) | F3: Total (R$) | G3: Fonte
A4: Perfuração hélice | B4: Ø40cm | C4: =ROUND(INDICES!D11*INDICES!D12,0) | D4: m | E4: 82 | F4: =C4*E4 | G4: PU base R$ 82/m (6p)
A5: Concreto estacas | B5: fck30 | C5: =ROUND(INDICES!D11*3.14159*0.04*INDICES!D12,0) | D5: m³ | E5: 632 | F5: =C5*E5 | G5: PU base R$ 632 (6p)
A6: Concreto blocos | B6: Baldrames | C6: =ROUND(0.02*DADOS_PROJETO!B5,0) | D6: m³ | E6: 590 | F6: =C6*E6 | G6: Índ 0,02 m³/m²
A7: Aço CA-50 | B7: Fundação | C7: =ROUND(90*(C5+C6),0) | D7: kg | E7: 8.77 | F7: =C7*E7 | G7: PU base R$ 8,77 (7p)
A8: Forma | B8: Blocos/baldrames | C8: =ROUND(0.10*DADOS_PROJETO!B5,0) | D8: m² | E8: 45.64 | F8: =C8*E8 | G8: PU base R$ 45,64 (8p)
A9: Arrasamento | B9: Estacas | C9: =INDICES!D11 | D9: un | E9: 65 | F9: =C9*E9 | G9: PU base R$ 65 (2p)
A10: Limpeza/remoção | B10: Solo perfuração | C10: 1 | D10: vb | E10: 35000 | F10: =C10*E10 | G10: PU base R$ 35k (2p)
A11: MO fundação | B11: Empreitada (35,5%) | C11: 1 | D11: vb | E11: =ROUND(SUM(F4:F10)*0.355/0.645,0) | F11: =C11*E11 | G11: Split 35,5% (7p)
A12: Contenção | B12: Se houver subsolo | C12: 1 | D12: vb | E12: =INDICES!D24 | F12: =C12*E12 | G12: IF Sub>0
A13: TOTAL | F13: =SUM(F4:F12)

Sheet Mov. Terra
A1: MOV. TERRA | G1: Total:
G2: =F5
A3: Item | B3: Descrição | C3: Qtd | D3: Un | E3: PU (R$) | F3: Total (R$) | G3: Fonte
A4: Terraplanagem | B4: Corte+aterro+bota-fora | C4: =DADOS_PROJETO!B5 | D4: m² | E4: =INDICES!D25 | F4: =C4*E4 | G4: Param. base + IF sub
A5: TOTAL | F5: =SUM(F4:F4)

Sheet Gerenciamento
A1: GERENCIAMENTO | G1: Total:
G2: =F24
A3: Item | B3: Descrição | C3: Qtd | D3: Un | E3: PU (R$) | F3: Total (R$) | G3: Fonte
A4: Projetos | B4: Arq+compl+compat | C4: 1 | D4: vb | E4: 650000 | F4: =C4*E4 | G4: Param. base
A5: Consultorias | B5: ATP+compat BIM | C5: 1 | D5: vb | E5: 180000 | F5: =C5*E5 | G5: Param. base
A6: Ensaios | B6: Ctrl tecnol. | C6: 1 | D6: vb | E6: 130000 | F6: =C6*E6 | G6: Param. base
A7: Taxas e seguros | B7: Incorp+licenças | C7: 1 | D7: vb | E7: 380000 | F7: =C7*E7 | G7: Param. base
A8: Engenheiro PJ | B8: 1×prazo | C8: =DADOS_PROJETO!B11 | D8: mês | E8: 10500 | F8: =C8*E8 | G8: Master R$ 10,5k (5p)
A9: Mestre obras | B9: 1×prazo | C9: =DADOS_PROJETO!B11 | D9: mês | E9: 9940 | F9: =C9*E9 | G9: Master R$ 9,9k (4p)
A10: Encarregado | B10: 1×prazo | C10: =DADOS_PROJETO!B11 | D10: mês | E10: 8000 | F10: =C10*E10 | G10: Narrativo R$ 8k
A11: Estagiário | B11: 2×prazo | C11: =DADOS_PROJETO!B11*2 | D11: mês | E11: 1580 | F11: =C11*E11 | G11: Master R$ 1,6k (3p)
A12: Téc.segurança | B12: 1×prazo | C12: =DADOS_PROJETO!B11 | D12: mês | E12: 6000 | F12: =C12*E12 | G12: PJ R$ 6k/mês
A13: Almoxarife | B13: 1×prazo | C13: =DADOS_PROJETO!B11 | D13: mês | E13: 3377 | F13: =C13*E13 | G13: Master R$ 3,4k (4p)
A14: Limpeza obra | B14: 2×prazo | C14: =DADOS_PROJETO!B11*2 | D14: mês | E14: 2500 | F14: =C14*E14 | G14: PJ R$ 2,5k/mês
A15: Vigilância | B15: 1×prazo | C15: =DADOS_PROJETO!B11 | D15: mês | E15: 15261 | F15: =C15*E15 | G15: Narrativo R$ 15,3k
A16: EPCs | B16: Fixo por porte | C16: 1 | D16: vb | E16: =IF(DADOS_PROJETO!B5<5000,150000,IF(DADOS_PROJETO!B5<15000,300000,500000)) | F16: =C16*E16 | G16: Master 75 exec
A17: EPI | B17: Individual | C17: =DADOS_PROJETO!B11 | D17: mês | E17: 908 | F17: =C17*E17 | G17: PU base R$ 908 (8p)
A18: Meio ambiente | B18: PCMAT+PCMSO | C18: 1 | D18: vb | E18: 45000 | F18: =C18*E18 | G18: Param. base
A19: Op. inicial | B19: Mobilização | C19: 1 | D19: vb | E19: 55000 | F19: =C19*E19 | G19: Param. base
A20: Inst. provisórias | B20: Canteiro+containers | C20: 1 | D20: vb | E20: 160000 | F20: =C20*E20 | G20: Param. base
A21: Desp. consumo | B21: Água+en+internet+IPTU | C21: =DADOS_PROJETO!B11 | D21: mês | E21: 11500 | F21: =C21*E21 | G21: PU base (9p)
A22: Equipamentos | B22: Grua+cremalheira | C22: 1 | D22: vb | E22: 480000 | F22: =C22*E22 | G22: Narrativo
A23: Comunic.visual | B23: Placas+tapume | C23: 1 | D23: vb | E23: 47000 | F23: =C23*E23 | G23: PU base R$ 47k (17p)
A24: TOTAL | F24: =SUM(F4:F23)

Sheet Alvenaria
A1: ALVENARIA | G1: Total:
G2: =F9
A3: Item | B3: Descrição | C3: Qtd | D3: Un | E3: PU (R$) | F3: Total (R$) | G3: Fonte
A4: Bloco cerâm. | B4: Vedação 14cm | C4: =ROUND(INDICES!D13*DADOS_PROJETO!B5*0.40,0) | D4: m² | E4: 32.95 | F4: =C4*E4 | G4: Índ 2,25×40%
A5: Drywall ST | B5: Internas | C5: =ROUND(INDICES!D13*DADOS_PROJETO!B5*0.25,0) | D5: m² | E5: 156 | F5: =C5*E5 | G5: Índ 2,25×25%
A6: Drywall RU | B6: Molhadas | C6: =ROUND(INDICES!D13*DADOS_PROJETO!B5*0.08,0) | D6: m² | E6: 195 | F6: =C6*E6 | G6: Índ 2,25×8%
A7: Argamassa | B7: Assentamento | C7: =ROUND(INDICES!D13*DADOS_PROJETO!B5*0.40,0) | D7: m² | E7: 3.8 | F7: =C7*E7 | G7: PU base
A8: MO Alvenaria | B8: Empreitada | C8: =ROUND(INDICES!D13*DADOS_PROJETO!B5*0.40,0) | D8: m² | E8: 28.5 | F8: =C8*E8 | G8: Split 35,7% (9p)
A9: TOTAL | F9: =SUM(F4:F8)

Sheet Impermeabilização
A1: IMPERMEABILIZAÇÃO | G1: Total:
G2: =F9
A3: Item | B3: Descrição | C3: Qtd | D3: Un | E3: PU (R$) | F3: Total (R$) | G3: Fonte
A4: Manta 4mm | B4: Material | C4: =ROUND(INDICES!D19*DADOS_PROJETO!B5,0) | D4: m² | E4: 82.11 | F4: =C4*E4 | G4: Índ impermeab×AC
A5: Arg.polim. | B5: BWC | C5: =ROUND(INDICES!D19*DADOS_PROJETO!B5*0.3,0) | D5: m² | E5: 8.5 | F5: =C5*E5 | G5: PU base
A6: Regulariz. | B6: Superfície | C6: =ROUND(INDICES!D19*DADOS_PROJETO!B5,0) | D6: m² | E6: 5.57 | F6: =C6*E6 | G6: PU base (15p)
A7: MO imper. | B7: Empreitada | C7: =ROUND(INDICES!D19*DADOS_PROJETO!B5,0) | D7: m² | E7: 68 | F7: =C7*E7 | G7: Split 56,5% (6p)
A8: MO regul. | B8: Empreitada | C8: =ROUND(INDICES!D19*DADOS_PROJETO!B5,0) | D8: m² | E8: 19.5 | F8: =C8*E8 | G8: PU base (7p)
A9: TOTAL | F9: =SUM(F4:F8)

Sheet Instalações
A1: INSTALAÇÕES | G1: Total:
G2: =F11
A3: Item | B3: Descrição | C3: Qtd | D3: Un | E3: PU (R$) | F3: Total (R$) | G3: Fonte
A4: Elétricas mat. | B4: IF Tipologia | C4: =DADOS_PROJETO!B5 | D4: m² | E4: =ROUND(130*(DADOS_PROJETO!B12/2752.67)/1.1*0.618*INDICES!D27,2) | F4: =C4*E4 | G4: Índ 1,77m/m² × fator tipol (D27)
A5: Elétricas MO | B5: Empreitada | C5: =DADOS_PROJETO!B5 | D5: m² | E5: =ROUND(130*(DADOS_PROJETO!B12/2752.67)/1.1*0.382*INDICES!D27,2) | F5: =C5*E5 | G5: Split 38,2% × fator tipol (D27)
A6: Hidro mat. | B6: IF BWC/apto | C6: =DADOS_PROJETO!B5 | D6: m² | E6: =ROUND(145*(DADOS_PROJETO!B12/2752.67)/1.1*0.66*INDICES!D35,2) | F6: =C6*E6 | G6: Índ 1,08m/m² × fator hidro (D35)
A7: Hidro MO | B7: Empreitada | C7: =DADOS_PROJETO!B5 | D7: m² | E7: =ROUND(145*(DADOS_PROJETO!B12/2752.67)/1.1*0.34*INDICES!D35,2) | F7: =C7*E7 | G7: Split 34,0% × fator hidro (D35)
A8: Preventivas | B8: Mat+MO | C8: =DADOS_PROJETO!B5 | D8: m² | E8: =ROUND(45*(DADOS_PROJETO!B12/2752.67)/1.1,2) | F8: =C8*E8 | G8: Param.
A9: Gás | B9: Mat+MO | C9: =DADOS_PROJETO!B5 | D9: m² | E9: =ROUND(18*(DADOS_PROJETO!B12/2752.67)/1.1,2) | F9: =C9*E9 | G9: Param. base
A10: Telecom | B10: Mat+MO | C10: =DADOS_PROJETO!B5 | D10: m² | E10: =ROUND(15*(DADOS_PROJETO!B12/2752.67)/1.1,2) | F10: =C10*E10 | G10: Param. base
A11: TOTAL | F11: =SUM(F4:F10)

Sheet Sist. Especiais
A1: SIST. ESPECIAIS | G1: Total:
G2: =F15
A3: Item | B3: Descrição | C3: Qtd | D3: Un | E3: PU (R$) | F3: Total (R$) | G3: Fonte
A4: Elevador social | B4: N-1 elevadores | C4: =MAX(1,DADOS_PROJETO!B9-1) | D4: un | E4: 192450 | F4: =C4*E4 | G4: PU base (5p)
A5: Elevador serv. | B5: 1un | C5: 1 | D5: un | E5: 96000 | F5: =C5*E5 | G5: PU base (5p)
A6: Gerador | B6: IF Gerador+Torres | C6: 1 | D6: vb | E6: =INDICES!D23 | F6: =C6*E6 | G6: IF Gerador B11 + Torres B10
A7: Automação | B7: BMS+sensores | C7: 1 | D7: vb | E7: 120000 | F7: =C7*E7 | G7: Param. base
A8: Piscina | B8: IF Piscina B17 | C8: 1 | D8: vb | E8: =INDICES!D30 | F8: =C8*E8 | G8: IF Piscina (Sim/Não/Aquecida)
A9: CFTV | B9: Câmeras+DVR | C9: 1 | D9: vb | E9: 120000 | F9: =C9*E9 | G9: Param. base
A10: Pressurização | B10: IF Pressurização B9 | C10: 1 | D10: vb | E10: =INDICES!D22 | F10: =C10*E10 | G10: IF Pressurização
A11: SPDA | B11: Para-raios+malha | C11: 1 | D11: vb | E11: 55000 | F11: =C11*E11 | G11: Param. base
A12: Interfonia | B12: Ctrl acesso | C12: 1 | D12: vb | E12: 130000 | F12: =C12*E12 | G12: Param. base
A13: Bombas | B13: Recalque+incêndio | C13: 1 | D13: vb | E13: 95000 | F13: =C13*E13 | G13: Param. base
A14: Quadros comando | B14: Bombas+sist | C14: 1 | D14: vb | E14: 60000 | F14: =C14*E14 | G14: Param. base
A15: TOTAL | F15: =SUM(F4:F14)

Sheet Climatização
A1: CLIMATIZAÇÃO | G1: Total:
G2: =F8
A3: Item | B3: Descrição | C3: Qtd | D3: Un | E3: PU (R$) | F3: Total (R$) | G3: Fonte
A4: Split | B4: 1,5/apto | C4: =ROUND(DADOS_PROJETO!B6*1.5,0) | D4: un | E4: 3500 | F4: =C4*E4 | G4: Param. 1,5/apto
A5: Exaust.BWC | B5: 4/pav enclaus. | C5: =4*DADOS_PROJETO!B8 | D5: un | E5: 1200 | F5: =C5*E5 | G5: 4 bwc/pav
A6: Exaust.churr. | B6: 2/pav+lazer | C6: =2*DADOS_PROJETO!B8+2 | D6: un | E6: 2500 | F6: =C6*E6 | G6: 2/pav+lazer
A7: Infra AR | B7: Dutos+tub | C7: =DADOS_PROJETO!B5 | D7: m² | E7: 10 | F7: =C7*E7 | G7: PU base
A8: TOTAL | F8: =SUM(F4:F7)

Sheet Rev. Int. Parede
A1: REV. INT. PAREDE | G1: Total:
G2: =F15
A3: Item | B3: Descrição | C3: Qtd | D3: Un | E3: PU (R$) | F3: Total (R$) | G3: Fonte
A4: Reboco | B4: Massa única | C4: =ROUND(INDICES!D15*DADOS_PROJETO!B5*0.35,0) | D4: m² | E4: 7 | F4: =C4*E4 | G4: Índ 2,85×35%
A5: Chapisco | B5: Rolado+colante | C5: =ROUND(INDICES!D15*DADOS_PROJETO!B5*0.35,0) | D5: m² | E5: 5.5 | F5: =C5*E5 | G5: PU base
A6: Cerâm.BWC | B6: 30×60 | C6: =ROUND(INDICES!D15*DADOS_PROJETO!B5*0.14,0) | D6: m² | E6: =48*INDICES!D20 | F6: =C6*E6 | G6: PU×fator padrão
A7: Cerâm.cozinha | B7: 30×60 | C7: =ROUND(INDICES!D15*DADOS_PROJETO!B5*0.06,0) | D7: m² | E7: =42*INDICES!D20 | F7: =C7*E7 | G7: PU×fator padrão
A8: Porcel.parede | B8: Comuns | C8: =ROUND(INDICES!D15*DADOS_PROJETO!B5*0.04,0) | D8: m² | E8: =85*INDICES!D20 | F8: =C8*E8 | G8: PU×fator padrão
A9: Granito bancadas | B9: Lavat+coz | C9: =ROUND(DADOS_PROJETO!B6*3.5,0) | D9: m | E9: =180*INDICES!D20 | F9: =C9*E9 | G9: R$ 180×fator padrão
A10: Arg.colante | B10: AC-II/III | C10: =ROUND(INDICES!D15*DADOS_PROJETO!B5*0.24,0) | D10: m² | E10: 12 | F10: =C10*E10 | G10: PU base
A11: Rejunte | B11: Flexível | C11: =ROUND(INDICES!D15*DADOS_PROJETO!B5*0.24,0) | D11: m² | E11: 5 | F11: =C11*E11 | G11: PU base
A12: MO reboco | B12: Empreitada | C12: =ROUND(INDICES!D15*DADOS_PROJETO!B5*0.35,0) | D12: m² | E12: 22.5 | F12: =C12*E12 | G12: Split 54,4%
A13: MO cerâmica | B13: Assentamento | C13: =ROUND(INDICES!D15*DADOS_PROJETO!B5*0.24,0) | D13: m² | E13: 35 | F13: =C13*E13 | G13: Split 54,4%
A14: MO granito | B14: Instalação | C14: =ROUND(DADOS_PROJETO!B6*3.5,0) | D14: m | E14: 35.9 | F14: =C14*E14 | G14: PU base R$ 36
A15: TOTAL | F15: =SUM(F4:F14)

Sheet Teto
A1: TETO | G1: Total:
G2: =F8
A3: Item | B3: Descrição | C3: Qtd | D3: Un | E3: PU (R$) | F3: Total (R$) | G3: Fonte
A4: Forro ST | B4: Acartonado | C4: =ROUND(INDICES!D16*DADOS_PROJETO!B5*0.70,0) | D4: m² | E4: 28 | F4: =C4*E4 | G4: Índ 1,16×70%
A5: Forro RU | B5: BWC | C5: =ROUND(INDICES!D16*DADOS_PROJETO!B5*0.15,0) | D5: m² | E5: 35 | F5: =C5*E5 | G5: PU base
A6: Perfis | B6: Estrutura | C6: =ROUND(INDICES!D16*DADOS_PROJETO!B5*0.85,0) | D6: m² | E6: 15 | F6: =C6*E6 | G6: PU base
A7: MO forro | B7: Empreitada | C7: =ROUND(INDICES!D16*DADOS_PROJETO!B5,0) | D7: m² | E7: 25 | F7: =C7*E7 | G7: Split 79,1%
A8: TOTAL | F8: =SUM(F4:F7)

Sheet Pisos
A1: PISOS | G1: Total:
G2: =F11
A3: Item | B3: Descrição | C3: Qtd | D3: Un | E3: PU (R$) | F3: Total (R$) | G3: Fonte
A4: Contrapiso | B4: Autonivelante | C4: =ROUND(INDICES!D14*DADOS_PROJETO!B5,0) | D4: m² | E4: 12.1 | F4: =C4*E4 | G4: Índ piso×AC (IF shell)
A5: Piso principal | B5: IF Tipo Piso | C5: =ROUND(INDICES!D14*DADOS_PROJETO!B5*0.50,0) | D5: m² | E5: =INDICES!D29 | F5: =C5*E5 | G5: PU IF Tipo Piso × Padrão
A6: Cimentado | B6: Garagem 20% | C6: =ROUND(INDICES!D14*DADOS_PROJETO!B5*0.20,0) | D6: m² | E6: 32 | F6: =C6*E6 | G6: PU base
A7: Granito | B7: Halls 5% | C7: =ROUND(INDICES!D14*DADOS_PROJETO!B5*0.05,0) | D7: m² | E7: =180*INDICES!D20 | F7: =C7*E7 | G7: PU×fator padrão
A8: Rodapé | B8: Poliestireno | C8: =ROUND(INDICES!D14*DADOS_PROJETO!B5*0.35,0) | D8: m | E8: 10.77 | F8: =C8*E8 | G8: PU base (10p)
A9: MO contrapiso | B9: Empreitada | C9: =ROUND(INDICES!D14*DADOS_PROJETO!B5,0) | D9: m² | E9: 18 | F9: =C9*E9 | G9: Split 54%
A10: MO pisos | B10: Assentamento | C10: =ROUND(INDICES!D14*DADOS_PROJETO!B5*0.70,0) | D10: m² | E10: 32 | F10: =C10*E10 | G10: Split 54%
A11: TOTAL | F11: =SUM(F4:F10)

Sheet Pintura
A1: PINTURA | G1: Total:
G2: =F10
A3: Item | B3: Descrição | C3: Qtd | D3: Un | E3: PU (R$) | F3: Total (R$) | G3: Fonte
A4: Massa PVA | B4: Paredes 2dem | C4: =ROUND(INDICES!D17*DADOS_PROJETO!B5*0.55,0) | D4: m² | E4: 4.29 | F4: =C4*E4 | G4: Índ pintura×55%
A5: Acrílica par. | B5: 3 demãos | C5: =ROUND(INDICES!D17*DADOS_PROJETO!B5*0.55,0) | D5: m² | E5: 5.4 | F5: =C5*E5 | G5: PU base (6p)
A6: Acrílica teto | B6: 2 demãos | C6: =ROUND(INDICES!D17*DADOS_PROJETO!B5*0.20,0) | D6: m² | E6: 3.83 | F6: =C6*E6 | G6: PU base
A7: Selador | B7: Base | C7: =ROUND(INDICES!D17*DADOS_PROJETO!B5*0.75,0) | D7: m² | E7: 2.5 | F7: =C7*E7 | G7: PU base
A8: MO pintura | B8: Empreitada | C8: =ROUND(INDICES!D17*DADOS_PROJETO!B5,0) | D8: m² | E8: 15 | F8: =C8*E8 | G8: Split 66,2%
A9: MO lixamento | B9: Preparação | C9: =ROUND(INDICES!D17*DADOS_PROJETO!B5*0.55,0) | D9: m² | E9: 8 | F9: =C9*E9 | G9: Split 66,2%
A10: TOTAL | F10: =SUM(F4:F9)

Sheet Esquadrias
A1: ESQUADRIAS | G1: Total:
G2: =F6
A3: Item | B3: Descrição | C3: Qtd | D3: Un | E3: PU (R$) | F3: Total (R$) | G3: Fonte
A4: Esquadrias Al | B4: Jan+portas | C4: =DADOS_PROJETO!B5 | D4: m² | E4: =280*INDICES!D20*INDICES!D28 | F4: =C4*E4 | G4: R$280 × padrão × entrega
A5: Serralheria | B5: GC+corrimão | C5: =DADOS_PROJETO!B5 | D5: m² | E5: =45*INDICES!D20 | F5: =C5*E5 | G5: R$45 × fator padrão
A6: TOTAL | F6: =SUM(F4:F5)

Sheet Louças e Metais
A1: LOUÇAS E METAIS | G1: Total:
G2: =F5
A3: Item | B3: Descrição | C3: Qtd | D3: Un | E3: PU (R$) | F3: Total (R$) | G3: Fonte
A4: Louças+metais | B4: IF Tipol+BWC+Padrão+Entrega | C4: =DADOS_PROJETO!B6 | D4: apto | E4: =2800*INDICES!D20*INDICES!D26*INDICES!D32*INDICES!D28 | F4: =C4*E4 | G4: R$2800 × padrão × tipol × bwc × entrega
A5: TOTAL | F5: =SUM(F4:F4)

Sheet Fachada
A1: FACHADA | G1: Total:
G2: =F7
A3: Item | B3: Descrição | C3: Qtd | D3: Un | E3: PU (R$) | F3: Total (R$) | G3: Fonte
A4: Revestimento | B4: Conforme briefing | C4: =ROUND(INDICES!D18*DADOS_PROJETO!B5,0) | D4: m² | E4: =INDICES!D21 | F4: =C4*E4 | G4: IF tipo fachada
A5: MO fachada | B5: Empreitada | C5: =ROUND(INDICES!D18*DADOS_PROJETO!B5,0) | D5: m² | E5: 35 | F5: =C5*E5 | G5: PU base
A6: Balancim | B6: Fachadeiro | C6: =ROUND(INDICES!D18*DADOS_PROJETO!B5,0) | D6: m² | E6: 18 | F6: =C6*E6 | G6: PU base
A7: TOTAL | F7: =SUM(F4:F6)

Sheet Complementares
A1: COMPLEMENTARES | G1: Total:
G2: =F14
A3: Item | B3: Descrição | C3: Qtd | D3: Un | E3: PU (R$) | F3: Total (R$) | G3: Fonte
A4: Mobiliário | B4: Áreas comuns | C4: 1 | D4: vb | E4: 540000 | F4: =C4*E4 | G4: PU base R$ 540k (5p)
A5: Ambientação | B5: Decoração halls | C5: 1 | D5: vb | E5: =300000*INDICES!D20 | F5: =C5*E5 | G5: R$ 300k×fator padrão
A6: Paisagismo | C6: 1 | D6: vb | E6: 120000 | F6: =C6*E6 | G6: Param. base
A7: Equip. lazer | B7: Acad+playground | C7: 1 | D7: vb | E7: 180000 | F7: =C7*E7 | G7: PU base (8p)
A8: Limpeza final | C8: =DADOS_PROJETO!B5 | D8: m² | E8: 12 | F8: =C8*E8 | G8: PU base R$ 12/m² (10p)
A9: Comunic.visual | B9: Sinalização | C9: 1 | D9: vb | E9: 47000 | F9: =C9*E9 | G9: PU base R$ 47k (17p)
A10: Cobertura | B10: Telhado+estrutura | C10: =ROUND(DADOS_PROJETO!B5*0.04,0) | D10: m² | E10: 95 | F10: =C10*E10 | G10: PU base
A11: Ligações def. | B11: Água+energia+gás | C11: 1 | D11: vb | E11: 60000 | F11: =C11*E11 | G11: Param. base
A12: Desmobilização | B12: Pessoal+equip | C12: 1 | D12: vb | E12: 15000 | F12: =C12*E12 | G12: PU base (6p)
A13: Paviment.ext. | B13: Calçadas | C13: =ROUND(DADOS_PROJETO!B5*0.06,0) | D13: m² | E13: 80 | F13: =C13*E13 | G13: PU base
A14: TOTAL | F14: =SUM(F4:F13)

Sheet Imprevistos
A1: IMPREVISTOS | G1: Total:
G2: =F5
A3: Item | B3: Descrição | C3: Qtd | D3: Un | E3: PU (R$) | F3: Total (R$) | G3: Fonte
A4: Imprevistos | B4: 1,5% do subtotal | C4: 1 | D4: vb | E4: =ROUND(SUM(CUSTOS_MACROGRUPO!D4:D20)*0.015,0) | F4: =C4*E4 | G4: Percentual padrão
A5: TOTAL | F5: =SUM(F4:F4)

Sheet PREMISSAS
A2: PARAMÉTRICO V2 — Flow da Lagoa
A3: 18/18 macrogrupos bottom-up | 14 dropdowns interativos
A4: Altere os dropdowns na aba BRIEFING para recalcular automaticamente
A6: FONTES: calibration-indices.json (75 exec + 79 narrativos + IFC + curva ABC)
A7: PUs: base-pus-cartesian.json (1.504 itens, medianas de 75 executivos)
A8: Splits MO/Material: medianas reais de 38 executivos detalhados
A10: 14 DROPDOWNS ATIVOS:
A11: 1. Laje: Convencional/Protendida/Nervurada → concreto, aço, forma, escoramento
A12: 2. Subsolos: 0-3 → contenção, mov.terra, impermeabilização, fundação
A13: 3. Fundação: Hélice/Tubulão/Sapata → infraestrutura
A14: 4. Padrão: Médio/Médio-Alto/Alto/Luxo → acabamentos, esquadrias, louças (×0.85-1.35)
A15: 5. Fachada: Textura/Cerâmica/Pele de vidro/ACM → PU fachada R$ 100-350/m²
... A26: Baseado revisão Patricia (coord. custos) + calibração 75 exec — 24/mar/2026

Sheet BDI_PREMISSAS
A1: BDI / BIFES - CENÁRIOS PARA VALIDAÇÃO
A3: Cenário | B3: BDI | C3: Custo direto | D3: Preço com BDI | E3: Observação
A4: Sem BDI | B4: 0 | C4: 55202282 | D4: 55202282 | E4: uso para custo direto/obra
A5: BDI 15% | B5: 0.15 | C5: 55202282 | D5: 63482624 | E5: referência enxuta
A6: BDI 20% | B6: 0.2 | C6: 55202282 | D6: 66242738 | E6: referência intermediária
A7: BDI 25% | B7: 0.25 | C7: 55202282 | D7: 69002852 | E7: referência conservadora

Sheet FLOW_FONTES
A1: FONTES E BENCHMARKS USADOS NO V01
A3: Dados extraídos do projeto
A4: Campo | B4: Valor | C4: Fonte
A5: Área construída | B5: 15.000,62 m² | C5: ARQ AP 008 CORTE/TABELAS R12, quadro Área Total a Construir
A6: Área computável | B6: 8.122,55 m² | C6: ARQ AP 008 CORTE/TABELAS R12, quadro Área Total a Construir
A7: Área privativa | B7: 8.343,90 m² | C7: ARQ AP 008 CORTE/TABELAS R12, quadro Área Privativa
A8: Pavimentos principais | B8: NA01 a NA06 | C8: ARQ AP 008 CORTE/TABELAS R12 e cortes
A9: Níveis técnicos | B9: NA07 Barrilete, NA08 Reservatório Superior, NA09 Tampa | C9: ARQ AP 008 CORTE/TABELAS R12
A10: Vagas automóveis | B10: 161 | C10: Quadro de vagas: 4 comerciais + 149 privativas + 8 visitantes
A11: Vagas bicicleta | B11: 213 | C11: Quadro de vagas: 5 comerciais + 198 privativas + 10 visitantes
A12: Núcleos verticais | B12: 4 | C12: Leitura visual das plantas e cortes; elevadores a validar
A13: Unidades residenciais | B13: 236 | C13: Premissa por área privativa média de 35,36 m²/UR; quadro de unidades não encontrado
A14: Estrutura | B14: Lajes maciças/mistas e=20 cm | C14: IFC estrutural R06: slabs, beams e columns; sem indício de protensão
A15: Piscina | B15: Sim | C15: Há disciplina PISCINA com DWG/PDF/IFC
A18: Calibração Supabase por macrogrupo
A19: Padrão | B19: Macrogrupo | C19: N | D19: P25 | E19: Mediana | F19: P75
A20: Médio-Alto | B20: Alvenaria | C20: 33 | D20: 121.14 | E20: 139.7 | F20: 167.52
A21: Médio-Alto | B21: Climatização | C21: 9 | D21: 29.37 | E21: 30.59 | F21: 68.2
A22: Médio-Alto | B22: Complementares | C22: 27 | D22: 129.36 | E22: 201.06 | F22: 293.93
A23: Médio-Alto | B23: Esquadrias | C23: 35 | D23: 256.91 | E23: 301.24 | F23: 475.17
A24: Médio-Alto | B24: Fachada | C24: 20 | D24: 84.26 | E24: 117.38 | F24: 166.19
A25: Médio-Alto | B25: Gerenciamento | C25: 36 | D25: 339.65 | E25: 474.74 | F25: 1223.46
A26: Médio-Alto | B26: Impermeabilização | C26: 33 | D26: 41.71 | E26: 60 | F26: 93.23
A27: Médio-Alto | B27: Imprevistos | C27: 15 | D27: 44.33 | E27: 49.98 | F27: 72.41
A28: Médio-Alto | B28: Infraestrutura | C28: 37 | D28: 141.55 | E28: 196.14 | F28: 240.53
A29: Médio-Alto | B29: Instalações | C29: 33 | D29: 281.74 | E29: 332.12 | F29: 411.27
A30: Médio-Alto | B30: Louças e Metais | C30: 24 | D30: 39.6 | E30: 59.73 | F30: 147.71
A31: Médio-Alto | B31: Movimentação de Terra | C31: 37 | D31: 82.18 | E31: 114.52 | F31: 147.52
... A55: Alto | B55: Teto | C55: 12 | D55: 52.54 | E55: 62.23 | F55: 85.03
A58: PUs Supabase / Ampli
A59: Fonte | B59: Descrição | C59: Unidade | D59: Projetos | E59: Obs | F59: P25/Min | G59: Med/Avg | H59: P75/Max
A60: Supabase | B60: Concreto usinado bombeável fck 40 MPa | C60: m³ | D60: 37 | E60: 136 | F60: 444.15 | G60: 477.75 | H60: 551.25
A61: Supabase | B61: Concreto usinado 40 MPa para estacas | C61: m³ | D61: 16 | E61: 51 | F61: 502 | G61: 517.65 | H61: 565
A62: Supabase | B62: Esquadrias de alumínio - G2 | C62: m² | D62: 77 | E62: 40 | F62: 824 | G62: 939.74 | H62: 1049.07
A63: Supabase | B63: Fornecimento e instalação de esquadrias de alumínio | C63: m² | D63: 39 | E63: 29 | F63: 1050 | G63: 1088.02 | H63: 1250
A64: Supabase | B64: Elevadores | C64: un | D64: 43 | E64: 10 | F64: 197190 | G64: 261192.12 | H64: 326782.5
A65: Supabase | B65: Elevador social | C65: un | D65: 27 | E65: 9 | F65: 107927.75 | G65: 220000 | H65: 405000
A66: Supabase | B66: TOTAL IMPERMEABILIZAÇÃO | C66: R$/m² AC | D66: 88 | E66: 111 | F66: 47.92 | G66: 61.39 | H66: 87.54
A67: Supabase | B67: Mão de obra porcelanato piso | C67: m² | D67: 17 | E67: 40 | F67: 42 | G67: 48 | H67: 48
A68: Supabase | B68: Pintura latex acrílica paredes internas | C68: m² | D68: 32 | E68: 37 | F68: 6.12 | G68: 6.12 | H68: 11.23
...
