Workbook
Name \0: #REF!
Name \0: #REF!
Name \1: #REF!
Name \a: #REF!
Name \a: #REF!
Name \b: #REF!
Name \c: #REF!
Name \d: #REF!
Name \e: #REF!
Name \i: #REF!
Name \J: #REF!
Name \k: #REF!
Name \l: #N/A
Name \m: #REF!
Name \m: #REF!
Name \o: #REF!
Name \p: #REF!
Name \r: #REF!
Name \T: #REF!
Name \z: #REF!
Name ______ACR10: #REF!
Name ______ACR15: #REF!
Name ______acr20: #REF!
Name ______acr5: #REF!
Name ______ARQ1: #REF!
Name ______QT100: #REF!
Name ______QT2: #REF!
Name ______QT3: #REF!
Name ______QT4: #REF!
Name ______QT50: #REF!
Name ______QT75: #REF!
Name _____ACR10: #REF!
Name _____ACR15: #REF!
Name _____acr20: #REF!
Name _____acr5: #REF!
Name _____ARQ1: #REF!
Name _____QT100: #REF!
Name _____QT2: #REF!
Name _____QT3: #REF!
Name _____QT4: #REF!
Name _____QT50: #REF!
Name _____QT75: #REF!
Name ___ACR10: #REF!
Name ___ACR15: #REF!
Name ___acr20: #REF!
Name ___acr5: #REF!
Name ___ARQ1: #REF!
Name ___QT100: #REF!
Name ___QT2: #REF!
Name ___QT3: #REF!
Name ___QT4: #REF!
Name ___QT50: #REF!
Name ___QT75: #REF!
Name __ACR10: #REF!
Name __ACR15: #REF!
Name __acr20: #REF!
Name __acr5: #REF!
Name __ARQ1: #REF!
Name __Axe3: #REF!
Name __Axe4: #REF!

Sheet ORÇAMENTO EXECUTIVO
A1: ETAPA | B1: Orçamento Executivo
B2: VALOR | C2: % | D2: VALOR / m² | F2: ÁREA CONSTRUÍDA | G2: 11102.72 | H2: m²
A3: GERENCIAMENTO TÉCNICO E ADMINISTRATIVO | B3: ='[2]Obra '!$C$32 -> 4073248.1 | C3: =B3/$B$19 -> 0.10110362 | D3: =B3/$G$2 -> 366.86939
A4: MOVIMENTAÇÃO DE TERRA | B4: ='[2]Obra '!$C$33 -> 198728.54 | C4: =B4/$B$19 -> 0.0049327159 | D4: =B4/$G$2 -> 17.899086
A5: INFRAESTRUTURA | B5: ='[2]Obra '!$C$34 -> 1941462.1 | C5: =B5/$B$19 -> 0.04818976 | D5: =B5/$G$2 -> 174.86365
A6: SUPRAESTRUTURA | B6: ='[2]Obra '!$C$35 -> 6615187.4 | C6: =B6/$B$19 -> 0.16419805 | D6: =B6/$G$2 -> 595.81682
A7: ALVENARIA | B7: ='[2]Obra '!$C$36 -> 1669934.2 | C7: =B7/$B$19 -> 0.041450064 | D7: =B7/$G$2 -> 150.40766
A8: INSTALAÇÕES ELÉTRICAS, HIDRÁULICAS, GLP E PREVENTIVAS | B8: ='[2]Obra '!$C$37 -> 4311922.1 | C8: =B8/$B$19 -> 0.10702784 | D8: =B8/$G$2 -> 388.36628
A9: EQUIPAMENTOS E SISTEMAS ESPECIAIS | B9: ='[2]Obra '!$C$38 -> 1997062.3 | C9: =B9/$B$19 -> 0.049569833 | D9: =B9/$G$2 -> 179.87144
A10: IMPERMEABILIZAÇÃO | B10: ='[2]Obra '!$C$39 -> 948728.57 | C10: =B10/$B$19 -> 0.023548748 | D10: =B10/$G$2 -> 85.450103
A11: REVESTIMENTOS E ACABAMENTOS INTERNOS EM PAREDE | B11: ='[2]Obra '!$C$40 -> 3214008.9 | C11: =B11/$B$19 -> 0.079776121 | D11: =B11/$G$2 -> 289.47941
A12: REVESTIMENTOS E ACABAMENTOS INTERNOS EM TETO | B12: ='[2]Obra '!$C$41 -> 753156.1 | C12: =B12/$B$19 -> 0.01869437 | D12: =B12/$G$2 -> 67.835278
A13: REVESTIMENTOS E ACABAMENTOS INTERNOS EM PISO | B13: ='[2]Obra '!$C$42 -> 4313008.2 | C13: =B13/$B$19 -> 0.1070548 | D13: =B13/$G$2 -> 388.4641
A14: PINTURA INTERNA | B14: ='[2]Obra '!$C$43 -> 1273615.9 | C14: =B14/$B$19 -> 0.031612897 | D14: =B14/$G$2 -> 114.71206
A15: ESQUADRIAS, VIDROS E FERRAGENS | B15: ='[2]Obra '!$C$44 -> 3821896.6 | C15: =B15/$B$19 -> 0.094864731 | D15: =B15/$G$2 -> 344.23066
A16: COBERTURA | B16: ='[2]Obra '!$C$45 -> 375409.41 | C16: =B16/$B$19 -> 0.0093181779 | D16: =B16/$G$2 -> 33.812382
A17: REVESTIMENTOS E ACABAMENTOS DE FACHADA | B17: ='[2]Obra '!$C$46 -> 1517055.6 | C17: =B17/$B$19 -> 0.037655407 | D17: =B17/$G$2 -> 136.63819
A18: SERVIÇOS COMPLEMENTARES | B18: ='[2]Obra '!$C$47 -> 3263431.9 | C18: =B18/$B$19 -> 0.08100287 | D18: =B18/$G$2 -> 293.93085
A19: TOTAL | B19: =SUM(B3:B18) -> 40287856 | C19: =SUM(C3:C18) -> 1 | D19: =SUM(D3:D18) -> 3628.6474
A20: CUB/SC | B20: 2911.91 | C20: 45870 | D20: =ROUNDUP(+D19/B20,2)&" CUB" -> 1,25 CUB
B24: 2007.57
B25: 2461.35
B26: =B25/B24 -> 1.2260345
D29: 1.1023
A31: 900,00 - 1100 | B31: 900
A32: 25,00 - 30,00 | B32: 25
A33: 15,00 - 22,00 | B33: 15
A34: 150,00 - 200,00 | B34: 150
A35: 440,00 - 510,00 | B35: 440
A36: -
A37: 55,00 - 70,00 | B37: 55
A38: 170,00 - 200,00 | B38: 170
A39: 165,00 - 230,00 | B39: 165
A40: 40,00 - 70,00 | B40: 40
A41: 55,00 - 77,00 | B41: 55
A42: 35,00 - 50,00 | B42: 35
A43: 130,00 - 175,00 | B43: 130
A44: 35,00 - 65,00 | B44: 35
A45: 35,00 - 55,00 | B45: 35
A46: 430,00 - 550,00 | B46: 430
...

Sheet Versões
A1: ETAPA | B1: Preliminar R01 | D1: Preliminar R01 indexado | F1: Orçamento Executivo | H1: Diferença
B2: VALOR | C2: VALOR / m² | D2: VALOR | E2: VALOR / m² | F2: VALOR | G2: VALOR / m² | H2: VALOR | I2: VALOR / m² | J2: Justificativas | L2: ÁREA CONSTRUÍDA | M2: 11102.72 | N2: m²
A3: GERENCIAMENTO TÉCNICO E ADMINISTRATIVO | B3: =[1]Versões!$E$3 -> 3400044 | C3: =B3/'[2]Obra '!$E$9 -> 306.23523 | D3: =B3/$B$20*$D$20 -> 3484282 | E3: =D3/'[2]Obra '!$E$9 -> 313.82238 | F3: ='[2]Obra '!$C$32 -> 4073248.1 | G3: =F3/$M$2 -> 366.86939 | H3: =F3-D3 -> 588966.03 | I3: =G3-E3 -> 53.047004
A4: MOVIMENTAÇÃO DE TERRA | B4: =[1]Versões!$E$4 -> 949970.27 | C4: 296.08146 | D4: =B4/$B$20*$D$20 -> 973506.31 | E4: =D4/'[2]Obra '!$E$9 -> 87.681785 | F4: ='[2]Obra '!$C$33 -> 198728.54 | G4: =F4/$M$2 -> 17.899086 | H4: =F4-D4 -> -774777.77 | I4: =G4-E4 -> -69.782699 | J4: * Revisão de quantidades de fundação rasa
A5: INFRAESTRUTURA | B5: =[1]Versões!$E$5 -> 2915254.7 | C5: =B5/'[2]Obra '!$E$9 -> 262.57121 | D5: =B5/$B$20*$D$20 -> 2987481.7 | E5: =D5/'[2]Obra '!$E$9 -> 269.07656 | F5: ='[2]Obra '!$C$34 -> 1941462.1 | G5: =F5/$M$2 -> 174.86365 | H5: =F5-D5 -> -1046019.6 | I5: =G5-E5 -> -94.212916 | J5: *Além da revisão da fundação rasa ivemos redução do que se tinha estimado também em fundação profunda além da redução do diâmetro tivemos redução na profundidade de 18 para 12m.
A6: SUPRAESTRUTURA | B6: =[1]Versões!$E$6 -> 8246852.6 | C6: =B6/'[2]Obra '!$E$9 -> 742.77768 | D6: =B6/$B$20*$D$20 -> 8451172.9 | E6: =D6/'[2]Obra '!$E$9 -> 761.18041 | F6: ='[2]Obra '!$C$35 -> 6615187.4 | G6: =F6/$M$2 -> 595.81682 | H6: =F6-D6 -> -1835985.6 | I6: =G6-E6 -> -165.36358 | J6: *Revisão com os quantitativos do projetista
A7: ALVENARIA | B7: =[1]Versões!$E$7 -> 1936039.1 | C7: =B7/'[2]Obra '!$E$9 -> 174.37521 | D7: =B7/$B$20*$D$20 -> 1984005.5 | E7: =D7/'[2]Obra '!$E$9 -> 178.69545 | F7: ='[2]Obra '!$C$36 -> 1669934.2 | G7: =F7/$M$2 -> 150.40766 | H7: =F7-D7 -> -314071.34 | I7: =G7-E7 -> -28.287784
A8: INSTALAÇÕES ELÉTRICAS, HIDRÁULICAS, GLP E PREVENTIVAS | B8: =[1]Versões!$E$8 -> 4059519.6 | C8: =B8/'[2]Obra '!$E$9 -> 365.63289 | D8: =B8/$B$20*$D$20 -> 4160096.5 | E8: =D8/'[2]Obra '!$E$9 -> 374.69165 | F8: ='[2]Obra '!$C$37 -> 4311922.1 | G8: =F8/$M$2 -> 388.36628 | H8: =F8-D8 -> 151825.58 | I8: =G8-E8 -> 13.67463
A9: EQUIPAMENTOS E SISTEMAS ESPECIAIS | B9: =[1]Versões!$E$9 -> 1816668.7 | C9: =B9/'[2]Obra '!$E$9 -> 163.62375 | D9: =B9/$B$20*$D$20 -> 1861677.7 | E9: =D9/'[2]Obra '!$E$9 -> 167.67762 | F9: ='[2]Obra '!$C$38 -> 1997062.3 | G9: =F9/$M$2 -> 179.87144 | H9: =F9-D9 -> 135384.61 | I9: =G9-E9 -> 12.193824
A10: IMPERMEABILIZAÇÃO | B10: =[1]Versões!$E$10 -> 851494.31 | C10: =B10/'[2]Obra '!$E$9 -> 76.692406 | D10: =B10/$B$20*$D$20 -> 872590.56 | E10: =D10/'[2]Obra '!$E$9 -> 78.592503 | F10: ='[2]Obra '!$C$39 -> 948728.57 | G10: =F10/$M$2 -> 85.450103 | H10: =F10-D10 -> 76138.011 | I10: =G10-E10 -> 6.8575999
A11: REVESTIMENTOS E ACABAMENTOS INTERNOS EM PAREDE | B11: =[1]Versões!$E$11 -> 2914839.5 | C11: =B11/'[2]Obra '!$E$9 -> 262.53382 | D11: =B11/$B$20*$D$20 -> 2987056.3 | E11: =D11/'[2]Obra '!$E$9 -> 269.03824 | F11: ='[2]Obra '!$C$40 -> 3214008.9 | G11: =F11/$M$2 -> 289.47941 | H11: =F11-D11 -> 226952.58 | I11: =G11-E11 -> 20.441169 | J11: * Ajuste do custo de empreitada Global conforme distribução
A12: REVESTIMENTOS E ACABAMENTOS INTERNOS EM TETO | B12: =[1]Versões!$E$12 -> 454052.27 | C12: =B12/'[2]Obra '!$E$9 -> 40.895589 | D12: =B12/$B$20*$D$20 -> 465301.67 | E12: =D12/'[2]Obra '!$E$9 -> 41.9088 | F12: ='[2]Obra '!$C$41 -> 753156.1 | G12: =F12/$M$2 -> 67.835278 | H12: =F12-D12 -> 287854.42 | I12: =G12-E12 -> 25.926478 | J12: *inclusão do forro de madeira das varandas
A13: REVESTIMENTOS E ACABAMENTOS INTERNOS EM PISO | B13: =[1]Versões!$E$13 -> 3357328.4 | C13: =B13/'[2]Obra '!$E$9 -> 302.38792 | D13: =B13/$B$20*$D$20 -> 3440508.1 | E13: =D13/'[2]Obra '!$E$9 -> 309.87975 | F13: ='[2]Obra '!$C$42 -> 4313008.2 | G13: =F13/$M$2 -> 388.4641 | H13: =F13-D13 -> 872500.09 | I13: =G13-E13 -> 78.584355 | J13: * Ajustes de preços dos custos unitário e inclusão do Piso Laminado que tem custo mais elevado que o porcelanato e revisão de quantidades de rodapé
A14: PINTURA INTERNA | B14: =[1]Versões!$E$14 -> 1454024.7 | C14: =B14/'[2]Obra '!$E$9 -> 130.96113 | D14: =B14/$B$20*$D$20 -> 1490049 | E14: =D14/'[2]Obra '!$E$9 -> 134.20576 | F14: ='[2]Obra '!$C$43 -> 1273615.9 | G14: =F14/$M$2 -> 114.71206 | H14: =F14-D14 -> -216433.15 | I14: =G14-E14 -> -19.493705 | J14: *Ajuste de composições e quantidades
A15: ESQUADRIAS, VIDROS E FERRAGENS | B15: =[1]Versões!$E$15 -> 3586027.9 | C15: =B15/'[2]Obra '!$E$9 -> 322.98643 | D15: =B15/$B$20*$D$20 -> 3674873.7 | E15: =D15/'[2]Obra '!$E$9 -> 330.9886 | F15: ='[2]Obra '!$C$44 -> 3821896.6 | G15: =F15/$M$2 -> 344.23066 | H15: =F15-D15 -> 147022.83 | I15: =G15-E15 -> 13.242055
A16: COBERTURA | B16: =[1]Versões!$E$16 -> 217990.91 | C16: =B16/'[2]Obra '!$E$9 -> 19.63401 | D16: =B16/$B$20*$D$20 -> 223391.76 | E16: =D16/'[2]Obra '!$E$9 -> 20.120453 | F16: ='[2]Obra '!$C$45 -> 375409.41 | G16: =F16/$M$2 -> 33.812382 | H16: =F16-D16 -> 152017.65 | I16: =G16-E16 -> 13.691929
A17: REVESTIMENTOS E ACABAMENTOS DE FACHADA | B17: =[1]Versões!$E$17 -> 1680036 | C17: =B17/'[2]Obra '!$E$9 -> 151.31751 | D17: =B17/$B$20*$D$20 -> 1721659.8 | E17: =D17/'[2]Obra '!$E$9 -> 155.06649 | F17: ='[2]Obra '!$C$46 -> 1517055.6 | G17: =F17/$M$2 -> 136.63819 | H17: =F17-D17 -> -204604.2 | I17: =G17-E17 -> -18.428295
A18: SERVIÇOS COMPLEMENTARES | B18: =[1]Versões!$E$18 -> 2343882.5 | C18: =B18/'[2]Obra '!$E$9 -> 211.10885 | D18: =B18/$B$20*$D$20 -> 2401953.5 | E18: =D18/'[2]Obra '!$E$9 -> 216.33919 | F18: ='[2]Obra '!$C$47 -> 3263431.9 | G18: =F18/$M$2 -> 293.93085 | H18: =F18-D18 -> 861478.44 | I18: =G18-E18 -> 77.591657 | J18: * Revisão dos mobiliáreios conforme ambientes
A19: TOTAL | B19: =SUM(B3:B18) -> 40184025 | C19: =SUM(C3:C18) -> 3829.8151 | D19: =SUM(D3:D18) -> 41179607 | E19: =SUM(E3:E18) -> 3708.9657 | F19: =SUM(F3:F18) -> 40287856 | G19: =SUM(G3:G18) -> 3628.6474 | H19: =SUM(H3:H18) -> -891751.42 | I19: =SUM(I4:I18) -> -133.36529
A20: CUB/SC | B20: 2841.51 | C20: 45536 | D20: =F20 -> 2911.91 | E20: =G20 -> 45870 | F20: 2911.91 | G20: 45870 | H20: 2911.91 | I20: 45870
B24: 2007.57 | D24: 2007.57 | F24: 2007.57 | H24: 2007.57
B25: 2461.35 | D25: 2461.35 | F25: 2461.35 | H25: 2461.35
B26: =B25/B24 -> 1.2260345 | D26: =D25/D24 -> 1.2260345 | F26: =F25/F24 -> 1.2260345 | H26: =H25/H24 -> 1.2260345
C29: 1.1023 | E29: 1.1023 | G29: 1.1023 | I29: 1.1023 | J29: 1.1023
A31: 900,00 - 1100 | B31: 900 | D31: 900 | F31: 900 | H31: 900
A32: 25,00 - 30,00 | B32: 25 | D32: 25 | F32: 25 | H32: 25
A33: 15,00 - 22,00 | B33: 15 | D33: 15 | F33: 15 | H33: 15
A34: 150,00 - 200,00 | B34: 150 | D34: 150 | F34: 150 | H34: 150
A35: 440,00 - 510,00 | B35: 440 | D35: 440 | F35: 440 | H35: 440
A36: -
A37: 55,00 - 70,00 | B37: 55 | D37: 55 | F37: 55 | H37: 55
A38: 170,00 - 200,00 | B38: 170 | D38: 170 | F38: 170 | H38: 170
A39: 165,00 - 230,00 | B39: 165 | D39: 165 | F39: 165 | H39: 165
A40: 40,00 - 70,00 | B40: 40 | D40: 40 | F40: 40 | H40: 40
A41: 55,00 - 77,00 | B41: 55 | D41: 55 | F41: 55 | H41: 55
A42: 35,00 - 50,00 | B42: 35 | D42: 35 | F42: 35 | H42: 35
A43: 130,00 - 175,00 | B43: 130 | D43: 130 | F43: 130 | H43: 130
A44: 35,00 - 65,00 | B44: 35 | D44: 35 | F44: 35 | H44: 35
A45: 35,00 - 55,00 | B45: 35 | D45: 35 | F45: 35 | H45: 35
A46: 430,00 - 550,00 | B46: 430 | D46: 430 | F46: 430 | H46: 430
...

Sheet ANÁLISE_CUSTOS
A1: ETAPA | B1: OBRA | D1: OBRA SIMILAR | E1: JUSTIFICATIVA
B2: VALOR | C2: VALOR / m² | D2: VALOR / m²
A3: =[3]ORÇAMENTO_EXECUTIVO!A2 -> GERENCIAMENTO TÉCNICO E ADMINISTRATIVO | B3: =Versões!F3 -> 4073248.1 | C3: =B3/Versões!$M$2 -> 366.86939 | D3: =FIXED(CÁLCULO_MÉDIAS!AF13,2,FALSE)&" "&"-"&FIXED(CÁLCULO_MÉDIAS!AG13,2,FALSE) -> 290,00 -410,00
A4: =[3]ORÇAMENTO_EXECUTIVO!A3 -> MOVIMENTAÇÃO DE TERRA | B4: =Versões!F4 -> 198728.54 | C4: =B4/Versões!$M$2 -> 17.899086 | D4: =FIXED(CÁLCULO_MÉDIAS!AF14,2,FALSE)&" "&"-"&FIXED(CÁLCULO_MÉDIAS!AG14,2,FALSE) -> 15,00 -90,00
A5: =[3]ORÇAMENTO_EXECUTIVO!A4 -> INFRAESTRUTURA | B5: =Versões!F5 -> 1941462.1 | C5: =B5/Versões!$M$2 -> 174.86365 | D5: =FIXED(CÁLCULO_MÉDIAS!AF15,2,FALSE)&" "&"-"&FIXED(CÁLCULO_MÉDIAS!AG15,2,FALSE) -> 110,00 -200,00 | E5: Grande area de projeção
A6: =[3]ORÇAMENTO_EXECUTIVO!A5 -> SUPRAESTRUTURA | B6: =Versões!F6 -> 6615187.4 | C6: =B6/Versões!$M$2 -> 595.81682 | D6: =FIXED(CÁLCULO_MÉDIAS!AF17,2,FALSE)&" "&"-"&FIXED(CÁLCULO_MÉDIAS!AG17,2,FALSE) -> 580,00 -660,00 | E6: Poucas utilizações de formas
A7: =[3]ORÇAMENTO_EXECUTIVO!A6 -> ALVENARIA | B7: =Versões!F7 -> 1669934.2 | C7: =B7/Versões!$M$2 -> 150.40766 | D7: =FIXED(CÁLCULO_MÉDIAS!AF18,2,FALSE)&" "&"-"&FIXED(CÁLCULO_MÉDIAS!AG18,2,FALSE) -> 120,00 -190,00
A8: =[3]ORÇAMENTO_EXECUTIVO!A7 -> INSTALAÇÕES ELÉTRICAS, HIDRÁULICAS, GLP E PREVENTIVAS | B8: =Versões!F8 -> 4311922.1 | C8: =B8/Versões!$M$2 -> 388.36628 | D8: =FIXED(CÁLCULO_MÉDIAS!AF19,2,FALSE)&" "&"-"&FIXED(CÁLCULO_MÉDIAS!AG19,2,FALSE) -> 320,00 -400,00
A9: =[3]ORÇAMENTO_EXECUTIVO!A8 -> EQUIPAMENTOS E SISTEMAS ESPECIAIS | B9: =Versões!F9 -> 1997062.3 | C9: =B9/Versões!$M$2 -> 179.87144 | D9: =FIXED(CÁLCULO_MÉDIAS!AF20,2,FALSE)&" "&"-"&FIXED(CÁLCULO_MÉDIAS!AG20,2,FALSE) -> 160,00 -200,00
A10: =[3]ORÇAMENTO_EXECUTIVO!A9 -> IMPERMEABILIZAÇÃO | B10: =Versões!F10 -> 948728.57 | C10: =B10/Versões!$M$2 -> 85.450103 | D10: =FIXED(CÁLCULO_MÉDIAS!AF21,2,FALSE)&" "&"-"&FIXED(CÁLCULO_MÉDIAS!AG21,2,FALSE) -> 65,00 -110,00
A11: =[3]ORÇAMENTO_EXECUTIVO!A10 -> REVESTIMENTOS E ACABAMENTOS INTERNOS EM PAREDE | B11: =Versões!F11 -> 3214008.9 | C11: =B11/Versões!$M$2 -> 289.47941 | D11: =FIXED(CÁLCULO_MÉDIAS!AF22,2,FALSE)&" "&"-"&FIXED(CÁLCULO_MÉDIAS!AG22,2,FALSE) -> 160,00 -235,00 | E11: *Está acima da média devio o elevado custo do empreiteiro atribuído nesta etapa normalmente custa 75,00/m2 e está 189,00/m2
A12: =[3]ORÇAMENTO_EXECUTIVO!A11 -> REVESTIMENTOS E ACABAMENTOS INTERNOS EM TETO | B12: =Versões!F12 -> 753156.1 | C12: =B12/Versões!$M$2 -> 67.835278 | D12: =FIXED(CÁLCULO_MÉDIAS!AF23,2,FALSE)&" "&"-"&FIXED(CÁLCULO_MÉDIAS!AG23,2,FALSE) -> 55,00 -70,00 | E12: grande parte argamasssado
A13: =[3]ORÇAMENTO_EXECUTIVO!A12 -> REVESTIMENTOS E ACABAMENTOS INTERNOS EM PISO | B13: =Versões!F13 -> 4313008.2 | C13: =B13/Versões!$M$2 -> 388.4641 | D13: =FIXED(CÁLCULO_MÉDIAS!AF24,2,FALSE)&" "&"-"&FIXED(CÁLCULO_MÉDIAS!AG24,2,FALSE) -> 220,00 -320,00 | E13: *Está acima da média devio o elevado custo do empreiteiro atribuído nesta etapa normalmente custa 75,00/m2 e está 189,00/m2
A14: =[3]ORÇAMENTO_EXECUTIVO!A13 -> PINTURA INTERNA | B14: =Versões!F14 -> 1273615.9 | C14: =B14/Versões!$M$2 -> 114.71206 | D14: =FIXED(CÁLCULO_MÉDIAS!AF25,2,FALSE)&" "&"-"&FIXED(CÁLCULO_MÉDIAS!AG25,2,FALSE) -> 90,00 -120,00
A15: =[3]ORÇAMENTO_EXECUTIVO!A14 -> ESQUADRIAS, VIDROS E FERRAGENS | B15: =Versões!F15 -> 3821896.6 | C15: =B15/Versões!$M$2 -> 344.23066 | D15: =FIXED(CÁLCULO_MÉDIAS!AF26,2,FALSE)&" "&"-"&FIXED(CÁLCULO_MÉDIAS!AG26,2,FALSE) -> 320,00 -415,00
A16: =[3]ORÇAMENTO_EXECUTIVO!A15 -> COBERTURA | B16: =Versões!F16 -> 375409.41 | C16: =B16/Versões!$M$2 -> 33.812382 | D16: =FIXED(CÁLCULO_MÉDIAS!AF27,2,FALSE)&" "&"-"&FIXED(CÁLCULO_MÉDIAS!AG27,2,FALSE) -> 25,00 -35,00
A17: =[3]ORÇAMENTO_EXECUTIVO!A16 -> REVESTIMENTOS E ACABAMENTOS DE FACHADA | B17: =Versões!F17 -> 1517055.6 | C17: =B17/Versões!$M$2 -> 136.63819 | D17: =FIXED(CÁLCULO_MÉDIAS!AF28,2,FALSE)&" "&"-"&FIXED(CÁLCULO_MÉDIAS!AG28,2,FALSE) -> 90,00 -180,00
A18: =[3]ORÇAMENTO_EXECUTIVO!A17 -> SERVIÇOS COMPLEMENTARES | B18: =Versões!F18 -> 3263431.9 | C18: =B18/Versões!$M$2 -> 293.93085 | D18: =FIXED(CÁLCULO_MÉDIAS!AF29,2,FALSE)&" "&"-"&FIXED(CÁLCULO_MÉDIAS!AG29,2,FALSE) -> 180,00 -250,00 | E18: * os outros empreendimentos não tem o custo de Causão
A19: TOTAL | B19: =SUM(B4:B18) -> 36214608 | C19: =SUM(C4:C18) -> 3261.778 | D19: =FIXED(CÁLCULO_MÉDIAS!AF32,2,FALSE)&" "&"-"&FIXED(CÁLCULO_MÉDIAS!AG32,2,FALSE) -> 2.510,00 -3.475,00
B23: 2007.57
B24: 2461.35
B25: =B24/B23 -> 1.2260345
C28: 1.1023
A30: 900,00 - 1100 | B30: 900
A31: 25,00 - 30,00 | B31: 25
A32: 15,00 - 22,00 | B32: 15
A33: 150,00 - 200,00 | B33: 150
A34: 440,00 - 510,00 | B34: 440
A35: -
A36: 55,00 - 70,00 | B36: 55
A37: 170,00 - 200,00 | B37: 170
A38: 165,00 - 230,00 | B38: 165
A39: 40,00 - 70,00 | B39: 40
A40: 55,00 - 77,00 | B40: 55
A41: 35,00 - 50,00 | B41: 35
A42: 130,00 - 175,00 | B42: 130
A43: 35,00 - 65,00 | B43: 35
A44: 35,00 - 55,00 | B44: 35
A45: 430,00 - 550,00 | B45: 430
A46: 35,00 - 50,00 | B46: 35
...

Sheet AREAS_PRIVATIVAS
A1: ETAPA | B1: VALOR ORÇADO | C1: % | D1: VALOR / m²
A2: GERENCIAMENTO TÉCNICO E ADMINISTRATIVO | B2: =[3]ORÇAMENTO_EXECUTIVO!B2 -> 4305949.9 | C2: =B2/B$19 -> 0.10758876 | D2: =B2/AREAS_PRIVATIVAS!G$2 -> 678.79718 | F2: ÁREA PRIVATIVA | G2: =B22 -> 6343.5 | I2: m²
A3: MOVIMENTAÇÃO DE TERRA | B3: =ANÁLISE_CUSTOS!B4 -> 198728.54 | C3: =B3/B$19 -> 0.0049654452 | D3: =B3/AREAS_PRIVATIVAS!G$2 -> 31.327902
A4: INFRAESTRUTURA | B4: =ANÁLISE_CUSTOS!B5 -> 1941462.1 | C4: =B4/B$19 -> 0.048509506 | D4: =B4/AREAS_PRIVATIVAS!G$2 -> 306.05535
A5: SUPRAESTRUTURA | B5: =ANÁLISE_CUSTOS!B6 -> 6615187.4 | C5: =B5/B$19 -> 0.16528753 | D5: =B5/AREAS_PRIVATIVAS!G$2 -> 1042.8293
A6: ALVENARIA | B6: =ANÁLISE_CUSTOS!B7 -> 1669934.2 | C6: =B6/B$19 -> 0.041725091 | D6: =B6/AREAS_PRIVATIVAS!G$2 -> 263.25123
A7: INSTALAÇÕES ELÉTRICAS, HIDRÁULICAS, GLP E PREVENTIVAS | B7: =ANÁLISE_CUSTOS!B8 -> 4311922.1 | C7: =B7/B$19 -> 0.10773798 | D7: =B7/AREAS_PRIVATIVAS!G$2 -> 679.73864
A8: EQUIPAMENTOS E SISTEMAS ESPECIAIS | B8: =ANÁLISE_CUSTOS!B9 -> 1997062.3 | C8: =B8/B$19 -> 0.049898736 | D8: =B8/AREAS_PRIVATIVAS!G$2 -> 314.82025
A9: IMPERMEABILIZAÇÃO | B9: =ANÁLISE_CUSTOS!B10 -> 948728.57 | C9: =B9/B$19 -> 0.023704998 | D9: =B9/AREAS_PRIVATIVAS!G$2 -> 149.55917
A10: REVESTIMENTOS INTERNOS EM PISO E PAREDE | B10: =ANÁLISE_CUSTOS!B11 -> 3214008.9 | C10: =B10/B$19 -> 0.080305448 | D10: =B10/AREAS_PRIVATIVAS!G$2 -> 506.66176
A11: REVESTIMENTOS E ACABAMENTOS INTERNOS EM TETO | B11: =ANÁLISE_CUSTOS!B12 -> 753156.1 | C11: =B11/B$19 -> 0.01881841 | D11: =B11/AREAS_PRIVATIVAS!G$2 -> 118.72879
A12: ACABAMENTOS EM PISO E PAREDE | B12: =ANÁLISE_CUSTOS!B13 -> 4313008.2 | C12: =B12/B$19 -> 0.10776512 | D12: =B12/AREAS_PRIVATIVAS!G$2 -> 679.90986
A13: PINTURA INTERNA | B13: =ANÁLISE_CUSTOS!B14 -> 1273615.9 | C13: =B13/B$19 -> 0.031822654 | D13: =B13/AREAS_PRIVATIVAS!G$2 -> 200.77494
A14: ESQUADRIAS, VIDROS E FERRAGENS | B14: =ANÁLISE_CUSTOS!B15 -> 3821896.6 | C14: =B14/B$19 -> 0.095494173 | D14: =B14/AREAS_PRIVATIVAS!G$2 -> 602.4902
... A16: REVESTIMENTOS E ACABAMENTOS DE FACHADA | B16: =ANÁLISE_CUSTOS!B17 -> 1517055.6 | C16: =B16/B$19 -> 0.037905256 | D16: =B16/AREAS_PRIVATIVAS!G$2 -> 239.15119
A17: SERVIÇOS COMPLEMENTARES | B17: =[3]ORÇAMENTO_EXECUTIVO!B17 -> 1572023 | C17: =B17/B$19 -> 0.039278677 | D17: =B17/AREAS_PRIVATIVAS!G$2 -> 247.81635
A18: IMPREVISTOS E CONTINGENCIAS | B18: =[3]ORÇAMENTO_EXECUTIVO!B18 -> 1193153 | C18: =B18/B$19 -> 0.029812204 | D18: =B18/AREAS_PRIVATIVAS!G$2 -> 188.09065
A19: TOTAL | B19: =SUM(B2:B18) -> 40022302 | C19: =SUM(C2:C18) -> 1 | D19: =SUM(D2:D18) -> 6309.1829
A21: DESCRIÇÃO | B21: ÁREA (m²) | C21: QUANT. | D21: VALOR TOTAL
A22: VALOR POR ÁREA PRIVATIVA (R$/m²) | B22: 6343.5 | D22: =[3]ORÇAMENTO_EXECUTIVO!B19/AREAS_PRIVATIVAS!B22 -> 6457.7789
A23: APT01 - TB | C23: 1 | D23: =B23*$D$22 -> 0
A24: APT02 - TB | C24: 1 | D24: =B24*$D$22 -> 0
A25: APT03 - TB | C25: 1 | D25: =B25*$D$22 -> 0
A26: APT04 - TB | C26: 1 | D26: =B26*$D$22 -> 0
A27: APT01 - TA | C27: 1 | D27: =B27*$D$22 -> 0
A28: APT04 (2 PAVIMENTOS) - TA | C28: 1 | D28: =B28*$D$22 -> 0
A29: APT11 - TB | C29: 1 | D29: =B29*$D$22 -> 0
A30: APT12 - TB | C30: 1 | D30: =B30*$D$22 -> 0
A31: APT13 - TB | C31: 1 | D31: =B31*$D$22 -> 0
A32: APT14 - TB | C32: 1 | D32: =B32*$D$22 -> 0
A33: APT11 - TA | C33: 1 | D33: =B33*$D$22 -> 0
A34: APT12 - TA | C34: 1 | D34: =B34*$D$22 -> 0
... A45: APT32 (COM LAZER SUPERIOR) - TA | C45: 1 | D45: =B45*$D$22 -> 0
A46: APT33 (COM LAZER SUPERIOR) - TA | C46: 1 | D46: =B46*D22 -> 0
A49: ÁREA DE LAZER

Sheet CÁLCULO_MÉDIAS
C3: DATA BASE | D3: 45231 | E3: DATA BASE | G3: DATA BASE | H3: 45047 | I3: DATA BASE | J3: 44652 | K3: DATA BASE | L3: 45078 | M3: DATA BASE | O3: DATA BASE | P3: 45323 | Q3: DATA BASE | R3: 44958 | S3: DATA BASE | T3: 45017 | U3: DATA BASE | V3: 45231 | W3: DATA BASE | X3: 44958 | Y3: DATA BASE | Z3: 45383 | AA3: DATA BASE | AC3: DATA BASE
C4: CUB | D4: 2754.98 | E4: CUB | G4: CUB | H4: 2688.94 | I4: CUB | J4: 2461.35 | K4: CUB | L4: 2725.79 | M4: CUB | O4: CUB | P4: 2753.62 | Q4: CUB | R4: 2662.47 | S4: CUB | T4: 2680.84 | U4: CUB | V4: 2754.98 | W4: CUB | X4: 2662.47 | Y4: CUB | Z4: 2757.56 | AA4: CUB | AC4: CUB
C5: ÁREA TERRENO | D5: 2394.02 | E5: ÁREA TERRENO | G5: ÁREA TERRENO | I5: ÁREA TERRENO | K5: ÁREA TERRENO | L5: 2133.78 | M5: ÁREA TERRENO | O5: ÁREA TERRENO | Q5: ÁREA TERRENO | S5: ÁREA TERRENO | U5: ÁREA TERRENO | W5: ÁREA TERRENO | Y5: ÁREA TERRENO | Z5: 3794.1 | AA5: ÁREA TERRENO | AC5: ÁREA TERRENO
C6: ÁREA CONSTRUÍDA | D6: 7642.76 | E6: ÁREA CONSTRUÍDA | G6: ÁREA CONSTRUÍDA | H6: 3282.64 | I6: ÁREA CONSTRUÍDA | J6: 4811.62 | K6: ÁREA CONSTRUÍDA | L6: 12953.8 | M6: ÁREA CONSTRUÍDA | O6: ÁREA CONSTRUÍDA | P6: 13434.29 | Q6: ÁREA CONSTRUÍDA | R6: 6003.01 | S6: ÁREA CONSTRUÍDA | T6: 16348.1 | U6: ÁREA CONSTRUÍDA | V6: 7642.76 | W6: ÁREA CONSTRUÍDA | X6: 14888.46 | Y6: ÁREA CONSTRUÍDA | Z6: 13223.24 | AA6: ÁREA CONSTRUÍDA | AC6: ÁREA CONSTRUÍDA
C7: PAVTOS | D7: Subsolo com vagas de garagem Térreo, 2º e 3º PVTO com 2 aptos por andar Cobertura com Rooftop | E7: PAVTOS | G7: PAVTOS | I7: PAVTOS | K7: PAVTOS | L7: 16 | M7: PAVTOS | O7: PAVTOS | P7: 20 | Q7: PAVTOS | R7: 25 | S7: PAVTOS | T7: 33 | U7: PAVTOS | W7: PAVTOS | Y7: PAVTOS | Z7: 6 | AA7: PAVTOS | AC7: PAVTOS
C8: ESPECIFICAÇÕES | D8: 6 apartamentos 3 Elevadores Salão de festas e academia Pavimento Rooftop | E8: ESPECIFICAÇÕES | G8: ESPECIFICAÇÕES | I8: ESPECIFICAÇÕES | K8: ESPECIFICAÇÕES | L8: 9 tipos 2 pav diferenciados 98 unidades habitacionais | M8: ESPECIFICAÇÕES | O8: ESPECIFICAÇÕES | Q8: ESPECIFICAÇÕES | S8: ESPECIFICAÇÕES | T8: 24 tipos 5 diferenciados 55 uni habitacionais | U8: ESPECIFICAÇÕES | W8: ESPECIFICAÇÕES | Y8: ESPECIFICAÇÕES | Z8: 41 meses de obra 99 unidades privativas = 6387 m² | AA8: ESPECIFICAÇÕES | AC8: ESPECIFICAÇÕES
C9: DIFERENCIAIS | D9: -Uma piscina por apartamento - Padrão elevado de esquadrias - Alto investimento em paisagismo | E9: DIFERENCIAIS | G9: DIFERENCIAIS | H9: Hélice | I9: DIFERENCIAIS | J9: Hélice | K9: DIFERENCIAIS | L9: FLORIANOPOLIS 11 aptos por andar (1 estudio) 2 elevadores piscina +academia+salão gourmet+sala de jogos+playground instalação de sistema de som+carro eletrico terraplanagem, demolição e locação= sondagem e estudo topografico do terreno+ limpeza camada+ demolição+ escavação vertical do terreno+bota fora parede diafragma+formas para mureta guia e viga de coroamento fundação rasa+profunda estaca hélice continua de (50,60 e 70 cm) laje nervurada escoras e cubetas proprias churrasqueira préfabricada cobogó em concreto na ventilação da garagem shaft banheiro placa de gesso shaft de painel de madeira em corredores teto em estucamento e massa unica forro= resistente a umidade nos bnheiros da area comum e apartamentos + standart em area lazer+resistente ao fogo hall de entrada forro madeira incluso no valor de ambientação em serviço complementar fachada: tela antifissuração no reboco e tratamento de junta dilat. impermeabilização bem completa - ver comentario na celula porcelanato nas escadas acesso principal e entrada mezanino + piso 84x84 terraço e salas comerciais + piso predominante é porcelanato + piso concreto polido escadas e garagem telha em fibrocimento ondulada e estrutura de madeira motorização das persianas linha 25mm esquadrias pergolado metalico com vidro corrimao escadas madeira textura parede escadas esmalte sintetico nas portas madeiras 2 cisternas+bomba de recalque+pressurizador+subestação transformadora+gerador a diesel plataforma vertical piscina infra + entrega equipamentos(areas comum) climatização complementares: arremates e acabamentos+desmobilização canteiro empreitada global | M9: DIFERENCIAIS | O9: DIFERENCIAIS | P9: ITAJAÍ AT 1412,41 20 pavimentos 5 Aptos por andar 3 pavtos garagem Esta Hélice BLOCOS CERÂMICOS CUBETAS ALUGADAS PARA O LAZER / AQUISIÇÃO PARA O TIPO MO praticada pela construtora, escoramento.. | Q9: DIFERENCIAIS | R9: BALNEÁRIO CAMBORIÚ 1 apto por andar 3 suítes 1 lavabo Estaca raiz Garagens laje nervurada Tipo laje maciça | S9: DIFERENCIAIS | T9: BALNEÁRIO CAMBORIÚ Hélice Contúnua(50 e 60 cm - 30m prof.) 30MPa Blocos e baldrames fck 30 e 45MPa - forma é tabua de madeira Supra laje maciça - forma de compensado plastificado - concreto 35,40 e 45 mpa Alvenaria bloco cerâmico - escada sical custo de distanciamento de rede de alta tensão em instalações+melhoria de rede de energia ESPECIAIS: telefonia+3 elevadores+piscina+hidromassagem e ofuro+sauna+pista boliche+subestação+gerador+bomba de recalque e sucção+exaust. churras e coifas+infra carro eletrico (101 pontos) infra ar cond.+10 equipamentos de ar+exaust. mecanica+pressurização escada+instalação desenfumagem imper: baldrama(tinta asfalt)+floreira(argm. rigida)+banheiros, cozinha, area serviço(arg. polimerica flexivel com fibras)+peitoril(resina termoplastica e proteção UV)+laje exposta, piscina e terraço(manta asfaltica 4mm)+tratamento junta dilatação com isopor manta acustica area de apartamentos reboco no teto de garagens, escadas e area tecnica, o resto forro gesso mineral lajota hidraulica em rampas pintura piso epoxi garagem e quadra poliesportiva pintura piso escada textura no teto de garagem cobertura com trama de madeira e telha fibrocimento de 6mm esquadrias linha gold 32mm pele de vidro e brise metalico fachada: textura+brise+moldura pastilha+marquise em pastilha+pastilha complementares: playground+quadra esportiva+desmobilização+personalização de unidade privativa | U9: DIFERENCIAIS | W9: DIFERENCIAIS | X9: FLORIANOPOLIS 'Pintura - é interna e externa *Teve desmonte de rocha - e itens dessa etapa foram lançados pelo cliente *Fundação rasa, somente + uma contenção de parede de concreto *Laje em concreto protendido *esquadria aluminio 32mm *cobertura com telha de fibrocimento e estrutura madeira *tem piscina e reservatório *forro acartonado somente em banheiros, sacadas e area comum, resto chapisco e reboco *fachada com: ceramico + acabamento em granito + pedra + tinta emborrachada *ESPECIAIS: Piscina e sauna + spa + 4 elevadores + plataforma elevatoria + gerador + infra ar cond. + exaustao mecanica, churrasqueiras e coifas Complementares: alargaento viario + inovação | Y9: DIFERENCIAIS | Z9: *FLORIANOPOLIS '*2 elevadores *piscina *infra para carro eletrico *Aterro com 30% fator de empolamento *escavação mecanizada vertical + rebaixamento lençol freatico da supra *rebaixamento d lençol para alivio laje subsolo *contenção + estrutura de tubulação para drenagem *escoras madeira + locação cubetas + juntas dilatação divisão blocos *estimativa instalações *2 plataforma elevatoria + cadeira transferencia piscina + subestação + infra e maquinas completas de climatização *areas externas e terraço e piscina com manta asfaltica + laje tecnica argmassa polimerica *estucamento em teto de subsolo e escada, resto forro em placa *textura parede escada e garagem *fachada: textura stolit serviços complementares: quadra externa | AA9: DIFERENCIAIS | AC9: DIFERENCIAIS
C11: ESTALEIRO - ABC EMPREENDIMENTOS (PRELIMINAR) | G11: MENDES - BRAVA SIXTEEN | I11: MENDES - BRAVA MUNDO | K11: COTA - AFONSO PENA | M11: BRAVA - OCEAN (EXECUTIVO) | O11: AMALFI - RAVELLO (EXECUTIVO) | Q11: ESSEGE - DOM (EXECUTIVO) | S11: AS RAMOS - PAESSAGGIO (EXECUTIVO) | U11: ABC - ESTALEIRO | W11: LUMIS - LIVE (EXECUTIVO) | Y11: VIVA 4 - BARRA 4 PARAMÉTRICO | AF11: MÉDIAS
C12: VALOR / M2 | D12: INDEXADO | F12: INDEXADO | G12: VALOR / M2 | H12: INDEXADO | I12: VALOR / M2 | J12: INDEXADO | K12: VALOR / M2 | L12: INDEXADO | N12: INDEXADO | O12: VALOR / M2 | P12: INDEXADO | Q12: VALOR / M2 | R12: INDEXADO | S12: VALOR / M2 | T12: INDEXADO | U12: VALOR / M2 | V12: INDEXADO | X12: INDEXADO | Z12: INDEXADO | AB12: INDEXADO | AD12: INDEXADO | AF12: MÍNIMA | AG12: MÁXIMA
B13: GERENCIAMENTO TECNICO E ADMINISTRATIVO | C13: 400.87571 | D13: =[3]ORÇAMENTO_EXECUTIVO!$B$20/CÁLCULO_MÉDIAS!D$4*C13 -> 413.46664 | F13: =[3]ORÇAMENTO_EXECUTIVO!$B$20/CÁLCULO_MÉDIAS!F$4*E13 -> #DIV/0! | G13: 750.56 | H13: =[3]ORÇAMENTO_EXECUTIVO!$B$20/CÁLCULO_MÉDIAS!H$4*G13 -> 793.14665 | I13: 647.1 | J13: =[3]ORÇAMENTO_EXECUTIVO!$B$20/CÁLCULO_MÉDIAS!J$4*I13 -> 747.04578 | K13: 247.43 | L13: =Versões!$F$20/CÁLCULO_MÉDIAS!L$4*K13 -> 264.3248 | N13: =[3]ORÇAMENTO_EXECUTIVO!$B$20/CÁLCULO_MÉDIAS!N$4*M13 -> #DIV/0! | O13: 353.32967 | P13: =Versões!$F$20/CÁLCULO_MÉDIAS!P$4*O13 -> 373.64059 | Q13: 425.96974 | R13: =[3]ORÇAMENTO_EXECUTIVO!$B$20/CÁLCULO_MÉDIAS!R$4*Q13 -> 454.61442 | S13: 570.26 | T13: =Versões!$F$20/CÁLCULO_MÉDIAS!T$4*S13 -> 619.4125 | U13: 400.88 | V13: =[3]ORÇAMENTO_EXECUTIVO!$B$20/CÁLCULO_MÉDIAS!V$4*U13 -> 413.47107 | W13: 194.23 | X13: =Versões!$F$20/CÁLCULO_MÉDIAS!X$4*W13 -> 212.42691 | Y13: 361.93 | Z13: =Versões!$F$20/CÁLCULO_MÉDIAS!Z$4*Y13 -> 382.18845 | AB13: =[3]ORÇAMENTO_EXECUTIVO!$B$20/CÁLCULO_MÉDIAS!AB$4*AA13 -> #DIV/0! | AD13: =[3]ORÇAMENTO_EXECUTIVO!$B$20/CÁLCULO_MÉDIAS!AD$4*AC13 -> #DIV/0! | AF13: 290 | AG13: 410
B14: MOVIMENTAÇÃO DE TERRA | C14: 38.001581 | D14: =[3]ORÇAMENTO_EXECUTIVO!$B$20/CÁLCULO_MÉDIAS!D$4*C14 -> 39.195156 | F14: =[3]ORÇAMENTO_EXECUTIVO!$B$20/CÁLCULO_MÉDIAS!F$4*E14 -> #DIV/0! | G14: 40.84 | H14: =[3]ORÇAMENTO_EXECUTIVO!$B$20/CÁLCULO_MÉDIAS!H$4*G14 -> 43.157255 | I14: 93.34 | J14: =[3]ORÇAMENTO_EXECUTIVO!$B$20/CÁLCULO_MÉDIAS!J$4*I14 -> 107.75653 | K14: 51.13 | L14: =Versões!$F$20/CÁLCULO_MÉDIAS!L$4*K14 -> 54.621214 | N14: =[3]ORÇAMENTO_EXECUTIVO!$B$20/CÁLCULO_MÉDIAS!N$4*M14 -> #DIV/0! | O14: 6.8428238 | P14: =Versões!$F$20/CÁLCULO_MÉDIAS!P$4*O14 -> 7.236179 | Q14: 19.58779 | R14: =[3]ORÇAMENTO_EXECUTIVO!$B$20/CÁLCULO_MÉDIAS!R$4*Q14 -> 20.904987 | S14: 57.26 | T14: =Versões!$F$20/CÁLCULO_MÉDIAS!T$4*S14 -> 62.195419 | U14: 38 | V14: =[3]ORÇAMENTO_EXECUTIVO!$B$20/CÁLCULO_MÉDIAS!V$4*U14 -> 39.193526 | W14: 131.35 | X14: =Versões!$F$20/CÁLCULO_MÉDIAS!X$4*W14 -> 143.65585 | Y14: 88.84 | Z14: =Versões!$F$20/CÁLCULO_MÉDIAS!Z$4*Y14 -> 93.812677 | AB14: =[3]ORÇAMENTO_EXECUTIVO!$B$20/CÁLCULO_MÉDIAS!AB$4*AA14 -> #DIV/0! | AD14: =[3]ORÇAMENTO_EXECUTIVO!$B$20/CÁLCULO_MÉDIAS!AD$4*AC14 -> #DIV/0! | AF14: 15 | AG14: 90
B15: INFRAESTRUTURA | C15: 160.6985 | D15: =[3]ORÇAMENTO_EXECUTIVO!$B$20/CÁLCULO_MÉDIAS!D$4*C15 -> 165.74581 | F15: =[3]ORÇAMENTO_EXECUTIVO!$B$20/CÁLCULO_MÉDIAS!F$4*E15 -> #DIV/0! | G15: 134.84 | H15: =[3]ORÇAMENTO_EXECUTIVO!$B$20/CÁLCULO_MÉDIAS!H$4*G15 -> 142.4908 | I15: 316.11 | J15: =[3]ORÇAMENTO_EXECUTIVO!$B$20/CÁLCULO_MÉDIAS!J$4*I15 -> 364.93377 | K15: 337.43 | L15: =Versões!$F$20/CÁLCULO_MÉDIAS!L$4*K15 -> 360.4701 | N15: =[3]ORÇAMENTO_EXECUTIVO!$B$20/CÁLCULO_MÉDIAS!N$4*M15 -> #DIV/0! | O15: 167.92237 | P15: =Versões!$F$20/CÁLCULO_MÉDIAS!P$4*O15 -> 177.57527 | Q15: 195.5904 | R15: =[3]ORÇAMENTO_EXECUTIVO!$B$20/CÁLCULO_MÉDIAS!R$4*Q15 -> 208.74303 | S15: 310.7 | T15: =Versões!$F$20/CÁLCULO_MÉDIAS!T$4*S15 -> 337.48021 | U15: 160.7 | V15: =[3]ORÇAMENTO_EXECUTIVO!$B$20/CÁLCULO_MÉDIAS!V$4*U15 -> 165.74736 | W15: 99.33 | X15: =Versões!$F$20/CÁLCULO_MÉDIAS!X$4*W15 -> 108.63597 | Y15: 174.06 | Z15: =Versões!$F$20/CÁLCULO_MÉDIAS!Z$4*Y15 -> 183.80273 | AB15: =[3]ORÇAMENTO_EXECUTIVO!$B$20/CÁLCULO_MÉDIAS!AB$4*AA15 -> #DIV/0! | AD15: =[3]ORÇAMENTO_EXECUTIVO!$B$20/CÁLCULO_MÉDIAS!AD$4*AC15 -> #DIV/0! | AF15: 110 | AG15: 200
B16: CONTENÇÕES | L16: =Versões!$F$20/CÁLCULO_MÉDIAS!L$4*K16 -> 0 | P16: =Versões!$F$20/CÁLCULO_MÉDIAS!P$4*O16 -> 0 | T16: =Versões!$F$20/CÁLCULO_MÉDIAS!T$4*S16 -> 0 | X16: =Versões!$F$20/CÁLCULO_MÉDIAS!X$4*W16 -> 0 | Y16: 52.9 | Z16: =Versões!$F$20/CÁLCULO_MÉDIAS!Z$4*Y16 -> 55.860993
B17: SUPRAESTRUTURA | C17: 678.58014 | D17: =[3]ORÇAMENTO_EXECUTIVO!$B$20/CÁLCULO_MÉDIAS!D$4*C17 -> 699.89337 | F17: =[3]ORÇAMENTO_EXECUTIVO!$B$20/CÁLCULO_MÉDIAS!F$4*E17 -> #DIV/0! | G17: 769.54 | H17: =[3]ORÇAMENTO_EXECUTIVO!$B$20/CÁLCULO_MÉDIAS!H$4*G17 -> 813.20357 | I17: 749.05 | J17: =[3]ORÇAMENTO_EXECUTIVO!$B$20/CÁLCULO_MÉDIAS!J$4*I17 -> 864.74214 | K17: 540.46 | L17: =Versões!$F$20/CÁLCULO_MÉDIAS!L$4*K17 -> 577.36322 | N17: =[3]ORÇAMENTO_EXECUTIVO!$B$20/CÁLCULO_MÉDIAS!N$4*M17 -> #DIV/0! | O17: 649.76457 | P17: =Versões!$F$20/CÁLCULO_MÉDIAS!P$4*O17 -> 687.11585 | Q17: 730.88829 | R17: =[3]ORÇAMENTO_EXECUTIVO!$B$20/CÁLCULO_MÉDIAS!R$4*Q17 -> 780.03748 | S17: 819.7 | T17: =Versões!$F$20/CÁLCULO_MÉDIAS!T$4*S17 -> 890.35251 | U17: 678.58 | V17: =[3]ORÇAMENTO_EXECUTIVO!$B$20/CÁLCULO_MÉDIAS!V$4*U17 -> 699.89323 | W17: 670.84 | X17: =Versões!$F$20/CÁLCULO_MÉDIAS!X$4*W17 -> 733.68928 | Y17: 626.18 | Z17: =Versões!$F$20/CÁLCULO_MÉDIAS!Z$4*Y17 -> 661.22942 | AB17: =[3]ORÇAMENTO_EXECUTIVO!$B$20/CÁLCULO_MÉDIAS!AB$4*AA17 -> #DIV/0! | AD17: =[3]ORÇAMENTO_EXECUTIVO!$B$20/CÁLCULO_MÉDIAS!AD$4*AC17 -> #DIV/0! | AF17: 580 | AG17: 660
B18: ALVENARIA | C18: 81.675557 | D18: =[3]ORÇAMENTO_EXECUTIVO!$B$20/CÁLCULO_MÉDIAS!D$4*C18 -> 84.24087 | F18: =[3]ORÇAMENTO_EXECUTIVO!$B$20/CÁLCULO_MÉDIAS!F$4*E18 -> #DIV/0! | G18: 161.68 | H18: =[3]ORÇAMENTO_EXECUTIVO!$B$20/CÁLCULO_MÉDIAS!H$4*G18 -> 170.8537 | I18: 151.59 | J18: =[3]ORÇAMENTO_EXECUTIVO!$B$20/CÁLCULO_MÉDIAS!J$4*I18 -> 175.00335 | K18: 140.35 | L18: =Versões!$F$20/CÁLCULO_MÉDIAS!L$4*K18 -> 149.93326 | N18: =[3]ORÇAMENTO_EXECUTIVO!$B$20/CÁLCULO_MÉDIAS!N$4*M18 -> #DIV/0! | O18: 158.61182 | P18: =Versões!$F$20/CÁLCULO_MÉDIAS!P$4*O18 -> 167.72952 | Q18: 119.11837 | R18: =[3]ORÇAMENTO_EXECUTIVO!$B$20/CÁLCULO_MÉDIAS!R$4*Q18 -> 127.12859 | S18: 99.17 | T18: =Versões!$F$20/CÁLCULO_MÉDIAS!T$4*S18 -> 107.71777 | U18: 81.68 | V18: =[3]ORÇAMENTO_EXECUTIVO!$B$20/CÁLCULO_MÉDIAS!V$4*U18 -> 84.245453 | W18: 150.15 | X18: =Versões!$F$20/CÁLCULO_MÉDIAS!X$4*W18 -> 164.21717 | Y18: 152.16 | Z18: =Versões!$F$20/CÁLCULO_MÉDIAS!Z$4*Y18 -> 160.67691 | AB18: =[3]ORÇAMENTO_EXECUTIVO!$B$20/CÁLCULO_MÉDIAS!AB$4*AA18 -> #DIV/0! | AD18: =[3]ORÇAMENTO_EXECUTIVO!$B$20/CÁLCULO_MÉDIAS!AD$4*AC18 -> #DIV/0! | AF18: 120 | AG18: 190
B19: INSTALAÇÕES ELÉTRICAS, HIDRÁULICAS, GLP E PREVENTIVAS | C19: 361.2 | D19: =[3]ORÇAMENTO_EXECUTIVO!$B$20/CÁLCULO_MÉDIAS!D$4*C19 -> 372.54478 | F19: =[3]ORÇAMENTO_EXECUTIVO!$B$20/CÁLCULO_MÉDIAS!F$4*E19 -> #DIV/0! | G19: 475.97 | H19: =[3]ORÇAMENTO_EXECUTIVO!$B$20/CÁLCULO_MÉDIAS!H$4*G19 -> 502.97646 | I19: 374.08 | J19: =[3]ORÇAMENTO_EXECUTIVO!$B$20/CÁLCULO_MÉDIAS!J$4*I19 -> 431.85734 | K19: 371.77 | L19: =Versões!$F$20/CÁLCULO_MÉDIAS!L$4*K19 -> 397.15487 | N19: =[3]ORÇAMENTO_EXECUTIVO!$B$20/CÁLCULO_MÉDIAS!N$4*M19 -> #DIV/0! | O19: 310.07307 | P19: =Versões!$F$20/CÁLCULO_MÉDIAS!P$4*O19 -> 327.89742 | Q19: 311.09537 | R19: =[3]ORÇAMENTO_EXECUTIVO!$B$20/CÁLCULO_MÉDIAS!R$4*Q19 -> 332.01523 | S19: 285.64 | T19: =Versões!$F$20/CÁLCULO_MÉDIAS!T$4*S19 -> 310.26021 | U19: 361.2 | V19: =[3]ORÇAMENTO_EXECUTIVO!$B$20/CÁLCULO_MÉDIAS!V$4*U19 -> 372.54478 | W19: 301.65 | X19: =Versões!$F$20/CÁLCULO_MÉDIAS!X$4*W19 -> 329.91082 | Y19: 305 | Z19: =Versões!$F$20/CÁLCULO_MÉDIAS!Z$4*Y19 -> 322.07189 | AB19: =[3]ORÇAMENTO_EXECUTIVO!$B$20/CÁLCULO_MÉDIAS!AB$4*AA19 -> #DIV/0! | AD19: =[3]ORÇAMENTO_EXECUTIVO!$B$20/CÁLCULO_MÉDIAS!AD$4*AC19 -> #DIV/0! | AF19: 320 | AG19: 400
B20: EQUIPAMENTOS E SISTEMAS ESPECIAIS | C20: 329.029 | D20: =[3]ORÇAMENTO_EXECUTIVO!$B$20/CÁLCULO_MÉDIAS!D$4*C20 -> 339.36333 | F20: =[3]ORÇAMENTO_EXECUTIVO!$B$20/CÁLCULO_MÉDIAS!F$4*E20 -> #DIV/0! | G20: 292.98 | H20: =[3]ORÇAMENTO_EXECUTIVO!$B$20/CÁLCULO_MÉDIAS!H$4*G20 -> 309.60364 | I20: 277.64 | J20: =[3]ORÇAMENTO_EXECUTIVO!$B$20/CÁLCULO_MÉDIAS!J$4*I20 -> 320.522 | K20: 92.01 | L20: =Versões!$F$20/CÁLCULO_MÉDIAS!L$4*K20 -> 98.292546 | N20: =[3]ORÇAMENTO_EXECUTIVO!$B$20/CÁLCULO_MÉDIAS!N$4*M20 -> #DIV/0! | O20: 122.47621 | P20: =Versões!$F$20/CÁLCULO_MÉDIAS!P$4*O20 -> 129.51667 | Q20: 234.95757 | R20: =[3]ORÇAMENTO_EXECUTIVO!$B$20/CÁLCULO_MÉDIAS!R$4*Q20 -> 250.75749 | S20: 494.41 | T20: =Versões!$F$20/CÁLCULO_MÉDIAS!T$4*S20 -> 537.02475 | U20: 329.03 | V20: =[3]ORÇAMENTO_EXECUTIVO!$B$20/CÁLCULO_MÉDIAS!V$4*U20 -> 339.36436 | W20: 121.63 | X20: =Versões!$F$20/CÁLCULO_MÉDIAS!X$4*W20 -> 133.0252 | Y20: 157.66 | Z20: =Versões!$F$20/CÁLCULO_MÉDIAS!Z$4*Y20 -> 166.48477 | AB20: =[3]ORÇAMENTO_EXECUTIVO!$B$20/CÁLCULO_MÉDIAS!AB$4*AA20 -> #DIV/0! | AD20: =[3]ORÇAMENTO_EXECUTIVO!$B$20/CÁLCULO_MÉDIAS!AD$4*AC20 -> #DIV/0! | AF20: 160 | AG20: 200
B21: IMPERMEABILIZAÇÃO | C21: 64.341352 | D21: =[3]ORÇAMENTO_EXECUTIVO!$B$20/CÁLCULO_MÉDIAS!D$4*C21 -> 66.362222 | F21: =[3]ORÇAMENTO_EXECUTIVO!$B$20/CÁLCULO_MÉDIAS!F$4*E21 -> #DIV/0! | G21: 45.54 | H21: =[3]ORÇAMENTO_EXECUTIVO!$B$20/CÁLCULO_MÉDIAS!H$4*G21 -> 48.123932 | I21: 61.96 | J21: =[3]ORÇAMENTO_EXECUTIVO!$B$20/CÁLCULO_MÉDIAS!J$4*I21 -> 71.529835 | K21: 27.46 | L21: =Versões!$F$20/CÁLCULO_MÉDIAS!L$4*K21 -> 29.335 | N21: =[3]ORÇAMENTO_EXECUTIVO!$B$20/CÁLCULO_MÉDIAS!N$4*M21 -> #DIV/0! | O21: 60.962018 | P21: =Versões!$F$20/CÁLCULO_MÉDIAS!P$4*O21 -> 64.466378 | Q21: 40.38554 | R21: =[3]ORÇAMENTO_EXECUTIVO!$B$20/CÁLCULO_MÉDIAS!R$4*Q21 -> 43.101299 | S21: 45.69 | T21: =Versões!$F$20/CÁLCULO_MÉDIAS!T$4*S21 -> 49.628164 | U21: 64.34 | V21: =[3]ORÇAMENTO_EXECUTIVO!$B$20/CÁLCULO_MÉDIAS!V$4*U21 -> 66.360828 | W21: 61.19 | X21: =Versões!$F$20/CÁLCULO_MÉDIAS!X$4*W21 -> 66.922734 | Y21: 105.47 | Z21: =Versões!$F$20/CÁLCULO_MÉDIAS!Z$4*Y21 -> 111.37351 | AB21: =[3]ORÇAMENTO_EXECUTIVO!$B$20/CÁLCULO_MÉDIAS!AB$4*AA21 -> #DIV/0! | AD21: =[3]ORÇAMENTO_EXECUTIVO!$B$20/CÁLCULO_MÉDIAS!AD$4*AC21 -> #DIV/0! | AF21: 65 | AG21: 110
B22: REVESTIMENTOS INTERNOS DE PAREDE | C22: 81.847539 | D22: =[3]ORÇAMENTO_EXECUTIVO!$B$20/CÁLCULO_MÉDIAS!D$4*C22 -> 84.418254 | F22: =[3]ORÇAMENTO_EXECUTIVO!$B$20/CÁLCULO_MÉDIAS!F$4*E22 -> #DIV/0! | G22: 219.39 | H22: =[3]ORÇAMENTO_EXECUTIVO!$B$20/CÁLCULO_MÉDIAS!H$4*G22 -> 231.83815 | I22: 94.96 | J22: =[3]ORÇAMENTO_EXECUTIVO!$B$20/CÁLCULO_MÉDIAS!J$4*I22 -> 109.62675 | K22: 135.75 | L22: =Versões!$F$20/CÁLCULO_MÉDIAS!L$4*K22 -> 145.01916 | N22: =[3]ORÇAMENTO_EXECUTIVO!$B$20/CÁLCULO_MÉDIAS!N$4*M22 -> #DIV/0! | O22: 168.50558 | P22: =Versões!$F$20/CÁLCULO_MÉDIAS!P$4*O22 -> 178.19201 | R22: =[3]ORÇAMENTO_EXECUTIVO!$B$20/CÁLCULO_MÉDIAS!R$4*Q22 -> 0 | S22: 132.83 | T22: =Versões!$F$20/CÁLCULO_MÉDIAS!T$4*S22 -> 144.27903 | U22: 81.85 | V22: =[3]ORÇAMENTO_EXECUTIVO!$B$20/CÁLCULO_MÉDIAS!V$4*U22 -> 84.420792 | W22: 191.99 | X22: =Versões!$F$20/CÁLCULO_MÉDIAS!X$4*W22 -> 209.97705 | Y22: 172.28 | Z22: =Versões!$F$20/CÁLCULO_MÉDIAS!Z$4*Y22 -> 181.9231 | AB22: =[3]ORÇAMENTO_EXECUTIVO!$B$20/CÁLCULO_MÉDIAS!AB$4*AA22 -> #DIV/0! | AD22: =[3]ORÇAMENTO_EXECUTIVO!$B$20/CÁLCULO_MÉDIAS!AD$4*AC22 -> #DIV/0! | AF22: 160 | AG22: 235
B23: REVESTIMENTOS E ACABAMENTOS INTERNOS EM TETO | C23: 33.843157 | D23: =[3]ORÇAMENTO_EXECUTIVO!$B$20/CÁLCULO_MÉDIAS!D$4*C23 -> 34.906123 | F23: =[3]ORÇAMENTO_EXECUTIVO!$B$20/CÁLCULO_MÉDIAS!F$4*E23 -> #DIV/0! | G23: 80.68 | H23: =[3]ORÇAMENTO_EXECUTIVO!$B$20/CÁLCULO_MÉDIAS!H$4*G23 -> 85.25777 | I23: 59.11 | J23: =[3]ORÇAMENTO_EXECUTIVO!$B$20/CÁLCULO_MÉDIAS!J$4*I23 -> 68.239647 | K23: 48.84 | L23: =Versões!$F$20/CÁLCULO_MÉDIAS!L$4*K23 -> 52.17485 | N23: =[3]ORÇAMENTO_EXECUTIVO!$B$20/CÁLCULO_MÉDIAS!N$4*M23 -> #DIV/0! | O23: 53.679931 | P23: =Versões!$F$20/CÁLCULO_MÉDIAS!P$4*O23 -> 56.765685 | Q23: 82.252956 | R23: =[3]ORÇAMENTO_EXECUTIVO!$B$20/CÁLCULO_MÉDIAS!R$4*Q23 -> 87.784125 | S23: 104.14 | T23: =Versões!$F$20/CÁLCULO_MÉDIAS!T$4*S23 -> 113.11615 | U23: 12.04 | V23: =[3]ORÇAMENTO_EXECUTIVO!$B$20/CÁLCULO_MÉDIAS!V$4*U23 -> 12.418159 | W23: 38.14 | X23: =Versões!$F$20/CÁLCULO_MÉDIAS!X$4*W23 -> 41.713239 | Y23: 63.63 | Z23: =Versões!$F$20/CÁLCULO_MÉDIAS!Z$4*Y23 -> 67.191587 | AB23: =[3]ORÇAMENTO_EXECUTIVO!$B$20/CÁLCULO_MÉDIAS!AB$4*AA23 -> #DIV/0! | AD23: =[3]ORÇAMENTO_EXECUTIVO!$B$20/CÁLCULO_MÉDIAS!AD$4*AC23 -> #DIV/0! | AF23: 55 | AG23: 70
B24: PISOS E PAVIMENTAÇÕES | C24: 253.39718 | D24: =[3]ORÇAMENTO_EXECUTIVO!$B$20/CÁLCULO_MÉDIAS!D$4*C24 -> 261.35602 | F24: =[3]ORÇAMENTO_EXECUTIVO!$B$20/CÁLCULO_MÉDIAS!F$4*E24 -> #DIV/0! | G24: 258.11 | H24: =[3]ORÇAMENTO_EXECUTIVO!$B$20/CÁLCULO_MÉDIAS!H$4*G24 -> 272.75512 | I24: 221.98 | J24: =[3]ORÇAMENTO_EXECUTIVO!$B$20/CÁLCULO_MÉDIAS!J$4*I24 -> 256.26522 | K24: 232.62 | L24: =Versões!$F$20/CÁLCULO_MÉDIAS!L$4*K24 -> 248.50355 | N24: =[3]ORÇAMENTO_EXECUTIVO!$B$20/CÁLCULO_MÉDIAS!N$4*M24 -> #DIV/0! | O24: 142.21829 | P24: =Versões!$F$20/CÁLCULO_MÉDIAS!P$4*O24 -> 150.39361 | R24: =[3]ORÇAMENTO_EXECUTIVO!$B$20/CÁLCULO_MÉDIAS!R$4*Q24 -> 0 | S24: 275.59 | T24: =Versões!$F$20/CÁLCULO_MÉDIAS!T$4*S24 -> 299.34397 | U24: 237.36 | V24: =[3]ORÇAMENTO_EXECUTIVO!$B$20/CÁLCULO_MÉDIAS!V$4*U24 -> 244.81514 | W24: 203.24 | X24: =Versões!$F$20/CÁLCULO_MÉDIAS!X$4*W24 -> 222.28104 | Y24: 201.49 | Z24: =Versões!$F$20/CÁLCULO_MÉDIAS!Z$4*Y24 -> 212.76808 | AB24: =[3]ORÇAMENTO_EXECUTIVO!$B$20/CÁLCULO_MÉDIAS!AB$4*AA24 -> #DIV/0! | AD24: =[3]ORÇAMENTO_EXECUTIVO!$B$20/CÁLCULO_MÉDIAS!AD$4*AC24 -> #DIV/0! | AF24: 220 | AG24: 320
B25: PINTURA INTERNA | C25: 75.431687 | D25: =[3]ORÇAMENTO_EXECUTIVO!$B$20/CÁLCULO_MÉDIAS!D$4*C25 -> 77.800889 | F25: =[3]ORÇAMENTO_EXECUTIVO!$B$20/CÁLCULO_MÉDIAS!F$4*E25 -> #DIV/0! | G25: 168.13 | H25: =[3]ORÇAMENTO_EXECUTIVO!$B$20/CÁLCULO_MÉDIAS!H$4*G25 -> 177.66967 | I25: 88.9 | J25: =[3]ORÇAMENTO_EXECUTIVO!$B$20/CÁLCULO_MÉDIAS!J$4*I25 -> 102.63077 | K25: 58.7 | L25: =Versões!$F$20/CÁLCULO_MÉDIAS!L$4*K25 -> 62.708102 | N25: =[3]ORÇAMENTO_EXECUTIVO!$B$20/CÁLCULO_MÉDIAS!N$4*M25 -> #DIV/0! | O25: 139.12075 | P25: =Versões!$F$20/CÁLCULO_MÉDIAS!P$4*O25 -> 147.11801 | Q25: 131.71985 | R25: =[3]ORÇAMENTO_EXECUTIVO!$B$20/CÁLCULO_MÉDIAS!R$4*Q25 -> 140.57746 | S25: 77.54 | T25: =Versões!$F$20/CÁLCULO_MÉDIAS!T$4*S25 -> 84.223416 | U25: 75.43 | V25: =[3]ORÇAMENTO_EXECUTIVO!$B$20/CÁLCULO_MÉDIAS!V$4*U25 -> 77.799149 | W25: 90.86 | X25: =Versões!$F$20/CÁLCULO_MÉDIAS!X$4*W25 -> 99.372441 | Y25: 110 | Z25: =Versões!$F$20/CÁLCULO_MÉDIAS!Z$4*Y25 -> 116.15707 | AB25: =[3]ORÇAMENTO_EXECUTIVO!$B$20/CÁLCULO_MÉDIAS!AB$4*AA25 -> #DIV/0! | AD25: =[3]ORÇAMENTO_EXECUTIVO!$B$20/CÁLCULO_MÉDIAS!AD$4*AC25 -> #DIV/0! | AF25: 90 | AG25: 120
B26: ESQUADRIAS, VIDROS E FERRAGENS | C26: 563.3688 | D26: =[3]ORÇAMENTO_EXECUTIVO!$B$20/CÁLCULO_MÉDIAS!D$4*C26 -> 581.06341 | F26: =[3]ORÇAMENTO_EXECUTIVO!$B$20/CÁLCULO_MÉDIAS!F$4*E26 -> #DIV/0! | G26: 695.51 | H26: =[3]ORÇAMENTO_EXECUTIVO!$B$20/CÁLCULO_MÉDIAS!H$4*G26 -> 734.97312 | I26: 557.55 | J26: =[3]ORÇAMENTO_EXECUTIVO!$B$20/CÁLCULO_MÉDIAS!J$4*I26 -> 643.66462 | K26: 298.16 | L26: =Versões!$F$20/CÁLCULO_MÉDIAS!L$4*K26 -> 318.5187 | N26: =[3]ORÇAMENTO_EXECUTIVO!$B$20/CÁLCULO_MÉDIAS!N$4*M26 -> #DIV/0! | O26: 228.01196 | P26: =Versões!$F$20/CÁLCULO_MÉDIAS!P$4*O26 -> 241.11907 | Q26: 323.47432 | R26: =[3]ORÇAMENTO_EXECUTIVO!$B$20/CÁLCULO_MÉDIAS!R$4*Q26 -> 345.22661 | S26: 538.76 | T26: =Versões!$F$20/CÁLCULO_MÉDIAS!T$4*S26 -> 585.19741 | U26: 563.37 | V26: =[3]ORÇAMENTO_EXECUTIVO!$B$20/CÁLCULO_MÉDIAS!V$4*U26 -> 581.06465 | W26: 393.73 | X26: =Versões!$F$20/CÁLCULO_MÉDIAS!X$4*W26 -> 430.61756 | Y26: 248.7 | Z26: =Versões!$F$20/CÁLCULO_MÉDIAS!Z$4*Y26 -> 262.62058 | AB26: =[3]ORÇAMENTO_EXECUTIVO!$B$20/CÁLCULO_MÉDIAS!AB$4*AA26 -> #DIV/0! | AD26: =[3]ORÇAMENTO_EXECUTIVO!$B$20/CÁLCULO_MÉDIAS!AD$4*AC26 -> #DIV/0! | AF26: 320 | AG26: 415
B27: COBERTURA | C27: 563.3688 | D27: =[3]ORÇAMENTO_EXECUTIVO!$B$20/CÁLCULO_MÉDIAS!D$4*C27 -> 581.06341 | F27: =[3]ORÇAMENTO_EXECUTIVO!$B$20/CÁLCULO_MÉDIAS!F$4*E27 -> #DIV/0! | G27: 695.51 | H27: =[3]ORÇAMENTO_EXECUTIVO!$B$20/CÁLCULO_MÉDIAS!H$4*G27 -> 734.97312 | I27: 557.55 | J27: =[3]ORÇAMENTO_EXECUTIVO!$B$20/CÁLCULO_MÉDIAS!J$4*I27 -> 643.66462 | K27: 18.25 | L27: =Versões!$F$20/CÁLCULO_MÉDIAS!L$4*K27 -> 19.49613 | N27: =[3]ORÇAMENTO_EXECUTIVO!$B$20/CÁLCULO_MÉDIAS!N$4*M27 -> #DIV/0! | O27: 30.766772 | P27: =Versões!$F$20/CÁLCULO_MÉDIAS!P$4*O27 -> 32.535379 | Q27: 5.0049675 | R27: =[3]ORÇAMENTO_EXECUTIVO!$B$20/CÁLCULO_MÉDIAS!R$4*Q27 -> 5.3415307 | S27: 21.68 | T27: =Versões!$F$20/CÁLCULO_MÉDIAS!T$4*S27 -> 23.548667 | U27: 563.37 | V27: =[3]ORÇAMENTO_EXECUTIVO!$B$20/CÁLCULO_MÉDIAS!V$4*U27 -> 581.06465 | W27: 21.09 | X27: =Versões!$F$20/CÁLCULO_MÉDIAS!X$4*W27 -> 23.065868 | Y27: 7.25 | Z27: =Versões!$F$20/CÁLCULO_MÉDIAS!Z$4*Y27 -> 7.6558071 | AB27: =[3]ORÇAMENTO_EXECUTIVO!$B$20/CÁLCULO_MÉDIAS!AB$4*AA27 -> #DIV/0! | AD27: =[3]ORÇAMENTO_EXECUTIVO!$B$20/CÁLCULO_MÉDIAS!AD$4*AC27 -> #DIV/0! | AF27: 25 | AG27: 35
B28: REVESTIMENTOS E ACABAMENTOS DE FACHADA | C28: 106.61098 | D28: =[3]ORÇAMENTO_EXECUTIVO!$B$20/CÁLCULO_MÉDIAS!D$4*C28 -> 109.95948 | F28: =[3]ORÇAMENTO_EXECUTIVO!$B$20/CÁLCULO_MÉDIAS!F$4*E28 -> #DIV/0! | G28: 273.88 | H28: =[3]ORÇAMENTO_EXECUTIVO!$B$20/CÁLCULO_MÉDIAS!H$4*G28 -> 289.4199 | I28: 155.33 | J28: =[3]ORÇAMENTO_EXECUTIVO!$B$20/CÁLCULO_MÉDIAS!J$4*I28 -> 179.321 | K28: 164.45 | L28: =Versões!$F$20/CÁLCULO_MÉDIAS!L$4*K28 -> 175.67883 | N28: =[3]ORÇAMENTO_EXECUTIVO!$B$20/CÁLCULO_MÉDIAS!N$4*M28 -> #DIV/0! | O28: 165.52214 | P28: =Versões!$F$20/CÁLCULO_MÉDIAS!P$4*O28 -> 175.03707 | Q28: 165.68145 | R28: =[3]ORÇAMENTO_EXECUTIVO!$B$20/CÁLCULO_MÉDIAS!R$4*Q28 -> 176.82284 | S28: 360.6 | T28: =Versões!$F$20/CÁLCULO_MÉDIAS!T$4*S28 -> 391.68124 | U28: 106.61 | V28: =[3]ORÇAMENTO_EXECUTIVO!$B$20/CÁLCULO_MÉDIAS!V$4*U28 -> 109.95847 | W28: 120.6 | X28: =Versões!$F$20/CÁLCULO_MÉDIAS!X$4*W28 -> 131.89871 | Y28: 73.95 | Z28: =Versões!$F$20/CÁLCULO_MÉDIAS!Z$4*Y28 -> 78.089233 | AB28: =[3]ORÇAMENTO_EXECUTIVO!$B$20/CÁLCULO_MÉDIAS!AB$4*AA28 -> #DIV/0! | AD28: =[3]ORÇAMENTO_EXECUTIVO!$B$20/CÁLCULO_MÉDIAS!AD$4*AC28 -> #DIV/0! | AF28: 90 | AG28: 180
B29: SERVIÇOS COMPLEMENTARES | C29: 371.14469 | D29: =[3]ORÇAMENTO_EXECUTIVO!$B$20/CÁLCULO_MÉDIAS!D$4*C29 -> 382.80182 | F29: =[3]ORÇAMENTO_EXECUTIVO!$B$20/CÁLCULO_MÉDIAS!F$4*E29 -> #DIV/0! | G29: 334.34 | H29: =[3]ORÇAMENTO_EXECUTIVO!$B$20/CÁLCULO_MÉDIAS!H$4*G29 -> 353.31039 | I29: 82.14 | J29: =[3]ORÇAMENTO_EXECUTIVO!$B$20/CÁLCULO_MÉDIAS!J$4*I29 -> 94.826673 | K29: 167.95 | L29: =Versões!$F$20/CÁLCULO_MÉDIAS!L$4*K29 -> 179.41781 | N29: =[3]ORÇAMENTO_EXECUTIVO!$B$20/CÁLCULO_MÉDIAS!N$4*M29 -> #DIV/0! | O29: 168.56441 | P29: =Versões!$F$20/CÁLCULO_MÉDIAS!P$4*O29 -> 178.25422 | Q29: 142.84172 | R29: =[3]ORÇAMENTO_EXECUTIVO!$B$20/CÁLCULO_MÉDIAS!R$4*Q29 -> 152.44723 | S29: 229.66 | T29: =Versões!$F$20/CÁLCULO_MÉDIAS!T$4*S29 -> 249.45512 | U29: 371.14 | V29: =[3]ORÇAMENTO_EXECUTIVO!$B$20/CÁLCULO_MÉDIAS!V$4*U29 -> 382.79698 | W29: 152.51 | X29: =Versões!$F$20/CÁLCULO_MÉDIAS!X$4*W29 -> 166.79827 | Y29: 192.08 | Z29: =Versões!$F$20/CÁLCULO_MÉDIAS!Z$4*Y29 -> 202.83137 | AB29: =[3]ORÇAMENTO_EXECUTIVO!$B$20/CÁLCULO_MÉDIAS!AB$4*AA29 -> #DIV/0! | AD29: =[3]ORÇAMENTO_EXECUTIVO!$B$20/CÁLCULO_MÉDIAS!AD$4*AC29 -> #DIV/0! | AF29: 180 | AG29: 250
B30: MÃO DE OBRA | C30: 371.14469 | D30: =[3]ORÇAMENTO_EXECUTIVO!$B$20/CÁLCULO_MÉDIAS!D$4*C30 -> 382.80182 | F30: =[3]ORÇAMENTO_EXECUTIVO!$B$20/CÁLCULO_MÉDIAS!F$4*E30 -> #DIV/0! | G30: 334.34 | H30: =[3]ORÇAMENTO_EXECUTIVO!$B$20/CÁLCULO_MÉDIAS!H$4*G30 -> 353.31039 | I30: 82.14 | J30: =[3]ORÇAMENTO_EXECUTIVO!$B$20/CÁLCULO_MÉDIAS!J$4*I30 -> 94.826673 | L30: =Versões!$F$20/CÁLCULO_MÉDIAS!L$4*K30 -> 0 | N30: =[3]ORÇAMENTO_EXECUTIVO!$B$20/CÁLCULO_MÉDIAS!N$4*M30 -> #DIV/0! | P30: =Versões!$F$20/CÁLCULO_MÉDIAS!P$4*O30 -> 0 | R30: =[3]ORÇAMENTO_EXECUTIVO!$B$20/CÁLCULO_MÉDIAS!R$4*Q30 -> 0 | S30: 2131.58 | T30: =Versões!$F$20/CÁLCULO_MÉDIAS!T$4*S30 -> 2315.3076 | U30: 371.14 | V30: =[3]ORÇAMENTO_EXECUTIVO!$B$20/CÁLCULO_MÉDIAS!V$4*U30 -> 382.79698 | X30: =Versões!$F$20/CÁLCULO_MÉDIAS!X$4*W30 -> 0 | Z30: =Versões!$F$20/CÁLCULO_MÉDIAS!Z$4*Y30 -> 0 | AB30: =[3]ORÇAMENTO_EXECUTIVO!$B$20/CÁLCULO_MÉDIAS!AB$4*AA30 -> #DIV/0! | AD30: =[3]ORÇAMENTO_EXECUTIVO!$B$20/CÁLCULO_MÉDIAS!AD$4*AC30 -> #DIV/0!
B31: PÓS OBRA | C31: 371.14469 | D31: =[3]ORÇAMENTO_EXECUTIVO!$B$20/CÁLCULO_MÉDIAS!D$4*C31 -> 382.80182 | F31: =[3]ORÇAMENTO_EXECUTIVO!$B$20/CÁLCULO_MÉDIAS!F$4*E31 -> #DIV/0! | G31: 334.34 | H31: =[3]ORÇAMENTO_EXECUTIVO!$B$20/CÁLCULO_MÉDIAS!H$4*G31 -> 353.31039 | I31: 82.14 | J31: =[3]ORÇAMENTO_EXECUTIVO!$B$20/CÁLCULO_MÉDIAS!J$4*I31 -> 94.826673 | L31: =Versões!$F$20/CÁLCULO_MÉDIAS!L$4*K31 -> 0 | N31: =[3]ORÇAMENTO_EXECUTIVO!$B$20/CÁLCULO_MÉDIAS!N$4*M31 -> #DIV/0! | P31: =Versões!$F$20/CÁLCULO_MÉDIAS!P$4*O31 -> 0 | R31: =[3]ORÇAMENTO_EXECUTIVO!$B$20/CÁLCULO_MÉDIAS!R$4*Q31 -> 0 | S31: 48.793744 | T31: =Versões!$F$20/CÁLCULO_MÉDIAS!T$4*S31 -> 52.99943 | U31: 371.14 | V31: =[3]ORÇAMENTO_EXECUTIVO!$B$20/CÁLCULO_MÉDIAS!V$4*U31 -> 382.79698 | X31: =Versões!$F$20/CÁLCULO_MÉDIAS!X$4*W31 -> 0 | Z31: =Versões!$F$20/CÁLCULO_MÉDIAS!Z$4*Y31 -> 0 | AB31: =[3]ORÇAMENTO_EXECUTIVO!$B$20/CÁLCULO_MÉDIAS!AB$4*AA31 -> #DIV/0! | AD31: =[3]ORÇAMENTO_EXECUTIVO!$B$20/CÁLCULO_MÉDIAS!AD$4*AC31 -> #DIV/0!
B32: TOTAL | C32: =SUM(C13:C31) -> 4905.704 | D32: =SUM(D13:D31) -> 5059.7852 | E32: =SUM(E13:E31) -> 0 | F32: =SUM(F13:F31) -> #DIV/0! | G32: =SUM(G13:G31) -> 6066.18 | H32: =SUM(H13:H31) -> 6410.374 | I32: =SUM(I13:I31) -> 4652.67 | J32: =SUM(J13:J31) -> 5371.2834 | ... AD32: =SUM(AD13:AD31) -> #DIV/0! | AF32: =SUM(AF14:AF31) -> 2510 | AG32: =SUM(AG14:AG31) -> 3475
