Workbook

Sheet B02. TABELA DE ALVENARIAS
B1: Nível | C1: Tipo | D1: Descrição | E1: Área | G1: Tabela de alvenaria
B2: MOD_00_TER
B3: MOD_00_TER | C3: 02_ALV 11,5 cm OSSO | D3: BLOCO CERAMICO, 11,5 cm | E3: 165.82 | G3: Pavimento | H3: Descrição | I3: área
B4: MOD_00_TER | C4: 03_ALV 14 cm OSSO | D4: BLOCO CERAMICO, 14 cm | E4: 172.94 | G4: MOD_00_TER | H4: BLOCO CERAMICO, 11,5 cm | I4: =SUMIFS(E:E,B:B,G4,D:D,H4) -> 165.82
B5: MOD_00_TER | C5: 14_ACF 12,5 cm OSSO | D5: ALVENARIA_CORTA_FOGO_12,5cm | E5: 155.28 | G5: MOD_00_TER | H5: BLOCO CERAMICO, 14 cm | I5: =SUMIFS(E:E,B:B,G5,D:D,H5) -> 172.94
B6: MOD_01_MEZ | G6: MOD_00_TER | H6: ALVENARIA_CORTA_FOGO_12,5cm | I6: =SUMIFS(E:E,B:B,G6,D:D,H6) -> 155.28
B7: MOD_01_MEZ | C7: 02_ALV 11,5 cm OSSO | D7: BLOCO CERAMICO, 11,5 cm | E7: 95.32 | G7: MOD_00_TER | H7: DRY WALL_7cm com lã de rocha | I7: =SUMIFS(E:E,B:B,G7,D:D,H7) -> 0
B8: MOD_01_MEZ | C8: 03_ALV 14 cm OSSO | D8: BLOCO CERAMICO, 14 cm | E8: 216.7 | G8: MOD_00_TER | H8: TIJOLO REFRATÁRIO 22,9x11,4x2,5cm | I8: =SUMIFS(E:E,B:B,G8,D:D,H8) -> 0
B9: MOD_01_MEZ | C9: 08_DRY_7 cm com Lã de Rocha OSSO | D9: DRY WALL_7cm com lã de rocha | E9: 24.72 | G9: MOD_00_TER | H9: DRY WALL_9cm com lã de rocha | I9: =SUMIFS(E:E,B:B,G9,D:D,H9) -> 0
B10: MOD_01_MEZ | C10: 14_ACF 12,5 cm OSSO | D10: ALVENARIA_CORTA_FOGO_12,5cm | E10: 82.26 | G10: MOD_00_TER | H10: ALVENARIA_CORTA_FOGO_10cm | I10: =SUMIFS(E:E,B:B,G10,D:D,H10) -> 0
B11: MOD_02_G01
B12: MOD_02_G01 | C12: 02_ALV 11,5 cm OSSO | D12: BLOCO CERAMICO, 11,5 cm | E12: 17.6 | G12: Pavimento | H12: Descrição | I12: área
B13: MOD_02_G01 | C13: 03_ALV 14 cm OSSO | D13: BLOCO CERAMICO, 14 cm | E13: 203.66 | G13: MOD_01_MEZ | H13: BLOCO CERAMICO, 11,5 cm | I13: =SUMIFS(E:E,B:B,G13,D:D,H13) -> 95.32
B14: MOD_02_G01 | C14: 14_ACF 12,5 cm OSSO | D14: ALVENARIA_CORTA_FOGO_12,5cm | E14: 49.56 | G14: MOD_01_MEZ | H14: BLOCO CERAMICO, 14 cm | I14: =SUMIFS(E:E,B:B,G14,D:D,H14) -> 216.7
B15: MOD_03_G02 | G15: MOD_01_MEZ | H15: ALVENARIA_CORTA_FOGO_12,5cm | I15: =SUMIFS(E:E,B:B,G15,D:D,H15) -> 82.26
B16: MOD_03_G02 | C16: 02_ALV 11,5 cm OSSO | D16: BLOCO CERAMICO, 11,5 cm | E16: 18.76 | G16: MOD_01_MEZ | H16: DRY WALL_7cm com lã de rocha | I16: =SUMIFS(E:E,B:B,G16,D:D,H16) -> 24.72
B17: MOD_03_G02 | C17: 03_ALV 14 cm OSSO | D17: BLOCO CERAMICO, 14 cm | E17: 206.95 | G17: MOD_01_MEZ | H17: TIJOLO REFRATÁRIO 22,9x11,4x2,5cm | I17: =SUMIFS(E:E,B:B,G17,D:D,H17) -> 0
B18: MOD_03_G02 | C18: 14_ACF 12,5 cm OSSO | D18: ALVENARIA_CORTA_FOGO_12,5cm | E18: 49.57 | G18: MOD_01_MEZ | H18: DRY WALL_9cm com lã de rocha | I18: =SUMIFS(E:E,B:B,G18,D:D,H18) -> 0
B19: MOD_04_G03 | G19: MOD_01_MEZ | H19: ALVENARIA_CORTA_FOGO_10cm | I19: =SUMIFS(E:E,B:B,G19,D:D,H19) -> 0
B20: MOD_04_G03 | C20: 02_ALV 11,5 cm OSSO | D20: BLOCO CERAMICO, 11,5 cm | E20: 19.12
B21: MOD_04_G03 | C21: 03_ALV 14 cm OSSO | D21: BLOCO CERAMICO, 14 cm | E21: 221.73 | G21: Pavimento | H21: Descrição | I21: área
B22: MOD_04_G03 | C22: 14_ACF 12,5 cm OSSO | D22: ALVENARIA_CORTA_FOGO_12,5cm | E22: 49.98 | G22: MOD_02_G01 | H22: BLOCO CERAMICO, 11,5 cm | I22: =SUMIFS(E:E,B:B,G22,D:D,H22) -> 17.6
B23: MOD_05_LAZ | G23: MOD_02_G01 | H23: BLOCO CERAMICO, 14 cm | I23: =SUMIFS(E:E,B:B,G23,D:D,H23) -> 203.66
B24: MOD_05_LAZ | C24: 02_ALV 11,5 cm OSSO | D24: BLOCO CERAMICO, 11,5 cm | E24: 412.91 | G24: MOD_02_G01 | H24: ALVENARIA_CORTA_FOGO_12,5cm | I24: =SUMIFS(E:E,B:B,G24,D:D,H24) -> 49.56
B25: MOD_05_LAZ | C25: 03_ALV 14 cm OSSO | D25: BLOCO CERAMICO, 14 cm | E25: 62.94 | G25: MOD_02_G01 | H25: DRY WALL_7cm com lã de rocha | I25: =SUMIFS(E:E,B:B,G25,D:D,H25) -> 0
B26: MOD_05_LAZ | C26: 08_DRY_7 cm com Lã de Rocha OSSO | D26: DRY WALL_7cm com lã de rocha | E26: 10.39 | G26: MOD_02_G01 | H26: TIJOLO REFRATÁRIO 22,9x11,4x2,5cm | I26: =SUMIFS(E:E,B:B,G26,D:D,H26) -> 0
B27: MOD_05_LAZ | C27: 14_ACF 12,5 cm OSSO | D27: ALVENARIA_CORTA_FOGO_12,5cm | E27: 48.46 | G27: MOD_02_G01 | H27: DRY WALL_9cm com lã de rocha | I27: =SUMIFS(E:E,B:B,G27,D:D,H27) -> 0
B28: MOD_05_LAZ | C28: 67_TIJOLO REFRATÁRIO 22,9x11,4x2,5cm | D28: TIJOLO REFRATÁRIO 22,9x11,4x2,5cm | E28: 8.56 | G28: MOD_02_G01 | H28: ALVENARIA_CORTA_FOGO_10cm | I28: =SUMIFS(E:E,B:B,G28,D:D,H28) -> 0
A29: MOD_TIPO | B29: MOD_06_TIPO 01
A30: MOD_TIPO | B30: MOD_06_TIPO 01 | C30: 02_ALV 11,5 cm OSSO | D30: BLOCO CERAMICO, 11,5 cm | E30: 118.41 | G30: Pavimento | H30: Descrição | I30: área
A31: MOD_TIPO | B31: MOD_06_TIPO 01 | C31: 03_ALV 14 cm OSSO | D31: BLOCO CERAMICO, 14 cm | E31: 92.49 | G31: MOD_03_G02 | H31: BLOCO CERAMICO, 11,5 cm | I31: =SUMIFS(E:E,B:B,G31,D:D,H31) -> 18.76
B32: MOD_06_TIPO 01 | C32: 08_DRY_7 cm com Lã de Rocha OSSO | D32: DRY WALL_7cm com lã de rocha | E32: 266.45 | G32: MOD_03_G02 | H32: BLOCO CERAMICO, 14 cm | I32: =SUMIFS(E:E,B:B,G32,D:D,H32) -> 206.95
B33: MOD_06_TIPO 01 | C33: 09_DRY_09 cm com lã de rocha OSSO | D33: DRY WALL_9cm com lã de rocha | E33: 21 | G33: MOD_03_G02 | H33: ALVENARIA_CORTA_FOGO_12,5cm | I33: =SUMIFS(E:E,B:B,G33,D:D,H33) -> 49.57
A34: MOD_TIPO | B34: MOD_06_TIPO 01 | C34: 14_ACF 12,5 cm OSSO | D34: ALVENARIA_CORTA_FOGO_12,5cm | E34: 71.53 | G34: MOD_03_G02 | H34: DRY WALL_7cm com lã de rocha | I34: =SUMIFS(E:E,B:B,G34,D:D,H34) -> 0
B35: MOD_06_TIPO 01 | C35: 67_TIJOLO REFRATÁRIO 22,9x11,4x2,5cm | D35: TIJOLO REFRATÁRIO 22,9x11,4x2,5cm | E35: 6.36 | G35: MOD_03_G02 | H35: TIJOLO REFRATÁRIO 22,9x11,4x2,5cm | I35: =SUMIFS(E:E,B:B,G35,D:D,H35) -> 0
A36: MOD_TIPO | B36: MOD_07_TIPO 02 | G36: MOD_03_G02 | H36: DRY WALL_9cm com lã de rocha | I36: =SUMIFS(E:E,B:B,G36,D:D,H36) -> 0
A37: MOD_TIPO | B37: MOD_07_TIPO 02 | C37: 02_ALV 11,5 cm OSSO | D37: BLOCO CERAMICO, 11,5 cm | E37: 118.31 | G37: MOD_03_G02 | H37: ALVENARIA_CORTA_FOGO_10cm | I37: =SUMIFS(E:E,B:B,G37,D:D,H37) -> 0
A38: MOD_TIPO | B38: MOD_07_TIPO 02 | C38: 03_ALV 14 cm OSSO | D38: BLOCO CERAMICO, 14 cm | E38: 92.49
B39: MOD_07_TIPO 02 | C39: 08_DRY_7 cm com Lã de Rocha OSSO | D39: DRY WALL_7cm com lã de rocha | E39: 266.62 | G39: Pavimento | H39: Descrição | I39: área
B40: MOD_07_TIPO 02 | C40: 09_DRY_09 cm com lã de rocha OSSO | D40: DRY WALL_9cm com lã de rocha | E40: 21 | G40: MOD_04_G03 | H40: BLOCO CERAMICO, 11,5 cm | I40: =SUMIFS(E:E,B:B,G40,D:D,H40) -> 19.12
...

Sheet B03. TABELA DE ALVENARIAS GERAL
A1: Tipo | B1: Descrição | C1: Area | F1: Tabela alvenaria geral
A2: 02_ALV 11,5 cm OSSO | B2: BLOCO CERAMICO, 11,5 cm | C2: 2829.66
A3: 03_ALV 14 cm OSSO | B3: BLOCO CERAMICO, 14 cm | C3: 2725.02 | F3: Descrição | G3: área
A4: 03_ALV CONC 14 cm OSSO | B4: BLOCO CERAMICO, 14 cm | C4: 10.54 | F4: BLOCO CERAMICO, 11,5 cm | G4: 2829.66
A5: 08_DRY_7 cm com Lã de Rocha OSSO | B5: DRY WALL_7cm com lã de rocha | C5: 4285.9 | F5: BLOCO CERAMICO, 14 cm | G5: 2725.02
A6: 09_DRY_09 cm com lã de rocha OSSO | B6: DRY WALL_9cm com lã de rocha | C6: 315.01 | F6: BLOCO CERAMICO, 14 cm | G6: 10.54
A7: 13_ACF 10 cm OSSO | B7: ALVENARIA_CORTA_FOGO_10cm | C7: 69.81 | F7: DRY WALL_7cm com lã de rocha | G7: 4285.9
A8: 14_ACF 12,5 cm OSSO | B8: ALVENARIA_CORTA_FOGO_12,5cm | C8: 1708.24 | F8: DRY WALL_9cm com lã de rocha | G8: 315.01
A9: 67_TIJOLO REFRATÁRIO 22,9x11,4x2,5cm | B9: TIJOLO REFRATÁRIO 22,9x11,4x2,5cm | C9: 110.17 | F9: ALVENARIA_CORTA_FOGO_10cm | G9: 69.81
F10: ALVENARIA_CORTA_FOGO_12,5cm | G10: 1708.24
F11: TIJOLO REFRATÁRIO 22,9x11,4x2,5cm | G11: 110.17

Sheet B04. TABELA REVEST PAREDES
A1: Nível | B1: Chapisco | D1: Tipo | E1: Comprimento | F1: Área | I1: REVESTIMENTO DE PAREDES
A2: MOD_00_TER | I2: REVESTIMENTO BRUTO
A3: MOD_00_TER | B3: Alvenaria | C3: Pintura | D3: 25_PINTURA PAREDE PARA LAVABOS A. COMUM | E3: 16,05 m | F3: 39.2 | I3: Descrição | J3: m2
A4: MOD_00_TER | B4: Alvenaria | C4: Pintura | D4: 25_PINTURA PAREDE SALAS COMERCIAIS | E4: 56,85 m | F4: 156.5 | I4: Alvenaria | J4: =SUMIF(B:B,I4,F:F) -> 7421.54
A5: MOD_00_TER | B5: Estrutura | C5: Pintura | D5: 26_PINTURA PAREDE PARA LAVABOS ESTRUTURA A. COMUM | E5: 3,18 m | F5: 0.95 | I5: Estrutura | J5: =SUMIF(B:B,I5,F:F) -> 2979.74
A6: MOD_00_TER | B6: Estrutura | C6: Pintura | D6: 26_PINTURA SALAS COMERCIAIS ESTRUTURA | E6: 147,26 m | F6: 114.47 | I6: Estucamento | J6: =SUMIF(B:B,I6,F:F) -> 2006.83
A7: MOD_00_TER | B7: Alvenaria | C7: Pintura | D7: 28_PINTURA PAREDE A. COMUM (2cm) | E7: 25,33 m | F7: 45.15 | I7: Reboco | J7: =J5+J4 -> 10401.28
A8: MOD_00_TER | B8: Estrutura | C8: Pintura | D8: 29_PINTURA PAREDE ESTRUTURA A. COMUM (2cm) | E8: 27,29 m | F8: 44.75
A9: MOD_00_TER | B9: Estrutura | C9: Pintura | D9: 30_PINTURA PAREDE CISTERNA (2,5cm) | E9: 20,36 m | F9: 31.3
A10: MOD_00_TER | B10: Estrutura | C10: Pintura | D10: 30_PINTURA PAREDE CISTERNA ESTRUTURA (2,5cm) | E10: 11,53 m | F10: 9.11 | I10: REVESTIMENTO FINO
A11: MOD_00_TER | B11: Alvenaria | C11: Pintura | D11: 31_PINTURA PAREDE A. COMUM (1,5cm) | E11: 50,94 m | F11: 136.33 | I11: Descrição | J11: m2
A12: MOD_00_TER | B12: Estrutura | C12: Pintura | D12: 32_PINTURA PAREDE ESTRUTURA A. COMUM (1,5cm) | E12: 37,88 m | F12: 20.24 | I12: Drywall | J12: =SUMIF(C:C,I12,F:F) -> 6349.99
A13: MOD_00_TER | B13: Estrutura | C13: Pintura | D13: 36_PINTURA PAREDE PARA HALL COMUM ESTRUTURA | E13: 5,50 m | F13: 2.76 | I13: Pintura | J13: =SUMIF(C:C,I13,F:F) -> 5714.68
A14: MOD_00_TER | B14: Alvenaria | C14: Revestimento | D14: 43_REVESTIMENTO CERÂMICO PAREDE LIXEIRA | E14: 7,37 m | F14: 18.32 | I14: Revestimento | J14: =SUMIF(C:C,I14,F:F) -> 1153.25
A15: MOD_00_TER | B15: Alvenaria | C15: Pintura | D15: 44_PINTURA PAREDE CIMENTO QUEIMADO BRANCO | E15: 12,68 m | F15: 33.12 | I15: Revestimento Drywall | J15: =SUMIF(C:C,I15,F:F) -> 2005.74
A16: MOD_00_TER | B16: Alvenaria | C16: Textura | D16: 55_TEXTURA PAREDE PARA ESCADARIA | E16: 4,77 m | F16: 6.36 | I16: Textura | J16: =SUMIF(C:C,I16,F:F) -> 2480.92
A17: MOD_00_TER | B17: Estrutura | C17: Textura | D17: 56_TEXTURA PAREDE PARA ESCADARIA ESTRUTURA | E17: 6,78 m | F17: 7.35 | I17: Fosso | J17: =SUMIF(C:C,I17,F:F) -> 1084.63
A18: MOD_00_TER | B18: Alvenaria | C18: Textura | D18: 57_PINTURA PAREDE PARA GARAGEM | E18: 79,01 m | F18: 158.17 | I18: Revestimento (com drywall) | J18: =J15+J14 -> 3158.99
A19: MOD_00_TER | B19: Estrutura | C19: Textura | D19: 58_PINTURA PAREDE PARA GARAGEM ESTRUTURA | E19: 83,85 m | F19: 66.85 | I19: DESCRIÇÃO | J19: M2 | K19: ESPECIFICAÇÕES
A20: MOD_00_TER | B20: Alvenaria | C20: Revestimento | D20: 59_VINILICO MARMO SILVER 90x90 | E20: 11,91 m | F20: 20.59 | I20: 43_REVESTIMENTO CERÂMICO PAREDE LIXEIRA | J20: =SUMIF(D:D,I20,F:F) -> 18.32 | K20: 45x45
A21: MOD_00_TER | B21: Estrutura | C21: Revestimento | D21: 59_VINILICO MARMO SILVER 90x90 ESTRUTURA | E21: 3,40 m | F21: 2.65 | I21: 59_VINILICO MARMO SILVER 90x90 | J21: =SUMIF(D:D,I21,F:F) -> 98.45 | K21: 90x90
A22: MOD_00_TER | B22: Alvenaria | C22: Pintura | D22: 64_PINTURA BRANCA | E22: 16,50 m | F22: 38.38 | I22: 59_VINILICO MARMO SILVER 90x90 ESTRUTURA | J22: =SUMIF(D:D,I22,F:F) -> 9.61 | K22: 90x90
A23: MOD_00_TER | B23: Estrutura | C23: Pintura | D23: 64_PINTURA BRANCA ESTRUTURA | E23: 10,99 m | F23: 3.92 | I23: 66_PORCELANATO CINZA MARMORIZADO ITALIAGRIS | J23: =SUMIF(D:D,I23,F:F) -> 63.78 | K23: 80x160
A24: MOD_00_TER | B24: Alvenaria | C24: Revestimento | D24: 66_PORCELANATO CINZA MARMORIZADO ITALIAGRIS | E24: 5,64 m | F24: 14.43 | I24: 66_PORCELANATO CINZA MARMORIZADO ITALIAGRIS ESTRUTURA | J24: =SUMIF(D:D,I24,F:F) -> 8.89 | K24: 80x160
A25: MOD_00_TER | B25: Estrutura | C25: Revestimento | D25: 66_PORCELANATO CINZA MARMORIZADO ITALIAGRIS ESTRUTURA | E25: 1,21 m | F25: 3.57 | I25: 88_MANHATTAN GREY ANTIDERRAPANTE- Level Acabamentos 84x84 2 | J25: =SUMIF(D:D,I25,F:F) -> 69.14 | K25: 84x84
A26: MOD_00_TER | B26: Alvenaria | C26: Revestimento | D26: 88_MANHATTAN GREY ANTIDERRAPANTE- Level Acabamentos 84x84 2 | E26: 3,38 m | F26: 9.97 | I26: 61_VINILICO MADEIRADO CARVALHO | J26: =SUMIF(D:D,I26,F:F) -> 85.02 | K26: vinílico
A27: MOD_00_TER | B27: Alvenaria | C27: Fosso | D27: 90_PINTURA DE DUTOS E FOSSOS | E27: 14,84 m | F27: 65.03 | I27: 61_VINILICO MADEIRADO CARVALHO ESTRUTURA | J27: =SUMIF(D:D,I27,F:F) -> 22.04 | K27: vinílico
A28: MOD_00_TER | B28: Estucamento | D28: 91_REVESTIMENTO PAREDE ESTUCAMENTO DE PILAR | E28: 9,11 m | F28: 25.18 | I28: 63_REVESTIMENTO PORTOBELLO GOUACHE NUAGE | J28: =SUMIF(D:D,I28,F:F) -> 32.69 | K28: 15.5
A29: MOD_00_TER | B29: Estucamento | D29: 92_REVESTIMENTO PAREDE ESTUCAMENTO DE VIGA | E29: 10,40 m | F29: 4.49 | I29: 63_REVESTIMENTO PORTOBELLO GOUACHE NUAGE ESTRUTURA | J29: =SUMIF(D:D,I29,F:F) -> 0.66 | K29: 15.5
A30: MOD_00_TER | B30: Estucamento | D30: 93_REVESTIMENTO PAREDE ESTUCAMENTO DE PAREDES | E30: 22,31 m | F30: 36.52 | I30: 66_DRY_PORCELANATO CINZA MARMORIZADO ITALIAGRIS | J30: =SUMIF(D:D,I30,F:F) -> 3.3 | K30: 80x160
A31: MOD_01_MEZ | I31: 82_PASTILHA AZUL Hijau Leme - Level Acabamentos - 19,5x19,5cm | J31: =SUMIF(D:D,I31,F:F) -> 44.63 | K31: 19,5x19,5 pedra
A32: MOD_01_MEZ | C32: Drywall | D32: 25_DRY PINTURA PAREDE SALAS COMERCIAIS | E32: 22,08 m | F32: 44.74 | I32: 89_MANHATTAN GREY ANTIDERRAPANTE ESTRUTURA- Level Acabamentos 84x84 | J32: =SUMIF(D:D,I32,F:F) -> 5.93 | K32: 84x84
A33: MOD_01_MEZ | B33: Alvenaria | C33: Pintura | D33: 25_PINTURA PAREDE SALAS COMERCIAIS | E33: 59,40 m | F33: 116.97 | I33: 71_DRY_REVESTIMENTO PAREDE BANHEIRO | J33: =SUMIF(D:D,I33,F:F) -> 2000.5 | K33: 30x60
A34: MOD_01_MEZ | B34: Estrutura | C34: Pintura | D34: 26_PINTURA SALAS COMERCIAIS ESTRUTURA | E34: 94,51 m | F34: 75.53 | I34: 71_REVESTIMENTO PAREDE BANHEIRO | J34: =SUMIF(D:D,I34,F:F) -> 466.1 | K34: 30x60
A35: MOD_01_MEZ | B35: Alvenaria | C35: Pintura | D35: 28_PINTURA PAREDE A. COMUM (2cm) | E35: 41,20 m | F35: 88.56 | I35: 72_REVESTIMENTO PAREDE BANHEIRO ESTRUTURA | J35: =SUMIF(D:D,I35,F:F) -> 195.79 | K35: 30x60
A36: MOD_01_MEZ | B36: Estrutura | C36: Pintura | D36: 29_PINTURA PAREDE ESTRUTURA A. COMUM (2cm) | E36: 27,57 m | F36: 21.61 | I36: 82_REVESTIMENTO DE PISCINA EXTERNA | J36: =SUMIF(D:D,I36,F:F) -> 32.2
A37: MOD_01_MEZ | B37: Alvenaria | C37: Pintura | D37: 35_PINTURA PAREDE PARA HALL COMUM | E37: 17,27 m | F37: 26.53 | I37: 59_DRY_VINILICO MARMO SILVER 90x90 | J37: =SUMIF(D:D,I37,F:F) -> 1.94
A38: MOD_01_MEZ | B38: Estrutura | C38: Pintura | D38: 36_PINTURA PAREDE PARA HALL COMUM ESTRUTURA | E38: 14,22 m | F38: 5.42
A39: MOD_01_MEZ | B39: Alvenaria | C39: Pintura | D39: 44_PINTURA PAREDE CIMENTO QUEIMADO BRANCO | E39: 19,19 m | F39: 17.9 | I39: Total | J39: =SUM(J20:J38) -> 3158.99
A40: MOD_01_MEZ | B40: Estrutura | C40: Pintura | D40: 44_PINTURA PAREDE CIMENTO QUEIMADO BRANCO ESTRUTURA | E40: 3,76 m | F40: 1
...

Sheet B05. TABELA REVEST FACHADAS
A1: Nível | B1: Chapisco | C1: Tipo | D1: Área | F1: REVESTIMENTO DE FACHADA
A2: MOD_00_TER | F2: TIPO | G2: M2
A3: MOD_00_TER | B3: Estrutura | C3: 108_TEXTURA PROJETADA CINZA MEDIO ESTRUTURA FACHADA | D3: 0.15 | F3: Estrutura | G3: =SUMIF(B:B,F3,D:D) -> 2335.84
A4: MOD_00_TER | B4: Alvenaria | C4: 109_TEXTURA PROJETADA CINZA CLARO FACHADA | D4: 8.32 | F4: Alvenaria | G4: =SUMIF(B:B,F4,D:D) -> 3540.83
A5: MOD_00_TER | B5: Estrutura | C5: 110_TEXTURA PROJETADA CINZA CLARO ESTRUTURA FACHADA | D5: 2.06 | F5: Total | G5: =SUM(G3:G4) -> 5876.67
A6: MOD_00_TER | B6: Alvenaria | C6: 113_TEXTURA PROJETADA BRANCA FACHADA (DIVISA VIZINHO) | D6: 49.21
A7: MOD_00_TER | B7: Estrutura | C7: 114_TEXTURA PROJETADA BRANCA ESTRUTURA FACHADA (DIVISA VIZINHO) | D7: 21.59
A8: MOD_00_TER | B8: Alvenaria | C8: 105_TEXTURA STO 3mm CINZA ESCURO FACHADA | D8: 1.34
A9: MOD_00_TER | B9: Estrutura | C9: 106_TEXTURA STO 3mm CINZA ESCURO FACHADA ESTRUTURA | D9: 0.31
A10: MOD_00_TER | B10: Estrutura | C10: 116_TEXTURA STO 3mm CINZA MÉDIO FACHADA ESTRUTURA - EMBASAMENTO | D10: 9.45
A11: MOD_00_TER | C11: FACHADA EM VIDRO | D11: 48.24
A12: MOD_00_TER | B12: Alvenaria | C12: 107_TEXTURA PROJETADA CINZA MEDIO FACHADA | D12: 0.43
A13: MOD_00_TER | B13: Alvenaria | C13: 109_TEXTURA PROJETADA CINZA CLARO FACHADA | D13: 37.7
A14: MOD_00_TER | B14: Estrutura | C14: 110_TEXTURA PROJETADA CINZA CLARO ESTRUTURA FACHADA | D14: 32.68
A15: MOD_00_TER | B15: Alvenaria | C15: 115_TEXTURA STO 3mm CINZA MÉDIO FACHADA - EMBASAMENTO | D15: 1.45
A16: MOD_00_TER | B16: Estrutura | C16: 116_TEXTURA STO 3mm CINZA MÉDIO FACHADA ESTRUTURA - EMBASAMENTO | D16: 4.92
A17: MOD_00_TER | C17: FACHADA EM VIDRO | D17: 44.85
A18: MOD_00_TER | B18: Alvenaria | C18: 113_TEXTURA PROJETADA BRANCA FACHADA (DIVISA VIZINHO) | D18: 78.39
A19: MOD_00_TER | B19: Estrutura | C19: 114_TEXTURA PROJETADA BRANCA ESTRUTURA FACHADA (DIVISA VIZINHO) | D19: 26.01
A20: MOD_00_TER | B20: Estrutura | C20: 116_TEXTURA STO 3mm CINZA MÉDIO FACHADA ESTRUTURA - EMBASAMENTO | D20: 1.76
A21: MOD_01_MEZ
A22: MOD_01_MEZ | B22: Alvenaria | C22: 113_TEXTURA PROJETADA BRANCA FACHADA (DIVISA VIZINHO) | D22: 47.61
A23: MOD_01_MEZ | B23: Estrutura | C23: 114_TEXTURA PROJETADA BRANCA ESTRUTURA FACHADA (DIVISA VIZINHO) | D23: 17.78
A24: MOD_01_MEZ | B24: Alvenaria | C24: 111_TEXTURA PROJETADA BRANCA FACHADA - DETALHE FACHADA | D24: 5.47
A25: MOD_01_MEZ | B25: Alvenaria | C25: 113_TEXTURA PROJETADA BRANCA FACHADA (DIVISA VIZINHO) | D25: 0.26
A26: MOD_01_MEZ | B26: Estrutura | C26: 114_TEXTURA PROJETADA BRANCA ESTRUTURA FACHADA (DIVISA VIZINHO) | D26: 2.37
A27: MOD_01_MEZ | B27: Alvenaria | C27: 115_TEXTURA STO 3mm CINZA MÉDIO FACHADA - EMBASAMENTO | D27: 17.99
A28: MOD_01_MEZ | B28: Estrutura | C28: 116_TEXTURA STO 3mm CINZA MÉDIO FACHADA ESTRUTURA - EMBASAMENTO | D28: 41.84
A29: MOD_01_MEZ | C29: 1001_BRISE METÁLICO | D29: 7.07
A30: MOD_01_MEZ | C30: FACHADA EM VIDRO | D30: 15.99
A31: MOD_01_MEZ | B31: Estrutura | C31: 108_TEXTURA PROJETADA CINZA MEDIO ESTRUTURA FACHADA | D31: 2.97
A32: MOD_01_MEZ | B32: Alvenaria | C32: 109_TEXTURA PROJETADA CINZA CLARO FACHADA | D32: 6.57
A33: MOD_01_MEZ | B33: Estrutura | C33: 110_TEXTURA PROJETADA CINZA CLARO ESTRUTURA FACHADA | D33: 5.65
A34: MOD_01_MEZ | B34: Alvenaria | C34: 111_TEXTURA PROJETADA BRANCA FACHADA - DETALHE FACHADA | D34: 7.56
A35: MOD_01_MEZ | B35: Alvenaria | C35: 115_TEXTURA STO 3mm CINZA MÉDIO FACHADA - EMBASAMENTO | D35: 9.88
A36: MOD_01_MEZ | B36: Estrutura | C36: 116_TEXTURA STO 3mm CINZA MÉDIO FACHADA ESTRUTURA - EMBASAMENTO | D36: 28.45
A37: MOD_01_MEZ | C37: 1001_BRISE METÁLICO | D37: 50.25
A38: MOD_01_MEZ | C38: FACHADA EM VIDRO | D38: 11.84
A39: MOD_01_MEZ | B39: Alvenaria | C39: 113_TEXTURA PROJETADA BRANCA FACHADA (DIVISA VIZINHO) | D39: 73.97
A40: MOD_01_MEZ | B40: Estrutura | C40: 114_TEXTURA PROJETADA BRANCA ESTRUTURA FACHADA (DIVISA VIZINHO) | D40: 27.31
...

Sheet B06. TABELA REVEST PISO
A1: Nível | B1: Tipo | C1: Área
A2: MOD_00_TER
A3: MOD_00_TER | B3: 41_PISO PORCELANATO HALL | C3: 22 | D3: 80x80 | F3: 141_PISO CIMENTADO | G3: Pintura em piso | H3: =SUMIF(B:B,F3,C:C) -> 407 | I3: =H3-C9+15 -> 344
A4: MOD_00_TER | B4: 46_PISO PORCELANATO SALA COMERCIAL | C4: 233 | D4: 80x80
A5: MOD_00_TER | B5: 48_PISO PORCELANATO ANTECAMARA E ESCADA | C5: 3 | D5: 80x80
A6: MOD_00_TER | B6: 74_POLIMENTO DE PISO + RESINA ACRILICA | C6: 268 | D6: polimento | F6: 80x80 | H6: =SUMIF(D:D,F6,C:C) -> 3075 | J6: mão de obra porcelanato | K6: =H6+H11+H12+H17+H18+H14 -> 3820
A7: MOD_00_TER | B7: 75_RESINA A BASE DE SOLVENTE - HIDRONORTH | C7: 6 | D7: resina | F7: polimento | H7: =SUMIF(D:D,F7,C:C) -> 2563 | J7: Mão de obra pastilha | K7: =H23 -> 26
A8: MOD_00_TER | B8: 102_PISO PORCELANATO LAVABO | C8: 6 | D8: 80x80 | F8: resina | H8: =SUMIF(D:D,F8,C:C) -> 99 | J8: Mão de obra vinílico | K8: =H15+H24 -> 1646
A9: MOD_00_TER | B9: 141_PISO CIMENTADO | C9: 78 | D9: cimentado | F9: cimentado | H9: =SUMIF(D:D,F9,C:C) -> 407 | J9: Mão de obra pedra | K9: =H21 -> 5
A10: MOD_00_TER | B10: 145_LADRILHO HIDRÁULICO | C10: 83 | D10: ladrilho | F10: ladrilho | H10: =SUMIF(D:D,F10,C:C) -> 344 | J10: Mão de obra ladrilho | K10: =H10 -> 344
A11: MOD_00_TER | B11: 171_PISO PORCELANATO CINZA MARMORIZADO - Italiagris Level Acabamentos - 80x80cm | C11: 46 | D11: luminositá | F11: luminositá | H11: =SUMIF(D:D,F11,C:C) -> 406 | J11: Mão de obra carpet | K11: =H16 -> 9
A12: MOD_00_TER | B12: 176_PISO MANHATTAN GREY ANTIDERRAPANTE- Level Acabamentos 84x84 | C12: 13 | D12: 84x84 | F12: 84x84 | H12: =SUMIF(D:D,F12,C:C) -> 83 | J12: Mão de obra PVC | K12: =H20 -> 72
A13: MOD_00_TER | B13: 202_PISO CONCRETO ESTAMPADO | C13: 310 | D13: estampado | F13: estampado | H13: =SUMIF(D:D,F13,C:C) -> 310 | K13: =SUM(K6:K12) -> 5922
A14: MOD_01_MEZ | F14: 19,5x19,5 | H14: =SUMIF(D:D,F14,C:C) -> 78
A15: MOD_01_MEZ | B15: 46_PISO PORCELANATO SALA COMERCIAL | C15: 65 | D15: 80x80 | F15: vinílico | H15: =SUMIF(D:D,F15,C:C) -> 1600
A16: MOD_01_MEZ | B16: 48_PISO PORCELANATO ANTECAMARA E ESCADA | C16: 3 | D16: 80x80 | F16: carpet | H16: =SUMIF(D:D,F16,C:C) -> 9
A17: MOD_01_MEZ | B17: 74_POLIMENTO DE PISO + RESINA ACRILICA | C17: 350 | D17: polimento | F17: 120x120 | H17: =SUMIF(D:D,F17,C:C) -> 33
A18: MOD_01_MEZ | B18: 75_RESINA A BASE DE SOLVENTE - HIDRONORTH | C18: 12 | D18: resina | F18: 19,4x118,22 | H18: =SUMIF(D:D,F18,C:C) -> 145
A19: MOD_01_MEZ | B19: 141_PISO CIMENTADO | C19: 14 | D19: cimentado | F19: epóxi | H19: =SUMIF(D:D,F19,C:C) -> 97
A20: MOD_01_MEZ | B20: 145_LADRILHO HIDRÁULICO | C20: 87 | D20: ladrilho | F20: PVC | H20: =SUMIF(D:D,F20,C:C) -> 72
A21: MOD_01_MEZ | B21: 171_PISO PORCELANATO CINZA MARMORIZADO - Italiagris Level Acabamentos - 80x80cm | C21: 8 | D21: luminositá | F21: Granito | H21: =SUMIF(D:D,F21,C:C) -> 5
A22: MOD_02_G01 | F22: deck | H22: =SUMIF(D:D,F22,C:C) -> 34
A23: MOD_02_G01 | B23: 41_PISO PORCELANATO HALL | C23: 8 | D23: 80x80 | F23: pastilha | H23: =SUMIF(D:D,F23,C:C) -> 26
A24: MOD_02_G01 | B24: 48_PISO PORCELANATO ANTECAMARA E ESCADA | C24: 3 | D24: 80x80 | F24: madeirado | H24: =SUMIF(D:D,F24,C:C) -> 46
A25: MOD_02_G01 | B25: 74_POLIMENTO DE PISO + RESINA ACRILICA | C25: 644 | D25: polimento
A26: MOD_02_G01 | B26: 75_RESINA A BASE DE SOLVENTE - HIDRONORTH | C26: 27 | D26: resina | H26: =SUM(H6:H25) -> 9432
A27: MOD_02_G01 | B27: 141_PISO CIMENTADO | C27: 14 | D27: cimentado | H27: =H26-H22-H19-H9-H8-H7-H13 -> 5922
A28: MOD_02_G01 | B28: 145_LADRILHO HIDRÁULICO | C28: 87 | D28: ladrilho
A29: MOD_03_G02
A30: MOD_03_G02 | B30: 41_PISO PORCELANATO HALL | C30: 8 | D30: 80x80
A31: MOD_03_G02 | B31: 48_PISO PORCELANATO ANTECAMARA E ESCADA | C31: 3 | D31: 80x80
A32: MOD_03_G02 | B32: 74_POLIMENTO DE PISO + RESINA ACRILICA | C32: 644 | D32: polimento
A33: MOD_03_G02 | B33: 75_RESINA A BASE DE SOLVENTE - HIDRONORTH | C33: 27 | D33: resina
A34: MOD_03_G02 | B34: 141_PISO CIMENTADO | C34: 14 | D34: cimentado
A35: MOD_03_G02 | B35: 145_LADRILHO HIDRÁULICO | C35: 87 | D35: ladrilho
A36: MOD_04_G03
A37: MOD_04_G03 | B37: 41_PISO PORCELANATO HALL | C37: 8 | D37: 80x80
A38: MOD_04_G03 | B38: 48_PISO PORCELANATO ANTECAMARA E ESCADA | C38: 3 | D38: 80x80
A39: MOD_04_G03 | B39: 74_POLIMENTO DE PISO + RESINA ACRILICA | C39: 657 | D39: polimento
A40: MOD_04_G03 | B40: 75_RESINA A BASE DE SOLVENTE - HIDRONORTH | C40: 27 | D40: resina
...

Sheet B07. TABELA CONTRAPISOS
A1: Nível | B1: Tipo | C1: Descrição | D1: Área | G1: TABELA CONTRAPISOS
A2: MOD_00_TER | K2: CONTRAPISOS
A3: MOD_00_TER | B3: 01_CONTRA PISO 4 cm | C3: REVESTIMENTO INTERNO - CONTRA PISO, 4 cm | D3: 433 | G3: Pavimento | H3: Tipo | I3: Área | K3: TIPO | L3: M2
A4: MOD_01_MEZ | G4: MOD_00_TER | H4: 01_CONTRA PISO 4 cm | I4: 433 | K4: REVESTIMENTO INTERNO - CONTRA PISO, 4 cm | L4: =SUMIF(C:C,K4,D:D) -> 5609
A5: MOD_01_MEZ | B5: 01_CONTRA PISO 4 cm | C5: REVESTIMENTO INTERNO - CONTRA PISO, 4 cm | D5: 152 | K5: REVESTIMENTO INTERNO - CONTRA PISO, 5 cm | L5: =SUMIF(C:C,K5,D:D) -> 447
A6: MOD_02_G01 | G6: Pavimento | H6: Tipo | I6: Área | K6: REVESTIMENTO INTERNO - CONTRA PISO, 6 cm | L6: =SUMIF(C:C,K6,D:D) -> 90
A7: MOD_02_G01 | B7: 01_CONTRA PISO 4 cm | C7: REVESTIMENTO INTERNO - CONTRA PISO, 4 cm | D7: 25 | G7: MOD_01_MEZ | H7: 01_CONTRA PISO 4 cm | I7: 152 | K7: Total | L7: =SUM(L4:L6) -> 6146
A8: MOD_03_G02
A9: MOD_03_G02 | B9: 01_CONTRA PISO 4 cm | C9: REVESTIMENTO INTERNO - CONTRA PISO, 4 cm | D9: 25 | G9: Pavimento | H9: Tipo | I9: Área
A10: MOD_04_G03 | G10: MOD_02_G01 | H10: 01_CONTRA PISO 4 cm | I10: 25
A11: MOD_04_G03 | B11: 01_CONTRA PISO 4 cm | C11: REVESTIMENTO INTERNO - CONTRA PISO, 4 cm | D11: 25
A12: MOD_05_LAZ | G12: Pavimento | H12: Tipo | I12: Área
A13: MOD_05_LAZ | B13: 01_CONTRA PISO 4 cm | C13: REVESTIMENTO INTERNO - CONTRA PISO, 4 cm | D13: 268 | G13: MOD_03_G02 | H13: 01_CONTRA PISO 4 cm | I13: 25
A14: MOD_05_LAZ | B14: 02_CONTRA PISO 5 cm | C14: REVESTIMENTO INTERNO - CONTRA PISO, 5 cm | D14: 364
A15: MOD_05_LAZ | B15: 03_CONTRA PISO 6 cm | C15: REVESTIMENTO INTERNO - CONTRA PISO, 6 cm | D15: 90 | G15: Pavimento | H15: Tipo | I15: Área
A16: MOD_06_TIPO 01 | G16: MOD_04_G03 | H16: 01_CONTRA PISO 4 cm | I16: 25
A17: MOD_06_TIPO 01 | B17: 01_CONTRA PISO 4 cm | C17: REVESTIMENTO INTERNO - CONTRA PISO, 4 cm | D17: 282
A18: MOD_07_TIPO 02 | G18: Pavimento | H18: Tipo | I18: Área
A19: MOD_07_TIPO 02 | B19: 01_CONTRA PISO 4 cm | C19: REVESTIMENTO INTERNO - CONTRA PISO, 4 cm | D19: 282 | G19: MOD_05_LAZ | H19: 01_CONTRA PISO 4 cm | I19: 268
A20: MOD_08_TIPO 03 | G20: MOD_05_LAZ | H20: 02_CONTRA PISO 5 cm | I20: 364
A21: MOD_08_TIPO 03 | B21: 01_CONTRA PISO 4 cm | C21: REVESTIMENTO INTERNO - CONTRA PISO, 4 cm | D21: 282 | G21: MOD_05_LAZ | H21: 03_CONTRA PISO 6 cm | I21: 90
A22: MOD_09_TIPO 04
A23: MOD_09_TIPO 04 | B23: 01_CONTRA PISO 4 cm | C23: REVESTIMENTO INTERNO - CONTRA PISO, 4 cm | D23: 282 | G23: Pavimento | H23: Tipo | I23: Área
A24: MOD_10_TIPO 05 | G24: MOD_TIPO | H24: 01_CONTRA PISO 4 cm | I24: =SUM(D17:D45) -> 4205
A25: MOD_10_TIPO 05 | B25: 01_CONTRA PISO 4 cm | C25: REVESTIMENTO INTERNO - CONTRA PISO, 4 cm | D25: 257
A26: MOD_11_TIPO 06 | G26: Pavimento | H26: Tipo | I26: Área
A27: MOD_11_TIPO 06 | B27: 01_CONTRA PISO 4 cm | C27: REVESTIMENTO INTERNO - CONTRA PISO, 4 cm | D27: 282 | G27: MOD_21_DINF | H27: 01_CONTRA PISO 4 cm | I27: 283
A28: MOD_12_TIPO 07
A29: MOD_12_TIPO 07 | B29: 01_CONTRA PISO 4 cm | C29: REVESTIMENTO INTERNO - CONTRA PISO, 4 cm | D29: 282 | G29: Pavimento | H29: Tipo | I29: Área
A30: MOD_13_TIPO 08 | G30: MOD_22_DSUP | H30: 01_CONTRA PISO 4 cm | I30: 152
A31: MOD_13_TIPO 08 | B31: 01_CONTRA PISO 4 cm | C31: REVESTIMENTO INTERNO - CONTRA PISO, 4 cm | D31: 282 | G31: MOD_22_DSUP | H31: 02_CONTRA PISO 5 cm | I31: 83
A32: MOD_14_TIPO 09
A33: MOD_14_TIPO 09 | B33: 01_CONTRA PISO 4 cm | C33: REVESTIMENTO INTERNO - CONTRA PISO, 4 cm | D33: 282 | G33: Pavimento | H33: Tipo | I33: Área
A34: MOD_15_TIPO 10 | G34: MOD_23_TERRAÇO | H34: 01_CONTRA PISO 4 cm | I34: 25
A35: MOD_15_TIPO 10 | B35: 01_CONTRA PISO 4 cm | C35: REVESTIMENTO INTERNO - CONTRA PISO, 4 cm | D35: 282
A36: MOD_16_TIPO 11 | G36: Pavimento | H36: Tipo | I36: Área
A37: MOD_16_TIPO 11 | B37: 01_CONTRA PISO 4 cm | C37: REVESTIMENTO INTERNO - CONTRA PISO, 4 cm | D37: 282 | G37: MOD_24_CMQ | H37: 01_CONTRA PISO 4 cm | I37: 16
A38: MOD_17_TIPO 12
A39: MOD_17_TIPO 12 | B39: 01_CONTRA PISO 4 cm | C39: REVESTIMENTO INTERNO - CONTRA PISO, 4 cm | D39: 282
A40: MOD_18_TIPO 13
...

Sheet B08. TABELA DE TETOS
B1: dvdv | C1: Tipo | D1: Área | E1: Períetro | H1: TABELA TETOS
B2: MOD_00_TER | N2: TETOS
B3: MOD_00_TER | C3: ESTUCAMENTO EM TETO COM PINTURA | D3: 152.08 | E3: 186.41 | H3: Pavimento | I3: Descrição | J3: Área | K3: Perímetro | N3: DESCRIÇÃO | O3: M2
B4: MOD_00_TER | C4: FORRO DE GESSO ACARTONADO, STANDART ST, ÁREA SECA | D4: 208.32 | E4: 244.41 | H4: MOD_00_TER | I4: ESTUCAMENTO EM TETO COM PINTURA | J4: 152.08 | K4: 186.41 | N4: ESTUCAMENTO EM TETO COM PINTURA | O4: =SUMIF(C:C,N4,D:D) -> 3120.94
B5: MOD_01_MEZ | H5: MOD_00_TER | I5: FORRO DE GESSO ACARTONADO, STANDART ST, ÁREA SECA | J5: 208.32 | K5: 244.41 | N5: FORRO DE GESSO ACARTONADO, STANDART ST, ÁREA SECA | O5: =SUMIF(C:C,N5,D:D) -> 5093.85
B6: MOD_01_MEZ | C6: ESTUCAMENTO EM TETO COM PINTURA | D6: 539.19 | E6: 231.51 | N6: REVESTIMENTO ARGAMASSADO COM PINTURA EM TETO | O6: =SUMIF(C:C,N6,D:D) -> 10.85
B7: MOD_01_MEZ | C7: FORRO DE GESSO ACARTONADO, STANDART ST, ÁREA SECA | D7: 184.73 | E7: 180.16 | H7: Pavimento | I7: Descrição | J7: Área | K7: Perímetro | N7: Total | O7: =SUM(O4:O6) -> 8225.64
B8: MOD_01_MEZ | C8: TEXTURA PROJETADA BRANCA FACHADA - DETALHE FACHADA | D8: 82.41 | E8: 169.89 | H8: MOD_01_MEZ | I8: ESTUCAMENTO EM TETO COM PINTURA | J8: 539.19 | K8: 231.51
B9: MOD_02_G01 | H9: MOD_01_MEZ | I9: FORRO DE GESSO ACARTONADO, STANDART ST, ÁREA SECA | J9: 184.73 | K9: 180.16
B10: MOD_02_G01 | C10: ESTUCAMENTO EM TETO COM PINTURA | D10: 743.31 | E10: 248.33 | H10: MOD_01_MEZ | I10: TEXTURA PROJETADA BRANCA FACHADA - DETALHE FACHADA | J10: 82.41 | K10: 169.89
B11: MOD_02_G01 | C11: FORRO DE GESSO ACARTONADO, STANDART ST, ÁREA SECA | D11: 10.67 | E11: 21.22
B12: MOD_02_G01 | C12: TEXTURA PROJETADA BRANCA FACHADA - DETALHE FACHADA | D12: 124.31 | E12: 451.5 | H12: Pavimento | I12: Descrição | J12: Área | K12: Perímetro
B13: MOD_03_G02 | H13: MOD_02_G01 | I13: ESTUCAMENTO EM TETO COM PINTURA | J13: 743.31 | K13: 248.33
B14: MOD_03_G02 | C14: ESTUCAMENTO EM TETO COM PINTURA | D14: 671.01 | E14: 208.71 | H14: MOD_02_G01 | I14: FORRO DE GESSO ACARTONADO, STANDART ST, ÁREA SECA | J14: 10.67 | K14: 21.22
B15: MOD_03_G02 | C15: FORRO DE GESSO ACARTONADO, STANDART ST, ÁREA SECA | D15: 10.72 | E15: 21.35 | H15: MOD_02_G01 | I15: TEXTURA PROJETADA BRANCA FACHADA - DETALHE FACHADA | J15: 124.31 | K15: 451.5
B16: MOD_03_G02 | C16: TEXTURA PROJETADA BRANCA FACHADA - DETALHE FACHADA | D16: 79.3 | E16: 294.94
B17: MOD_04_G03 | H17: Pavimento | I17: Descrição | J17: Área | K17: Perímetro
B18: MOD_04_G03 | C18: ESTUCAMENTO EM TETO COM PINTURA | D18: 730.74 | E18: 822.43 | H18: MOD_03_G02 | I18: ESTUCAMENTO EM TETO COM PINTURA | J18: 671.01 | K18: 208.71
B19: MOD_04_G03 | C19: FORRO DE GESSO ACARTONADO, STANDART ST, ÁREA SECA | D19: 10.67 | E19: 21.22 | H19: MOD_03_G02 | I19: FORRO DE GESSO ACARTONADO, STANDART ST, ÁREA SECA | J19: 10.72 | K19: 21.35
B20: MOD_04_G03 | C20: TEXTURA PROJETADA BRANCA FACHADA - DETALHE FACHADA | D20: 113.2 | E20: 390.69 | H20: MOD_03_G02 | I20: TEXTURA PROJETADA BRANCA FACHADA - DETALHE FACHADA | J20: 79.3 | K20: 294.94
B21: MOD_05_LAZ
B22: MOD_05_LAZ | C22: ESTUCAMENTO EM TETO COM PINTURA | D22: 14.15 | E22: 31.53 | H22: Pavimento | I22: Descrição | J22: Área | K22: Perímetro
B23: MOD_05_LAZ | C23: FORRO DE GESSO ACARTONADO, STANDART ST, ÁREA SECA | D23: 288.04 | E23: 444.08 | H23: MOD_04_G03 | I23: ESTUCAMENTO EM TETO COM PINTURA | J23: 730.74 | K23: 822.43
B24: MOD_05_LAZ | C24: TEXTURA PROJETADA BRANCA FACHADA - DETALHE FACHADA | D24: 34.7 | E24: 112.59 | H24: MOD_04_G03 | I24: FORRO DE GESSO ACARTONADO, STANDART ST, ÁREA SECA | J24: 10.67 | K24: 21.22
A25: MOD_TIPO | B25: MOD_06_TIPO 01 | H25: MOD_04_G03 | I25: TEXTURA PROJETADA BRANCA FACHADA - DETALHE FACHADA | J25: 113.2 | K25: 390.69
A26: MOD_TIPO | B26: MOD_06_TIPO 01 | C26: ESTUCAMENTO EM TETO COM PINTURA | D26: 14.57 | E26: 31.61
A27: MOD_TIPO | B27: MOD_06_TIPO 01 | C27: FORRO DE GESSO ACARTONADO, STANDART ST, ÁREA SECA | D27: 267.28 | E27: 345.45 | H27: Pavimento | I27: Descrição | J27: Área | K27: Perímetro
A28: MOD_TIPO | B28: MOD_07_TIPO 02 | H28: MOD_05_LAZ | I28: ESTUCAMENTO EM TETO COM PINTURA | J28: 14.15 | K28: 31.53
A29: MOD_TIPO | B29: MOD_07_TIPO 02 | C29: ESTUCAMENTO EM TETO COM PINTURA | D29: 14.61 | E29: 31.57 | H29: MOD_05_LAZ | I29: FORRO DE GESSO ACARTONADO, STANDART ST, ÁREA SECA | J29: 288.04 | K29: 444.08
A30: MOD_TIPO | B30: MOD_07_TIPO 02 | C30: FORRO DE GESSO ACARTONADO, STANDART ST, ÁREA SECA | D30: 267.28 | E30: 345.45 | H30: MOD_05_LAZ | I30: TEXTURA PROJETADA BRANCA FACHADA - DETALHE FACHADA | J30: 34.7 | K30: 112.59
A31: MOD_TIPO | B31: MOD_08_TIPO 03
A32: MOD_TIPO | B32: MOD_08_TIPO 03 | C32: ESTUCAMENTO EM TETO COM PINTURA | D32: 14.61 | E32: 31.57 | H32: Pavimento | I32: Descrição | J32: Área | K32: Perímetro
A33: MOD_TIPO | B33: MOD_08_TIPO 03 | C33: FORRO DE GESSO ACARTONADO, STANDART ST, ÁREA SECA | D33: 267.28 | E33: 345.45 | H33: MOD_TIPO | I33: ESTUCAMENTO EM TETO COM PINTURA | J33: =SUMIFS(D:D,A:A,H33,C:C,I33) -> 204.5 | K33: =SUMIFS(E:E,A:A,H33,C:C,I33) -> 442.02
A34: MOD_TIPO | B34: MOD_09_TIPO 04 | H34: MOD_TIPO | I34: FORRO DE GESSO ACARTONADO, STANDART ST, ÁREA SECA | J34: =SUMIFS(D:D,A:A,H34,C:C,I34) -> 3998.52 | K34: =SUMIFS(E:E,A:A,H34,C:C,I34) -> 5160.28
A35: MOD_TIPO | B35: MOD_09_TIPO 04 | C35: ESTUCAMENTO EM TETO COM PINTURA | D35: 14.61 | E35: 31.57
A36: MOD_TIPO | B36: MOD_09_TIPO 04 | C36: FORRO DE GESSO ACARTONADO, STANDART ST, ÁREA SECA | D36: 267.28 | E36: 345.45 | H36: Pavimento | I36: Descrição | J36: Área | K36: Perímetro
A37: MOD_TIPO | B37: MOD_10_TIPO 05 | H37: MOD_21_DINF | I37: ESTUCAMENTO EM TETO COM PINTURA | J37: 14.61 | K37: 31.57
A38: MOD_TIPO | B38: MOD_10_TIPO 05 | C38: FORRO DE GESSO ACARTONADO, STANDART ST, ÁREA SECA | D38: 256.6 | E38: 323.98 | H38: MOD_21_DINF | I38: FORRO DE GESSO ACARTONADO, STANDART ST, ÁREA SECA | J38: 255.27 | K38: 339.9
A39: MOD_TIPO | B39: MOD_11_TIPO 06
A40: MOD_TIPO | B40: MOD_11_TIPO 06 | C40: ESTUCAMENTO EM TETO COM PINTURA | D40: 14.61 | E40: 31.57 | H40: Pavimento | I40: Descrição | J40: Área | K40: Perímetro
...

Sheet B09. TABELA DE PORTAS GERAL
A1: Código | B1: Descrição | C1: Largura | D1: Altura | E1: Qtd. | F1: Largura | G1: Altura | H1: Qtd.
A2: P1 | B2: PORTA DE ABRIR, 1 FOLHA, MDF, 90 x 210 cm | C2: 90 | D2: 210 | E2: 34 | F2: =C2/100 -> 0.9 | G2: =D2/100 -> 2.1 | H2: =_xlfn.NUMBERVALUE(E2) -> 34
A3: P2 | B3: PORTA DE ABRIR, 1 FOLHA, MDF, 80 x 210 cm | C3: 80 | D3: 210 | E3: 137 | F3: =C3/100 -> 0.8 | G3: =D3/100 -> 2.1 | H3: =_xlfn.NUMBERVALUE(E3) -> 137
A4: P3 | B4: PORTA DE ABRIR, 1 FOLHA, MDF, 70 x 210 cm | C4: 70 | D4: 210 | E4: 164 | F4: =C4/100 -> 0.7 | G4: =D4/100 -> 2.1 | H4: =_xlfn.NUMBERVALUE(E4) -> 164
A5: P5 | B5: PORTA DE ABRIR, 1 FOLHA, ALUMÍNIO VENEZIANA, 90 x 210 cm | C5: 90 | D5: 210 | E5: 3 | F5: =C5/100 -> 0.9 | G5: =D5/100 -> 2.1 | H5: =_xlfn.NUMBERVALUE(E5) -> 3
A6: P6 | B6: PORTA DE ABRIR, 1 FOLHA, CORTA-FOGO, 60 x 210 cm | C6: 60 | D6: 210 | E6: 1 | F6: =C6/100 -> 0.6 | G6: =D6/100 -> 2.1 | H6: =_xlfn.NUMBERVALUE(E6) -> 1
A7: P7 | B7: PORTA DE ABRIR, 1 FOLHA, VIDRO E ALUMÍNIO, 90 x 210 cm | C7: 90 | D7: 210 | E7: 4 | F7: =C7/100 -> 0.9 | G7: =D7/100 -> 2.1 | H7: =_xlfn.NUMBERVALUE(E7) -> 4
A8: P8 | B8: PORTA PIVOTANTE, 1 FOLHA, MDF, 120 x 430 cm | C8: 120 | D8: 430 | E8: 1 | F8: =C8/100 -> 1.2 | G8: =D8/100 -> 4.3 | H8: =_xlfn.NUMBERVALUE(E8) -> 1
A9: P9 | B9: PORTA DE CORRER, 2 FOLHAS, ALUMÍNIO VENEZIANA, 150 x 210 cm | C9: 150 | D9: 210 | E9: 1 | F9: =C9/100 -> 1.5 | G9: =D9/100 -> 2.1 | H9: =_xlfn.NUMBERVALUE(E9) -> 1
A10: P10 | B10: PORTA DE ABRIR, 1 FOLHA, ALUMÍNIO VENEZIANA, 80 x 210 cm | C10: 80 | D10: 210 | E10: 2 | F10: =C10/100 -> 0.8 | G10: =D10/100 -> 2.1 | H10: =_xlfn.NUMBERVALUE(E10) -> 2
A11: P11 | B11: PORTA DE CORRER, 1 FOLHA, MDF, 80 x 210 cm | C11: 80 | D11: 210 | E11: 1 | F11: =C11/100 -> 0.8 | G11: =D11/100 -> 2.1 | H11: =_xlfn.NUMBERVALUE(E11) -> 1
A12: P12 | B12: PORTA ALÇAPÃO, 1 FOLHA, ALUMÍNIO, 60 x 60 cm À CONFIRMAR | C12: 60 | D12: 60 | E12: 4 | F12: =C12/100 -> 0.6 | G12: =D12/100 -> 0.6 | H12: =_xlfn.NUMBERVALUE(E12) -> 4
A13: P13 | B13: PORTA DE ABRIR, 1 FOLHA, CORTA-FOGO, 100 x 210 cm | C13: 100 | D13: 210 | E13: 1 | F13: =C13/100 -> 1 | G13: =D13/100 -> 2.1 | H13: =_xlfn.NUMBERVALUE(E13) -> 1
... A30: PJ10 | B30: PJ10 - PORTA DE CORRER, 4 FOLHAS, ALUMÍNIO E VIDRO, 390 x 234 cm | C30: 390 | D30: 234 | E30: 1 | F30: =C30/100 -> 3.9 | G30: =D30/100 -> 2.34 | H30: =_xlfn.NUMBERVALUE(E30) -> 1

Sheet B10. TABELA DE JANELAS GERAL
A1: Marca de tipo | B1: Descrição | C1: Largura | D1: Altura | E1: Altura do peitoril | F1: Qtd. | G1: Largura | H1: Altura | I1: Qtd.
A2: CHU-01 | B2: ABERTURA PARA CHURRASQUEIRA - 70 x 60 | C2: 70 | D2: 60 | E2: 105,00 cm | F2: 32 | G2: =C2/100 -> 0.7 | H2: =D2/100 -> 0.6 | I2: =_xlfn.NUMBERVALUE(F2) -> 32
A3: CHU-02 | B3: ABERTURA PARA CHURRASQUEIRA - 80 x 60 | C3: 80 | D3: 60 | E3: 105,00 cm | F3: 2 | G3: =C3/100 -> 0.8 | H3: =D3/100 -> 0.6 | I3: =_xlfn.NUMBERVALUE(F3) -> 2
A4: GRE-01 | B4: GRELHA COM REGULAGEM MECÂNICA, ALUMÍNIO, 1 FOLHA, 50 x 30 cm | C4: 50 | D4: 30 | E4: 160,00 cm | F4: 1 | G4: =C4/100 -> 0.5 | H4: =D4/100 -> 0.3 | I4: =_xlfn.NUMBERVALUE(F4) -> 1
A5: GRE-02 | B5: GRELHA COM REGULAGEM MECÂNICA, ALUMÍNIO, 1 FOLHA, 60 x 30 cm | C5: 60 | D5: 30 | E5: 160,00 cm | F5: 22 | G5: =C5/100 -> 0.6 | H5: =D5/100 -> 0.3 | I5: =_xlfn.NUMBERVALUE(F5) -> 22
A6: J1 | B6: JANELA DE CORRER, 2 FOLHAS + PEITORIL FIXO, ALUMÍNIO E VIDRO, 150 x 200 cm | C6: 150 | D6: 200 | E6: 52,00 cm | F6: 128 | G6: =C6/100 -> 1.5 | H6: =D6/100 -> 2 | I6: =_xlfn.NUMBERVALUE(F6) -> 128
A7: J2 | B7: JANELA MAXIM-AIR, 1 FOLHA, ALUMÍNIO E VIDRO, 50 x 90 cm | C7: 50 | D7: 90 | E7: 162,00 cm | F7: 160 | G7: =C7/100 -> 0.5 | H7: =D7/100 -> 0.9 | I7: =_xlfn.NUMBERVALUE(F7) -> 160
A8: J3 | B8: JANELA DE CORRER, 2 FOLHAS + PEITORIL FIXO, ALUMÍNIO E VIDRO, 200 x 200 cm | C8: 200 | D8: 200 | E8: 52,00 cm | F8: 34 | G8: =C8/100 -> 2 | H8: =D8/100 -> 2 | I8: =_xlfn.NUMBERVALUE(F8) -> 34
A9: J4 | B9: JANELA MAXIM-AIR, 4 FOLHAS, ALUMÍNIO E VIDRO, 200 x 60 cm | C9: 200 | D9: 60 | E9: 192,00 cm | F9: 2 | G9: =C9/100 -> 2 | H9: =D9/100 -> 0.6 | I9: =_xlfn.NUMBERVALUE(F9) -> 2
A10: J5 | B10: JANELA FIXA, 2 FOLHAS, ALUMÍNIO E VIDRO, 162 x 135 cm | C10: 162 | D10: 135 | E10: 117,00 cm | F10: 1 | G10: =C10/100 -> 1.62 | H10: =D10/100 -> 1.35 | I10: =_xlfn.NUMBERVALUE(F10) -> 1
A11: J6 | B11: JANELA FIXA, 2 FOLHAS, ALUMÍNIO E VIDRO, 53 x 135 cm | C11: 53 | D11: 135 | E11: 117,00 cm | F11: 1 | G11: =C11/100 -> 0.53 | H11: =D11/100 -> 1.35 | I11: =_xlfn.NUMBERVALUE(F11) -> 1
A12: J7 | B12: JANELA DE CORRER, 4 FOLHAS, ALUMÍNIO E VIDRO, 375 x 132 cm | C12: 375 | D12: 132 | E12: 120,00 cm | F12: 1 | G12: =C12/100 -> 3.75 | H12: =D12/100 -> 1.32 | I12: =_xlfn.NUMBERVALUE(F12) -> 1
A13: J8 | B13: JANELA FIXA, 1 FOLHA, ALUMÍNIO E VIDRO, 150 x 159 cm | C13: 150 | D13: 159 | E13: 60,00 cm | F13: 1 | G13: =C13/100 -> 1.5 | H13: =D13/100 -> 1.59 | I13: =_xlfn.NUMBERVALUE(F13) -> 1
... A19: J14 | B19: JANELA DE CORRER, 2 FOLHAS + BANDEIRA VENEZIANA SUPERIOR, ALUMÍNIO E VIDRO, 120 x 135 cm | C19: 120 | D19: 135 | E19: 117,00 cm | F19: 32 | G19: =C19/100 -> 1.2 | H19: =D19/100 -> 1.35 | I19: =_xlfn.NUMBERVALUE(F19) -> 32
A20: JAN-01 | B20: JANELA DE DESENFUMAGEM AUTOMATIZADA COM ABERTURA SUPERIOR, 1 FOLHA, ALUMÍNIO E VIDRO TELADO, 100 x 100 cm | C20: 95 | D20: 95 | F20: 18 | G20: =C20/100 -> 0.95 | H20: =D20/100 -> 0.95 | I20: =_xlfn.NUMBERVALUE(F20) -> 18
A21: JAN-02 | B21: JANELA DE DESENFUMAGEM AUTOMATIZADA COM ABERTURA INFERIOR, 1 FOLHA, ALUMÍNIO E VIDRO TELADO, 100 x 100 cm | C21: 95 | D21: 95 | E21: 156,50 cm | F21: 1 | G21: =C21/100 -> 0.95 | H21: =D21/100 -> 0.95 | I21: =_xlfn.NUMBERVALUE(F21) -> 1
A22: VEN-01 | B22: JANELA FIXA, 1 FOLHA, ALUMÍNIO VENEZIANA TIPO TAE, 200 x 100 cm | C22: 195 | D22: 99 | E22: 4,50 cm | F22: 1 | G22: =C22/100 -> 1.95 | H22: =D22/100 -> 0.99 | I22: =_xlfn.NUMBERVALUE(F22) -> 1
A23: VEN-02 | B23: JANELA FIXA, 1 FOLHA, ALUMÍNIO VENEZIANA TIPO TAE, 50 x 50 cm | C23: 45 | D23: 45 | E23: 256,50 cm | F23: 2 | G23: =C23/100 -> 0.45 | H23: =D23/100 -> 0.45 | I23: =_xlfn.NUMBERVALUE(F23) -> 2

Sheet B11. TABELA DE BRISES
A1: Restrição da base | B1: Tipo | C1: Descrição | D1: Area
A2: MOD_00_TER
A3: MOD_00_TER | B3: 1002_BRISE METÁLICO INTERNO | C3: BRISE METÁLICO INTERNO | D3: 1 m² | F3: 1
A4: MOD_01_MEZ
A5: MOD_01_MEZ | B5: 1001_BRISE METÁLICO | C5: BRISE METÁLICO FACHADA | D5: 57 m² | F5: 57
A6: MOD_02_G01
A7: MOD_02_G01 | B7: 1001_BRISE METÁLICO | C7: BRISE METÁLICO FACHADA | D7: 89 m² | F7: 89
A8: MOD_03_G02
A9: MOD_03_G02 | B9: 1001_BRISE METÁLICO | C9: BRISE METÁLICO FACHADA | D9: 89 m² | F9: 89
A10: MOD_04_G03
A11: MOD_04_G03 | B11: 1001_BRISE METÁLICO | C11: BRISE METÁLICO FACHADA | D11: 97 m² | F11: 97
A12: MOD_05_LAZ
A13: MOD_05_LAZ | B13: BRISE HORIZONTAL | C13: BRISE METÁLICO CONDENSADORAS | D13: 29 m² | F13: 29
A14: MOD_06_TIPO 01
A15: MOD_06_TIPO 01 | B15: 1001_BRISE METÁLICO | C15: BRISE METÁLICO FACHADA | D15: 4 m² | F15: 4
A16: MOD_07_TIPO 02
A17: MOD_07_TIPO 02 | B17: 1001_BRISE METÁLICO | C17: BRISE METÁLICO FACHADA | D17: 4 m² | F17: 4
A18: MOD_08_TIPO 03
A19: MOD_08_TIPO 03 | B19: 1001_BRISE METÁLICO | C19: BRISE METÁLICO FACHADA | D19: 4 m² | F19: 4
A20: MOD_09_TIPO 04
A21: MOD_09_TIPO 04 | B21: 1001_BRISE METÁLICO | C21: BRISE METÁLICO FACHADA | D21: 4 m² | F21: 4
A22: MOD_10_TIPO 05
A23: MOD_10_TIPO 05 | B23: 1001_BRISE METÁLICO | C23: BRISE METÁLICO FACHADA | D23: 4 m² | F23: 4
A24: MOD_11_TIPO 06
A25: MOD_11_TIPO 06 | B25: 1001_BRISE METÁLICO | C25: BRISE METÁLICO FACHADA | D25: 4 m² | F25: 4
A26: MOD_12_TIPO 07
A27: MOD_12_TIPO 07 | B27: 1001_BRISE METÁLICO | C27: BRISE METÁLICO FACHADA | D27: 4 m² | F27: 4
A28: MOD_13_TIPO 08
A29: MOD_13_TIPO 08 | B29: 1001_BRISE METÁLICO | C29: BRISE METÁLICO FACHADA | D29: 4 m² | F29: 4
A30: MOD_14_TIPO 09
A31: MOD_14_TIPO 09 | B31: 1001_BRISE METÁLICO | C31: BRISE METÁLICO FACHADA | D31: 4 m² | F31: 4
A32: MOD_15_TIPO 10
A33: MOD_15_TIPO 10 | B33: 1001_BRISE METÁLICO | C33: BRISE METÁLICO FACHADA | D33: 4 m² | F33: 4
A34: MOD_16_TIPO 11
A35: MOD_16_TIPO 11 | B35: 1001_BRISE METÁLICO | C35: BRISE METÁLICO FACHADA | D35: 4 m² | F35: 4
A36: MOD_17_TIPO 12
A37: MOD_17_TIPO 12 | B37: 1001_BRISE METÁLICO | C37: BRISE METÁLICO FACHADA | D37: 4 m² | F37: 4
A38: MOD_18_TIPO 13
A39: MOD_18_TIPO 13 | B39: 1001_BRISE METÁLICO | C39: BRISE METÁLICO FACHADA | D39: 4 m² | F39: 4
A40: MOD_19_TIPO 14
...

Sheet B12. TABELA DE PAINEL DE VIDRO
A1: Restrição da base | B1: Tipo | C1: Descrição | D1: Area
A2: MOD_00_TER
A3: MOD_00_TER | B3: FACHADA EM VIDRO | C3: FACHADA EM VIDRO | D3: 93 m² | F3: 93
A4: MOD_01_MEZ
A5: MOD_01_MEZ | B5: FACHADA EM VIDRO | C5: FACHADA EM VIDRO | D5: 28 m² | F5: 28
A6: MOD_05_LAZ
A7: MOD_05_LAZ | B7: PAINEL DE VIDRO | C7: PAINEL EM VIDRO | D7: 1 m² | F7: 1
A8: MOD_06_TIPO 01
A9: MOD_06_TIPO 01 | B9: FACHADA EM VIDRO | C9: FACHADA EM VIDRO | D9: 26 m² | F9: 26
A10: MOD_07_TIPO 02
A11: MOD_07_TIPO 02 | B11: FACHADA EM VIDRO | C11: FACHADA EM VIDRO | D11: 26 m² | F11: 26
A12: MOD_08_TIPO 03
A13: MOD_08_TIPO 03 | B13: FACHADA EM VIDRO | C13: FACHADA EM VIDRO | D13: 26 m² | F13: 26
A14: MOD_09_TIPO 04
A15: MOD_09_TIPO 04 | B15: FACHADA EM VIDRO | C15: FACHADA EM VIDRO | D15: 26 m² | F15: 26
A16: MOD_10_TIPO 05
A17: MOD_10_TIPO 05 | B17: FACHADA EM VIDRO | C17: FACHADA EM VIDRO | D17: 26 m² | F17: 26
A18: MOD_11_TIPO 06
A19: MOD_11_TIPO 06 | B19: FACHADA EM VIDRO | C19: FACHADA EM VIDRO | D19: 26 m² | F19: 26
A20: MOD_12_TIPO 07
A21: MOD_12_TIPO 07 | B21: FACHADA EM VIDRO | C21: FACHADA EM VIDRO | D21: 26 m² | F21: 26
A22: MOD_13_TIPO 08
A23: MOD_13_TIPO 08 | B23: FACHADA EM VIDRO | C23: FACHADA EM VIDRO | D23: 26 m² | F23: 26
A24: MOD_14_TIPO 09
A25: MOD_14_TIPO 09 | B25: FACHADA EM VIDRO | C25: FACHADA EM VIDRO | D25: 26 m² | F25: 26
A26: MOD_15_TIPO 10
A27: MOD_15_TIPO 10 | B27: FACHADA EM VIDRO | C27: FACHADA EM VIDRO | D27: 26 m² | F27: 26
A28: MOD_16_TIPO 11
A29: MOD_16_TIPO 11 | B29: FACHADA EM VIDRO | C29: FACHADA EM VIDRO | D29: 26 m² | F29: 26
A30: MOD_17_TIPO 12
A31: MOD_17_TIPO 12 | B31: FACHADA EM VIDRO | C31: FACHADA EM VIDRO | D31: 26 m² | F31: 26
A32: MOD_18_TIPO 13
A33: MOD_18_TIPO 13 | B33: FACHADA EM VIDRO | C33: FACHADA EM VIDRO | D33: 26 m² | F33: 26
A34: MOD_19_TIPO 14
A35: MOD_19_TIPO 14 | B35: FACHADA EM VIDRO | C35: FACHADA EM VIDRO | D35: 26 m² | F35: 26
A36: MOD_20_TIPO 15
A37: MOD_20_TIPO 15 | B37: FACHADA EM VIDRO | C37: FACHADA EM VIDRO | D37: 26 m² | F37: 26
A38: MOD_21_DINF
A39: MOD_21_DINF | B39: FACHADA EM VIDRO | C39: FACHADA EM VIDRO | D39: 26 m² | F39: 26
A40: MOD_22_DSUP
...

Sheet CTN_TABELA DE RODAPÉS
A1: Nível | B1: Tipo | C1: Local de aplicação | D1: Copriento
A2: MOD_00_TER
A3: MOD_00_TER | B3: 01_RODAPE POLIESTIRENO - 10 cm | C3: APLICAÇÃO INTERNA | D3: 117.09 | F3: 01_RODAPE POLIESTIRENO - 10 cm | G3: =SUMIF(B:B,F3,D:D) -> 4124.88
A4: MOD_00_TER | B4: 21_RODAPE PORCELANATO - 10 cm | C4: APLICAÇÃO INTERNA/ EXTERNA | D4: 2.67 | F4: 21_RODAPE PORCELANATO - 10 cm | G4: =SUMIF(B:B,F4,D:D) -> 440.38
A5: MOD_00_TER | B5: 52_RODAPE EM PEDRA NATURAL, 10 cm | C5: APLICAÇÃO INTERNA | D5: 15.54 | F5: 52_RODAPE EM PEDRA NATURAL, 10 cm | G5: =SUMIF(B:B,F5,D:D) -> 47.54
A6: MOD_01_MEZ
A7: MOD_01_MEZ | B7: 01_RODAPE POLIESTIRENO - 10 cm | C7: APLICAÇÃO INTERNA | D7: 49.84
A8: MOD_01_MEZ | B8: 52_RODAPE EM PEDRA NATURAL, 10 cm | C8: APLICAÇÃO INTERNA | D8: 32
A9: MOD_02_G01
A10: MOD_02_G01 | B10: 01_RODAPE POLIESTIRENO - 10 cm | C10: APLICAÇÃO INTERNA | D10: 9.23
A11: MOD_03_G02
A12: MOD_03_G02 | B12: 01_RODAPE POLIESTIRENO - 10 cm | C12: APLICAÇÃO INTERNA | D12: 9.23
A13: MOD_04_G03
A14: MOD_04_G03 | B14: 01_RODAPE POLIESTIRENO - 10 cm | C14: APLICAÇÃO INTERNA | D14: 9.23
A15: MOD_05_LAZ
A16: MOD_05_LAZ | B16: 01_RODAPE POLIESTIRENO - 10 cm | C16: APLICAÇÃO INTERNA | D16: 192.52
A17: MOD_05_LAZ | B17: 21_RODAPE PORCELANATO - 10 cm | C17: APLICAÇÃO INTERNA/ EXTERNA | D17: 249.19
A18: MOD_06_TIPO 01
A19: MOD_06_TIPO 01 | B19: 01_RODAPE POLIESTIRENO - 10 cm | C19: APLICAÇÃO INTERNA | D19: 228.39
A20: MOD_06_TIPO 01 | B20: 21_RODAPE PORCELANATO - 10 cm | C20: APLICAÇÃO INTERNA/ EXTERNA | D20: 7.79
A21: MOD_07_TIPO 02
A22: MOD_07_TIPO 02 | B22: 01_RODAPE POLIESTIRENO - 10 cm | C22: APLICAÇÃO INTERNA | D22: 228.39
A23: MOD_07_TIPO 02 | B23: 21_RODAPE PORCELANATO - 10 cm | C23: APLICAÇÃO INTERNA/ EXTERNA | D23: 7.79
A24: MOD_08_TIPO 03
A25: MOD_08_TIPO 03 | B25: 01_RODAPE POLIESTIRENO - 10 cm | C25: APLICAÇÃO INTERNA | D25: 228.39
A26: MOD_08_TIPO 03 | B26: 21_RODAPE PORCELANATO - 10 cm | C26: APLICAÇÃO INTERNA/ EXTERNA | D26: 7.79
A27: MOD_09_TIPO 04
A28: MOD_09_TIPO 04 | B28: 01_RODAPE POLIESTIRENO - 10 cm | C28: APLICAÇÃO INTERNA | D28: 228.39
A29: MOD_09_TIPO 04 | B29: 21_RODAPE PORCELANATO - 10 cm | C29: APLICAÇÃO INTERNA/ EXTERNA | D29: 7.79
A30: MOD_10_TIPO 05
A31: MOD_10_TIPO 05 | B31: 01_RODAPE POLIESTIRENO - 10 cm | C31: APLICAÇÃO INTERNA | D31: 228.39
A32: MOD_10_TIPO 05 | B32: 21_RODAPE PORCELANATO - 10 cm | C32: APLICAÇÃO INTERNA/ EXTERNA | D32: 7.79
A33: MOD_11_TIPO 06
A34: MOD_11_TIPO 06 | B34: 01_RODAPE POLIESTIRENO - 10 cm | C34: APLICAÇÃO INTERNA | D34: 228.39
A35: MOD_11_TIPO 06 | B35: 21_RODAPE PORCELANATO - 10 cm | C35: APLICAÇÃO INTERNA/ EXTERNA | D35: 7.79
A36: MOD_12_TIPO 07
A37: MOD_12_TIPO 07 | B37: 01_RODAPE POLIESTIRENO - 10 cm | C37: APLICAÇÃO INTERNA | D37: 228.39
A38: MOD_12_TIPO 07 | B38: 21_RODAPE PORCELANATO - 10 cm | C38: APLICAÇÃO INTERNA/ EXTERNA | D38: 7.79
A39: MOD_13_TIPO 08
A40: MOD_13_TIPO 08 | B40: 01_RODAPE POLIESTIRENO - 10 cm | C40: APLICAÇÃO INTERNA | D40: 228.39
...

Sheet CTN_TABELA IMPERMEABILIZAÇÃO PA
A1: Name - CTN_TABELA IMPERMEABILIZAÇÃO PAREDE
A2: VV | B2: Tipo | C2: Descrição | D2: Área | E2: Copriento
A3: MOD_00_TER
A4: MOD_00_TER | B4: ARGAMASSA POLIMERICA IMPERMEABILIZANTE EM PAREDE | C4: IMPERMEABILIZAÇÃO POLIMÉRICA PARA PAREDE | D4: 4.96 | E4: 3.31 | H4: ARGAMASSA POLIMERICA IMPERMEABILIZANTE EM PAREDE | I4: =SUMIF(B:B,H4,D:D) -> 4.96
A5: MOD_00_TER | B5: MANTA IMPERMEABILIZANTE A BASE DE ASFALTO EM RESERVATORIOS | C5: IMPERMEABILIZAÇÃO EM MANTA ASFÁLTICA PARA RESERVATÓRIOS | D5: 60.69 | E5: 35.54 | H5: MANTA IMPERMEABILIZANTE A BASE DE ASFALTO EM RESERVATORIOS | I5: =SUMIF(B:B,H5,D:D) -> 127.88
A6: MOD_00_TER | B6: MANTA IMPERMEABILIZANTE A BASE DE ASFALTO EM TERRAÇOS | C6: IMPERMEABILIZAÇÃO EM MANTA ASFÁLTICA PARA TERRAÇOS | D6: 6.96 | E6: 28.17 | H6: MANTA IMPERMEABILIZANTE A BASE DE ASFALTO EM TERRAÇOS | I6: =SUMIF(B:B,H6,D:D) -> 529.6
A7: MOD_01_MEZ | I7: =SUMIF(B:B,H7,D:D) -> 0
A8: MOD_01_MEZ | B8: MANTA IMPERMEABILIZANTE A BASE DE ASFALTO EM TERRAÇOS | C8: IMPERMEABILIZAÇÃO EM MANTA ASFÁLTICA PARA TERRAÇOS | D8: 62.95 | E8: 340.19 | H8: MANTA LÍQUIDA | I8: =SUMIF(B:B,H8,D:D) -> 0.86
A9: MOD_01_MEZ | B9: MANTA LÍQUIDA | C9: IMPERMEABILIZAÇÃO EM MANTA LÍQUIDA | D9: 0.86 | E9: 2.48 | H9: IMPERMEABILIZAÇÃO POLIMÉRICA PARA PEITORIL | I9: =SUMIF(B:B,H9,D:D) -> 76.35
A10: MOD_02_G01 | H10: MANTA IMPERMEABILIZANTE A BASE DE ASFALTO EM PISCINAS | I10: =SUMIF(B:B,H10,D:D) -> 54.07
A11: MOD_02_G01 | B11: MANTA IMPERMEABILIZANTE A BASE DE ASFALTO EM TERRAÇOS | C11: IMPERMEABILIZAÇÃO EM MANTA ASFÁLTICA PARA TERRAÇOS | D11: 90.59 | E11: 551.61 | H11: ARGAMASSA POLIMERICA IMPERMEABILIZANTE EM BOX BANHEIRO | I11: =SUMIF(B:B,H11,D:D) -> 543.52
A12: MOD_03_G02 | H12: MANTA IMPERMEABILIZANTE A BASE DE ASFALTO EM FLOREIRAS | I12: =SUMIF(B:B,H12,D:D) -> 30.94
A13: MOD_03_G02 | B13: MANTA IMPERMEABILIZANTE A BASE DE ASFALTO EM TERRAÇOS | C13: IMPERMEABILIZAÇÃO EM MANTA ASFÁLTICA PARA TERRAÇOS | D13: 44.89 | E13: 221.48 | H13: MANTA IMPERMEABILIZANTE A BASE DE ASFALTO EM SACADAS | I13: =SUMIF(B:B,H13,D:D) -> 81.82
A14: MOD_04_G03 | H14: ARGAMASSA POLIMERICA IMPERMEABILIZANTE EM SACADA | I14: =SUMIF(B:B,H14,D:D) -> 0.42
A15: MOD_04_G03 | B15: MANTA IMPERMEABILIZANTE A BASE DE ASFALTO EM TERRAÇOS | C15: IMPERMEABILIZAÇÃO EM MANTA ASFÁLTICA PARA TERRAÇOS | D15: 81.37 | E15: 370.46
A16: MOD_05_LAZ
A17: MOD_05_LAZ | B17: IMPERMEABILIZAÇÃO POLIMÉRICA PARA PEITORIL | C17: IMPERMEABILIZAÇÃO POLIMÉRICA PARA PEITORIL | D17: 1.41 | E17: 14.06
A18: MOD_05_LAZ | B18: MANTA IMPERMEABILIZANTE A BASE DE ASFALTO EM PISCINAS | C18: IMPERMEABILIZAÇÃO EM MANTA ASFÁLTICA PARA PISCINAS | D18: 41.36 | E18: 47.22
A19: MOD_05_LAZ | B19: MANTA IMPERMEABILIZANTE A BASE DE ASFALTO EM TERRAÇOS | C19: IMPERMEABILIZAÇÃO EM MANTA ASFÁLTICA PARA TERRAÇOS | D19: 79.16 | E19: 255.12
A20: MOD_06_TIPO 01
A21: MOD_06_TIPO 01 | B21: ARGAMASSA POLIMERICA IMPERMEABILIZANTE EM BOX BANHEIRO | C21: IMPERMEABILIZAÇÃO POLIMÉRICA PARA BOX DE BANHEIRO | D21: 33.97 | E21: 22.64
A22: MOD_06_TIPO 01 | B22: IMPERMEABILIZAÇÃO POLIMÉRICA PARA PEITORIL | C22: IMPERMEABILIZAÇÃO POLIMÉRICA PARA PEITORIL | D22: 4.6 | E22: 45.96
A23: MOD_06_TIPO 01 | B23: MANTA IMPERMEABILIZANTE A BASE DE ASFALTO EM FLOREIRAS | C23: IMPERMEABILIZAÇÃO EM MANTA ASFÁLTICA PARA FLOREIRAS | D23: 30.94 | E23: 110.94
A24: MOD_06_TIPO 01 | B24: MANTA IMPERMEABILIZANTE A BASE DE ASFALTO EM SACADAS | C24: IMPERMEABILIZAÇÃO EM MANTA ASFÁLTICA PARA SACADAS | D24: 4.84 | E24: 12.09
A25: MOD_07_TIPO 02
A26: MOD_07_TIPO 02 | B26: ARGAMASSA POLIMERICA IMPERMEABILIZANTE EM BOX BANHEIRO | C26: IMPERMEABILIZAÇÃO POLIMÉRICA PARA BOX DE BANHEIRO | D26: 33.97 | E26: 22.64
A27: MOD_07_TIPO 02 | B27: IMPERMEABILIZAÇÃO POLIMÉRICA PARA PEITORIL | C27: IMPERMEABILIZAÇÃO POLIMÉRICA PARA PEITORIL | D27: 4.6 | E27: 45.97
A28: MOD_07_TIPO 02 | B28: MANTA IMPERMEABILIZANTE A BASE DE ASFALTO EM SACADAS | C28: IMPERMEABILIZAÇÃO EM MANTA ASFÁLTICA PARA SACADAS | D28: 4.84 | E28: 12.09
A29: MOD_08_TIPO 03
A30: MOD_08_TIPO 03 | B30: ARGAMASSA POLIMERICA IMPERMEABILIZANTE EM BOX BANHEIRO | C30: IMPERMEABILIZAÇÃO POLIMÉRICA PARA BOX DE BANHEIRO | D30: 33.97 | E30: 22.64
A31: MOD_08_TIPO 03 | B31: IMPERMEABILIZAÇÃO POLIMÉRICA PARA PEITORIL | C31: IMPERMEABILIZAÇÃO POLIMÉRICA PARA PEITORIL | D31: 4.6 | E31: 45.97
A32: MOD_08_TIPO 03 | B32: MANTA IMPERMEABILIZANTE A BASE DE ASFALTO EM SACADAS | C32: IMPERMEABILIZAÇÃO EM MANTA ASFÁLTICA PARA SACADAS | D32: 4.84 | E32: 12.09
A33: MOD_09_TIPO 04
A34: MOD_09_TIPO 04 | B34: ARGAMASSA POLIMERICA IMPERMEABILIZANTE EM BOX BANHEIRO | C34: IMPERMEABILIZAÇÃO POLIMÉRICA PARA BOX DE BANHEIRO | D34: 33.97 | E34: 22.64
A35: MOD_09_TIPO 04 | B35: IMPERMEABILIZAÇÃO POLIMÉRICA PARA PEITORIL | C35: IMPERMEABILIZAÇÃO POLIMÉRICA PARA PEITORIL | D35: 4.6 | E35: 45.97
A36: MOD_09_TIPO 04 | B36: MANTA IMPERMEABILIZANTE A BASE DE ASFALTO EM SACADAS | C36: IMPERMEABILIZAÇÃO EM MANTA ASFÁLTICA PARA SACADAS | D36: 4.84 | E36: 12.09
A37: MOD_10_TIPO 05
A38: MOD_10_TIPO 05 | B38: ARGAMASSA POLIMERICA IMPERMEABILIZANTE EM BOX BANHEIRO | C38: IMPERMEABILIZAÇÃO POLIMÉRICA PARA BOX DE BANHEIRO | D38: 33.97 | E38: 22.64
A39: MOD_10_TIPO 05 | B39: IMPERMEABILIZAÇÃO POLIMÉRICA PARA PEITORIL | C39: IMPERMEABILIZAÇÃO POLIMÉRICA PARA PEITORIL | D39: 4.6 | E39: 45.97
A40: MOD_10_TIPO 05 | B40: MANTA IMPERMEABILIZANTE A BASE DE ASFALTO EM SACADAS | C40: IMPERMEABILIZAÇÃO EM MANTA ASFÁLTICA PARA SACADAS | D40: 4.84 | E40: 12.09
...

Sheet CTN_TABELA IMPERMEABILIZAÇÃO PI
A1: Name - CTN_TABELA IMPERMEABILIZAÇÃO PISOS
A2: Nível | B2: Tipo | C2: Descrição | D2: Área
A3: MOD_00_TER | F3: ARGAMASSA POLIMERICA IMPERMEABILIZANTE EM PISO | G3: =SUMIF(B:B,F3,D:D) -> 1.32 | I3: ARGAMASSA POLIMERICA IMPERMEABILIZANTE EM PISO | J3: =SUMIF(F:F,I3,G:G) -> 1.32
A4: MOD_00_TER | B4: ARGAMASSA POLIMERICA IMPERMEABILIZANTE EM PISO | C4: IMPERMEABILIZAÇÃO POLIMÉRICA PARA PISO | D4: 1.32 | F4: MANTA IMPERMEABILIZANTE A BASE DE ASFALTO EM RESERVATORIOS | G4: =SUMIF(B:B,F4,D:D) -> 64.35 | I4: MANTA IMPERMEABILIZANTE A BASE DE ASFALTO EM RESERVATORIOS | J4: =SUMIF(F:F,I4,G:G) -> 192.23
A5: MOD_00_TER | B5: MANTA IMPERMEABILIZANTE A BASE DE ASFALTO EM RESERVATORIOS | C5: IMPERMEABILIZAÇÃO EM MANTA ASFÁLTICA PARA RESERVATORIOS | D5: 33.75 | F5: MANTA IMPERMEABILIZANTE A BASE DE ASFALTO EM RESERVATORIOS COM PROTECAO MECANICA | G5: =SUMIF(B:B,F5,D:D) -> 64.8 | I5: MANTA IMPERMEABILIZANTE A BASE DE ASFALTO EM RESERVATORIOS COM PROTECAO MECANICA | J5: =SUMIF(F:F,I5,G:G) -> 64.8
A6: MOD_00_TER | B6: MANTA IMPERMEABILIZANTE A BASE DE ASFALTO EM RESERVATORIOS COM PROTECAO MECANICA | C6: IMPERMEABILIZAÇÃO EM MANTA ASFÁLTICA PARA RESERVATORIOS | D6: 34.2 | G6: =SUMIF(B:B,F6,D:D) -> 0 | I6: MANTA IMPERMEABILIZANTE A BASE DE ASFALTO EM TERRAÇOS | J6: =SUMIF(F:F,I6,G:G) -> 1674.07
A7: MOD_01_MEZ | F7: MANTA IMPERMEABILIZANTE A BASE DE ASFALTO EM TERRAÇOS | G7: =SUMIF(B:B,F7,D:D) -> 1144.47 | I7: MANTA LÍQUIDA | J7: =SUMIF(F:F,I7,G:G) -> 1.25
A8: MOD_01_MEZ | B8: MANTA IMPERMEABILIZANTE A BASE DE ASFALTO EM TERRAÇOS | C8: IMPERMEABILIZAÇÃO EM MANTA ASFÁLTICA PARA TERRAÇOS | D8: 123.08 | F8: MANTA LÍQUIDA | G8: =SUMIF(B:B,F8,D:D) -> 0.39 | I8: MANTA IMPERMEABILIZANTE A BASE DE ASFALTO PARA PISCINA | J8: =SUMIF(F:F,I8,G:G) -> 105.22
A9: MOD_01_MEZ | B9: MANTA LÍQUIDA | C9: IMPERMEABILIZAÇÃO EM MANTA LÍQUIDA | D9: 0.39 | F9: MANTA IMPERMEABILIZANTE A BASE DE ASFALTO PARA PISCINA | G9: =SUMIF(B:B,F9,D:D) -> 105.22 | I9: ARGAMASSA POLIMERICA IMPERMEABILIZANTE EM BOX BANHEIRO | J9: =SUMIF(F:F,I9,G:G) -> 672.48
A10: MOD_02_G01 | F10: ARGAMASSA POLIMERICA IMPERMEABILIZANTE EM BOX BANHEIRO | G10: =SUMIF(B:B,F10,D:D) -> 128.96 | I10: MANTA IMPERMEABILIZANTE A BASE DE ASFALTO EM FLOREIRAS | J10: =SUMIF(F:F,I10,G:G) -> 52.71
A11: MOD_02_G01 | B11: MANTA IMPERMEABILIZANTE A BASE DE ASFALTO EM TERRAÇOS | C11: IMPERMEABILIZAÇÃO EM MANTA ASFÁLTICA PARA TERRAÇOS | D11: 116.61 | F11: MANTA IMPERMEABILIZANTE A BASE DE ASFALTO EM FLOREIRAS | G11: =SUMIF(B:B,F11,D:D) -> 21.77 | I11: MANTA IMPERMEABILIZANTE A BASE DE ASFALTO EM SACADAS | J11: =SUMIF(F:F,I11,G:G) -> 155.22
A12: MOD_03_G02 | F12: MANTA IMPERMEABILIZANTE A BASE DE ASFALTO EM SACADAS | G12: =SUMIF(B:B,F12,D:D) -> 73.4 | I12: ARGAMASSA POLIMERICA IMPERMEABILIZANTE EM SACADA | J12: =SUMIF(F:F,I12,G:G) -> 0.68
A13: MOD_03_G02 | B13: MANTA IMPERMEABILIZANTE A BASE DE ASFALTO EM TERRAÇOS | C13: IMPERMEABILIZAÇÃO EM MANTA ASFÁLTICA PARA TERRAÇOS | D13: 88.2 | F13: ARGAMASSA POLIMERICA IMPERMEABILIZANTE EM SACADA | G13: =SUMIF(B:B,F13,D:D) -> 0.26
A14: MOD_04_G03
A15: MOD_04_G03 | B15: MANTA IMPERMEABILIZANTE A BASE DE ASFALTO EM TERRAÇOS | C15: IMPERMEABILIZAÇÃO EM MANTA ASFÁLTICA PARA TERRAÇOS | D15: 136.68 | F15: ='CTN_TABELA IMPERMEABILIZAÇÃO PA'!H4 -> ARGAMASSA POLIMERICA IMPERMEABILIZANTE EM PAREDE | G15: ='CTN_TABELA IMPERMEABILIZAÇÃO PA'!I4 -> 4.96
A16: MOD_05_LAZ | F16: ='CTN_TABELA IMPERMEABILIZAÇÃO PA'!H5 -> MANTA IMPERMEABILIZANTE A BASE DE ASFALTO EM RESERVATORIOS | G16: ='CTN_TABELA IMPERMEABILIZAÇÃO PA'!I5 -> 127.88
A17: MOD_05_LAZ | B17: MANTA IMPERMEABILIZANTE A BASE DE ASFALTO EM TERRAÇOS | C17: IMPERMEABILIZAÇÃO EM MANTA ASFÁLTICA PARA TERRAÇOS | D17: 384.63 | F17: ='CTN_TABELA IMPERMEABILIZAÇÃO PA'!H6 -> MANTA IMPERMEABILIZANTE A BASE DE ASFALTO EM TERRAÇOS | G17: ='CTN_TABELA IMPERMEABILIZAÇÃO PA'!I6 -> 529.6
A18: MOD_05_LAZ | B18: MANTA IMPERMEABILIZANTE A BASE DE ASFALTO PARA PISCINA | C18: IMPERMEABILIZAÇÃO EM MANTA ASFÁLTICA PARA PISCINA | D18: 79.45 | F18: ='CTN_TABELA IMPERMEABILIZAÇÃO PA'!H7 | G18: ='CTN_TABELA IMPERMEABILIZAÇÃO PA'!I7 -> 0
A19: MOD_06_TIPO 01 | F19: ='CTN_TABELA IMPERMEABILIZAÇÃO PA'!H8 -> MANTA LÍQUIDA | G19: ='CTN_TABELA IMPERMEABILIZAÇÃO PA'!I8 -> 0.86
A20: MOD_06_TIPO 01 | B20: ARGAMASSA POLIMERICA IMPERMEABILIZANTE EM BOX BANHEIRO | C20: IMPERMEABILIZAÇÃO POLIMÉRICA PARA BOX DE BANHEIRO | D20: 8.06 | F20: ='CTN_TABELA IMPERMEABILIZAÇÃO PA'!H9 -> IMPERMEABILIZAÇÃO POLIMÉRICA PARA PEITORIL | G20: ='CTN_TABELA IMPERMEABILIZAÇÃO PA'!I9 -> 76.35
A21: MOD_06_TIPO 01 | B21: MANTA IMPERMEABILIZANTE A BASE DE ASFALTO EM FLOREIRAS | C21: IMPERMEABILIZAÇÃO EM MANTA ASFÁLTICA PARA FLOREIRAS | D21: 21.77 | F21: ='CTN_TABELA IMPERMEABILIZAÇÃO PA'!H10 -> MANTA IMPERMEABILIZANTE A BASE DE ASFALTO EM PISCINAS | G21: ='CTN_TABELA IMPERMEABILIZAÇÃO PA'!I10 -> 54.07
A22: MOD_06_TIPO 01 | B22: MANTA IMPERMEABILIZANTE A BASE DE ASFALTO EM SACADAS | C22: IMPERMEABILIZAÇÃO EM MANTA ASFÁLTICA PARA SACADAS | D22: 4.52 | F22: ='CTN_TABELA IMPERMEABILIZAÇÃO PA'!H11 -> ARGAMASSA POLIMERICA IMPERMEABILIZANTE EM BOX BANHEIRO | G22: ='CTN_TABELA IMPERMEABILIZAÇÃO PA'!I11 -> 543.52
A23: MOD_07_TIPO 02 | F23: ='CTN_TABELA IMPERMEABILIZAÇÃO PA'!H12 -> MANTA IMPERMEABILIZANTE A BASE DE ASFALTO EM FLOREIRAS | G23: ='CTN_TABELA IMPERMEABILIZAÇÃO PA'!I12 -> 30.94
A24: MOD_07_TIPO 02 | B24: ARGAMASSA POLIMERICA IMPERMEABILIZANTE EM BOX BANHEIRO | C24: IMPERMEABILIZAÇÃO POLIMÉRICA PARA BOX DE BANHEIRO | D24: 8.06 | F24: ='CTN_TABELA IMPERMEABILIZAÇÃO PA'!H13 -> MANTA IMPERMEABILIZANTE A BASE DE ASFALTO EM SACADAS | G24: ='CTN_TABELA IMPERMEABILIZAÇÃO PA'!I13 -> 81.82
A25: MOD_07_TIPO 02 | B25: MANTA IMPERMEABILIZANTE A BASE DE ASFALTO EM SACADAS | C25: IMPERMEABILIZAÇÃO EM MANTA ASFÁLTICA PARA SACADAS | D25: 4.52 | F25: ='CTN_TABELA IMPERMEABILIZAÇÃO PA'!H14 -> ARGAMASSA POLIMERICA IMPERMEABILIZANTE EM SACADA | G25: ='CTN_TABELA IMPERMEABILIZAÇÃO PA'!I14 -> 0.42
A26: MOD_08_TIPO 03
A27: MOD_08_TIPO 03 | B27: ARGAMASSA POLIMERICA IMPERMEABILIZANTE EM BOX BANHEIRO | C27: IMPERMEABILIZAÇÃO POLIMÉRICA PARA BOX DE BANHEIRO | D27: 8.06
A28: MOD_08_TIPO 03 | B28: MANTA IMPERMEABILIZANTE A BASE DE ASFALTO EM SACADAS | C28: IMPERMEABILIZAÇÃO EM MANTA ASFÁLTICA PARA SACADAS | D28: 4.52
A29: MOD_09_TIPO 04
A30: MOD_09_TIPO 04 | B30: ARGAMASSA POLIMERICA IMPERMEABILIZANTE EM BOX BANHEIRO | C30: IMPERMEABILIZAÇÃO POLIMÉRICA PARA BOX DE BANHEIRO | D30: 8.06
A31: MOD_09_TIPO 04 | B31: MANTA IMPERMEABILIZANTE A BASE DE ASFALTO EM SACADAS | C31: IMPERMEABILIZAÇÃO EM MANTA ASFÁLTICA PARA SACADAS | D31: 4.52
A32: MOD_10_TIPO 05
A33: MOD_10_TIPO 05 | B33: ARGAMASSA POLIMERICA IMPERMEABILIZANTE EM BOX BANHEIRO | C33: IMPERMEABILIZAÇÃO POLIMÉRICA PARA BOX DE BANHEIRO | D33: 8.06
A34: MOD_10_TIPO 05 | B34: MANTA IMPERMEABILIZANTE A BASE DE ASFALTO EM SACADAS | C34: IMPERMEABILIZAÇÃO EM MANTA ASFÁLTICA PARA SACADAS | D34: 4.52
A35: MOD_11_TIPO 06
A36: MOD_11_TIPO 06 | B36: ARGAMASSA POLIMERICA IMPERMEABILIZANTE EM BOX BANHEIRO | C36: IMPERMEABILIZAÇÃO POLIMÉRICA PARA BOX DE BANHEIRO | D36: 8.06
A37: MOD_11_TIPO 06 | B37: MANTA IMPERMEABILIZANTE A BASE DE ASFALTO EM SACADAS | C37: IMPERMEABILIZAÇÃO EM MANTA ASFÁLTICA PARA SACADAS | D37: 4.52
A38: MOD_12_TIPO 07
A39: MOD_12_TIPO 07 | B39: ARGAMASSA POLIMERICA IMPERMEABILIZANTE EM BOX BANHEIRO | C39: IMPERMEABILIZAÇÃO POLIMÉRICA PARA BOX DE BANHEIRO | D39: 8.06
A40: MOD_12_TIPO 07 | B40: MANTA IMPERMEABILIZANTE A BASE DE ASFALTO EM SACADAS | C40: IMPERMEABILIZAÇÃO EM MANTA ASFÁLTICA PARA SACADAS | D40: 4.52
...
