Workbook
Name \0: #REF!
Name \0: #REF!
Name \0: #REF!
Name \1: #REF!
Name \a: #REF!
Name \a: #REF!
Name \a: #REF!
Name \b: #REF!
Name \c: #REF!
Name \d: #REF!
Name \e: #REF!
Name \i: #REF!
Name \J: #REF!
Name \k: #REF!
Name \l: #N/A
Name \m: #REF!
Name \m: #REF!
Name \m: #REF!
Name \o: #REF!
Name \p: #REF!
Name \r: #REF!
Name \T: #REF!
Name \z: #REF!
Name _\0: #REF!
Name _\1: #REF!
Name _\a: #REF!
Name _\b: #REF!
Name _\c: #REF!
Name _\d: #REF!
Name _\e: #REF!
Name _\i: #REF!
Name _\J: #REF!
Name _\k: #REF!
Name _\l: #N/A
Name _\m: #REF!
Name _\o: #REF!
Name _\p: #REF!
Name _\r: #REF!
Name _\T: #REF!
Name _\z: #REF!
Name ______ACR10: #REF!
Name ______ACR15: #REF!
Name ______acr20: #REF!
Name ______acr5: #REF!
Name ______ARQ1: #REF!
Name ______QT100: #REF!
Name ______QT2: #REF!
Name ______QT3: #REF!
Name ______QT4: #REF!
Name ______QT50: #REF!
Name ______QT75: #REF!
Name _____ACR10: #REF!
Name _____ACR15: #REF!
Name _____acr20: #REF!
Name _____acr5: #REF!
Name _____ARQ1: #REF!
Name _____QT100: #REF!
Name _____QT2: #REF!
Name _____QT3: #REF!
Name _____QT4: #REF!

Sheet PREÇO
B1: Projeto | C1: ='Equipamentos de emergência'!D1 -> Senna Tower
B2: Empresa | C2: ='Equipamentos de emergência'!D2 -> FG
B3: Origem | C3: ='Equipamentos de emergência'!D3 -> SEN-EX-ILU-001-MAT-R00.xlsx
B4: Revisão | C4: ='Equipamentos de emergência'!D4 -> R00 - Letícia
A5: ='Equipamentos de emergência'!A5 -> EQUIPAMENTOS DE EMERGÊNCIA
C6: Descrição | D6: Unidade | E6: Custo unitário
C7: Acionador Manual de Alarme de Incêndio | D7: =_xlfn.XLOOKUP(PREÇO!C7,'Equipamentos de emergência'!$E$8:$E$1260,'Equipamentos de emergência'!$J$8:$J$1260) -> pç | E7: 65
C8: Anunciador Audiovisual de Alarme de Incêndio de Parede | D8: =_xlfn.XLOOKUP(PREÇO!C8,'Equipamentos de emergência'!$E$8:$E$1260,'Equipamentos de emergência'!$J$8:$J$1260) -> pç | E8: 191.81
C9: Anunciador Audiovisual de Alarme de Incêndio de Teto | D9: =_xlfn.XLOOKUP(PREÇO!C9,'Equipamentos de emergência'!$E$8:$E$1260,'Equipamentos de emergência'!$J$8:$J$1260) -> pç | E9: 169.96
C10: Atuador Janela Desenfumagem | D10: =_xlfn.XLOOKUP(PREÇO!C10,'Equipamentos de emergência'!$E$8:$E$1260,'Equipamentos de emergência'!$J$8:$J$1260) -> pç | E10: 1150
C11: Caixa 4x2" de Embutir em PVC Padrão NBR IEC 60670 | D11: =_xlfn.XLOOKUP(PREÇO!C11,'Equipamentos de emergência'!$E$8:$E$1260,'Equipamentos de emergência'!$J$8:$J$1260) -> pç | E11: 1.72
C12: Caixa 4x4" de Embutir em PVC Padrão NBR IEC 60670 | D12: =_xlfn.XLOOKUP(PREÇO!C12,'Equipamentos de emergência'!$E$8:$E$1260,'Equipamentos de emergência'!$J$8:$J$1260) -> pç | E12: 1.72
C13: Caixa Octogonal Padrão NBR IEC 60670 | D13: =_xlfn.XLOOKUP(PREÇO!C13,'Equipamentos de emergência'!$E$8:$E$1260,'Equipamentos de emergência'!$J$8:$J$1260) -> pç | E13: 5.32
C14: Central ADW - Detecção de incêndio por sensor linear de temperatura | D14: =_xlfn.XLOOKUP(PREÇO!C14,'Equipamentos de emergência'!$E$8:$E$1260,'Equipamentos de emergência'!$J$8:$J$1260) -> pç | E14: 20000
C15: Central de Alarme de Incêndio | D15: =_xlfn.XLOOKUP(PREÇO!C15,'Equipamentos de emergência'!$E$8:$E$1260,'Equipamentos de emergência'!$J$8:$J$1260) -> pç | E15: 855.86
C16: Central de detecção de fumaça por aspiração | D16: =_xlfn.XLOOKUP(PREÇO!C16,'Equipamentos de emergência'!$E$8:$E$1260,'Equipamentos de emergência'!$J$8:$J$1260) -> pç | E16: 15493.53
C17: Classe A - PVC Anti-chama - 105ºC - Isolação 600V 0.75 mm² | D17: =_xlfn.XLOOKUP(PREÇO!C17,'Equipamentos de emergência'!$E$8:$E$1260,'Equipamentos de emergência'!$J$8:$J$1260) -> m | E17: 0.99
C18: Classe B - PVC Anti-chama - 105ºC - Isolação 600V 1.5 mm² | D18: =_xlfn.XLOOKUP(PREÇO!C18,'Equipamentos de emergência'!$E$8:$E$1260,'Equipamentos de emergência'!$J$8:$J$1260) -> m | E18: 1.69
... C20: Dispositivo Eletromagnético de Porta Aberta | D20: =_xlfn.XLOOKUP(PREÇO!C20,'Equipamentos de emergência'!$E$8:$E$1260,'Equipamentos de emergência'!$J$8:$J$1260) -> pç | E20: 416.9
C21: Extintor ABC | D21: Unidade | E21: 646.56
C22: Eletroduto leve 1" | D22: =_xlfn.XLOOKUP(PREÇO!C22,'Equipamentos de emergência'!$E$8:$E$1260,'Equipamentos de emergência'!$J$8:$J$1260) -> m | E22: 6.67
C23: Eletroduto leve 3/4" | D23: =_xlfn.XLOOKUP(PREÇO!C23,'Equipamentos de emergência'!$E$8:$E$1260,'Equipamentos de emergência'!$J$8:$J$1260) -> m | E23: 8.1
C24: Isolação em PVC (70ºC) 1.5 mm² - Amarelo | D24: =_xlfn.XLOOKUP(PREÇO!C24,'Equipamentos de emergência'!$E$8:$E$1260,'Equipamentos de emergência'!$J$8:$J$1260) -> m | E24: 1.59
C25: Isolação em PVC (70ºC) 1.5 mm² - Preto | D25: =_xlfn.XLOOKUP(PREÇO!C25,'Equipamentos de emergência'!$E$8:$E$1260,'Equipamentos de emergência'!$J$8:$J$1260) -> m | E25: 1.59
C26: Isolação em PVC (70ºC) 1.5 mm² - Vermelho | D26: =_xlfn.XLOOKUP(PREÇO!C26,'Equipamentos de emergência'!$E$8:$E$1260,'Equipamentos de emergência'!$J$8:$J$1260) -> m | E26: 1.59
C27: Isolação em PVC (70ºC) 2.5 mm² - Amarelo | D27: =_xlfn.XLOOKUP(PREÇO!C27,'Equipamentos de emergência'!$E$8:$E$1260,'Equipamentos de emergência'!$J$8:$J$1260) -> m | E27: 2.19
C28: Isolação em PVC (70ºC) 2.5 mm² - Preto | D28: =_xlfn.XLOOKUP(PREÇO!C28,'Equipamentos de emergência'!$E$8:$E$1260,'Equipamentos de emergência'!$J$8:$J$1260) -> m | E28: 2.19
C29: Isolação em PVC (70ºC) 2.5 mm² - Vermelho | D29: =_xlfn.XLOOKUP(PREÇO!C29,'Equipamentos de emergência'!$E$8:$E$1260,'Equipamentos de emergência'!$J$8:$J$1260) -> m | E29: 2.19
C30: Isolação em PVC (70ºC) 4 mm² - Amarelo | D30: =_xlfn.XLOOKUP(PREÇO!C30,'Equipamentos de emergência'!$E$8:$E$1260,'Equipamentos de emergência'!$J$8:$J$1260) -> m | E30: 3.89
C31: Isolação em PVC (70ºC) 4 mm² - Preto | D31: =_xlfn.XLOOKUP(PREÇO!C31,'Equipamentos de emergência'!$E$8:$E$1260,'Equipamentos de emergência'!$J$8:$J$1260) -> m | E31: 3.89
C32: Isolação em PVC (70ºC) 4 mm² - Vermelho | D32: =_xlfn.XLOOKUP(PREÇO!C32,'Equipamentos de emergência'!$E$8:$E$1260,'Equipamentos de emergência'!$J$8:$J$1260) -> m | E32: 3.89
C33: Isolação em PVC (70ºC) 6 mm² - Preto | D33: =_xlfn.XLOOKUP(PREÇO!C33,'Equipamentos de emergência'!$E$8:$E$1260,'Equipamentos de emergência'!$J$8:$J$1260) -> m | E33: 5.79
... C52: PVC Flexível Antichama - NBR 15465 ø3/4" | D52: =_xlfn.XLOOKUP(PREÇO!C52,'Equipamentos de emergência'!$E$8:$E$1260,'Equipamentos de emergência'!$J$8:$J$1260) -> m | E52: 1.8
C53: PVC Rígido - NBR 15465 ø2" | D53: =_xlfn.XLOOKUP(PREÇO!C53,'Equipamentos de emergência'!$E$8:$E$1260,'Equipamentos de emergência'!$J$8:$J$1260) -> m | E53: =75.99/3 -> 25.33
C54: Quadro rebaixador de tensão | D54: =_xlfn.XLOOKUP(PREÇO!C54,'Equipamentos de emergência'!$E$8:$E$1260,'Equipamentos de emergência'!$J$8:$J$1260) -> pç | E54: 700
C55: Repetidor para Central de Alarme de Incêndio | D55: =_xlfn.XLOOKUP(PREÇO!C55,'Equipamentos de emergência'!$E$8:$E$1260,'Equipamentos de emergência'!$J$8:$J$1260) -> pç | E55: 922.9
C56: Sensor de Fumaça | D56: =_xlfn.XLOOKUP(PREÇO!C56,'Equipamentos de emergência'!$E$8:$E$1260,'Equipamentos de emergência'!$J$8:$J$1260) -> pç | E56: 53.9
C57: Sensor de Fumaça para Duto | D57: =_xlfn.XLOOKUP(PREÇO!C57,'Equipamentos de emergência'!$E$8:$E$1260,'Equipamentos de emergência'!$J$8:$J$1260) -> pç | E57: 3680
C58: Sensor de Presença 24V de teto | D58: =_xlfn.XLOOKUP(PREÇO!C58,'Equipamentos de emergência'!$E$8:$E$1260,'Equipamentos de emergência'!$J$8:$J$1260) -> pç | E58: 38.4
C59: Suporte p/ caixa 4x2" Padrão NBR IEC 60670 | D59: =_xlfn.XLOOKUP(PREÇO!C59,'Equipamentos de emergência'!$E$8:$E$1260,'Equipamentos de emergência'!$J$8:$J$1260) -> pç | E59: 1.85
...

Sheet Equipamentos de emergência
C1: Projeto | D1: Senna Tower
C2: Empresa | D2: FG
C3: Origem | D3: SEN-EX-ILU-001-MAT-R00.xlsx
C4: Revisão | D4: R00 - Letícia
A5: EQUIPAMENTOS DE EMERGÊNCIA
A6: TORRE | B6: PAVIMENTO | C6: GRUPO/EAP | D6: SUBGRUPO | E6: Descrição | F6: Quantidade | G6: Repetição | H6: Perda | I6: Qte com perda | J6: Unidade | K6: Custo unitário | L6: Custo Total | N6: Torre | O6: EAP | P6: {=TRANSPOSE(_xlfn.UNIQUE(_xlfn._xlws.FILTER($C$7:$C$1048576,$C$7:$C$1048576<>"")))} -> Cabeamento e equipamentos alarme de incêndio | Q6: Automação iluminação de emergência | R6: Extintores e placas de sinalização | S6: TOTAL
A7: GERAL | B7: SUBSOLO | L7: =IF(SUM(F7:K7)=0,SUMIFS($L8:$L$1593,$B8:$B$1593,$B7,$A8:$A$1593,$A7),I7*K7) -> 30825.523 | N7: GERAL | O7: {=_xlfn.UNIQUE(_xlfn._xlws.FILTER($B$7:$B$1048576,$B$7:$B$1048576<>""))} -> SUBSOLO | P7: =SUMIFS($L$7:$L$1260,$C$7:$C$1260,P$6,$B$7:$B$1260,$O7,$A$7:$A$1260,$N7) -> 18908.343 | Q7: =SUMIFS($L$7:$L$1260,$C$7:$C$1260,Q$6,$B$7:$B$1260,$O7,$A$7:$A$1260,$N7) -> 1396.5 | R7: =SUMIFS($L$7:$L$1260,$C$7:$C$1260,R$6,$B$7:$B$1260,$O7,$A$7:$A$1260,$N7) -> 10520.68 | S7: =SUM(P7:R7) -> 30825.523
A8: =A7 -> GERAL | B8: =B7 -> SUBSOLO | C8: Cabeamento e equipamentos alarme de incêndio | D8: =_xlfn.XLOOKUP(E8,Subsolo!$D$6:$D$58,Subsolo!$C$6:$C$58) -> Acionadores | E8: Acionador Manual de Alarme de Incêndio | F8: 7 | G8: 1 | H8: 0 | I8: =(F8+H8*F8)*G8 -> 7 | J8: pç | K8: =_xlfn.XLOOKUP($E8,PREÇO!$C$7:$C$91,PREÇO!$E$7:$E$91) -> 65 | L8: =IF(SUM(F8:K8)=0,SUMIFS($L9:$L$1593,$B9:$B$1593,$B8,$A9:$A$1593,$A8),I8*K8) -> 455 | N8: GERAL | O8: 1° PAV. TÉRREO | P8: =SUMIFS($L$7:$L$1260,$C$7:$C$1260,P$6,$B$7:$B$1260,$O8,$A$7:$A$1260,$N8) -> 29821.845 | Q8: =SUMIFS($L$7:$L$1260,$C$7:$C$1260,Q$6,$B$7:$B$1260,$O8,$A$7:$A$1260,$N8) -> 6113.7 | R8: =SUMIFS($L$7:$L$1260,$C$7:$C$1260,R$6,$B$7:$B$1260,$O8,$A$7:$A$1260,$N8) -> 12604.64 | S8: =SUM(P8:R8) -> 48540.185
A9: =A8 -> GERAL | B9: =B8 -> SUBSOLO | C9: Cabeamento e equipamentos alarme de incêndio | D9: =_xlfn.XLOOKUP(E9,Subsolo!$D$6:$D$58,Subsolo!$C$6:$C$58) -> Anunciadores | E9: Anunciador Audiovisual de Alarme de Incêndio de Parede | F9: 7 | G9: 1 | H9: 0 | I9: =(F9+H9*F9)*G9 -> 7 | J9: pç | K9: =_xlfn.XLOOKUP($E9,PREÇO!$C$7:$C$91,PREÇO!$E$7:$E$91) -> 191.81 | L9: =IF(SUM(F9:K9)=0,SUMIFS($L10:$L$1593,$B10:$B$1593,$B9,$A10:$A$1593,$A9),I9*K9) -> 1342.67 | N9: GERAL | O9: 2° PAV. - ESTAC. 01 | P9: =SUMIFS($L$7:$L$1260,$C$7:$C$1260,P$6,$B$7:$B$1260,$O9,$A$7:$A$1260,$N9) -> 22694.598 | Q9: =SUMIFS($L$7:$L$1260,$C$7:$C$1260,Q$6,$B$7:$B$1260,$O9,$A$7:$A$1260,$N9) -> 6211.7 | R9: =SUMIFS($L$7:$L$1260,$C$7:$C$1260,R$6,$B$7:$B$1260,$O9,$A$7:$A$1260,$N9) -> 10470.02 | S9: =SUM(P9:R9) -> 39376.318
A10: =A9 -> GERAL | B10: =B9 -> SUBSOLO | C10: Cabeamento e equipamentos alarme de incêndio | D10: =_xlfn.XLOOKUP(E10,Subsolo!$D$6:$D$58,Subsolo!$C$6:$C$58) -> Atuadores | E10: Atuador Janela Desenfumagem | F10: 1 | G10: 1 | H10: 0 | I10: =(F10+H10*F10)*G10 -> 1 | J10: pç | K10: =_xlfn.XLOOKUP($E10,PREÇO!$C$7:$C$91,PREÇO!$E$7:$E$91) -> 1150 | L10: =IF(SUM(F10:K10)=0,SUMIFS($L11:$L$1593,$B11:$B$1593,$B10,$A11:$A$1593,$A10),I10*K10) -> 1150 | N10: GERAL | O10: 3° PAV. - ESTAC. 02 | P10: =SUMIFS($L$7:$L$1260,$C$7:$C$1260,P$6,$B$7:$B$1260,$O10,$A$7:$A$1260,$N10) -> 18568.466 | Q10: =SUMIFS($L$7:$L$1260,$C$7:$C$1260,Q$6,$B$7:$B$1260,$O10,$A$7:$A$1260,$N10) -> 6113.4 | R10: =SUMIFS($L$7:$L$1260,$C$7:$C$1260,R$6,$B$7:$B$1260,$O10,$A$7:$A$1260,$N10) -> 10408.36 | S10: =SUM(P10:R10) -> 35090.226
A11: =A10 -> GERAL | B11: =B10 -> SUBSOLO | C11: Cabeamento e equipamentos alarme de incêndio | D11: =_xlfn.XLOOKUP(E11,Subsolo!$D$6:$D$58,Subsolo!$C$6:$C$58) -> Sensores | E11: Sensor de Fumaça | F11: 11 | G11: 1 | H11: 0 | I11: =(F11+H11*F11)*G11 -> 11 | J11: pç | K11: =_xlfn.XLOOKUP($E11,PREÇO!$C$7:$C$91,PREÇO!$E$7:$E$91) -> 53.9 | L11: =IF(SUM(F11:K11)=0,SUMIFS($L12:$L$1593,$B12:$B$1593,$B11,$A12:$A$1593,$A11),I11*K11) -> 592.9 | N11: GERAL | O11: 4º PAV. - ESTAC. 03 | P11: =SUMIFS($L$7:$L$1260,$C$7:$C$1260,P$6,$B$7:$B$1260,$O11,$A$7:$A$1260,$N11) -> 18537.743 | Q11: =SUMIFS($L$7:$L$1260,$C$7:$C$1260,Q$6,$B$7:$B$1260,$O11,$A$7:$A$1260,$N11) -> 6113.4 | R11: =SUMIFS($L$7:$L$1260,$C$7:$C$1260,R$6,$B$7:$B$1260,$O11,$A$7:$A$1260,$N11) -> 19460.2 | S11: =SUM(P11:R11) -> 44111.342
A12: =A11 -> GERAL | B12: =B11 -> SUBSOLO | C12: Cabeamento e equipamentos alarme de incêndio | D12: =_xlfn.XLOOKUP(E12,Subsolo!$D$6:$D$58,Subsolo!$C$6:$C$58) -> Caixas | E12: Caixa Octogonal Padrão NBR IEC 60670 | F12: 62 | G12: 1 | H12: 0 | I12: =(F12+H12*F12)*G12 -> 62 | J12: pç | K12: =_xlfn.XLOOKUP($E12,PREÇO!$C$7:$C$91,PREÇO!$E$7:$E$91) -> 5.32 | L12: =IF(SUM(F12:K12)=0,SUMIFS($L13:$L$1593,$B13:$B$1593,$B12,$A13:$A$1593,$A12),I12*K12) -> 329.84 | N12: GERAL | O12: 5º PAV. - ESTAC. 04 | P12: =SUMIFS($L$7:$L$1260,$C$7:$C$1260,P$6,$B$7:$B$1260,$O12,$A$7:$A$1260,$N12) -> 19291.904 | Q12: =SUMIFS($L$7:$L$1260,$C$7:$C$1260,Q$6,$B$7:$B$1260,$O12,$A$7:$A$1260,$N12) -> 6221.7 | R12: =SUMIFS($L$7:$L$1260,$C$7:$C$1260,R$6,$B$7:$B$1260,$O12,$A$7:$A$1260,$N12) -> 1479.84 | S12: =SUM(P12:R12) -> 26993.444
A13: =A12 -> GERAL | B13: =B12 -> SUBSOLO | C13: Cabeamento e equipamentos alarme de incêndio | D13: =_xlfn.XLOOKUP(E13,Subsolo!$D$6:$D$58,Subsolo!$C$6:$C$58) -> Placas | E13: Placa cega para caixa octogonal Padrão NBR IEC 60670 | F13: 44 | G13: 1 | H13: 0 | I13: =(F13+H13*F13)*G13 -> 44 | J13: pç | K13: =_xlfn.XLOOKUP($E13,PREÇO!$C$7:$C$91,PREÇO!$E$7:$E$91) -> 2.5 | L13: =IF(SUM(F13:K13)=0,SUMIFS($L14:$L$1593,$B14:$B$1593,$B13,$A14:$A$1593,$A13),I13*K13) -> 110 | N13: GERAL | O13: 6º PAV. - ESTAC. 05 | P13: =SUMIFS($L$7:$L$1260,$C$7:$C$1260,P$6,$B$7:$B$1260,$O13,$A$7:$A$1260,$N13) -> 19088.124 | Q13: =SUMIFS($L$7:$L$1260,$C$7:$C$1260,Q$6,$B$7:$B$1260,$O13,$A$7:$A$1260,$N13) -> 6113.4 | R13: =SUMIFS($L$7:$L$1260,$C$7:$C$1260,R$6,$B$7:$B$1260,$O13,$A$7:$A$1260,$N13) -> 10470.02 | S13: =SUM(P13:R13) -> 35671.544
A14: =A13 -> GERAL | B14: =B13 -> SUBSOLO | C14: Cabeamento e equipamentos alarme de incêndio | D14: =_xlfn.XLOOKUP(E14,Subsolo!$D$6:$D$58,Subsolo!$C$6:$C$58) -> Caixas | E14: Caixa 4x2" de Embutir em PVC Padrão NBR IEC 60670 | F14: 103 | G14: 1 | H14: 0 | I14: =(F14+H14*F14)*G14 -> 103 | J14: pç | K14: =_xlfn.XLOOKUP($E14,PREÇO!$C$7:$C$91,PREÇO!$E$7:$E$91) -> 1.72 | L14: =IF(SUM(F14:K14)=0,SUMIFS($L15:$L$1593,$B15:$B$1593,$B14,$A15:$A$1593,$A14),I14*K14) -> 177.16 | N14: GERAL | O14: 7º PAV. - ESTAC. 06 | P14: =SUMIFS($L$7:$L$1260,$C$7:$C$1260,P$6,$B$7:$B$1260,$O14,$A$7:$A$1260,$N14) -> 18419.213 | Q14: =SUMIFS($L$7:$L$1260,$C$7:$C$1260,Q$6,$B$7:$B$1260,$O14,$A$7:$A$1260,$N14) -> 5896.8 | R14: =SUMIFS($L$7:$L$1260,$C$7:$C$1260,R$6,$B$7:$B$1260,$O14,$A$7:$A$1260,$N14) -> 10408.36 | S14: =SUM(P14:R14) -> 34724.373
A15: =A14 -> GERAL | B15: =B14 -> SUBSOLO | C15: Cabeamento e equipamentos alarme de incêndio | D15: =_xlfn.XLOOKUP(E15,Subsolo!$D$6:$D$58,Subsolo!$C$6:$C$58) -> Caixas | E15: Caixa 4x4" de Embutir em PVC Padrão NBR IEC 60670 | F15: 2 | G15: 1 | H15: 0 | I15: =(F15+H15*F15)*G15 -> 2 | J15: pç | K15: =_xlfn.XLOOKUP($E15,PREÇO!$C$7:$C$91,PREÇO!$E$7:$E$91) -> 1.72 | L15: =IF(SUM(F15:K15)=0,SUMIFS($L16:$L$1593,$B16:$B$1593,$B15,$A16:$A$1593,$A15),I15*K15) -> 3.44 | N15: GERAL | O15: 8º PAV. - LAZER PÚBLICO 01 | P15: =SUMIFS($L$7:$L$1260,$C$7:$C$1260,P$6,$B$7:$B$1260,$O15,$A$7:$A$1260,$N15) -> 11072.128 | Q15: =SUMIFS($L$7:$L$1260,$C$7:$C$1260,Q$6,$B$7:$B$1260,$O15,$A$7:$A$1260,$N15) -> 2319.9 | R15: =SUMIFS($L$7:$L$1260,$C$7:$C$1260,R$6,$B$7:$B$1260,$O15,$A$7:$A$1260,$N15) -> 9619.26 | S15: =SUM(P15:R15) -> 23011.288
A16: =A15 -> GERAL | B16: =B15 -> SUBSOLO | C16: Cabeamento e equipamentos alarme de incêndio | D16: =_xlfn.XLOOKUP(E16,Subsolo!$D$6:$D$58,Subsolo!$C$6:$C$58) -> Placas | E16: Placa 4x2" cega Padrão NBR IEC 60670 | F16: 66 | G16: 1 | H16: 0 | I16: =(F16+H16*F16)*G16 -> 66 | J16: pç | K16: =_xlfn.XLOOKUP($E16,PREÇO!$C$7:$C$91,PREÇO!$E$7:$E$91) -> 4.59 | L16: =IF(SUM(F16:K16)=0,SUMIFS($L17:$L$1593,$B17:$B$1593,$B16,$A17:$A$1593,$A16),I16*K16) -> 302.94 | N16: GERAL | O16: 9º PAV. - LAZER PÚBLICO 02 | P16: =SUMIFS($L$7:$L$1260,$C$7:$C$1260,P$6,$B$7:$B$1260,$O16,$A$7:$A$1260,$N16) -> 8782.3704 | Q16: =SUMIFS($L$7:$L$1260,$C$7:$C$1260,Q$6,$B$7:$B$1260,$O16,$A$7:$A$1260,$N16) -> 1877.1 | R16: =SUMIFS($L$7:$L$1260,$C$7:$C$1260,R$6,$B$7:$B$1260,$O16,$A$7:$A$1260,$N16) -> 9822.96 | S16: =SUM(P16:R16) -> 20482.43
A17: =A16 -> GERAL | B17: =B16 -> SUBSOLO | C17: Cabeamento e equipamentos alarme de incêndio | D17: =_xlfn.XLOOKUP(E17,Subsolo!$D$6:$D$58,Subsolo!$C$6:$C$58) -> Placas | E17: Placa 4x2" com furo para saída de cabos Padrão NBR IEC 60670 | F17: 37 | G17: 1 | H17: 0 | I17: =(F17+H17*F17)*G17 -> 37 | J17: pç | K17: =_xlfn.XLOOKUP($E17,PREÇO!$C$7:$C$91,PREÇO!$E$7:$E$91) -> 6.55 | L17: =IF(SUM(F17:K17)=0,SUMIFS($L18:$L$1593,$B18:$B$1593,$B17,$A18:$A$1593,$A17),I17*K17) -> 242.35 | N17: GERAL | O17: 10º PAV. - LAZER 01 | P17: =SUMIFS($L$7:$L$1260,$C$7:$C$1260,P$6,$B$7:$B$1260,$O17,$A$7:$A$1260,$N17) -> 7509.7772 | Q17: =SUMIFS($L$7:$L$1260,$C$7:$C$1260,Q$6,$B$7:$B$1260,$O17,$A$7:$A$1260,$N17) -> 941.7 | R17: =SUMIFS($L$7:$L$1260,$C$7:$C$1260,R$6,$B$7:$B$1260,$O17,$A$7:$A$1260,$N17) -> 9890.86 | S17: =SUM(P17:R17) -> 18342.337
A18: =A17 -> GERAL | B18: =B17 -> SUBSOLO | C18: Cabeamento e equipamentos alarme de incêndio | D18: =_xlfn.XLOOKUP(E18,Subsolo!$D$6:$D$58,Subsolo!$C$6:$C$58) -> Placas | E18: Placa 4x4" cega Padrão NBR IEC 60670 | F18: 2 | G18: 1 | H18: 0 | I18: =(F18+H18*F18)*G18 -> 2 | J18: pç | K18: =_xlfn.XLOOKUP($E18,PREÇO!$C$7:$C$91,PREÇO!$E$7:$E$91) -> 12.25 | L18: =IF(SUM(F18:K18)=0,SUMIFS($L19:$L$1593,$B19:$B$1593,$B18,$A19:$A$1593,$A18),I18*K18) -> 24.5 | N18: GERAL | O18: 11º PAV. - LAZER 02 | P18: =SUMIFS($L$7:$L$1260,$C$7:$C$1260,P$6,$B$7:$B$1260,$O18,$A$7:$A$1260,$N18) -> 6643.056 | Q18: =SUMIFS($L$7:$L$1260,$C$7:$C$1260,Q$6,$B$7:$B$1260,$O18,$A$7:$A$1260,$N18) -> 878.1 | R18: =SUMIFS($L$7:$L$1260,$C$7:$C$1260,R$6,$B$7:$B$1260,$O18,$A$7:$A$1260,$N18) -> 9816.72 | S18: =SUM(P18:R18) -> 17337.876
A19: =A18 -> GERAL | B19: =B18 -> SUBSOLO | C19: Cabeamento e equipamentos alarme de incêndio | D19: =_xlfn.XLOOKUP(E19,Subsolo!$D$6:$D$58,Subsolo!$C$6:$C$58) -> Suportes | E19: Suporte p/ caixa 4x2" Padrão NBR IEC 60670 | F19: 103 | G19: 1 | H19: 0 | I19: =(F19+H19*F19)*G19 -> 103 | J19: pç | K19: =_xlfn.XLOOKUP($E19,PREÇO!$C$7:$C$91,PREÇO!$E$7:$E$91) -> 1.85 | L19: =IF(SUM(F19:K19)=0,SUMIFS($L20:$L$1593,$B20:$B$1593,$B19,$A20:$A$1593,$A19),I19*K19) -> 190.55 | N19: GERAL | O19: 12º PAV. - ÁREA TÉCNICA 01 | P19: =SUMIFS($L$7:$L$1260,$C$7:$C$1260,P$6,$B$7:$B$1260,$O19,$A$7:$A$1260,$N19) -> 3576.0521 | Q19: =SUMIFS($L$7:$L$1260,$C$7:$C$1260,Q$6,$B$7:$B$1260,$O19,$A$7:$A$1260,$N19) -> 591.9 | R19: =SUMIFS($L$7:$L$1260,$C$7:$C$1260,R$6,$B$7:$B$1260,$O19,$A$7:$A$1260,$N19) -> 2771.22 | S19: =SUM(P19:R19) -> 6939.1721
... A21: =A20 -> GERAL | B21: =B20 -> SUBSOLO | C21: Cabeamento e equipamentos alarme de incêndio | D21: =_xlfn.XLOOKUP(E21,Subsolo!$D$6:$D$58,Subsolo!$C$6:$C$58) -> Embutir | E21: Cx de passagem de embutir com dimensão de 50x50x15 cm | F21: 1 | G21: 1 | H21: 0 | I21: =(F21+H21*F21)*G21 -> 1 | J21: pç | K21: =_xlfn.XLOOKUP($E21,PREÇO!$C$7:$C$91,PREÇO!$E$7:$E$91) -> 291.6 | L21: =IF(SUM(F21:K21)=0,SUMIFS($L22:$L$1593,$B22:$B$1593,$B21,$A22:$A$1593,$A21),I21*K21) -> 291.6 | N21: GERAL | O21: 19º PAV. - TIPO 02 - x3 - LANÇAMENTO | P21: =SUMIFS($L$7:$L$1260,$C$7:$C$1260,P$6,$B$7:$B$1260,$O21,$A$7:$A$1260,$N21) -> 14441.874 | Q21: =SUMIFS($L$7:$L$1260,$C$7:$C$1260,Q$6,$B$7:$B$1260,$O21,$A$7:$A$1260,$N21) -> 1537.2 | R21: =SUMIFS($L$7:$L$1260,$C$7:$C$1260,R$6,$B$7:$B$1260,$O21,$A$7:$A$1260,$N21) -> 2124.66 | S21: =SUM(P21:R21) -> 18103.734
A22: =A21 -> GERAL | B22: =B21 -> SUBSOLO | C22: Cabeamento e equipamentos alarme de incêndio | D22: Eletrodutos | E22: PVC Flexível Antichama - NBR 15465 ø1" | F22: 125.45 | G22: 1 | H22: 0 | I22: =(F22+H22*F22)*G22 -> 125.45 | J22: m | K22: =_xlfn.XLOOKUP($E22,PREÇO!$C$7:$C$91,PREÇO!$E$7:$E$91) -> 2.53 | L22: =IF(SUM(F22:K22)=0,SUMIFS($L23:$L$1593,$B23:$B$1593,$B22,$A23:$A$1593,$A22),I22*K22) -> 317.3885 | N22: GERAL | O22: 22º PAV. - ÁREA TÉCNICA 02 | P22: =SUMIFS($L$7:$L$1260,$C$7:$C$1260,P$6,$B$7:$B$1260,$O22,$A$7:$A$1260,$N22) -> 8700.4222 | Q22: =SUMIFS($L$7:$L$1260,$C$7:$C$1260,Q$6,$B$7:$B$1260,$O22,$A$7:$A$1260,$N22) -> 1498.2 | R22: =SUMIFS($L$7:$L$1260,$C$7:$C$1260,R$6,$B$7:$B$1260,$O22,$A$7:$A$1260,$N22) -> 2771.22 | S22: =SUM(P22:R22) -> 12969.842
A23: =A22 -> GERAL | B23: =B22 -> SUBSOLO | C23: Cabeamento e equipamentos alarme de incêndio | D23: Eletrodutos | E23: PVC Flexível Antichama - NBR 15465 ø3/4" | F23: 563.68 | G23: 1 | H23: 0 | I23: =(F23+H23*F23)*G23 -> 563.68 | J23: m | K23: =_xlfn.XLOOKUP($E23,PREÇO!$C$7:$C$91,PREÇO!$E$7:$E$91) -> 1.8 | L23: =IF(SUM(F23:K23)=0,SUMIFS($L24:$L$1593,$B24:$B$1593,$B23,$A24:$A$1593,$A23),I23*K23) -> 1014.624 | N23: GERAL | O23: 23º PAV. - TIPO 03A - x11 - LANÇAMENTO | P23: =SUMIFS($L$7:$L$1260,$C$7:$C$1260,P$6,$B$7:$B$1260,$O23,$A$7:$A$1260,$N23) -> 52391.692 | Q23: =SUMIFS($L$7:$L$1260,$C$7:$C$1260,Q$6,$B$7:$B$1260,$O23,$A$7:$A$1260,$N23) -> 5636.4 | R23: =SUMIFS($L$7:$L$1260,$C$7:$C$1260,R$6,$B$7:$B$1260,$O23,$A$7:$A$1260,$N23) -> 7790.42 | S23: =SUM(P23:R23) -> 65818.512
A24: =A23 -> GERAL | B24: =B23 -> SUBSOLO | C24: Automação iluminação de emergência | D24: =_xlfn.XLOOKUP(E24,Subsolo!$D$6:$D$58,Subsolo!$C$6:$C$58) -> Luminárias e Placas de Saída | E24: Luminária de Emergência 24V de Parede | F24: 63 | G24: 1 | H24: 0 | I24: =(F24+H24*F24)*G24 -> 63 | J24: pç | K24: =_xlfn.XLOOKUP($E24,PREÇO!$C$7:$C$91,PREÇO!$E$7:$E$91) -> 15.9 | L24: =IF(SUM(F24:K24)=0,SUMIFS($L25:$L$1593,$B25:$B$1593,$B24,$A25:$A$1593,$A24),I24*K24) -> 1001.7 | N24: GERAL | O24: 34º PAV. - TIPO 03B - x8 - MODELO | P24: =SUMIFS($L$7:$L$1260,$C$7:$C$1260,P$6,$B$7:$B$1260,$O24,$A$7:$A$1260,$N24) -> 36451.486 | Q24: =SUMIFS($L$7:$L$1260,$C$7:$C$1260,Q$6,$B$7:$B$1260,$O24,$A$7:$A$1260,$N24) -> 4099.2 | R24: =SUMIFS($L$7:$L$1260,$C$7:$C$1260,R$6,$B$7:$B$1260,$O24,$A$7:$A$1260,$N24) -> 5665.76 | S24: =SUM(P24:R24) -> 46216.446
A25: =A24 -> GERAL | B25: =B24 -> SUBSOLO | C25: Automação iluminação de emergência | D25: =_xlfn.XLOOKUP(E25,Subsolo!$D$6:$D$58,Subsolo!$C$6:$C$58) -> Luminárias e Placas de Saída | E25: Luminária de Emergência 24V de Teto | F25: 4 | G25: 1 | H25: 0 | I25: =(F25+H25*F25)*G25 -> 4 | J25: pç | K25: =_xlfn.XLOOKUP($E25,PREÇO!$C$7:$C$91,PREÇO!$E$7:$E$91) -> 69.9 | L25: =IF(SUM(F25:K25)=0,SUMIFS($L26:$L$1593,$B26:$B$1593,$B25,$A26:$A$1593,$A25),I25*K25) -> 279.6 | N25: GERAL | O25: 42º PAV. - ÁREA TÉCNICA 03 | P25: =SUMIFS($L$7:$L$1260,$C$7:$C$1260,P$6,$B$7:$B$1260,$O25,$A$7:$A$1260,$N25) -> 4886.2467 | Q25: =SUMIFS($L$7:$L$1260,$C$7:$C$1260,Q$6,$B$7:$B$1260,$O25,$A$7:$A$1260,$N25) -> 1498.2 | R25: =SUMIFS($L$7:$L$1260,$C$7:$C$1260,R$6,$B$7:$B$1260,$O25,$A$7:$A$1260,$N25) -> 2771.22 | S25: =SUM(P25:R25) -> 9155.6667
A26: =A25 -> GERAL | B26: =B25 -> SUBSOLO | C26: Extintores e placas de sinalização | D26: =_xlfn.XLOOKUP(E26,Subsolo!$D$6:$D$58,Subsolo!$C$6:$C$58) -> Luminárias e Placas de Saída | E26: Placa de Saída 24V de Parede com Direção | F26: 18 | G26: 1 | H26: 0 | I26: =(F26+H26*F26)*G26 -> 18 | J26: pç | K26: =_xlfn.XLOOKUP($E26,PREÇO!$C$7:$C$91,PREÇO!$E$7:$E$91) -> 67.9 | L26: =IF(SUM(F26:K26)=0,SUMIFS($L27:$L$1593,$B27:$B$1593,$B26,$A27:$A$1593,$A26),I26*K26) -> 1222.2 | N26: GERAL | O26: 43º PAV. - TIPO 03C - x9 - MODELO | P26: =SUMIFS($L$7:$L$1260,$C$7:$C$1260,P$6,$B$7:$B$1260,$O26,$A$7:$A$1260,$N26) -> 42664.635 | Q26: =SUMIFS($L$7:$L$1260,$C$7:$C$1260,Q$6,$B$7:$B$1260,$O26,$A$7:$A$1260,$N26) -> 4611.6 | R26: =SUMIFS($L$7:$L$1260,$C$7:$C$1260,R$6,$B$7:$B$1260,$O26,$A$7:$A$1260,$N26) -> 6373.98 | S26: =SUM(P26:R26) -> 53650.215
A27: =A26 -> GERAL | B27: =B26 -> SUBSOLO | C27: Extintores e placas de sinalização | D27: =_xlfn.XLOOKUP(E27,Subsolo!$D$6:$D$58,Subsolo!$C$6:$C$58) -> Luminárias e Placas de Saída | E27: Placa de Saída 24V de Parede sem Direção | F27: 2 | G27: 1 | H27: 0 | I27: =(F27+H27*F27)*G27 -> 2 | J27: pç | K27: =_xlfn.XLOOKUP($E27,PREÇO!$C$7:$C$91,PREÇO!$E$7:$E$91) -> 61.66 | L27: =IF(SUM(F27:K27)=0,SUMIFS($L28:$L$1593,$B28:$B$1593,$B27,$A28:$A$1593,$A27),I27*K27) -> 123.32 | N27: GERAL | O27: 52º PAV. - TIPO 04A - x10 - LANÇAMENTO | P27: =SUMIFS($L$7:$L$1260,$C$7:$C$1260,P$6,$B$7:$B$1260,$O27,$A$7:$A$1260,$N27) -> 50180.864 | Q27: =SUMIFS($L$7:$L$1260,$C$7:$C$1260,Q$6,$B$7:$B$1260,$O27,$A$7:$A$1260,$N27) -> 5124 | R27: =SUMIFS($L$7:$L$1260,$C$7:$C$1260,R$6,$B$7:$B$1260,$O27,$A$7:$A$1260,$N27) -> 7082.2 | S27: =SUM(P27:R27) -> 62387.064
A28: =A27 -> GERAL | B28: =B27 -> SUBSOLO | C28: Extintores e placas de sinalização | D28: =_xlfn.XLOOKUP(E28,Subsolo!$D$6:$D$58,Subsolo!$C$6:$C$58) -> Luminárias e Placas de Saída | E28: Placa de Saída Dupla Face 24V de Teto com Direção | F28: 2 | G28: 1 | H28: 0 | I28: =(F28+H28*F28)*G28 -> 2 | J28: pç | K28: =_xlfn.XLOOKUP($E28,PREÇO!$C$7:$C$91,PREÇO!$E$7:$E$91) -> 61.66 | L28: =IF(SUM(F28:K28)=0,SUMIFS($L30:$L$1593,$B30:$B$1593,$B28,$A30:$A$1593,$A28),I28*K28) -> 123.32 | N28: GERAL | O28: 62º PAV. - ÁREA TÉCNICA 04 | P28: =SUMIFS($L$7:$L$1260,$C$7:$C$1260,P$6,$B$7:$B$1260,$O28,$A$7:$A$1260,$N28) -> 5926.3326 | Q28: =SUMIFS($L$7:$L$1260,$C$7:$C$1260,Q$6,$B$7:$B$1260,$O28,$A$7:$A$1260,$N28) -> 2125.2 | R28: =SUMIFS($L$7:$L$1260,$C$7:$C$1260,R$6,$B$7:$B$1260,$O28,$A$7:$A$1260,$N28) -> 2894.54 | S28: =SUM(P28:R28) -> 10946.073
A29: =A27 -> GERAL | B29: =B27 -> SUBSOLO | C29: Extintores e placas de sinalização | D29: Extintior | E29: Extintor ABC | F29: 14 | G29: 1 | H29: 0 | I29: =(F29+H29*F29)*G29 -> 14 | J29: Unidade | K29: =_xlfn.XLOOKUP($E29,PREÇO!$C$7:$C$91,PREÇO!$E$7:$E$91) -> 646.56 | L29: =IF(SUM(F29:K29)=0,SUMIFS($L30:$L$1593,$B30:$B$1593,$B29,$A30:$A$1593,$A29),I29*K29) -> 9051.84 | N29: GERAL | O29: 63º PAV. - LAZER 03 | P29: =SUMIFS($L$7:$L$1260,$C$7:$C$1260,P$6,$B$7:$B$1260,$O29,$A$7:$A$1260,$N29) -> 3886.7686 | Q29: =SUMIFS($L$7:$L$1260,$C$7:$C$1260,Q$6,$B$7:$B$1260,$O29,$A$7:$A$1260,$N29) -> 703.2 | R29: =SUMIFS($L$7:$L$1260,$C$7:$C$1260,R$6,$B$7:$B$1260,$O29,$A$7:$A$1260,$N29) -> 1613.9 | S29: =SUM(P29:R29) -> 6203.8686
A30: =A28 -> GERAL | B30: =B28 -> SUBSOLO | C30: Automação iluminação de emergência | D30: =_xlfn.XLOOKUP(E30,Subsolo!$D$6:$D$58,Subsolo!$C$6:$C$58) -> Sensores de Presença | E30: Sensor de Presença 24V de teto | F30: 3 | G30: 1 | H30: 0 | I30: =(F30+H30*F30)*G30 -> 3 | J30: pç | K30: =_xlfn.XLOOKUP($E30,PREÇO!$C$7:$C$91,PREÇO!$E$7:$E$91) -> 38.4 | L30: =IF(SUM(F30:K30)=0,SUMIFS($L31:$L$1593,$B31:$B$1593,$B30,$A31:$A$1593,$A30),I30*K30) -> 115.2 | N30: GERAL | O30: 64º PAV. - LAZER 04 | P30: =SUMIFS($L$7:$L$1260,$C$7:$C$1260,P$6,$B$7:$B$1260,$O30,$A$7:$A$1260,$N30) -> 3530.0916 | Q30: =SUMIFS($L$7:$L$1260,$C$7:$C$1260,Q$6,$B$7:$B$1260,$O30,$A$7:$A$1260,$N30) -> 687.3 | R30: =SUMIFS($L$7:$L$1260,$C$7:$C$1260,R$6,$B$7:$B$1260,$O30,$A$7:$A$1260,$N30) -> 1478.1 | S30: =SUM(P30:R30) -> 5695.4916
A31: =A30 -> GERAL | B31: =B30 -> SUBSOLO | C31: Cabeamento e equipamentos alarme de incêndio | D31: Cabo Unipolar Cobre | E31: =Subsolo!C40&" "&Subsolo!D40 -> Isolação em PVC (70ºC) 1.5 mm² - Amarelo | F31: =Subsolo!E40 -> 14.43 | G31: 1 | H31: 0 | I31: =(F31+H31*F31)*G31 -> 14.43 | J31: =Subsolo!F40 -> m | K31: =_xlfn.XLOOKUP($E31,PREÇO!$C$7:$C$91,PREÇO!$E$7:$E$91) -> 1.59 | L31: =IF(SUM(F31:K31)=0,SUMIFS($L32:$L$1593,$B32:$B$1593,$B31,$A32:$A$1593,$A31),I31*K31) -> 22.9437 | N31: GERAL | O31: 65º PAV. - TIPO 04B - x36 - MODELO | P31: =SUMIFS($L$7:$L$1260,$C$7:$C$1260,P$6,$B$7:$B$1260,$O31,$A$7:$A$1260,$N31) -> 158915.86 | Q31: =SUMIFS($L$7:$L$1260,$C$7:$C$1260,Q$6,$B$7:$B$1260,$O31,$A$7:$A$1260,$N31) -> 18446.4 | R31: =SUMIFS($L$7:$L$1260,$C$7:$C$1260,R$6,$B$7:$B$1260,$O31,$A$7:$A$1260,$N31) -> 25495.92 | S31: =SUM(P31:R31) -> 202858.18
A32: =A31 -> GERAL | B32: =B31 -> SUBSOLO | C32: Cabeamento e equipamentos alarme de incêndio | D32: Cabo Unipolar Cobre | E32: =Subsolo!C41&" "&Subsolo!D41 -> Isolação em PVC (70ºC) 1.5 mm² - Preto | F32: =Subsolo!E41 -> 7.22 | G32: 1 | H32: 0 | I32: =(F32+H32*F32)*G32 -> 7.22 | J32: =Subsolo!F41 -> m | K32: =_xlfn.XLOOKUP($E32,PREÇO!$C$7:$C$91,PREÇO!$E$7:$E$91) -> 1.59 | L32: =IF(SUM(F32:K32)=0,SUMIFS($L33:$L$1593,$B33:$B$1593,$B32,$A33:$A$1593,$A32),I32*K32) -> 11.4798 | N32: GERAL | O32: 82º PAV. - ÁREA TÉCNICA 05 | P32: =SUMIFS($L$7:$L$1260,$C$7:$C$1260,P$6,$B$7:$B$1260,$O32,$A$7:$A$1260,$N32) -> 8465.2044 | Q32: =SUMIFS($L$7:$L$1260,$C$7:$C$1260,Q$6,$B$7:$B$1260,$O32,$A$7:$A$1260,$N32) -> 1498.2 | R32: =SUMIFS($L$7:$L$1260,$C$7:$C$1260,R$6,$B$7:$B$1260,$O32,$A$7:$A$1260,$N32) -> 2771.22 | S32: =SUM(P32:R32) -> 12734.624
A33: =A32 -> GERAL | B33: =B32 -> SUBSOLO | C33: Cabeamento e equipamentos alarme de incêndio | D33: Cabo Unipolar Cobre | E33: =Subsolo!C42&" "&Subsolo!D42 -> Isolação em PVC (70ºC) 1.5 mm² - Vermelho | F33: =Subsolo!E42 -> 7.22 | G33: 1 | H33: 0 | I33: =(F33+H33*F33)*G33 -> 7.22 | J33: =Subsolo!F42 -> m | K33: =_xlfn.XLOOKUP($E33,PREÇO!$C$7:$C$91,PREÇO!$E$7:$E$91) -> 1.59 | L33: =IF(SUM(F33:K33)=0,SUMIFS($L34:$L$1593,$B34:$B$1593,$B33,$A34:$A$1593,$A33),I33*K33) -> 11.4798 | N33: GERAL | O33: 102º PAV. - ÁREA TÉCNICA 06 | P33: =SUMIFS($L$7:$L$1260,$C$7:$C$1260,P$6,$B$7:$B$1260,$O33,$A$7:$A$1260,$N33) -> 4858.5708 | Q33: =SUMIFS($L$7:$L$1260,$C$7:$C$1260,Q$6,$B$7:$B$1260,$O33,$A$7:$A$1260,$N33) -> 1498.2 | R33: =SUMIFS($L$7:$L$1260,$C$7:$C$1260,R$6,$B$7:$B$1260,$O33,$A$7:$A$1260,$N33) -> 2771.22 | S33: =SUM(P33:R33) -> 9127.9908
A34: =A33 -> GERAL | B34: =B33 -> SUBSOLO | C34: Cabeamento e equipamentos alarme de incêndio | D34: Cabo Unipolar Cobre | E34: =Subsolo!C43&" "&Subsolo!D43 -> Isolação em PVC (70ºC) 2.5 mm² - Amarelo | F34: =Subsolo!E43 -> 12.57 | G34: 1 | H34: 0 | I34: =(F34+H34*F34)*G34 -> 12.57 | J34: =Subsolo!F43 -> m | K34: =_xlfn.XLOOKUP($E34,PREÇO!$C$7:$C$91,PREÇO!$E$7:$E$91) -> 2.19 | L34: =IF(SUM(F34:K34)=0,SUMIFS($L35:$L$1593,$B35:$B$1593,$B34,$A35:$A$1593,$A34),I34*K34) -> 27.5283 | N34: GERAL | O34: 103º PAV. - TIPO 04C - x19 - MODELO | P34: =SUMIFS($L$7:$L$1260,$C$7:$C$1260,P$6,$B$7:$B$1260,$O34,$A$7:$A$1260,$N34) -> 89713.664 | Q34: =SUMIFS($L$7:$L$1260,$C$7:$C$1260,Q$6,$B$7:$B$1260,$O34,$A$7:$A$1260,$N34) -> 9735.6 | R34: =SUMIFS($L$7:$L$1260,$C$7:$C$1260,R$6,$B$7:$B$1260,$O34,$A$7:$A$1260,$N34) -> 13456.18 | S34: =SUM(P34:R34) -> 112905.44
A35: =A34 -> GERAL | B35: =B34 -> SUBSOLO | C35: Cabeamento e equipamentos alarme de incêndio | D35: Cabo Unipolar Cobre | E35: =Subsolo!C44&" "&Subsolo!D44 -> Isolação em PVC (70ºC) 2.5 mm² - Preto | F35: =Subsolo!E44 -> 112.72 | G35: 1 | H35: 0 | I35: =(F35+H35*F35)*G35 -> 112.72 | J35: =Subsolo!F44 -> m | K35: =_xlfn.XLOOKUP($E35,PREÇO!$C$7:$C$91,PREÇO!$E$7:$E$91) -> 2.19 | L35: =IF(SUM(F35:K35)=0,SUMIFS($L36:$L$1593,$B36:$B$1593,$B35,$A36:$A$1593,$A35),I35*K35) -> 246.8568 | N35: GERAL | O35: 122º PAV. - ÁREA TÉCNICA 07 | P35: =SUMIFS($L$7:$L$1260,$C$7:$C$1260,P$6,$B$7:$B$1260,$O35,$A$7:$A$1260,$N35) -> 7291.1146 | Q35: =SUMIFS($L$7:$L$1260,$C$7:$C$1260,Q$6,$B$7:$B$1260,$O35,$A$7:$A$1260,$N35) -> 1498.2 | R35: =SUMIFS($L$7:$L$1260,$C$7:$C$1260,R$6,$B$7:$B$1260,$O35,$A$7:$A$1260,$N35) -> 2771.22 | S35: =SUM(P35:R35) -> 11560.535
A36: =A35 -> GERAL | B36: =B35 -> SUBSOLO | C36: Cabeamento e equipamentos alarme de incêndio | D36: Cabo Unipolar Cobre | E36: =Subsolo!C45&" "&Subsolo!D45 -> Isolação em PVC (70ºC) 2.5 mm² - Vermelho | F36: =Subsolo!E45 -> 112.72 | G36: 1 | H36: 0 | I36: =(F36+H36*F36)*G36 -> 112.72 | J36: =Subsolo!F45 -> m | K36: =_xlfn.XLOOKUP($E36,PREÇO!$C$7:$C$91,PREÇO!$E$7:$E$91) -> 2.19 | L36: =IF(SUM(F36:K36)=0,SUMIFS($L37:$L$1593,$B37:$B$1593,$B36,$A37:$A$1593,$A36),I36*K36) -> 246.8568 | N36: GERAL | O36: 123º PAV. - TIPO 04D - x9 - MODELO | P36: =SUMIFS($L$7:$L$1260,$C$7:$C$1260,P$6,$B$7:$B$1260,$O36,$A$7:$A$1260,$N36) -> 42302.086 | Q36: =SUMIFS($L$7:$L$1260,$C$7:$C$1260,Q$6,$B$7:$B$1260,$O36,$A$7:$A$1260,$N36) -> 4611.6 | R36: =SUMIFS($L$7:$L$1260,$C$7:$C$1260,R$6,$B$7:$B$1260,$O36,$A$7:$A$1260,$N36) -> 6373.98 | S36: =SUM(P36:R36) -> 53287.666
A37: =A36 -> GERAL | B37: =B36 -> SUBSOLO | C37: Cabeamento e equipamentos alarme de incêndio | D37: Cabo Unipolar Cobre | E37: =Subsolo!C46&" "&Subsolo!D46 -> Isolação em PVC (70ºC) 4 mm² - Preto | F37: =Subsolo!E46 -> 489.91 | G37: 1 | H37: 0 | I37: =(F37+H37*F37)*G37 -> 489.91 | J37: =Subsolo!F46 -> m | K37: =_xlfn.XLOOKUP($E37,PREÇO!$C$7:$C$91,PREÇO!$E$7:$E$91) -> 3.89 | L37: =IF(SUM(F37:K37)=0,SUMIFS($L38:$L$1593,$B38:$B$1593,$B37,$A38:$A$1593,$A37),I37*K37) -> 1905.7499 | N37: GERAL | O37: 132º PAV. - DUPLEX INF REBAIXADOR- LANÇAMENTO | P37: =SUMIFS($L$7:$L$1260,$C$7:$C$1260,P$6,$B$7:$B$1260,$O37,$A$7:$A$1260,$N37) -> 7564.5446 | Q37: =SUMIFS($L$7:$L$1260,$C$7:$C$1260,Q$6,$B$7:$B$1260,$O37,$A$7:$A$1260,$N37) -> 1024.8 | R37: =SUMIFS($L$7:$L$1260,$C$7:$C$1260,R$6,$B$7:$B$1260,$O37,$A$7:$A$1260,$N37) -> 1416.44 | S37: =SUM(P37:R37) -> 10005.785
A38: =A37 -> GERAL | B38: =B37 -> SUBSOLO | C38: Cabeamento e equipamentos alarme de incêndio | D38: Cabo Unipolar Cobre | E38: =Subsolo!C47&" "&Subsolo!D47 -> Isolação em PVC (70ºC) 4 mm² - Vermelho | F38: =Subsolo!E47 -> 489.91 | G38: 1 | H38: 0 | I38: =(F38+H38*F38)*G38 -> 489.91 | J38: =Subsolo!F47 -> m | K38: =_xlfn.XLOOKUP($E38,PREÇO!$C$7:$C$91,PREÇO!$E$7:$E$91) -> 3.89 | L38: =IF(SUM(F38:K38)=0,SUMIFS($L39:$L$1593,$B39:$B$1593,$B38,$A39:$A$1593,$A38),I38*K38) -> 1905.7499 | N38: GERAL | O38: 133º PAV. - DUPLEX SUP - LANÇAMENTO | P38: =SUMIFS($L$7:$L$1260,$C$7:$C$1260,P$6,$B$7:$B$1260,$O38,$A$7:$A$1260,$N38) -> 9790.4764 | Q38: =SUMIFS($L$7:$L$1260,$C$7:$C$1260,Q$6,$B$7:$B$1260,$O38,$A$7:$A$1260,$N38) -> 1024.8 | R38: =SUMIFS($L$7:$L$1260,$C$7:$C$1260,R$6,$B$7:$B$1260,$O38,$A$7:$A$1260,$N38) -> 1416.44 | S38: =SUM(P38:R38) -> 12231.716
A39: =A38 -> GERAL | B39: =B38 -> SUBSOLO | C39: Cabeamento e equipamentos alarme de incêndio | D39: Cabo Unipolar Cobre | E39: =Subsolo!C48&" "&Subsolo!D48 -> Isolação em PVC (70ºC) 6 mm² - Preto | F39: =Subsolo!E48 -> 532.57 | G39: 1 | H39: 0 | I39: =(F39+H39*F39)*G39 -> 532.57 | J39: =Subsolo!F48 -> m | K39: =_xlfn.XLOOKUP($E39,PREÇO!$C$7:$C$91,PREÇO!$E$7:$E$91) -> 5.79 | L39: =IF(SUM(F39:K39)=0,SUMIFS($L40:$L$1593,$B40:$B$1593,$B39,$A40:$A$1593,$A39),I39*K39) -> 3083.5803 | N39: GERAL | O39: 136º PAV. - TRIPLEX - LANÇAMENTO | P39: =SUMIFS($L$7:$L$1260,$C$7:$C$1260,P$6,$B$7:$B$1260,$O39,$A$7:$A$1260,$N39) -> 2877.4507 | Q39: =SUMIFS($L$7:$L$1260,$C$7:$C$1260,Q$6,$B$7:$B$1260,$O39,$A$7:$A$1260,$N39) -> 512.4 | R39: =SUMIFS($L$7:$L$1260,$C$7:$C$1260,R$6,$B$7:$B$1260,$O39,$A$7:$A$1260,$N39) -> 708.22 | S39: =SUM(P39:R39) -> 4098.0707
A40: =A39 -> GERAL | B40: =B39 -> SUBSOLO | C40: Cabeamento e equipamentos alarme de incêndio | D40: Cabo Unipolar Cobre | E40: =Subsolo!C49&" "&Subsolo!D49 -> Isolação em PVC (70ºC) 6 mm² - Vermelho | F40: =Subsolo!E49 -> 532.57 | G40: 1 | H40: 0 | I40: =(F40+H40*F40)*G40 -> 532.57 | J40: =Subsolo!F49 -> m | K40: =_xlfn.XLOOKUP($E40,PREÇO!$C$7:$C$91,PREÇO!$E$7:$E$91) -> 5.79 | L40: =IF(SUM(F40:K40)=0,SUMIFS($L41:$L$1593,$B41:$B$1593,$B40,$A41:$A$1593,$A40),I40*K40) -> 3083.5803 | N40: GERAL | O40: 137º PAV. - TRIPLEX REBAIXADOR - LANÇAMENTO | P40: =SUMIFS($L$7:$L$1260,$C$7:$C$1260,P$6,$B$7:$B$1260,$O40,$A$7:$A$1260,$N40) -> 3898.8215 | Q40: =SUMIFS($L$7:$L$1260,$C$7:$C$1260,Q$6,$B$7:$B$1260,$O40,$A$7:$A$1260,$N40) -> 512.4 | R40: =SUMIFS($L$7:$L$1260,$C$7:$C$1260,R$6,$B$7:$B$1260,$O40,$A$7:$A$1260,$N40) -> 708.22 | S40: =SUM(P40:R40) -> 5119.4415
A41: =A40 -> GERAL | B41: =B40 -> SUBSOLO | C41: Cabeamento e equipamentos alarme de incêndio | D41: Eletrodutos | E41: =Subsolo!C53&" "&Subsolo!D53 -> PVC Flexível Antichama - NBR 15465 ø1" | F41: =Subsolo!E53 -> 382.07 | G41: 1 | H41: 0 | I41: =(F41+H41*F41)*G41 -> 382.07 | J41: =Subsolo!F53 -> m | K41: =_xlfn.XLOOKUP($E41,PREÇO!$C$7:$C$91,PREÇO!$E$7:$E$91) -> 2.53 | L41: =IF(SUM(F41:K41)=0,SUMIFS($L42:$L$1593,$B42:$B$1593,$B41,$A42:$A$1593,$A41),I41*K41) -> 966.6371 | N41: GERAL | O41: 138º PAV. - TRIPLEX - LANÇAMENTO | P41: =SUMIFS($L$7:$L$1260,$C$7:$C$1260,P$6,$B$7:$B$1260,$O41,$A$7:$A$1260,$N41) -> 4899.6372 | Q41: =SUMIFS($L$7:$L$1260,$C$7:$C$1260,Q$6,$B$7:$B$1260,$O41,$A$7:$A$1260,$N41) -> 512.4 | R41: =SUMIFS($L$7:$L$1260,$C$7:$C$1260,R$6,$B$7:$B$1260,$O41,$A$7:$A$1260,$N41) -> 708.22 | S41: =SUM(P41:R41) -> 6120.2572
...

Sheet Tipo 3A - x11
B2: Lista de Materiais (23º PAV. - TIPO 03A - x11 - LANÇAMENTO)
B3: Elétrica
B4: .. Alarme de Incêndio
B5: Nº | C5: Descrição | D5: Item | E5: Quantidade | F5: Unidade
B6: 1 | C6: Acionadores | D6: Acionador Manual de Alarme de Incêndio | E6: 1 | F6: pç
B7: 2 | C7: Anunciadores | D7: Anunciador Audiovisual de Alarme de Incêndio de Parede | E7: 1 | F7: pç
B8: 3 | C8: Anunciadores | D8: Anunciador Audiovisual de Alarme de Incêndio de Teto | E8: 2 | F8: pç
B9: 4 | C9: Atuadores | D9: Atuador Janela Desenfumagem | E9: 1 | F9: pç
B10: 5 | C10: Atuadores | D10: Dispositivo Eletromagnético de Porta Aberta | E10: 1 | F10: pç
B11: 6 | C11: Sensores | D11: Sensor de Fumaça | E11: 17 | F11: pç
B12: .. Caixa Octogonal
B13: Nº | C13: Descrição | D13: Item | E13: Quantidade | F13: Unidade
B14: 1 | C14: Caixas | D14: Caixa Octogonal Padrão NBR IEC 60670 | E14: 29 | F14: pç
B15: 2 | C15: Placas | D15: Placa cega para caixa octogonal Padrão NBR IEC 60670 | E15: 2 | F15: pç
B16: .. Caixas 4x2" e 4x4"
B17: Nº | C17: Descrição | D17: Item | E17: Quantidade | F17: Unidade
B18: 1 | C18: Caixas | D18: Caixa 4x2" de Embutir em PVC Padrão NBR IEC 60670 | E18: 9 | F18: pç
B19: 2 | C19: Placas | D19: Placa 4x2" cega Padrão NBR IEC 60670 | E19: 3 | F19: pç
B20: 3 | C20: Placas | D20: Placa 4x2" com furo para saída de cabos Padrão NBR IEC 60670 | E20: 6 | F20: pç
B21: 4 | C21: Suportes | D21: Suporte p/ caixa 4x2" Padrão NBR IEC 60670 | E21: 9 | F21: pç
B22: .. Eletrodutos
B23: Nº | C23: Descrição | D23: Item | E23: Quantidade | F23: Unidade
B24: 1 | C24: PVC Flexível Antichama - NBR 15465 | D24: ø1" | E24: 21 | F24: m
B25: 2 | C25: PVC Flexível Antichama - NBR 15465 | D25: ø3/4" | E25: 35.38 | F25: m
B26: .. Iluminação Emergência
B27: Nº | C27: Descrição | D27: Item | E27: Quantidade | F27: Unidade
B28: 1 | C28: Luminárias e Placas de Saída | D28: Luminária de Emergência 24V de Parede | E28: 3 | F28: pç
B29: 2 | C29: Luminárias e Placas de Saída | D29: Luminária de Emergência 24V de Teto | E29: 5 | F29: pç
B30: 3 | C30: Luminárias e Placas de Saída | D30: Placa de Saída 24V de Parede sem Direção | E30: 1 | F30: pç
B31: 4 | C31: Sensores de Presença | D31: Sensor de Presença 24V de teto | E31: 3 | F31: pç
B32: Cabo Unipolar Cobre
B33: Nº | C33: Descrição | D33: Item | E33: Quantidade | F33: Unidade
B34: 1 | C34: Isolação em PVC (70ºC) | D34: 1.5 mm² - Amarelo | E34: 73.02 | F34: m
B35: 2 | C35: Isolação em PVC (70ºC) | D35: 1.5 mm² - Preto | E35: 110.62 | F35: m
B36: 3 | C36: Isolação em PVC (70ºC) | D36: 1.5 mm² - Vermelho | E36: 110.62 | F36: m
B37: 4 | C37: Isolação em PVC (70ºC) | D37: 2.5 mm² - Amarelo | E37: 24.88 | F37: m
B38: 5 | C38: Isolação em PVC (70ºC) | D38: 2.5 mm² - Preto | E38: 12.44 | F38: m
B39: 6 | C39: Isolação em PVC (70ºC) | D39: 2.5 mm² - Vermelho | E39: 12.44 | F39: m
B40: Elétrica (Alarme)
B41: .. Eletrodutos
...

Sheet Tipo 3B - x8
B2: Lista de Materiais (34º PAV. - TIPO 03B - x8 - MODELO)
B3: Elétrica
B4: .. Alarme de Incêndio
B5: Nº | C5: Descrição | D5: Item | E5: Quantidade | F5: Unidade
B6: 1 | C6: Acionadores | D6: Acionador Manual de Alarme de Incêndio | E6: 1 | F6: pç
B7: 2 | C7: Anunciadores | D7: Anunciador Audiovisual de Alarme de Incêndio de Parede | E7: 1 | F7: pç
B8: 3 | C8: Anunciadores | D8: Anunciador Audiovisual de Alarme de Incêndio de Teto | E8: 2 | F8: pç
B9: 4 | C9: Atuadores | D9: Atuador Janela Desenfumagem | E9: 1 | F9: pç
B10: 5 | C10: Atuadores | D10: Dispositivo Eletromagnético de Porta Aberta | E10: 1 | F10: pç
B11: 6 | C11: Sensores | D11: Sensor de Fumaça | E11: 19 | F11: pç
B12: .. Caixa Octogonal
B13: Nº | C13: Descrição | D13: Item | E13: Quantidade | F13: Unidade
B14: 1 | C14: Caixas | D14: Caixa Octogonal Padrão NBR IEC 60670 | E14: 31 | F14: pç
B15: 2 | C15: Placas | D15: Placa cega para caixa octogonal Padrão NBR IEC 60670 | E15: 2 | F15: pç
B16: .. Caixas 4x2" e 4x4"
B17: Nº | C17: Descrição | D17: Item | E17: Quantidade | F17: Unidade
B18: 1 | C18: Caixas | D18: Caixa 4x2" de Embutir em PVC Padrão NBR IEC 60670 | E18: 9 | F18: pç
B19: 2 | C19: Placas | D19: Placa 4x2" cega Padrão NBR IEC 60670 | E19: 3 | F19: pç
B20: 3 | C20: Placas | D20: Placa 4x2" com furo para saída de cabos Padrão NBR IEC 60670 | E20: 6 | F20: pç
B21: 4 | C21: Suportes | D21: Suporte p/ caixa 4x2" Padrão NBR IEC 60670 | E21: 9 | F21: pç
B22: .. Eletrodutos
B23: Nº | C23: Descrição | D23: Item | E23: Quantidade | F23: Unidade
B24: 1 | C24: PVC Flexível Antichama - NBR 15465 | D24: ø1" | E24: 29.07 | F24: m
B25: 2 | C25: PVC Flexível Antichama - NBR 15465 | D25: ø3/4" | E25: 27.08 | F25: m
B26: .. Iluminação Emergência
B27: Nº | C27: Descrição | D27: Item | E27: Quantidade | F27: Unidade
B28: 1 | C28: Luminárias e Placas de Saída | D28: Luminária de Emergência 24V de Parede | E28: 3 | F28: pç
B29: 2 | C29: Luminárias e Placas de Saída | D29: Luminária de Emergência 24V de Teto | E29: 5 | F29: pç
B30: 3 | C30: Luminárias e Placas de Saída | D30: Placa de Saída 24V de Parede sem Direção | E30: 1 | F30: pç
B31: 4 | C31: Sensores de Presença | D31: Sensor de Presença 24V de teto | E31: 3 | F31: pç
B32: Cabo Unipolar Cobre
B33: Nº | C33: Descrição | D33: Item | E33: Quantidade | F33: Unidade
B34: 1 | C34: Isolação em PVC (70ºC) | D34: 1.5 mm² - Amarelo | E34: 49.82 | F34: m
B35: 2 | C35: Isolação em PVC (70ºC) | D35: 1.5 mm² - Preto | E35: 61.19 | F35: m
B36: 3 | C36: Isolação em PVC (70ºC) | D36: 1.5 mm² - Vermelho | E36: 61.19 | F36: m
B37: 4 | C37: Isolação em PVC (70ºC) | D37: 2.5 mm² - Amarelo | E37: 22.48 | F37: m
B38: 5 | C38: Isolação em PVC (70ºC) | D38: 2.5 mm² - Preto | E38: 14.84 | F38: m
B39: 6 | C39: Isolação em PVC (70ºC) | D39: 2.5 mm² - Vermelho | E39: 14.84 | F39: m
B40: Elétrica (Alarme)
B41: .. Eletrodutos
...

Sheet Técnico 3
B2: Lista de Materiais (42º PAV. - ÁREA TÉCNICA 03)
B3: Elétrica
B4: .. Alarme de Incêndio
B5: Nº | C5: Descrição | D5: Item | E5: Quantidade | F5: Unidade
B6: 1 | C6: Acionadores | D6: Acionador Manual de Alarme de Incêndio | E6: 1 | F6: pç
B7: 2 | C7: Anunciadores | D7: Anunciador Audiovisual de Alarme de Incêndio de Parede | E7: 1 | F7: pç
B8: 3 | C8: Atuadores | D8: Atuador Janela Desenfumagem | E8: 1 | F8: pç
B9: 4 | C9: Central de Alarme | D9: Central de Alarme de Incêndio | E9: 1 | F9: pç
B10: 5 | C10: Sensores | D10: Sensor de Fumaça | E10: 8 | F10: pç
B11: .. Caixa Octogonal
B12: Nº | C12: Descrição | D12: Item | E12: Quantidade | F12: Unidade
B13: 1 | C13: Caixas | D13: Caixa Octogonal Padrão NBR IEC 60670 | E13: 31 | F13: pç
B14: .. Caixas 4x2" e 4x4"
B15: Nº | C15: Descrição | D15: Item | E15: Quantidade | F15: Unidade
B16: 1 | C16: Caixas | D16: Caixa 4x2" de Embutir em PVC Padrão NBR IEC 60670 | E16: 12 | F16: pç
B17: 2 | C17: Placas | D17: Placa 4x2" cega Padrão NBR IEC 60670 | E17: 5 | F17: pç
B18: 3 | C18: Placas | D18: Placa 4x2" com furo para saída de cabos Padrão NBR IEC 60670 | E18: 7 | F18: pç
B19: 4 | C19: Suportes | D19: Suporte p/ caixa 4x2" Padrão NBR IEC 60670 | E19: 12 | F19: pç
B20: .. Cx de Passagem
B21: Nº | C21: Descrição | D21: Item | E21: Quantidade | F21: Unidade
B22: 1 | C22: Embutir | D22: Cx de passagem de embutir com dimensão de 50x50x15 cm | E22: 1 | F22: pç
B23: .. Eletrodutos
B24: Nº | C24: Descrição | D24: Item | E24: Quantidade | F24: Unidade
B25: 1 | C25: PVC Flexível Antichama - NBR 15465 | D25: ø1" | E25: 15 | F25: m
B26: 2 | C26: PVC Flexível Antichama - NBR 15465 | D26: ø3/4" | E26: 119.25 | F26: m
B27: .. Iluminação Emergência
B28: Nº | C28: Descrição | D28: Item | E28: Quantidade | F28: Unidade
B29: 1 | C29: Luminárias e Placas de Saída | D29: Luminária de Emergência 24V de Parede | E29: 5 | F29: pç
B30: 2 | C30: Luminárias e Placas de Saída | D30: Luminária de Emergência 24V de Teto | E30: 17 | F30: pç
B31: 3 | C31: Luminárias e Placas de Saída | D31: Placa de Saída 24V de Parede sem Direção | E31: 3 | F31: pç
B32: 4 | C32: Sensores de Presença | D32: Sensor de Presença 24V de teto | E32: 6 | F32: pç
B33: Cabo Unipolar Cobre
B34: Nº | C34: Descrição | D34: Item | E34: Quantidade | F34: Unidade
B35: 1 | C35: Isolação em PVC (70ºC) | D35: 1.5 mm² - Amarelo | E35: 118.06 | F35: m
B36: 2 | C36: Isolação em PVC (70ºC) | D36: 1.5 mm² - Preto | E36: 88.15 | F36: m
B37: 3 | C37: Isolação em PVC (70ºC) | D37: 1.5 mm² - Vermelho | E37: 88.15 | F37: m
B38: 4 | C38: Isolação em PVC (70ºC) | D38: 2.5 mm² - Amarelo | E38: 17.26 | F38: m
B39: 5 | C39: Isolação em PVC (70ºC) | D39: 2.5 mm² - Preto | E39: 138.72 | F39: m
B40: 6 | C40: Isolação em PVC (70ºC) | D40: 2.5 mm² - Vermelho | E40: 138.72 | F40: m
B41: Elétrica (Alarme)
...

Sheet Tipo 3C - x9
B2: Lista de Materiais (43º PAV. - TIPO 03C - x9 - MODELO)
B3: Elétrica
B4: .. Alarme de Incêndio
B5: Nº | C5: Descrição | D5: Item | E5: Quantidade | F5: Unidade
B6: 1 | C6: Acionadores | D6: Acionador Manual de Alarme de Incêndio | E6: 1 | F6: pç
B7: 2 | C7: Anunciadores | D7: Anunciador Audiovisual de Alarme de Incêndio de Parede | E7: 1 | F7: pç
B8: 3 | C8: Anunciadores | D8: Anunciador Audiovisual de Alarme de Incêndio de Teto | E8: 2 | F8: pç
B9: 4 | C9: Atuadores | D9: Atuador Janela Desenfumagem | E9: 1 | F9: pç
B10: 5 | C10: Atuadores | D10: Dispositivo Eletromagnético de Porta Aberta | E10: 1 | F10: pç
B11: 6 | C11: Sensores | D11: Sensor de Fumaça | E11: 19 | F11: pç
B12: .. Caixa Octogonal
B13: Nº | C13: Descrição | D13: Item | E13: Quantidade | F13: Unidade
B14: 1 | C14: Caixas | D14: Caixa Octogonal Padrão NBR IEC 60670 | E14: 31 | F14: pç
B15: 2 | C15: Placas | D15: Placa cega para caixa octogonal Padrão NBR IEC 60670 | E15: 2 | F15: pç
B16: .. Caixas 4x2" e 4x4"
B17: Nº | C17: Descrição | D17: Item | E17: Quantidade | F17: Unidade
B18: 1 | C18: Caixas | D18: Caixa 4x2" de Embutir em PVC Padrão NBR IEC 60670 | E18: 9 | F18: pç
B19: 2 | C19: Placas | D19: Placa 4x2" cega Padrão NBR IEC 60670 | E19: 3 | F19: pç
B20: 3 | C20: Placas | D20: Placa 4x2" com furo para saída de cabos Padrão NBR IEC 60670 | E20: 6 | F20: pç
B21: 4 | C21: Suportes | D21: Suporte p/ caixa 4x2" Padrão NBR IEC 60670 | E21: 9 | F21: pç
B22: .. Eletrodutos
B23: Nº | C23: Descrição | D23: Item | E23: Quantidade | F23: Unidade
B24: 1 | C24: PVC Flexível Antichama - NBR 15465 | D24: ø1" | E24: 24.07 | F24: m
B25: 2 | C25: PVC Flexível Antichama - NBR 15465 | D25: ø3/4" | E25: 32.12 | F25: m
B26: .. Iluminação Emergência
B27: Nº | C27: Descrição | D27: Item | E27: Quantidade | F27: Unidade
B28: 1 | C28: Luminárias e Placas de Saída | D28: Luminária de Emergência 24V de Parede | E28: 3 | F28: pç
B29: 2 | C29: Luminárias e Placas de Saída | D29: Luminária de Emergência 24V de Teto | E29: 5 | F29: pç
B30: 3 | C30: Luminárias e Placas de Saída | D30: Placa de Saída 24V de Parede sem Direção | E30: 1 | F30: pç
B31: 4 | C31: Sensores de Presença | D31: Sensor de Presença 24V de teto | E31: 3 | F31: pç
B32: Cabo Unipolar Cobre
B33: Nº | C33: Descrição | D33: Item | E33: Quantidade | F33: Unidade
B34: 1 | C34: Isolação em PVC (70ºC) | D34: 1.5 mm² - Amarelo | E34: 73.02 | F34: m
B35: 2 | C35: Isolação em PVC (70ºC) | D35: 1.5 mm² - Preto | E35: 110.53 | F35: m
B36: 3 | C36: Isolação em PVC (70ºC) | D36: 1.5 mm² - Vermelho | E36: 110.53 | F36: m
B37: 4 | C37: Isolação em PVC (70ºC) | D37: 2.5 mm² - Amarelo | E37: 24.68 | F37: m
B38: 5 | C38: Isolação em PVC (70ºC) | D38: 2.5 mm² - Preto | E38: 12.34 | F38: m
B39: 6 | C39: Isolação em PVC (70ºC) | D39: 2.5 mm² - Vermelho | E39: 12.34 | F39: m
B40: Elétrica (Alarme)
B41: .. Eletrodutos
...

Sheet Tipo 4A - x10
B2: Lista de Materiais (52º PAV. - TIPO 04A - x10 - LANÇAMENTO)
B3: Elétrica
B4: .. Alarme de Incêndio
B5: Nº | C5: Descrição | D5: Item | E5: Quantidade | F5: Unidade
B6: 1 | C6: Acionadores | D6: Acionador Manual de Alarme de Incêndio | E6: 1 | F6: pç
B7: 2 | C7: Anunciadores | D7: Anunciador Audiovisual de Alarme de Incêndio de Parede | E7: 1 | F7: pç
B8: 3 | C8: Anunciadores | D8: Anunciador Audiovisual de Alarme de Incêndio de Teto | E8: 2 | F8: pç
B9: 4 | C9: Atuadores | D9: Atuador Janela Desenfumagem | E9: 1 | F9: pç
B10: 5 | C10: Atuadores | D10: Dispositivo Eletromagnético de Porta Aberta | E10: 1 | F10: pç
B11: 6 | C11: Sensores | D11: Sensor de Fumaça | E11: 19 | F11: pç
B12: .. Caixa Octogonal
B13: Nº | C13: Descrição | D13: Item | E13: Quantidade | F13: Unidade
B14: 1 | C14: Caixas | D14: Caixa Octogonal Padrão NBR IEC 60670 | E14: 31 | F14: pç
B15: 2 | C15: Placas | D15: Placa cega para caixa octogonal Padrão NBR IEC 60670 | E15: 2 | F15: pç
B16: .. Caixas 4x2" e 4x4"
B17: Nº | C17: Descrição | D17: Item | E17: Quantidade | F17: Unidade
B18: 1 | C18: Caixas | D18: Caixa 4x2" de Embutir em PVC Padrão NBR IEC 60670 | E18: 9 | F18: pç
B19: 2 | C19: Placas | D19: Placa 4x2" cega Padrão NBR IEC 60670 | E19: 3 | F19: pç
B20: 3 | C20: Placas | D20: Placa 4x2" com furo para saída de cabos Padrão NBR IEC 60670 | E20: 6 | F20: pç
B21: 4 | C21: Suportes | D21: Suporte p/ caixa 4x2" Padrão NBR IEC 60670 | E21: 9 | F21: pç
B22: .. Cx de Passagem
B23: Nº | C23: Descrição | D23: Item | E23: Quantidade | F23: Unidade
B24: 1 | C24: Embutir | D24: Cx de passagem de embutir com dimensão de 50x50x15 cm | E24: 1 | F24: pç
B25: .. Eletrodutos
B26: Nº | C26: Descrição | D26: Item | E26: Quantidade | F26: Unidade
B27: 1 | C27: PVC Flexível Antichama - NBR 15465 | D27: ø1" | E27: 24.07 | F27: m
B28: 2 | C28: PVC Flexível Antichama - NBR 15465 | D28: ø3/4" | E28: 35.78 | F28: m
B29: .. Iluminação Emergência
B30: Nº | C30: Descrição | D30: Item | E30: Quantidade | F30: Unidade
B31: 1 | C31: Luminárias e Placas de Saída | D31: Luminária de Emergência 24V de Parede | E31: 3 | F31: pç
B32: 2 | C32: Luminárias e Placas de Saída | D32: Luminária de Emergência 24V de Teto | E32: 5 | F32: pç
B33: 3 | C33: Luminárias e Placas de Saída | D33: Placa de Saída 24V de Parede sem Direção | E33: 1 | F33: pç
B34: 4 | C34: Sensores de Presença | D34: Sensor de Presença 24V de teto | E34: 3 | F34: pç
B35: Cabo Unipolar Cobre
B36: Nº | C36: Descrição | D36: Item | E36: Quantidade | F36: Unidade
B37: 1 | C37: Isolação em PVC (70ºC) | D37: 1.5 mm² - Amarelo | E37: 63.56 | F37: m
B38: 2 | C38: Isolação em PVC (70ºC) | D38: 1.5 mm² - Preto | E38: 59.55 | F38: m
B39: 3 | C39: Isolação em PVC (70ºC) | D39: 1.5 mm² - Vermelho | E39: 59.55 | F39: m
B40: 4 | C40: Isolação em PVC (70ºC) | D40: 2.5 mm² - Amarelo | E40: 15.28 | F40: m
B41: 5 | C41: Isolação em PVC (70ºC) | D41: 2.5 mm² - Preto | E41: 52.78 | F41: m
...

Sheet Técnico 4
B2: Lista de Materiais (62º PAV. - ÁREA TÉCNICA 04)
B3: Elétrica
B4: .. Alarme de Incêndio
B5: Nº | C5: Descrição | D5: Item | E5: Quantidade | F5: Unidade
B6: 1 | C6: Acionadores | D6: Acionador Manual de Alarme de Incêndio | E6: 1 | F6: pç
B7: 2 | C7: Anunciadores | D7: Anunciador Audiovisual de Alarme de Incêndio de Parede | E7: 1 | F7: pç
B8: 3 | C8: Atuadores | D8: Atuador Janela Desenfumagem | E8: 1 | F8: pç
B9: 4 | C9: Central de Alarme | D9: Central de Alarme de Incêndio | E9: 1 | F9: pç
B10: 5 | C10: Sensores | D10: Sensor de Fumaça | E10: 11 | F10: pç
B11: .. Caixa Octogonal
B12: Nº | C12: Descrição | D12: Item | E12: Quantidade | F12: Unidade
B13: 1 | C13: Caixas | D13: Caixa Octogonal Padrão NBR IEC 60670 | E13: 45 | F13: pç
B14: .. Caixas 4x2" e 4x4"
B15: Nº | C15: Descrição | D15: Item | E15: Quantidade | F15: Unidade
B16: 1 | C16: Caixas | D16: Caixa 4x2" de Embutir em PVC Padrão NBR IEC 60670 | E16: 13 | F16: pç
B17: 2 | C17: Placas | D17: Placa 4x2" cega Padrão NBR IEC 60670 | E17: 4 | F17: pç
B18: 3 | C18: Placas | D18: Placa 4x2" com furo para saída de cabos Padrão NBR IEC 60670 | E18: 9 | F18: pç
B19: 4 | C19: Suportes | D19: Suporte p/ caixa 4x2" Padrão NBR IEC 60670 | E19: 13 | F19: pç
B20: .. Cx de Passagem
B21: Nº | C21: Descrição | D21: Item | E21: Quantidade | F21: Unidade
B22: 1 | C22: Embutir | D22: Cx de passagem de embutir com dimensão de 50x50x15 cm | E22: 1 | F22: pç
B23: .. Eletrodutos
B24: Nº | C24: Descrição | D24: Item | E24: Quantidade | F24: Unidade
B25: 1 | C25: PVC Flexível Antichama - NBR 15465 | D25: ø1" | E25: 27.2 | F25: m
B26: 2 | C26: PVC Flexível Antichama - NBR 15465 | D26: ø3/4" | E26: 132.75 | F26: m
B27: .. Iluminação Emergência
B28: Nº | C28: Descrição | D28: Item | E28: Quantidade | F28: Unidade
B29: 1 | C29: Luminárias e Placas de Saída | D29: Luminária de Emergência 24V de Parede | E29: 4 | F29: pç
B30: 2 | C30: Luminárias e Placas de Saída | D30: Luminária de Emergência 24V de Teto | E30: 24 | F30: pç
B31: 3 | C31: Luminárias e Placas de Saída | D31: Placa de Saída 24V de Parede sem Direção | E31: 5 | F31: pç
B32: 4 | C32: Sensores de Presença | D32: Sensor de Presença 24V de teto | E32: 10 | F32: pç
B33: Cabo Unipolar Cobre
B34: Nº | C34: Descrição | D34: Item | E34: Quantidade | F34: Unidade
B35: 1 | C35: Isolação em PVC (70ºC) | D35: 1.5 mm² - Amarelo | E35: 236.52 | F35: m
B36: 2 | C36: Isolação em PVC (70ºC) | D36: 1.5 mm² - Preto | E36: 242.44 | F36: m
B37: 3 | C37: Isolação em PVC (70ºC) | D37: 1.5 mm² - Vermelho | E37: 242.44 | F37: m
B38: 4 | C38: Isolação em PVC (70ºC) | D38: 2.5 mm² - Amarelo | E38: 17.88 | F38: m
B39: 5 | C39: Isolação em PVC (70ºC) | D39: 2.5 mm² - Preto | E39: 123.88 | F39: m
B40: 6 | C40: Isolação em PVC (70ºC) | D40: 2.5 mm² - Vermelho | E40: 123.88 | F40: m
B41: Elétrica (Alarme)
...

Sheet Lazer 3
B2: Lista de Materiais (63º PAV. - LAZER 03)
B3: Elétrica
B4: .. Alarme de Incêndio
B5: Nº | C5: Descrição | D5: Item | E5: Quantidade | F5: Unidade
B6: 1 | C6: Acionadores | D6: Acionador Manual de Alarme de Incêndio | E6: 1 | F6: pç
B7: 2 | C7: Anunciadores | D7: Anunciador Audiovisual de Alarme de Incêndio de Parede | E7: 1 | F7: pç
B8: 3 | C8: Atuadores | D8: Atuador Janela Desenfumagem | E8: 1 | F8: pç
B9: 4 | C9: Atuadores | D9: Dispositivo Eletromagnético de Porta Aberta | E9: 1 | F9: pç
B10: 5 | C10: Sensores | D10: Sensor de Fumaça | E10: 3 | F10: pç
B11: .. Caixa Octogonal
B12: Nº | C12: Descrição | D12: Item | E12: Quantidade | F12: Unidade
B13: 1 | C13: Caixas | D13: Caixa Octogonal Padrão NBR IEC 60670 | E13: 14 | F13: pç
B14: 2 | C14: Placas | D14: Placa cega para caixa octogonal Padrão NBR IEC 60670 | E14: 3 | F14: pç
B15: .. Caixas 4x2" e 4x4"
B16: Nº | C16: Descrição | D16: Item | E16: Quantidade | F16: Unidade
B17: 1 | C17: Caixas | D17: Caixa 4x2" de Embutir em PVC Padrão NBR IEC 60670 | E17: 24 | F17: pç
B18: 2 | C18: Placas | D18: Placa 4x2" cega Padrão NBR IEC 60670 | E18: 15 | F18: pç
B19: 3 | C19: Placas | D19: Placa 4x2" com furo para saída de cabos Padrão NBR IEC 60670 | E19: 9 | F19: pç
B20: 4 | C20: Suportes | D20: Suporte p/ caixa 4x2" Padrão NBR IEC 60670 | E20: 24 | F20: pç
B21: .. Eletrodutos
B22: Nº | C22: Descrição | D22: Item | E22: Quantidade | F22: Unidade
B23: 1 | C23: PVC Flexível Antichama - NBR 15465 | D23: ø1" | E23: 13.77 | F23: m
B24: 2 | C24: PVC Flexível Antichama - NBR 15465 | D24: ø3/4" | E24: 130.7 | F24: m
B25: .. Iluminação Emergência
B26: Nº | C26: Descrição | D26: Item | E26: Quantidade | F26: Unidade
B27: 1 | C27: Luminárias e Placas de Saída | D27: Luminária de Emergência 24V de Parede | E27: 15 | F27: pç
B28: 2 | C28: Luminárias e Placas de Saída | D28: Luminária de Emergência 24V de Teto | E28: 5 | F28: pç
B29: 3 | C29: Luminárias e Placas de Saída | D29: Placa de Saída 24V de Parede com Direção | E29: 2 | F29: pç
B30: 4 | C30: Luminárias e Placas de Saída | D30: Placa de Saída 24V de Parede sem Direção | E30: 3 | F30: pç
B31: 5 | C31: Sensores de Presença | D31: Sensor de Presença 24V de teto | E31: 3 | F31: pç
B32: Cabo Unipolar Cobre
B33: Nº | C33: Descrição | D33: Item | E33: Quantidade | F33: Unidade
B34: 1 | C34: Isolação em PVC (70ºC) | D34: 1.5 mm² - Amarelo | E34: 82.38 | F34: m
B35: 2 | C35: Isolação em PVC (70ºC) | D35: 1.5 mm² - Preto | E35: 66.5 | F35: m
B36: 3 | C36: Isolação em PVC (70ºC) | D36: 1.5 mm² - Vermelho | E36: 66.5 | F36: m
B37: 4 | C37: Isolação em PVC (70ºC) | D37: 2.5 mm² - Amarelo | E37: 39.02 | F37: m
B38: 5 | C38: Isolação em PVC (70ºC) | D38: 2.5 mm² - Preto | E38: 184.86 | F38: m
B39: 6 | C39: Isolação em PVC (70ºC) | D39: 2.5 mm² - Vermelho | E39: 184.86 | F39: m
B40: Elétrica (Alarme)
B41: .. Eletrodutos
...

Sheet Lazer 4
B2: Lista de Materiais (64º PAV. - LAZER 04)
B3: Elétrica
B4: .. Alarme de Incêndio
B5: Nº | C5: Descrição | D5: Item | E5: Quantidade | F5: Unidade
B6: 1 | C6: Acionadores | D6: Acionador Manual de Alarme de Incêndio | E6: 1 | F6: pç
B7: 2 | C7: Anunciadores | D7: Anunciador Audiovisual de Alarme de Incêndio de Parede | E7: 1 | F7: pç
B8: 3 | C8: Atuadores | D8: Atuador Janela Desenfumagem | E8: 1 | F8: pç
B9: 4 | C9: Atuadores | D9: Dispositivo Eletromagnético de Porta Aberta | E9: 1 | F9: pç
B10: 5 | C10: Sensores | D10: Sensor de Fumaça | E10: 2 | F10: pç
B11: .. Caixa Octogonal
B12: Nº | C12: Descrição | D12: Item | E12: Quantidade | F12: Unidade
B13: 1 | C13: Caixas | D13: Caixa Octogonal Padrão NBR IEC 60670 | E13: 15 | F13: pç
B14: 2 | C14: Placas | D14: Placa cega para caixa octogonal Padrão NBR IEC 60670 | E14: 5 | F14: pç
B15: .. Caixas 4x2" e 4x4"
B16: Nº | C16: Descrição | D16: Item | E16: Quantidade | F16: Unidade
B17: 1 | C17: Caixas | D17: Caixa 4x2" de Embutir em PVC Padrão NBR IEC 60670 | E17: 21 | F17: pç
B18: 2 | C18: Placas | D18: Placa 4x2" cega Padrão NBR IEC 60670 | E18: 14 | F18: pç
B19: 3 | C19: Placas | D19: Placa 4x2" com furo para saída de cabos Padrão NBR IEC 60670 | E19: 7 | F19: pç
B20: 4 | C20: Suportes | D20: Suporte p/ caixa 4x2" Padrão NBR IEC 60670 | E20: 21 | F20: pç
B21: .. Eletrodutos
B22: Nº | C22: Descrição | D22: Item | E22: Quantidade | F22: Unidade
B23: 1 | C23: PVC Flexível Antichama - NBR 15465 | D23: ø1" | E23: 13.77 | F23: m
B24: 2 | C24: PVC Flexível Antichama - NBR 15465 | D24: ø3/4" | E24: 127.92 | F24: m
B25: .. Iluminação Emergência
B26: Nº | C26: Descrição | D26: Item | E26: Quantidade | F26: Unidade
B27: 1 | C27: Luminárias e Placas de Saída | D27: Luminária de Emergência 24V de Parede | E27: 14 | F27: pç
B28: 2 | C28: Luminárias e Placas de Saída | D28: Luminária de Emergência 24V de Teto | E28: 5 | F28: pç
B29: 3 | C29: Luminárias e Placas de Saída | D29: Placa de Saída 24V de Parede sem Direção | E29: 3 | F29: pç
B30: 4 | C30: Sensores de Presença | D30: Sensor de Presença 24V de teto | E30: 3 | F30: pç
B31: Cabo Unipolar Cobre
B32: Nº | C32: Descrição | D32: Item | E32: Quantidade | F32: Unidade
B33: 1 | C33: Isolação em PVC (70ºC) | D33: 1.5 mm² - Amarelo | E33: 63.58 | F33: m
B34: 2 | C34: Isolação em PVC (70ºC) | D34: 1.5 mm² - Preto | E34: 52.4 | F34: m
B35: 3 | C35: Isolação em PVC (70ºC) | D35: 1.5 mm² - Vermelho | E35: 52.4 | F35: m
B36: 4 | C36: Isolação em PVC (70ºC) | D36: 2.5 mm² - Amarelo | E36: 29.42 | F36: m
B37: 5 | C37: Isolação em PVC (70ºC) | D37: 2.5 mm² - Preto | E37: 148.41 | F37: m
B38: 6 | C38: Isolação em PVC (70ºC) | D38: 2.5 mm² - Vermelho | E38: 148.41 | F38: m
B39: Elétrica (Alarme)
B40: .. Eletrodutos
B41: Nº | C41: Descrição | D41: Item | E41: Quantidade | F41: Unidade
...

Sheet Tipo 4B - x36
B2: Lista de Materiais (65º PAV. - TIPO 04B - x36 - MODELO)
B3: Elétrica
B4: .. Alarme de Incêndio
B5: Nº | C5: Descrição | D5: Item | E5: Quantidade | F5: Unidade
B6: 1 | C6: Acionadores | D6: Acionador Manual de Alarme de Incêndio | E6: 1 | F6: pç
B7: 2 | C7: Anunciadores | D7: Anunciador Audiovisual de Alarme de Incêndio de Parede | E7: 1 | F7: pç
B8: 3 | C8: Anunciadores | D8: Anunciador Audiovisual de Alarme de Incêndio de Teto | E8: 2 | F8: pç
B9: 4 | C9: Atuadores | D9: Atuador Janela Desenfumagem | E9: 1 | F9: pç
B10: 5 | C10: Atuadores | D10: Dispositivo Eletromagnético de Porta Aberta | E10: 1 | F10: pç
B11: 6 | C11: Sensores | D11: Sensor de Fumaça | E11: 19 | F11: pç
B12: .. Caixa Octogonal
B13: Nº | C13: Descrição | D13: Item | E13: Quantidade | F13: Unidade
B14: 1 | C14: Caixas | D14: Caixa Octogonal Padrão NBR IEC 60670 | E14: 31 | F14: pç
B15: 2 | C15: Placas | D15: Placa cega para caixa octogonal Padrão NBR IEC 60670 | E15: 2 | F15: pç
B16: .. Caixas 4x2" e 4x4"
B17: Nº | C17: Descrição | D17: Item | E17: Quantidade | F17: Unidade
B18: 1 | C18: Caixas | D18: Caixa 4x2" de Embutir em PVC Padrão NBR IEC 60670 | E18: 9 | F18: pç
