Workbook
Name \0: #REF!
Name \1: #REF!
Name \a: #REF!
Name \b: #REF!
Name \c: #REF!
Name \d: #REF!
Name \e: #REF!
Name \i: #REF!
Name \J: #REF!
Name \k: #REF!
Name \l: #N/A
Name \m: #REF!
Name \o: #REF!
Name \p: #REF!
Name \r: #REF!
Name \T: #REF!
Name \z: #REF!
Name _: #REF!
Name _\0: #REF!
Name _\1: #REF!
Name _\a: #REF!
Name _\b: #REF!
Name _\c: #REF!
Name _\d: #REF!
Name _\e: #REF!
Name _\i: #REF!
Name _\J: #REF!
Name _\k: #REF!
Name _\l: #N/A
Name _\m: #REF!
Name _\o: #REF!
Name _\p: #REF!
Name _\r: #REF!
Name _\T: #REF!
Name _\z: #REF!
Name __: #REF!
Name ______ACR10: #REF!
Name ______ACR15: #REF!
Name ______acr20: #REF!
Name ______acr5: #REF!
Name ______ARQ1: #REF!
Name ______QT100: #REF!
Name ______QT2: #REF!
Name ______QT3: #REF!
Name ______QT4: #REF!
Name ______QT50: #REF!
Name ______QT75: #REF!
Name _____ACR10: #REF!
Name _____ACR15: #REF!
Name _____acr20: #REF!
Name _____acr5: #REF!
Name _____ARQ1: #REF!
Name _____key2: #REF!
Name _____QT100: #REF!
Name _____QT2: #REF!
Name _____QT3: #REF!
Name _____QT4: #REF!
Name _____QT50: #REF!
Name _____QT75: #REF!
Name ____key2: #REF!

Sheet CAPA
A1: DADOS DO EMPREENDIMENTO
B2: Projeto: | C2: Electra Towers | E2: ENDEREÇO DA OBRA: | F2: Rua 254, 215, Meia Praia, Itapema/SC
B3: Empresa: | C3: Thozen Empreendimentos | E3: Cidade/ES: | F3: Itapema, SC
B4: Revisão: | C4: R00 | E4: CNPJ: | F4: 43.339.082/0001-06
B6: Pazo de Obra: | C6: 48 | E6: Nº Unid. Residenciais: | F6: 192 | I6: Imagens
B8: Área do Terreno: | C8: 2095.43 | E8: Nº Unid. Comerciais: | F8: 7
B10: Área Construída: | C10: 37893.89 | E10: Nº Pavimentos: | F10: 57
B12: Área Privativa: | C12: 22778.64 | E12: Total de Dormitórios: | F12: 576
B14: Área de Lazer: | C14: 1736.27 | E14: Nº Subsolos: | F14: 0
B16: Área Comercial: | C16: 500.04 | E16: Nº Vagas: | F16: 399
B18: Torre | C18: Pavimento | D18: Área | E18: Área Privativa | F18: Perímetro | G18: Pé direito
B19: Embasamento | C19: Térreo | D19: 1565.91 | E19: 0 | G19: 4.3
B20: Embasamento | C20: Garagem 01 | D20: 1736.27 | E20: 0
B21: Embasamento | C21: Garagem 02 | D21: 1736.27 | E21: 0
B22: Embasamento | C22: Garagem 03 | D22: 1736.27 | E22: 0
B23: Embasamento | C23: Garagem 04 | D23: 1736.27 | E23: 0
B24: Embasamento | C24: Garagem 05 | D24: 1736.27 | E24: 0
B25: Embasamento | C25: Pavimento diferenciado — Lazer | D25: 1736.27 | E25: 0 | G25: 3.6
B26: Torre A | C26: Pavimento tipo — Torre A (×24) | D26: 12720.48 | E26: 11382.72 | G26: 3.24
B27: Torre B | C27: Pavimento tipo — Torre B (×24) | D27: 12892.32 | E27: 11397.12 | G27: 3.24
B28: Cobertura | C28: Casa de Máquinas | D28: 176.26 | E28: 0
B29: Cobertura | C29: Reservatórios | D29: 121.3 | E29: 0
B37: Torre | C37: Pavimento | D37: Descrição | E37: Área | I37: ETAPA
B38: Áreas Comuns | C38: =_xlfn.XLOOKUP(D38,MOBILIÁRIO!C:C,MOBILIÁRIO!B:B) -> TÉRREO | D38: {=_xlfn.UNIQUE(_xlfn._xlws.FILTER(MOBILIÁRIO!C7:C316,MOBILIÁRIO!C7:C316<>""))} -> Hall Externo | E38: =_xlfn.XLOOKUP(D38,MOBILIÁRIO!C:C,MOBILIÁRIO!F:F) -> 12.33 | I38: GERENCIAMENTO TÉCNICO E ADMINISTRATIVO
B39: Áreas Comuns | C39: =_xlfn.XLOOKUP(D39,MOBILIÁRIO!C:C,MOBILIÁRIO!B:B) -> TÉRREO | D39: Hall Térreo | E39: =_xlfn.XLOOKUP(D39,MOBILIÁRIO!C:C,MOBILIÁRIO!F:F) -> 35.27 | I39: MOVIMENTAÇÃO DE TERRA
B40: Áreas Comuns | C40: =_xlfn.XLOOKUP(D40,MOBILIÁRIO!C:C,MOBILIÁRIO!B:B) -> TÉRREO | D40: Guarita | E40: =_xlfn.XLOOKUP(D40,MOBILIÁRIO!C:C,MOBILIÁRIO!F:F) -> 4.72 | I40: CONTENÇÃO
B41: Áreas Comuns | C41: =_xlfn.XLOOKUP(D41,MOBILIÁRIO!C:C,MOBILIÁRIO!B:B) -> TÉRREO | D41: Lavapés | E41: =_xlfn.XLOOKUP(D41,MOBILIÁRIO!C:C,MOBILIÁRIO!F:F) -> 1 | I41: INFRAESTRUTURA
B42: Áreas Comuns | C42: =_xlfn.XLOOKUP(D42,MOBILIÁRIO!C:C,MOBILIÁRIO!B:B) -> TÉRREO | D42: Lavabo Pne - Térreo | E42: =_xlfn.XLOOKUP(D42,MOBILIÁRIO!C:C,MOBILIÁRIO!F:F) -> 3.77 | I42: SUPRAESTRUTURA
B43: Áreas Comuns | C43: =_xlfn.XLOOKUP(D43,MOBILIÁRIO!C:C,MOBILIÁRIO!B:B) -> TÉRREO | D43: Bicicletário/Box | E43: =_xlfn.XLOOKUP(D43,MOBILIÁRIO!C:C,MOBILIÁRIO!F:F) -> 87.33 | I43: ALVENARIAS E VEDAÇÕES
B44: Áreas Comuns | C44: =_xlfn.XLOOKUP(D44,MOBILIÁRIO!C:C,MOBILIÁRIO!B:B) -> TÉRREO | D44: Antecâmara - Térreo | E44: =_xlfn.XLOOKUP(D44,MOBILIÁRIO!C:C,MOBILIÁRIO!F:F) -> 8.07 | I44: SISTEMAS E INSTALAÇÕES ELÉTRICAS
B45: Áreas Comuns | C45: =_xlfn.XLOOKUP(D45,MOBILIÁRIO!C:C,MOBILIÁRIO!B:B) -> 2º AO 5º PAVIMENTO - GARAGENS (X5) | D45: Antecâmara - Garagens (x5) | E45: =_xlfn.XLOOKUP(D45,MOBILIÁRIO!C:C,MOBILIÁRIO!F:F) -> 33.6 | I45: SISTEMAS E INSTALAÇÕES HIDROSSANITÁRIAS E DRENAGEM
B46: Áreas Comuns | C46: =_xlfn.XLOOKUP(D46,MOBILIÁRIO!C:C,MOBILIÁRIO!B:B) -> 4º PAVIMENTO - LAZER/GARAGENS | D46: Sala de massagem | E46: =_xlfn.XLOOKUP(D46,MOBILIÁRIO!C:C,MOBILIÁRIO!F:F) -> 7.47 | I46: INSTALAÇÕES PREVENTIVAS
B47: Áreas Comuns | C47: =_xlfn.XLOOKUP(D47,MOBILIÁRIO!C:C,MOBILIÁRIO!B:B) -> 4º PAVIMENTO - LAZER/GARAGENS | D47: Banheiro - Lazer/Garagem | E47: =_xlfn.XLOOKUP(D47,MOBILIÁRIO!C:C,MOBILIÁRIO!F:F) -> 3.91 | I47: INSTALAÇÕES DE GÁS
B48: Áreas Comuns | C48: =_xlfn.XLOOKUP(D48,MOBILIÁRIO!C:C,MOBILIÁRIO!B:B) -> 4º PAVIMENTO - LAZER/GARAGENS | D48: Lavabo - Lazer/Garagem | E48: =_xlfn.XLOOKUP(D48,MOBILIÁRIO!C:C,MOBILIÁRIO!F:F) -> 2.61 | I48: EQUIPAMENTOS E SISTEMAS ESPECIAIS
B49: Áreas Comuns | C49: =_xlfn.XLOOKUP(D49,MOBILIÁRIO!C:C,MOBILIÁRIO!B:B) -> 4º PAVIMENTO - LAZER/GARAGENS | D49: Lavabo Pne - Lazer/Garagem | E49: =_xlfn.XLOOKUP(D49,MOBILIÁRIO!C:C,MOBILIÁRIO!F:F) -> 4.33 | I49: CLIMATIZAÇÃO, EXAUSTÃO MECÂNICA
B50: Áreas Comuns | C50: =_xlfn.XLOOKUP(D50,MOBILIÁRIO!C:C,MOBILIÁRIO!B:B) -> 4º PAVIMENTO - LAZER/GARAGENS | D50: Circulação - Lazer/garagem | E50: =_xlfn.XLOOKUP(D50,MOBILIÁRIO!C:C,MOBILIÁRIO!F:F) -> 30.85 | I50: INSTALAÇÕES ESPECIAIS
... B63: Áreas Comuns | C63: =_xlfn.XLOOKUP(D63,MOBILIÁRIO!C:C,MOBILIÁRIO!B:B) -> 5º PAVIMENTO - LAZER | D63: Laje Verde | E63: =_xlfn.XLOOKUP(D63,MOBILIÁRIO!C:C,MOBILIÁRIO!F:F) -> 269.95 | I63: CUB/SC
B64: Áreas Comuns | C64: =_xlfn.XLOOKUP(D64,MOBILIÁRIO!C:C,MOBILIÁRIO!B:B) -> 5º PAVIMENTO - LAZER | D64: Brinquedoteca | E64: =_xlfn.XLOOKUP(D64,MOBILIÁRIO!C:C,MOBILIÁRIO!F:F) -> 16.32
B65: Áreas Comuns | C65: =_xlfn.XLOOKUP(D65,MOBILIÁRIO!C:C,MOBILIÁRIO!B:B) -> 5º PAVIMENTO - LAZER | D65: Game Center | E65: =_xlfn.XLOOKUP(D65,MOBILIÁRIO!C:C,MOBILIÁRIO!F:F) -> 13.09 | I65: DESCRIÇÃO
B66: Áreas Comuns | C66: =_xlfn.XLOOKUP(D66,MOBILIÁRIO!C:C,MOBILIÁRIO!B:B) -> 5º PAVIMENTO - LAZER | D66: Sala de Festas | E66: =_xlfn.XLOOKUP(D66,MOBILIÁRIO!C:C,MOBILIÁRIO!F:F) -> 93.46 | I66: VALOR POR ÁREA PRIVATIVA (R$/m²)
...

Sheet EAP
A1: EAP DE ORÇAMENTO
A3: Contrutora - Obra
A5: UNIDADE CONSTRUTIVA | B5: 1 | C5: GERENCIAMENTO TÉCNICO E ADMINISTRATIVO
A6: CÉLULA CONSTRUTIVA | B6: 1 | C6: SERVIÇOS TÉCNICOS
A7: ETAPA | B7: 1.001 | C7: ESTUDOS, PROJETOS E CONSULTORIAS
A8: Subetapa | B8: 01.001.001 | C8: Estudos
A9: Subetapa | B9: 01.001.002 | C9: Projetos
A10: Subetapa | B10: 01.001.003 | C10: Consultorias
A11: Subetapa | B11: 01.001.004 | C11: Ensaios
A12: ETAPA | B12: 1.002 | C12: TAXAS E DOCUMENTOS
A13: Subetapa | B13: 01.002.001 | C13: Licenciamentos, Taxas, Impostos, Aprovações e Seguros
A14: Subetapa | B14: 01.002.002 | C14: Documentos
A15: CÉLULA CONSTRUTIVA | B15: 2 | C15: SERVIÇOS INICIAIS
A16: ETAPA | B16: 2.001 | C16: SEGURANÇA, MEIO AMBIENTE, SAÚDE
A17: Subetapa | B17: 02.001.001 | C17: Segurança do trabalho
A18: Subetapa | B18: 02.001.002 | C18: Equipamentos de proteção
A19: Subetapa | B19: 02.001.003 | C19: Meio ambiente
A20: Subetapa | B20: 02.001.004 | C20: Saúde ocupacional
A21: ETAPA | B21: 2.002 | C21: ADMINISTRAÇÃO E CANTEIRO DE OBRA
A22: Subetapa | B22: 02.002.001 | C22: Equipe de Gestão e Apoio
A23: Subetapa | B23: 02.002.002 | C23: Operação inicial de canteiro
A24: Subetapa | B24: 02.002.003 | C24: Despesas de consumo e manutenção
A25: Subetapa | B25: 02.002.004 | C25: Instalações provisórias
A26: Subetapa | B26: 02.002.005 | C26: Ligações Provisórias
A27: ETAPA | B27: 2.003 | C27: SERVIÇOS PRELIMINARES
... A29: Subetapa | B29: 02.003.002 | C29: Limpeza de terreno
A30: CÉLULA CONSTRUTIVA | B30: 3 | C30: EQUIPAMENTOS
A31: ETAPA | B31: 3.001 | C31: EQUIPAMENTOS
A32: Subetapa | B32: 03.001.001 | C32: Equipamentos de Carga e Transporte
A33: Subetapa | B33: 03.001.002 | C33: Equipamentos de obra
A34: Subetapa | B34: 03.001.003 | C34: Balancins e Andaimes
A35: UNIDADE CONSTRUTIVA | B35: 2 | C35: GERENCIAMENTO EXECUTIVO
A36: CÉLULA CONSTRUTIVA | B36: 1 | C36: INFRAESTRUTURA
A37: ETAPA | B37: 1.001 | C37: MOVIMENTAÇÃO DE TERRA
A38: Subetapa | B38: 01.001.001 | C38: Corte e aterro
A39: Subetapa | B39: 01.001.002 | C39: Rebaixamento de lençol
A40: Subetapa | B40: 01.001.003 | C40: Escavação e Reaterro de Valas
A41: Subetapa | B41: 01.001.004 | C41: Lastro de estrutura de concreto
A42: Subetapa | B42: 01.001.005 | C42: Movimentação de bota - fora
A43: ETAPA | B43: 1.002 | C43: FUNDAÇÃO PROFUNDA
...

Sheet CLIMATIZAÇÃO
C1: Projeto | D1: Elizabeth II
C2: Empresa | D2: Gessele
C3: Origem | D3: GES-CLI-000-QTD-R00
C4: Revisão | D4: R00 - Raquel 05/01/2025
A5: Climatização
A6: TORRE | B6: PAVIMENTO | C6: GRUPO/EAP | D6: SUBGRUPO | E6: Descrição | F6: Quantidade | G6: Repetição | H6: Perda | I6: Qte com perda | J6: Unidade | K6: Custo unitário | L6: Custo Total | N6: Torre | O6: EAP | P6: LOJAS | Q6: LAZER | R6: TORRE | S6: TOTAL
A7: TORRE | B7: LOJAS | L7: =IF(SUM(F7:K7)=0,SUMIFS($L8:$L$403,$B8:$B$403,$B7,$A8:$A$403,$A7),I7*K7) -> 37326.477 | N7: TORRE | O7: {=_xlfn.UNIQUE(_xlfn._xlws.FILTER($D$7:$D$1048576,$A$7:$A$1048576=N7))} -> 0 | P7: =SUMIFS($L$7:$L$70,$D$7:$D$70,$O7,$B$7:$B$70,P$6,$A$7:$A$70,$N7) -> 0 | Q7: =SUMIFS($L$7:$L$70,$D$7:$D$70,$O7,$B$7:$B$70,Q$6,$A$7:$A$70,$N7) -> 0 | R7: =SUMIFS($L$7:$L$70,$D$7:$D$70,$O7,$B$7:$B$70,R$6,$A$7:$A$70,$N7) -> 0 | S7: =SUM(O7:R7) -> 0
A8: TORRE | B8: =B7 -> LOJAS | C8: CLIMATIZAÇÃO | D8: EQUIPAMENTOS | E8: CAIXA DE DRENO - CPP 005 POLAR | F8: 5 | G8: 1 | H8: 0 | I8: =(F8+H8*F8)*G8 -> 5 | J8: pç | K8: 28 | L8: =IF(SUM(F8:K8)=0,SUMIFS($L9:$L$403,$B9:$B$403,$B8,$A9:$A$403,$A8),I8*K8) -> 140 | N8: TORRE | O8: EQUIPAMENTOS | P8: =SUMIFS($L$7:$L$70,$D$7:$D$70,$O8,$B$7:$B$70,P$6,$A$7:$A$70,$N8) -> 140 | Q8: =SUMIFS($L$7:$L$70,$D$7:$D$70,$O8,$B$7:$B$70,Q$6,$A$7:$A$70,$N8) -> 87794 | R8: =SUMIFS($L$7:$L$70,$D$7:$D$70,$O8,$B$7:$B$70,R$6,$A$7:$A$70,$N8) -> 31240 | S8: =SUM(O8:R8) -> 119174
A9: TORRE | B9: =B8 -> LOJAS | C9: CLIMATIZAÇÃO | D9: EQUIPAMENTOS | E9: CONDENSADORA - MINI VRF 52.900 BTU'S (6HP) CRUN060GSS5 LG 4.300 W (220V F+N+T) | F9: 3 | G9: 1 | H9: 0 | I9: =(F9+H9*F9)*G9 -> 3 | J9: pç | L9: =IF(SUM(F9:K9)=0,SUMIFS($L10:$L$403,$B10:$B$403,$B9,$A10:$A$403,$A9),I9*K9) -> 0 | N9: TORRE | O9: EQUIPAMENTOS - EXAUSTÃO | P9: =SUMIFS($L$7:$L$70,$D$7:$D$70,$O9,$B$7:$B$70,P$6,$A$7:$A$70,$N9) -> 24686.78 | Q9: =SUMIFS($L$7:$L$70,$D$7:$D$70,$O9,$B$7:$B$70,Q$6,$A$7:$A$70,$N9) -> 1687.74 | R9: =SUMIFS($L$7:$L$70,$D$7:$D$70,$O9,$B$7:$B$70,R$6,$A$7:$A$70,$N9) -> 3977.68 | S9: =SUM(O9:R9) -> 30352.2
A10: =A9 -> TORRE | B10: =B9 -> LOJAS | C10: CLIMATIZAÇÃO | D10: EQUIPAMENTOS | E10: CONDENSADORA - MINI VRF 76.400 BTU'S (8HP) CRUN080BSS0 LG 6.000 W (220V 3F+N+T) | F10: 2 | G10: 1 | H10: 0 | I10: =(F10+H10*F10)*G10 -> 2 | J10: pç | L10: =IF(SUM(F10:K10)=0,SUMIFS($L11:$L$403,$B11:$B$403,$B10,$A11:$A$403,$A10),I10*K10) -> 0 | N10: TORRE | O10: INFRAESTRUTURA PARA INSTALAÇÃO | P10: =SUMIFS($L$7:$L$70,$D$7:$D$70,$O10,$B$7:$B$70,P$6,$A$7:$A$70,$N10) -> 12499.697 | Q10: =SUMIFS($L$7:$L$70,$D$7:$D$70,$O10,$B$7:$B$70,Q$6,$A$7:$A$70,$N10) -> 11247.357 | R10: =SUMIFS($L$7:$L$70,$D$7:$D$70,$O10,$B$7:$B$70,R$6,$A$7:$A$70,$N10) -> 225031.98 | S10: =SUM(O10:R10) -> 248779.03
A11: =A10 -> TORRE | B11: =B10 -> LOJAS | C11: CLIMATIZAÇÃO | D11: EQUIPAMENTOS | E11: CONDENSADORA - MINI VRF 114.700 BTU'S (12HP) CRUN120BSS0 LG 9.950 W (220V 3F+N+T) | F11: 1 | G11: 1 | H11: 0 | I11: =(F11+H11*F11)*G11 -> 1 | J11: pç | L11: =IF(SUM(F11:K11)=0,SUMIFS($L12:$L$403,$B12:$B$403,$B11,$A12:$A$403,$A11),I11*K11) -> 0 | N11: TORRE | O11: EQUIPAMENTOS - LIMPEZA | P11: =SUMIFS($L$7:$L$70,$D$7:$D$70,$O11,$B$7:$B$70,P$6,$A$7:$A$70,$N11) -> 0 | Q11: =SUMIFS($L$7:$L$70,$D$7:$D$70,$O11,$B$7:$B$70,Q$6,$A$7:$A$70,$N11) -> 0 | R11: =SUMIFS($L$7:$L$70,$D$7:$D$70,$O11,$B$7:$B$70,R$6,$A$7:$A$70,$N11) -> 0 | S11: =SUM(O11:R11) -> 0
A12: =A11 -> TORRE | B12: =B11 -> LOJAS | C12: CLIMATIZAÇÃO | D12: EQUIPAMENTOS | E12: EVAP. CASSETE 4-VIAS - VRF 24.200 BTU'S CRNU24GTPB4 LG 51 W / 0,20 A (220V/1F) | F12: 5 | G12: 1 | H12: 0 | I12: =(F12+H12*F12)*G12 -> 5 | J12: pç | L12: =IF(SUM(F12:K12)=0,SUMIFS($L13:$L$403,$B13:$B$403,$B12,$A13:$A$403,$A12),I12*K12) -> 0 | P12: =SUM(P7:P11) -> 37326.477 | Q12: =SUM(Q7:Q11) -> 100729.1 | R12: =SUM(R7:R11) -> 260249.66 | S12: =SUM(S7:S11) -> 398305.23
A13: =A12 -> TORRE | B13: =B12 -> LOJAS | C13: CLIMATIZAÇÃO | D13: EQUIPAMENTOS | E13: EVAP. CASSETE 4-VIAS - VRF 36.200 BTU'S CRNU36GTNA4 LG 135 W / 0,56 A (220V/1F) | F13: 5 | G13: 1 | H13: 0 | I13: =(F13+H13*F13)*G13 -> 5 | J13: pç | L13: =IF(SUM(F13:K13)=0,SUMIFS($L14:$L$403,$B14:$B$403,$B13,$A14:$A$403,$A13),I13*K13) -> 0 | P13: =P12/$S$12 -> 0.093713246 | Q13: =Q12/$S$12 -> 0.25289423 | R13: =R12/$S$12 -> 0.65339252 | X13: 400000 | Y13: 119174 | Z13: 30352.2 | AA13: 1921.5 | AB13: 212000 | AC13: 95004 | AD13: 46200 | AE13: 28800
A14: =A13 -> TORRE | B14: =B13 -> LOJAS | C14: CLIMATIZAÇÃO | D14: EQUIPAMENTOS | E14: EVAP. HI-WALL - VRF 19.100 BTU'S CRNU18GSKN4 LG 58 W / 0,52 A (220V/1F) | F14: 3 | G14: 1 | H14: 0 | I14: =(F14+H14*F14)*G14 -> 3 | J14: pç | L14: =IF(SUM(F14:K14)=0,SUMIFS($L15:$L$403,$B15:$B$403,$B14,$A15:$A$403,$A14),I14*K14) -> 0 | O14: Infraestrutura para instalação de ar condicionado | P14: =P$13*$S14 -> 37485.299 | Q14: =Q$13*$S14 -> 101157.69 | R14: =R$13*$S14 -> 261357.01 | S14: 400000 | V14: PAVIMENTOS | W14: ÁREA | X14: Infraestrutura para instalação de ar condicionado | Y14: Equipamento de ar condicionado | Z14: Equipamento de exaustão | AA14: Equipamento de Aspiração | AB14: Infraestrutua de Aspiração | AC14: Exaustão de churrasqueiras | AD14: Exaustão de cozinha | AE14: Mão de obra de instalação de equipamentos
A15: =A14 -> TORRE | B15: =B14 -> LOJAS | C15: CLIMATIZAÇÃO | D15: EQUIPAMENTOS | E15: EVAP. HI-WALL - VRF 24.200 BTU'S CRNU24GSKN4 LG 58 W / 0,52 A (220V/1F) | F15: 2 | G15: 1 | H15: 0 | I15: =(F15+H15*F15)*G15 -> 2 | J15: pç | L15: =IF(SUM(F15:K15)=0,SUMIFS($L16:$L$403,$B16:$B$403,$B15,$A16:$A$403,$A15),I15*K15) -> 0 | O15: Infraestrutua de Aspiração | P15: =P$13*$S15 -> 19867.208 | Q15: =Q$13*$S15 -> 53613.578 | R15: =R$13*$S15 -> 138519.21 | S15: 212000 | V15: ÁREA – 1º PAVTO. (TÉRREO) | W15: 784.58 | X15: =($W15/$W$59)*X$13 -> 25725.179 | Y15: =($W15/$W$59)*Y$13 -> 7664.4311 | Z15: =($W15/$W$59)*Z$13 -> 1952.0394 | AA15: =($W15/$W$59)*AA$13 -> 123.57733 | AB15: =($W15/$W$59)*AB$13 -> 13634.345 | AC15: =($W15/$W$59)*AC$13 -> 6109.9871 | AD15: =($W15/$W$59)*AD$13 -> 2971.2581 | AE15: =($W15/$W$59)*AE$13 -> 1852.2129
A16: =A15 -> TORRE | B16: =B15 -> LOJAS | C16: CLIMATIZAÇÃO | D16: EQUIPAMENTOS - EXAUSTÃO | E16: EXAUSTOR INLINE MAXX 150 SICFLUX 88W (220V/1F) | F16: 3 | G16: 1 | H16: 0 | I16: =(F16+H16*F16)*G16 -> 3 | J16: pç | K16: 530 | L16: =IF(SUM(F16:K16)=0,SUMIFS($L17:$L$403,$B17:$B$403,$B16,$A17:$A$403,$A16),I16*K16) -> 1590 | V16: ÁREA – MEZANINO DO 1º PAVTO. | X16: =($W16/$W$59)*X$13 -> 0 | Y16: =($W16/$W$59)*Y$13 -> 0 | Z16: =($W16/$W$59)*Z$13 -> 0 | AA16: =($W16/$W$59)*AA$13 -> 0 | AB16: =($W16/$W$59)*AB$13 -> 0 | AC16: =($W16/$W$59)*AC$13 -> 0 | AD16: =($W16/$W$59)*AD$13 -> 0 | AE16: =($W16/$W$59)*AE$13 -> 0
A17: =A16 -> TORRE | B17: =B16 -> LOJAS | C17: CLIMATIZAÇÃO | D17: EQUIPAMENTOS - EXAUSTÃO | E17: GABINETE DE VENTILAÇÃO SICFLUX 95W (220V F+N+T) | F17: 3 | G17: 1 | H17: 0 | I17: =(F17+H17*F17)*G17 -> 3 | J17: pç | K17: 7035 | L17: =IF(SUM(F17:K17)=0,SUMIFS($L18:$L$403,$B18:$B$403,$B17,$A18:$A$403,$A17),I17*K17) -> 21105 | N17: Torre | O17: EAP | P17: LOJAS | Q17: LAZER | R17: TORRE | S17: TOTAL | V17: ÁREA – 2º PAVIMENTO | X17: =($W17/$W$59)*X$13 -> 0 | Y17: =($W17/$W$59)*Y$13 -> 0 | Z17: =($W17/$W$59)*Z$13 -> 0 | AA17: =($W17/$W$59)*AA$13 -> 0 | AB17: =($W17/$W$59)*AB$13 -> 0 | AC17: =($W17/$W$59)*AC$13 -> 0 | AD17: =($W17/$W$59)*AD$13 -> 0 | AE17: =($W17/$W$59)*AE$13 -> 0
A18: =A17 -> TORRE | B18: =B17 -> LOJAS | C18: CLIMATIZAÇÃO | D18: EQUIPAMENTOS - EXAUSTÃO | E18: GRELHA EXTERNA, PLÁSTICO S150 SICFLUX | F18: 7 | G18: 1 | H18: 0 | I18: =(F18+H18*F18)*G18 -> 7 | J18: pç | K18: 29.5 | L18: =IF(SUM(F18:K18)=0,SUMIFS($L19:$L$403,$B19:$B$403,$B18,$A19:$A$403,$A18),I18*K18) -> 206.5 | N18: TORRE | O18: {=_xlfn.UNIQUE(_xlfn._xlws.FILTER($D$7:$D$1048576,$A$7:$A$1048576=N18))} -> 0 | P18: =SUMIFS($I$8:$I$71,$D$7:$D$70,$O18,$B$7:$B$70,P$6,$A$7:$A$70,$N18) -> 0 | Q18: =SUMIFS($I$8:$I$71,$D$7:$D$70,$O18,$B$7:$B$70,Q$6,$A$7:$A$70,$N18) -> 0 | R18: =SUMIFS($I$8:$I$71,$D$7:$D$70,$O18,$B$7:$B$70,R$6,$A$7:$A$70,$N18) -> 0 | S18: =SUM(O18:R18) -> 0 | V18: ÁREA – MEZANINO DO 2º PAVTO. | X18: =($W18/$W$59)*X$13 -> 0 | Y18: =($W18/$W$59)*Y$13 -> 0 | Z18: =($W18/$W$59)*Z$13 -> 0 | AA18: =($W18/$W$59)*AA$13 -> 0 | AB18: =($W18/$W$59)*AB$13 -> 0 | AC18: =($W18/$W$59)*AC$13 -> 0 | AD18: =($W18/$W$59)*AD$13 -> 0 | AE18: =($W18/$W$59)*AE$13 -> 0
A19: =A18 -> TORRE | B19: =B18 -> LOJAS | C19: CLIMATIZAÇÃO | D19: EQUIPAMENTOS - EXAUSTÃO | E19: MINIEXAUSTOR, NO FORRO MEGA 25 SICFLUX 37W (220V F+N+T) | F19: 7 | G19: 1 | H19: 0 | I19: =(F19+H19*F19)*G19 -> 7 | J19: pç | K19: 255.04 | L19: =IF(SUM(F19:K19)=0,SUMIFS($L20:$L$403,$B20:$B$403,$B19,$A20:$A$403,$A19),I19*K19) -> 1785.28 | N19: TORRE | O19: EQUIPAMENTOS | P19: =SUMIFS($I$7:$I$70,$D$7:$D$70,$O19,$B$7:$B$70,P$6,$A$7:$A$70,$N19) -> 26 | Q19: =SUMIFS($I$7:$I$70,$D$7:$D$70,$O19,$B$7:$B$70,Q$6,$A$7:$A$70,$N19) -> 24 | R19: =SUMIFS($I$7:$I$70,$D$7:$D$70,$O19,$B$7:$B$70,R$6,$A$7:$A$70,$N19) -> 770 | S19: =SUM(O19:R19) -> 820 | V19: ÁREA – 3º PAVIMENTO | X19: =($W19/$W$59)*X$13 -> 0 | Y19: =($W19/$W$59)*Y$13 -> 0 | Z19: =($W19/$W$59)*Z$13 -> 0 | AA19: =($W19/$W$59)*AA$13 -> 0 | AB19: =($W19/$W$59)*AB$13 -> 0 | AC19: =($W19/$W$59)*AC$13 -> 0 | AD19: =($W19/$W$59)*AD$13 -> 0 | AE19: =($W19/$W$59)*AE$13 -> 0
A20: =A19 -> TORRE | B20: =B19 -> LOJAS | C20: CLIMATIZAÇÃO | D20: INFRAESTRUTURA PARA INSTALAÇÃO | E20: 10 mm - 3/8" REDE FRIGORÍGENA DE COBRE | F20: 105.3 | G20: 1 | H20: 0 | I20: =(F20+H20*F20)*G20 -> 105.3 | J20: m | K20: 28.71 | L20: =IF(SUM(F20:K20)=0,SUMIFS($L21:$L$403,$B21:$B$403,$B20,$A21:$A$403,$A20),I20*K20) -> 3023.163 | N20: TORRE | O20: EQUIPAMENTOS - EXAUSTÃO | P20: =SUMIFS($I$7:$I$70,$D$7:$D$70,$O20,$B$7:$B$70,P$6,$A$7:$A$70,$N20) -> 20 | Q20: =SUMIFS($I$7:$I$70,$D$7:$D$70,$O20,$B$7:$B$70,Q$6,$A$7:$A$70,$N20) -> 11 | R20: =SUMIFS($I$7:$I$70,$D$7:$D$70,$O20,$B$7:$B$70,R$6,$A$7:$A$70,$N20) -> 79 | S20: =SUM(O20:R20) -> 110 | V20: ÁREA – MEZANINO DO 3º PAVTO. | X20: =($W20/$W$59)*X$13 -> 0 | Y20: =($W20/$W$59)*Y$13 -> 0 | Z20: =($W20/$W$59)*Z$13 -> 0 | AA20: =($W20/$W$59)*AA$13 -> 0 | AB20: =($W20/$W$59)*AB$13 -> 0 | AC20: =($W20/$W$59)*AC$13 -> 0 | AD20: =($W20/$W$59)*AD$13 -> 0 | AE20: =($W20/$W$59)*AE$13 -> 0
A21: =A20 -> TORRE | B21: =B20 -> LOJAS | C21: CLIMATIZAÇÃO | D21: INFRAESTRUTURA PARA INSTALAÇÃO | E21: 13 mm - 1/2" REDE FRIGORÍGENA DE COBRE | F21: 28.63 | G21: 1 | H21: 0 | I21: =(F21+H21*F21)*G21 -> 28.63 | J21: m | K21: 33 | L21: =IF(SUM(F21:K21)=0,SUMIFS($L22:$L$403,$B22:$B$403,$B21,$A22:$A$403,$A21),I21*K21) -> 944.79 | N21: TORRE | O21: INFRAESTRUTURA PARA INSTALAÇÃO | P21: =SUMIFS($I$7:$I$70,$D$7:$D$70,$O21,$B$7:$B$70,P$6,$A$7:$A$70,$N21) -> 354.08 | Q21: =SUMIFS($I$7:$I$70,$D$7:$D$70,$O21,$B$7:$B$70,Q$6,$A$7:$A$70,$N21) -> 365.9 | R21: =SUMIFS($I$7:$I$70,$D$7:$D$70,$O21,$B$7:$B$70,R$6,$A$7:$A$70,$N21) -> 9457.65 | S21: =SUM(O21:R21) -> 10177.63 | V21: ÁREA – 4º PAVIMENTO GARAGEM/LAZER | W21: 892.45 | X21: =($W21/$W$59)*X$13 -> 29262.071 | Y21: =($W21/$W$59)*Y$13 -> 8718.1951 | Z21: =($W21/$W$59)*Z$13 -> 2220.4206 | AA21: =($W21/$W$59)*AA$13 -> 140.56767 | AB21: =($W21/$W$59)*AB$13 -> 15508.898 | AC21: =($W21/$W$59)*AC$13 -> 6950.0345 | AD21: =($W21/$W$59)*AD$13 -> 3379.7692 | AE21: =($W21/$W$59)*AE$13 -> 2106.8691
A22: =A21 -> TORRE | B22: =B21 -> LOJAS | C22: CLIMATIZAÇÃO | D22: INFRAESTRUTURA PARA INSTALAÇÃO | E22: 19 mm - 5/8" REDE FRIGORÍGENA DE COBRE | F22: 104.98 | G22: 1 | H22: 0 | I22: =(F22+H22*F22)*G22 -> 104.98 | J22: m | K22: 40 | L22: =IF(SUM(F22:K22)=0,SUMIFS($L23:$L$403,$B23:$B$403,$B22,$A23:$A$403,$A22),I22*K22) -> 4199.2 | N22: TORRE | O22: EQUIPAMENTOS - LIMPEZA | P22: =SUMIFS($I$7:$I$70,$D$7:$D$70,$O22,$B$7:$B$70,P$6,$A$7:$A$70,$N22) -> 0 | Q22: =SUMIFS($I$7:$I$70,$D$7:$D$70,$O22,$B$7:$B$70,Q$6,$A$7:$A$70,$N22) -> 0 | R22: =SUMIFS($I$7:$I$70,$D$7:$D$70,$O22,$B$7:$B$70,R$6,$A$7:$A$70,$N22) -> 0 | S22: =SUM(O22:R22) -> 0 | V22: ÁREA – 5º PAVIMENTO LAZER | W22: 499.27 | X22: =($W22/$W$59)*X$13 -> 16370.3 | Y22: =($W22/$W$59)*Y$13 -> 4877.2853 | Z22: =($W22/$W$59)*Z$13 -> 1242.1865 | AA22: =($W22/$W$59)*AA$13 -> 78.638828 | AB22: =($W22/$W$59)*AB$13 -> 8676.2589 | AC22: =($W22/$W$59)*AC$13 -> 3888.1099 | AD22: =($W22/$W$59)*AD$13 -> 1890.7696 | AE22: =($W22/$W$59)*AE$13 -> 1178.6616
A23: =A22 -> TORRE | B23: =B22 -> LOJAS | C23: CLIMATIZAÇÃO | D23: INFRAESTRUTURA PARA INSTALAÇÃO | E23: 29 mm - 5/8" REDE FRIGORÍGENA DE COBRE | F23: 28.27 | G23: 1 | H23: 0 | I23: =(F23+H23*F23)*G23 -> 28.27 | J23: m | K23: 41.58 | L23: =IF(SUM(F23:K23)=0,SUMIFS($L24:$L$403,$B24:$B$403,$B23,$A24:$A$403,$A23),I23*K23) -> 1175.4666 | V23: ÁREA – 6º PAVIMENTO TIPO - DIFERENCIADO | W23: 345.53 | X23: =($W23/$W$59)*X$13 -> 11329.4 | Y23: =($W23/$W$59)*Y$13 -> 3375.4249 | Z23: =($W23/$W$59)*Z$13 -> 859.68056 | AA23: =($W23/$W$59)*AA$13 -> 54.423607 | AB23: =($W23/$W$59)*AB$13 -> 6004.5822 | AC23: =($W23/$W$59)*AC$13 -> 2690.8459 | AD23: =($W23/$W$59)*AD$13 -> 1308.5457 | AE23: =($W23/$W$59)*AE$13 -> 815.71683
A24: =A23 -> TORRE | B24: =B23 -> LOJAS | C24: CLIMATIZAÇÃO | D24: INFRAESTRUTURA PARA INSTALAÇÃO | E24: 150 mm - 6" TUBO PVC | F24: 86.9 | G24: 1 | H24: 0 | I24: =(F24+H24*F24)*G24 -> 86.9 | J24: m | K24: 36.33 | L24: =IF(SUM(F24:K24)=0,SUMIFS($L25:$L$403,$B25:$B$403,$B24,$A25:$A$403,$A24),I24*K24) -> 3157.077 | P24: EQUIPAMENTO | Q24: EQUIPAMENTO | R24: PONTO | V24: ÁREA – 7º AO 14° PAVIMENTO TIPO - X8 | W24: =2427.28/8 -> 303.41 | X24: =($W24/$W$59)*X$13 -> 9948.35 | Y24: =($W24/$W$59)*Y$13 -> 2963.9616 | Z24: =($W24/$W$59)*Z$13 -> 754.88577 | AA24: =($W24/$W$59)*AA$13 -> 47.789386 | AB24: =($W24/$W$59)*AB$13 -> 5272.6255 | AC24: =($W24/$W$59)*AC$13 -> 2362.8326 | AD24: =($W24/$W$59)*AD$13 -> 1149.0344 | AE24: =($W24/$W$59)*AE$13 -> 716.2812
A25: TORRE | B25: LAZER | L25: =IF(SUM(F25:K25)=0,SUMIFS($L26:$L$403,$B26:$B$403,$B25,$A26:$A$403,$A25),I25*K25) -> 100729.1 | V25: ÁREA – 7º AO 14° PAVIMENTO TIPO - X8 | W25: =2427.28/8 -> 303.41 | X25: =($W25/$W$59)*X$13 -> 9948.35 | Y25: =($W25/$W$59)*Y$13 -> 2963.9616 | Z25: =($W25/$W$59)*Z$13 -> 754.88577 | AA25: =($W25/$W$59)*AA$13 -> 47.789386 | AB25: =($W25/$W$59)*AB$13 -> 5272.6255 | AC25: =($W25/$W$59)*AC$13 -> 2362.8326 | AD25: =($W25/$W$59)*AD$13 -> 1149.0344 | AE25: =($W25/$W$59)*AE$13 -> 716.2812
A26: =A25 -> TORRE | B26: =B25 -> LAZER | C26: CLIMATIZAÇÃO | D26: EQUIPAMENTOS | E26: CAIXA DE DRENO - CPP 005 POLAR | F26: 6 | G26: 1 | H26: 0 | I26: =(F26+H26*F26)*G26 -> 6 | J26: pç | K26: 28 | L26: =IF(SUM(F26:K26)=0,SUMIFS($L27:$L$403,$B27:$B$403,$B26,$A27:$A$403,$A26),I26*K26) -> 168 | V26: ÁREA – 7º AO 14° PAVIMENTO TIPO - X8 | W26: =2427.28/8 -> 303.41 | X26: =($W26/$W$59)*X$13 -> 9948.35 | Y26: =($W26/$W$59)*Y$13 -> 2963.9616 | Z26: =($W26/$W$59)*Z$13 -> 754.88577 | AA26: =($W26/$W$59)*AA$13 -> 47.789386 | AB26: =($W26/$W$59)*AB$13 -> 5272.6255 | AC26: =($W26/$W$59)*AC$13 -> 2362.8326 | AD26: =($W26/$W$59)*AD$13 -> 1149.0344 | AE26: =($W26/$W$59)*AE$13 -> 716.2812
A27: =A25 -> TORRE | B27: =B26 -> LAZER | C27: CLIMATIZAÇÃO | D27: EQUIPAMENTOS | E27: COND. SPLIT 9.000 BTU'S 38MBCB09M5 MIDEA 780 (220V/1F)2 | F27: 1 | G27: 1 | H27: 0 | I27: =(F27+H27*F27)*G27 -> 1 | J27: pç | K27: 2200 | L27: =IF(SUM(F27:K27)=0,SUMIFS($L28:$L$403,$B28:$B$403,$B27,$A28:$A$403,$A27),I27*K27) -> 2200 | V27: ÁREA – 7º AO 14° PAVIMENTO TIPO - X8 | W27: =2427.28/8 -> 303.41 | X27: =($W27/$W$59)*X$13 -> 9948.35 | Y27: =($W27/$W$59)*Y$13 -> 2963.9616 | Z27: =($W27/$W$59)*Z$13 -> 754.88577 | AA27: =($W27/$W$59)*AA$13 -> 47.789386 | AB27: =($W27/$W$59)*AB$13 -> 5272.6255 | AC27: =($W27/$W$59)*AC$13 -> 2362.8326 | AD27: =($W27/$W$59)*AD$13 -> 1149.0344 | AE27: =($W27/$W$59)*AE$13 -> 716.2812
A28: =A26 -> TORRE | B28: =B27 -> LAZER | C28: CLIMATIZAÇÃO | D28: EQUIPAMENTOS | E28: COND. SPLIT 25.000 BTU'S ATUW24GPLP0 LG 2.700 W / 220 V / 1F | F28: 3 | G28: 1 | H28: 0 | I28: =(F28+H28*F28)*G28 -> 3 | J28: pç | K28: 5100 | L28: =IF(SUM(F28:K28)=0,SUMIFS($L29:$L$403,$B29:$B$403,$B28,$A29:$A$403,$A28),I28*K28) -> 15300 | V28: ÁREA – 7º AO 14° PAVIMENTO TIPO - X8 | W28: =2427.28/8 -> 303.41 | X28: =($W28/$W$59)*X$13 -> 9948.35 | Y28: =($W28/$W$59)*Y$13 -> 2963.9616 | Z28: =($W28/$W$59)*Z$13 -> 754.88577 | AA28: =($W28/$W$59)*AA$13 -> 47.789386 | AB28: =($W28/$W$59)*AB$13 -> 5272.6255 | AC28: =($W28/$W$59)*AC$13 -> 2362.8326 | AD28: =($W28/$W$59)*AD$13 -> 1149.0344 | AE28: =($W28/$W$59)*AE$13 -> 716.2812
A29: =A27 -> TORRE | B29: =B28 -> LAZER | C29: CLIMATIZAÇÃO | D29: EQUIPAMENTOS | E29: COND. SPLIT 24.000 BTU'S 38MBCA24M5 MIDEA 2.700 W / 220 V / 1F | F29: 2 | G29: 1 | H29: 0 | I29: =(F29+H29*F29)*G29 -> 2 | J29: pç | K29: 4900 | L29: =IF(SUM(F29:K29)=0,SUMIFS($L30:$L$403,$B30:$B$403,$B29,$A30:$A$403,$A29),I29*K29) -> 9800 | V29: ÁREA – 7º AO 14° PAVIMENTO TIPO - X8 | W29: =2427.28/8 -> 303.41 | X29: =($W29/$W$59)*X$13 -> 9948.35 | Y29: =($W29/$W$59)*Y$13 -> 2963.9616 | Z29: =($W29/$W$59)*Z$13 -> 754.88577 | AA29: =($W29/$W$59)*AA$13 -> 47.789386 | AB29: =($W29/$W$59)*AB$13 -> 5272.6255 | AC29: =($W29/$W$59)*AC$13 -> 2362.8326 | AD29: =($W29/$W$59)*AD$13 -> 1149.0344 | AE29: =($W29/$W$59)*AE$13 -> 716.2812
A30: =A28 -> TORRE | B30: =B29 -> LAZER | C30: CLIMATIZAÇÃO | D30: EQUIPAMENTOS | E30: COND. SPLIT 12.000 BTU'S 38MBCB12M5 MIDEA 1.070 W / 220 V / 1F | F30: 3 | G30: 1 | H30: 0 | I30: =(F30+H30*F30)*G30 -> 3 | J30: pç | K30: 2400 | L30: =IF(SUM(F30:K30)=0,SUMIFS($L31:$L$403,$B31:$B$403,$B30,$A31:$A$403,$A30),I30*K30) -> 7200 | V30: ÁREA – 7º AO 14° PAVIMENTO TIPO - X8 | W30: =2427.28/8 -> 303.41 | X30: =($W30/$W$59)*X$13 -> 9948.35 | Y30: =($W30/$W$59)*Y$13 -> 2963.9616 | Z30: =($W30/$W$59)*Z$13 -> 754.88577 | AA30: =($W30/$W$59)*AA$13 -> 47.789386 | AB30: =($W30/$W$59)*AB$13 -> 5272.6255 | AC30: =($W30/$W$59)*AC$13 -> 2362.8326 | AD30: =($W30/$W$59)*AD$13 -> 1149.0344 | AE30: =($W30/$W$59)*AE$13 -> 716.2812
A31: =A29 -> TORRE | B31: =B30 -> LAZER | C31: CLIMATIZAÇÃO | D31: EQUIPAMENTOS | E31: EVAP. CASSETE 4-VIAS 24.000 BTU'S ATNW24GPLP0 LG | F31: 3 | G31: 1 | H31: 0 | I31: =(F31+H31*F31)*G31 -> 3 | J31: pç | K31: 10300 | L31: =IF(SUM(F31:K31)=0,SUMIFS($L32:$L$403,$B32:$B$403,$B31,$A32:$A$403,$A31),I31*K31) -> 30900 | V31: ÁREA – 7º AO 14° PAVIMENTO TIPO - X8 | W31: =2427.28/8 -> 303.41 | X31: =($W31/$W$59)*X$13 -> 9948.35 | Y31: =($W31/$W$59)*Y$13 -> 2963.9616 | Z31: =($W31/$W$59)*Z$13 -> 754.88577 | AA31: =($W31/$W$59)*AA$13 -> 47.789386 | AB31: =($W31/$W$59)*AB$13 -> 5272.6255 | AC31: =($W31/$W$59)*AC$13 -> 2362.8326 | AD31: =($W31/$W$59)*AD$13 -> 1149.0344 | AE31: =($W31/$W$59)*AE$13 -> 716.2812
A32: =A30 -> TORRE | B32: =B31 -> LAZER | C32: CLIMATIZAÇÃO | D32: EQUIPAMENTOS | E32: EVAP. HI-WALL SPLIT 9.000 BTU'S 42MBCB09M5 MIDEA | F32: 1 | G32: 1 | H32: 0 | I32: =(F32+H32*F32)*G32 -> 1 | J32: pç | K32: 2326 | L32: =IF(SUM(F32:K32)=0,SUMIFS($L33:$L$403,$B33:$B$403,$B32,$A33:$A$403,$A32),I32*K32) -> 2326 | V32: ÁREA – 15º AO 35° PAVIMENTO TIPO - X21 | W32: =6374.97/21 -> 303.57 | X32: =($W32/$W$59)*X$13 -> 9953.5961 | Y32: =($W32/$W$59)*Y$13 -> 2965.5247 | Z32: =($W32/$W$59)*Z$13 -> 755.28385 | AA32: =($W32/$W$59)*AA$13 -> 47.814587 | AB32: =($W32/$W$59)*AB$13 -> 5275.4059 | AC32: =($W32/$W$59)*AC$13 -> 2364.0786 | AD32: =($W32/$W$59)*AD$13 -> 1149.6404 | AE32: =($W32/$W$59)*AE$13 -> 716.65892
A33: =A25 -> TORRE | B33: =B32 -> LAZER | C33: CLIMATIZAÇÃO | D33: EQUIPAMENTOS | E33: EVAP. HI-WALL SPLIT 24.000 BTU'S 42MBCA24M5 MIDEA | F33: 3 | G33: 1 | H33: 0 | I33: =(F33+H33*F33)*G33 -> 3 | J33: pç | K33: 4900 | L33: =IF(SUM(F33:K33)=0,SUMIFS($L34:$L$403,$B34:$B$403,$B33,$A34:$A$403,$A33),I33*K33) -> 14700 | V33: ÁREA – 15º AO 35° PAVIMENTO TIPO - X21 | W33: =6374.97/21 -> 303.57 | X33: =($W33/$W$59)*X$13 -> 9953.5961 | Y33: =($W33/$W$59)*Y$13 -> 2965.5247 | Z33: =($W33/$W$59)*Z$13 -> 755.28385 | AA33: =($W33/$W$59)*AA$13 -> 47.814587 | AB33: =($W33/$W$59)*AB$13 -> 5275.4059 | AC33: =($W33/$W$59)*AC$13 -> 2364.0786 | AD33: =($W33/$W$59)*AD$13 -> 1149.6404 | AE33: =($W33/$W$59)*AE$13 -> 716.65892
A34: =A26 -> TORRE | B34: =B33 -> LAZER | C34: CLIMATIZAÇÃO | D34: EQUIPAMENTOS | E34: EVAP. HI-WALL SPLIT 12.000 BTU'S 42MBCB12M5 MIDEA | F34: 2 | G34: 1 | H34: 0 | I34: =(F34+H34*F34)*G34 -> 2 | J34: pç | K34: 2600 | L34: =IF(SUM(F34:K34)=0,SUMIFS($L35:$L$403,$B35:$B$403,$B34,$A35:$A$403,$A34),I34*K34) -> 5200 | V34: ÁREA – 15º AO 35° PAVIMENTO TIPO - X21 | W34: =6374.97/21 -> 303.57 | X34: =($W34/$W$59)*X$13 -> 9953.5961 | Y34: =($W34/$W$59)*Y$13 -> 2965.5247 | Z34: =($W34/$W$59)*Z$13 -> 755.28385 | AA34: =($W34/$W$59)*AA$13 -> 47.814587 | AB34: =($W34/$W$59)*AB$13 -> 5275.4059 | AC34: =($W34/$W$59)*AC$13 -> 2364.0786 | AD34: =($W34/$W$59)*AD$13 -> 1149.6404 | AE34: =($W34/$W$59)*AE$13 -> 716.65892
A35: =A27 -> TORRE | B35: =B34 -> LAZER | C35: CLIMATIZAÇÃO | D35: EQUIPAMENTOS - EXAUSTÃO | E35: GRELHA EXTERNA, PLÁSTICO - S150 MIDEA | F35: 5 | G35: 1 | H35: 0 | I35: =(F35+H35*F35)*G35 -> 5 | J35: pç | K35: 31.5 | L35: =IF(SUM(F35:K35)=0,SUMIFS($L36:$L$403,$B36:$B$403,$B35,$A36:$A$403,$A35),I35*K35) -> 157.5 | V35: ÁREA – 15º AO 35° PAVIMENTO TIPO - X21 | W35: =6374.97/21 -> 303.57 | X35: =($W35/$W$59)*X$13 -> 9953.5961 | Y35: =($W35/$W$59)*Y$13 -> 2965.5247 | Z35: =($W35/$W$59)*Z$13 -> 755.28385 | AA35: =($W35/$W$59)*AA$13 -> 47.814587 | AB35: =($W35/$W$59)*AB$13 -> 5275.4059 | AC35: =($W35/$W$59)*AC$13 -> 2364.0786 | AD35: =($W35/$W$59)*AD$13 -> 1149.6404 | AE35: =($W35/$W$59)*AE$13 -> 716.65892
A36: =A28 -> TORRE | B36: =B35 -> LAZER | C36: CLIMATIZAÇÃO | D36: EQUIPAMENTOS - EXAUSTÃO | E36: MINIEXAUSTOR, NO FORRO MEGA 25 SICFLUX 37W (220V F+N+T) | F36: 6 | G36: 1 | H36: 0 | I36: =(F36+H36*F36)*G36 -> 6 | J36: pç | K36: 255.04 | L36: =IF(SUM(F36:K36)=0,SUMIFS($L37:$L$403,$B37:$B$403,$B36,$A37:$A$403,$A36),I36*K36) -> 1530.24 | V36: ÁREA – 15º AO 35° PAVIMENTO TIPO - X21 | W36: =6374.97/21 -> 303.57 | X36: =($W36/$W$59)*X$13 -> 9953.5961 | Y36: =($W36/$W$59)*Y$13 -> 2965.5247 | Z36: =($W36/$W$59)*Z$13 -> 755.28385 | AA36: =($W36/$W$59)*AA$13 -> 47.814587 | AB36: =($W36/$W$59)*AB$13 -> 5275.4059 | AC36: =($W36/$W$59)*AC$13 -> 2364.0786 | AD36: =($W36/$W$59)*AD$13 -> 1149.6404 | AE36: =($W36/$W$59)*AE$13 -> 716.65892
A37: =A29 -> TORRE | B37: =B36 -> LAZER | C37: CLIMATIZAÇÃO | D37: INFRAESTRUTURA PARA INSTALAÇÃO | E37: 6 mm - 1/4" REDE FRIGORÍGENA DE COBRE | F37: 62.1 | G37: 1 | H37: 0 | I37: =(F37+H37*F37)*G37 -> 62.1 | J37: m | K37: 16.66 | L37: =IF(SUM(F37:K37)=0,SUMIFS($L38:$L$403,$B38:$B$403,$B37,$A38:$A$403,$A37),I37*K37) -> 1034.586 | V37: ÁREA – 15º AO 35° PAVIMENTO TIPO - X21 | W37: =6374.97/21 -> 303.57 | X37: =($W37/$W$59)*X$13 -> 9953.5961 | Y37: =($W37/$W$59)*Y$13 -> 2965.5247 | Z37: =($W37/$W$59)*Z$13 -> 755.28385 | AA37: =($W37/$W$59)*AA$13 -> 47.814587 | AB37: =($W37/$W$59)*AB$13 -> 5275.4059 | AC37: =($W37/$W$59)*AC$13 -> 2364.0786 | AD37: =($W37/$W$59)*AD$13 -> 1149.6404 | AE37: =($W37/$W$59)*AE$13 -> 716.65892
A38: =A30 -> TORRE | B38: =B37 -> LAZER | C38: CLIMATIZAÇÃO | D38: INFRAESTRUTURA PARA INSTALAÇÃO | E38: 10 mm - 3/8" REDE FRIGORÍGENA DE COBRE | F38: 129.85 | G38: 1 | H38: 0 | I38: =(F38+H38*F38)*G38 -> 129.85 | J38: m | K38: 28.71 | L38: =IF(SUM(F38:K38)=0,SUMIFS($L39:$L$403,$B39:$B$403,$B38,$A39:$A$403,$A38),I38*K38) -> 3727.9935 | V38: ÁREA – 15º AO 35° PAVIMENTO TIPO - X21 | W38: =6374.97/21 -> 303.57 | X38: =($W38/$W$59)*X$13 -> 9953.5961 | Y38: =($W38/$W$59)*Y$13 -> 2965.5247 | Z38: =($W38/$W$59)*Z$13 -> 755.28385 | AA38: =($W38/$W$59)*AA$13 -> 47.814587 | AB38: =($W38/$W$59)*AB$13 -> 5275.4059 | AC38: =($W38/$W$59)*AC$13 -> 2364.0786 | AD38: =($W38/$W$59)*AD$13 -> 1149.6404 | AE38: =($W38/$W$59)*AE$13 -> 716.65892
A39: =A31 -> TORRE | B39: =B38 -> LAZER | C39: CLIMATIZAÇÃO | D39: INFRAESTRUTURA PARA INSTALAÇÃO | E39: 13 mm - 1/2" REDE FRIGORÍGENA DE COBRE | F39: 44.19 | G39: 1 | H39: 0 | I39: =(F39+H39*F39)*G39 -> 44.19 | J39: m | K39: 33 | L39: =IF(SUM(F39:K39)=0,SUMIFS($L40:$L$403,$B40:$B$403,$B39,$A40:$A$403,$A39),I39*K39) -> 1458.27 | V39: ÁREA – 15º AO 35° PAVIMENTO TIPO - X21 | W39: =6374.97/21 -> 303.57 | X39: =($W39/$W$59)*X$13 -> 9953.5961 | Y39: =($W39/$W$59)*Y$13 -> 2965.5247 | Z39: =($W39/$W$59)*Z$13 -> 755.28385 | AA39: =($W39/$W$59)*AA$13 -> 47.814587 | AB39: =($W39/$W$59)*AB$13 -> 5275.4059 | AC39: =($W39/$W$59)*AC$13 -> 2364.0786 | AD39: =($W39/$W$59)*AD$13 -> 1149.6404 | AE39: =($W39/$W$59)*AE$13 -> 716.65892
A40: =A32 -> TORRE | B40: =B39 -> LAZER | C40: CLIMATIZAÇÃO | D40: INFRAESTRUTURA PARA INSTALAÇÃO | E40: 16 mm - 5/8" REDE FRIGORÍGENA DE COBRE | F40: 111.76 | G40: 1 | H40: 0 | I40: =(F40+H40*F40)*G40 -> 111.76 | J40: m | K40: 38 | L40: =IF(SUM(F40:K40)=0,SUMIFS($L41:$L$403,$B41:$B$403,$B40,$A41:$A$403,$A40),I40*K40) -> 4246.88 | V40: ÁREA – 15º AO 35° PAVIMENTO TIPO - X21 | W40: =6374.97/21 -> 303.57 | X40: =($W40/$W$59)*X$13 -> 9953.5961 | Y40: =($W40/$W$59)*Y$13 -> 2965.5247 | Z40: =($W40/$W$59)*Z$13 -> 755.28385 | AA40: =($W40/$W$59)*AA$13 -> 47.814587 | AB40: =($W40/$W$59)*AB$13 -> 5275.4059 | AC40: =($W40/$W$59)*AC$13 -> 2364.0786 | AD40: =($W40/$W$59)*AD$13 -> 1149.6404 | AE40: =($W40/$W$59)*AE$13 -> 716.65892
...

Sheet Ger_Executivo_Manual
H4: PROJETO: | I4: Electra Towers | O4: REVISÃO: | P4: DATA
H5: EMPRESA: | I5: Thozen | O5: R00
A6: Unidade Construtiva | B6: Célula Construtiva | C6: Etapa | D6: Subetapa | E6: Serviço | G6: GERENCIAMENTO EXECUTIVO
A7: 0 | B7: 0 | C7: 0 | D7: 0 | E7: 0 | G7: EAP | H7: NIVEL | I7: Item | J7: Descrição | K7: Unidade | L7: Quant. | M7: Preço un | N7: Total | O7: Considerações | P7: Situação
A8: 0 | B8: 1 | C8: 0 | D8: 0 | E8: 0 | H8: CÉLULA CONSTRUTIVA | I8: 01 | J8: MOVIMENTAÇÃO DE TERRA
A9: 0 | B9: 1 | C9: 1 | D9: 0 | E9: 0 | H9: ETAPA | I9: 01.001 | J9: DEMOLIÇÕES, LIMPEZA DE TERRENO E LOCAÇÃO DE OBRA | N9: 26235.314 | O9: 1.5663183
A10: 0 | B10: 1 | C10: 1 | D10: 1 | E10: 0 | H10: SUBETAPA | I10: 01.001.001 | J10: Locação e gabarito de obra | N10: 26235.314 | O10: 1.5663183
A11: 0 | B11: 1 | C11: 1 | D11: 1 | E11: 1 | G11: MOVIMENTAÇÃO DE TERRA | H11: SERVIÇO | I11: 01.001.001.001 | J11: Locação da obra | K11: m2 | N11: 26235.314 | P11: Pendente
A12: 0 | B12: 1 | C12: 2 | D12: 0 | E12: 1 | H12: ETAPA | I12: 01.002 | J12: SERVIÇOS PRELIMINARES
A13: 0 | B13: 1 | C13: 2 | D13: 1 | E13: 0 | H13: SUBETAPA | I13: 01.002.001 | J13: Limpeza Permanente e Remoção entulho
A14: 0 | B14: 1 | C14: 2 | D14: 1 | E14: 1 | G14: MOVIMENTAÇÃO DE TERRA | H14: SERVIÇO | I14: 01.002.001.001 | J14: Limpeza da camada vegetal | K14: m2 | P14: Pendente
A15: 0 | B15: 1 | C15: 2 | D15: 1 | E15: 2 | G15: MOVIMENTAÇÃO DE TERRA | H15: SERVIÇO | I15: 01.002.001.002 | J15: Remoção de entulhos e resíduos | P15: Pendente
A16: 0 | B16: 1 | C16: 2 | D16: 2 | E16: 0 | H16: SUBETAPA | I16: 01.002.002 | J16: Mão de Obra de Canteiro
A17: 0 | B17: 1 | C17: 2 | D17: 2 | E17: 1 | G17: MOVIMENTAÇÃO DE TERRA | H17: SERVIÇO | I17: 01.002.002.001 | J17: Mão de Obra de Canteiro | K17: vb | P17: Pendente
A18: 0 | B18: 1 | C18: 3 | D18: 0 | E18: 1 | H18: ETAPA | I18: 01.003 | J18: SERVIÇOS DE TERRAPLANAGEM | N18: 271126.19 | O18: 16.186957
A19: 0 | B19: 1 | C19: 3 | D19: 1 | E19: 0 | H19: SUBETAPA | I19: 01.003.001 | J19: Mao de obra - movimentações de terra | N19: 271126.19 | O19: 16.186957
A20: 0 | B20: 1 | C20: 3 | D20: 1 | E20: 1 | G20: MOVIMENTAÇÃO DE TERRA | H20: SERVIÇO | I20: 01.003.001.001 | J20: Mão de obra movimentação de terra | K20: vb | N20: 233000 | P20: Pendente
A21: 0 | B21: 1 | C21: 4 | D21: 0 | E21: 2 | H21: ETAPA | I21: 01.004 | J21: SERVIÇO DE DRENAGEM | N21: 80000 | O21: 4.7762135
A22: 0 | B22: 1 | C22: 4 | D22: 1 | E22: 0 | H22: SUBETAPA | I22: 01.004.001 | J22: Drenagem | N22: 80000 | O22: 4.7762135
A23: 0 | B23: 1 | C23: 4 | D23: 1 | E23: 1 | G23: MOVIMENTAÇÃO DE TERRA | H23: SERVIÇO | I23: 01.004.001.001 | J23: Rebaixamento de Lençol freático | K23: vb | N23: 80000 | P23: Pendente
A24: 0 | B24: 2 | C24: 0 | D24: 1 | E24: 1 | H24: CÉLULA CONSTRUTIVA | I24: 02 | J24: CONTENÇÃO | N24: 772006.63 | O24: 46.090856
A25: 0 | B25: 2 | C25: 1 | D25: 0 | E25: 1 | H25: ETAPA | I25: 02.001 | J25: MURETA GUIA | N25: 18739.389 | O25: 1.1187915
A26: 0 | B26: 2 | C26: 1 | D26: 1 | E26: 0 | H26: SUBETAPA | I26: 02.001.001 | J26: Forma | N26: 6673.9436 | O26: 0.39845225
A27: 0 | B27: 2 | C27: 1 | D27: 1 | E27: 1 | G27: CONTENÇÃO | H27: SERVIÇO | I27: 02.001.001.001 | J27: Forma para infraestrutura em Tábuas de Madeira Serrada 2x reaproveitamento | K27: m2 | L27: 111.3136 | M27: 59.956229 | N27: 6673.9436 | P27: Pendente
A28: 0 | B28: 2 | C28: 1 | D28: 2 | E28: 0 | H28: SUBETAPA | I28: 02.001.002 | J28: Armadura | N28: 4318.7306 | O28: 0.25783974
A29: 0 | B29: 2 | C29: 1 | D29: 2 | E29: 1 | G29: CONTENÇÃO | H29: SERVIÇO | I29: 02.001.002.001 | J29: Armação aço CA-50 ø 6,3mm para Contenções (corte e dobra em obra) | K29: un | L29: 670.32 | M29: 6.0795674 | N29: 4075.2556 | P29: Pendente
A30: 0 | B30: 2 | C30: 1 | D30: 2 | E30: 2 | G30: CONTENÇÃO | H30: SERVIÇO | I30: 02.001.002.002 | J30: Armação aço CA-50 ø 12,5mm para Contenções (corte e dobra em obra) | K30: un | L30: 41.6016 | M30: 5.8525391 | N30: 243.47499 | P30: Pendente
A31: 0 | B31: 2 | C31: 1 | D31: 3 | E31: 0 | H31: SUBETAPA | I31: 02.001.003 | J31: Concreto | N31: 7746.7147 | O31: 0.46249954
A32: 0 | B32: 2 | C32: 1 | D32: 3 | E32: 1 | G32: CONTENÇÃO | H32: SERVIÇO | I32: 02.001.003.001 | J32: Concreto Usinado bombeável 50MPa para infraestrutura- incluindo serviço de bombeamento | K32: m3 | L32: 11.390452 | M32: 680.106 | N32: 7746.7147 | P32: Pendente
A33: 0 | B33: 2 | C33: 2 | D33: 0 | E33: 1 | H33: ETAPA | I33: 02.002 | J33: LAMELAS | PAREDE DIAFRAGMA | N33: 331865.23 | O33: 19.81324
A34: 0 | B34: 2 | C34: 2 | D34: 1 | E34: 0 | H34: SUBETAPA | I34: 02.002.001 | J34: Armadura | N34: 155967.97 | O34: 9.3117038
A35: 0 | B35: 2 | C35: 2 | D35: 1 | E35: 1 | G35: CONTENÇÃO | H35: SERVIÇO | I35: 02.002.001.001 | J35: Armação aço CA-50 ø 6,3mm para Contenções (corte e dobra em Indústria) | K35: un | L35: 2282 | M35: 8.964145 | N35: 20456.179 | P35: Pendente
A36: 0 | B36: 2 | C36: 2 | D36: 1 | E36: 2 | G36: CONTENÇÃO | H36: SERVIÇO | I36: 02.002.001.002 | J36: Armação aço CA-50 ø 8,0mm para Contenções (corte e dobra em Indústria) | K36: un | L36: 77 | M36: 8.964145 | N36: 690.23916 | P36: Pendente
A37: 0 | B37: 2 | C37: 2 | D37: 1 | E37: 3 | G37: CONTENÇÃO | H37: SERVIÇO | I37: 02.002.001.003 | J37: Armação aço CA-50 ø 12,5mm para Contenções (corte e dobra em Indústria) | K37: un | L37: 3884 | M37: 8.484145 | N37: 32952.419 | P37: Pendente
A38: 0 | B38: 2 | C38: 2 | D38: 1 | E38: 4 | G38: CONTENÇÃO | H38: SERVIÇO | I38: 02.002.001.004 | J38: Armação aço CA-50 ø 25,0mm para Contenções (corte e dobra em Indústria) | K38: un | L38: 12007 | M38: 8.484145 | N38: 101869.13 | P38: Pendente
A39: 0 | B39: 2 | C39: 2 | D39: 2 | E39: 0 | H39: SUBETAPA | I39: 02.002.002 | J39: Concreto | N39: 175897.26 | O39: 10.501536
A40: 0 | B40: 2 | C40: 2 | D40: 2 | E40: 1 | G40: CONTENÇÃO | H40: SERVIÇO | I40: 02.002.002.001 | J40: Concreto Usinado bombeável 50MPa com Penetron para infraestrutura- incluindo serviço de bombeamento | K40: m3 | L40: 210 | M40: 837.606 | N40: 175897.26 | P40: Pendente
A41: 0 | B41: 2 | C41: 3 | D41: 0 | E41: 1 | H41: ETAPA | I41: 02.003 | J41: VIGAS COROAMENTO | N41: 37645.991 | O41: 2.2475661
A42: 0 | B42: 2 | C42: 3 | D42: 1 | E42: 0 | H42: SUBETAPA | I42: 02.003.001 | J42: Forma | N42: 2482.1879 | O42: 0.14819324
A43: 0 | B43: 2 | C43: 3 | D43: 1 | E43: 1 | G43: CONTENÇÃO | H43: SERVIÇO | I43: 02.003.001.001 | J43: Forma para infraestrutura em Tábuas de Madeira Serrada 2x reaproveitamento | K43: m2 | L43: 41.4 | M43: 59.956229 | N43: 2482.1879 | P43: Pendente
...

Sheet Orçamento
A1: DADOS
A2: Titulo | B2: ORÇAMENTO
A3: Obra | B3: ELECTRA TOWERS
A4: Cliente | B4: THOZEN
A5: Cidade | B5: Porto Belo
A6: Endereço
A7: Descrição
A8: UF | B8: SC
A10: RESUMO
A11: Tipo | C11: Preço | E11: Observação
A12: Total | C12: 21718825 | E12: Geral da edificação
A13: Material | C13: 15467433
A14: Execução | C14: 6251392.4
A16: TABELA DE ORÇAMENTO
A17: Item | B17: Referência | C17: Tipo | D17: Código | E17: Descrição | F17: Unid. | G17: Quantidade | H17: Custo unitário | I17: Preço total | J17: % | K17: Observação
A19: 1. | E19: 03. PAREDES E PAINÉIS | I19: 1964071 | J19: 0.090431735
A20: 1.1. | E20: ARQ_Embasamento | I20: 228660.08 | J20: 0.010528198
A21: 1.1.1. | E21: 03.001. Alvenaria de vedação com blocos cerâmicos | I21: 133087.99 | J21: 0.006127771
A22: 1.1.1.1 | E22: BLOCO CERAMICO, 0,05 (Parede padrão) | F22: m² | G22: 35.77 | H22: 0 | I22: 0
A23: 1.1.1.2 | E23: BLOCO CERAMICO, 0,09 (Parede padrão) | F23: m² | G23: 171.98 | H23: 0 | I23: 0
A24: 1.1.1.3 | B24: Thozen - Electra | C24: COMPOSICAO | D24: 4825 | E24: Alvenaria de vedação de blocos cerâmicos furados na horizontal de 11,5x19x19cm (espessura 11,5cm) com argamassa industrializada de assentamento | F24: m2 | G24: 1262.88 | H24: 25.096 | I24: 31693.236 | J24: 0.0014592519
A25: 1.1.1.4 | B25: Thozen - Electra | C25: COMPOSICAO | D25: 4826 | E25: Alvenaria de vedação de blocos cerâmicos furados na horizontal de 14x19x19cm (espessura 14cm) com argamassa industrializada de assentamento | F25: m2 | G25: 1610.87 | H25: 40.7664 | I25: 65669.371 | J25: 0.0030236152
A26: 1.1.1.5 | B26: Thozen - Electra | C26: COMPOSICAO | D26: 90472 | E26: Alvenaria de vedação de blocos cerâmicos furados na horizontal de 19x19x19cm (espessura 19cm) com argamassa industrializada de assentamento | F26: m2 | G26: 631.36 | H26: 56.5848 | I26: 35725.379 | J26: 0.0016449039
A27: 1.1.2. | E27: 03.002. Alvenaria de vedação com blocos de concreto | I27: 0
A28: 1.1.2.1 | E28: BLOCO CONCRETO, 0,05 (Parede padrão) | F28: m² | G28: 1.49 | H28: 0 | I28: 0
A29: 1.1.2.2 | E29: BLOCO ANTI CHAMAS, 0,125 (Parede padrão) | F29: m² | G29: 252.44 | H29: 0 | I29: 0
A30: 1.1.2.3 | E30: BLOCO ANTI CHAMAS, 0,15 (Parede padrão) | F30: m² | G30: 774.4 | H30: 0 | I30: 0
A31: 1.1.3. | E31: 03.003. Serviços complementares para alvenaria de vedação | I31: 95572.097 | J31: 0.0044004266
A32: 1.1.3.1 | B32: Thozen - Electra | C32: COMPOSICAO | D32: 4831 | E32: Verga/contraverga de concreto, moldada in loco | F32: m | G32: 104.16 | H32: 43.712512 | I32: 4553.0952 | J32: 0.00020963819
A33: 1.1.3.2 | B33: Thozen - Electra | C33: COMPOSICAO | D33: 4828 | E33: Encunhamento de alvenaria de vedação com argamassa expansiva | F33: m | G33: 18470.23 | H33: 3.633798 | I33: 67117.085 | J33: 0.0030902724
A34: 1.1.3.3 | B34: Thozen - Electra | C34: COMPOSICAO | D34: 4829 | E34: Tela soldada para ligação alvenaria/estrutura | F34: m² | G34: 2370.59 | H34: 1.85 | I34: 4385.5915 | J34: 0.00020192582
A35: 1.1.3.4 | B35: Thozen - Electra | C35: COMPOSICAO | D35: 4831 | E35: Verga/contraverga de concreto, moldada in loco | F35: m | G35: 446.47 | H35: 43.712512 | I35: 19516.325 | J35: 0.00089859028
A36: 1.1.4. | E36: 03.005. Mão de obra | I36: 0
A37: 1.1.4.1 | E37: Mão de obra alvenaria cerâmica | F37: m² | G37: 4045.19 | H37: 0 | I37: 0
A38: 1.1.4.2 | E38: Mão de obra blocos sílico calcário (Parede padrão) | F38: m² | G38: 1028.33 | H38: 0 | I38: 0
A39: 1.1.5. | E39: Alvenaria de vedação com tijolo refratário | I39: 0
A40: 1.1.5.1 | E40: TIJOLO REFRATARIO, 0,016 (Parede padrão) | F40: m² | G40: 14.56 | H40: 0 | I40: 0
A41: 1.2. | E41: ARQ_Impermeab | I41: 45754.495 | J41: 0.0021066745
A42: 1.2.1. | E42: 03.003. Serviços complementares para alvenaria de vedação | I42: 45754.495 | J42: 0.0021066745
A43: 1.2.1.1 | B43: Thozen - Electra | C43: COMPOSICAO | D43: 4828 | E43: Encunhamento de alvenaria de vedação com argamassa expansiva | F43: m | G43: 12591.37 | H43: 3.633798 | I43: 45754.495 | J43: 0.0021066745
...

Sheet Composições
A1: DADOS
A2: Titulo | B2: ORÇAMENTO
A3: Obra | B3: ELECTRA TOWERS
A4: Cliente | B4: THOZEN
A5: Cidade | B5: Porto Belo
A6: Endereço
A7: Descrição
A8: UF | B8: SC
A11: TABELA DE COMPOSIÇÕES UTILIZADAS
A12: Código | B12: Referência | C12: Tipo | D12: Tipo | E12: Descrição | F12: Unid. | G12: Multiplicador | H12: Preço | J12: Ref. Tabela | K12: Ref. Código | L12: Justificativa | M12: Grupo de Serviço | N12: Serviço
H13: Unitário | I13: Total
A14: 4825 | B14: Thozen - Electra | D14: Original | E14: Alvenaria de vedação de blocos cerâmicos furados na horizontal de 11,5x19x19cm (espessura 11,5cm) com argamassa industrializada de assentamento | F14: m2 | I14: 25.096 | N14: BLOCOS | O14: =A14&B14&C14 -> 4825Thozen - Electra
A15: 194 | B15: Thozen - Electra | C15: INSUMO | D15: Original | E15: ARGAMASSA ESTABILIZADA PARA ASSENTAMENTO | F15: m3 | G15: 0.0125 | H15: 480 | I15: 6
A16: 228 | B16: Thozen - Electra | C16: INSUMO | D16: Original | E16: BLOCO CERÂMICO 11,5X19X19CM | F16: un | G16: 17.36 | H16: 1.1 | I16: 19.096
A17: 4826 | B17: Thozen - Electra | D17: Original | E17: Alvenaria de vedação de blocos cerâmicos furados na horizontal de 14x19x19cm (espessura 14cm) com argamassa industrializada de assentamento | F17: m2 | I17: 40.7664 | N17: BLOCOS | O17: =A17&B17&C17 -> 4826Thozen - Electra
A18: 194 | B18: Thozen - Electra | C18: INSUMO | D18: Original | E18: ARGAMASSA ESTABILIZADA PARA ASSENTAMENTO | F18: m3 | G18: 0.022 | H18: 480 | I18: 10.56
A19: 232 | B19: Thozen - Electra | C19: INSUMO | D19: Original | E19: BLOCO CERÂMICO 14X19X19CM | F19: un | G19: 17.36 | H19: 1.74 | I19: 30.2064
A20: 90472 | B20: Thozen - Electra | D20: Original | E20: Alvenaria de vedação de blocos cerâmicos furados na horizontal de 19x19x19cm (espessura 19cm) com argamassa industrializada de assentamento | F20: m2 | I20: 56.5848 | N20: BLOCOS | O20: =A20&B20&C20 -> 90472Thozen - Electra
A21: 194 | B21: Thozen - Electra | C21: INSUMO | D21: Original | E21: ARGAMASSA ESTABILIZADA PARA ASSENTAMENTO | F21: m3 | G21: 0.03 | H21: 480 | I21: 14.4
A22: 48433 | B22: Thozen - Electra | C22: INSUMO | D22: Original | E22: BLOCO CERÂMICO 19X19X19CM | F22: un | G22: 17.36 | H22: 2.43 | I22: 42.1848
A23: 4831 | B23: Thozen - Electra | D23: Original | E23: Verga/contraverga de concreto, moldada in loco | F23: m | I23: 43.712512 | O23: =A23&B23&C23 -> 4831Thozen - Electra
A24: 759 | B24: Thozen - Electra | C24: INSUMO | D24: Original | E24: CONCRETO USINADO FCK 20 MPA, SLUMP 14+/-2 | F24: m3 | G24: 0.0264 | H24: 450 | I24: 11.88
A25: 4800 | B25: Thozen - Electra | C25: INSUMO | D25: Original | E25: DESMOLDANTE DE FORMAS PARA CONCRETO | F25: l | G25: 0.007 | H25: 6.45 | I25: 0.04515
A26: 1412 | B26: Thozen - Electra | C26: INSUMO | D26: Original | E26: ESPAÇADOR PLÁSTICO | F26: un | G26: 6 | H26: 0.15 | I26: 0.9
A27: 2324 | B27: Thozen - Electra | C27: INSUMO | D27: Original | E27: PONTALETE 7,5X7,5 CM PINUS | F27: m3 | G27: 0.0012 | H27: 1310 | I27: 1.572
A28: 2362 | B28: Thozen - Electra | C28: INSUMO | D28: Original | E28: PREGO POLIDO COM CABEÇA 17X21 | F28: kg | G28: 0.0512 | H28: 10.91 | I28: 0.558592
A29: 2546 | B29: Thozen - Electra | C29: INSUMO | D29: Original | E29: SARRAFO 2,5X7,5 CM PINUS | F29: m3 | G29: 0.003171 | H29: 1300 | I29: 4.1223
A30: 2611 | B30: Thozen - Electra | C30: INSUMO | D30: Original | E30: TÁBUA 1"X12" 2,5X30CM PINUS | F30: m3 | G30: 0.011676 | H30: 1800 | I30: 21.0168
A31: 32 | B31: Thozen - Electra | C31: INSUMO | D31: Original | E31: AÇO CA-50 DIÂMETRO 6,30 MM | F31: kg | G31: 0.5243 | H31: 6.9 | I31: 3.61767
A32: 4828 | B32: Thozen - Electra | D32: Original | E32: Encunhamento de alvenaria de vedação com argamassa expansiva | F32: m | I32: 3.633798 | N32: ENCUNHAMENTO | O32: =A32&B32&C32 -> 4828Thozen - Electra
A33: 48435 | B33: Thozen - Electra | C33: INSUMO | D33: Original | E33: ARGAMASSA EXPANSIVA PARA ENCUNHAMENTO | F33: Kg | G33: 0.2154 | H33: 16.87 | I33: 3.633798
A34: 4829 | B34: Thozen - Electra | D34: Original | E34: Tela soldada para ligação alvenaria/estrutura | F34: m² | I34: 1.85 | O34: =A34&B34&C34 -> 4829Thozen - Electra
A35: 718 | B35: Thozen - Electra | C35: INSUMO | D35: Original | E35: CARTUCHO 22 - CARGA LEVE PARA FINCA PINO E POLVORA | F35: un | G35: 1 | H35: 0.3 | I35: 0.3
A36: 2260 | B36: Thozen - Electra | C36: INSUMO | D36: Original | E36: PINO LISO EM AÇO GALVANIZADO 1/2 X 22MM COM ARRUELA | F36: un | G36: 1 | H36: 0.3 | I36: 0.3
A37: 2901 | B37: Thozen - Electra | C37: INSUMO | D37: Original | E37: TELA DE ACO SOLDADA, FIO 1,24MM, MALHA 15X15MM | F37: m2 | G37: 0.5 | H37: 2.5 | I37: 1.25
A38: 4842 | B38: Thozen - Electra | D38: Original | E38: Impermeabilização com argamassa polimérica, 3 demãos | F38: m2 | I38: 36.225 | O38: =A38&B38&C38 -> 4842Thozen - Electra
A39: 202 | B39: Thozen - Electra | C39: INSUMO | D39: Original | E39: ARGAMASSA POLIMÉRICA IMPERMEABILIZANTE | F39: kg | G39: 3.15 | H39: 11.5 | I39: 36.225
A40: 90541 | B40: Thozen - Electra | D40: Original | E40: Chapisco adesivo aplicado em concreto, com desempenadeira dentada | F40: m2 | I40: 6.459 | N40: CHAPISCO | O40: =A40&B40&C40 -> 90541Thozen - Electra
A41: 197 | B41: Thozen - Electra | C41: INSUMO | D41: Original | E41: ARGAMASSA ESTABILIZADA PARA REBOCO | F41: m3 | G41: 0.0033 | H41: 480 | I41: 1.584
A42: 48481 | B42: Thozen - Electra | C42: INSUMO | D42: Original | E42: ADITIVO ADESIVO LÍQUIDO PARA ARGAMASSA | F42: L | G42: 0.625 | H42: 7.8 | I42: 4.875
...

Sheet Insumos (2)
A1: DADOS
A2: Titulo | B2: Tabela de insumos utilizados no projeto
A3: Obra | B3: ELECTRA TOWERS
A4: Cliente | B4: THOZEN
A5: Cidade | B5: Porto Belo
A6: Endereço
A7: Descrição
A8: UF | B8: SC
A11: INSUMOS UTILIZADOS
A12: Código | B12: Tabela | C12: Tipo | D12: Descrição | E12: Unid. | F12: Preço | G12: Origem custo | H12: Justificativa
A14: 194 | B14: Thozen - Electra | C14: Material | D14: ARGAMASSA ESTABILIZADA PARA ASSENTAMENTO | E14: m3 | F14: 480 | I14: =A14&B14 -> 194Thozen - Electra
A15: 228 | B15: Thozen - Electra | C15: Material | D15: BLOCO CERÂMICO 11,5X19X19CM | E15: un | F15: 1.1 | I15: =A15&B15 -> 228Thozen - Electra
A16: 232 | B16: Thozen - Electra | C16: Material | D16: BLOCO CERÂMICO 14X19X19CM | E16: un | F16: 1.74 | I16: =A16&B16 -> 232Thozen - Electra
A17: 48433 | B17: Thozen - Electra | C17: Material | D17: BLOCO CERÂMICO 19X19X19CM | E17: un | F17: 2.43 | I17: =A17&B17 -> 48433Thozen - Electra
A18: 759 | B18: Thozen - Electra | C18: Material | D18: CONCRETO USINADO FCK 20 MPA, SLUMP 14+/-2 | E18: m3 | F18: 450 | I18: =A18&B18 -> 759Thozen - Electra
A19: 4800 | B19: Thozen - Electra | C19: Material | D19: DESMOLDANTE DE FORMAS PARA CONCRETO | E19: l | F19: 6.45 | I19: =A19&B19 -> 4800Thozen - Electra
A20: 1412 | B20: Thozen - Electra | C20: Material | D20: ESPAÇADOR PLÁSTICO | E20: un | F20: 0.15 | I20: =A20&B20 -> 1412Thozen - Electra
A21: 2324 | B21: Thozen - Electra | C21: Material | D21: PONTALETE 7,5X7,5 CM PINUS | E21: m3 | F21: 1310 | I21: =A21&B21 -> 2324Thozen - Electra
A22: 2362 | B22: Thozen - Electra | C22: Material | D22: PREGO POLIDO COM CABEÇA 17X21 | E22: kg | F22: 10.91 | I22: =A22&B22 -> 2362Thozen - Electra
A23: 2546 | B23: Thozen - Electra | C23: Material | D23: SARRAFO 2,5X7,5 CM PINUS | E23: m3 | F23: 1300 | I23: =A23&B23 -> 2546Thozen - Electra
A24: 2611 | B24: Thozen - Electra | C24: Material | D24: TÁBUA 1"X12" 2,5X30CM PINUS | E24: m3 | F24: 1800 | I24: =A24&B24 -> 2611Thozen - Electra
A25: 32 | B25: Thozen - Electra | C25: Material | D25: AÇO CA-50 DIÂMETRO 6,30 MM | E25: kg | F25: 6.9 | G25: GERDAU | I25: =A25&B25 -> 32Thozen - Electra
A26: 48435 | B26: Thozen - Electra | C26: Material | D26: ARGAMASSA EXPANSIVA PARA ENCUNHAMENTO | E26: Kg | F26: 16.87 | I26: =A26&B26 -> 48435Thozen - Electra
A27: 718 | B27: Thozen - Electra | C27: Material | D27: CARTUCHO 22 - CARGA LEVE PARA FINCA PINO E POLVORA | E27: un | F27: 0.3 | I27: =A27&B27 -> 718Thozen - Electra
A28: 2260 | B28: Thozen - Electra | C28: Material | D28: PINO LISO EM AÇO GALVANIZADO 1/2 X 22MM COM ARRUELA | E28: un | F28: 0.3 | I28: =A28&B28 -> 2260Thozen - Electra
A29: 2901 | B29: Thozen - Electra | C29: Material | D29: TELA DE ACO SOLDADA, FIO 1,24MM, MALHA 15X15MM | E29: m2 | F29: 2.5 | I29: =A29&B29 -> 2901Thozen - Electra
A30: 202 | B30: Thozen - Electra | C30: Material | D30: ARGAMASSA POLIMÉRICA IMPERMEABILIZANTE | E30: kg | F30: 11.5 | I30: =A30&B30 -> 202Thozen - Electra
A31: 197 | B31: Thozen - Electra | C31: Material | D31: ARGAMASSA ESTABILIZADA PARA REBOCO | E31: m3 | F31: 480 | I31: =A31&B31 -> 197Thozen - Electra
A32: 48481 | B32: Thozen - Electra | C32: Material | D32: ADITIVO ADESIVO LÍQUIDO PARA ARGAMASSA | E32: L | F32: 7.8 | I32: =A32&B32 -> 48481Thozen - Electra
A33: 48373 | B33: Thozen - Electra | C33: Material | D33: CHAPISCO COLANTE 20KG | E33: Kg | F33: 1.31 | I33: =A33&B33 -> 48373Thozen - Electra
A34: 2154 | B34: Thozen - Electra | C34: Mao_obra | D34: MÃO DE OBRA PARA EXECUÇÃO DE CHAPISCO E REBOCO INTERNO EM PAREDES | E34: m2 | F34: 35 | I34: =A34&B34 -> 2154Thozen - Electra
A35: 193 | B35: Thozen - Electra | C35: Material | D35: ARGAMASSA COLANTE AC III | E35: kg | F35: 2.345 | I35: =A35&B35 -> 193Thozen - Electra
A36: 4881 | B36: Thozen - Electra | C36: Material | D36: ESPAÇADOR PARA REVESTIMENTO CERÂMICO TIPO CRUZETA 5 MM | E36: un | F36: 0.2 | I36: =A36&B36 -> 4881Thozen - Electra
A37: 4880 | B37: Thozen - Electra | C37: Material | D37: REJUNTE FLEXÍVEL | E37: m2 | F37: 2.0643 | I37: =A37&B37 -> 4880Thozen - Electra
... A61: 2552 | B61: Thozen - Electra | C61: Material | D61: SELADOR ACRÍLICO | E61: l | F61: 9.44 | I61: =A61&B61 -> 2552Thozen - Electra

Sheet PROJETOS
B1: GESTÃO DOS PROJETOS | J1: LEGENDA
A2: Obra | B2: Electra Towers (Rubens Alves) | J2: NÃO SE APLICA
A3: Empresa | B3: Thozen Empreendimentos | J3: PENDENTE
A4: Revisão | B4: R01 | J4: RECEBIDO
B5: PAVIMENTO | C5: DISCIPLINA | D5: PROJETOS | E5: CAMINHO | F5: STATUS | G5: OBSERVAÇÕES | J5: REVISADO
B7: ESTRUTURA
B8: TERRAPLENAGEM | C8: INFRAESTRUTURA | F8: NÃO SE APLICA
B9: MOVIMENTAÇÃO DE TERRA | C9: INFRAESTRUTURA | F9: PENDENTE
B10: FUNDAÇÃO PROFUNDA | C10: INFRAESTRUTURA | D10: 1203 - PREFORMAS - R20.DWG | E10: 01 ESTRUTURA/DWG | F10: RECEBIDO | G10: DWG Pré-formas Rev.20
B11: FUNDAÇÃO RASA | C11: INFRAESTRUTURA | D11: 1203 - THOZEN - RUBENS ALVES - BLOCOS+RAMPAS DE ACESSO - R26.ifc | E11: 01 ESTRUTURA/IFC | F11: RECEBIDO | G11: IFC Blocos + Rampas de Acesso Rev.26
B12: CONTENÇÃO | C12: INFRAESTRUTURA | F12: NÃO SE APLICA
B13: ÁREA – 1º PAVTO. (TÉRREO) | C13: SUPRAESTRUTURA | F13: RECEBIDO | G13: Coberto pelo IFC estrutural completo
B14: ÁREA – MEZANINO DO 1º PAVTO. | C14: SUPRAESTRUTURA | F14: RECEBIDO | G14: Coberto pelo IFC estrutural completo
B15: ÁREA – 2º PAVIMENTO | C15: SUPRAESTRUTURA | F15: RECEBIDO | G15: Coberto pelo IFC estrutural completo
B16: ÁREA – MEZANINO DO 2º PAVTO. | C16: SUPRAESTRUTURA | F16: RECEBIDO | G16: Coberto pelo IFC estrutural completo
B17: ÁREA – 3º PAVIMENTO | C17: SUPRAESTRUTURA | F17: RECEBIDO | G17: Coberto pelo IFC estrutural completo
B18: ÁREA – MEZANINO DO 3º PAVTO. | C18: SUPRAESTRUTURA | F18: RECEBIDO | G18: Coberto pelo IFC estrutural completo
B19: ÁREA – 4º PAVIMENTO GARAGEM/LAZER | C19: SUPRAESTRUTURA | F19: RECEBIDO | G19: Coberto pelo IFC estrutural completo
B20: ÁREA – 5º PAVIMENTO LAZER | C20: SUPRAESTRUTURA | F20: RECEBIDO | G20: Coberto pelo IFC estrutural completo
B21: ÁREA – 6º PAVIMENTO TIPO - DIFERENCIADO | C21: SUPRAESTRUTURA | F21: RECEBIDO | G21: Coberto pelo IFC estrutural completo
B22: ÁREA – 7º AO 14° PAVIMENTO TIPO - X8 | C22: SUPRAESTRUTURA | F22: RECEBIDO | G22: Coberto pelo IFC estrutural completo
B23: ÁREA – 15º AO 35° PAVIMENTO TIPO - X21 | C23: SUPRAESTRUTURA | F23: RECEBIDO | G23: Coberto pelo IFC estrutural completo
B24: ARQUITETURA
B25: TERRAPLENAGEM | C25: ARQUITETURA | F25: NÃO SE APLICA
B26: MOVIMENTAÇÃO DE TERRA | C26: ARQUITETURA | F26: NÃO SE APLICA
B27: FUNDAÇÃO PROFUNDA | C27: ARQUITETURA | F27: NÃO SE APLICA
B28: FUNDAÇÃO RASA | C28: ARQUITETURA | F28: NÃO SE APLICA
B29: CONTENÇÃO | C29: ARQUITETURA | F29: NÃO SE APLICA
B30: TÉRREO 01 | C30: ARQUITETURA | D30: RA_ARQ_EXE_01_TÉRREO_R02.dwg | E30: 02 ARQUITETURA/DWG | F30: RECEBIDO | G30: DWG Executivo Rev.02
B31: TÉRREO 02 | C31: ARQUITETURA | D31: RA_ARQ_EXE_10_CORTE1_R02.dwg + RA_ARQ_EXE_11_CORTE2_R02.dwg | E31: 02 ARQUITETURA/DWG | F31: RECEBIDO | G31: Cortes 1 e 2, Rev.02
B32: GARAGEM 01 | C32: ARQUITETURA | D32: RA_ARQ_EXE_02_G1_R02.dwg | E32: 02 ARQUITETURA/DWG | F32: RECEBIDO | G32: DWG Executivo Rev.02
B33: GARAGEM 02 | C33: ARQUITETURA | D33: RA_ARQ_EXE_03_G2_R02.dwg | E33: 02 ARQUITETURA/DWG | F33: RECEBIDO | G33: DWG Executivo Rev.02
B34: GARAGEM 03 | C34: ARQUITETURA | D34: RA_ARQ_EXE_04_G3_R02.dwg | E34: 02 ARQUITETURA/DWG | F34: RECEBIDO | G34: DWG Executivo Rev.02
B35: GARAGEM 04 | C35: ARQUITETURA | D35: RA_ARQ_EXE_05_G4_R02.dwg | E35: 02 ARQUITETURA/DWG | F35: RECEBIDO | G35: DWG Executivo Rev.02
B36: LAZER 01 | C36: ARQUITETURA | D36: RA_ARQ_EXE_06_G5_R02.dwg | E36: 02 ARQUITETURA/DWG | F36: RECEBIDO | G36: DWG Executivo Rev.02
B37: LAZER 02 | C37: ARQUITETURA | D37: RA_ARQ_EXE_07_LAZER_R02.dwg | E37: 02 ARQUITETURA/DWG | F37: RECEBIDO | G37: DWG Executivo Rev.02
B38: TIPO DIFERENCIADO 01 | C38: ARQUITETURA | D38: RA_ARQ_EXE_MODELAGEM EMBASAMENTO + COBERTURA_R08.ifc | E38: 02 ARQUITETURA/IFC | F38: RECEBIDO | G38: IFC Embasamento + Cobertura Rev.08
B39: TIPO DIFERENCIADO 02 | C39: ARQUITETURA | D39: RA_ARQ_EXE_MODELAGEM TIPO_R07.ifc | E39: 02 ARQUITETURA/IFC | F39: RECEBIDO | G39: IFC Tipo Rev.07
B40: TIPO (30x) | C40: ARQUITETURA | D40: RA_ARQ_EXE_08_TIPOS_R02.dwg | E40: 02 ARQUITETURA/DWG | F40: RECEBIDO | G40: DWG Executivo Rev.02
B41: DUPLEX INFERIOR (3x) | C41: ARQUITETURA | F41: NÃO SE APLICA
...

Sheet Ger_Tec e Adm
A4: PROJETO: | C4: Electra Towers | I4: REVISÃO: | J4: DATA
A5: EMPRESA: | C5: Thozen | I5: R00
A6: GERENCIAMENTO EXECUTIVO
A7: Atalho | B7: NIVEL | C7: Item | D7: Descrição | E7: Unidade | F7: Quant. | G7: Preço un | H7: Total | I7: Considerações | J7: Situação
B8: CÉLULA CONSTRUTIVA | C8: 01 | D8: SERVIÇOS TÉCNICOS | H8: =H9+H57 -> 3668982.5
B9: ETAPA | C9: 01.001 | D9: ESTUDOS, PROJETOS E CONSULTORIAS | H9: =H10+H20+H41+H46 -> 2273047.4 | J9: -
B10: SUBETAPA | C10: 01.001.001 | D10: Estudos | H10: =H11+H12+H13+H14+H15+H16+H17+H18+H19 -> 260925.31
B11: SERVIÇO | C11: 01.001.001.001 | D11: Memorial descritivo | E11: vb | F11: 1 | G11: 18386.35 | H11: =G11*F11 -> 18386.35 | I11: Estimado | J11: Lançado ERP
B12: SERVIÇO | C12: 01.001.001.002 | D12: Levantamento topográfico | E12: vb | F12: 1 | G12: 3000 | H12: =G12*F12 -> 3000 | I12: Recebido | J12: Lançado ERP
B13: SERVIÇO | C13: 01.001.001.003 | D13: Estudo geológico | E13: vb | F13: 1 | G13: 26930.408 | H13: =G13*F13 -> 26930.408 | I13: Estimado | J13: Lançado ERP
B14: SERVIÇO | C14: 01.001.001.004 | D14: Estudo ambiental | E14: vb | F14: 1 | G14: 4500 | H14: =G14*F14 -> 4500 | I14: Recebido | J14: Lançado ERP
B15: SERVIÇO | C15: 01.001.001.005 | D15: Sondagem do terreno | E15: vb | F15: 1 | G15: 7947.99 | H15: =G15*F15 -> 7947.99 | I15: Recebido | J15: Lançado ERP
B16: SERVIÇO | C16: 01.001.001.006 | D16: Projeto de canteiro | E16: vb | F16: 1 | G16: 11160.563 | H16: =G16*F16 -> 11160.563 | I16: Estimado | J16: Lançado ERP
B17: SERVIÇO | C17: 01.001.001.007 | D17: EFEG - Teste de Carga | E17: vb | F17: 1 | G17: 29000 | H17: =G17*F17 -> 29000 | I17: Recebido | J17: Lançado ERP
B18: SERVIÇO | C18: 01.001.001.008 | D18: Solugeot - Teste de Carga | E18: vb | F18: 1 | G18: 140000 | H18: =G18*F18 -> 140000 | I18: Recebido | J18: Lançado ERP
