Workbook

Sheet Dados Gerais
A2: ORÇAMENTO PARAMÉTRICO GERENCIAMENTO EXECUTIVO
A7: Documento | B7: CTN_STM_UNI Orçamento Preliminar
A8: Cliente | B8: Santa Maria
A9: Obra | B9: Unimed
A10: Data | B10: 45266 | E10: Revisão | F10: R01 | G10: Status | H10: Em andamento | I10: Responsável | J10: Amanda
A12: Descrição | D12: Identificador | E12: Informação
A13: Área do terreno | D13: AT | E13: 2671.88 | H13: m² | I13: OK
A14: Testada do terreno | D14: TT | E14: 47.74 | H14: m | I14: OK
A15: Área total construída | D15: AC | E15: 52516.04 | H15: m² | I15: OK
A16: N° total de pavimentos | D16: NP | E16: 35 | H16: un | I16: OK
A17: N° de pavimentos tipo | D17: NPT | E17: 21 | H17: un | I17: OK
A18: N° de pavimentos tipo diferenciado | D18: NPD | E18: 0 | H18: un | I18: OK | O18: 2368.23
A19: N° de pavimentos duplex | D19: ND | E19: 0 | H19: un | I19: OK | O19: 2314.98
A20: Área de projeção da torre | D20: APT | E20: 1700.42 | H20: m² | I20: OK | O20: 2314.98
A21: Perímetro de projeção da torre | D21: PPT | E21: 234.93 | H21: m | I21: OK | O21: 2314.98
A22: Área Lazer | D22: AL | E22: 2031.39 | H22: m² | I22: OK | O22: 2319.46
A23: Locação da obra | D23: LC | E23: 268.93 | H23: m | I23: OK | O23: 2048.87
A24: Área do embasamento | D24: AE | E24: 19828.1 | H24: m² | I24: OK | O24: 2048.87
A25: Área de subsolos | D25: AS | E25: 2193.38 | H25: m² | I25: OK | O25: 2048.87
A26: N° de subsolos | D26: NS | E26: 1 | H26: un | I26: OK | O26: 2048.87
A27: Área de projeção do embasamento | D27: APE | E27: 2670.58 | H27: m² | I27: OK | O27: =SUM(O18:O26) -> 19828.11
A28: Perímetro de projeção embasamento | D28: PPE | E28: 268.93 | H28: m | I28: OK
A29: N° de pavimentos de embasamento | D29: NPE | E29: 10 | H29: un | I29: Térreo, mezanino, garagens e lazer

Sheet Resumo
A2: ORÇAMENTO PARAMÉTRICO GERENCIAMENTO EXECUTIVO
A7: Documento | B7: MTH_ART-RES Orçamento Paramétrico
A8: Cliente | B8: P&B Incoporadora LTDA
A9: Obra | B9: Ilhas de Porto Belo
A10: Data | B10: 45170 | E10: Revisão | F10: R01 | G10: Status | H10: Em andamento | I10: Responsável | J10: Amanda/Luisa
A12: MOVIMENTAÇÃO DE TERRA
A14: Descrição | D14: Valor total
A15: ='Movimentação de Terra'!A19 -> REBAIXAMENTO DE LENÇOL | D15: ='Movimentação de Terra'!I23 -> 1500
A16: ='Movimentação de Terra'!A33 -> ESCAVAÇÃO E REATERRO DE VALAS | D16: ='Movimentação de Terra'!I39+'Movimentação de Terra'!I30 -> 456566.38
A17: ='Movimentação de Terra'!A42 -> REGULARIZAÇÃO E APILOAMENTO DE FUNDO DE VALAS | D17: ='Movimentação de Terra'!I46 -> 35550
A18: TOTAL | D18: =SUM(D15:H17) -> 493616.38
A22: INFRAESTRUTURA
A24: Descrição | D24: Valor total
A25: =Infraestrutura!#REF! -> #REF! | D25: =Infraestrutura!#REF! -> #REF!
A26: =Infraestrutura!A24 -> FUNDAÇÃO RASA | D26: =Infraestrutura!I31 -> 4309171.6
A27: TOTAL | D27: =SUM(D25:H26) -> #REF!
A30: SUPRAESTRUTURA
A32: Descrição | D32: Valor total
A33: =+Supraestrutura!A12 -> SUPRAESTRUTURA | D33: =+Supraestrutura!I22 -> 35464738
A34: TOTAL | D34: =SUM(D33:H33) -> 35464738
A37: ALVENARIA
A39: Descrição | D39: Valor total
A40: =+Alvenaria!A12 -> ALVENARIA | D40: =+Alvenaria!I21 -> 6057180.1
A41: TOTAL | D41: =SUM(D40) -> 6057180.1
A44: INSTALAÇÕES
A46: Descrição | D46: Valor total
A47: =+Instalações!A12 -> INSTALAÇÕES ELÉTRICAS | D47: =+Instalações!I22 -> 9190307
A48: =+Instalações!A24 -> INSTALAÇÕES HIDRÁULICAS | D48: =+Instalações!I35 -> 8822694.7
A49: =+Instalações!A38 -> INSTALAÇÕES PREVENTIVAS E GLP | D49: =+Instalações!I44 -> 4463863.4
A50: TOTAL | D50: =SUM(D47:H49) -> 22476865
A53: SISTEMAS ESPECIAIS
A55: Descrição | D55: Valor total
A56: ='Sistemas especiais'!A12 -> CLIMATIZAÇÃO, EXAUSTÃO MECÂNICA E PRESSURIZAÇÃO | D56: ='Sistemas especiais'!I20 -> 4101000
A57: ='Sistemas especiais'!A32 -> AUTOMAÇÃO | D57: ='Sistemas especiais'!I36 -> 787740.6
A58: COMUNICAÇÃO | D58: ='Sistemas especiais'!I29 -> 1312901
A59: ='Sistemas especiais'!A39 -> OUTROS SISTEMAS ESPECIAIS | D59: ='Sistemas especiais'!I43 -> 1050320.8
A60: ='Sistemas especiais'!A46 -> EQUIPAMENTOS | D60: ='Sistemas especiais'!I52 -> 10777568
A61: TOTAL | D61: =SUM(D56:H60) -> 18029531
A64: IMPERMEABILIZAÇÃO
A66: Descrição | D66: Valor total
...

Sheet Movimentação de Terra
A2: ORÇAMENTO PARAMÉTRICO MOVIMENTAÇÃO DE TERRA
A7: Documento | B7: CTN_STM_UNI Orçamento Preliminar
A8: Cliente | B8: Santa Maria
A9: Obra | B9: Unimed
A10: Data | B10: 45266 | E10: Revisão | F10: R01 | G10: Status | H10: Em andamento | I10: Responsável | J10: Amanda
A12: ESCAVAÇÃO
A14: Descrição | D14: Quantidade | F14: Parâmetro | H14: Referência | I14: Valor total
A15: Escavação | D15: =+'[1]Dados Gerais'!E25*3.06 -> 0 | E15: m³ | F15: 28.5 | G15: R$ / m³ | H15: Pedro Chaves | I15: =+D15*F15 -> 0
A16: TOTAL | I16: =SUM(I15:J15) -> 0
A19: REBAIXAMENTO DE LENÇOL
A21: Descrição | D21: Quantidade | F21: Parâmetro | H21: Referência | I21: Valor total
A22: Rebaixamento de Lençol | D22: 10 | E22: dias | F22: 150 | G22: R$ / dia | H22: Média | I22: =F22*D22 -> 1500
A23: TOTAL | I23: =SUM(I22:J22) -> 1500
A26: ESCAVAÇÃO VERTICAL PARA SUBSOLO
A28: Descrição | D28: Quantidade | F28: Parâmetro | H28: Referência | I28: Valor total
A29: Escavação vertical | D29: ='Dados Gerais'!E25*1.5 -> 3290.07 | E29: m³ | F29: 1.5 | G29: m³ / AS | H29: Média | I29: =D29*80 -> 263205.6
A30: TOTAL | I30: =SUM(I29:J29) -> 263205.6
A33: ESCAVAÇÃO E REATERRO DE VALAS
A35: Descrição | D35: Quantidade | F35: Parâmetro | H35: Referência | I35: Valor total
A36: Escavação mecanizada para blocos e baldrames | D36: =Infraestrutura!D29*1.3 -> 1389.3776 | E36: m³ | F36: 0.5 | G36: m³ / AE | H36: Média | I36: =+ROUNDUP((F36*'Dados Gerais'!$E$13*65),0) -> 86837
A37: Reaterro para blocos e baldrames | D37: =D36-Infraestrutura!D29 -> 320.6256 | E37: m³ | F37: 0.2 | G37: m³ / AE | H37: Média | I37: =+ROUNDUP((F37*'Dados Gerais'!$E$13*15),0) -> 8016
A38: Movimentação de terra das estacas | D38: =Infraestrutura!D19*F38 -> 2189.0618 | E38: m³ | F38: 1.3 | G38: m³ / m³ | H38: Média | I38: =+D38*45 -> 98507.779
A39: TOTAL | I39: =SUM(I36:J38) -> 193360.78
A42: REGULARIZAÇÃO E APILOAMENTO DE FUNDO DE VALAS
A44: Descrição | D44: Quantidade | F44: Parâmetro | H44: Referência | I44: Valor total
A45: Lastro de concreto magro e= 10cm - Blocos | D45: =+F45*'Dados Gerais'!E22 -> 1015.695 | E45: m² | F45: 0.5 | G45: m² / AE | H45: Média | I45: =ROUNDUP((D45*35),0) -> 35550
A46: TOTAL | I46: =SUM(I45:J45) -> 35550
J49: =I46+I39+I23+I30 -> 493616.38 | K49: =J49/'Dados Gerais'!E15 -> 9.399345

Sheet Infraestrutura
A2: ORÇAMENTO PARAMÉTRICO INFRAESTRUTURA
A7: Documento | B7: CTN_STM_UNI Orçamento Preliminar
A8: Cliente | B8: Santa Maria
A9: Obra | B9: Unimed
A10: Data | B10: 45266 | E10: Revisão | F10: R01 | G10: Status | H10: Em andamento | I10: Responsável | J10: Amanda
A12: FUNDAÇÃO PROFUNDA
A14: Descrição | D14: Quantidade | F14: Parâmetro | H14: Referência | I14: Valor total
A15: Número de Estacas | D15: =ROUNDUP(F15*'Dados Gerais'!E27,0) -> 268 | E15: un | F15: 0.1 | G15: un / APE | H15: Média | I15: -
A16: Número de Estacas Raiz | D16: =D15 -> 268 | E16: un | F16: 100 | G16: % | H16: Média | I16: -
A17: Estaca Escavada Diâmetro 100 Raiz | D17: =ROUNDUP((F17*D16),0) -> 2144 | E17: m | F17: 8 | G17: m / un | H17: Média | I17: =+ROUNDUP((D17*120),0) -> 257280
A18: Armação | D18: =F18*D19 -> 168389.37 | E18: kg | F18: 100 | G18: kg / m³ | H18: Média | I18: =+ROUNDUP((D18*8.5),0) -> 1431310
A19: Concreto | D19: =PI()*((1^2)/4)*D17 -> 1683.8937 | E19: m³ | F19: 650 | G19: R$ / m³ | H19: Média | I19: =+ROUNDUP((D19*F19),0)*1.1 -> 1203984.1
A20: Mobilização | D20: 1 | E20: vb | F20: 150000 | G20: R$ | H20: Média | I20: =+ROUNDUP((D20*F20),0) -> 150000
A21: TOTAL | I21: =SUM(I15:I20) -> 3042574.1
A24: FUNDAÇÃO RASA
A26: Descrição | D26: Quantidade | F26: Parâmetro | H26: Referência | I26: Valor total
A27: Fabricação, montagem e desmontagem de forma para blocos e baldrames | D27: =D29/0.4 -> 2671.88 | E27: m² | F27: 0.76 | G27: m² / AT | H27: Média | I27: =+D27*60 -> 160312.8 | L27: consideração de altura média de bloco de 40cm
A28: Armação | D28: =D29*F28 -> 106875.2 | E28: kg | F28: 100 | G28: kg / m³ | H28: Média | I28: =+D28*8.1 -> 865689.12
A29: Concreto | D29: =F29*'Dados Gerais'!E13 -> 1068.752 | E29: m³ | F29: 0.4 | G29: m³ / AT | H29: Média | I29: =+D29*650*1.05 -> 729423.24
A30: Mão de obra | D30: 7093.74 | E30: m² | F30: 240 | G30: R$ / AT | H30: Média | I30: =+D30*F30*1.5 -> 2553746.4 | L30: Consideração de área do térreo
A31: TOTAL | I31: =SUM(I27:J30) -> 4309171.6
A34: CONTENÇÃO
A36: Descrição | D36: Quantidade | F36: Parâmetro | H36: Referência | I36: Valor total
A37: Número de Estacas | D37: 237 | E37: un | F37: 1.25 | G37: un / m | H37: Média | I37: 0
A38: Estaca Raiz Diâmetro 310 | D38: 143 | E38: un | F38: 100 | G38: % | H38: Média | I38: 0
A39: Estaca Raiz Diâmetro 310 | D39: =ROUNDUP((F39*D38),0) -> 429 | E39: m | F39: 3 | G39: m / un | H39: Média | I39: =+ROUNDUP((D39*150),0) -> 64350
A40: Estaca Raiz Diâmetro 250 | D40: 94 | E40: un | F40: 100 | G40: % | H40: Média | I40: 0
A41: Estaca Raiz Diâmetro 250 | D41: =ROUNDUP((F41*D40),0) -> 282 | E41: m | F41: 3 | G41: m / un | H41: Média | I41: =+ROUNDUP((D41*150),0) -> 42300
A42: Armação | D42: =D39*F42 -> 34320 | E42: kg | F42: 80 | G42: kg / m3 | H42: Média | I42: =+D42*8.5 -> 291720
A43: Concreto | D43: =PI()*(0.25^2)*D39 -> 84.233953 | E43: m³ | F43: =D43/'Dados Gerais'!E13 -> 0.031526099 | G43: m³ / AT | H43: Média | I43: =+D43*630*1.2 -> 63680.868
A44: Forma para viga de coroamento - 50x30 | D44: ='Dados Gerais'!E28*0.5*0.3 -> 40.3395 | E44: m2 | F44: 50 | G44: R$ / m² | H44: Média | I44: =+D44*F44 -> 2016.975
A45: Concreto para viga de coroamento | D45: ='Dados Gerais'!E28*0.5*0.3 -> 40.3395 | E45: m3 | F45: =555+35 -> 590 | G45: R$ / m³ | H45: Média | I45: =+D45*F45*1.05 -> 24990.32
A46: Armação para viga de coroamento | D46: =D45*F46 -> 3227.16 | E46: vb | F46: 80 | G46: kg / m3 | H46: Média | I46: =+D46*7.3 -> 23558.268
A47: Mão de obra para viga de coroamento | D47: =D45 -> 40.3395 | E47: m3 | F47: 950 | G47: R$ / m3 | H47: Média | I47: =+D47*F47 -> 38322.525
A48: Mão de obra armação | D48: =D42 -> 34320 | E48: kg | F48: 2.5 | G48: R$ / kg | H48: Média | I48: =+D48*F48 -> 85800
A49: Mão de obra concretagem | D49: =D43 -> 84.233953 | E49: m³ | F49: 600 | G49: R$ / m³ | H49: Média | I49: =+D49*F49 -> 50540.372
A50: Mobilização | D50: 1 | E50: vb | F50: 100000 | G50: R$ | H50: Média | I50: =+D50*F50 -> 100000
A51: TOTAL | I51: =SUM(I37:J50) -> 787279.33
J54: =I21+I31 -> 7351745.7 | K54: =J54/'Dados Gerais'!E15 -> 139.99048
J55: =I51 -> 787279.33 | K55: =J55/'Dados Gerais'!E15 -> 14.991217
...

Sheet Supraestrutura
A2: ORÇAMENTO PARAMÉTRICO SUPRAESTRUTURA
A7: Documento | B7: CTN_STM_UNI Orçamento Preliminar
A8: Cliente | B8: Santa Maria
A9: Obra | B9: Unimed
A10: Data | B10: 45266 | E10: Revisão | F10: R01 | G10: Status | H10: Em andamento | I10: Responsável | J10: Amanda
A12: SUPRAESTRUTURA | L12: OK
A14: Descrição | D14: Quantidade | F14: Parâmetro | H14: Referência | I14: Valor total
A15: Fabricação forma | D15: =(D16/8) -> 16411.263 | E15: m² | F15: 25 | G15: % | H15: Média | I15: =+D15*125 -> 2051407.8
A16: Montagem de forma | D16: =(+'Dados Gerais'!$E$15*F16) -> 131290.1 | E16: m² | F16: 2.5 | G16: m² / AC | H16: Média | I16: =+D16*11.5 -> 1509836.2
A17: Escoramento - Torre | D17: ='Dados Gerais'!E15-'Dados Gerais'!E24 -> 32687.94 | E17: m² | F17: 60 | G17: R$ / m² | H17: Média | I17: =+D17*F17 -> 1961276.4
A18: Escoramento - Embasamento | D18: =('Dados Gerais'!E24) -> 19828.1 | E18: m² | F18: 60 | G18: R$ / m² | H18: Média | I18: =+D18*F18 -> 1189686
A19: Armadura Convencional para Estrutura | D19: =D20*F19 -> 1050320.8 | E19: kg | F19: 80 | G19: kg / m³ | H19: Média | I19: =+D19*8.5 -> 8927726.8
A20: Concreto | D20: =+F20*'Dados Gerais'!E15 -> 13129.01 | E20: m³ | F20: 0.25 | G20: m³ / AC | H20: Média | I20: =+D20*550 -> 7220955.5
A21: Mão de obra | D21: =(+'Dados Gerais'!E15) -> 52516.04 | E21: m² | F21: 240 | G21: R$ / m² | H21: Média | I21: =+D21*F21 -> 12603850
A22: TOTAL | I22: =SUM(I15:J21) -> 35464738
J25: =I22 -> 35464738 | K25: =J25/'Dados Gerais'!E15 -> 675.3125

Sheet Alvenaria
A2: ORÇAMENTO PARAMÉTRICO ALVENARIA
A7: Documento | B7: CTN_STM_UNI Orçamento Preliminar
A8: Cliente | B8: Santa Maria
A9: Obra | B9: Unimed
A10: Data | B10: 45266 | E10: Revisão | F10: R01 | G10: Status | H10: Em andamento | I10: Responsável | J10: Amanda
A12: ALVENARIA | L12: OK
A14: Descrição | D14: Quantidade | F14: Parâmetro | H14: Referência | I14: Valor total
A15: Alvenaria | D15: 38509.02 | E15: m² | F15: 60 | G15: m² / R$ | H15: Média | I15: =+D15*F15 -> 2310541.2 | L15: =1355.33+780.39+629.5+649.5+649.5+649.5+649.5+649.5+983.27+1028.18+9083+6639.88+1017.59+881.36+816.98+838.05+820.55+742.56+735.06+753.12+605.54+793.13+565.74+511.28+513.44+499.63+375.77+320.32+189.67+236.58+796.26+708.25+322.15+363.91+547.12+32.21+15.08+19.47+239.17+15.57+133.44 -> 38156.05 | M15: =L15-D17 -> 31000.66
A16: Drywall (MAT E MO) | D16: 16798.23 | E16: m² | F16: 80 | G16: m² / R$ | H16: Média | I16: =+D16*F16 -> 1343858.4 | L16: =183.99+791.01+791.01+791.01+791.01+792.69+791.01+791.01+1184.52+1233.65+14.1+181.57+1233.65+1033.88+1027.05+1026.97+1027.38+893.11+892.93+894.08+671.43+492.77+491.8+491.72+246.88+246.88+45.43+69.77 -> 19122.31
A17: Bloco de concreto autoclavado | D17: 7155.39 | E17: m² | F17: 50 | G17: m²/R$ | H17: Média | I17: =+D17*F17 -> 357769.5 | L17: Escadas
A18: Serviços complementares | D18: =D19+D20 -> 45664.41 | E18: m² | F18: 9 | G18: R$ / m² de alv. | H18: Média | I18: =F18*D18 -> 410979.69 | L18: Encunhamento, tela, verga e contraverga
A19: Mão de obra - Bloco Cerâmico | D19: =D15 -> 38509.02 | E19: m² | F19: 35 | G19: R$ / m² | H19: Média | I19: =+D19*F19 -> 1347815.7
A20: Mão de obra - Bloco Concreto | D20: =D17 -> 7155.39 | E20: m² | F20: 40 | G20: R$ / m² | H20: Média | I20: =+D20*F20 -> 286215.6 | L20: =I19+I20 -> 1634031.3
A21: TOTAL | I21: =SUM(I15:J20) -> 6057180.1
D24: =D20+D19 -> 45664.41 | J24: =I21 -> 6057180.1 | K24: =J24/'Dados Gerais'!E15 -> 115.33962

Sheet Instalações
A2: ORÇAMENTO PARAMÉTRICO INSTALAÇÕES
A7: Documento | B7: CTN_STM_UNI Orçamento Preliminar
A8: Cliente | B8: Santa Maria
A9: Obra | B9: Unimed
A10: Data | B10: 45266 | E10: Revisão | F10: R01 | G10: Status | H10: Em andamento | I10: Responsável | J10: Amanda
A12: INSTALAÇÕES ELÉTRICAS | L12: OK
A14: Descrição | D14: Quantidade | F14: Parâmetro | H14: Referência | I14: Valor total
A15: Entrada de Energia | D15: 1 | E15: vb | F15: 15 | G15: R$ / AC | H15: Média | I15: =+F15*'Dados Gerais'!$E$15 -> 787740.6
A16: Eletrodutos e Eletrocalhas | D16: 1 | E16: vb | F16: 15 | G16: R$ / AC | H16: Média | I16: =+F16*'Dados Gerais'!$E$15 -> 787740.6
A17: Pontos de tomadas e interruptores | D17: 1 | E17: vb | F17: 10 | G17: R$ / AC | H17: Média | I17: =+F17*'Dados Gerais'!$E$15 -> 525160.4
A18: Cabos e Fiações | D18: 1 | E18: vb | F18: 35 | G18: R$ / AC | H18: Média | I18: =+F18*'Dados Gerais'!$E$15 -> 1838061.4
A19: Quadros e Disjuntores | D19: 1 | E19: vb | F19: 25 | G19: R$ / AC | H19: Média | I19: =+F19*'Dados Gerais'!$E$15 -> 1312901
A20: Equipamentos e Iluminação | D20: 1 | E20: vb | F20: 20 | G20: R$ / AC | H20: Média | I20: =+F20*'Dados Gerais'!$E$15 -> 1050320.8
A21: Mão de Obra para Instalações Elétricas | D21: 1 | E21: vb | F21: 55 | G21: R$ / AC | H21: Média | I21: =+F21*'Dados Gerais'!$E$15 -> 2888382.2
A22: TOTAL | I22: =SUM(I15:J21) -> 9190307
A24: INSTALAÇÕES HIDRÁULICAS
A26: Descrição | D26: Quantidade | F26: Parâmetro | H26: Referência | I26: Valor total
A27: Instalações de Água Fria | D27: 1 | E27: vb | F27: 35 | G27: R$ / AC | H27: Média | I27: =+F27*'Dados Gerais'!$E$15 -> 1838061.4
A28: Instalações de Água Quente | D28: 1 | E28: vb | F28: 15 | G28: R$ / AC | H28: Média | I28: =+F28*'Dados Gerais'!$E$15 -> 787740.6
A29: Instalações de Águas Pluviais | D29: 1 | E29: vb | F29: 10 | G29: R$ / AC | H29: Média | I29: =+F29*'Dados Gerais'!$E$15 -> 525160.4
A30: Instalações Sanitárias | D30: 1 | E30: vb | F30: 15 | G30: R$ / AC | H30: Média | I30: =+F30*'Dados Gerais'!$E$15 -> 787740.6
A31: Cisterna | D31: 1 | E31: vb | F31: 3 | G31: R$ / AC | H31: Média | I31: =+F31*'Dados Gerais'!$E$15 -> 157548.12
A32: Sistema de bombas | D32: 1 | E32: vb | F32: 5 | G32: R$ / AC | H32: Média | I32: =+F32*'Dados Gerais'!$E$15 -> 262580.2
A33: Louças e Metais | D33: 1 | E33: vb | F33: 35 | G33: R$ / AC | H33: Média | I33: =+F33*'Dados Gerais'!$E$15 -> 1838061.4
A34: Mão de Obra para Instalações Hidráulicas | D34: 1 | E34: vb | F34: 50 | G34: R$ / AC | H34: Média | I34: =+F34*'Dados Gerais'!$E$15 -> 2625802
A35: TOTAL | I35: =SUM(I27:J34) -> 8822694.7
A38: INSTALAÇÕES PREVENTIVAS E GLP
A40: Descrição | D40: Quantidade | F40: Parâmetro | H40: Referência | I40: Valor total
A41: Instalações Preventivas | D41: 1 | E41: vb | F41: 45 | G41: R$ / AC | H41: Média | I41: =+F41*'Dados Gerais'!$E$15 -> 2363221.8
A42: Instalações de SPDA | D42: 1 | E42: vb | F42: 15 | G42: R$ / AC | H42: Média | I42: =+F42*'Dados Gerais'!$E$15 -> 787740.6
A43: Instalações de GLP | D43: 1 | E43: vb | F43: 25 | G43: R$ / AC | H43: Média | I43: =+F43*'Dados Gerais'!$E$15 -> 1312901
A44: TOTAL | I44: =SUM(I41:J43) -> 4463863.4
J47: =I44+I35+I22 -> 22476865 | K47: =J47/'Dados Gerais'!E15 -> 428

Sheet Sistemas especiais
A2: ORÇAMENTO PARAMÉTRICO INSTALAÇÕES
A7: Documento | B7: CTN_STM_UNI Orçamento Preliminar
A8: Cliente | B8: Santa Maria
A9: Obra | B9: Unimed
A10: Data | B10: 45266 | E10: Revisão | F10: R01 | G10: Status | H10: Em andamento | I10: Responsável | J10: Amanda
A12: CLIMATIZAÇÃO, EXAUSTÃO MECÂNICA E PRESSURIZAÇÃO | L12: OK
A14: Descrição | D14: Quantidade | F14: Parâmetro | H14: Referência | I14: Valor total
A15: Infraestrutura para Instalação de Ar Condicionado | D15: 30 | E15: pç | F15: 1500 | G15: R$ / ponto | H15: Média | I15: =F15*D15 -> 45000
A16: Máquinas de Ar Condiocinado para as áreas comuns | D16: 30 | E16: pç | F16: 6000 | G16: R$ / máquina | H16: Média | I16: =F16*D16 -> 180000
A17: Exaustão Mecânica Garagens | D17: 8 | E17: un | F17: 150000 | G17: R$ / un | H17: Média | I17: =+D17*F17 -> 1200000
A18: Ventokit | D18: 476 | E18: un | F18: 1000 | G18: R$ / un | H18: Média | I18: =+D18*F18 -> 476000
A19: Exaustão Mecânica Corredores | D19: 22 | E19: pvto | F19: 100000 | G19: R$ / un | H19: Média | I19: =D19*F19 -> 2200000
A20: TOTAL | I20: =SUM(I15:J19) -> 4101000
A23: COMUNICAÇÃO
A25: Descrição | D25: Quantidade | F25: Parâmetro | H25: Referência | I25: Valor total
A26: CFTV | D26: 1 | E26: vb | F26: 3 | G26: R$ / AC | H26: Média | I26: =+F26*'Dados Gerais'!E15 -> 157548.12
A27: Interfone | D27: 1 | E27: vb | F27: 10 | G27: R$ / AC | H27: Média | I27: =+F27*'Dados Gerais'!E15 -> 525160.4
A28: TV e internet | D28: 1 | E28: vb | F28: 12 | G28: R$ / AC | H28: Média | I28: =+F28*'Dados Gerais'!E15 -> 630192.48
A29: TOTAL | I29: =SUM(I26:I28) -> 1312901
A32: AUTOMAÇÃO
A34: Descrição | D34: Quantidade | F34: Parâmetro | H34: Referência | I34: Valor total
A35: Automação, telecomunicação e sistemas de segurança | D35: 1 | E35: vb | F35: 15 | G35: R$ / AC | H35: Média | I35: =F35*'Dados Gerais'!E15 -> 787740.6
A36: TOTAL | I36: =SUM(I35:J35) -> 787740.6
A39: OUTROS SISTEMAS ESPECIAIS
A41: Descrição | D41: Quantidade | F41: Parâmetro | H41: Referência | I41: Valor total
A42: Outros sistemas | D42: 1 | E42: vb | F42: 20 | G42: R$ / AC | H42: Média | I42: =+F42*'Dados Gerais'!E15 -> 1050320.8
A43: TOTAL | I43: =SUM(I42:J42) -> 1050320.8
A46: EQUIPAMENTOS
A48: Descrição | D48: Quantidade | F48: Parâmetro | H48: Referência | I48: Valor total
A49: Elevadores sociais | D49: 14 | E49: un | F49: 9645900 | G49: R$ | H49: Média | I49: =F49 -> 9645900
A50: Grupo de geradores | D50: 1 | E50: un | F50: 500000 | G50: R$ | H50: Média | I50: =+D50*F50 -> 500000
A51: Escada pressurizada | D51: 68 | E51: pvto | F51: 9289.24 | G51: R$ / PVTO | H51: Média | I51: =+D51*F51 -> 631668.32
A52: TOTAL | I52: =SUM(I49:J51) -> 10777568
J55: =I52+I43+I36+I20+I29 -> 18029531 | K55: =J55/'Dados Gerais'!E15 -> 343.31474

Sheet Impermeabilização
A2: ORÇAMENTO PARAMÉTRICO IMPERMEABILIZAÇÃO
A7: Documento | B7: CTN_STM_UNI Orçamento Preliminar
A8: Cliente | B8: Santa Maria
A9: Obra | B9: Unimed
A10: Data | B10: 45266 | E10: Revisão | F10: R01 | G10: Status | H10: Em andamento | I10: Responsável | J10: Amanda
A12: IMPERMEABILIZAÇÃO | L12: OK
A14: Descrição | D14: Quantidade | F14: Parâmetro | H14: Referência | I14: Valor total
A15: Regularização de Superfície | D15: =+D19+D20 -> 8661.934 | E15: m² | F15: 15.5 | G15: R$ / m² | H15: Média | I15: =+D15*F15 -> 134259.98
A16: Poço do elevador | D16: 119.25 | E16: m² | F16: 45 | G16: R$ / m² | H16: Média | I16: =+F16*D16 -> 5366.25
A17: Baldrame | D17: =0.7*Infraestrutura!D27 -> 1870.316 | E17: m² | F17: 45 | G17: R$ / m² | H17: Média | I17: =+F17*D17 -> 84164.22
A18: Ralos | D18: 1 | E18: vb | F18: 2.8 | G18: R$ / AC | H18: Média | I18: =+F18*'Dados Gerais'!$E$15 -> 147044.91
A19: Impermeabilizações cimenticias | D19: =+F19*'Dados Gerais'!$E$15 -> 5251.604 | E19: m² | F19: 0.1 | G19: m² / AC | H19: Média | I19: =+D19*40 -> 210064.16
A20: Impermeabilizações com manta asfaltica | D20: 3410.33 | E20: m² | F20: 0.2 | G20: m² / AC | H20: Média | I20: =+D20*105 -> 358084.65
A21: Impermeabilização de peitoril | D21: 1 | E21: vb | F21: 0.75 | G21: R$ / AC | H21: Média | I21: =+F21*'Dados Gerais'!$E$15 -> 39387.03
A22: Proteção Mecânica | D22: =+D20 -> 3410.33 | E22: m² | F22: 60 | G22: R$ / m² | H22: Média | I22: =+D22*60 -> 204619.8
A23: TOTAL | I23: =SUM(I15:J22) -> 1182991
J26: =I23 -> 1182991 | K26: =J26/'Dados Gerais'!E15 -> 22.52628

Sheet Rev. Internos Piso e Parede
A2: ORÇAMENTO PARAMÉTRICO REVESTIMENTOS INTERNOS EM PISO E PAREDE
A7: Documento | B7: CTN_STM_UNI Orçamento Preliminar
A8: Cliente | B8: Santa Maria
A9: Obra | B9: Unimed
A10: Data | B10: 45266 | E10: Revisão | F10: R01 | G10: Status | H10: Em andamento | I10: Responsável | J10: Amanda
A12: REVESTIMENTOS INTERNOS EM PISO E PAREDE | L12: OK
A14: Descrição | D14: Quantidade | F14: Parâmetro | H14: Referência | I14: Valor total
A15: Contrapiso | D15: 33084.66 | E15: m² | F15: 35 | G15: m² / R$ | H15: Média | I15: =+D15*F15 -> 1157963.1 | L15: =1956.96+1301.35+1301.13+1300.75+1300.75+1300.75+1300.75+1300.75+1222.64+1230.56+1889.9+1229.42+1233.95+1230.08+1231.33+1230.94+1239.37+1067.92+1071.46+1097.34+927.9+667.22+673.14+687.7+463.6+459.55+635.37+1300.75+1231.33 -> 33084.66
A16: Chapisco | D16: =(Alvenaria!D15+Alvenaria!D17)*1.8 -> 82195.938 | E16: m² | F16: 2.5 | G16: m² / R$ | H16: Média | I16: =+D16*F16 -> 205489.84
A17: Reboco | D17: =D16 -> 82195.938 | E17: m² | F17: 20 | G17: m² / R$ | H17: Média | I17: =+D17*F17 -> 1643918.8
A18: Estucamento | D18: 1 | E18: vb | F18: 10 | G18: R$ / AC | H18: Média | I18: =+F18*'Dados Gerais'!$E$15 -> 525160.4
A19: MO Contrapiso | D19: =D15 -> 33084.66 | E19: m² | F19: 26 | G19: R$ / m² | H19: Média | I19: =F19*D19 -> 860201.16
A20: MO Reboco | D20: =D17 -> 82195.938 | E20: m² | F20: 30.5 | G20: R$ / m² | H20: Média | I20: =35*D20 -> 2876857.8
A21: TOTAL | I21: =SUM(I15:J20) -> 7269591.1
J24: =I21 -> 7269591.1 | K24: =J24/'Dados Gerais'!E15 -> 138.42611

Sheet Acabamentos de Teto
A2: ORÇAMENTO PARAMÉTRICO REVESTIMENTOS E ACABAMENTOS INTERNOS EM TETO
A7: Documento | B7: CTN_STM_UNI Orçamento Preliminar
A8: Cliente | B8: Santa Maria
A9: Obra | B9: Unimed
A10: Data | B10: 45266 | E10: Revisão | F10: R01 | G10: Status | H10: Em andamento | I10: Responsável | J10: Amanda
A12: ACABAMENTOS DE TETO | L12: OK
A14: Descrição | D14: Quantidade | F14: Parâmetro | H14: Referência | I14: Valor total
A15: Forro modular | D15: =29225.55-9741.85-210.26 -> 19273.44 | E15: m² | F15: 50 | G15: R$ / m² | H15: Média | I15: =+D15*F15 -> 963672 | L15: =1285.87+293.62+294.5+210.26+294.5+282.34+282.34+282.34+282.34+251.68+251.68+251.68+270.9+165.03+165.03+165.03+103.72+103.72+1351.13+2138.97+183.99+791.01+791.01+791.01+791.01+792.69+791.01+791.01+1184.52+1233.65+14.1+181.57+7.41+1233.65+1033.88+1027.05+1026.97+1027.38+893.11+892.93+894.08+671.43+18.02+492.77+491.8+491.72+246.88+246.88+45.43+69.77+1351.13 -> 29225.55 | M15: =L15/3 -> 9741.85
A16: Forro de gesso | D16: 9741.85 | E16: m² | F16: 80 | G16: R$ / m² | H16: Média | I16: =+D16*F16 -> 779348
A17: Forro de gesso | D17: 210.26 | E17: m² | F17: 120 | G17: R$ / m² | H17: Média | I17: =+D17*F17 -> 25231.2
A18: TOTAL | I18: =SUM(I15:J17) -> 1768251.2
J21: =I18 -> 1768251.2 | K21: =J21/'Dados Gerais'!E15 -> 33.670688

Sheet Acabamentos de Piso e Parede
A2: ORÇAMENTO PARAMÉTRICO ACABAMENTOS EM PISO E PAREDE
A7: Documento | B7: CTN_STM_UNI Orçamento Preliminar
A8: Cliente | B8: Santa Maria
A9: Obra | B9: Unimed
A10: Data | B10: 45266 | E10: Revisão | F10: R01 | G10: Status | H10: Em andamento | I10: Responsável | J10: Amanda
A12: ACABAMENTOS EM PISO E PAREDE | L12: OK
A14: Descrição | D14: Quantidade | F14: Parâmetro | H14: Referência | I14: Valor total
A15: Piso porcelanato 80x80 | D15: =7567.86+317.42 -> 7885.28 | E15: m² | F15: 100 | G15: R$ / m² | H15: Média | I15: =+F15*D15 -> 788528 | L15: rejunte epoxi
A16: Piso vinilico | D16: 256.02 | E16: m² | F16: 200 | G16: R$ / m² | H16: Média | I16: =+F16*D16 -> 51204
A17: Revestimento de piso em paver | D17: 2027.63 | E17: m² | F17: 90 | G17: R$ / m² | H17: Média | I17: =+F17*D17 -> 182486.7
A18: Revestimento em asfalto | D18: 6078.9 | E18: m² | F18: 250 | G18: R$ / m² | H18: Média | I18: =+F18*D18 -> 1519725
A19: Grama | D19: =67.29+77.84 -> 145.13 | E19: m² | F19: 130 | G19: R$ / m² | H19: Média | I19: =+F19*D19 -> 18866.9
A20: Piso concreto estampado | D20: 16490.13 | E20: m² | F20: 200 | G20: R$ / m² | H20: Média | I20: =+F20*D20 -> 3298026
A21: Rodapés | D21: 1 | E21: vb | F21: 30 | G21: R$ / AC | H21: Média | I21: =+F21*'Dados Gerais'!$E$15 -> 1575481.2 | L21: poliestireno branco
A22: Revestimentos de Parede Granito | D22: 97.34 | E22: m² | F22: 150 | G22: R$ / AC | H22: Média | I22: =+D22*F22 -> 14601
A23: Soleiras e peitoris | D23: 1 | E23: vb | F23: 10.6 | G23: R$ / AC | H23: Média | I23: =+F23*'Dados Gerais'!E15 -> 556670.02
A24: MO Granito | D24: =D22 -> 97.34 | E24: m² | F24: 60 | G24: R$ / m² | H24: Média | I24: =+F24*D24 -> 5840.4
A25: MO Porcelanato | D25: =D15 -> 7885.28 | E25: m² | F25: 50 | G25: R$ / m² | H25: Média | I25: =+F25*D25 -> 394264
A26: MO Laminado | D26: =D16 -> 256.02 | E26: m² | F26: 50 | G26: R$ / m² | H26: Média | I26: =+F26*D26 -> 12801
A27: TOTAL | I27: =SUM(I15:J26) -> 8418494.2
J30: =I27 -> 8418494.2 | K30: =J30/'Dados Gerais'!E15 -> 160.30329
A31: PAREDE | I31: PISO
A32: granito | D32: =72.39+24.95 -> 97.34 | F32: térreo,lazer | I32: 80x80 | J32: =1809.88+310.22+317.42+1025.59+317.42+302.08+301.14+301.14+301.14+274.59+274.59+274.59+224.28+364.51+364.51+528.07+122.19+122.19+26.59+5.72 -> 7567.86 | K32: lazer, 18pvto, 19pvto, terreo, tipo 2, tipo 3, tipo 4, tipo 5, tipo 6
A33: pintura branca | D33: =0.59+67.64+33.81+169.41+159.92 -> 431.37 | F33: lazer, subsolo, terreo, tipo 5, cobertura | I33: pintura cinza | J33: =5.44+5.44+5.44+5.44+5.44+5.44+5.44+5.44+5.44+5.44+13.25+5.44+5.44+5.44+5.44+5.44+5.44+5.44+5.44+5.44+5.44+5.44+5.44+5.44+5.44+6.21+5.44+5.44+5.44+5.44+5.44+5.44+5.44+5.45 -> 193.55
A34: textura - grafiato cinza | D34: =1278.13+780.39+629.5+649.5+649.5+649.5+649.5+649.5+657.05+709.62+8270.73+4840.87+699.04+630.24+564.31+585.04+567.54+531.07+523.88+541.63+411.61+507.34+545.23+395.23+397.06+395.62+271.76+319.2+188.86+235.77+795.14+707.13+321.02+361.38+387.19+32.21+15.08+133.44+19.47+15.57 -> 31511.85 | I34: pintura acrilica | J34: =94.4+35.21+35.21+35.21+35.21+35.21+35.21+104.82+63.8+63.8+63.8+63.8+63.8+63.8+54.91+54.91+54.91+25.26+25.26+25.26+25.26 -> 1059.05
A35: vidro | D35: =4.23+326.22+318.56+10.49+318.56+251.12+252.68+253.01+253.01+211.49+211.18+211.49+175.91+116.38+3.96+116.05+116.38+104.01+104.01+239.17 -> 3597.91 | I35: madeira | J35: 256.02 | K35: mezanino
A36: pintura verde | D36: 361.73 | E36: terreo | I36: cimento polido | J36: 2152.72 | K36: subsolo
A38: aluminio | D38: 15.55 | I38: aluminium black | J38: 4.85 | K38: terreo
I40: telha | J40: 76.11 | K40: g1
I41: terra | J41: =5.66+12.03+12.03+12.03+12.03+12.03+12.03 -> 77.84 | K41: g2, g3, g4, g5, g6, g7, g8
I43: cobertura | J43: =459.55+217.12+68.42 -> 745.09
I44: grama | J44: 67.29 | K44: terreo
I45: asfalto | J45: 6078.9 | K45: terreo
I46: paver | J46: =1810.87+147.93+68.83 -> 2027.63 | K46: terreo

Sheet Pintura Interna
A2: ORÇAMENTO PARAMÉTRICO PINTURA INTERNA
A7: Documento | B7: CTN_STM_UNI Orçamento Preliminar
A8: Cliente | B8: Santa Maria
A9: Obra | B9: Unimed
A10: Data | B10: 45266 | E10: Revisão | F10: R01 | G10: Status | H10: Em andamento | I10: Responsável | J10: Amanda
A12: PINTURA INTERNA | L12: OK
A14: Descrição | D14: Quantidade | F14: Parâmetro | H14: Referência | I14: Valor total
A15: Pintura acrílica paredes | D15: =431.37+361.73+5.44 -> 798.54 | E15: m2 | F15: 70 | G15: R$ / m² | H15: Média | I15: =+D15*F15 -> 55897.8
A16: Pintura acrílica piso | D16: =1059.05+193.55+63.8+2095.88+2179.39+2185.92+2139+1918.28+1909.27+1909.67+1803.72 -> 17457.53 | E16: m2 | F16: 70 | G16: R$ / m² | H16: Média | I16: =+D16*F16 -> 1222027.1
A17: Textura grafiato paredes | D17: =31511.85+657.02+630.24 -> 32799.11 | E17: m2 | F17: 80 | G17: R$ / m² | H17: Média | I17: =+D17*F17 -> 2623928.8
A18: TOTAL | I18: =SUM(I15:J17) -> 3901853.7
J21: =I18 -> 3901853.7 | K21: =J21/'Dados Gerais'!E15 -> 74.298323

Sheet Esquadrias
A2: ORÇAMENTO PARAMÉTRICO ESQUADRIAS
A7: Documento | B7: CTN_STM_UNI Orçamento Preliminar
A8: Cliente | B8: Santa Maria
A9: Obra | B9: Unimed
A10: Data | B10: 45266 | E10: Revisão | F10: R01 | G10: Status | H10: Em andamento | I10: Responsável | J10: Amanda
A12: ESQUADRIAS | L12: OK
A14: Descrição | D14: Quantidade | F14: Parâmetro | H14: Referência | I14: Valor total
A15: Esquadrias de Alumínio | D15: 367.76 | E15: m² | F15: 1800 | G15: R$ / m² | H15: Média | I15: =+F15*D15 -> 661968
A16: Guarda corpo de vidro | D16: 1925.31 | E16: m² | F16: 1279.7 | G16: R$ / m² | H16: Média | I16: =+D16*F16 -> 2463819.2
A17: Serralherias | D17: 1 | E17: vb | F17: 800000 | G17: R$ | H17: Média | I17: =+D17*F17 -> 800000
A18: PCF | D18: 156 | E18: un | F18: 1750 | G18: R$ / un | H18: Média | I18: =+D18*F18 -> 273000 | L18: =4+4+4+4+4+4+4+4+4+4+4+4+3+4+4+4+4+4+4+4+4+4+5+4+2+4+2+4+4+4+4+4+4+4+4+4+4+4+5+2+1 -> 156
A19: Corrimão | D19: 1789.76 | E19: m | F19: 80 | G19: R$ / m | H19: Média | I19: =+D19*F19 -> 143180.8
A20: Esquadrias Internas de Madeira | D20: 641 | E20: un | F20: 3000 | G20: R$ | H20: Média | I20: =+F20*D20 -> 1923000 | L20: =17+21+21+21+21+20+21+21+63+35+2+8+35+35+35+35+35+32+32+32+24+18+1+18+18+7+6+3+4 -> 641
A21: Portão de alumínio | D21: 3 | E21: un | F21: 50000 | G21: R$ / un | H21: Média | I21: =+F21*D21 -> 150000
A22: Esquadrias de Vidro | D22: 5061.72 | E22: m² | F22: 1200 | G22: R$ / m² | H22: Média | I22: =+D22*F22 -> 6074064
A23: TOTAL | I23: =SUM(I15:J22) -> 12489032 | M23: aluminio | Q23: vidro
M24: =0.6*2.1 -> 1.26 | N24: 6 | O24: =M24*N24 -> 7.56 | Q24: =1.6*2.1 -> 3.36 | R24: 5 | S24: =Q24*R24 -> 16.8
M25: =0.8*2.1 -> 1.68 | N25: =6+1+1+1+1+1+1+1+1+6+1+2 -> 23 | O25: =M25*N25 -> 38.64 | Q25: =1.1*2.1 -> 2.31 | R25: =5+1+1+1 -> 8 | S25: =Q25*R25 -> 18.48
J26: =I23 -> 12489032 | K26: =J26/'Dados Gerais'!E15 -> 237.81367 | M26: =0.9381*3.97 -> 3.724257 | N26: 8 | O26: =M26*N26 -> 29.794056 | Q26: =1.3*2.1 -> 2.73 | R26: =30+30+30+30+30+30+26+26+26+17+13+13+5 -> 306 | S26: =Q26*R26 -> 835.38
M27: =1.1*0.6 -> 0.66 | N27: =10+10+10+10+10+10+10+10+10+10+10+10+10+10+9+9+9+7+5+5+5+4+2+2 -> 197 | O27: =M27*N27 -> 130.02 | Q27: =1.6*2.4 -> 3.84 | R27: 1 | S27: =Q27*R27 -> 3.84
A28: PAREDE | I28: PISO | M28: =0.825*0.425 -> 0.350625 | N28: =1+1+1+1+1+1+1+1+1+1+1+1+1+1+1+1+1+1+1+1+1+1+1+1+1+1+1+1+1+1+1+1+1+1 -> 34 | O28: =M28*N28 -> 11.92125 | Q28: =0.9*2.1 -> 1.89 | R28: 1 | S28: =Q28*R28 -> 1.89
A29: vidro | D29: =4.23+326.22+318.56+10.49+318.56+251.12+252.68+253.01+253.01+211.49+211.18+211.49+175.91+116.38+3.96+116.05+116.38+104.01+104.01+239.17 -> 3597.91 | I29: aluminium black | J29: 4.85 | K29: terreo | M29: =3.14*2.5 -> 7.85 | N29: 1 | O29: =M29*N29 -> 7.85 | Q29: =0.9*2.4 -> 2.16 | R29: 1 | S29: =Q29*R29 -> 2.16
A30: aluminio | D30: 15.55 | M30: =0.9*0.9 -> 0.81 | N30: =4+2 -> 6 | O30: =M30*N30 -> 4.86 | Q30: =1.1*2.4 -> 2.64 | R30: =1+1+1 -> 3 | S30: =Q30*R30 -> 7.92
M31: =2.7*1.5 -> 4.05 | N31: 1 | O31: =M31*N31 -> 4.05 | S31: 326.22
M32: =1.7*2.1 -> 3.57 | N32: =1+1+1+1+1+1+1+1 -> 8 | O32: =M32*N32 -> 28.56 | S32: 251.12
M33: =1.6*2.4 -> 3.84 | N33: 6 | O33: =M33*N33 -> 23.04 | S33: =SUM(S24:S32,D29) -> 5061.72
M34: =2*2.4 -> 4.8 | N34: 3 | O34: =M34*N34 -> 14.4
M35: =1.4*1.4 -> 1.96 | N35: =4+2+1+1+4 -> 12 | O35: =M35*N35 -> 23.52
M36: =9.5*0.8 -> 7.6 | N36: 1 | O36: =M36*N36 -> 7.6
M37: =1.6*2.1 -> 3.36 | N37: 1 | O37: =M37*N37 -> 3.36
J38: =68+(36.02*6)+(161.53*7)+(197.8*3)+104.77+(87.65*3) -> 2375.95 | M38: =1.4*2.1 -> 2.94 | N38: =1+2 -> 3 | O38: =M38*N38 -> 8.82
M39: =1.2*0.7 -> 0.84 | N39: 4 | O39: =M39*N39 -> 3.36
O40: =SUM(O24:O39,D30,J29) -> 367.75531

Sheet Cobertura
A2: ORÇAMENTO PARAMÉTRICO COBERTURA
A7: Documento | B7: CTN_STM_UNI Orçamento Preliminar
A8: Cliente | B8: Santa Maria
A9: Obra | B9: Unimed
A10: Data | B10: 45266 | E10: Revisão | F10: R01 | G10: Status | H10: Em andamento | I10: Responsável | J10: Amanda
A12: COBERTURA | L12: OK
A14: Descrição | D14: Quantidade | F14: Parâmetro | H14: Referência | I14: Valor total
A15: Cobertura | D15: 745.09 | E15: m² | F15: 200 | G15: R$ / m² | H15: Média | I15: =F15*D15 -> 149018
A16: Complementares | D16: 1 | E16: m² | F16: 26.3 | G16: R$ / m² | H16: Média | I16: =F16*D15 -> 19595.867
A17: TOTAL | I17: =SUM(I15:J16) -> 168613.87
J19: =I17 -> 168613.87 | K19: =J19/'Dados Gerais'!E15 -> 3.2107118

Sheet Rev. Fachada
A2: ORÇAMENTO PARAMÉTRICO REVESTIMENTOS E ACABAMENTOS DE FACHADA
A7: Documento | B7: CTN_STM_UNI Orçamento Preliminar
A8: Cliente | B8: Santa Maria
A9: Obra | B9: Unimed
A10: Data | B10: 45266 | E10: Revisão | F10: R01 | G10: Status | H10: Em andamento | I10: Responsável | J10: Amanda
A12: REVESTIMENTOS ARGAMASSADOS | L12: OK
A14: Descrição | D14: Quantidade | F14: Parâmetro | H14: Referência | I14: Valor total
A15: Chapisco e Reboco | D15: =352.3*15 -> 5284.5 | E15: m² | F15: 25 | G15: R$/m² | H15: - | I15: =+D15*F15 -> 132112.5 | L15: =+D15*F15 -> 132112.5
A16: Mão de obra | D16: =D15 -> 5284.5 | E16: m² | F16: 55 | G16: R$/m² | H16: - | I16: =+D16*F16 -> 290647.5 | L16: =+D16*F16 -> 290647.5
A17: TOTAL | I17: =SUM(I15:J16) -> 422760
A20: PINTURA
A22: Descrição | D22: Quantidade | F22: Parâmetro | H22: Referência | I22: Valor total
A23: Textura / Pintura | D23: 0 | E23: m² | F23: 3.75 | G23: m² / PT * (NPT+NPD+ND) | H23: - | I23: =+D23*F23*150 -> 0 | M23: =I23*0.6 -> 0
A24: TOTAL | I24: =SUM(I23:J23) -> 0 | M24: =I23*0.4 -> 0
A26: REVESTIMENTOS ESPECIAIS
A28: Descrição | D28: Quantidade | F28: Parâmetro | H28: Referência | I28: Valor total
A29: Pele de Vidro - área de vidro | D29: 6305.5 | E29: m² | F29: 1918.22 | G29: RS / m² | H29: Média | I29: =D29*F29 -> 12095336
A30: Pele de Vidro - área ACM plano | D30: 2655.6 | E30: m² | F30: 1983.59 | G30: RS / m² | H30: Média | I30: =D30*F30 -> 5267621.6
A31: Pele de Vidro - área ACM volume | D31: 311.31 | E31: m² | F31: 5759.26 | G31: RS / m² | H31: Média | I31: =D31*F31 -> 1792915.2
A32: Pele de Vidro - área de vidro | D32: 3958.3 | E32: m² | F32: 2006.69 | G32: RS / m² | H32: Média | I32: =D32*F32 -> 7943081
A33: Pele de Vidro - área ACM plano | D33: 232 | E33: m² | F33: 2072.06 | G33: RS / m² | H33: Média | I33: =D33*F33 -> 480717.92
A34: Revestimento em ACM | D34: 186.07 | E34: m² | F34: 1289.86 | G34: RS / m² | H34: Média | I34: =D34*F34 -> 240004.25
I35: =SUM(I29:J34) -> 27819676
J37: =I35+I24+I17 -> 28242436 | K37: =J37/'Dados Gerais'!E15 -> 537.78686

Sheet Complementares
A2: ORÇAMENTO PARAMÉTRICO EQUIPAMENTOS
A7: Documento | B7: CTN_STM_UNI Orçamento Preliminar
A8: Cliente | B8: Santa Maria
A9: Obra | B9: Unimed
A10: Data | B10: 45266 | E10: Revisão | F10: R01 | G10: Status | H10: Em andamento | I10: Responsável | J10: Amanda
A12: SERVIÇOS COMPLEMENTARES | L12: OK
A14: Descrição | D14: Quantidade | F14: Parâmetro | H14: Referência | I14: Valor total
A15: Móveis e decoração | D15: 1 | E15: vb | F15: 2700 | G15: R$ / AL | H15: Média | I15: =D15*F15*'Dados Gerais'!$E$22 -> 5484753
A16: Comunicação visual | D16: 1 | E16: vb | F16: 35 | G16: R$ / AC | H16: Média | I16: =D16*F16*'Dados Gerais'!$E$15 -> 1838061.4
A17: Paisagismo | D17: 1 | E17: vb | F17: 30 | G17: R$ / AC | H17: Média | I17: =D17*F17*'Dados Gerais'!$E$15 -> 1575481.2
A18: Ligações definitivas | D18: 1 | E18: vb | F18: 10 | G18: R$ / AC | H18: Média | I18: =D18*F18*'Dados Gerais'!$E$15 -> 525160.4
A19: Desmobilização | D19: 1 | E19: vb | F19: 7 | G19: R$ / AC | H19: Média | I19: =D19*F19*'Dados Gerais'!$E$15 -> 367612.28
A20: Limpeza | D20: 1 | E20: vb | F20: 15 | G20: R$ / AC | H20: Média | I20: =D20*F20*'Dados Gerais'!$E$15 -> 787740.6
A21: TOTAL | I21: =SUM(I15:J20) -> 10578809
J24: =I21 -> 10578809 | K24: =J24/'Dados Gerais'!E15 -> 201.43958
