Workbook

Sheet Gerenciamento executivo 
A1: ETAPA | B1: PORTAL | D1: OBRA SIMILAR
C2: VALOR / m² | D2: VALOR / m² | E2: Valor 1 | F2: Valor 2
A3: MOVIMENTAÇÃO DE TERRA | B3: =+B22 -> 71531.25 | C3: =+B3/10250.13 -> 6.97857 | D3: 4,50 - 7,50 | E3: 4.5 | F3: 3
A4: INFRAESTRUTURA | B4: =+B23 -> 1364173.9 | C4: =+B4/10250.13 -> 133.08845 | D4: 100,00 - 150,00 | E4: 100 | F4: 50
A5: SUPRAESTRUTURA | B5: =+B24+B39+B55 -> 5582951.2 | C5: =+B5/10250.13 -> 544.67126 | D5: 520,00 - 580,00 | E5: 520 | F5: 60
A6: ALVENARIA | B6: =+B25+B40+B56 -> 965384.86 | C6: =+B6/10250.13 -> 94.182694 | D6: 85,00 - 110,00 | E6: 85 | F6: =110-85 -> 25
A7: INSTALAÇÕES ELÉTRICAS, HIDRÁULICAS, GLP E PREVENTIVAS | B7: =+B26+B41+B57 -> 2595791 | C7: =+B7/10250.13 -> 253.24469 | D7: 230,00 - 270,00 | E7: 230 | F7: =270-230 -> 40
A8: SISTEMAS E EQUIPAMENTOS ESPECIAIS | B8: =+B27+B42+B58 -> 1672622.9 | C8: =+B8/10250.13 -> 163.18066 | D8: 100,00 - 180,00 | E8: 100 | F8: 80
A9: IMPERMEABILIZAÇÃO | B9: =+B28+B43+B59 -> 467279.84 | C9: =+B9/10250.13 -> 45.587699 | D9: 40,00 - 50,00 | E9: 40 | F9: 10
A10: REVESTIMENTOS INTERNOS EM PISO E PAREDE | B10: =+B29+B44+B60 -> 956255.86 | C10: =+B10/10250.13 -> 93.292071 | D10: 140,00 - 160,00 | E10: 140 | F10: 20
A11: REVESTIMENTOS E ACABAMENTOS INTERNOS EM TETO | B11: =+B30+B45+B61 -> 256181.1 | C11: =+B11/10250.13 -> 24.992961 | D11: 60,00 - 70,00 | E11: 60 | F11: 10
A12: ACABAMENTOS EM PISO E PAREDE | B12: =+B31+B46+B62 -> 1598846.9 | C12: =+B12/10250.13 -> 155.98309 | D12: 130,00 - 160,00 | E12: 130 | F12: 30
A13: PINTURA INTERNA | B13: =+B32+B47+B63 -> 1281142.7 | C13: =+B13/10250.13 -> 124.98795 | D13: 110,00 - 130,00 | E13: 110 | F13: 30
A14: ESQUADRIAS, VIDROS E FERRAGENS | B14: =+B33+B48+B64 -> 2397558.2 | C14: =+B14/10250.13 -> 233.90515 | D14: 175,00 - 200,00 | E14: 175 | F14: =200-E14 -> 25
A15: COBERTURA | B15: =+B65+B49 -> 313624.06 | C15: =+B15/10250.13 -> 30.597081 | D15: 30,00 - 40,00 | E15: 30 | F15: 40
A16: REVESTIMENTOS E ACABAMENTOS DE FACHADA | B16: =+B34+B50+B66 -> 1117409.6 | C16: =+B16/10250.13 -> 109.01419 | D16: 85,00 - 120,00 | E16: 85 | F16: =120-E16 -> 35
A17: SERVIÇOS COMPLEMENTARES | B17: =+B71 -> 1282500 | C17: =+B17/10250.13 -> 125.12036 | D17: 130,00 - 135,00 | E17: 130 | F17: 5
A18: TOTAL | B18: =SUM(B3:B17) -> 21923253 | C18: =SUM(C3:C17) -> 2138.8269 | D18: 1939,50 - 2402,50
A20: ETAPA | B20: PORTAL
A22: MOVIMENTAÇÃO DE TERRA | B22: 71531.25
A23: INFRAESTRUTURA | B23: 1364173.9
A24: SUPRAESTRUTURA | B24: 2871535.5
A25: ALVENARIA | B25: 250803.97
A26: INSTALAÇÕES ELÉTRICAS, HIDRÁULICAS, GLP E PREVENTIVAS | B26: =435201.31+436456.51+346403.81 -> 1218061.6
A27: SISTEMAS E EQUIPAMENTOS ESPECIAIS | B27: 388704.99
A28: IMPERMEABILIZAÇÃO | B28: 177028
A29: REVESTIMENTOS INTERNOS EM PISO E PAREDE | B29: 475192.65
A30: REVESTIMENTOS E ACABAMENTOS INTERNOS EM TETO | B30: 89351.75
A31: ACABAMENTOS EM PISO E PAREDE | B31: 446062.14
A32: PINTURA INTERNA | B32: 712359.99
A33: ESQUADRIAS, VIDROS E FERRAGENS | B33: 970896.05
A34: REVESTIMENTOS E ACABAMENTOS DE FACHADA | B34: 333207.67
A35: TOTAL | B35: =SUM(B22:B34) -> 9368909.5
A37: ETAPA | B37: PORTAL
A39: SUPRAESTRUTURA | B39: 1401106.7
A40: ALVENARIA | B40: 402310.41
A41: INSTALAÇÕES ELÉTRICAS, HIDRÁULICAS, GLP E PREVENTIVAS | B41: =336283.94+407376.65 -> 743660.59
A42: SISTEMAS E EQUIPAMENTOS ESPECIAIS | B42: 665676.76
A43: IMPERMEABILIZAÇÃO | B43: 191969.25
A44: REVESTIMENTOS INTERNOS EM PISO E PAREDE | B44: 389629.78
...

Sheet Executivo
A1: ETAPA | B1: VALOR ORÇADO | C1: % | D1: VALOR / m² | E1: VALOR / UNIDADE
A2: GERENCIAMENTO TÉCNICO E ADMINISTRATIVO | B2: 2773099.4 | C2: =B2/B$18 -> 0.11228781 | D2: =B2/H$11 -> 270.54285 | E2: =B2/H$7 -> 51353.693
A3: MOVIMENTAÇÃO DE TERRA | B3: =+'Gerenciamento executivo '!B3 -> 71531.25 | C3: =B3/B$18 -> 0.0028964297 | D3: =B3/H$11 -> 6.97857 | E3: =B3/H$7 -> 1324.6528
A4: INFRAESTRUTURA | B4: =+'Gerenciamento executivo '!B4 -> 1364173.9 | C4: =B4/B$18 -> 0.055237868 | D4: =B4/H$11 -> 133.08845 | E4: =B4/H$7 -> 25262.479
A5: SUPRAESTRUTURA | B5: =+'Gerenciamento executivo '!B5 -> 5582951.2 | C5: =B5/B$18 -> 0.22606379 | D5: =B5/H$11 -> 544.67126 | E5: =B5/H$7 -> 103387.99
A6: ALVENARIA | B6: =+'[1]Gerenciamento executivo '!B6 -> 965384.86 | C6: =B6/B$18 -> 0.039090179 | D6: =B6/H$11 -> 94.182694 | E6: =B6/H$7 -> 17877.497
A7: INSTALAÇÕES ELÉTRICAS, HIDRÁULICAS, GLP E PREVENTIVAS | B7: =+'Gerenciamento executivo '!B7 -> 2595791 | C7: =B7/B$18 -> 0.10510827 | D7: =B7/H$11 -> 253.24469 | E7: =B7/H$7 -> 48070.204 | H7: 54
A8: SISTEMAS E EQUIPAMENTOS ESPECIAIS | B8: =+'Gerenciamento executivo '!B8 -> 1672622.9 | C8: =B8/B$18 -> 0.067727529 | D8: =B8/H$11 -> 163.18066 | E8: =B8/H$7 -> 30974.499
A9: IMPERMEABILIZAÇÃO | B9: =+'Gerenciamento executivo '!B9 -> 467279.84 | C9: =B9/B$18 -> 0.018921006 | D9: =B9/H$11 -> 45.587699 | E9: =B9/H$7 -> 8653.3304
A10: REVESTIMENTOS INTERNOS EM PISO E PAREDE | B10: =+'Gerenciamento executivo '!B10 -> 956255.86 | C10: =B10/B$18 -> 0.03872053 | D10: =B10/H$11 -> 93.292071 | E10: =B10/H$7 -> 17708.442 | I10: REVESTIMENTOS INTERNOS EM PISO E PAREDE
A11: REVESTIMENTOS E ACABAMENTOS INTERNOS EM TETO | B11: =+'Gerenciamento executivo '!B11 -> 256181.1 | C11: =B11/B$18 -> 0.010373236 | D11: =B11/H$11 -> 24.992961 | E11: =B11/H$7 -> 4744.0944 | H11: 10250.13 | I11: REVESTIMENTOS E ACABAMENTOS INTERNOS EM TETO
A12: ACABAMENTOS EM PISO E PAREDE | B12: =+'Gerenciamento executivo '!B12 -> 1598846.9 | C12: =B12/B$18 -> 0.064740204 | D12: =B12/H$11 -> 155.98309 | E12: =B12/H$7 -> 29608.276 | I12: ACABAMENTOS EM PISO E PAREDE
A13: PINTURA INTERNA | B13: =+'Gerenciamento executivo '!B13 -> 1281142.7 | C13: =B13/B$18 -> 0.051875785 | D13: =B13/H$11 -> 124.98795 | E13: =B13/H$7 -> 23724.865 | I13: PINTURA INTERNA
A14: ESQUADRIAS, VIDROS E FERRAGENS | B14: =+'Gerenciamento executivo '!B14 -> 2397558.2 | C14: =B14/B$18 -> 0.097081468 | D14: =B14/H$11 -> 233.90515 | E14: =B14/H$7 -> 44399.226 | I14: ESQUADRIAS, VIDROS E FERRAGENS
A15: COBERTURA | B15: =+'Gerenciamento executivo '!B15 -> 313624.06 | C15: =B15/B$18 -> 0.012699206 | D15: =B15/H$11 -> 30.597081 | E15: =B15/H$7 -> 5807.853 | I15: COBERTURA
A16: REVESTIMENTOS E ACABAMENTOS DE FACHADA | B16: =+'Gerenciamento executivo '!B16 -> 1117409.6 | C16: =B16/B$18 -> 0.045245935 | D16: =B16/H$11 -> 109.01419 | E16: =B16/H$7 -> 20692.77 | I16: REVESTIMENTOS E ACABAMENTOS DE FACHADA
A17: SERVIÇOS COMPLEMENTARES | B17: =+'Gerenciamento executivo '!B17 -> 1282500 | C17: =B17/B$18 -> 0.051930745 | D17: =B17/H$11 -> 125.12036 | E17: =B17/H$7 -> 23750
A18: TOTAL | B18: =SUM(B2:B17) -> 24696353 | C18: =SUM(C2:C17) -> 1 | D18: =SUM(D2:D17) -> 2409.3697 | E18: =SUM(E2:E17) -> 457339.87
A19: CUB/SC | B19: 2307.92 | C19: 44378 | D19: =+D18/B19 -> 1.0439572 | E19: CUBs

Sheet Curva ABC
A1: ETAPA | B1: VALOR TOTAL (R$) | C1: %
A2: MÃO DE OBRA EMPREITADA PARA EXECUÇÃO DE ESTRUTURA DE CONCRETO ARMADO EM SUPRAESTRUTURA* | B2: 1797638.4 | C2: 7.307
A3: CONCRETO USINADO BOMBEÁVEL, PARA SUPRAESTRUTURA, FCK 35MPA, SLUMP 10+/- 2, INCLUINDO SERVIÇO DE BOMBEAMENTO* | B3: 890507.44 | C3: 10.9267
A4: MOBILIARIO E DECORAÇÃO* | B4: 675000 | C4: 13.6704
A5: ARMAÇÃO AÇO CA-50, DIÂMETRO 6,3MM PARA SUPRAESTRUTURA - CORTADO E DOBRADO EM INDÚSTRIA* | B5: 584807.88 | C5: 16.0475
A6: MÃO DE OBRA EMPREITADA PARA INSTALAÇÕES HIDRÁULICAS E SANITÁRIAS* | B6: 531382.5 | C6: 18.2074
A7: MÃO DE OBRA EMPREITADA PARA INSTALAÇÕES ELÉTRICAS* | B7: 456361.65 | C7: 20.0624

Sheet Planilha2
A1: DESCRIÇÃO
A2: EXECUCAO TAPUME METALICO H=3,00M
A3: CONCRETO CONVENCIONAL RODADO EM OBRA 20MPA
A4: ALUGUEL GERADOR 3,0KW
A5: ALUGUEL BETONEIRA 400L
A6: EXECUCAO SAPATAS (0,5 x 0,5 x 0,4m) PARA CONTAINER DE PLANTAO DE VENDAS
A7: EXECUCAO DE VIGA DE CONCRETO (0,2 X 0,3M) PARA TRILHO DE PORTAO DE OBRA
A8: EXECUCAO DE GUIA DE TRAVAMENTO PARA PAVER
A9: EXECUCAO DE MEIO FIO
A10: FABRICAÇÃO, MONTAGEM E DESMONTAGEM DE FORMA PARA BLOCOS DE COROAMENTO E VIGAS BALDRAMES, EM COMPENSADO RESINADO 17MM
A11: IMPERMEABILIZAÇÃO DE BALDRAMES COM TINTA ASFÁLTICA*
A12: PREPARACAO SUBSTRATO PARA RECEBIMENTO PISO DE CONCRETO (LONA+BRITA)
... A454: ITENS ADICIONAIS ELÉTRICA - TORRE B*

Sheet Planilha3
A1: DESCRIÇÃO | B1: VALOR | C1: TIPO
A2: MÃO DE OBRA EMPREITADA PARA EXECUÇÃO DE ESTRUTURA DE CONCRETO ARMADO EM SUPRAESTRUTURA* | B2: 1797638.4 | C2: MÃO DE OBRA | E2: MÃO DE OBRA | F2: =SUMIF($C$2:$C$418,E2,$B$2:$B$418) -> 6599033.8 | G2: =+F2/$F$9 -> 0.26823502
A3: CONCRETO USINADO BOMBEÁVEL, PARA SUPRAESTRUTURA, FCK 35MPA, SLUMP 10+/- 2, INCLUINDO SERVIÇO DE BOMBEAMENTO* | B3: 890507.44 | C3: MATERIAIS | E3: MATERIAIS | F3: =SUMIF($C$2:$C$418,E3,$B$2:$B$418) -> 10596923 | G3: =+F3/$F$9 -> 0.43073972
A4: MOBILIARIO E DECORAÇÃO* | B4: 675000 | C4: SERVIÇOS COMPLEMENTARES | E4: SERVIÇOS - MATERIAL E MÃO DE OBRA | F4: =SUMIF($C$2:$C$418,E4,$B$2:$B$418) -> 3563262.2 | G4: =+F4/$F$9 -> 0.14483813
A5: ARMAÇÃO AÇO CA-50, DIÂMETRO 6,3MM PARA SUPRAESTRUTURA - CORTADO E DOBRADO EM INDÚSTRIA* | B5: 584807.88 | C5: MATERIAIS | E5: SERVIÇOS COMPLEMENTARES | F5: =SUMIF($C$2:$C$418,E5,$B$2:$B$418) -> 1282500 | G5: =+F5/$F$9 -> 0.052130573
A6: MÃO DE OBRA EMPREITADA PARA INSTALAÇÕES HIDRÁULICAS E SANITÁRIAS* | B6: 531382.5 | C6: MÃO DE OBRA | E6: MÃO DE OBRA PRÓPRIA | F6: =SUMIF($C$2:$C$418,E6,$B$2:$B$418) -> 838800 | G6: =+F6/$F$9 -> 0.034095224
A7: MÃO DE OBRA EMPREITADA PARA INSTALAÇÕES ELÉTRICAS* | B7: 456361.65 | C7: MÃO DE OBRA | E7: DESPESAS INDIRETAS | F7: =SUMIF($C$2:$C$418,E7,$B$2:$B$418) -> 1042077.5 | G7: =+F7/$F$9 -> 0.042357971
A8: MESTRE DE OBRAS* | B8: 432000 | C8: MÃO DE OBRA PRÓPRIA | E8: EQUIPAMENTOS | F8: =SUMIF($C$2:$C$418,E8,$B$2:$B$418) -> 679089.29 | G8: =+F8/$F$9 -> 0.027603364
A9: MÃO DE OBRA MISTA PARA REBOCO INTERNO EM PAREDES, INCLUSO CHAPISCO* | B9: 389358.92 | C9: MÃO DE OBRA | F9: =SUM(F2:F8) -> 24601686 | G9: =+F9/$F$9 -> 1
A10: MÃO DE OBRA EMPREITADA PARA EXECUÇÃO DE BLOCOS E BALDRAMES* | B10: 378132.5 | C10: MÃO DE OBRA
A11: IMPREVISTOS E CONTINGÊNCIAS* | B11: 345000 | C11: SERVIÇOS COMPLEMENTARES
A12: CONCRETO USINADO BOMBEÁVEL, PARA ESTACAS, FCK 30MPA, SLUMP 22+-3CM BRITA 0, INCLUI SERVIÇO DE BOMBEAMENTO* | B12: 314496 | C12: MATERIAIS
A13: ARMAÇÃO AÇO CA-50, DIÂMETRO 10,0MM PARA SUPRAESTRUTURA - CORTADO E DOBRADO EM INDÚSTRIA* | B13: 310081.2 | C13: MATERIAIS
A14: ELEVADOR SOCIAL* | B14: 280000 | C14: SERVIÇOS - MATERIAL E MÃO DE OBRA
A15: PORTA DE MADEIRA, DE ABRIR 80X210CM, FIXAÇÃO COM ESPUMA EXPANSIVA* | B15: 277224.04 | C15: MATERIAIS
A16: PELE DE VIDRO* | B16: 262548 | C16: SERVIÇOS - MATERIAL E MÃO DE OBRA
A17: PISO DE CONCRETO SOBRE SOLO, ESPESSURA 15 CM | B17: 261966.43 | C17: MATERIAIS
A18: MÃO DE OBRA EMPREITADA VEDAÇÕES INTERNAS E EXTERNAS - ASSENTAMENTO BLOCOS CERÂMICOS* | B18: 255137.12 | C18: MÃO DE OBRA
A19: FABRICAÇÃO DE FÔRMA PARA LAJES, EM CHAPAS DE MADEIRA COMPENSADA PLASTIFICADA, E=18MM* | B19: 241776.87 | C19: MATERIAIS
A20: GUARDA-CORPO DE ALUMÍNIO COM VIDRO LAMINADO, FIXAÇÃO COM ADESIVO EPÓXI* | B20: 233449.95 | C20: SERVIÇOS - MATERIAL E MÃO DE OBRA
A21: PORTA DE MADEIRA, DE ABRIR 60X210CM, FIXAÇÃO COM ESPUMA EXPANSIVA* | B21: 219342.11 | C21: MATERIAIS
... A418: CHAPISCO INTERNO DE ARGAMASSA CIMENTO E AREIA (1:4), APLICADO EM TETO, COM DESEMPENADEIRA DENTADA* | B418: 9.74 | C418: MATERIAIS
