Workbook
Name \0: #REF!
Name \0: #REF!
Name \1: #REF!
Name \1: #REF!
Name \a: #REF!
Name \b: #REF!
Name \c: #REF!
Name \d: #REF!
Name \e: #REF!
Name \i: #REF!
Name \J: #REF!
Name \k: #REF!
Name \l: #N/A
Name \m: #REF!
Name \m: #REF!
Name \o: #REF!
Name \o: #REF!
Name \p: #REF!
Name \p: #REF!
Name \r: #REF!
Name \T: #REF!
Name \z: #REF!
Name _: #REF!
Name _\0: #REF!
Name _\0: #REF!
Name _\1: #REF!
Name _\a: #REF!
Name _\b: #REF!
Name _\c: #REF!
Name _\d: #REF!
Name _\e: #REF!
Name _\i: #REF!
Name _\J: #REF!
Name _\k: #REF!
Name _\l: #N/A
Name _\m: #REF!
Name _\m: #REF!
Name _\o: #REF!
Name _\o: #REF!
Name _\p: #REF!
Name _\p: #REF!
Name _\r: #REF!
Name _\T: #REF!
Name _\z: #REF!
Name _\z: #REF!
Name __: #REF!
Name ______ACR10: #REF!
Name ______ACR10: #REF!
Name ______ACR15: #REF!
Name ______ACR15: #REF!
Name ______acr20: #REF!
Name ______acr20: #REF!
Name ______acr5: #REF!
Name ______ARQ1: #REF!
Name ______QT100: #REF!
Name ______QT2: #REF!
Name ______QT3: #REF!
Name ______QT4: #REF!
Name ______QT50: #REF!
Name ______QT75: #REF!

Sheet Resumo Estrutura
B1: Projeto: | C1: =[1]CAPA!$C$2 -> Elizabeth II Royal Home
B2: Empresa: | C2: =[1]CAPA!$C$3 -> Gessele
B3: Revisão: | C3: R00
A4: Item | B4: Disciplina | C4: EAP - Arquitetura | D4: Pavimento Proj. Estrutural | E4: Etapa | F4: Projetos | G4: Área Pavimento | H4: Mpa | I4: Concreto | J4: Forma Convencional | K4: Forma Convencional Fabricação | L4: Cubeta inteira | M4: Meia Cubeta | N4: Aço | O4: Ø5.0mm 0,154 kg/m | P4: Ø6.3mm 0,245 kg/m | Q4: Ø8.0mm 0,395 kg/m | R4: Ø10.0mm 0,617 kg/m | S4: Ø12.5mm 0,963 kg/m | T4: Ø16.0mm 1,578 kg/m | U4: Ø20.0mm 2,466 kg/m | V4: Ø25.0mm 3,853 kg/m | W4: Ø32.0mm 6,313 kg/m
A5: Torre | O5: =O81/SUM($O$81:$W$81) -> 0.0056284419 | P5: =P81/SUM($O$81:$W$81) -> 0.063127632 | Q5: =Q81/SUM($O$81:$W$81) -> 0.069768384 | R5: =R81/SUM($O$81:$W$81) -> 0.079324587 | S5: =S81/SUM($O$81:$W$81) -> 0.089771623 | T5: =T81/SUM($O$81:$W$81) -> 0.030085844 | U5: =U81/SUM($O$81:$W$81) -> 0.11503887 | V5: =V81/SUM($O$81:$W$81) -> 0.54725462 | W5: =W81/SUM($O$81:$W$81) -> 0
A6: =A5 -> Torre | B6: Fundação | C6: Contenções | D6: Contenções | E6: Mureta guia | F6: PR-1248-00-CON-FO-01-R00 | H6: 50 | I6: ='[1]Fund. Rasa | Contenção'!AG84 -> 11.390452 | J6: ='[1]Fund. Rasa | Contenção'!AD84 -> 222.6272 | N6: =SUM(O6:W6) -> 711.9216 | P6: =(30*48+(1.02+1.07+0.07+0.02+0.07+0.17+0.12+0.07+0.02+0.07)*48*2/0.2)*0.245 -> 670.32 | S6: =0.45*48*2*0.963 -> 41.6016
A7: =A5 -> Torre | B7: Fundação | C7: Contenções | D7: Contenções | E7: Parede de Diafragma | H7: 50 | I7: 210 | J7: 1050 | N7: =SUM(O7:W7) -> 18250 | P7: 2282 | Q7: 77 | S7: 3884 | V7: 12007
A8: =A7 -> Torre | B8: Fundação | C8: Contenções | D8: Contenções | E8: Estroncas | F8: PR-1248-00-CON-FO-01-R00 | H8: 50 | I8: 8.4 | J8: 37.2 | N8: =SUM(O8:W8) -> 608.81818 | Q8: =(62+84.7)/1.1 -> 133.36364 | S8: =49.9/1.1 -> 45.363636 | U8: =473.1/1.1 -> 430.09091
A9: =A7 -> Torre | B9: Fundação | C9: Contenções | D9: Contenções | E9: Viga Coroamento | F9: PR-1248-00-CON-VI-01-R01 | H9: 50 | I9: 9.4 | J9: 45.6 | N9: =SUM(O9:W9) -> 2057.2727 | Q9: =858/1.1 -> 780 | T9: =1405/1.1 -> 1277.2727
D10: TOTAL - CONTENÇÃO | I10: =SUM(I7:I9) -> 227.8 | J10: =SUM(J7:J9) -> 1132.8 | K10: =SUM(K7:K9) -> 0 | L10: =SUM(L7:L9) -> 0 | M10: =SUM(M7:M9) -> 0 | N10: =SUM(N7:N9) -> 20916.091 | O10: =SUM(O7:O9) -> 0 | P10: =SUM(P7:P9) -> 2282 | ... W10: =SUM(W7:W9) -> 0
A11: =A5 -> Torre | B11: Fundação | C11: Fundação - Estacas | D11: Fundação | E11: Estacas | H11: 50 | I11: =[1]Estacas!K7 -> 83.448555 | P11: =[1]Estacas!M7 -> 6175 | U11: =[1]Estacas!N7 -> 41456
D12: TOTAL - FUNDAÇÃO ESTACA | I12: =SUM(I11) -> 83.448555 | J12: =SUM(J11) -> 0 | K12: =SUM(K11) -> 0 | L12: =SUM(L11) -> 0 | M12: =SUM(M11) -> 0 | N12: =SUM(N11) -> 0 | O12: =SUM(O11) -> 0 | P12: =SUM(P11) -> 6175 | ... W12: =SUM(W11) -> 0
A13: =A5 -> Torre | B13: Fundação | C13: Fundação - Blocos | D13: Fundação | E13: Blocos | F13: PR-1248-00-FUN-AR-01-R01 | H13: 50 | I13: 658.5 | J13: 524.5 | N13: =SUM(O13:W13) -> 69835.455 | S13: =581/1.1 -> 528.18182 | T13: =8065/1.1 -> 7331.8182 | U13: =1450/1.1 -> 1318.1818 | V13: =66723/1.1 -> 60657.273
D14: TOTAL - FUNDAÇÃO BLOCOS | I14: =SUM(I13) -> 658.5 | J14: =SUM(J13) -> 524.5 | K14: =SUM(K13) -> 0 | L14: =SUM(L13) -> 0 | M14: =SUM(M13) -> 0 | N14: =SUM(N13) -> 69835.455 | O14: =SUM(O13) -> 0 | P14: =SUM(P13) -> 0 | ... W14: =SUM(W13) -> 0
A15: =A5 -> Torre | B15: Fundação | C15: Fundação - Vigas etc. | D15: Fundação | E15: Pilares | F15: PR-1248-00-FUN-AR-01-R01 | H15: 50 | I15: 18.7 | J15: 122.9 | N15: =SUM(O15:W15) -> 44086 | O15: =31 -> 31 | P15: =97+14+12 -> 123 | Q15: =83+15+1 -> 99 | R15: =4397+153+1118 -> 5668 | S15: =4398+60+195 -> 4653 | T15: =484+130 -> 614 | U15: =902 -> 902 | V15: =3332+1348 -> 4680 | W15: =27316 -> 27316
A16: =A5 -> Torre | B16: Fundação | C16: Fundação - Vigas etc. | D16: Fundação | E16: Vigas | H16: 50
A17: =A16 -> Torre | B17: Fundação | C17: Fundação - Vigas etc. | D17: Fundação | E17: Laje p/ equipamentos | F17: PR-1248-00-FUN-LA-01-R01 | H17: 50 | I17: =1.4*(1.19*2.325)+0.3*(4.2*4.2) -> 9.16545 | J17: =4.2*4*0.3+(1.19*2+2.325*2)*1.4 -> 14.882 | N17: =SUM(O17:W17) -> 829.90909 | S17: =(191.8+551.8)/1.1 -> 676 | T17: =169.3/1.1 -> 153.90909
A18: =A5 -> Torre | B18: Fundação | C18: Fundação - Vigas etc. | D18: Fundação | E18: Contrapiso | H18: 50 | N18: =SUM(O18:W18) -> 17 | O18: =11 -> 11 | R18: =6 -> 6
A19: =A5 -> Torre | B19: Fundação | C19: Fundação - Vigas etc. | D19: Fundação | E19: Cisternas | F19: PR-1248-01-CIS-FO-01-R02 | H19: 50 | I19: ='[1]Cálculo de apoio'!D8 -> 23.18176 | J19: ='[1]Cálculo de apoio'!E6 -> 28.95 | N19: =SUM(O19:W19) -> 3419.1818 | O19: ='[1]Cálculo de apoio'!J8 -> 10 | P19: ='[1]Cálculo de apoio'!K8 -> 7.2727273 | Q19: ='[1]Cálculo de apoio'!L8 -> 883.63636 | R19: ='[1]Cálculo de apoio'!M8 -> 1337.6364 | S19: ='[1]Cálculo de apoio'!N8 -> 678.81818 | T19: ='[1]Cálculo de apoio'!O8 -> 501.81818 | U19: ='[1]Cálculo de apoio'!P8 -> 0 | V19: ='[1]Cálculo de apoio'!Q8 -> 0
A20: =A5 -> Torre | B20: Fundação | C20: Fundação - Vigas etc. | D20: Fundação | E20: Dutos | H20: 50 | N20: =SUM(O20:W20) -> 0
C21: TOTAL - VIGAS BALDRAMES/PILARES DE ARRANQUE/CISTERNAS E DUTOS | I21: =SUM(I15:I20) -> 51.04721 | J21: =SUM(J15:J20) -> 166.732 | K21: =SUM(K15:K20) -> 0 | L21: =SUM(L15:L20) -> 0 | M21: =SUM(M15:M20) -> 0 | N21: =SUM(N15:N20) -> 48352.091 | O21: =SUM(O15:O20) -> 52 | P21: =SUM(P15:P20) -> 130.27273 | ... W21: =SUM(W15:W20) -> 27316
A22: =A20 -> Torre | B22: Supraestrutura | C22: Térreo | D22: Térreo | E22: Pilares | H22: 50 | K22: =J28*3 -> 1733.4 | N22: =SUM(O22:W22) -> 0
A23: =A22 -> Torre | B23: Supraestrutura | C23: Térreo | D23: Térreo | E23: Vigas | H23: 50 | I23: 106.6 | J23: 582.1 | K23: =J23*3 -> 1746.3 | N23: =SUM(O23:W23) -> 17598 | P23: 1364 | Q23: 1169 | R23: 2046 | S23: 1225 | T23: 1240 | U23: 3719 | V23: 6835
A24: =A23 -> Torre | B24: Supraestrutura | C24: Térreo | D24: Térreo | E24: Lajes | H24: 50 | I24: 97 | K24: =J30*3 -> 1261.185 | N24: =SUM(O24:W24) -> 4886.3636 | P24: =777.2/1.1+909.4/1.1+1201.9/1.1+1189.3/1.1 -> 3707.0909 | Q24: =673.2/1.1+292.6/1.1+267.4/1.1+64/1.1 -> 1179.2727
A25: =A24 -> Torre | B25: Supraestrutura | C25: Térreo | D25: Térreo | E25: Capiteis | H25: 50 | N25: =SUM(O25:W25) -> 0
A26: =A25 -> Torre | B26: Supraestrutura | C26: Térreo | D26: Térreo | E26: Lajes | H26: 50 | I26: 4.8 | J26: =(0.5816+0.5128+(3.01+2.65)*1.2+3.1+3.2*1.2)/1.6*4.8 -> 44.4792 | K26: =J32*3 -> 133.4376 | N26: =SUM(O26:W26) -> 302.54545 | P26: =10/1.1 -> 9.0909091 | Q26: 9 | R26: =55/1.1+36/1.1+25/1.1 -> 105.45455 | S26: 145 | T26: 34
D27: ="TOTAL - "&UPPER(C26) -> TOTAL - TÉRREO | I27: =SUM(I22:I26) -> 208.4 | J27: =SUM(J22:J26) -> 626.5792 | K27: =SUM(K22:K26) -> 4874.3226 | L27: =SUM(L22:L26) -> 0 | M27: =SUM(M22:M26) -> 0 | N27: =SUM(N22:N26) -> 22786.909 | O27: =SUM(O22:O26) -> 0 | P27: =SUM(P22:P26) -> 5080.1818 | ... W27: =SUM(W22:W26) -> 0
A28: =A5 -> Torre | B28: Supraestrutura | C28: Mezanino G1 | D28: Garagem G1 | E28: Pilares | H28: 50 | I28: 101.9 | J28: 577.8 | N28: =SUM(O28:W28) -> 45075 | P28: 311 | Q28: 278 | R28: 6542 | S28: 8103 | T28: 760 | U28: 629 | V28: 7983 | W28: 20469
A29: =A5 -> Torre | B29: Supraestrutura | C29: Mezanino G1 | D29: Garagem G1 | E29: Vigas | H29: 50 | I29: 37 | J29: 329.6 | N29: =SUM(O29:W29) -> 7215 | O29: 5 | P29: 449 | Q29: 632 | R29: 246 | S29: 964 | T29: 1526 | U29: 1632 | V29: 1761
A30: =A5 -> Torre | B30: Supraestrutura | C30: Mezanino G1 | D30: Garagem G1 | E30: Lajes | H30: 50 | I30: 101.3 | J30: =I30*4.15 -> 420.395 | N30: =SUM(O30:W30) -> 6276 | P30: 275 | Q30: 4210 | R30: 1216 | S30: 247 | T30: 328
A31: =A7 -> Torre | B31: Supraestrutura | C31: Mezanino G1 | D31: Garagem G1 | E31: Capiteis | H31: 50 | N31: =SUM(O31:W31) -> 580.90909 | P31: =7/1.1 -> 6.3636364 | Q31: =8/1.1 -> 7.2727273 | S31: =263/1.1 -> 239.09091 | T31: =361/1.1 -> 328.18182
A32: =A5 -> Torre | B32: Supraestrutura | C32: Mezanino G1 | D32: Garagem G1 | E32: Escadas | H32: 50 | I32: 4.8 | J32: =(0.5816+0.5128+(3.01+2.65)*1.2+3.1+3.2*1.2)/1.6*4.8 -> 44.4792 | N32: =SUM(O32:W32) -> 302.54545 | P32: =10/1.1 -> 9.0909091 | Q32: 9 | R32: =55/1.1+36/1.1+25/1.1 -> 105.45455 | S32: 145 | T32: 34
D33: ="TOTAL - "&UPPER(C32) -> TOTAL - MEZANINO G1 | I33: =SUM(I28:I32) -> 245 | J33: =SUM(J28:J32) -> 1372.2742 | K33: =SUM(K28:K32) -> 0 | L33: =SUM(L28:L32) -> 0 | M33: =SUM(M28:M32) -> 0 | N33: =SUM(N28:N32) -> 59449.455 | O33: =SUM(O28:O32) -> 5 | P33: =SUM(P28:P32) -> 1050.4545 | ... W33: =SUM(W28:W32) -> 20469
A34: =A5 -> Torre | B34: Supraestrutura | C34: G2 | D34: Garagem G2 | E34: Pilares | H34: 50 | I34: 73.8 | J34: 477.3 | N34: =SUM(O34:W34) -> 28668 | P34: 318 | Q34: 265 | R34: 3264 | S34: 4826 | T34: 604 | U34: 353 | V34: 5463 | W34: 13575
A35: =A5 -> Torre | B35: Supraestrutura | C35: G2 | D35: Garagem G2 | E35: Vigas | H35: 50 | I35: 31.8 | J35: 303.1 | N35: =SUM(O35:W35) -> 6621 | O35: 1 | P35: 500 | Q35: 693 | R35: 188 | S35: 866 | T35: 1890 | U35: 1043 | V35: 1440
A36: =A5 -> Torre | B36: Supraestrutura | C36: G2 | D36: Garagem G2 | E36: Lajes | H36: 50 | I36: 174.5 | J36: =I36*4.15 -> 724.175 | N36: =SUM(O36:W36) -> 11527 | P36: 705 | Q36: 7045 | R36: 3087 | S36: 63 | T36: 627
A37: =A7 -> Torre | B37: Supraestrutura | C37: G2 | D37: Garagem G2 | E37: Capiteis | H37: 50 | N37: =SUM(O37:W37) -> 1879.0909 | P37: =31/1.1 -> 28.181818 | Q37: =40/1.1 -> 36.363636 | R37: =333/1.1 -> 302.72727 | S37: =236/1.1 -> 214.54545 | T37: =1427/1.1 -> 1297.2727
A38: =A5 -> Torre | B38: Supraestrutura | C38: G2 | D38: Garagem G2 | E38: Escadas | H38: 50 | I38: 1.6 | J38: =(0.5816+0.5128+(3.01+2.65)*1.2+3.1+3.2*1.2)*1 -> 14.8264 | N38: =SUM(O38:W38) -> 106 | P38: 20 | Q38: 14 | R38: 72
D39: ="TOTAL - "&UPPER(C38) -> TOTAL - G2 | I39: =SUM(I34:I38) -> 281.7 | J39: =SUM(J34:J38) -> 1519.4014 | K39: =SUM(K34:K38) -> 0 | L39: =SUM(L34:L38) -> 0 | M39: =SUM(M34:M38) -> 0 | N39: =SUM(N34:N38) -> 48801.091 | O39: =SUM(O34:O38) -> 1 | P39: =SUM(P34:P38) -> 1571.1818 | ... W39: =SUM(W34:W38) -> 13575
A40: =A5 -> Torre | B40: Supraestrutura | C40: Mezanino G2 | D40: Garagem G3 | E40: Pilares | H40: 50 | I40: 79 | J40: 506.1 | N40: =SUM(O40:W40) -> 15968.154 | O40: =O$5*$N40 -> 89.875825 | P40: =P$5*$N40 -> 1008.0317 | Q40: =Q$5*$N40 -> 1114.0723 | R40: =R$5*$N40 -> 1266.6672 | S40: =S$5*$N40 -> 1433.4871 | T40: =T$5*$N40 -> 480.41538 | U40: =U$5*$N40 -> 1836.9584 | V40: =V$5*$N40 -> 8738.6458 | W40: =W$5*$N40 -> 0
...

Sheet RESUMO
A1: Projetista 1203 (Rubens Alves) — Fundação Electra consolidado
A2: Gerado: 2026-04-17 | Fonte LIBERTÉ: 1203-2025-R0
A4: 1. Fundação Profunda (Estacas Hélice Contínua) — Empreendimento
A5: Fonte | B5: Ø (m) | C5: Qtd (un) | D5: L médio (m) | E5: L total (m) | F5: Concreto (m³) | G5: Aço ø6.3 (kg) | H5: Aço ø16 (kg)
A6: LIBERTÉ (proposta) | B6: 0.5 | C6: 17 | D6: 25 | E6: 425 | F6: 83.45
A7: LIBERTÉ (proposta) | B7: 0.6 | C7: 406 | D7: 25 | E7: 10150 | F7: 2869.84
A8: LIBERTÉ total (sem sobre) | C8: 423 | E8: 10575 | F8: 2953.33 | G8: 6175 | H8: 41456
A9: LIBERTÉ total (+20% sobre) | F9: 3544
A11: Fonte | F11: Concreto (m³) | G11: Aço ø6.3 (kg) | H11: Aço ø16 (kg)
A12: Bloco A (CONTROLE-REV) | F12: 1424.1667 | G12: 3002 | H12: 20183
A13: Bloco B (CONTROLE-REV) | F13: 1529.1667 | G13: 3173 | H13: 21273
A14: Soma A + B | F14: 2953.3333 | G14: 6175 | H14: 41456
A16: Validação cruzada CONTROLE-REV vs LIBERTÉ
A17: Aço total estacas | F17: CR A+B: | G17: 47631 | H17: 47631
A18: Divergência aço | G18: 0 | H18: %
A20: 2. Fundação Rasa / Blocos de Coroamento
A21: Bloco | B21: Item | C21: Fôrma (m²) | D21: Volume (m³) | E21: Aço total (kg)
A22: A | B22: Lajes maciças (topo arquivo — Laje Fund?) | C22: 0 | D22: 1021.75 | E22: 112136
A23: B | B23: Zapatas isoladas | C23: 1.44 | D23: 0.216 | E23: 15
A24: B | B24: Blocos de coroamento | C24: 746.31 | D24: 750.967 | E24: 66021
A26: Resumo QUANT-A (r245-247) | D26: Volume (m³) | E26: Aço (kg)
A27: HÉLICE | D27: 2200 | E27: 47631
A28: BLOCOS | D28: 2066.36 | E28: 213051
A29: TOTAL | D29: 15597.7 | E29: 1683602

Sheet Supra A por pav
A1: Supraestrutura Bloco A — aço por bitola + concreto
A3: Pavimento | B3: Elemento | C3: øQ92 (kg) | D3: ø5 (kg) | E3: ø6.3 (kg) | F3: ø8 (kg) | G3: ø10 (kg) | H3: ø12.5 (kg) | I3: ø16 (kg) | J3: ø20 (kg) | K3: ø25 (kg) | L3: Aço total (kg) | M3: Concreto (m³)
A4: L1 - Térreo | B4: Vigas | C4: 0 | D4: 218 | E4: 553 | F4: 531 | G4: 474 | H4: 1492 | I4: 1453 | J4: 2020 | K4: 0 | L4: 6741 | M4: 58.7
A5: L1 - Térreo | B5: Pilares | C5: 0 | D5: 0 | E5: 0 | F5: 0 | G5: 0 | H5: 0 | I5: 0 | J5: 0 | K5: 0 | L5: 0 | M5: 0
A6: L1 - Térreo | B6: Lajes | C6: 1068 | D6: 0 | E6: 76 | F6: 3868 | G6: 1310 | H6: 0 | I6: 0 | J6: 0 | K6: 0 | L6: 6322 | M6: 90.8
A7: L1 - Térreo | B7: Escadas | C7: 0 | D7: 0 | E7: 0 | F7: 0 | G7: 0 | H7: 0 | I7: 0 | J7: 0 | K7: 0 | L7: 0 | M7: 0
A8: L1 - Térreo | B8: Rampas | C8: 0 | D8: 0 | E8: 0 | F8: 0 | G8: 0 | H8: 0 | I8: 0 | J8: 0 | K8: 0 | L8: 0 | M8: 0
A9: L1 - Térreo | B9: Blocos | C9: 0 | D9: 75 | E9: 160 | F9: 1785 | G9: 861 | H9: 6907 | I9: 20136 | J9: 31531 | K9: 53447 | L9: 114902 | M9: 1021.75
A10: L1 - Térreo | B10: Reserv. Inferior | C10: 0 | D10: 0 | E10: 169 | F10: 361 | G10: 1691 | H10: 0 | I10: 647.27273 | J10: 0 | K10: 0 | L10: 2868.2727 | M10: 22.5
A11: L1 - Térreo | B11: Duto | C11: 0 | D11: 0 | E11: 358 | F11: 1165 | G11: 11 | H11: 750 | I11: 0 | J11: 0 | K11: 0 | L11: 2284 | M11: 22.3
A12: L1 - Térreo | B12: TOTAL | C12: 1068 | D12: 293 | E12: 1316 | F12: 7710 | G12: 4347 | H12: 9149 | I12: 22236.273 | J12: 33551 | K12: 53447 | L12: 133117.27 | M12: 1216.05
A13: L2 - Garagem 1 | B13: Vigas | C13: 0 | D13: 198 | E13: 633 | F13: 19 | G13: 423 | H13: 736 | I13: 707 | J13: 1221 | K13: 0 | L13: 3937 | M13: 39
A14: L2 - Garagem 1 | B14: Pilares | C14: 0 | D14: 115 | E14: 143 | F14: 1617 | G14: 194 | H14: 111 | I14: 567 | J14: 3951 | K14: 7767 | L14: 14465 | M14: 56.4
A15: L2 - Garagem 1 | B15: Lajes | C15: 1046 | D15: 0 | E15: 0 | F15: 2012 | G15: 930 | H15: 1314 | I15: 2937 | J15: 0 | K15: 0 | L15: 8239 | M15: 105.5
... A204: L33 - Casa de Máquinas, L34/L35 - Reservatório Inferior (JUNTOS) | B204: TOTAL | C204: 0 | D204: 81 | E204: 544 | F204: 1931 | G204: 960 | H204: 745 | I204: 1935 | J204: 0 | K204: 0 | L204: 6196 | M204: 63.83

Sheet Supra B por pav
A1: Supraestrutura Bloco B — aço por bitola + concreto
A3: Pavimento | B3: Elemento | C3: øQ92 (kg) | D3: ø5 (kg) | E3: ø6.3 (kg) | F3: ø8 (kg) | G3: ø10 (kg) | H3: ø12.5 (kg) | I3: ø16 (kg) | J3: ø20 (kg) | K3: ø25 (kg) | L3: Aço total (kg) | M3: Concreto (m³)
A4: L1 - Térreo | B4: Vigas | C4: 0 | D4: 349 | E4: 1084 | F4: 478 | G4: 841 | H4: 2155 | I4: 1720 | J4: 3033 | K4: 0 | L4: 9660 | M4: 80.83
A5: L1 - Térreo | B5: Pilares | C5: 0 | D5: 0 | E5: 0 | F5: 0 | G5: 0 | H5: 0 | I5: 0 | J5: 0 | K5: 0 | L5: 0 | M5: 0
A6: L1 - Térreo | B6: Lajes | C6: 1744 | D6: 0 | E6: 247 | F6: 4858 | G6: 3533 | H6: 488.2 | I6: 0 | J6: 0 | K6: 0 | L6: 10870.2 | M6: 147
A7: L1 - Térreo | B7: Escadas | C7: 0 | D7: 0 | E7: 0 | F7: 0 | G7: 0 | H7: 0 | I7: 0 | J7: 0 | K7: 0 | L7: 0 | M7: 0
A8: L1 - Térreo | B8: Rampas | C8: 0 | D8: 0 | E8: 0 | F8: 0 | G8: 0 | H8: 0 | I8: 0 | J8: 0 | K8: 0 | L8: 0 | M8: 0
A9: L1 - Térreo | B9: Blocos | C9: 0 | D9: 87 | E9: 98 | F9: 2400 | G9: 997 | H9: 14785 | I9: 18141 | J9: 14487 | K9: 51689 | L9: 102684 | M9: 1044.61
A10: L1 - Térreo | B10: Reserv. Inferior | C10: 0 | D10: 0 | E10: 0 | F10: 2012 | G10: 7412.9091 | H10: 0 | I10: 2355.4545 | J10: 0 | K10: 0 | L10: 11780.364 | M10: 57.6
A11: L1 - Térreo | B11: Dutos | C11: 0 | D11: 0 | E11: 156 | F11: 4315 | G11: 31 | H11: 889 | I11: 1239 | J11: 0 | K11: 0 | L11: 6630 | M11: 49.2
A12: L1 - Térreo | B12: TOTAL | C12: 1744 | D12: 436 | E12: 1585 | F12: 14063 | G12: 12814.909 | H12: 18317.2 | I12: 23455.455 | J12: 17520 | K12: 51689 | L12: 141624.56 | M12: 1379.24
A13: L2 - Garagem 1 | B13: Vigas | C13: 0 | D13: 275 | E13: 808 | F13: 195 | G13: 645 | H13: 1060 | I13: 323 | J13: 1729 | K13: 0 | L13: 5035 | M13: 25.92
A14: L2 - Garagem 1 | B14: Pilares | C14: 0 | D14: 296 | E14: 141 | F14: 1905 | G14: 181 | H14: 232 | I14: 1017 | J14: 1433 | K14: 14254 | L14: 19459 | M14: 71.59
A15: L2 - Garagem 1 | B15: Lajes | C15: 1635 | D15: 0 | E15: 0 | F15: 3619 | G15: 1414 | H15: 2357 | I15: 5421 | J15: 0 | K15: 0 | L15: 14446 | M15: 168.5
... A204: L33 - Casa de Máquinas, L34/L35 - Reservatório Inferior (JUNTOS) | B204: TOTAL | C204: 0 | D204: 178 | E204: 682 | F204: 1918 | G204: 1254 | H204: 185 | I204: 1890 | J204: 622 | K204: 0 | L204: 6729 | M204: 63.12

Sheet Supra por pavimento
A1: Torre/Bloco | B1: Disciplina | C1: EAP - Supraestrutura | D1: Pavimento Proj. | E1: Elemento | F1: Mpa | G1: Concreto (m³) | H1: Aço Total (kg) | I1: øQ92 | J1: ø5.0 | K1: ø6.3 | L1: ø8.0 | M1: ø10.0 | N1: ø12.5 | O1: ø16.0 | P1: ø20.0 | Q1: ø25.0
A2: Embasamento | B2: Supraestrutura | C2: L1 - Térreo | D2: L1 - Térreo | E2: Vigas | F2: 50 | G2: ='Supra A por pav'!M4+'Supra B por pav'!M4 -> 139.53 | H2: ='Supra A por pav'!L4+'Supra B por pav'!L4 -> 16401 | I2: ='Supra A por pav'!C4+'Supra B por pav'!C4 -> 0 | J2: ='Supra A por pav'!D4+'Supra B por pav'!D4 -> 567 | K2: ='Supra A por pav'!E4+'Supra B por pav'!E4 -> 1637 | L2: ='Supra A por pav'!F4+'Supra B por pav'!F4 -> 1009 | M2: ='Supra A por pav'!G4+'Supra B por pav'!G4 -> 1315 | N2: ='Supra A por pav'!H4+'Supra B por pav'!H4 -> 3647 | O2: ='Supra A por pav'!I4+'Supra B por pav'!I4 -> 3173 | P2: ='Supra A por pav'!J4+'Supra B por pav'!J4 -> 5053 | Q2: ='Supra A por pav'!K4+'Supra B por pav'!K4 -> 0
E3: Pilares | G3: ='Supra A por pav'!M5+'Supra B por pav'!M5 -> 0 | H3: ='Supra A por pav'!L5+'Supra B por pav'!L5 -> 0 | I3: ='Supra A por pav'!C5+'Supra B por pav'!C5 -> 0 | J3: ='Supra A por pav'!D5+'Supra B por pav'!D5 -> 0 | K3: ='Supra A por pav'!E5+'Supra B por pav'!E5 -> 0 | L3: ='Supra A por pav'!F5+'Supra B por pav'!F5 -> 0 | M3: ='Supra A por pav'!G5+'Supra B por pav'!G5 -> 0 | N3: ='Supra A por pav'!H5+'Supra B por pav'!H5 -> 0 | O3: ='Supra A por pav'!I5+'Supra B por pav'!I5 -> 0 | P3: ='Supra A por pav'!J5+'Supra B por pav'!J5 -> 0 | Q3: ='Supra A por pav'!K5+'Supra B por pav'!K5 -> 0
E4: Lajes | G4: ='Supra A por pav'!M6+'Supra B por pav'!M6 -> 237.8 | H4: ='Supra A por pav'!L6+'Supra B por pav'!L6 -> 17192.2 | I4: ='Supra A por pav'!C6+'Supra B por pav'!C6 -> 2812 | J4: ='Supra A por pav'!D6+'Supra B por pav'!D6 -> 0 | K4: ='Supra A por pav'!E6+'Supra B por pav'!E6 -> 323 | L4: ='Supra A por pav'!F6+'Supra B por pav'!F6 -> 8726 | M4: ='Supra A por pav'!G6+'Supra B por pav'!G6 -> 4843 | N4: ='Supra A por pav'!H6+'Supra B por pav'!H6 -> 488.2 | O4: ='Supra A por pav'!I6+'Supra B por pav'!I6 -> 0 | P4: ='Supra A por pav'!J6+'Supra B por pav'!J6 -> 0 | Q4: ='Supra A por pav'!K6+'Supra B por pav'!K6 -> 0
E5: Escadas | G5: ='Supra A por pav'!M7+'Supra B por pav'!M7 -> 0 | H5: ='Supra A por pav'!L7+'Supra B por pav'!L7 -> 0 | I5: ='Supra A por pav'!C7+'Supra B por pav'!C7 -> 0 | J5: ='Supra A por pav'!D7+'Supra B por pav'!D7 -> 0 | K5: ='Supra A por pav'!E7+'Supra B por pav'!E7 -> 0 | L5: ='Supra A por pav'!F7+'Supra B por pav'!F7 -> 0 | M5: ='Supra A por pav'!G7+'Supra B por pav'!G7 -> 0 | N5: ='Supra A por pav'!H7+'Supra B por pav'!H7 -> 0 | O5: ='Supra A por pav'!I7+'Supra B por pav'!I7 -> 0 | P5: ='Supra A por pav'!J7+'Supra B por pav'!J7 -> 0 | Q5: ='Supra A por pav'!K7+'Supra B por pav'!K7 -> 0
E6: Rampas | G6: ='Supra A por pav'!M8+'Supra B por pav'!M8 -> 0 | H6: ='Supra A por pav'!L8+'Supra B por pav'!L8 -> 0 | I6: ='Supra A por pav'!C8+'Supra B por pav'!C8 -> 0 | J6: ='Supra A por pav'!D8+'Supra B por pav'!D8 -> 0 | K6: ='Supra A por pav'!E8+'Supra B por pav'!E8 -> 0 | L6: ='Supra A por pav'!F8+'Supra B por pav'!F8 -> 0 | M6: ='Supra A por pav'!G8+'Supra B por pav'!G8 -> 0 | N6: ='Supra A por pav'!H8+'Supra B por pav'!H8 -> 0 | O6: ='Supra A por pav'!I8+'Supra B por pav'!I8 -> 0 | P6: ='Supra A por pav'!J8+'Supra B por pav'!J8 -> 0 | Q6: ='Supra A por pav'!K8+'Supra B por pav'!K8 -> 0
E7: Blocos | G7: ='Supra A por pav'!M9+'Supra B por pav'!M9 -> 2066.36 | H7: ='Supra A por pav'!L9+'Supra B por pav'!L9 -> 217586 | I7: ='Supra A por pav'!C9+'Supra B por pav'!C9 -> 0 | J7: ='Supra A por pav'!D9+'Supra B por pav'!D9 -> 162 | K7: ='Supra A por pav'!E9+'Supra B por pav'!E9 -> 258 | L7: ='Supra A por pav'!F9+'Supra B por pav'!F9 -> 4185 | M7: ='Supra A por pav'!G9+'Supra B por pav'!G9 -> 1858 | N7: ='Supra A por pav'!H9+'Supra B por pav'!H9 -> 21692 | O7: ='Supra A por pav'!I9+'Supra B por pav'!I9 -> 38277 | P7: ='Supra A por pav'!J9+'Supra B por pav'!J9 -> 46018 | Q7: ='Supra A por pav'!K9+'Supra B por pav'!K9 -> 105136
E8: Reserv. Inferior | G8: ='Supra A por pav'!M10+'Supra B por pav'!M10 -> 80.1 | H8: ='Supra A por pav'!L10+'Supra B por pav'!L10 -> 14648.636 | I8: ='Supra A por pav'!C10+'Supra B por pav'!C10 -> 0 | J8: ='Supra A por pav'!D10+'Supra B por pav'!D10 -> 0 | K8: ='Supra A por pav'!E10+'Supra B por pav'!E10 -> 169 | L8: ='Supra A por pav'!F10+'Supra B por pav'!F10 -> 2373 | M8: ='Supra A por pav'!G10+'Supra B por pav'!G10 -> 9103.9091 | N8: ='Supra A por pav'!H10+'Supra B por pav'!H10 -> 0 | O8: ='Supra A por pav'!I10+'Supra B por pav'!I10 -> 3002.7273 | P8: ='Supra A por pav'!J10+'Supra B por pav'!J10 -> 0 | Q8: ='Supra A por pav'!K10+'Supra B por pav'!K10 -> 0
E9: Dutos | G9: ='Supra A por pav'!M11+'Supra B por pav'!M11 -> 71.5 | H9: ='Supra A por pav'!L11+'Supra B por pav'!L11 -> 8914 | I9: ='Supra A por pav'!C11+'Supra B por pav'!C11 -> 0 | J9: ='Supra A por pav'!D11+'Supra B por pav'!D11 -> 0 | K9: ='Supra A por pav'!E11+'Supra B por pav'!E11 -> 514 | L9: ='Supra A por pav'!F11+'Supra B por pav'!F11 -> 5480 | M9: ='Supra A por pav'!G11+'Supra B por pav'!G11 -> 42 | N9: ='Supra A por pav'!H11+'Supra B por pav'!H11 -> 1639 | O9: ='Supra A por pav'!I11+'Supra B por pav'!I11 -> 1239 | P9: ='Supra A por pav'!J11+'Supra B por pav'!J11 -> 0 | Q9: ='Supra A por pav'!K11+'Supra B por pav'!K11 -> 0
A10: Embasamento | B10: Supraestrutura | C10: L1 - Térreo | D10: TOTAL - L1 - TÉRREO | F10: 50 | G10: =SUM(G2:G9) -> 2595.29 | H10: =SUM(H2:H9) -> 274741.84 | I10: =SUM(I2:I9) -> 2812 | J10: =SUM(J2:J9) -> 729 | K10: =SUM(K2:K9) -> 2901 | L10: =SUM(L2:L9) -> 21773 | M10: =SUM(M2:M9) -> 17161.909 | N10: =SUM(N2:N9) -> 27466.2 | ... Q10: =SUM(Q2:Q9) -> 105136
A11: Embasamento | B11: Supraestrutura | C11: L2 - Garagem 1 | D11: L2 - Garagem 1 | E11: Vigas | F11: 50 | G11: ='Supra A por pav'!M13+'Supra B por pav'!M13 -> 64.92 | H11: ='Supra A por pav'!L13+'Supra B por pav'!L13 -> 8972 | I11: ='Supra A por pav'!C13+'Supra B por pav'!C13 -> 0 | J11: ='Supra A por pav'!D13+'Supra B por pav'!D13 -> 473 | K11: ='Supra A por pav'!E13+'Supra B por pav'!E13 -> 1441 | L11: ='Supra A por pav'!F13+'Supra B por pav'!F13 -> 214 | M11: ='Supra A por pav'!G13+'Supra B por pav'!G13 -> 1068 | N11: ='Supra A por pav'!H13+'Supra B por pav'!H13 -> 1796 | O11: ='Supra A por pav'!I13+'Supra B por pav'!I13 -> 1030 | P11: ='Supra A por pav'!J13+'Supra B por pav'!J13 -> 2950 | Q11: ='Supra A por pav'!K13+'Supra B por pav'!K13 -> 0
E12: Pilares | G12: ='Supra A por pav'!M14+'Supra B por pav'!M14 -> 127.99 | H12: ='Supra A por pav'!L14+'Supra B por pav'!L14 -> 33924 | I12: ='Supra A por pav'!C14+'Supra B por pav'!C14 -> 0 | J12: ='Supra A por pav'!D14+'Supra B por pav'!D14 -> 411 | K12: ='Supra A por pav'!E14+'Supra B por pav'!E14 -> 284 | L12: ='Supra A por pav'!F14+'Supra B por pav'!F14 -> 3522 | M12: ='Supra A por pav'!G14+'Supra B por pav'!G14 -> 375 | N12: ='Supra A por pav'!H14+'Supra B por pav'!H14 -> 343 | O12: ='Supra A por pav'!I14+'Supra B por pav'!I14 -> 1584 | P12: ='Supra A por pav'!J14+'Supra B por pav'!J14 -> 5384 | Q12: ='Supra A por pav'!K14+'Supra B por pav'!K14 -> 22021
E13: Lajes | G13: ='Supra A por pav'!M15+'Supra B por pav'!M15 -> 274 | H13: ='Supra A por pav'!L15+'Supra B por pav'!L15 -> 22685 | I13: ='Supra A por pav'!C15+'Supra B por pav'!C15 -> 2681 | J13: ='Supra A por pav'!D15+'Supra B por pav'!D15 -> 0 | K13: ='Supra A por pav'!E15+'Supra B por pav'!E15 -> 0 | L13: ='Supra A por pav'!F15+'Supra B por pav'!F15 -> 5631 | M13: ='Supra A por pav'!G15+'Supra B por pav'!G15 -> 2344 | N13: ='Supra A por pav'!H15+'Supra B por pav'!H15 -> 3671 | O13: ='Supra A por pav'!I15+'Supra B por pav'!I15 -> 8358 | P13: ='Supra A por pav'!J15+'Supra B por pav'!J15 -> 0 | Q13: ='Supra A por pav'!K15+'Supra B por pav'!K15 -> 0
E14: Escadas | G14: ='Supra A por pav'!M16+'Supra B por pav'!M16 -> 3.78 | H14: ='Supra A por pav'!L16+'Supra B por pav'!L16 -> 338 | I14: ='Supra A por pav'!C16+'Supra B por pav'!C16 -> 0 | J14: ='Supra A por pav'!D16+'Supra B por pav'!D16 -> 0 | K14: ='Supra A por pav'!E16+'Supra B por pav'!E16 -> 0 | L14: ='Supra A por pav'!F16+'Supra B por pav'!F16 -> 14 | M14: ='Supra A por pav'!G16+'Supra B por pav'!G16 -> 228 | N14: ='Supra A por pav'!H16+'Supra B por pav'!H16 -> 96 | O14: ='Supra A por pav'!I16+'Supra B por pav'!I16 -> 0 | P14: ='Supra A por pav'!J16+'Supra B por pav'!J16 -> 0 | Q14: ='Supra A por pav'!K16+'Supra B por pav'!K16 -> 0
E15: Rampas | G15: ='Supra A por pav'!M17+'Supra B por pav'!M17 -> 9.5 | H15: ='Supra A por pav'!L17+'Supra B por pav'!L17 -> 652 | I15: ='Supra A por pav'!C17+'Supra B por pav'!C17 -> 109 | J15: ='Supra A por pav'!D17+'Supra B por pav'!D17 -> 0 | K15: ='Supra A por pav'!E17+'Supra B por pav'!E17 -> 0 | L15: ='Supra A por pav'!F17+'Supra B por pav'!F17 -> 190 | M15: ='Supra A por pav'!G17+'Supra B por pav'!G17 -> 353 | N15: ='Supra A por pav'!H17+'Supra B por pav'!H17 -> 0 | O15: ='Supra A por pav'!I17+'Supra B por pav'!I17 -> 0 | P15: ='Supra A por pav'!J17+'Supra B por pav'!J17 -> 0 | Q15: ='Supra A por pav'!K17+'Supra B por pav'!K17 -> 0
A16: Embasamento | B16: Supraestrutura | C16: L2 - Garagem 1 | D16: TOTAL - L2 - GARAGEM 1 | F16: 50 | G16: =SUM(G11:G15) -> 480.19 | H16: =SUM(H11:H15) -> 66571 | I16: =SUM(I11:I15) -> 2790 | J16: =SUM(J11:J15) -> 884 | K16: =SUM(K11:K15) -> 1725 | L16: =SUM(L11:L15) -> 9571 | M16: =SUM(M11:M15) -> 4368 | N16: =SUM(N11:N15) -> 5906 | ... Q16: =SUM(Q11:Q15) -> 22021
A17: Embasamento | B17: Supraestrutura | C17: L3 - Garagem 2 | D17: L3 - Garagem 2 | E17: Vigas | F17: 50 | G17: ='Supra A por pav'!M19+'Supra B por pav'!M19 -> 99.9 | H17: ='Supra A por pav'!L19+'Supra B por pav'!L19 -> 16314 | I17: ='Supra A por pav'!C19+'Supra B por pav'!C19 -> 0 | J17: ='Supra A por pav'!D19+'Supra B por pav'!D19 -> 346 | K17: ='Supra A por pav'!E19+'Supra B por pav'!E19 -> 730 | L17: ='Supra A por pav'!F19+'Supra B por pav'!F19 -> 162 | M17: ='Supra A por pav'!G19+'Supra B por pav'!G19 -> 650 | N17: ='Supra A por pav'!H19+'Supra B por pav'!H19 -> 1157 | O17: ='Supra A por pav'!I19+'Supra B por pav'!I19 -> 4038 | P17: ='Supra A por pav'!J19+'Supra B por pav'!J19 -> 1008 | Q17: ='Supra A por pav'!K19+'Supra B por pav'!K19 -> 8223
E18: Pilares | G18: ='Supra A por pav'!M20+'Supra B por pav'!M20 -> 99.69 | H18: ='Supra A por pav'!L20+'Supra B por pav'!L20 -> 24850 | I18: ='Supra A por pav'!C20+'Supra B por pav'!C20 -> 0 | J18: ='Supra A por pav'!D20+'Supra B por pav'!D20 -> 348 | K18: ='Supra A por pav'!E20+'Supra B por pav'!E20 -> 618 | L18: ='Supra A por pav'!F20+'Supra B por pav'!F20 -> 2273 | M18: ='Supra A por pav'!G20+'Supra B por pav'!G20 -> 313 | N18: ='Supra A por pav'!H20+'Supra B por pav'!H20 -> 408 | O18: ='Supra A por pav'!I20+'Supra B por pav'!I20 -> 2169 | P18: ='Supra A por pav'!J20+'Supra B por pav'!J20 -> 7114 | Q18: ='Supra A por pav'!K20+'Supra B por pav'!K20 -> 11607
E19: Lajes | G19: ='Supra A por pav'!M21+'Supra B por pav'!M21 -> 281.7 | H19: ='Supra A por pav'!L21+'Supra B por pav'!L21 -> 27148 | I19: ='Supra A por pav'!C21+'Supra B por pav'!C21 -> 2703 | J19: ='Supra A por pav'!D21+'Supra B por pav'!D21 -> 0 | K19: ='Supra A por pav'!E21+'Supra B por pav'!E21 -> 0 | L19: ='Supra A por pav'!F21+'Supra B por pav'!F21 -> 4537 | M19: ='Supra A por pav'!G21+'Supra B por pav'!G21 -> 3769 | N19: ='Supra A por pav'!H21+'Supra B por pav'!H21 -> 2508 | O19: ='Supra A por pav'!I21+'Supra B por pav'!I21 -> 13631 | P19: ='Supra A por pav'!J21+'Supra B por pav'!J21 -> 0 | Q19: ='Supra A por pav'!K21+'Supra B por pav'!K21 -> 0
E20: Escadas | G20: ='Supra A por pav'!M22+'Supra B por pav'!M22 -> 3.973 | H20: ='Supra A por pav'!L22+'Supra B por pav'!L22 -> 386.75 | I20: ='Supra A por pav'!C22+'Supra B por pav'!C22 -> 0 | J20: ='Supra A por pav'!D22+'Supra B por pav'!D22 -> 0 | K20: ='Supra A por pav'!E22+'Supra B por pav'!E22 -> 0 | L20: ='Supra A por pav'!F22+'Supra B por pav'!F22 -> 18 | M20: ='Supra A por pav'!G22+'Supra B por pav'!G22 -> 368.75 | N20: ='Supra A por pav'!H22+'Supra B por pav'!H22 -> 0 | O20: ='Supra A por pav'!I22+'Supra B por pav'!I22 -> 0 | P20: ='Supra A por pav'!J22+'Supra B por pav'!J22 -> 0 | Q20: ='Supra A por pav'!K22+'Supra B por pav'!K22 -> 0
E21: Rampas | G21: ='Supra A por pav'!M23+'Supra B por pav'!M23 -> 9.5 | H21: ='Supra A por pav'!L23+'Supra B por pav'!L23 -> 624 | I21: ='Supra A por pav'!C23+'Supra B por pav'!C23 -> 109 | J21: ='Supra A por pav'!D23+'Supra B por pav'!D23 -> 0 | K21: ='Supra A por pav'!E23+'Supra B por pav'!E23 -> 0 | L21: ='Supra A por pav'!F23+'Supra B por pav'!F23 -> 184 | M21: ='Supra A por pav'!G23+'Supra B por pav'!G23 -> 331 | N21: ='Supra A por pav'!H23+'Supra B por pav'!H23 -> 0 | O21: ='Supra A por pav'!I23+'Supra B por pav'!I23 -> 0 | P21: ='Supra A por pav'!J23+'Supra B por pav'!J23 -> 0 | Q21: ='Supra A por pav'!K23+'Supra B por pav'!K23 -> 0
A22: Embasamento | B22: Supraestrutura | C22: L3 - Garagem 2 | D22: TOTAL - L3 - GARAGEM 2 | F22: 50 | G22: =SUM(G17:G21) -> 494.763 | H22: =SUM(H17:H21) -> 69322.75 | I22: =SUM(I17:I21) -> 2812 | J22: =SUM(J17:J21) -> 694 | K22: =SUM(K17:K21) -> 1348 | L22: =SUM(L17:L21) -> 7174 | M22: =SUM(M17:M21) -> 5431.75 | N22: =SUM(N17:N21) -> 4073 | ... Q22: =SUM(Q17:Q21) -> 19830
A23: Embasamento | B23: Supraestrutura | C23: L4 - Garagem 3 | D23: L4 - Garagem 3 | E23: Vigas | F23: 50 | G23: ='Supra A por pav'!M25+'Supra B por pav'!M25 -> 46.52 | H23: ='Supra A por pav'!L25+'Supra B por pav'!L25 -> 4964 | I23: ='Supra A por pav'!C25+'Supra B por pav'!C25 -> 0 | J23: ='Supra A por pav'!D25+'Supra B por pav'!D25 -> 348 | K23: ='Supra A por pav'!E25+'Supra B por pav'!E25 -> 708 | L23: ='Supra A por pav'!F25+'Supra B por pav'!F25 -> 235 | M23: ='Supra A por pav'!G25+'Supra B por pav'!G25 -> 289 | N23: ='Supra A por pav'!H25+'Supra B por pav'!H25 -> 1253 | O23: ='Supra A por pav'!I25+'Supra B por pav'!I25 -> 841 | P23: ='Supra A por pav'!J25+'Supra B por pav'!J25 -> 1290 | Q23: ='Supra A por pav'!K25+'Supra B por pav'!K25 -> 0
E24: Pilares | G24: ='Supra A por pav'!M26+'Supra B por pav'!M26 -> 104.08 | H24: ='Supra A por pav'!L26+'Supra B por pav'!L26 -> 23836 | I24: ='Supra A por pav'!C26+'Supra B por pav'!C26 -> 0 | J24: ='Supra A por pav'!D26+'Supra B por pav'!D26 -> 447 | K24: ='Supra A por pav'!E26+'Supra B por pav'!E26 -> 543 | L24: ='Supra A por pav'!F26+'Supra B por pav'!F26 -> 2304 | M24: ='Supra A por pav'!G26+'Supra B por pav'!G26 -> 151 | N24: ='Supra A por pav'!H26+'Supra B por pav'!H26 -> 361 | O24: ='Supra A por pav'!I26+'Supra B por pav'!I26 -> 2142 | P24: ='Supra A por pav'!J26+'Supra B por pav'!J26 -> 8911 | Q24: ='Supra A por pav'!K26+'Supra B por pav'!K26 -> 8977
E25: Lajes | G25: ='Supra A por pav'!M27+'Supra B por pav'!M27 -> 288.6 | H25: ='Supra A por pav'!L27+'Supra B por pav'!L27 -> 29605 | I25: ='Supra A por pav'!C27+'Supra B por pav'!C27 -> 2769 | J25: ='Supra A por pav'!D27+'Supra B por pav'!D27 -> 0 | K25: ='Supra A por pav'!E27+'Supra B por pav'!E27 -> 0 | L25: ='Supra A por pav'!F27+'Supra B por pav'!F27 -> 4383 | M25: ='Supra A por pav'!G27+'Supra B por pav'!G27 -> 3548 | N25: ='Supra A por pav'!H27+'Supra B por pav'!H27 -> 3335 | O25: ='Supra A por pav'!I27+'Supra B por pav'!I27 -> 15173 | P25: ='Supra A por pav'!J27+'Supra B por pav'!J27 -> 397 | Q25: ='Supra A por pav'!K27+'Supra B por pav'!K27 -> 0
E26: Escadas | G26: ='Supra A por pav'!M28+'Supra B por pav'!M28 -> 3.973 | H26: ='Supra A por pav'!L28+'Supra B por pav'!L28 -> 386.75 | I26: ='Supra A por pav'!C28+'Supra B por pav'!C28 -> 0 | J26: ='Supra A por pav'!D28+'Supra B por pav'!D28 -> 0 | K26: ='Supra A por pav'!E28+'Supra B por pav'!E28 -> 0 | L26: ='Supra A por pav'!F28+'Supra B por pav'!F28 -> 18 | M26: ='Supra A por pav'!G28+'Supra B por pav'!G28 -> 368.75 | N26: ='Supra A por pav'!H28+'Supra B por pav'!H28 -> 0 | O26: ='Supra A por pav'!I28+'Supra B por pav'!I28 -> 0 | P26: ='Supra A por pav'!J28+'Supra B por pav'!J28 -> 0 | Q26: ='Supra A por pav'!K28+'Supra B por pav'!K28 -> 0
E27: Rampas | G27: ='Supra A por pav'!M29+'Supra B por pav'!M29 -> 9.5 | H27: ='Supra A por pav'!L29+'Supra B por pav'!L29 -> 624 | I27: ='Supra A por pav'!C29+'Supra B por pav'!C29 -> 109 | J27: ='Supra A por pav'!D29+'Supra B por pav'!D29 -> 0 | K27: ='Supra A por pav'!E29+'Supra B por pav'!E29 -> 0 | L27: ='Supra A por pav'!F29+'Supra B por pav'!F29 -> 184 | M27: ='Supra A por pav'!G29+'Supra B por pav'!G29 -> 331 | N27: ='Supra A por pav'!H29+'Supra B por pav'!H29 -> 0 | O27: ='Supra A por pav'!I29+'Supra B por pav'!I29 -> 0 | P27: ='Supra A por pav'!J29+'Supra B por pav'!J29 -> 0 | Q27: ='Supra A por pav'!K29+'Supra B por pav'!K29 -> 0
A28: Embasamento | B28: Supraestrutura | C28: L4 - Garagem 3 | D28: TOTAL - L4 - GARAGEM 3 | F28: 50 | G28: =SUM(G23:G27) -> 452.673 | H28: =SUM(H23:H27) -> 59415.75 | I28: =SUM(I23:I27) -> 2878 | J28: =SUM(J23:J27) -> 795 | K28: =SUM(K23:K27) -> 1251 | L28: =SUM(L23:L27) -> 7124 | M28: =SUM(M23:M27) -> 4687.75 | N28: =SUM(N23:N27) -> 4949 | ... Q28: =SUM(Q23:Q27) -> 8977
A29: Embasamento | B29: Supraestrutura | C29: L5 - Garagem 4 | D29: L5 - Garagem 4 | E29: Vigas | F29: 50 | G29: ='Supra A por pav'!M31+'Supra B por pav'!M31 -> 46.28 | H29: ='Supra A por pav'!L31+'Supra B por pav'!L31 -> 5129 | I29: ='Supra A por pav'!C31+'Supra B por pav'!C31 -> 0 | J29: ='Supra A por pav'!D31+'Supra B por pav'!D31 -> 351 | K29: ='Supra A por pav'!E31+'Supra B por pav'!E31 -> 683 | L29: ='Supra A por pav'!F31+'Supra B por pav'!F31 -> 271 | M29: ='Supra A por pav'!G31+'Supra B por pav'!G31 -> 268 | N29: ='Supra A por pav'!H31+'Supra B por pav'!H31 -> 1308 | O29: ='Supra A por pav'!I31+'Supra B por pav'!I31 -> 715 | P29: ='Supra A por pav'!J31+'Supra B por pav'!J31 -> 1533 | Q29: ='Supra A por pav'!K31+'Supra B por pav'!K31 -> 0
E30: Pilares | G30: ='Supra A por pav'!M32+'Supra B por pav'!M32 -> 101.92 | H30: ='Supra A por pav'!L32+'Supra B por pav'!L32 -> 22195 | I30: ='Supra A por pav'!C32+'Supra B por pav'!C32 -> 0 | J30: ='Supra A por pav'!D32+'Supra B por pav'!D32 -> 425 | K30: ='Supra A por pav'!E32+'Supra B por pav'!E32 -> 570 | L30: ='Supra A por pav'!F32+'Supra B por pav'!F32 -> 2308 | M30: ='Supra A por pav'!G32+'Supra B por pav'!G32 -> 0 | N30: ='Supra A por pav'!H32+'Supra B por pav'!H32 -> 365 | O30: ='Supra A por pav'!I32+'Supra B por pav'!I32 -> 2142 | P30: ='Supra A por pav'!J32+'Supra B por pav'!J32 -> 9738 | Q30: ='Supra A por pav'!K32+'Supra B por pav'!K32 -> 6647
E31: Lajes | G31: ='Supra A por pav'!M33+'Supra B por pav'!M33 -> 289.6 | H31: ='Supra A por pav'!L33+'Supra B por pav'!L33 -> 29572 | I31: ='Supra A por pav'!C33+'Supra B por pav'!C33 -> 2769 | J31: ='Supra A por pav'!D33+'Supra B por pav'!D33 -> 0 | K31: ='Supra A por pav'!E33+'Supra B por pav'!E33 -> 0 | L31: ='Supra A por pav'!F33+'Supra B por pav'!F33 -> 4427 | M31: ='Supra A por pav'!G33+'Supra B por pav'!G33 -> 3418 | N31: ='Supra A por pav'!H33+'Supra B por pav'!H33 -> 3705 | O31: ='Supra A por pav'!I33+'Supra B por pav'!I33 -> 15253 | P31: ='Supra A por pav'!J33+'Supra B por pav'!J33 -> 0 | Q31: ='Supra A por pav'!K33+'Supra B por pav'!K33 -> 0
E32: Escadas | G32: ='Supra A por pav'!M34+'Supra B por pav'!M34 -> 3.973 | H32: ='Supra A por pav'!L34+'Supra B por pav'!L34 -> 386.75 | I32: ='Supra A por pav'!C34+'Supra B por pav'!C34 -> 0 | J32: ='Supra A por pav'!D34+'Supra B por pav'!D34 -> 0 | K32: ='Supra A por pav'!E34+'Supra B por pav'!E34 -> 0 | L32: ='Supra A por pav'!F34+'Supra B por pav'!F34 -> 18 | M32: ='Supra A por pav'!G34+'Supra B por pav'!G34 -> 368.75 | N32: ='Supra A por pav'!H34+'Supra B por pav'!H34 -> 0 | O32: ='Supra A por pav'!I34+'Supra B por pav'!I34 -> 0 | P32: ='Supra A por pav'!J34+'Supra B por pav'!J34 -> 0 | Q32: ='Supra A por pav'!K34+'Supra B por pav'!K34 -> 0
E33: Rampas | G33: ='Supra A por pav'!M35+'Supra B por pav'!M35 -> 9.5 | H33: ='Supra A por pav'!L35+'Supra B por pav'!L35 -> 624 | I33: ='Supra A por pav'!C35+'Supra B por pav'!C35 -> 109 | J33: ='Supra A por pav'!D35+'Supra B por pav'!D35 -> 0 | K33: ='Supra A por pav'!E35+'Supra B por pav'!E35 -> 0 | L33: ='Supra A por pav'!F35+'Supra B por pav'!F35 -> 184 | M33: ='Supra A por pav'!G35+'Supra B por pav'!G35 -> 331 | N33: ='Supra A por pav'!H35+'Supra B por pav'!H35 -> 0 | O33: ='Supra A por pav'!I35+'Supra B por pav'!I35 -> 0 | P33: ='Supra A por pav'!J35+'Supra B por pav'!J35 -> 0 | Q33: ='Supra A por pav'!K35+'Supra B por pav'!K35 -> 0
A34: Embasamento | B34: Supraestrutura | C34: L5 - Garagem 4 | D34: TOTAL - L5 - GARAGEM 4 | F34: 50 | G34: =SUM(G29:G33) -> 451.273 | H34: =SUM(H29:H33) -> 57906.75 | I34: =SUM(I29:I33) -> 2878 | J34: =SUM(J29:J33) -> 776 | K34: =SUM(K29:K33) -> 1253 | L34: =SUM(L29:L33) -> 7208 | M34: =SUM(M29:M33) -> 4385.75 | N34: =SUM(N29:N33) -> 5378 | ... Q34: =SUM(Q29:Q33) -> 6647
A35: Embasamento | B35: Supraestrutura | C35: L6 - Garagem 5 | D35: L6 - Garagem 5 | E35: Vigas | F35: 50 | G35: ='Supra A por pav'!M37+'Supra B por pav'!M37 -> 46.92 | H35: ='Supra A por pav'!L37+'Supra B por pav'!L37 -> 5466 | I35: ='Supra A por pav'!C37+'Supra B por pav'!C37 -> 0 | J35: ='Supra A por pav'!D37+'Supra B por pav'!D37 -> 360 | K35: ='Supra A por pav'!E37+'Supra B por pav'!E37 -> 670 | L35: ='Supra A por pav'!F37+'Supra B por pav'!F37 -> 305 | M35: ='Supra A por pav'!G37+'Supra B por pav'!G37 -> 173 | N35: ='Supra A por pav'!H37+'Supra B por pav'!H37 -> 1267 | O35: ='Supra A por pav'!I37+'Supra B por pav'!I37 -> 1134 | P35: ='Supra A por pav'!J37+'Supra B por pav'!J37 -> 1557 | Q35: ='Supra A por pav'!K37+'Supra B por pav'!K37 -> 0
E36: Pilares | G36: ='Supra A por pav'!M38+'Supra B por pav'!M38 -> 102.3 | H36: ='Supra A por pav'!L38+'Supra B por pav'!L38 -> 21819 | I36: ='Supra A por pav'!C38+'Supra B por pav'!C38 -> 0 | J36: ='Supra A por pav'!D38+'Supra B por pav'!D38 -> 448 | K36: ='Supra A por pav'!E38+'Supra B por pav'!E38 -> 603 | L36: ='Supra A por pav'!F38+'Supra B por pav'!F38 -> 2198 | M36: ='Supra A por pav'!G38+'Supra B por pav'!G38 -> 0 | N36: ='Supra A por pav'!H38+'Supra B por pav'!H38 -> 378 | O36: ='Supra A por pav'!I38+'Supra B por pav'!I38 -> 2567 | P36: ='Supra A por pav'!J38+'Supra B por pav'!J38 -> 8978 | Q36: ='Supra A por pav'!K38+'Supra B por pav'!K38 -> 6647
E37: Lajes | G37: ='Supra A por pav'!M39+'Supra B por pav'!M39 -> 289.6 | H37: ='Supra A por pav'!L39+'Supra B por pav'!L39 -> 29319 | I37: ='Supra A por pav'!C39+'Supra B por pav'!C39 -> 2790 | J37: ='Supra A por pav'!D39+'Supra B por pav'!D39 -> 0 | K37: ='Supra A por pav'!E39+'Supra B por pav'!E39 -> 0 | L37: ='Supra A por pav'!F39+'Supra B por pav'!F39 -> 4382 | M37: ='Supra A por pav'!G39+'Supra B por pav'!G39 -> 3308 | N37: ='Supra A por pav'!H39+'Supra B por pav'!H39 -> 3826 | O37: ='Supra A por pav'!I39+'Supra B por pav'!I39 -> 15013 | P37: ='Supra A por pav'!J39+'Supra B por pav'!J39 -> 0 | Q37: ='Supra A por pav'!K39+'Supra B por pav'!K39 -> 0
E38: Escadas | G38: ='Supra A por pav'!M40+'Supra B por pav'!M40 -> 3.973 | H38: ='Supra A por pav'!L40+'Supra B por pav'!L40 -> 386.75 | I38: ='Supra A por pav'!C40+'Supra B por pav'!C40 -> 0 | J38: ='Supra A por pav'!D40+'Supra B por pav'!D40 -> 0 | K38: ='Supra A por pav'!E40+'Supra B por pav'!E40 -> 0 | L38: ='Supra A por pav'!F40+'Supra B por pav'!F40 -> 18 | M38: ='Supra A por pav'!G40+'Supra B por pav'!G40 -> 368.75 | N38: ='Supra A por pav'!H40+'Supra B por pav'!H40 -> 0 | O38: ='Supra A por pav'!I40+'Supra B por pav'!I40 -> 0 | P38: ='Supra A por pav'!J40+'Supra B por pav'!J40 -> 0 | Q38: ='Supra A por pav'!K40+'Supra B por pav'!K40 -> 0
E39: Rampas | G39: ='Supra A por pav'!M41+'Supra B por pav'!M41 -> 8.5 | H39: ='Supra A por pav'!L41+'Supra B por pav'!L41 -> 587 | I39: ='Supra A por pav'!C41+'Supra B por pav'!C41 -> 109 | J39: ='Supra A por pav'!D41+'Supra B por pav'!D41 -> 0 | K39: ='Supra A por pav'!E41+'Supra B por pav'!E41 -> 0 | L39: ='Supra A por pav'!F41+'Supra B por pav'!F41 -> 172 | M39: ='Supra A por pav'!G41+'Supra B por pav'!G41 -> 306 | N39: ='Supra A por pav'!H41+'Supra B por pav'!H41 -> 0 | O39: ='Supra A por pav'!I41+'Supra B por pav'!I41 -> 0 | P39: ='Supra A por pav'!J41+'Supra B por pav'!J41 -> 0 | Q39: ='Supra A por pav'!K41+'Supra B por pav'!K41 -> 0
A40: Embasamento | B40: Supraestrutura | C40: L6 - Garagem 5 | D40: TOTAL - L6 - GARAGEM 5 | F40: 50 | G40: =SUM(G35:G39) -> 451.293 | H40: =SUM(H35:H39) -> 57577.75 | I40: =SUM(I35:I39) -> 2899 | J40: =SUM(J35:J39) -> 808 | K40: =SUM(K35:K39) -> 1273 | L40: =SUM(L35:L39) -> 7075 | M40: =SUM(M35:M39) -> 4155.75 | N40: =SUM(N35:N39) -> 5471 | ... Q40: =SUM(Q35:Q39) -> 6647
...

Sheet Aço por Bitola
A1: Aço CA-50 por bitola — sem sobreconsumo
A3: Bloco | B3: Item | C3: øQ92 | D3: ø5 | E3: ø6.3 | F3: ø8 | G3: ø10 | H3: ø12.5 | I3: ø16 | J3: ø20 | K3: ø25 | L3: Total (kg)
A4: A | B4: Estacas Hélice Contínua | C4: 0 | D4: 0 | E4: 3002 | F4: 0 | G4: 0 | H4: 0 | I4: 20183 | J4: 0 | K4: 0 | L4: 23185
A5: A | B5: Fundação (resumo) | C5: 0 | D5: 0 | E5: 3002 | F5: 0 | G5: 0 | H5: 0 | I5: 20183 | J5: 0 | K5: 0 | L5: 23185
A6: A | B6: Estrutura (supra) | C6: 28484 | D6: 10022 | E6: 46462 | F6: 60707 | G6: 63360 | H6: 117498 | I6: 201239.27 | J6: 102629 | K6: 98243 | L6: 728644.27
A7: B | B7: Estacas Hélice Contínua | C7: 0 | D7: 0 | E7: 3173 | F7: 0 | G7: 0 | H7: 0 | I7: 21273 | J7: 0 | K7: 0 | L7: 24446
A8: B | B8: Fundação (resumo) | C8: 0 | D8: 0 | E8: 3173 | F8: 0 | G8: 0 | H8: 0 | I8: 21273 | J8: 0 | K8: 0 | L8: 24446
A9: B | B9: Estrutura (supra) | C9: 34226 | D9: 11152 | E9: 43191 | F9: 88176 | G9: 80726.909 | H9: 140980.2 | I9: 251239.45 | J9: 100801 | K9: 123332 | L9: 873824.56

Sheet Fund. Rasa detalhe
A1: Fundação Rasa — detalhe por bloco
A3: Bloco | B3: Item | C3: Fôrma (m²) | D3: Volume (m³) | E3: Aço (kg) | F3: Fonte
A4: A | B4: Lajes maciças (fundação/topo arquivo) | C4: 0 | D4: 1021.75 | E4: 112136 | F4: QUANT-A r3
A5: A | B5: L1 Térreo - Blocos (CR) | C5: - | D5: 1021.75 | E5: 114902 | F5: CR-A L1 Blocos
A6: B | B6: Zapatas isoladas | C6: 1.44 | D6: 0.216 | E6: 15 | F6: QUANT-B r3
A7: B | B7: Blocos de coroamento | C7: 746.31 | D7: 750.967 | E7: 66021 | F7: QUANT-B r4
A8: B | B8: L1 Térreo - Blocos (CR) | C8: - | D8: 1044.61 | E8: 102684 | F8: CR-B L1 Blocos
