Workbook

Sheet GER_EXECUTIVO
A1: ETAPA | B1: VALOR ORÇADO | C1: % | D1: VALOR / m²
A2: GERENCIAMENTO TÉCNICO E ADMINISTRATIVO | B2: ='[5]Obra '!$C31 -> 6459783.5 | C2: =B2/B$19 -> 0.12047398 | D2: =B2/GER_EXECUTIVO!G$2 -> 384.76171 | F2: ÁREA CONSTRUÍDA | G2: 16789.05 | H2: m²
A3: MOVIMENTAÇÃO DE TERRA | B3: ='[5]Obra '!$C32 -> 290742.39 | C3: =B3/B$19 -> 0.0054223014 | D3: =B3/GER_EXECUTIVO!G$2 -> 17.317382
A4: INFRAESTRUTURA | B4: ='[5]Obra '!$C33 -> 3912290.7 | C4: =B4/B$19 -> 0.072963628 | D4: =B4/GER_EXECUTIVO!G$2 -> 233.02633
A5: SUPRAESTRUTURA | B5: ='[5]Obra '!$C34 -> 9983387.5 | C5: =B5/B$19 -> 0.18618866 | D5: =B5/GER_EXECUTIVO!G$2 -> 594.63683
A6: ALVENARIA | B6: ='[5]Obra '!$C$35 -> 3190022.9 | C6: =B6/B$19 -> 0.059493442 | D6: =B6/GER_EXECUTIVO!G$2 -> 190.00616
A7: INSTALAÇÕES ELÉTRICAS, HIDRÁULICAS, GLP E PREVENTIVAS | B7: ='[5]Obra '!$C$37 -> 5730937.8 | C7: =B7/B$19 -> 0.10688112 | D7: =B7/GER_EXECUTIVO!G$2 -> 341.34973
A8: EQUIPAMENTOS E SISTEMAS ESPECIAIS | B8: ='[5]Obra '!$C$38+'[5]Obra '!$C$39 -> 2585975.8 | C8: =B8/B$19 -> 0.048228055 | D8: =B8/GER_EXECUTIVO!G$2 -> 154.02752 | E8: Incluso climatização
A9: IMPERMEABILIZAÇÃO | B9: ='[5]Obra '!$C$36 -> 1463560.6 | C9: =B9/B$19 -> 0.027295184 | D9: =B9/GER_EXECUTIVO!G$2 -> 87.173523
A10: REVESTIMENTOS INTERNOS DE PAREDE | B10: ='[5]Obra '!$C40 -> 2002760.7 | C10: =B10/B$19 -> 0.037351183 | D10: =B10/GER_EXECUTIVO!G$2 -> 119.2897
A11: REVESTIMENTOS E ACABAMENTOS INTERNOS EM TETO | B11: ='[5]Obra '!$C41 -> 1410266.6 | C11: =B11/B$19 -> 0.026301257 | D11: =B11/GER_EXECUTIVO!G$2 -> 83.999188
A12: PISOS E PAVIMENTAÇÕES | B12: ='[5]Obra '!$C42 -> 2974617.8 | C12: =B12/B$19 -> 0.05547617 | D12: =B12/GER_EXECUTIVO!G$2 -> 177.17606
A13: PINTURA INTERNA | B13: ='[5]Obra '!$C43 -> 3275186.5 | C13: =B13/B$19 -> 0.061081731 | D13: =B13/GER_EXECUTIVO!G$2 -> 195.07873
A14: ESQUADRIAS, VIDROS E FERRAGENS | B14: ='[5]Obra '!$C44 -> 5304562 | C14: =B14/B$19 -> 0.098929275 | D14: =B14/GER_EXECUTIVO!G$2 -> 315.95367
A15: LOUÇAS E METAIS | B15: ='[5]Obra '!$C45 -> 505846.32 | C15: =B15/B$19 -> 0.009433957 | D15: =B15/GER_EXECUTIVO!G$2 -> 30.129538
A16: REVESTIMENTOS E ACABAMENTOS DE FACHADA | B16: ='[5]Obra '!$C46 -> 1515128.7 | C16: =B16/B$19 -> 0.028256921 | D16: =B16/GER_EXECUTIVO!G$2 -> 90.245055
A17: SERVIÇOS COMPLEMENTARES | B17: ='[5]Obra '!$C47 -> 2317724.7 | C17: =B17/B$19 -> 0.043225213 | D17: =B17/GER_EXECUTIVO!G$2 -> 138.04978
A18: IMPREVISTOS E CONTIGÊNCIAS | B18: ='[5]Obra '!$C48 -> 696945.16 | C18: =B18/B$19 -> 0.012997921 | D18: =B18/GER_EXECUTIVO!G$2 -> 41.511888
A19: TOTAL | B19: =SUM(B2:B18) -> 53619740 | C19: =SUM(C2:C18) -> 1 | D19: =SUM(D2:D18) -> 3193.7328
A20: CUB/SC | B20: 2965.54 | C20: 45839 | D20: =ROUND(D19/B20,2)&" CUB" -> 1,08 CUB
A23: Rótulos de Linha | B23: Soma de %
A24: INFRAESTRUTURA | B24: 0.14152999
A25: GERENCIAMENTO TÉCNICO E ADMINISTRATIVO | B25: 0.12128875
A26: ESQUADRIAS, VIDROS E FERRAGENS | B26: 0.11791698
A27: INSTALAÇÕES ELÉTRICAS, HIDRÁULICAS, GLP E PREVENTIVAS | B27: 0.11577127
A28: SERVIÇOS COMPLEMENTARES | B28: 0.10444394
A29: PISOS E PAVIMENTAÇÕES | B29: 0.068886111
A30: REVESTIMENTOS INTERNOS DE PAREDE | B30: 0.063383398
A31: PINTURA INTERNA | B31: 0.062897664
A32: ALVENARIA | B32: 0.042390695
A33: EQUIPAMENTOS E SISTEMAS ESPECIAIS | B33: 0.034969812
A34: REVESTIMENTOS E ACABAMENTOS DE FACHADA | B34: 0.033623986
A35: IMPERMEABILIZAÇÃO | B35: 0.030181159
... A41: Total Geral | B41: 0.98683824
A45: GERENCIAMENTO TÉCNICO E ADMINISTRATIVO | B45: =[1]Ger_Administrativo!$N$126 -> 7644518.6
A46: MEGA
A47: MOVIMENTAÇÃO DE TERRA | B47: ='[1]Ger_Executivo MEGA'!$N$126 -> 1415598.8
A48: ESTRUTURA | B48: ='[1]Ger_Executivo MEGA'!$N$132 -> 18775886 | C48: =B48-B52 -> 18362172 | D48: SEM IMPREVISTO
A49: INFRAESTRUTURA | B49: ='[1]Ger_Executivo MEGA'!$N$133 -> 2368306.5
A50: SUPRAESTRUTURA | B50: ='[1]Ger_Executivo MEGA'!$N$151 -> 4417376.6
...

Sheet ANÁLISE_CUSTOS
A1: ETAPA | B1: AQUARIUS | D1: OBRAS DE REFERÊNCIA
B2: VALOR | C2: VALOR / m² | D2: VALOR / m²
A3: GERENCIAMENTO TÉCNICO E ADMINISTRATIVO | B3: =GER_EXECUTIVO!B2 -> 6459783.5 | C3: =B3/GER_EXECUTIVO!$G$2 -> 384.76171 | D3: =FIXED(CÁLCULO_MÉDIAS!R11,2,FALSE)&" "&"-"&FIXED(CÁLCULO_MÉDIAS!S11,2,FALSE) -> 360,00 -420,00
A4: MOVIMENTAÇÃO DE TERRA | B4: =GER_EXECUTIVO!B3 -> 290742.39 | C4: =B4/GER_EXECUTIVO!$G$2 -> 17.317382 | D4: =FIXED(CÁLCULO_MÉDIAS!R12,2,FALSE)&" "&"-"&FIXED(CÁLCULO_MÉDIAS!S12,2,FALSE) -> 15,00 -25,00
A5: =GER_EXECUTIVO!A4 -> INFRAESTRUTURA | B5: =GER_EXECUTIVO!B4 -> 3912290.7 | C5: =B5/GER_EXECUTIVO!$G$2 -> 233.02633 | D5: =FIXED(CÁLCULO_MÉDIAS!R13,2,FALSE)&" "&"-"&FIXED(CÁLCULO_MÉDIAS!S13,2,FALSE) -> 240,00 -340,00
A6: =GER_EXECUTIVO!A5 -> SUPRAESTRUTURA | B6: =GER_EXECUTIVO!B5 -> 9983387.5 | C6: =B6/GER_EXECUTIVO!$G$2 -> 594.63683 | D6: =FIXED(CÁLCULO_MÉDIAS!R14,2,FALSE)&" "&"-"&FIXED(CÁLCULO_MÉDIAS!S14,2,FALSE) -> 670,00 -700,00 | E6: equipamnetos proprios
A7: =GER_EXECUTIVO!A6 -> ALVENARIA | B7: =GER_EXECUTIVO!B6 -> 3190022.9 | C7: =B7/GER_EXECUTIVO!$G$2 -> 190.00616 | D7: =FIXED(CÁLCULO_MÉDIAS!R15,2,FALSE)&" "&"-"&FIXED(CÁLCULO_MÉDIAS!S15,2,FALSE) -> 110,00 -170,00 | E7: ok - drywall interno - mão de obra propria
A8: =GER_EXECUTIVO!A7 -> INSTALAÇÕES ELÉTRICAS, HIDRÁULICAS, GLP E PREVENTIVAS | B8: =GER_EXECUTIVO!B7+GER_EXECUTIVO!B15 -> 6236784.1 | C8: =B8/GER_EXECUTIVO!$G$2 -> 371.47927 | D8: =FIXED(CÁLCULO_MÉDIAS!R16,2,FALSE)&" "&"-"&FIXED(CÁLCULO_MÉDIAS!S16,2,FALSE) -> 360,00 -430,00
A9: =GER_EXECUTIVO!A8 -> EQUIPAMENTOS E SISTEMAS ESPECIAIS | B9: =GER_EXECUTIVO!B8 -> 2585975.8 | C9: =B9/GER_EXECUTIVO!$G$2 -> 154.02752 | D9: =FIXED(CÁLCULO_MÉDIAS!R17,2,FALSE)&" "&"-"&FIXED(CÁLCULO_MÉDIAS!S17,2,FALSE) -> 130,00 -180,00
A10: =GER_EXECUTIVO!A9 -> IMPERMEABILIZAÇÃO | B10: =GER_EXECUTIVO!B9 -> 1463560.6 | C10: =B10/GER_EXECUTIVO!$G$2 -> 87.173523 | D10: =FIXED(CÁLCULO_MÉDIAS!R18,2,FALSE)&" "&"-"&FIXED(CÁLCULO_MÉDIAS!S18,2,FALSE) -> 60,00 -90,00 | E10: ok - tratamento de frisos
A11: REVESTIMENTOS INTERNOS DE PAREDE | B11: =GER_EXECUTIVO!B10 -> 2002760.7 | C11: =B11/GER_EXECUTIVO!$G$2 -> 119.2897 | D11: =FIXED(CÁLCULO_MÉDIAS!R19,2,FALSE)&" "&"-"&FIXED(CÁLCULO_MÉDIAS!S19,2,FALSE) -> 120,00 -160,00 | E11: ok - mo propria para argamassados + drywall
A12: REVESTIMENTOS E ACABAMENTOS INTERNOS EM TETO | B12: =GER_EXECUTIVO!B11 -> 1410266.6 | C12: =B12/GER_EXECUTIVO!$G$2 -> 83.999188 | D12: =FIXED(CÁLCULO_MÉDIAS!R20,2,FALSE)&" "&"-"&FIXED(CÁLCULO_MÉDIAS!S20,2,FALSE) -> 80,00 -110,00 | E12: ok - acartonado + estucamento mo propria
A13: PISOS E PAVIMENTAÇÕES | B13: =GER_EXECUTIVO!B12 -> 2974617.8 | C13: =B13/GER_EXECUTIVO!$G$2 -> 177.17606 | D13: =FIXED(CÁLCULO_MÉDIAS!R21,2,FALSE)&" "&"-"&FIXED(CÁLCULO_MÉDIAS!S21,2,FALSE) -> 160,00 -200,00 | E13: ok
A14: =GER_EXECUTIVO!A13 -> PINTURA INTERNA | B14: =GER_EXECUTIVO!B13 -> 3275186.5 | C14: =B14/GER_EXECUTIVO!$G$2 -> 195.07873 | D14: =FIXED(CÁLCULO_MÉDIAS!R22,2,FALSE)&" "&"-"&FIXED(CÁLCULO_MÉDIAS!S22,2,FALSE) -> 150,00 -180,00 | E14: pintura epoxi no piso da escadas e 2 demaos de textura
A15: =GER_EXECUTIVO!A14 -> ESQUADRIAS, VIDROS E FERRAGENS | B15: =GER_EXECUTIVO!B14 -> 5304562 | C15: =B15/GER_EXECUTIVO!$G$2 -> 315.95367 | D15: =FIXED(CÁLCULO_MÉDIAS!R23,2,FALSE)&" "&"-"&FIXED(CÁLCULO_MÉDIAS!S23,2,FALSE) -> 290,00 -340,00
A16: REVESTIMENTOS E ACABAMENTOS DE FACHADA | B16: =GER_EXECUTIVO!B16 -> 1515128.7 | C16: =B16/GER_EXECUTIVO!$G$2 -> 90.245055 | D16: =FIXED(CÁLCULO_MÉDIAS!R25,2,FALSE)&" "&"-"&FIXED(CÁLCULO_MÉDIAS!S25,2,FALSE) -> 100,00 -160,00 | E16: praticamente tudo textura, granitina mais barato que a textura preta
A17: SERVIÇOS COMPLEMENTARES | B17: =GER_EXECUTIVO!B17 -> 2317724.7 | C17: =B17/GER_EXECUTIVO!$G$2 -> 138.04978 | D17: =FIXED(CÁLCULO_MÉDIAS!R26,2,FALSE)&" "&"-"&FIXED(CÁLCULO_MÉDIAS!S26,2,FALSE) -> 120,00 -180,00
A18: TOTAL | B18: =SUM(B3:B17) -> 52922794 | C18: =SUM(C3:C17) -> 3152.2209 | D18: =FIXED(CÁLCULO_MÉDIAS!R27,2,FALSE)&" "&"-"&FIXED(CÁLCULO_MÉDIAS!S27,2,FALSE) -> 2.968,00 -3.690,00

Sheet CÁLCULO_MÉDIAS
C3: DATA BASE | D3: 45597 | E3: DATA BASE | F3: 44682 | G3: DATA BASE | H3: 45658 | I3: DATA BASE | J3: 45017 | K3: DATA BASE | L3: 45017 | M3: DATA BASE | N3: 45809 | O3: DATA BASE | P3: 45323
C4: CUB | D4: 2863.73 | E4: CUB | F4: 2470.83 | G4: CUB | H4: 2887.91 | I4: CUB | J4: 2680.84 | K4: CUB | L4: 2680.84 | M4: CUB | N4: 2934.53 | O4: CUB | P4: 2753.62
C5: M2 | N5: =#REF! -> #REF! | P5: =#REF! -> #REF!
C6: PAVIMENTOS
C8: A= 22.087,95 M² | E8: A=15.492,69 m² | G8: A=22.461,09 m² | I8: A=16.348,10 m² | K8: A=14.559,12 m² | M8: A= 15.602,85 M² | O8: A= 13.434,29 M²
C9: JTA - ASPEN | E9: CN - BRAVA BREEZE | G9: BE BRAVE - MERAKI | I9: AS RAMOS - PAESSAGGIO | K9: NEUHAUS - ORIGEM 3300 | M9: AMALFI - TRAMONTI | O9: AMALFI - RAVELLO | R9: MÉDIAS
C10: VALOR / M2 | D10: INDEXADO | E10: VALOR / M2 | F10: INDEXADO | G10: VALOR / M2 | H10: INDEXADO | I10: VALOR / M2 | J10: INDEXADO | K10: VALOR / M2 | L10: INDEXADO | M10: VALOR / M2 | N10: INDEXADO | O10: VALOR / M2 | P10: INDEXADO | R10: MÍNIMA | S10: MÁXIMA
B11: GERENCIAMENTO TÉCNICO E ADMINISTRATIVO | C11: 348.23953 | D11: =(GER_EXECUTIVO!$B$20/CÁLCULO_MÉDIAS!D$4)*C11 -> 360.61998 | E11: 497.92 | F11: =(GER_EXECUTIVO!$B$20/CÁLCULO_MÉDIAS!F$4)*E11 -> 597.61363 | G11: 349.09454 | H11: =(GER_EXECUTIVO!$B$20/CÁLCULO_MÉDIAS!H$4)*G11 -> 358.47856 | I11: 263.25798 | J11: =(GER_EXECUTIVO!$B$20/CÁLCULO_MÉDIAS!J$4)*I11 -> 291.21547 | K11: 830.79084 | L11: =(GER_EXECUTIVO!$B$20/CÁLCULO_MÉDIAS!L$4)*K11 -> 919.01921 | M11: 494.3728 | N11: =(GER_EXECUTIVO!$B$20/CÁLCULO_MÉDIAS!N$4)*M11 -> 499.59698 | O11: 353.32967 | P11: =(GER_EXECUTIVO!$B$20/CÁLCULO_MÉDIAS!P$4)*O11 -> 380.5221 | R11: 360 | S11: 420
B12: MOVIMENTAÇÃO DE TERRA | C12: 8.9791864 | D12: =(GER_EXECUTIVO!$B$20/CÁLCULO_MÉDIAS!D$4)*C12 -> 9.2984103 | E12: 3.34 | F12: =(GER_EXECUTIVO!$B$20/CÁLCULO_MÉDIAS!F$4)*E12 -> 4.0087354 | G12: 14.094794 | H12: =(GER_EXECUTIVO!$B$20/CÁLCULO_MÉDIAS!H$4)*G12 -> 14.473676 | I12: 26.515285 | J12: =(GER_EXECUTIVO!$B$20/CÁLCULO_MÉDIAS!J$4)*I12 -> 29.331157 | K12: 22.967891 | L12: =(GER_EXECUTIVO!$B$20/CÁLCULO_MÉDIAS!L$4)*K12 -> 25.407036 | M12: 90.726936 | N12: =(GER_EXECUTIVO!$B$20/CÁLCULO_MÉDIAS!N$4)*M12 -> 91.685673 | O12: 6.8428238 | P12: =(GER_EXECUTIVO!$B$20/CÁLCULO_MÉDIAS!P$4)*O12 -> 7.3694511 | R12: 15 | S12: 25
B13: INFRAESTRUTURA | C13: 209.58679 | D13: =(GER_EXECUTIVO!$B$20/CÁLCULO_MÉDIAS!D$4)*C13 -> 217.03793 | E13: 107.1 | F13: =(GER_EXECUTIVO!$B$20/CÁLCULO_MÉDIAS!F$4)*E13 -> 128.54358 | G13: 234.22276 | H13: =(GER_EXECUTIVO!$B$20/CÁLCULO_MÉDIAS!H$4)*G13 -> 240.51891 | I13: 309.92994 | J13: =(GER_EXECUTIVO!$B$20/CÁLCULO_MÉDIAS!J$4)*I13 -> 342.8439 | K13: 218.6753 | L13: =(GER_EXECUTIVO!$B$20/CÁLCULO_MÉDIAS!L$4)*K13 -> 241.89819 | M13: 151.78679 | N13: =(GER_EXECUTIVO!$B$20/CÁLCULO_MÉDIAS!N$4)*M13 -> 153.39076 | O13: 167.92237 | P13: =(GER_EXECUTIVO!$B$20/CÁLCULO_MÉDIAS!P$4)*O13 -> 180.84576 | R13: 240 | S13: 340
B14: SUPRAESTRUTURA | C14: 651.15796 | D14: =(GER_EXECUTIVO!$B$20/CÁLCULO_MÉDIAS!D$4)*C14 -> 674.30762 | E14: 427.85 | F14: =(GER_EXECUTIVO!$B$20/CÁLCULO_MÉDIAS!F$4)*E14 -> 513.5142 | G14: 769.3126 | H14: =(GER_EXECUTIVO!$B$20/CÁLCULO_MÉDIAS!H$4)*G14 -> 789.99251 | I14: 776.71351 | J14: =(GER_EXECUTIVO!$B$20/CÁLCULO_MÉDIAS!J$4)*I14 -> 859.19898 | K14: 985.74568 | L14: =(GER_EXECUTIVO!$B$20/CÁLCULO_MÉDIAS!L$4)*K14 -> 1090.43 | M14: 1051.5758 | N14: =(GER_EXECUTIVO!$B$20/CÁLCULO_MÉDIAS!N$4)*M14 -> 1062.6881 | O14: 649.76457 | P14: =(GER_EXECUTIVO!$B$20/CÁLCULO_MÉDIAS!P$4)*O14 -> 699.77078 | R14: 670 | S14: 700
B15: PAREDES E PAINÉIS | C15: 183.17403 | D15: =(GER_EXECUTIVO!$B$20/CÁLCULO_MÉDIAS!D$4)*C15 -> 189.68615 | E15: 88.69 | F15: =(GER_EXECUTIVO!$B$20/CÁLCULO_MÉDIAS!F$4)*E15 -> 106.44753 | G15: 213.31803 | H15: =(GER_EXECUTIVO!$B$20/CÁLCULO_MÉDIAS!H$4)*G15 -> 219.05224 | I15: 98.69403 | J15: =(GER_EXECUTIVO!$B$20/CÁLCULO_MÉDIAS!J$4)*I15 -> 109.17514 | K15: 223.60659 | L15: =(GER_EXECUTIVO!$B$20/CÁLCULO_MÉDIAS!L$4)*K15 -> 247.35318 | M15: 203.85761 | N15: =(GER_EXECUTIVO!$B$20/CÁLCULO_MÉDIAS!N$4)*M15 -> 206.01183 | O15: 158.61182 | P15: =(GER_EXECUTIVO!$B$20/CÁLCULO_MÉDIAS!P$4)*O15 -> 170.81867 | R15: 110 | S15: 170
B16: INSTALAÇÕES ELÉTRICAS, HIDRÁULICAS, GLP E PREVENTIVAS | C16: 398.50014 | D16: =(GER_EXECUTIVO!$B$20/CÁLCULO_MÉDIAS!D$4)*C16 -> 412.66743 | E16: 361.85 | F16: =(GER_EXECUTIVO!$B$20/CÁLCULO_MÉDIAS!F$4)*E16 -> 434.29967 | G16: 444.29 | H16: =(GER_EXECUTIVO!$B$20/CÁLCULO_MÉDIAS!H$4)*G16 -> 456.23297 | I16: 252.23203 | J16: =(GER_EXECUTIVO!$B$20/CÁLCULO_MÉDIAS!J$4)*I16 -> 279.01858 | K16: 366.15 | L16: =(GER_EXECUTIVO!$B$20/CÁLCULO_MÉDIAS!L$4)*K16 -> 405.03442 | M16: 419.07 | N16: =(GER_EXECUTIVO!$B$20/CÁLCULO_MÉDIAS!N$4)*M16 -> 423.49843 | O16: 340.84 | P16: =(GER_EXECUTIVO!$B$20/CÁLCULO_MÉDIAS!P$4)*O16 -> 367.07122 | R16: 360 | S16: 430
B17: EQUIPAMENTOS E SISTEMAS ESPECIAIS | C17: 231.08116 | D17: =(GER_EXECUTIVO!$B$20/CÁLCULO_MÉDIAS!D$4)*C17 -> 239.29645 | E17: 395.93 | F17: =(GER_EXECUTIVO!$B$20/CÁLCULO_MÉDIAS!F$4)*E17 -> 475.20317 | G17: 219.95619 | H17: =(GER_EXECUTIVO!$B$20/CÁLCULO_MÉDIAS!H$4)*G17 -> 225.86884 | I17: 247.28447 | J17: =(GER_EXECUTIVO!$B$20/CÁLCULO_MÉDIAS!J$4)*I17 -> 273.5456 | K17: 254.94 | L17: =(GER_EXECUTIVO!$B$20/CÁLCULO_MÉDIAS!L$4)*K17 -> 282.01413 | M17: 171.69117 | N17: =(GER_EXECUTIVO!$B$20/CÁLCULO_MÉDIAS!N$4)*M17 -> 173.50548 | O17: 122.47621 | P17: =(GER_EXECUTIVO!$B$20/CÁLCULO_MÉDIAS!P$4)*O17 -> 131.90204 | R17: 130 | S17: 180
B18: IMPERMEABILIZAÇÃO | C18: 48.366382 | D18: =(GER_EXECUTIVO!$B$20/CÁLCULO_MÉDIAS!D$4)*C18 -> 50.085881 | E18: 50.44 | F18: =(GER_EXECUTIVO!$B$20/CÁLCULO_MÉDIAS!F$4)*E18 -> 60.539105 | G18: 48.289899 | H18: =(GER_EXECUTIVO!$B$20/CÁLCULO_MÉDIAS!H$4)*G18 -> 49.587981 | I18: 50.859372 | J18: =(GER_EXECUTIVO!$B$20/CÁLCULO_MÉDIAS!J$4)*I18 -> 56.260539 | K18: 79.430797 | L18: =(GER_EXECUTIVO!$B$20/CÁLCULO_MÉDIAS!L$4)*K18 -> 87.866194 | M18: 52.58614 | N18: =(GER_EXECUTIVO!$B$20/CÁLCULO_MÉDIAS!N$4)*M18 -> 53.141833 | O18: 60.962018 | P18: =(GER_EXECUTIVO!$B$20/CÁLCULO_MÉDIAS!P$4)*O18 -> 65.653685 | R18: 60 | S18: 90
B19: REVESTIMENTOS INTERNOS DE PAREDE | C19: =([2]Ger_Executivo!$N$196+[2]Ger_Executivo!$N$207+[2]Ger_Executivo!$N$210)/[2]Obra!$E$9 -> 223.0544 | D19: =(GER_EXECUTIVO!$B$20/CÁLCULO_MÉDIAS!D$4)*C19 -> 230.98433 | E19: 220.7515 | F19: =(GER_EXECUTIVO!$B$20/CÁLCULO_MÉDIAS!F$4)*E19 -> 264.95041 | G19: 116.32389 | H19: =(GER_EXECUTIVO!$B$20/CÁLCULO_MÉDIAS!H$4)*G19 -> 119.4508 | J19: =(GER_EXECUTIVO!$B$20/CÁLCULO_MÉDIAS!J$4)*I19 -> 0 | K19: =[3]Ger_Executivo!$N$1463/[3]OBRA!$E$9+[3]OBRA!$E$43 -> 119.86635 | L19: =(GER_EXECUTIVO!$B$20/CÁLCULO_MÉDIAS!L$4)*K19 -> 132.59592 | M19: 121.28928 | N19: =(GER_EXECUTIVO!$B$20/CÁLCULO_MÉDIAS!N$4)*M19 -> 122.57098 | O19: 168.50558 | P19: =(GER_EXECUTIVO!$B$20/CÁLCULO_MÉDIAS!P$4)*O19 -> 181.47386 | R19: 120 | S19: 160
B20: REVESTIMENTOS E ACABAMENTOS INTERNOS EM TETO | C20: =([2]Ger_Executivo!$N$242+[2]Ger_Executivo!$N$208+[2]Ger_Executivo!$N$200)/[2]Obra!$E$9 -> 70.555596 | D20: =(GER_EXECUTIVO!$B$20/CÁLCULO_MÉDIAS!D$4)*C20 -> 73.063956 | E20: 66.57 | F20: =(GER_EXECUTIVO!$B$20/CÁLCULO_MÉDIAS!F$4)*E20 -> 79.898657 | G20: 104.03196 | H20: =(GER_EXECUTIVO!$B$20/CÁLCULO_MÉDIAS!H$4)*G20 -> 106.82845 | I20: 63.568288 | J20: =(GER_EXECUTIVO!$B$20/CÁLCULO_MÉDIAS!J$4)*I20 -> 70.319117 | K20: 83.16 | L20: =(GER_EXECUTIVO!$B$20/CÁLCULO_MÉDIAS!L$4)*K20 -> 91.99143 | M20: 108.19728 | N20: =(GER_EXECUTIVO!$B$20/CÁLCULO_MÉDIAS!N$4)*M20 -> 109.34063 | O20: 53.679931 | P20: =(GER_EXECUTIVO!$B$20/CÁLCULO_MÉDIAS!P$4)*O20 -> 57.811165 | R20: 80 | S20: 110
B21: PISOS E PAVIMENTAÇÕES | C21: =([2]Ger_Executivo!$N$202+[2]Ger_Executivo!$N$209+[2]Ger_Executivo!$N$221)/[2]Obra!$E$9 -> 185.88186 | D21: =(GER_EXECUTIVO!$B$20/CÁLCULO_MÉDIAS!D$4)*C21 -> 192.49025 | E21: 170.0685 | F21: =(GER_EXECUTIVO!$B$20/CÁLCULO_MÉDIAS!F$4)*E21 -> 204.11964 | G21: 205.46341 | H21: =(GER_EXECUTIVO!$B$20/CÁLCULO_MÉDIAS!H$4)*G21 -> 210.98648 | J21: =(GER_EXECUTIVO!$B$20/CÁLCULO_MÉDIAS!J$4)*I21 -> 0 | K21: =[3]Ger_Executivo!$N$1721/[3]OBRA!$E$9+[3]OBRA!$E$44 -> 201.68775 | L21: =(GER_EXECUTIVO!$B$20/CÁLCULO_MÉDIAS!L$4)*K21 -> 223.1066 | M21: 160.67916 | N21: =(GER_EXECUTIVO!$B$20/CÁLCULO_MÉDIAS!N$4)*M21 -> 162.3771 | O21: 142.21829 | P21: =(GER_EXECUTIVO!$B$20/CÁLCULO_MÉDIAS!P$4)*O21 -> 153.16348 | R21: 160 | S21: 200
B22: PINTURA INTERNA | C22: 169.53261 | D22: =(GER_EXECUTIVO!$B$20/CÁLCULO_MÉDIAS!D$4)*C22 -> 175.55975 | E22: 149.19 | F22: =(GER_EXECUTIVO!$B$20/CÁLCULO_MÉDIAS!F$4)*E22 -> 179.06085 | G22: 110.60376 | H22: =(GER_EXECUTIVO!$B$20/CÁLCULO_MÉDIAS!H$4)*G22 -> 113.5769 | I22: 133.62135 | J22: =(GER_EXECUTIVO!$B$20/CÁLCULO_MÉDIAS!J$4)*I22 -> 147.81167 | K22: 148.07044 | L22: =(GER_EXECUTIVO!$B$20/CÁLCULO_MÉDIAS!L$4)*K22 -> 163.79523 | M22: 163.94097 | N22: =(GER_EXECUTIVO!$B$20/CÁLCULO_MÉDIAS!N$4)*M22 -> 165.67338 | O22: 139.12075 | P22: =(GER_EXECUTIVO!$B$20/CÁLCULO_MÉDIAS!P$4)*O22 -> 149.82755 | R22: 150 | S22: 180
B23: ESQUADRIAS, VIDROS E FERRAGENS | C23: 441.48351 | D23: =(GER_EXECUTIVO!$B$20/CÁLCULO_MÉDIAS!D$4)*C23 -> 457.17893 | E23: 313.81 | F23: =(GER_EXECUTIVO!$B$20/CÁLCULO_MÉDIAS!F$4)*E23 -> 376.64109 | G23: 306.96786 | H23: =(GER_EXECUTIVO!$B$20/CÁLCULO_MÉDIAS!H$4)*G23 -> 315.21947 | I23: 259.7904 | J23: =(GER_EXECUTIVO!$B$20/CÁLCULO_MÉDIAS!J$4)*I23 -> 287.37964 | K23: 395.06037 | L23: =(GER_EXECUTIVO!$B$20/CÁLCULO_MÉDIAS!L$4)*K23 -> 437.01501 | M23: 325.90368 | N23: =(GER_EXECUTIVO!$B$20/CÁLCULO_MÉDIAS!N$4)*M23 -> 329.3476 | O23: 228.01196 | P23: =(GER_EXECUTIVO!$B$20/CÁLCULO_MÉDIAS!P$4)*O23 -> 245.55988 | R23: 290 | S23: 340
B24: COBERTURA | C24: 100.67725 | D24: =(GER_EXECUTIVO!$B$20/CÁLCULO_MÉDIAS!D$4)*C24 -> 104.25648 | F24: =(GER_EXECUTIVO!$B$20/CÁLCULO_MÉDIAS!F$4)*E24 -> 0 | G24: 2.5906134 | H24: =(GER_EXECUTIVO!$B$20/CÁLCULO_MÉDIAS!H$4)*G24 -> 2.6602517 | I24: 4.0117127 | J24: =(GER_EXECUTIVO!$B$20/CÁLCULO_MÉDIAS!J$4)*I24 -> 4.4377488 | L24: =(GER_EXECUTIVO!$B$20/CÁLCULO_MÉDIAS!L$4)*K24 -> 0 | M24: 0 | N24: =(GER_EXECUTIVO!$B$20/CÁLCULO_MÉDIAS!N$4)*M24 -> 0 | P24: =(GER_EXECUTIVO!$B$20/CÁLCULO_MÉDIAS!P$4)*O24 -> 0 | R24: 3 | S24: 5
B25: REVESTIMENTOS E ACABAMENTOS DE FACHADA | C25: 11.757488 | D25: =(GER_EXECUTIVO!$B$20/CÁLCULO_MÉDIAS!D$4)*C25 -> 12.175485 | E25: 84.76 | F25: =(GER_EXECUTIVO!$B$20/CÁLCULO_MÉDIAS!F$4)*E25 -> 101.73066 | G25: 334.40653 | H25: =(GER_EXECUTIVO!$B$20/CÁLCULO_MÉDIAS!H$4)*G25 -> 343.39572 | I25: 231.41623 | J25: =(GER_EXECUTIVO!$B$20/CÁLCULO_MÉDIAS!J$4)*I25 -> 255.99218 | K25: 179.37177 | L25: =(GER_EXECUTIVO!$B$20/CÁLCULO_MÉDIAS!L$4)*K25 -> 198.42071 | M25: 165.05702 | N25: =(GER_EXECUTIVO!$B$20/CÁLCULO_MÉDIAS!N$4)*M25 -> 166.80123 | O25: 165.52214 | P25: =(GER_EXECUTIVO!$B$20/CÁLCULO_MÉDIAS!P$4)*O25 -> 178.26081 | R25: 100 | S25: 160
B26: SERVIÇOS COMPLEMENTARES | C26: 194.4379 | D26: =(GER_EXECUTIVO!$B$20/CÁLCULO_MÉDIAS!D$4)*C26 -> 201.35047 | E26: 182.12 | F26: =(GER_EXECUTIVO!$B$20/CÁLCULO_MÉDIAS!F$4)*E26 -> 218.5841 | G26: 180.7037 | H26: =(GER_EXECUTIVO!$B$20/CÁLCULO_MÉDIAS!H$4)*G26 -> 185.5612 | I26: 106.34114 | J26: =(GER_EXECUTIVO!$B$20/CÁLCULO_MÉDIAS!J$4)*I26 -> 117.63437 | K26: 263.72633 | L26: =(GER_EXECUTIVO!$B$20/CÁLCULO_MÉDIAS!L$4)*K26 -> 291.73356 | M26: 161.57705 | N26: =(GER_EXECUTIVO!$B$20/CÁLCULO_MÉDIAS!N$4)*M26 -> 163.28448 | O26: 168.56441 | P26: =(GER_EXECUTIVO!$B$20/CÁLCULO_MÉDIAS!P$4)*O26 -> 181.53721 | R26: 120 | S26: 180
B27: TOTAL | C27: =SUM(C11:C26) -> 3476.4658 | D27: =SUM(D11:D26) -> 3600.0595 | E27: =SUM(E11:E26) -> 3120.39 | F27: =SUM(F11:F26) -> 3745.155 | G27: =SUM(G11:G26) -> 3653.6705 | H27: =SUM(H11:H26) -> 3751.885 | I27: =SUM(I11:I26) -> 2824.2357 | J27: =SUM(J11:J26) -> 3124.1641 | ... P27: =SUM(P11:P26) -> 3151.5877 | R27: =SUM(R11:R26) -> 2968 | S27: =SUM(S11:S26) -> 3690

Sheet AREAS PRIVATIVAS
A1: ETAPA | B1: VALOR ORÇADO | C1: % | D1: VALOR / m²
A2: GERENCIAMENTO TÉCNICO E ADMINISTRATIVO | B2: =#REF! -> #REF! | C2: =B2/B$19 -> #REF! | D2: =B2/$B$23 -> #REF! | E2: =B2/GER_EXECUTIVO!$G$2 -> #REF!
A3: MOVIMENTAÇÃO DE TERRA | B3: =#REF! -> #REF! | C3: =B3/B$19 -> #REF! | D3: =B3/$B$23 -> #REF! | E3: =B3/GER_EXECUTIVO!$G$2 -> #REF!
A4: INFRAESTRUTURA | B4: =#REF! -> #REF! | C4: =B4/B$19 -> #REF! | D4: =B4/$B$23 -> #REF! | E4: =B4/GER_EXECUTIVO!$G$2 -> #REF!
A5: CONTENÇÕES | B5: 0 | C5: =B5/B$19 -> #REF! | D5: =B5/$B$23 -> 0 | E5: =B5/GER_EXECUTIVO!$G$2 -> 0
A6: SUPRAESTRUTURA | B6: =#REF! -> #REF! | C6: =B6/B$19 -> #REF! | D6: =B6/$B$23 -> #REF! | E6: =B6/GER_EXECUTIVO!$G$2 -> #REF!
A7: PAREDES E PAINÉIS | B7: =#REF! -> #REF! | C7: =B7/B$19 -> #REF! | D7: =B7/$B$23 -> #REF! | E7: =B7/GER_EXECUTIVO!$G$2 -> #REF!
A8: INSTALAÇÕES ELÉTRICAS, HIDRÁULICAS, GLP E PREVENTIVAS | B8: =#REF!+#REF! -> #REF! | C8: =B8/B$19 -> #REF! | D8: =B8/$B$23 -> #REF! | E8: =B8/GER_EXECUTIVO!$G$2 -> #REF!
A9: EQUIPAMENTOS E SISTEMAS ESPECIAIS | B9: =#REF! -> #REF! | C9: =B9/B$19 -> #REF! | D9: =B9/$B$23 -> #REF! | E9: =B9/GER_EXECUTIVO!$G$2 -> #REF!
A10: IMPERMEABILIZAÇÃO | B10: =#REF! -> #REF! | C10: =B10/B$19 -> #REF! | D10: =B10/$B$23 -> #REF! | E10: =B10/GER_EXECUTIVO!$G$2 -> #REF!
A11: REVESTIMENTOS INTERNOS EM PISO E PAREDE | B11: =#REF!+#REF! -> #REF! | C11: =B11/B$19 -> #REF! | D11: =B11/$B$23 -> #REF! | E11: =B11/GER_EXECUTIVO!$G$2 -> #REF!
A12: REVESTIMENTOS E ACABAMENTOS INTERNOS EM TETO | B12: =#REF! -> #REF! | C12: =B12/B$19 -> #REF! | D12: =B12/$B$23 -> #REF! | E12: =B12/GER_EXECUTIVO!$G$2 -> #REF!
A13: ACABAMENTOS EM PISO E PAREDE | B13: =#REF!+#REF! -> #REF! | C13: =B13/B$19 -> #REF! | D13: =B13/$B$23 -> #REF! | E13: =B13/GER_EXECUTIVO!$G$2 -> #REF!
A14: PINTURA INTERNA | B14: =#REF! -> #REF! | C14: =B14/B$19 -> #REF! | D14: =B14/$B$23 -> #REF! | E14: =B14/GER_EXECUTIVO!$G$2 -> #REF!
A15: ESQUADRIAS, VIDROS E FERRAGENS | B15: =#REF! -> #REF! | C15: =B15/B$19 -> #REF! | D15: =B15/$B$23 -> #REF! | E15: =B15/GER_EXECUTIVO!$G$2 -> #REF!
A16: REVESTIMENTOS E ACABAMENTOS DE FACHADA | B16: =#REF!+#REF! -> #REF! | C16: =B16/B$19 -> #REF! | D16: =B16/$B$23 -> #REF! | E16: =B16/GER_EXECUTIVO!$G$2 -> #REF!
A17: SERVIÇOS COMPLEMENTARES | B17: =#REF! -> #REF! | C17: =B17/B$19 -> #REF! | D17: =B17/$B$23 -> #REF! | E17: =B17/GER_EXECUTIVO!$G$2 -> #REF!
A18: IMPREVISTOS E CONTINGÊNCIAS | B18: =SUM(B2:B17)*0.03 -> #REF! | C18: =B18/B$19 -> #REF! | D18: =B18/$B$23 -> #REF! | E18: =B18/GER_EXECUTIVO!$G$2 -> #REF!
A19: TOTAL | B19: =SUM(B2:B18) -> #REF! | C19: =SUM(C2:C18) -> #REF! | D19: =SUM(D2:D17) -> #REF!
A22: DESCRIÇÃO | B22: ÁREA (m²) | C22: VALOR TOTAL
A23: VALOR POR ÁREA PRIVATIVA (R$/m²) | B23: =(B24+B27+B25+B26+B28)*18 -> 7928.64 | C23: =[4]GER_EXECUTIVO!B19/'[4]AREAS PRIVATIVAS'!B23 -> 7067.1421
A24: VALOR POR UNIDADE 01 | B24: 106.4 | C24: =$C$23*B24 -> 751943.92
A25: VALOR POR UNIDADE 02 | B25: 75.53 | C25: =$C$23*B25 -> 533781.24
A26: VALOR POR UNIDADE 03 | B26: 104.02 | C26: =$C$23*B26 -> 735124.12
A27: VALOR POR UNIDADE 04 | B27: 78.07 | C27: =$C$23*B27 -> 551731.78
A28: VALOR POR UNIDADE 05 | B28: 76.46 | C28: =$C$23*B28 -> 540353.68
A31: DESCRIÇÃO | B31: ÁREA (m²) | C31: VALOR POR ÁREA PRIVATIVA (R$/m²)
A32: RAVELLO | B32: 6651.9 | C32: 5907.0751
A33: MARINE | B33: 2651.04 | C33: 5321.4146
A34: MAIORI | B34: 4969.86 | C34: 5067.6946
A36: PROFUNDIDADE DAS ESTACAS E CONTENÇÕES
A37: 93/M2 SÓ DE CONTNEÇÃO
A39: DESCRIÇÃO | B39: VALOR | C39: VALOR POR ÁREA PRIVATIVA (R$/m²)
A40: MOVIMENTAÇÃO DE TERRA | B40: 665180.32 | C40: 83.895892
A41: INFRAESTRUTURA | B41: 3748752.5 | C41: 472.81154
A42: CONTENÇÕES | B42: 1651819.6 | C42: 208.3358
