Workbook
Name \0: #REF!
Name \0: #REF!
Name \0: #REF!
Name \0: #REF!
Name \0: #REF!
Name \0: #REF!
Name \0: #REF!
Name \0: #REF!
Name \0: #REF!
Name \0: #REF!
Name \0: #REF!
Name \0: #REF!
Name \1: #REF!
Name \1: #REF!
Name \1: #REF!
Name \1: #REF!
Name \1: #REF!
Name \1: #REF!
Name \1: #REF!
Name \1: #REF!
Name \1: #REF!
Name \a: #REF!
Name \a: #REF!
Name \a: #REF!
Name \a: #REF!
Name \a: #REF!
Name \a: #REF!
Name \a: #REF!
Name \a: #REF!
Name \a: #REF!
Name \a: #REF!
Name \a: #REF!
Name \b: #REF!
Name \b: #REF!
Name \b: #REF!
Name \b: #REF!
Name \b: #REF!
Name \b: #REF!
Name \b: #REF!
Name \b: #REF!
Name \c: #REF!
Name \c: #REF!
Name \c: #REF!
Name \c: #REF!
Name \c: #REF!
Name \c: #REF!
Name \c: #REF!
Name \c: #REF!
Name \d: #REF!
Name \d: #REF!
Name \d: #REF!
Name \d: #REF!
Name \d: #REF!
Name \d: #REF!
Name \d: #REF!
Name \d: #REF!
Name \e: #REF!
Name \e: #REF!
Name \e: #REF!
Name \e: #REF!

Sheet OBRA
A1: Obra | B1: Sense106
A2: Empresa | B2: HOLZE Empreendimentos
A3: Revisão | B3: R00
A4: DADOS OBRA
A6: ARQUITETURA
B8: Descrição | C8: Unidade | D8: Quantidade
B9: ÁREA DO TERRENO | C9: M2 | D9: 720.16
B10: ÁREA CONSTRUÍDA | C10: M2 | D10: 8700
B11: NÚMERO DE UNIDADES HABITACIONAIS | C11: UN | D11: =20*3 -> 60
B12: MESES DE OBRA | C12: MÊS | D12: 48
B13: NÚMERO DE PAVIMENTOS | C13: UN | D13: 27

Sheet EPC's
A1: Obra | B1: =OBRA!B1 -> Sense106
A2: Empresa | B2: =OBRA!B2 -> HOLZE Empreendimentos
A3: Revisão | B3: =OBRA!B3 -> R00
A4: LEVANTAMENTO QUANTITATIVO
A6: Equipamentos de proteção coletiva
A8: Bandejas de proteção
B10: Descrição | C10: Unidade | D10: Quantidade
B11: Perímetro de projeção embasamento | C11: m | D11: 102.22
B12: Número de montagens de bandeja primária | C12: un | D12: 1
B13: Perímetro de projeção torre | C13: m | D13: 69.49
B14: Número de montagens de bandeja primária | C14: un | D14: 1
B15: Bandeja de proteção primária | C15: m | D15: =D11*D12+D13*D14 -> 171.71
B16: Perímetro de projeção torre | C16: m | D16: =D13 -> 69.49
B17: Número de montagens de bandeja secundária | C17: un | D17: 5
B18: Bandeja de proteção secundária | C18: m | D18: =D16*D17 -> 347.45
A20: Guarda - corpo de desforma
B22: Descrição | C22: Unidade | D22: Quantidade
B23: Perímetro de projeção da torre | C23: m | D23: =D16 -> 69.49
B24: Repetições de pavimentos** | C24: un | D24: 4
B25: Proteção de periferia pós desforma torre | C25: m | D25: =(D23*D24) -> 277.96
A27: Tela fachadeira
B29: Descrição | C29: Unidade | D29: Quantidade
B30: Area da fachada coberta | C30: m² | D30: =1998.89+2*2016.93 -> 6032.75
B31: Tela fachadeira | C31: m2 | D31: =D30 -> 6032.75
A33: Fechamento removível de vãos em madeira
B35: Descrição | C35: Unidade | D35: Quantidade
B36: Área das portas de elevadores | C36: m2 | D36: =0.9*2.4 -> 2.16
B37: Quantidade de elevadores | C37: un | D37: 2
B38: Quantidade de portas de elevadores | C38: un | D38: =D37*25 -> 50
B39: Fechamento removível de vãos em madeira | C39: m2 | D39: =D36*D38 -> 108
A41: Guarda - corpo de vãos
B43: Descrição | C43: Unidade | D43: Quantidade
B44: Perímetro de vãos | C44: m | D44: =9.8+14.5+12.2+23.56+12.8*20 -> 316.06
B45: Guarda - corpo de vãos | C45: m | D45: =D44 -> 316.06
A47: Tapume
B49: Descrição | C49: Unidade | D49: Quantidade
B50: Perímetro de encontro com pavimentação | C50: m | D50: 25.72
B51: Altura do tapume | C51: m | D51: 2.4
B52: Área de tapume | C52: m2 | D52: =D51*D50 -> 61.728
A54: Linha de vida
...

Sheet CANTEIRO
A1: Obra | B1: =OBRA!B1 -> Sense106
A2: Empresa | B2: =OBRA!B2 -> HOLZE Empreendimentos
A3: Revisão | B3: =OBRA!B3 -> R00
A4: LEVANTAMENTO QUANTITATIVO
A6: Instalações de canteiro
A8: Instalações de canteiro
B10: Descrição | C10: Unidade | D10: Quantidade
B11: Produtividade média | C11: ac/prazo | D11: =OBRA!D10/OBRA!D12 -> 181.25
B12: Pm | C12: h/m2 | D12: 49
B13: Numero de funcionários | C13: un | D13: =ROUNDUP((D12*OBRA!D10)/OBRA!D12/180,) -> 50
B14: Equipe administrativa | C14: un | D14: 5
B15: Pontos de água e esgoto | C15: un | D15: =ROUNDUP(($D$13+D14)/20,0) -> 3 | E15: 20 funcionários/ponto
B16: Bebedouro | C16: un | D16: =ROUNDUP(OBRA!$D$13/5,0) -> 6 | E16: 1 / 5 pav.
B17: Ferramentas | C17: R$ | D17: =800*(D13+D14) -> 44000 | E17: 800,00/func.
B18: EPI | C18: R$ | D18: =500*(D13+D14) -> 27500 | E18: 500,00/func.
B19: Banheiro | C19: un | D19: =ROUNDUP(($D$13+D14)/20,0) -> 3 | E19: 1/20 func
A21: Mobiliário de canteiro
B23: Descrição | C23: Unidade | D23: Quantidade | E23: Custo unitário | F23: Custo total
B24: Cadeira | C24: un | D24: =ROUNDUP(D28*1.5,0) -> 8 | E24: 200 | F24: =D24*E24 -> 1600
B25: Mesa | C25: un | D25: 1 | E25: 1000 | F25: =E25*D25 -> 1000
B26: Ar condicionado | C26: un | D26: 1 | E26: 5000 | F26: =E26*D26 -> 5000
B27: Armário | C27: m | D27: 6 | E27: 900 | F27: =E27*D27 -> 5400
B28: Escrivaninha | C28: un | D28: =D14 -> 5 | E28: 800 | F28: =E28*D28 -> 4000
B29: TOTAL | F29: =F26+F27+F28+F25+F24 -> 17000
B30: Descrição | C30: Unidade | D30: Quantidade | E30: Custo unitário | F30: Custo total
B31: Computador pessoal | C31: un | D31: =D14 -> 5 | E31: 6000 | F31: =D31*E31 -> 30000
B32: Impressora | C32: un | D32: 1 | E32: 2000 | F32: =E32*D32 -> 2000
B33: Roteador | C33: un | D33: 2 | E33: 500 | F33: =E33*D33 -> 1000
B34: TOTAL | F34: =+F31+F32+F33 -> 33000

Sheet CONTROLE_TEC
E5: COND.01
A6: Item | B6: Descrição/Especificação | C6: Unid. | D6: V. Unit. (R$) | E6: Qtde. | F6: V. Total (R$) | G6: Observações
B7: CONTROLE TECNOLÓGICO - CONCRETO
A8: 1 | B8: Laudo e ART | C8: vb | D8: 1450 | E8: 1 | F8: =$D8*E8 -> 1450
A9: =A8+1 -> 2 | B9: Controle Tecnologico - Coleta materiais da obra | C9: unid. | D9: 20 | E9: =ROUNDUP((ORÇAMENTO!L226+ORÇAMENTO!L235+ORÇAMENTO!L251+SUPRA!K53)/8,0)*4 -> 1780 | F9: =$D9*E9 -> 35600 | G9: 4 CPs por caminhão betoneira de 8m³
A10: =A9+1 -> 3 | B10: Controle Tecnológico - Ensaio de concreto endurecido/grouth - compressão simples / Detalhe: Concreto | C10: cps | D10: 12.5 | E10: =E9 -> 1780 | F10: =$D10*E10 -> 22250 | G10: 4 CPs por caminhão betoneira de 8m³
A11: =A10+1 -> 4 | B11: Determinação do módulo de deformação tangente inicial (Eci) (módulo de elasticidade), Incluindo Avaliação Estática dos Resultados (NBR 8522 e NBR 12655) | C11: ensaio | D11: 480 | E11: 5 | F11: =$D11*E11 -> 2400 | G11: A cada 5 pav. (e quando houver troca de fornecedor)
C12: SUBTOTAL: | F12: =SUM(F8:F11) -> 61700
B14: ENSAIOS PARA ARGAMASSA DE REVESTIMENTO (FACHADA)
A15: 1 | B15: Ensaio de arrancamento de argamassa de revestimento Determinação da aderencia a tração | C15: ensaios | D15: 2760 | E15: 1 | F15: =$D15*E15 -> 2760 | G15: 1 ensaio por torre
C16: SUBTOTAL: | F16: =F15 -> 2760
C18: VALOR TOTAL: | F18: =F16+F12 -> 64460

Sheet ORÇAMENTO
G4: PROJETO: | I4: SENSE106 | O4: REVISÃO: | P4: DATA
G5: EMPRESA: | I5: HOLZE EMPREENDIMENTOS | O5: R01 - Edileni Silva | P5: 45608
A6: Unidade Construtiva | B6: Célula Construtiva | C6: Etapa | D6: Subetapa | E6: Serviço | G6: GERENCIAMENTO EXECUTIVO
A7: 0 | B7: 0 | C7: 0 | D7: 0 | E7: 0 | G7: Atalho | H7: NIVEL | I7: Item | J7: Descrição | K7: Unidade | L7: Quant. | M7: Preço un | N7: Total | O7: Considerações | P7: Situação
A8: =IF($H8="UNIDADE CONSTRUTIVA",OFFSET(A8,-1,0)+1,LARGE(A$3:A5,1)) -> 1 | B8: =IF(H8="UNIDADE CONSTRUTIVA",0,IF(H8="CÉLULA CONSTRUTIVA",OFFSET(B8,-1,0)+1,OFFSET(B8,-1,0))) -> 0 | C8: =IF(H8="CÉLULA CONSTRUTIVA",0,IF(H8="ETAPA",OFFSET(C8,-1,0)+1,OFFSET(C8,-1,0))) -> 0 | D8: =IF(H8="ETAPA",0,IF(H8="SUBETAPA",OFFSET(D8,-1,0)+1,OFFSET(D8,-1,0))) -> 0 | E8: =IF(H8="Subetapa",0,IF(H8="serviço",OFFSET(E8,-1,0)+1,OFFSET(E8,-1,0))) -> 0 | H8: UNIDADE CONSTRUTIVA | I8: =IF(H8="Unidade Construtiva",TEXT(A8,"00"),IF(H8="Célula Construtiva",TEXT(B8,"00"),IF(H8="Etapa",CONCATENATE(TEXT(B8,"00"),".",TEXT(C8,"000")),IF(H8="Subetapa",CONCATENATE(TEXT(B8,"00"),".",TEXT(C8,"000"),".",TEXT(D8,"000")),IF(H8="Serviço",CONCATENATE(TEXT(B8,"00"),".",TEXT(C8,"000"),".",TEXT(D8,"000"),".",TEXT(E8,"000")),""))))) -> 01 | J8: CUSTOS INDIRETOS | N8: =SUM(N9,N13,N47,N78,N111,N175) -> 5309214
H9: CÉLULA CONSTRUTIVA | I9: 01 | J9: AQUISIÇÃO DO TERRENO | N9: =N10 -> 450000
H10: ETAPA | I10: 01 | J10: AQUISIÇÃO DO TERRENO | N10: =N11 -> 450000
H11: SUBETAPA | I11: 01.000.001 | J11: Aquisição do terreno | N11: =N12 -> 450000
H12: SERVIÇO | I12: 01.000.001.001 | J12: Aquisição do terreno | K12: vb | L12: 1 | M12: 450000 | N12: =M12*L12 -> 450000 | O12: Custo atualizado conforme solicitação do dia 27/10/2024 | P12: Lançado ERP
H13: CÉLULA CONSTRUTIVA | I13: 02 | J13: ESTUDOS, PROJETOS E CONSULTORIAS | N13: =SUM(N14,N25,N35,N42) -> 598398.03
H14: ETAPA | I14: 02.001 | J14: ESTUDOS, PROJETOS E CONSULTORIAS | N14: =SUM(N15,N17,N19,N21,N23) -> 23178.03
H15: SUBETAPA | I15: 02.001.001 | J15: Memorial descritivo | N15: =SUM(N16) -> 4134.83
H16: SERVIÇO | I16: 02.001.001.001 | J16: Memorial descritivo | K16: vb | L16: 1 | M16: =VLOOKUP(J16,Preços!$C$7:$F$498,4,FALSE) -> 4134.83 | N16: =M16*L16 -> 4134.83 | O16: Custo conforme respostas informadas no formulário de custos indiretos. | P16: Lançado ERP
H17: SUBETAPA | I17: 02.001.002 | J17: Levantamento Topográfico | N17: =SUM(N18) -> 1224.76
H18: SERVIÇO | I18: 02.001.002.001 | J18: Levantamento Topográfico | K18: vb | L18: 1 | M18: =VLOOKUP(J18,Preços!$C$7:$F$498,4,FALSE) -> 1224.76 | N18: =M18*L18 -> 1224.76 | O18: Custo conforme respostas informadas no formulário de custos indiretos. | P18: Lançado ERP
H19: SUBETAPA | I19: 02.001.003 | J19: Estudo ambiental | N19: =SUM(N20) -> 4318.44
H20: SERVIÇO | I20: 02.001.003.001 | J20: Estudo ambiental | K20: vb | L20: 1 | M20: =VLOOKUP(J20,Preços!$C$7:$F$498,4,FALSE) -> 4318.44 | N20: =M20*L20 -> 4318.44 | O20: Custo conforme respostas informadas no formulário de custos indiretos. | P20: Lançado ERP
H21: SUBETAPA | I21: 02.001.004 | J21: Sondagem do terreno | N21: =SUM(N22) -> 9500
H22: SERVIÇO | I22: 02.001.004.001 | J22: Sondagem do terreno | K22: vb | L22: 1 | M22: =VLOOKUP(J22,Preços!$C$7:$F$498,4,FALSE) -> 9500 | N22: =M22*L22 -> 9500 | O22: Custo conforme respostas informadas no formulário de custos indiretos. | P22: Lançado ERP
H23: SUBETAPA | I23: 02.001.005 | J23: Projeto de canteiro | N23: =SUM(N24) -> 4000
H24: SERVIÇO | I24: 02.001.005.001 | J24: Projeto de canteiro | K24: vb | L24: 1 | M24: =VLOOKUP(J24,Preços!$C$7:$F$498,4,FALSE) -> 4000 | N24: =M24*L24 -> 4000 | O24: Custo conforme respostas informadas no formulário de custos indiretos. | P24: Lançado ERP
H25: ETAPA | I25: 02.002 | J25: PROJETOS | N25: =SUM(N26,N28,N30,N32) -> 348000
H26: SUBETAPA | I26: 02.002.001 | J26: Legalização de incorporação | N26: =SUM(N27) -> 33000
H27: SERVIÇO | I27: 02.002.000.001 | J27: Legalização de incorporação | K27: vb | L27: 1 | M27: =VLOOKUP(J27,Preços!$C$7:$F$498,4,FALSE) -> 33000 | N27: =M27*L27 -> 33000 | O27: Custo conforme respostas informadas no formulário de custos indiretos. | P27: Lançado ERP
H28: SUBETAPA | I28: 02.002.001 | J28: Projetos Integrados | N28: =SUM(N29) -> 230000
H29: SERVIÇO | I29: 02.002.001.001 | J29: Projeto Arquitetônico legal | K29: vb | L29: 1 | M29: 230000 | N29: =M29*L29 -> 230000 | O29: Custo atualizado conforme solicitação do dia 27/10/2024 | P29: Lançado ERP
H30: SUBETAPA | I30: 02.002.002 | J30: Projeto de interiores | N30: =SUM(N31) -> 25000
H31: SERVIÇO | I31: 02.002.002.001 | J31: Projeto de interiores | K31: vb | L31: 1 | M31: =VLOOKUP(J31,Preços!$C$7:$F$498,4,FALSE) -> 25000 | N31: =M31*L31 -> 25000 | O31: Custo conforme respostas informadas no formulário de custos indiretos. | P31: Lançado ERP
H32: SUBETAPA | I32: 02.002.003 | J32: Projetos Estrutural e Fundações | N32: =SUM(N33:N34) -> 60000
H33: SERVIÇO | I33: 02.002.003.001 | J33: Projeto Fundações | K33: vb | L33: 1 | M33: =VLOOKUP(J33,Preços!$C$7:$F$498,4,FALSE) -> 8000 | N33: =M33*L33 -> 8000 | O33: Custo conforme respostas informadas no formulário de custos indiretos. | P33: Lançado ERP
H34: SERVIÇO | I34: 02.002.003.002 | J34: Projeto Estrutural | K34: vb | L34: 1 | M34: =VLOOKUP(J34,Preços!$C$7:$F$498,4,FALSE) -> 52000 | N34: =M34*L34 -> 52000 | O34: Custo conforme respostas informadas no formulário de custos indiretos. | P34: Lançado ERP
H35: ETAPA | I35: 02.003 | J35: CONSULTORIAS | N35: =SUM(N36,N38) -> 160000
H36: SUBETAPA | I36: 02.003.001 | J36: Orçamento e planejamento | N36: =SUM(N37) -> 40000
H37: SERVIÇO | I37: 02.003.001.001 | J37: Orçamento e planejamento | K37: vb | L37: 1 | M37: =VLOOKUP(J37,Preços!$C$7:$F$498,4,FALSE) -> 40000 | N37: =M37*L37 -> 40000 | O37: Custo conforme respostas informadas no formulário de custos indiretos. | P37: Lançado ERP
H38: SUBETAPA | I38: 02.003.002 | J38: Softwares | N38: =SUM(N39:N41) -> 120000
H39: SERVIÇO | I39: 02.003.002.001 | J39: Assinatura Ampli | K39: vb | L39: 1 | M39: 33887.04 | N39: =M39*L39 -> 33887.04 | O39: Custo atualizado conforme solicitação do dia 27/10/2024 | P39: Lançado ERP
H40: SERVIÇO | I40: 02.003.002.002 | J40: Assinatura Prevision | K40: vb | L40: 1 | M40: 71760.8 | N40: =M40*L40 -> 71760.8 | O40: Custo atualizado conforme solicitação do dia 27/10/2024 | P40: Lançado ERP
H41: SERVIÇO | I41: 02.003.002.003 | J41: Assinatura Nuvem de Dados | K41: vb | L41: 1 | M41: 14352.16 | N41: =M41*L41 -> 14352.16 | O41: Custo atualizado conforme solicitação do dia 27/10/2024 | P41: Lançado ERP
H42: ETAPA | I42: 02.004 | J42: ENSAIOS E LAUDOS | N42: =SUM(N43,N45) -> 67220
H43: SUBETAPA | I43: 02.004.001 | J43: Controle Tecnologico de Concreto | N43: =SUM(N44) -> 64460
...

Sheet MO Infra
L6: =(92273.31+12957.46+45908+7494) -> 158632.77 | M6: =L6/(259.53*2+288.02) -> 196.55148

Sheet Composições
B1: Projeto | C1: =ORÇAMENTO!I4 -> SENSE106
B2: Empresa | C2: =ORÇAMENTO!I5 -> HOLZE EMPREENDIMENTOS
B3: Revisão | C3: =ORÇAMENTO!O5 -> R01 - Edileni Silva
A4: COMPOSIÇÕES
A6: PILARES
A7: Montagem | E7: Fabricação | G7: =13/2 -> 6.5 | H7: 1x | I7: 6x | J7: 10x
A8: Arame | B8: kg | C8: 0.0357 | E8: Prego 17x21 | F8: kg | G8: 0.215 | H8: =G8/$G$7 -> 0.033076923 | I8: =H8*6 -> 0.19846154 | J8: =H8*10 -> 0.33076923
A9: Desmoldante | B9: l | C9: 0.017 | E9: Pontalete | F9: m3 | G9: 0.0338 | H9: =G9/$G$7 -> 0.0052 | I9: =H9*6 -> 0.0312 | J9: =H9*10 -> 0.052
A10: Prego 17x21 | B10: kg | C10: 0.027 | E10: Compensado | F10: um | G10: 0.552 | H10: =G10/$G$7 -> 0.084923077 | I10: =H10*6 -> 0.50953846 | J10: =H10*10 -> 0.84923077
E11: Sarrafo | F11: m3 | G11: 0.017 | H11: =G11/$G$7 -> 0.0026153846 | I11: =H11*6 -> 0.015692308 | J11: =H11*10 -> 0.026153846
A13: Fabricação+montagem
A14: Arame | B14: kg | C14: =C8 -> 0.0357 | D14: 12.05
A15: Desmoldante | B15: l | C15: =C9 -> 0.017 | D15: 7.7
A16: Prego 17x21 | B16: kg | C16: =C10+J8 -> 0.35776923 | D16: 17.19
A17: Pontalete | B17: m | C17: =J9/(0.025*0.1) -> 20.8 | D17: =1100*(0.1*0.025) -> 2.75
A18: Compensado | B18: um | C18: =J10 -> 0.84923077 | D18: 102.89
A19: Sarrafo | B19: m | C19: =J11/(0.07*0.07) -> 5.3375196 | D19: =1100*(0.07*0.07) -> 5.39
D20: =SUMPRODUCT(C14:C19,D14:D19) -> 180.05772
A23: VIGAS
A24: Montagem | E24: Fabricação | G24: =13/2 -> 6.5 | H24: 1x | I24: 6x | J24: 10x
A25: Arame | B25: kg | C25: 0.0357 | E25: Prego 17x21 | F25: kg | G25: 0.159 | H25: =G25/$G$7 -> 0.024461538 | I25: =H25*6 -> 0.14676923 | J25: =H25*10 -> 0.24461538
A26: Desmoldante | B26: l | C26: 0.017 | E26: Pontalete | F26: m3 | G26: 0.0009 | H26: =G26/$G$7 -> 0.00013846154 | I26: =H26*6 -> 0.00083076923 | J26: =H26*10 -> 0.0013846154
A27: Prego 17x21 | B27: kg | C27: 0.049 | E27: Compensado | F27: um | G27: 0.4736 | H27: =G27/$G$7 -> 0.072861538 | I27: =H27*6 -> 0.43716923 | J27: =H27*10 -> 0.72861538
A28: Pontalete | B28: m3 | C28: 0.00164 | E28: Sarrafo | F28: m3 | G28: 0.0145 | H28: =G28/$G$7 -> 0.0022307692 | I28: =H28*6 -> 0.013384615 | J28: =H28*10 -> 0.022307692
A30: Fabricação+montagem
A31: Arame | B31: kg | C31: =C25 -> 0.0357 | D31: 12.05
A32: Desmoldante | B32: l | C32: =C26 -> 0.017 | D32: 7.7
A33: Prego 17x21 | B33: kg | C33: =C27+J25 -> 0.29361538 | D33: 17.19
A34: Pontalete | B34: m | C34: =(J26+C28)/(0.025*0.1) -> 1.2098462 | D34: =1100*(0.1*0.025) -> 2.75
A35: Compensado | B35: um | C35: =J27 -> 0.72861538 | D35: 102.89
A36: Sarrafo | B36: m | C36: =J28/(0.07*0.07) -> 4.5525903 | D36: =1100*(0.07*0.07) -> 5.39
D37: =SUMPRODUCT(C31:C36,D31:D36) -> 108.44111
A40: RAMPAS
A41: Montagem
A42: Arame | B42: kg | C42: 0.0357
A43: Desmoldante | B43: l | C43: 0.017
A44: Prego 17x21 | B44: kg | C44: 0.049
A45: Pontalete | B45: m3 | C45: 0.00164
A47: Fabricação+montagem | D47: 1x | E47: 10x
A48: Arame | B48: kg | C48: =C42 -> 0.0357 | D48: =C48 -> 0.0357 | E48: =D48 -> 0.0357 | F48: 12.05
...

Sheet Preços
B1: Projeto | C1: =ORÇAMENTO!I4 -> SENSE106
B2: Empresa | C2: =ORÇAMENTO!I5 -> HOLZE EMPREENDIMENTOS
B3: Revisão | C3: =ORÇAMENTO!O5 -> R01 - Edileni Silva
A4: SERVIÇOS
B6: Código | C6: Descrição | E6: Unidade | F6: Total
B7: 2149 | C7: Levantamento Topográfico | E7: vb | F7: 1224.76
B8: 2155 | C8: Projeto Arquitetônico legal | E8: vb | F8: 230000
B9: 2158 | C9: Projeto Estrutural | E9: vb | F9: 52000
B10: 2164 | C10: Projeto Fundações | E10: vb | F10: 8000
B11: 2168 | C11: Comunicação Visual | E11: vb | F11: 86965.7
B12: 2384 | C12: Escavação Mecânica Vala Exceto Rocha até 1.5m | E12: m3 | F12: 37.44
B13: 2413 | C13: Contrapiso comum, aderido, espessura de 6cm, com argamassa usinada | E13: m2 | F13: 26.73
B14: 2414 | C14: Contrapiso comum, aderido, espessura de 8cm, com argamassa usinada | E14: m2 | F14: 35.64
B15: 2417 | C15: Contrapiso comum, aderido, espessura de 5cm, com argamassa usinada | E15: m2 | F15: 22.275
B16: 2523 | C16: Forma Compensado Plástica 17mm Reaproveitamento 7x | E16: m2 | F16: 195031.93
B17: 2558 | C17: Armação aço CA-50 ø 6,3mm para supraestrutura (corte e dobra em indústria) | E17: kg | F17: 7.5498
B18: 2559 | C18: Armação aço CA-50 ø 8mm para supraestrutura (corte e dobra em indústria) | E18: kg | F18: 7.2105
... B443: 80138 | C443: Aquisição do terreno | E443: vb | F443: 450000
M467: =VLOOKUP(J467,Preços!$C$6:$E$1205,4,FALSE) -> #N/A

Sheet Projeção torre
B1: Projeto | C1: =ORÇAMENTO!I4 -> SENSE106
B2: Empresa | C2: =ORÇAMENTO!I5 -> HOLZE EMPREENDIMENTOS
B3: Revisão | C3: =ORÇAMENTO!O5 -> R01 - Edileni Silva
A4: PROJEÇÃO DA TORRE
E41: Área: | F41: 720.16 | G41: m²
E42: Perímetro | F42: =28*2+25.72*2 -> 107.44 | G42: m
E45: TÉRREO | F45: 622.81
E46: GARAGEM G2 | F46: 653.05
E47: GARAGEM G3 | F47: 653.05
E48: GARAGEM G4 | F48: 653.05
E49: LAZER | F49: 653.05
E50: TIPOS | F50: =269.69*20 -> 5393.8
E51: COBERTURA | F51: 269.69
E52: RES. SUPERIOR | F52: 67.76
E55: ÁREA CONSTRUÍDA | F55: =F45+F46+F47+F48+F49+F50+F52 -> 8696.57

Sheet Cotações
B1: Projeto | C1: =ORÇAMENTO!I4 -> SENSE106
B2: Empresa | C2: =ORÇAMENTO!I5 -> HOLZE EMPREENDIMENTOS
B3: Revisão | C3: R00 - Michelle Furlan - 06/02/24
A4: CONTROLE DE COTAÇÕES
A5: INFORMAÇÕES IMPORTANTES: CNPJ XXXX / XXXXX / Endereço da obra: XXXX
A6: Item | B6: Data | C6: Site | D6: Status | E6: E-mail

Sheet Estacas
B1: Projeto | C1: =ORÇAMENTO!I4 -> SENSE106
B2: Empresa | C2: =ORÇAMENTO!I5 -> HOLZE EMPREENDIMENTOS
B3: Revisão | C3: R00 - Michelle Furlan -
A4: ESTACAS
A5: ITEM | B5: TIPO | C5: QUANT | D5: DIMENSÕES UNITÁRIAS | H5: TOTAL | I5: ESCAV | J5: BOTA-FORA | K5: CONCRETO | M5: TAXA AÇO
D6: C. Topo | E6: C. Apoio | F6: Ø peça | G6: H | M6: KG/M3
D7: m | E7: m | F7: m | G7: m | H7: m | I7: m3 | J7: m3 | K7: m3 | L7: TIPO
A8: 1091 - LOCAÇÃO DAS ESTACAS - R0.pdf // 1092 - LOCAÇÃO DAS ESTACAS - R0.pdf // 1093 - LOCAÇÃO DAS ESTACAS - R0.pdf // 1094 - LOCAÇÃO DAS ESTACAS - R0.pdf // 1095 - LOCAÇÃO DAS ESTACAS - R0.pdf // 1096 - LOCAÇÃO DAS ESTACAS - R0.pdf // 1097 - LOCAÇÃO DAS ESTACAS - R0.pdf // 1098 - LOCAÇÃO DAS ESTACAS - R0.pdf // 1099 - LOCAÇÃO DAS ESTACAS - R0.pdf // 1100 - LOCAÇÃO DAS ESTACAS - R0.pdf // 1101 - LOCAÇÃO DAS ESTACAS - R0.pdf // 1102 - LOCAÇÃO DAS ESTACAS - R0.pdf // 1103 - LOCAÇÃO DAS ESTACAS - R0.pdf // 1104 - LOCAÇÃO DAS ESTACAS - R0.pdf // 1105 - LOCAÇÃO DAS ESTACAS - R0.pdf // 1106 - LOCAÇÃO DAS ESTACAS - R0.pdf // 1107 - LOCAÇÃO DAS ESTACAS - R0.pdf // 1108 - LOCAÇÃO DAS ESTACAS - R0.pdf // 1109 - LOCAÇÃO DAS ESTACAS - R0.pdf // 1110 - LOCAÇÃO DAS ESTACAS - R0.pdf // 1111 - LOCAÇÃO DAS ESTACAS - R0.pdf // 1112 - LOCAÇÃO DAS ESTACAS - R0.pdf // 1113 - LOCAÇÃO DAS ESTACAS - R0.pdf // 1114 - LOCAÇÃO DAS ESTACAS - R0.pdf // 1115 - LOCAÇÃO DAS ESTACAS - R0.pdf // 1116 - LOCAÇÃO DAS ESTACAS - R0.pdf // 1117 - LOCAÇÃO DAS ESTACAS - R0.pdf // 1118 - LOCAÇÃO DAS ESTACAS - R0.pdf // 1119 - LOCAÇÃO DAS ESTACAS - R0.pdf // 1120 - LOCAÇÃO DAS ESTACAS - R0.pdf // 1121 - LOCAÇÃO DAS ESTACAS - R0.pdf // 1122 - LOCAÇÃO DAS ESTACAS - R0.pdf
A9: F1 | B9: Hélice diam 50 cm | C9: 1 | E9: 35 | F9: 0.5 | G9: =IF(C9="","",ROUNDUP((E9-D9),1)) -> 35 | H9: =IF(C9="","",C9*G9) -> 35 | I9: =IF(C9="","",PI()*((F9/2)^2)*H9) -> 6.8722339 | J9: =IF(C9="","",I9*1.3) -> 8.9339041 | K9: =IF(C9="","",I9) -> 6.8722339 | L9: 40 MPa | M9: =IF(C9="","",K9*$M$7) -> 0
A10: F2 | B10: Hélice diam 50 cm | C10: 1 | E10: 35 | F10: 0.5 | G10: =IF(C10="","",ROUNDUP((E10-D10),1)) -> 35 | H10: =IF(C10="","",C10*G10) -> 35 | I10: =IF(C10="","",PI()*((F10/2)^2)*H10) -> 6.8722339 | J10: =IF(C10="","",I10*1.3) -> 8.9339041 | K10: =IF(C10="","",I10) -> 6.8722339 | L10: 40 MPa | M10: =IF(C10="","",K10*$M$7) -> 0
A11: F3 | B11: Hélice diam 50 cm | C11: 1 | E11: 35 | F11: 0.5 | G11: =IF(C11="","",ROUNDUP((E11-D11),1)) -> 35 | H11: =IF(C11="","",C11*G11) -> 35 | I11: =IF(C11="","",PI()*((F11/2)^2)*H11) -> 6.8722339 | J11: =IF(C11="","",I11*1.3) -> 8.9339041 | K11: =IF(C11="","",I11) -> 6.8722339 | L11: 40 MPa | M11: =IF(C11="","",K11*$M$7) -> 0
A12: F4 | B12: Hélice diam 50 cm | C12: 1 | E12: 35 | F12: 0.5 | G12: =IF(C12="","",ROUNDUP((E12-D12),1)) -> 35 | H12: =IF(C12="","",C12*G12) -> 35 | I12: =IF(C12="","",PI()*((F12/2)^2)*H12) -> 6.8722339 | J12: =IF(C12="","",I12*1.3) -> 8.9339041 | K12: =IF(C12="","",I12) -> 6.8722339 | L12: 40 MPa | M12: =IF(C12="","",K12*$M$7) -> 0
A13: F5 | B13: Hélice diam 50 cm | C13: 1 | E13: 35 | F13: 0.5 | G13: =IF(C13="","",ROUNDUP((E13-D13),1)) -> 35 | H13: =IF(C13="","",C13*G13) -> 35 | I13: =IF(C13="","",PI()*((F13/2)^2)*H13) -> 6.8722339 | J13: =IF(C13="","",I13*1.3) -> 8.9339041 | K13: =IF(C13="","",I13) -> 6.8722339 | L13: 40 MPa | M13: =IF(C13="","",K13*$M$7) -> 0
A14: F6 | B14: Hélice diam 50 cm | C14: 1 | E14: 35 | F14: 0.5 | G14: =IF(C14="","",ROUNDUP((E14-D14),1)) -> 35 | H14: =IF(C14="","",C14*G14) -> 35 | I14: =IF(C14="","",PI()*((F14/2)^2)*H14) -> 6.8722339 | J14: =IF(C14="","",I14*1.3) -> 8.9339041 | K14: =IF(C14="","",I14) -> 6.8722339 | L14: 40 MPa | M14: =IF(C14="","",K14*$M$7) -> 0
A15: F7 | B15: Hélice diam 50 cm | C15: 1 | E15: 35 | F15: 0.5 | G15: =IF(C15="","",ROUNDUP((E15-D15),1)) -> 35 | H15: =IF(C15="","",C15*G15) -> 35 | I15: =IF(C15="","",PI()*((F15/2)^2)*H15) -> 6.8722339 | J15: =IF(C15="","",I15*1.3) -> 8.9339041 | K15: =IF(C15="","",I15) -> 6.8722339 | L15: 40 MPa | M15: =IF(C15="","",K15*$M$7) -> 0
A16: F8 | B16: Hélice diam 50 cm | C16: 1 | E16: 35 | F16: 0.5 | G16: =IF(C16="","",ROUNDUP((E16-D16),1)) -> 35 | H16: =IF(C16="","",C16*G16) -> 35 | I16: =IF(C16="","",PI()*((F16/2)^2)*H16) -> 6.8722339 | J16: =IF(C16="","",I16*1.3) -> 8.9339041 | K16: =IF(C16="","",I16) -> 6.8722339 | L16: 40 MPa | M16: =IF(C16="","",K16*$M$7) -> 0
A17: F9 | B17: Hélice diam 50 cm | C17: 1 | E17: 35 | F17: 0.5 | G17: =IF(C17="","",ROUNDUP((E17-D17),1)) -> 35 | H17: =IF(C17="","",C17*G17) -> 35 | I17: =IF(C17="","",PI()*((F17/2)^2)*H17) -> 6.8722339 | J17: =IF(C17="","",I17*1.3) -> 8.9339041 | K17: =IF(C17="","",I17) -> 6.8722339 | L17: 40 MPa | M17: =IF(C17="","",K17*$M$7) -> 0
A18: F10 | B18: Hélice diam 50 cm | C18: 1 | E18: 35 | F18: 0.5 | G18: =IF(C18="","",ROUNDUP((E18-D18),1)) -> 35 | H18: =IF(C18="","",C18*G18) -> 35 | I18: =IF(C18="","",PI()*((F18/2)^2)*H18) -> 6.8722339 | J18: =IF(C18="","",I18*1.3) -> 8.9339041 | K18: =IF(C18="","",I18) -> 6.8722339 | L18: 40 MPa | M18: =IF(C18="","",K18*$M$7) -> 0
A19: F11 | B19: Hélice diam 50 cm | C19: 1 | E19: 35 | F19: 0.5 | G19: =IF(C19="","",ROUNDUP((E19-D19),1)) -> 35 | H19: =IF(C19="","",C19*G19) -> 35 | I19: =IF(C19="","",PI()*((F19/2)^2)*H19) -> 6.8722339 | J19: =IF(C19="","",I19*1.3) -> 8.9339041 | K19: =IF(C19="","",I19) -> 6.8722339 | L19: 40 MPa | M19: =IF(C19="","",K19*$M$7) -> 0
A20: F12 | B20: Hélice diam 60 cm | C20: 1 | E20: 35 | F20: 0.6 | G20: =IF(C20="","",ROUNDUP((E20-D20),1)) -> 35 | H20: =IF(C20="","",C20*G20) -> 35 | I20: =IF(C20="","",PI()*((F20/2)^2)*H20) -> 9.8960169 | J20: =IF(C20="","",I20*1.3) -> 12.864822 | K20: =IF(C20="","",I20) -> 9.8960169 | L20: 40 MPa | M20: =IF(C20="","",K20*$M$7) -> 0
... A40: P26+P31 | B40: Hélice diam 60 cm | C40: 8 | E40: 35 | F40: 0.6 | G40: =IF(C40="","",ROUNDUP((E40-D40),1)) -> 35 | H40: =IF(C40="","",C40*G40) -> 280 | I40: =IF(C40="","",PI()*((F40/2)^2)*H40) -> 79.168135 | J40: =IF(C40="","",I40*1.3) -> 102.91858 | K40: =IF(C40="","",I40) -> 79.168135 | L40: 40 MPa | M40: =IF(C40="","",K40*$M$7) -> 0
G41: =IF(C41="","",ROUNDUP((E41-D41),1)) | H41: =IF(C41="","",C41*G41) | I41: =IF(C41="","",PI()*((F41/2)^2)*H41) | J41: =IF(C41="","",I41*1.3) | K41: =IF(C41="","",I41) | M41: =IF(C41="","",K41*$M$7)
A42: Prova de carga | F42: =IF(B42="","",VLOOKUP(B42,$F$44:$G$52,2,0)) | G42: =IF(C42="","",ROUNDUP((E42-D42),1)) | H42: =IF(C42="","",C42*G42) | I42: =IF(C42="","",PI()*((F42/2)^2)*H42) | J42: =IF(C42="","",I42*1.3) | K42: =IF(C42="","",I42) | M42: =IF(C42="","",K42*$M$7)
A43: TOTAL GERAL | B43: Arrasamento | C43: =SUM(C8:C42) -> 92 | H43: =SUM(H8:H42) -> 3220 | I43: =SUM(I$8:I42) -> 840.88654 | J43: =SUM(J$8:J42) -> 1093.1525 | K43: =SUM(K$8:K42) -> 840.88654 | M43: =SUM(M$8:M42) -> 0
A44: OBSERVAÇÕES: | F44: Hélice diam 35 cm | G44: 0.35 | H44: =SUMIF($B$8:$B$42,$F44,$H$8:$H$42) -> 0 | K44: =SUMIF($L$8:$L$42,$L44,$K$8:$K$42) -> 0 | L44: 20 MPa
F45: Hélice diam 40 cm | G45: 0.4 | H45: =SUMIF($B$8:$B$42,$F45,$H$8:$H$42) -> 0 | K45: =SUMIF($L$8:$L$42,$L45,$K$8:$K$42) -> 0 | L45: 25 MPa
F46: Hélice diam 50 cm | G46: 0.5 | H46: =SUMIF($B$8:$B$42,$F46,$H$8:$H$42) -> 805 | K46: =SUMIF($L$8:$L$42,$L46,$K$8:$K$42) -> 0 | L46: 30 MPa
F47: Hélice diam 60 cm | G47: 0.6 | H47: =SUMIF($B$8:$B$42,$F47,$H$8:$H$42) -> 2415 | K47: =SUMIF($L$8:$L$42,$L47,$K$8:$K$42) -> 0 | L47: 35 MPa
F48: Hélice diam 70 cm | G48: 0.7 | H48: =SUMIF($B$8:$B$42,$F48,$H$8:$H$42) -> 0 | K48: =SUMIF($L$8:$L$42,$L48,$K$8:$K$42) -> 840.88654 | L48: 40 MPa
F49: Hélice diam 80 cm | G49: 0.8 | H49: =SUMIF($B$8:$B$42,$F49,$H$8:$H$42) -> 0 | K49: =SUMIF($L$8:$L$42,$L49,$K$8:$K$42) -> 0 | L49: .... MPa
F50: Hélice diam 90 cm | G50: 0.9 | H50: =SUMIF($B$8:$B$42,$F50,$H$8:$H$42) -> 0 | K50: =SUMIF($L$8:$L$42,$L50,$K$8:$K$42) -> 0 | L50: .... MPa
F51: E.P. Hélice diam 70 cm | G51: 0.7 | H51: =SUMIF($B$8:$B$42,$F51,$H$8:$H$42) -> 0 | K51: =SUMIF($L$8:$L$42,$L51,$K$8:$K$42) -> 0 | L51: .... MPa
F52: - | H52: =SUMIF($B$8:$B$42,$F52,$H$8:$H$42) -> 0 | K52: =SUMIF($L$8:$L$42,$L52,$K$8:$K$42) -> 0 | L52: .... MPa
A134: CUSTO
A135: *proposta salva no drive

Sheet Arm. Estacas
B1: Projeto | C1: =ORÇAMENTO!I4 -> SENSE106
B2: Empresa | C2: =ORÇAMENTO!I5 -> HOLZE EMPREENDIMENTOS
B3: Revisão | C3: R00 - Michelle Furlan - 15/05
A4: ARMAÇÃO ESTACAS
A5: ITEM | C5: QUANT | D5: QUANTIDADE POR ITEM CA-50 - m | K5: CA-60 - m
D6: 6.3 | E6: 8 | F6: 10 | G6: 12.5 | H6: 16 | I6: 20 | J6: 25 | K6: 5 | L6: 0 | M6: 0 | N6: 0 | O6: 0
A7: =Estacas!$A$8 -> 1091 - LOCAÇÃO DAS ESTACAS - R0.pdf // 1092 - LOCAÇÃO DAS ESTACAS - R0.pdf // 1093 - LOCAÇÃO DAS ESTACAS - R0.pdf // 1094 - LOCAÇÃO DAS ESTACAS - R0.pdf // 1095 - LOCAÇÃO DAS ESTACAS - R0.pdf // 1096 - LOCAÇÃO DAS ESTACAS - R0.pdf // 1097 - LOCAÇÃO DAS ESTACAS - R0.pdf // 1098 - LOCAÇÃO DAS ESTACAS - R0.pdf // 1099 - LOCAÇÃO DAS ESTACAS - R0.pdf // 1100 - LOCAÇÃO DAS ESTACAS - R0.pdf // 1101 - LOCAÇÃO DAS ESTACAS - R0.pdf // 1102 - LOCAÇÃO DAS ESTACAS - R0.pdf // 1103 - LOCAÇÃO DAS ESTACAS - R0.pdf // 1104 - LOCAÇÃO DAS ESTACAS - R0.pdf // 1105 - LOCAÇÃO DAS ESTACAS - R0.pdf // 1106 - LOCAÇÃO DAS ESTACAS - R0.pdf // 1107 - LOCAÇÃO DAS ESTACAS - R0.pdf // 1108 - LOCAÇÃO DAS ESTACAS - R0.pdf // 1109 - LOCAÇÃO DAS ESTACAS - R0.pdf // 1110 - LOCAÇÃO DAS ESTACAS - R0.pdf // 1111 - LOCAÇÃO DAS ESTACAS - R0.pdf // 1112 - LOCAÇÃO DAS ESTACAS - R0.pdf // 1113 - LOCAÇÃO DAS ESTACAS - R0.pdf // 1114 - LOCAÇÃO DAS ESTACAS - R0.pdf // 1115 - LOCAÇÃO DAS ESTACAS - R0.pdf // 1116 - LOCAÇÃO DAS ESTACAS - R0.pdf // 1117 - LOCAÇÃO DAS ESTACAS - R0.pdf // 1118 - LOCAÇÃO DAS ESTACAS - R0.pdf // 1119 - LOCAÇÃO DAS ESTACAS - R0.pdf // 1120 - LOCAÇÃO DAS ESTACAS - R0.pdf // 1121 - LOCAÇÃO DAS ESTACAS - R0.pdf // 1122 - LOCAÇÃO DAS ESTACAS - R0.pdf
A8: F1 | C8: 1 | D8: 8.575 | H8: 47.31
A9: F2 | C9: 1 | D9: 8.575 | H9: 47.31
A10: F3 | C10: 1 | D10: 8.575 | H10: 47.31
A11: F4 | C11: 1 | D11: 8.575 | H11: 47.31
A12: F5 | C12: 1 | D12: 8.575 | H12: 47.31
A13: F6 | C13: 1 | D13: 8.575 | H13: 47.31
A14: F7 | C14: 1 | D14: 8.575 | H14: 47.31
A15: F8 | C15: 1 | D15: 8.575 | H15: 47.31
A16: F9 | C16: 1 | D16: 8.575 | H16: 47.31
A17: F10 | C17: 1 | D17: 8.575 | H17: 47.31
A18: F11 | C18: 1 | D18: 10.78 | H18: 75.696
A19: F12 | C19: 1 | D19: 8.575 | H19: 47.31
... A39: P26+P31 | C39: 8 | D39: 10.78 | H39: 75.696
A40: PROJETO | D40: 1052 | H40: 6905.49
B41: TOTAL - M | C41: =SUM(D41:O41) -> 7922.695 | D41: =SUMPRODUCT(D7:D40,$C7:$C40) -> 1031.205 | E41: =SUMPRODUCT(E7:E40,$C7:$C40) -> 0 | F41: =SUMPRODUCT(F7:F40,$C7:$C40) -> 0 | G41: =SUMPRODUCT(G7:G40,$C7:$C40) -> 0 | H41: =SUMPRODUCT(H7:H40,$C7:$C40) -> 6891.49 | I41: =SUMPRODUCT(I7:I40,$C7:$C40) -> 0 | J41: =SUMPRODUCT(J7:J40,$C7:$C40) -> 0 | K41: =SUMPRODUCT(K7:K40,$C7:$C40) -> 0 | ... O41: =SUMPRODUCT(O7:O40,$C7:$C40) -> 0
B42: PESO kg/m | D42: 1 | E42: 1 | F42: 1 | G42: 1 | H42: 1 | I42: 1 | J42: 1 | K42: 1 | L42: 1 | M42: 1 | N42: 1 | O42: 1
B43: TOTAL - kg | C43: =SUM(D43:O43) -> 7922.695 | D43: =D42*D41 -> 1031.205 | E43: =E42*E41 -> 0 | F43: =F42*F41 -> 0 | G43: =G42*G41 -> 0 | H43: =H42*H41 -> 6891.49 | I43: =I42*I41 -> 0 | J43: =J42*J41 -> 0 | K43: =K42*K41 -> 0 | ... O43: =O42*O41 -> 0
A44: OBSERVAÇÕES: | D44: =1-D41/D40 -> 0.01976711 | E44: =IF(D44<10%,"Usar valor de projeto","Confirmar com cliente") -> Usar valor de projeto | H44: =1-H41/H40 -> 0.0020273724 | I44: =IF(H44<10%,"Usar valor de projeto","Confirmar com cliente") -> Usar valor de projeto
A46: TABELA DE AÇO
A47: CA-50 | D47: CA-60
A48: Ø - mm | B48: kg/m | C48: pol | D48: Ø - mm | E48: kg/m
A49: 6.3 | B49: 0.245 | C49: 1/4" | D49: 3.4 | E49: 0.079
A50: 8 | B50: 0.395 | C50: 5/16" | D50: 4.2 | E50: 0.109
A51: 10 | B51: 0.617 | C51: 3/8" | D51: 5 | E51: 0.154
A52: 12.5 | B52: 0.963 | C52: 1/2" | D52: 6 | E52: 0.222
A53: 16 | B53: 1.578 | C53: 5/8" | D53: 7 | E53: 0.302
A54: 20 | B54: 2.466 | C54: 3/4" | D54: 8 | E54: 0.395
A55: 25 | B55: 3.853 | C55: 1" | D55: 9.5 | E55: 0.558
A56: 32 | B56: 6.313 | C56: 1 1/4" | D56: 0
A57: 40 | B57: 9.865 | C57: 1 5/8" | D57: 0

Sheet Duto&Cisterna
D1: Projeto | E1: =ORÇAMENTO!I4 -> SENSE106
D2: Empresa | E2: =ORÇAMENTO!I5 -> HOLZE EMPREENDIMENTOS
D3: Revisão | E3: R00 - Michelle Furlan -
A4: DUTO E CISTERNA
A5: PROJETO:
A6: CÓDIGO DO RESERVATÓRIO | B6: NÚMERO DE REPETIÇÕES | C6: COMPRIMENTO DO RESERVATÓRIO | D6: LARGURA DO RESERVATÓRIO | E6: ESPESSURA DE CONCRETO | F6: ALTURA DO RESERVATÓRIO | G6: ALTURA INTERNA DO RESERVATÓRIO | H6: COMPRIMENTO INTERNO DO RESERVATÓRIO | I6: LARGURA INTERNA DO RESERVATÓRIO | J6: ESPESSURA DE LASTRO PARA O RESERVATÓRIO | K6: ESPAÇAMENTO LATERAL PARA ESCAVAÇÃO | L6: FORMA DO RESERVATÓRIO | M6: VOLUME DE CONCRETO | N6: VOLUME DE ESCAVAÇÃO | O6: VOLUME DE REATERRO | P6: VOLUME DE BOTA-FORA | Q6: APILOAMENTO DE VALA | R6: VOLUME DE LASTRO
A7: COD. | B7: R | C7: L | D7: B | E7: e.C. | F7: H | G7: h | H7: l | I7: b | J7: e.L. | K7: K | L7: F | M7: C | N7: VE | O7: VA | P7: VB | Q7: AP | R7: VM
B8: UD | C8: m | D8: m | E8: m | F8: m | G8: m | H8: m | I8: m | J8: m | K8: m | L8: m2 | M8: m3 | N8: m3 | O8: m3 | P8: m3 | Q8: m2 | R8: m3
A9: CISTERNA | B9: 1 | C9: 5.1 | D9: 3.2 | E9: 0.2 | F9: 3 | G9: =F9-E9 -> 2.8 | H9: =C9-E9*2 -> 4.7 | I9: =D9-E9*2 -> 2.8 | J9: 0.05 | K9: =G9 -> 2.8 | L9: =(C9*F9*2+D9*F9*2+I9*G9*2+H9*G9*2)*B9 -> 91.8 | M9: =C9*D9*F9-G9*H9*I9 -> 12.112 | N9: =(C9+K9)*(D9+K9)*(F9+J9)*B9 -> 144.57 | O9: =N9-C9*D9*F9*B9 -> 95.61 | P9: =N9-O9 -> 48.96 | Q9: =C9*D9*B9 -> 16.32 | R9: =J9*Q9 -> 0.816
A10: TAMPA CISTERNA | B10: 1 | C10: 5.1 | D10: 3.2 | E10: 0.2 | F10: 0.2 | G10: =F10-E10 -> 0 | H10: =C10-E10*2 -> 4.7 | I10: =D10-E10*2 -> 2.8 | K10: =G10 -> 0 | L10: =(2*E10*D10+2*E10*C10+H10*I10)*B10 -> 16.48 | M10: =C10*D10*F10-G10*H10*I10 -> 3.264
A11: DUTO DE AR - TRECHO 1 | B11: 1 | C11: 23.35 | D11: 2.35 | E11: 0.15 | F11: 2.2 | G11: =F11-E11 -> 2.05 | H11: =C11-E11*2 -> 23.05 | I11: =D11-E11*2 -> 2.05 | J11: 0.05 | K11: =G11 -> 2.05 | L11: =G11*(7.55)+F11+(8.13)+0.35*(2.35+2.05) -> 27.3475 | M11: 40 | N11: =(C11+K11)*(D11+K11)*(F11+J11)*B11 -> 251.46 | O11: =N11-C11*D11*G11*B11 -> 138.97138 | P11: =N11-O11 -> 112.48863 | Q11: =C11*D11*B11 -> 54.8725 | R11: =J11*Q11 -> 2.743625
A12: DUTO DE AR - TRECHO 2 | B12: 1 | C12: 2.9 | D12: 2.35 | E12: 0.15 | F12: 1.85 | G12: =F12-E12 -> 1.7 | H12: =C12-E12*2 -> 2.6 | I12: =D12-E12*2 -> 2.05 | J12: 0.05 | K12: =G12 -> 1.7 | L12: =F12*(46.247)+G12*(46.397) -> 164.43185 | N12: =(C12+K12)*(D12+K12)*(F12+J12)*B12 -> 35.397 | O12: =N12-C12*D12*G12*B12 -> 23.8115 | P12: =N12-O12 -> 11.5855 | Q12: =C12*D12*B12 -> 6.815 | R12: =J12*Q12 -> 0.34075
A13: DUTO DE AR - TRECHO 1.1 | B13: 1 | C13: 3.25 | D13: 1.3 | E13: 0.15 | F13: 2.2 | G13: =F13-E13 -> 2.05 | H13: =C13-E13*2 -> 2.95 | I13: =D13-E13*2 -> 1 | K13: =G13 -> 2.05 | L13: =F13*(7.8)+G13+(7.05) -> 26.26 | N13: =(C13+K13)*(D13+K13)*(F13+J13)*B13 -> 39.061 | O13: =N13-C13*D13*G13*B13 -> 30.39975 | P13: =N13-O13 -> 8.66125 | Q13: =I13*E13 -> 0.15 | R13: =J13*Q13 -> 0
A14: DUTO DE AR - TETO | L14: 57.63
A15: TOTAL | L15: =SUM(L9:L14) -> 383.94935 | M15: =SUM(M9:M14) -> 55.376 | N15: =SUM(N9:N14) -> 470.488 | O15: =SUM(O9:O14) -> 288.79263 | P15: =SUM(P9:P14) -> 181.69538 | Q15: =SUM(Q9:Q14) -> 78.1575 | R15: =SUM(R9:R14) -> 3.900375

Sheet Blocos
D1: Projeto | E1: =ORÇAMENTO!I4 -> SENSE106
D2: Empresa | E2: =ORÇAMENTO!I5 -> HOLZE EMPREENDIMENTOS
D3: Revisão | E3: R00 - Michelle Furlan -
A4: BLOCOS RETANGULARES
A5: ITEM | F5: QUANT | G5: DIMENSÕES UNITÁRIAS - m | J5: ADIÇÃO | K5: ADIÇÃO | L5: ESCAV | M5: APILOA | N5: REATER | O5: BOTA FORA | P5: LASTRO | Q5: FORMA | R5: FORMA (PROJETISTA) | S5: CONCRETO | T5: CONCRETO (PROJETISTA) | U5: TIPO | W5: RESUMO - CONCRETO
G6: LARGURA | H6: COMPR | I6: ALTURA | J6: LARGURA | K6: ALTURA | P6: Concreto (m3)
G7: A | H7: C | I7: B | J7: m | K7: m | L7: m3 | M7: m2 | N7: m3 | O7: m3 | P7: 0.05 | Q7: m2 | R7: m2 | S7: m3 | T7: m3 | W7: m3 | X7: TIPO
A8: Sense - Blocos de Fundação.dwg | W8: =SUMIF($U$8:$U$33,$X8,$S$8:$S$33)+SUMIF($U$51:$U$57,$X8,$S$51:$S$57) -> 0 | X8: 25 MPa
A9: BF1 | F9: 1 | G9: 0.9 | H9: 0.9 | I9: 0.8 | J9: =IF(I9<=1,0.6,I9) -> 0.6 | L9: =(G9+J9)*(I9+K9+$P$7)*(H9+J9)*F9 -> 1.9125 | M9: =(G9)*(H9)*F9 -> 0.81 | N9: =+L9-S9 -> 1.2645 | O9: =(L9-N9)*1.3 -> 0.8424 | P9: =M9*$P$7 -> 0.0405 | Q9: =(2*G9+H9*2)*I9*F9 -> 2.88 | R9: 2.88 | S9: =G9*I9*H9*F9 -> 0.648 | T9: 0.65 | U9: 40 MPa | W9: =SUMIF($U$8:$U$33,$X9,$S$8:$S$33)+SUMIF($U$51:$U$57,$X9,$S$51:$S$57) -> 0 | X9: 30 MPa
A10: BF2 | F10: 1 | G10: 0.9 | H10: 0.9 | I10: 0.8 | J10: =IF(I10<=1,0.6,I10) -> 0.6 | L10: =(G10+J10)*(I10+K10+$P$7)*(H10+J10)*F10 -> 1.9125 | M10: =(G10)*(H10)*F10 -> 0.81 | N10: =+L10-S10 -> 1.2645 | O10: =(L10-N10)*1.3 -> 0.8424 | P10: =M10*$P$7 -> 0.0405 | Q10: =(2*G10+H10*2)*I10*F10 -> 2.88 | R10: 2.88 | S10: =G10*I10*H10*F10 -> 0.648 | T10: 0.65 | U10: 40 MPa | W10: =SUMIF($U$8:$U$33,$X10,$S$8:$S$33)+SUMIF($U$51:$U$57,$X10,$S$51:$S$57) -> 0 | X10: 35 MPa
A11: BF3 | F11: 1 | G11: 0.9 | H11: 0.9 | I11: 0.8 | J11: =IF(I11<=1,0.6,I11) -> 0.6 | L11: =(G11+J11)*(I11+K11+$P$7)*(H11+J11)*F11 -> 1.9125 | M11: =(G11)*(H11)*F11 -> 0.81 | N11: =+L11-S11 -> 1.2645 | O11: =(L11-N11)*1.3 -> 0.8424 | P11: =M11*$P$7 -> 0.0405 | Q11: =(2*G11+H11*2)*I11*F11 -> 2.88 | R11: 2.88 | S11: =G11*I11*H11*F11 -> 0.648 | T11: 0.65 | U11: 40 MPa | W11: =SUMIF($U$8:$U$33,$X11,$S$8:$S$33)+SUMIF($U$51:$U$57,$X11,$S$51:$S$57) -> 230.13784 | X11: 40 MPa
A12: BF4 | F12: 1 | G12: 0.9 | H12: 0.9 | I12: 0.8 | J12: =IF(I12<=1,0.6,I12) -> 0.6 | L12: =(G12+J12)*(I12+K12+$P$7)*(H12+J12)*F12 -> 1.9125 | M12: =(G12)*(H12)*F12 -> 0.81 | N12: =+L12-S12 -> 1.2645 | O12: =(L12-N12)*1.3 -> 0.8424 | P12: =M12*$P$7 -> 0.0405 | Q12: =(2*G12+H12*2)*I12*F12 -> 2.88 | R12: 2.88 | S12: =G12*I12*H12*F12 -> 0.648 | T12: 0.65 | U12: 40 MPa | W12: =SUMIF($U$8:$U$33,$X12,$S$8:$S$33)+SUMIF($U$51:$U$57,$X12,$S$51:$S$57) -> 0
A13: BF5 | F13: 1 | G13: 0.9 | H13: 0.9 | I13: 0.8 | J13: =IF(I13<=1,0.6,I13) -> 0.6 | L13: =(G13+J13)*(I13+K13+$P$7)*(H13+J13)*F13 -> 1.9125 | M13: =(G13)*(H13)*F13 -> 0.81 | N13: =+L13-S13 -> 1.2645 | O13: =(L13-N13)*1.3 -> 0.8424 | P13: =M13*$P$7 -> 0.0405 | Q13: =(2*G13+H13*2)*I13*F13 -> 2.88 | R13: 2.88 | S13: =G13*I13*H13*F13 -> 0.648 | T13: 0.65 | U13: 40 MPa | W13: =SUMIF($U$8:$U$33,$X13,$S$8:$S$33)+SUMIF($U$51:$U$57,$X13,$S$51:$S$57) -> 0
A14: BF6 | F14: 1 | G14: 0.9 | H14: 0.9 | I14: 0.8 | J14: =IF(I14<=1,0.6,I14) -> 0.6 | L14: =(G14+J14)*(I14+K14+$P$7)*(H14+J14)*F14 -> 1.9125 | M14: =(G14)*(H14)*F14 -> 0.81 | N14: =+L14-S14 -> 1.2645 | O14: =(L14-N14)*1.3 -> 0.8424 | P14: =M14*$P$7 -> 0.0405 | Q14: =(2*G14+H14*2)*I14*F14 -> 2.88 | R14: 2.88 | S14: =G14*I14*H14*F14 -> 0.648 | T14: 0.65 | U14: 40 MPa | W14: =SUMIF($U$8:$U$33,$X14,$S$8:$S$33)+SUMIF($U$51:$U$57,$X14,$S$51:$S$57) -> 0
A15: BF7 | F15: 1 | G15: 0.9 | H15: 0.9 | I15: 0.8 | J15: =IF(I15<=1,0.6,I15) -> 0.6 | L15: =(G15+J15)*(I15+K15+$P$7)*(H15+J15)*F15 -> 1.9125 | M15: =(G15)*(H15)*F15 -> 0.81 | N15: =+L15-S15 -> 1.2645 | O15: =(L15-N15)*1.3 -> 0.8424 | P15: =M15*$P$7 -> 0.0405 | Q15: =(2*G15+H15*2)*I15*F15 -> 2.88 | R15: 2.88 | S15: =G15*I15*H15*F15 -> 0.648 | T15: 0.65 | U15: 40 MPa | W15: =SUM(W8:W14) -> 230.13784 | X15: =IF(S34=W15,"OK","Conferir") -> Conferir
A16: BF8 | F16: 1 | G16: 0.9 | H16: 0.9 | I16: 0.8 | J16: =IF(I16<=1,0.6,I16) -> 0.6 | L16: =(G16+J16)*(I16+K16+$P$7)*(H16+J16)*F16 -> 1.9125 | M16: =(G16)*(H16)*F16 -> 0.81 | N16: =+L16-S16 -> 1.2645 | O16: =(L16-N16)*1.3 -> 0.8424 | P16: =M16*$P$7 -> 0.0405 | Q16: =(2*G16+H16*2)*I16*F16 -> 2.88 | R16: 2.88 | S16: =G16*I16*H16*F16 -> 0.648 | T16: 0.65 | U16: 40 MPa
A17: BF9 | F17: 1 | G17: 0.9 | H17: 0.9 | I17: 0.8 | J17: =IF(I17<=1,0.6,I17) -> 0.6 | L17: =(G17+J17)*(I17+K17+$P$7)*(H17+J17)*F17 -> 1.9125 | M17: =(G17)*(H17)*F17 -> 0.81 | N17: =+L17-S17 -> 1.2645 | O17: =(L17-N17)*1.3 -> 0.8424 | P17: =M17*$P$7 -> 0.0405 | Q17: =(2*G17+H17*2)*I17*F17 -> 2.88 | R17: 2.88 | S17: =G17*I17*H17*F17 -> 0.648 | T17: 0.65 | U17: 40 MPa
A18: BF10 | F18: 1 | G18: 0.9 | H18: 0.9 | I18: 0.8 | J18: =IF(I18<=1,0.6,I18) -> 0.6 | L18: =(G18+J18)*(I18+K18+$P$7)*(H18+J18)*F18 -> 1.9125 | M18: =(G18)*(H18)*F18 -> 0.81 | N18: =+L18-S18 -> 1.2645 | O18: =(L18-N18)*1.3 -> 0.8424 | P18: =M18*$P$7 -> 0.0405 | Q18: =(2*G18+H18*2)*I18*F18 -> 2.88 | R18: 2.88 | S18: =G18*I18*H18*F18 -> 0.648 | T18: 0.65 | U18: 40 MPa
A19: BF11 | F19: 1 | G19: 1 | H19: 1 | I19: 1 | J19: =IF(I19<=1,0.6,I19) -> 0.6 | L19: =(G19+J19)*(I19+K19+$P$7)*(H19+J19)*F19 -> 2.688 | M19: =(G19)*(H19)*F19 -> 1 | N19: =+L19-S19 -> 1.688 | O19: =(L19-N19)*1.3 -> 1.3 | P19: =M19*$P$7 -> 0.05 | Q19: =(2*G19+H19*2)*I19*F19 -> 4 | R19: 4 | S19: =G19*I19*H19*F19 -> 1 | T19: 1 | U19: 40 MPa
A20: BF12 | F20: 1 | G20: 0.9 | H20: 0.9 | I20: 0.8 | J20: =IF(I20<=1,0.6,I20) -> 0.6 | L20: =(G20+J20)*(I20+K20+$P$7)*(H20+J20)*F20 -> 1.9125 | M20: =(G20)*(H20)*F20 -> 0.81 | N20: =+L20-S20 -> 1.2645 | O20: =(L20-N20)*1.3 -> 0.8424 | P20: =M20*$P$7 -> 0.0405 | Q20: =(2*G20+H20*2)*I20*F20 -> 2.88 | R20: 2.88 | S20: =G20*I20*H20*F20 -> 0.648 | T20: 0.65 | U20: 40 MPa
A21: BF13 | F21: 1 | G21: 0.9 | H21: 0.9 | I21: 0.8 | J21: =IF(I21<=1,0.6,I21) -> 0.6 | L21: =(G21+J21)*(I21+K21+$P$7)*(H21+J21)*F21 -> 1.9125 | M21: =(G21)*(H21)*F21 -> 0.81 | N21: =+L21-S21 -> 1.2645 | O21: =(L21-N21)*1.3 -> 0.8424 | P21: =M21*$P$7 -> 0.0405 | Q21: =(2*G21+H21*2)*I21*F21 -> 2.88 | R21: 2.88 | S21: =G21*I21*H21*F21 -> 0.648 | T21: 0.65 | U21: 40 MPa
A22: BF14 | F22: 1 | G22: 0.9 | H22: 0.9 | I22: 0.8 | J22: =IF(I22<=1,0.6,I22) -> 0.6 | L22: =(G22+J22)*(I22+K22+$P$7)*(H22+J22)*F22 -> 1.9125 | M22: =(G22)*(H22)*F22 -> 0.81 | N22: =+L22-S22 -> 1.2645 | O22: =(L22-N22)*1.3 -> 0.8424 | P22: =M22*$P$7 -> 0.0405 | Q22: =(2*G22+H22*2)*I22*F22 -> 2.88 | R22: 2.88 | S22: =G22*I22*H22*F22 -> 0.648 | T22: 0.65 | U22: 40 MPa
A23: BF15 | F23: 1 | G23: 0.9 | H23: 0.9 | I23: 0.8 | J23: =IF(I23<=1,0.6,I23) -> 0.6 | L23: =(G23+J23)*(I23+K23+$P$7)*(H23+J23)*F23 -> 1.9125 | M23: =(G23)*(H23)*F23 -> 0.81 | N23: =+L23-S23 -> 1.2645 | O23: =(L23-N23)*1.3 -> 0.8424 | P23: =M23*$P$7 -> 0.0405 | Q23: =(2*G23+H23*2)*I23*F23 -> 2.88 | R23: 2.88 | S23: =G23*I23*H23*F23 -> 0.648 | T23: 0.65 | U23: 40 MPa
A24: BF16 | F24: 1 | G24: 0.9 | H24: 0.9 | I24: 0.8 | J24: =IF(I24<=1,0.6,I24) -> 0.6 | L24: =(G24+J24)*(I24+K24+$P$7)*(H24+J24)*F24 -> 1.9125 | M24: =(G24)*(H24)*F24 -> 0.81 | N24: =+L24-S24 -> 1.2645 | O24: =(L24-N24)*1.3 -> 0.8424 | P24: =M24*$P$7 -> 0.0405 | Q24: =(2*G24+H24*2)*I24*F24 -> 2.88 | R24: 2.88 | S24: =G24*I24*H24*F24 -> 0.648 | T24: 0.65 | U24: 40 MPa
A25: B8 | F25: 1 | G25: 2.65 | H25: 1 | I25: 1 | J25: =IF(I25<=1,0.6,I25) -> 0.6 | L25: =(G25+J25)*(I25+K25+$P$7)*(H25+J25)*F25 -> 5.46 | M25: =(G25)*(H25)*F25 -> 2.65 | N25: =+L25-S25 -> 2.81 | O25: =(L25-N25)*1.3 -> 3.445 | P25: =M25*$P$7 -> 0.1325 | Q25: =(2*G25+H25*2)*I25*F25 -> 7.3 | R25: 20.82 | S25: =G25*I25*H25*F25 -> 2.65 | T25: 12.97 | U25: 40 MPa
A26: B9 | F26: 1 | G26: 3.66 | H26: 2.095 | I26: 1.35 | J26: =IF(I26<=1,0.6,I26) -> 1.35 | L26: =(G26+J26)*(I26+K26+$P$7)*(H26+J26)*F26 -> 24.16323 | M26: =(G26)*(H26)*F26 -> 7.6677 | N26: =+L26-S26 -> 13.811835 | O26: =(L26-N26)*1.3 -> 13.456814 | P26: =M26*$P$7 -> 0.383385 | Q26: =(2*G26+H26*2)*I26*F26 -> 15.5385 | S26: =G26*I26*H26*F26 -> 10.351395 | U26: 40 MPa
A27: B10 | F27: 1 | G27: 4.118 | H27: 4.6 | I27: 1.8 | J27: =IF(I27<=1,0.6,I27) -> 1.8 | L27: =(G27+J27)*(I27+K27+$P$7)*(H27+J27)*F27 -> 70.06912 | M27: =(G27)*(H27)*F27 -> 18.9428 | N27: =+L27-S27 -> 35.97208 | O27: =(L27-N27)*1.3 -> 44.326152 | P27: =M27*$P$7 -> 0.94714 | Q27: =(2*G27+H27*2)*I27*F27 -> 31.3848 | R27: 57.06 | S27: =G27*I27*H27*F27 -> 34.09704 | T27: 67.8 | U27: 40 MPa
A28: B11 | F28: 1 | G28: 4.118 | H28: 4.6 | I28: 1.8 | J28: =IF(I28<=1,0.6,I28) -> 1.8 | L28: =(G28+J28)*(I28+K28+$P$7)*(H28+J28)*F28 -> 70.06912 | M28: =(G28)*(H28)*F28 -> 18.9428 | N28: =+L28-S28 -> 35.97208 | O28: =(L28-N28)*1.3 -> 44.326152 | P28: =M28*$P$7 -> 0.94714 | Q28: =(2*G28+H28*2)*I28*F28 -> 31.3848 | S28: =G28*I28*H28*F28 -> 34.09704 | U28: 40 MPa
A29: B17 | F29: 1 | G29: 2.65 | H29: 2.65 | I29: 1.2 | J29: =IF(I29<=1,0.6,I29) -> 1.2 | L29: =(G29+J29)*(I29+K29+$P$7)*(H29+J29)*F29 -> 18.528125 | M29: =(G29)*(H29)*F29 -> 7.0225 | N29: =+L29-S29 -> 10.101125 | O29: =(L29-N29)*1.3 -> 10.9551 | P29: =M29*$P$7 -> 0.351125 | Q29: =(2*G29+H29*2)*I29*F29 -> 12.72 | R29: 12.72 | S29: =G29*I29*H29*F29 -> 8.427 | T29: 8.26 | U29: 40 MPa
A30: B18 | F30: 1 | G30: 4.3 | H30: 4.3 | I30: 1.8 | J30: =IF(I30<=1,0.6,I30) -> 1.8 | L30: =(G30+J30)*(I30+K30+$P$7)*(H30+J30)*F30 -> 68.8385 | M30: =(G30)*(H30)*F30 -> 18.49 | N30: =+L30-S30 -> 35.5565 | O30: =(L30-N30)*1.3 -> 43.2666 | P30: =M30*$P$7 -> 0.9245 | Q30: =(2*G30+H30*2)*I30*F30 -> 30.96 | R30: 43 | S30: =G30*I30*H30*F30 -> 33.282 | T30: 33.4 | U30: 40 MPa
A31: B19 | F31: 1 | G31: 2.649 | H31: 3.859 | I31: 1.5 | J31: =IF(I31<=1,0.6,I31) -> 1.5 | L31: =(G31+J31)*(I31+K31+$P$7)*(H31+J31)*F31 -> 34.463461 | M31: =(G31)*(H31)*F31 -> 10.222491 | N31: =+L31-S31 -> 19.129725 | O31: =(L31-N31)*1.3 -> 19.933857 | P31: =M31*$P$7 -> 0.51112455 | Q31: =(2*G31+H31*2)*I31*F31 -> 19.524 | R31: 20 | S31: =G31*I31*H31*F31 -> 15.333737 | T31: 15.34 | U31: 40 MPa
A32: B(P25+P30) | F32: 1 | G32: 5.95 | H32: 2.65 | I32: 1.5 | J32: =IF(I32<=1,0.6,I32) -> 1.5 | L32: =(G32+J32)*(I32+K32+$P$7)*(H32+J32)*F32 -> 47.922125 | M32: =(G32)*(H32)*F32 -> 15.7675 | N32: =+L32-S32 -> 24.270875 | O32: =(L32-N32)*1.3 -> 30.746625 | P32: =M32*$P$7 -> 0.788375 | Q32: =(2*G32+H32*2)*I32*F32 -> 25.8 | R32: =31.8/2 -> 15.9 | S32: =G32*I32*H32*F32 -> 23.65125 | T32: =47.2/2 -> 23.6 | U32: 40 MPa
A33: B(P26+P31) | F33: 1 | G33: 5.95 | H33: 2.65 | I33: 1.5 | J33: =IF(I33<=1,0.6,I33) -> 1.5 | L33: =(G33+J33)*(I33+K33+$P$7)*(H33+J33)*F33 -> 47.922125 | M33: =(G33)*(H33)*F33 -> 15.7675 | N33: =+L33-S33 -> 24.270875 | O33: =(L33-N33)*1.3 -> 30.746625 | P33: =M33*$P$7 -> 0.788375 | Q33: =(2*G33+H33*2)*I33*F33 -> 25.8 | R33: =31.8/2 -> 15.9 | S33: =G33*I33*H33*F33 -> 23.65125 | T33: =47.2/2 -> 23.6 | U33: 40 MPa
A34: TOTAL | L34: =SUM(L7:L33) -> 418.81131 | M34: =SUM(M7:M33) -> 128.62329 | N34: =SUM(N7:N33) -> 222.55059 | O34: =SUM(O7:O33) -> 255.13892 | P34: =SUM(P7:P33) -> 6.4811646 | Q34: =SUM(Q7:Q33) -> 247.6121 | R34: =SUM(R9:R33) -> 232.6 | S34: =SUM(S8:S33) -> 196.26071 | T34: =SUM(T9:T33) -> 195.72
A35: QUANTITATIVOS PROJETISTA | Q35: 0 | S35: 0
R36: =1-Q34/R34 -> -0.064540413 | T36: =1-S34/T34 -> -0.0027626788
H37: DETALHE TÍPICO | R37: =IF(R36<10%,"Usar valor de projeto","Confirmar com cliente") -> Usar valor de projeto | T37: =IF(T36<10%,"Usar valor de projeto","Confirmar com cliente") -> Usar valor de projeto
A46: BLOCOS TRIANGULARES
A47: ITEM | B47: QUANT | C47: LADO 1 DO BLOCO | D47: LADO 2 DO BLOCO | E47: LADO 3 DO BLOCO | F47: LADO 4 DO BLOCO | G47: LADO 5 DO BLOCO | H47: ALTURA DO BLOCO | I47: ESPESSURA DO LASTRO DE CONCRETO | J47: ADICIONAL LARGURA | K47: ADICIONAL ALTURA | L47: ESCAV | M47: APILOA | N47: REATERRO | O47: BOTA-FORA | P47: LASTRO | Q47: FORMA | R47: FORMA (PROJETISTA) | S47: CONCRETO | T47: CONCRETO (PROJETISTA) | U47: TIPO
B48: R | C48: h1 + h2 | D48: h2 | E48: B | F48: b2 | G48: b1 | H48: Hb | I48: e.L. | J48: K | K48: K | L48: VE | M48: AP | N48: VA | O48: VB | P48: VM | Q48: F | R48: F | S48: C | T48: C
...

Sheet Arm. Cortina
B1: Projeto | C1: =ORÇAMENTO!I4 -> SENSE106
B2: Empresa | C2: =ORÇAMENTO!I5 -> HOLZE EMPREENDIMENTOS
B3: Revisão | C3: R00 - Michelle Furlan
A4: ARMAÇÃO CORTINA
A5: ITEM | C5: QUANT | D5: QUANTIDADE POR ITEM CA-50 - m | K5: CA-60 - m
D6: 6.3 | E6: 8 | F6: 10 | G6: 12.5 | H6: 16 | I6: 20 | J6: 25 | K6: 5 | L6: 0 | M6: 0 | N6: 0 | O6: 0
A7: PROJETO:
C8: 1
A9: PROJETO:
C10: 1
A11: PROJETO:
C12: 1
A13: PROJETO:
C14: 1
A15: PROJETO:
C16: 1
B17: TOTAL - M | C17: =SUM(D17:O17) -> 0 | D17: =SUMPRODUCT(D7:D16,$C7:$C16) -> 0 | E17: =SUMPRODUCT(E7:E16,$C7:$C16) -> 0 | F17: =SUMPRODUCT(F7:F16,$C7:$C16) -> 0 | G17: =SUMPRODUCT(G7:G16,$C7:$C16) -> 0 | H17: =SUMPRODUCT(H7:H16,$C7:$C16) -> 0 | I17: =SUMPRODUCT(I7:I16,$C7:$C16) -> 0 | J17: =SUMPRODUCT(J7:J16,$C7:$C16) -> 0 | K17: =SUMPRODUCT(K7:K16,$C7:$C16) -> 0 | ... O17: =SUMPRODUCT(O7:O16,$C7:$C16) -> 0
B18: PESO kg/m | D18: 1 | E18: 1 | F18: 1 | G18: 1 | H18: 1 | I18: 1 | J18: 1 | K18: 1 | L18: 1 | M18: 1 | N18: 1 | O18: 1
B19: TOTAL - kg | C19: =SUM(D19:O19) -> 0 | D19: =D18*D17 -> 0 | E19: =E18*E17 -> 0 | F19: =F18*F17 -> 0 | G19: =G18*G17 -> 0 | H19: =H18*H17 -> 0 | I19: =I18*I17 -> 0 | J19: =J18*J17 -> 0 | K19: =K18*K17 -> 0 | ... O19: =O18*O17 -> 0

Sheet Tabela de Aço
A1: TABELA DE AÇO
A2: CA-50 | D2: CA-60
A3: Ø - mm | B3: kg/m | C3: pol | D3: Ø - mm | E3: kg/m
A4: 6.3 | B4: 0.245 | C4: 1/4" | D4: 3.4 | E4: 0.079
A5: 8 | B5: 0.395 | C5: 5/16" | D5: 4.2 | E5: 0.109
A6: 10 | B6: 0.617 | C6: 3/8" | D6: 5 | E6: 0.154
A7: 12.5 | B7: 0.963 | C7: 1/2" | D7: 6 | E7: 0.222
A8: 16 | B8: 1.578 | C8: 5/8" | D8: 7 | E8: 0.302
A9: 20 | B9: 2.466 | C9: 3/4" | D9: 8 | E9: 0.395
A10: 25 | B10: 3.853 | C10: 1" | D10: 9.5 | E10: 0.558
A11: 32 | B11: 6.313 | C11: 1 1/4" | D11: 0
A12: 40 | B12: 9.865 | C12: 1 5/8" | D12: 0

Sheet Vigas Fundação
B1: Projeto | C1: =ORÇAMENTO!I4 -> SENSE106
B2: Empresa | C2: =ORÇAMENTO!I5 -> HOLZE EMPREENDIMENTOS
B3: Revisão | C3: R00 - Michelle Furlan
A4: VIGAS FUNDAÇÃO
A5: ITEM | B5: DIMENSÕES UNITÁRIAS - m | E5: Adição | H5: ESCAV | I5: APILOA | J5: REATER | K5: BOTA FORA | L5: LASTRO | M5: FORMA | O5: FORMA (PROJETISTA) | P5: CONCRETO | Q5: CONCRETO (PROJETISTA) | S5: TAXA AÇO (KG/M3) | T5: IMPERM | V5: RESUMO - CONCRETO
B6: LARG | C6: COMP | D6: ALT | E6: LARG | F6: ALT | G6: QUANT | L6: m3 | V6: m3 | W6: TIPO
B7: A | C7: C | D7: B | E7: m | F7: m | H7: m3 | I7: m2 | J7: m3 | K7: m3 | L7: 0.05 | M7: lados | N7: m2 | P7: m3 | R7: TIPO | T7: m2
A8: PROJETO: PRÉ-FORMA-R03 | V8: =SUMIF($R$8:$R$68,$W8,$P$8:$P$68) -> 0 | W8: 20 MPa
A9: V1 | B9: 0.2 | C9: 5.14 | D9: 0.6 | E9: =IF(D9<=1,0.6,1.2) -> 0.6 | G9: 1 | H9: =((B9+E9)*(D9+F9)*C9)*G9 -> 2.4672 | I9: =(B9)*(C9)*G9 -> 1.028 | J9: =H9-P9 -> 1.8504 | K9: =(H9-J9)*1.3 -> 0.80184 | L9: =I9*$L$7 -> 0.0514 | M9: 2 | N9: =((C9*D9*M9))*G9 -> 6.168 | O9: 39.05 | P9: =B9*D9*C9*G9 -> 0.6168 | Q9: 3.59 | R9: 40 MPa | S9: =P9*$S$7 -> 0 | T9: =C9*B9+2*C9*D9 -> 7.196 | V9: =SUMIF($R$8:$R$68,$W9,$P$8:$P$68) -> 0 | W9: 25 MPa
A10: V2 | B10: 0.2 | C10: 9.52 | D10: 0.6 | E10: =IF(D10<=1,0.6,1.2) -> 0.6 | G10: 1 | H10: =((B10+E10)*(D10+F10)*C10)*G10 -> 4.5696 | I10: =(B10)*(C10)*G10 -> 1.904 | J10: =H10-P10 -> 3.4272 | K10: =(H10-J10)*1.3 -> 1.48512 | L10: =I10*$L$7 -> 0.0952 | M10: 2 | N10: =((C10*D10*M10))*G10 -> 11.424 | P10: =B10*D10*C10*G10 -> 1.1424 | R10: 40 MPa | S10: =P10*$S$7 -> 0 | T10: =C10*B10+2*C10*D10 -> 13.328 | V10: =SUMIF($R$8:$R$68,$W10,$P$8:$P$68) -> 0 | W10: 30 MPa
A11: V3 | B11: 0.2 | C11: 12 | D11: 0.6 | E11: =IF(D11<=1,0.6,1.2) -> 0.6 | G11: 1 | H11: =((B11+E11)*(D11+F11)*C11)*G11 -> 5.76 | I11: =(B11)*(C11)*G11 -> 2.4 | J11: =H11-P11 -> 4.32 | K11: =(H11-J11)*1.3 -> 1.872 | L11: =I11*$L$7 -> 0.12 | M11: 2 | N11: =((C11*D11*M11))*G11 -> 14.4 | P11: =B11*D11*C11*G11 -> 1.44 | R11: 40 MPa | S11: =P11*$S$7 -> 0 | T11: =C11*B11+2*C11*D11 -> 16.8 | V11: =SUMIF($R$8:$R$68,$W11,$P$8:$P$68) -> 0 | W11: 35 MPa
A12: V4 | B12: 0.15 | C12: 3.5 | D12: 0.6 | E12: =IF(D12<=1,0.6,1.2) -> 0.6 | G12: 1 | H12: =((B12+E12)*(D12+F12)*C12)*G12 -> 1.575 | I12: =(B12)*(C12)*G12 -> 0.525 | J12: =H12-P12 -> 1.26 | K12: =(H12-J12)*1.3 -> 0.4095 | L12: =I12*$L$7 -> 0.02625 | M12: 2 | N12: =((C12*D12*M12))*G12 -> 4.2 | P12: =B12*D12*C12*G12 -> 0.315 | R12: 40 MPa | S12: =P12*$S$7 -> 0 | T12: =C12*B12+2*C12*D12 -> 4.725 | V12: =SUMIF($R$8:$R$68,$W12,$P$8:$P$68) -> 54.5681 | W12: 40 MPa
A13: V5 | B13: 0.15 | C13: 4.16 | D13: 0.6 | E13: =IF(D13<=1,0.6,1.2) -> 0.6 | G13: 1 | H13: =((B13+E13)*(D13+F13)*C13)*G13 -> 1.872 | I13: =(B13)*(C13)*G13 -> 0.624 | J13: =H13-P13 -> 1.4976 | K13: =(H13-J13)*1.3 -> 0.48672 | L13: =I13*$L$7 -> 0.0312 | M13: 2 | N13: =((C13*D13*M13))*G13 -> 4.992 | P13: =B13*D13*C13*G13 -> 0.3744 | R13: 40 MPa | S13: =P13*$S$7 -> 0 | T13: =C13*B13+2*C13*D13 -> 5.616
A14: V6 | B14: 0.15 | C14: 4.4 | D14: 0.6 | E14: =IF(D14<=1,0.6,1.2) -> 0.6 | G14: 1 | H14: =((B14+E14)*(D14+F14)*C14)*G14 -> 1.98 | I14: =(B14)*(C14)*G14 -> 0.66 | J14: =H14-P14 -> 1.584 | K14: =(H14-J14)*1.3 -> 0.5148 | L14: =I14*$L$7 -> 0.033 | M14: 2 | N14: =((C14*D14*M14))*G14 -> 5.28 | O14: 19.01 | P14: =B14*D14*C14*G14 -> 0.396 | Q14: 2.72 | R14: 40 MPa | S14: =P14*$S$7 -> 0 | T14: =C14*B14+2*C14*D14 -> 5.94
A15: V7 | B15: 0.5 | C15: 4.54 | D15: 0.6 | E15: =IF(D15<=1,0.6,1.2) -> 0.6 | G15: 1 | H15: =((B15+E15)*(D15+F15)*C15)*G15 -> 2.9964 | I15: =(B15)*(C15)*G15 -> 2.27 | J15: =H15-P15 -> 1.6344 | K15: =(H15-J15)*1.3 -> 1.7706 | L15: =I15*$L$7 -> 0.1135 | M15: 2 | N15: =((C15*D15*M15))*G15 -> 5.448 | P15: =B15*D15*C15*G15 -> 1.362 | R15: 40 MPa | S15: =P15*$S$7 -> 0 | T15: =C15*B15+2*C15*D15 -> 7.718
A16: V8 | B16: 0.3 | C16: 5.56 | D16: 0.6 | E16: =IF(D16<=1,0.6,1.2) -> 0.6 | G16: 1 | H16: =((B16+E16)*(D16+F16)*C16)*G16 -> 3.0024 | I16: =(B16)*(C16)*G16 -> 1.668 | J16: =H16-P16 -> 2.0016 | K16: =(H16-J16)*1.3 -> 1.30104 | L16: =I16*$L$7 -> 0.0834 | M16: 2 | N16: =((C16*D16*M16))*G16 -> 6.672 | P16: =B16*D16*C16*G16 -> 1.0008 | R16: 40 MPa | S16: =P16*$S$7 -> 0 | T16: =C16*B16+2*C16*D16 -> 8.34
A17: V9 | B17: 0.2 | C17: 4.2 | D17: 0.6 | E17: =IF(D17<=1,0.6,1.2) -> 0.6 | G17: 1 | H17: =((B17+E17)*(D17+F17)*C17)*G17 -> 2.016 | I17: =(B17)*(C17)*G17 -> 0.84 | J17: =H17-P17 -> 1.512 | K17: =(H17-J17)*1.3 -> 0.6552 | L17: =I17*$L$7 -> 0.042 | M17: 2 | N17: =((C17*D17*M17))*G17 -> 5.04 | P17: =B17*D17*C17*G17 -> 0.504 | R17: 40 MPa | S17: =P17*$S$7 -> 0 | T17: =C17*B17+2*C17*D17 -> 5.88
A18: V10 | B18: 0.5 | C18: 6.15 | D18: 0.6 | E18: =IF(D18<=1,0.6,1.2) -> 0.6 | G18: 1 | H18: =((B18+E18)*(D18+F18)*C18)*G18 -> 4.059 | I18: =(B18)*(C18)*G18 -> 3.075 | J18: =H18-P18 -> 2.214 | K18: =(H18-J18)*1.3 -> 2.3985 | L18: =I18*$L$7 -> 0.15375 | M18: 2 | N18: =((C18*D18*M18))*G18 -> 7.38 | O18: 21.81 | P18: =B18*D18*C18*G18 -> 1.845 | Q18: 3.78 | R18: 40 MPa | S18: =P18*$S$7 -> 0 | T18: =C18*B18+2*C18*D18 -> 10.455
A19: V11 | B19: 0.14 | C19: 6.1 | D19: 0.5 | E19: =IF(D19<=1,0.6,1.2) -> 0.6 | G19: 1 | H19: =((B19+E19)*(D19+F19)*C19)*G19 -> 2.257 | I19: =(B19)*(C19)*G19 -> 0.854 | J19: =H19-P19 -> 1.83 | K19: =(H19-J19)*1.3 -> 0.5551 | L19: =I19*$L$7 -> 0.0427 | M19: 2 | N19: =((C19*D19*M19))*G19 -> 6.1 | P19: =B19*D19*C19*G19 -> 0.427 | R19: 40 MPa | S19: =P19*$S$7 -> 0 | T19: =C19*B19+2*C19*D19 -> 6.954
A20: V12 | B20: 0.5 | C20: 6.15 | D20: 0.6 | E20: =IF(D20<=1,0.6,1.2) -> 0.6 | G20: 1 | H20: =((B20+E20)*(D20+F20)*C20)*G20 -> 4.059 | I20: =(B20)*(C20)*G20 -> 3.075 | J20: =H20-P20 -> 2.214 | K20: =(H20-J20)*1.3 -> 2.3985 | L20: =I20*$L$7 -> 0.15375 | M20: 2 | N20: =((C20*D20*M20))*G20 -> 7.38 | P20: =B20*D20*C20*G20 -> 1.845 | R20: 40 MPa | S20: =P20*$S$7 -> 0 | T20: =C20*B20+2*C20*D20 -> 10.455
A21: V13 | B21: 0.5 | C21: 4.54 | D21: 0.6 | E21: =IF(D21<=1,0.6,1.2) -> 0.6 | G21: 1 | H21: =((B21+E21)*(D21+F21)*C21)*G21 -> 2.9964 | I21: =(B21)*(C21)*G21 -> 2.27 | J21: =H21-P21 -> 1.6344 | K21: =(H21-J21)*1.3 -> 1.7706 | L21: =I21*$L$7 -> 0.1135 | M21: 2 | N21: =((C21*D21*M21))*G21 -> 5.448 | O21: 24.83 | P21: =B21*D21*C21*G21 -> 1.362 | Q21: 2.38 | R21: 40 MPa | S21: =P21*$S$7 -> 0 | T21: =C21*B21+2*C21*D21 -> 7.718
A22: V14 | B22: 0.14 | C22: 2.25 | D22: 1.9 | E22: =IF(D22<=1,0.6,1.2) -> 1.2 | G22: 1 | H22: =((B22+E22)*(D22+F22)*C22)*G22 -> 5.7285 | I22: =(B22)*(C22)*G22 -> 0.315 | J22: =H22-P22 -> 5.13 | K22: =(H22-J22)*1.3 -> 0.77805 | L22: =I22*$L$7 -> 0.01575 | M22: 2 | N22: =((C22*D22*M22))*G22 -> 8.55 | P22: =B22*D22*C22*G22 -> 0.5985 | R22: 40 MPa | S22: =P22*$S$7 -> 0 | T22: =C22*B22+2*C22*D22 -> 8.865
A23: V15 | B23: 0.14 | C23: 2.34 | D23: 0.5 | E23: =IF(D23<=1,0.6,1.2) -> 0.6 | G23: 1 | H23: =((B23+E23)*(D23+F23)*C23)*G23 -> 0.8658 | I23: =(B23)*(C23)*G23 -> 0.3276 | J23: =H23-P23 -> 0.702 | K23: =(H23-J23)*1.3 -> 0.21294 | L23: =I23*$L$7 -> 0.01638 | M23: 2 | N23: =((C23*D23*M23))*G23 -> 2.34 | P23: =B23*D23*C23*G23 -> 0.1638 | R23: 40 MPa | S23: =P23*$S$7 -> 0 | T23: =C23*B23+2*C23*D23 -> 2.6676
A24: V16 | B24: 0.14 | C24: 4 | D24: 0.5 | E24: =IF(D24<=1,0.6,1.2) -> 0.6 | G24: 1 | H24: =((B24+E24)*(D24+F24)*C24)*G24 -> 1.48 | I24: =(B24)*(C24)*G24 -> 0.56 | J24: =H24-P24 -> 1.2 | K24: =(H24-J24)*1.3 -> 0.364 | L24: =I24*$L$7 -> 0.028 | M24: 2 | N24: =((C24*D24*M24))*G24 -> 4 | P24: =B24*D24*C24*G24 -> 0.28 | R24: 40 MPa | S24: =P24*$S$7 -> 0 | T24: =C24*B24+2*C24*D24 -> 4.56
A25: V17 | B25: 0.14 | C25: 2.25 | D25: 1.9 | E25: =IF(D25<=1,0.6,1.2) -> 1.2 | G25: 1 | H25: =((B25+E25)*(D25+F25)*C25)*G25 -> 5.7285 | I25: =(B25)*(C25)*G25 -> 0.315 | J25: =H25-P25 -> 5.13 | K25: =(H25-J25)*1.3 -> 0.77805 | L25: =I25*$L$7 -> 0.01575 | M25: 2 | N25: =((C25*D25*M25))*G25 -> 8.55 | P25: =B25*D25*C25*G25 -> 0.5985 | R25: 40 MPa | S25: =P25*$S$7 -> 0 | T25: =C25*B25+2*C25*D25 -> 8.865
A26: V18 | B26: 0.15 | C26: 3.71 | D26: 0.6 | E26: =IF(D26<=1,0.6,1.2) -> 0.6 | G26: 1 | H26: =((B26+E26)*(D26+F26)*C26)*G26 -> 1.6695 | I26: =(B26)*(C26)*G26 -> 0.5565 | J26: =H26-P26 -> 1.3356 | K26: =(H26-J26)*1.3 -> 0.43407 | L26: =I26*$L$7 -> 0.027825 | M26: 2 | N26: =((C26*D26*M26))*G26 -> 4.452 | O26: 17.44 | P26: =B26*D26*C26*G26 -> 0.3339 | Q26: 3.11 | R26: 40 MPa | S26: =P26*$S$7 -> 0 | T26: =C26*B26+2*C26*D26 -> 5.0085
A27: V19 | B27: 0.5 | C27: 6.5 | D27: 0.6 | E27: =IF(D27<=1,0.6,1.2) -> 0.6 | G27: 1 | H27: =((B27+E27)*(D27+F27)*C27)*G27 -> 4.29 | I27: =(B27)*(C27)*G27 -> 3.25 | J27: =H27-P27 -> 2.34 | K27: =(H27-J27)*1.3 -> 2.535 | L27: =I27*$L$7 -> 0.1625 | M27: 2 | N27: =((C27*D27*M27))*G27 -> 7.8 | P27: =B27*D27*C27*G27 -> 1.95 | R27: 40 MPa | S27: =P27*$S$7 -> 0 | T27: =C27*B27+2*C27*D27 -> 11.05
A28: V20 | B28: 0.5 | C28: 4.54 | D28: 0.6 | E28: =IF(D28<=1,0.6,1.2) -> 0.6 | G28: 1 | H28: =((B28+E28)*(D28+F28)*C28)*G28 -> 2.9964 | I28: =(B28)*(C28)*G28 -> 2.27 | J28: =H28-P28 -> 1.6344 | K28: =(H28-J28)*1.3 -> 1.7706 | L28: =I28*$L$7 -> 0.1135 | M28: 2 | N28: =((C28*D28*M28))*G28 -> 5.448 | P28: =B28*D28*C28*G28 -> 1.362 | R28: 40 MPa | S28: =P28*$S$7 -> 0 | T28: =C28*B28+2*C28*D28 -> 7.718
A29: V21 | B29: 0.5 | C29: 5.135 | D29: 0.6 | E29: =IF(D29<=1,0.6,1.2) -> 0.6 | G29: 1 | H29: =((B29+E29)*(D29+F29)*C29)*G29 -> 3.3891 | I29: =(B29)*(C29)*G29 -> 2.5675 | J29: =H29-P29 -> 1.8486 | K29: =(H29-J29)*1.3 -> 2.00265 | L29: =I29*$L$7 -> 0.128375 | M29: 2 | N29: =((C29*D29*M29))*G29 -> 6.162 | O29: 27.62 | P29: =B29*D29*C29*G29 -> 1.5405 | Q29: 4.28 | R29: 40 MPa | S29: =P29*$S$7 -> 0 | T29: =C29*B29+2*C29*D29 -> 8.7295
A30: V22 | B30: 0.2 | C30: 15.725 | D30: 0.5 | E30: =IF(D30<=1,0.6,1.2) -> 0.6 | G30: 1 | H30: =((B30+E30)*(D30+F30)*C30)*G30 -> 6.29 | I30: =(B30)*(C30)*G30 -> 3.145 | J30: =H30-P30 -> 4.7175 | K30: =(H30-J30)*1.3 -> 2.04425 | L30: =I30*$L$7 -> 0.15725 | M30: 2 | N30: =((C30*D30*M30))*G30 -> 15.725 | P30: =B30*D30*C30*G30 -> 1.5725 | R30: 40 MPa | S30: =P30*$S$7 -> 0 | T30: =C30*B30+2*C30*D30 -> 18.87
A31: V23 | B31: 0.5 | C31: 5.4 | D31: 0.6 | E31: =IF(D31<=1,0.6,1.2) -> 0.6 | G31: 1 | H31: =((B31+E31)*(D31+F31)*C31)*G31 -> 3.564 | I31: =(B31)*(C31)*G31 -> 2.7 | J31: =H31-P31 -> 1.944 | K31: =(H31-J31)*1.3 -> 2.106 | L31: =I31*$L$7 -> 0.135 | M31: 2 | N31: =((C31*D31*M31))*G31 -> 6.48 | P31: =B31*D31*C31*G31 -> 1.62 | R31: 40 MPa | S31: =P31*$S$7 -> 0 | T31: =C31*B31+2*C31*D31 -> 9.18
A32: V24 | B32: 0.5 | C32: 5.135 | D32: 0.6 | E32: =IF(D32<=1,0.6,1.2) -> 0.6 | G32: 1 | H32: =((B32+E32)*(D32+F32)*C32)*G32 -> 3.3891 | I32: =(B32)*(C32)*G32 -> 2.5675 | J32: =H32-P32 -> 1.8486 | K32: =(H32-J32)*1.3 -> 2.00265 | L32: =I32*$L$7 -> 0.128375 | M32: 2 | N32: =((C32*D32*M32))*G32 -> 6.162 | O32: 30.18 | P32: =B32*D32*C32*G32 -> 1.5405 | Q32: 4.28 | R32: 40 MPa | S32: =P32*$S$7 -> 0 | T32: =C32*B32+2*C32*D32 -> 8.7295
A33: V25 | B33: 0.2 | C33: 15.725 | D33: 0.5 | E33: =IF(D33<=1,0.6,1.2) -> 0.6 | G33: 1 | H33: =((B33+E33)*(D33+F33)*C33)*G33 -> 6.29 | I33: =(B33)*(C33)*G33 -> 3.145 | J33: =H33-P33 -> 4.7175 | K33: =(H33-J33)*1.3 -> 2.04425 | L33: =I33*$L$7 -> 0.15725 | M33: 2 | N33: =((C33*D33*M33))*G33 -> 15.725 | P33: =B33*D33*C33*G33 -> 1.5725 | R33: 40 MPa | S33: =P33*$S$7 -> 0 | T33: =C33*B33+2*C33*D33 -> 18.87
A34: V26 | B34: 0.5 | C34: 5.4 | D34: 0.6 | E34: =IF(D34<=1,0.6,1.2) -> 0.6 | G34: 1 | H34: =((B34+E34)*(D34+F34)*C34)*G34 -> 3.564 | I34: =(B34)*(C34)*G34 -> 2.7 | J34: =H34-P34 -> 1.944 | K34: =(H34-J34)*1.3 -> 2.106 | L34: =I34*$L$7 -> 0.135 | M34: 2 | N34: =((C34*D34*M34))*G34 -> 6.48 | P34: =B34*D34*C34*G34 -> 1.62 | R34: 40 MPa | S34: =P34*$S$7 -> 0 | T34: =C34*B34+2*C34*D34 -> 9.18
A35: V27 | B35: 0.2 | C35: 3.6 | D35: 0.6 | E35: =IF(D35<=1,0.6,1.2) -> 0.6 | G35: 1 | H35: =((B35+E35)*(D35+F35)*C35)*G35 -> 1.728 | I35: =(B35)*(C35)*G35 -> 0.72 | J35: =H35-P35 -> 1.296 | K35: =(H35-J35)*1.3 -> 0.5616 | L35: =I35*$L$7 -> 0.036 | M35: 2 | N35: =((C35*D35*M35))*G35 -> 4.32 | O35: 44.87 | P35: =B35*D35*C35*G35 -> 0.432 | Q35: 3.89 | R35: 40 MPa | S35: =P35*$S$7 -> 0 | T35: =C35*B35+2*C35*D35 -> 5.04
