Workbook
Name \0: #REF!
Name \a: #REF!
Name \m: #REF!
Name aa: #REF!
Name aaaa: #REF!
Name angelo: #REF!
Name area: #REF!
Name aux: #REF!
Name BDA: #REF!
Name BDI: #REF!
Name ca: #REF!
Name Capa: #REF!
Name cronograma: #REF!
Name D: #REF!
Name direto: #REF!
Name DRE: #REF!
Name ea: #REF!
Name FFFFFFF: #REF!
Name item_1: #REF!
Name LS: #REF!
Name MENU: #REF!
Name MENU1: #REF!
Name MENU2: #REF!
Name MENU3: #REF!
Name MENU4: #REF!
Name MENU5: #REF!
Name MENU6: #REF!
Name mo: #REF!
Name OAE: #REF!
Name ParamValues1: #REF!
Name PAV: #REF!
Name pr: #REF!
Name PRE: #REF!
Name Print_Area_MI: #REF!
Name qe: #REF!
Name qee: #REF!
Name reforsu: #REF!
Name ren: #REF!
Name REV: #REF!
Name sa: #REF!
Name SEG: #REF!
Name SIH: #REF!
Name SIV: #REF!
Name ss: #REF!
Name susref: #REF!
Name tania: #REF!
Name tc: #REF!
Name titulos: #REF!
Name TOT: #REF!
Name Total: #REF!
Name TRP: #REF!
Name xxxx: #REF!

Sheet MÃO DE OBRA
A1: ETAPA | B1: MATERIAL | C1: EMPREITADA GLOBAL | D1: VALOR TOTAL | E1: % | F1: VALOR / m²
A2: GERENCIAMENTO TÉCNICO E ADMINISTRATIVO | B2: ='[1]Obra '!$C$33 -> 3667981.1 | C2: ='[1]MÃO DE OBRA'!$D$12 -> 226030.6 | D2: =C2+B2 -> 3894011.7 | E2: =D2/D$19 -> 0.063847711 | F2: =D2/'MÃO DE OBRA'!I$2 -> 222.44428 | H2: ÁREA CONSTRUÍDA | I2: ='[1]Obra '!$E$9 -> 17505.56 | J2: m²
A3: MOVIMENTAÇÃO DE TERRA | B3: ='[1]Obra '!$C$34 -> 1400464.9 | C3: 0 | D3: =C3+B3 -> 1400464.9 | E3: =D3/D$19 -> 0.022962559 | F3: =D3/'MÃO DE OBRA'!I$2 -> 80.001146
A4: INFRAESTRUTURA | B4: ='[1]Obra '!$C$35 -> 2627275.7 | C4: ='[1]MÃO DE OBRA'!$D$14 -> 1130153 | D4: =C4+B4 -> 3757428.7 | E4: =D4/D$19 -> 0.061608242 | F4: =D4/'MÃO DE OBRA'!I$2 -> 214.64201
A5: CONTENÇÃO | B5: ='[1]Obra '!$C$36 -> 1381816.6 | C5: ='[1]MÃO DE OBRA'!$D$13 -> 339045.9 | D5: =C5+B5 -> 1720862.5 | E5: =D5/D$19 -> 0.028215922 | F5: =D5/'MÃO DE OBRA'!I$2 -> 98.303767
A6: SUPRAESTRUTURA | B6: ='[1]Obra '!$C$37 -> 6463760.8 | C6: ='[1]MÃO DE OBRA'!$D$15 -> 5424734.4 | D6: =C6+B6 -> 11888495 | E6: =D6/D$19 -> 0.19492833 | F6: =D6/'MÃO DE OBRA'!I$2 -> 679.12682 | H6: =C6/ORÇAMENTO_EXECUTIVO!G2 -> 309.88637
A7: ALVENARIA | B7: ='[1]Obra '!$C$38 -> 1539779.4 | C7: ='[1]MÃO DE OBRA'!$D$16 -> 1130153 | D7: =C7+B7 -> 2669932.4 | E7: =D7/D$19 -> 0.043777236 | F7: =D7/'MÃO DE OBRA'!I$2 -> 152.51911
A8: INSTALAÇÕES ELÉTRICAS, HIDRÁULICAS, GLP E PREVENTIVAS | B8: ='[1]Obra '!$C$39+'[1]Obra '!$C$48 -> 4111849.3 | C8: ='[1]MÃO DE OBRA'!$E$25 -> 2712367.2 | D8: =C8+B8 -> 6824216.5 | E8: =D8/D$19 -> 0.11189247 | F8: =D8/'MÃO DE OBRA'!I$2 -> 389.83137
A9: EQUIPAMENTOS E SISTEMAS ESPECIAIS | B9: ='[1]Obra '!$C$40+'[1]Obra '!$C$49 -> 3389279.9 | C9: 0 | D9: =C9+B9 -> 3389279.9 | E9: =D9/D$19 -> 0.055571933 | F9: =D9/'MÃO DE OBRA'!I$2 -> 193.61162
A10: IMPERMEABILIZAÇÃO | B10: ='[1]Obra '!$C$43 -> 511572.58 | C10: ='[1]MÃO DE OBRA'!$D$20 -> 452061.2 | D10: =C10+B10 -> 963633.78 | E10: =D10/D$19 -> 0.015800109 | F10: =D10/'MÃO DE OBRA'!I$2 -> 55.047298 | H10: REVESTIMENTOS | I10: ACABAMENTOS
A11: REVESTIMENTOS INTERNOS EM PISO E PAREDE | B11: =H11+H12 -> 1695279.1 | C11: ='[1]MÃO DE OBRA'!$D$22 -> 2260306 | D11: =C11+B11 -> 3955585.1 | E11: =D11/D$19 -> 0.064857291 | F11: =D11/'MÃO DE OBRA'!I$2 -> 225.96164 | G11: PISO | H11: =[1]Ger_Executivo!$N$189+[1]Ger_Executivo!$N$193 -> 863517.75 | I11: ='[1]Obra '!$C$44-H11 -> 1675663.7
A12: REVESTIMENTOS E ACABAMENTOS INTERNOS EM TETO | B12: ='[1]Obra '!$C$42 -> 349137.96 | C12: ='[1]MÃO DE OBRA'!$D$21 -> 791107.1 | D12: =C12+B12 -> 1140245.1 | E12: =D12/D$19 -> 0.018695896 | F12: =D12/'MÃO DE OBRA'!I$2 -> 65.136166 | G12: PAREDE | H12: =[1]Ger_Executivo!$N$166+[1]Ger_Executivo!$N$168 -> 831761.34 | I12: ='[1]Obra '!$C$41-H12 -> 594463.01
A13: ACABAMENTOS EM PISO E PAREDE | B13: =I11+I12 -> 2270126.7 | C13: ='[1]MÃO DE OBRA'!$D$24 -> 2034275.4 | D13: =C13+B13 -> 4304402.1 | E13: =D13/D$19 -> 0.070576628 | F13: =D13/'MÃO DE OBRA'!I$2 -> 245.88771
A14: PINTURA INTERNA | B14: ='[1]Obra '!$C$45 -> 786426.24 | C14: ='[1]MÃO DE OBRA'!$D$27 -> 1808244.8 | D14: =C14+B14 -> 2594671 | E14: =D14/D$19 -> 0.042543222 | F14: =D14/'MÃO DE OBRA'!I$2 -> 148.21983
A15: ESQUADRIAS, VIDROS E FERRAGENS | B15: ='[1]Obra '!$C$47 -> 5007297.9 | C15: ='[1]MÃO DE OBRA'!$E$18 -> 904122.4 | D15: =C15+B15 -> 5911420.4 | E15: =D15/D$19 -> 0.096925917 | F15: =D15/'MÃO DE OBRA'!I$2 -> 337.68816
A16: REVESTIMENTOS E ACABAMENTOS DE FACHADA | B16: ='[1]Obra '!$C$46 -> 561222.52 | C16: ='[1]MÃO DE OBRA'!$D$23 -> 1582214.2 | D16: =C16+B16 -> 2143436.7 | E16: =D16/D$19 -> 0.035144611 | F16: =D16/'MÃO DE OBRA'!I$2 -> 122.4432
A17: SERVIÇOS COMPLEMENTARES | B17: ='[1]Obra '!$C$50 -> 1941982 | C17: ='[1]MÃO DE OBRA'!$D$28 -> 678091.8 | D17: =C17+B17 -> 2620073.8 | E17: =D17/D$19 -> 0.042959736 | F17: =D17/'MÃO DE OBRA'!I$2 -> 149.67095
A18: IMPREVISTOS E CONTINGENCIAS | B18: ='[1]Obra '!$C$52 -> 680745.43 | C18: ='[1]MÃO DE OBRA'!$D$29 -> 1130153 | D18: =C18+B18 -> 1810898.4 | E18: =D18/D$19 -> 0.029692186 | F18: =D18/'MÃO DE OBRA'!I$2 -> 103.44704
A19: TOTAL | B19: =SUM(B2:B18) -> 38385998 | C19: =SUM(C2:C18) -> 22603060 | D19: =SUM(D2:D18) -> 60989058 | E19: =SUM(E2:E18) -> 1 | F19: =SUM(F2:F18) -> 3483.9821
A20: CUB/SC | B20: 2965.54 | E20: 45839 | F20: =+F19/B20 -> 1.1748222

Sheet ALVENARIA-DRYWALL
B3: PAREDES | C3: DRYWALL | D3: ALVENARIA | E3: DIFERENÇA | H3: DRYWALL | J3: ALVENARIA
B4: VALOR PAREDE | C4: ='MÃO DE OBRA'!D7 -> 2669932.4 | D4: 2676647 | E4: =D4-C4 -> 6714.6385 | H4: PAREDES E PAINEIS | I4: =ORÇAMENTO_EXECUTIVO!B7 -> 2669932.4 | J4: 2676647
B5: VALOR ARGAMASSADOS | C5: 2483408.3 | D5: 2803453.8 | E5: =D5-C5 -> 320045.55 | H5: ARGAMASSADOS | I5: 223102.28 | J5: 530511.22
B6: VALOR TOTAL | C6: =C4+C5 -> 5153340.7 | D6: =D4+D5 -> 5480100.9 | E6: =D6-C6 -> 326760.19 | H6: MO PAREDE | I6: ='MÃO DE OBRA'!C11 -> 2260306 | J6: 2272942.6
B7: VALOR / PAREDE | C7: 254.29138 | D7: 333.37451 | E7: =D7-C7 -> 79.083136 | I7: =I4+I5+I6 -> 5153340.7 | J7: =J4+J5+J6 -> 5480100.9
B8: VALOR TOTAL ORÇADO | C8: =ORÇAMENTO_EXECUTIVO!B19 -> 60989058 | D8: =C8+E6 -> 61315818 | E8: =D8-C8 -> 326760.19
B9: VALOR / AC* | C9: =C8/ORÇAMENTO_EXECUTIVO!G2 -> 3483.9821 | D9: =D8/ORÇAMENTO_EXECUTIVO!G2 -> 3502.6482 | E9: =D9-C9 -> 18.66608
B10: VALOR / AP** | C10: =C8/'AREA PRIVATIVA'!C3 -> 6156.5061 | D10: =D8/'AREA PRIVATIVA'!C3 -> 6189.4907 | E10: =D10-C10 -> 32.984623
B11: VALOR / UNIDADE | C11: =C8/129 -> 472783.4 | D11: =D8/129 -> 475316.42 | E11: =D11-C11 -> 2533.0247
E12: =E8/C8 -> 0.0053576854

Sheet ORÇAMENTO_EXECUTIVO
A1: ETAPA | B1: VALOR ORÇADO | C1: % | D1: VALOR / m²
A2: GERENCIAMENTO TÉCNICO E ADMINISTRATIVO | B2: ='MÃO DE OBRA'!D2 -> 3894011.7 | C2: =B2/B$19 -> 0.063847711 | D2: =B2/ORÇAMENTO_EXECUTIVO!G$2 -> 222.44428 | F2: ÁREA CONSTRUÍDA | G2: 17505.56 | H2: m²
A3: MOVIMENTAÇÃO DE TERRA | B3: ='MÃO DE OBRA'!D3 -> 1400464.9 | C3: =B3/B$19 -> 0.022962559 | D3: =B3/ORÇAMENTO_EXECUTIVO!G$2 -> 80.001146
A4: INFRAESTRUTURA | B4: ='MÃO DE OBRA'!D4 -> 3757428.7 | C4: =B4/B$19 -> 0.061608242 | D4: =B4/ORÇAMENTO_EXECUTIVO!G$2 -> 214.64201
A5: CONTENÇÃO | B5: ='MÃO DE OBRA'!D5 -> 1720862.5 | C5: =B5/B$19 -> 0.028215922 | D5: =B5/ORÇAMENTO_EXECUTIVO!G$2 -> 98.303767
A6: SUPRAESTRUTURA | B6: ='MÃO DE OBRA'!D6 -> 11888495 | C6: =B6/B$19 -> 0.19492833 | D6: =B6/ORÇAMENTO_EXECUTIVO!G$2 -> 679.12682
A7: ALVENARIA | B7: ='MÃO DE OBRA'!D7 -> 2669932.4 | C7: =B7/B$19 -> 0.043777236 | D7: =B7/ORÇAMENTO_EXECUTIVO!G$2 -> 152.51911
A8: INSTALAÇÕES ELÉTRICAS, HIDRÁULICAS, GLP E PREVENTIVAS | B8: ='MÃO DE OBRA'!D8 -> 6824216.5 | C8: =B8/B$19 -> 0.11189247 | D8: =B8/ORÇAMENTO_EXECUTIVO!G$2 -> 389.83137
A9: EQUIPAMENTOS E SISTEMAS ESPECIAIS | B9: ='MÃO DE OBRA'!D9 -> 3389279.9 | C9: =B9/B$19 -> 0.055571933 | D9: =B9/ORÇAMENTO_EXECUTIVO!G$2 -> 193.61162
A10: IMPERMEABILIZAÇÃO | B10: ='MÃO DE OBRA'!D10 -> 963633.78 | C10: =B10/B$19 -> 0.015800109 | D10: =B10/ORÇAMENTO_EXECUTIVO!G$2 -> 55.047298
A11: REVESTIMENTOS INTERNOS EM PISO E PAREDE | B11: ='MÃO DE OBRA'!D11 -> 3955585.1 | C11: =B11/B$19 -> 0.064857291 | D11: =B11/ORÇAMENTO_EXECUTIVO!G$2 -> 225.96164
A12: REVESTIMENTOS E ACABAMENTOS INTERNOS EM TETO | B12: ='MÃO DE OBRA'!D12 -> 1140245.1 | C12: =B12/B$19 -> 0.018695896 | D12: =B12/ORÇAMENTO_EXECUTIVO!G$2 -> 65.136166
A13: ACABAMENTOS EM PISO E PAREDE | B13: ='MÃO DE OBRA'!D13 -> 4304402.1 | C13: =B13/B$19 -> 0.070576628 | D13: =B13/ORÇAMENTO_EXECUTIVO!G$2 -> 245.88771
A14: PINTURA INTERNA | B14: ='MÃO DE OBRA'!D14 -> 2594671 | C14: =B14/B$19 -> 0.042543222 | D14: =B14/ORÇAMENTO_EXECUTIVO!G$2 -> 148.21983
... A18: IMPREVISTOS E CONTINGENCIAS | B18: ='MÃO DE OBRA'!D18 -> 1810898.4 | C18: =B18/B$19 -> 0.029692186 | D18: =B18/ORÇAMENTO_EXECUTIVO!G$2 -> 103.44704
A19: TOTAL | B19: =SUM(B2:B18) -> 60989058 | C19: =SUM(C2:C18) -> 1 | D19: =SUM(D2:D18) -> 3483.9821
A20: CUB/SC | B20: 2965.54 | C20: 45839 | D20: =+D19/B20 -> 1.1748222
A23: Rótulos de Linha | B23: Soma de %
A24: SUPRAESTRUTURA | B24: 0.17808563
A25: INSTALAÇÕES ELÉTRICAS, HIDRÁULICAS, GLP E PREVENTIVAS | B25: 0.10140636
A26: ESQUADRIAS, VIDROS E FERRAGENS | B26: 0.097736624
A27: SERVIÇOS COMPLEMENTARES | B27: 0.065615724
A28: ALVENARIA | B28: 0.064250497
A29: INFRAESTRUTURA | B29: 0.063094854
A30: GERENCIAMENTO TÉCNICO E ADMINISTRATIVO | B30: 0.056178201
A31: ACABAMENTOS EM PISO E PAREDE | B31: 0.056149061
A32: EQUIPAMENTOS E SISTEMAS ESPECIAIS | B32: 0.053398094
A33: REVESTIMENTOS INTERNOS EM PISO E PAREDE | B33: 0.048778735
A34: CONTENÇÃO | B34: 0.043693151
A35: IMPREVISTOS E CONTINGENCIAS | B35: 0.035823183
... A42: Total Geral | B42: 1

Sheet ANÁLISE_CUSTOS VERSÕES
A1: ETAPA | B1: 365 - PRELIMINAR R00 | D1: 365 - PARAMETRICO | F1: 365 PARAMETRICO- INDEXADO | H1: DIFERENÇA
B2: VALOR | C2: VALOR / m² | D2: VALOR | E2: VALOR / m² | F2: VALOR | G2: VALOR / m² | H2: VALOR | I2: VALOR / m²
A3: =ORÇAMENTO_EXECUTIVO!A2 -> GERENCIAMENTO TÉCNICO E ADMINISTRATIVO | B3: =ORÇAMENTO_EXECUTIVO!B2 -> 3894011.7 | C3: =ORÇAMENTO_EXECUTIVO!D2 -> 222.44428 | D3: 3504714.1 | E3: 200.57793 | F3: =D3*$D$80 -> 3651768 | G3: =E3*$D$80 -> 208.99395 | H3: =B3-F3 -> 242243.73 | I3: =C3-G3 -> 13.450333 | J3: Adição de remoção de residuos e aumento do ticket medio da equipe
A4: =ORÇAMENTO_EXECUTIVO!A3 -> MOVIMENTAÇÃO DE TERRA | B4: =ORÇAMENTO_EXECUTIVO!B3 -> 1400464.9 | C4: =ORÇAMENTO_EXECUTIVO!D3 -> 80.001146 | D4: 1364651.1 | E4: 78.100205 | F4: =D4*$D$80 -> 1421910.4 | G4: =E4*$D$80 -> 81.377201 | H4: =B4-F4 -> -21445.489 | I4: =C4-G4 -> -1.3760554 | J4: custos não acompanharam aumento de cub
A5: INFRAESTRUTURA E CONTENÇÃO | B5: =ORÇAMENTO_EXECUTIVO!B4+ORÇAMENTO_EXECUTIVO!B5 -> 5478291.1 | C5: =ORÇAMENTO_EXECUTIVO!D4+ORÇAMENTO_EXECUTIVO!D5 -> 312.94578 | D5: 6317421.7 | E5: 361.55169 | F5: =D5*$D$80 -> 6582493.6 | G5: =E5*$D$80 -> 376.722 | H5: =B5-F5 -> -1104202.4 | I5: =C5-G5 -> -63.776216 | J5: Redução da área de contenção significativaemnte
A6: =ORÇAMENTO_EXECUTIVO!A6 -> SUPRAESTRUTURA | B6: =ORÇAMENTO_EXECUTIVO!B6 -> 11888495 | C6: =ORÇAMENTO_EXECUTIVO!D6 -> 679.12682 | D6: 10402968 | E6: 595.37115 | F6: =D6*$D$80 -> 10839465 | G6: =E6*$D$80 -> 620.35225 | H6: =B6-F6 -> 1049030.7 | I6: =C6-G6 -> 58.774565 | J6: Auemtno volume de concreto e por consequencia aço e aumento nos jogos de formas
A7: =ORÇAMENTO_EXECUTIVO!A7 -> ALVENARIA | B7: =ORÇAMENTO_EXECUTIVO!B7 -> 2669932.4 | C7: =ORÇAMENTO_EXECUTIVO!D7 -> 152.51911 | D7: 2649104.4 | E7: 151.61062 | F7: =D7*$D$80 -> 2760257.9 | G7: =E7*$D$80 -> 157.97203 | H7: =B7-F7 -> -90325.464 | I7: =C7-G7 -> -5.4529187 | J7: custos não acompanharam aumento de cub
A8: =ORÇAMENTO_EXECUTIVO!A8 -> INSTALAÇÕES ELÉTRICAS, HIDRÁULICAS, GLP E PREVENTIVAS | B8: =ORÇAMENTO_EXECUTIVO!B8 -> 6824216.5 | C8: =ORÇAMENTO_EXECUTIVO!D8 -> 389.83137 | D8: 6444580.4 | E8: 368.8291 | F8: =D8*$D$80 -> 6714987.8 | G8: =E8*$D$80 -> 384.30476 | H8: =B8-F8 -> 109228.67 | I8: =C8-G8 -> 5.5266125 | J8: aumento pequeno de louças e metais
A9: =ORÇAMENTO_EXECUTIVO!A9 -> EQUIPAMENTOS E SISTEMAS ESPECIAIS | B9: =ORÇAMENTO_EXECUTIVO!B9 -> 3389279.9 | C9: =ORÇAMENTO_EXECUTIVO!D9 -> 193.61162 | D9: 3372799 | E9: 193.0283 | F9: =D9*$D$80 -> 3514317.9 | G9: =E9*$D$80 -> 201.12756 | H9: =B9-F9 -> -125038 | I9: =C9-G9 -> -7.5159334 | J9: redução de incertezas
A10: =ORÇAMENTO_EXECUTIVO!A10 -> IMPERMEABILIZAÇÃO | B10: =ORÇAMENTO_EXECUTIVO!B10 -> 963633.78 | C10: =ORÇAMENTO_EXECUTIVO!D10 -> 55.047298 | D10: 646680 | E10: 37.010075 | F10: =D10*$D$80 -> 673813.96 | G10: =E10*$D$80 -> 38.562976 | H10: =B10-F10 -> 289819.82 | I10: =C10-G10 -> 16.484322 | J10: mais da distribuição de mo e cobertura
A11: =ORÇAMENTO_EXECUTIVO!A11 -> REVESTIMENTOS INTERNOS EM PISO E PAREDE | B11: =ORÇAMENTO_EXECUTIVO!B11 -> 3955585.1 | C11: =ORÇAMENTO_EXECUTIVO!D11 -> 225.96164 | D11: 3911886.4 | E11: 223.88076 | F11: =D11*$D$80 -> 4076024.7 | G11: =E11*$D$80 -> 233.27454 | H11: =B11-F11 -> -120439.66 | I11: =C11-G11 -> -7.3129004
A12: =ORÇAMENTO_EXECUTIVO!A12 -> REVESTIMENTOS E ACABAMENTOS INTERNOS EM TETO | B12: =ORÇAMENTO_EXECUTIVO!B12 -> 1140245.1 | C12: =ORÇAMENTO_EXECUTIVO!D12 -> 65.136166 | D12: 1954740.9 | E12: 111.87157 | F12: =D12*$D$80 -> 2036759.7 | G12: =E12*$D$80 -> 116.56558 | H12: =B12-F12 -> -896514.6 | I12: =C12-G12 -> -51.429412 | J12: gesso acartonado para mineral e maior proporção de estucamento
A13: =ORÇAMENTO_EXECUTIVO!A13 -> ACABAMENTOS EM PISO E PAREDE | B13: =ORÇAMENTO_EXECUTIVO!B13 -> 4304402.1 | C13: =ORÇAMENTO_EXECUTIVO!D13 -> 245.88771 | D13: 3486357.6 | E13: 199.52736 | F13: =D13*$D$80 -> 3632641.3 | G13: =E13*$D$80 -> 207.89931 | H13: =B13-F13 -> 671760.81 | I13: =C13-G13 -> 37.988401 | J13: troca de ceramica para um porcelanato mias elevado
A14: =ORÇAMENTO_EXECUTIVO!A14 -> PINTURA INTERNA | B14: =ORÇAMENTO_EXECUTIVO!B14 -> 2594671 | C14: =ORÇAMENTO_EXECUTIVO!D14 -> 148.21983 | D14: 2122696.8 | E14: 121.48383 | F14: =D14*$D$80 -> 2211762.7 | G14: =E14*$D$80 -> 126.58116 | H14: =B14-F14 -> 382908.32 | I14: =C14-G14 -> 21.638666
A15: =ORÇAMENTO_EXECUTIVO!A15 -> ESQUADRIAS, VIDROS E FERRAGENS | B15: =ORÇAMENTO_EXECUTIVO!B15 -> 5911420.4 | C15: =ORÇAMENTO_EXECUTIVO!D15 -> 337.68816 | D15: 5968623.2 | E15: 341.58964 | F15: =D15*$D$80 -> 6219059.9 | G15: =E15*$D$80 -> 355.92236 | H15: =B15-F15 -> -307639.55 | I15: =C15-G15 -> -18.234201
A16: COBERTURA | D16: 389789.63 | E16: 22.308009 | F16: =D16*$D$80 -> 406144.76 | G16: =E16*$D$80 -> 23.244028 | H16: =B16-F16 -> -406144.76 | I16: =C16-G16 -> -23.244028
A17: =ORÇAMENTO_EXECUTIVO!A16 -> REVESTIMENTOS E ACABAMENTOS DE FACHADA | B17: =ORÇAMENTO_EXECUTIVO!B16 -> 2143436.7 | C17: =ORÇAMENTO_EXECUTIVO!D16 -> 122.4432 | D17: 1910131.1 | E17: 109.31851 | F17: =D17*$D$80 -> 1990278 | G17: =E17*$D$80 -> 113.90539 | H17: =B17-F17 -> 153158.7 | I17: =C17-G17 -> 8.5378045 | J17: rufo e porcelanato
A18: =ORÇAMENTO_EXECUTIVO!A17 -> SERVIÇOS COMPLEMENTARES | B18: =ORÇAMENTO_EXECUTIVO!B17 -> 2620073.8 | C18: =ORÇAMENTO_EXECUTIVO!D17 -> 149.67095 | D18: 2243441.3 | E18: 128.39415 | F18: =D18*$D$80 -> 2337573.6 | G18: =E18*$D$80 -> 133.78143 | H18: =B18-F18 -> 282500.24 | I18: =C18-G18 -> 15.889524 | J18: perolado e calçada
A19: =ORÇAMENTO_EXECUTIVO!A18 -> IMPREVISTOS E CONTINGENCIAS | B19: =ORÇAMENTO_EXECUTIVO!B18 -> 1810898.4 | C19: =ORÇAMENTO_EXECUTIVO!D18 -> 103.44704 | D19: 2139091.8 | E19: 122.42214 | F19: =D19*$D$80 -> 2228845.7 | G19: =E19*$D$80 -> 127.55883 | H19: =B19-F19 -> -417947.22 | I19: =C19-G19 -> -24.111787
A20: TOTAL | B20: =SUM(B3:B19) -> 60989058 | C20: =SUM(C3:C19) -> 3483.9821 | D20: =SUM(D3:D19) -> 58829677 | E20: =SUM(E3:E19) -> 3366.875 | F20: =SUM(F3:F19) -> 61298104 | G20: =SUM(G3:G19) -> 3508.1453 | H20: =SUM(H3:H19) -> -309046.19 | I20: =SUM(I3:I19) -> -24.163223
A21: CUB/SC | B21: 2965.54 | C21: =C20/B21 -> 1.1748222 | D21: 2846.12 | E21: =E20/D21 -> 1.1829702 | G21: =G20/B21 -> 1.1829702 | I21: =H20/B20 -> -0.00506724
B22: 45839 | D22: 45566
D23: 45566
D24: 2846.12
B25: 2007.57 | D25: =ORÇAMENTO_EXECUTIVO!C20 -> 45839 | F25: 2007.57 | H25: 2007.57
B26: 2461.35 | D26: 2007.57 | F26: 2461.35 | H26: 2461.35
B27: =B26/B25 -> 1.2260345 | D27: 2461.35 | F27: =F26/F25 -> 1.2260345 | H27: =H26/H25 -> 1.2260345
D28: =D27/D26 -> 1.2260345
C30: 1.1023 | E30: 1.1023 | G30: 1.1023 | I30: 1.1023
A32: 900,00 - 1100 | B32: 900 | F32: 900 | H32: 900
A33: 25,00 - 30,00 | B33: 25 | D33: 900 | F33: 25 | H33: 25
A34: 15,00 - 22,00 | B34: 15 | D34: 25 | F34: 15 | H34: 15
A35: 150,00 - 200,00 | B35: 150 | D35: 15 | F35: 150 | H35: 150
A36: 440,00 - 510,00 | B36: 440 | D36: 150 | F36: 440 | H36: 440
A37: - | D37: 440
A38: 55,00 - 70,00 | B38: 55 | F38: 55 | H38: 55
A39: 170,00 - 200,00 | B39: 170 | D39: 55 | F39: 170 | H39: 170
A40: 165,00 - 230,00 | B40: 165 | D40: 170 | F40: 165 | H40: 165
A41: 40,00 - 70,00 | B41: 40 | D41: 165 | F41: 40 | H41: 40
A42: 55,00 - 77,00 | B42: 55 | D42: 40 | F42: 55 | H42: 55
...

Sheet ANÁLISE_CUSTOS
A1: ETAPA | B1: PRELIMINAR | D1: OBRA SIMILAR
B2: VALOR | C2: VALOR / m² | D2: VALOR / m²
A3: =ORÇAMENTO_EXECUTIVO!A3 -> MOVIMENTAÇÃO DE TERRA | B3: =ORÇAMENTO_EXECUTIVO!B3 -> 1400464.9 | C3: =ORÇAMENTO_EXECUTIVO!D3 -> 80.001146 | D3: =FIXED(CÁLCULO_MÉDIAS!AD10,2,FALSE)&" "&"-"&FIXED(CÁLCULO_MÉDIAS!AE10,2,FALSE) -> 80,00 -110,00
A4: INFRAESTRUTURA E CONTENÇÃO | B4: =ORÇAMENTO_EXECUTIVO!B4+ORÇAMENTO_EXECUTIVO!B5 -> 5478291.1 | C4: =ORÇAMENTO_EXECUTIVO!D4+ORÇAMENTO_EXECUTIVO!D5 -> 312.94578 | D4: =FIXED(CÁLCULO_MÉDIAS!AD11,2,FALSE)&" "&"-"&FIXED(CÁLCULO_MÉDIAS!AE11,2,FALSE) -> 310,00 -380,00
A5: =ORÇAMENTO_EXECUTIVO!A6 -> SUPRAESTRUTURA | B5: =ORÇAMENTO_EXECUTIVO!B6 -> 11888495 | C5: =ORÇAMENTO_EXECUTIVO!D6 -> 679.12682 | D5: =FIXED(CÁLCULO_MÉDIAS!AD12,2,FALSE)&" "&"-"&FIXED(CÁLCULO_MÉDIAS!AE12,2,FALSE) -> 693,00 -858,00
A6: =ORÇAMENTO_EXECUTIVO!A7 -> ALVENARIA | B6: =ORÇAMENTO_EXECUTIVO!B7 -> 2669932.4 | C6: =ORÇAMENTO_EXECUTIVO!D7 -> 152.51911 | D6: =FIXED(CÁLCULO_MÉDIAS!AD13,2,FALSE)&" "&"-"&FIXED(CÁLCULO_MÉDIAS!AE13,2,FALSE) -> 143,00 -198,00
A7: =ORÇAMENTO_EXECUTIVO!A8 -> INSTALAÇÕES ELÉTRICAS, HIDRÁULICAS, GLP E PREVENTIVAS | B7: =ORÇAMENTO_EXECUTIVO!B8 -> 6824216.5 | C7: =ORÇAMENTO_EXECUTIVO!D8 -> 389.83137 | D7: =FIXED(CÁLCULO_MÉDIAS!AD14,2,FALSE)&" "&"-"&FIXED(CÁLCULO_MÉDIAS!AE14,2,FALSE) -> 352,00 -473,00
A8: =ORÇAMENTO_EXECUTIVO!A9 -> EQUIPAMENTOS E SISTEMAS ESPECIAIS | B8: =ORÇAMENTO_EXECUTIVO!B9 -> 3389279.9 | C8: =ORÇAMENTO_EXECUTIVO!D9 -> 193.61162 | D8: =FIXED(CÁLCULO_MÉDIAS!AD15,2,FALSE)&" "&"-"&FIXED(CÁLCULO_MÉDIAS!AE15,2,FALSE) -> 154,00 -264,00
A9: =ORÇAMENTO_EXECUTIVO!A10 -> IMPERMEABILIZAÇÃO | B9: =ORÇAMENTO_EXECUTIVO!B10 -> 963633.78 | C9: =ORÇAMENTO_EXECUTIVO!D10 -> 55.047298 | D9: =FIXED(CÁLCULO_MÉDIAS!AD16,2,FALSE)&" "&"-"&FIXED(CÁLCULO_MÉDIAS!AE16,2,FALSE) -> 33,00 -72,00
A10: =ORÇAMENTO_EXECUTIVO!A11 -> REVESTIMENTOS INTERNOS EM PISO E PAREDE | B10: =ORÇAMENTO_EXECUTIVO!B11 -> 3955585.1 | C10: =ORÇAMENTO_EXECUTIVO!D11 -> 225.96164 | D10: =FIXED(CÁLCULO_MÉDIAS!AD17,2,FALSE)&" "&"-"&FIXED(CÁLCULO_MÉDIAS!AE17,2,FALSE) -> 187,00 -242,00
A11: =ORÇAMENTO_EXECUTIVO!A12 -> REVESTIMENTOS E ACABAMENTOS INTERNOS EM TETO | B11: =ORÇAMENTO_EXECUTIVO!B12 -> 1140245.1 | C11: =ORÇAMENTO_EXECUTIVO!D12 -> 65.136166 | D11: =FIXED(CÁLCULO_MÉDIAS!AD18,2,FALSE)&" "&"-"&FIXED(CÁLCULO_MÉDIAS!AE18,2,FALSE) -> 50,00 -80,00
A12: =ORÇAMENTO_EXECUTIVO!A13 -> ACABAMENTOS EM PISO E PAREDE | B12: =ORÇAMENTO_EXECUTIVO!B13 -> 4304402.1 | C12: =ORÇAMENTO_EXECUTIVO!D13 -> 245.88771 | D12: =FIXED(CÁLCULO_MÉDIAS!AD19,2,FALSE)&" "&"-"&FIXED(CÁLCULO_MÉDIAS!AE19,2,FALSE) -> 185,00 -255,00
A13: =ORÇAMENTO_EXECUTIVO!A14 -> PINTURA INTERNA | B13: =ORÇAMENTO_EXECUTIVO!B14 -> 2594671 | C13: =ORÇAMENTO_EXECUTIVO!D14 -> 148.21983 | D13: =FIXED(CÁLCULO_MÉDIAS!AD20,2,FALSE)&" "&"-"&FIXED(CÁLCULO_MÉDIAS!AE20,2,FALSE) -> 110,00 -150,00
A14: =ORÇAMENTO_EXECUTIVO!A15 -> ESQUADRIAS, VIDROS E FERRAGENS | B14: =ORÇAMENTO_EXECUTIVO!B15 -> 5911420.4 | C14: =ORÇAMENTO_EXECUTIVO!D15 -> 337.68816 | D14: =FIXED(CÁLCULO_MÉDIAS!AD21,2,FALSE)&" "&"-"&FIXED(CÁLCULO_MÉDIAS!AE21,2,FALSE) -> 286,00 -418,00
A15: =ORÇAMENTO_EXECUTIVO!A16 -> REVESTIMENTOS E ACABAMENTOS DE FACHADA | B15: =ORÇAMENTO_EXECUTIVO!B16 -> 2143436.7 | C15: =ORÇAMENTO_EXECUTIVO!D16 -> 122.4432 | D15: =FIXED(CÁLCULO_MÉDIAS!AD23,2,FALSE)&" "&"-"&FIXED(CÁLCULO_MÉDIAS!AE23,2,FALSE) -> 110,00 -176,00
A16: =ORÇAMENTO_EXECUTIVO!A17 -> SERVIÇOS COMPLEMENTARES | B16: =ORÇAMENTO_EXECUTIVO!B17 -> 2620073.8 | C16: =ORÇAMENTO_EXECUTIVO!D17 -> 149.67095 | D16: =FIXED(CÁLCULO_MÉDIAS!AD24,2,FALSE)&" "&"-"&FIXED(CÁLCULO_MÉDIAS!AE24,2,FALSE) -> 110,00 -242,00
A17: TOTAL | B17: =SUM(B3:B16) -> 55284148 | C17: =SUM(C3:C16) -> 3158.0908 | D17: =FIXED(CÁLCULO_MÉDIAS!AD25,2,FALSE)&" "&"-"&FIXED(CÁLCULO_MÉDIAS!AE25,2,FALSE) -> 2.816,00 -3.940,00
B21: 2007.57
B22: 2461.35
B23: =B22/B21 -> 1.2260345
C26: 1.1023
A28: 900,00 - 1100 | B28: 900
A29: 25,00 - 30,00 | B29: 25
A30: 15,00 - 22,00 | B30: 15
A31: 150,00 - 200,00 | B31: 150
A32: 440,00 - 510,00 | B32: 440
A33: -
A34: 55,00 - 70,00 | B34: 55
A35: 170,00 - 200,00 | B35: 170
A36: 165,00 - 230,00 | B36: 165
A37: 40,00 - 70,00 | B37: 40
A38: 55,00 - 77,00 | B38: 55
A39: 35,00 - 50,00 | B39: 35
A40: 130,00 - 175,00 | B40: 130
A41: 35,00 - 65,00 | B41: 35
A42: 35,00 - 55,00 | B42: 35
A43: 430,00 - 550,00 | B43: 430
A44: 35,00 - 50,00 | B44: 35
A45: 150,00 - 220,00 | B45: 150

Sheet AREA PRIVATIVA
B2: DESCRIÇÃO | C2: AREA (m²) | D2: VALOR TOTAL | I2: DESCRIÇÃO | J2: AREA (m²) | K2: VALOR TOTAL
B3: VALOR POR ÁREA PRIVATIVA (R$/m²) | C3: 9906.44 | D3: =ORÇAMENTO_EXECUTIVO!$B$19/'AREA PRIVATIVA'!C3 -> 6156.5061 | G3: =C3/ORÇAMENTO_EXECUTIVO!G2 -> 0.56590249 | I3: VALOR POR ÁREA PRIVATIVA (R$/m²) | K3: =ORÇAMENTO_EXECUTIVO!$B$19/'AREA PRIVATIVA'!J3 -> #DIV/0!
B4: VALOR MÉDIO POR UNIDADE RESIDENCIAL + COMERCIAL | C4: 176+4 un | D4: =ORÇAMENTO_EXECUTIVO!B19/(176+4) -> 338828.1
B5: TIPO 1A | C5: 38.0689 | D5: =C5*$D$3 -> 234371.41 | I5: LOJA | K5: =J5*$D$3 -> 0
B6: TIPO 1B | C6: 38.3317 | D6: =C6*$D$3 -> 235989.34 | I6: SALA COMERCIAL 1 | K6: =J6*$D$3 -> 0
B7: TIPO 2 | C7: 43.8075 | D7: =C7*$D$3 -> 269701.14 | I7: SALA COMERCIAL 2 | K7: =J7*$D$3 -> 0
B8: TIPO 3 | C8: 35.7102 | D8: =C8*$D$3 -> 219850.06 | I8: SALA COMERCIAL 3 | K8: =J8*$D$3 -> 0
B9: TIPO 4 | C9: 81.29 | D9: =C9*$D$3 -> 500462.38
B10: TIPO 5 | C10: 75.11 | D10: =C10*$D$3 -> 462415.17 | J10: =J5+J6+J7+J8 -> 0
B11: TIPO 6 | C11: 79.9135 | D11: =C11*$D$3 -> 491987.95
B12: AREA COMERCIAL | C12: =C3-9026.89 -> 879.55 | D12: =C12*$D$3 -> 5414954.9
B15: AREA COMERCIAL | D15: =C15*$D$3 -> 0
B21: DESCRIÇÃO | C21: QUANT | D21: ÁREA | E21: TIPO | F21: DORM | G21: W.C.
B22: TIPO 1A | C22: 40 | D22: 38.0689 | E22: STUDIO | G22: 1
B23: TIPO 1B | C23: 40 | D23: 38.3317 | E23: STUDIO | G23: 1
B24: TIPO 2 | C24: 22 | D24: 43.8075 | E24: KIT | F24: 1 | G24: 1
B25: TIPO 3 | C25: 18 | D25: 35.7102 | E25: STUDIO | G25: 1
B26: TIPO 4 | C26: 4 | D26: 81.29 | E26: APTO 2 DORM | F26: 2 | G26: 2
B27: TIPO 5 | C27: 3 | D27: 75.11 | E27: APTO 2 DORM | F27: 2 | G27: 3
B28: TIPO 6 | C28: 2 | D28: 79.9135 | E28: APTO 2 DORM | F28: 2 | G28: 2 | H28: Terraço
C29: =SUM(C22:C28) -> 129 | D29: =SUMPRODUCT($C$22:$C$28,D22:D28) -> 5372.8896 | F29: =SUMPRODUCT($C$22:$C$28,F22:F28) -> 40 | G29: =SUMPRODUCT($C$22:$C$28,G22:G28) -> 141

Sheet CÁLCULO_MÉDIAS
C3: DATA BASE | D3: 44805 | E3: DATA BASE | F3: 45047 | G3: DATA BASE | H3: 44409 | I3: DATA BASE | J3: 44621 | K3: DATA BASE | L3: 44652 | M3: DATA BASE | N3: 45017 | O3: DATA BASE | P3: 44652 | Q3: DATA BASE | R3: 44958 | S3: DATA BASE | T3: 44958 | U3: DATA BASE | V3: 44927 | W3: DATA BASE | X3: 45383 | Y3: DATA BASE | Z3: 44805 | AA3: DATA BASE | AB3: 45566
C4: CUB | D4: 2623.42 | E4: CUB | F4: 2680.84 | G4: CUB | H4: 2329.85 | I4: CUB | J4: 2444.3 | K4: CUB | L4: 2461.35 | M4: CUB | N4: 2680.84 | O4: CUB | P4: 2461.35 | Q4: CUB | R4: 2662.47 | S4: CUB | T4: 2662.47 | U4: CUB | V4: 2651.17 | W4: CUB | X4: 2757.56 | Y4: CUB | Z4: 2623.42 | AA4: CUB | AB4: 2846.12
C5: INDICE | D5: =ORÇAMENTO_EXECUTIVO!$B$20/CÁLCULO_MÉDIAS!D4 -> 1.1304099 | E5: INDICE | F5: =ORÇAMENTO_EXECUTIVO!$B$20/CÁLCULO_MÉDIAS!F4 -> 1.1061981 | G5: INDICE | H5: =ORÇAMENTO_EXECUTIVO!$B$20/CÁLCULO_MÉDIAS!H4 -> 1.2728459 | I5: INDICE | J5: =ORÇAMENTO_EXECUTIVO!$B$20/CÁLCULO_MÉDIAS!J4 -> 1.2132471 | K5: INDICE | L5: =ORÇAMENTO_EXECUTIVO!$B$20/CÁLCULO_MÉDIAS!L4 -> 1.2048429 | M5: INDICE | N5: =ORÇAMENTO_EXECUTIVO!$B$20/CÁLCULO_MÉDIAS!N4 -> 1.1061981 | O5: INDICE | P5: =ORÇAMENTO_EXECUTIVO!$B$20/CÁLCULO_MÉDIAS!P4 -> 1.2048429 | Q5: INDICE | R5: =ORÇAMENTO_EXECUTIVO!$B$20/CÁLCULO_MÉDIAS!R4 -> 1.1138304 | S5: INDICE | T5: =ORÇAMENTO_EXECUTIVO!$B$20/CÁLCULO_MÉDIAS!T4 -> 1.1138304 | U5: INDICE | V5: =ORÇAMENTO_EXECUTIVO!$B$20/CÁLCULO_MÉDIAS!V4 -> 1.1185778 | W5: INDICE | X5: =ORÇAMENTO_EXECUTIVO!$B$20/CÁLCULO_MÉDIAS!X4 -> 1.0754217 | Y5: INDICE | Z5: =ORÇAMENTO_EXECUTIVO!$B$20/CÁLCULO_MÉDIAS!Z4 -> 1.1304099 | AA5: INDICE | AB5: =ORÇAMENTO_EXECUTIVO!$B$20/CÁLCULO_MÉDIAS!AB4 -> 1.0419589
C7: BELISSIMO | E7: CELEBRATION | G7: BARÃO DE ALBUQUERQUE | I7: VANCOUVER | K7: ONE PALACE | M7: AS RAMOS | O7: MENDES - BRAVA MUNDO | Q7: COSTÃO DO SANTINHO | S7: LUMIS - LIVE | U7: M VILLAGE | W7: GRAN TOWER | Y7: NOUVE 354 | AA7: 365 | AD7: MÉDIAS
C8: VALOR / M2 | D8: INDEXADO | E8: VALOR / M2 | F8: INDEXADO | G8: VALOR / M2 | H8: INDEXADO | I8: VALOR / M2 | J8: INDEXADO | K8: VALOR / M2 | L8: INDEXADO | M8: VALOR / M2 | N8: INDEXADO | O8: VALOR / M2 | P8: INDEXADO | Q8: VALOR / M2 | R8: INDEXADO | S8: VALOR / M2 | T8: INDEXADO | U8: VALOR / M2 | V8: INDEXADO | W8: VALOR / M2 | X8: INDEXADO | Y8: VALOR / M2 | Z8: INDEXADO | AA8: VALOR / M2 | AB8: INDEXADO | AD8: MÍNIMA | AE8: MÁXIMA
B9: GERENCIAMENTO TECNICO E ADMINISTRATIVO | C9: 228.969 | D9: =ORÇAMENTO_EXECUTIVO!$B$20/CÁLCULO_MÉDIAS!D$4*C9 -> 258.82882 | E9: 158.50958 | F9: =ORÇAMENTO_EXECUTIVO!$B$20/CÁLCULO_MÉDIAS!F$4*E9 -> 175.34299 | G9: 320.9214 | H9: =ORÇAMENTO_EXECUTIVO!$B$20/CÁLCULO_MÉDIAS!H$4*G9 -> 408.48349 | I9: 287.62009 | J9: =ORÇAMENTO_EXECUTIVO!$B$20/CÁLCULO_MÉDIAS!J$4*I9 -> 348.95425 | K9: 281.42632 | L9: =ORÇAMENTO_EXECUTIVO!$B$20/CÁLCULO_MÉDIAS!L$4*K9 -> 339.0745 | M9: 263.25798 | N9: =ORÇAMENTO_EXECUTIVO!$B$20/CÁLCULO_MÉDIAS!N$4*M9 -> 291.21547 | O9: 647.1 | P9: =$P$5*O9 -> 779.65382 | Q9: 446.32712 | R9: =ORÇAMENTO_EXECUTIVO!$B$20/CÁLCULO_MÉDIAS!R$4*Q9 -> 497.13271 | S9: 192.5376 | T9: =ORÇAMENTO_EXECUTIVO!$B$20/CÁLCULO_MÉDIAS!T$4*S9 -> 214.45423 | U9: 400.33008 | V9: =ORÇAMENTO_EXECUTIVO!$B$20/CÁLCULO_MÉDIAS!V$4*U9 -> 447.80035 | W9: 744.07978 | X9: =ORÇAMENTO_EXECUTIVO!$B$20/CÁLCULO_MÉDIAS!X$4*W9 -> 800.19957 | Y9: 487.93175 | Z9: =ORÇAMENTO_EXECUTIVO!$B$20/CÁLCULO_MÉDIAS!Z$4*Y9 -> 551.56289 | AA9: 200.57793 | AB9: =ORÇAMENTO_EXECUTIVO!$B$20/CÁLCULO_MÉDIAS!AB$4*AA9 -> 208.99395 | AC9: 200 | AD9: =ROUND(AC9*1.1,0) -> 220 | AE9: =ROUND(AF9*1.1,0) -> 385 | AF9: 350
B10: MOVIMENTAÇÃO DE TERRA | C10: 10.059586 | D10: =ORÇAMENTO_EXECUTIVO!$B$20/CÁLCULO_MÉDIAS!D$4*C10 -> 11.371456 | E10: 12.392262 | F10: =ORÇAMENTO_EXECUTIVO!$B$20/CÁLCULO_MÉDIAS!F$4*E10 -> 13.708296 | G10: 5.6355099 | H10: =ORÇAMENTO_EXECUTIVO!$B$20/CÁLCULO_MÉDIAS!H$4*G10 -> 7.1731357 | I10: 19.883589 | J10: =ORÇAMENTO_EXECUTIVO!$B$20/CÁLCULO_MÉDIAS!J$4*I10 -> 24.123708 | K10: 6.2112129 | L10: =ORÇAMENTO_EXECUTIVO!$B$20/CÁLCULO_MÉDIAS!L$4*K10 -> 7.4835355 | M10: 26.515285 | N10: =ORÇAMENTO_EXECUTIVO!$B$20/CÁLCULO_MÉDIAS!N$4*M10 -> 29.331157 | O10: 93.34 | P10: =$P$5*O10 -> 112.46003 | Q10: 97.490109 | R10: =ORÇAMENTO_EXECUTIVO!$B$20/CÁLCULO_MÉDIAS!R$4*Q10 -> 108.58745 | S10: 131.35298 | T10: =ORÇAMENTO_EXECUTIVO!$B$20/CÁLCULO_MÉDIAS!T$4*S10 -> 146.30494 | U10: 73.603581 | V10: =ORÇAMENTO_EXECUTIVO!$B$20/CÁLCULO_MÉDIAS!V$4*U10 -> 82.331335 | W10: 72.150818 | X10: =ORÇAMENTO_EXECUTIVO!$B$20/CÁLCULO_MÉDIAS!X$4*W10 -> 77.592559 | Y10: 12.078623 | Z10: =ORÇAMENTO_EXECUTIVO!$B$20/CÁLCULO_MÉDIAS!Z$4*Y10 -> 13.653795 | AA10: 78.100205 | AB10: =ORÇAMENTO_EXECUTIVO!$B$20/CÁLCULO_MÉDIAS!AB$4*AA10 -> 81.377201 | AC10: 80 | AD10: 80 | AE10: 110 | AF10: 110
B11: INFRAESTRUTURA+CONTENÇÃO | C11: 167.14434 | D11: =ORÇAMENTO_EXECUTIVO!$B$20/CÁLCULO_MÉDIAS!D$4*C11 -> 188.94162 | E11: 108.74598 | F11: =ORÇAMENTO_EXECUTIVO!$B$20/CÁLCULO_MÉDIAS!F$4*E11 -> 120.29459 | G11: 124.41721 | H11: =ORÇAMENTO_EXECUTIVO!$B$20/CÁLCULO_MÉDIAS!H$4*G11 -> 158.36394 | I11: 139.84147 | J11: =ORÇAMENTO_EXECUTIVO!$B$20/CÁLCULO_MÉDIAS!J$4*I11 -> 169.66227 | K11: 113.54018 | L11: =ORÇAMENTO_EXECUTIVO!$B$20/CÁLCULO_MÉDIAS!L$4*K11 -> 136.79807 | M11: 309.92994 | N11: =ORÇAMENTO_EXECUTIVO!$B$20/CÁLCULO_MÉDIAS!N$4*M11 -> 342.8439 | O11: 316.11 | P11: =$P$5*O11 -> 380.86288 | Q11: 261.81 | R11: =ORÇAMENTO_EXECUTIVO!$B$20/CÁLCULO_MÉDIAS!R$4*Q11 -> 291.61193 | S11: 99.325701 | T11: =ORÇAMENTO_EXECUTIVO!$B$20/CÁLCULO_MÉDIAS!T$4*S11 -> 110.63198 | U11: 475.11878 | V11: =ORÇAMENTO_EXECUTIVO!$B$20/CÁLCULO_MÉDIAS!V$4*U11 -> 531.45734 | W11: 291.7423 | X11: =ORÇAMENTO_EXECUTIVO!$B$20/CÁLCULO_MÉDIAS!X$4*W11 -> 313.74601 | Y11: 157.74779 | Z11: =ORÇAMENTO_EXECUTIVO!$B$20/CÁLCULO_MÉDIAS!Z$4*Y11 -> 178.31967 | AA11: 361.55169 | AB11: =ORÇAMENTO_EXECUTIVO!$B$20/CÁLCULO_MÉDIAS!AB$4*AA11 -> 376.722 | AD11: 310 | AE11: 380
B12: SUPRAESTRUTURA | C12: 350.58818 | D12: =ORÇAMENTO_EXECUTIVO!$B$20/CÁLCULO_MÉDIAS!D$4*C12 -> 396.30836 | E12: 761.96986 | F12: =ORÇAMENTO_EXECUTIVO!$B$20/CÁLCULO_MÉDIAS!F$4*E12 -> 842.88958 | G12: 617.18899 | H12: =ORÇAMENTO_EXECUTIVO!$B$20/CÁLCULO_MÉDIAS!H$4*G12 -> 785.58646 | I12: 698.52393 | J12: =ORÇAMENTO_EXECUTIVO!$B$20/CÁLCULO_MÉDIAS!J$4*I12 -> 847.48217 | K12: 640.53849 | L12: =ORÇAMENTO_EXECUTIVO!$B$20/CÁLCULO_MÉDIAS!L$4*K12 -> 771.74824 | M12: 776.71351 | N12: =ORÇAMENTO_EXECUTIVO!$B$20/CÁLCULO_MÉDIAS!N$4*M12 -> 859.19898 | O12: 749.05 | P12: =$P$5*O12 -> 902.48755 | Q12: 698.98267 | R12: =ORÇAMENTO_EXECUTIVO!$B$20/CÁLCULO_MÉDIAS!R$4*Q12 -> 778.54814 | S12: 670.8352 | T12: =ORÇAMENTO_EXECUTIVO!$B$20/CÁLCULO_MÉDIAS!T$4*S12 -> 747.19664 | U12: 724.13886 | V12: =ORÇAMENTO_EXECUTIVO!$B$20/CÁLCULO_MÉDIAS!V$4*U12 -> 810.00568 | W12: 1362.2978 | X12: =ORÇAMENTO_EXECUTIVO!$B$20/CÁLCULO_MÉDIAS!X$4*W12 -> 1465.0447 | Y12: 578.45426 | Z12: =ORÇAMENTO_EXECUTIVO!$B$20/CÁLCULO_MÉDIAS!Z$4*Y12 -> 653.89044 | AA12: 595.37115 | AB12: =ORÇAMENTO_EXECUTIVO!$B$20/CÁLCULO_MÉDIAS!AB$4*AA12 -> 620.35225 | AD12: =630*1.1 -> 693 | AE12: =780*1.1 -> 858
B13: ALVENARIA | C13: 180.1426 | D13: =ORÇAMENTO_EXECUTIVO!$B$20/CÁLCULO_MÉDIAS!D$4*C13 -> 203.63498 | E13: 161.08825 | F13: =ORÇAMENTO_EXECUTIVO!$B$20/CÁLCULO_MÉDIAS!F$4*E13 -> 178.19551 | G13: 108.56391 | H13: =ORÇAMENTO_EXECUTIVO!$B$20/CÁLCULO_MÉDIAS!H$4*G13 -> 138.18512 | I13: 139.69907 | J13: =ORÇAMENTO_EXECUTIVO!$B$20/CÁLCULO_MÉDIAS!J$4*I13 -> 169.4895 | K13: 124.50957 | L13: =ORÇAMENTO_EXECUTIVO!$B$20/CÁLCULO_MÉDIAS!L$4*K13 -> 150.01447 | M13: 98.69403 | N13: =ORÇAMENTO_EXECUTIVO!$B$20/CÁLCULO_MÉDIAS!N$4*M13 -> 109.17514 | O13: 151.59 | P13: =$P$5*O13 -> 182.64213 | Q13: 160.86391 | R13: =ORÇAMENTO_EXECUTIVO!$B$20/CÁLCULO_MÉDIAS!R$4*Q13 -> 179.17512 | S13: 151.38702 | T13: =ORÇAMENTO_EXECUTIVO!$B$20/CÁLCULO_MÉDIAS!T$4*S13 -> 168.61946 | U13: 168.13978 | V13: =ORÇAMENTO_EXECUTIVO!$B$20/CÁLCULO_MÉDIAS!V$4*U13 -> 188.07743 | W13: 272.22542 | X13: =ORÇAMENTO_EXECUTIVO!$B$20/CÁLCULO_MÉDIAS!X$4*W13 -> 292.75714 | Y13: 112.59325 | Z13: =ORÇAMENTO_EXECUTIVO!$B$20/CÁLCULO_MÉDIAS!Z$4*Y13 -> 127.27652 | AA13: 151.61062 | AB13: =ORÇAMENTO_EXECUTIVO!$B$20/CÁLCULO_MÉDIAS!AB$4*AA13 -> 157.97203 | AC13: 130 | AD13: =ROUND(AC13*1.1,0) -> 143 | AE13: =ROUND(AF13*1.1,0) -> 198 | AF13: 180
B14: INSTALAÇÕES ELÉTRICAS, HIDRÁULICAS, GLP E PREVENTIVAS | C14: 208.77218 | D14: =ORÇAMENTO_EXECUTIVO!$B$20/CÁLCULO_MÉDIAS!D$4*C14 -> 235.99815 | E14: 310.24178 | F14: =ORÇAMENTO_EXECUTIVO!$B$20/CÁLCULO_MÉDIAS!F$4*E14 -> 343.18885 | G14: 266.66808 | H14: =ORÇAMENTO_EXECUTIVO!$B$20/CÁLCULO_MÉDIAS!H$4*G14 -> 339.42737 | I14: 273.46067 | J14: =ORÇAMENTO_EXECUTIVO!$B$20/CÁLCULO_MÉDIAS!J$4*I14 -> 331.77538 | K14: 333.98698 | L14: =ORÇAMENTO_EXECUTIVO!$B$20/CÁLCULO_MÉDIAS!L$4*K14 -> 402.40183 | M14: 252.23203 | N14: =ORÇAMENTO_EXECUTIVO!$B$20/CÁLCULO_MÉDIAS!N$4*M14 -> 279.01858 | O14: 374.08 | P14: =$P$5*O14 -> 450.70762 | Q14: 431.14601 | R14: =ORÇAMENTO_EXECUTIVO!$B$20/CÁLCULO_MÉDIAS!R$4*Q14 -> 480.22353 | S14: 301.65243 | T14: =ORÇAMENTO_EXECUTIVO!$B$20/CÁLCULO_MÉDIAS!T$4*S14 -> 335.98964 | U14: 319.4673 | V14: =ORÇAMENTO_EXECUTIVO!$B$20/CÁLCULO_MÉDIAS!V$4*U14 -> 357.34904 | W14: 604.82909 | X14: =ORÇAMENTO_EXECUTIVO!$B$20/CÁLCULO_MÉDIAS!X$4*W14 -> 650.44636 | Y14: 240.74097 | Z14: =ORÇAMENTO_EXECUTIVO!$B$20/CÁLCULO_MÉDIAS!Z$4*Y14 -> 272.13598 | AA14: 368.8291 | AB14: =ORÇAMENTO_EXECUTIVO!$B$20/CÁLCULO_MÉDIAS!AB$4*AA14 -> 384.30476 | AC14: 320 | AD14: =ROUND(AC14*1.1,0) -> 352 | AE14: =ROUND(AF14*1.1,0) -> 473 | AF14: 430
B15: EQUIPAMENTOS E SISTEMAS ESPECIAIS | C15: 111.62697 | D15: =ORÇAMENTO_EXECUTIVO!$B$20/CÁLCULO_MÉDIAS!D$4*C15 -> 126.18424 | F15: =ORÇAMENTO_EXECUTIVO!$B$20/CÁLCULO_MÉDIAS!F$4*E15 -> 0 | G15: 192.58192 | H15: =ORÇAMENTO_EXECUTIVO!$B$20/CÁLCULO_MÉDIAS!H$4*G15 -> 245.12711 | I15: 204.14545 | J15: =ORÇAMENTO_EXECUTIVO!$B$20/CÁLCULO_MÉDIAS!J$4*I15 -> 247.67888 | K15: 187.87175 | L15: =ORÇAMENTO_EXECUTIVO!$B$20/CÁLCULO_MÉDIAS!L$4*K15 -> 226.35594 | M15: 247.28447 | N15: =ORÇAMENTO_EXECUTIVO!$B$20/CÁLCULO_MÉDIAS!N$4*M15 -> 273.5456 | O15: 277.64 | P15: =$P$5*O15 -> 334.51257 | Q15: 224.83791 | R15: =ORÇAMENTO_EXECUTIVO!$B$20/CÁLCULO_MÉDIAS!R$4*Q15 -> 250.4313 | S15: 121.62815 | T15: =ORÇAMENTO_EXECUTIVO!$B$20/CÁLCULO_MÉDIAS!T$4*S15 -> 135.47313 | U15: 126.03404 | V15: =ORÇAMENTO_EXECUTIVO!$B$20/CÁLCULO_MÉDIAS!V$4*U15 -> 140.97889 | W15: 438.9906 | X15: =ORÇAMENTO_EXECUTIVO!$B$20/CÁLCULO_MÉDIAS!X$4*W15 -> 472.10004 | Y15: 244.07509 | Z15: =ORÇAMENTO_EXECUTIVO!$B$20/CÁLCULO_MÉDIAS!Z$4*Y15 -> 275.9049 | AA15: 193.0283 | AB15: =ORÇAMENTO_EXECUTIVO!$B$20/CÁLCULO_MÉDIAS!AB$4*AA15 -> 201.12756 | AC15: 140 | AD15: =ROUND(AC15*1.1,0) -> 154 | AE15: =ROUND(AF15*1.1,0) -> 264 | AF15: 240
B16: IMPERMEABILIZAÇÃO | C16: 16.630694 | D16: =ORÇAMENTO_EXECUTIVO!$B$20/CÁLCULO_MÉDIAS!D$4*C16 -> 18.799502 | E16: 48.175292 | F16: =ORÇAMENTO_EXECUTIVO!$B$20/CÁLCULO_MÉDIAS!F$4*E16 -> 53.291415 | G16: 25.029614 | H16: =ORÇAMENTO_EXECUTIVO!$B$20/CÁLCULO_MÉDIAS!H$4*G16 -> 31.858841 | I16: 16.719234 | J16: =ORÇAMENTO_EXECUTIVO!$B$20/CÁLCULO_MÉDIAS!J$4*I16 -> 20.284563 | K16: 16.045568 | L16: =ORÇAMENTO_EXECUTIVO!$B$20/CÁLCULO_MÉDIAS!L$4*K16 -> 19.332388 | M16: 50.859372 | N16: =ORÇAMENTO_EXECUTIVO!$B$20/CÁLCULO_MÉDIAS!N$4*M16 -> 56.260539 | O16: 61.96 | P16: =$P$5*O16 -> 74.652064 | Q16: 79.544459 | R16: =ORÇAMENTO_EXECUTIVO!$B$20/CÁLCULO_MÉDIAS!R$4*Q16 -> 88.599036 | S16: 61.191658 | T16: =ORÇAMENTO_EXECUTIVO!$B$20/CÁLCULO_MÉDIAS!T$4*S16 -> 68.157128 | U16: 88.819904 | V16: =ORÇAMENTO_EXECUTIVO!$B$20/CÁLCULO_MÉDIAS!V$4*U16 -> 99.351976 | W16: 127.43889 | X16: =ORÇAMENTO_EXECUTIVO!$B$20/CÁLCULO_MÉDIAS!X$4*W16 -> 137.05056 | Y16: 45.575749 | Z16: =ORÇAMENTO_EXECUTIVO!$B$20/CÁLCULO_MÉDIAS!Z$4*Y16 -> 51.519279 | AA16: 37.010075 | AB16: =ORÇAMENTO_EXECUTIVO!$B$20/CÁLCULO_MÉDIAS!AB$4*AA16 -> 38.562976 | AC16: 30 | AD16: =ROUND(AC16*1.1,0) -> 33 | AE16: =ROUND(AF16*1.1,0) -> 72 | AF16: 65
B17: REVESTIMENTOS INTERNOS EM PISO E PAREDE | C17: 99.615058 | D17: =ORÇAMENTO_EXECUTIVO!$B$20/CÁLCULO_MÉDIAS!D$4*C17 -> 112.60585 | E17: 120.22823 | F17: =ORÇAMENTO_EXECUTIVO!$B$20/CÁLCULO_MÉDIAS!F$4*E17 -> 132.99623 | G17: 93.008633 | H17: =ORÇAMENTO_EXECUTIVO!$B$20/CÁLCULO_MÉDIAS!H$4*G17 -> 118.38566 | I17: 116.1494 | J17: =ORÇAMENTO_EXECUTIVO!$B$20/CÁLCULO_MÉDIAS!J$4*I17 -> 140.91792 | K17: 115.30953 | L17: =ORÇAMENTO_EXECUTIVO!$B$20/CÁLCULO_MÉDIAS!L$4*K17 -> 138.92986 | M17: 186.96494 | N17: =ORÇAMENTO_EXECUTIVO!$B$20/CÁLCULO_MÉDIAS!N$4*M17 -> 206.82026 | O17: 94.96 | P17: =$P$5*O17 -> 114.41188 | Q17: 174.86802 | R17: =ORÇAMENTO_EXECUTIVO!$B$20/CÁLCULO_MÉDIAS!R$4*Q17 -> 194.77332 | S17: 161.7371 | T17: =ORÇAMENTO_EXECUTIVO!$B$20/CÁLCULO_MÉDIAS!T$4*S17 -> 180.1477 | U17: 208.78186 | V17: =ORÇAMENTO_EXECUTIVO!$B$20/CÁLCULO_MÉDIAS!V$4*U17 -> 233.53876 | W17: 323.39785 | X17: =ORÇAMENTO_EXECUTIVO!$B$20/CÁLCULO_MÉDIAS!X$4*W17 -> 347.78909 | Y17: 177.78961 | Z17: =ORÇAMENTO_EXECUTIVO!$B$20/CÁLCULO_MÉDIAS!Z$4*Y17 -> 200.97514 | AA17: 223.88076 | AB17: =ORÇAMENTO_EXECUTIVO!$B$20/CÁLCULO_MÉDIAS!AB$4*AA17 -> 233.27454 | AC17: 170 | AD17: =ROUND(AC17*1.1,0) -> 187 | AE17: =ROUND(AF17*1.1,0) -> 242 | AF17: 220
B18: REVESTIMENTOS E ACABAMENTOS INTERNOS EM TETO | C18: 25.636019 | D18: =ORÇAMENTO_EXECUTIVO!$B$20/CÁLCULO_MÉDIAS!D$4*C18 -> 28.97921 | E18: 60.615435 | F18: =ORÇAMENTO_EXECUTIVO!$B$20/CÁLCULO_MÉDIAS!F$4*E18 -> 67.052677 | G18: 68.03556 | H18: =ORÇAMENTO_EXECUTIVO!$B$20/CÁLCULO_MÉDIAS!H$4*G18 -> 86.598784 | I18: 41.89188 | J18: =ORÇAMENTO_EXECUTIVO!$B$20/CÁLCULO_MÉDIAS!J$4*I18 -> 50.825204 | K18: 56.158883 | L18: =ORÇAMENTO_EXECUTIVO!$B$20/CÁLCULO_MÉDIAS!L$4*K18 -> 67.66263 | M18: 63.568288 | N18: =ORÇAMENTO_EXECUTIVO!$B$20/CÁLCULO_MÉDIAS!N$4*M18 -> 70.319117 | O18: 59.11 | P18: =$P$5*O18 -> 71.218262 | Q18: 58.787436 | R18: =ORÇAMENTO_EXECUTIVO!$B$20/CÁLCULO_MÉDIAS!R$4*Q18 -> 65.479232 | S18: 38.140863 | T18: =ORÇAMENTO_EXECUTIVO!$B$20/CÁLCULO_MÉDIAS!T$4*S18 -> 42.482453 | U18: 69.865565 | V18: =ORÇAMENTO_EXECUTIVO!$B$20/CÁLCULO_MÉDIAS!V$4*U18 -> 78.150073 | W18: 112.85164 | X18: =ORÇAMENTO_EXECUTIVO!$B$20/CÁLCULO_MÉDIAS!X$4*W18 -> 121.36311 | Y18: 48.608027 | Z18: =ORÇAMENTO_EXECUTIVO!$B$20/CÁLCULO_MÉDIAS!Z$4*Y18 -> 54.946996 | AA18: 111.87157 | AB18: =ORÇAMENTO_EXECUTIVO!$B$20/CÁLCULO_MÉDIAS!AB$4*AA18 -> 116.56558 | AC18: 80 | AD18: 50 | AE18: 80 | AF18: 110
B19: ACABAMENTOS EM PISO E PAREDE | C19: 143.31445 | D19: =ORÇAMENTO_EXECUTIVO!$B$20/CÁLCULO_MÉDIAS!D$4*C19 -> 162.00407 | E19: 180.49982 | F19: =ORÇAMENTO_EXECUTIVO!$B$20/CÁLCULO_MÉDIAS!F$4*E19 -> 199.66855 | G19: 149.11808 | H19: =ORÇAMENTO_EXECUTIVO!$B$20/CÁLCULO_MÉDIAS!H$4*G19 -> 189.80433 | I19: 167.57897 | J19: =ORÇAMENTO_EXECUTIVO!$B$20/CÁLCULO_MÉDIAS!J$4*I19 -> 203.31471 | K19: 173.07743 | L19: =ORÇAMENTO_EXECUTIVO!$B$20/CÁLCULO_MÉDIAS!L$4*K19 -> 208.53111 | M19: 185.49679 | N19: =ORÇAMENTO_EXECUTIVO!$B$20/CÁLCULO_MÉDIAS!N$4*M19 -> 205.19619 | O19: 221.98 | P19: =$P$5*O19 -> 267.45102 | Q19: 239.48072 | R19: =ORÇAMENTO_EXECUTIVO!$B$20/CÁLCULO_MÉDIAS!R$4*Q19 -> 266.7409 | S19: 233.49804 | T19: =ORÇAMENTO_EXECUTIVO!$B$20/CÁLCULO_MÉDIAS!T$4*S19 -> 260.07721 | U19: 169.91386 | V19: =ORÇAMENTO_EXECUTIVO!$B$20/CÁLCULO_MÉDIAS!V$4*U19 -> 190.06187 | W19: 430.44909 | X19: =ORÇAMENTO_EXECUTIVO!$B$20/CÁLCULO_MÉDIAS!X$4*W19 -> 462.91432 | Y19: 198.16454 | Z19: =ORÇAMENTO_EXECUTIVO!$B$20/CÁLCULO_MÉDIAS!Z$4*Y19 -> 224.00717 | AA19: 199.52736 | AB19: =ORÇAMENTO_EXECUTIVO!$B$20/CÁLCULO_MÉDIAS!AB$4*AA19 -> 207.89931 | AD19: 185 | AE19: 255
B20: PINTURA INTERNA | C20: 78.866728 | D20: =ORÇAMENTO_EXECUTIVO!$B$20/CÁLCULO_MÉDIAS!D$4*C20 -> 89.151732 | E20: 114.52019 | F20: =ORÇAMENTO_EXECUTIVO!$B$20/CÁLCULO_MÉDIAS!F$4*E20 -> 126.68201 | G20: 105.18524 | H20: =ORÇAMENTO_EXECUTIVO!$B$20/CÁLCULO_MÉDIAS!H$4*G20 -> 133.88461 | I20: 102.5452 | J20: =ORÇAMENTO_EXECUTIVO!$B$20/CÁLCULO_MÉDIAS!J$4*I20 -> 124.41267 | K20: 88.941826 | L20: =ORÇAMENTO_EXECUTIVO!$B$20/CÁLCULO_MÉDIAS!L$4*K20 -> 107.16092 | M20: 133.62135 | N20: =ORÇAMENTO_EXECUTIVO!$B$20/CÁLCULO_MÉDIAS!N$4*M20 -> 147.81167 | O20: 88.9 | P20: =$P$5*O20 -> 107.11053 | Q20: 110.42908 | R20: =ORÇAMENTO_EXECUTIVO!$B$20/CÁLCULO_MÉDIAS!R$4*Q20 -> 122.99926 | S20: 60.245257 | T20: =ORÇAMENTO_EXECUTIVO!$B$20/CÁLCULO_MÉDIAS!T$4*S20 -> 67.102998 | U20: 91.971567 | V20: =ORÇAMENTO_EXECUTIVO!$B$20/CÁLCULO_MÉDIAS!V$4*U20 -> 102.87736 | W20: 211.697 | X20: =ORÇAMENTO_EXECUTIVO!$B$20/CÁLCULO_MÉDIAS!X$4*W20 -> 227.66356 | Y20: 90.169148 | Z20: =ORÇAMENTO_EXECUTIVO!$B$20/CÁLCULO_MÉDIAS!Z$4*Y20 -> 101.9281 | AA20: 121.48383 | AB20: =ORÇAMENTO_EXECUTIVO!$B$20/CÁLCULO_MÉDIAS!AB$4*AA20 -> 126.58116 | AC20: 100 | AD20: =ROUND(AC20*1.1,0) -> 110 | AE20: 150 | AF20: 130
B21: ESQUADRIAS, VIDROS E FERRAGENS | C21: 135.30744 | D21: =ORÇAMENTO_EXECUTIVO!$B$20/CÁLCULO_MÉDIAS!D$4*C21 -> 152.95287 | E21: 245.72947 | F21: =ORÇAMENTO_EXECUTIVO!$B$20/CÁLCULO_MÉDIAS!F$4*E21 -> 271.82547 | G21: 236.04487 | H21: =ORÇAMENTO_EXECUTIVO!$B$20/CÁLCULO_MÉDIAS!H$4*G21 -> 300.44874 | I21: 277.0891 | J21: =ORÇAMENTO_EXECUTIVO!$B$20/CÁLCULO_MÉDIAS!J$4*I21 -> 336.17756 | K21: 227.17269 | L21: =ORÇAMENTO_EXECUTIVO!$B$20/CÁLCULO_MÉDIAS!L$4*K21 -> 273.70739 | M21: 259.7904 | N21: =ORÇAMENTO_EXECUTIVO!$B$20/CÁLCULO_MÉDIAS!N$4*M21 -> 287.37964 | O21: 557.55 | P21: =$P$5*O21 -> 671.76014 | Q21: 352.92352 | R21: =ORÇAMENTO_EXECUTIVO!$B$20/CÁLCULO_MÉDIAS!R$4*Q21 -> 393.09694 | S21: 393.73193 | T21: =ORÇAMENTO_EXECUTIVO!$B$20/CÁLCULO_MÉDIAS!T$4*S21 -> 438.55059 | U21: 334.99379 | V21: =ORÇAMENTO_EXECUTIVO!$B$20/CÁLCULO_MÉDIAS!V$4*U21 -> 374.71662 | W21: 507.41336 | X21: =ORÇAMENTO_EXECUTIVO!$B$20/CÁLCULO_MÉDIAS!X$4*W21 -> 545.68336 | Y21: 281.037 | Z21: =ORÇAMENTO_EXECUTIVO!$B$20/CÁLCULO_MÉDIAS!Z$4*Y21 -> 317.68701 | AA21: 341.58964 | AB21: =ORÇAMENTO_EXECUTIVO!$B$20/CÁLCULO_MÉDIAS!AB$4*AA21 -> 355.92236 | AC21: 260 | AD21: =ROUND(AC21*1.1,0) -> 286 | AE21: =ROUND(AF21*1.1,0) -> 418 | AF21: 380
B22: COBERTURA | C22: 4.0071969 | D22: =ORÇAMENTO_EXECUTIVO!$B$20/CÁLCULO_MÉDIAS!D$4*C22 -> 4.5297752 | E22: 15.647632 | F22: =ORÇAMENTO_EXECUTIVO!$B$20/CÁLCULO_MÉDIAS!F$4*E22 -> 17.30938 | G22: 4.7387028 | H22: =ORÇAMENTO_EXECUTIVO!$B$20/CÁLCULO_MÉDIAS!H$4*G22 -> 6.0316383 | I22: 4.7465773 | J22: =ORÇAMENTO_EXECUTIVO!$B$20/CÁLCULO_MÉDIAS!J$4*I22 -> 5.7587714 | K22: 1.815167 | L22: =ORÇAMENTO_EXECUTIVO!$B$20/CÁLCULO_MÉDIAS!L$4*K22 -> 2.186991 | M22: 4.0117127 | N22: =ORÇAMENTO_EXECUTIVO!$B$20/CÁLCULO_MÉDIAS!N$4*M22 -> 4.4377488 | O22: 0 | P22: =$P$5*O22 -> 0 | Q22: 67.327504 | R22: =ORÇAMENTO_EXECUTIVO!$B$20/CÁLCULO_MÉDIAS!R$4*Q22 -> 74.99142 | S22: 18.057176 | T22: =ORÇAMENTO_EXECUTIVO!$B$20/CÁLCULO_MÉDIAS!T$4*S22 -> 20.112631 | U22: 42.324726 | V22: =ORÇAMENTO_EXECUTIVO!$B$20/CÁLCULO_MÉDIAS!V$4*U22 -> 47.3435 | W22: 461.85446 | X22: =ORÇAMENTO_EXECUTIVO!$B$20/CÁLCULO_MÉDIAS!X$4*W22 -> 496.68834 | Y22: 91.542599 | Z22: =ORÇAMENTO_EXECUTIVO!$B$20/CÁLCULO_MÉDIAS!Z$4*Y22 -> 103.48066 | AA22: 22.308009 | AB22: =ORÇAMENTO_EXECUTIVO!$B$20/CÁLCULO_MÉDIAS!AB$4*AA22 -> 23.244028 | AC22: 12 | AD22: =ROUND(AC22*1.1,0) -> 13 | AE22: =ROUND(AF22*1.1,0) -> 22 | AF22: 20
B23: REVESTIMENTOS E ACABAMENTOS DE FACHADA | C23: 87.43161 | D23: =ORÇAMENTO_EXECUTIVO!$B$20/CÁLCULO_MÉDIAS!D$4*C23 -> 98.83356 | E23: 109.63024 | F23: =ORÇAMENTO_EXECUTIVO!$B$20/CÁLCULO_MÉDIAS!F$4*E23 -> 121.27276 | G23: 85.43767 | H23: =ORÇAMENTO_EXECUTIVO!$B$20/CÁLCULO_MÉDIAS!H$4*G23 -> 108.74899 | I23: 117.12921 | J23: =ORÇAMENTO_EXECUTIVO!$B$20/CÁLCULO_MÉDIAS!J$4*I23 -> 142.10668 | K23: 112.90382 | L23: =ORÇAMENTO_EXECUTIVO!$B$20/CÁLCULO_MÉDIAS!L$4*K23 -> 136.03137 | M23: 231.41623 | N23: =ORÇAMENTO_EXECUTIVO!$B$20/CÁLCULO_MÉDIAS!N$4*M23 -> 255.99218 | O23: 155.33 | P23: =$P$5*O23 -> 187.14824 | Q23: 199.92092 | R23: =ORÇAMENTO_EXECUTIVO!$B$20/CÁLCULO_MÉDIAS!R$4*Q23 -> 222.67799 | S23: 152.18185 | T23: =ORÇAMENTO_EXECUTIVO!$B$20/CÁLCULO_MÉDIAS!T$4*S23 -> 169.50477 | U23: 128.59148 | V23: =ORÇAMENTO_EXECUTIVO!$B$20/CÁLCULO_MÉDIAS!V$4*U23 -> 143.83958 | W23: 65.54734 | X23: =ORÇAMENTO_EXECUTIVO!$B$20/CÁLCULO_MÉDIAS!X$4*W23 -> 70.491035 | Y23: 3.8263675 | Z23: =ORÇAMENTO_EXECUTIVO!$B$20/CÁLCULO_MÉDIAS!Z$4*Y23 -> 4.3253638 | AA23: 109.31851 | AB23: =ORÇAMENTO_EXECUTIVO!$B$20/CÁLCULO_MÉDIAS!AB$4*AA23 -> 113.90539 | AC23: 100 | AD23: =ROUND(AC23*1.1,0) -> 110 | AE23: =ROUND(AF23*1.1,0) -> 176 | AF23: 160
B24: SERVIÇOS COMPLEMENTARES | C24: 105.34595 | D24: =ORÇAMENTO_EXECUTIVO!$B$20/CÁLCULO_MÉDIAS!D$4*C24 -> 119.08411 | E24: 104.62153 | F24: =ORÇAMENTO_EXECUTIVO!$B$20/CÁLCULO_MÉDIAS!F$4*E24 -> 115.73213 | G24: 189.05137 | H24: =ORÇAMENTO_EXECUTIVO!$B$20/CÁLCULO_MÉDIAS!H$4*G24 -> 240.63326 | I24: 111.80889 | J24: =ORÇAMENTO_EXECUTIVO!$B$20/CÁLCULO_MÉDIAS!J$4*I24 -> 135.65182 | K24: 122.2838 | L24: =ORÇAMENTO_EXECUTIVO!$B$20/CÁLCULO_MÉDIAS!L$4*K24 -> 147.33276 | M24: 106.34114 | N24: =ORÇAMENTO_EXECUTIVO!$B$20/CÁLCULO_MÉDIAS!N$4*M24 -> 117.63437 | O24: 82.14 | P24: =$P$5*O24 -> 98.965793 | Q24: 995.26777 | R24: =ORÇAMENTO_EXECUTIVO!$B$20/CÁLCULO_MÉDIAS!R$4*Q24 -> 1108.5595 | S24: 152.5097 | T24: =ORÇAMENTO_EXECUTIVO!$B$20/CÁLCULO_MÉDIAS!T$4*S24 -> 169.86993 | U24: 206.87294 | V24: =ORÇAMENTO_EXECUTIVO!$B$20/CÁLCULO_MÉDIAS!V$4*U24 -> 231.40349 | W24: 523.77946 | X24: =ORÇAMENTO_EXECUTIVO!$B$20/CÁLCULO_MÉDIAS!X$4*W24 -> 563.28383 | Y24: 102.51544 | Z24: =ORÇAMENTO_EXECUTIVO!$B$20/CÁLCULO_MÉDIAS!Z$4*Y24 -> 115.88447 | AA24: 128.39415 | AB24: =ORÇAMENTO_EXECUTIVO!$B$20/CÁLCULO_MÉDIAS!AB$4*AA24 -> 133.78143 | AC24: 100 | AD24: =ROUND(AC24*1.1,0) -> 110 | AE24: =ROUND(AF24*1.1,0) -> 242 | AF24: 220
B25: TOTAL | C25: =SUM(C9:C24) -> 1953.458 | D25: =SUM(D9:D24) -> 2208.2083 | E25: =SUM(E9:E24) -> 2512.6155 | F25: =SUM(F9:F24) -> 2779.4504 | G25: =SUM(G9:G24) -> 2591.6268 | H25: =SUM(H9:H24) -> 3298.7415 | I25: =SUM(I9:I24) -> 2718.8327 | J25: =SUM(J9:J24) -> 3298.6161 | ... AB25: =SUM(AB9:AB24) -> 3380.5865 | AD25: =SUM(AD10:AD24) -> 2816 | AE25: =SUM(AE10:AE24) -> 3940

Sheet ANÁLISE_CONSTRUTORA
A1: ETAPA | B1: 365 - AFONSO PENA | D1: SÃO FRANCISCO | F1: DIFERENÇA
B2: VALOR | C2: VALOR / m² | D2: VALOR | E2: VALOR / m² | F2: VALOR | G2: VALOR / m²
A3: =ORÇAMENTO_EXECUTIVO!A2 -> GERENCIAMENTO TÉCNICO E ADMINISTRATIVO | B3: ='[1]Obra '!$C$33 -> 3667981.1 | C3: =B3/ORÇAMENTO_EXECUTIVO!$G$2 -> 209.53235 | D3: 3252723.7 | E3: =D3/$D$22 -> 195.34235 | F3: =B3-D3 -> 415257.48 | G3: =C3-E3 -> 14.189998 | H3: mais projetos
A4: =ORÇAMENTO_EXECUTIVO!A3 -> MOVIMENTAÇÃO DE TERRA | B4: ='[1]Obra '!$C$34 -> 1400464.9 | C4: =B4/ORÇAMENTO_EXECUTIVO!$G$2 -> 80.001146 | D4: 1460125.1 | E4: =D4/$D$22 -> 87.687827 | F4: =B4-D4 -> -59660.216 | G4: =C4-E4 -> -7.6866807
A5: INFRAESTRUTURA E CONTENÇÃO | B5: ='[1]Obra '!$C$35+'[1]Obra '!$C$36 -> 4009092.2 | C5: =B5/ORÇAMENTO_EXECUTIVO!$G$2 -> 229.01822 | D5: 4156281.3 | E5: =D5/$D$22 -> 249.60552 | F5: =B5-D5 -> -147189.11 | G5: =C5-E5 -> -20.587297
A6: =ORÇAMENTO_EXECUTIVO!A6 -> SUPRAESTRUTURA | B6: ='[1]Obra '!$C$37 -> 6463760.8 | C6: =B6/ORÇAMENTO_EXECUTIVO!$G$2 -> 369.24045 | D6: 5378160 | E6: =D6/$D$22 -> 322.98545 | F6: =B6-D6 -> 1085600.9 | G6: =C6-E6 -> 46.254995
A7: =ORÇAMENTO_EXECUTIVO!A7 -> ALVENARIA | B7: ='[1]Obra '!$C$38 -> 1539779.4 | C7: =B7/ORÇAMENTO_EXECUTIVO!$G$2 -> 87.959448 | D7: 3849164.2 | E7: =D7/$D$22 -> 231.1616 | F7: =B7-D7 -> -2309384.8 | G7: =C7-E7 -> -143.20215 | H7: são francisco tem drywall
A8: =ORÇAMENTO_EXECUTIVO!A8 -> INSTALAÇÕES ELÉTRICAS, HIDRÁULICAS, GLP E PREVENTIVAS | B8: ='[1]Obra '!$C$39+'[1]Obra '!$C$48 -> 4111849.3 | C8: =B8/ORÇAMENTO_EXECUTIVO!$G$2 -> 234.88819 | D8: 4705105.6 | E8: =D8/$D$22 -> 282.56516 | F8: =B8-D8 -> -593256.29 | G8: =C8-E8 -> -47.676975
A9: =ORÇAMENTO_EXECUTIVO!A9 -> EQUIPAMENTOS E SISTEMAS ESPECIAIS | B9: ='[1]Obra '!$C$40+'[1]Obra '!$C$49 -> 3389279.9 | C9: =B9/ORÇAMENTO_EXECUTIVO!$G$2 -> 193.61162 | D9: 3157566.8 | E9: =D9/$D$22 -> 189.62771 | F9: =B9-D9 -> 231713.04 | G9: =C9-E9 -> 3.9839133
A10: =ORÇAMENTO_EXECUTIVO!A10 -> IMPERMEABILIZAÇÃO | B10: ='[1]Obra '!$C$43 -> 511572.58 | C10: =B10/ORÇAMENTO_EXECUTIVO!$G$2 -> 29.223434 | D10: 662766.79 | E10: =D10/$D$22 -> 39.802467 | F10: =B10-D10 -> -151194.21 | G10: =C10-E10 -> -10.579032
A11: REVESTIMENTOS E ACABAMENTOS EM PAREDE | B11: ='[1]Obra '!$C$41 -> 1426224.3 | C11: =B11/ORÇAMENTO_EXECUTIVO!$G$2 -> 81.472649 | D11: 759339.36 | E11: =D11/$D$22 -> 45.602133 | F11: =B11-D11 -> 666884.98 | G11: =C11-E11 -> 35.870516 | H11: são francisco tem drywall
A12: =ORÇAMENTO_EXECUTIVO!A12 -> REVESTIMENTOS E ACABAMENTOS INTERNOS EM TETO | B12: ='[1]Obra '!$C$42 -> 349137.96 | C12: =B12/ORÇAMENTO_EXECUTIVO!$G$2 -> 19.944404 | D12: 703030.67 | E12: =D12/$D$22 -> 42.220514 | F12: =B12-D12 -> -353892.71 | G12: =C12-E12 -> -22.27611
A13: PISOS E PAVIMENTAÇÕES | B13: ='[1]Obra '!$C$44 -> 2539181.4 | C13: =B13/ORÇAMENTO_EXECUTIVO!$G$2 -> 145.05 | D13: 2733518.3 | E13: =D13/$D$22 -> 164.16147 | F13: =B13-D13 -> -194336.92 | G13: =C13-E13 -> -19.111476
A14: =ORÇAMENTO_EXECUTIVO!A14 -> PINTURA INTERNA | B14: ='[1]Obra '!$C$45 -> 786426.24 | C14: =B14/ORÇAMENTO_EXECUTIVO!$G$2 -> 44.924369 | D14: 772340.09 | E14: =D14/$D$22 -> 46.382892 | F14: =B14-D14 -> 14086.15 | G14: =C14-E14 -> -1.458523
A15: =ORÇAMENTO_EXECUTIVO!A15 -> ESQUADRIAS, VIDROS E FERRAGENS | B15: ='[1]Obra '!$C$47 -> 5007297.9 | C15: =B15/ORÇAMENTO_EXECUTIVO!$G$2 -> 286.04043 | D15: 6010218.4 | E15: =D15/$D$22 -> 360.94373 | F15: =B15-D15 -> -1002920.4 | G15: =C15-E15 -> -74.903294 | H15: SF Ccom Mais guarda-corpos e portas de entrada (fechadura biometrica)
A16: COBERTURA | C16: =B16/ORÇAMENTO_EXECUTIVO!$G$2 -> 0 | E16: =D16/$D$22 -> 0 | F16: =B16-D16 -> 0 | G16: =C16-E16 -> 0
A17: =ORÇAMENTO_EXECUTIVO!A16 -> REVESTIMENTOS E ACABAMENTOS DE FACHADA | B17: ='[1]Obra '!$C$46 -> 561222.52 | C17: =B17/ORÇAMENTO_EXECUTIVO!$G$2 -> 32.059673 | D17: 721237.85 | E17: =D17/$D$22 -> 43.313946 | F17: =B17-D17 -> -160015.32 | G17: =C17-E17 -> -11.254274
A18: =ORÇAMENTO_EXECUTIVO!A17 -> SERVIÇOS COMPLEMENTARES | B18: ='[1]Obra '!$C$50 -> 1941982 | C18: =B18/ORÇAMENTO_EXECUTIVO!$G$2 -> 110.93515 | D18: 2518422.6 | E18: =D18/$D$22 -> 151.2439 | F18: =B18-D18 -> -576440.61 | G18: =C18-E18 -> -40.308742
A19: =ORÇAMENTO_EXECUTIVO!A18 -> IMPREVISTOS E CONTINGENCIAS | B19: ='[1]Obra '!$C$52 -> 680745.43 | C19: =B19/ORÇAMENTO_EXECUTIVO!$G$2 -> 38.887384 | D19: 872126.34 | E19: =D19/$D$22 -> 52.375556 | F19: =B19-D19 -> -191380.91 | G19: =C19-E19 -> -13.488173
A20: MAO DE OBRA | B20: ='[1]Obra '!$C$51 -> 22603060 | C20: =B20/ORÇAMENTO_EXECUTIVO!$G$2 -> 1291.1932 | D20: 20141550 | E20: =D20/$D$22 -> 1209.601 | F20: =B20-D20 -> 2461509.9 | G20: =C20-E20 -> 81.5922
A21: TOTAL | B21: =SUM(B3:B20) -> 60989058 | C21: =SUM(C3:C19) -> 2192.7889 | D21: =SUM(D3:D20) -> 61853677 | E21: =SUM(E3:E20) -> 3714.6232 | F21: =SUM(F4:F18) -> -3550005.6 | G21: =SUM(G4:G18) -> -312.93513
D22: 16651.4
B25: 2007.57
B26: 2461.35
B27: =B26/B25 -> 1.2260345
C30: 1.1023
A32: 900,00 - 1100 | B32: 900
A33: 25,00 - 30,00 | B33: 25
A34: 15,00 - 22,00 | B34: 15
A35: 150,00 - 200,00 | B35: 150
A36: 440,00 - 510,00 | B36: 440
A37: -
A38: 55,00 - 70,00 | B38: 55
A39: 170,00 - 200,00 | B39: 170
A40: 165,00 - 230,00 | B40: 165
A41: 40,00 - 70,00 | B41: 40
A42: 55,00 - 77,00 | B42: 55
A43: 35,00 - 50,00 | B43: 35
A44: 130,00 - 175,00 | B44: 130
A45: 35,00 - 65,00 | B45: 35
...

Sheet VERSÕES
A1: ETAPA | B1: PARAMÉTRICO NOVO | E1: PARAMÉTRICO ANTERIOR | I1: DIFERENÇA
B2: VALOR ORÇADO | C2: % | D2: VALOR / m² | E2: VALOR ORÇADO | F2: VALOR INDEXADO | G2: % | H2: VALOR / m² | I2: VALOR ORÇADO | J2: VALOR / m²
A3: GERENCIAMENTO TÉCNICO E ADMINISTRATIVO | B3: =ORÇAMENTO_EXECUTIVO!B2 -> 3894011.7 | C3: =B3/B$20 -> #REF! | D3: =B3/VERSÕES!M$4 -> 222.44428 | E3: 3527122.5 | F3: =E3*$L$5 -> 3682827.3 | G3: =F3/F$20 -> 0.082935581 | H3: =F3/VERSÕES!M$3 -> 261.03625 | I3: =B3-F3 -> 211184.41 | J3: =D3-H3 -> -38.591967 | L3: ÁREA CONSTRUÍDA ANTERIOR | M3: 14108.49 | N3: m²
A4: MOVIMENTAÇÃO DE TERRA | B4: =ORÇAMENTO_EXECUTIVO!B3 -> 1400464.9 | C4: =B4/B$20 -> #REF! | D4: =B4/VERSÕES!M$4 -> 80.001146 | E4: 673079.32 | F4: =E4*$L$5 -> 702792.4 | G4: =F4/F$20 -> 0.015826562 | H4: =F4/VERSÕES!M$3 -> 49.813439 | I4: =B4-F4 -> 697672.46 | J4: =D4-H4 -> 30.187707 | K4: Paramétrico anterior considerado custo baixo de mov de terra subsolos | L4: ÁREA CONSTRUÍDA | M4: =ORÇAMENTO_EXECUTIVO!G2 -> 17505.56 | N4: m²
A5: INFRAESTRUTURA E CONTENÇÃO | B5: =ORÇAMENTO_EXECUTIVO!B4+ORÇAMENTO_EXECUTIVO!B5 -> 5478291.1 | C5: =B5/B$20 -> #REF! | D5: =B5/VERSÕES!M$4 -> 312.94578 | E5: 4758622.6 | F5: =E5*$L$5 -> 4968692 | G5: =F5/F$20 -> 0.11189266 | H5: =F5/VERSÕES!M$3 -> 352.17745 | I5: =B5-F5 -> 509599.17 | J5: =D5-H5 -> -39.231665 | L5: 1.044145
A6: SUPRAESTRUTURA | B6: =ORÇAMENTO_EXECUTIVO!B6 -> 11888495 | C6: =B6/B$20 -> #REF! | D6: =B6/VERSÕES!M$4 -> 679.12682 | E6: 8711995.6 | F6: =E6*$L$5 -> 9096586.7 | G6: =F6/F$20 -> 0.20485096 | H6: =F6/VERSÕES!M$3 -> 644.75976 | I6: =B6-F6 -> 2791908.6 | J6: =D6-H6 -> 34.367054 | K6: OK
A7: ALVENARIA | B7: =ORÇAMENTO_EXECUTIVO!B7 -> 2669932.4 | C7: =B7/B$20 -> #REF! | D7: =B7/VERSÕES!M$4 -> 152.51911 | E7: 1663392.7 | F7: =E7*$L$5 -> 1736823.1 | G7: =F7/F$20 -> 0.03911246 | H7: =F7/VERSÕES!M$3 -> 123.10482 | I7: =B7-F7 -> 933109.26 | J7: =D7-H7 -> 29.414287 | K7: Novo paramétrico considerado divisórias internas em drywall
A8: INSTALAÇÕES ELÉTRICAS, HIDRÁULICAS, GLP E PREVENTIVAS | B8: =ORÇAMENTO_EXECUTIVO!B8 -> 6824216.5 | C8: =B8/B$20 -> #REF! | D8: =B8/VERSÕES!M$4 -> 389.83137 | E8: 5123863 | F8: =E8*$L$5 -> 5350055.9 | G8: =F8/F$20 -> 0.1204808 | H8: =F8/VERSÕES!M$3 -> 379.20826 | I8: =B8-F8 -> 1474160.5 | J8: =D8-H8 -> 10.623112 | K8: OK
A9: EQUIPAMENTOS E SISTEMAS ESPECIAIS | B9: =ORÇAMENTO_EXECUTIVO!B9 -> 3389279.9 | C9: =B9/B$20 -> #REF! | D9: =B9/VERSÕES!M$4 -> 193.61162 | E9: 2581391.5 | F9: =E9*$L$5 -> 2695347 | G9: =F9/F$20 -> 0.060697977 | H9: =F9/VERSÕES!M$3 -> 191.04433 | I9: =B9-F9 -> 693932.9 | J9: =D9-H9 -> 2.5672954 | K9: OK
A10: IMPERMEABILIZAÇÃO | B10: =ORÇAMENTO_EXECUTIVO!B10 -> 963633.78 | C10: =B10/B$20 -> #REF! | D10: =B10/VERSÕES!M$4 -> 55.047298 | E10: 1028245.4 | F10: =E10*$L$5 -> 1073637.3 | G10: =F10/F$20 -> 0.024177819 | H10: =F10/VERSÕES!M$3 -> 76.098668 | I10: =B10-F10 -> -110003.52 | J10: =D10-H10 -> -21.05137 | K10: OK
A11: REVESTIMENTOS INTERNOS EM PISO E PAREDE | B11: =ORÇAMENTO_EXECUTIVO!B11 -> 3955585.1 | C11: =B11/B$20 -> #REF! | D11: =B11/VERSÕES!M$4 -> 225.96164 | E11: 2214204.6 | F11: =E11*$L$5 -> 2311950.6 | G11: =F11/F$20 -> 0.052064067 | H11: =F11/VERSÕES!M$3 -> 163.86946 | I11: =B11-F11 -> 1643634.5 | J11: =D11-H11 -> 62.092183 | K11: Custo menor na MO paramétrico anterior
A12: REVESTIMENTOS E ACABAMENTOS INTERNOS EM TETO | B12: =ORÇAMENTO_EXECUTIVO!B12 -> 1140245.1 | C12: =B12/B$20 -> #REF! | D12: =B12/VERSÕES!M$4 -> 65.136166 | E12: 1107529.2 | F12: =E12*$L$5 -> 1156421.1 | G12: =F12/F$20 -> 0.026042072 | H12: =F12/VERSÕES!M$3 -> 81.966325 | I12: =B12-F12 -> -16176.022 | J12: =D12-H12 -> -16.830159 | K12: maior proporção de forro (ANTERIOR 0,33m²/m² e NOVO 0,41m²/m²) + consideração negativo
A13: ACABAMENTOS EM PISO E PAREDE | B13: =ORÇAMENTO_EXECUTIVO!B13 -> 4304402.1 | C13: =B13/B$20 -> #REF! | D13: =B13/VERSÕES!M$4 -> 245.88771 | E13: 2186816 | F13: =E13*$L$5 -> 2283352.9 | G13: =F13/F$20 -> 0.05142006 | H13: =F13/VERSÕES!M$3 -> 161.84248 | I13: =B13-F13 -> 2021049.1 | J13: =D13-H13 -> 84.045236 | K13: Custo menor na MO paramétrico anterior
A14: PINTURA INTERNA | B14: =ORÇAMENTO_EXECUTIVO!B14 -> 2594671 | C14: =B14/B$20 -> #REF! | D14: =B14/VERSÕES!M$4 -> 148.21983 | E14: 1481391.4 | F14: =E14*$L$5 -> 1546787.5 | G14: =F14/F$20 -> 0.034832944 | H14: =F14/VERSÕES!M$3 -> 109.63523 | I14: =B14-F14 -> 1047883.6 | J14: =D14-H14 -> 38.5846 | K14: Novo paramétrico com quant de projeto
A15: ESQUADRIAS, VIDROS E FERRAGENS | B15: =ORÇAMENTO_EXECUTIVO!B15 -> 5911420.4 | C15: =B15/B$20 -> #REF! | D15: =B15/VERSÕES!M$4 -> 337.68816 | E15: 3194869.5 | F15: =E15*$L$5 -> 3335907 | G15: =F15/F$20 -> 0.075123095 | H15: =F15/VERSÕES!M$3 -> 236.44678 | I15: =B15-F15 -> 2575513.3 | J15: =D15-H15 -> 101.24138 | K15: Novo paramétrico com quant de projeto
A16: COBERTURA | B16: =ORÇAMENTO_EXECUTIVO!#REF! -> #REF! | C16: =B16/B$20 -> #REF! | D16: =B16/VERSÕES!M$4 -> #REF! | F16: =E16*$L$5 -> 0 | G16: =F16/F$20 -> 0 | H16: =F16/VERSÕES!M$3 -> 0 | I16: =B16-F16 -> #REF! | J16: =D16-H16 -> #REF! | K16: Novo paramétrico laje impermeab.
A17: REVESTIMENTOS E ACABAMENTOS DE FACHADA | B17: =ORÇAMENTO_EXECUTIVO!B16 -> 2143436.7 | C17: =B17/B$20 -> #REF! | D17: =B17/VERSÕES!M$4 -> 122.4432 | E17: 1823115.7 | F17: =E17*$L$5 -> 1903597.2 | G17: =F17/F$20 -> 0.042868135 | H17: =F17/VERSÕES!M$3 -> 134.92565 | I17: =B17-F17 -> 239839.53 | J17: =D17-H17 -> -12.482454
A18: SERVIÇOS COMPLEMENTARES | B18: =ORÇAMENTO_EXECUTIVO!B17 -> 2620073.8 | C18: =B18/B$20 -> #REF! | D18: =B18/VERSÕES!M$4 -> 149.67095 | E18: 2452820.6 | F18: =E18*$L$5 -> 2561100.3 | G18: =F18/F$20 -> 0.057674804 | H18: =F18/VERSÕES!M$3 -> 181.52902 | I18: =B18-F18 -> 58973.461 | J18: =D18-H18 -> -31.858068 | K18: OK
A19: IMPREVISTOS E CONTINGENCIAS | B19: =ORÇAMENTO_EXECUTIVO!B18 -> 1810898.4 | C19: =B19/B$20 -> #REF! | D19: =B19/VERSÕES!M$4 -> 103.44704 | E19: 0 | F19: =E19*$L$5 -> 0 | G19: =F19/F$20 -> 0 | H19: =F19/VERSÕES!M$3 -> 0 | I19: =B19-F19 -> 1810898.4 | J19: =D19-H19 -> 103.44704
A20: TOTAL | B20: =SUM(B3:B19) -> #REF! | C20: =SUM(C3:C19) -> #REF! | D20: =SUM(D3:D19) -> #REF! | E20: =SUM(E3:E19) -> 42528460 | F20: =SUM(F3:F19) -> 44405878 | G20: =SUM(G3:G19) -> 1 | H20: =SUM(H3:H19) -> 3147.4579 | I20: =SUM(I3:I19) -> #REF! | J20: =SUM(J3:J19) -> #REF!
A21: CUB/SC | B21: 2846.12 | C21: 45566 | D21: =D20/B21 -> #REF! | H21: =+H20/B21 -> 1.1058767 | I21: =J20/D20 -> #REF!

Sheet CONSTRUTORA
A1: ETAPA | B1: SÃO FRANCISCO | E1: 365 | H1: DIFERENÇA
B2: VALOR ORÇADO | C2: % | D2: VALOR / m² | E2: VALOR INDEXADO | F2: % | G2: VALOR / m² | H2: VALOR ORÇADO | I2: VALOR / m²
A3: GERENCIAMENTO TÉCNICO E ADMINISTRATIVO | B3: =ORÇAMENTO_EXECUTIVO!B2 -> 3894011.7 | C3: =B3/B$20 -> #REF! | D3: =B3/CONSTRUTORA!L$4 -> 222.44428 | E3: 3504714.1 | F3: =E3/E$20 -> 0.059573914 | G3: =E3/CONSTRUTORA!L$3 -> 200.57793 | H3: =B3-E3 -> 389297.6 | I3: =D3-G3 -> 21.866358 | J3: mesmo prazo, menos ac | K3: ÁREA CONSTRUÍDA 365 | L3: 17473.08 | M3: m²
A4: MOVIMENTAÇÃO DE TERRA | B4: =ORÇAMENTO_EXECUTIVO!B3 -> 1400464.9 | C4: =B4/B$20 -> #REF! | D4: =B4/CONSTRUTORA!L$4 -> 80.001146 | E4: 1364651.1 | F4: =E4/E$20 -> 0.023196645 | G4: =E4/CONSTRUTORA!L$3 -> 78.100205 | H4: =B4-E4 -> 35813.74 | I4: =D4-G4 -> 1.9009415 | J4: 3 SUBSOLOS | K4: ÁREA CONSTRUÍDA SF | L4: =ORÇAMENTO_EXECUTIVO!G2 -> 17505.56 | M4: m²
A5: INFRAESTRUTURA E CONTENÇÃO | B5: =ORÇAMENTO_EXECUTIVO!B4+ORÇAMENTO_EXECUTIVO!B5 -> 5478291.1 | C5: =B5/B$20 -> #REF! | D5: =B5/CONSTRUTORA!L$4 -> 312.94578 | E5: 6317421.7 | F5: =E5/E$20 -> 0.10738495 | G5: =E5/CONSTRUTORA!L$3 -> 361.55169 | H5: =B5-E5 -> -839130.52 | I5: =D5-G5 -> -48.605913 | J5: um pouco menos de área pra distribuir | K5: 1.044145
A6: SUPRAESTRUTURA | B6: =ORÇAMENTO_EXECUTIVO!B6 -> 11888495 | C6: =B6/B$20 -> #REF! | D6: =B6/CONSTRUTORA!L$4 -> 679.12682 | E6: 10402968 | F6: =E6/E$20 -> 0.17683197 | G6: =E6/CONSTRUTORA!L$3 -> 595.37115 | H6: =B6-E6 -> 1485527.6 | I6: =D6-G6 -> 83.75567 | J6: um pouco mais de mo (distribuição custo do drywall)
A7: ALVENARIA | B7: =ORÇAMENTO_EXECUTIVO!B7 -> 2669932.4 | C7: =B7/B$20 -> #REF! | D7: =B7/CONSTRUTORA!L$4 -> 152.51911 | E7: 2649104.4 | F7: =E7/E$20 -> 0.045030069 | G7: =E7/CONSTRUTORA!L$3 -> 151.61062 | H7: =B7-E7 -> 20827.984 | I7: =D7-G7 -> 0.90849255 | J7: divisórias internas em drywall
A8: INSTALAÇÕES ELÉTRICAS, HIDRÁULICAS, GLP E PREVENTIVAS | B8: =ORÇAMENTO_EXECUTIVO!B8 -> 6824216.5 | C8: =B8/B$20 -> #REF! | D8: =B8/CONSTRUTORA!L$4 -> 389.83137 | E8: 6444580.4 | F8: =E8/E$20 -> 0.10954642 | G8: =E8/CONSTRUTORA!L$3 -> 368.8291 | H8: =B8-E8 -> 379636.03 | I8: =D8-G8 -> 21.002268 | J8: OK
A9: EQUIPAMENTOS E SISTEMAS ESPECIAIS | B9: =ORÇAMENTO_EXECUTIVO!B9 -> 3389279.9 | C9: =B9/B$20 -> #REF! | D9: =B9/CONSTRUTORA!L$4 -> 193.61162 | E9: 3372799 | F9: =E9/E$20 -> 0.057331591 | G9: =E9/CONSTRUTORA!L$3 -> 193.0283 | H9: =B9-E9 -> 16480.86 | I9: =D9-G9 -> 0.58331756 | J9: OK
A10: IMPERMEABILIZAÇÃO | B10: =ORÇAMENTO_EXECUTIVO!B10 -> 963633.78 | C10: =B10/B$20 -> #REF! | D10: =B10/CONSTRUTORA!L$4 -> 55.047298 | E10: 646680 | F10: =E10/E$20 -> 0.010992411 | G10: =E10/CONSTRUTORA!L$3 -> 37.010075 | H10: =B10-E10 -> 316953.79 | I10: =D10-G10 -> 18.037223 | J10: laje impermeabilizada
A11: REVESTIMENTOS INTERNOS EM PISO E PAREDE | B11: =ORÇAMENTO_EXECUTIVO!B11 -> 3955585.1 | C11: =B11/B$20 -> #REF! | D11: =B11/CONSTRUTORA!L$4 -> 225.96164 | E11: 3911886.4 | F11: =E11/E$20 -> 0.066495119 | G11: =E11/CONSTRUTORA!L$3 -> 223.88076 | H11: =B11-E11 -> 43698.702 | I11: =D11-G11 -> 2.0808849 | J11: divisórias internas em drywall
