Workbook
Name \0: #REF!
Name \0: #REF!
Name \0: #REF!
Name \0: #REF!
Name \0: #REF!
Name \0: #REF!
Name \0: #REF!
Name \0: #REF!
Name \0: #REF!
Name \0: #REF!
Name \1: #REF!
Name \1: #REF!
Name \1: #REF!
Name \1: #REF!
Name \a: #REF!
Name \a: #REF!
Name \a: #REF!
Name \a: #REF!
Name \a: #REF!
Name \a: #REF!
Name \a: #REF!
Name \b: #REF!
Name \b: #REF!
Name \c: #REF!
Name \c: #REF!
Name \d: #REF!
Name \d: #REF!
Name \e: #REF!
Name \e: #REF!
Name \i: #REF!
Name \i: #REF!
Name \J: #REF!
Name \J: #REF!
Name \k: #REF!
Name \k: #REF!
Name \k: #REF!
Name \l: #N/A
Name \m: #REF!
Name \m: #REF!
Name \m: #REF!
Name \m: #REF!
Name \m: #REF!
Name \m: #REF!
Name \m: #REF!
Name \m: #REF!
Name \o: #REF!
Name \o: #REF!
Name \p: #REF!
Name \p: #REF!
Name \r: #REF!
Name \r: #REF!
Name \T: #REF!
Name \T: #REF!
Name \z: #REF!
Name \z: #REF!
Name \z: #REF!
Name \z: #REF!
Name _\0: #REF!
Name _\1: #REF!
Name _\a: #REF!

Sheet Versões
A1: ETAPA | B1: 365 - PRELIMINAR R00 | D1: 365 - PARAMETRICO | F1: 365 PARAMETRICO- INDEXADO | H1: DIFERENÇA
B2: VALOR | C2: VALOR / m² | D2: VALOR | E2: VALOR / m² | F2: VALOR | G2: VALOR / m² | H2: VALOR | I2: VALOR / m²
A3: =[1]ORÇAMENTO_EXECUTIVO!A2 -> GERENCIAMENTO TÉCNICO E ADMINISTRATIVO | B3: =[1]ORÇAMENTO_EXECUTIVO!B2 -> 3894011.7 | C3: =[1]ORÇAMENTO_EXECUTIVO!D2 -> 222.44428 | D3: 3504714.1 | E3: 200.57793 | F3: =D3*$D$80 -> 3651768 | G3: =E3*$D$80 -> 208.99395 | H3: =B3-F3 -> 242243.73 | I3: =C3-G3 -> 13.450333
A4: =[1]ORÇAMENTO_EXECUTIVO!A3 -> MOVIMENTAÇÃO DE TERRA | B4: =[1]ORÇAMENTO_EXECUTIVO!B3 -> 1400464.9 | C4: =[1]ORÇAMENTO_EXECUTIVO!D3 -> 80.001146 | D4: 1364651.1 | E4: 78.100205 | F4: =D4*$D$80 -> 1421910.4 | G4: =E4*$D$80 -> 81.377201 | H4: =B4-F4 -> -21445.489 | I4: =C4-G4 -> -1.3760554
A5: INFRAESTRUTURA E CONTENÇÃO | B5: =[1]ORÇAMENTO_EXECUTIVO!B4+[1]ORÇAMENTO_EXECUTIVO!B5 -> 5478291.1 | C5: =[1]ORÇAMENTO_EXECUTIVO!D4+[1]ORÇAMENTO_EXECUTIVO!D5 -> 312.94578 | D5: 6317421.7 | E5: 361.55169 | F5: =D5*$D$80 -> 6582493.6 | G5: =E5*$D$80 -> 376.722 | H5: =B5-F5 -> -1104202.4 | I5: =C5-G5 -> -63.776216
A6: =[1]ORÇAMENTO_EXECUTIVO!A6 -> SUPRAESTRUTURA | B6: =[1]ORÇAMENTO_EXECUTIVO!B6 -> 11888495 | C6: =[1]ORÇAMENTO_EXECUTIVO!D6 -> 679.12682 | D6: 10402968 | E6: 595.37115 | F6: =D6*$D$80 -> 10839465 | G6: =E6*$D$80 -> 620.35225 | H6: =B6-F6 -> 1049030.7 | I6: =C6-G6 -> 58.774565
A7: =[1]ORÇAMENTO_EXECUTIVO!A7 -> ALVENARIA | B7: =[1]ORÇAMENTO_EXECUTIVO!B7 -> 2669932.4 | C7: =[1]ORÇAMENTO_EXECUTIVO!D7 -> 152.51911 | D7: 2649104.4 | E7: 151.61062 | F7: =D7*$D$80 -> 2760257.9 | G7: =E7*$D$80 -> 157.97203 | H7: =B7-F7 -> -90325.464 | I7: =C7-G7 -> -5.4529187
A8: =[1]ORÇAMENTO_EXECUTIVO!A8 -> INSTALAÇÕES ELÉTRICAS, HIDRÁULICAS, GLP E PREVENTIVAS | B8: =[1]ORÇAMENTO_EXECUTIVO!B8 -> 6824216.5 | C8: =[1]ORÇAMENTO_EXECUTIVO!D8 -> 389.83137 | D8: 6444580.4 | E8: 368.8291 | F8: =D8*$D$80 -> 6714987.8 | G8: =E8*$D$80 -> 384.30476 | H8: =B8-F8 -> 109228.67 | I8: =C8-G8 -> 5.5266125
A9: =[1]ORÇAMENTO_EXECUTIVO!A9 -> EQUIPAMENTOS E SISTEMAS ESPECIAIS | B9: =[1]ORÇAMENTO_EXECUTIVO!B9 -> 3389279.9 | C9: =[1]ORÇAMENTO_EXECUTIVO!D9 -> 193.61162 | D9: 3372799 | E9: 193.0283 | F9: =D9*$D$80 -> 3514317.9 | G9: =E9*$D$80 -> 201.12756 | H9: =B9-F9 -> -125038 | I9: =C9-G9 -> -7.5159334
A10: =[1]ORÇAMENTO_EXECUTIVO!A10 -> IMPERMEABILIZAÇÃO | B10: =[1]ORÇAMENTO_EXECUTIVO!B10 -> 963633.78 | C10: =[1]ORÇAMENTO_EXECUTIVO!D10 -> 55.047298 | D10: 646680 | E10: 37.010075 | F10: =D10*$D$80 -> 673813.96 | G10: =E10*$D$80 -> 38.562976 | H10: =B10-F10 -> 289819.82 | I10: =C10-G10 -> 16.484322
A11: =[1]ORÇAMENTO_EXECUTIVO!A11 -> REVESTIMENTOS INTERNOS EM PISO E PAREDE | B11: =[1]ORÇAMENTO_EXECUTIVO!B11 -> 3955585.1 | C11: =[1]ORÇAMENTO_EXECUTIVO!D11 -> 225.96164 | D11: 3911886.4 | E11: 223.88076 | F11: =D11*$D$80 -> 4076024.7 | G11: =E11*$D$80 -> 233.27454 | H11: =B11-F11 -> -120439.66 | I11: =C11-G11 -> -7.3129004
A12: =[1]ORÇAMENTO_EXECUTIVO!A12 -> REVESTIMENTOS E ACABAMENTOS INTERNOS EM TETO | B12: =[1]ORÇAMENTO_EXECUTIVO!B12 -> 1140245.1 | C12: =[1]ORÇAMENTO_EXECUTIVO!D12 -> 65.136166 | D12: 1954740.9 | E12: 111.87157 | F12: =D12*$D$80 -> 2036759.7 | G12: =E12*$D$80 -> 116.56558 | H12: =B12-F12 -> -896514.6 | I12: =C12-G12 -> -51.429412
A13: =[1]ORÇAMENTO_EXECUTIVO!A13 -> ACABAMENTOS EM PISO E PAREDE | B13: =[1]ORÇAMENTO_EXECUTIVO!B13 -> 4304402.1 | C13: =[1]ORÇAMENTO_EXECUTIVO!D13 -> 245.88771 | D13: 3486357.6 | E13: 199.52736 | F13: =D13*$D$80 -> 3632641.3 | G13: =E13*$D$80 -> 207.89931 | H13: =B13-F13 -> 671760.81 | I13: =C13-G13 -> 37.988401
A14: =[1]ORÇAMENTO_EXECUTIVO!A14 -> PINTURA INTERNA | B14: =[1]ORÇAMENTO_EXECUTIVO!B14 -> 2594671 | C14: =[1]ORÇAMENTO_EXECUTIVO!D14 -> 148.21983 | D14: 2122696.8 | E14: 121.48383 | F14: =D14*$D$80 -> 2211762.7 | G14: =E14*$D$80 -> 126.58116 | H14: =B14-F14 -> 382908.32 | I14: =C14-G14 -> 21.638666
A15: =[1]ORÇAMENTO_EXECUTIVO!A15 -> ESQUADRIAS, VIDROS E FERRAGENS | B15: =[1]ORÇAMENTO_EXECUTIVO!B15 -> 5911420.4 | C15: =[1]ORÇAMENTO_EXECUTIVO!D15 -> 337.68816 | D15: 5968623.2 | E15: 341.58964 | F15: =D15*$D$80 -> 6219059.9 | G15: =E15*$D$80 -> 355.92236 | H15: =B15-F15 -> -307639.55 | I15: =C15-G15 -> -18.234201
A16: COBERTURA | D16: 389789.63 | E16: 22.308009 | F16: =D16*$D$80 -> 406144.76 | G16: =E16*$D$80 -> 23.244028 | H16: =B16-F16 -> -406144.76 | I16: =C16-G16 -> -23.244028
A17: =[1]ORÇAMENTO_EXECUTIVO!A16 -> REVESTIMENTOS E ACABAMENTOS DE FACHADA | B17: =[1]ORÇAMENTO_EXECUTIVO!B16 -> 2143436.7 | C17: =[1]ORÇAMENTO_EXECUTIVO!D16 -> 122.4432 | D17: 1910131.1 | E17: 109.31851 | F17: =D17*$D$80 -> 1990278 | G17: =E17*$D$80 -> 113.90539 | H17: =B17-F17 -> 153158.7 | I17: =C17-G17 -> 8.5378045
A18: =[1]ORÇAMENTO_EXECUTIVO!A17 -> SERVIÇOS COMPLEMENTARES | B18: =[1]ORÇAMENTO_EXECUTIVO!B17 -> 2620073.8 | C18: =[1]ORÇAMENTO_EXECUTIVO!D17 -> 149.67095 | D18: 2243441.3 | E18: 128.39415 | F18: =D18*$D$80 -> 2337573.6 | G18: =E18*$D$80 -> 133.78143 | H18: =B18-F18 -> 282500.24 | I18: =C18-G18 -> 15.889524
A19: =[1]ORÇAMENTO_EXECUTIVO!A18 -> IMPREVISTOS E CONTINGENCIAS | B19: =[1]ORÇAMENTO_EXECUTIVO!B18 -> 1810898.4 | C19: =[1]ORÇAMENTO_EXECUTIVO!D18 -> 103.44704 | D19: 2139091.8 | E19: 122.42214 | F19: =D19*$D$80 -> 2228845.7 | G19: =E19*$D$80 -> 127.55883 | H19: =B19-F19 -> -417947.22 | I19: =C19-G19 -> -24.111787
A20: TOTAL | B20: =SUM(B3:B19) -> 60989058 | C20: =SUM(C3:C19) -> 3483.9821 | D20: =SUM(D3:D19) -> 58829677 | E20: =SUM(E3:E19) -> 3366.875 | F20: =SUM(F3:F19) -> 61298104 | G20: =SUM(G3:G19) -> 3508.1453 | H20: =SUM(H3:H19) -> -309046.19 | I20: =SUM(I3:I19) -> -24.163223
A21: CUB/SC | B21: 2965.54 | C21: =C20/B21 -> 1.1748222 | D21: 2846.12 | E21: =E20/D21 -> 1.1829702 | G21: =G20/B21 -> 1.1829702 | I21: =H20/B20 -> -0.00506724
B22: 45839 | D22: 45566
D23: 45566
D24: 2846.12
B25: 2007.57 | D25: =[1]ORÇAMENTO_EXECUTIVO!C20 -> 45839 | F25: 2007.57 | H25: 2007.57
B26: 2461.35 | D26: 2007.57 | F26: 2461.35 | H26: 2461.35
B27: =B26/B25 -> 1.2260345 | D27: 2461.35 | F27: =F26/F25 -> 1.2260345 | H27: =H26/H25 -> 1.2260345
D28: =D27/D26 -> 1.2260345
C30: 1.1023 | E30: 1.1023 | G30: 1.1023 | I30: 1.1023
A32: 900,00 - 1100 | B32: 900 | F32: 900 | H32: 900
A33: 25,00 - 30,00 | B33: 25 | D33: 900 | F33: 25 | H33: 25
A34: 15,00 - 22,00 | B34: 15 | D34: 25 | F34: 15 | H34: 15
A35: 150,00 - 200,00 | B35: 150 | D35: 15 | F35: 150 | H35: 150
A36: 440,00 - 510,00 | B36: 440 | D36: 150 | F36: 440 | H36: 440
A37: - | D37: 440
A38: 55,00 - 70,00 | B38: 55 | F38: 55 | H38: 55
A39: 170,00 - 200,00 | B39: 170 | D39: 55 | F39: 170 | H39: 170
A40: 165,00 - 230,00 | B40: 165 | D40: 170 | F40: 165 | H40: 165
A41: 40,00 - 70,00 | B41: 40 | D41: 165 | F41: 40 | H41: 40
A42: 55,00 - 77,00 | B42: 55 | D42: 40 | F42: 55 | H42: 55
...

Sheet Obra 
C1: Projeto | D1: 365
C2: Empresa | D2: COTA
C3: Revisão | D3: R00
A4: QUADRO DE ÁREAS
B6: Descrição | C6: Unidade | E6: Quantidade | G6: Imagens
B7: MESES DE OBRA | C7: MÊS | E7: 43
B8: ÁREA DO TERRENO | C8: M² | E8: 2133.78
B9: ÁREA CONSTRUÍDA | C9: M² | E9: 17505.56
B10: NÚMERO DE UNIDADES HABITACIONAIS | C10: UN | E10: 176
B11: NÚMERO DE UNIDADES COMERCIAIS | C11: UN | E11: 0
B12: ÁREA PRIVATIVA | C12: M² | E12: 9509.28
B13: NÚMERO DE PAVIMENTOS | C13: UN | E13: 15
B15: Subsolo - Garagem 2 | C15: M² | E15: 1641.67
B16: Subsolo - Garagem 1 | C16: M² | E16: 1592.5
B17: Térreo | C17: M² | E17: 1559.6
B18: Mezanino | C18: M² | E18: 1588.25
B19: 2º pavimento | C19: M² | E19: 1155.62
... B22: Área Técnica | C22: M² | E22: 157.49
B32: ETAPA | C32: VALOR ORÇADO | D32: % | E32: VALOR / m²
B33: GERENCIAMENTO TÉCNICO E ADMINISTRATIVO | C33: ='Ger_Tec e Adm'!N101 -> 3667981.1 | D33: =C33/C$53 -> 0.060141626 | E33: =C33/$E$9 -> 209.53235
B34: MOVIMENTAÇÃO DE TERRA | C34: =Ger_Executivo!N8 -> 1400464.9 | D34: =C34/C$53 -> 0.022962559 | E34: =C34/$E$9 -> 80.001146
B35: INFRAESTRUTURA | C35: =Ger_Executivo!N23 -> 2627275.7 | D35: =C35/C$53 -> 0.04307782 | E35: =C35/$E$9 -> 150.08235
B36: CONTENÇÃO | C36: =Ger_Executivo!N47 -> 1381816.6 | D36: =C36/C$53 -> 0.022656795 | E36: =C36/$E$9 -> 78.935869
B37: SUPRAESTRUTURA | C37: =Ger_Executivo!N55 -> 6463760.8 | D37: =C37/C$53 -> 0.1059823 | E37: =C37/$E$9 -> 369.24045
B38: ALVENARIA | C38: =Ger_Executivo!N78 -> 1539779.4 | D38: =C38/C$53 -> 0.025246814 | E38: =C38/$E$9 -> 87.959448
B39: INSTALAÇÕES ELÉTRICAS, HIDRÁULICAS, GLP E PREVENTIVAS | C39: =Ger_Executivo!N105+Ger_Executivo!N114+Ger_Executivo!N128+Ger_Executivo!N133 -> 3600893.7 | D39: =C39/C$53 -> 0.059041635 | E39: =C39/$E$9 -> 205.7
B40: CLIMATIZAÇÃO, EXAUSTÃO MECÂNICA E PRESSURIZAÇÃO | C40: =Ger_Executivo!N156 -> 1083704.9 | D40: =C40/C$53 -> 0.017768841 | E40: =C40/$E$9 -> 61.906324
B41: REVESTIMENTOS E ACABAMENTOS EM PAREDE | C41: =Ger_Executivo!N164 -> 1426224.3 | D41: =C41/C$53 -> 0.023384922 | E41: =C41/$E$9 -> 81.472649
B42: REVESTIMENTOS ARGAMASSADOS TETO | C42: =Ger_Executivo!N177 -> 349137.96 | D42: =C42/C$53 -> 0.0057245999 | E42: =C42/$E$9 -> 19.944404
B43: IMPERMEABILIZAÇÃO | C43: =Ger_Executivo!N90 -> 511572.58 | D43: =C43/C$53 -> 0.0083879404 | E43: =C43/$E$9 -> 29.223434
B44: PISOS E PAVIMENTAÇÕES | C44: =Ger_Executivo!N187 -> 2539181.4 | D44: =C44/C$53 -> 0.041633393 | E44: =C44/$E$9 -> 145.05
B45: PINTURA INTERNA | C45: =Ger_Executivo!N206 -> 786426.24 | D45: =C45/C$53 -> 0.012894546 | E45: =C45/$E$9 -> 44.924369
B46: REVESTIMENTOS E ACABAMENTOS DE FACHADA | C46: =Ger_Executivo!N258 -> 561222.52 | D46: =C46/C$53 -> 0.0092020199 | E46: =C46/$E$9 -> 32.059673
B47: ESQUADRIAS, VIDROS E FERRAGENS | C47: =Ger_Executivo!N216 -> 5007297.9 | D47: =C47/C$53 -> 0.082101579 | E47: =C47/$E$9 -> 286.04043
B48: LOUÇAS E METAIS | C48: =Ger_Executivo!N250 -> 510955.57 | D48: =C48/C$53 -> 0.0083778236 | E48: =C48/$E$9 -> 29.188188
B49: EQUIPAMENTOS E SISTEMAS ESPECIAIS | C49: =Ger_Executivo!N145+Ger_Executivo!N137 -> 2305575 | D49: =C49/C$53 -> 0.037803093 | E49: =C49/$E$9 -> 131.7053
B50: SERVIÇOS COMPLEMENTARES | C50: =Ger_Executivo!N272 -> 1941982 | D50: =C50/C$53 -> 0.031841482 | E50: =C50/$E$9 -> 110.93515
B51: MÃO DE OBRA | C51: =Ger_Executivo!N291 -> 22603060 | D51: =C51/C$53 -> 0.37060845 | E51: =C51/$E$9 -> 1291.1932
B52: IMPREVISTOS | C52: =Ger_Executivo!N327 -> 680745.43 | D52: =C52/C$53 -> 0.011161763 | E52: =C52/$E$9 -> 38.887384
B53: TOTAL | C53: =SUM(C33:C52) -> 60989058 | D53: =SUM(D33:D52) -> 1 | E53: =SUM(E33:E52) -> 3483.9821
...

Sheet Ger_Tec e Adm
G4: PROJETO: | I4: ='Obra '!D1 -> 365 | O4: REVISÃO: | P4: DATA
G5: EMPRESA: | I5: ='Obra '!D2 -> COTA | O5: ='Obra '!D3 -> R00 | P5: 45551
A6: Unidade Construtiva | B6: Célula Construtiva | C6: Etapa | D6: Subetapa | E6: Serviço | G6: GERENCIAMENTO EXECUTIVO
A7: 0 | B7: 0 | C7: 0 | D7: 0 | E7: 0 | G7: Atalho | H7: NIVEL | I7: Item | J7: Descrição | K7: Unidade | L7: Quant. | M7: Preço un | N7: Total | O7: Considerações | P7: Situação
A8: =IF($H8="UNIDADE CONSTRUTIVA",OFFSET(A8,-1,0)+1,LARGE(A$3:A7,1)) -> 0 | B8: =IF(H8="UNIDADE CONSTRUTIVA",0,IF(H8="CÉLULA CONSTRUTIVA",OFFSET(B8,-1,0)+1,OFFSET(B8,-1,0))) -> 1 | C8: =IF(H8="CÉLULA CONSTRUTIVA",0,IF(H8="ETAPA",OFFSET(C8,-1,0)+1,OFFSET(C8,-1,0))) -> 0 | D8: =IF(H8="ETAPA",0,IF(H8="SUBETAPA",OFFSET(D8,-1,0)+1,OFFSET(D8,-1,0))) -> 0 | E8: =IF(H8="Subetapa",0,IF(H8="serviço",OFFSET(E8,-1,0)+1,OFFSET(E8,-1,0))) -> 0 | H8: CÉLULA CONSTRUTIVA | I8: =IF(H8="Unidade Construtiva",TEXT(A8,"00"),IF(H8="Célula Construtiva",TEXT(B8,"00"),IF(H8="Etapa",CONCATENATE(TEXT(B8,"00"),".",TEXT(C8,"000")),IF(H8="Subetapa",CONCATENATE(TEXT(B8,"00"),".",TEXT(C8,"000"),".",TEXT(D8,"000")),IF(H8="Serviço",CONCATENATE(TEXT(B8,"00"),".",TEXT(C8,"000"),".",TEXT(D8,"000"),".",TEXT(E8,"000")),""))))) -> 01 | J8: SERVIÇOS TÉCNICOS | N8: =IF(H8="Serviço",M8*L8,IF(H8="CÉLULA CONSTRUTIVA",SUMIFS($N$8:$N$397,$B$8:$B$397,B8,$H$8:$H$397,"Serviço"),IF(H8="ETAPA",SUMIFS($N$8:$N$397,$B$8:$B$397,B8,$C$8:$C$397,C8,$H$8:$H$397,"Serviço"),IF(H8="SUBETAPA",SUMIFS($N$8:$N$397,$B$8:$B$397,B8,$C$8:$C$397,C8,$D$8:$D$397,D8,$H$8:$H$397,"Serviço"),0)))) -> 1783946.5 | P8: -
A9: =IF($H9="UNIDADE CONSTRUTIVA",OFFSET(A9,-1,0)+1,LARGE(A$3:A8,1)) -> 0 | B9: =IF(H9="UNIDADE CONSTRUTIVA",0,IF(H9="CÉLULA CONSTRUTIVA",OFFSET(B9,-1,0)+1,OFFSET(B9,-1,0))) -> 1 | C9: =IF(H9="CÉLULA CONSTRUTIVA",0,IF(H9="ETAPA",OFFSET(C9,-1,0)+1,OFFSET(C9,-1,0))) -> 1 | D9: =IF(H9="ETAPA",0,IF(H9="SUBETAPA",OFFSET(D9,-1,0)+1,OFFSET(D9,-1,0))) -> 0 | E9: =IF(H9="Subetapa",0,IF(H9="serviço",OFFSET(E9,-1,0)+1,OFFSET(E9,-1,0))) -> 0 | H9: ETAPA | I9: =IF(H9="Unidade Construtiva",TEXT(A9,"00"),IF(H9="Célula Construtiva",TEXT(B9,"00"),IF(H9="Etapa",CONCATENATE(TEXT(B9,"00"),".",TEXT(C9,"000")),IF(H9="Subetapa",CONCATENATE(TEXT(B9,"00"),".",TEXT(C9,"000"),".",TEXT(D9,"000")),IF(H9="Serviço",CONCATENATE(TEXT(B9,"00"),".",TEXT(C9,"000"),".",TEXT(D9,"000"),".",TEXT(E9,"000")),""))))) -> 01.001 | J9: ESTUDOS, PROJETOS, CONSULTORIA E ENSAIOS | N9: =IF(H9="Serviço",M9*L9,IF(H9="CÉLULA CONSTRUTIVA",SUMIFS($N$8:$N$397,$B$8:$B$397,B9,$H$8:$H$397,"Serviço"),IF(H9="ETAPA",SUMIFS($N$8:$N$397,$B$8:$B$397,B9,$C$8:$C$397,C9,$H$8:$H$397,"Serviço"),IF(H9="SUBETAPA",SUMIFS($N$8:$N$397,$B$8:$B$397,B9,$C$8:$C$397,C9,$D$8:$D$397,D9,$H$8:$H$397,"Serviço"),0)))) -> 1380455.6 | P9: -
A10: =IF($H10="UNIDADE CONSTRUTIVA",OFFSET(A10,-1,0)+1,LARGE(A$3:A9,1)) -> 0 | B10: =IF(H10="UNIDADE CONSTRUTIVA",0,IF(H10="CÉLULA CONSTRUTIVA",OFFSET(B10,-1,0)+1,OFFSET(B10,-1,0))) -> 1 | C10: =IF(H10="CÉLULA CONSTRUTIVA",0,IF(H10="ETAPA",OFFSET(C10,-1,0)+1,OFFSET(C10,-1,0))) -> 1 | D10: =IF(H10="ETAPA",0,IF(H10="SUBETAPA",OFFSET(D10,-1,0)+1,OFFSET(D10,-1,0))) -> 1 | E10: =IF(H10="Subetapa",0,IF(H10="serviço",OFFSET(E10,-1,0)+1,OFFSET(E10,-1,0))) -> 0 | H10: SUBETAPA | I10: =IF(H10="Unidade Construtiva",TEXT(A10,"00"),IF(H10="Célula Construtiva",TEXT(B10,"00"),IF(H10="Etapa",CONCATENATE(TEXT(B10,"00"),".",TEXT(C10,"000")),IF(H10="Subetapa",CONCATENATE(TEXT(B10,"00"),".",TEXT(C10,"000"),".",TEXT(D10,"000")),IF(H10="Serviço",CONCATENATE(TEXT(B10,"00"),".",TEXT(C10,"000"),".",TEXT(D10,"000"),".",TEXT(E10,"000")),""))))) -> 01.001.001 | J10: Estudos | N10: =IF(H10="Serviço",M10*L10,IF(H10="CÉLULA CONSTRUTIVA",SUMIFS($N$8:$N$397,$B$8:$B$397,B10,$H$8:$H$397,"Serviço"),IF(H10="ETAPA",SUMIFS($N$8:$N$397,$B$8:$B$397,B10,$C$8:$C$397,C10,$H$8:$H$397,"Serviço"),IF(H10="SUBETAPA",SUMIFS($N$8:$N$397,$B$8:$B$397,B10,$C$8:$C$397,C10,$D$8:$D$397,D10,$H$8:$H$397,"Serviço"),0)))) -> 53255.71
A11: =IF($H11="UNIDADE CONSTRUTIVA",OFFSET(A11,-1,0)+1,LARGE(A$3:A10,1)) -> 0 | B11: =IF(H11="UNIDADE CONSTRUTIVA",0,IF(H11="CÉLULA CONSTRUTIVA",OFFSET(B11,-1,0)+1,OFFSET(B11,-1,0))) -> 1 | C11: =IF(H11="CÉLULA CONSTRUTIVA",0,IF(H11="ETAPA",OFFSET(C11,-1,0)+1,OFFSET(C11,-1,0))) -> 1 | D11: =IF(H11="ETAPA",0,IF(H11="SUBETAPA",OFFSET(D11,-1,0)+1,OFFSET(D11,-1,0))) -> 1 | E11: =IF(H11="Subetapa",0,IF(H11="serviço",OFFSET(E11,-1,0)+1,OFFSET(E11,-1,0))) -> 1 | G11: 2149 | H11: SERVIÇO | I11: =IF(H11="Unidade Construtiva",TEXT(A11,"00"),IF(H11="Célula Construtiva",TEXT(B11,"00"),IF(H11="Etapa",CONCATENATE(TEXT(B11,"00"),".",TEXT(C11,"000")),IF(H11="Subetapa",CONCATENATE(TEXT(B11,"00"),".",TEXT(C11,"000"),".",TEXT(D11,"000")),IF(H11="Serviço",CONCATENATE(TEXT(B11,"00"),".",TEXT(C11,"000"),".",TEXT(D11,"000"),".",TEXT(E11,"000")),""))))) -> 01.001.001.001 | J11: Levantamento Topográfico | K11: vb | L11: 1 | M11: 9350.6735 | N11: =IF(H11="Serviço",M11*L11,IF(H11="CÉLULA CONSTRUTIVA",SUMIFS($N$8:$N$397,$B$8:$B$397,B11,$H$8:$H$397,"Serviço"),IF(H11="ETAPA",SUMIFS($N$8:$N$397,$B$8:$B$397,B11,$C$8:$C$397,C11,$H$8:$H$397,"Serviço"),IF(H11="SUBETAPA",SUMIFS($N$8:$N$397,$B$8:$B$397,B11,$C$8:$C$397,C11,$D$8:$D$397,D11,$H$8:$H$397,"Serviço"),0)))) -> 9350.6735 | P11: Lançado ERP
A12: =IF($H12="UNIDADE CONSTRUTIVA",OFFSET(A12,-1,0)+1,LARGE(A$3:A11,1)) -> 0 | B12: =IF(H12="UNIDADE CONSTRUTIVA",0,IF(H12="CÉLULA CONSTRUTIVA",OFFSET(B12,-1,0)+1,OFFSET(B12,-1,0))) -> 1 | C12: =IF(H12="CÉLULA CONSTRUTIVA",0,IF(H12="ETAPA",OFFSET(C12,-1,0)+1,OFFSET(C12,-1,0))) -> 1 | D12: =IF(H12="ETAPA",0,IF(H12="SUBETAPA",OFFSET(D12,-1,0)+1,OFFSET(D12,-1,0))) -> 1 | E12: =IF(H12="Subetapa",0,IF(H12="serviço",OFFSET(E12,-1,0)+1,OFFSET(E12,-1,0))) -> 2 | G12: 4666 | H12: SERVIÇO | I12: =IF(H12="Unidade Construtiva",TEXT(A12,"00"),IF(H12="Célula Construtiva",TEXT(B12,"00"),IF(H12="Etapa",CONCATENATE(TEXT(B12,"00"),".",TEXT(C12,"000")),IF(H12="Subetapa",CONCATENATE(TEXT(B12,"00"),".",TEXT(C12,"000"),".",TEXT(D12,"000")),IF(H12="Serviço",CONCATENATE(TEXT(B12,"00"),".",TEXT(C12,"000"),".",TEXT(D12,"000"),".",TEXT(E12,"000")),""))))) -> 01.001.001.002 | J12: Estudo ambiental | K12: vb | L12: 1 | M12: 25248.338 | N12: =IF(H12="Serviço",M12*L12,IF(H12="CÉLULA CONSTRUTIVA",SUMIFS($N$8:$N$397,$B$8:$B$397,B12,$H$8:$H$397,"Serviço"),IF(H12="ETAPA",SUMIFS($N$8:$N$397,$B$8:$B$397,B12,$C$8:$C$397,C12,$H$8:$H$397,"Serviço"),IF(H12="SUBETAPA",SUMIFS($N$8:$N$397,$B$8:$B$397,B12,$C$8:$C$397,C12,$D$8:$D$397,D12,$H$8:$H$397,"Serviço"),0)))) -> 25248.338 | P12: Lançado ERP
A13: =IF($H13="UNIDADE CONSTRUTIVA",OFFSET(A13,-1,0)+1,LARGE(A$3:A12,1)) -> 0 | B13: =IF(H13="UNIDADE CONSTRUTIVA",0,IF(H13="CÉLULA CONSTRUTIVA",OFFSET(B13,-1,0)+1,OFFSET(B13,-1,0))) -> 1 | C13: =IF(H13="CÉLULA CONSTRUTIVA",0,IF(H13="ETAPA",OFFSET(C13,-1,0)+1,OFFSET(C13,-1,0))) -> 1 | D13: =IF(H13="ETAPA",0,IF(H13="SUBETAPA",OFFSET(D13,-1,0)+1,OFFSET(D13,-1,0))) -> 1 | E13: =IF(H13="Subetapa",0,IF(H13="serviço",OFFSET(E13,-1,0)+1,OFFSET(E13,-1,0))) -> 3 | G13: 2153 | H13: SERVIÇO | I13: =IF(H13="Unidade Construtiva",TEXT(A13,"00"),IF(H13="Célula Construtiva",TEXT(B13,"00"),IF(H13="Etapa",CONCATENATE(TEXT(B13,"00"),".",TEXT(C13,"000")),IF(H13="Subetapa",CONCATENATE(TEXT(B13,"00"),".",TEXT(C13,"000"),".",TEXT(D13,"000")),IF(H13="Serviço",CONCATENATE(TEXT(B13,"00"),".",TEXT(C13,"000"),".",TEXT(D13,"000"),".",TEXT(E13,"000")),""))))) -> 01.001.001.003 | J13: Sondagem do terreno | K13: vb | L13: 1 | M13: 18656.699 | N13: =IF(H13="Serviço",M13*L13,IF(H13="CÉLULA CONSTRUTIVA",SUMIFS($N$8:$N$397,$B$8:$B$397,B13,$H$8:$H$397,"Serviço"),IF(H13="ETAPA",SUMIFS($N$8:$N$397,$B$8:$B$397,B13,$C$8:$C$397,C13,$H$8:$H$397,"Serviço"),IF(H13="SUBETAPA",SUMIFS($N$8:$N$397,$B$8:$B$397,B13,$C$8:$C$397,C13,$D$8:$D$397,D13,$H$8:$H$397,"Serviço"),0)))) -> 18656.699 | P13: Lançado ERP
A14: =IF($H14="UNIDADE CONSTRUTIVA",OFFSET(A14,-1,0)+1,LARGE(A$3:A13,1)) -> 0 | B14: =IF(H14="UNIDADE CONSTRUTIVA",0,IF(H14="CÉLULA CONSTRUTIVA",OFFSET(B14,-1,0)+1,OFFSET(B14,-1,0))) -> 1 | C14: =IF(H14="CÉLULA CONSTRUTIVA",0,IF(H14="ETAPA",OFFSET(C14,-1,0)+1,OFFSET(C14,-1,0))) -> 1 | D14: =IF(H14="ETAPA",0,IF(H14="SUBETAPA",OFFSET(D14,-1,0)+1,OFFSET(D14,-1,0))) -> 2 | E14: =IF(H14="Subetapa",0,IF(H14="serviço",OFFSET(E14,-1,0)+1,OFFSET(E14,-1,0))) -> 0 | H14: SUBETAPA | I14: =IF(H14="Unidade Construtiva",TEXT(A14,"00"),IF(H14="Célula Construtiva",TEXT(B14,"00"),IF(H14="Etapa",CONCATENATE(TEXT(B14,"00"),".",TEXT(C14,"000")),IF(H14="Subetapa",CONCATENATE(TEXT(B14,"00"),".",TEXT(C14,"000"),".",TEXT(D14,"000")),IF(H14="Serviço",CONCATENATE(TEXT(B14,"00"),".",TEXT(C14,"000"),".",TEXT(D14,"000"),".",TEXT(E14,"000")),""))))) -> 01.001.002 | J14: Projetos | N14: =IF(H14="Serviço",M14*L14,IF(H14="CÉLULA CONSTRUTIVA",SUMIFS($N$8:$N$397,$B$8:$B$397,B14,$H$8:$H$397,"Serviço"),IF(H14="ETAPA",SUMIFS($N$8:$N$397,$B$8:$B$397,B14,$C$8:$C$397,C14,$H$8:$H$397,"Serviço"),IF(H14="SUBETAPA",SUMIFS($N$8:$N$397,$B$8:$B$397,B14,$C$8:$C$397,C14,$D$8:$D$397,D14,$H$8:$H$397,"Serviço"),0)))) -> 1138195.7
A15: =IF($H15="UNIDADE CONSTRUTIVA",OFFSET(A15,-1,0)+1,LARGE(A$3:A14,1)) -> 0 | B15: =IF(H15="UNIDADE CONSTRUTIVA",0,IF(H15="CÉLULA CONSTRUTIVA",OFFSET(B15,-1,0)+1,OFFSET(B15,-1,0))) -> 1 | C15: =IF(H15="CÉLULA CONSTRUTIVA",0,IF(H15="ETAPA",OFFSET(C15,-1,0)+1,OFFSET(C15,-1,0))) -> 1 | D15: =IF(H15="ETAPA",0,IF(H15="SUBETAPA",OFFSET(D15,-1,0)+1,OFFSET(D15,-1,0))) -> 2 | E15: =IF(H15="Subetapa",0,IF(H15="serviço",OFFSET(E15,-1,0)+1,OFFSET(E15,-1,0))) -> 1 | G15: 4706 | H15: SERVIÇO | I15: =IF(H15="Unidade Construtiva",TEXT(A15,"00"),IF(H15="Célula Construtiva",TEXT(B15,"00"),IF(H15="Etapa",CONCATENATE(TEXT(B15,"00"),".",TEXT(C15,"000")),IF(H15="Subetapa",CONCATENATE(TEXT(B15,"00"),".",TEXT(C15,"000"),".",TEXT(D15,"000")),IF(H15="Serviço",CONCATENATE(TEXT(B15,"00"),".",TEXT(C15,"000"),".",TEXT(D15,"000"),".",TEXT(E15,"000")),""))))) -> 01.001.002.001 | J15: Legalização de incorporação | K15: vb | L15: 1 | M15: 133121.85 | N15: =IF(H15="Serviço",M15*L15,IF(H15="CÉLULA CONSTRUTIVA",SUMIFS($N$8:$N$397,$B$8:$B$397,B15,$H$8:$H$397,"Serviço"),IF(H15="ETAPA",SUMIFS($N$8:$N$397,$B$8:$B$397,B15,$C$8:$C$397,C15,$H$8:$H$397,"Serviço"),IF(H15="SUBETAPA",SUMIFS($N$8:$N$397,$B$8:$B$397,B15,$C$8:$C$397,C15,$D$8:$D$397,D15,$H$8:$H$397,"Serviço"),0)))) -> 133121.85 | P15: Lançado ERP
A16: =IF($H16="UNIDADE CONSTRUTIVA",OFFSET(A16,-1,0)+1,LARGE(A$3:A15,1)) -> 0 | B16: =IF(H16="UNIDADE CONSTRUTIVA",0,IF(H16="CÉLULA CONSTRUTIVA",OFFSET(B16,-1,0)+1,OFFSET(B16,-1,0))) -> 1 | C16: =IF(H16="CÉLULA CONSTRUTIVA",0,IF(H16="ETAPA",OFFSET(C16,-1,0)+1,OFFSET(C16,-1,0))) -> 1 | D16: =IF(H16="ETAPA",0,IF(H16="SUBETAPA",OFFSET(D16,-1,0)+1,OFFSET(D16,-1,0))) -> 2 | E16: =IF(H16="Subetapa",0,IF(H16="serviço",OFFSET(E16,-1,0)+1,OFFSET(E16,-1,0))) -> 2 | H16: SERVIÇO | I16: =IF(H16="Unidade Construtiva",TEXT(A16,"00"),IF(H16="Célula Construtiva",TEXT(B16,"00"),IF(H16="Etapa",CONCATENATE(TEXT(B16,"00"),".",TEXT(C16,"000")),IF(H16="Subetapa",CONCATENATE(TEXT(B16,"00"),".",TEXT(C16,"000"),".",TEXT(D16,"000")),IF(H16="Serviço",CONCATENATE(TEXT(B16,"00"),".",TEXT(C16,"000"),".",TEXT(D16,"000"),".",TEXT(E16,"000")),""))))) -> 01.001.002.002 | J16: Projeto arquitetônico legal | K16: vb | L16: 1 | M16: 163931.27 | N16: =IF(H16="Serviço",M16*L16,IF(H16="CÉLULA CONSTRUTIVA",SUMIFS($N$8:$N$397,$B$8:$B$397,B16,$H$8:$H$397,"Serviço"),IF(H16="ETAPA",SUMIFS($N$8:$N$397,$B$8:$B$397,B16,$C$8:$C$397,C16,$H$8:$H$397,"Serviço"),IF(H16="SUBETAPA",SUMIFS($N$8:$N$397,$B$8:$B$397,B16,$C$8:$C$397,C16,$D$8:$D$397,D16,$H$8:$H$397,"Serviço"),0)))) -> 163931.27 | P16: Lançado ERP
A17: =IF($H17="UNIDADE CONSTRUTIVA",OFFSET(A17,-1,0)+1,LARGE(A$3:A16,1)) -> 0 | B17: =IF(H17="UNIDADE CONSTRUTIVA",0,IF(H17="CÉLULA CONSTRUTIVA",OFFSET(B17,-1,0)+1,OFFSET(B17,-1,0))) -> 1 | C17: =IF(H17="CÉLULA CONSTRUTIVA",0,IF(H17="ETAPA",OFFSET(C17,-1,0)+1,OFFSET(C17,-1,0))) -> 1 | D17: =IF(H17="ETAPA",0,IF(H17="SUBETAPA",OFFSET(D17,-1,0)+1,OFFSET(D17,-1,0))) -> 2 | E17: =IF(H17="Subetapa",0,IF(H17="serviço",OFFSET(E17,-1,0)+1,OFFSET(E17,-1,0))) -> 3 | H17: SERVIÇO | I17: =IF(H17="Unidade Construtiva",TEXT(A17,"00"),IF(H17="Célula Construtiva",TEXT(B17,"00"),IF(H17="Etapa",CONCATENATE(TEXT(B17,"00"),".",TEXT(C17,"000")),IF(H17="Subetapa",CONCATENATE(TEXT(B17,"00"),".",TEXT(C17,"000"),".",TEXT(D17,"000")),IF(H17="Serviço",CONCATENATE(TEXT(B17,"00"),".",TEXT(C17,"000"),".",TEXT(D17,"000"),".",TEXT(E17,"000")),""))))) -> 01.001.002.003 | J17: Projeto arquitetônico executivo | K17: vb | L17: 1 | M17: 87917.954 | N17: =IF(H17="Serviço",M17*L17,IF(H17="CÉLULA CONSTRUTIVA",SUMIFS($N$8:$N$397,$B$8:$B$397,B17,$H$8:$H$397,"Serviço"),IF(H17="ETAPA",SUMIFS($N$8:$N$397,$B$8:$B$397,B17,$C$8:$C$397,C17,$H$8:$H$397,"Serviço"),IF(H17="SUBETAPA",SUMIFS($N$8:$N$397,$B$8:$B$397,B17,$C$8:$C$397,C17,$D$8:$D$397,D17,$H$8:$H$397,"Serviço"),0)))) -> 87917.954 | P17: Lançado ERP
A18: =IF($H18="UNIDADE CONSTRUTIVA",OFFSET(A18,-1,0)+1,LARGE(A$3:A16,1)) -> 0 | B18: =IF(H18="UNIDADE CONSTRUTIVA",0,IF(H18="CÉLULA CONSTRUTIVA",OFFSET(B18,-1,0)+1,OFFSET(B18,-1,0))) -> 1 | C18: =IF(H18="CÉLULA CONSTRUTIVA",0,IF(H18="ETAPA",OFFSET(C18,-1,0)+1,OFFSET(C18,-1,0))) -> 1 | D18: =IF(H18="ETAPA",0,IF(H18="SUBETAPA",OFFSET(D18,-1,0)+1,OFFSET(D18,-1,0))) -> 2 | E18: =IF(H18="Subetapa",0,IF(H18="serviço",OFFSET(E18,-1,0)+1,OFFSET(E18,-1,0))) -> 4 | H18: SERVIÇO | I18: =IF(H18="Unidade Construtiva",TEXT(A18,"00"),IF(H18="Célula Construtiva",TEXT(B18,"00"),IF(H18="Etapa",CONCATENATE(TEXT(B18,"00"),".",TEXT(C18,"000")),IF(H18="Subetapa",CONCATENATE(TEXT(B18,"00"),".",TEXT(C18,"000"),".",TEXT(D18,"000")),IF(H18="Serviço",CONCATENATE(TEXT(B18,"00"),".",TEXT(C18,"000"),".",TEXT(D18,"000"),".",TEXT(E18,"000")),""))))) -> 01.001.002.004 | J18: Projeto arquitetônico interiores/ambientação | K18: vb | L18: 1 | M18: 81457.198 | N18: =IF(H18="Serviço",M18*L18,IF(H18="CÉLULA CONSTRUTIVA",SUMIFS($N$8:$N$397,$B$8:$B$397,B18,$H$8:$H$397,"Serviço"),IF(H18="ETAPA",SUMIFS($N$8:$N$397,$B$8:$B$397,B18,$C$8:$C$397,C18,$H$8:$H$397,"Serviço"),IF(H18="SUBETAPA",SUMIFS($N$8:$N$397,$B$8:$B$397,B18,$C$8:$C$397,C18,$D$8:$D$397,D18,$H$8:$H$397,"Serviço"),0)))) -> 81457.198 | P18: Lançado ERP
A19: =IF($H19="UNIDADE CONSTRUTIVA",OFFSET(A19,-1,0)+1,LARGE(A$3:A17,1)) -> 0 | B19: =IF(H19="UNIDADE CONSTRUTIVA",0,IF(H19="CÉLULA CONSTRUTIVA",OFFSET(B19,-1,0)+1,OFFSET(B19,-1,0))) -> 1 | C19: =IF(H19="CÉLULA CONSTRUTIVA",0,IF(H19="ETAPA",OFFSET(C19,-1,0)+1,OFFSET(C19,-1,0))) -> 1 | D19: =IF(H19="ETAPA",0,IF(H19="SUBETAPA",OFFSET(D19,-1,0)+1,OFFSET(D19,-1,0))) -> 2 | E19: =IF(H19="Subetapa",0,IF(H19="serviço",OFFSET(E19,-1,0)+1,OFFSET(E19,-1,0))) -> 5 | H19: SERVIÇO | I19: =IF(H19="Unidade Construtiva",TEXT(A19,"00"),IF(H19="Célula Construtiva",TEXT(B19,"00"),IF(H19="Etapa",CONCATENATE(TEXT(B19,"00"),".",TEXT(C19,"000")),IF(H19="Subetapa",CONCATENATE(TEXT(B19,"00"),".",TEXT(C19,"000"),".",TEXT(D19,"000")),IF(H19="Serviço",CONCATENATE(TEXT(B19,"00"),".",TEXT(C19,"000"),".",TEXT(D19,"000"),".",TEXT(E19,"000")),""))))) -> 01.001.002.005 | J19: Projeto técnico de fachada | K19: vb | L19: 1 | M19: 16003.599 | N19: =IF(H19="Serviço",M19*L19,IF(H19="CÉLULA CONSTRUTIVA",SUMIFS($N$8:$N$397,$B$8:$B$397,B19,$H$8:$H$397,"Serviço"),IF(H19="ETAPA",SUMIFS($N$8:$N$397,$B$8:$B$397,B19,$C$8:$C$397,C19,$H$8:$H$397,"Serviço"),IF(H19="SUBETAPA",SUMIFS($N$8:$N$397,$B$8:$B$397,B19,$C$8:$C$397,C19,$D$8:$D$397,D19,$H$8:$H$397,"Serviço"),0)))) -> 16003.599 | P19: Lançado ERP
A20: =IF($H20="UNIDADE CONSTRUTIVA",OFFSET(A20,-1,0)+1,LARGE(A$3:A16,1)) -> 0 | B20: =IF(H20="UNIDADE CONSTRUTIVA",0,IF(H20="CÉLULA CONSTRUTIVA",OFFSET(B20,-1,0)+1,OFFSET(B20,-1,0))) -> 1 | C20: =IF(H20="CÉLULA CONSTRUTIVA",0,IF(H20="ETAPA",OFFSET(C20,-1,0)+1,OFFSET(C20,-1,0))) -> 1 | D20: =IF(H20="ETAPA",0,IF(H20="SUBETAPA",OFFSET(D20,-1,0)+1,OFFSET(D20,-1,0))) -> 2 | E20: =IF(H20="Subetapa",0,IF(H20="serviço",OFFSET(E20,-1,0)+1,OFFSET(E20,-1,0))) -> 6 | H20: SERVIÇO | I20: =IF(H20="Unidade Construtiva",TEXT(A20,"00"),IF(H20="Célula Construtiva",TEXT(B20,"00"),IF(H20="Etapa",CONCATENATE(TEXT(B20,"00"),".",TEXT(C20,"000")),IF(H20="Subetapa",CONCATENATE(TEXT(B20,"00"),".",TEXT(C20,"000"),".",TEXT(D20,"000")),IF(H20="Serviço",CONCATENATE(TEXT(B20,"00"),".",TEXT(C20,"000"),".",TEXT(D20,"000"),".",TEXT(E20,"000")),""))))) -> 01.001.002.006 | J20: Projeto de Fundação | K20: vb | L20: 1 | M20: 34231.753 | N20: =IF(H20="Serviço",M20*L20,IF(H20="CÉLULA CONSTRUTIVA",SUMIFS($N$8:$N$397,$B$8:$B$397,B20,$H$8:$H$397,"Serviço"),IF(H20="ETAPA",SUMIFS($N$8:$N$397,$B$8:$B$397,B20,$C$8:$C$397,C20,$H$8:$H$397,"Serviço"),IF(H20="SUBETAPA",SUMIFS($N$8:$N$397,$B$8:$B$397,B20,$C$8:$C$397,C20,$D$8:$D$397,D20,$H$8:$H$397,"Serviço"),0)))) -> 34231.753 | P20: Lançado ERP
A21: =IF($H21="UNIDADE CONSTRUTIVA",OFFSET(A21,-1,0)+1,LARGE(A$3:A18,1)) -> 0 | B21: =IF(H21="UNIDADE CONSTRUTIVA",0,IF(H21="CÉLULA CONSTRUTIVA",OFFSET(B21,-1,0)+1,OFFSET(B21,-1,0))) -> 1 | C21: =IF(H21="CÉLULA CONSTRUTIVA",0,IF(H21="ETAPA",OFFSET(C21,-1,0)+1,OFFSET(C21,-1,0))) -> 1 | D21: =IF(H21="ETAPA",0,IF(H21="SUBETAPA",OFFSET(D21,-1,0)+1,OFFSET(D21,-1,0))) -> 2 | E21: =IF(H21="Subetapa",0,IF(H21="serviço",OFFSET(E21,-1,0)+1,OFFSET(E21,-1,0))) -> 7 | H21: SERVIÇO | I21: =IF(H21="Unidade Construtiva",TEXT(A21,"00"),IF(H21="Célula Construtiva",TEXT(B21,"00"),IF(H21="Etapa",CONCATENATE(TEXT(B21,"00"),".",TEXT(C21,"000")),IF(H21="Subetapa",CONCATENATE(TEXT(B21,"00"),".",TEXT(C21,"000"),".",TEXT(D21,"000")),IF(H21="Serviço",CONCATENATE(TEXT(B21,"00"),".",TEXT(C21,"000"),".",TEXT(D21,"000"),".",TEXT(E21,"000")),""))))) -> 01.001.002.007 | J21: Projeto Estrutura | K21: vb | L21: 1 | M21: 109121.83 | N21: =IF(H21="Serviço",M21*L21,IF(H21="CÉLULA CONSTRUTIVA",SUMIFS($N$8:$N$397,$B$8:$B$397,B21,$H$8:$H$397,"Serviço"),IF(H21="ETAPA",SUMIFS($N$8:$N$397,$B$8:$B$397,B21,$C$8:$C$397,C21,$H$8:$H$397,"Serviço"),IF(H21="SUBETAPA",SUMIFS($N$8:$N$397,$B$8:$B$397,B21,$C$8:$C$397,C21,$D$8:$D$397,D21,$H$8:$H$397,"Serviço"),0)))) -> 109121.83 | P21: Lançado ERP
A22: =IF($H22="UNIDADE CONSTRUTIVA",OFFSET(A22,-1,0)+1,LARGE(A$3:A21,1)) -> 0 | B22: =IF(H22="UNIDADE CONSTRUTIVA",0,IF(H22="CÉLULA CONSTRUTIVA",OFFSET(B22,-1,0)+1,OFFSET(B22,-1,0))) -> 1 | C22: =IF(H22="CÉLULA CONSTRUTIVA",0,IF(H22="ETAPA",OFFSET(C22,-1,0)+1,OFFSET(C22,-1,0))) -> 1 | D22: =IF(H22="ETAPA",0,IF(H22="SUBETAPA",OFFSET(D22,-1,0)+1,OFFSET(D22,-1,0))) -> 2 | E22: =IF(H22="Subetapa",0,IF(H22="serviço",OFFSET(E22,-1,0)+1,OFFSET(E22,-1,0))) -> 8 | H22: SERVIÇO | I22: =IF(H22="Unidade Construtiva",TEXT(A22,"00"),IF(H22="Célula Construtiva",TEXT(B22,"00"),IF(H22="Etapa",CONCATENATE(TEXT(B22,"00"),".",TEXT(C22,"000")),IF(H22="Subetapa",CONCATENATE(TEXT(B22,"00"),".",TEXT(C22,"000"),".",TEXT(D22,"000")),IF(H22="Serviço",CONCATENATE(TEXT(B22,"00"),".",TEXT(C22,"000"),".",TEXT(D22,"000"),".",TEXT(E22,"000")),""))))) -> 01.001.002.008 | J22: Projeto elétrico/comunicação/telefonia/luminotécnico | K22: vb | L22: 1 | M22: 225325.76 | N22: =IF(H22="Serviço",M22*L22,IF(H22="CÉLULA CONSTRUTIVA",SUMIFS($N$8:$N$397,$B$8:$B$397,B22,$H$8:$H$397,"Serviço"),IF(H22="ETAPA",SUMIFS($N$8:$N$397,$B$8:$B$397,B22,$C$8:$C$397,C22,$H$8:$H$397,"Serviço"),IF(H22="SUBETAPA",SUMIFS($N$8:$N$397,$B$8:$B$397,B22,$C$8:$C$397,C22,$D$8:$D$397,D22,$H$8:$H$397,"Serviço"),0)))) -> 225325.76 | P22: Lançado ERP
A23: =IF($H23="UNIDADE CONSTRUTIVA",OFFSET(A23,-1,0)+1,LARGE(A$3:A22,1)) -> 0 | B23: =IF(H23="UNIDADE CONSTRUTIVA",0,IF(H23="CÉLULA CONSTRUTIVA",OFFSET(B23,-1,0)+1,OFFSET(B23,-1,0))) -> 1 | C23: =IF(H23="CÉLULA CONSTRUTIVA",0,IF(H23="ETAPA",OFFSET(C23,-1,0)+1,OFFSET(C23,-1,0))) -> 1 | D23: =IF(H23="ETAPA",0,IF(H23="SUBETAPA",OFFSET(D23,-1,0)+1,OFFSET(D23,-1,0))) -> 2 | E23: =IF(H23="Subetapa",0,IF(H23="serviço",OFFSET(E23,-1,0)+1,OFFSET(E23,-1,0))) -> 9 | H23: SERVIÇO | I23: =IF(H23="Unidade Construtiva",TEXT(A23,"00"),IF(H23="Célula Construtiva",TEXT(B23,"00"),IF(H23="Etapa",CONCATENATE(TEXT(B23,"00"),".",TEXT(C23,"000")),IF(H23="Subetapa",CONCATENATE(TEXT(B23,"00"),".",TEXT(C23,"000"),".",TEXT(D23,"000")),IF(H23="Serviço",CONCATENATE(TEXT(B23,"00"),".",TEXT(C23,"000"),".",TEXT(D23,"000"),".",TEXT(E23,"000")),""))))) -> 01.001.002.009 | J23: Projeto hidrossanitário/drenagem/pluvial | K23: vb | L23: 1 | M23: 60933.617 | N23: =IF(H23="Serviço",M23*L23,IF(H23="CÉLULA CONSTRUTIVA",SUMIFS($N$8:$N$397,$B$8:$B$397,B23,$H$8:$H$397,"Serviço"),IF(H23="ETAPA",SUMIFS($N$8:$N$397,$B$8:$B$397,B23,$C$8:$C$397,C23,$H$8:$H$397,"Serviço"),IF(H23="SUBETAPA",SUMIFS($N$8:$N$397,$B$8:$B$397,B23,$C$8:$C$397,C23,$D$8:$D$397,D23,$H$8:$H$397,"Serviço"),0)))) -> 60933.617 | P23: Lançado ERP
A24: =IF($H24="UNIDADE CONSTRUTIVA",OFFSET(A24,-1,0)+1,LARGE(A$3:A23,1)) -> 0 | B24: =IF(H24="UNIDADE CONSTRUTIVA",0,IF(H24="CÉLULA CONSTRUTIVA",OFFSET(B24,-1,0)+1,OFFSET(B24,-1,0))) -> 1 | C24: =IF(H24="CÉLULA CONSTRUTIVA",0,IF(H24="ETAPA",OFFSET(C24,-1,0)+1,OFFSET(C24,-1,0))) -> 1 | D24: =IF(H24="ETAPA",0,IF(H24="SUBETAPA",OFFSET(D24,-1,0)+1,OFFSET(D24,-1,0))) -> 2 | E24: =IF(H24="Subetapa",0,IF(H24="serviço",OFFSET(E24,-1,0)+1,OFFSET(E24,-1,0))) -> 10 | H24: SERVIÇO | I24: =IF(H24="Unidade Construtiva",TEXT(A24,"00"),IF(H24="Célula Construtiva",TEXT(B24,"00"),IF(H24="Etapa",CONCATENATE(TEXT(B24,"00"),".",TEXT(C24,"000")),IF(H24="Subetapa",CONCATENATE(TEXT(B24,"00"),".",TEXT(C24,"000"),".",TEXT(D24,"000")),IF(H24="Serviço",CONCATENATE(TEXT(B24,"00"),".",TEXT(C24,"000"),".",TEXT(D24,"000"),".",TEXT(E24,"000")),""))))) -> 01.001.002.010 | J24: Projeto preventivo (PPCI - Plano de Prevenção e Proteção Contra Incêndios) e Gás | K24: vb | L24: 1 | M24: 22961.088 | N24: =IF(H24="Serviço",M24*L24,IF(H24="CÉLULA CONSTRUTIVA",SUMIFS($N$8:$N$397,$B$8:$B$397,B24,$H$8:$H$397,"Serviço"),IF(H24="ETAPA",SUMIFS($N$8:$N$397,$B$8:$B$397,B24,$C$8:$C$397,C24,$H$8:$H$397,"Serviço"),IF(H24="SUBETAPA",SUMIFS($N$8:$N$397,$B$8:$B$397,B24,$C$8:$C$397,C24,$D$8:$D$397,D24,$H$8:$H$397,"Serviço"),0)))) -> 22961.088 | P24: Lançado ERP
A25: =IF($H25="UNIDADE CONSTRUTIVA",OFFSET(A25,-1,0)+1,LARGE(A$3:A23,1)) -> 0 | B25: =IF(H25="UNIDADE CONSTRUTIVA",0,IF(H25="CÉLULA CONSTRUTIVA",OFFSET(B25,-1,0)+1,OFFSET(B25,-1,0))) -> 1 | C25: =IF(H25="CÉLULA CONSTRUTIVA",0,IF(H25="ETAPA",OFFSET(C25,-1,0)+1,OFFSET(C25,-1,0))) -> 1 | D25: =IF(H25="ETAPA",0,IF(H25="SUBETAPA",OFFSET(D25,-1,0)+1,OFFSET(D25,-1,0))) -> 2 | E25: =IF(H25="Subetapa",0,IF(H25="serviço",OFFSET(E25,-1,0)+1,OFFSET(E25,-1,0))) -> 11 | G25: 4704 | H25: SERVIÇO | I25: =IF(H25="Unidade Construtiva",TEXT(A25,"00"),IF(H25="Célula Construtiva",TEXT(B25,"00"),IF(H25="Etapa",CONCATENATE(TEXT(B25,"00"),".",TEXT(C25,"000")),IF(H25="Subetapa",CONCATENATE(TEXT(B25,"00"),".",TEXT(C25,"000"),".",TEXT(D25,"000")),IF(H25="Serviço",CONCATENATE(TEXT(B25,"00"),".",TEXT(C25,"000"),".",TEXT(D25,"000"),".",TEXT(E25,"000")),""))))) -> 01.001.002.011 | J25: Projeto de Climatização | K25: vb | L25: 1 | M25: 22550.526 | N25: =IF(H25="Serviço",M25*L25,IF(H25="CÉLULA CONSTRUTIVA",SUMIFS($N$8:$N$397,$B$8:$B$397,B25,$H$8:$H$397,"Serviço"),IF(H25="ETAPA",SUMIFS($N$8:$N$397,$B$8:$B$397,B25,$C$8:$C$397,C25,$H$8:$H$397,"Serviço"),IF(H25="SUBETAPA",SUMIFS($N$8:$N$397,$B$8:$B$397,B25,$C$8:$C$397,C25,$D$8:$D$397,D25,$H$8:$H$397,"Serviço"),0)))) -> 22550.526 | P25: Lançado ERP
A26: =IF($H26="UNIDADE CONSTRUTIVA",OFFSET(A26,-1,0)+1,LARGE(A$3:A24,1)) -> 0 | B26: =IF(H26="UNIDADE CONSTRUTIVA",0,IF(H26="CÉLULA CONSTRUTIVA",OFFSET(B26,-1,0)+1,OFFSET(B26,-1,0))) -> 1 | C26: =IF(H26="CÉLULA CONSTRUTIVA",0,IF(H26="ETAPA",OFFSET(C26,-1,0)+1,OFFSET(C26,-1,0))) -> 1 | D26: =IF(H26="ETAPA",0,IF(H26="SUBETAPA",OFFSET(D26,-1,0)+1,OFFSET(D26,-1,0))) -> 2 | E26: =IF(H26="Subetapa",0,IF(H26="serviço",OFFSET(E26,-1,0)+1,OFFSET(E26,-1,0))) -> 12 | H26: SERVIÇO | I26: =IF(H26="Unidade Construtiva",TEXT(A26,"00"),IF(H26="Célula Construtiva",TEXT(B26,"00"),IF(H26="Etapa",CONCATENATE(TEXT(B26,"00"),".",TEXT(C26,"000")),IF(H26="Subetapa",CONCATENATE(TEXT(B26,"00"),".",TEXT(C26,"000"),".",TEXT(D26,"000")),IF(H26="Serviço",CONCATENATE(TEXT(B26,"00"),".",TEXT(C26,"000"),".",TEXT(D26,"000"),".",TEXT(E26,"000")),""))))) -> 01.001.002.012 | J26: Projeto de Paisagismo | K26: vb | L26: 1 | M26: 21765.216 | N26: =IF(H26="Serviço",M26*L26,IF(H26="CÉLULA CONSTRUTIVA",SUMIFS($N$8:$N$397,$B$8:$B$397,B26,$H$8:$H$397,"Serviço"),IF(H26="ETAPA",SUMIFS($N$8:$N$397,$B$8:$B$397,B26,$C$8:$C$397,C26,$H$8:$H$397,"Serviço"),IF(H26="SUBETAPA",SUMIFS($N$8:$N$397,$B$8:$B$397,B26,$C$8:$C$397,C26,$D$8:$D$397,D26,$H$8:$H$397,"Serviço"),0)))) -> 21765.216 | P26: Lançado ERP
A27: =IF($H27="UNIDADE CONSTRUTIVA",OFFSET(A27,-1,0)+1,LARGE(A$3:A25,1)) -> 0 | B27: =IF(H27="UNIDADE CONSTRUTIVA",0,IF(H27="CÉLULA CONSTRUTIVA",OFFSET(B27,-1,0)+1,OFFSET(B27,-1,0))) -> 1 | C27: =IF(H27="CÉLULA CONSTRUTIVA",0,IF(H27="ETAPA",OFFSET(C27,-1,0)+1,OFFSET(C27,-1,0))) -> 1 | D27: =IF(H27="ETAPA",0,IF(H27="SUBETAPA",OFFSET(D27,-1,0)+1,OFFSET(D27,-1,0))) -> 2 | E27: =IF(H27="Subetapa",0,IF(H27="serviço",OFFSET(E27,-1,0)+1,OFFSET(E27,-1,0))) -> 13 | G27: 4678 | H27: SERVIÇO | I27: =IF(H27="Unidade Construtiva",TEXT(A27,"00"),IF(H27="Célula Construtiva",TEXT(B27,"00"),IF(H27="Etapa",CONCATENATE(TEXT(B27,"00"),".",TEXT(C27,"000")),IF(H27="Subetapa",CONCATENATE(TEXT(B27,"00"),".",TEXT(C27,"000"),".",TEXT(D27,"000")),IF(H27="Serviço",CONCATENATE(TEXT(B27,"00"),".",TEXT(C27,"000"),".",TEXT(D27,"000"),".",TEXT(E27,"000")),""))))) -> 01.001.002.013 | J27: Projeto acústico | K27: vb | L27: 1 | M27: 17458.472 | N27: =IF(H27="Serviço",M27*L27,IF(H27="CÉLULA CONSTRUTIVA",SUMIFS($N$8:$N$397,$B$8:$B$397,B27,$H$8:$H$397,"Serviço"),IF(H27="ETAPA",SUMIFS($N$8:$N$397,$B$8:$B$397,B27,$C$8:$C$397,C27,$H$8:$H$397,"Serviço"),IF(H27="SUBETAPA",SUMIFS($N$8:$N$397,$B$8:$B$397,B27,$C$8:$C$397,C27,$D$8:$D$397,D27,$H$8:$H$397,"Serviço"),0)))) -> 17458.472 | P27: Lançado ERP
A28: =IF($H28="UNIDADE CONSTRUTIVA",OFFSET(A28,-1,0)+1,LARGE(A$3:A26,1)) -> 0 | B28: =IF(H28="UNIDADE CONSTRUTIVA",0,IF(H28="CÉLULA CONSTRUTIVA",OFFSET(B28,-1,0)+1,OFFSET(B28,-1,0))) -> 1 | C28: =IF(H28="CÉLULA CONSTRUTIVA",0,IF(H28="ETAPA",OFFSET(C28,-1,0)+1,OFFSET(C28,-1,0))) -> 1 | D28: =IF(H28="ETAPA",0,IF(H28="SUBETAPA",OFFSET(D28,-1,0)+1,OFFSET(D28,-1,0))) -> 2 | E28: =IF(H28="Subetapa",0,IF(H28="serviço",OFFSET(E28,-1,0)+1,OFFSET(E28,-1,0))) -> 14 | G28: 4680 | H28: SERVIÇO | I28: =IF(H28="Unidade Construtiva",TEXT(A28,"00"),IF(H28="Célula Construtiva",TEXT(B28,"00"),IF(H28="Etapa",CONCATENATE(TEXT(B28,"00"),".",TEXT(C28,"000")),IF(H28="Subetapa",CONCATENATE(TEXT(B28,"00"),".",TEXT(C28,"000"),".",TEXT(D28,"000")),IF(H28="Serviço",CONCATENATE(TEXT(B28,"00"),".",TEXT(C28,"000"),".",TEXT(D28,"000"),".",TEXT(E28,"000")),""))))) -> 01.001.002.014 | J28: Projeto piscina/fonte | K28: vb | L28: 1 | M28: 9829.0552 | N28: =IF(H28="Serviço",M28*L28,IF(H28="CÉLULA CONSTRUTIVA",SUMIFS($N$8:$N$397,$B$8:$B$397,B28,$H$8:$H$397,"Serviço"),IF(H28="ETAPA",SUMIFS($N$8:$N$397,$B$8:$B$397,B28,$C$8:$C$397,C28,$H$8:$H$397,"Serviço"),IF(H28="SUBETAPA",SUMIFS($N$8:$N$397,$B$8:$B$397,B28,$C$8:$C$397,C28,$D$8:$D$397,D28,$H$8:$H$397,"Serviço"),0)))) -> 9829.0552 | P28: Lançado ERP
A29: =IF($H29="UNIDADE CONSTRUTIVA",OFFSET(A29,-1,0)+1,LARGE(A$3:A26,1)) -> 0 | B29: =IF(H29="UNIDADE CONSTRUTIVA",0,IF(H29="CÉLULA CONSTRUTIVA",OFFSET(B29,-1,0)+1,OFFSET(B29,-1,0))) -> 1 | C29: =IF(H29="CÉLULA CONSTRUTIVA",0,IF(H29="ETAPA",OFFSET(C29,-1,0)+1,OFFSET(C29,-1,0))) -> 1 | D29: =IF(H29="ETAPA",0,IF(H29="SUBETAPA",OFFSET(D29,-1,0)+1,OFFSET(D29,-1,0))) -> 2 | E29: =IF(H29="Subetapa",0,IF(H29="serviço",OFFSET(E29,-1,0)+1,OFFSET(E29,-1,0))) -> 15 | G29: 4681 | H29: SERVIÇO | I29: =IF(H29="Unidade Construtiva",TEXT(A29,"00"),IF(H29="Célula Construtiva",TEXT(B29,"00"),IF(H29="Etapa",CONCATENATE(TEXT(B29,"00"),".",TEXT(C29,"000")),IF(H29="Subetapa",CONCATENATE(TEXT(B29,"00"),".",TEXT(C29,"000"),".",TEXT(D29,"000")),IF(H29="Serviço",CONCATENATE(TEXT(B29,"00"),".",TEXT(C29,"000"),".",TEXT(D29,"000"),".",TEXT(E29,"000")),""))))) -> 01.001.002.015 | J29: Projetos de Segurança do Trabalho | K29: vb | L29: 1 | M29: 5990.5769 | N29: =IF(H29="Serviço",M29*L29,IF(H29="CÉLULA CONSTRUTIVA",SUMIFS($N$8:$N$397,$B$8:$B$397,B29,$H$8:$H$397,"Serviço"),IF(H29="ETAPA",SUMIFS($N$8:$N$397,$B$8:$B$397,B29,$C$8:$C$397,C29,$H$8:$H$397,"Serviço"),IF(H29="SUBETAPA",SUMIFS($N$8:$N$397,$B$8:$B$397,B29,$C$8:$C$397,C29,$D$8:$D$397,D29,$H$8:$H$397,"Serviço"),0)))) -> 5990.5769 | P29: Lançado ERP
A30: =IF($H30="UNIDADE CONSTRUTIVA",OFFSET(A30,-1,0)+1,LARGE(A$3:A27,1)) -> 0 | B30: =IF(H30="UNIDADE CONSTRUTIVA",0,IF(H30="CÉLULA CONSTRUTIVA",OFFSET(B30,-1,0)+1,OFFSET(B30,-1,0))) -> 1 | C30: =IF(H30="CÉLULA CONSTRUTIVA",0,IF(H30="ETAPA",OFFSET(C30,-1,0)+1,OFFSET(C30,-1,0))) -> 1 | D30: =IF(H30="ETAPA",0,IF(H30="SUBETAPA",OFFSET(D30,-1,0)+1,OFFSET(D30,-1,0))) -> 2 | E30: =IF(H30="Subetapa",0,IF(H30="serviço",OFFSET(E30,-1,0)+1,OFFSET(E30,-1,0))) -> 16 | G30: 4684 | H30: SERVIÇO | I30: =IF(H30="Unidade Construtiva",TEXT(A30,"00"),IF(H30="Célula Construtiva",TEXT(B30,"00"),IF(H30="Etapa",CONCATENATE(TEXT(B30,"00"),".",TEXT(C30,"000")),IF(H30="Subetapa",CONCATENATE(TEXT(B30,"00"),".",TEXT(C30,"000"),".",TEXT(D30,"000")),IF(H30="Serviço",CONCATENATE(TEXT(B30,"00"),".",TEXT(C30,"000"),".",TEXT(D30,"000"),".",TEXT(E30,"000")),""))))) -> 01.001.002.016 | J30: Projeto de canteiro | K30: vb | L30: 1 | M30: 5878.053 | N30: =IF(H30="Serviço",M30*L30,IF(H30="CÉLULA CONSTRUTIVA",SUMIFS($N$8:$N$397,$B$8:$B$397,B30,$H$8:$H$397,"Serviço"),IF(H30="ETAPA",SUMIFS($N$8:$N$397,$B$8:$B$397,B30,$C$8:$C$397,C30,$H$8:$H$397,"Serviço"),IF(H30="SUBETAPA",SUMIFS($N$8:$N$397,$B$8:$B$397,B30,$C$8:$C$397,C30,$D$8:$D$397,D30,$H$8:$H$397,"Serviço"),0)))) -> 5878.053 | P30: Lançado ERP
A31: =IF($H31="UNIDADE CONSTRUTIVA",OFFSET(A31,-1,0)+1,LARGE(A$3:A26,1)) -> 0 | B31: =IF(H31="UNIDADE CONSTRUTIVA",0,IF(H31="CÉLULA CONSTRUTIVA",OFFSET(B31,-1,0)+1,OFFSET(B31,-1,0))) -> 1 | C31: =IF(H31="CÉLULA CONSTRUTIVA",0,IF(H31="ETAPA",OFFSET(C31,-1,0)+1,OFFSET(C31,-1,0))) -> 1 | D31: =IF(H31="ETAPA",0,IF(H31="SUBETAPA",OFFSET(D31,-1,0)+1,OFFSET(D31,-1,0))) -> 2 | E31: =IF(H31="Subetapa",0,IF(H31="serviço",OFFSET(E31,-1,0)+1,OFFSET(E31,-1,0))) -> 17 | G31: 4686 | H31: SERVIÇO | I31: =IF(H31="Unidade Construtiva",TEXT(A31,"00"),IF(H31="Célula Construtiva",TEXT(B31,"00"),IF(H31="Etapa",CONCATENATE(TEXT(B31,"00"),".",TEXT(C31,"000")),IF(H31="Subetapa",CONCATENATE(TEXT(B31,"00"),".",TEXT(C31,"000"),".",TEXT(D31,"000")),IF(H31="Serviço",CONCATENATE(TEXT(B31,"00"),".",TEXT(C31,"000"),".",TEXT(D31,"000"),".",TEXT(E31,"000")),""))))) -> 01.001.002.017 | J31: Compatibilização de Projetos BIM | K31: vb | L31: 1 | M31: 119717.83 | N31: =IF(H31="Serviço",M31*L31,IF(H31="CÉLULA CONSTRUTIVA",SUMIFS($N$8:$N$397,$B$8:$B$397,B31,$H$8:$H$397,"Serviço"),IF(H31="ETAPA",SUMIFS($N$8:$N$397,$B$8:$B$397,B31,$C$8:$C$397,C31,$H$8:$H$397,"Serviço"),IF(H31="SUBETAPA",SUMIFS($N$8:$N$397,$B$8:$B$397,B31,$C$8:$C$397,C31,$D$8:$D$397,D31,$H$8:$H$397,"Serviço"),0)))) -> 119717.83 | P31: Lançado ERP
A32: =IF($H32="UNIDADE CONSTRUTIVA",OFFSET(A32,-1,0)+1,LARGE(A$3:A23,1)) -> 0 | B32: =IF(H32="UNIDADE CONSTRUTIVA",0,IF(H32="CÉLULA CONSTRUTIVA",OFFSET(B32,-1,0)+1,OFFSET(B32,-1,0))) -> 1 | C32: =IF(H32="CÉLULA CONSTRUTIVA",0,IF(H32="ETAPA",OFFSET(C32,-1,0)+1,OFFSET(C32,-1,0))) -> 1 | D32: =IF(H32="ETAPA",0,IF(H32="SUBETAPA",OFFSET(D32,-1,0)+1,OFFSET(D32,-1,0))) -> 3 | E32: =IF(H32="Subetapa",0,IF(H32="serviço",OFFSET(E32,-1,0)+1,OFFSET(E32,-1,0))) -> 0 | H32: SUBETAPA | I32: =IF(H32="Unidade Construtiva",TEXT(A32,"00"),IF(H32="Célula Construtiva",TEXT(B32,"00"),IF(H32="Etapa",CONCATENATE(TEXT(B32,"00"),".",TEXT(C32,"000")),IF(H32="Subetapa",CONCATENATE(TEXT(B32,"00"),".",TEXT(C32,"000"),".",TEXT(D32,"000")),IF(H32="Serviço",CONCATENATE(TEXT(B32,"00"),".",TEXT(C32,"000"),".",TEXT(D32,"000"),".",TEXT(E32,"000")),""))))) -> 01.001.003 | J32: Consultorias | N32: =IF(H32="Serviço",M32*L32,IF(H32="CÉLULA CONSTRUTIVA",SUMIFS($N$8:$N$397,$B$8:$B$397,B32,$H$8:$H$397,"Serviço"),IF(H32="ETAPA",SUMIFS($N$8:$N$397,$B$8:$B$397,B32,$C$8:$C$397,C32,$H$8:$H$397,"Serviço"),IF(H32="SUBETAPA",SUMIFS($N$8:$N$397,$B$8:$B$397,B32,$C$8:$C$397,C32,$D$8:$D$397,D32,$H$8:$H$397,"Serviço"),0)))) -> 89661.773
A33: =IF($H33="UNIDADE CONSTRUTIVA",OFFSET(A33,-1,0)+1,LARGE(A$3:A32,1)) -> 0 | B33: =IF(H33="UNIDADE CONSTRUTIVA",0,IF(H33="CÉLULA CONSTRUTIVA",OFFSET(B33,-1,0)+1,OFFSET(B33,-1,0))) -> 1 | C33: =IF(H33="CÉLULA CONSTRUTIVA",0,IF(H33="ETAPA",OFFSET(C33,-1,0)+1,OFFSET(C33,-1,0))) -> 1 | D33: =IF(H33="ETAPA",0,IF(H33="SUBETAPA",OFFSET(D33,-1,0)+1,OFFSET(D33,-1,0))) -> 3 | E33: =IF(H33="Subetapa",0,IF(H33="serviço",OFFSET(E33,-1,0)+1,OFFSET(E33,-1,0))) -> 1 | G33: 4688 | H33: SERVIÇO | I33: =IF(H33="Unidade Construtiva",TEXT(A33,"00"),IF(H33="Célula Construtiva",TEXT(B33,"00"),IF(H33="Etapa",CONCATENATE(TEXT(B33,"00"),".",TEXT(C33,"000")),IF(H33="Subetapa",CONCATENATE(TEXT(B33,"00"),".",TEXT(C33,"000"),".",TEXT(D33,"000")),IF(H33="Serviço",CONCATENATE(TEXT(B33,"00"),".",TEXT(C33,"000"),".",TEXT(D33,"000"),".",TEXT(E33,"000")),""))))) -> 01.001.003.001 | J33: Auditoria de qualidade | K33: vb | L33: 1 | M33: 29097.453 | N33: =IF(H33="Serviço",M33*L33,IF(H33="CÉLULA CONSTRUTIVA",SUMIFS($N$8:$N$397,$B$8:$B$397,B33,$H$8:$H$397,"Serviço"),IF(H33="ETAPA",SUMIFS($N$8:$N$397,$B$8:$B$397,B33,$C$8:$C$397,C33,$H$8:$H$397,"Serviço"),IF(H33="SUBETAPA",SUMIFS($N$8:$N$397,$B$8:$B$397,B33,$C$8:$C$397,C33,$D$8:$D$397,D33,$H$8:$H$397,"Serviço"),0)))) -> 29097.453 | P33: Lançado ERP
A34: =IF($H34="UNIDADE CONSTRUTIVA",OFFSET(A34,-1,0)+1,LARGE(A$3:A33,1)) -> 0 | B34: =IF(H34="UNIDADE CONSTRUTIVA",0,IF(H34="CÉLULA CONSTRUTIVA",OFFSET(B34,-1,0)+1,OFFSET(B34,-1,0))) -> 1 | C34: =IF(H34="CÉLULA CONSTRUTIVA",0,IF(H34="ETAPA",OFFSET(C34,-1,0)+1,OFFSET(C34,-1,0))) -> 1 | D34: =IF(H34="ETAPA",0,IF(H34="SUBETAPA",OFFSET(D34,-1,0)+1,OFFSET(D34,-1,0))) -> 3 | E34: =IF(H34="Subetapa",0,IF(H34="serviço",OFFSET(E34,-1,0)+1,OFFSET(E34,-1,0))) -> 2 | H34: SERVIÇO | I34: =IF(H34="Unidade Construtiva",TEXT(A34,"00"),IF(H34="Célula Construtiva",TEXT(B34,"00"),IF(H34="Etapa",CONCATENATE(TEXT(B34,"00"),".",TEXT(C34,"000")),IF(H34="Subetapa",CONCATENATE(TEXT(B34,"00"),".",TEXT(C34,"000"),".",TEXT(D34,"000")),IF(H34="Serviço",CONCATENATE(TEXT(B34,"00"),".",TEXT(C34,"000"),".",TEXT(D34,"000"),".",TEXT(E34,"000")),""))))) -> 01.001.003.002 | J34: Orçamento e planejamento | K34: vb | L34: 1 | M34: 60564.32 | N34: =IF(H34="Serviço",M34*L34,IF(H34="CÉLULA CONSTRUTIVA",SUMIFS($N$8:$N$397,$B$8:$B$397,B34,$H$8:$H$397,"Serviço"),IF(H34="ETAPA",SUMIFS($N$8:$N$397,$B$8:$B$397,B34,$C$8:$C$397,C34,$H$8:$H$397,"Serviço"),IF(H34="SUBETAPA",SUMIFS($N$8:$N$397,$B$8:$B$397,B34,$C$8:$C$397,C34,$D$8:$D$397,D34,$H$8:$H$397,"Serviço"),0)))) -> 60564.32 | P34: Lançado ERP
A35: =IF($H35="UNIDADE CONSTRUTIVA",OFFSET(A35,-1,0)+1,LARGE(A$3:A34,1)) -> 0 | B35: =IF(H35="UNIDADE CONSTRUTIVA",0,IF(H35="CÉLULA CONSTRUTIVA",OFFSET(B35,-1,0)+1,OFFSET(B35,-1,0))) -> 1 | C35: =IF(H35="CÉLULA CONSTRUTIVA",0,IF(H35="ETAPA",OFFSET(C35,-1,0)+1,OFFSET(C35,-1,0))) -> 1 | D35: =IF(H35="ETAPA",0,IF(H35="SUBETAPA",OFFSET(D35,-1,0)+1,OFFSET(D35,-1,0))) -> 4 | E35: =IF(H35="Subetapa",0,IF(H35="serviço",OFFSET(E35,-1,0)+1,OFFSET(E35,-1,0))) -> 0 | H35: SUBETAPA | I35: =IF(H35="Unidade Construtiva",TEXT(A35,"00"),IF(H35="Célula Construtiva",TEXT(B35,"00"),IF(H35="Etapa",CONCATENATE(TEXT(B35,"00"),".",TEXT(C35,"000")),IF(H35="Subetapa",CONCATENATE(TEXT(B35,"00"),".",TEXT(C35,"000"),".",TEXT(D35,"000")),IF(H35="Serviço",CONCATENATE(TEXT(B35,"00"),".",TEXT(C35,"000"),".",TEXT(D35,"000"),".",TEXT(E35,"000")),""))))) -> 01.001.004 | J35: Ensaios | N35: =IF(H35="Serviço",M35*L35,IF(H35="CÉLULA CONSTRUTIVA",SUMIFS($N$8:$N$397,$B$8:$B$397,B35,$H$8:$H$397,"Serviço"),IF(H35="ETAPA",SUMIFS($N$8:$N$397,$B$8:$B$397,B35,$C$8:$C$397,C35,$H$8:$H$397,"Serviço"),IF(H35="SUBETAPA",SUMIFS($N$8:$N$397,$B$8:$B$397,B35,$C$8:$C$397,C35,$D$8:$D$397,D35,$H$8:$H$397,"Serviço"),0)))) -> 99342.435
A36: =IF($H36="UNIDADE CONSTRUTIVA",OFFSET(A36,-1,0)+1,LARGE(A$3:A35,1)) -> 0 | B36: =IF(H36="UNIDADE CONSTRUTIVA",0,IF(H36="CÉLULA CONSTRUTIVA",OFFSET(B36,-1,0)+1,OFFSET(B36,-1,0))) -> 1 | C36: =IF(H36="CÉLULA CONSTRUTIVA",0,IF(H36="ETAPA",OFFSET(C36,-1,0)+1,OFFSET(C36,-1,0))) -> 1 | D36: =IF(H36="ETAPA",0,IF(H36="SUBETAPA",OFFSET(D36,-1,0)+1,OFFSET(D36,-1,0))) -> 4 | E36: =IF(H36="Subetapa",0,IF(H36="serviço",OFFSET(E36,-1,0)+1,OFFSET(E36,-1,0))) -> 1 | G36: 2621 | H36: SERVIÇO | I36: =IF(H36="Unidade Construtiva",TEXT(A36,"00"),IF(H36="Célula Construtiva",TEXT(B36,"00"),IF(H36="Etapa",CONCATENATE(TEXT(B36,"00"),".",TEXT(C36,"000")),IF(H36="Subetapa",CONCATENATE(TEXT(B36,"00"),".",TEXT(C36,"000"),".",TEXT(D36,"000")),IF(H36="Serviço",CONCATENATE(TEXT(B36,"00"),".",TEXT(C36,"000"),".",TEXT(D36,"000"),".",TEXT(E36,"000")),""))))) -> 01.001.004.001 | J36: Controle Tecnologico de Concreto | K36: vb | L36: 1 | M36: 99342.435 | N36: =IF(H36="Serviço",M36*L36,IF(H36="CÉLULA CONSTRUTIVA",SUMIFS($N$8:$N$397,$B$8:$B$397,B36,$H$8:$H$397,"Serviço"),IF(H36="ETAPA",SUMIFS($N$8:$N$397,$B$8:$B$397,B36,$C$8:$C$397,C36,$H$8:$H$397,"Serviço"),IF(H36="SUBETAPA",SUMIFS($N$8:$N$397,$B$8:$B$397,B36,$C$8:$C$397,C36,$D$8:$D$397,D36,$H$8:$H$397,"Serviço"),0)))) -> 99342.435 | P36: Lançado ERP
A37: =IF($H37="UNIDADE CONSTRUTIVA",OFFSET(A37,-1,0)+1,LARGE(A$3:A36,1)) -> 0 | B37: =IF(H37="UNIDADE CONSTRUTIVA",0,IF(H37="CÉLULA CONSTRUTIVA",OFFSET(B37,-1,0)+1,OFFSET(B37,-1,0))) -> 1 | C37: =IF(H37="CÉLULA CONSTRUTIVA",0,IF(H37="ETAPA",OFFSET(C37,-1,0)+1,OFFSET(C37,-1,0))) -> 2 | D37: =IF(H37="ETAPA",0,IF(H37="SUBETAPA",OFFSET(D37,-1,0)+1,OFFSET(D37,-1,0))) -> 0 | E37: =IF(H37="Subetapa",0,IF(H37="serviço",OFFSET(E37,-1,0)+1,OFFSET(E37,-1,0))) -> 1 | H37: ETAPA | I37: =IF(H37="Unidade Construtiva",TEXT(A37,"00"),IF(H37="Célula Construtiva",TEXT(B37,"00"),IF(H37="Etapa",CONCATENATE(TEXT(B37,"00"),".",TEXT(C37,"000")),IF(H37="Subetapa",CONCATENATE(TEXT(B37,"00"),".",TEXT(C37,"000"),".",TEXT(D37,"000")),IF(H37="Serviço",CONCATENATE(TEXT(B37,"00"),".",TEXT(C37,"000"),".",TEXT(D37,"000"),".",TEXT(E37,"000")),""))))) -> 01.002 | J37: CONSUMOS, TAXAS E DOCUMENTOS | N37: =IF(H37="Serviço",M37*L37,IF(H37="CÉLULA CONSTRUTIVA",SUMIFS($N$8:$N$397,$B$8:$B$397,B37,$H$8:$H$397,"Serviço"),IF(H37="ETAPA",SUMIFS($N$8:$N$397,$B$8:$B$397,B37,$C$8:$C$397,C37,$H$8:$H$397,"Serviço"),IF(H37="SUBETAPA",SUMIFS($N$8:$N$397,$B$8:$B$397,B37,$C$8:$C$397,C37,$D$8:$D$397,D37,$H$8:$H$397,"Serviço"),0)))) -> 403490.89 | P37: -
A38: =IF($H38="UNIDADE CONSTRUTIVA",OFFSET(A38,-1,0)+1,LARGE(A$3:A37,1)) -> 0 | B38: =IF(H38="UNIDADE CONSTRUTIVA",0,IF(H38="CÉLULA CONSTRUTIVA",OFFSET(B38,-1,0)+1,OFFSET(B38,-1,0))) -> 1 | C38: =IF(H38="CÉLULA CONSTRUTIVA",0,IF(H38="ETAPA",OFFSET(C38,-1,0)+1,OFFSET(C38,-1,0))) -> 2 | D38: =IF(H38="ETAPA",0,IF(H38="SUBETAPA",OFFSET(D38,-1,0)+1,OFFSET(D38,-1,0))) -> 1 | E38: =IF(H38="Subetapa",0,IF(H38="serviço",OFFSET(E38,-1,0)+1,OFFSET(E38,-1,0))) -> 0 | H38: SUBETAPA | I38: =IF(H38="Unidade Construtiva",TEXT(A38,"00"),IF(H38="Célula Construtiva",TEXT(B38,"00"),IF(H38="Etapa",CONCATENATE(TEXT(B38,"00"),".",TEXT(C38,"000")),IF(H38="Subetapa",CONCATENATE(TEXT(B38,"00"),".",TEXT(C38,"000"),".",TEXT(D38,"000")),IF(H38="Serviço",CONCATENATE(TEXT(B38,"00"),".",TEXT(C38,"000"),".",TEXT(D38,"000"),".",TEXT(E38,"000")),""))))) -> 01.002.001 | J38: Licenciamentos, Taxas, Impostos, Aprovações e Seguros | N38: =IF(H38="Serviço",M38*L38,IF(H38="CÉLULA CONSTRUTIVA",SUMIFS($N$8:$N$397,$B$8:$B$397,B38,$H$8:$H$397,"Serviço"),IF(H38="ETAPA",SUMIFS($N$8:$N$397,$B$8:$B$397,B38,$C$8:$C$397,C38,$H$8:$H$397,"Serviço"),IF(H38="SUBETAPA",SUMIFS($N$8:$N$397,$B$8:$B$397,B38,$C$8:$C$397,C38,$D$8:$D$397,D38,$H$8:$H$397,"Serviço"),0)))) -> 314060.8
A39: =IF($H39="UNIDADE CONSTRUTIVA",OFFSET(A39,-1,0)+1,LARGE(A$3:A38,1)) -> 0 | B39: =IF(H39="UNIDADE CONSTRUTIVA",0,IF(H39="CÉLULA CONSTRUTIVA",OFFSET(B39,-1,0)+1,OFFSET(B39,-1,0))) -> 1 | C39: =IF(H39="CÉLULA CONSTRUTIVA",0,IF(H39="ETAPA",OFFSET(C39,-1,0)+1,OFFSET(C39,-1,0))) -> 2 | D39: =IF(H39="ETAPA",0,IF(H39="SUBETAPA",OFFSET(D39,-1,0)+1,OFFSET(D39,-1,0))) -> 1 | E39: =IF(H39="Subetapa",0,IF(H39="serviço",OFFSET(E39,-1,0)+1,OFFSET(E39,-1,0))) -> 1 | H39: SERVIÇO | I39: =IF(H39="Unidade Construtiva",TEXT(A39,"00"),IF(H39="Célula Construtiva",TEXT(B39,"00"),IF(H39="Etapa",CONCATENATE(TEXT(B39,"00"),".",TEXT(C39,"000")),IF(H39="Subetapa",CONCATENATE(TEXT(B39,"00"),".",TEXT(C39,"000"),".",TEXT(D39,"000")),IF(H39="Serviço",CONCATENATE(TEXT(B39,"00"),".",TEXT(C39,"000"),".",TEXT(D39,"000"),".",TEXT(E39,"000")),""))))) -> 01.002.001.001 | J39: Despesas de Seguros | K39: vb | L39: 1 | M39: 34982.491 | N39: =IF(H39="Serviço",M39*L39,IF(H39="CÉLULA CONSTRUTIVA",SUMIFS($N$8:$N$397,$B$8:$B$397,B39,$H$8:$H$397,"Serviço"),IF(H39="ETAPA",SUMIFS($N$8:$N$397,$B$8:$B$397,B39,$C$8:$C$397,C39,$H$8:$H$397,"Serviço"),IF(H39="SUBETAPA",SUMIFS($N$8:$N$397,$B$8:$B$397,B39,$C$8:$C$397,C39,$D$8:$D$397,D39,$H$8:$H$397,"Serviço"),0)))) -> 34982.491 | P39: Lançado ERP
A40: =IF($H40="UNIDADE CONSTRUTIVA",OFFSET(A40,-1,0)+1,LARGE(A$3:A39,1)) -> 0 | B40: =IF(H40="UNIDADE CONSTRUTIVA",0,IF(H40="CÉLULA CONSTRUTIVA",OFFSET(B40,-1,0)+1,OFFSET(B40,-1,0))) -> 1 | C40: =IF(H40="CÉLULA CONSTRUTIVA",0,IF(H40="ETAPA",OFFSET(C40,-1,0)+1,OFFSET(C40,-1,0))) -> 2 | D40: =IF(H40="ETAPA",0,IF(H40="SUBETAPA",OFFSET(D40,-1,0)+1,OFFSET(D40,-1,0))) -> 1 | E40: =IF(H40="Subetapa",0,IF(H40="serviço",OFFSET(E40,-1,0)+1,OFFSET(E40,-1,0))) -> 2 | H40: SERVIÇO | I40: =IF(H40="Unidade Construtiva",TEXT(A40,"00"),IF(H40="Célula Construtiva",TEXT(B40,"00"),IF(H40="Etapa",CONCATENATE(TEXT(B40,"00"),".",TEXT(C40,"000")),IF(H40="Subetapa",CONCATENATE(TEXT(B40,"00"),".",TEXT(C40,"000"),".",TEXT(D40,"000")),IF(H40="Serviço",CONCATENATE(TEXT(B40,"00"),".",TEXT(C40,"000"),".",TEXT(D40,"000"),".",TEXT(E40,"000")),""))))) -> 01.002.001.002 | J40: Aprovação e legalização ambiental | K40: vb | L40: 1 | M40: 117024.3 | N40: =IF(H40="Serviço",M40*L40,IF(H40="CÉLULA CONSTRUTIVA",SUMIFS($N$8:$N$397,$B$8:$B$397,B40,$H$8:$H$397,"Serviço"),IF(H40="ETAPA",SUMIFS($N$8:$N$397,$B$8:$B$397,B40,$C$8:$C$397,C40,$H$8:$H$397,"Serviço"),IF(H40="SUBETAPA",SUMIFS($N$8:$N$397,$B$8:$B$397,B40,$C$8:$C$397,C40,$D$8:$D$397,D40,$H$8:$H$397,"Serviço"),0)))) -> 117024.3 | P40: Lançado ERP
A41: =IF($H41="UNIDADE CONSTRUTIVA",OFFSET(A41,-1,0)+1,LARGE(A$3:A40,1)) -> 0 | B41: =IF(H41="UNIDADE CONSTRUTIVA",0,IF(H41="CÉLULA CONSTRUTIVA",OFFSET(B41,-1,0)+1,OFFSET(B41,-1,0))) -> 1 | C41: =IF(H41="CÉLULA CONSTRUTIVA",0,IF(H41="ETAPA",OFFSET(C41,-1,0)+1,OFFSET(C41,-1,0))) -> 2 | D41: =IF(H41="ETAPA",0,IF(H41="SUBETAPA",OFFSET(D41,-1,0)+1,OFFSET(D41,-1,0))) -> 1 | E41: =IF(H41="Subetapa",0,IF(H41="serviço",OFFSET(E41,-1,0)+1,OFFSET(E41,-1,0))) -> 3 | G41: 4692 | H41: SERVIÇO | I41: =IF(H41="Unidade Construtiva",TEXT(A41,"00"),IF(H41="Célula Construtiva",TEXT(B41,"00"),IF(H41="Etapa",CONCATENATE(TEXT(B41,"00"),".",TEXT(C41,"000")),IF(H41="Subetapa",CONCATENATE(TEXT(B41,"00"),".",TEXT(C41,"000"),".",TEXT(D41,"000")),IF(H41="Serviço",CONCATENATE(TEXT(B41,"00"),".",TEXT(C41,"000"),".",TEXT(D41,"000"),".",TEXT(E41,"000")),""))))) -> 01.002.001.003 | J41: Aprovação e legalização prefeitura | K41: vb | L41: 1 | M41: 35080.372 | N41: =IF(H41="Serviço",M41*L41,IF(H41="CÉLULA CONSTRUTIVA",SUMIFS($N$8:$N$397,$B$8:$B$397,B41,$H$8:$H$397,"Serviço"),IF(H41="ETAPA",SUMIFS($N$8:$N$397,$B$8:$B$397,B41,$C$8:$C$397,C41,$H$8:$H$397,"Serviço"),IF(H41="SUBETAPA",SUMIFS($N$8:$N$397,$B$8:$B$397,B41,$C$8:$C$397,C41,$D$8:$D$397,D41,$H$8:$H$397,"Serviço"),0)))) -> 35080.372 | P41: Lançado ERP
A42: =IF($H42="UNIDADE CONSTRUTIVA",OFFSET(A42,-1,0)+1,LARGE(A$3:A41,1)) -> 0 | B42: =IF(H42="UNIDADE CONSTRUTIVA",0,IF(H42="CÉLULA CONSTRUTIVA",OFFSET(B42,-1,0)+1,OFFSET(B42,-1,0))) -> 1 | C42: =IF(H42="CÉLULA CONSTRUTIVA",0,IF(H42="ETAPA",OFFSET(C42,-1,0)+1,OFFSET(C42,-1,0))) -> 2 | D42: =IF(H42="ETAPA",0,IF(H42="SUBETAPA",OFFSET(D42,-1,0)+1,OFFSET(D42,-1,0))) -> 1 | E42: =IF(H42="Subetapa",0,IF(H42="serviço",OFFSET(E42,-1,0)+1,OFFSET(E42,-1,0))) -> 4 | G42: 4694 | H42: SERVIÇO | I42: =IF(H42="Unidade Construtiva",TEXT(A42,"00"),IF(H42="Célula Construtiva",TEXT(B42,"00"),IF(H42="Etapa",CONCATENATE(TEXT(B42,"00"),".",TEXT(C42,"000")),IF(H42="Subetapa",CONCATENATE(TEXT(B42,"00"),".",TEXT(C42,"000"),".",TEXT(D42,"000")),IF(H42="Serviço",CONCATENATE(TEXT(B42,"00"),".",TEXT(C42,"000"),".",TEXT(D42,"000"),".",TEXT(E42,"000")),""))))) -> 01.002.001.004 | J42: Aprovação e legalização bombeiros | K42: vb | L42: 1 | M42: 16641.102 | N42: =IF(H42="Serviço",M42*L42,IF(H42="CÉLULA CONSTRUTIVA",SUMIFS($N$8:$N$397,$B$8:$B$397,B42,$H$8:$H$397,"Serviço"),IF(H42="ETAPA",SUMIFS($N$8:$N$397,$B$8:$B$397,B42,$C$8:$C$397,C42,$H$8:$H$397,"Serviço"),IF(H42="SUBETAPA",SUMIFS($N$8:$N$397,$B$8:$B$397,B42,$C$8:$C$397,C42,$D$8:$D$397,D42,$H$8:$H$397,"Serviço"),0)))) -> 16641.102 | P42: Lançado ERP
A43: =IF($H43="UNIDADE CONSTRUTIVA",OFFSET(A43,-1,0)+1,LARGE(A$3:A42,1)) -> 0 | B43: =IF(H43="UNIDADE CONSTRUTIVA",0,IF(H43="CÉLULA CONSTRUTIVA",OFFSET(B43,-1,0)+1,OFFSET(B43,-1,0))) -> 1 | C43: =IF(H43="CÉLULA CONSTRUTIVA",0,IF(H43="ETAPA",OFFSET(C43,-1,0)+1,OFFSET(C43,-1,0))) -> 2 | D43: =IF(H43="ETAPA",0,IF(H43="SUBETAPA",OFFSET(D43,-1,0)+1,OFFSET(D43,-1,0))) -> 1 | E43: =IF(H43="Subetapa",0,IF(H43="serviço",OFFSET(E43,-1,0)+1,OFFSET(E43,-1,0))) -> 5 | G43: 4696 | H43: SERVIÇO | I43: =IF(H43="Unidade Construtiva",TEXT(A43,"00"),IF(H43="Célula Construtiva",TEXT(B43,"00"),IF(H43="Etapa",CONCATENATE(TEXT(B43,"00"),".",TEXT(C43,"000")),IF(H43="Subetapa",CONCATENATE(TEXT(B43,"00"),".",TEXT(C43,"000"),".",TEXT(D43,"000")),IF(H43="Serviço",CONCATENATE(TEXT(B43,"00"),".",TEXT(C43,"000"),".",TEXT(D43,"000"),".",TEXT(E43,"000")),""))))) -> 01.002.001.005 | J43: Taxas de ART | K43: vb | L43: 1 | M43: 4476.4481 | N43: =IF(H43="Serviço",M43*L43,IF(H43="CÉLULA CONSTRUTIVA",SUMIFS($N$8:$N$397,$B$8:$B$397,B43,$H$8:$H$397,"Serviço"),IF(H43="ETAPA",SUMIFS($N$8:$N$397,$B$8:$B$397,B43,$C$8:$C$397,C43,$H$8:$H$397,"Serviço"),IF(H43="SUBETAPA",SUMIFS($N$8:$N$397,$B$8:$B$397,B43,$C$8:$C$397,C43,$D$8:$D$397,D43,$H$8:$H$397,"Serviço"),0)))) -> 4476.4481 | P43: Lançado ERP
...

Sheet Ger_Executivo
G4: PROJETO: | I4: ='Ger_Tec e Adm'!I4 -> 365 | O4: REVISÃO: | P4: DATA
G5: EMPRESA: | I5: ='Ger_Tec e Adm'!I5 -> COTA | O5: R00
A6: Unidade Construtiva | B6: Célula Construtiva | C6: Etapa | D6: Subetapa | E6: Serviço | G6: GERENCIAMENTO EXECUTIVO
A7: 0 | B7: 0 | C7: 0 | D7: 0 | E7: 0 | G7: Atalho | H7: NIVEL | I7: Item | J7: Descrição | K7: Unidade | L7: Quant. | M7: Preço un | N7: Total | O7: Considerações | P7: Situação
A8: =IF($H8="UNIDADE CONSTRUTIVA",OFFSET(A8,-1,0)+1,LARGE(A$3:A7,1)) -> 0 | B8: =IF(H8="UNIDADE CONSTRUTIVA",0,IF(H8="CÉLULA CONSTRUTIVA",OFFSET(B8,-1,0)+1,OFFSET(B8,-1,0))) -> 1 | C8: =IF(H8="CÉLULA CONSTRUTIVA",0,IF(H8="ETAPA",OFFSET(C8,-1,0)+1,OFFSET(C8,-1,0))) -> 0 | D8: =IF(H8="ETAPA",0,IF(H8="SUBETAPA",OFFSET(D8,-1,0)+1,OFFSET(D8,-1,0))) -> 0 | E8: =IF(H8="Subetapa",0,IF(H8="serviço",OFFSET(E8,-1,0)+1,OFFSET(E8,-1,0))) -> 0 | H8: CÉLULA CONSTRUTIVA | I8: =IF(H8="Unidade Construtiva",TEXT(A8,"00"),IF(H8="Célula Construtiva",TEXT(B8,"00"),IF(H8="Etapa",CONCATENATE(TEXT(B8,"00"),".",TEXT(C8,"000")),IF(H8="Subetapa",CONCATENATE(TEXT(B8,"00"),".",TEXT(C8,"000"),".",TEXT(D8,"000")),IF(H8="Serviço",CONCATENATE(TEXT(B8,"00"),".",TEXT(C8,"000"),".",TEXT(D8,"000"),".",TEXT(E8,"000")),""))))) -> 01 | J8: MOVIMENTAÇÃO DE TERRA | N8: =IF(H8="Serviço",M8*L8,IF(H8="CÉLULA CONSTRUTIVA",SUMIFS($N$8:$N$335,$B$8:$B$335,B8,$H$8:$H$335,"Serviço"),IF(H8="ETAPA",SUMIFS($N$8:$N$335,$B$8:$B$335,B8,$C$8:$C$335,C8,$H$8:$H$335,"Serviço"),IF(H8="SUBETAPA",SUMIFS($N$8:$N$335,$B$8:$B$335,B8,$C$8:$C$335,C8,$D$8:$D$335,D8,$H$8:$H$335,"Serviço"),0)))) -> 1400464.9
A9: =IF($H9="UNIDADE CONSTRUTIVA",OFFSET(A9,-1,0)+1,LARGE(A$3:A8,1)) -> 0 | B9: =IF(H9="UNIDADE CONSTRUTIVA",0,IF(H9="CÉLULA CONSTRUTIVA",OFFSET(B9,-1,0)+1,OFFSET(B9,-1,0))) -> 1 | C9: =IF(H9="CÉLULA CONSTRUTIVA",0,IF(H9="ETAPA",OFFSET(C9,-1,0)+1,OFFSET(C9,-1,0))) -> 1 | D9: =IF(H9="ETAPA",0,IF(H9="SUBETAPA",OFFSET(D9,-1,0)+1,OFFSET(D9,-1,0))) -> 0 | E9: =IF(H9="Subetapa",0,IF(H9="serviço",OFFSET(E9,-1,0)+1,OFFSET(E9,-1,0))) -> 0 | H9: ETAPA | I9: =IF(H9="Unidade Construtiva",TEXT(A9,"00"),IF(H9="Célula Construtiva",TEXT(B9,"00"),IF(H9="Etapa",CONCATENATE(TEXT(B9,"00"),".",TEXT(C9,"000")),IF(H9="Subetapa",CONCATENATE(TEXT(B9,"00"),".",TEXT(C9,"000"),".",TEXT(D9,"000")),IF(H9="Serviço",CONCATENATE(TEXT(B9,"00"),".",TEXT(C9,"000"),".",TEXT(D9,"000"),".",TEXT(E9,"000")),""))))) -> 01.001 | J9: MOVIMENTAÇÃO DE TERRA | N9: =IF(H9="Serviço",M9*L9,IF(H9="CÉLULA CONSTRUTIVA",SUMIFS($N$8:$N$335,$B$8:$B$335,B9,$H$8:$H$335,"Serviço"),IF(H9="ETAPA",SUMIFS($N$8:$N$335,$B$8:$B$335,B9,$C$8:$C$335,C9,$H$8:$H$335,"Serviço"),IF(H9="SUBETAPA",SUMIFS($N$8:$N$335,$B$8:$B$335,B9,$C$8:$C$335,C9,$D$8:$D$335,D9,$H$8:$H$335,"Serviço"),0)))) -> 1400464.9
