Workbook
Name \0: #REF!
Name \0: #REF!
Name \0: #REF!
Name \0: #REF!
Name \0: #REF!
Name \0: #REF!
Name \0: #REF!
Name \a: #REF!
Name \a: #REF!
Name \m: #REF!
Name \m: #REF!
Name aa: #REF!
Name aa: #REF!
Name aaaa: '[1]M.O.'!#REF!
Name aaaa: '[1]M.O.'!#REF!
Name aaaa: '[1]M.O.'!#REF!
Name aaaa: '[1]M.O.'!#REF!
Name aaaa: '[1]M.O.'!#REF!
Name aaaa: '[1]M.O.'!#REF!
Name aaaa: '[1]M.O.'!#REF!
Name angelo: [2]Geral!#REF!
Name angelo: [2]Geral!#REF!
Name angelo: [2]Geral!#REF!
Name angelo: [2]Geral!#REF!
Name angelo: [2]Geral!#REF!
Name angelo: [2]Geral!#REF!
Name angelo: [2]Geral!#REF!
Name area: #REF!
Name aux: #REF!
Name aux: #REF!
Name aux: #REF!
Name aux: #REF!
Name aux: #REF!
Name aux: #REF!
Name aux: #REF!
Name BDA: #REF!
Name BDA: #REF!
Name BDI: #REF!
Name ca: #REF!
Name Capa: #REF!
Name cronograma: #REF!
Name D: #REF!
Name direto: #REF!
Name DRE: #REF!
Name ea: #REF!
Name FFFFFFF: #REF!
Name FFFFFFF: #REF!
Name FFFFFFF: #REF!
Name FFFFFFF: #REF!
Name FFFFFFF: #REF!
Name FFFFFFF: #REF!
Name FFFFFFF: #REF!
Name item_1: #REF!
Name item_1: #REF!
Name item_1: #REF!
Name item_1: #REF!
Name item_1: #REF!
Name item_1: #REF!
Name item_1: #REF!
Name LS: '[1]M.O.'!#REF!

Sheet DADOS_INICIAIS
A1: Obra | B1: Cacupé
A2: Empresa | B2: Adore Incorporações
A3: Revisão | B3: R00
A4: Arquitetura base | B4: XXX
A5: DADOS OBRA | I5: Banheiros
B7: Descrição | C7: Identificador | D7: Unidade | E7: Quantidade | J7: Nível 1 | K7: Nível 2 | L7: Nível 3 | M7: Nível 4 | N7: Nível 5 | O7: Nível 6 | P7: Nível 7
B8: ÁREA DO TERRENO | C8: AT | D8: M2 | E8: 1502.83 | I8: Banheiros | J8: 2 | L8: 25 | M8: 25 | N8: 25 | O8: 25 | P8: 9
B9: ÁREA TOTAL CONSTRUÍDA | C9: AC | D9: M2 | E9: 6494.63 | I9: Cozinhas | J9: 2 | L9: 11 | M9: 11 | N9: 11 | O9: 11 | P9: 3
B10: UNIDADES RESIDENCIAIS | C10: UR | D10: UN | E10: 46 | I10: Dormitórios | L10: 24 | M10: 24 | N10: 24 | O10: 24 | P10: 5
B11: Dormitórios | C11: dorm | D11: UN | E11: =SUM($J$10:$Q$10) -> 101
B12: Banheiros | C12: ban | D12: UN | E12: =SUM($J$8:$Q$8) -> 111
B13: UNIDADES COMERCIAIS | C13: UC | D13: UN | E13: 1
B14: Churrasqueiras | C14: CHU | D14: UN | E14: =11*4 -> 44
B15: NÚMERO TOTAL DE PAVIMENTOS | C15: NP | D15: UN | E15: 8
B16: NÚMERO DE PAVIMENTOS TIPO | C16: NPT | D16: UN | E16: 4
B17: NÚMERO DE PAVIMENTOS TIPO DIFERENCIADOS | C17: NPD | D17: UN | E17: 1
B18: NÚMERO DE PAVIMENTOS DUPLEX | C18: ND | D18: UN
B19: ÁREA DE PROJEÇÃO DA TORRE | C19: APT | D19: M2 | E19: 888.9615
B20: PERÍMETRO DE PROJEÇÃO DA TORRE | C20: PPT | D20: M | E20: 177.07
B21: ÁREA DE LAZER | C21: AL | D21: M2 | E21: 347.6948
B22: ÁREA DO EMBASAMENTO | C22: AE | D22: M2 | E22: 1143.09
B23: ÁREA DE SUBSOLOS | C23: S | D23: M2
B24: NÚMERO DE SUBSOLOS | C24: NS | D24: UN
B25: ÁREA DE PROJEÇÃO DO EMBASAMENTO | C25: APE | D25: M2 | E25: 1193.28
B26: PERÍMETRO DE PROJEÇÃO DE EMBAMENTO | C26: PE | D26: M | E26: 185.03
B27: NÚMERO DE PAVIMENTOS DE EMBASAMENTO | C27: NE | D27: UN | E27: 2

Sheet MOVIMENTAÇÃO_DE_TERRA
A2: MOVIMENTAÇÃO DE TERRA
A3: Data | B3: 45668
A4: Arquivo base | B4: -
A6: ESCAVAÇÃO VERTICAL DE SUBSOLO
A8: Descrição | B8: Área de subsolo (m) | C8: Altura do subsolo (m) | D8: Volume total de escavação (m3) | E8: Preço unitário de escavação (R$ / m3) | F8: Valor total | G8: Observação
A9: Escavação | B9: =DADOS_INICIAIS!E23 -> 0 | D9: =J10 -> 3527 | E9: 0 | F9: =E9*D9*1.1 -> 0 | G9: Volume de terraplenagem conforme projeto recebido do cliente | I9: Volume de terraplenagem conforme projeto recebido do cliente
A10: TOTAL | F10: =SUM(F9:F9) -> 0 | I10: Corte | J10: 3527
I11: Atetto | J11: 163
A12: REBAIXAMENTO DE LENÇOL FREÁTICO | I12: Bota fora | J12: =(J10-J11)*1.3 -> 4373.2
A14: Descrição | B14: Quantidade (dias) | E14: Preço unitário de rebaixamento (R$ / dias) | F14: Valor total | G14: Observação
A15: Rebaixamento de lençol | B15: 180 | E15: 200 | F15: =B15*E15*1.1 -> 39600 | G15: Considerado o tempo de 6 meses para fundação
A16: TOTAL | F16: =SUM(F15:F15) -> 39600
A18: ESCAVAÇÃO E REATERRO DE VALAS
A20: Descrição | B20: Parâmetro | D20: Volume total de escavação (m3) | E20: Preço unitário (R$ / m3) | F20: Valor total | G20: Observação
A21: Escavação mecanizada para blocos e baldrames | B21: 1.3 | C21: m³ / Vol infra | D21: =B21*INFRAESTRUTURA!D29 -> 1008.3216 | E21: 60 | F21: =E21*D21*1.1 -> 66549.226
A22: Reaterro para blocos e baldrames | B22: 0.6 | C22: m³ / Vol Escavação | D22: =D21-INFRAESTRUTURA!D29 -> 232.6896 | E22: 20 | F22: =E22*D22*1.1 -> 5119.1712
A23: Movimentação de bota-fora | B23: 1.3 | D23: =(D21-D22)*B23 -> 1008.3216 | E23: 40 | F23: =E23*D23*1.1 -> 44366.15
A24: Movimentação de terra das estacas | B24: 1 | C24: m³ | D24: =INFRAESTRUTURA!D19 -> 1163.7716 | E24: 40 | F24: =E24*D24*1.1*0 -> 0 | G24: Não tem estacas
A25: TOTAL | F25: =SUM(F21:F24) -> 116034.55
A27: REGULARIZAÇÃO E APILOAMENTO DE FUNDO DE VALAS
A29: Descrição | B29: Parâmetro | D29: Área de lastro (m²) | E29: Preço unitário (R$ / m2) | F29: Valor total | G29: Observação
A30: Lastro de concreto magto e=5cm | B30: 0.8 | C30: m² / APE | D30: =B30*DADOS_INICIAIS!E25 -> 954.624 | E30: =370*0.05 -> 18.5 | F30: =E30*D30*1.1 -> 19426.598 | G30: Definição trazida do Celebration da Passe | H30: =F30/DADOS_INICIAIS!E25 -> 16.28
A31: TOTAL | F31: =SUM(F30:F30) -> 19426.598
A33: TOTAL MOVIMENTAÇÃO DE TERRA | F33: =F10+F16+F25+F31 -> 175061.15 | G33: =F33/DADOS_INICIAIS!E9 -> 26.954753

Sheet INFRAESTRUTURA
A3: INFRAESTRUTURA
A4: Data | B4: 45668
A5: Arquivo base | B5: -
A7: FUNDAÇÃO PROFUNDA
A9: Descrição | B9: Parâmetro | D9: Quantidade | F9: Preço unitário | G9: Valor total | H9: Observação
A10: Número de Estacas | B10: 0.15 | C10: un / APE | D10: =ROUNDUP(B10*DADOS_INICIAIS!$E$25,0) -> 179 | E10: un | H10: Não tem fundação profunda
A11: Estaca Hélice Continua Diâmetro 40 | B11: 0 | D11: =ROUNDUP(B11*$D$10,0) -> 0 | E11: un
B12: 28 | C12: m/un | D12: =B12*D11 -> 0 | E12: m | F12: 70 | G12: =F12*D12*1.1*0 -> 0
A13: Estaca Hélice Continua Diâmetro 50 | B13: 0.6 | D13: =ROUNDUP(B13*D10,0) -> 108 | E13: un | G13: =F13*D13*1.1*0 -> 0
B14: 28 | C14: m/un | D14: =B14*D13 -> 3024 | E14: m | F14: 90 | G14: =F14*D14*1.1*0 -> 0
A15: Estaca Hélice Continua Diâmetro 60 | B15: 0.4 | C15: un / APE | D15: =ROUNDUP(B15*$D$10,0) -> 72 | E15: un | G15: =F15*D15*1.1*0 -> 0
B16: 28 | C16: m/un | D16: =B16*D15 -> 2016 | E16: m | F16: 105 | G16: =F16*D16*1.1*0 -> 0
A17: Estaca Hélice Continua Diâmetro 80 | B17: 0 | C17: un / APE | D17: =ROUNDUP(B17*$D$10,0) -> 0 | E17: un | G17: =F17*D17*1.1*0 -> 0
B18: 30 | C18: m/un | D18: =B18*D17 -> 0 | E18: m | F18: 120 | G18: =F18*D18*1.1*0 -> 0
A19: Concreto (40 Mpa) | B19: 1.3 | C19: perda | D19: =(PI()*((0.4^2)/4)*D12+PI()*((0.5^2)/4)*D14+PI()*((0.6^2)/4)*D16) -> 1163.7716 | E19: m³ | F19: =535+45 -> 580 | G19: =F19*D19*1.1*0 -> 0
A20: Armação | B20: 12 | C20: kg / m³ | D20: =B20*D19 -> 13965.259 | E20: kg | F20: 7.62 | G20: =F20*D20*1.1*0 -> 0
A21: Mobilização | B21: 1 | C21: vb | D21: 1 | E21: vb | F21: 14500 | G21: =F21*D21*1.1*0 -> 0
A22: Apoio e arrasamento de estacas | D22: =D10 -> 179 | E22: un | F22: 300 | G22: =F22*D22*1.1*0 -> 0
A23: TOTAL | G23: =SUM(G10:G22) -> 0
A25: FUNDAÇÃO RASA
A27: Descrição | B27: Parâmetro | D27: Quantidade | F27: Preço unitário | G27: Valor total | H27: Observação
A28: Fabricação, montagem e desmontagem de forma para blocos e baldrames resinado | B28: 1.1 | C28: m² / APE | D28: =B28*DADOS_INICIAIS!E25 -> 1312.608 | E28: m² | F28: 68 | G28: =F28*D28*1.1 -> 98183.078 | I28: =G28/D28 -> 74.8
A29: Concreto (40 Mpa) | B29: 0.65 | C29: m³ / APE | D29: =B29*DADOS_INICIAIS!E25 -> 775.632 | E29: m³ | F29: =535+45 -> 580 | G29: =F29*D29*1.05*1.1 -> 519595.88 | I29: =G29/D29 -> 669.9
A30: Armação | B30: 80 | C30: kg / m³ | D30: =B30*D29 -> 62050.56 | E30: kg | F30: 8.42 | G30: =F30*D30*1.1 -> 574712.29 | H30: Base obra Barra4
A31: Piso de concreto armado | B31: 1 | C31: m² / APE | D31: =B31*DADOS_INICIAIS!E25 -> 1193.28 | E31: m² | F31: 180 | G31: =F31*D31*1.1 -> 236269.44
A32: Mão de obra | B32: =SUPRAESTRUTURA!B15*1.5 -> 360 | C32: R$ / APE | D32: =DADOS_INICIAIS!E25 -> 1193.28 | E32: m² | F32: =B32 -> 360 | G32: =F32*D32*1.1 -> 472538.88
A33: TOTAL | G33: =SUM(G28:G32) -> 1901299.6
A36: TOTAL INFRAESTRUTURA | G36: =G23+G33 -> 1901299.6 | H36: =G36/DADOS_INICIAIS!E9 -> 292.74948
H38: =H36/1.1 -> 266.13589

Sheet SUPRAESTRUTURA
A3: SUPRAESTRUTURA
A4: Data | B4: 45469
A5: Arquivo base | B5: -
A7: SUPRAESTRUTURA - LAJE MACIÇA
A9: Descrição | B9: Parâmetro | D9: Quantidade | F9: Preço unitário | G9: Valor total | H9: Observação
A10: Fabricação forma | B10: 2 | C10: Jogos | D10: =(D11/DADOS_INICIAIS!$E$15)*B10 -> 4059.1438 | E10: m² | F10: 110 | G10: =F10*D10*1.1 -> 491156.39
A11: Montagem de forma | B11: 2.5 | C11: m² / AC | D11: =B11*(DADOS_INICIAIS!$E$9) -> 16236.575 | E11: m² | F11: 2.5 | G11: =F11*D11*1.1 -> 44650.581
A12: Escoramento | B12: 2 | C12: un / AE | D12: =ROUNDUP(B12*DADOS_INICIAIS!$E$25*B10,0) -> 4774 | E12: un | F12: =17 -> 17 | G12: =F12*D12*1.1 -> 89273.8
A13: Concreto | B13: 0.22 | C13: m³ / AC | D13: =B13*((DADOS_INICIAIS!$E$9-DADOS_INICIAIS!E25*1.5)) -> 1035.0362 | E13: m³ | F13: =535+45 -> 580 | G13: =F13*D13*1.1 -> 660353.1
A14: Armadura Convencional para Estrutura | B14: 110 | C14: kg / m³ | D14: =D13*B14 -> 113853.98 | E14: kg | F14: 7.62 | G14: =F14*D14*1.1 -> 954324.08
A15: Mão de obra - estrutura em concreto armado | B15: 240 | C15: R$ / AC | D15: =DADOS_INICIAIS!$E$9 -> 6494.63 | E15: m² | F15: =B15 -> 240 | G15: =F15*D15*1.1 -> 1714582.3 | I15: =G15/D15 -> 264
A16: Perfuração de vigas | B16: 5300 | C16: R$ / NP | D16: 1 | E16: vb | F16: =B16*(DADOS_INICIAIS!$E$15) -> 42400 | G16: =F16*D16*1.1 -> 46640 | H16: Coeficiente originário do Gran Torino (R$ 160,00/un) | I16: Nova utiliza a verba de 1.500,00 por pav
A17: TOTAL | G17: =SUM(G10:G16) -> 4000980.3
A19: SUPRAESTRUTURA - LAJE CUBETAS (somente Embasamento)
A21: Descrição | B21: Parâmetro | D21: Quantidade | F21: Preço unitário | G21: Valor total | H21: Observação
A22: Fabricação forma | B22: 2 | C22: Jogos | D22: =(D23/DADOS_INICIAIS!$E$15)*B22 -> 939.708 | E22: m² | F22: 110 | G22: =F22*D22*1.1 -> 113704.67
A23: Montagem de forma | B23: 2.1 | C23: m² / AC | D23: =B23*(DADOS_INICIAIS!$E$25+DADOS_INICIAIS!$E$25/2) -> 3758.832 | E23: m² | F23: 2.5 | G23: =F23*D23*1.1 -> 10336.788
A24: Escoramento | B24: 2 | C24: un / APT*NPT | D24: =ROUNDUP(B24*DADOS_INICIAIS!$E$25*B22,0) -> 4774 | E24: un | F24: =17 -> 17 | G24: =F24*D24*1.1 -> 89273.8
A25: Cubetas | B25: 25 | C25: R$ / AC | D25: 1 | E25: vb | F25: =B25*((DADOS_INICIAIS!$E$25+DADOS_INICIAIS!$E$25/2)) -> 44748 | G25: =F25*D25*1.1 -> 49222.8
A26: Concreto | B26: 0.25 | C26: m³ / AC | D26: =B26*(DADOS_INICIAIS!E25*1.5) -> 447.48 | E26: m³ | F26: =535+45 -> 580 | G26: =F26*D26*1.05*1.1 -> 299766.85
A27: Armadura Convencional para Estrutura | B27: 110 | C27: kg / m³ | D27: =D26*B27 -> 49222.8 | E27: kg | F27: 7.62 | G27: =F27*D27*1.1 -> 412585.51
A28: TOTAL | G28: =SUM(G22:G27) -> 974890.42
A30: SUPRAESTRUTURA - LAJE TRELIÇADA
A32: Descrição | B32: Parâmetro | D32: Quantidade | F32: Preço unitário | G32: Valor total | H32: Observação
A33: Fabricação forma | B33: 2 | C33: Jogos | D33: =(D34/DADOS_INICIAIS!$E$15)*B33 -> 0 | E33: m² | F33: 85 | G33: =F33*D33*1.1 -> 0
A34: Montagem de forma | B34: 2.1 | C34: m² / AC | D34: =B34*DADOS_INICIAIS!E38 -> 0 | E34: m² | F34: 1.5 | G34: =F34*D34*1.1 -> 0
A35: Escoramento - Torre | B35: 2 | C35: un / APT*NPT | D35: =B35*DADOS_INICIAIS!E47*DADOS_INICIAIS!E44 -> 0 | E35: un | F35: 17 | G35: =F35*D35*1.1 -> 0
A36: Escoramento - Embasamento | B36: 2 | C36: un / AE | D36: =B36*DADOS_INICIAIS!E50 -> 0 | E36: un | F36: 17 | G36: =F36*D36*1.1 -> 0
A37: Cubetas | B37: 25 | C37: R$ / AC | D37: =B37*DADOS_INICIAIS!E38 -> 0 | E37: m³ | F37: =B37 -> 25 | G37: =F37*D37*1.1 -> 0
A38: Concreto | B38: 0.25 | C38: m³ / AC | D38: =B38*DADOS_INICIAIS!E38 -> 0 | E38: m³ | F38: =575 -> 575 | G38: =F38*D38*1.05*1.1 -> 0
A39: Armadura Convencional para Estrutura | B39: 110 | C39: kg / m³ | D39: =D38*B39 -> 0 | E39: kg | F39: 7.25 | G39: =F39*D39*1.1 -> 0
A40: Mão de obra - estrutura em concreto armado | B40: 240 | C40: R$ / AC | D40: =DADOS_INICIAIS!E38 -> 0 | E40: m² | F40: =B40 -> 240 | G40: =F40*D40*1.1 -> 0
A41: Perfuração de vigas | B41: 5300 | C41: R$ / NP | D41: 1 | E41: vb | F41: =B41*DADOS_INICIAIS!E43 -> 0 | G41: =F41*D41*1.1 -> 0 | H41: Coeficiente originário do Gran Torino (R$ 160,00/un)
A42: TOTAL | G42: =SUM(G33:G41) -> 0
A44: SUPRAESTRUTURA - LAJE PROTENDIDA
A46: Descrição | B46: Parâmetro | D46: Quantidade | F46: Preço unitário | G46: Valor total | H46: Observação
A47: Fabricação forma | B47: 3 | C47: Jogos | D47: =(D48/DADOS_INICIAIS!$E$15)*B47 -> 5114.5211 | E47: m² | F47: 110 | G47: =F47*D47*1.1*0 -> 0
A48: Montagem de forma | B48: 2.1 | C48: m² / AC | D48: =B48*DADOS_INICIAIS!$E$9 -> 13638.723 | E48: m² | F48: 2.5 | G48: =F48*D48*1.1*0 -> 0
A49: Escoramento | B49: 3 | C49: un / AE | D49: =ROUNDUP(B49*DADOS_INICIAIS!$E$25*B47,0) -> 10740 | E49: un | F49: 17 | G49: =F49*D49*1.1*0 -> 0
A50: Protensão - lajes - materiais | B50: 12.3 | C50: RS / m² | D50: =(DADOS_INICIAIS!$E$16+DADOS_INICIAIS!$E$17)*DADOS_INICIAIS!$E$19+DADOS_INICIAIS!$E$22 -> 5587.8975 | E50: m² | F50: =B50 -> 12.3 | G50: =F50*D50*1.1*0 -> 0
...

Sheet INSTALAÇÕES
A2: INSTALAÇÕES
A4: INSTALAÇÕES ELÉTRICAS
A6: Descrição | B6: Parâmetro | D6: Valor total
A7: Entrada de Energia | B7: 5.5 | C7: R$ / AC | D7: =B7*DADOS_INICIAIS!$E$9*1.1 -> 39292.512
A8: Eletrodutos e Eletrocalhas | B8: 10 | C8: R$ / AC | D8: =B8*DADOS_INICIAIS!$E$9*1.1 -> 71440.93
A9: Cabos e Fiações | B9: 30 | C9: R$ / AC | D9: =B9*DADOS_INICIAIS!$E$9*1.1 -> 214322.79
A10: Quadros e Disjuntores | B10: 15 | C10: R$ / AC | D10: =B10*DADOS_INICIAIS!$E$9*1.1 -> 107161.4
A11: Acabamentos Elétricos | B11: 10 | C11: R$ / AC | D11: =B11*DADOS_INICIAIS!$E$9*1.1 -> 71440.93
A12: Equipamentos e Iluminação | B12: 10 | C12: R$ / AC | D12: =B12*DADOS_INICIAIS!$E$9*1.1 -> 71440.93
A13: Mão de Obra para Instalações Elétricas | B13: 60 | C13: R$ / AC | D13: =B13*DADOS_INICIAIS!$E$9*1.1 -> 428645.58
A14: TOTAL | D14: =SUM(D7:D13) -> 1003745.1 | E14: ok
A16: INSTALAÇÕES HIDROSSANITÁRIAS
A18: Descrição | B18: Parâmetro | D18: Valor total
A19: Instalações de Água Fria | B19: 20 | C19: R$ / AC | D19: =B19*DADOS_INICIAIS!$E$9*1.1 -> 142881.86
A20: Instalações de Água Quente | B20: 18 | C20: R$ / AC | D20: =B20*DADOS_INICIAIS!$E$9*1.1 -> 128593.67
A21: Instalações de Águas Pluviais | B21: 10 | C21: R$ / AC | D21: =B21*DADOS_INICIAIS!$E$9*1.1 -> 71440.93
A22: Instalações Sanitárias | B22: 15 | C22: R$ / AC | D22: =B22*DADOS_INICIAIS!$E$9*1.1 -> 107161.4
A23: Louças e Metais | B23: 45 | C23: R$ / AC | D23: =B23*DADOS_INICIAIS!$E$9*1.1 -> 321484.18
A24: Mão de Obra para Instalações Hidráulicas | B24: 55 | C24: R$ / AC | D24: =B24*DADOS_INICIAIS!$E$9*1.1 -> 392925.12
A25: TOTAL | D25: =SUM(D19:D24) -> 1164487.2 | E25: ok
A27: INSTALAÇÕES PREVENTIVAS E GLP
A29: Descrição | B29: Parâmetro | D29: Valor total
A30: Instalações Preventivas | B30: 10 | C30: R$ / AC | D30: =B30*DADOS_INICIAIS!$E$9*1.1 -> 71440.93 | E30: 12828.33 | F30: área construída do Atlântia
A31: Instalações de GLP - Medidores, reguladores e registro | B31: 4.78 | C31: R$ / AC | D31: =B31*DADOS_INICIAIS!$E$9*1.1 -> 34148.765 | E31: =61265.61/E30 -> 4.7758056
A32: Instalações de GLP - Rede primária | B32: 9.11 | C32: R$ / AC | D32: =B32*DADOS_INICIAIS!$E$9*1.1 -> 65082.687 | E32: =116889.55/E30 -> 9.1118291
A33: Instalações de GLP - Rede Secundária | B33: 7.05 | C33: R$ / AC | D33: =B33*DADOS_INICIAIS!$E$9*1.1 -> 50365.856 | E33: =90478.11/E30 -> 7.0529921
A34: Instalações de Proteção e Aterramento - SPDA | B34: 4 | C34: R$ / AC | D34: =B34*DADOS_INICIAIS!$E$9*1.1 -> 28576.372
A35: TOTAL | D35: =SUM(D30:D34) -> 249614.61
A37: TOTAL INSTALAÇÕES | D37: =D14+D25+D35 -> 2417846.8 | E37: =D37/DADOS_INICIAIS!E9 -> 372.284
E39: =E37/1.1 -> 338.44

Sheet SISTEMAS ESPECIAIS
A2: SISTEMAS ESPECIAIS
A4: CLIMATIZAÇÃO, EXAUSTÃO MECÂNICA E PRESSURIZAÇÃO
A6: Descrição | B6: Quantidade | C6: Preço Unitário | D6: Valor total | G6: NÍVEL 1 - (PAV.01 e PAV. SUBSOLO 02) | H6: NÍVEL 2 - (SL/MEZ e PAV. SUBSOLO 01) | I6: NÍVEL 3 - (PAV02 e PAV01) | J6: NÍVEL 4 - (PAV03 e PAV02) | K6: NÍVEL 5 - (PAV04 e PAV03) | L6: NÍVEL 6 - (PAV05 e PAV04) | M6: NÍVEL 7 - (PAV COBERTURA) | N6: RESERVATÓRIOS
A7: Infraestrutura para Instalação de Ar Condicionado | B7: =SUM(G7:N7) -> 155 | C7: 1200 | D7: =B7*C7*1.1 -> 204600 | F7: Infraestrutura para Instalação de Ar Condicionado | G7: 2 | I7: =12+12+11 -> 35 | J7: =12+12+11 -> 35 | K7: =12+12+11 -> 35 | L7: =12+12+11 -> 35 | M7: =7+6 -> 13
A8: Instalação de Ar Condicionado | B8: =SUM(G8:N8) -> 6 | C8: 5000 | D8: =B8*C8*1.1 -> 33000 | F8: Instalação de Ar Condicionado | M8: 6
A9: Ventokit | B9: =SUM(G9:N9) -> 107 | C9: 900 | D9: =B9*C9*1.1 -> 105930 | F9: Ventokit | I9: =I12 -> 25 | J9: =J12 -> 25 | K9: =K12 -> 25 | L9: =L12 -> 25 | M9: =M12+M13 -> 7
A10: Churrasqueiras | B10: =SUM(G10:N10) -> 45 | C10: 2600 | D10: =B10*C10*1.1 -> 128700 | F10: Churrasqueiras | I10: =I14 -> 11 | J10: =J14 -> 11 | K10: =K14 -> 11 | L10: =L14 -> 11 | M10: 1
A11: TOTAL | D11: =SUM(D7:D10) -> 472230 | F11: Banheiros comuns | G11: 1 | M11: 3
F12: Banheiros privativos | G12: 1 | I12: =3+8+8+2+2+2 -> 25 | J12: =3+8+8+2+2+2 -> 25 | K12: =3+8+8+2+2+2 -> 25 | L12: =3+8+8+2+2+2 -> 25 | M12: 6
A13: COMUNICAÇÃO | F13: Cozinhas comuns | G13: 1 | M13: 1
F14: Cozinhas privativas | G14: 1 | I14: 11 | J14: 11 | K14: 11 | L14: 11 | M14: 2
A15: Descrição | B15: Parâmetro | D15: Valor total | F15: Varanda Gourmet | G15: 1 | I15: 11 | J15: 11 | K15: 11 | L15: 11
A16: CFTV | B16: 2 | C16: R$ / AC | D16: =B16*DADOS_INICIAIS!$E$9*1.1 -> 14288.186 | F16: Ralos | G16: =G15+SUM(G11:G14)*2 -> 9 | H16: =H15+SUM(H11:H14)*2 -> 0 | I16: =I15+SUM(I11:I14)*2 -> 83 | J16: =J15+SUM(J11:J14)*2 -> 83 | K16: =K15+SUM(K11:K14)*2 -> 83 | L16: =L15+SUM(L11:L14)*2 -> 83 | M16: =M15+SUM(M11:M14)*2 -> 24 | N16: =N15+SUM(N11:N14)*2 -> 0
A17: Interfone | B17: 5 | C17: R$ / AC | D17: =B17*DADOS_INICIAIS!$E$9*1.1 -> 35720.465
A18: TV e internet | B18: 3 | C18: R$ / AC | D18: =B18*DADOS_INICIAIS!$E$9*1.1 -> 21432.279
A19: Automação, telecomunicação e sistemas de segurança | B19: 5 | C19: R$ / AC | D19: =B19*DADOS_INICIAIS!$E$9*1.1 -> 35720.465
A20: TOTAL | D20: =SUM(D16:D19) -> 107161.4
A22: EQUIPAMENTOS
A24: Descrição | B24: Quantidade | C24: Preço Unitário | D24: Valor total
A25: Elevadores | B25: 2 | C25: =(768900/2)*0.85 -> 326782.5 | D25: =B25*C25*1.1 -> 718921.5
A26: Grupo de geradores | B26: 1 | C26: 18000 | D26: =B26*C26*1.1 -> 19800
A27: Bombas | B27: 1 | C27: 8000 | D27: =B27*C27*1.1 -> 8800
A28: Infra de carro elétrico | B28: 2 | C28: 560 | D28: =B28*C28*1.1 -> 1232
A29: Equipamento de piscina | B29: 1 | C29: 25000 | D29: =B29*C29*1.1 -> 27500
A30: Sistema de aquecimento | B30: 0 | C30: =55*DADOS_INICIAIS!E9 -> 357204.65 | D30: =B30*C30 -> 0
A31: TOTAL | D31: =SUM(D25:D30) -> 776253.5
A33: OUTROS SISTEMAS ESPECIAIS
A35: Descrição | B35: Parâmetro | D35: Valor total
A36: Outros sistemas | B36: 20 | C36: R$ / AC | D36: =B36*DADOS_INICIAIS!E9*1.1 -> 142881.86
A37: TOTAL | D37: =SUM(D36:D36) -> 142881.86
A39: TOTAL SISTEMAS ESPECIAIS | D39: =D11+D20+D31+D37 -> 1498526.8 | E39: =D39/DADOS_INICIAIS!E9 -> 230.7332

Sheet COMPLEMENTARES
A2: COMPLEMENTARES
A3: Data | B3: 45460
A4: Arquivo base | B4: -
A6: SERVIÇOS COMPLEMENTARES
A8: Descrição | B8: Parâmetro | D8: Quantidade | F8: Valor total
A9: Móveis e decoração | B9: 1900 | C9: R$ / AL | D9: =DADOS_INICIAIS!E21-184.89*0.5 -> 255.2498 | E9: m² | F9: =D9*B9*1.1 -> 533472.08
A10: Comunicação visual | B10: 10 | C10: R$ / AC | D10: =B10*DADOS_INICIAIS!$E$9 -> 64946.3 | E10: vb | F10: =D10*1.1 -> 71440.93
A11: Paisagismo | B11: 12 | C11: R$ / AC | D11: =B11*DADOS_INICIAIS!$E$9 -> 77935.56 | E11: vb | F11: =D11*1.1 -> 85729.116
A12: Ligações definitivas | B12: 4 | C12: R$ / AC | D12: =B12*DADOS_INICIAIS!$E$9 -> 25978.52 | E12: vb | F12: =D12*1.1 -> 28576.372
A13: Desmobilização | B13: 5 | C13: R$ / AC | D13: =B13*DADOS_INICIAIS!$E$9 -> 32473.15 | E13: vb | F13: =D13*1.1 -> 35720.465
A14: Limpeza | B14: 15 | C14: R$ / AC | D14: =B14*DADOS_INICIAIS!$E$9 -> 97419.45 | E14: vb | F14: =D14*1.1 -> 107161.4
A15: TOTAL | F15: =SUM(F9:F14) -> 862100.36
A17: TOTAL COMPLEMENTARES | F17: =F15 -> 862100.36 | G17: =F17/DADOS_INICIAIS!$E$9 -> 132.74049

Sheet ALVENARIA
A3: PAREDES E PAINÉIS
A4: Data | B4: 45469
A5: Arquivo base | B5: -
A7: ALVENARIA | D7: =D16/2.91 -> 3651.6136 | E7: 2.86 | F7: 2.91 | G7: 2.97
A9: Descrição | B9: Parâmetro | D9: Quantidade | F9: Preço unitário | G9: Valor total | H9: Observação
A10: Alvenaria embasamento | B10: 1 | C10: m² / AE | D10: =B10*DADOS_INICIAIS!$E$22 -> 1143.09 | E10: m² | F10: 45 | G10: =F10*D10*1.1 -> 56582.955
A11: Alvenaria lazer | B11: 0.4 | C11: m² / AL | D11: =B11*DADOS_INICIAIS!$E$21 -> 139.07792 | E11: m² | F11: 45 | G11: =F11*D11*1.1 -> 6884.357
A12: Alvenaria tipo | B12: 1.65 | C12: m² / APT*(NPT+2ND) | D12: =B12*(DADOS_INICIAIS!$E$19*(DADOS_INICIAIS!$E$16+DADOS_INICIAIS!$E$17)) -> 7333.9324 | E12: m² | F12: 45 | G12: =F12*D12*1.1 -> 363029.65
A13: Alvenaria escadas | B13: 0.2 | C13: m² / AC | D13: =B13*DADOS_INICIAIS!$E$9 -> 1298.926 | E13: m² | F13: 70 | G13: =F13*D13*1.05*1.1 -> 105018.17
A14: Alvenaria cobertura / reservatório | B14: 0.8 | C14: m² / APT | D14: =B14*DADOS_INICIAIS!$E$19 -> 711.1692 | E14: m² | F14: 45 | G14: =F14*D14*1.1 -> 35202.875
A15: Alvenaria refratárias | B15: 1.75 | C15: m² * CHU | D15: =B15*DADOS_INICIAIS!$E$14 -> 77 | E15: un | F15: 210 | G15: =F15*D15*1.1 -> 17787
A16: Serviços complementares | B16: 12.5 | C16: R$ / m² | D16: =D10+D11+D12+D13+D14 -> 10626.195 | E16: m² | F16: =B16 -> 12.5 | G16: =F16*D16*1.1 -> 146110.19
A17: Mão de obra | B17: 35 | C17: R$ / m² | D17: =D10+D11+D12+D13+D14 -> 10626.195 | E17: m² | F17: 35 | G17: =F17*D17*1.1 -> 409108.53
A18: TOTAL | G18: =SUM(G10:G17) -> 1139723.7 | K18: =4160+1440+1120+2880+4800+91680+4000 -> 110080 | L18: =K18/21 -> 5241.9048
E19: =G17/D17 -> 38.5
A20: ALVENARIA - DRYWALL
A22: Descrição | B22: Parâmetro | D22: Quantidade | F22: Preço unitário | G22: Valor total | H22: Observação
A23: Alvenaria embasamento | B23: 1 | C23: m² / AE | D23: =B23*DADOS_INICIAIS!$E$22 -> 1143.09 | E23: m² | F23: 45 | G23: =F23*D23*1.1 -> 56582.955
A24: Alvenaria lazer | B24: 0.4 | C24: m² / AL | D24: =B24*DADOS_INICIAIS!$E$21 -> 139.07792 | E24: m² | F24: 45 | G24: =F24*D24*1.1 -> 6884.357
A25: Alvenaria tipo | B25: 1.65 | C25: m² / APT*(NPT+2ND) | D25: =B25*(DADOS_INICIAIS!$E$19*(DADOS_INICIAIS!$E$16+DADOS_INICIAIS!$E$17))*0.4 -> 2933.5729 | E25: m² | F25: 45 | G25: =F25*D25*1.1 -> 145211.86
A26: Drywall tipo | B26: 1.65 | C26: m² / APT*(NPT+2ND) | D26: =B26*(DADOS_INICIAIS!$E$19*(DADOS_INICIAIS!$E$16+DADOS_INICIAIS!$E$17))*0.6 -> 4400.3594 | E26: m² | F26: 220 | G26: =F26*D26*1.1 -> 1064887 | J26: =D26/(D30+D26) -> 0.41410488
A27: Alvenaria escadas | B27: 0.2 | C27: m² / AC | D27: =B27*DADOS_INICIAIS!$E$9 -> 1298.926 | E27: m² | F27: 70 | G27: =F27*D27*1.1 -> 100017.3 | J27: =1-J26 -> 0.58589512
A28: Alvenaria cobertura / reservatório | B28: 0.8 | C28: m² / APT | D28: =B28*DADOS_INICIAIS!$E$19 -> 711.1692 | E28: m³ | F28: 45 | G28: =F28*D28*1.1 -> 35202.875
A29: Alvenaria refratárias | B29: 1.75 | C29: m² * CHU | D29: ='SISTEMAS ESPECIAIS'!B10 -> 45 | E29: un | F29: 210 | G29: =F29*D29*1.1 -> 10395
A30: Serviços complementares | B30: 12.5 | C30: R$ / m² | D30: =D24+D25+D23+D27+D28 -> 6225.8361 | E30: m² | F30: =B30 -> 12.5 | G30: =F30*D30*1.1 -> 85605.246
A31: Mão de obra | B31: 35 | C31: R$ / m² | D31: =D24+D25+D23+D27+D28 -> 6225.8361 | E31: m² | F31: 35 | G31: =F31*D31*1.1 -> 239694.69
A32: TOTAL | G32: =SUM(G23:G31) -> 1744481.3
A35: TOTAL ALVENARIA | G35: =G32 -> 1744481.3 | H35: =G35/DADOS_INICIAIS!E9 -> 268.60364
G38: =G35/1.1 -> 1585892.1 | H38: =G38/DADOS_INICIAIS!E9 -> 244.18513

Sheet Rev. Fachada
A2: ORÇAMENTO PARAMÉTRICO GERENCIAMENTO EXECUTIVO
A7: Cliente | B7: Passe
A8: Obra | B8: Connect
A9: Data | B9: 45460
A10: Revisão | B10: R00
A12: REVESTIMENTOS ARGAMASSADOS
A14: Descrição | B14: Quantidade | D14: Parâmetro | F14: Referência | G14: Valor total
A15: Chapisco e reboco | B15: =(K18*L18+K19*L19+K21*L21+K20*L20+K22*L22-ESQUADRIAS!D10) -> 8687.7295 | C15: m² | D15: =25+70 -> 95 | E15: R$ / m² | F15: - | G15: =B15*D15*1.1 -> 907867.73
A16: TOTAL | G16: =SUM(G15:G15) -> 907867.73
A18: PINTURA | J18: EMBASAMENTO | K18: =DADOS_INICIAIS!E26 -> 185.03 | L18: =3.2*3 -> 9.6
J19: TORRE 1 | K19: =DADOS_INICIAIS!E20 -> 177.07 | L19: =3.2*9 -> 28.8
A20: Descrição | B20: Quantidade | D20: Parâmetro | F20: Referência | G20: Valor total | J20: TORRE 2 | K20: =K19 -> 177.07 | L20: =3.2*4+1.2 -> 14
A21: Textura | B21: =B15 -> 8687.7295 | C21: m² | D21: =70+15 -> 85 | E21: R$ / m² | F21: - | G21: =B21*D21*1.1 -> 812302.71 | J21: ATICO | K21: 44.25 | L21: 3.2
A22: TOTAL | G22: =SUM(G21:G21) -> 812302.71 | J22: RESERV | K22: 25.85 | L22: =6.4 -> 6.4
L23: =K18*L18+K19*L19+K20*L20+K21*L21+K22*L22 -> 9661.924
A24: ACABAMENTOS ESPECIAIS
A26: Descrição | B26: Quantidade | D26: Parâmetro | F26: Referência | G26: Valor total
A27: Brise | B27: =16.56*3.2*2 -> 105.984 | C27: M² | E27: R$ / m² | F27: - | G27: =B27*D27*1.1 -> 0
G28: =SUM(G27:G27) -> 0
J29: =25.78*2 -> 51.56
A31: TOTAL FACHADA | G31: =G22+G16+G28 -> 1720170.4 | H31: =G31/DADOS_INICIAIS!E9 -> 264.86042
H32: =H31/1.1 -> 240.7822

Sheet IMPERMEABILIZAÇÃO
A3: IMPERMEABILIZAÇÃO
A4: Data | B4: 45471
A5: Arquivo base | B5: -
A7: ALVENARIA
A9: Descrição | B9: Parâmetro | D9: Quantidade | F9: Preço unitário | G9: Valor total | H9: Observação
A10: Regularização de Superfície | B10: 25 | C10: R$ / m² | D10: =D14+D15 -> 2666.0456 | E10: m² | F10: 22 | G10: =F10*D10*1.1 -> 64518.304
A11: Poço do elevador | B11: 45 | C11: R$ / m² | D11: =(3.24+(7.2)*1.8)*2 -> 32.4 | E11: m² | F11: 41 | G11: =F11*D11*1.1 -> 1461.24
A12: Baldrames | B12: 30 | C12: R$ / m² | D12: =INFRAESTRUTURA!D28 -> 1312.608 | E12: m² | F12: 35 | G12: =F12*D12*1.1 -> 50535.408
A13: Ralos | B13: 1 | C13: R$ / AC | D13: 1 | E13: vb | F13: =B13*DADOS_INICIAIS!$E$9 -> 6494.63 | G13: =F13*D13*1.1 -> 7144.093
A14: Impermeabilizações cimenticias | B14: 0.25 | C14: m² / AC | D14: =B14*DADOS_INICIAIS!E9 -> 1623.6575 | E14: m² | F14: 60 | G14: =F14*D14*1.1 -> 107161.4
A15: Impermeabilizações com manta asfaltica | B15: 0.1605 | C15: m² / AC | D15: =B15*DADOS_INICIAIS!E9 -> 1042.3881 | E15: m² | F15: 110 | G15: =F15*D15*1.1 -> 126128.96
A16: Impermeabilização de peitoril | B16: 0.6 | C16: R$ / AC | D16: 1 | E16: vb | F16: =B16*DADOS_INICIAIS!$E$9 -> 3896.778 | G16: =F16*D16*1.1 -> 4286.4558
A17: Proteção Mecânica | B17: 28 | C17: R$ / m² | D17: =D15 -> 1042.3881 | E17: m² | F17: 28 | G17: =F17*D17*1.1 -> 32105.554
A18: TOTAL | G18: =SUM(G10:G17) -> 393341.41 | K18: =4160+1440+1120+2880+4800+91680+4000 -> 110080 | L18: =K18/21 -> 5241.9048
A20: TOTAL IMPERMEABILIZAÇÃO | G20: =G18 -> 393341.41 | H20: =G20/DADOS_INICIAIS!E9 -> 60.564099
H23: =H20/1.1 -> 55.058271

Sheet Rev. Internos Piso e Parede
A2: ORÇAMENTO PARAMÉTRICO GERENCIAMENTO EXECUTIVO
A7: Cliente
A8: Obra
A9: Data | B9: 45471
A10: Revisão | B10: R00
A12: REVESTIMENTOS INTERNOS EM PISO E PAREDE
J13: =SUM(G15:G18) -> 328608.78
A14: Descrição | B14: Quantidade | D14: Parâmetro | F14: Referência | G14: Valor total | J14: =G19+G20 -> 438504.43
A15: Polimento de concreto | B15: ='Acabamentos de Piso e Parede'!B30 -> 1250.1 | C15: m² | D15: 16.5 | E15: R$ / m² | F15: Média | G15: =D15*B15*1.1 -> 22689.315
A16: Piso alisado | B16: ='Acabamentos de Piso e Parede'!B35 -> 345.474 | C16: m² | D16: 25 | E16: R$ / m² | F16: Média | G16: =D16*B16*1.1 -> 9500.535
A17: Contrapiso | B17: 3047.1 | C17: m² | D17: =B17/DADOS_INICIAIS!E9 -> 0.46917222 | E17: m² / AC | F17: Média | G17: =+B17*65*1.1 -> 217867.65
A18: Manta acústica | B18: =B17-190.69 -> 2856.41 | C18: m² | D18: =B18/DADOS_INICIAIS!E9 -> 0.43981104 | E18: m² / AC | F18: Média | G18: =+B18*25*1.1 -> 78551.275
A19: Chapisco | B19: =DADOS_INICIAIS!E9*'Rev. Internos Piso e Parede'!D19*0.62 -> 7248.0071 | C19: m² | D19: 1.8 | E19: m² / AC | F19: Média | G19: =+B19*5*1.1 -> 39864.039
A20: Reboco | B20: =DADOS_INICIAIS!E9*'Rev. Internos Piso e Parede'!D20*0.62 -> 7248.0071 | C20: m² | D20: 1.8 | E20: m² / AC | F20: Média | G20: =50*B20*1.1 -> 398640.39
A21: TOTAL | G21: =SUM(G15:G20) -> 767113.2
A24: TOTAL REVESTIMENTOS | G24: =G21 -> 767113.2 | H24: =G24/DADOS_INICIAIS!E9 -> 118.115
H26: =H24/1.1 -> 107.37727

Sheet TETO
A3: REVESTIMENTOS E ACABAMENTOS DE TETO
A4: Data | B4: 45471
A5: Arquivo base | B5: -
A7: ALVENARIA
A9: Descrição | B9: Parâmetro | D9: Quantidade | F9: Preço unitário | G9: Valor total | H9: Observação
A10: Forro gesso acartonado st | B10: 0.5 | C10: m² / AC | D10: =B10*DADOS_INICIAIS!$E$9 -> 3247.315 | E10: m² | F10: 110 | G10: =F10*D10*1.1 -> 392925.12
A11: Forro gesso acartonado ru | B11: 0.2 | C11: m² / AC | D11: =B11*DADOS_INICIAIS!$E$9 -> 1298.926 | E11: m² | F11: 120 | G11: =F11*D11*1.1 -> 171458.23
A12: Negativo | B12: 1.2 | C12: m / FORRO | D12: =(D10+D11)*B12 -> 5455.4892 | E12: m² | F12: 22 | G12: =F12*D12*1.1 -> 132022.84
A13: Estucamento | B13: =1-B10-B11 -> 0.3 | C13: m² / AC | D13: =B13*DADOS_INICIAIS!$E$9 -> 1948.389 | E13: m² | F13: 24 | G13: =F13*D13*1.1 -> 51437.47
A14: TOTAL | G14: =SUM(G10:G13) -> 747843.66 | K14: =4160+1440+1120+2880+4800+91680+4000 -> 110080 | L14: =K14/21 -> 5241.9048
A16: TOTAL FORRO | G16: =G14 -> 747843.66 | H16: =G16/DADOS_INICIAIS!E9 -> 115.148
H19: =H16/1.1 -> 104.68

Sheet Acabamentos de Piso e Parede
A2: ORÇAMENTO PARAMÉTRICO GERENCIAMENTO EXECUTIVO
A7: Cliente
A8: Obra
A9: Data | B9: 45471
A10: Revisão | B10: R00
A12: ACABAMENTOS EM PISO E PAREDE
A14: Descrição | B14: Quantidade | D14: Parâmetro | F14: Referência | G14: Valor total
A15: Porcelanato | B15: =B29 -> 3047.1 | C15: m² | D15: 125 | E15: R$ / m² | F15: Média | G15: =+D15*B15*1.1 -> 418976.25
A16: Piscina | B16: =B33 -> 34.98 | C16: m² | D16: 250 | E16: R$ / m² | F16: Média | G16: =+D16*B16*1.1 -> 9619.5
A17: Deck | B17: =B32 -> 18 | C17: m² | D17: 450 | E17: R$ / m² | F17: Média | G17: =+D17*B17*1.1 -> 8910
A18: Paver | B18: =B31 -> 79.64 | C18: m² | D18: 60 | E18: R$ / m² | F18: Média | G18: =+D18*B18*1.1 -> 5256.24
A19: Ladrilho hidaraulico | B19: =B34 -> 103.0845 | C19: m² | D19: 180 | E19: R$ / m² | F19: Média | G19: =+D19*B19*1.1 -> 20410.731
A20: Rodapés | B20: 1 | C20: vb | D20: 30 | E20: R$ / AC | F20: Média | G20: =D20*DADOS_INICIAIS!$E$9*1.1 -> 214322.79
A21: Soleiras e peitoris | B21: 1 | C21: vb | D21: 20 | E21: R$ / AC | F21: Média | G21: =D21*DADOS_INICIAIS!$E$9*1.1 -> 142881.86
A22: Revestimentos de Parede | B22: 1 | C22: vb | D22: 50 | E22: R$ / AC | F22: Média | G22: =D22*DADOS_INICIAIS!$E$9*1.1 -> 357204.65
A23: =20*40 -> 800 | G23: =SUM(G15:G22) -> 1177582
A26: TOTAL ACABAMENTOS | G26: =G23 -> 1177582 | H26: =G26/DADOS_INICIAIS!E9 -> 181.31626
H28: =H26/1.1 -> 164.83296
A29: PORCELANATO | B29: 3047.1
A30: CIMENTADO | B30: 1250.1
A31: PAVER | B31: 79.64
A32: DECK | B32: 18
A33: PASTILHA | B33: 34.98
A34: LADRILHO | B34: 103.0845
A35: CIMENTADO ESCADA | B35: 345.474

Sheet PINTURA INTERNA
A3: PINTURA INTERNA
A4: Data | B4: 45457
A5: Arquivo base | B5: -
A7: ALVENARIA
A9: Descrição | B9: Parâmetro | D9: Quantidade | F9: Preço unitário | G9: Valor total | H9: Observação
A10: Pintura piso epoxi | B10: 25 | C10: R$ / m² | D10: ='Rev. Internos Piso e Parede'!B15 -> 1250.1 | E10: m² | F10: 110 | G10: =F10*D10*1.1 -> 151262.1
A11: Pintura acrílica antiderrapante | B11: 45 | C11: R$ / m² | D11: ='Rev. Internos Piso e Parede'!B16 -> 345.474 | E11: m² | F11: 65 | G11: =F11*D11*1.1 -> 24701.391
A12: Textura escadas | B12: 15 | C12: R$ / AC | D12: 1 | E12: vb | F12: =B12*DADOS_INICIAIS!$E$9 -> 97419.45 | G12: =F12*D12*1.1 -> 107161.4
A13: Pintura Interna | B13: 60 | C13: R$ / AC | D13: 1 | E13: vb | F13: =B13*DADOS_INICIAIS!$E$9 -> 389677.8 | G13: =F13*D13*1.1 -> 428645.58
A14: TOTAL | G14: =SUM(G10:G13) -> 711770.47 | K14: =4160+1440+1120+2880+4800+91680+4000 -> 110080 | L14: =K14/21 -> 5241.9048
A16: TOTAL IMPERMEABILIZAÇÃO | G16: =G14 -> 711770.47 | H16: =G16/DADOS_INICIAIS!E9 -> 109.59369
H18: =H16/1.1 -> 99.630627

Sheet ESQUADRIAS
A3: ESQUADRIAS
A4: Data | B4: 45460
A5: Arquivo base | B5: -
A7: ESQUADRIAS
A9: Descrição | B9: Parâmetro | D9: Quantidade | G9: Valor total | H9: Observação
A10: Esquadrias de Alumínio | B10: 0.15 | C10: m² / AC | D10: =B10*DADOS_INICIAIS!E9 -> 974.1945 | E10: m² | F10: 980 | G10: =F10*D10*1.1 -> 1050181.7 | H10: =G10/DADOS_INICIAIS!E9 -> 161.7 | I10: =G10/D10 -> 1078
A11: Brise de aluminio | D11: =16.56*3.2*2 -> 105.984 | E11: m² | F11: 1600 | G11: =F11*D11*1.1 -> 186531.84 | I11: =G11/D11 -> 1760
A12: Portão de alumínio | D12: 1 | E12: un | F12: 18000 | G12: =F12*D12*1.1 -> 19800 | I12: =G12/D12 -> 19800
A13: Guarda-corpo - vidro | D13: =7.2*8+6.16*4+18+5.56*8+4.39*4 -> 162.28 | E13: m | F13: =750*1.1 -> 825 | G13: =F13*D13*1.1 -> 147269.1 | I13: =G13/D13 -> 907.5
A14: Gradil - BRISE | D14: =(2.9*8+5.52*8+3.82*4)*3.2 -> 264.448 | E14: m² | F14: 710 | G14: =F14*D14*1.1 -> 206533.89 | I14: =G14/D14 -> 781
A15: Corrimão inox | D15: =1.9*2 -> 3.8 | E15: m | F15: 150 | G15: =F15*D15*1.1 -> 627 | I15: =G15/D15 -> 165 | J15: =I15*1.5 -> 247.5
A16: Serralherias | B16: 10 | C16: R$ / AC | D16: 1 | E16: vb | F16: =B16*DADOS_INICIAIS!$E$9 -> 64946.3 | G16: =F16*D16*1.1 -> 71440.93 | I16: =G16/D16 -> 71440.93
A17: PCF | D17: =2*DADOS_INICIAIS!E15 -> 16 | E17: un | F17: 1750 | G17: =F17*D17*1.1 -> 30800 | I17: =G17/D17 -> 1925
A18: Corrimão madeira | D18: =((3.52*2+2.4+2.32*2)*1.2)*17 -> 287.232 | E18: m | F18: 65 | G18: =F18*D18*1.1 -> 20537.088 | I18: =G18/D18 -> 71.5
A19: Fechadura Biometrica | D19: =5+7*8+6*4 -> 85 | E19: un | F19: 1500 | G19: =F19*D19*1.1 -> 140250 | I19: =G19/D19 -> 1650
A20: Esquadrias de Madeira | D20: 192 | E20: un | F20: 1450 | G20: =F20*D20*1.1 -> 306240 | I20: =G20/D20 -> 1595
A21: TOTAL | G21: =SUM(G10:G20) -> 2180211.5 | K21: =4160+1440+1120+2880+4800+91680+4000 -> 110080 | L21: =K21/21 -> 5241.9048
A23: TOTAL ESQUADRIAS | G23: =G21 -> 2180211.5 | H23: =G23/DADOS_INICIAIS!E9 -> 335.69449

Sheet COBERTURA
A2: COBERTURA
A3: Data | B3: 45460
A4: Arquivo base | B4: -
A6: TELHADO
A8: Descrição | B8: Parâmetro | D8: Quantidade | F8: Preço unitário | G8: Valor total | H8: Observação
A9: Estrutura e telhamento | D9: =15.74+61.87 -> 77.61 | E9: m² | F9: 500 | G9: =F9*D9*1.1 -> 42685.5
A10: Serviços complementares | D10: =D9 -> 77.61 | E10: m² | F10: 45 | G10: =F10*D10*1.1 -> 3841.695
A11: Pergolados | G11: =F11*D11*1.1 -> 0
A12: Passarelas | G12: =F12*D12*1.1 -> 0
A13: TOTAL | G13: =SUM(G9:G12) -> 46527.195
A15: TOTAL COMPLEMENTARES | G15: =G13 -> 46527.195 | H15: =G15/DADOS_INICIAIS!$E$9 -> 7.1639485
