Workbook
Name \0: #REF!
Name \0: #REF!
Name \0: #REF!
Name \0: #REF!
Name \0: #REF!
Name \0: #REF!
Name \0: #REF!
Name \0: #REF!
Name \0: #REF!
Name \1: #REF!
Name \1: #REF!
Name \1: #REF!
Name \1: #REF!
Name \1: #REF!
Name \a: #REF!
Name \a: #REF!
Name \a: #REF!
Name \a: #REF!
Name \a: #REF!
Name \a: #REF!
Name \a: #REF!
Name \a: #REF!
Name \a: #REF!
Name \b: #REF!
Name \b: #REF!
Name \b: #REF!
Name \c: #REF!
Name \c: #REF!
Name \c: #REF!
Name \d: #REF!
Name \d: #REF!
Name \d: #REF!
Name \e: #REF!
Name \e: #REF!
Name \e: #REF!
Name \i: #REF!
Name \i: #REF!
Name \i: #REF!
Name \J: #REF!
Name \J: #REF!
Name \J: #REF!
Name \k: #REF!
Name \k: #REF!
Name \k: #REF!
Name \k: #REF!
Name \l: #N/A
Name \m: #REF!
Name \m: #REF!
Name \m: #REF!
Name \m: #REF!
Name \m: #REF!
Name \m: #REF!
Name \m: #REF!
Name \m: #REF!
Name \m: #REF!
Name \o: #REF!
Name \o: #REF!
Name \o: #REF!
Name \p: #REF!
Name \p: #REF!

Sheet Obra 
C1: Projeto | D1: Mowe
C2: Empresa | D2: MARTINS|FRANCEZ ENGENHARIA
C3: Revisão | D3: R00
A4: QUADRO DE ÁREAS
B6: Descrição | C6: Unidade | E6: Quantidade | G6: Imagens
B7: MESES DE OBRA | C7: MÊS | E7: 14
B8: ÁREA DO TERRENO | C8: M² | E8: 434.37
B9: ÁREA CONSTRUÍDA | C9: M² | E9: 329.57
B10: NÚMERO DE UNIDADES HABITACIONAIS | C10: UN | E10: 1
B11: NÚMERO DE UNIDADES COMERCIAIS | C11: UN | E11: 0
B12: ÁREA PRIVATIVA | C12: M² | E12: 329.57
B13: NÚMERO DE PAVIMENTOS | C13: UN | E13: 4
B15: Térreo | C15: M² | E15: 162.78
B16: Segundo Pavimento | C16: M² | E16: 166.79
B17: Cobertura | C17: M² | E17: 188.81
B18: Reservatório | C18: M² | E18: 10.04
B31: ETAPA | C31: VALOR ORÇADO | D31: % | E31: VALOR / m²
B32: GERENCIAMENTO TÉCNICO E ADMINISTRATIVO | C32: ='Ger_Tec e Adm'!N71 -> 243899.47 | D32: =C32/C$47 -> 0.15212846 | E32: =C32/$E$9 -> 740.0536
B33: INFRAESTRUTURA | C33: =Ger_Executivo!N8 -> 113009.8 | D33: =C33/C$47 -> 0.070488085 | E33: =C33/$E$9 -> 342.90075
B34: SUPRAESTRUTURA | C34: =Ger_Executivo!N35 -> 190194.42 | D34: =C34/C$47 -> 0.11863078 | E34: =C34/$E$9 -> 577.09871
B35: ALVENARIA | C35: =Ger_Executivo!N59 -> 60429.042 | D35: =C35/C$47 -> 0.037691665 | E35: =C35/$E$9 -> 183.35723
B36: INSTALAÇÕES ELÉTRICAS, HIDRÁULICAS, GLP E PREVENTIVAS | C36: =Ger_Executivo!N76+Ger_Executivo!N85+Ger_Executivo!N101 -> 207012.27 | D36: =C36/C$47 -> 0.12912065 | E36: =C36/$E$9 -> 628.12839
B37: CLIMATIZAÇÃO, EXAUSTÃO MECÂNICA E PRESSURIZAÇÃO | C37: =Ger_Executivo!N107 -> 11221.223 | D37: =C37/C$47 -> 0.0069990614 | E37: =C37/$E$9 -> 34.048072
B38: REVESTIMENTOS ARGAMASSADOS PISO E PAREDE | C38: =Ger_Executivo!N113 -> 80151.686 | D38: =C38/C$47 -> 0.049993354 | E38: =C38/$E$9 -> 243.2008
B39: IMPERMEABILIZAÇÃO | C39: =Ger_Executivo!N131 -> 70071.758 | D39: =C39/C$47 -> 0.043706157 | E39: =C39/$E$9 -> 212.61571
B40: ACABAMENTOS INTERNOS EM PAREDE E PISO | C40: =Ger_Executivo!N148 -> 150930.3 | D40: =C40/C$47 -> 0.094140399 | E40: =C40/$E$9 -> 457.96127
B41: ACABAMENTOS E REVESTIMENTOS INTERNOS EM TETO | C41: =Ger_Executivo!N174 -> 50473.202 | D41: =C41/C$47 -> 0.031481866 | E41: =C41/$E$9 -> 153.14865
B42: PINTURA INTERNA | C42: =Ger_Executivo!N187 -> 41028.634 | D42: =C42/C$47 -> 0.025590965 | E42: =C42/$E$9 -> 124.49141
B43: REVESTIMENTOS E ACABAMENTOS DE FACHADA | C43: =Ger_Executivo!N216 -> 184438.31 | D43: =C43/C$47 -> 0.11504049 | E43: =C43/$E$9 -> 559.63318
B44: ESQUADRIAS, VIDROS E FERRAGENS | C44: =Ger_Executivo!N197 -> 137257 | D44: =C44/C$47 -> 0.085611897 | E44: =C44/$E$9 -> 416.47299
B45: SERVIÇOS COMPLEMENTARES | C45: =Ger_Executivo!N234 -> 36475.844 | D45: =C45/C$47 -> 0.022751234 | E45: =C45/$E$9 -> 110.67708
B46: IMPREVISTOS | C46: =Ger_Executivo!N250 -> 26653.87 | D46: =C46/C$47 -> 0.016624932 | E46: =C46/$E$9 -> 80.874685
B47: TOTAL | C47: =SUM(C32:C46) -> 1603246.8 | D47: =SUM(D32:D46) -> 1 | E47: =SUM(E32:E46) -> 4864.6625
B48: CUB/SC | C48: 2978.02 | D48: 45870 | E48: =ROUNDUP(+E47/C48,2)&" CUB" -> 1,64 CUB
C53: =SUM(C33:C45)*0.19 -> 253211.76 | D53: =190649.26/964799.8 -> 0.197605
C54: =C53*0.11 -> 27853.294

Sheet EAP Análise
A1: ETAPA | B1: VALOR ORÇADO | C1: % | D1: VALOR / m²
A2: GERENCIAMENTO TÉCNICO E ADMINISTRATIVO | B2: ='Obra '!C32 -> 243899.47 | C2: =B2/$B$27 -> 0.15212846 | D2: =B2/'Obra '!$E$9 -> 740.0536
A3: MOVIMENTAÇÃO DE TERRA | B3: =Ger_Executivo!N9 -> 10084.168 | C3: =B3/$B$27 -> 0.0062898411 | D3: =B3/'Obra '!$E$9 -> 30.597954
A4: INFRAESTRUTURA | B4: =Ger_Executivo!N19 -> 102925.63 | C4: =B4/$B$27 -> 0.064198244 | D4: =B4/'Obra '!$E$9 -> 312.30279
A5: SUPRAESTRUTURA | B5: =Ger_Executivo!N35 -> 190194.42 | C5: =B5/$B$27 -> 0.11863078 | D5: =B5/'Obra '!$E$9 -> 577.09871
A6: ALVENARIA | B6: =Ger_Executivo!N59 -> 60429.042 | C6: =B6/$B$27 -> 0.037691665 | D6: =B6/'Obra '!$E$9 -> 183.35723
A7: INSTALAÇÕES ELÉTRICAS, HIDRÁULICAS, GLP E PREVENTIVAS | B7: =Ger_Executivo!N76+Ger_Executivo!N85+Ger_Executivo!N101-B10-B23 -> 127201.76 | C7: =B7/$B$27 -> 0.079340098 | D7: =B7/'Obra '!$E$9 -> 385.9628
A8: CLIMATIZAÇÃO, EXAUSTÃO MECÂNICA E PRESSURIZAÇÃO | B8: =Ger_Executivo!N107 -> 11221.223 | C8: =B8/$B$27 -> 0.0069990614 | D8: =B8/'Obra '!$E$9 -> 34.048072
A9: EQUIPAMENTOS E SISTEMAS ESPECIAIS | B9: 0 | C9: =B9/$B$27 -> 0 | D9: =B9/'Obra '!$E$9 -> 0
A10: INSTALAÇÕES ESPECIAIS | B10: =Ger_Executivo!N97 -> 10955.698 | C10: =B10/$B$27 -> 0.0068334444 | D10: =B10/'Obra '!$E$9 -> 33.242401
A11: REVESTIMENTOS ARGAMASSADOS PISO | B11: =SUMIF(Ger_Executivo!Q:Q,A11,Ger_Executivo!N:N) -> 26511.96 | C11: =B11/$B$27 -> 0.016536418 | D11: =B11/'Obra '!$E$9 -> 80.444092
A12: REVESTIMENTOS ARGAMASSADOS PAREDE | B12: =SUMIF(Ger_Executivo!Q:Q,A12,Ger_Executivo!N:N) -> 33446.834 | C12: =B12/$B$27 -> 0.020861937 | D12: =B12/'Obra '!$E$9 -> 101.48628
A13: REVESTIMENTOS ARGAMASSADOS TETO | B13: =SUMIF(Ger_Executivo!Q:Q,A13,Ger_Executivo!N:N) -> 380.6722 | C13: =B13/$B$27 -> 0.0002374383 | D13: =B13/'Obra '!$E$9 -> 1.1550572
A14: IMPERMEABILIZAÇÃO | B14: =SUMIF(Ger_Executivo!Q:Q,A14,Ger_Executivo!N:N) -> 90264.65 | C14: =B14/$B$27 -> 0.056301156 | D14: =B14/'Obra '!$E$9 -> 273.88612
A15: ACABAMENTOS INTERNOS EM PAREDE | B15: =SUMIF(Ger_Executivo!Q:Q,A15,Ger_Executivo!N:N) -> 28197.117 | C15: =B15/$B$27 -> 0.017587508 | D15: =B15/'Obra '!$E$9 -> 85.557292
A16: ACABAMENTOS EM PISOS E PAVIMENTAÇÕES | B16: =SUMIF(Ger_Executivo!Q:Q,A16,Ger_Executivo!N:N) -> 122733.18 | C16: =B16/$B$27 -> 0.076552891 | D16: =B16/'Obra '!$E$9 -> 372.40398
A17: ACABAMENTOS INTERNOS EM TETO | B17: =SUMIF(Ger_Executivo!Q:Q,A17,Ger_Executivo!N:N) -> 50092.53 | C17: =B17/$B$27 -> 0.031244428 | D17: =B17/'Obra '!$E$9 -> 151.9936
A18: PINTURA INTERNA | B18: =SUMIF(Ger_Executivo!Q:Q,A18,Ger_Executivo!N:N) -> 41028.634 | C18: =B18/$B$27 -> 0.025590965 | D18: =B18/'Obra '!$E$9 -> 124.49141
A19: PINTURA DE FACHADA | B19: =SUMIF(Ger_Executivo!Q:Q,A19,Ger_Executivo!N:N) -> 49075.814 | C19: =B19/$B$27 -> 0.030610268 | D19: =B19/'Obra '!$E$9 -> 148.90862
A20: REVESTIMENTOS ARGAMASSADOS DE FACHADA | B20: =SUMIF(Ger_Executivo!Q:Q,A20,Ger_Executivo!N:N) -> 48409.092 | C20: =B20/$B$27 -> 0.03019441 | D20: =B20/'Obra '!$E$9 -> 146.88561
A21: ACABAMENTOS DE FACHADA | B21: =SUMIF(Ger_Executivo!Q:Q,A21,Ger_Executivo!N:N) -> 100308.05 | C21: =B21/$B$27 -> 0.06256557 | D21: =B21/'Obra '!$E$9 -> 304.36038
A22: ESQUADRIAS, VIDROS E FERRAGENS | B22: =SUMIF(Ger_Executivo!Q:Q,A22,Ger_Executivo!N:N) -> 137257 | C22: =B22/$B$27 -> 0.085611897 | D22: =B22/'Obra '!$E$9 -> 416.47299
A23: LOUÇAS E METAIS | B23: =Ger_Executivo!N81 -> 68854.816 | C23: =B23/$B$27 -> 0.042947109 | D23: =B23/'Obra '!$E$9 -> 208.92319
A24: COBERTURA | B24: =Ger_Executivo!N379 -> 0 | C24: =B24/$B$27 -> 0 | D24: =B24/'Obra '!$E$9 -> 0
A25: SERVIÇOS COMPLEMENTARES | B25: =Ger_Executivo!N242+Ger_Executivo!N236 -> 23121.192 | C25: =B25/$B$27 -> 0.01442148 | D25: =B25/'Obra '!$E$9 -> 70.155632
A26: IMPREVISTOS | B26: =Ger_Executivo!N250 -> 26653.87 | C26: =B26/$B$27 -> 0.016624932 | D26: =B26/'Obra '!$E$9 -> 80.874685
A27: TOTAL | B27: =SUM(B2:B26) -> 1603246.8 | C27: =SUM(C2:C26) -> 1 | D27: =SUM(D2:D26) -> 4864.6625
A28: CUB/SC | B28: 2978.02 | C28: 45870 | D28: =ROUNDUP(+D27/B28,2)&" CUB" -> 1,64 CUB

Sheet Ensaios 
C1: Projeto | D1: ='Obra '!D1 -> Mowe
C2: Empresa | D2: ='Obra '!D2 -> MARTINS|FRANCEZ ENGENHARIA
C3: Revisão | D3: ='Obra '!D3 -> R00
A4: ENSAIOS
A5: Item | B5: Descrição/Especificação | C5: Unid. | D5: V. Unit. (R$) | E5: Qtde. | F5: V. Total (R$) | G5: Observações
B6: CONTROLE TECNOLÓGICO - CONCRETO | F6: =SUM(F7:F11) -> 3490
A7: 1 | B7: Laudo e ART | C7: vb | D7: 1450 | E7: 1 | F7: =$D7*E7 -> 1450
A8: =A7+1 -> 2 | B8: Controle Tecnologico Infraestrutura - Coleta materiais da obra | C8: unid. | D8: 20 | E8: =ROUNDUP(Ger_Executivo!L32/8,0)*4 -> 16 | F8: =$D8*E8 -> 320 | G8: 4 CPs por caminhão betoneira de 8m³
A9: =#REF!+1 -> #REF! | B9: Controle Tecnologico Supraestrutura - Coleta materiais da obra | C9: unid. | D9: 20 | E9: =ROUNDUP(Ger_Executivo!L54/8,0)*4 -> 32 | F9: =$D9*E9 -> 640 | G9: 4 CPs por caminhão betoneira de 8m³
A10: =A8+1 -> 3 | B10: Controle Tecnológico - Ensaio de concreto endurecido/grouth - compressão simples / Detalhe: Concreto | C10: cps | D10: 12.5 | E10: =E8+E9 -> 48 | F10: =$D10*E10 -> 600
A11: =A10+1 -> 4 | B11: Determinação do módulo de deformação tangente inicial (Eci) (módulo de elasticidade), Incluindo Avaliação Estática dos Resultados (NBR 8522 e NBR 12655) | C11: ensaio | D11: 480 | E11: 1 | F11: =$D11*E11 -> 480 | G11: A cada 5 pav. (e quando houver troca de fornecedor)
C12: SUBTOTAL: | F12: =F6 -> 3490

Sheet CANTEIRO
A1: Obra | B1: ='Obra '!D1 -> Mowe
A2: Empresa | B2: ='Obra '!D2 -> MARTINS|FRANCEZ ENGENHARIA
A3: Revisão | B3: ='Obra '!D3 -> R00
A4: Instalações de canteiro
A5: Instalações de canteiro
B7: Descrição | C7: Unidade | D7: Quantidade
B8: Produtividade média | C8: m2 / mês | D8: ='Obra '!$E$9/'Obra '!$E$7 -> 23.540714
B9: Pm | C9: h/m2 | D9: 49
B10: Numero de funcionários | C10: un | D10: =ROUNDUP(('Obra '!E9*D9)/'Obra '!E7/180,) -> 7
B11: Equipe administrativa | C11: un | D11: 2
B12: Pontos de água e esgoto | C12: un | D12: =ROUNDUP($D$10/20,0) -> 1 | E12: 20 funcionários/ponto
B13: Bebedouro | C13: un | D13: =ROUNDUP('Obra '!$E$13/5,0) -> 1 | E13: 1 / 5 pav.
B14: Ferramentas | C14: R$ | D14: =800*D10 -> 5600 | E14: 800,00/func.
B15: EPI | C15: R$ | D15: =500*(D10+D11) -> 4500 | E15: 500,00/func.
B16: Banheiro | C16: un | D16: =ROUNDUP($D$10/20,0) -> 1 | E16: 1/20 func

Sheet Ger_Tec e Adm
G4: PROJETO: | I4: ='Obra '!D1 -> Mowe | O4: REVISÃO: | P4: DATA
G5: EMPRESA: | I5: ='Obra '!D2 -> MARTINS|FRANCEZ ENGENHARIA | O5: ='Obra '!D3 -> R00 | P5: 45551
A6: Unidade Construtiva | B6: Célula Construtiva | C6: Etapa | D6: Subetapa | E6: Serviço | G6: GERENCIAMENTO EXECUTIVO
A7: 0 | B7: 0 | C7: 0 | D7: 0 | E7: 0 | G7: Atalho | H7: NIVEL | I7: Item | J7: Descrição | K7: Unidade | L7: Quant. | M7: Preço un | N7: Total | O7: Considerações | P7: Situação
A8: =IF($H8="UNIDADE CONSTRUTIVA",OFFSET(A8,-1,0)+1,LARGE(A$3:A7,1)) -> 0 | B8: =IF(H8="UNIDADE CONSTRUTIVA",0,IF(H8="CÉLULA CONSTRUTIVA",OFFSET(B8,-1,0)+1,OFFSET(B8,-1,0))) -> 1 | C8: =IF(H8="CÉLULA CONSTRUTIVA",0,IF(H8="ETAPA",OFFSET(C8,-1,0)+1,OFFSET(C8,-1,0))) -> 0 | D8: =IF(H8="ETAPA",0,IF(H8="SUBETAPA",OFFSET(D8,-1,0)+1,OFFSET(D8,-1,0))) -> 0 | E8: =IF(H8="Subetapa",0,IF(H8="serviço",OFFSET(E8,-1,0)+1,OFFSET(E8,-1,0))) -> 0 | H8: CÉLULA CONSTRUTIVA | I8: =IF(H8="Unidade Construtiva",TEXT(A8,"00"),IF(H8="Célula Construtiva",TEXT(B8,"00"),IF(H8="Etapa",CONCATENATE(TEXT(B8,"00"),".",TEXT(C8,"000")),IF(H8="Subetapa",CONCATENATE(TEXT(B8,"00"),".",TEXT(C8,"000"),".",TEXT(D8,"000")),IF(H8="Serviço",CONCATENATE(TEXT(B8,"00"),".",TEXT(C8,"000"),".",TEXT(D8,"000"),".",TEXT(E8,"000")),""))))) -> 01 | J8: SERVIÇOS TÉCNICOS | N8: =IF(H8="Serviço",M8*L8,IF(H8="CÉLULA CONSTRUTIVA",SUMIFS($N$8:$N$368,$B$8:$B$368,B8,$H$8:$H$368,"Serviço"),IF(H8="ETAPA",SUMIFS($N$8:$N$368,$B$8:$B$368,B8,$C$8:$C$368,C8,$H$8:$H$368,"Serviço"),IF(H8="SUBETAPA",SUMIFS($N$8:$N$368,$B$8:$B$368,B8,$C$8:$C$368,C8,$D$8:$D$368,D8,$H$8:$H$368,"Serviço"),0)))) -> 103622.51 | Q8: =N8/'Obra '!$E$9 -> 314.4173
A9: =IF($H9="UNIDADE CONSTRUTIVA",OFFSET(A9,-1,0)+1,LARGE(A$3:A8,1)) -> 0 | B9: =IF(H9="UNIDADE CONSTRUTIVA",0,IF(H9="CÉLULA CONSTRUTIVA",OFFSET(B9,-1,0)+1,OFFSET(B9,-1,0))) -> 1 | C9: =IF(H9="CÉLULA CONSTRUTIVA",0,IF(H9="ETAPA",OFFSET(C9,-1,0)+1,OFFSET(C9,-1,0))) -> 1 | D9: =IF(H9="ETAPA",0,IF(H9="SUBETAPA",OFFSET(D9,-1,0)+1,OFFSET(D9,-1,0))) -> 0 | E9: =IF(H9="Subetapa",0,IF(H9="serviço",OFFSET(E9,-1,0)+1,OFFSET(E9,-1,0))) -> 0 | H9: ETAPA | I9: =IF(H9="Unidade Construtiva",TEXT(A9,"00"),IF(H9="Célula Construtiva",TEXT(B9,"00"),IF(H9="Etapa",CONCATENATE(TEXT(B9,"00"),".",TEXT(C9,"000")),IF(H9="Subetapa",CONCATENATE(TEXT(B9,"00"),".",TEXT(C9,"000"),".",TEXT(D9,"000")),IF(H9="Serviço",CONCATENATE(TEXT(B9,"00"),".",TEXT(C9,"000"),".",TEXT(D9,"000"),".",TEXT(E9,"000")),""))))) -> 01.001 | J9: ESTUDOS, PROJETOS E CONSULTORIAS | N9: =IF(H9="Serviço",M9*L9,IF(H9="CÉLULA CONSTRUTIVA",SUMIFS($N$8:$N$368,$B$8:$B$368,B9,$H$8:$H$368,"Serviço"),IF(H9="ETAPA",SUMIFS($N$8:$N$368,$B$8:$B$368,B9,$C$8:$C$368,C9,$H$8:$H$368,"Serviço"),IF(H9="SUBETAPA",SUMIFS($N$8:$N$368,$B$8:$B$368,B9,$C$8:$C$368,C9,$D$8:$D$368,D9,$H$8:$H$368,"Serviço"),0)))) -> 78606.076
A10: =IF($H10="UNIDADE CONSTRUTIVA",OFFSET(A10,-1,0)+1,LARGE(A$3:A9,1)) -> 0 | B10: =IF(H10="UNIDADE CONSTRUTIVA",0,IF(H10="CÉLULA CONSTRUTIVA",OFFSET(B10,-1,0)+1,OFFSET(B10,-1,0))) -> 1 | C10: =IF(H10="CÉLULA CONSTRUTIVA",0,IF(H10="ETAPA",OFFSET(C10,-1,0)+1,OFFSET(C10,-1,0))) -> 1 | D10: =IF(H10="ETAPA",0,IF(H10="SUBETAPA",OFFSET(D10,-1,0)+1,OFFSET(D10,-1,0))) -> 1 | E10: =IF(H10="Subetapa",0,IF(H10="serviço",OFFSET(E10,-1,0)+1,OFFSET(E10,-1,0))) -> 0 | H10: SUBETAPA | I10: =IF(H10="Unidade Construtiva",TEXT(A10,"00"),IF(H10="Célula Construtiva",TEXT(B10,"00"),IF(H10="Etapa",CONCATENATE(TEXT(B10,"00"),".",TEXT(C10,"000")),IF(H10="Subetapa",CONCATENATE(TEXT(B10,"00"),".",TEXT(C10,"000"),".",TEXT(D10,"000")),IF(H10="Serviço",CONCATENATE(TEXT(B10,"00"),".",TEXT(C10,"000"),".",TEXT(D10,"000"),".",TEXT(E10,"000")),""))))) -> 01.001.001 | J10: Estudos | N10: =IF(H10="Serviço",M10*L10,IF(H10="CÉLULA CONSTRUTIVA",SUMIFS($N$8:$N$368,$B$8:$B$368,B10,$H$8:$H$368,"Serviço"),IF(H10="ETAPA",SUMIFS($N$8:$N$368,$B$8:$B$368,B10,$C$8:$C$368,C10,$H$8:$H$368,"Serviço"),IF(H10="SUBETAPA",SUMIFS($N$8:$N$368,$B$8:$B$368,B10,$C$8:$C$368,C10,$D$8:$D$368,D10,$H$8:$H$368,"Serviço"),0)))) -> 8070.3784
A11: =IF($H11="UNIDADE CONSTRUTIVA",OFFSET(A11,-1,0)+1,LARGE(A$3:A10,1)) -> 0 | B11: =IF(H11="UNIDADE CONSTRUTIVA",0,IF(H11="CÉLULA CONSTRUTIVA",OFFSET(B11,-1,0)+1,OFFSET(B11,-1,0))) -> 1 | C11: =IF(H11="CÉLULA CONSTRUTIVA",0,IF(H11="ETAPA",OFFSET(C11,-1,0)+1,OFFSET(C11,-1,0))) -> 1 | D11: =IF(H11="ETAPA",0,IF(H11="SUBETAPA",OFFSET(D11,-1,0)+1,OFFSET(D11,-1,0))) -> 1 | E11: =IF(H11="Subetapa",0,IF(H11="serviço",OFFSET(E11,-1,0)+1,OFFSET(E11,-1,0))) -> 1 | H11: SERVIÇO | I11: =IF(H11="Unidade Construtiva",TEXT(A11,"00"),IF(H11="Célula Construtiva",TEXT(B11,"00"),IF(H11="Etapa",CONCATENATE(TEXT(B11,"00"),".",TEXT(C11,"000")),IF(H11="Subetapa",CONCATENATE(TEXT(B11,"00"),".",TEXT(C11,"000"),".",TEXT(D11,"000")),IF(H11="Serviço",CONCATENATE(TEXT(B11,"00"),".",TEXT(C11,"000"),".",TEXT(D11,"000"),".",TEXT(E11,"000")),""))))) -> 01.001.001.001 | J11: Levantamento Topográfico | K11: vb | L11: 1 | M11: 3769.3983 | N11: =IF(H11="Serviço",M11*L11,IF(H11="CÉLULA CONSTRUTIVA",SUMIFS($N$8:$N$368,$B$8:$B$368,B11,$H$8:$H$368,"Serviço"),IF(H11="ETAPA",SUMIFS($N$8:$N$368,$B$8:$B$368,B11,$C$8:$C$368,C11,$H$8:$H$368,"Serviço"),IF(H11="SUBETAPA",SUMIFS($N$8:$N$368,$B$8:$B$368,B11,$C$8:$C$368,C11,$D$8:$D$368,D11,$H$8:$H$368,"Serviço"),0)))) -> 3769.3983 | O11: Estimado com base em índices históricos | P11: Finalizado
A12: =IF($H12="UNIDADE CONSTRUTIVA",OFFSET(A12,-1,0)+1,LARGE(A$3:A11,1)) -> 0 | B12: =IF(H12="UNIDADE CONSTRUTIVA",0,IF(H12="CÉLULA CONSTRUTIVA",OFFSET(B12,-1,0)+1,OFFSET(B12,-1,0))) -> 1 | C12: =IF(H12="CÉLULA CONSTRUTIVA",0,IF(H12="ETAPA",OFFSET(C12,-1,0)+1,OFFSET(C12,-1,0))) -> 1 | D12: =IF(H12="ETAPA",0,IF(H12="SUBETAPA",OFFSET(D12,-1,0)+1,OFFSET(D12,-1,0))) -> 1 | E12: =IF(H12="Subetapa",0,IF(H12="serviço",OFFSET(E12,-1,0)+1,OFFSET(E12,-1,0))) -> 2 | H12: SERVIÇO | I12: =IF(H12="Unidade Construtiva",TEXT(A12,"00"),IF(H12="Célula Construtiva",TEXT(B12,"00"),IF(H12="Etapa",CONCATENATE(TEXT(B12,"00"),".",TEXT(C12,"000")),IF(H12="Subetapa",CONCATENATE(TEXT(B12,"00"),".",TEXT(C12,"000"),".",TEXT(D12,"000")),IF(H12="Serviço",CONCATENATE(TEXT(B12,"00"),".",TEXT(C12,"000"),".",TEXT(D12,"000"),".",TEXT(E12,"000")),""))))) -> 01.001.001.002 | J12: Sondagem do terreno | K12: vb | L12: 1 | M12: 4300.9801 | N12: =IF(H12="Serviço",M12*L12,IF(H12="CÉLULA CONSTRUTIVA",SUMIFS($N$8:$N$368,$B$8:$B$368,B12,$H$8:$H$368,"Serviço"),IF(H12="ETAPA",SUMIFS($N$8:$N$368,$B$8:$B$368,B12,$C$8:$C$368,C12,$H$8:$H$368,"Serviço"),IF(H12="SUBETAPA",SUMIFS($N$8:$N$368,$B$8:$B$368,B12,$C$8:$C$368,C12,$D$8:$D$368,D12,$H$8:$H$368,"Serviço"),0)))) -> 4300.9801 | O12: Estimado com base em índices históricos | P12: Finalizado
A13: =IF($H13="UNIDADE CONSTRUTIVA",OFFSET(A13,-1,0)+1,LARGE(A$3:A12,1)) -> 0 | B13: =IF(H13="UNIDADE CONSTRUTIVA",0,IF(H13="CÉLULA CONSTRUTIVA",OFFSET(B13,-1,0)+1,OFFSET(B13,-1,0))) -> 1 | C13: =IF(H13="CÉLULA CONSTRUTIVA",0,IF(H13="ETAPA",OFFSET(C13,-1,0)+1,OFFSET(C13,-1,0))) -> 1 | D13: =IF(H13="ETAPA",0,IF(H13="SUBETAPA",OFFSET(D13,-1,0)+1,OFFSET(D13,-1,0))) -> 2 | E13: =IF(H13="Subetapa",0,IF(H13="serviço",OFFSET(E13,-1,0)+1,OFFSET(E13,-1,0))) -> 0 | H13: SUBETAPA | I13: =IF(H13="Unidade Construtiva",TEXT(A13,"00"),IF(H13="Célula Construtiva",TEXT(B13,"00"),IF(H13="Etapa",CONCATENATE(TEXT(B13,"00"),".",TEXT(C13,"000")),IF(H13="Subetapa",CONCATENATE(TEXT(B13,"00"),".",TEXT(C13,"000"),".",TEXT(D13,"000")),IF(H13="Serviço",CONCATENATE(TEXT(B13,"00"),".",TEXT(C13,"000"),".",TEXT(D13,"000"),".",TEXT(E13,"000")),""))))) -> 01.001.002 | J13: Projetos | N13: =IF(H13="Serviço",M13*L13,IF(H13="CÉLULA CONSTRUTIVA",SUMIFS($N$8:$N$368,$B$8:$B$368,B13,$H$8:$H$368,"Serviço"),IF(H13="ETAPA",SUMIFS($N$8:$N$368,$B$8:$B$368,B13,$C$8:$C$368,C13,$H$8:$H$368,"Serviço"),IF(H13="SUBETAPA",SUMIFS($N$8:$N$368,$B$8:$B$368,B13,$C$8:$C$368,C13,$D$8:$D$368,D13,$H$8:$H$368,"Serviço"),0)))) -> 49545.697
A14: =IF($H14="UNIDADE CONSTRUTIVA",OFFSET(A14,-1,0)+1,LARGE(A$3:A13,1)) -> 0 | B14: =IF(H14="UNIDADE CONSTRUTIVA",0,IF(H14="CÉLULA CONSTRUTIVA",OFFSET(B14,-1,0)+1,OFFSET(B14,-1,0))) -> 1 | C14: =IF(H14="CÉLULA CONSTRUTIVA",0,IF(H14="ETAPA",OFFSET(C14,-1,0)+1,OFFSET(C14,-1,0))) -> 1 | D14: =IF(H14="ETAPA",0,IF(H14="SUBETAPA",OFFSET(D14,-1,0)+1,OFFSET(D14,-1,0))) -> 2 | E14: =IF(H14="Subetapa",0,IF(H14="serviço",OFFSET(E14,-1,0)+1,OFFSET(E14,-1,0))) -> 1 | H14: SERVIÇO | I14: =IF(H14="Unidade Construtiva",TEXT(A14,"00"),IF(H14="Célula Construtiva",TEXT(B14,"00"),IF(H14="Etapa",CONCATENATE(TEXT(B14,"00"),".",TEXT(C14,"000")),IF(H14="Subetapa",CONCATENATE(TEXT(B14,"00"),".",TEXT(C14,"000"),".",TEXT(D14,"000")),IF(H14="Serviço",CONCATENATE(TEXT(B14,"00"),".",TEXT(C14,"000"),".",TEXT(D14,"000"),".",TEXT(E14,"000")),""))))) -> 01.001.002.001 | J14: Projeto arquitetônico interiores/ambientação | K14: vb | L14: 1 | M14: 24522.284 | N14: =IF(H14="Serviço",M14*L14,IF(H14="CÉLULA CONSTRUTIVA",SUMIFS($N$8:$N$368,$B$8:$B$368,B14,$H$8:$H$368,"Serviço"),IF(H14="ETAPA",SUMIFS($N$8:$N$368,$B$8:$B$368,B14,$C$8:$C$368,C14,$H$8:$H$368,"Serviço"),IF(H14="SUBETAPA",SUMIFS($N$8:$N$368,$B$8:$B$368,B14,$C$8:$C$368,C14,$D$8:$D$368,D14,$H$8:$H$368,"Serviço"),0)))) -> 24522.284 | O14: Estimado com base em índices históricos | P14: Finalizado
A15: =IF($H15="UNIDADE CONSTRUTIVA",OFFSET(A15,-1,0)+1,LARGE(A$3:A14,1)) -> 0 | B15: =IF(H15="UNIDADE CONSTRUTIVA",0,IF(H15="CÉLULA CONSTRUTIVA",OFFSET(B15,-1,0)+1,OFFSET(B15,-1,0))) -> 1 | C15: =IF(H15="CÉLULA CONSTRUTIVA",0,IF(H15="ETAPA",OFFSET(C15,-1,0)+1,OFFSET(C15,-1,0))) -> 1 | D15: =IF(H15="ETAPA",0,IF(H15="SUBETAPA",OFFSET(D15,-1,0)+1,OFFSET(D15,-1,0))) -> 2 | E15: =IF(H15="Subetapa",0,IF(H15="serviço",OFFSET(E15,-1,0)+1,OFFSET(E15,-1,0))) -> 2 | H15: SERVIÇO | I15: =IF(H15="Unidade Construtiva",TEXT(A15,"00"),IF(H15="Célula Construtiva",TEXT(B15,"00"),IF(H15="Etapa",CONCATENATE(TEXT(B15,"00"),".",TEXT(C15,"000")),IF(H15="Subetapa",CONCATENATE(TEXT(B15,"00"),".",TEXT(C15,"000"),".",TEXT(D15,"000")),IF(H15="Serviço",CONCATENATE(TEXT(B15,"00"),".",TEXT(C15,"000"),".",TEXT(D15,"000"),".",TEXT(E15,"000")),""))))) -> 01.001.002.002 | J15: Projeto Estrutura | K15: vb | L15: 1 | M15: 8348.0116 | N15: =IF(H15="Serviço",M15*L15,IF(H15="CÉLULA CONSTRUTIVA",SUMIFS($N$8:$N$368,$B$8:$B$368,B15,$H$8:$H$368,"Serviço"),IF(H15="ETAPA",SUMIFS($N$8:$N$368,$B$8:$B$368,B15,$C$8:$C$368,C15,$H$8:$H$368,"Serviço"),IF(H15="SUBETAPA",SUMIFS($N$8:$N$368,$B$8:$B$368,B15,$C$8:$C$368,C15,$D$8:$D$368,D15,$H$8:$H$368,"Serviço"),0)))) -> 8348.0116 | O15: Estimado com base em índices históricos | P15: Finalizado
A16: =IF($H16="UNIDADE CONSTRUTIVA",OFFSET(A16,-1,0)+1,LARGE(A$3:A15,1)) -> 0 | B16: =IF(H16="UNIDADE CONSTRUTIVA",0,IF(H16="CÉLULA CONSTRUTIVA",OFFSET(B16,-1,0)+1,OFFSET(B16,-1,0))) -> 1 | C16: =IF(H16="CÉLULA CONSTRUTIVA",0,IF(H16="ETAPA",OFFSET(C16,-1,0)+1,OFFSET(C16,-1,0))) -> 1 | D16: =IF(H16="ETAPA",0,IF(H16="SUBETAPA",OFFSET(D16,-1,0)+1,OFFSET(D16,-1,0))) -> 2 | E16: =IF(H16="Subetapa",0,IF(H16="serviço",OFFSET(E16,-1,0)+1,OFFSET(E16,-1,0))) -> 3 | H16: SERVIÇO | I16: =IF(H16="Unidade Construtiva",TEXT(A16,"00"),IF(H16="Célula Construtiva",TEXT(B16,"00"),IF(H16="Etapa",CONCATENATE(TEXT(B16,"00"),".",TEXT(C16,"000")),IF(H16="Subetapa",CONCATENATE(TEXT(B16,"00"),".",TEXT(C16,"000"),".",TEXT(D16,"000")),IF(H16="Serviço",CONCATENATE(TEXT(B16,"00"),".",TEXT(C16,"000"),".",TEXT(D16,"000"),".",TEXT(E16,"000")),""))))) -> 01.001.002.003 | J16: Projeto Fundações | K16: vb | L16: 1 | M16: 2066.3815 | N16: =IF(H16="Serviço",M16*L16,IF(H16="CÉLULA CONSTRUTIVA",SUMIFS($N$8:$N$368,$B$8:$B$368,B16,$H$8:$H$368,"Serviço"),IF(H16="ETAPA",SUMIFS($N$8:$N$368,$B$8:$B$368,B16,$C$8:$C$368,C16,$H$8:$H$368,"Serviço"),IF(H16="SUBETAPA",SUMIFS($N$8:$N$368,$B$8:$B$368,B16,$C$8:$C$368,C16,$D$8:$D$368,D16,$H$8:$H$368,"Serviço"),0)))) -> 2066.3815 | O16: Estimado com base em índices históricos | P16: Finalizado
A17: =IF($H17="UNIDADE CONSTRUTIVA",OFFSET(A17,-1,0)+1,LARGE(A$3:A16,1)) -> 0 | B17: =IF(H17="UNIDADE CONSTRUTIVA",0,IF(H17="CÉLULA CONSTRUTIVA",OFFSET(B17,-1,0)+1,OFFSET(B17,-1,0))) -> 1 | C17: =IF(H17="CÉLULA CONSTRUTIVA",0,IF(H17="ETAPA",OFFSET(C17,-1,0)+1,OFFSET(C17,-1,0))) -> 1 | D17: =IF(H17="ETAPA",0,IF(H17="SUBETAPA",OFFSET(D17,-1,0)+1,OFFSET(D17,-1,0))) -> 2 | E17: =IF(H17="Subetapa",0,IF(H17="serviço",OFFSET(E17,-1,0)+1,OFFSET(E17,-1,0))) -> 4 | H17: SERVIÇO | I17: =IF(H17="Unidade Construtiva",TEXT(A17,"00"),IF(H17="Célula Construtiva",TEXT(B17,"00"),IF(H17="Etapa",CONCATENATE(TEXT(B17,"00"),".",TEXT(C17,"000")),IF(H17="Subetapa",CONCATENATE(TEXT(B17,"00"),".",TEXT(C17,"000"),".",TEXT(D17,"000")),IF(H17="Serviço",CONCATENATE(TEXT(B17,"00"),".",TEXT(C17,"000"),".",TEXT(D17,"000"),".",TEXT(E17,"000")),""))))) -> 01.001.002.004 | J17: Projeto elétrico | K17: vb | L17: 1 | M17: 7304.5102 | N17: =IF(H17="Serviço",M17*L17,IF(H17="CÉLULA CONSTRUTIVA",SUMIFS($N$8:$N$368,$B$8:$B$368,B17,$H$8:$H$368,"Serviço"),IF(H17="ETAPA",SUMIFS($N$8:$N$368,$B$8:$B$368,B17,$C$8:$C$368,C17,$H$8:$H$368,"Serviço"),IF(H17="SUBETAPA",SUMIFS($N$8:$N$368,$B$8:$B$368,B17,$C$8:$C$368,C17,$D$8:$D$368,D17,$H$8:$H$368,"Serviço"),0)))) -> 7304.5102 | O17: Estimado com base em índices históricos | P17: Finalizado
A18: =IF($H18="UNIDADE CONSTRUTIVA",OFFSET(A18,-1,0)+1,LARGE(A$3:A17,1)) -> 0 | B18: =IF(H18="UNIDADE CONSTRUTIVA",0,IF(H18="CÉLULA CONSTRUTIVA",OFFSET(B18,-1,0)+1,OFFSET(B18,-1,0))) -> 1 | C18: =IF(H18="CÉLULA CONSTRUTIVA",0,IF(H18="ETAPA",OFFSET(C18,-1,0)+1,OFFSET(C18,-1,0))) -> 1 | D18: =IF(H18="ETAPA",0,IF(H18="SUBETAPA",OFFSET(D18,-1,0)+1,OFFSET(D18,-1,0))) -> 2 | E18: =IF(H18="Subetapa",0,IF(H18="serviço",OFFSET(E18,-1,0)+1,OFFSET(E18,-1,0))) -> 5 | H18: SERVIÇO | I18: =IF(H18="Unidade Construtiva",TEXT(A18,"00"),IF(H18="Célula Construtiva",TEXT(B18,"00"),IF(H18="Etapa",CONCATENATE(TEXT(B18,"00"),".",TEXT(C18,"000")),IF(H18="Subetapa",CONCATENATE(TEXT(B18,"00"),".",TEXT(C18,"000"),".",TEXT(D18,"000")),IF(H18="Serviço",CONCATENATE(TEXT(B18,"00"),".",TEXT(C18,"000"),".",TEXT(D18,"000"),".",TEXT(E18,"000")),""))))) -> 01.001.002.005 | J18: Projeto hidrossanitário | K18: vb | L18: 1 | M18: 7304.5102 | N18: =IF(H18="Serviço",M18*L18,IF(H18="CÉLULA CONSTRUTIVA",SUMIFS($N$8:$N$368,$B$8:$B$368,B18,$H$8:$H$368,"Serviço"),IF(H18="ETAPA",SUMIFS($N$8:$N$368,$B$8:$B$368,B18,$C$8:$C$368,C18,$H$8:$H$368,"Serviço"),IF(H18="SUBETAPA",SUMIFS($N$8:$N$368,$B$8:$B$368,B18,$C$8:$C$368,C18,$D$8:$D$368,D18,$H$8:$H$368,"Serviço"),0)))) -> 7304.5102 | O18: Estimado com base em índices históricos | P18: Finalizado
A19: =IF($H19="UNIDADE CONSTRUTIVA",OFFSET(A19,-1,0)+1,LARGE(A$3:A17,1)) -> 0 | B19: =IF(H19="UNIDADE CONSTRUTIVA",0,IF(H19="CÉLULA CONSTRUTIVA",OFFSET(B19,-1,0)+1,OFFSET(B19,-1,0))) -> 1 | C19: =IF(H19="CÉLULA CONSTRUTIVA",0,IF(H19="ETAPA",OFFSET(C19,-1,0)+1,OFFSET(C19,-1,0))) -> 1 | D19: =IF(H19="ETAPA",0,IF(H19="SUBETAPA",OFFSET(D19,-1,0)+1,OFFSET(D19,-1,0))) -> 3 | E19: =IF(H19="Subetapa",0,IF(H19="serviço",OFFSET(E19,-1,0)+1,OFFSET(E19,-1,0))) -> 0 | H19: SUBETAPA | I19: =IF(H19="Unidade Construtiva",TEXT(A19,"00"),IF(H19="Célula Construtiva",TEXT(B19,"00"),IF(H19="Etapa",CONCATENATE(TEXT(B19,"00"),".",TEXT(C19,"000")),IF(H19="Subetapa",CONCATENATE(TEXT(B19,"00"),".",TEXT(C19,"000"),".",TEXT(D19,"000")),IF(H19="Serviço",CONCATENATE(TEXT(B19,"00"),".",TEXT(C19,"000"),".",TEXT(D19,"000"),".",TEXT(E19,"000")),""))))) -> 01.001.003 | J19: Consultorias | N19: =IF(H19="Serviço",M19*L19,IF(H19="CÉLULA CONSTRUTIVA",SUMIFS($N$8:$N$368,$B$8:$B$368,B19,$H$8:$H$368,"Serviço"),IF(H19="ETAPA",SUMIFS($N$8:$N$368,$B$8:$B$368,B19,$C$8:$C$368,C19,$H$8:$H$368,"Serviço"),IF(H19="SUBETAPA",SUMIFS($N$8:$N$368,$B$8:$B$368,B19,$C$8:$C$368,C19,$D$8:$D$368,D19,$H$8:$H$368,"Serviço"),0)))) -> 17500
A20: =IF($H20="UNIDADE CONSTRUTIVA",OFFSET(A20,-1,0)+1,LARGE(A$3:A19,1)) -> 0 | B20: =IF(H20="UNIDADE CONSTRUTIVA",0,IF(H20="CÉLULA CONSTRUTIVA",OFFSET(B20,-1,0)+1,OFFSET(B20,-1,0))) -> 1 | C20: =IF(H20="CÉLULA CONSTRUTIVA",0,IF(H20="ETAPA",OFFSET(C20,-1,0)+1,OFFSET(C20,-1,0))) -> 1 | D20: =IF(H20="ETAPA",0,IF(H20="SUBETAPA",OFFSET(D20,-1,0)+1,OFFSET(D20,-1,0))) -> 3 | E20: =IF(H20="Subetapa",0,IF(H20="serviço",OFFSET(E20,-1,0)+1,OFFSET(E20,-1,0))) -> 1 | H20: SERVIÇO | I20: =IF(H20="Unidade Construtiva",TEXT(A20,"00"),IF(H20="Célula Construtiva",TEXT(B20,"00"),IF(H20="Etapa",CONCATENATE(TEXT(B20,"00"),".",TEXT(C20,"000")),IF(H20="Subetapa",CONCATENATE(TEXT(B20,"00"),".",TEXT(C20,"000"),".",TEXT(D20,"000")),IF(H20="Serviço",CONCATENATE(TEXT(B20,"00"),".",TEXT(C20,"000"),".",TEXT(D20,"000"),".",TEXT(E20,"000")),""))))) -> 01.001.003.001 | J20: Modelagem BIM arquitetônica | K20: vb | L20: 1 | M20: 3638.39 | N20: =IF(H20="Serviço",M20*L20,IF(H20="CÉLULA CONSTRUTIVA",SUMIFS($N$8:$N$368,$B$8:$B$368,B20,$H$8:$H$368,"Serviço"),IF(H20="ETAPA",SUMIFS($N$8:$N$368,$B$8:$B$368,B20,$C$8:$C$368,C20,$H$8:$H$368,"Serviço"),IF(H20="SUBETAPA",SUMIFS($N$8:$N$368,$B$8:$B$368,B20,$C$8:$C$368,C20,$D$8:$D$368,D20,$H$8:$H$368,"Serviço"),0)))) -> 3638.39 | O20: Contrato Cartesian | P20: Finalizado
A21: =IF($H21="UNIDADE CONSTRUTIVA",OFFSET(A21,-1,0)+1,LARGE(A$3:A20,1)) -> 0 | B21: =IF(H21="UNIDADE CONSTRUTIVA",0,IF(H21="CÉLULA CONSTRUTIVA",OFFSET(B21,-1,0)+1,OFFSET(B21,-1,0))) -> 1 | C21: =IF(H21="CÉLULA CONSTRUTIVA",0,IF(H21="ETAPA",OFFSET(C21,-1,0)+1,OFFSET(C21,-1,0))) -> 1 | D21: =IF(H21="ETAPA",0,IF(H21="SUBETAPA",OFFSET(D21,-1,0)+1,OFFSET(D21,-1,0))) -> 3 | E21: =IF(H21="Subetapa",0,IF(H21="serviço",OFFSET(E21,-1,0)+1,OFFSET(E21,-1,0))) -> 2 | H21: SERVIÇO | I21: =IF(H21="Unidade Construtiva",TEXT(A21,"00"),IF(H21="Célula Construtiva",TEXT(B21,"00"),IF(H21="Etapa",CONCATENATE(TEXT(B21,"00"),".",TEXT(C21,"000")),IF(H21="Subetapa",CONCATENATE(TEXT(B21,"00"),".",TEXT(C21,"000"),".",TEXT(D21,"000")),IF(H21="Serviço",CONCATENATE(TEXT(B21,"00"),".",TEXT(C21,"000"),".",TEXT(D21,"000"),".",TEXT(E21,"000")),""))))) -> 01.001.003.002 | J21: Orçamento e planejamento | K21: vb | L21: 1 | M21: =8083.27+4032.46+1745.88 -> 13861.61 | N21: =IF(H21="Serviço",M21*L21,IF(H21="CÉLULA CONSTRUTIVA",SUMIFS($N$8:$N$368,$B$8:$B$368,B21,$H$8:$H$368,"Serviço"),IF(H21="ETAPA",SUMIFS($N$8:$N$368,$B$8:$B$368,B21,$C$8:$C$368,C21,$H$8:$H$368,"Serviço"),IF(H21="SUBETAPA",SUMIFS($N$8:$N$368,$B$8:$B$368,B21,$C$8:$C$368,C21,$D$8:$D$368,D21,$H$8:$H$368,"Serviço"),0)))) -> 13861.61 | O21: Contrato Cartesian | P21: Finalizado
A22: =IF($H22="UNIDADE CONSTRUTIVA",OFFSET(A22,-1,0)+1,LARGE(A$3:A21,1)) -> 0 | B22: =IF(H22="UNIDADE CONSTRUTIVA",0,IF(H22="CÉLULA CONSTRUTIVA",OFFSET(B22,-1,0)+1,OFFSET(B22,-1,0))) -> 1 | C22: =IF(H22="CÉLULA CONSTRUTIVA",0,IF(H22="ETAPA",OFFSET(C22,-1,0)+1,OFFSET(C22,-1,0))) -> 1 | D22: =IF(H22="ETAPA",0,IF(H22="SUBETAPA",OFFSET(D22,-1,0)+1,OFFSET(D22,-1,0))) -> 4 | E22: =IF(H22="Subetapa",0,IF(H22="serviço",OFFSET(E22,-1,0)+1,OFFSET(E22,-1,0))) -> 0 | H22: SUBETAPA | I22: =IF(H22="Unidade Construtiva",TEXT(A22,"00"),IF(H22="Célula Construtiva",TEXT(B22,"00"),IF(H22="Etapa",CONCATENATE(TEXT(B22,"00"),".",TEXT(C22,"000")),IF(H22="Subetapa",CONCATENATE(TEXT(B22,"00"),".",TEXT(C22,"000"),".",TEXT(D22,"000")),IF(H22="Serviço",CONCATENATE(TEXT(B22,"00"),".",TEXT(C22,"000"),".",TEXT(D22,"000"),".",TEXT(E22,"000")),""))))) -> 01.001.004 | J22: Ensaios | N22: =IF(H22="Serviço",M22*L22,IF(H22="CÉLULA CONSTRUTIVA",SUMIFS($N$8:$N$368,$B$8:$B$368,B22,$H$8:$H$368,"Serviço"),IF(H22="ETAPA",SUMIFS($N$8:$N$368,$B$8:$B$368,B22,$C$8:$C$368,C22,$H$8:$H$368,"Serviço"),IF(H22="SUBETAPA",SUMIFS($N$8:$N$368,$B$8:$B$368,B22,$C$8:$C$368,C22,$D$8:$D$368,D22,$H$8:$H$368,"Serviço"),0)))) -> 3490
A23: =IF($H23="UNIDADE CONSTRUTIVA",OFFSET(A23,-1,0)+1,LARGE(A$3:A22,1)) -> 0 | B23: =IF(H23="UNIDADE CONSTRUTIVA",0,IF(H23="CÉLULA CONSTRUTIVA",OFFSET(B23,-1,0)+1,OFFSET(B23,-1,0))) -> 1 | C23: =IF(H23="CÉLULA CONSTRUTIVA",0,IF(H23="ETAPA",OFFSET(C23,-1,0)+1,OFFSET(C23,-1,0))) -> 1 | D23: =IF(H23="ETAPA",0,IF(H23="SUBETAPA",OFFSET(D23,-1,0)+1,OFFSET(D23,-1,0))) -> 4 | E23: =IF(H23="Subetapa",0,IF(H23="serviço",OFFSET(E23,-1,0)+1,OFFSET(E23,-1,0))) -> 1 | H23: SERVIÇO | I23: =IF(H23="Unidade Construtiva",TEXT(A23,"00"),IF(H23="Célula Construtiva",TEXT(B23,"00"),IF(H23="Etapa",CONCATENATE(TEXT(B23,"00"),".",TEXT(C23,"000")),IF(H23="Subetapa",CONCATENATE(TEXT(B23,"00"),".",TEXT(C23,"000"),".",TEXT(D23,"000")),IF(H23="Serviço",CONCATENATE(TEXT(B23,"00"),".",TEXT(C23,"000"),".",TEXT(D23,"000"),".",TEXT(E23,"000")),""))))) -> 01.001.004.001 | J23: Controle Tecnologico de Concreto | K23: vb | L23: 1 | M23: ='Ensaios '!F12 -> 3490 | N23: =IF(H23="Serviço",M23*L23,IF(H23="CÉLULA CONSTRUTIVA",SUMIFS($N$8:$N$368,$B$8:$B$368,B23,$H$8:$H$368,"Serviço"),IF(H23="ETAPA",SUMIFS($N$8:$N$368,$B$8:$B$368,B23,$C$8:$C$368,C23,$H$8:$H$368,"Serviço"),IF(H23="SUBETAPA",SUMIFS($N$8:$N$368,$B$8:$B$368,B23,$C$8:$C$368,C23,$D$8:$D$368,D23,$H$8:$H$368,"Serviço"),0)))) -> 3490 | O23: Cnoforme aba auxiliar | P23: Finalizado
A24: =IF($H24="UNIDADE CONSTRUTIVA",OFFSET(A24,-1,0)+1,LARGE(A$3:A23,1)) -> 0 | B24: =IF(H24="UNIDADE CONSTRUTIVA",0,IF(H24="CÉLULA CONSTRUTIVA",OFFSET(B24,-1,0)+1,OFFSET(B24,-1,0))) -> 1 | C24: =IF(H24="CÉLULA CONSTRUTIVA",0,IF(H24="ETAPA",OFFSET(C24,-1,0)+1,OFFSET(C24,-1,0))) -> 2 | D24: =IF(H24="ETAPA",0,IF(H24="SUBETAPA",OFFSET(D24,-1,0)+1,OFFSET(D24,-1,0))) -> 0 | E24: =IF(H24="Subetapa",0,IF(H24="serviço",OFFSET(E24,-1,0)+1,OFFSET(E24,-1,0))) -> 1 | H24: ETAPA | I24: =IF(H24="Unidade Construtiva",TEXT(A24,"00"),IF(H24="Célula Construtiva",TEXT(B24,"00"),IF(H24="Etapa",CONCATENATE(TEXT(B24,"00"),".",TEXT(C24,"000")),IF(H24="Subetapa",CONCATENATE(TEXT(B24,"00"),".",TEXT(C24,"000"),".",TEXT(D24,"000")),IF(H24="Serviço",CONCATENATE(TEXT(B24,"00"),".",TEXT(C24,"000"),".",TEXT(D24,"000"),".",TEXT(E24,"000")),""))))) -> 01.002 | J24: TAXAS E DOCUMENTOS | N24: =IF(H24="Serviço",M24*L24,IF(H24="CÉLULA CONSTRUTIVA",SUMIFS($N$8:$N$368,$B$8:$B$368,B24,$H$8:$H$368,"Serviço"),IF(H24="ETAPA",SUMIFS($N$8:$N$368,$B$8:$B$368,B24,$C$8:$C$368,C24,$H$8:$H$368,"Serviço"),IF(H24="SUBETAPA",SUMIFS($N$8:$N$368,$B$8:$B$368,B24,$C$8:$C$368,C24,$D$8:$D$368,D24,$H$8:$H$368,"Serviço"),0)))) -> 25016.432 | P24: -
A25: =IF($H25="UNIDADE CONSTRUTIVA",OFFSET(A25,-1,0)+1,LARGE(A$3:A24,1)) -> 0 | B25: =IF(H25="UNIDADE CONSTRUTIVA",0,IF(H25="CÉLULA CONSTRUTIVA",OFFSET(B25,-1,0)+1,OFFSET(B25,-1,0))) -> 1 | C25: =IF(H25="CÉLULA CONSTRUTIVA",0,IF(H25="ETAPA",OFFSET(C25,-1,0)+1,OFFSET(C25,-1,0))) -> 2 | D25: =IF(H25="ETAPA",0,IF(H25="SUBETAPA",OFFSET(D25,-1,0)+1,OFFSET(D25,-1,0))) -> 1 | E25: =IF(H25="Subetapa",0,IF(H25="serviço",OFFSET(E25,-1,0)+1,OFFSET(E25,-1,0))) -> 0 | H25: SUBETAPA | I25: =IF(H25="Unidade Construtiva",TEXT(A25,"00"),IF(H25="Célula Construtiva",TEXT(B25,"00"),IF(H25="Etapa",CONCATENATE(TEXT(B25,"00"),".",TEXT(C25,"000")),IF(H25="Subetapa",CONCATENATE(TEXT(B25,"00"),".",TEXT(C25,"000"),".",TEXT(D25,"000")),IF(H25="Serviço",CONCATENATE(TEXT(B25,"00"),".",TEXT(C25,"000"),".",TEXT(D25,"000"),".",TEXT(E25,"000")),""))))) -> 01.002.001 | J25: Licenciamentos, Taxas, Impostos, Aprovações e Seguros | N25: =IF(H25="Serviço",M25*L25,IF(H25="CÉLULA CONSTRUTIVA",SUMIFS($N$8:$N$368,$B$8:$B$368,B25,$H$8:$H$368,"Serviço"),IF(H25="ETAPA",SUMIFS($N$8:$N$368,$B$8:$B$368,B25,$C$8:$C$368,C25,$H$8:$H$368,"Serviço"),IF(H25="SUBETAPA",SUMIFS($N$8:$N$368,$B$8:$B$368,B25,$C$8:$C$368,C25,$D$8:$D$368,D25,$H$8:$H$368,"Serviço"),0)))) -> 6545.3003
A26: =IF($H26="UNIDADE CONSTRUTIVA",OFFSET(A26,-1,0)+1,LARGE(A$3:A25,1)) -> 0 | B26: =IF(H26="UNIDADE CONSTRUTIVA",0,IF(H26="CÉLULA CONSTRUTIVA",OFFSET(B26,-1,0)+1,OFFSET(B26,-1,0))) -> 1 | C26: =IF(H26="CÉLULA CONSTRUTIVA",0,IF(H26="ETAPA",OFFSET(C26,-1,0)+1,OFFSET(C26,-1,0))) -> 2 | D26: =IF(H26="ETAPA",0,IF(H26="SUBETAPA",OFFSET(D26,-1,0)+1,OFFSET(D26,-1,0))) -> 1 | E26: =IF(H26="Subetapa",0,IF(H26="serviço",OFFSET(E26,-1,0)+1,OFFSET(E26,-1,0))) -> 1 | H26: SERVIÇO | I26: =IF(H26="Unidade Construtiva",TEXT(A26,"00"),IF(H26="Célula Construtiva",TEXT(B26,"00"),IF(H26="Etapa",CONCATENATE(TEXT(B26,"00"),".",TEXT(C26,"000")),IF(H26="Subetapa",CONCATENATE(TEXT(B26,"00"),".",TEXT(C26,"000"),".",TEXT(D26,"000")),IF(H26="Serviço",CONCATENATE(TEXT(B26,"00"),".",TEXT(C26,"000"),".",TEXT(D26,"000"),".",TEXT(E26,"000")),""))))) -> 01.002.001.001 | J26: Despesas de Seguros | K26: vb | L26: 1 | M26: 1200 | N26: =IF(H26="Serviço",M26*L26,IF(H26="CÉLULA CONSTRUTIVA",SUMIFS($N$8:$N$368,$B$8:$B$368,B26,$H$8:$H$368,"Serviço"),IF(H26="ETAPA",SUMIFS($N$8:$N$368,$B$8:$B$368,B26,$C$8:$C$368,C26,$H$8:$H$368,"Serviço"),IF(H26="SUBETAPA",SUMIFS($N$8:$N$368,$B$8:$B$368,B26,$C$8:$C$368,C26,$D$8:$D$368,D26,$H$8:$H$368,"Serviço"),0)))) -> 1200 | O26: Estimado com base em índices históricos | P26: Finalizado
A27: =IF($H27="UNIDADE CONSTRUTIVA",OFFSET(A27,-1,0)+1,LARGE(A$3:A26,1)) -> 0 | B27: =IF(H27="UNIDADE CONSTRUTIVA",0,IF(H27="CÉLULA CONSTRUTIVA",OFFSET(B27,-1,0)+1,OFFSET(B27,-1,0))) -> 1 | C27: =IF(H27="CÉLULA CONSTRUTIVA",0,IF(H27="ETAPA",OFFSET(C27,-1,0)+1,OFFSET(C27,-1,0))) -> 2 | D27: =IF(H27="ETAPA",0,IF(H27="SUBETAPA",OFFSET(D27,-1,0)+1,OFFSET(D27,-1,0))) -> 1 | E27: =IF(H27="Subetapa",0,IF(H27="serviço",OFFSET(E27,-1,0)+1,OFFSET(E27,-1,0))) -> 2 | H27: SERVIÇO | I27: =IF(H27="Unidade Construtiva",TEXT(A27,"00"),IF(H27="Célula Construtiva",TEXT(B27,"00"),IF(H27="Etapa",CONCATENATE(TEXT(B27,"00"),".",TEXT(C27,"000")),IF(H27="Subetapa",CONCATENATE(TEXT(B27,"00"),".",TEXT(C27,"000"),".",TEXT(D27,"000")),IF(H27="Serviço",CONCATENATE(TEXT(B27,"00"),".",TEXT(C27,"000"),".",TEXT(D27,"000"),".",TEXT(E27,"000")),""))))) -> 01.002.001.002 | J27: Taxas de ART | K27: vb | L27: 1 | M27: 1000 | N27: =IF(H27="Serviço",M27*L27,IF(H27="CÉLULA CONSTRUTIVA",SUMIFS($N$8:$N$368,$B$8:$B$368,B27,$H$8:$H$368,"Serviço"),IF(H27="ETAPA",SUMIFS($N$8:$N$368,$B$8:$B$368,B27,$C$8:$C$368,C27,$H$8:$H$368,"Serviço"),IF(H27="SUBETAPA",SUMIFS($N$8:$N$368,$B$8:$B$368,B27,$C$8:$C$368,C27,$D$8:$D$368,D27,$H$8:$H$368,"Serviço"),0)))) -> 1000 | O27: Estimado com base em índices históricos | P27: Finalizado
A28: =IF($H28="UNIDADE CONSTRUTIVA",OFFSET(A28,-1,0)+1,LARGE(A$3:A27,1)) -> 0 | B28: =IF(H28="UNIDADE CONSTRUTIVA",0,IF(H28="CÉLULA CONSTRUTIVA",OFFSET(B28,-1,0)+1,OFFSET(B28,-1,0))) -> 1 | C28: =IF(H28="CÉLULA CONSTRUTIVA",0,IF(H28="ETAPA",OFFSET(C28,-1,0)+1,OFFSET(C28,-1,0))) -> 2 | D28: =IF(H28="ETAPA",0,IF(H28="SUBETAPA",OFFSET(D28,-1,0)+1,OFFSET(D28,-1,0))) -> 1 | E28: =IF(H28="Subetapa",0,IF(H28="serviço",OFFSET(E28,-1,0)+1,OFFSET(E28,-1,0))) -> 3 | H28: SERVIÇO | I28: =IF(H28="Unidade Construtiva",TEXT(A28,"00"),IF(H28="Célula Construtiva",TEXT(B28,"00"),IF(H28="Etapa",CONCATENATE(TEXT(B28,"00"),".",TEXT(C28,"000")),IF(H28="Subetapa",CONCATENATE(TEXT(B28,"00"),".",TEXT(C28,"000"),".",TEXT(D28,"000")),IF(H28="Serviço",CONCATENATE(TEXT(B28,"00"),".",TEXT(C28,"000"),".",TEXT(D28,"000"),".",TEXT(E28,"000")),""))))) -> 01.002.001.003 | J28: Alvará Construção | K28: vb | L28: 1 | M28: 1080.1762 | N28: =IF(H28="Serviço",M28*L28,IF(H28="CÉLULA CONSTRUTIVA",SUMIFS($N$8:$N$368,$B$8:$B$368,B28,$H$8:$H$368,"Serviço"),IF(H28="ETAPA",SUMIFS($N$8:$N$368,$B$8:$B$368,B28,$C$8:$C$368,C28,$H$8:$H$368,"Serviço"),IF(H28="SUBETAPA",SUMIFS($N$8:$N$368,$B$8:$B$368,B28,$C$8:$C$368,C28,$D$8:$D$368,D28,$H$8:$H$368,"Serviço"),0)))) -> 1080.1762 | O28: Estimado com base em índices históricos | P28: Finalizado
A29: =IF($H29="UNIDADE CONSTRUTIVA",OFFSET(A29,-1,0)+1,LARGE(A$3:A28,1)) -> 0 | B29: =IF(H29="UNIDADE CONSTRUTIVA",0,IF(H29="CÉLULA CONSTRUTIVA",OFFSET(B29,-1,0)+1,OFFSET(B29,-1,0))) -> 1 | C29: =IF(H29="CÉLULA CONSTRUTIVA",0,IF(H29="ETAPA",OFFSET(C29,-1,0)+1,OFFSET(C29,-1,0))) -> 2 | D29: =IF(H29="ETAPA",0,IF(H29="SUBETAPA",OFFSET(D29,-1,0)+1,OFFSET(D29,-1,0))) -> 1 | E29: =IF(H29="Subetapa",0,IF(H29="serviço",OFFSET(E29,-1,0)+1,OFFSET(E29,-1,0))) -> 4 | H29: SERVIÇO | I29: =IF(H29="Unidade Construtiva",TEXT(A29,"00"),IF(H29="Célula Construtiva",TEXT(B29,"00"),IF(H29="Etapa",CONCATENATE(TEXT(B29,"00"),".",TEXT(C29,"000")),IF(H29="Subetapa",CONCATENATE(TEXT(B29,"00"),".",TEXT(C29,"000"),".",TEXT(D29,"000")),IF(H29="Serviço",CONCATENATE(TEXT(B29,"00"),".",TEXT(C29,"000"),".",TEXT(D29,"000"),".",TEXT(E29,"000")),""))))) -> 01.002.001.004 | J29: Despesas cartório, licenças, certidões e jurídicas | K29: vb | L29: 1 | M29: 1857.0059 | N29: =IF(H29="Serviço",M29*L29,IF(H29="CÉLULA CONSTRUTIVA",SUMIFS($N$8:$N$368,$B$8:$B$368,B29,$H$8:$H$368,"Serviço"),IF(H29="ETAPA",SUMIFS($N$8:$N$368,$B$8:$B$368,B29,$C$8:$C$368,C29,$H$8:$H$368,"Serviço"),IF(H29="SUBETAPA",SUMIFS($N$8:$N$368,$B$8:$B$368,B29,$C$8:$C$368,C29,$D$8:$D$368,D29,$H$8:$H$368,"Serviço"),0)))) -> 1857.0059 | O29: Estimado com base em índices históricos | P29: Finalizado
A30: =IF($H30="UNIDADE CONSTRUTIVA",OFFSET(A30,-1,0)+1,LARGE(A$3:A29,1)) -> 0 | B30: =IF(H30="UNIDADE CONSTRUTIVA",0,IF(H30="CÉLULA CONSTRUTIVA",OFFSET(B30,-1,0)+1,OFFSET(B30,-1,0))) -> 1 | C30: =IF(H30="CÉLULA CONSTRUTIVA",0,IF(H30="ETAPA",OFFSET(C30,-1,0)+1,OFFSET(C30,-1,0))) -> 2 | D30: =IF(H30="ETAPA",0,IF(H30="SUBETAPA",OFFSET(D30,-1,0)+1,OFFSET(D30,-1,0))) -> 1 | E30: =IF(H30="Subetapa",0,IF(H30="serviço",OFFSET(E30,-1,0)+1,OFFSET(E30,-1,0))) -> 5 | H30: SERVIÇO | I30: =IF(H30="Unidade Construtiva",TEXT(A30,"00"),IF(H30="Célula Construtiva",TEXT(B30,"00"),IF(H30="Etapa",CONCATENATE(TEXT(B30,"00"),".",TEXT(C30,"000")),IF(H30="Subetapa",CONCATENATE(TEXT(B30,"00"),".",TEXT(C30,"000"),".",TEXT(D30,"000")),IF(H30="Serviço",CONCATENATE(TEXT(B30,"00"),".",TEXT(C30,"000"),".",TEXT(D30,"000"),".",TEXT(E30,"000")),""))))) -> 01.002.001.005 | J30: Iptu | K30: vb | L30: 1 | M30: 390 | N30: =IF(H30="Serviço",M30*L30,IF(H30="CÉLULA CONSTRUTIVA",SUMIFS($N$8:$N$368,$B$8:$B$368,B30,$H$8:$H$368,"Serviço"),IF(H30="ETAPA",SUMIFS($N$8:$N$368,$B$8:$B$368,B30,$C$8:$C$368,C30,$H$8:$H$368,"Serviço"),IF(H30="SUBETAPA",SUMIFS($N$8:$N$368,$B$8:$B$368,B30,$C$8:$C$368,C30,$D$8:$D$368,D30,$H$8:$H$368,"Serviço"),0)))) -> 390 | O30: Estimado com base em índices históricos | P30: Finalizado
A31: =IF($H31="UNIDADE CONSTRUTIVA",OFFSET(A31,-1,0)+1,LARGE(A$3:A30,1)) -> 0 | B31: =IF(H31="UNIDADE CONSTRUTIVA",0,IF(H31="CÉLULA CONSTRUTIVA",OFFSET(B31,-1,0)+1,OFFSET(B31,-1,0))) -> 1 | C31: =IF(H31="CÉLULA CONSTRUTIVA",0,IF(H31="ETAPA",OFFSET(C31,-1,0)+1,OFFSET(C31,-1,0))) -> 2 | D31: =IF(H31="ETAPA",0,IF(H31="SUBETAPA",OFFSET(D31,-1,0)+1,OFFSET(D31,-1,0))) -> 1 | E31: =IF(H31="Subetapa",0,IF(H31="serviço",OFFSET(E31,-1,0)+1,OFFSET(E31,-1,0))) -> 6 | H31: SERVIÇO | I31: =IF(H31="Unidade Construtiva",TEXT(A31,"00"),IF(H31="Célula Construtiva",TEXT(B31,"00"),IF(H31="Etapa",CONCATENATE(TEXT(B31,"00"),".",TEXT(C31,"000")),IF(H31="Subetapa",CONCATENATE(TEXT(B31,"00"),".",TEXT(C31,"000"),".",TEXT(D31,"000")),IF(H31="Serviço",CONCATENATE(TEXT(B31,"00"),".",TEXT(C31,"000"),".",TEXT(D31,"000"),".",TEXT(E31,"000")),""))))) -> 01.002.001.006 | J31: Alvará Habite-se | K31: vb | L31: 1 | M31: 1018.1182 | N31: =IF(H31="Serviço",M31*L31,IF(H31="CÉLULA CONSTRUTIVA",SUMIFS($N$8:$N$368,$B$8:$B$368,B31,$H$8:$H$368,"Serviço"),IF(H31="ETAPA",SUMIFS($N$8:$N$368,$B$8:$B$368,B31,$C$8:$C$368,C31,$H$8:$H$368,"Serviço"),IF(H31="SUBETAPA",SUMIFS($N$8:$N$368,$B$8:$B$368,B31,$C$8:$C$368,C31,$D$8:$D$368,D31,$H$8:$H$368,"Serviço"),0)))) -> 1018.1182 | O31: Estimado com base em índices históricos | P31: Finalizado
A32: =IF($H32="UNIDADE CONSTRUTIVA",OFFSET(A32,-1,0)+1,LARGE(A$3:A31,1)) -> 0 | B32: =IF(H32="UNIDADE CONSTRUTIVA",0,IF(H32="CÉLULA CONSTRUTIVA",OFFSET(B32,-1,0)+1,OFFSET(B32,-1,0))) -> 1 | C32: =IF(H32="CÉLULA CONSTRUTIVA",0,IF(H32="ETAPA",OFFSET(C32,-1,0)+1,OFFSET(C32,-1,0))) -> 2 | D32: =IF(H32="ETAPA",0,IF(H32="SUBETAPA",OFFSET(D32,-1,0)+1,OFFSET(D32,-1,0))) -> 2 | E32: =IF(H32="Subetapa",0,IF(H32="serviço",OFFSET(E32,-1,0)+1,OFFSET(E32,-1,0))) -> 0 | H32: SUBETAPA | I32: =IF(H32="Unidade Construtiva",TEXT(A32,"00"),IF(H32="Célula Construtiva",TEXT(B32,"00"),IF(H32="Etapa",CONCATENATE(TEXT(B32,"00"),".",TEXT(C32,"000")),IF(H32="Subetapa",CONCATENATE(TEXT(B32,"00"),".",TEXT(C32,"000"),".",TEXT(D32,"000")),IF(H32="Serviço",CONCATENATE(TEXT(B32,"00"),".",TEXT(C32,"000"),".",TEXT(D32,"000"),".",TEXT(E32,"000")),""))))) -> 01.002.002 | J32: Documentos | N32: =IF(H32="Serviço",M32*L32,IF(H32="CÉLULA CONSTRUTIVA",SUMIFS($N$8:$N$368,$B$8:$B$368,B32,$H$8:$H$368,"Serviço"),IF(H32="ETAPA",SUMIFS($N$8:$N$368,$B$8:$B$368,B32,$C$8:$C$368,C32,$H$8:$H$368,"Serviço"),IF(H32="SUBETAPA",SUMIFS($N$8:$N$368,$B$8:$B$368,B32,$C$8:$C$368,C32,$D$8:$D$368,D32,$H$8:$H$368,"Serviço"),0)))) -> 18471.132
A33: =IF($H33="UNIDADE CONSTRUTIVA",OFFSET(A33,-1,0)+1,LARGE(A$3:A32,1)) -> 0 | B33: =IF(H33="UNIDADE CONSTRUTIVA",0,IF(H33="CÉLULA CONSTRUTIVA",OFFSET(B33,-1,0)+1,OFFSET(B33,-1,0))) -> 1 | C33: =IF(H33="CÉLULA CONSTRUTIVA",0,IF(H33="ETAPA",OFFSET(C33,-1,0)+1,OFFSET(C33,-1,0))) -> 2 | D33: =IF(H33="ETAPA",0,IF(H33="SUBETAPA",OFFSET(D33,-1,0)+1,OFFSET(D33,-1,0))) -> 2 | E33: =IF(H33="Subetapa",0,IF(H33="serviço",OFFSET(E33,-1,0)+1,OFFSET(E33,-1,0))) -> 1 | H33: SERVIÇO | I33: =IF(H33="Unidade Construtiva",TEXT(A33,"00"),IF(H33="Célula Construtiva",TEXT(B33,"00"),IF(H33="Etapa",CONCATENATE(TEXT(B33,"00"),".",TEXT(C33,"000")),IF(H33="Subetapa",CONCATENATE(TEXT(B33,"00"),".",TEXT(C33,"000"),".",TEXT(D33,"000")),IF(H33="Serviço",CONCATENATE(TEXT(B33,"00"),".",TEXT(C33,"000"),".",TEXT(D33,"000"),".",TEXT(E33,"000")),""))))) -> 01.002.002.001 | J33: Certidão INSS | K33: vb | L33: 1 | M33: =(SUM('Obra '!C33:C45)*0.18)*0.11*0.7 -> 18471.132 | N33: =IF(H33="Serviço",M33*L33,IF(H33="CÉLULA CONSTRUTIVA",SUMIFS($N$8:$N$368,$B$8:$B$368,B33,$H$8:$H$368,"Serviço"),IF(H33="ETAPA",SUMIFS($N$8:$N$368,$B$8:$B$368,B33,$C$8:$C$368,C33,$H$8:$H$368,"Serviço"),IF(H33="SUBETAPA",SUMIFS($N$8:$N$368,$B$8:$B$368,B33,$C$8:$C$368,C33,$D$8:$D$368,D33,$H$8:$H$368,"Serviço"),0)))) -> 18471.132 | O33: Estimado como 11% da mão de obra da obra com indice de redução de 0,7 | P33: Finalizado
A34: =IF($H34="UNIDADE CONSTRUTIVA",OFFSET(A34,-1,0)+1,LARGE(A$3:A33,1)) -> 0 | B34: =IF(H34="UNIDADE CONSTRUTIVA",0,IF(H34="CÉLULA CONSTRUTIVA",OFFSET(B34,-1,0)+1,OFFSET(B34,-1,0))) -> 2 | C34: =IF(H34="CÉLULA CONSTRUTIVA",0,IF(H34="ETAPA",OFFSET(C34,-1,0)+1,OFFSET(C34,-1,0))) -> 0 | D34: =IF(H34="ETAPA",0,IF(H34="SUBETAPA",OFFSET(D34,-1,0)+1,OFFSET(D34,-1,0))) -> 2 | E34: =IF(H34="Subetapa",0,IF(H34="serviço",OFFSET(E34,-1,0)+1,OFFSET(E34,-1,0))) -> 1 | H34: CÉLULA CONSTRUTIVA | I34: =IF(H34="Unidade Construtiva",TEXT(A34,"00"),IF(H34="Célula Construtiva",TEXT(B34,"00"),IF(H34="Etapa",CONCATENATE(TEXT(B34,"00"),".",TEXT(C34,"000")),IF(H34="Subetapa",CONCATENATE(TEXT(B34,"00"),".",TEXT(C34,"000"),".",TEXT(D34,"000")),IF(H34="Serviço",CONCATENATE(TEXT(B34,"00"),".",TEXT(C34,"000"),".",TEXT(D34,"000"),".",TEXT(E34,"000")),""))))) -> 02 | J34: SERVIÇOS INICIAIS | N34: =IF(H34="Serviço",M34*L34,IF(H34="CÉLULA CONSTRUTIVA",SUMIFS($N$8:$N$368,$B$8:$B$368,B34,$H$8:$H$368,"Serviço"),IF(H34="ETAPA",SUMIFS($N$8:$N$368,$B$8:$B$368,B34,$C$8:$C$368,C34,$H$8:$H$368,"Serviço"),IF(H34="SUBETAPA",SUMIFS($N$8:$N$368,$B$8:$B$368,B34,$C$8:$C$368,C34,$D$8:$D$368,D34,$H$8:$H$368,"Serviço"),0)))) -> 125416.66 | Q34: =N34/'Obra '!$E$9 -> 380.54636
A35: =IF($H35="UNIDADE CONSTRUTIVA",OFFSET(A35,-1,0)+1,LARGE(A$3:A34,1)) -> 0 | B35: =IF(H35="UNIDADE CONSTRUTIVA",0,IF(H35="CÉLULA CONSTRUTIVA",OFFSET(B35,-1,0)+1,OFFSET(B35,-1,0))) -> 2 | C35: =IF(H35="CÉLULA CONSTRUTIVA",0,IF(H35="ETAPA",OFFSET(C35,-1,0)+1,OFFSET(C35,-1,0))) -> 1 | D35: =IF(H35="ETAPA",0,IF(H35="SUBETAPA",OFFSET(D35,-1,0)+1,OFFSET(D35,-1,0))) -> 0 | E35: =IF(H35="Subetapa",0,IF(H35="serviço",OFFSET(E35,-1,0)+1,OFFSET(E35,-1,0))) -> 1 | H35: ETAPA | I35: =IF(H35="Unidade Construtiva",TEXT(A35,"00"),IF(H35="Célula Construtiva",TEXT(B35,"00"),IF(H35="Etapa",CONCATENATE(TEXT(B35,"00"),".",TEXT(C35,"000")),IF(H35="Subetapa",CONCATENATE(TEXT(B35,"00"),".",TEXT(C35,"000"),".",TEXT(D35,"000")),IF(H35="Serviço",CONCATENATE(TEXT(B35,"00"),".",TEXT(C35,"000"),".",TEXT(D35,"000"),".",TEXT(E35,"000")),""))))) -> 02.001 | J35: SEGURANÇA, MEIO AMBIENTE E SAÚDE | N35: =IF(H35="Serviço",M35*L35,IF(H35="CÉLULA CONSTRUTIVA",SUMIFS($N$8:$N$368,$B$8:$B$368,B35,$H$8:$H$368,"Serviço"),IF(H35="ETAPA",SUMIFS($N$8:$N$368,$B$8:$B$368,B35,$C$8:$C$368,C35,$H$8:$H$368,"Serviço"),IF(H35="SUBETAPA",SUMIFS($N$8:$N$368,$B$8:$B$368,B35,$C$8:$C$368,C35,$D$8:$D$368,D35,$H$8:$H$368,"Serviço"),0)))) -> 9321.249
A36: =IF($H36="UNIDADE CONSTRUTIVA",OFFSET(A36,-1,0)+1,LARGE(A$3:A35,1)) -> 0 | B36: =IF(H36="UNIDADE CONSTRUTIVA",0,IF(H36="CÉLULA CONSTRUTIVA",OFFSET(B36,-1,0)+1,OFFSET(B36,-1,0))) -> 2 | C36: =IF(H36="CÉLULA CONSTRUTIVA",0,IF(H36="ETAPA",OFFSET(C36,-1,0)+1,OFFSET(C36,-1,0))) -> 1 | D36: =IF(H36="ETAPA",0,IF(H36="SUBETAPA",OFFSET(D36,-1,0)+1,OFFSET(D36,-1,0))) -> 1 | E36: =IF(H36="Subetapa",0,IF(H36="serviço",OFFSET(E36,-1,0)+1,OFFSET(E36,-1,0))) -> 0 | H36: SUBETAPA | I36: =IF(H36="Unidade Construtiva",TEXT(A36,"00"),IF(H36="Célula Construtiva",TEXT(B36,"00"),IF(H36="Etapa",CONCATENATE(TEXT(B36,"00"),".",TEXT(C36,"000")),IF(H36="Subetapa",CONCATENATE(TEXT(B36,"00"),".",TEXT(C36,"000"),".",TEXT(D36,"000")),IF(H36="Serviço",CONCATENATE(TEXT(B36,"00"),".",TEXT(C36,"000"),".",TEXT(D36,"000"),".",TEXT(E36,"000")),""))))) -> 02.001.001 | J36: Segurança do Trabalho | N36: =IF(H36="Serviço",M36*L36,IF(H36="CÉLULA CONSTRUTIVA",SUMIFS($N$8:$N$368,$B$8:$B$368,B36,$H$8:$H$368,"Serviço"),IF(H36="ETAPA",SUMIFS($N$8:$N$368,$B$8:$B$368,B36,$C$8:$C$368,C36,$H$8:$H$368,"Serviço"),IF(H36="SUBETAPA",SUMIFS($N$8:$N$368,$B$8:$B$368,B36,$C$8:$C$368,C36,$D$8:$D$368,D36,$H$8:$H$368,"Serviço"),0)))) -> 4500
A37: =IF($H37="UNIDADE CONSTRUTIVA",OFFSET(A37,-1,0)+1,LARGE(A$3:A36,1)) -> 0 | B37: =IF(H37="UNIDADE CONSTRUTIVA",0,IF(H37="CÉLULA CONSTRUTIVA",OFFSET(B37,-1,0)+1,OFFSET(B37,-1,0))) -> 2 | C37: =IF(H37="CÉLULA CONSTRUTIVA",0,IF(H37="ETAPA",OFFSET(C37,-1,0)+1,OFFSET(C37,-1,0))) -> 1 | D37: =IF(H37="ETAPA",0,IF(H37="SUBETAPA",OFFSET(D37,-1,0)+1,OFFSET(D37,-1,0))) -> 1 | E37: =IF(H37="Subetapa",0,IF(H37="serviço",OFFSET(E37,-1,0)+1,OFFSET(E37,-1,0))) -> 1 | H37: SERVIÇO | I37: =IF(H37="Unidade Construtiva",TEXT(A37,"00"),IF(H37="Célula Construtiva",TEXT(B37,"00"),IF(H37="Etapa",CONCATENATE(TEXT(B37,"00"),".",TEXT(C37,"000")),IF(H37="Subetapa",CONCATENATE(TEXT(B37,"00"),".",TEXT(C37,"000"),".",TEXT(D37,"000")),IF(H37="Serviço",CONCATENATE(TEXT(B37,"00"),".",TEXT(C37,"000"),".",TEXT(D37,"000"),".",TEXT(E37,"000")),""))))) -> 02.001.001.001 | J37: Equipamentos de proteção individual - EPI | K37: vb | L37: 1 | M37: =CANTEIRO!D15 -> 4500 | N37: =IF(H37="Serviço",M37*L37,IF(H37="CÉLULA CONSTRUTIVA",SUMIFS($N$8:$N$368,$B$8:$B$368,B37,$H$8:$H$368,"Serviço"),IF(H37="ETAPA",SUMIFS($N$8:$N$368,$B$8:$B$368,B37,$C$8:$C$368,C37,$H$8:$H$368,"Serviço"),IF(H37="SUBETAPA",SUMIFS($N$8:$N$368,$B$8:$B$368,B37,$C$8:$C$368,C37,$D$8:$D$368,D37,$H$8:$H$368,"Serviço"),0)))) -> 4500 | O37: Confrome cálculo da aba "Canteiro" | P37: Finalizado
A38: =IF($H38="UNIDADE CONSTRUTIVA",OFFSET(A38,-1,0)+1,LARGE(A$3:A37,1)) -> 0 | B38: =IF(H38="UNIDADE CONSTRUTIVA",0,IF(H38="CÉLULA CONSTRUTIVA",OFFSET(B38,-1,0)+1,OFFSET(B38,-1,0))) -> 2 | C38: =IF(H38="CÉLULA CONSTRUTIVA",0,IF(H38="ETAPA",OFFSET(C38,-1,0)+1,OFFSET(C38,-1,0))) -> 1 | D38: =IF(H38="ETAPA",0,IF(H38="SUBETAPA",OFFSET(D38,-1,0)+1,OFFSET(D38,-1,0))) -> 2 | E38: =IF(H38="Subetapa",0,IF(H38="serviço",OFFSET(E38,-1,0)+1,OFFSET(E38,-1,0))) -> 0 | H38: SUBETAPA | I38: =IF(H38="Unidade Construtiva",TEXT(A38,"00"),IF(H38="Célula Construtiva",TEXT(B38,"00"),IF(H38="Etapa",CONCATENATE(TEXT(B38,"00"),".",TEXT(C38,"000")),IF(H38="Subetapa",CONCATENATE(TEXT(B38,"00"),".",TEXT(C38,"000"),".",TEXT(D38,"000")),IF(H38="Serviço",CONCATENATE(TEXT(B38,"00"),".",TEXT(C38,"000"),".",TEXT(D38,"000"),".",TEXT(E38,"000")),""))))) -> 02.001.002 | J38: Equipamentos de proteção | N38: =IF(H38="Serviço",M38*L38,IF(H38="CÉLULA CONSTRUTIVA",SUMIFS($N$8:$N$368,$B$8:$B$368,B38,$H$8:$H$368,"Serviço"),IF(H38="ETAPA",SUMIFS($N$8:$N$368,$B$8:$B$368,B38,$C$8:$C$368,C38,$H$8:$H$368,"Serviço"),IF(H38="SUBETAPA",SUMIFS($N$8:$N$368,$B$8:$B$368,B38,$C$8:$C$368,C38,$D$8:$D$368,D38,$H$8:$H$368,"Serviço"),0)))) -> 821.24899
A39: =IF($H39="UNIDADE CONSTRUTIVA",OFFSET(A39,-1,0)+1,LARGE(A$3:A38,1)) -> 0 | B39: =IF(H39="UNIDADE CONSTRUTIVA",0,IF(H39="CÉLULA CONSTRUTIVA",OFFSET(B39,-1,0)+1,OFFSET(B39,-1,0))) -> 2 | C39: =IF(H39="CÉLULA CONSTRUTIVA",0,IF(H39="ETAPA",OFFSET(C39,-1,0)+1,OFFSET(C39,-1,0))) -> 1 | D39: =IF(H39="ETAPA",0,IF(H39="SUBETAPA",OFFSET(D39,-1,0)+1,OFFSET(D39,-1,0))) -> 2 | E39: =IF(H39="Subetapa",0,IF(H39="serviço",OFFSET(E39,-1,0)+1,OFFSET(E39,-1,0))) -> 1 | H39: SERVIÇO | I39: =IF(H39="Unidade Construtiva",TEXT(A39,"00"),IF(H39="Célula Construtiva",TEXT(B39,"00"),IF(H39="Etapa",CONCATENATE(TEXT(B39,"00"),".",TEXT(C39,"000")),IF(H39="Subetapa",CONCATENATE(TEXT(B39,"00"),".",TEXT(C39,"000"),".",TEXT(D39,"000")),IF(H39="Serviço",CONCATENATE(TEXT(B39,"00"),".",TEXT(C39,"000"),".",TEXT(D39,"000"),".",TEXT(E39,"000")),""))))) -> 02.001.002.001 | J39: Guarda-corpo de vãos, fixado em fôrma de madeira, em trama de madeira com tela de polipropileno | K39: m | L39: =Ger_Executivo!L203/1.1 -> 13.583636 | M39: =CPU!H164 -> 38.622647 | N39: =IF(H39="Serviço",M39*L39,IF(H39="CÉLULA CONSTRUTIVA",SUMIFS($N$8:$N$368,$B$8:$B$368,B39,$H$8:$H$368,"Serviço"),IF(H39="ETAPA",SUMIFS($N$8:$N$368,$B$8:$B$368,B39,$C$8:$C$368,C39,$H$8:$H$368,"Serviço"),IF(H39="SUBETAPA",SUMIFS($N$8:$N$368,$B$8:$B$368,B39,$C$8:$C$368,C39,$D$8:$D$368,D39,$H$8:$H$368,"Serviço"),0)))) -> 524.63599 | P39: Finalizado
A40: =IF($H40="UNIDADE CONSTRUTIVA",OFFSET(A40,-1,0)+1,LARGE(A$3:A39,1)) -> 0 | B40: =IF(H40="UNIDADE CONSTRUTIVA",0,IF(H40="CÉLULA CONSTRUTIVA",OFFSET(B40,-1,0)+1,OFFSET(B40,-1,0))) -> 2 | C40: =IF(H40="CÉLULA CONSTRUTIVA",0,IF(H40="ETAPA",OFFSET(C40,-1,0)+1,OFFSET(C40,-1,0))) -> 1 | D40: =IF(H40="ETAPA",0,IF(H40="SUBETAPA",OFFSET(D40,-1,0)+1,OFFSET(D40,-1,0))) -> 2 | E40: =IF(H40="Subetapa",0,IF(H40="serviço",OFFSET(E40,-1,0)+1,OFFSET(E40,-1,0))) -> 2 | H40: SERVIÇO | I40: =IF(H40="Unidade Construtiva",TEXT(A40,"00"),IF(H40="Célula Construtiva",TEXT(B40,"00"),IF(H40="Etapa",CONCATENATE(TEXT(B40,"00"),".",TEXT(C40,"000")),IF(H40="Subetapa",CONCATENATE(TEXT(B40,"00"),".",TEXT(C40,"000"),".",TEXT(D40,"000")),IF(H40="Serviço",CONCATENATE(TEXT(B40,"00"),".",TEXT(C40,"000"),".",TEXT(D40,"000"),".",TEXT(E40,"000")),""))))) -> 02.001.002.002 | J40: Sinalização geral da obra | K40: un | L40: 1 | M40: 296.613 | N40: =IF(H40="Serviço",M40*L40,IF(H40="CÉLULA CONSTRUTIVA",SUMIFS($N$8:$N$368,$B$8:$B$368,B40,$H$8:$H$368,"Serviço"),IF(H40="ETAPA",SUMIFS($N$8:$N$368,$B$8:$B$368,B40,$C$8:$C$368,C40,$H$8:$H$368,"Serviço"),IF(H40="SUBETAPA",SUMIFS($N$8:$N$368,$B$8:$B$368,B40,$C$8:$C$368,C40,$D$8:$D$368,D40,$H$8:$H$368,"Serviço"),0)))) -> 296.613 | O40: Estimado com base em índices históricos | P40: Finalizado
A41: =IF($H41="UNIDADE CONSTRUTIVA",OFFSET(A41,-1,0)+1,LARGE(A$3:A39,1)) -> 0 | B41: =IF(H41="UNIDADE CONSTRUTIVA",0,IF(H41="CÉLULA CONSTRUTIVA",OFFSET(B41,-1,0)+1,OFFSET(B41,-1,0))) -> 2 | C41: =IF(H41="CÉLULA CONSTRUTIVA",0,IF(H41="ETAPA",OFFSET(C41,-1,0)+1,OFFSET(C41,-1,0))) -> 1 | D41: =IF(H41="ETAPA",0,IF(H41="SUBETAPA",OFFSET(D41,-1,0)+1,OFFSET(D41,-1,0))) -> 3 | E41: =IF(H41="Subetapa",0,IF(H41="serviço",OFFSET(E41,-1,0)+1,OFFSET(E41,-1,0))) -> 0 | H41: SUBETAPA | I41: =IF(H41="Unidade Construtiva",TEXT(A41,"00"),IF(H41="Célula Construtiva",TEXT(B41,"00"),IF(H41="Etapa",CONCATENATE(TEXT(B41,"00"),".",TEXT(C41,"000")),IF(H41="Subetapa",CONCATENATE(TEXT(B41,"00"),".",TEXT(C41,"000"),".",TEXT(D41,"000")),IF(H41="Serviço",CONCATENATE(TEXT(B41,"00"),".",TEXT(C41,"000"),".",TEXT(D41,"000"),".",TEXT(E41,"000")),""))))) -> 02.001.003 | J41: Meio Ambiente | N41: =IF(H41="Serviço",M41*L41,IF(H41="CÉLULA CONSTRUTIVA",SUMIFS($N$8:$N$368,$B$8:$B$368,B41,$H$8:$H$368,"Serviço"),IF(H41="ETAPA",SUMIFS($N$8:$N$368,$B$8:$B$368,B41,$C$8:$C$368,C41,$H$8:$H$368,"Serviço"),IF(H41="SUBETAPA",SUMIFS($N$8:$N$368,$B$8:$B$368,B41,$C$8:$C$368,C41,$D$8:$D$368,D41,$H$8:$H$368,"Serviço"),0)))) -> 4000
A42: =IF($H42="UNIDADE CONSTRUTIVA",OFFSET(A42,-1,0)+1,LARGE(A$3:A41,1)) -> 0 | B42: =IF(H42="UNIDADE CONSTRUTIVA",0,IF(H42="CÉLULA CONSTRUTIVA",OFFSET(B42,-1,0)+1,OFFSET(B42,-1,0))) -> 2 | C42: =IF(H42="CÉLULA CONSTRUTIVA",0,IF(H42="ETAPA",OFFSET(C42,-1,0)+1,OFFSET(C42,-1,0))) -> 1 | D42: =IF(H42="ETAPA",0,IF(H42="SUBETAPA",OFFSET(D42,-1,0)+1,OFFSET(D42,-1,0))) -> 3 | E42: =IF(H42="Subetapa",0,IF(H42="serviço",OFFSET(E42,-1,0)+1,OFFSET(E42,-1,0))) -> 1 | H42: SERVIÇO | I42: =IF(H42="Unidade Construtiva",TEXT(A42,"00"),IF(H42="Célula Construtiva",TEXT(B42,"00"),IF(H42="Etapa",CONCATENATE(TEXT(B42,"00"),".",TEXT(C42,"000")),IF(H42="Subetapa",CONCATENATE(TEXT(B42,"00"),".",TEXT(C42,"000"),".",TEXT(D42,"000")),IF(H42="Serviço",CONCATENATE(TEXT(B42,"00"),".",TEXT(C42,"000"),".",TEXT(D42,"000"),".",TEXT(E42,"000")),""))))) -> 02.001.003.001 | J42: Remoção de entulhos e resíduos | K42: vb | L42: 1 | M42: =400*10 -> 4000 | N42: =IF(H42="Serviço",M42*L42,IF(H42="CÉLULA CONSTRUTIVA",SUMIFS($N$8:$N$368,$B$8:$B$368,B42,$H$8:$H$368,"Serviço"),IF(H42="ETAPA",SUMIFS($N$8:$N$368,$B$8:$B$368,B42,$C$8:$C$368,C42,$H$8:$H$368,"Serviço"),IF(H42="SUBETAPA",SUMIFS($N$8:$N$368,$B$8:$B$368,B42,$C$8:$C$368,C42,$D$8:$D$368,D42,$H$8:$H$368,"Serviço"),0)))) -> 4000 | O42: Estimado uma caçamba ao mês por 10 meses | P42: Finalizado
A43: =IF($H43="UNIDADE CONSTRUTIVA",OFFSET(A43,-1,0)+1,LARGE(A$3:A42,1)) -> 0 | B43: =IF(H43="UNIDADE CONSTRUTIVA",0,IF(H43="CÉLULA CONSTRUTIVA",OFFSET(B43,-1,0)+1,OFFSET(B43,-1,0))) -> 2 | C43: =IF(H43="CÉLULA CONSTRUTIVA",0,IF(H43="ETAPA",OFFSET(C43,-1,0)+1,OFFSET(C43,-1,0))) -> 2 | D43: =IF(H43="ETAPA",0,IF(H43="SUBETAPA",OFFSET(D43,-1,0)+1,OFFSET(D43,-1,0))) -> 0 | E43: =IF(H43="Subetapa",0,IF(H43="serviço",OFFSET(E43,-1,0)+1,OFFSET(E43,-1,0))) -> 1 | H43: ETAPA | I43: =IF(H43="Unidade Construtiva",TEXT(A43,"00"),IF(H43="Célula Construtiva",TEXT(B43,"00"),IF(H43="Etapa",CONCATENATE(TEXT(B43,"00"),".",TEXT(C43,"000")),IF(H43="Subetapa",CONCATENATE(TEXT(B43,"00"),".",TEXT(C43,"000"),".",TEXT(D43,"000")),IF(H43="Serviço",CONCATENATE(TEXT(B43,"00"),".",TEXT(C43,"000"),".",TEXT(D43,"000"),".",TEXT(E43,"000")),""))))) -> 02.002 | J43: ADMINISTRAÇÃO E CANTEIRO DE OBRA | N43: =IF(H43="Serviço",M43*L43,IF(H43="CÉLULA CONSTRUTIVA",SUMIFS($N$8:$N$368,$B$8:$B$368,B43,$H$8:$H$368,"Serviço"),IF(H43="ETAPA",SUMIFS($N$8:$N$368,$B$8:$B$368,B43,$C$8:$C$368,C43,$H$8:$H$368,"Serviço"),IF(H43="SUBETAPA",SUMIFS($N$8:$N$368,$B$8:$B$368,B43,$C$8:$C$368,C43,$D$8:$D$368,D43,$H$8:$H$368,"Serviço"),0)))) -> 116095.41
...

Sheet Ger_Executivo
G4: PROJETO: | I4: ='Ger_Tec e Adm'!I4 -> Mowe | O4: REVISÃO: | P4: DATA
G5: EMPRESA: | I5: ='Ger_Tec e Adm'!I5 -> MARTINS|FRANCEZ ENGENHARIA | O5: R00
A6: Unidade Construtiva | B6: Célula Construtiva | C6: Etapa | D6: Subetapa | E6: Serviço | G6: GERENCIAMENTO EXECUTIVO
A7: 0 | B7: 0 | C7: 0 | D7: 0 | E7: 0 | G7: Atalho | H7: NIVEL | I7: Item | J7: Descrição | K7: Unidade | L7: Quant. | M7: Preço un | N7: Total | O7: Considerações | P7: Situação
A8: =IF($H8="UNIDADE CONSTRUTIVA",OFFSET(A8,-1,0)+1,LARGE(A$3:A7,1)) -> 0 | B8: =IF(H8="UNIDADE CONSTRUTIVA",0,IF(H8="CÉLULA CONSTRUTIVA",OFFSET(B8,-1,0)+1,OFFSET(B8,-1,0))) -> 1 | C8: =IF(H8="CÉLULA CONSTRUTIVA",0,IF(H8="ETAPA",OFFSET(C8,-1,0)+1,OFFSET(C8,-1,0))) -> 0 | D8: =IF(H8="ETAPA",0,IF(H8="SUBETAPA",OFFSET(D8,-1,0)+1,OFFSET(D8,-1,0))) -> 0 | E8: =IF(H8="Subetapa",0,IF(H8="serviço",OFFSET(E8,-1,0)+1,OFFSET(E8,-1,0))) -> 0 | H8: CÉLULA CONSTRUTIVA | I8: =IF(H8="Unidade Construtiva",TEXT(A8,"00"),IF(H8="Célula Construtiva",TEXT(B8,"00"),IF(H8="Etapa",CONCATENATE(TEXT(B8,"00"),".",TEXT(C8,"000")),IF(H8="Subetapa",CONCATENATE(TEXT(B8,"00"),".",TEXT(C8,"000"),".",TEXT(D8,"000")),IF(H8="Serviço",CONCATENATE(TEXT(B8,"00"),".",TEXT(C8,"000"),".",TEXT(D8,"000"),".",TEXT(E8,"000")),""))))) -> 01 | J8: INFRAESTRUTURA | N8: =IF(H8="Serviço",M8*L8,IF(H8="CÉLULA CONSTRUTIVA",SUMIFS($N$8:$N$258,$B$8:$B$258,B8,$H$8:$H$258,"Serviço"),IF(H8="ETAPA",SUMIFS($N$8:$N$258,$B$8:$B$258,B8,$C$8:$C$258,C8,$H$8:$H$258,"Serviço"),IF(H8="SUBETAPA",SUMIFS($N$8:$N$258,$B$8:$B$258,B8,$C$8:$C$258,C8,$D$8:$D$258,D8,$H$8:$H$258,"Serviço"),0)))) -> 113009.8 | O8: =N8/'Obra '!E$9 -> 342.90075
A9: =IF($H9="UNIDADE CONSTRUTIVA",OFFSET(A9,-1,0)+1,LARGE(A$3:A8,1)) -> 0 | B9: =IF(H9="UNIDADE CONSTRUTIVA",0,IF(H9="CÉLULA CONSTRUTIVA",OFFSET(B9,-1,0)+1,OFFSET(B9,-1,0))) -> 1 | C9: =IF(H9="CÉLULA CONSTRUTIVA",0,IF(H9="ETAPA",OFFSET(C9,-1,0)+1,OFFSET(C9,-1,0))) -> 1 | D9: =IF(H9="ETAPA",0,IF(H9="SUBETAPA",OFFSET(D9,-1,0)+1,OFFSET(D9,-1,0))) -> 0 | E9: =IF(H9="Subetapa",0,IF(H9="serviço",OFFSET(E9,-1,0)+1,OFFSET(E9,-1,0))) -> 0 | H9: ETAPA | I9: =IF(H9="Unidade Construtiva",TEXT(A9,"00"),IF(H9="Célula Construtiva",TEXT(B9,"00"),IF(H9="Etapa",CONCATENATE(TEXT(B9,"00"),".",TEXT(C9,"000")),IF(H9="Subetapa",CONCATENATE(TEXT(B9,"00"),".",TEXT(C9,"000"),".",TEXT(D9,"000")),IF(H9="Serviço",CONCATENATE(TEXT(B9,"00"),".",TEXT(C9,"000"),".",TEXT(D9,"000"),".",TEXT(E9,"000")),""))))) -> 01.001 | J9: LIMPEZA E MOVIMENTAÇÃO DE TERRA | N9: =IF(H9="Serviço",M9*L9,IF(H9="CÉLULA CONSTRUTIVA",SUMIFS($N$8:$N$258,$B$8:$B$258,B9,$H$8:$H$258,"Serviço"),IF(H9="ETAPA",SUMIFS($N$8:$N$258,$B$8:$B$258,B9,$C$8:$C$258,C9,$H$8:$H$258,"Serviço"),IF(H9="SUBETAPA",SUMIFS($N$8:$N$258,$B$8:$B$258,B9,$C$8:$C$258,C9,$D$8:$D$258,D9,$H$8:$H$258,"Serviço"),0)))) -> 10084.168 | O9: =N9/'Obra '!E$9 -> 30.597954
