Workbook
Name ____PK2: {"'장비'!$A$3:$M$12"}
Name ____PK2: {"'장비'!$A$3:$M$12"}
Name ____PK2: {"'장비'!$A$3:$M$12"}
Name ____PK2: {"'장비'!$A$3:$M$12"}
Name ____PK2: {"'장비'!$A$3:$M$12"}
Name ____PK2: {"'장비'!$A$3:$M$12"}
Name ____PK2: {"'장비'!$A$3:$M$12"}
Name ____PK2: {"'장비'!$A$3:$M$12"}
Name ____PKG3: {"'장비'!$A$3:$M$12"}
Name ____PKG3: {"'장비'!$A$3:$M$12"}
Name ____PKG3: {"'장비'!$A$3:$M$12"}
Name ____PKG3: {"'장비'!$A$3:$M$12"}
Name ____PKG3: {"'장비'!$A$3:$M$12"}
Name ____PKG3: {"'장비'!$A$3:$M$12"}
Name ____PKG3: {"'장비'!$A$3:$M$12"}
Name ____PKG3: {"'장비'!$A$3:$M$12"}
Name ____qqq222: {"'장비'!$A$3:$M$12"}
Name ____qqq222: {"'장비'!$A$3:$M$12"}
Name ____qqq222: {"'장비'!$A$3:$M$12"}
Name ____qqq222: {"'장비'!$A$3:$M$12"}
Name ____qqq222: {"'장비'!$A$3:$M$12"}
Name ____qqq222: {"'장비'!$A$3:$M$12"}
Name ____qqq222: {"'장비'!$A$3:$M$12"}
Name ____qqq222: {"'장비'!$A$3:$M$12"}
Name ___PK2: {"'장비'!$A$3:$M$12"}
Name ___PK2: {"'장비'!$A$3:$M$12"}
Name ___PK2: {"'장비'!$A$3:$M$12"}
Name ___PK2: {"'장비'!$A$3:$M$12"}
Name ___PK2: {"'장비'!$A$3:$M$12"}
Name ___PK2: {"'장비'!$A$3:$M$12"}
Name ___PK2: {"'장비'!$A$3:$M$12"}
Name ___PK2: {"'장비'!$A$3:$M$12"}
Name ___PKG3: {"'장비'!$A$3:$M$12"}
Name ___PKG3: {"'장비'!$A$3:$M$12"}
Name ___PKG3: {"'장비'!$A$3:$M$12"}
Name ___PKG3: {"'장비'!$A$3:$M$12"}
Name ___PKG3: {"'장비'!$A$3:$M$12"}
Name ___PKG3: {"'장비'!$A$3:$M$12"}
Name ___PKG3: {"'장비'!$A$3:$M$12"}
Name ___PKG3: {"'장비'!$A$3:$M$12"}
Name ___qqq222: {"'장비'!$A$3:$M$12"}
Name ___qqq222: {"'장비'!$A$3:$M$12"}
Name ___qqq222: {"'장비'!$A$3:$M$12"}
Name ___qqq222: {"'장비'!$A$3:$M$12"}
Name ___qqq222: {"'장비'!$A$3:$M$12"}
Name ___qqq222: {"'장비'!$A$3:$M$12"}
Name ___qqq222: {"'장비'!$A$3:$M$12"}
Name ___qqq222: {"'장비'!$A$3:$M$12"}
Name __PK2: {"'장비'!$A$3:$M$12"}
Name __PK2: {"'장비'!$A$3:$M$12"}
Name __PK2: {"'장비'!$A$3:$M$12"}
Name __PK2: {"'장비'!$A$3:$M$12"}
Name __PK2: {"'장비'!$A$3:$M$12"}
Name __PK2: {"'장비'!$A$3:$M$12"}
Name __PK2: {"'장비'!$A$3:$M$12"}
Name __PK2: {"'장비'!$A$3:$M$12"}
Name __PKG3: {"'장비'!$A$3:$M$12"}
Name __PKG3: {"'장비'!$A$3:$M$12"}
Name __PKG3: {"'장비'!$A$3:$M$12"}
Name __PKG3: {"'장비'!$A$3:$M$12"}

Sheet Planilha1
D1: =SUM(D2:D10) -> 10831779
C2: Mão de Obra de Empreitada Civil | D2: =Ger_Executivo!G278 -> 6499067.7 | E2: =-D2/$D$1 -> -0.6
C3: Mão de Obra Contenção | D3: =Ger_Executivo!G279 -> 216635.59 | E3: =-D3/$D$1 -> -0.02 | F3: Movimentação | G3: =0.54/66.25 -> 0.0081509434 | H3: 0.075 | I3: =H3*$D$2 -> 487430.07
C4: Mão de Obra de Empreitada Pintura | D4: =Ger_Executivo!G280 -> 1083177.9 | E4: =-D4/$D$1 -> -0.1 | F4: Infraestrutura | G4: =3.26/66.25 -> 0.049207547 | H4: 0.055 | I4: =H4*$D$2 -> 357448.72
C5: Mão de Obra de Empreitada Revestimento Cerâmicos | D5: =Ger_Executivo!G281 -> 1083177.9 | E5: =-D5/$D$1 -> -0.1 | F5: Supraestrutura | G5: =25/66.25 -> 0.37735849 | H5: 0.35 | I5: =H5*$D$2 -> 2274673.7
C6: Mão de Obra de Empreitada Limpeza Contínua e Ajudantes | D6: =Ger_Executivo!G282 -> 216635.59 | E6: =-D6/$D$1 -> -0.02 | F6: Alvenaria | G6: =10/66.25 -> 0.1509434 | H6: 0.12 | I6: =H6*$D$2 -> 779888.12
C7: Mão de Obra Instalações Hidrossanitárias | D7: =Ger_Executivo!G283 -> 649906.77 | E7: =-D7/$D$1 -> -0.06 | F7: Argamassado | G7: =26/66.25 -> 0.39245283 | H7: 0.35 | I7: =H7*$D$2 -> 2274673.7
C8: Mão de Obra Instalações Elétricas | D8: =Ger_Executivo!G284 -> 649906.77 | E8: =-D8/$D$1 -> -0.06 | F8: Cobertura | G8: =0.3/66.25 -> 0.0045283019 | H8: 0.04 | I8: =H8*$D$2 -> 259962.71
C9: Mão de Obra de Instalação de Louças e Metais | D9: =Ger_Executivo!G285 -> 108317.79 | E9: =-D9/$D$1 -> -0.01 | F9: Complementares | G9: =1.15/66.25 -> 0.017358491 | H9: 0.01 | I9: =H9*$D$2 -> 64990.677
C10: Mão de Obra Instalação de Portas e Rodapés | D10: =Ger_Executivo!G286 -> 324953.38 | E10: =-D10/$D$1 -> -0.03
H11: =SUM(H3:H9) -> 1 | I11: =SUM(G3:G9) -> 1

Sheet Obra 
C1: Projeto | D1: PARKSIDE RIO BRANCO
C2: Empresa | D2: PARKSIDE
C3: Revisão | D3: R00 -
A4: QUADRO DE ÁREAS
B6: Descrição | C6: Unidade | E6: Quantidade | G6: Imagens
B7: MESES DE OBRA | C7: MÊS | E7: =H9 -> 33 | G7: Início obra | H7: 46113
B8: ÁREA DO TERRENO | C8: M² | E8: 884.99 | G8: Conclusão meta | H8: 47088
B9: ÁREA CONSTRUÍDA | C9: M² | E9: =SUM(E14:E22) -> 8660.1 | G9: Total meses obra | H9: =ROUNDUP(((H8-H7)/30),0) -> 33
B10: NÚMERO DE UNIDADES HABITACIONAIS | C10: UN | E10: 160
B11: NÚMERO DE UNIDADES COMERCIAIS | C11: UN | E11: 3
B12: ÁREA PRIVATIVA | C12: M² | E12: 5303.81
B13: NÚMERO DE PAVIMENTOS | C13: UN | E13: 21
B14: Subsolo 2 | E14: 700.82
B15: Subsolo 1 | C15: M² | E15: =613.5 -> 613.5
B16: Térreo | C16: M² | E16: 560.05
B17: Pav 2 | C17: M² | E17: 403.28
B18: Garden | C18: M² | E18: 488.63
B19: Tipo (x15) | C19: M² | E19: =(15*365.41) -> 5481.15
B20: Cobertura | C20: M² | E20: 322.67
B21: Barrilete | C21: M² | E21: 45
B22: Reservatório | C22: M² | E22: 45
B31: ETAPA | C31: VALOR ORÇADO | D31: % | E31: VALOR / m²
B32: GERENCIAMENTO TÉCNICO E ADMINISTRATIVO | C32: =C33+C34 -> 1334002.8 | D32: =C32/C$68 -> 0.032403558 | E32: =C32/$E$9 -> 154.04012
B33: ='Ger_Tec e Adm'!J8 -> SERVIÇOS TÉCNICOS | C33: ='Ger_Tec e Adm'!N8 -> 412448.85 | D33: =C33/C$68 -> 0.010018577 | E33: =C33/$E$9 -> 47.626338
B34: ='Ger_Tec e Adm'!J21 -> SERVIÇOS PRELIMINARES E CANTEIRO | C34: ='Ger_Tec e Adm'!N21 -> 921553.96 | D34: =C34/C$68 -> 0.022384981 | E34: =C34/$E$9 -> 106.41378 | L34: =C35-C62 -> 18658249
B35: GERENCIAMENTO EXECUTIVO | C35: =C36+C41 -> 29490028 | D35: =C35/C$68 -> 0.7163267 | E35: =C35/$E$9 -> 3405.2757 | L35: =L34+C32 -> 19992251
B36: =Ger_Executivo!D8 -> INFRAESTRUTURA | C36: =Ger_Executivo!H8 -> 1566010.8 | D36: =C36/C$68 -> 0.038039142 | E36: =C36/$E$9 -> 180.83057
B37: =Ger_Executivo!D9 -> SERVIÇOS PRELIMINARES | C37: =Ger_Executivo!H9 -> 37755.331 | D37: =C37/C$68 -> 0.0009170948 | E37: =C37/$E$9 -> 4.3596876
B38: =Ger_Executivo!D12 -> SERVIÇOS EM TERRA | C38: =Ger_Executivo!H12 -> 340525.06 | D38: =C38/C$68 -> 0.0082715143 | E38: =C38/$E$9 -> 39.321146
B39: =Ger_Executivo!D22 -> CONTENÇÕES E FUNDAÇÕES | C39: =Ger_Executivo!H22 -> 1163561 | D39: =C39/C$68 -> 0.028263445 | E39: =C39/$E$9 -> 134.35884
B40: =Ger_Executivo!D34 -> DRENAGEM | C40: =Ger_Executivo!H34 -> 24169.458 | D40: =C40/C$68 -> 0.00058708753 | E40: =C40/$E$9 -> 2.7908982
B41: =Ger_Executivo!D39 -> OBRA | C41: =Ger_Executivo!H39 -> 27924017 | D41: =C41/C$68 -> 0.67828755 | E41: =C41/$E$9 -> 3224.4451
B42: =Ger_Executivo!D40 -> EQUIPAMENTOS | C42: =Ger_Executivo!H40 -> 863599.44 | D42: =C42/C$68 -> 0.020977238 | E42: =C42/$E$9 -> 99.721648
B43: =Ger_Executivo!D51 -> ESTRUTURAS | C43: =Ger_Executivo!H51 -> 3324999.5 | D43: =C43/C$68 -> 0.080765807 | E43: =C43/$E$9 -> 383.9447
B44: =Ger_Executivo!D63 -> COBERTURA | C44: =Ger_Executivo!H63 -> 31661.147 | D44: =C44/C$68 -> 0.0007690642 | E44: =C44/$E$9 -> 3.6559794
B45: =Ger_Executivo!D71 -> PAREDES E FECHAMENTOS | C45: =Ger_Executivo!H71 -> 743690.92 | D45: =C45/C$68 -> 0.018064603 | E45: =C45/$E$9 -> 85.875558
B46: =Ger_Executivo!D81 -> REVESTIMENTOS ARGAMASSADOS | C46: =Ger_Executivo!H81 -> 875012.99 | D46: =C46/C$68 -> 0.021254478 | E46: =C46/$E$9 -> 101.03959
B47: =Ger_Executivo!D94 -> IMPERMEABILIZAÇÃO | C47: =Ger_Executivo!H94 -> 411650.95 | D47: =C47/C$68 -> 0.0099991958 | E47: =C47/$E$9 -> 47.534203
B48: =Ger_Executivo!D130 -> INSTALAÇÕES ELÉTRICAS E TELECOMUNICAÇÕES | C48: =Ger_Executivo!H130 -> 1111154.4 | D48: =C48/C$68 -> 0.026990464 | E48: =C48/$E$9 -> 128.30734
B49: =Ger_Executivo!D142 -> INSTALAÇÕES HIDROSSANITÁRIAS | C49: =Ger_Executivo!H142 -> 1252179.6 | D49: =C49/C$68 -> 0.030416035 | E49: =C49/$E$9 -> 144.59182
...

Sheet EAP ANALISE
A1: ETAPA | B1: VALOR ORÇADO | C1: % | D1: VALOR / m²
A2: GERENCIAMENTO TÉCNICO E ADMINISTRATIVO | B2: ='Obra '!C32+'Obra '!C42 -> 2197602.3 | C2: =B2/$B$29 -> 0.053380796 | D2: =B2/'Obra '!$E$9 -> 253.76176
A3: MOVIMENTAÇÃO DE TERRA | B3: =Ger_Executivo!H9+Ger_Executivo!H12 -> 378280.39 | C3: =B3/$B$29 -> 0.0091886091 | D3: =B3/'Obra '!$E$9 -> 43.680834
A4: INFRAESTRUTURA | B4: =Ger_Executivo!H23+Ger_Executivo!H34 -> 909261.04 | C4: =B4/$B$29 -> 0.02208638 | D4: =B4/'Obra '!$E$9 -> 104.99429 | G4: Mão de Obra de Empreitada Civil | H4: =Ger_Executivo!H278 -> 6499067.7
A5: CONTEÇÃO | B5: =Ger_Executivo!H29 -> 278469.38 | C5: =B5/$B$29 -> 0.0067641527 | D5: =B5/'Obra '!$E$9 -> 32.155447 | G5: Mão de Obra Mureta Guia | H5: =Ger_Executivo!H279 -> 216635.59
A6: SUPRAESTRUTURA | B6: =Ger_Executivo!H51 -> 3324999.5 | C6: =B6/$B$29 -> 0.080765807 | D6: =B6/'Obra '!$E$9 -> 383.9447 | G6: Estimativas / Mão de Obra Paredes de Diafragma | H6: =Ger_Executivo!#REF! -> #ERROR!
A7: ALVENARIA | B7: =Ger_Executivo!H71 -> 743690.92 | C7: =B7/$B$29 -> 0.018064603 | D7: =B7/'Obra '!$E$9 -> 85.875558 | G7: Mão de Obra de Empreitada Pintura | H7: =Ger_Executivo!H280 -> 1083177.9
A8: INSTALAÇÕES ELÉTRICAS, HIDRÁULICAS, GLP E PREVENTIVAS | B8: =Ger_Executivo!H130+Ger_Executivo!H142+Ger_Executivo!H157 -> 2728300.1 | C8: =B8/$B$29 -> 0.066271697 | D8: =B8/'Obra '!$E$9 -> 315.04256 | G8: Mão de Obra de Empreitada Revestimento Cerâmicos | H8: =Ger_Executivo!H281 -> 1083177.9
A9: CLIMATIZAÇÃO, EXAUSTÃO MECÂNICA E PRESSURIZAÇÃO | B9: =Ger_Executivo!H171 -> 476100 | C9: =B9/$B$29 -> 0.011564694 | D9: =B9/'Obra '!$E$9 -> 54.97627 | G9: Mão de Obra de Empreitada Limpeza Contínua e Ajudantes | H9: =Ger_Executivo!H282 -> 216635.59
A10: EQUIPAMENTOS E SISTEMAS ESPECIAIS | B10: =Ger_Executivo!H233 -> 903000 | C10: =B10/$B$29 -> 0.021934296 | D10: =B10/'Obra '!$E$9 -> 104.27131 | G10: Mão de Obra Instalações Hidrossanitárias | H10: =Ger_Executivo!H283 -> 649906.77
A11: INSTALAÇÕES ESPECIAIS | C11: =B11/$B$29 -> 0 | D11: =B11/'Obra '!$E$9 -> 0 | G11: Mão de Obra Instalações Elétricas | H11: =Ger_Executivo!H284 -> 649906.77
A12: REVESTIMENTOS ARGAMASSADOS PISO | B12: =Ger_Executivo!H90 -> 617052.6 | C12: =B12/$B$29 -> 0.014988499 | D12: =B12/'Obra '!$E$9 -> 71.252364 | G12: Mão de Obra de Instalação de Louças e Metais | H12: =Ger_Executivo!H285 -> 108317.79
A13: REVESTIMENTOS ARGAMASSADOS PAREDE | B13: =Ger_Executivo!H83 -> 148023.32 | C13: =B13/$B$29 -> 0.0035955562 | D13: =B13/'Obra '!$E$9 -> 17.092564 | G13: Mão de Obra Instalação de Portas e Rodapés | H13: =Ger_Executivo!H286 -> 324953.38
A14: REVESTIMENTOS ARGAMASSADOS TETO | C14: =B14/$B$29 -> 0 | D14: =B14/'Obra '!$E$9 -> 0
A15: IMPERMEABILIZAÇÃO | B15: =Ger_Executivo!H94 -> 411650.95 | C15: =B15/$B$29 -> 0.0099991958 | D15: =B15/'Obra '!$E$9 -> 47.534203
A16: ACABAMENTOS INTERNOS EM PAREDE E PISO | B16: =Ger_Executivo!H176+Ger_Executivo!H227 -> 1467903.6 | C16: =B16/$B$29 -> 0.035656072 | D16: =B16/'Obra '!$E$9 -> 169.50193
A17: ACABAMENTOS INTERNOS EM TETO | B17: =Ger_Executivo!H195 -> 1074213 | C17: =B17/$B$29 -> 0.026093141 | D17: =B17/'Obra '!$E$9 -> 124.04164
A18: PINTURA INTERNA | B18: =Ger_Executivo!H199 -> 114895.83 | C18: =B18/$B$29 -> 0.002790874 | D18: =B18/'Obra '!$E$9 -> 13.267264
A19: PINTURA DE FACHADA | B19: =Ger_Executivo!H207 -> 49084.56 | C19: =B19/$B$29 -> 0.0011922871 | D19: =B19/'Obra '!$E$9 -> 5.6678976
A20: REVESTIMENTOS ARGAMASSADOS DE FACHADA | B20: =Ger_Executivo!H86 -> 109937.07 | C20: =B20/$B$29 -> 0.0026704232 | D20: =B20/'Obra '!$E$9 -> 12.694665
A21: ACABAMENTOS DE FACHADA | C21: =B21/$B$29 -> 0 | D21: =B21/'Obra '!$E$9 -> 0
A22: ESQUADRIAS, VIDROS E FERRAGENS | B22: =Ger_Executivo!H212+Ger_Executivo!H236 -> 2816849.7 | C22: =B22/$B$29 -> 0.068422608 | D22: =B22/'Obra '!$E$9 -> 325.26757
A23: LOUÇAS E METAIS | B23: =Ger_Executivo!H249 -> 553892.57 | C23: =B23/$B$29 -> 0.013454312 | D23: =B23/'Obra '!$E$9 -> 63.959142
A24: COBERTURA | B24: =Ger_Executivo!H63 -> 31661.147 | C24: =B24/$B$29 -> 0.0007690642 | D24: =B24/'Obra '!$E$9 -> 3.6559794
A25: SERVIÇOS COMPLEMENTARES | B25: =Ger_Executivo!H246+Ger_Executivo!H271 -> 365403 | C25: =B25/$B$29 -> 0.0088758113 | D25: =B25/'Obra '!$E$9 -> 42.193855
A26: IMPREVISTOS | B26: =Ger_Executivo!H287 -> 291980.48 | C26: =B26/$B$29 -> 0.0070923435 | D26: =B26/'Obra '!$E$9 -> 33.715601
A27: EMPREITADA GLOBAL | B27: =Ger_Executivo!H276 -> 10831779 | C27: =B27/$B$29 -> 0.26310903 | D27: =B27/'Obra '!$E$9 -> 1250.7684
A28: ENXOVAL | B28: ='Custos Enxoval'!N8 -> 10344375 | C28: =B28/$B$29 -> 0.25126975 | D28: =B28/'Obra '!$E$9 -> 1194.4868
A29: TOTAL | B29: =SUM(B2:B28) -> 41168406 | C29: =SUM(C2:C28) -> 1 | D29: =SUM(D2:D28) -> 4753.8026
A30: CUB/SC | B30: ='Obra '!C69 -> 2978.02 | C30: ='Obra '!D69 -> 45870 | D30: =ROUNDUP(+D29/B30,2)&" CUB" -> 1,6 CUB

Sheet Ger_Tec e Adm
G4: PROJETO: | I4: ='Obra '!D1 -> PARKSIDE RIO BRANCO | O4: REVISÃO: | P4: DATA
G5: EMPRESA: | I5: ='Obra '!D2 -> PARKSIDE | O5: ='Obra '!D3 -> R00 - | P5: 45551
A6: Unidade Construtiva | B6: Célula Construtiva | C6: Etapa | D6: Subetapa | E6: Serviço | G6: GERENCIAMENTO EXECUTIVO
A7: 0 | B7: 0 | C7: 0 | D7: 0 | E7: 0 | G7: Atalho | H7: NIVEL | I7: Item | J7: Descrição | K7: Unidade | L7: Quant. | M7: Preço un | N7: Total | O7: Considerações | P7: Situação
A8: =IF($H8="UNIDADE CONSTRUTIVA",OFFSET(A8,-1,0)+1,LARGE(A$3:A7,1)) -> 0 | B8: =IF(H8="UNIDADE CONSTRUTIVA",0,IF(H8="CÉLULA CONSTRUTIVA",OFFSET(B8,-1,0)+1,OFFSET(B8,-1,0))) -> 1 | C8: =IF(H8="CÉLULA CONSTRUTIVA",0,IF(H8="ETAPA",OFFSET(C8,-1,0)+1,OFFSET(C8,-1,0))) -> 0 | D8: =IF(H8="ETAPA",0,IF(H8="SUBETAPA",OFFSET(D8,-1,0)+1,OFFSET(D8,-1,0))) -> 0 | E8: =IF(H8="Subetapa",0,IF(H8="serviço",OFFSET(E8,-1,0)+1,OFFSET(E8,-1,0))) -> 0 | H8: CÉLULA CONSTRUTIVA | I8: =IF(H8="Unidade Construtiva",TEXT(A8,"00"),IF(H8="Célula Construtiva",TEXT(B8,"00"),IF(H8="Etapa",CONCATENATE(TEXT(B8,"00"),".",TEXT(C8,"000")),IF(H8="Subetapa",CONCATENATE(TEXT(B8,"00"),".",TEXT(C8,"000"),".",TEXT(D8,"000")),IF(H8="Serviço",CONCATENATE(TEXT(B8,"00"),".",TEXT(C8,"000"),".",TEXT(D8,"000"),".",TEXT(E8,"000")),""))))) -> 01 | J8: SERVIÇOS TÉCNICOS | N8: =IF(H8="Serviço",M8*L8,IF(H8="CÉLULA CONSTRUTIVA",SUMIFS($N$8:$N$356,$B$8:$B$356,B8,$H$8:$H$356,"Serviço"),IF(H8="ETAPA",SUMIFS($N$8:$N$356,$B$8:$B$356,B8,$C$8:$C$356,C8,$H$8:$H$356,"Serviço"),IF(H8="SUBETAPA",SUMIFS($N$8:$N$356,$B$8:$B$356,B8,$C$8:$C$356,C8,$D$8:$D$356,D8,$H$8:$H$356,"Serviço"),0)))) -> 412448.85
A9: =IF($H9="UNIDADE CONSTRUTIVA",OFFSET(A9,-1,0)+1,LARGE(A$3:A8,1)) -> 0 | B9: =IF(H9="UNIDADE CONSTRUTIVA",0,IF(H9="CÉLULA CONSTRUTIVA",OFFSET(B9,-1,0)+1,OFFSET(B9,-1,0))) -> 1 | C9: =IF(H9="CÉLULA CONSTRUTIVA",0,IF(H9="ETAPA",OFFSET(C9,-1,0)+1,OFFSET(C9,-1,0))) -> 1 | D9: =IF(H9="ETAPA",0,IF(H9="SUBETAPA",OFFSET(D9,-1,0)+1,OFFSET(D9,-1,0))) -> 0 | E9: =IF(H9="Subetapa",0,IF(H9="serviço",OFFSET(E9,-1,0)+1,OFFSET(E9,-1,0))) -> 0 | H9: ETAPA | I9: =IF(H9="Unidade Construtiva",TEXT(A9,"00"),IF(H9="Célula Construtiva",TEXT(B9,"00"),IF(H9="Etapa",CONCATENATE(TEXT(B9,"00"),".",TEXT(C9,"000")),IF(H9="Subetapa",CONCATENATE(TEXT(B9,"00"),".",TEXT(C9,"000"),".",TEXT(D9,"000")),IF(H9="Serviço",CONCATENATE(TEXT(B9,"00"),".",TEXT(C9,"000"),".",TEXT(D9,"000"),".",TEXT(E9,"000")),""))))) -> 01.001 | J9: SERVIÇOS DE ENGENHARIA | N9: =IF(H9="Serviço",M9*L9,IF(H9="CÉLULA CONSTRUTIVA",SUMIFS($N$8:$N$356,$B$8:$B$356,B9,$H$8:$H$356,"Serviço"),IF(H9="ETAPA",SUMIFS($N$8:$N$356,$B$8:$B$356,B9,$C$8:$C$356,C9,$H$8:$H$356,"Serviço"),IF(H9="SUBETAPA",SUMIFS($N$8:$N$356,$B$8:$B$356,B9,$C$8:$C$356,C9,$D$8:$D$356,D9,$H$8:$H$356,"Serviço"),0)))) -> 412448.85
A10: =IF($H10="UNIDADE CONSTRUTIVA",OFFSET(A10,-1,0)+1,LARGE(A$3:A9,1)) -> 0 | B10: =IF(H10="UNIDADE CONSTRUTIVA",0,IF(H10="CÉLULA CONSTRUTIVA",OFFSET(B10,-1,0)+1,OFFSET(B10,-1,0))) -> 1 | C10: =IF(H10="CÉLULA CONSTRUTIVA",0,IF(H10="ETAPA",OFFSET(C10,-1,0)+1,OFFSET(C10,-1,0))) -> 1 | D10: =IF(H10="ETAPA",0,IF(H10="SUBETAPA",OFFSET(D10,-1,0)+1,OFFSET(D10,-1,0))) -> 1 | E10: =IF(H10="Subetapa",0,IF(H10="serviço",OFFSET(E10,-1,0)+1,OFFSET(E10,-1,0))) -> 0 | H10: SUBETAPA | I10: =IF(H10="Unidade Construtiva",TEXT(A10,"00"),IF(H10="Célula Construtiva",TEXT(B10,"00"),IF(H10="Etapa",CONCATENATE(TEXT(B10,"00"),".",TEXT(C10,"000")),IF(H10="Subetapa",CONCATENATE(TEXT(B10,"00"),".",TEXT(C10,"000"),".",TEXT(D10,"000")),IF(H10="Serviço",CONCATENATE(TEXT(B10,"00"),".",TEXT(C10,"000"),".",TEXT(D10,"000"),".",TEXT(E10,"000")),""))))) -> 01.001.001 | J10: PROJETOS | N10: =IF(H10="Serviço",M10*L10,IF(H10="CÉLULA CONSTRUTIVA",SUMIFS($N$8:$N$356,$B$8:$B$356,B10,$H$8:$H$356,"Serviço"),IF(H10="ETAPA",SUMIFS($N$8:$N$356,$B$8:$B$356,B10,$C$8:$C$356,C10,$H$8:$H$356,"Serviço"),IF(H10="SUBETAPA",SUMIFS($N$8:$N$356,$B$8:$B$356,B10,$C$8:$C$356,C10,$D$8:$D$356,D10,$H$8:$H$356,"Serviço"),0)))) -> 17060.944
A11: =IF($H11="UNIDADE CONSTRUTIVA",OFFSET(A11,-1,0)+1,LARGE(A$3:A10,1)) -> 0 | B11: =IF(H11="UNIDADE CONSTRUTIVA",0,IF(H11="CÉLULA CONSTRUTIVA",OFFSET(B11,-1,0)+1,OFFSET(B11,-1,0))) -> 1 | C11: =IF(H11="CÉLULA CONSTRUTIVA",0,IF(H11="ETAPA",OFFSET(C11,-1,0)+1,OFFSET(C11,-1,0))) -> 1 | D11: =IF(H11="ETAPA",0,IF(H11="SUBETAPA",OFFSET(D11,-1,0)+1,OFFSET(D11,-1,0))) -> 1 | E11: =IF(H11="Subetapa",0,IF(H11="serviço",OFFSET(E11,-1,0)+1,OFFSET(E11,-1,0))) -> 1 | H11: SERVIÇO | I11: =IF(H11="Unidade Construtiva",TEXT(A11,"00"),IF(H11="Célula Construtiva",TEXT(B11,"00"),IF(H11="Etapa",CONCATENATE(TEXT(B11,"00"),".",TEXT(C11,"000")),IF(H11="Subetapa",CONCATENATE(TEXT(B11,"00"),".",TEXT(C11,"000"),".",TEXT(D11,"000")),IF(H11="Serviço",CONCATENATE(TEXT(B11,"00"),".",TEXT(C11,"000"),".",TEXT(D11,"000"),".",TEXT(E11,"000")),""))))) -> 01.001.001.001 | J11: Projeto de Canteiro | K11: vb | L11: 1 | M11: 6174.8985 | N11: =IF(H11="Serviço",M11*L11,IF(H11="CÉLULA CONSTRUTIVA",SUMIFS($N$8:$N$356,$B$8:$B$356,B11,$H$8:$H$356,"Serviço"),IF(H11="ETAPA",SUMIFS($N$8:$N$356,$B$8:$B$356,B11,$C$8:$C$356,C11,$H$8:$H$356,"Serviço"),IF(H11="SUBETAPA",SUMIFS($N$8:$N$356,$B$8:$B$356,B11,$C$8:$C$356,C11,$D$8:$D$356,D11,$H$8:$H$356,"Serviço"),0)))) -> 6174.8985 | O11: Estimado com base em índices históricos | P11: Finalizado
A12: =IF($H12="UNIDADE CONSTRUTIVA",OFFSET(A12,-1,0)+1,LARGE(A$3:A11,1)) -> 0 | B12: =IF(H12="UNIDADE CONSTRUTIVA",0,IF(H12="CÉLULA CONSTRUTIVA",OFFSET(B12,-1,0)+1,OFFSET(B12,-1,0))) -> 1 | C12: =IF(H12="CÉLULA CONSTRUTIVA",0,IF(H12="ETAPA",OFFSET(C12,-1,0)+1,OFFSET(C12,-1,0))) -> 1 | D12: =IF(H12="ETAPA",0,IF(H12="SUBETAPA",OFFSET(D12,-1,0)+1,OFFSET(D12,-1,0))) -> 1 | E12: =IF(H12="Subetapa",0,IF(H12="serviço",OFFSET(E12,-1,0)+1,OFFSET(E12,-1,0))) -> 2 | H12: SERVIÇO | I12: =IF(H12="Unidade Construtiva",TEXT(A12,"00"),IF(H12="Célula Construtiva",TEXT(B12,"00"),IF(H12="Etapa",CONCATENATE(TEXT(B12,"00"),".",TEXT(C12,"000")),IF(H12="Subetapa",CONCATENATE(TEXT(B12,"00"),".",TEXT(C12,"000"),".",TEXT(D12,"000")),IF(H12="Serviço",CONCATENATE(TEXT(B12,"00"),".",TEXT(C12,"000"),".",TEXT(D12,"000"),".",TEXT(E12,"000")),""))))) -> 01.001.001.002 | J12: Estimativas / Sondagens | K12: vb | L12: 1 | M12: 10886.045 | N12: =IF(H12="Serviço",M12*L12,IF(H12="CÉLULA CONSTRUTIVA",SUMIFS($N$8:$N$356,$B$8:$B$356,B12,$H$8:$H$356,"Serviço"),IF(H12="ETAPA",SUMIFS($N$8:$N$356,$B$8:$B$356,B12,$C$8:$C$356,C12,$H$8:$H$356,"Serviço"),IF(H12="SUBETAPA",SUMIFS($N$8:$N$356,$B$8:$B$356,B12,$C$8:$C$356,C12,$D$8:$D$356,D12,$H$8:$H$356,"Serviço"),0)))) -> 10886.045 | O12: Estimado com base em índices históricos | P12: Finalizado
A13: =IF($H13="UNIDADE CONSTRUTIVA",OFFSET(A13,-1,0)+1,LARGE(A$3:A12,1)) -> 0 | B13: =IF(H13="UNIDADE CONSTRUTIVA",0,IF(H13="CÉLULA CONSTRUTIVA",OFFSET(B13,-1,0)+1,OFFSET(B13,-1,0))) -> 1 | C13: =IF(H13="CÉLULA CONSTRUTIVA",0,IF(H13="ETAPA",OFFSET(C13,-1,0)+1,OFFSET(C13,-1,0))) -> 1 | D13: =IF(H13="ETAPA",0,IF(H13="SUBETAPA",OFFSET(D13,-1,0)+1,OFFSET(D13,-1,0))) -> 2 | E13: =IF(H13="Subetapa",0,IF(H13="serviço",OFFSET(E13,-1,0)+1,OFFSET(E13,-1,0))) -> 0 | H13: SUBETAPA | I13: =IF(H13="Unidade Construtiva",TEXT(A13,"00"),IF(H13="Célula Construtiva",TEXT(B13,"00"),IF(H13="Etapa",CONCATENATE(TEXT(B13,"00"),".",TEXT(C13,"000")),IF(H13="Subetapa",CONCATENATE(TEXT(B13,"00"),".",TEXT(C13,"000"),".",TEXT(D13,"000")),IF(H13="Serviço",CONCATENATE(TEXT(B13,"00"),".",TEXT(C13,"000"),".",TEXT(D13,"000"),".",TEXT(E13,"000")),""))))) -> 01.001.002 | J13: CONSULTORIAS EXTERNAS | N13: =IF(H13="Serviço",M13*L13,IF(H13="CÉLULA CONSTRUTIVA",SUMIFS($N$8:$N$356,$B$8:$B$356,B13,$H$8:$H$356,"Serviço"),IF(H13="ETAPA",SUMIFS($N$8:$N$356,$B$8:$B$356,B13,$C$8:$C$356,C13,$H$8:$H$356,"Serviço"),IF(H13="SUBETAPA",SUMIFS($N$8:$N$356,$B$8:$B$356,B13,$C$8:$C$356,C13,$D$8:$D$356,D13,$H$8:$H$356,"Serviço"),0)))) -> 367830.52
A14: =IF($H14="UNIDADE CONSTRUTIVA",OFFSET(A14,-1,0)+1,LARGE(A$3:A13,1)) -> 0 | B14: =IF(H14="UNIDADE CONSTRUTIVA",0,IF(H14="CÉLULA CONSTRUTIVA",OFFSET(B14,-1,0)+1,OFFSET(B14,-1,0))) -> 1 | C14: =IF(H14="CÉLULA CONSTRUTIVA",0,IF(H14="ETAPA",OFFSET(C14,-1,0)+1,OFFSET(C14,-1,0))) -> 1 | D14: =IF(H14="ETAPA",0,IF(H14="SUBETAPA",OFFSET(D14,-1,0)+1,OFFSET(D14,-1,0))) -> 2 | E14: =IF(H14="Subetapa",0,IF(H14="serviço",OFFSET(E14,-1,0)+1,OFFSET(E14,-1,0))) -> 1 | H14: SERVIÇO | I14: =IF(H14="Unidade Construtiva",TEXT(A14,"00"),IF(H14="Célula Construtiva",TEXT(B14,"00"),IF(H14="Etapa",CONCATENATE(TEXT(B14,"00"),".",TEXT(C14,"000")),IF(H14="Subetapa",CONCATENATE(TEXT(B14,"00"),".",TEXT(C14,"000"),".",TEXT(D14,"000")),IF(H14="Serviço",CONCATENATE(TEXT(B14,"00"),".",TEXT(C14,"000"),".",TEXT(D14,"000"),".",TEXT(E14,"000")),""))))) -> 01.001.002.001 | J14: Programa de Segurança do Trabalho (PCMAT) | K14: vb | L14: 1 | M14: 5665.1418 | N14: =IF(H14="Serviço",M14*L14,IF(H14="CÉLULA CONSTRUTIVA",SUMIFS($N$8:$N$356,$B$8:$B$356,B14,$H$8:$H$356,"Serviço"),IF(H14="ETAPA",SUMIFS($N$8:$N$356,$B$8:$B$356,B14,$C$8:$C$356,C14,$H$8:$H$356,"Serviço"),IF(H14="SUBETAPA",SUMIFS($N$8:$N$356,$B$8:$B$356,B14,$C$8:$C$356,C14,$D$8:$D$356,D14,$H$8:$H$356,"Serviço"),0)))) -> 5665.1418 | O14: Estimado com base em índices históricos | P14: Finalizado
A15: =IF($H15="UNIDADE CONSTRUTIVA",OFFSET(A15,-1,0)+1,LARGE(A$3:A14,1)) -> 0 | B15: =IF(H15="UNIDADE CONSTRUTIVA",0,IF(H15="CÉLULA CONSTRUTIVA",OFFSET(B15,-1,0)+1,OFFSET(B15,-1,0))) -> 1 | C15: =IF(H15="CÉLULA CONSTRUTIVA",0,IF(H15="ETAPA",OFFSET(C15,-1,0)+1,OFFSET(C15,-1,0))) -> 1 | D15: =IF(H15="ETAPA",0,IF(H15="SUBETAPA",OFFSET(D15,-1,0)+1,OFFSET(D15,-1,0))) -> 2 | E15: =IF(H15="Subetapa",0,IF(H15="serviço",OFFSET(E15,-1,0)+1,OFFSET(E15,-1,0))) -> 2 | H15: SERVIÇO | I15: =IF(H15="Unidade Construtiva",TEXT(A15,"00"),IF(H15="Célula Construtiva",TEXT(B15,"00"),IF(H15="Etapa",CONCATENATE(TEXT(B15,"00"),".",TEXT(C15,"000")),IF(H15="Subetapa",CONCATENATE(TEXT(B15,"00"),".",TEXT(C15,"000"),".",TEXT(D15,"000")),IF(H15="Serviço",CONCATENATE(TEXT(B15,"00"),".",TEXT(C15,"000"),".",TEXT(D15,"000"),".",TEXT(E15,"000")),""))))) -> 01.001.002.002 | J15: Consultoria em Segurança do Trabalho | K15: mês | L15: 33 | M15: 10565.322 | N15: =IF(H15="Serviço",M15*L15,IF(H15="CÉLULA CONSTRUTIVA",SUMIFS($N$8:$N$356,$B$8:$B$356,B15,$H$8:$H$356,"Serviço"),IF(H15="ETAPA",SUMIFS($N$8:$N$356,$B$8:$B$356,B15,$C$8:$C$356,C15,$H$8:$H$356,"Serviço"),IF(H15="SUBETAPA",SUMIFS($N$8:$N$356,$B$8:$B$356,B15,$C$8:$C$356,C15,$D$8:$D$356,D15,$H$8:$H$356,"Serviço"),0)))) -> 348655.63 | O15: Estimado com base em índices históricos | P15: Finalizado
A16: =IF($H16="UNIDADE CONSTRUTIVA",OFFSET(A16,-1,0)+1,LARGE(A$3:A15,1)) -> 0 | B16: =IF(H16="UNIDADE CONSTRUTIVA",0,IF(H16="CÉLULA CONSTRUTIVA",OFFSET(B16,-1,0)+1,OFFSET(B16,-1,0))) -> 1 | C16: =IF(H16="CÉLULA CONSTRUTIVA",0,IF(H16="ETAPA",OFFSET(C16,-1,0)+1,OFFSET(C16,-1,0))) -> 1 | D16: =IF(H16="ETAPA",0,IF(H16="SUBETAPA",OFFSET(D16,-1,0)+1,OFFSET(D16,-1,0))) -> 2 | E16: =IF(H16="Subetapa",0,IF(H16="serviço",OFFSET(E16,-1,0)+1,OFFSET(E16,-1,0))) -> 3 | H16: SERVIÇO | I16: =IF(H16="Unidade Construtiva",TEXT(A16,"00"),IF(H16="Célula Construtiva",TEXT(B16,"00"),IF(H16="Etapa",CONCATENATE(TEXT(B16,"00"),".",TEXT(C16,"000")),IF(H16="Subetapa",CONCATENATE(TEXT(B16,"00"),".",TEXT(C16,"000"),".",TEXT(D16,"000")),IF(H16="Serviço",CONCATENATE(TEXT(B16,"00"),".",TEXT(C16,"000"),".",TEXT(D16,"000"),".",TEXT(E16,"000")),""))))) -> 01.001.002.003 | J16: Laudos e Vistorias / Vistoria Cautelar de Vizinhança | K16: vb | L16: 1 | M16: 13509.756 | N16: =IF(H16="Serviço",M16*L16,IF(H16="CÉLULA CONSTRUTIVA",SUMIFS($N$8:$N$356,$B$8:$B$356,B16,$H$8:$H$356,"Serviço"),IF(H16="ETAPA",SUMIFS($N$8:$N$356,$B$8:$B$356,B16,$C$8:$C$356,C16,$H$8:$H$356,"Serviço"),IF(H16="SUBETAPA",SUMIFS($N$8:$N$356,$B$8:$B$356,B16,$C$8:$C$356,C16,$D$8:$D$356,D16,$H$8:$H$356,"Serviço"),0)))) -> 13509.756 | O16: Estimado com base em índices históricos | P16: Finalizado
A17: =IF($H17="UNIDADE CONSTRUTIVA",OFFSET(A17,-1,0)+1,LARGE(A$3:A16,1)) -> 0 | B17: =IF(H17="UNIDADE CONSTRUTIVA",0,IF(H17="CÉLULA CONSTRUTIVA",OFFSET(B17,-1,0)+1,OFFSET(B17,-1,0))) -> 1 | C17: =IF(H17="CÉLULA CONSTRUTIVA",0,IF(H17="ETAPA",OFFSET(C17,-1,0)+1,OFFSET(C17,-1,0))) -> 1 | D17: =IF(H17="ETAPA",0,IF(H17="SUBETAPA",OFFSET(D17,-1,0)+1,OFFSET(D17,-1,0))) -> 3 | E17: =IF(H17="Subetapa",0,IF(H17="serviço",OFFSET(E17,-1,0)+1,OFFSET(E17,-1,0))) -> 0 | H17: SUBETAPA | I17: =IF(H17="Unidade Construtiva",TEXT(A17,"00"),IF(H17="Célula Construtiva",TEXT(B17,"00"),IF(H17="Etapa",CONCATENATE(TEXT(B17,"00"),".",TEXT(C17,"000")),IF(H17="Subetapa",CONCATENATE(TEXT(B17,"00"),".",TEXT(C17,"000"),".",TEXT(D17,"000")),IF(H17="Serviço",CONCATENATE(TEXT(B17,"00"),".",TEXT(C17,"000"),".",TEXT(D17,"000"),".",TEXT(E17,"000")),""))))) -> 01.001.003 | J17: SEGUROS | N17: =IF(H17="Serviço",M17*L17,IF(H17="CÉLULA CONSTRUTIVA",SUMIFS($N$8:$N$356,$B$8:$B$356,B17,$H$8:$H$356,"Serviço"),IF(H17="ETAPA",SUMIFS($N$8:$N$356,$B$8:$B$356,B17,$C$8:$C$356,C17,$H$8:$H$356,"Serviço"),IF(H17="SUBETAPA",SUMIFS($N$8:$N$356,$B$8:$B$356,B17,$C$8:$C$356,C17,$D$8:$D$356,D17,$H$8:$H$356,"Serviço"),0)))) -> 24373.298
A18: =IF($H18="UNIDADE CONSTRUTIVA",OFFSET(A18,-1,0)+1,LARGE(A$3:A17,1)) -> 0 | B18: =IF(H18="UNIDADE CONSTRUTIVA",0,IF(H18="CÉLULA CONSTRUTIVA",OFFSET(B18,-1,0)+1,OFFSET(B18,-1,0))) -> 1 | C18: =IF(H18="CÉLULA CONSTRUTIVA",0,IF(H18="ETAPA",OFFSET(C18,-1,0)+1,OFFSET(C18,-1,0))) -> 1 | D18: =IF(H18="ETAPA",0,IF(H18="SUBETAPA",OFFSET(D18,-1,0)+1,OFFSET(D18,-1,0))) -> 3 | E18: =IF(H18="Subetapa",0,IF(H18="serviço",OFFSET(E18,-1,0)+1,OFFSET(E18,-1,0))) -> 1 | H18: SERVIÇO | I18: =IF(H18="Unidade Construtiva",TEXT(A18,"00"),IF(H18="Célula Construtiva",TEXT(B18,"00"),IF(H18="Etapa",CONCATENATE(TEXT(B18,"00"),".",TEXT(C18,"000")),IF(H18="Subetapa",CONCATENATE(TEXT(B18,"00"),".",TEXT(C18,"000"),".",TEXT(D18,"000")),IF(H18="Serviço",CONCATENATE(TEXT(B18,"00"),".",TEXT(C18,"000"),".",TEXT(D18,"000"),".",TEXT(E18,"000")),""))))) -> 01.001.003.001 | J18: Seguros de Obra | K18: vb | L18: 1 | M18: 24373.297 | N18: =IF(H18="Serviço",M18*L18,IF(H18="CÉLULA CONSTRUTIVA",SUMIFS($N$8:$N$356,$B$8:$B$356,B18,$H$8:$H$356,"Serviço"),IF(H18="ETAPA",SUMIFS($N$8:$N$356,$B$8:$B$356,B18,$C$8:$C$356,C18,$H$8:$H$356,"Serviço"),IF(H18="SUBETAPA",SUMIFS($N$8:$N$356,$B$8:$B$356,B18,$C$8:$C$356,C18,$D$8:$D$356,D18,$H$8:$H$356,"Serviço"),0)))) -> 24373.298 | O18: Estimado com base em índices históricos | P18: Finalizado
A19: =IF($H19="UNIDADE CONSTRUTIVA",OFFSET(A19,-1,0)+1,LARGE(A$3:A18,1)) -> 0 | B19: =IF(H19="UNIDADE CONSTRUTIVA",0,IF(H19="CÉLULA CONSTRUTIVA",OFFSET(B19,-1,0)+1,OFFSET(B19,-1,0))) -> 1 | C19: =IF(H19="CÉLULA CONSTRUTIVA",0,IF(H19="ETAPA",OFFSET(C19,-1,0)+1,OFFSET(C19,-1,0))) -> 1 | D19: =IF(H19="ETAPA",0,IF(H19="SUBETAPA",OFFSET(D19,-1,0)+1,OFFSET(D19,-1,0))) -> 4 | E19: =IF(H19="Subetapa",0,IF(H19="serviço",OFFSET(E19,-1,0)+1,OFFSET(E19,-1,0))) -> 0 | H19: SUBETAPA | I19: =IF(H19="Unidade Construtiva",TEXT(A19,"00"),IF(H19="Célula Construtiva",TEXT(B19,"00"),IF(H19="Etapa",CONCATENATE(TEXT(B19,"00"),".",TEXT(C19,"000")),IF(H19="Subetapa",CONCATENATE(TEXT(B19,"00"),".",TEXT(C19,"000"),".",TEXT(D19,"000")),IF(H19="Serviço",CONCATENATE(TEXT(B19,"00"),".",TEXT(C19,"000"),".",TEXT(D19,"000"),".",TEXT(E19,"000")),""))))) -> 01.001.004 | J19: TAXAS E OUTROS | N19: =IF(H19="Serviço",M19*L19,IF(H19="CÉLULA CONSTRUTIVA",SUMIFS($N$8:$N$356,$B$8:$B$356,B19,$H$8:$H$356,"Serviço"),IF(H19="ETAPA",SUMIFS($N$8:$N$356,$B$8:$B$356,B19,$C$8:$C$356,C19,$H$8:$H$356,"Serviço"),IF(H19="SUBETAPA",SUMIFS($N$8:$N$356,$B$8:$B$356,B19,$C$8:$C$356,C19,$D$8:$D$356,D19,$H$8:$H$356,"Serviço"),0)))) -> 3184.0855
A20: =IF($H20="UNIDADE CONSTRUTIVA",OFFSET(A20,-1,0)+1,LARGE(A$3:A19,1)) -> 0 | B20: =IF(H20="UNIDADE CONSTRUTIVA",0,IF(H20="CÉLULA CONSTRUTIVA",OFFSET(B20,-1,0)+1,OFFSET(B20,-1,0))) -> 1 | C20: =IF(H20="CÉLULA CONSTRUTIVA",0,IF(H20="ETAPA",OFFSET(C20,-1,0)+1,OFFSET(C20,-1,0))) -> 1 | D20: =IF(H20="ETAPA",0,IF(H20="SUBETAPA",OFFSET(D20,-1,0)+1,OFFSET(D20,-1,0))) -> 4 | E20: =IF(H20="Subetapa",0,IF(H20="serviço",OFFSET(E20,-1,0)+1,OFFSET(E20,-1,0))) -> 1 | H20: SERVIÇO | I20: =IF(H20="Unidade Construtiva",TEXT(A20,"00"),IF(H20="Célula Construtiva",TEXT(B20,"00"),IF(H20="Etapa",CONCATENATE(TEXT(B20,"00"),".",TEXT(C20,"000")),IF(H20="Subetapa",CONCATENATE(TEXT(B20,"00"),".",TEXT(C20,"000"),".",TEXT(D20,"000")),IF(H20="Serviço",CONCATENATE(TEXT(B20,"00"),".",TEXT(C20,"000"),".",TEXT(D20,"000"),".",TEXT(E20,"000")),""))))) -> 01.001.004.001 | J20: ART de Execução | K20: vb | L20: 1 | M20: 3184.0855 | N20: =IF(H20="Serviço",M20*L20,IF(H20="CÉLULA CONSTRUTIVA",SUMIFS($N$8:$N$356,$B$8:$B$356,B20,$H$8:$H$356,"Serviço"),IF(H20="ETAPA",SUMIFS($N$8:$N$356,$B$8:$B$356,B20,$C$8:$C$356,C20,$H$8:$H$356,"Serviço"),IF(H20="SUBETAPA",SUMIFS($N$8:$N$356,$B$8:$B$356,B20,$C$8:$C$356,C20,$D$8:$D$356,D20,$H$8:$H$356,"Serviço"),0)))) -> 3184.0855 | O20: Estimado com base em índices históricos | P20: Finalizado
A21: =IF($H21="UNIDADE CONSTRUTIVA",OFFSET(A21,-1,0)+1,LARGE(A$3:A20,1)) -> 0 | B21: =IF(H21="UNIDADE CONSTRUTIVA",0,IF(H21="CÉLULA CONSTRUTIVA",OFFSET(B21,-1,0)+1,OFFSET(B21,-1,0))) -> 2 | C21: =IF(H21="CÉLULA CONSTRUTIVA",0,IF(H21="ETAPA",OFFSET(C21,-1,0)+1,OFFSET(C21,-1,0))) -> 0 | D21: =IF(H21="ETAPA",0,IF(H21="SUBETAPA",OFFSET(D21,-1,0)+1,OFFSET(D21,-1,0))) -> 4 | E21: =IF(H21="Subetapa",0,IF(H21="serviço",OFFSET(E21,-1,0)+1,OFFSET(E21,-1,0))) -> 1 | H21: CÉLULA CONSTRUTIVA | I21: =IF(H21="Unidade Construtiva",TEXT(A21,"00"),IF(H21="Célula Construtiva",TEXT(B21,"00"),IF(H21="Etapa",CONCATENATE(TEXT(B21,"00"),".",TEXT(C21,"000")),IF(H21="Subetapa",CONCATENATE(TEXT(B21,"00"),".",TEXT(C21,"000"),".",TEXT(D21,"000")),IF(H21="Serviço",CONCATENATE(TEXT(B21,"00"),".",TEXT(C21,"000"),".",TEXT(D21,"000"),".",TEXT(E21,"000")),""))))) -> 02 | J21: SERVIÇOS PRELIMINARES E CANTEIRO | N21: =IF(H21="Serviço",M21*L21,IF(H21="CÉLULA CONSTRUTIVA",SUMIFS($N$8:$N$356,$B$8:$B$356,B21,$H$8:$H$356,"Serviço"),IF(H21="ETAPA",SUMIFS($N$8:$N$356,$B$8:$B$356,B21,$C$8:$C$356,C21,$H$8:$H$356,"Serviço"),IF(H21="SUBETAPA",SUMIFS($N$8:$N$356,$B$8:$B$356,B21,$C$8:$C$356,C21,$D$8:$D$356,D21,$H$8:$H$356,"Serviço"),0)))) -> 921553.96
A22: =IF($H22="UNIDADE CONSTRUTIVA",OFFSET(A22,-1,0)+1,LARGE(A$3:A20,1)) -> 0 | B22: =IF(H22="UNIDADE CONSTRUTIVA",0,IF(H22="CÉLULA CONSTRUTIVA",OFFSET(B22,-1,0)+1,OFFSET(B22,-1,0))) -> 2 | C22: =IF(H22="CÉLULA CONSTRUTIVA",0,IF(H22="ETAPA",OFFSET(C22,-1,0)+1,OFFSET(C22,-1,0))) -> 1 | D22: =IF(H22="ETAPA",0,IF(H22="SUBETAPA",OFFSET(D22,-1,0)+1,OFFSET(D22,-1,0))) -> 0 | E22: =IF(H22="Subetapa",0,IF(H22="serviço",OFFSET(E22,-1,0)+1,OFFSET(E22,-1,0))) -> 1 | H22: ETAPA | I22: =IF(H22="Unidade Construtiva",TEXT(A22,"00"),IF(H22="Célula Construtiva",TEXT(B22,"00"),IF(H22="Etapa",CONCATENATE(TEXT(B22,"00"),".",TEXT(C22,"000")),IF(H22="Subetapa",CONCATENATE(TEXT(B22,"00"),".",TEXT(C22,"000"),".",TEXT(D22,"000")),IF(H22="Serviço",CONCATENATE(TEXT(B22,"00"),".",TEXT(C22,"000"),".",TEXT(D22,"000"),".",TEXT(E22,"000")),""))))) -> 02.001 | J22: DESPESAS INDIRETAS | N22: =IF(H22="Serviço",M22*L22,IF(H22="CÉLULA CONSTRUTIVA",SUMIFS($N$8:$N$356,$B$8:$B$356,B22,$H$8:$H$356,"Serviço"),IF(H22="ETAPA",SUMIFS($N$8:$N$356,$B$8:$B$356,B22,$C$8:$C$356,C22,$H$8:$H$356,"Serviço"),IF(H22="SUBETAPA",SUMIFS($N$8:$N$356,$B$8:$B$356,B22,$C$8:$C$356,C22,$D$8:$D$356,D22,$H$8:$H$356,"Serviço"),0)))) -> 397448.76
A23: =IF($H23="UNIDADE CONSTRUTIVA",OFFSET(A23,-1,0)+1,LARGE(A$3:A22,1)) -> 0 | B23: =IF(H23="UNIDADE CONSTRUTIVA",0,IF(H23="CÉLULA CONSTRUTIVA",OFFSET(B23,-1,0)+1,OFFSET(B23,-1,0))) -> 2 | C23: =IF(H23="CÉLULA CONSTRUTIVA",0,IF(H23="ETAPA",OFFSET(C23,-1,0)+1,OFFSET(C23,-1,0))) -> 1 | D23: =IF(H23="ETAPA",0,IF(H23="SUBETAPA",OFFSET(D23,-1,0)+1,OFFSET(D23,-1,0))) -> 1 | E23: =IF(H23="Subetapa",0,IF(H23="serviço",OFFSET(E23,-1,0)+1,OFFSET(E23,-1,0))) -> 0 | H23: SUBETAPA | I23: =IF(H23="Unidade Construtiva",TEXT(A23,"00"),IF(H23="Célula Construtiva",TEXT(B23,"00"),IF(H23="Etapa",CONCATENATE(TEXT(B23,"00"),".",TEXT(C23,"000")),IF(H23="Subetapa",CONCATENATE(TEXT(B23,"00"),".",TEXT(C23,"000"),".",TEXT(D23,"000")),IF(H23="Serviço",CONCATENATE(TEXT(B23,"00"),".",TEXT(C23,"000"),".",TEXT(D23,"000"),".",TEXT(E23,"000")),""))))) -> 02.001.001 | J23: DESPESAS INDIRETAS | N23: =IF(H23="Serviço",M23*L23,IF(H23="CÉLULA CONSTRUTIVA",SUMIFS($N$8:$N$356,$B$8:$B$356,B23,$H$8:$H$356,"Serviço"),IF(H23="ETAPA",SUMIFS($N$8:$N$356,$B$8:$B$356,B23,$C$8:$C$356,C23,$H$8:$H$356,"Serviço"),IF(H23="SUBETAPA",SUMIFS($N$8:$N$356,$B$8:$B$356,B23,$C$8:$C$356,C23,$D$8:$D$356,D23,$H$8:$H$356,"Serviço"),0)))) -> 397448.76
A24: =IF($H24="UNIDADE CONSTRUTIVA",OFFSET(A24,-1,0)+1,LARGE(A$3:A23,1)) -> 0 | B24: =IF(H24="UNIDADE CONSTRUTIVA",0,IF(H24="CÉLULA CONSTRUTIVA",OFFSET(B24,-1,0)+1,OFFSET(B24,-1,0))) -> 2 | C24: =IF(H24="CÉLULA CONSTRUTIVA",0,IF(H24="ETAPA",OFFSET(C24,-1,0)+1,OFFSET(C24,-1,0))) -> 1 | D24: =IF(H24="ETAPA",0,IF(H24="SUBETAPA",OFFSET(D24,-1,0)+1,OFFSET(D24,-1,0))) -> 1 | E24: =IF(H24="Subetapa",0,IF(H24="serviço",OFFSET(E24,-1,0)+1,OFFSET(E24,-1,0))) -> 1 | H24: SERVIÇO | I24: =IF(H24="Unidade Construtiva",TEXT(A24,"00"),IF(H24="Célula Construtiva",TEXT(B24,"00"),IF(H24="Etapa",CONCATENATE(TEXT(B24,"00"),".",TEXT(C24,"000")),IF(H24="Subetapa",CONCATENATE(TEXT(B24,"00"),".",TEXT(C24,"000"),".",TEXT(D24,"000")),IF(H24="Serviço",CONCATENATE(TEXT(B24,"00"),".",TEXT(C24,"000"),".",TEXT(D24,"000"),".",TEXT(E24,"000")),""))))) -> 02.001.001.001 | J24: Consumo de Água | K24: mes | L24: 33 | M24: 1621.5412 | N24: =IF(H24="Serviço",M24*L24,IF(H24="CÉLULA CONSTRUTIVA",SUMIFS($N$8:$N$356,$B$8:$B$356,B24,$H$8:$H$356,"Serviço"),IF(H24="ETAPA",SUMIFS($N$8:$N$356,$B$8:$B$356,B24,$C$8:$C$356,C24,$H$8:$H$356,"Serviço"),IF(H24="SUBETAPA",SUMIFS($N$8:$N$356,$B$8:$B$356,B24,$C$8:$C$356,C24,$D$8:$D$356,D24,$H$8:$H$356,"Serviço"),0)))) -> 53510.86 | O24: Estimado com base em índices históricos | P24: Finalizado
A25: =IF($H25="UNIDADE CONSTRUTIVA",OFFSET(A25,-1,0)+1,LARGE(A$3:A24,1)) -> 0 | B25: =IF(H25="UNIDADE CONSTRUTIVA",0,IF(H25="CÉLULA CONSTRUTIVA",OFFSET(B25,-1,0)+1,OFFSET(B25,-1,0))) -> 2 | C25: =IF(H25="CÉLULA CONSTRUTIVA",0,IF(H25="ETAPA",OFFSET(C25,-1,0)+1,OFFSET(C25,-1,0))) -> 1 | D25: =IF(H25="ETAPA",0,IF(H25="SUBETAPA",OFFSET(D25,-1,0)+1,OFFSET(D25,-1,0))) -> 1 | E25: =IF(H25="Subetapa",0,IF(H25="serviço",OFFSET(E25,-1,0)+1,OFFSET(E25,-1,0))) -> 2 | H25: SERVIÇO | I25: =IF(H25="Unidade Construtiva",TEXT(A25,"00"),IF(H25="Célula Construtiva",TEXT(B25,"00"),IF(H25="Etapa",CONCATENATE(TEXT(B25,"00"),".",TEXT(C25,"000")),IF(H25="Subetapa",CONCATENATE(TEXT(B25,"00"),".",TEXT(C25,"000"),".",TEXT(D25,"000")),IF(H25="Serviço",CONCATENATE(TEXT(B25,"00"),".",TEXT(C25,"000"),".",TEXT(D25,"000"),".",TEXT(E25,"000")),""))))) -> 02.001.001.002 | J25: Consumo de Telefone e Internet | K25: mes | L25: 33 | M25: 379.4236 | N25: =IF(H25="Serviço",M25*L25,IF(H25="CÉLULA CONSTRUTIVA",SUMIFS($N$8:$N$356,$B$8:$B$356,B25,$H$8:$H$356,"Serviço"),IF(H25="ETAPA",SUMIFS($N$8:$N$356,$B$8:$B$356,B25,$C$8:$C$356,C25,$H$8:$H$356,"Serviço"),IF(H25="SUBETAPA",SUMIFS($N$8:$N$356,$B$8:$B$356,B25,$C$8:$C$356,C25,$D$8:$D$356,D25,$H$8:$H$356,"Serviço"),0)))) -> 12520.979 | O25: Estimado com base em índices históricos | P25: Finalizado
A26: =IF($H26="UNIDADE CONSTRUTIVA",OFFSET(A26,-1,0)+1,LARGE(A$3:A25,1)) -> 0 | B26: =IF(H26="UNIDADE CONSTRUTIVA",0,IF(H26="CÉLULA CONSTRUTIVA",OFFSET(B26,-1,0)+1,OFFSET(B26,-1,0))) -> 2 | C26: =IF(H26="CÉLULA CONSTRUTIVA",0,IF(H26="ETAPA",OFFSET(C26,-1,0)+1,OFFSET(C26,-1,0))) -> 1 | D26: =IF(H26="ETAPA",0,IF(H26="SUBETAPA",OFFSET(D26,-1,0)+1,OFFSET(D26,-1,0))) -> 1 | E26: =IF(H26="Subetapa",0,IF(H26="serviço",OFFSET(E26,-1,0)+1,OFFSET(E26,-1,0))) -> 3 | H26: SERVIÇO | I26: =IF(H26="Unidade Construtiva",TEXT(A26,"00"),IF(H26="Célula Construtiva",TEXT(B26,"00"),IF(H26="Etapa",CONCATENATE(TEXT(B26,"00"),".",TEXT(C26,"000")),IF(H26="Subetapa",CONCATENATE(TEXT(B26,"00"),".",TEXT(C26,"000"),".",TEXT(D26,"000")),IF(H26="Serviço",CONCATENATE(TEXT(B26,"00"),".",TEXT(C26,"000"),".",TEXT(D26,"000"),".",TEXT(E26,"000")),""))))) -> 02.001.001.003 | J26: Consumo de Energia | K26: mes | L26: 33 | M26: 1578.8277 | N26: =IF(H26="Serviço",M26*L26,IF(H26="CÉLULA CONSTRUTIVA",SUMIFS($N$8:$N$356,$B$8:$B$356,B26,$H$8:$H$356,"Serviço"),IF(H26="ETAPA",SUMIFS($N$8:$N$356,$B$8:$B$356,B26,$C$8:$C$356,C26,$H$8:$H$356,"Serviço"),IF(H26="SUBETAPA",SUMIFS($N$8:$N$356,$B$8:$B$356,B26,$C$8:$C$356,C26,$D$8:$D$356,D26,$H$8:$H$356,"Serviço"),0)))) -> 52101.314 | O26: Estimado com base em índices históricos | P26: Finalizado
A27: =IF($H27="UNIDADE CONSTRUTIVA",OFFSET(A27,-1,0)+1,LARGE(A$3:A26,1)) -> 0 | B27: =IF(H27="UNIDADE CONSTRUTIVA",0,IF(H27="CÉLULA CONSTRUTIVA",OFFSET(B27,-1,0)+1,OFFSET(B27,-1,0))) -> 2 | C27: =IF(H27="CÉLULA CONSTRUTIVA",0,IF(H27="ETAPA",OFFSET(C27,-1,0)+1,OFFSET(C27,-1,0))) -> 1 | D27: =IF(H27="ETAPA",0,IF(H27="SUBETAPA",OFFSET(D27,-1,0)+1,OFFSET(D27,-1,0))) -> 1 | E27: =IF(H27="Subetapa",0,IF(H27="serviço",OFFSET(E27,-1,0)+1,OFFSET(E27,-1,0))) -> 4 | H27: SERVIÇO | I27: =IF(H27="Unidade Construtiva",TEXT(A27,"00"),IF(H27="Célula Construtiva",TEXT(B27,"00"),IF(H27="Etapa",CONCATENATE(TEXT(B27,"00"),".",TEXT(C27,"000")),IF(H27="Subetapa",CONCATENATE(TEXT(B27,"00"),".",TEXT(C27,"000"),".",TEXT(D27,"000")),IF(H27="Serviço",CONCATENATE(TEXT(B27,"00"),".",TEXT(C27,"000"),".",TEXT(D27,"000"),".",TEXT(E27,"000")),""))))) -> 02.001.001.004 | J27: Consumo de Fotocópias, Impressões e Plotagens | K27: mes | L27: 33 | M27: 2972.0228 | N27: =IF(H27="Serviço",M27*L27,IF(H27="CÉLULA CONSTRUTIVA",SUMIFS($N$8:$N$356,$B$8:$B$356,B27,$H$8:$H$356,"Serviço"),IF(H27="ETAPA",SUMIFS($N$8:$N$356,$B$8:$B$356,B27,$C$8:$C$356,C27,$H$8:$H$356,"Serviço"),IF(H27="SUBETAPA",SUMIFS($N$8:$N$356,$B$8:$B$356,B27,$C$8:$C$356,C27,$D$8:$D$356,D27,$H$8:$H$356,"Serviço"),0)))) -> 98076.751 | O27: Estimado com base em índices históricos | P27: Finalizado
A28: =IF($H28="UNIDADE CONSTRUTIVA",OFFSET(A28,-1,0)+1,LARGE(A$3:A27,1)) -> 0 | B28: =IF(H28="UNIDADE CONSTRUTIVA",0,IF(H28="CÉLULA CONSTRUTIVA",OFFSET(B28,-1,0)+1,OFFSET(B28,-1,0))) -> 2 | C28: =IF(H28="CÉLULA CONSTRUTIVA",0,IF(H28="ETAPA",OFFSET(C28,-1,0)+1,OFFSET(C28,-1,0))) -> 1 | D28: =IF(H28="ETAPA",0,IF(H28="SUBETAPA",OFFSET(D28,-1,0)+1,OFFSET(D28,-1,0))) -> 1 | E28: =IF(H28="Subetapa",0,IF(H28="serviço",OFFSET(E28,-1,0)+1,OFFSET(E28,-1,0))) -> 5 | H28: SERVIÇO | I28: =IF(H28="Unidade Construtiva",TEXT(A28,"00"),IF(H28="Célula Construtiva",TEXT(B28,"00"),IF(H28="Etapa",CONCATENATE(TEXT(B28,"00"),".",TEXT(C28,"000")),IF(H28="Subetapa",CONCATENATE(TEXT(B28,"00"),".",TEXT(C28,"000"),".",TEXT(D28,"000")),IF(H28="Serviço",CONCATENATE(TEXT(B28,"00"),".",TEXT(C28,"000"),".",TEXT(D28,"000"),".",TEXT(E28,"000")),""))))) -> 02.001.001.005 | J28: Equipamentos de Segurança do Trabalho | K28: vb | L28: 1 | M28: =EPCs!F81+CANTEIRO!D15 -> 143227.82 | N28: =IF(H28="Serviço",M28*L28,IF(H28="CÉLULA CONSTRUTIVA",SUMIFS($N$8:$N$356,$B$8:$B$356,B28,$H$8:$H$356,"Serviço"),IF(H28="ETAPA",SUMIFS($N$8:$N$356,$B$8:$B$356,B28,$C$8:$C$356,C28,$H$8:$H$356,"Serviço"),IF(H28="SUBETAPA",SUMIFS($N$8:$N$356,$B$8:$B$356,B28,$C$8:$C$356,C28,$D$8:$D$356,D28,$H$8:$H$356,"Serviço"),0)))) -> 143227.82 | O28: Conforme abas "CANTEIRO" e "EPC's" - Bandejas, guarda corpo, tela fachadeira, linha de vida, slqa, EPI | P28: Finalizado
A29: =IF($H29="UNIDADE CONSTRUTIVA",OFFSET(A29,-1,0)+1,LARGE(A$3:A28,1)) -> 0 | B29: =IF(H29="UNIDADE CONSTRUTIVA",0,IF(H29="CÉLULA CONSTRUTIVA",OFFSET(B29,-1,0)+1,OFFSET(B29,-1,0))) -> 2 | C29: =IF(H29="CÉLULA CONSTRUTIVA",0,IF(H29="ETAPA",OFFSET(C29,-1,0)+1,OFFSET(C29,-1,0))) -> 1 | D29: =IF(H29="ETAPA",0,IF(H29="SUBETAPA",OFFSET(D29,-1,0)+1,OFFSET(D29,-1,0))) -> 1 | E29: =IF(H29="Subetapa",0,IF(H29="serviço",OFFSET(E29,-1,0)+1,OFFSET(E29,-1,0))) -> 6 | H29: SERVIÇO | I29: =IF(H29="Unidade Construtiva",TEXT(A29,"00"),IF(H29="Célula Construtiva",TEXT(B29,"00"),IF(H29="Etapa",CONCATENATE(TEXT(B29,"00"),".",TEXT(C29,"000")),IF(H29="Subetapa",CONCATENATE(TEXT(B29,"00"),".",TEXT(C29,"000"),".",TEXT(D29,"000")),IF(H29="Serviço",CONCATENATE(TEXT(B29,"00"),".",TEXT(C29,"000"),".",TEXT(D29,"000"),".",TEXT(E29,"000")),""))))) -> 02.001.001.006 | J29: Monitoramento de Vigilância | K29: mes | L29: 33 | M29: 1060 | N29: =IF(H29="Serviço",M29*L29,IF(H29="CÉLULA CONSTRUTIVA",SUMIFS($N$8:$N$356,$B$8:$B$356,B29,$H$8:$H$356,"Serviço"),IF(H29="ETAPA",SUMIFS($N$8:$N$356,$B$8:$B$356,B29,$C$8:$C$356,C29,$H$8:$H$356,"Serviço"),IF(H29="SUBETAPA",SUMIFS($N$8:$N$356,$B$8:$B$356,B29,$C$8:$C$356,C29,$D$8:$D$356,D29,$H$8:$H$356,"Serviço"),0)))) -> 34980 | O29: Estimado com base em índices históricos | P29: Finalizado
A30: =IF($H30="UNIDADE CONSTRUTIVA",OFFSET(A30,-1,0)+1,LARGE(A$3:A29,1)) -> 0 | B30: =IF(H30="UNIDADE CONSTRUTIVA",0,IF(H30="CÉLULA CONSTRUTIVA",OFFSET(B30,-1,0)+1,OFFSET(B30,-1,0))) -> 2 | C30: =IF(H30="CÉLULA CONSTRUTIVA",0,IF(H30="ETAPA",OFFSET(C30,-1,0)+1,OFFSET(C30,-1,0))) -> 1 | D30: =IF(H30="ETAPA",0,IF(H30="SUBETAPA",OFFSET(D30,-1,0)+1,OFFSET(D30,-1,0))) -> 1 | E30: =IF(H30="Subetapa",0,IF(H30="serviço",OFFSET(E30,-1,0)+1,OFFSET(E30,-1,0))) -> 7 | H30: SERVIÇO | I30: =IF(H30="Unidade Construtiva",TEXT(A30,"00"),IF(H30="Célula Construtiva",TEXT(B30,"00"),IF(H30="Etapa",CONCATENATE(TEXT(B30,"00"),".",TEXT(C30,"000")),IF(H30="Subetapa",CONCATENATE(TEXT(B30,"00"),".",TEXT(C30,"000"),".",TEXT(D30,"000")),IF(H30="Serviço",CONCATENATE(TEXT(B30,"00"),".",TEXT(C30,"000"),".",TEXT(D30,"000"),".",TEXT(E30,"000")),""))))) -> 02.001.001.007 | J30: Equipamentos e Instalação para Segurança e Monitoramento | K30: vb | L30: 1 | M30: 3031.035 | N30: =IF(H30="Serviço",M30*L30,IF(H30="CÉLULA CONSTRUTIVA",SUMIFS($N$8:$N$356,$B$8:$B$356,B30,$H$8:$H$356,"Serviço"),IF(H30="ETAPA",SUMIFS($N$8:$N$356,$B$8:$B$356,B30,$C$8:$C$356,C30,$H$8:$H$356,"Serviço"),IF(H30="SUBETAPA",SUMIFS($N$8:$N$356,$B$8:$B$356,B30,$C$8:$C$356,C30,$D$8:$D$356,D30,$H$8:$H$356,"Serviço"),0)))) -> 3031.035 | O30: Estimado com base em índices históricos | P30: Finalizado
A31: =IF($H31="UNIDADE CONSTRUTIVA",OFFSET(A31,-1,0)+1,LARGE(A$3:A30,1)) -> 0 | B31: =IF(H31="UNIDADE CONSTRUTIVA",0,IF(H31="CÉLULA CONSTRUTIVA",OFFSET(B31,-1,0)+1,OFFSET(B31,-1,0))) -> 2 | C31: =IF(H31="CÉLULA CONSTRUTIVA",0,IF(H31="ETAPA",OFFSET(C31,-1,0)+1,OFFSET(C31,-1,0))) -> 2 | D31: =IF(H31="ETAPA",0,IF(H31="SUBETAPA",OFFSET(D31,-1,0)+1,OFFSET(D31,-1,0))) -> 0 | E31: =IF(H31="Subetapa",0,IF(H31="serviço",OFFSET(E31,-1,0)+1,OFFSET(E31,-1,0))) -> 7 | H31: ETAPA | I31: =IF(H31="Unidade Construtiva",TEXT(A31,"00"),IF(H31="Célula Construtiva",TEXT(B31,"00"),IF(H31="Etapa",CONCATENATE(TEXT(B31,"00"),".",TEXT(C31,"000")),IF(H31="Subetapa",CONCATENATE(TEXT(B31,"00"),".",TEXT(C31,"000"),".",TEXT(D31,"000")),IF(H31="Serviço",CONCATENATE(TEXT(B31,"00"),".",TEXT(C31,"000"),".",TEXT(D31,"000"),".",TEXT(E31,"000")),""))))) -> 02.002 | J31: INSTALAÇÕES PROVISÓRIAS | N31: =IF(H31="Serviço",M31*L31,IF(H31="CÉLULA CONSTRUTIVA",SUMIFS($N$8:$N$356,$B$8:$B$356,B31,$H$8:$H$356,"Serviço"),IF(H31="ETAPA",SUMIFS($N$8:$N$356,$B$8:$B$356,B31,$C$8:$C$356,C31,$H$8:$H$356,"Serviço"),IF(H31="SUBETAPA",SUMIFS($N$8:$N$356,$B$8:$B$356,B31,$C$8:$C$356,C31,$D$8:$D$356,D31,$H$8:$H$356,"Serviço"),0)))) -> 524105.2
A32: =IF($H32="UNIDADE CONSTRUTIVA",OFFSET(A32,-1,0)+1,LARGE(A$3:A31,1)) -> 0 | B32: =IF(H32="UNIDADE CONSTRUTIVA",0,IF(H32="CÉLULA CONSTRUTIVA",OFFSET(B32,-1,0)+1,OFFSET(B32,-1,0))) -> 2 | C32: =IF(H32="CÉLULA CONSTRUTIVA",0,IF(H32="ETAPA",OFFSET(C32,-1,0)+1,OFFSET(C32,-1,0))) -> 2 | D32: =IF(H32="ETAPA",0,IF(H32="SUBETAPA",OFFSET(D32,-1,0)+1,OFFSET(D32,-1,0))) -> 1 | E32: =IF(H32="Subetapa",0,IF(H32="serviço",OFFSET(E32,-1,0)+1,OFFSET(E32,-1,0))) -> 0 | H32: SUBETAPA | I32: =IF(H32="Unidade Construtiva",TEXT(A32,"00"),IF(H32="Célula Construtiva",TEXT(B32,"00"),IF(H32="Etapa",CONCATENATE(TEXT(B32,"00"),".",TEXT(C32,"000")),IF(H32="Subetapa",CONCATENATE(TEXT(B32,"00"),".",TEXT(C32,"000"),".",TEXT(D32,"000")),IF(H32="Serviço",CONCATENATE(TEXT(B32,"00"),".",TEXT(C32,"000"),".",TEXT(D32,"000"),".",TEXT(E32,"000")),""))))) -> 02.002.001 | J32: LIGAÇÕES | N32: =IF(H32="Serviço",M32*L32,IF(H32="CÉLULA CONSTRUTIVA",SUMIFS($N$8:$N$356,$B$8:$B$356,B32,$H$8:$H$356,"Serviço"),IF(H32="ETAPA",SUMIFS($N$8:$N$356,$B$8:$B$356,B32,$C$8:$C$356,C32,$H$8:$H$356,"Serviço"),IF(H32="SUBETAPA",SUMIFS($N$8:$N$356,$B$8:$B$356,B32,$C$8:$C$356,C32,$D$8:$D$356,D32,$H$8:$H$356,"Serviço"),0)))) -> 5100
A33: =IF($H33="UNIDADE CONSTRUTIVA",OFFSET(A33,-1,0)+1,LARGE(A$3:A32,1)) -> 0 | B33: =IF(H33="UNIDADE CONSTRUTIVA",0,IF(H33="CÉLULA CONSTRUTIVA",OFFSET(B33,-1,0)+1,OFFSET(B33,-1,0))) -> 2 | C33: =IF(H33="CÉLULA CONSTRUTIVA",0,IF(H33="ETAPA",OFFSET(C33,-1,0)+1,OFFSET(C33,-1,0))) -> 2 | D33: =IF(H33="ETAPA",0,IF(H33="SUBETAPA",OFFSET(D33,-1,0)+1,OFFSET(D33,-1,0))) -> 1 | E33: =IF(H33="Subetapa",0,IF(H33="serviço",OFFSET(E33,-1,0)+1,OFFSET(E33,-1,0))) -> 1 | H33: SERVIÇO | I33: =IF(H33="Unidade Construtiva",TEXT(A33,"00"),IF(H33="Célula Construtiva",TEXT(B33,"00"),IF(H33="Etapa",CONCATENATE(TEXT(B33,"00"),".",TEXT(C33,"000")),IF(H33="Subetapa",CONCATENATE(TEXT(B33,"00"),".",TEXT(C33,"000"),".",TEXT(D33,"000")),IF(H33="Serviço",CONCATENATE(TEXT(B33,"00"),".",TEXT(C33,"000"),".",TEXT(D33,"000"),".",TEXT(E33,"000")),""))))) -> 02.002.001.001 | J33: Ligação Provisória de Água | K33: vb | L33: 1 | M33: 300 | N33: =IF(H33="Serviço",M33*L33,IF(H33="CÉLULA CONSTRUTIVA",SUMIFS($N$8:$N$356,$B$8:$B$356,B33,$H$8:$H$356,"Serviço"),IF(H33="ETAPA",SUMIFS($N$8:$N$356,$B$8:$B$356,B33,$C$8:$C$356,C33,$H$8:$H$356,"Serviço"),IF(H33="SUBETAPA",SUMIFS($N$8:$N$356,$B$8:$B$356,B33,$C$8:$C$356,C33,$D$8:$D$356,D33,$H$8:$H$356,"Serviço"),0)))) -> 300 | O33: Estimado com base em índices históricos - Taxa de ligação | P33: Finalizado
A34: =IF($H34="UNIDADE CONSTRUTIVA",OFFSET(A34,-1,0)+1,LARGE(A$3:A33,1)) -> 0 | B34: =IF(H34="UNIDADE CONSTRUTIVA",0,IF(H34="CÉLULA CONSTRUTIVA",OFFSET(B34,-1,0)+1,OFFSET(B34,-1,0))) -> 2 | C34: =IF(H34="CÉLULA CONSTRUTIVA",0,IF(H34="ETAPA",OFFSET(C34,-1,0)+1,OFFSET(C34,-1,0))) -> 2 | D34: =IF(H34="ETAPA",0,IF(H34="SUBETAPA",OFFSET(D34,-1,0)+1,OFFSET(D34,-1,0))) -> 1 | E34: =IF(H34="Subetapa",0,IF(H34="serviço",OFFSET(E34,-1,0)+1,OFFSET(E34,-1,0))) -> 2 | H34: SERVIÇO | I34: =IF(H34="Unidade Construtiva",TEXT(A34,"00"),IF(H34="Célula Construtiva",TEXT(B34,"00"),IF(H34="Etapa",CONCATENATE(TEXT(B34,"00"),".",TEXT(C34,"000")),IF(H34="Subetapa",CONCATENATE(TEXT(B34,"00"),".",TEXT(C34,"000"),".",TEXT(D34,"000")),IF(H34="Serviço",CONCATENATE(TEXT(B34,"00"),".",TEXT(C34,"000"),".",TEXT(D34,"000"),".",TEXT(E34,"000")),""))))) -> 02.002.001.002 | J34: Ligação Provisória Trifásica Distância=25m | K34: vb | L34: 1 | M34: =1000+3000+800 -> 4800 | N34: =IF(H34="Serviço",M34*L34,IF(H34="CÉLULA CONSTRUTIVA",SUMIFS($N$8:$N$356,$B$8:$B$356,B34,$H$8:$H$356,"Serviço"),IF(H34="ETAPA",SUMIFS($N$8:$N$356,$B$8:$B$356,B34,$C$8:$C$356,C34,$H$8:$H$356,"Serviço"),IF(H34="SUBETAPA",SUMIFS($N$8:$N$356,$B$8:$B$356,B34,$C$8:$C$356,C34,$D$8:$D$356,D34,$H$8:$H$356,"Serviço"),0)))) -> 4800 | O34: Estimado com base em índices históricos - Taxa + ligação | P34: Finalizado
A35: =IF($H35="UNIDADE CONSTRUTIVA",OFFSET(A35,-1,0)+1,LARGE(A$3:A34,1)) -> 0 | B35: =IF(H35="UNIDADE CONSTRUTIVA",0,IF(H35="CÉLULA CONSTRUTIVA",OFFSET(B35,-1,0)+1,OFFSET(B35,-1,0))) -> 2 | C35: =IF(H35="CÉLULA CONSTRUTIVA",0,IF(H35="ETAPA",OFFSET(C35,-1,0)+1,OFFSET(C35,-1,0))) -> 2 | D35: =IF(H35="ETAPA",0,IF(H35="SUBETAPA",OFFSET(D35,-1,0)+1,OFFSET(D35,-1,0))) -> 2 | E35: =IF(H35="Subetapa",0,IF(H35="serviço",OFFSET(E35,-1,0)+1,OFFSET(E35,-1,0))) -> 0 | H35: SUBETAPA | I35: =IF(H35="Unidade Construtiva",TEXT(A35,"00"),IF(H35="Célula Construtiva",TEXT(B35,"00"),IF(H35="Etapa",CONCATENATE(TEXT(B35,"00"),".",TEXT(C35,"000")),IF(H35="Subetapa",CONCATENATE(TEXT(B35,"00"),".",TEXT(C35,"000"),".",TEXT(D35,"000")),IF(H35="Serviço",CONCATENATE(TEXT(B35,"00"),".",TEXT(C35,"000"),".",TEXT(D35,"000"),".",TEXT(E35,"000")),""))))) -> 02.002.002 | J35: REDES PROVISÓRIAS | N35: =IF(H35="Serviço",M35*L35,IF(H35="CÉLULA CONSTRUTIVA",SUMIFS($N$8:$N$356,$B$8:$B$356,B35,$H$8:$H$356,"Serviço"),IF(H35="ETAPA",SUMIFS($N$8:$N$356,$B$8:$B$356,B35,$C$8:$C$356,C35,$H$8:$H$356,"Serviço"),IF(H35="SUBETAPA",SUMIFS($N$8:$N$356,$B$8:$B$356,B35,$C$8:$C$356,C35,$D$8:$D$356,D35,$H$8:$H$356,"Serviço"),0)))) -> 19589.289
A36: =IF($H36="UNIDADE CONSTRUTIVA",OFFSET(A36,-1,0)+1,LARGE(A$3:A35,1)) -> 0 | B36: =IF(H36="UNIDADE CONSTRUTIVA",0,IF(H36="CÉLULA CONSTRUTIVA",OFFSET(B36,-1,0)+1,OFFSET(B36,-1,0))) -> 2 | C36: =IF(H36="CÉLULA CONSTRUTIVA",0,IF(H36="ETAPA",OFFSET(C36,-1,0)+1,OFFSET(C36,-1,0))) -> 2 | D36: =IF(H36="ETAPA",0,IF(H36="SUBETAPA",OFFSET(D36,-1,0)+1,OFFSET(D36,-1,0))) -> 2 | E36: =IF(H36="Subetapa",0,IF(H36="serviço",OFFSET(E36,-1,0)+1,OFFSET(E36,-1,0))) -> 1 | H36: SERVIÇO | I36: =IF(H36="Unidade Construtiva",TEXT(A36,"00"),IF(H36="Célula Construtiva",TEXT(B36,"00"),IF(H36="Etapa",CONCATENATE(TEXT(B36,"00"),".",TEXT(C36,"000")),IF(H36="Subetapa",CONCATENATE(TEXT(B36,"00"),".",TEXT(C36,"000"),".",TEXT(D36,"000")),IF(H36="Serviço",CONCATENATE(TEXT(B36,"00"),".",TEXT(C36,"000"),".",TEXT(D36,"000"),".",TEXT(E36,"000")),""))))) -> 02.002.002.001 | J36: Rede de Água Provisória | K36: vb | L36: 1 | M36: 10439.393 | N36: =IF(H36="Serviço",M36*L36,IF(H36="CÉLULA CONSTRUTIVA",SUMIFS($N$8:$N$356,$B$8:$B$356,B36,$H$8:$H$356,"Serviço"),IF(H36="ETAPA",SUMIFS($N$8:$N$356,$B$8:$B$356,B36,$C$8:$C$356,C36,$H$8:$H$356,"Serviço"),IF(H36="SUBETAPA",SUMIFS($N$8:$N$356,$B$8:$B$356,B36,$C$8:$C$356,C36,$D$8:$D$356,D36,$H$8:$H$356,"Serviço"),0)))) -> 10439.393 | O36: Estimado com base em índices históricos | P36: Finalizado
A37: =IF($H37="UNIDADE CONSTRUTIVA",OFFSET(A37,-1,0)+1,LARGE(A$3:A36,1)) -> 0 | B37: =IF(H37="UNIDADE CONSTRUTIVA",0,IF(H37="CÉLULA CONSTRUTIVA",OFFSET(B37,-1,0)+1,OFFSET(B37,-1,0))) -> 2 | C37: =IF(H37="CÉLULA CONSTRUTIVA",0,IF(H37="ETAPA",OFFSET(C37,-1,0)+1,OFFSET(C37,-1,0))) -> 2 | D37: =IF(H37="ETAPA",0,IF(H37="SUBETAPA",OFFSET(D37,-1,0)+1,OFFSET(D37,-1,0))) -> 2 | E37: =IF(H37="Subetapa",0,IF(H37="serviço",OFFSET(E37,-1,0)+1,OFFSET(E37,-1,0))) -> 2 | H37: SERVIÇO | I37: =IF(H37="Unidade Construtiva",TEXT(A37,"00"),IF(H37="Célula Construtiva",TEXT(B37,"00"),IF(H37="Etapa",CONCATENATE(TEXT(B37,"00"),".",TEXT(C37,"000")),IF(H37="Subetapa",CONCATENATE(TEXT(B37,"00"),".",TEXT(C37,"000"),".",TEXT(D37,"000")),IF(H37="Serviço",CONCATENATE(TEXT(B37,"00"),".",TEXT(C37,"000"),".",TEXT(D37,"000"),".",TEXT(E37,"000")),""))))) -> 02.002.002.002 | J37: Rede de Energia Provisória | K37: vb | L37: 1 | M37: 9149.8965 | N37: =IF(H37="Serviço",M37*L37,IF(H37="CÉLULA CONSTRUTIVA",SUMIFS($N$8:$N$356,$B$8:$B$356,B37,$H$8:$H$356,"Serviço"),IF(H37="ETAPA",SUMIFS($N$8:$N$356,$B$8:$B$356,B37,$C$8:$C$356,C37,$H$8:$H$356,"Serviço"),IF(H37="SUBETAPA",SUMIFS($N$8:$N$356,$B$8:$B$356,B37,$C$8:$C$356,C37,$D$8:$D$356,D37,$H$8:$H$356,"Serviço"),0)))) -> 9149.8965 | O37: Estimado com base em índices históricos | P37: Finalizado
A38: =IF($H38="UNIDADE CONSTRUTIVA",OFFSET(A38,-1,0)+1,LARGE(A$3:A37,1)) -> 0 | B38: =IF(H38="UNIDADE CONSTRUTIVA",0,IF(H38="CÉLULA CONSTRUTIVA",OFFSET(B38,-1,0)+1,OFFSET(B38,-1,0))) -> 2 | C38: =IF(H38="CÉLULA CONSTRUTIVA",0,IF(H38="ETAPA",OFFSET(C38,-1,0)+1,OFFSET(C38,-1,0))) -> 2 | D38: =IF(H38="ETAPA",0,IF(H38="SUBETAPA",OFFSET(D38,-1,0)+1,OFFSET(D38,-1,0))) -> 3 | E38: =IF(H38="Subetapa",0,IF(H38="serviço",OFFSET(E38,-1,0)+1,OFFSET(E38,-1,0))) -> 0 | H38: SUBETAPA | I38: =IF(H38="Unidade Construtiva",TEXT(A38,"00"),IF(H38="Célula Construtiva",TEXT(B38,"00"),IF(H38="Etapa",CONCATENATE(TEXT(B38,"00"),".",TEXT(C38,"000")),IF(H38="Subetapa",CONCATENATE(TEXT(B38,"00"),".",TEXT(C38,"000"),".",TEXT(D38,"000")),IF(H38="Serviço",CONCATENATE(TEXT(B38,"00"),".",TEXT(C38,"000"),".",TEXT(D38,"000"),".",TEXT(E38,"000")),""))))) -> 02.002.003 | J38: TAPUME | N38: =IF(H38="Serviço",M38*L38,IF(H38="CÉLULA CONSTRUTIVA",SUMIFS($N$8:$N$356,$B$8:$B$356,B38,$H$8:$H$356,"Serviço"),IF(H38="ETAPA",SUMIFS($N$8:$N$356,$B$8:$B$356,B38,$C$8:$C$356,C38,$H$8:$H$356,"Serviço"),IF(H38="SUBETAPA",SUMIFS($N$8:$N$356,$B$8:$B$356,B38,$C$8:$C$356,C38,$D$8:$D$356,D38,$H$8:$H$356,"Serviço"),0)))) -> 25153.488
A39: =IF($H39="UNIDADE CONSTRUTIVA",OFFSET(A39,-1,0)+1,LARGE(A$3:A38,1)) -> 0 | B39: =IF(H39="UNIDADE CONSTRUTIVA",0,IF(H39="CÉLULA CONSTRUTIVA",OFFSET(B39,-1,0)+1,OFFSET(B39,-1,0))) -> 2 | C39: =IF(H39="CÉLULA CONSTRUTIVA",0,IF(H39="ETAPA",OFFSET(C39,-1,0)+1,OFFSET(C39,-1,0))) -> 2 | D39: =IF(H39="ETAPA",0,IF(H39="SUBETAPA",OFFSET(D39,-1,0)+1,OFFSET(D39,-1,0))) -> 3 | E39: =IF(H39="Subetapa",0,IF(H39="serviço",OFFSET(E39,-1,0)+1,OFFSET(E39,-1,0))) -> 1 | H39: SERVIÇO | I39: =IF(H39="Unidade Construtiva",TEXT(A39,"00"),IF(H39="Célula Construtiva",TEXT(B39,"00"),IF(H39="Etapa",CONCATENATE(TEXT(B39,"00"),".",TEXT(C39,"000")),IF(H39="Subetapa",CONCATENATE(TEXT(B39,"00"),".",TEXT(C39,"000"),".",TEXT(D39,"000")),IF(H39="Serviço",CONCATENATE(TEXT(B39,"00"),".",TEXT(C39,"000"),".",TEXT(D39,"000"),".",TEXT(E39,"000")),""))))) -> 02.002.003.001 | J39: Tapume Metálico | K39: m2 | L39: 126.6 | M39: 189.68 | N39: =IF(H39="Serviço",M39*L39,IF(H39="CÉLULA CONSTRUTIVA",SUMIFS($N$8:$N$356,$B$8:$B$356,B39,$H$8:$H$356,"Serviço"),IF(H39="ETAPA",SUMIFS($N$8:$N$356,$B$8:$B$356,B39,$C$8:$C$356,C39,$H$8:$H$356,"Serviço"),IF(H39="SUBETAPA",SUMIFS($N$8:$N$356,$B$8:$B$356,B39,$C$8:$C$356,C39,$D$8:$D$356,D39,$H$8:$H$356,"Serviço"),0)))) -> 24013.488 | O39: Frente + lateral terreno | P39: Finalizado
A40: =IF($H40="UNIDADE CONSTRUTIVA",OFFSET(A40,-1,0)+1,LARGE(A$3:A39,1)) -> 0 | B40: =IF(H40="UNIDADE CONSTRUTIVA",0,IF(H40="CÉLULA CONSTRUTIVA",OFFSET(B40,-1,0)+1,OFFSET(B40,-1,0))) -> 2 | C40: =IF(H40="CÉLULA CONSTRUTIVA",0,IF(H40="ETAPA",OFFSET(C40,-1,0)+1,OFFSET(C40,-1,0))) -> 2 | D40: =IF(H40="ETAPA",0,IF(H40="SUBETAPA",OFFSET(D40,-1,0)+1,OFFSET(D40,-1,0))) -> 3 | E40: =IF(H40="Subetapa",0,IF(H40="serviço",OFFSET(E40,-1,0)+1,OFFSET(E40,-1,0))) -> 2 | H40: SERVIÇO | I40: =IF(H40="Unidade Construtiva",TEXT(A40,"00"),IF(H40="Célula Construtiva",TEXT(B40,"00"),IF(H40="Etapa",CONCATENATE(TEXT(B40,"00"),".",TEXT(C40,"000")),IF(H40="Subetapa",CONCATENATE(TEXT(B40,"00"),".",TEXT(C40,"000"),".",TEXT(D40,"000")),IF(H40="Serviço",CONCATENATE(TEXT(B40,"00"),".",TEXT(C40,"000"),".",TEXT(D40,"000"),".",TEXT(E40,"000")),""))))) -> 02.002.003.002 | J40: Aluguel de Mini-Escavadeira / Cravação de Tapume | K40: vb | L40: 1 | M40: =380*3 -> 1140 | N40: =IF(H40="Serviço",M40*L40,IF(H40="CÉLULA CONSTRUTIVA",SUMIFS($N$8:$N$356,$B$8:$B$356,B40,$H$8:$H$356,"Serviço"),IF(H40="ETAPA",SUMIFS($N$8:$N$356,$B$8:$B$356,B40,$C$8:$C$356,C40,$H$8:$H$356,"Serviço"),IF(H40="SUBETAPA",SUMIFS($N$8:$N$356,$B$8:$B$356,B40,$C$8:$C$356,C40,$D$8:$D$356,D40,$H$8:$H$356,"Serviço"),0)))) -> 1140 | O40: Considerado 3 dias para execução (Diária R$ 380) | P40: Finalizado
A41: =IF($H41="UNIDADE CONSTRUTIVA",OFFSET(A41,-1,0)+1,LARGE(A$3:A40,1)) -> 0 | B41: =IF(H41="UNIDADE CONSTRUTIVA",0,IF(H41="CÉLULA CONSTRUTIVA",OFFSET(B41,-1,0)+1,OFFSET(B41,-1,0))) -> 2 | C41: =IF(H41="CÉLULA CONSTRUTIVA",0,IF(H41="ETAPA",OFFSET(C41,-1,0)+1,OFFSET(C41,-1,0))) -> 2 | D41: =IF(H41="ETAPA",0,IF(H41="SUBETAPA",OFFSET(D41,-1,0)+1,OFFSET(D41,-1,0))) -> 4 | E41: =IF(H41="Subetapa",0,IF(H41="serviço",OFFSET(E41,-1,0)+1,OFFSET(E41,-1,0))) -> 0 | H41: SUBETAPA | I41: =IF(H41="Unidade Construtiva",TEXT(A41,"00"),IF(H41="Célula Construtiva",TEXT(B41,"00"),IF(H41="Etapa",CONCATENATE(TEXT(B41,"00"),".",TEXT(C41,"000")),IF(H41="Subetapa",CONCATENATE(TEXT(B41,"00"),".",TEXT(C41,"000"),".",TEXT(D41,"000")),IF(H41="Serviço",CONCATENATE(TEXT(B41,"00"),".",TEXT(C41,"000"),".",TEXT(D41,"000"),".",TEXT(E41,"000")),""))))) -> 02.002.004 | J41: CONTAINERS E ESCRITÓRIOS | N41: =IF(H41="Serviço",M41*L41,IF(H41="CÉLULA CONSTRUTIVA",SUMIFS($N$8:$N$356,$B$8:$B$356,B41,$H$8:$H$356,"Serviço"),IF(H41="ETAPA",SUMIFS($N$8:$N$356,$B$8:$B$356,B41,$C$8:$C$356,C41,$H$8:$H$356,"Serviço"),IF(H41="SUBETAPA",SUMIFS($N$8:$N$356,$B$8:$B$356,B41,$C$8:$C$356,C41,$D$8:$D$356,D41,$H$8:$H$356,"Serviço"),0)))) -> 281301.47
A42: =IF($H42="UNIDADE CONSTRUTIVA",OFFSET(A42,-1,0)+1,LARGE(A$3:A41,1)) -> 0 | B42: =IF(H42="UNIDADE CONSTRUTIVA",0,IF(H42="CÉLULA CONSTRUTIVA",OFFSET(B42,-1,0)+1,OFFSET(B42,-1,0))) -> 2 | C42: =IF(H42="CÉLULA CONSTRUTIVA",0,IF(H42="ETAPA",OFFSET(C42,-1,0)+1,OFFSET(C42,-1,0))) -> 2 | D42: =IF(H42="ETAPA",0,IF(H42="SUBETAPA",OFFSET(D42,-1,0)+1,OFFSET(D42,-1,0))) -> 4 | E42: =IF(H42="Subetapa",0,IF(H42="serviço",OFFSET(E42,-1,0)+1,OFFSET(E42,-1,0))) -> 1 | H42: SERVIÇO | I42: =IF(H42="Unidade Construtiva",TEXT(A42,"00"),IF(H42="Célula Construtiva",TEXT(B42,"00"),IF(H42="Etapa",CONCATENATE(TEXT(B42,"00"),".",TEXT(C42,"000")),IF(H42="Subetapa",CONCATENATE(TEXT(B42,"00"),".",TEXT(C42,"000"),".",TEXT(D42,"000")),IF(H42="Serviço",CONCATENATE(TEXT(B42,"00"),".",TEXT(C42,"000"),".",TEXT(D42,"000"),".",TEXT(E42,"000")),""))))) -> 02.002.004.001 | J42: Container para Escritório - Locação | K42: mes | L42: 11 | M42: 800 | N42: =IF(H42="Serviço",M42*L42,IF(H42="CÉLULA CONSTRUTIVA",SUMIFS($N$8:$N$356,$B$8:$B$356,B42,$H$8:$H$356,"Serviço"),IF(H42="ETAPA",SUMIFS($N$8:$N$356,$B$8:$B$356,B42,$C$8:$C$356,C42,$H$8:$H$356,"Serviço"),IF(H42="SUBETAPA",SUMIFS($N$8:$N$356,$B$8:$B$356,B42,$C$8:$C$356,C42,$D$8:$D$356,D42,$H$8:$H$356,"Serviço"),0)))) -> 8800 | O42: Até 3º mês alvenaria - chegando no pavimento tipo | P42: Finalizado
A43: =IF($H43="UNIDADE CONSTRUTIVA",OFFSET(A43,-1,0)+1,LARGE(A$3:A42,1)) -> 0 | B43: =IF(H43="UNIDADE CONSTRUTIVA",0,IF(H43="CÉLULA CONSTRUTIVA",OFFSET(B43,-1,0)+1,OFFSET(B43,-1,0))) -> 2 | C43: =IF(H43="CÉLULA CONSTRUTIVA",0,IF(H43="ETAPA",OFFSET(C43,-1,0)+1,OFFSET(C43,-1,0))) -> 2 | D43: =IF(H43="ETAPA",0,IF(H43="SUBETAPA",OFFSET(D43,-1,0)+1,OFFSET(D43,-1,0))) -> 4 | E43: =IF(H43="Subetapa",0,IF(H43="serviço",OFFSET(E43,-1,0)+1,OFFSET(E43,-1,0))) -> 2 | H43: SERVIÇO | I43: =IF(H43="Unidade Construtiva",TEXT(A43,"00"),IF(H43="Célula Construtiva",TEXT(B43,"00"),IF(H43="Etapa",CONCATENATE(TEXT(B43,"00"),".",TEXT(C43,"000")),IF(H43="Subetapa",CONCATENATE(TEXT(B43,"00"),".",TEXT(C43,"000"),".",TEXT(D43,"000")),IF(H43="Serviço",CONCATENATE(TEXT(B43,"00"),".",TEXT(C43,"000"),".",TEXT(D43,"000"),".",TEXT(E43,"000")),""))))) -> 02.002.004.002 | J43: Container para Banheiro e Chuveiro - Locação | K43: mes | L43: 10 | M43: 5000 | N43: =IF(H43="Serviço",M43*L43,IF(H43="CÉLULA CONSTRUTIVA",SUMIFS($N$8:$N$356,$B$8:$B$356,B43,$H$8:$H$356,"Serviço"),IF(H43="ETAPA",SUMIFS($N$8:$N$356,$B$8:$B$356,B43,$C$8:$C$356,C43,$H$8:$H$356,"Serviço"),IF(H43="SUBETAPA",SUMIFS($N$8:$N$356,$B$8:$B$356,B43,$C$8:$C$356,C43,$D$8:$D$356,D43,$H$8:$H$356,"Serviço"),0)))) -> 50000 | O43: Até início alvenaria +1 mês para organização | P43: Finalizado
...

Sheet Ger_Executivo
A4: PROJETO: | C4: ='Ger_Tec e Adm'!I4 -> PARKSIDE RIO BRANCO | I4: REVISÃO: | J4: DATA
A5: EMPRESA: | C5: ='Ger_Tec e Adm'!I5 -> PARKSIDE | I5: R00
A6: GERENCIAMENTO EXECUTIVO
A7: Atalho | B7: NIVEL | C7: Item | D7: Descrição | E7: Unidade | F7: Quant. | G7: Preço un | H7: Total | I7: Considerações | J7: Situação
B8: CÉLULA CONSTRUTIVA | C8: 01 | D8: INFRAESTRUTURA | H8: =H9+H12+H22+H34 -> 1566010.8
B9: ETAPA | C9: 01.001 | D9: SERVIÇOS PRELIMINARES | H9: =H10 -> 37755.331
B10: SUBETAPA | C10: 01.001.001 | D10: DEMOLIÇÃO | H10: =H11 -> 37755.331
B11: SERVIÇO | C11: 01.001.001.001 | D11: Demolição de Estrutura Existente | E11: vb | F11: 1 | G11: 37755.331 | H11: =IF(B11="Serviço",G11*F11,IF(B11="CÉLULA CONSTRUTIVA",SUMIFS($H$8:$H$294,#REF!,#REF!,$B$8:$B$294,"Serviço"),IF(B11="ETAPA",SUMIFS($H$8:$H$294,#REF!,#REF!,#REF!,#REF!,$B$8:$B$294,"Serviço"),IF(B11="SUBETAPA",SUMIFS($H$8:$H$294,#REF!,#REF!,#REF!,#REF!,#REF!,#REF!,$B$8:$B$294,"Serviço"),0)))) -> 37755.331 | J11: Finalizado
B12: ETAPA | C12: 01.002 | D12: SERVIÇOS EM TERRA | H12: =H13 -> 340525.06
B13: SUBETAPA | C13: 01.002.001 | D13: MOVIMENTAÇÕES DE TERRA | H13: =H14+H17 -> 340525.06
