Workbook
Name \0: #REF!
Name \1: #REF!
Name \a: #REF!
Name \b: #REF!
Name \c: #REF!
Name \d: #REF!
Name \e: #REF!
Name \i: #REF!
Name \J: #REF!
Name \k: #REF!
Name \l: #N/A
Name \m: #REF!
Name \o: #REF!
Name \p: #REF!
Name \r: #REF!
Name \T: #REF!
Name \z: #REF!
Name ______ACR10: #REF!
Name ______ACR15: #REF!
Name ______acr20: #REF!
Name ______acr5: #REF!
Name ______ARQ1: #REF!
Name ______QT100: #REF!
Name ______QT2: #REF!
Name ______QT3: #REF!
Name ______QT4: #REF!
Name ______QT50: #REF!
Name ______QT75: #REF!
Name _____ACR10: #REF!
Name _____ACR15: #REF!
Name _____acr20: #REF!
Name _____acr5: #REF!
Name _____ARQ1: #REF!
Name _____QT100: #REF!
Name _____QT2: #REF!
Name _____QT3: #REF!
Name _____QT4: #REF!
Name _____QT50: #REF!
Name _____QT75: #REF!
Name ___ACR10: #REF!
Name ___ACR15: #REF!
Name ___acr20: #REF!
Name ___acr5: #REF!
Name ___ARQ1: #REF!
Name ___QT100: #REF!
Name ___QT2: #REF!
Name ___QT3: #REF!
Name ___QT4: #REF!
Name ___QT50: #REF!
Name ___QT75: #REF!
Name __ACR10: #REF!
Name __ACR15: #REF!
Name __acr20: #REF!
Name __acr5: #REF!
Name __ARQ1: #REF!
Name __Axe3: #REF!
Name __Axe4: #REF!
Name __htm2: #REF!
Name __htn2: #REF!
Name __iss2: #REF!

Sheet Relatório
D2: Orçamento
A5: Obra | E5: 45 - FG - SCENARIUM
A6: Unidade construtiva | E6: 1 - OBRA
A7: Tipo de obra | E7: 1 - Construção Civil
A8: Endereço da obra | E8: Itajaí/SC
A9: Versão do orçamento | E9: 1 - 09/08/2024 - 15:04:45 | L9: Data base | V9: 09/08/2024
A10: BDI | E10: não aplicado | L10: Encargos sociais | V10: não aplicado
A11: Preços expressos em | E11: R$ (REAL)
A13: Código | B13: Descrição | N13: Un. | Q13: Quantidade orçada | W13: Preço unitário | AC13: Preço total
A14: 01 | B14: CUSTOS PRELIMINARES, ADMINISTRATIVOS E OPERAÇÕES | AC14: 19628777 | AG14: =AC14+AC131 -> 22842123
A15: 01.001 | B15: SERVIÇOS TÉCNICOS | AC15: 3054816
A16: 01.001.001 | B16: Seviços topográficos | AC16: 24541.24
A17: 01.001.001.001 | B17: Levantamento Topografico | N17: vb | Q17: 1 | W17: 24541.24 | AC17: 24541.24
A18: 01.001.002 | B18: Ensaios e Laudos | AC18: 506428.07
A19: 01.001.002.001 | B19: Controle Tecnológico de Concreto | N19: vb | Q19: 1 | W19: 261480 | AC19: 261480
A20: 01.001.002.002 | B20: Ensaios de prova de carga de fundação | N20: vb | Q20: 1 | W20: 19166.15 | AC20: 19166.15
A21: 01.001.002.003 | B21: Ensaio de guarda corpo | N21: vb | Q21: 1 | W21: 57300 | AC21: 57300
A22: 01.001.002.004 | B22: Ensaio de arrancamento de fachada | N22: vb | Q22: 1 | W22: 11040 | AC22: 11040
A23: 01.001.002.005 | B23: Ensaio de arrancamento de gancho da cobertura | N23: vb | Q23: 1 | W23: 4500 | AC23: 4500
A24: 01.001.002.006 | B24: Ensaio Acústico | N24: vb | Q24: 1 | W24: 22000 | AC24: 22000
A25: 01.001.002.007 | B25: Ensaio de Integridade PIT | N25: vb | Q25: 1 | W25: 14500 | AC25: 14500
A26: 01.001.002.008 | B26: Estudo concreto massa - bloco de fundação | N26: vb | Q26: 1 | W26: 3625 | AC26: 3625
A27: 01.001.002.009 | B27: Laudo de vizinhança | N27: vb | Q27: 1 | W27: 7196.92 | AC27: 7196.92
A28: 01.001.002.010 | B28: Laudo de estanqueidade das esquadrias | N28: vb | Q28: 1 | W28: 41300 | AC28: 41300
A29: 01.001.002.011 | B29: Laudo de higienização/limpeza da caixa d'água | N29: un | Q29: 8 | W29: 2940 | AC29: 23520
A30: 01.001.002.012 | B30: Monitoramento de recalque prédios vizinhos | N30: vb | Q30: 1 | W30: 20400 | AC30: 20400
A31: 01.001.002.013 | B31: Monitoramento de verticalidade de prédios vizinhos | N31: vb | Q31: 1 | W31: 20400 | AC31: 20400
A32: 01.001.003 | B32: Estudos | AC32: 161621.89
A33: 01.001.003.001 | B33: Memoriais Descritivos | N33: vb | Q33: 1 | W33: 12134.38 | AC33: 12134.38
A34: 01.001.003.002 | B34: Estudo Geológico | N34: vb | Q34: 1 | W34: 20811.77 | AC34: 20811.77
A35: 01.001.003.003 | B35: Estudo Ambiental | N35: vb | Q35: 1 | W35: 38843.9 | AC35: 38843.9
A36: 01.001.003.004 | B36: Sondagem Terreno | N36: vb | Q36: 1 | W36: 79927.03 | AC36: 79927.03
A37: 01.001.003.005 | B37: Projeto De Canteiro | N37: vb | Q37: 1 | W37: 9904.81 | AC37: 9904.81
A38: 01.001.004 | B38: Projetos | AC38: 2176104.3
A39: 01.001.004.001 | B39: Projeto Arquitetônico Legal | N39: vb | Q39: 1 | W39: 103045.52 | AC39: 103045.52
A40: 01.001.004.002 | B40: Projeto Arquitetônico Executivo | N40: vb | Q40: 1 | W40: 507333.24 | AC40: 507333.24
A41: 01.001.004.003 | B41: Projeto Arquitetônico Interiores | N41: vb | Q41: 1 | W41: 352596.6 | AC41: 352596.6
A42: 01.001.004.004 | B42: Projeto Arquitetônico De Fachada | N42: vb | Q42: 1 | W42: 61810.1 | AC42: 61810.1
A43: 01.001.004.005 | B43: Projeto De Terraplenagem | N43: vb | Q43: 1 | W43: 9385.58 | AC43: 9385.58
A44: 01.001.004.006 | B44: Projeto De Fundação | N44: vb | Q44: 1 | W44: 146572.7 | AC44: 146572.7
...

Sheet ORÇAMENTO_EXECUTIVO
A1: ETAPA | B1: VALOR ORÇADO | C1: % | D1: VALOR / m²
A2: GERENCIAMENTO TÉCNICO E ADMINISTRATIVO | B2: =Relatório!AC14+Relatório!AC131 -> 22842123 | C2: =B2/$B$20 -> 0.11052248 | D2: =B2/$G$2 -> 540.28685 | F2: ÁREA CONSTRUÍDA | G2: 42277.77 | H2: m²
A3: MOVIEMNTAÇÃO DE TERRA | B3: =Relatório!AC153 -> 3078669.4 | C3: =B3/$B$20 -> 0.014896259 | D3: =B3/$G$2 -> 72.820052
A4: INFRAESTRUTURA | B4: =Relatório!AC171+Relatório!AC207 -> 8389757.8 | C4: =B4/$B$20 -> 0.040594161 | D4: =B4/$G$2 -> 198.44372
A5: CONTENÇÃO | B5: =Relatório!AC188 -> 5038678.7 | C5: =B5/$B$20 -> 0.024379838 | D5: =B5/$G$2 -> 119.18033 | H5: especiais | I5: acaba
A6: SUPRAESTRUTURA | B6: =Relatório!AC224 -> 30247018 | C6: =B6/$B$20 -> 0.14635134 | D6: =B6/$G$2 -> 715.43551 | H6: =[2]Obra!$C$68+[2]Obra!$C$69+[2]Obra!$C$75+[2]Obra!$C$76+[2]Obra!$C$77+[2]Obra!$C$78 -> 66708790 | I6: =[2]Obra!$C$70+[2]Obra!$C$71+[2]Obra!$C$73+[2]Obra!$C$74 -> 51415942
A7: PAREDES E DIVISÓRIAS | B7: =Relatório!AC301 -> 13469645 | C7: =B7/$B$20 -> 0.065173391 | D7: =B7/$G$2 -> 318.59877 | E7: =Relatório!AC908+Relatório!AC952+Relatório!AC969 -> 5397638.3 | H7: =B8+B9+B15+B16+B18 -> 66708789 | I7: =B11+B12+B13+B14+B17 -> 51415943
A8: INSTALAÇÕES ELÉTRICAS, HIDRÁULICAS, GLP E PREVENTIVAS | B8: =Relatório!AC951+Relatório!AC938+Relatório!AC910+Relatório!AC442+Relatório!AC426 -> 16985534 | C8: =B8/$B$20 -> 0.082185152 | D8: =B8/$G$2 -> 401.76041 | E8: =Relatório!AC426+Relatório!AC442 -> 14736927
A9: EQUIPAMENTOS E SISTEMAS ESPECIAIS | B9: =Relatório!AC921+Relatório!AC924+Relatório!AC943+Relatório!AC968 -> 12866747 | C9: =B9/$B$20 -> 0.062256241 | D9: =B9/$G$2 -> 304.33835 | E9: =E7+E8 -> 20134566
A10: IMPERMEABILIZAÇÃO | B10: =Relatório!AC569 -> 2429082.6 | C10: =B10/$B$20 -> 0.011753208 | D10: =B10/$G$2 -> 57.455316 | E10: =B7+B8 -> 30455180 | F10: =E10-E9 -> 10320614
A11: REVESTIMENTOS INTERNOS EM PISO E PAREDE | B11: =Relatório!AF480 -> 3615206.3 | C11: =B11/$B$20 -> 0.017492313 | D11: =B11/$G$2 -> 85.51081
A12: REVESTIMENTOS E ACABAMENTOS INTERNOS EM TETO | B12: =Relatório!AF478+Relatório!AC550 -> 2666469.6 | C12: =B12/$B$20 -> 0.012901814 | D12: =B12/$G$2 -> 63.070252
A13: ACABAMENTOS EM PISO E PAREDE | B13: =Relatório!AF765 -> 26983602 | C13: =B13/$B$20 -> 0.13056118 | D13: =B13/$G$2 -> 638.24563
A14: PINTURA INTERNA | B14: =Relatório!AC620-Relatório!AC732 -> 4509003.5 | C14: =B14/$B$20 -> 0.021816985 | D14: =B14/$G$2 -> 106.65188
A15: ESQUADRIAS, VIDROS E FERRAGENS | B15: =Relatório!AC859+Relatório!AC965+Relatório!AC972+Relatório!AC975 -> 24788341 | C15: =B15/$B$20 -> 0.11993933 | D15: =B15/$G$2 -> 586.32092
A16: COBERTURA | B16: =Relatório!AC958 -> 1253778.1 | C16: =B16/$B$20 -> 0.0060664529 | D16: =B16/$G$2 -> 29.655729
A17: REVESTIMENTOS E ACABAMENTOS DE FACHADA | B17: =Relatório!AF479+Relatório!AC732+Relatório!AF766 -> 13641661 | C17: =B17/$B$20 -> 0.066005695 | D17: =B17/$G$2 -> 322.66747
A18: SERVIÇOS COMPLEMENTARES | B18: =Relatório!AC978+Relatório!AC985 -> 10814389 | C18: =B18/$B$20 -> 0.05232583 | D18: =B18/$G$2 -> 255.79374 | H18: 3054295.6
A19: IMPREVISTOS E CONTINGENCIAS | B19: =SUM(B2:B18)*0.015 -> 3054295.6 | C19: =B19/$B$20 -> 0.014778325 | D19: =B19/$G$2 -> 72.243536 | F19: =B20/104 -> 1987250
A20: TOTAL | B20: =SUM(B2:B19) -> 2.06674e+08 | C20: =SUM(C2:C19) -> 1 | D20: =SUM(D2:D19) -> 4888.4793
A21: CUB/SC R16-A | B21: 3190.77 | C21: 45627 | D21: =ROUNDUP(+D20/B21,2)&" CUB" -> 1,54 CUB
A22: CUB/SC media | B22: 2868.56 | C22: 45627 | D22: =ROUNDUP(+D20/B22,2)&" CUB" -> 1,71 CUB
B23: 7385.89
A25: Rótulos de Linha | B25: Soma de %
A26: SUPRAESTRUTURA | B26: 0.13721717
A27: IMPREVISTOS E CONTINGENCIAS | B27: 0.13043478
A28: ACABAMENTOS EM PISO E PAREDE | B28: 0.12252729
A29: GERENCIAMENTO TÉCNICO E ADMINISTRATIVO | B29: 0.10362448
A30: INSTALAÇÕES ELÉTRICAS, HIDRÁULICAS, GLP E PREVENTIVAS | B30: 0.076993587
A31: REVESTIMENTOS E ACABAMENTOS DE FACHADA | B31: 0.062136749
A32: PAREDES E DIVISÓRIAS | B32: 0.061364611
A33: EQUIPAMENTOS E SISTEMAS ESPECIAIS | B33: 0.058595253
A34: ESQUADRIAS, VIDROS E FERRAGENS | B34: 0.058515314
A35: SERVIÇOS COMPLEMENTARES | B35: 0.04818337
A36: INFRAESTRUTURA | B36: 0.038051995
A37: CONTENÇÃO | B37: 0.022860407
... A44: Total Geral | B44: 1

Sheet ANÁLISE_CUSTOS
A1: ETAPA | B1: SCENARIUM | D1: OBRAS DE REFERÊNCIA | E1: JUSTIFICATIVA
B2: VALOR | C2: VALOR / m² | D2: VALOR / m²
A3: =ORÇAMENTO_EXECUTIVO!A2 -> GERENCIAMENTO TÉCNICO E ADMINISTRATIVO | B3: =ORÇAMENTO_EXECUTIVO!B2 -> 22842123 | C3: =B3/ORÇAMENTO_EXECUTIVO!$G$2 -> 540.28685 | D3: =FIXED(CÁLCULO_MÉDIAS!V8,2,FALSE)&" "&"-"&FIXED(CÁLCULO_MÉDIAS!W8,2,FALSE) -> 330,00 -480,00
A4: =ORÇAMENTO_EXECUTIVO!A3 -> MOVIEMNTAÇÃO DE TERRA | B4: =ORÇAMENTO_EXECUTIVO!B3 -> 3078669.4 | C4: =B4/ORÇAMENTO_EXECUTIVO!$G$2 -> 72.820052 | D4: =FIXED(CÁLCULO_MÉDIAS!V9,2,FALSE)&" "&"-"&FIXED(CÁLCULO_MÉDIAS!W9,2,FALSE) -> 25,00 -38,00 | E4: Bastante horizontal - pedras
A5: INFRAESTRUTURA E CONTENÇÃO | B5: =ORÇAMENTO_EXECUTIVO!B4+ORÇAMENTO_EXECUTIVO!B5 -> 13428436 | C5: =B5/ORÇAMENTO_EXECUTIVO!$G$2 -> 317.62405 | D5: =FIXED(CÁLCULO_MÉDIAS!V10,2,FALSE)&" "&"-"&FIXED(CÁLCULO_MÉDIAS!W10,2,FALSE) -> 310,00 -450,00 | E5: Bastante horizontal - soluções mais otimizadas (grampeamento e muro de flexão)
A6: =ORÇAMENTO_EXECUTIVO!A6 -> SUPRAESTRUTURA | B6: =ORÇAMENTO_EXECUTIVO!B6 -> 30247018 | C6: =B6/ORÇAMENTO_EXECUTIVO!$G$2 -> 715.43551 | D6: =FIXED(CÁLCULO_MÉDIAS!V11,2,FALSE)&" "&"-"&FIXED(CÁLCULO_MÉDIAS!W11,2,FALSE) -> 680,00 -740,00
A7: =ORÇAMENTO_EXECUTIVO!A7 -> PAREDES E DIVISÓRIAS | B7: =ORÇAMENTO_EXECUTIVO!B7 -> 13469645 | C7: =B7/ORÇAMENTO_EXECUTIVO!$G$2 -> 318.59877 | D7: =FIXED(CÁLCULO_MÉDIAS!V12,2,FALSE)&" "&"-"&FIXED(CÁLCULO_MÉDIAS!W12,2,FALSE) -> 115,00 -150,00 | E7: Steel frame
A8: =ORÇAMENTO_EXECUTIVO!A8 -> INSTALAÇÕES ELÉTRICAS, HIDRÁULICAS, GLP E PREVENTIVAS | B8: =ORÇAMENTO_EXECUTIVO!B8 -> 16985534 | C8: =B8/ORÇAMENTO_EXECUTIVO!$G$2 -> 401.76041 | D8: =FIXED(CÁLCULO_MÉDIAS!V13,2,FALSE)&" "&"-"&FIXED(CÁLCULO_MÉDIAS!W13,2,FALSE) -> 330,00 -350,00 | E8: Tubulação k5 | AA8: DIFERENÇAS EM QUNATITATIVOS:
A9: =ORÇAMENTO_EXECUTIVO!A9 -> EQUIPAMENTOS E SISTEMAS ESPECIAIS | B9: =ORÇAMENTO_EXECUTIVO!B9 -> 12866747 | C9: =B9/ORÇAMENTO_EXECUTIVO!$G$2 -> 304.33835 | D9: =FIXED(CÁLCULO_MÉDIAS!V14,2,FALSE)&" "&"-"&FIXED(CÁLCULO_MÉDIAS!W14,2,FALSE) -> 180,00 -250,00 | E9: Piscinas igui, aspiração central, escada helicoidal, nichos, exaustçao de subsolo | AA9: PISOS - AREAS TECNICAS E LAJES APENAS COM CONTRAPISO, SEM REVESTIMENTO
A10: =ORÇAMENTO_EXECUTIVO!A10 -> IMPERMEABILIZAÇÃO | B10: =ORÇAMENTO_EXECUTIVO!B10 -> 2429082.6 | C10: =B10/ORÇAMENTO_EXECUTIVO!$G$2 -> 57.455316 | D10: =FIXED(CÁLCULO_MÉDIAS!V15,2,FALSE)&" "&"-"&FIXED(CÁLCULO_MÉDIAS!W15,2,FALSE) -> 40,00 -75,00
A11: =ORÇAMENTO_EXECUTIVO!A11 -> REVESTIMENTOS INTERNOS EM PISO E PAREDE | B11: =ORÇAMENTO_EXECUTIVO!B11 -> 3615206.3 | C11: =B11/ORÇAMENTO_EXECUTIVO!$G$2 -> 85.51081 | D11: =FIXED(CÁLCULO_MÉDIAS!V16,2,FALSE)&" "&"-"&FIXED(CÁLCULO_MÉDIAS!W16,2,FALSE) -> 140,00 -170,00 | E11: Steel frame
A12: =ORÇAMENTO_EXECUTIVO!A12 -> REVESTIMENTOS E ACABAMENTOS INTERNOS EM TETO | B12: =ORÇAMENTO_EXECUTIVO!B12 -> 2666469.6 | C12: =B12/ORÇAMENTO_EXECUTIVO!$G$2 -> 63.070252 | D12: =FIXED(CÁLCULO_MÉDIAS!V17,2,FALSE)&" "&"-"&FIXED(CÁLCULO_MÉDIAS!W17,2,FALSE) -> 50,00 -65,00
A13: =ORÇAMENTO_EXECUTIVO!A13 -> ACABAMENTOS EM PISO E PAREDE | B13: =ORÇAMENTO_EXECUTIVO!B13 -> 26983602 | C13: =B13/ORÇAMENTO_EXECUTIVO!$G$2 -> 638.24563 | D13: =FIXED(CÁLCULO_MÉDIAS!V18,2,FALSE)&" "&"-"&FIXED(CÁLCULO_MÉDIAS!W18,2,FALSE) -> 140,00 -210,00 | E13: Marmore travertino R$ 1600,00/m2
A14: =ORÇAMENTO_EXECUTIVO!A14 -> PINTURA INTERNA | B14: =ORÇAMENTO_EXECUTIVO!B14 -> 4509003.5 | C14: =B14/ORÇAMENTO_EXECUTIVO!$G$2 -> 106.65188 | D14: =FIXED(CÁLCULO_MÉDIAS!V19,2,FALSE)&" "&"-"&FIXED(CÁLCULO_MÉDIAS!W19,2,FALSE) -> 105,00 -130,00
A15: =ORÇAMENTO_EXECUTIVO!A15 -> ESQUADRIAS, VIDROS E FERRAGENS | B15: =ORÇAMENTO_EXECUTIVO!B15 -> 24788341 | C15: =B15/ORÇAMENTO_EXECUTIVO!$G$2 -> 586.32092 | D15: =FIXED(CÁLCULO_MÉDIAS!V20,2,FALSE)&" "&"-"&FIXED(CÁLCULO_MÉDIAS!W20,2,FALSE) -> 350,00 -480,00
A16: =ORÇAMENTO_EXECUTIVO!A16 -> COBERTURA | B16: =ORÇAMENTO_EXECUTIVO!B16 -> 1253778.1 | C16: =B16/ORÇAMENTO_EXECUTIVO!$G$2 -> 29.655729 | D16: =FIXED(CÁLCULO_MÉDIAS!V21,2,FALSE)&" "&"-"&FIXED(CÁLCULO_MÉDIAS!W21,2,FALSE) -> 5,00 -12,00 | E16: pergolados
A17: =ORÇAMENTO_EXECUTIVO!A17 -> REVESTIMENTOS E ACABAMENTOS DE FACHADA | B17: =ORÇAMENTO_EXECUTIVO!B17 -> 13641661 | C17: =B17/ORÇAMENTO_EXECUTIVO!$G$2 -> 322.66747 | D17: =FIXED(CÁLCULO_MÉDIAS!V22,2,FALSE)&" "&"-"&FIXED(CÁLCULO_MÉDIAS!W22,2,FALSE) -> 190,00 -215,00 | E17: Marmore travertino R$ 1600,00/m2
A18: =ORÇAMENTO_EXECUTIVO!A18 -> SERVIÇOS COMPLEMENTARES | B18: =ORÇAMENTO_EXECUTIVO!B18 -> 10814389 | C18: =B18/ORÇAMENTO_EXECUTIVO!$G$2 -> 255.79374 | D18: =FIXED(CÁLCULO_MÉDIAS!V23,2,FALSE)&" "&"-"&FIXED(CÁLCULO_MÉDIAS!W23,2,FALSE) -> 180,00 -210,00 | E18: Mobiliario assinado
A19: TOTAL | B19: =SUM(B3:B18) -> 2.0361971e+08 | C19: =SUM(C3:C18) -> 4816.2357 | D19: =FIXED(CÁLCULO_MÉDIAS!V24,2,FALSE)&" "&"-"&FIXED(CÁLCULO_MÉDIAS!W24,2,FALSE) -> 3.170,00 -4.025,00
AE502: =25/3 -> 8.3333333

Sheet CÁLCULO_MÉDIAS
C2: área | D2: 10520.39 | E2: área | F2: 12518.96 | G2: área | H2: 13434.29 | I2: área | J2: 61763.96 | K2: área | L2: 6003.01 | M2: área | AA2: área | AC2: área | AE2: área | AG2: área | AI2: área
C3: DATA BASE | D3: 45047 | E3: DATA BASE | F3: 45383 | G3: DATA BASE | H3: 45323 | I3: DATA BASE | J3: 45231 | K3: DATA BASE | L3: 44682 | M3: DATA BASE | N3: 45017 | O3: DATA BASE | P3: 44986 | Q3: DATA BASE | R3: 44958 | S3: DATA BASE | T3: 45078 | AA3: DATA BASE | AB3: 44866 | AC3: DATA BASE | AD3: 44256 | AE3: DATA BASE | AF3: 44958 | AG3: DATA BASE | AH3: 45047 | AI3: DATA BASE | AJ3: 45261 | AK3: DATA BASE | AL3: 44774
C4: CUB | D4: 2688.94 | E4: CUB | F4: 2757.56 | G4: CUB | H4: 2753.62 | I4: CUB | J4: 2754.98 | K4: CUB | L4: 2470.83 | M4: CUB | N4: 2680.84 | O4: CUB | P4: 2671.09 | Q4: CUB | R4: 2662.47 | S4: CUB | T4: 2725.79 | U4: =170/J2 -> 0.0027524142 | AA4: CUB | AB4: 2633.22 | AC4: CUB | AD4: 2140.56 | AE4: CUB | AF4: 2662.47 | AG4: CUB | AH4: 2688.94 | AI4: CUB | AJ4: 2752.67 | AK4: CUB | AL4: 2572.55
F5: 254976.79 | G5: =F5/F2 -> 20.36725
C6: LIBERATO | E6: GRAN TORINO | G6: RAVELLO | I6: BRAVA OCEAN | K6: BRAVA - VALLEY | M6: PAESSAGGIO | O6: BRASIN | Q6: LUMIS | S6: ADDA | V6: MÉDIAS | AA6: DOM BOSCO | AC6: SAN MARINO | AE6: DOM | AG6: PAESSAGGIO | AI6: THOZEN | AK6: HABITAH
C7: VALOR / M2 | D7: INDEXADO | E7: VALOR / M2 | F7: INDEXADO | G7: VALOR / M2 | H7: INDEXADO | I7: VALOR / M2 | J7: INDEXADO | M7: VALOR / M2 | N7: INDEXADO | O7: VALOR / M2 | P7: INDEXADO | Q7: VALOR / M2 | R7: INDEXADO | S7: VALOR / M2 | T7: INDEXADO | V7: MÍNIMA | W7: MÁXIMA | AA7: VALOR / M2 | AB7: INDEXADO | AC7: VALOR / M2 | AD7: INDEXADO | AE7: VALOR / M2 | AF7: INDEXADO | AG7: VALOR / M2 | AH7: INDEXADO | AI7: VALOR / M2 | AJ7: INDEXADO | AK7: VALOR / M2 | AL7: INDEXADO
B8: GERENCIAMENTO TECNICO E ADMINISTRATIVO | C8: 283.33076 | D8: =(ORÇAMENTO_EXECUTIVO!$B$21/CÁLCULO_MÉDIAS!D$4)*C8 -> 336.20806 | E8: 336.40234 | F8: =(ORÇAMENTO_EXECUTIVO!$B$21/CÁLCULO_MÉDIAS!F$4)*E8 -> 389.25082 | G8: 387.84287 | H8: =(ORÇAMENTO_EXECUTIVO!$B$21/CÁLCULO_MÉDIAS!H$4)*G8 -> 449.41473 | I8: 505.35308 | J8: =(ORÇAMENTO_EXECUTIVO!$B$21/CÁLCULO_MÉDIAS!J$4)*I8 -> 585.29117 | K8: 368.15437 | L8: =(ORÇAMENTO_EXECUTIVO!$B$21/CÁLCULO_MÉDIAS!L$4)*K8 -> 475.42563 | M8: =306.853550565509+12.39 -> 319.24355 | N8: =(ORÇAMENTO_EXECUTIVO!$B$21/CÁLCULO_MÉDIAS!N$4)*M8 -> 379.96775 | O8: 458.34014 | P8: =(ORÇAMENTO_EXECUTIVO!$B$21/CÁLCULO_MÉDIAS!P$4)*O8 -> 547.51355 | Q8: 192.5376 | R8: =(ORÇAMENTO_EXECUTIVO!$B$21/CÁLCULO_MÉDIAS!R$4)*Q8 -> 230.74183 | S8: 322.07783 | T8: =(ORÇAMENTO_EXECUTIVO!$B$21/CÁLCULO_MÉDIAS!T$4)*S8 -> 377.01961 | V8: 330 | W8: 480 | AA8: 330.18696 | AB8: =(ORÇAMENTO_EXECUTIVO!#REF!/CÁLCULO_MÉDIAS!AB$4)*AA8 -> #REF! | AC8: =53.76+152.58 -> 206.34 | AD8: =(ORÇAMENTO_EXECUTIVO!#REF!/CÁLCULO_MÉDIAS!AD$4)*AC8 -> #REF! | AE8: 425.96974 | AF8: =(ORÇAMENTO_EXECUTIVO!#REF!/CÁLCULO_MÉDIAS!AF$4)*AE8 -> #REF! | AG8: =306.853550565509+12.39 -> 319.24355 | AH8: =(ORÇAMENTO_EXECUTIVO!#REF!/CÁLCULO_MÉDIAS!AH$4)*AG8 -> #REF! | AI8: 393.04915 | AJ8: =(ORÇAMENTO_EXECUTIVO!#REF!/CÁLCULO_MÉDIAS!AJ$4)*AI8 -> #REF! | AK8: 307.80119 | AL8: =(ORÇAMENTO_EXECUTIVO!#REF!/CÁLCULO_MÉDIAS!AL$4)*AK8 -> #REF!
B9: MOVIMENTAÇÃO DE TERRA | D9: =(ORÇAMENTO_EXECUTIVO!$B$21/CÁLCULO_MÉDIAS!D$4)*C9 -> 0 | E9: 0 | F9: =(ORÇAMENTO_EXECUTIVO!$B$21/CÁLCULO_MÉDIAS!F$4)*E9 -> 0 | G9: 6.8428238 | H9: =(ORÇAMENTO_EXECUTIVO!$B$21/CÁLCULO_MÉDIAS!H$4)*G9 -> 7.929154 | I9: 40.091957 | J9: =(ORÇAMENTO_EXECUTIVO!$B$21/CÁLCULO_MÉDIAS!J$4)*I9 -> 46.433808 | K9: 4.3941695 | L9: =(ORÇAMENTO_EXECUTIVO!$B$21/CÁLCULO_MÉDIAS!L$4)*K9 -> 5.674524 | M9: 26.515285 | N9: =(ORÇAMENTO_EXECUTIVO!$B$21/CÁLCULO_MÉDIAS!N$4)*M9 -> 31.558831 | O9: 51.378113 | P9: =(ORÇAMENTO_EXECUTIVO!$B$21/CÁLCULO_MÉDIAS!P$4)*O9 -> 61.374099 | Q9: 131.35298 | R9: =(ORÇAMENTO_EXECUTIVO!$B$21/CÁLCULO_MÉDIAS!R$4)*Q9 -> 157.41667 | S9: 16.687144 | T9: =(ORÇAMENTO_EXECUTIVO!$B$21/CÁLCULO_MÉDIAS!T$4)*S9 -> 19.533728 | V9: 25 | W9: 38 | AA9: 0 | AB9: =(ORÇAMENTO_EXECUTIVO!#REF!/CÁLCULO_MÉDIAS!AB$4)*AA9 -> #REF! | AC9: 0 | AD9: =(ORÇAMENTO_EXECUTIVO!#REF!/CÁLCULO_MÉDIAS!AD$4)*AC9 -> #REF! | AE9: 19.58779 | AF9: =(ORÇAMENTO_EXECUTIVO!#REF!/CÁLCULO_MÉDIAS!AF$4)*AE9 -> #REF! | AG9: 26.515285 | AH9: =(ORÇAMENTO_EXECUTIVO!#REF!/CÁLCULO_MÉDIAS!AH$4)*AG9 -> #REF! | AI9: 17.922886 | AJ9: =(ORÇAMENTO_EXECUTIVO!#REF!/CÁLCULO_MÉDIAS!AJ$4)*AI9 -> #REF! | AK9: 0 | AL9: =(ORÇAMENTO_EXECUTIVO!#REF!/CÁLCULO_MÉDIAS!AL$4)*AK9 -> #REF!
B10: INFRAESTRUTURA | C10: 171.5507 | D10: =(ORÇAMENTO_EXECUTIVO!$B$21/CÁLCULO_MÉDIAS!D$4)*C10 -> 203.56677 | E10: 162.9 | F10: =(ORÇAMENTO_EXECUTIVO!$B$21/CÁLCULO_MÉDIAS!F$4)*E10 -> 188.49143 | G10: 169.2913 | H10: =(ORÇAMENTO_EXECUTIVO!$B$21/CÁLCULO_MÉDIAS!H$4)*G10 -> 196.16708 | I10: 220.23825 | J10: =(ORÇAMENTO_EXECUTIVO!$B$21/CÁLCULO_MÉDIAS!J$4)*I10 -> 255.07611 | K10: 71.913534 | L10: =(ORÇAMENTO_EXECUTIVO!$B$21/CÁLCULO_MÉDIAS!L$4)*K10 -> 92.867396 | M10: =268.371509227372+41.56 -> 309.93151 | N10: =(ORÇAMENTO_EXECUTIVO!$B$21/CÁLCULO_MÉDIAS!N$4)*M10 -> 368.88444 | O10: 454.9241 | P10: =(ORÇAMENTO_EXECUTIVO!$B$21/CÁLCULO_MÉDIAS!P$4)*O10 -> 543.4329 | Q10: 99.325701 | R10: =(ORÇAMENTO_EXECUTIVO!$B$21/CÁLCULO_MÉDIAS!R$4)*Q10 -> 119.03438 | S10: 196.37958 | T10: =(ORÇAMENTO_EXECUTIVO!$B$21/CÁLCULO_MÉDIAS!T$4)*S10 -> 229.87907 | V10: 310 | W10: 450 | X10: parede diafragma | AA10: 138.77425 | AB10: =(ORÇAMENTO_EXECUTIVO!#REF!/CÁLCULO_MÉDIAS!AB$4)*AA10 -> #REF! | AC10: 203.75 | AD10: =(ORÇAMENTO_EXECUTIVO!#REF!/CÁLCULO_MÉDIAS!AD$4)*AC10 -> #REF! | AE10: 195.5904 | AF10: =(ORÇAMENTO_EXECUTIVO!#REF!/CÁLCULO_MÉDIAS!AF$4)*AE10 -> #REF! | AG10: =268.371509227372+41.56 -> 309.93151 | AH10: =(ORÇAMENTO_EXECUTIVO!#REF!/CÁLCULO_MÉDIAS!AH$4)*AG10 -> #REF! | AI10: 227.46251 | AJ10: =(ORÇAMENTO_EXECUTIVO!#REF!/CÁLCULO_MÉDIAS!AJ$4)*AI10 -> #REF! | AK10: 145.26 | AL10: =(ORÇAMENTO_EXECUTIVO!#REF!/CÁLCULO_MÉDIAS!AL$4)*AK10 -> #REF!
B11: SUPRAESTRUTURA | C11: 648.94588 | D11: =(ORÇAMENTO_EXECUTIVO!$B$21/CÁLCULO_MÉDIAS!D$4)*C11 -> 770.05699 | E11: 655 | F11: =(ORÇAMENTO_EXECUTIVO!$B$21/CÁLCULO_MÉDIAS!F$4)*E11 -> 757.89986 | G11: 638.86 | H11: =(ORÇAMENTO_EXECUTIVO!$B$21/CÁLCULO_MÉDIAS!H$4)*G11 -> 740.282 | I11: 766.93483 | J11: =(ORÇAMENTO_EXECUTIVO!$B$21/CÁLCULO_MÉDIAS!J$4)*I11 -> 888.2506 | K11: 330.42046 | L11: =(ORÇAMENTO_EXECUTIVO!$B$21/CÁLCULO_MÉDIAS!L$4)*K11 -> 426.69698 | M11: =424.075395917568+352.64 -> 776.7154 | N11: =(ORÇAMENTO_EXECUTIVO!$B$21/CÁLCULO_MÉDIAS!N$4)*M11 -> 924.45658 | O11: 753.32947 | P11: =(ORÇAMENTO_EXECUTIVO!$B$21/CÁLCULO_MÉDIAS!P$4)*O11 -> 899.8952 | Q11: 670.8352 | R11: =(ORÇAMENTO_EXECUTIVO!$B$21/CÁLCULO_MÉDIAS!R$4)*Q11 -> 803.94552 | S11: 705.38371 | T11: =(ORÇAMENTO_EXECUTIVO!$B$21/CÁLCULO_MÉDIAS!T$4)*S11 -> 825.71187 | V11: 680 | W11: 740 | AA11: 440.21003 | AB11: =(ORÇAMENTO_EXECUTIVO!#REF!/CÁLCULO_MÉDIAS!AB$4)*AA11 -> #REF! | AC11: 516.11 | AD11: =(ORÇAMENTO_EXECUTIVO!#REF!/CÁLCULO_MÉDIAS!AD$4)*AC11 -> #REF! | AE11: 730.88829 | AF11: =(ORÇAMENTO_EXECUTIVO!#REF!/CÁLCULO_MÉDIAS!AF$4)*AE11 -> #REF! | AG11: =424.075395917568+352.64 -> 776.7154 | AH11: =(ORÇAMENTO_EXECUTIVO!#REF!/CÁLCULO_MÉDIAS!AH$4)*AG11 -> #REF! | AI11: 753.33241 | AJ11: =(ORÇAMENTO_EXECUTIVO!#REF!/CÁLCULO_MÉDIAS!AJ$4)*AI11 -> #REF! | AK11: 684.09 | AL11: =(ORÇAMENTO_EXECUTIVO!#REF!/CÁLCULO_MÉDIAS!AL$4)*AK11 -> #REF!
B12: ALVENARIA | C12: 146.27237 | D12: =(ORÇAMENTO_EXECUTIVO!$B$21/CÁLCULO_MÉDIAS!D$4)*C12 -> 173.57081 | E12: 122.73 | F12: =(ORÇAMENTO_EXECUTIVO!$B$21/CÁLCULO_MÉDIAS!F$4)*E12 -> 142.01076 | G12: 117.55 | H12: =(ORÇAMENTO_EXECUTIVO!$B$21/CÁLCULO_MÉDIAS!H$4)*G12 -> 136.21161 | I12: 108.78678 | J12: =(ORÇAMENTO_EXECUTIVO!$B$21/CÁLCULO_MÉDIAS!J$4)*I12 -> 125.99496 | K12: 106.29101 | L12: =(ORÇAMENTO_EXECUTIVO!$B$21/CÁLCULO_MÉDIAS!L$4)*K12 -> 137.26163 | M12: =45.9182137373762+52.78 -> 98.698214 | N12: =(ORÇAMENTO_EXECUTIVO!$B$21/CÁLCULO_MÉDIAS!N$4)*M12 -> 117.47187 | O12: 144.44742 | P12: =(ORÇAMENTO_EXECUTIVO!$B$21/CÁLCULO_MÉDIAS!P$4)*O12 -> 172.55072 | Q12: 151.38702 | R12: =(ORÇAMENTO_EXECUTIVO!$B$21/CÁLCULO_MÉDIAS!R$4)*Q12 -> 181.42595 | S12: 126.28174 | T12: =(ORÇAMENTO_EXECUTIVO!$B$21/CÁLCULO_MÉDIAS!T$4)*S12 -> 147.82356 | V12: 115 | W12: 150 | AA12: 119.63619 | AB12: =(ORÇAMENTO_EXECUTIVO!#REF!/CÁLCULO_MÉDIAS!AB$4)*AA12 -> #REF! | AC12: 87.63 | AD12: =(ORÇAMENTO_EXECUTIVO!#REF!/CÁLCULO_MÉDIAS!AD$4)*AC12 -> #REF! | AE12: 119.11837 | AF12: =(ORÇAMENTO_EXECUTIVO!#REF!/CÁLCULO_MÉDIAS!AF$4)*AE12 -> #REF! | AG12: =45.9182137373762+52.78 -> 98.698214 | AH12: =(ORÇAMENTO_EXECUTIVO!#REF!/CÁLCULO_MÉDIAS!AH$4)*AG12 -> #REF! | AI12: 120.12284 | AJ12: =(ORÇAMENTO_EXECUTIVO!#REF!/CÁLCULO_MÉDIAS!AJ$4)*AI12 -> #REF! | AK12: 102.26703 | AL12: =(ORÇAMENTO_EXECUTIVO!#REF!/CÁLCULO_MÉDIAS!AL$4)*AK12 -> #REF!
B13: INSTALAÇÕES ELÉTRICAS, HIDRÁULICAS, GLP E PREVENTIVAS | C13: 273.47993 | D13: =(ORÇAMENTO_EXECUTIVO!$B$21/CÁLCULO_MÉDIAS!D$4)*C13 -> 324.51878 | E13: 346.19 | F13: =(ORÇAMENTO_EXECUTIVO!$B$21/CÁLCULO_MÉDIAS!F$4)*E13 -> 400.57611 | G13: 333.15 | H13: =(ORÇAMENTO_EXECUTIVO!$B$21/CÁLCULO_MÉDIAS!H$4)*G13 -> 386.03911 | I13: 308.48586 | J13: =(ORÇAMENTO_EXECUTIVO!$B$21/CÁLCULO_MÉDIAS!J$4)*I13 -> 357.28297 | K13: 696.27623 | L13: =(ORÇAMENTO_EXECUTIVO!$B$21/CÁLCULO_MÉDIAS!L$4)*K13 -> 899.15426 | M13: =133.232025739994+119 -> 252.23203 | N13: =(ORÇAMENTO_EXECUTIVO!$B$21/CÁLCULO_MÉDIAS!N$4)*M13 -> 300.20978 | O13: 356.29492 | P13: =(ORÇAMENTO_EXECUTIVO!$B$21/CÁLCULO_MÉDIAS!P$4)*O13 -> 425.61469 | Q13: 301.65243 | R13: =(ORÇAMENTO_EXECUTIVO!$B$21/CÁLCULO_MÉDIAS!R$4)*Q13 -> 361.50774 | S13: 253.86928 | T13: =(ORÇAMENTO_EXECUTIVO!$B$21/CÁLCULO_MÉDIAS!T$4)*S13 -> 297.17567 | V13: 330 | W13: 350 | AA13: 241.53845 | AB13: =(ORÇAMENTO_EXECUTIVO!#REF!/CÁLCULO_MÉDIAS!AB$4)*AA13 -> #REF! | AC13: =115.12+96.69+17.4 -> 229.21 | AD13: =(ORÇAMENTO_EXECUTIVO!#REF!/CÁLCULO_MÉDIAS!AD$4)*AC13 -> #REF! | AE13: 311.09537 | AF13: =(ORÇAMENTO_EXECUTIVO!#REF!/CÁLCULO_MÉDIAS!AF$4)*AE13 -> #REF! | AG13: =133.232025739994+119 -> 252.23203 | AH13: =(ORÇAMENTO_EXECUTIVO!#REF!/CÁLCULO_MÉDIAS!AH$4)*AG13 -> #REF! | AI13: 343.65138 | AJ13: =(ORÇAMENTO_EXECUTIVO!#REF!/CÁLCULO_MÉDIAS!AJ$4)*AI13 -> #REF! | AK13: 395.6489 | AL13: =(ORÇAMENTO_EXECUTIVO!#REF!/CÁLCULO_MÉDIAS!AL$4)*AK13 -> #REF!
B14: EQUIPAMENTOS E SISTEMAS ESPECIAIS | C14: 153.14326 | D14: =(ORÇAMENTO_EXECUTIVO!$B$21/CÁLCULO_MÉDIAS!D$4)*C14 -> 181.72399 | E14: 163.3 | F14: =(ORÇAMENTO_EXECUTIVO!$B$21/CÁLCULO_MÉDIAS!F$4)*E14 -> 188.95427 | G14: 118.21 | H14: =(ORÇAMENTO_EXECUTIVO!$B$21/CÁLCULO_MÉDIAS!H$4)*G14 -> 136.97639 | I14: 154.01107 | J14: =(ORÇAMENTO_EXECUTIVO!$B$21/CÁLCULO_MÉDIAS!J$4)*I14 -> 178.37294 | K14: 169.51893 | L14: =(ORÇAMENTO_EXECUTIVO!$B$21/CÁLCULO_MÉDIAS!L$4)*K14 -> 218.91264 | M14: 247.28447 | N14: =(ORÇAMENTO_EXECUTIVO!$B$21/CÁLCULO_MÉDIAS!N$4)*M14 -> 294.32113 | O14: 271.10199 | P14: =(ORÇAMENTO_EXECUTIVO!$B$21/CÁLCULO_MÉDIAS!P$4)*O14 -> 323.84685 | Q14: 121.62815 | R14: =(ORÇAMENTO_EXECUTIVO!$B$21/CÁLCULO_MÉDIAS!R$4)*Q14 -> 145.76219 | S14: 186.37267 | T14: =(ORÇAMENTO_EXECUTIVO!$B$21/CÁLCULO_MÉDIAS!T$4)*S14 -> 218.16513 | V14: 180 | W14: 250 | AA14: 125.58392 | AB14: =(ORÇAMENTO_EXECUTIVO!#REF!/CÁLCULO_MÉDIAS!AB$4)*AA14 -> #REF! | AC14: =126.98+36.9 -> 163.88 | AD14: =(ORÇAMENTO_EXECUTIVO!#REF!/CÁLCULO_MÉDIAS!AD$4)*AC14 -> #REF! | AE14: 234.95757 | AF14: =(ORÇAMENTO_EXECUTIVO!#REF!/CÁLCULO_MÉDIAS!AF$4)*AE14 -> #REF! | AG14: 247.28447 | AH14: =(ORÇAMENTO_EXECUTIVO!#REF!/CÁLCULO_MÉDIAS!AH$4)*AG14 -> #REF! | AI14: 183.52385 | AJ14: =(ORÇAMENTO_EXECUTIVO!#REF!/CÁLCULO_MÉDIAS!AJ$4)*AI14 -> #REF! | AK14: 151.23889 | AL14: =(ORÇAMENTO_EXECUTIVO!#REF!/CÁLCULO_MÉDIAS!AL$4)*AK14 -> #REF!
B15: IMPERMEABILIZAÇÃO | C15: 69.707842 | D15: =(ORÇAMENTO_EXECUTIVO!$B$21/CÁLCULO_MÉDIAS!D$4)*C15 -> 82.717238 | E15: 43.36 | F15: =(ORÇAMENTO_EXECUTIVO!$B$21/CÁLCULO_MÉDIAS!F$4)*E15 -> 50.171814 | G15: 59.85 | H15: =(ORÇAMENTO_EXECUTIVO!$B$21/CÁLCULO_MÉDIAS!H$4)*G15 -> 69.351466 | I15: 90.758973 | J15: =(ORÇAMENTO_EXECUTIVO!$B$21/CÁLCULO_MÉDIAS!J$4)*I15 -> 105.11547 | K15: 47.920219 | L15: =(ORÇAMENTO_EXECUTIVO!$B$21/CÁLCULO_MÉDIAS!L$4)*K15 -> 61.88301 | M15: =21.1585217854063+29.7 -> 50.858522 | N15: =(ORÇAMENTO_EXECUTIVO!$B$21/CÁLCULO_MÉDIAS!N$4)*M15 -> 60.532462 | O15: 83.531526 | P15: =(ORÇAMENTO_EXECUTIVO!$B$21/CÁLCULO_MÉDIAS!P$4)*O15 -> 99.783193 | Q15: 61.191658 | R15: =(ORÇAMENTO_EXECUTIVO!$B$21/CÁLCULO_MÉDIAS!R$4)*Q15 -> 73.333599 | S15: 40.10434 | T15: =(ORÇAMENTO_EXECUTIVO!$B$21/CÁLCULO_MÉDIAS!T$4)*S15 -> 46.945555 | V15: 40 | W15: 75 | AA15: 28.96163 | AB15: =(ORÇAMENTO_EXECUTIVO!#REF!/CÁLCULO_MÉDIAS!AB$4)*AA15 -> #REF! | AC15: 46.01 | AD15: =(ORÇAMENTO_EXECUTIVO!#REF!/CÁLCULO_MÉDIAS!AD$4)*AC15 -> #REF! | AE15: 40.38554 | AF15: =(ORÇAMENTO_EXECUTIVO!#REF!/CÁLCULO_MÉDIAS!AF$4)*AE15 -> #REF! | AG15: =21.1585217854063+29.7 -> 50.858522 | AH15: =(ORÇAMENTO_EXECUTIVO!#REF!/CÁLCULO_MÉDIAS!AH$4)*AG15 -> #REF! | AI15: 53.97562 | AJ15: =(ORÇAMENTO_EXECUTIVO!#REF!/CÁLCULO_MÉDIAS!AJ$4)*AI15 -> #REF! | AK15: 26.84 | AL15: =(ORÇAMENTO_EXECUTIVO!#REF!/CÁLCULO_MÉDIAS!AL$4)*AK15 -> #REF!
B16: REVESTIMENTOS INTERNOS EM PISO E PAREDE | C16: 152.31227 | D16: =(ORÇAMENTO_EXECUTIVO!$B$21/CÁLCULO_MÉDIAS!D$4)*C16 -> 180.73792 | E16: 146.21 | F16: =(ORÇAMENTO_EXECUTIVO!$B$21/CÁLCULO_MÉDIAS!F$4)*E16 -> 169.17945 | G16: 165.42 | H16: =(ORÇAMENTO_EXECUTIVO!$B$21/CÁLCULO_MÉDIAS!H$4)*G16 -> 191.6812 | I16: 91.153068 | J16: =(ORÇAMENTO_EXECUTIVO!$B$21/CÁLCULO_MÉDIAS!J$4)*I16 -> 105.5719 | K16: 163.06868 | L16: =(ORÇAMENTO_EXECUTIVO!$B$21/CÁLCULO_MÉDIAS!L$4)*K16 -> 210.58294 | M16: =61.5070901205645+125.46 -> 186.96709 | N16: =(ORÇAMENTO_EXECUTIVO!$B$21/CÁLCULO_MÉDIAS!N$4)*M16 -> 222.53062 | O16: 170.06207 | P16: =(ORÇAMENTO_EXECUTIVO!$B$21/CÁLCULO_MÉDIAS!P$4)*O16 -> 203.14889 | Q16: 161.7371 | R16: =(ORÇAMENTO_EXECUTIVO!$B$21/CÁLCULO_MÉDIAS!R$4)*Q16 -> 193.82975 | S16: 114.61672 | T16: =(ORÇAMENTO_EXECUTIVO!$B$21/CÁLCULO_MÉDIAS!T$4)*S16 -> 134.16866 | V16: 140 | W16: 170 | AA16: 234.72587 | AB16: =(ORÇAMENTO_EXECUTIVO!#REF!/CÁLCULO_MÉDIAS!AB$4)*AA16 -> #REF! | AC16: 107.18 | AD16: =(ORÇAMENTO_EXECUTIVO!#REF!/CÁLCULO_MÉDIAS!AD$4)*AC16 -> #REF! | AE16: 171.46501 | AF16: =(ORÇAMENTO_EXECUTIVO!#REF!/CÁLCULO_MÉDIAS!AF$4)*AE16 -> #REF! | AG16: =61.5070901205645+125.46 -> 186.96709 | AH16: =(ORÇAMENTO_EXECUTIVO!#REF!/CÁLCULO_MÉDIAS!AH$4)*AG16 -> #REF! | AI16: 181.93322 | AJ16: =(ORÇAMENTO_EXECUTIVO!#REF!/CÁLCULO_MÉDIAS!AJ$4)*AI16 -> #REF! | AK16: 143.04 | AL16: =(ORÇAMENTO_EXECUTIVO!#REF!/CÁLCULO_MÉDIAS!AL$4)*AK16 -> #REF!
B17: REVESTIMENTOS E ACABAMENTOS INTERNOS EM TETO | C17: 54.81864 | D17: =(ORÇAMENTO_EXECUTIVO!$B$21/CÁLCULO_MÉDIAS!D$4)*C17 -> 65.049303 | E17: 60.1 | F17: =(ORÇAMENTO_EXECUTIVO!$B$21/CÁLCULO_MÉDIAS!F$4)*E17 -> 69.541652 | G17: 56.68 | H17: =(ORÇAMENTO_EXECUTIVO!$B$21/CÁLCULO_MÉDIAS!H$4)*G17 -> 65.678214 | I17: 79.853996 | J17: =(ORÇAMENTO_EXECUTIVO!$B$21/CÁLCULO_MÉDIAS!J$4)*I17 -> 92.485511 | K17: 60.572927 | L17: =(ORÇAMENTO_EXECUTIVO!$B$21/CÁLCULO_MÉDIAS!L$4)*K17 -> 78.222411 | M17: =54.2873850783883+15.35 -> 69.637385 | N17: =(ORÇAMENTO_EXECUTIVO!$B$21/CÁLCULO_MÉDIAS!N$4)*M17 -> 82.883305 | O17: 97.026709 | P17: =(ORÇAMENTO_EXECUTIVO!$B$21/CÁLCULO_MÉDIAS!P$4)*O17 -> 115.90396 | Q17: 38.140863 | R17: =(ORÇAMENTO_EXECUTIVO!$B$21/CÁLCULO_MÉDIAS!R$4)*Q17 -> 45.708956 | S17: 33.709915 | T17: =(ORÇAMENTO_EXECUTIVO!$B$21/CÁLCULO_MÉDIAS!T$4)*S17 -> 39.460334 | V17: 50 | W17: 65 | AA17: 55.038679 | AB17: =(ORÇAMENTO_EXECUTIVO!#REF!/CÁLCULO_MÉDIAS!AB$4)*AA17 -> #REF! | AC17: 37.84 | AD17: =(ORÇAMENTO_EXECUTIVO!#REF!/CÁLCULO_MÉDIAS!AD$4)*AC17 -> #REF! | AE17: 82.252956 | AF17: =(ORÇAMENTO_EXECUTIVO!#REF!/CÁLCULO_MÉDIAS!AF$4)*AE17 -> #REF! | AG17: =54.2873850783883+15.35 -> 69.637385 | AH17: =(ORÇAMENTO_EXECUTIVO!#REF!/CÁLCULO_MÉDIAS!AH$4)*AG17 -> #REF! | AI17: 55.010609 | AJ17: =(ORÇAMENTO_EXECUTIVO!#REF!/CÁLCULO_MÉDIAS!AJ$4)*AI17 -> #REF! | AK17: 70.155612 | AL17: =(ORÇAMENTO_EXECUTIVO!#REF!/CÁLCULO_MÉDIAS!AL$4)*AK17 -> #REF!
B18: ACABAMENTOS EM PISO E PAREDE | C18: 210.03147 | D18: =(ORÇAMENTO_EXECUTIVO!$B$21/CÁLCULO_MÉDIAS!D$4)*C18 -> 249.22911 | E18: 153.35 | F18: =(ORÇAMENTO_EXECUTIVO!$B$21/CÁLCULO_MÉDIAS!F$4)*E18 -> 177.44114 | G18: 139.61 | H18: =(ORÇAMENTO_EXECUTIVO!$B$21/CÁLCULO_MÉDIAS!H$4)*G18 -> 161.77374 | I18: 220.71127 | J18: =(ORÇAMENTO_EXECUTIVO!$B$21/CÁLCULO_MÉDIAS!J$4)*I18 -> 255.62396 | K18: 203.44094 | L18: =(ORÇAMENTO_EXECUTIVO!$B$21/CÁLCULO_MÉDIAS!L$4)*K18 -> 262.7187 | M18: =128.113840140444+57.38 -> 185.49384 | N18: =(ORÇAMENTO_EXECUTIVO!$B$21/CÁLCULO_MÉDIAS!N$4)*M18 -> 220.77714 | O18: 197.59804 | P18: =(ORÇAMENTO_EXECUTIVO!$B$21/CÁLCULO_MÉDIAS!P$4)*O18 -> 236.04217 | Q18: 233.49804 | R18: =(ORÇAMENTO_EXECUTIVO!$B$21/CÁLCULO_MÉDIAS!R$4)*Q18 -> 279.82983 | S18: 151.57428 | T18: =(ORÇAMENTO_EXECUTIVO!$B$21/CÁLCULO_MÉDIAS!T$4)*S18 -> 177.43064 | V18: 140 | W18: 210 | AA18: 165.18749 | AB18: =(ORÇAMENTO_EXECUTIVO!#REF!/CÁLCULO_MÉDIAS!AB$4)*AA18 -> #REF! | AC18: 111.36 | AD18: =(ORÇAMENTO_EXECUTIVO!#REF!/CÁLCULO_MÉDIAS!AD$4)*AC18 -> #REF! | AE18: 171.08275 | AF18: =(ORÇAMENTO_EXECUTIVO!#REF!/CÁLCULO_MÉDIAS!AF$4)*AE18 -> #REF! | AG18: =128.113840140444+57.38 -> 185.49384 | AH18: =(ORÇAMENTO_EXECUTIVO!#REF!/CÁLCULO_MÉDIAS!AH$4)*AG18 -> #REF! | AI18: 148.70479 | AJ18: =(ORÇAMENTO_EXECUTIVO!#REF!/CÁLCULO_MÉDIAS!AJ$4)*AI18 -> #REF! | AK18: 167.78668 | AL18: =(ORÇAMENTO_EXECUTIVO!#REF!/CÁLCULO_MÉDIAS!AL$4)*AK18 -> #REF!
B19: PINTURA INTERNA | C19: 125.38088 | D19: =(ORÇAMENTO_EXECUTIVO!$B$21/CÁLCULO_MÉDIAS!D$4)*C19 -> 148.7804 | E19: 149.59 | F19: =(ORÇAMENTO_EXECUTIVO!$B$21/CÁLCULO_MÉDIAS!F$4)*E19 -> 173.09044 | G19: 136.5 | H19: =(ORÇAMENTO_EXECUTIVO!$B$21/CÁLCULO_MÉDIAS!H$4)*G19 -> 158.17001 | I19: 88.059982 | J19: =(ORÇAMENTO_EXECUTIVO!$B$21/CÁLCULO_MÉDIAS!J$4)*I19 -> 101.98954 | K19: 91.389271 | L19: =(ORÇAMENTO_EXECUTIVO!$B$21/CÁLCULO_MÉDIAS!L$4)*K19 -> 118.01789 | M19: =35.9030401086365+97.72 -> 133.62304 | N19: =(ORÇAMENTO_EXECUTIVO!$B$21/CÁLCULO_MÉDIAS!N$4)*M19 -> 159.03985 | O19: 107.13452 | P19: =(ORÇAMENTO_EXECUTIVO!$B$21/CÁLCULO_MÉDIAS!P$4)*O19 -> 127.97832 | Q19: 60.245257 | R19: =(ORÇAMENTO_EXECUTIVO!$B$21/CÁLCULO_MÉDIAS!R$4)*Q19 -> 72.199408 | S19: 128.87171 | T19: =(ORÇAMENTO_EXECUTIVO!$B$21/CÁLCULO_MÉDIAS!T$4)*S19 -> 150.85534 | V19: 105 | W19: 130 | AA19: 110.39979 | AB19: =(ORÇAMENTO_EXECUTIVO!#REF!/CÁLCULO_MÉDIAS!AB$4)*AA19 -> #REF! | AC19: 83.06 | AD19: =(ORÇAMENTO_EXECUTIVO!#REF!/CÁLCULO_MÉDIAS!AD$4)*AC19 -> #REF! | AE19: 131.71985 | AF19: =(ORÇAMENTO_EXECUTIVO!#REF!/CÁLCULO_MÉDIAS!AF$4)*AE19 -> #REF! | AG19: =35.9030401086365+97.72 -> 133.62304 | AH19: =(ORÇAMENTO_EXECUTIVO!#REF!/CÁLCULO_MÉDIAS!AH$4)*AG19 -> #REF! | AI19: 173.39863 | AJ19: =(ORÇAMENTO_EXECUTIVO!#REF!/CÁLCULO_MÉDIAS!AJ$4)*AI19 -> #REF! | AK19: 81.300168 | AL19: =(ORÇAMENTO_EXECUTIVO!#REF!/CÁLCULO_MÉDIAS!AL$4)*AK19 -> #REF!
B20: ESQUADRIAS, VIDROS E FERRAGENS | C20: 243.33429 | D20: =(ORÇAMENTO_EXECUTIVO!$B$21/CÁLCULO_MÉDIAS!D$4)*C20 -> 288.74715 | E20: 288.61 | F20: =(ORÇAMENTO_EXECUTIVO!$B$21/CÁLCULO_MÉDIAS!F$4)*E20 -> 333.95035 | G20: 223.84 | H20: =(ORÇAMENTO_EXECUTIVO!$B$21/CÁLCULO_MÉDIAS!H$4)*G20 -> 259.37564 | I20: 291.4143 | J20: =(ORÇAMENTO_EXECUTIVO!$B$21/CÁLCULO_MÉDIAS!J$4)*I20 -> 337.51098 | K20: 219.75659 | L20: =(ORÇAMENTO_EXECUTIVO!$B$21/CÁLCULO_MÉDIAS!L$4)*K20 -> 283.78833 | M20: =250.558807445514+9.23 -> 259.78881 | N20: =(ORÇAMENTO_EXECUTIVO!$B$21/CÁLCULO_MÉDIAS!N$4)*M20 -> 309.20396 | O20: 531.67128 | P20: =(ORÇAMENTO_EXECUTIVO!$B$21/CÁLCULO_MÉDIAS!P$4)*O20 -> 635.1118 | Q20: 393.73193 | R20: =(ORÇAMENTO_EXECUTIVO!$B$21/CÁLCULO_MÉDIAS!R$4)*Q20 -> 471.85809 | S20: 360.50074 | T20: =(ORÇAMENTO_EXECUTIVO!$B$21/CÁLCULO_MÉDIAS!T$4)*S20 -> 421.99691 | V20: 350 | W20: 480 | X20: ----------> | AA20: 147.28733 | AB20: =(ORÇAMENTO_EXECUTIVO!#REF!/CÁLCULO_MÉDIAS!AB$4)*AA20 -> #REF! | AC20: 186.71 | AD20: =(ORÇAMENTO_EXECUTIVO!#REF!/CÁLCULO_MÉDIAS!AD$4)*AC20 -> #REF! | AE20: 323.47432 | AF20: =(ORÇAMENTO_EXECUTIVO!#REF!/CÁLCULO_MÉDIAS!AF$4)*AE20 -> #REF! | AG20: =250.558807445514+9.23 -> 259.78881 | AH20: =(ORÇAMENTO_EXECUTIVO!#REF!/CÁLCULO_MÉDIAS!AH$4)*AG20 -> #REF! | AI20: 208.12266 | AJ20: =(ORÇAMENTO_EXECUTIVO!#REF!/CÁLCULO_MÉDIAS!AJ$4)*AI20 -> #REF! | AK20: 186.4553 | AL20: =(ORÇAMENTO_EXECUTIVO!#REF!/CÁLCULO_MÉDIAS!AL$4)*AK20 -> #REF!
B21: COBERTURA | C21: 0 | D21: =(ORÇAMENTO_EXECUTIVO!$B$21/CÁLCULO_MÉDIAS!D$4)*C21 -> 0 | E21: 2.47 | F21: =(ORÇAMENTO_EXECUTIVO!$B$21/CÁLCULO_MÉDIAS!F$4)*E21 -> 2.8580346 | H21: =(ORÇAMENTO_EXECUTIVO!$B$21/CÁLCULO_MÉDIAS!H$4)*G21 -> 0 | J21: =(ORÇAMENTO_EXECUTIVO!$B$21/CÁLCULO_MÉDIAS!J$4)*I21 -> 0 | L21: =(ORÇAMENTO_EXECUTIVO!$B$21/CÁLCULO_MÉDIAS!L$4)*K21 -> 0 | M21: 0 | N21: =(ORÇAMENTO_EXECUTIVO!$B$21/CÁLCULO_MÉDIAS!N$4)*M21 -> 0 | P21: =(ORÇAMENTO_EXECUTIVO!$B$21/CÁLCULO_MÉDIAS!P$4)*O21 -> 0 | Q21: 18.057176 | R21: =(ORÇAMENTO_EXECUTIVO!$B$21/CÁLCULO_MÉDIAS!R$4)*Q21 -> 21.640167 | S21: 5.2010821 | T21: =(ORÇAMENTO_EXECUTIVO!$B$21/CÁLCULO_MÉDIAS!T$4)*S21 -> 6.0883108 | V21: 5 | W21: 12 | AA21: 0 | AB21: =(ORÇAMENTO_EXECUTIVO!#REF!/CÁLCULO_MÉDIAS!AB$4)*AA21 -> #REF! | AC21: 12.08 | AD21: =(ORÇAMENTO_EXECUTIVO!#REF!/CÁLCULO_MÉDIAS!AD$4)*AC21 -> #REF! | AE21: 5.0049675 | AF21: =(ORÇAMENTO_EXECUTIVO!#REF!/CÁLCULO_MÉDIAS!AF$4)*AE21 -> #REF! | AG21: =2.57125170509111+1.44 -> 4.0112517 | AH21: =(ORÇAMENTO_EXECUTIVO!#REF!/CÁLCULO_MÉDIAS!AH$4)*AG21 -> #REF! | AI21: 13.493415 | AJ21: =(ORÇAMENTO_EXECUTIVO!#REF!/CÁLCULO_MÉDIAS!AJ$4)*AI21 -> #REF! | AK21: 8.67 | AL21: =(ORÇAMENTO_EXECUTIVO!#REF!/CÁLCULO_MÉDIAS!AL$4)*AK21 -> #REF!
B22: REVESTIMENTOS E ACABAMENTOS DE FACHADA | C22: 102.99303 | D22: =(ORÇAMENTO_EXECUTIVO!$B$21/CÁLCULO_MÉDIAS!D$4)*C22 -> 122.21436 | E22: 114.53 | F22: =(ORÇAMENTO_EXECUTIVO!$B$21/CÁLCULO_MÉDIAS!F$4)*E22 -> 132.52255 | G22: 162.49 | H22: =(ORÇAMENTO_EXECUTIVO!$B$21/CÁLCULO_MÉDIAS!H$4)*G22 -> 188.28604 | I22: 203.74923 | J22: =(ORÇAMENTO_EXECUTIVO!$B$21/CÁLCULO_MÉDIAS!J$4)*I22 -> 235.97882 | K22: 85.199371 | L22: =(ORÇAMENTO_EXECUTIVO!$B$21/CÁLCULO_MÉDIAS!L$4)*K22 -> 110.0244 | M22: =150.750039454126+64.44 -> 215.19004 | N22: =(ORÇAMENTO_EXECUTIVO!$B$21/CÁLCULO_MÉDIAS!N$4)*M22 -> 256.12193 | O22: 136.33577 | P22: =(ORÇAMENTO_EXECUTIVO!$B$21/CÁLCULO_MÉDIAS!P$4)*O22 -> 162.86089 | Q22: 152.18185 | R22: =(ORÇAMENTO_EXECUTIVO!$B$21/CÁLCULO_MÉDIAS!R$4)*Q22 -> 182.3785 | S22: 223.21246 | T22: =(ORÇAMENTO_EXECUTIVO!$B$21/CÁLCULO_MÉDIAS!T$4)*S22 -> 261.28925 | V22: 190 | W22: 215 | AA22: 26.873962 | AB22: =(ORÇAMENTO_EXECUTIVO!#REF!/CÁLCULO_MÉDIAS!AB$4)*AA22 -> #REF! | AC22: 126.33 | AD22: =(ORÇAMENTO_EXECUTIVO!#REF!/CÁLCULO_MÉDIAS!AD$4)*AC22 -> #REF! | AE22: 165.68145 | AF22: =(ORÇAMENTO_EXECUTIVO!#REF!/CÁLCULO_MÉDIAS!AF$4)*AE22 -> #REF! | AG22: =150.750039454126+64.44 -> 215.19004 | AH22: =(ORÇAMENTO_EXECUTIVO!#REF!/CÁLCULO_MÉDIAS!AH$4)*AG22 -> #REF! | AI22: 131.44434 | AJ22: =(ORÇAMENTO_EXECUTIVO!#REF!/CÁLCULO_MÉDIAS!AJ$4)*AI22 -> #REF! | AK22: 84.89 | AL22: =(ORÇAMENTO_EXECUTIVO!#REF!/CÁLCULO_MÉDIAS!AL$4)*AK22 -> #REF!
B23: SERVIÇOS COMPLEMENTARES | C23: 116.34736 | D23: =(ORÇAMENTO_EXECUTIVO!$B$21/CÁLCULO_MÉDIAS!D$4)*C23 -> 138.06097 | E23: 157.2 | F23: =(ORÇAMENTO_EXECUTIVO!$B$21/CÁLCULO_MÉDIAS!F$4)*E23 -> 181.89597 | G23: 165.48 | H23: =(ORÇAMENTO_EXECUTIVO!$B$21/CÁLCULO_MÉDIAS!H$4)*G23 -> 191.75072 | I23: 130.36455 | J23: =(ORÇAMENTO_EXECUTIVO!$B$21/CÁLCULO_MÉDIAS!J$4)*I23 -> 150.98596 | K23: 197.0076 | L23: =(ORÇAMENTO_EXECUTIVO!$B$21/CÁLCULO_MÉDIAS!L$4)*K23 -> 254.41084 | M23: =154.053109535665+12.4 -> 166.45311 | N23: =(ORÇAMENTO_EXECUTIVO!$B$21/CÁLCULO_MÉDIAS!N$4)*M23 -> 198.11462 | O23: 211.70893 | P23: =(ORÇAMENTO_EXECUTIVO!$B$21/CÁLCULO_MÉDIAS!P$4)*O23 -> 252.89844 | Q23: 152.5097 | R23: =(ORÇAMENTO_EXECUTIVO!$B$21/CÁLCULO_MÉDIAS!R$4)*Q23 -> 182.7714 | S23: 182.35745 | T23: =(ORÇAMENTO_EXECUTIVO!$B$21/CÁLCULO_MÉDIAS!T$4)*S23 -> 213.46497 | V23: 180 | W23: 210 | AA23: 125.12904 | AB23: =(ORÇAMENTO_EXECUTIVO!#REF!/CÁLCULO_MÉDIAS!AB$4)*AA23 -> #REF! | AC23: 74.23 | AD23: =(ORÇAMENTO_EXECUTIVO!#REF!/CÁLCULO_MÉDIAS!AD$4)*AC23 -> #REF! | AE23: 142.84172 | AF23: =(ORÇAMENTO_EXECUTIVO!#REF!/CÁLCULO_MÉDIAS!AF$4)*AE23 -> #REF! | AG23: =154.053109535665+12.4 -> 166.45311 | AH23: =(ORÇAMENTO_EXECUTIVO!#REF!/CÁLCULO_MÉDIAS!AH$4)*AG23 -> #REF! | AI23: 120.6576 | AJ23: =(ORÇAMENTO_EXECUTIVO!#REF!/CÁLCULO_MÉDIAS!AJ$4)*AI23 -> #REF! | AK23: 166.87012 | AL23: =(ORÇAMENTO_EXECUTIVO!#REF!/CÁLCULO_MÉDIAS!AL$4)*AK23 -> #REF!
B24: TOTAL | C24: =SUM(C8:C23) -> 2751.6487 | D24: =SUM(D8:D23) -> 3265.1819 | E24: =SUM(E8:E23) -> 2901.9423 | F24: =SUM(F8:F23) -> 3357.8347 | G24: =SUM(G8:G23) -> 2881.617 | H24: =SUM(H8:H23) -> 3339.0871 | I24: =SUM(I8:I23) -> 3299.9672 | J24: =SUM(J8:J23) -> 3821.9647 | ... T24: =SUM(T8:T23) -> 3567.0086 | V24: =SUM(V8:V23) -> 3170 | W24: =SUM(W8:W23) -> 4025 | AA24: =SUM(AA8:AA23) -> 2289.5336 | AB24: =SUM(AB8:AB23) -> #REF! | AC24: =SUM(AC8:AC23) -> 2191.72 | AD24: =SUM(AD8:AD23) -> #REF! | AE24: =SUM(AE8:AE23) -> 3271.1161 | AF24: =SUM(AF8:AF23) -> #REF! | AG24: =SUM(AG8:AG23) -> 3302.6435 | AH24: =SUM(AH8:AH23) -> #REF! | ... AL24: =SUM(AL8:AL23) -> #REF!
AC26: =AC24/AD4 -> 1.0239003

Sheet AREAS_PRIVATIVAS
A2: DESCRIÇÃO | B2: ÁREA (m²) | C2: QUANT. | D2: VALOR TOTAL | G2: DESCRIÇÃO | H2: ÁREA (m²) | I2: QUANT. | J2: VALOR TOTAL
A3: VALOR POR ÁREA PRIVATIVA (R$/m²) | B3: =SUMPRODUCT(B4:B21,C4:C21) -> 18462.8 | D3: =ORÇAMENTO_EXECUTIVO!#REF!/AREAS_PRIVATIVAS!B3 -> #REF! | G3: VALOR POR ÁREA PRIVATIVA (R$/m²) | H3: =SUM(H4:H9)*13+SUM(K4:K9) -> 9052.02 | J3: =ORÇAMENTO_EXECUTIVO!#REF!/AREAS_PRIVATIVAS!H3 -> #REF!
A4: 601 | B4: 227.35 | C4: 1 | D4: =B4*$D$3 -> #REF! | E4: 98.78 | G4: VALOR POR UNIDADE TIPO 01 | H4: 72.29 | I4: 6 | J4: =H4*$D$3 -> #REF! | K4: 86.29
A5: 602 | B5: 235.9 | C5: 1 | D5: =B5*$D$3 -> #REF! | E5: 78.65 | G5: VALOR POR UNIDADE TIPO 02 | H5: 87.86 | I5: =6+6 -> 12 | J5: =H5*$D$3 -> #REF! | K5: 99.74
A6: 603 | B6: 145.05 | C6: 1 | D6: =B6*$D$3 -> #REF! | E6: 87.5 | G6: VALOR POR UNIDADE TIPO 03 | H6: 96.26 | I6: 5 | J6: =H6*$D$3 -> #REF! | K6: 116.13
A7: 604 | B7: 144.5 | C7: 1 | D7: =B7*$D$3 -> #REF! | E7: 92.95 | F7: =B3/ORÇAMENTO_EXECUTIVO!G2 -> 0.43670231 | G7: VALOR POR UNIDADE TIPO 04 | H7: 113.26 | I7: 4 | J7: =H7*$D$3 -> #REF! | K7: 102.55 | L7: =H3/ORÇAMENTO_EXECUTIVO!L2 -> #DIV/0!
A8: 605 | B8: 108.25 | C8: 1 | D8: =B8*$D$3 -> #REF! | E8: 115.03 | G8: VALOR POR UNIDADE ESTÚDIO | H8: 46.51 | I8: 6 | J8: =H8*$D$3 -> #REF! | K8: 123.34
A9: 606 | B9: 185.85 | C9: 1 | D9: =B9*$D$3 -> #REF! | E9: 113.21 | G9: VALOR POR UNIDADE GARDEN | H9: 239.51 | I9: 1 | J9: =H9*$D$3 -> #REF!
A10: 607 | B10: 201.9 | C10: 1 | D10: =B10*$D$3 -> #REF!
A11: 608 | B11: 127.4 | C11: 1 | D11: =B11*$D$3 -> #REF!
A12: 609/610 | B12: 164.7 | C12: 2 | D12: =B12*$D$3 -> #REF!
A13: 701 a 1901 | B13: 155.9 | C13: 13 | D13: =B13*$D$3 -> #REF!
A14: 702 a 1902 | B14: 175.7 | C14: 13 | D14: =B14*$D$3 -> #REF!
A15: 703 a 1903 / 704 a 1904 / 709 a 1909 / 710 a 1910 / | B15: 114.7 | C15: 52 | D15: =B15*$D$3 -> #REF!
A16: 705 a 1905 | B16: 91.5 | C16: 13 | D16: =B16*$D$3 -> #REF!
A17: 706 a 1906 | B17: 137.1 | C17: 13 | D17: =B17*$D$3 -> #REF!
A18: 707 a 1907 | B18: 136.5 | C18: 13 | D18: =B18*$D$3 -> #REF!
A19: 708 a 1908 | B19: 90.75 | C19: 13 | D19: =B19*$D$3 -> #REF!
A20: 2001 | B20: 280.9 | C20: 1 | D20: =B20*$D$3 -> #REF! | E20: 45.73
A21: 2002 | B21: 275.05 | C21: 1 | D21: =B21*D3 -> #REF! | E21: 122.55
A24: ÁREA DE LAZER | B24: 640.39
