Workbook

Sheet CAPA
A1: Obra | B1: ACÁCIAS FLOWE'S HOSP.
A2: Empresa | B2: Construtora ALL Empreendimentos
A3: Revisão | B3: R00
A4: Data | B4: 45463
A5: ORÇAMENTO EXECUTIVO
A26: ="ORÇAMENTO EXECUTIVO - "&UPPER(B1) -> ORÇAMENTO EXECUTIVO - ACÁCIAS FLOWE'S HOSP.
A28: =B2 -> Construtora ALL Empreendimentos
A55: ="Itajaí, "&TEXT(B4,"mmmm")&" de "&TEXT(B4,"aaa") -> Itajaí, junho de 2024

Sheet Resumo_Parede
G1: Parede | H1: Massa | I1: =E8+E18+E19+E23+E33+E34+E38+E48+E49+E53+E64+E65+E69+E77+E78 -> 274173.64 | J1: Massa | K1: =I1+I3 -> 399462.75
G2: Parede | H2: Acabamento | I2: =E6-I1 -> 123061.53 | J2: Acabamento | K2: =I2+I4 -> 444162.31
G3: Piso | H3: Massa | I3: =E82+E94+E95+E101+E117+E125+E139+E146+E161+E168+E174 -> 125289.1
G4: Piso | H4: Acabamento | I4: =E80-I3 -> 321100.77
A5: Descrição | B5: Un. | C5: Quant. Serviço | D5: Preço Comp. | E5: Preço total / Verba
A6: =Orçamento!$S$1210 -> REVESTIMENTOS INTERNOS DE PAREDE | B6: =Orçamento!$T$1210 | C6: =Orçamento!$U$1210 | D6: =Orçamento!$Y$1210 | E6: =Orçamento!$Z$1210 -> 397235.17
A7: =Orçamento!$S$1211 -> REVESTIMENTOS INTERNOS DE PAREDE - 1º PAVIMENTO - SUBSOLO | B7: =Orçamento!$T$1211 | C7: =Orçamento!$U$1211 | D7: =Orçamento!$Y$1211 | E7: =Orçamento!$Z$1211 -> 36323.973
A8: =Orçamento!$S$1212 -> Reboco | B8: =Orçamento!$T$1212 | C8: =Orçamento!$U$1212 | D8: =Orçamento!$Y$1212 | E8: =Orçamento!$Z$1212 -> 11199.67
A9: =Orçamento!$S$1213 -> Chapisco aplicado em estruturas de concreto, com desempenadeira dentada, de argamassa industrializada | B9: =Orçamento!$T$1213 -> M2 | C9: =Orçamento!$U$1213 -> 223.73 | D9: =Orçamento!$Y$1213 -> 5.502 | E9: =Orçamento!$Z$1213 -> 1230.9625
A10: =Orçamento!$S$1215 -> Chapisco aplicado em alvenarias internas, com colher de pedreiro, de argamassa estabilizada | B10: =Orçamento!$T$1215 -> M2 | C10: =Orçamento!$U$1215 -> 203.57 | D10: =Orçamento!$Y$1215 -> 7.93 | E10: =Orçamento!$Z$1215 -> 1614.3101
A11: =Orçamento!$S$1217 -> Massa unica para reboco interno em argamassa estabilizada, espessura de 20mm, com execucao de taliscas | B11: =Orçamento!$T$1217 -> M2 | C11: =Orçamento!$U$1217 -> 427.3 | D11: =Orçamento!$Y$1217 -> 19.008 | E11: =Orçamento!$Z$1217 -> 8122.1184
A12: =Orçamento!$S$1219 -> Estucamento de estrutura de concreto em pilares e vigas | B12: =Orçamento!$T$1219 -> M2 | C12: =Orçamento!$U$1219 -> 57.36 | D12: =Orçamento!$Y$1219 -> 4.0495 | E12: =Orçamento!$Z$1219 -> 232.27932
A13: =Orçamento!$S$1224 -> Acabamentos Cerâmicos e Porcelanatos | B13: =Orçamento!$T$1224 | C13: =Orçamento!$U$1224 | D13: =Orçamento!$Y$1224 | E13: =Orçamento!$Z$1224 -> 2161.6075
A14: =Orçamento!$S$1225 -> Revestimento em Cerâmica 60x60cm interno | B14: =Orçamento!$T$1225 -> M2 | C14: =Orçamento!$U$1225 -> 32.5 | D14: =Orçamento!$Y$1225 -> 66.511 | E14: =Orçamento!$Z$1225 -> 2161.6075
A15: =Orçamento!$S$1230 -> Peitoris | B15: =Orçamento!$T$1230 | C15: =Orçamento!$U$1230 | D15: =Orçamento!$Y$1230 | E15: =Orçamento!$Z$1230 -> 261.61178
A16: =Orçamento!$S$1231 -> Peitoril em granito, acabamento polido, espessura 2cm | B16: =Orçamento!$T$1231 -> M | C16: =Orçamento!$U$1231 -> 2.7 | D16: =Orçamento!$Y$1231 -> 96.89325 | E16: =Orçamento!$Z$1231 -> 261.61178
A17: =Orçamento!$S$1234 -> Mão de Obra | B17: =Orçamento!$T$1234 | C17: =Orçamento!$U$1234 | D17: =Orçamento!$Y$1234 | E17: =Orçamento!$Z$1234 -> 22701.083
A18: =Orçamento!$S$1235 -> Mao de obra para reboco interno, incluindo chapisco | B18: =Orçamento!$T$1235 -> M2 | C18: =Orçamento!$U$1235 -> 427.3 | D18: =Orçamento!$Y$1235 -> 40.637259 | E18: =Orçamento!$Z$1235 -> 17364.301
A19: =Orçamento!$S$1237 -> Mao de obra para estucamento de estrutura em concreto | B19: =Orçamento!$T$1237 -> M2 | C19: =Orçamento!$U$1237 -> 57.36 | D19: =Orçamento!$Y$1237 -> 50.894747 | E19: =Orçamento!$Z$1237 -> 2919.3227
A20: =Orçamento!$S$1239 -> Mao de obra para colocacao e rejuntamento de Azulejo Cerâmico | B20: =Orçamento!$T$1239 -> M2 | C20: =Orçamento!$U$1239 -> 32.5 | D20: =Orçamento!$Y$1239 -> 73.51107 | E20: =Orçamento!$Z$1239 -> 2389.1098
A21: =Orçamento!$S$1241 -> Mao de obra para colocacao de peitoril | B21: =Orçamento!$T$1241 -> M | C21: =Orçamento!$U$1241 -> 2.7 | D21: =Orçamento!$Y$1241 -> 10.5 | E21: =Orçamento!$Z$1241 -> 28.35
A22: =Orçamento!$S$1243 -> REVESTIMENTOS INTERNOS DE PAREDE - 2º PAVIMENTO - TÉRREO | B22: =Orçamento!$T$1243 | C22: =Orçamento!$U$1243 | D22: =Orçamento!$Y$1243 | E22: =Orçamento!$Z$1243 -> 39428.127
A23: =Orçamento!$S$1244 -> Reboco | B23: =Orçamento!$T$1244 | C23: =Orçamento!$U$1244 | D23: =Orçamento!$Y$1244 | E23: =Orçamento!$Z$1244 -> 9707.3525
A24: =Orçamento!$S$1245 -> Chapisco aplicado em estruturas de concreto, com desempenadeira dentada, de argamassa industrializada | B24: =Orçamento!$T$1245 -> M2 | C24: =Orçamento!$U$1245 -> 67.914 | D24: =Orçamento!$Y$1245 -> 5.502 | E24: =Orçamento!$Z$1245 -> 373.66283
A25: =Orçamento!$S$1247 -> Chapisco aplicado em alvenarias internas, com colher de pedreiro, de argamassa estabilizada | B25: =Orçamento!$T$1247 -> M2 | C25: =Orçamento!$U$1247 -> 203.57 | D25: =Orçamento!$Y$1247 -> 7.93 | E25: =Orçamento!$Z$1247 -> 1614.3101
A26: =Orçamento!$S$1249 -> Massa unica para reboco interno em argamassa estabilizada, espessura de 20mm, com execucao de taliscas | B26: =Orçamento!$T$1249 -> M2 | C26: =Orçamento!$U$1249 -> 401.634 | D26: =Orçamento!$Y$1249 -> 19.008 | E26: =Orçamento!$Z$1249 -> 7634.2591
A27: =Orçamento!$S$1251 -> Estucamento de estrutura de concreto em pilares e vigas | B27: =Orçamento!$T$1251 -> M2 | C27: =Orçamento!$U$1251 -> 21.02 | D27: =Orçamento!$Y$1251 -> 4.0495 | E27: =Orçamento!$Z$1251 -> 85.12049
A28: =Orçamento!$S$1256 -> Acabamentos Cerâmicos e Porcelanatos | B28: =Orçamento!$T$1256 | C28: =Orçamento!$U$1256 | D28: =Orçamento!$Y$1256 | E28: =Orçamento!$Z$1256 -> 4616.5285
A29: =Orçamento!$S$1257 -> Revestimento em Cerâmica 60x60cm interno | B29: =Orçamento!$T$1257 -> M2 | C29: =Orçamento!$U$1257 -> 69.41 | D29: =Orçamento!$Y$1257 -> 66.511 | E29: =Orçamento!$Z$1257 -> 4616.5285
A30: =Orçamento!$S$1262 -> Peitoris | B30: =Orçamento!$T$1262 | C30: =Orçamento!$U$1262 | D30: =Orçamento!$Y$1262 | E30: =Orçamento!$Z$1262 -> 2355.4749
A31: =Orçamento!$S$1263 -> Peitoril em granito, acabamento polido, espessura 2cm | B31: =Orçamento!$T$1263 -> M | C31: =Orçamento!$U$1263 -> 24.31 | D31: =Orçamento!$Y$1263 -> 96.89325 | E31: =Orçamento!$Z$1263 -> 2355.4749
A32: =Orçamento!$S$1266 -> Mão de Obra | B32: =Orçamento!$T$1266 | C32: =Orçamento!$U$1266 | D32: =Orçamento!$Y$1266 | E32: =Orçamento!$Z$1266 -> 22748.771
A33: =Orçamento!$S$1267 -> Mao de obra para reboco interno, incluindo chapisco | B33: =Orçamento!$T$1267 -> M2 | C33: =Orçamento!$U$1267 -> 401.634 | D33: =Orçamento!$Y$1267 -> 40.637259 | E33: =Orçamento!$Z$1267 -> 16321.305
A34: =Orçamento!$S$1269 -> Mao de obra para estucamento de estrutura em concreto | B34: =Orçamento!$T$1269 -> M2 | C34: =Orçamento!$U$1269 -> 21.02 | D34: =Orçamento!$Y$1269 -> 50.894747 | E34: =Orçamento!$Z$1269 -> 1069.8076
A35: =Orçamento!$S$1271 -> Mao de obra para colocacao e rejuntamento de Azulejo Cerâmico | B35: =Orçamento!$T$1271 -> M2 | C35: =Orçamento!$U$1271 -> 69.41 | D35: =Orçamento!$Y$1271 -> 73.51107 | E35: =Orçamento!$Z$1271 -> 5102.4033
A36: =Orçamento!$S$1273 -> Mao de obra para colocacao de peitoril | B36: =Orçamento!$T$1273 -> M | C36: =Orçamento!$U$1273 -> 24.31 | D36: =Orçamento!$Y$1273 -> 10.5 | E36: =Orçamento!$Z$1273 -> 255.255
A37: =Orçamento!$S$1275 -> REVESTIMENTOS INTERNOS DE PAREDE - 3º ao 7º PAVIMENTO - TIPO | B37: =Orçamento!$T$1275 | C37: =Orçamento!$U$1275 | D37: =Orçamento!$Y$1275 | E37: =Orçamento!$Z$1275 -> 266698.24
A38: =Orçamento!$S$1276 -> Reboco | B38: =Orçamento!$T$1276 | C38: =Orçamento!$U$1276 | D38: =Orçamento!$Y$1276 | E38: =Orçamento!$Z$1276 -> 67943.162
A39: =Orçamento!$S$1277 -> Chapisco aplicado em estruturas de concreto, com desempenadeira dentada, de argamassa industrializada | B39: =Orçamento!$T$1277 -> M2 | C39: =Orçamento!$U$1277 -> 388.91 | D39: =Orçamento!$Y$1277 -> 5.502 | E39: =Orçamento!$Z$1277 -> 2139.7828
A40: =Orçamento!$S$1279 -> Chapisco aplicado em alvenarias internas, com colher de pedreiro, de argamassa estabilizada | B40: =Orçamento!$T$1279 -> M2 | C40: =Orçamento!$U$1279 -> 2144.56 | D40: =Orçamento!$Y$1279 -> 7.93 | E40: =Orçamento!$Z$1279 -> 17006.361
...

Sheet OBRA
A1: Obra | B1: =CAPA!B1 -> ACÁCIAS FLOWE'S HOSP.
A2: Empresa | B2: =CAPA!B2 -> Construtora ALL Empreendimentos
A3: Revisão | B3: =CAPA!B3 -> R00
A4: DADOS OBRA
A6: ARQUITETURA
B8: Descrição | C8: Unidade | D8: Quantidade
B9: ÁREA DO TERRENO | C9: M2 | D9: 460.03
B10: ÁREA CONSTRUÍDA | C10: M2 | D10: 1943.23
B11: NÚMERO DE APTOS | C11: UN | D11: =3+5*7 -> 38
B12: MESES DE OBRA | C12: MÊS | D12: 22
B13: NÚMERO DE PAVIMENTOS | C13: UN | D13: 8

Sheet Quadro de Áreas
B2: Empreendimento - Total | E2: R00 | G2: R01 | I2: R02 | K2: R03 | M2: R04
B3: Residencial | D3: Total | E3: 7433075.1 | G3: 7152374.4 | I3: =Resumo!E73 -> 6936553.5 | K3: 6954920.9 | M3: ='ABC Insumos'!$I$6 -> 6970627
D4: R$/und | E4: =E3/E23 -> 195607.24 | G4: 184693.28 | I4: =I3/I23 -> 182540.88 | K4: =K3/K23 -> 183024.23 | M4: =M3/M23 -> 183437.55
D5: R$/m2 - Total | E5: =E3/F13 -> 3963.4618 | G5: 3742.32 | I5: =I3/J13 -> 3698.7067 | K5: =K3/L13 -> 3708.5006 | M5: =M3/N13 -> 3716.8754
D6: R$/m2 - Privativo | E6: =E3/F9 -> 7816.9333 | G6: 7380.79 | I6: =I3/J9 -> 7294.7704 | K6: =K3/L9 -> 7314.0862 | M6: =M3/N9 -> 7330.6035
E7: 0 | F7: 0
B8: Áreas | E8: Real | F8: Equivalente | G8: Real | H8: Equivalente | I8: Real | J8: Equivalente | K8: Real | L8: Equivalente | M8: Real | N8: Equivalente
D9: (R1) - Total Privativa | E9: 1023.7465 | F9: 950.89402 | G9: 1023.7465 | H9: 950.89402 | I9: 1023.7465 | J9: 950.89402 | K9: 1023.7465 | L9: 950.89402 | M9: 1023.7465 | N9: 950.89402
D10: (R2) - Total Torre | E10: 1375.9826 | F10: 1226.6523 | G10: 1375.9826 | H10: 1226.6523 | I10: 1375.9826 | J10: 1226.6523 | K10: 1375.9826 | L10: 1226.6523 | M10: 1375.9826 | N10: 1226.6523
D11: (R6) - Total Residencial | E11: 2185.7979 | F11: 1875.3997 | G11: 2185.7979 | H11: 1875.3997 | I11: 0 | J11: 0 | K11: #REF! | L11: #REF! | M11: #REF! | N11: #REF!
D12: (C5) - Total Comercial | E12: 0 | F12: 0 | G12: 0 | H12: 0 | I12: 0 | J12: 0 | K12: #REF! | L12: #REF! | M12: #REF! | N12: #REF!
D13: (E1) - Total Empreendimento | E13: 2185.7979 | F13: 1875.3997 | G13: 2185.7979 | H13: 1875.3997 | I13: 2185.7979 | J13: 1875.3997 | K13: 2185.7979 | L13: 1875.3997 | M13: 2185.7979 | N13: 1875.3997
D14: Área Equivalente Torre - Média | E14: 32.280325 | G14: 32.280325 | I14: 32.280325 | K14: 32.280325 | M14: 32.280325
D15: Área Equivalente Residencial - Média | E15: 1875.3997 | G15: 49.352624 | I15: 0 | K15: #REF! | M15: #REF!
D16: Área Equivalente Comerciall - Média | E16: 0 | G16: 0 | I16: 0 | K16: #REF! | M16: #REF!
D17: Área Equivalente Total - Média | E17: 49.352624 | G17: 49.352624 | I17: 49.352624 | K17: 49.352624 | M17: 49.352624
D18: Área Privativa Unidades - Média | E18: 25.023527 | G18: 25.023527 | I18: 25.023527 | K18: 25.023527 | M18: 25.023527
B19: 0 | C19: 0 | D19: 0 | E19: 0 | F19: 0
B20: Unidades
D21: Nº Unidades Residencial | E21: 38 | G21: 38 | I21: 0 | K21: #REF! | M21: #REF!
D22: Nº Unidades Comercial | E22: 0 | G22: 0 | I22: 0 | K22: #REF! | M22: #REF!
D23: Total de Unidades | E23: 38 | G23: 38 | I23: 38 | K23: 38 | M23: 38
B24: 0 | C24: 0 | D24: 0 | E24: 0 | F24: 0 | G24: 0 | H24: 0 | I24: 0 | J24: 0
B25: Grau de Eficiência
D26: GE Emprendimento: ( E1 ÷ R1 ) | E26: 1.9722489 | G26: 1.9722489 | I26: 1.9722489 | K26: 1.9722489 | M26: 1.9722489
D27: GE Torre: ( R2 ÷ R1 ) | E27: 1.289999 | G27: 1.289999 | I27: 1.289999 | K27: 1.289999 | M27: 1.289999
D28: Total Construída ÷ Privativa Construída: ( R1 ÷ E1 ) | E28: 0.50703539 | G28: 0.50703539 | I28: 0.50703539 | K28: 0.50703539 | M28: 0.50703539
B29: 0 | C29: 0 | D29: 0 | I29: 0 | J29: 0

Sheet Resumo
A1: item | B1: ETAPA | C1: VALOR ORÇADO | D1: % | E1: VALOR / m²
A2: 01 | B2: GERENCIAMENTO TÉCNICO E ADMINISTRATIVO | C2: =Orçamento!$Z$12 -> 728402.37 | D2: =C2/C$19 -> 0.10449596 | E2: =C2/$G$2 -> 374.84105 | G2: 1943.23 | H2: m²
A3: 02 | B3: MOVIMENTAÇÃO DE TERRA | C3: =Orçamento!$Z$172 -> 145568.65 | D3: =C3/C$19 -> 0.020883149 | E3: =C3/$G$2 -> 74.910662
A4: 03 | B4: INFRAESTRUTURA | C4: =Orçamento!$Z$185+Orçamento!$Z$199 -> 502193.32 | D4: =C4/C$19 -> 0.072044211 | E4: =C4/$G$2 -> 258.43226
A5: 04 | B5: SUPRAESTRUTURA | C5: =Orçamento!$Z$234 -> 1352591 | D5: =C5/C$19 -> 0.1940415 | E5: =C5/$G$2 -> 696.05294
A6: 04 | B6: ALVENARIA | C6: =Orçamento!$Z$662 -> 261393.66 | D6: =C6/C$19 -> 0.037499304 | E6: =C6/$G$2 -> 134.51504
A7: 06 | B7: INSTALAÇÕES ELÉTRICAS, HIDRÁULICAS, GLP E PREVENTIVAS | C7: =Orçamento!$Z$973+Orçamento!$Z$1069+Orçamento!$Z$1135+Orçamento!$Z$1957 -> 641270.51 | D7: =C7/C$19 -> 0.091996102 | E7: =C7/$G$2 -> 330.00237
A8: 07 | B8: EQUIPAMENTOS E SISTEMAS ESPECIAIS | C8: =Orçamento!$Z$1160+Orçamento!$Z$1171+Orçamento!$Z$1191 -> 323614.15 | D8: =C8/C$19 -> 0.0464254 | E8: =C8/$G$2 -> 166.53415
A9: 08 | B9: IMPERMEABILIZAÇÃO | C9: =Orçamento!$Z$806 -> 175140.61 | D9: =C9/C$19 -> 0.025125517 | E9: =C9/$G$2 -> 90.128606
A10: 09 | B10: REVESTIMENTOS INTERNOS EM PAREDE | C10: =(Orçamento!$Z$1210) -> 397235.17 | D10: =C10/C$19 -> 0.056987008 | E10: =C10/$G$2 -> 204.42005
A11: 10 | B11: REVESTIMENTOS E ACABAMENTOS INTERNOS EM TETO | C11: =Orçamento!$Z$1369 -> 128940.66 | D11: =C11/C$19 -> 0.018497713 | E11: =C11/$G$2 -> 66.353781
A12: 11 | B12: PISOS E PAVIMENTAÇÕES | C12: =Orçamento!$Z$1456 -> 446389.88 | D12: =C12/C$19 -> 0.064038698 | E12: =C12/$G$2 -> 229.71541
A13: 12 | B13: PINTURA INTERNA | C13: =Orçamento!$Z$1726 -> 303208.12 | D13: =C13/C$19 -> 0.04349797 | E13: =C13/$G$2 -> 156.03306
A14: 13 | B14: ESQUADRIAS, VIDROS E FERRAGENS | C14: =Orçamento!$Z$1837 -> 578274.83 | D14: =C14/C$19 -> 0.082958796 | E14: =C14/$G$2 -> 297.58435
A15: 14 | B15: COBERTURA | C15: =Orçamento!$Z$2061 -> 38853.541 | D15: =C15/C$19 -> 0.0055738947 | E15: =C15/$G$2 -> 19.994309
A16: 15 | B16: REVESTIMENTOS E ACABAMENTOS DE FACHADA | C16: =Orçamento!$Z$2089 -> 365385.57 | D16: =C16/C$19 -> 0.052417891 | E16: =C16/$G$2 -> 188.03002
A17: 16 | B17: SERVIÇOS COMPLEMENTARES | C17: =Orçamento!$Z$2121 -> 442752.49 | D17: =C17/C$19 -> 0.063516881 | E17: =C17/$G$2 -> 227.84358
A18: 17 | B18: IMPREVISTOS E CONTINGENCIAS | C18: =Orçamento!$Z$2143 -> 139412.54 | D18: =C18/C$19 -> 0.02 | E18: =C18/$G$2 -> 71.742686
B19: TOTAL | C19: =SUM(C2:C18) -> 6970627 | D19: =SUM(D2:D18) -> 1 | E19: =SUM(E2:E18) -> 3587.1343
B20: CUB/ESTADO | C20: 2758.46 | D20: DATA BASE | E20: =+E19/C20 -> 1.3004119
A23: item | B23: ETAPA | C23: VALOR ORÇADO | D23: % | E23: VALOR / m²
A24: 01 | B24: GERENCIAMENTO TÉCNICO E ADMINISTRATIVO | C24: =Orçamento!$Z$12 -> 728402.37 | D24: =C24/C$42 -> 0.10449596 | E24: =C24/$G$2 -> 374.84105 | F24: SUPRAESTRUTURA | G24: =D27 -> 0.1940415
A25: 02 | B25: MOVIMENTAÇÃO DE TERRA | C25: =Orçamento!$Z$172 -> 145568.65 | D25: =C25/C$42 -> 0.020883149 | E25: =C25/$G$2 -> 74.910662 | F25: GERENCIAMENTO TÉCNICO E ADMINISTRATIVO | G25: =D24 -> 0.10449596
A26: 03 | B26: INFRAESTRUTURA | C26: =Orçamento!$Z$185+Orçamento!$Z$199 -> 502193.32 | D26: =C26/C$42 -> 0.072044211 | E26: =C26/$G$2 -> 258.43226 | F26: ESQUADRIAS, VIDROS E FERRAGENS | G26: =D36 -> 0.082958796
A27: 04 | B27: SUPRAESTRUTURA | C27: =Orçamento!$Z$234 -> 1352591 | D27: =C27/C$42 -> 0.1940415 | E27: =C27/$G$2 -> 696.05294 | F27: INSTALAÇÕES ELÉTRICAS, HIDRÁULICAS, GLP E PREVENTIVAS | G27: =D29 -> 0.079680478
A28: 04 | B28: ALVENARIA | C28: =Orçamento!$Z$662 -> 261393.66 | D28: =C28/C$42 -> 0.037499304 | E28: =C28/$G$2 -> 134.51504 | F28: INFRAESTRUTURA | G28: =D26 -> 0.072044211
A29: 06 | B29: INSTALAÇÕES ELÉTRICAS, HIDRÁULICAS, GLP E PREVENTIVAS | C29: =Orçamento!$Z$973+Orçamento!$Z$1069+Orçamento!$Z$1135 -> 555422.9 | D29: =C29/C$42 -> 0.079680478 | E29: =C29/$G$2 -> 285.82458 | F29: PISOS E PAVIMENTAÇÕES | G29: =D34 -> 0.064038698
A30: 07 | B30: EQUIPAMENTOS E SISTEMAS ESPECIAIS | C30: =Orçamento!$Z$1160+Orçamento!$Z$1171+Orçamento!$Z$1191 -> 323614.15 | D30: =C30/C$42 -> 0.0464254 | E30: =C30/$G$2 -> 166.53415
A31: 08 | B31: IMPERMEABILIZAÇÃO | C31: =Orçamento!$Z$806 -> 175140.61 | D31: =C31/C$42 -> 0.025125517 | E31: =C31/$G$2 -> 90.128606
A32: 09 | B32: REVESTIMENTOS INTERNOS EM PAREDE | C32: =(Orçamento!$Z$1210) -> 397235.17 | D32: =C32/C$42 -> 0.056987008 | E32: =C32/$G$2 -> 204.42005
A33: 10 | B33: REVESTIMENTOS E ACABAMENTOS INTERNOS EM TETO | C33: =Orçamento!$Z$1369 -> 128940.66 | D33: =C33/C$42 -> 0.018497713 | E33: =C33/$G$2 -> 66.353781
A34: 11 | B34: PISOS E PAVIMENTAÇÕES | C34: =Orçamento!$Z$1456 -> 446389.88 | D34: =C34/C$42 -> 0.064038698 | E34: =C34/$G$2 -> 229.71541
A35: 12 | B35: PINTURA INTERNA | C35: =Orçamento!$Z$1726 -> 303208.12 | D35: =C35/C$42 -> 0.04349797 | E35: =C35/$G$2 -> 156.03306
A36: 13 | B36: ESQUADRIAS, VIDROS E FERRAGENS | C36: =Orçamento!$Z$1837 -> 578274.83 | D36: =C36/C$42 -> 0.082958796 | E36: =C36/$G$2 -> 297.58435
A37: 14 | B37: LOUÇAS E METAIS | C37: =+Orçamento!$Z$1957 -> 85847.616 | D37: =C37/C$42 -> 0.012315623 | E37: =C37/$G$2 -> 44.177795
A38: 15 | B38: COBERTURA | C38: =Orçamento!$Z$2061 -> 38853.541 | D38: =C38/C$42 -> 0.0055738947 | E38: =C38/$G$2 -> 19.994309
A39: 16 | B39: REVESTIMENTOS E ACABAMENTOS DE FACHADA | C39: =Orçamento!$Z$2089 -> 365385.57 | D39: =C39/C$42 -> 0.052417891 | E39: =C39/$G$2 -> 188.03002
A40: 17 | B40: SERVIÇOS COMPLEMENTARES | C40: =Orçamento!$Z$2121 -> 442752.49 | D40: =C40/C$42 -> 0.063516881 | E40: =C40/$G$2 -> 227.84358
A41: 18 | B41: IMPREVISTOS E CONTINGENCIAS | C41: =Orçamento!$Z$2143 -> 139412.54 | D41: =C41/C$42 -> 0.02 | E41: =C41/$G$2 -> 71.742686
B42: TOTAL | C42: =SUM(C24:C41) -> 6970627 | D42: =SUM(D24:D41) -> 1 | E42: =SUM(E24:E41) -> 3587.1343
...

Sheet Orçamento
A2: ="ORÇAMENTO EXECUTIVO - "&UPPER(S5) -> ORÇAMENTO EXECUTIVO - ACÁCIAS FLOWE'S HOSP.
A4: Empresa: | S4: =CAPA!B2 -> Construtora ALL Empreendimentos | AE4: Cliente | AF4: =S4 -> Construtora ALL Empreendimentos
A5: Obra: | S5: =CAPA!B1 -> ACÁCIAS FLOWE'S HOSP. | AE5: Prazo | AF5: =OBRA!D12 -> 22
A6: Revisão | S6: =CAPA!B3 -> R00 | AE6: Área Construída | AF6: =OBRA!D10 -> 1943.23
A7: Data: | S7: =CAPA!B4 -> 45463 | AE7: Apto | AF7: =OBRA!D11 -> 38
A9: ORÇAMENTO DETALHADO | AE9: =UPPER(AF4) -> CONSTRUTORA ALL EMPREENDIMENTOS
B10: Nivel | C10: Repetições | D10: Código | E10: Coluna1 | F10: Nº Unidade Construtiva | G10: Unidade Construtiva | H10: Nº Célula Construtiva | I10: Célula Construtiva | J10: Nº Etapa | K10: Etapa | L10: Nº Subetapa | M10: Subetapa | N10: Nº Serviço | O10: Serviço | P10: Insumo Apoio | Q10: Serviço Apoio | R10: Base Quant. Serviço | S10: Descrição | T10: Un. | U10: Quant. Serviço | V10: Coef. | W10: Preço Unit. Insumo | X10: Quant. orçada | Y10: Preço Comp. | Z10: Preço total / Verba | AA10: Considerações Quant. | AB10: Ref. Preço | AC10: Perc. (%) | AE10: Índice | AF10: Parâmetro
F11: 0 | H11: 0 | J11: 0 | L11: 0 | N11: 0
B12: Unidade Construtiva | C12: =IF(B12="INSUMO",COUNTIFS(B:B,"INSUMO",S:S,S12),IF(B12="SERVIÇO",COUNTIFS(B:B,"SERVIÇO",S:S,S12),"")) | D12: =IF(B12="Unidade Construtiva",TEXT(F12,"00"),IF(B12="Célula Construtiva",TEXT(H12,"00"),IF(B12="Etapa",CONCATENATE(TEXT(H12,"00"),".",TEXT(J12,"000")),IF(B12="Subetapa",CONCATENATE(TEXT(H12,"00"),".",TEXT(J12,"000"),".",TEXT(L12,"000")),IF(B12="Serviço",CONCATENATE(TEXT(H12,"00"),".",TEXT(J12,"000"),".",TEXT(L12,"000"),".",TEXT(N12,"000")),""))))) -> 01 | E12: =IF(B12="*","",IFERROR(IF(B12="SERVIÇO",D12,OFFSET(E12,-1,0)),"")) -> 0 | F12: =IF($B12="UNIDADE CONSTRUTIVA",OFFSET(F12,-1,0)+1,LARGE(F$10:F11,1)) -> 1 | G12: =IF(B12="*","",IF(B12="UNIDADE CONSTRUTIVA",S12,OFFSET(G12,-1,0))) -> GERENCIAMENTO TÉCNICO E ADMINISTRATIVO | H12: =IF(B12="UNIDADE CONSTRUTIVA",0,IF(B12="CÉLULA CONSTRUTIVA",OFFSET(H12,-1,0)+1,OFFSET(H12,-1,0))) -> 0 | I12: =IF(B12="*","",IF(B12="CÉLULA CONSTRUTIVA",S12,OFFSET(I12,-1,0))) -> 0 | J12: =IF(B12="CÉLULA CONSTRUTIVA",0,IF(B12="ETAPA",OFFSET(J12,-1,0)+1,OFFSET(J12,-1,0))) -> 0 | K12: =IF(B12="*","",IF(B12="ETAPA",S12,OFFSET(K12,-1,0))) -> 0 | L12: =IF(B12="ETAPA",0,IF(B12="SUBETAPA",OFFSET(L12,-1,0)+1,OFFSET(L12,-1,0))) -> 0 | M12: =IF(B12="*","",IF(B12="SUBETAPA",S12,OFFSET(M12,-1,0))) -> 0 | N12: =IF(B12="Subetapa",0,IF(B12="serviço",OFFSET(N12,-1,0)+1,OFFSET(N12,-1,0))) -> 0 | O12: =IF(B12="*","",IF(B12="SERVIÇO",S12,OFFSET(O12,-1,0))) -> 0 | P12: =IF(S12="","",IF(Orçamento!$B12="INSUMO",S12,"")) | Q12: =IF(S12="","",IF(Orçamento!$B12="Serviço",S12,"")) | R12: =IF(B12="serviço",U12,OFFSET(R12,-1,0)) -> 0 | S12: GERENCIAMENTO TÉCNICO E ADMINISTRATIVO | U12: =IF($B12="insumo",R12,"") | W12: =IFERROR(IF(B12="INSUMO",_xlfn.XLOOKUP(S12,Insumos!A:A,Insumos!C:C),""),"Inserir Preço") | X12: =IF(B12="Complemento do insumo",V12,IF(R12="","",IF(B12="serviço",R12,IF(OR(B12="insumo"),V12*R12,"")))) | Y12: =IF(B12="insumo",W12*V12,IF(B12="serviço",SUMIFS(Y:Y,B:B,"insumo",E:E,E12,I:I,I12),"")) | Z12: =IFERROR(IF(B12="Unidade Construtiva",SUMIFS(Z:Z,B:B,"Célula Construtiva",G:G,G12),IF(B12="célula construtiva",SUMIFS(Z:Z,B:B,"Insumo",I:I,I12,G:G,G12),IF(B12="ETAPA",SUMIFS(Z:Z,B:B,"Insumo",K:K,K12,I:I,I12,G:G,G12),IF(B12="subetapa",SUMIFS(Z:Z,M:M,M12,B:B,"insumo",K:K,K12,I:I,I12,G:G,G12),IF(B12="complemento do insumo",V12*W12,IF(B12="INSUMO",R12*V12*W12,X12*Y12)))))),"") -> 728402.37 | AB12: =IF(B12="insumo",_xlfn.XLOOKUP(S12,Insumos!A:A,Insumos!D:D),"") | AC12: =IFERROR(IF(B12="","",Z12/SUMIF(B:B,"INSUMO",Z:Z)),0) -> 0.10449596 | AE12: =IFERROR(IF(OR(Z12="",Z12=0),"",IF(AF12="","",IF(AF12="R$/mês",Z12/OBRA!$D$12,IF(AF12="R$/m²",Z12/OBRA!$D$10,IF(AF12="R$/apto",Orçamento!Z12/OBRA!$D$11,""))))),"") -> 374.84105 | AF12: R$/m²
B13: Célula Construtiva | C13: =IF(B13="INSUMO",COUNTIFS(B:B,"INSUMO",S:S,S13),IF(B13="SERVIÇO",COUNTIFS(B:B,"SERVIÇO",S:S,S13),"")) | D13: =IF(B13="Unidade Construtiva",TEXT(F13,"00"),IF(B13="Célula Construtiva",TEXT(H13,"00"),IF(B13="Etapa",CONCATENATE(TEXT(H13,"00"),".",TEXT(J13,"000")),IF(B13="Subetapa",CONCATENATE(TEXT(H13,"00"),".",TEXT(J13,"000"),".",TEXT(L13,"000")),IF(B13="Serviço",CONCATENATE(TEXT(H13,"00"),".",TEXT(J13,"000"),".",TEXT(L13,"000"),".",TEXT(N13,"000")),""))))) -> 01 | E13: =IF(B13="*","",IFERROR(IF(B13="SERVIÇO",D13,OFFSET(E13,-1,0)),"")) -> 0 | F13: =IF($B13="UNIDADE CONSTRUTIVA",OFFSET(F13,-1,0)+1,LARGE(F$10:F12,1)) -> 1 | G13: =IF(B13="*","",IF(B13="UNIDADE CONSTRUTIVA",S13,OFFSET(G13,-1,0))) -> GERENCIAMENTO TÉCNICO E ADMINISTRATIVO | H13: =IF(B13="UNIDADE CONSTRUTIVA",0,IF(B13="CÉLULA CONSTRUTIVA",OFFSET(H13,-1,0)+1,OFFSET(H13,-1,0))) -> 1 | I13: =IF(B13="*","",IF(B13="CÉLULA CONSTRUTIVA",S13,OFFSET(I13,-1,0))) -> GERENCIAMENTO TÉCNICO | J13: =IF(B13="CÉLULA CONSTRUTIVA",0,IF(B13="ETAPA",OFFSET(J13,-1,0)+1,OFFSET(J13,-1,0))) -> 0 | K13: =IF(B13="*","",IF(B13="ETAPA",S13,OFFSET(K13,-1,0))) -> 0 | L13: =IF(B13="ETAPA",0,IF(B13="SUBETAPA",OFFSET(L13,-1,0)+1,OFFSET(L13,-1,0))) -> 0 | M13: =IF(B13="*","",IF(B13="SUBETAPA",S13,OFFSET(M13,-1,0))) -> 0 | N13: =IF(B13="Subetapa",0,IF(B13="serviço",OFFSET(N13,-1,0)+1,OFFSET(N13,-1,0))) -> 0 | O13: =IF(B13="*","",IF(B13="SERVIÇO",S13,OFFSET(O13,-1,0))) -> 0 | P13: =IF(S13="","",IF(Orçamento!$B13="INSUMO",S13,"")) | Q13: =IF(S13="","",IF(Orçamento!$B13="Serviço",S13,"")) | R13: =IF(B13="serviço",U13,OFFSET(R13,-1,0)) -> 0 | S13: GERENCIAMENTO TÉCNICO | U13: =IF($B13="insumo",R13,"") | W13: =IFERROR(IF(B13="INSUMO",_xlfn.XLOOKUP(S13,Insumos!A:A,Insumos!C:C),""),"Inserir Preço") | X13: =IF(B13="Complemento do insumo",V13,IF(R13="","",IF(B13="serviço",R13,IF(OR(B13="insumo"),V13*R13,"")))) | Y13: =IF(B13="insumo",W13*V13,IF(B13="serviço",SUMIFS(Y:Y,B:B,"insumo",E:E,E13,I:I,I13),"")) | Z13: =IFERROR(IF(B13="Unidade Construtiva",SUMIFS(Z:Z,B:B,"Célula Construtiva",G:G,G13),IF(B13="célula construtiva",SUMIFS(Z:Z,B:B,"Insumo",I:I,I13,G:G,G13),IF(B13="ETAPA",SUMIFS(Z:Z,B:B,"Insumo",K:K,K13,I:I,I13,G:G,G13),IF(B13="subetapa",SUMIFS(Z:Z,M:M,M13,B:B,"insumo",K:K,K13,I:I,I13,G:G,G13),IF(B13="complemento do insumo",V13*W13,IF(B13="INSUMO",R13*V13*W13,X13*Y13)))))),"") -> 206833.89 | AB13: =IF(B13="insumo",_xlfn.XLOOKUP(S13,Insumos!A:A,Insumos!D:D),"") | AC13: =IFERROR(IF(B13="","",Z13/SUMIF(B:B,"INSUMO",Z:Z)),0) -> 0.029672207 | AE13: =IFERROR(IF(OR(Z13="",Z13=0),"",IF(AF13="","",IF(AF13="R$/mês",Z13/OBRA!$D$12,IF(AF13="R$/m²",Z13/OBRA!$D$10,IF(AF13="R$/apto",Orçamento!Z13/OBRA!$D$11,""))))),"") -> 106.43819 | AF13: R$/m²
B14: Etapa | C14: =IF(B14="INSUMO",COUNTIFS(B:B,"INSUMO",S:S,S14),IF(B14="SERVIÇO",COUNTIFS(B:B,"SERVIÇO",S:S,S14),"")) | D14: =IF(B14="Unidade Construtiva",TEXT(F14,"00"),IF(B14="Célula Construtiva",TEXT(H14,"00"),IF(B14="Etapa",CONCATENATE(TEXT(H14,"00"),".",TEXT(J14,"000")),IF(B14="Subetapa",CONCATENATE(TEXT(H14,"00"),".",TEXT(J14,"000"),".",TEXT(L14,"000")),IF(B14="Serviço",CONCATENATE(TEXT(H14,"00"),".",TEXT(J14,"000"),".",TEXT(L14,"000"),".",TEXT(N14,"000")),""))))) -> 01.001 | E14: =IF(B14="*","",IFERROR(IF(B14="SERVIÇO",D14,OFFSET(E14,-1,0)),"")) -> 0 | F14: =IF($B14="UNIDADE CONSTRUTIVA",OFFSET(F14,-1,0)+1,LARGE(F$10:F13,1)) -> 1 | G14: =IF(B14="*","",IF(B14="UNIDADE CONSTRUTIVA",S14,OFFSET(G14,-1,0))) -> GERENCIAMENTO TÉCNICO E ADMINISTRATIVO | H14: =IF(B14="UNIDADE CONSTRUTIVA",0,IF(B14="CÉLULA CONSTRUTIVA",OFFSET(H14,-1,0)+1,OFFSET(H14,-1,0))) -> 1 | I14: =IF(B14="*","",IF(B14="CÉLULA CONSTRUTIVA",S14,OFFSET(I14,-1,0))) -> GERENCIAMENTO TÉCNICO | J14: =IF(B14="CÉLULA CONSTRUTIVA",0,IF(B14="ETAPA",OFFSET(J14,-1,0)+1,OFFSET(J14,-1,0))) -> 1 | K14: =IF(B14="*","",IF(B14="ETAPA",S14,OFFSET(K14,-1,0))) -> ESTUDOS | PROJETOS | CONSULTORIAS | L14: =IF(B14="ETAPA",0,IF(B14="SUBETAPA",OFFSET(L14,-1,0)+1,OFFSET(L14,-1,0))) -> 0 | M14: =IF(B14="*","",IF(B14="SUBETAPA",S14,OFFSET(M14,-1,0))) -> 0 | N14: =IF(B14="Subetapa",0,IF(B14="serviço",OFFSET(N14,-1,0)+1,OFFSET(N14,-1,0))) -> 0 | O14: =IF(B14="*","",IF(B14="SERVIÇO",S14,OFFSET(O14,-1,0))) -> 0 | P14: =IF(S14="","",IF(Orçamento!$B14="INSUMO",S14,"")) | Q14: =IF(S14="","",IF(Orçamento!$B14="Serviço",S14,"")) | R14: =IF(B14="serviço",U14,OFFSET(R14,-1,0)) -> 0 | S14: ESTUDOS | PROJETOS | CONSULTORIAS | U14: =IF($B14="insumo",R14,"") | W14: =IFERROR(IF(B14="INSUMO",_xlfn.XLOOKUP(S14,Insumos!A:A,Insumos!C:C),""),"Inserir Preço") | X14: =IF(B14="Complemento do insumo",V14,IF(R14="","",IF(B14="serviço",R14,IF(OR(B14="insumo"),V14*R14,"")))) | Y14: =IF(B14="insumo",W14*V14,IF(B14="serviço",SUMIFS(Y:Y,B:B,"insumo",E:E,E14,I:I,I14),"")) | Z14: =IFERROR(IF(B14="Unidade Construtiva",SUMIFS(Z:Z,B:B,"Célula Construtiva",G:G,G14),IF(B14="célula construtiva",SUMIFS(Z:Z,B:B,"Insumo",I:I,I14,G:G,G14),IF(B14="ETAPA",SUMIFS(Z:Z,B:B,"Insumo",K:K,K14,I:I,I14,G:G,G14),IF(B14="subetapa",SUMIFS(Z:Z,M:M,M14,B:B,"insumo",K:K,K14,I:I,I14,G:G,G14),IF(B14="complemento do insumo",V14*W14,IF(B14="INSUMO",R14*V14*W14,X14*Y14)))))),"") -> 161015.62 | AB14: =IF(B14="insumo",_xlfn.XLOOKUP(S14,Insumos!A:A,Insumos!D:D),"") | AC14: =IFERROR(IF(B14="","",Z14/SUMIF(B:B,"INSUMO",Z:Z)),0) -> 0.023099159 | AE14: =IFERROR(IF(OR(Z14="",Z14=0),"",IF(AF14="","",IF(AF14="R$/mês",Z14/OBRA!$D$12,IF(AF14="R$/m²",Z14/OBRA!$D$10,IF(AF14="R$/apto",Orçamento!Z14/OBRA!$D$11,""))))),"") -> 82.859785 | AF14: R$/m²
B15: Subetapa | C15: =IF(B15="INSUMO",COUNTIFS(B:B,"INSUMO",S:S,S15),IF(B15="SERVIÇO",COUNTIFS(B:B,"SERVIÇO",S:S,S15),"")) | D15: =IF(B15="Unidade Construtiva",TEXT(F15,"00"),IF(B15="Célula Construtiva",TEXT(H15,"00"),IF(B15="Etapa",CONCATENATE(TEXT(H15,"00"),".",TEXT(J15,"000")),IF(B15="Subetapa",CONCATENATE(TEXT(H15,"00"),".",TEXT(J15,"000"),".",TEXT(L15,"000")),IF(B15="Serviço",CONCATENATE(TEXT(H15,"00"),".",TEXT(J15,"000"),".",TEXT(L15,"000"),".",TEXT(N15,"000")),""))))) -> 01.001.001 | E15: =IF(B15="*","",IFERROR(IF(B15="SERVIÇO",D15,OFFSET(E15,-1,0)),"")) -> 0 | F15: =IF($B15="UNIDADE CONSTRUTIVA",OFFSET(F15,-1,0)+1,LARGE(F$10:F14,1)) -> 1 | G15: =IF(B15="*","",IF(B15="UNIDADE CONSTRUTIVA",S15,OFFSET(G15,-1,0))) -> GERENCIAMENTO TÉCNICO E ADMINISTRATIVO | H15: =IF(B15="UNIDADE CONSTRUTIVA",0,IF(B15="CÉLULA CONSTRUTIVA",OFFSET(H15,-1,0)+1,OFFSET(H15,-1,0))) -> 1 | I15: =IF(B15="*","",IF(B15="CÉLULA CONSTRUTIVA",S15,OFFSET(I15,-1,0))) -> GERENCIAMENTO TÉCNICO | J15: =IF(B15="CÉLULA CONSTRUTIVA",0,IF(B15="ETAPA",OFFSET(J15,-1,0)+1,OFFSET(J15,-1,0))) -> 1 | K15: =IF(B15="*","",IF(B15="ETAPA",S15,OFFSET(K15,-1,0))) -> ESTUDOS | PROJETOS | CONSULTORIAS | L15: =IF(B15="ETAPA",0,IF(B15="SUBETAPA",OFFSET(L15,-1,0)+1,OFFSET(L15,-1,0))) -> 1 | M15: =IF(B15="*","",IF(B15="SUBETAPA",S15,OFFSET(M15,-1,0))) -> Estudos | N15: =IF(B15="Subetapa",0,IF(B15="serviço",OFFSET(N15,-1,0)+1,OFFSET(N15,-1,0))) -> 0 | O15: =IF(B15="*","",IF(B15="SERVIÇO",S15,OFFSET(O15,-1,0))) -> 0 | P15: =IF(S15="","",IF(Orçamento!$B15="INSUMO",S15,"")) | Q15: =IF(S15="","",IF(Orçamento!$B15="Serviço",S15,"")) | R15: =IF(B15="serviço",U15,OFFSET(R15,-1,0)) -> 0 | S15: Estudos | U15: =IF($B15="insumo",R15,"") | W15: =IFERROR(IF(B15="INSUMO",_xlfn.XLOOKUP(S15,Insumos!A:A,Insumos!C:C),""),"Inserir Preço") | X15: =IF(B15="Complemento do insumo",V15,IF(R15="","",IF(B15="serviço",R15,IF(OR(B15="insumo"),V15*R15,"")))) | Y15: =IF(B15="insumo",W15*V15,IF(B15="serviço",SUMIFS(Y:Y,B:B,"insumo",E:E,E15,I:I,I15),"")) | Z15: =IFERROR(IF(B15="Unidade Construtiva",SUMIFS(Z:Z,B:B,"Célula Construtiva",G:G,G15),IF(B15="célula construtiva",SUMIFS(Z:Z,B:B,"Insumo",I:I,I15,G:G,G15),IF(B15="ETAPA",SUMIFS(Z:Z,B:B,"Insumo",K:K,K15,I:I,I15,G:G,G15),IF(B15="subetapa",SUMIFS(Z:Z,M:M,M15,B:B,"insumo",K:K,K15,I:I,I15,G:G,G15),IF(B15="complemento do insumo",V15*W15,IF(B15="INSUMO",R15*V15*W15,X15*Y15)))))),"") -> 16700 | AB15: =IF(B15="insumo",_xlfn.XLOOKUP(S15,Insumos!A:A,Insumos!D:D),"") | AC15: =IFERROR(IF(B15="","",Z15/SUMIF(B:B,"INSUMO",Z:Z)),0) -> 0.0023957673 | AE15: =IFERROR(IF(OR(Z15="",Z15=0),"",IF(AF15="","",IF(AF15="R$/mês",Z15/OBRA!$D$12,IF(AF15="R$/m²",Z15/OBRA!$D$10,IF(AF15="R$/apto",Orçamento!Z15/OBRA!$D$11,""))))),"") -> 8.593939 | AF15: R$/m²
B16: Serviço | C16: =IF(B16="INSUMO",COUNTIFS(B:B,"INSUMO",S:S,S16),IF(B16="SERVIÇO",COUNTIFS(B:B,"SERVIÇO",S:S,S16),"")) -> 1 | D16: =IF(B16="Unidade Construtiva",TEXT(F16,"00"),IF(B16="Célula Construtiva",TEXT(H16,"00"),IF(B16="Etapa",CONCATENATE(TEXT(H16,"00"),".",TEXT(J16,"000")),IF(B16="Subetapa",CONCATENATE(TEXT(H16,"00"),".",TEXT(J16,"000"),".",TEXT(L16,"000")),IF(B16="Serviço",CONCATENATE(TEXT(H16,"00"),".",TEXT(J16,"000"),".",TEXT(L16,"000"),".",TEXT(N16,"000")),""))))) -> 01.001.001.001 | E16: =IF(B16="*","",IFERROR(IF(B16="SERVIÇO",D16,OFFSET(E16,-1,0)),"")) -> 01.001.001.001 | F16: =IF($B16="UNIDADE CONSTRUTIVA",OFFSET(F16,-1,0)+1,LARGE(F$10:F15,1)) -> 1 | G16: =IF(B16="*","",IF(B16="UNIDADE CONSTRUTIVA",S16,OFFSET(G16,-1,0))) -> GERENCIAMENTO TÉCNICO E ADMINISTRATIVO | H16: =IF(B16="UNIDADE CONSTRUTIVA",0,IF(B16="CÉLULA CONSTRUTIVA",OFFSET(H16,-1,0)+1,OFFSET(H16,-1,0))) -> 1 | I16: =IF(B16="*","",IF(B16="CÉLULA CONSTRUTIVA",S16,OFFSET(I16,-1,0))) -> GERENCIAMENTO TÉCNICO | J16: =IF(B16="CÉLULA CONSTRUTIVA",0,IF(B16="ETAPA",OFFSET(J16,-1,0)+1,OFFSET(J16,-1,0))) -> 1 | K16: =IF(B16="*","",IF(B16="ETAPA",S16,OFFSET(K16,-1,0))) -> ESTUDOS | PROJETOS | CONSULTORIAS | L16: =IF(B16="ETAPA",0,IF(B16="SUBETAPA",OFFSET(L16,-1,0)+1,OFFSET(L16,-1,0))) -> 1 | M16: =IF(B16="*","",IF(B16="SUBETAPA",S16,OFFSET(M16,-1,0))) -> Estudos | N16: =IF(B16="Subetapa",0,IF(B16="serviço",OFFSET(N16,-1,0)+1,OFFSET(N16,-1,0))) -> 1 | O16: =IF(B16="*","",IF(B16="SERVIÇO",S16,OFFSET(O16,-1,0))) -> Serviço Levantamento Topografico | P16: =IF(S16="","",IF(Orçamento!$B16="INSUMO",S16,"")) | Q16: =IF(B16="","",IF(B16="Serviço",S16,"")) -> Serviço Levantamento Topografico | R16: =IF(B16="serviço",U16,OFFSET(R16,-1,0)) -> 1 | S16: Serviço Levantamento Topografico | T16: VB | U16: 1 | W16: =IFERROR(IF(B16="INSUMO",_xlfn.XLOOKUP(S16,Insumos!A:A,Insumos!C:C),""),"Inserir Preço") | X16: =IF(B16="Complemento do insumo",V16,IF(R16="","",IF(B16="serviço",R16,IF(OR(B16="insumo"),V16*R16,"")))) -> 1 | Y16: =IF(B16="insumo",W16*V16,IF(B16="serviço",SUMIFS(Y:Y,B:B,"insumo",E:E,E16,I:I,I16),"")) -> 7800 | Z16: =IFERROR(IF(B16="Unidade Construtiva",SUMIFS(Z:Z,B:B,"Célula Construtiva",G:G,G16),IF(B16="célula construtiva",SUMIFS(Z:Z,B:B,"Insumo",I:I,I16,G:G,G16),IF(B16="ETAPA",SUMIFS(Z:Z,B:B,"Insumo",K:K,K16,I:I,I16,G:G,G16),IF(B16="subetapa",SUMIFS(Z:Z,M:M,M16,B:B,"insumo",K:K,K16,I:I,I16,G:G,G16),IF(B16="complemento do insumo",V16*W16,IF(B16="INSUMO",R16*V16*W16,X16*Y16)))))),"") -> 7800 | AB16: =IF(B16="insumo",_xlfn.XLOOKUP(S16,Insumos!A:A,Insumos!D:D),"") | AC16: =IFERROR(IF(B16="","",Z16/SUMIF(B:B,"INSUMO",Z:Z)),0) -> 0.0011189811 | AE16: =IFERROR(IF(OR(Z16="",Z16=0),"",IF(AF16="","",IF(AF16="R$/mês",Z16/OBRA!$D$12,IF(AF16="R$/m²",Z16/OBRA!$D$10,IF(AF16="R$/apto",Orçamento!Z16/OBRA!$D$11,""))))),"") -> 4.0139356 | AF16: R$/m²
B17: Insumo | C17: =IF(B17="INSUMO",COUNTIFS(B:B,"INSUMO",S:S,S17),IF(B17="SERVIÇO",COUNTIFS(B:B,"SERVIÇO",S:S,S17),"")) -> 1 | D17: =IF(B17="Unidade Construtiva",TEXT(F17,"00"),IF(B17="Célula Construtiva",TEXT(H17,"00"),IF(B17="Etapa",CONCATENATE(TEXT(H17,"00"),".",TEXT(J17,"000")),IF(B17="Subetapa",CONCATENATE(TEXT(H17,"00"),".",TEXT(J17,"000"),".",TEXT(L17,"000")),IF(B17="Serviço",CONCATENATE(TEXT(H17,"00"),".",TEXT(J17,"000"),".",TEXT(L17,"000"),".",TEXT(N17,"000")),""))))) | E17: =IF(B17="*","",IFERROR(IF(B17="SERVIÇO",D17,OFFSET(E17,-1,0)),"")) -> 01.001.001.001 | F17: =IF($B17="UNIDADE CONSTRUTIVA",OFFSET(F17,-1,0)+1,LARGE(F$10:F16,1)) -> 1 | G17: =IF(B17="*","",IF(B17="UNIDADE CONSTRUTIVA",S17,OFFSET(G17,-1,0))) -> GERENCIAMENTO TÉCNICO E ADMINISTRATIVO | H17: =IF(B17="UNIDADE CONSTRUTIVA",0,IF(B17="CÉLULA CONSTRUTIVA",OFFSET(H17,-1,0)+1,OFFSET(H17,-1,0))) -> 1 | I17: =IF(B17="*","",IF(B17="CÉLULA CONSTRUTIVA",S17,OFFSET(I17,-1,0))) -> GERENCIAMENTO TÉCNICO | J17: =IF(B17="CÉLULA CONSTRUTIVA",0,IF(B17="ETAPA",OFFSET(J17,-1,0)+1,OFFSET(J17,-1,0))) -> 1 | K17: =IF(B17="*","",IF(B17="ETAPA",S17,OFFSET(K17,-1,0))) -> ESTUDOS | PROJETOS | CONSULTORIAS | L17: =IF(B17="ETAPA",0,IF(B17="SUBETAPA",OFFSET(L17,-1,0)+1,OFFSET(L17,-1,0))) -> 1 | M17: =IF(B17="*","",IF(B17="SUBETAPA",S17,OFFSET(M17,-1,0))) -> Estudos | N17: =IF(B17="Subetapa",0,IF(B17="serviço",OFFSET(N17,-1,0)+1,OFFSET(N17,-1,0))) -> 1 | O17: =IF(B17="*","",IF(B17="SERVIÇO",S17,OFFSET(O17,-1,0))) -> Serviço Levantamento Topografico | P17: =IF(S17="","",IF(Orçamento!$B17="INSUMO",S17,"")) -> LEVANTAMENTO TOPOGRAFICO | Q17: =IF(B17="","",IF(B17="Serviço",S17,"")) | R17: =IF(B17="serviço",U17,OFFSET(R17,-1,0)) -> 1 | S17: LEVANTAMENTO TOPOGRAFICO | T17: =_xlfn.XLOOKUP(S17,Insumos!$A$3:$A$371,Insumos!$B$3:$B$371) -> M3 | U17: =IF($B17="insumo",R17,"") -> 1 | V17: 1 | W17: =IFERROR(IF(B17="INSUMO",_xlfn.XLOOKUP(S17,Insumos!A:A,Insumos!C:C),""),"Inserir Preço") -> 7800 | X17: =IF(B17="Complemento do insumo",V17,IF(R17="","",IF(B17="serviço",R17,IF(OR(B17="insumo"),V17*R17,"")))) -> 1 | Y17: =IF(B17="insumo",W17*V17,IF(B17="serviço",SUMIFS(Y:Y,B:B,"insumo",E:E,E17,I:I,I17),"")) -> 7800 | Z17: =IFERROR(IF(B17="Unidade Construtiva",SUMIFS(Z:Z,B:B,"Célula Construtiva",G:G,G17),IF(B17="célula construtiva",SUMIFS(Z:Z,B:B,"Insumo",I:I,I17,G:G,G17),IF(B17="ETAPA",SUMIFS(Z:Z,B:B,"Insumo",K:K,K17,I:I,I17,G:G,G17),IF(B17="subetapa",SUMIFS(Z:Z,M:M,M17,B:B,"insumo",K:K,K17,I:I,I17,G:G,G17),IF(B17="complemento do insumo",V17*W17,IF(B17="INSUMO",R17*V17*W17,X17*Y17)))))),"") -> 7800 | AB17: =IF(B17="insumo",_xlfn.XLOOKUP(S17,Insumos!A:A,Insumos!D:D),"") -> Balancete | AC17: =IFERROR(IF(B17="","",Z17/SUMIF(B:B,"INSUMO",Z:Z)),0) -> 0.0011189811 | AE17: =IFERROR(IF(OR(Z17="",Z17=0),"",IF(AF17="","",IF(AF17="R$/mês",Z17/OBRA!$D$12,IF(AF17="R$/m²",Z17/OBRA!$D$10,IF(AF17="R$/apto",Orçamento!Z17/OBRA!$D$11,""))))),"") -> 4.0139356 | AF17: R$/m²
B18: Serviço | C18: =IF(B18="INSUMO",COUNTIFS(B:B,"INSUMO",S:S,S18),IF(B18="SERVIÇO",COUNTIFS(B:B,"SERVIÇO",S:S,S18),"")) -> 1 | D18: =IF(B18="Unidade Construtiva",TEXT(F18,"00"),IF(B18="Célula Construtiva",TEXT(H18,"00"),IF(B18="Etapa",CONCATENATE(TEXT(H18,"00"),".",TEXT(J18,"000")),IF(B18="Subetapa",CONCATENATE(TEXT(H18,"00"),".",TEXT(J18,"000"),".",TEXT(L18,"000")),IF(B18="Serviço",CONCATENATE(TEXT(H18,"00"),".",TEXT(J18,"000"),".",TEXT(L18,"000"),".",TEXT(N18,"000")),""))))) -> 01.001.001.002 | E18: =IF(B18="*","",IFERROR(IF(B18="SERVIÇO",D18,OFFSET(E18,-1,0)),"")) -> 01.001.001.002 | F18: =IF($B18="UNIDADE CONSTRUTIVA",OFFSET(F18,-1,0)+1,LARGE(F$10:F17,1)) -> 1 | G18: =IF(B18="*","",IF(B18="UNIDADE CONSTRUTIVA",S18,OFFSET(G18,-1,0))) -> GERENCIAMENTO TÉCNICO E ADMINISTRATIVO | H18: =IF(B18="UNIDADE CONSTRUTIVA",0,IF(B18="CÉLULA CONSTRUTIVA",OFFSET(H18,-1,0)+1,OFFSET(H18,-1,0))) -> 1 | I18: =IF(B18="*","",IF(B18="CÉLULA CONSTRUTIVA",S18,OFFSET(I18,-1,0))) -> GERENCIAMENTO TÉCNICO | J18: =IF(B18="CÉLULA CONSTRUTIVA",0,IF(B18="ETAPA",OFFSET(J18,-1,0)+1,OFFSET(J18,-1,0))) -> 1 | K18: =IF(B18="*","",IF(B18="ETAPA",S18,OFFSET(K18,-1,0))) -> ESTUDOS | PROJETOS | CONSULTORIAS | L18: =IF(B18="ETAPA",0,IF(B18="SUBETAPA",OFFSET(L18,-1,0)+1,OFFSET(L18,-1,0))) -> 1 | M18: =IF(B18="*","",IF(B18="SUBETAPA",S18,OFFSET(M18,-1,0))) -> Estudos | N18: =IF(B18="Subetapa",0,IF(B18="serviço",OFFSET(N18,-1,0)+1,OFFSET(N18,-1,0))) -> 2 | O18: =IF(B18="*","",IF(B18="SERVIÇO",S18,OFFSET(O18,-1,0))) -> Sondagem do terreno | P18: =IF(S18="","",IF(Orçamento!$B18="INSUMO",S18,"")) | Q18: =IF(B18="","",IF(B18="Serviço",S18,"")) -> Sondagem do terreno | R18: =IF(B18="serviço",U18,OFFSET(R18,-1,0)) -> 1 | S18: Sondagem do terreno | T18: VB | U18: 1 | W18: =IFERROR(IF(B18="INSUMO",_xlfn.XLOOKUP(S18,Insumos!A:A,Insumos!C:C),""),"Inserir Preço") | X18: =IF(B18="Complemento do insumo",V18,IF(R18="","",IF(B18="serviço",R18,IF(OR(B18="insumo"),V18*R18,"")))) -> 1 | Y18: =IF(B18="insumo",W18*V18,IF(B18="serviço",SUMIFS(Y:Y,B:B,"insumo",E:E,E18,I:I,I18),"")) -> 8900 | Z18: =IFERROR(IF(B18="Unidade Construtiva",SUMIFS(Z:Z,B:B,"Célula Construtiva",G:G,G18),IF(B18="célula construtiva",SUMIFS(Z:Z,B:B,"Insumo",I:I,I18,G:G,G18),IF(B18="ETAPA",SUMIFS(Z:Z,B:B,"Insumo",K:K,K18,I:I,I18,G:G,G18),IF(B18="subetapa",SUMIFS(Z:Z,M:M,M18,B:B,"insumo",K:K,K18,I:I,I18,G:G,G18),IF(B18="complemento do insumo",V18*W18,IF(B18="INSUMO",R18*V18*W18,X18*Y18)))))),"") -> 8900 | AB18: =IF(B18="insumo",_xlfn.XLOOKUP(S18,Insumos!A:A,Insumos!D:D),"") | AC18: =IFERROR(IF(B18="","",Z18/SUMIF(B:B,"INSUMO",Z:Z)),0) -> 0.0012767861 | AE18: =IFERROR(IF(OR(Z18="",Z18=0),"",IF(AF18="","",IF(AF18="R$/mês",Z18/OBRA!$D$12,IF(AF18="R$/m²",Z18/OBRA!$D$10,IF(AF18="R$/apto",Orçamento!Z18/OBRA!$D$11,""))))),"") -> 4.5800034 | AF18: R$/m²
B19: Insumo | C19: =IF(B19="INSUMO",COUNTIFS(B:B,"INSUMO",S:S,S19),IF(B19="SERVIÇO",COUNTIFS(B:B,"SERVIÇO",S:S,S19),"")) -> 1 | D19: =IF(B19="Unidade Construtiva",TEXT(F19,"00"),IF(B19="Célula Construtiva",TEXT(H19,"00"),IF(B19="Etapa",CONCATENATE(TEXT(H19,"00"),".",TEXT(J19,"000")),IF(B19="Subetapa",CONCATENATE(TEXT(H19,"00"),".",TEXT(J19,"000"),".",TEXT(L19,"000")),IF(B19="Serviço",CONCATENATE(TEXT(H19,"00"),".",TEXT(J19,"000"),".",TEXT(L19,"000"),".",TEXT(N19,"000")),""))))) | E19: =IF(B19="*","",IFERROR(IF(B19="SERVIÇO",D19,OFFSET(E19,-1,0)),"")) -> 01.001.001.002 | F19: =IF($B19="UNIDADE CONSTRUTIVA",OFFSET(F19,-1,0)+1,LARGE(F$10:F18,1)) -> 1 | G19: =IF(B19="*","",IF(B19="UNIDADE CONSTRUTIVA",S19,OFFSET(G19,-1,0))) -> GERENCIAMENTO TÉCNICO E ADMINISTRATIVO | H19: =IF(B19="UNIDADE CONSTRUTIVA",0,IF(B19="CÉLULA CONSTRUTIVA",OFFSET(H19,-1,0)+1,OFFSET(H19,-1,0))) -> 1 | I19: =IF(B19="*","",IF(B19="CÉLULA CONSTRUTIVA",S19,OFFSET(I19,-1,0))) -> GERENCIAMENTO TÉCNICO | J19: =IF(B19="CÉLULA CONSTRUTIVA",0,IF(B19="ETAPA",OFFSET(J19,-1,0)+1,OFFSET(J19,-1,0))) -> 1 | K19: =IF(B19="*","",IF(B19="ETAPA",S19,OFFSET(K19,-1,0))) -> ESTUDOS | PROJETOS | CONSULTORIAS | L19: =IF(B19="ETAPA",0,IF(B19="SUBETAPA",OFFSET(L19,-1,0)+1,OFFSET(L19,-1,0))) -> 1 | M19: =IF(B19="*","",IF(B19="SUBETAPA",S19,OFFSET(M19,-1,0))) -> Estudos | N19: =IF(B19="Subetapa",0,IF(B19="serviço",OFFSET(N19,-1,0)+1,OFFSET(N19,-1,0))) -> 2 | O19: =IF(B19="*","",IF(B19="SERVIÇO",S19,OFFSET(O19,-1,0))) -> Sondagem do terreno | P19: =IF(S19="","",IF(Orçamento!$B19="INSUMO",S19,"")) -> SONDAGEM | Q19: =IF(B19="","",IF(B19="Serviço",S19,"")) | R19: =IF(B19="serviço",U19,OFFSET(R19,-1,0)) -> 1 | S19: SONDAGEM | T19: =_xlfn.XLOOKUP(S19,Insumos!$A$3:$A$371,Insumos!$B$3:$B$371) -> VB | U19: =IF($B19="insumo",R19,"") -> 1 | V19: 1 | W19: =IFERROR(IF(B19="INSUMO",_xlfn.XLOOKUP(S19,Insumos!A:A,Insumos!C:C),""),"Inserir Preço") -> 8900 | X19: =IF(B19="Complemento do insumo",V19,IF(R19="","",IF(B19="serviço",R19,IF(OR(B19="insumo"),V19*R19,"")))) -> 1 | Y19: =IF(B19="insumo",W19*V19,IF(B19="serviço",SUMIFS(Y:Y,B:B,"insumo",E:E,E19,I:I,I19),"")) -> 8900 | Z19: =IFERROR(IF(B19="Unidade Construtiva",SUMIFS(Z:Z,B:B,"Célula Construtiva",G:G,G19),IF(B19="célula construtiva",SUMIFS(Z:Z,B:B,"Insumo",I:I,I19,G:G,G19),IF(B19="ETAPA",SUMIFS(Z:Z,B:B,"Insumo",K:K,K19,I:I,I19,G:G,G19),IF(B19="subetapa",SUMIFS(Z:Z,M:M,M19,B:B,"insumo",K:K,K19,I:I,I19,G:G,G19),IF(B19="complemento do insumo",V19*W19,IF(B19="INSUMO",R19*V19*W19,X19*Y19)))))),"") -> 8900 | AB19: =IF(B19="insumo",_xlfn.XLOOKUP(S19,Insumos!A:A,Insumos!D:D),"") -> Balancete | AC19: =IFERROR(IF(B19="","",Z19/SUMIF(B:B,"INSUMO",Z:Z)),0) -> 0.0012767861 | AE19: =IFERROR(IF(OR(Z19="",Z19=0),"",IF(AF19="","",IF(AF19="R$/mês",Z19/OBRA!$D$12,IF(AF19="R$/m²",Z19/OBRA!$D$10,IF(AF19="R$/apto",Orçamento!Z19/OBRA!$D$11,""))))),"") -> 4.5800034 | AF19: R$/m²
B20: Subetapa | C20: =IF(B20="INSUMO",COUNTIFS(B:B,"INSUMO",S:S,S20),IF(B20="SERVIÇO",COUNTIFS(B:B,"SERVIÇO",S:S,S20),"")) | D20: =IF(B20="Unidade Construtiva",TEXT(F20,"00"),IF(B20="Célula Construtiva",TEXT(H20,"00"),IF(B20="Etapa",CONCATENATE(TEXT(H20,"00"),".",TEXT(J20,"000")),IF(B20="Subetapa",CONCATENATE(TEXT(H20,"00"),".",TEXT(J20,"000"),".",TEXT(L20,"000")),IF(B20="Serviço",CONCATENATE(TEXT(H20,"00"),".",TEXT(J20,"000"),".",TEXT(L20,"000"),".",TEXT(N20,"000")),""))))) -> 01.001.002 | E20: =IF(B20="*","",IFERROR(IF(B20="SERVIÇO",D20,OFFSET(E20,-1,0)),"")) -> 01.001.001.002 | F20: =IF($B20="UNIDADE CONSTRUTIVA",OFFSET(F20,-1,0)+1,LARGE(F$10:F19,1)) -> 1 | G20: =IF(B20="*","",IF(B20="UNIDADE CONSTRUTIVA",S20,OFFSET(G20,-1,0))) -> GERENCIAMENTO TÉCNICO E ADMINISTRATIVO | H20: =IF(B20="UNIDADE CONSTRUTIVA",0,IF(B20="CÉLULA CONSTRUTIVA",OFFSET(H20,-1,0)+1,OFFSET(H20,-1,0))) -> 1 | I20: =IF(B20="*","",IF(B20="CÉLULA CONSTRUTIVA",S20,OFFSET(I20,-1,0))) -> GERENCIAMENTO TÉCNICO | J20: =IF(B20="CÉLULA CONSTRUTIVA",0,IF(B20="ETAPA",OFFSET(J20,-1,0)+1,OFFSET(J20,-1,0))) -> 1 | K20: =IF(B20="*","",IF(B20="ETAPA",S20,OFFSET(K20,-1,0))) -> ESTUDOS | PROJETOS | CONSULTORIAS | L20: =IF(B20="ETAPA",0,IF(B20="SUBETAPA",OFFSET(L20,-1,0)+1,OFFSET(L20,-1,0))) -> 2 | M20: =IF(B20="*","",IF(B20="SUBETAPA",S20,OFFSET(M20,-1,0))) -> Projetos | N20: =IF(B20="Subetapa",0,IF(B20="serviço",OFFSET(N20,-1,0)+1,OFFSET(N20,-1,0))) -> 0 | O20: =IF(B20="*","",IF(B20="SERVIÇO",S20,OFFSET(O20,-1,0))) -> Sondagem do terreno | P20: =IF(S20="","",IF(Orçamento!$B20="INSUMO",S20,"")) | Q20: =IF(B20="","",IF(B20="Serviço",S20,"")) | R20: =IF(B20="serviço",U20,OFFSET(R20,-1,0)) -> 1 | S20: Projetos | U20: =IF($B20="insumo",R20,"") | W20: =IFERROR(IF(B20="INSUMO",_xlfn.XLOOKUP(S20,Insumos!A:A,Insumos!C:C),""),"Inserir Preço") | X20: =IF(B20="Complemento do insumo",V20,IF(R20="","",IF(B20="serviço",R20,IF(OR(B20="insumo"),V20*R20,"")))) | Y20: =IF(B20="insumo",W20*V20,IF(B20="serviço",SUMIFS(Y:Y,B:B,"insumo",E:E,E20,I:I,I20),"")) | Z20: =IFERROR(IF(B20="Unidade Construtiva",SUMIFS(Z:Z,B:B,"Célula Construtiva",G:G,G20),IF(B20="célula construtiva",SUMIFS(Z:Z,B:B,"Insumo",I:I,I20,G:G,G20),IF(B20="ETAPA",SUMIFS(Z:Z,B:B,"Insumo",K:K,K20,I:I,I20,G:G,G20),IF(B20="subetapa",SUMIFS(Z:Z,M:M,M20,B:B,"insumo",K:K,K20,I:I,I20,G:G,G20),IF(B20="complemento do insumo",V20*W20,IF(B20="INSUMO",R20*V20*W20,X20*Y20)))))),"") -> 106486 | AB20: =IF(B20="insumo",_xlfn.XLOOKUP(S20,Insumos!A:A,Insumos!D:D),"") | AC20: =IFERROR(IF(B20="","",Z20/SUMIF(B:B,"INSUMO",Z:Z)),0) -> 0.015276388 | AE20: =IFERROR(IF(OR(Z20="",Z20=0),"",IF(AF20="","",IF(AF20="R$/mês",Z20/OBRA!$D$12,IF(AF20="R$/m²",Z20/OBRA!$D$10,IF(AF20="R$/apto",Orçamento!Z20/OBRA!$D$11,""))))),"") -> 54.798454 | AF20: R$/m²
B21: Serviço | C21: =IF(B21="INSUMO",COUNTIFS(B:B,"INSUMO",S:S,S21),IF(B21="SERVIÇO",COUNTIFS(B:B,"SERVIÇO",S:S,S21),"")) -> 1 | D21: =IF(B21="Unidade Construtiva",TEXT(F21,"00"),IF(B21="Célula Construtiva",TEXT(H21,"00"),IF(B21="Etapa",CONCATENATE(TEXT(H21,"00"),".",TEXT(J21,"000")),IF(B21="Subetapa",CONCATENATE(TEXT(H21,"00"),".",TEXT(J21,"000"),".",TEXT(L21,"000")),IF(B21="Serviço",CONCATENATE(TEXT(H21,"00"),".",TEXT(J21,"000"),".",TEXT(L21,"000"),".",TEXT(N21,"000")),""))))) -> 01.001.002.001 | E21: =IF(B21="*","",IFERROR(IF(B21="SERVIÇO",D21,OFFSET(E21,-1,0)),"")) -> 01.001.002.001 | F21: =IF($B21="UNIDADE CONSTRUTIVA",OFFSET(F21,-1,0)+1,LARGE(F$10:F20,1)) -> 1 | G21: =IF(B21="*","",IF(B21="UNIDADE CONSTRUTIVA",S21,OFFSET(G21,-1,0))) -> GERENCIAMENTO TÉCNICO E ADMINISTRATIVO | H21: =IF(B21="UNIDADE CONSTRUTIVA",0,IF(B21="CÉLULA CONSTRUTIVA",OFFSET(H21,-1,0)+1,OFFSET(H21,-1,0))) -> 1 | I21: =IF(B21="*","",IF(B21="CÉLULA CONSTRUTIVA",S21,OFFSET(I21,-1,0))) -> GERENCIAMENTO TÉCNICO | J21: =IF(B21="CÉLULA CONSTRUTIVA",0,IF(B21="ETAPA",OFFSET(J21,-1,0)+1,OFFSET(J21,-1,0))) -> 1 | K21: =IF(B21="*","",IF(B21="ETAPA",S21,OFFSET(K21,-1,0))) -> ESTUDOS | PROJETOS | CONSULTORIAS | L21: =IF(B21="ETAPA",0,IF(B21="SUBETAPA",OFFSET(L21,-1,0)+1,OFFSET(L21,-1,0))) -> 2 | M21: =IF(B21="*","",IF(B21="SUBETAPA",S21,OFFSET(M21,-1,0))) -> Projetos | N21: =IF(B21="Subetapa",0,IF(B21="serviço",OFFSET(N21,-1,0)+1,OFFSET(N21,-1,0))) -> 1 | O21: =IF(B21="*","",IF(B21="SERVIÇO",S21,OFFSET(O21,-1,0))) -> Projeto Arquitetônico | P21: =IF(S21="","",IF(Orçamento!$B21="INSUMO",S21,"")) | Q21: =IF(B21="","",IF(B21="Serviço",S21,"")) -> Projeto Arquitetônico | R21: =IF(B21="serviço",U21,OFFSET(R21,-1,0)) -> 1 | S21: Projeto Arquitetônico | T21: VB | U21: 1 | W21: =IFERROR(IF(B21="INSUMO",_xlfn.XLOOKUP(S21,Insumos!A:A,Insumos!C:C),""),"Inserir Preço") | X21: =IF(B21="Complemento do insumo",V21,IF(R21="","",IF(B21="serviço",R21,IF(OR(B21="insumo"),V21*R21,"")))) -> 1 | Y21: =IF(B21="insumo",W21*V21,IF(B21="serviço",SUMIFS(Y:Y,B:B,"insumo",E:E,E21,I:I,I21),"")) -> 40816 | Z21: =IFERROR(IF(B21="Unidade Construtiva",SUMIFS(Z:Z,B:B,"Célula Construtiva",G:G,G21),IF(B21="célula construtiva",SUMIFS(Z:Z,B:B,"Insumo",I:I,I21,G:G,G21),IF(B21="ETAPA",SUMIFS(Z:Z,B:B,"Insumo",K:K,K21,I:I,I21,G:G,G21),IF(B21="subetapa",SUMIFS(Z:Z,M:M,M21,B:B,"insumo",K:K,K21,I:I,I21,G:G,G21),IF(B21="complemento do insumo",V21*W21,IF(B21="INSUMO",R21*V21*W21,X21*Y21)))))),"") -> 40816 | AB21: =IF(B21="insumo",_xlfn.XLOOKUP(S21,Insumos!A:A,Insumos!D:D),"") | AC21: =IFERROR(IF(B21="","",Z21/SUMIF(B:B,"INSUMO",Z:Z)),0) -> 0.0058554273 | AE21: =IFERROR(IF(OR(Z21="",Z21=0),"",IF(AF21="","",IF(AF21="R$/mês",Z21/OBRA!$D$12,IF(AF21="R$/m²",Z21/OBRA!$D$10,IF(AF21="R$/apto",Orçamento!Z21/OBRA!$D$11,""))))),"") -> 21.004204 | AF21: R$/m²
B22: Insumo | C22: =IF(B22="INSUMO",COUNTIFS(B:B,"INSUMO",S:S,S22),IF(B22="SERVIÇO",COUNTIFS(B:B,"SERVIÇO",S:S,S22),"")) -> 1 | D22: =IF(B22="Unidade Construtiva",TEXT(F22,"00"),IF(B22="Célula Construtiva",TEXT(H22,"00"),IF(B22="Etapa",CONCATENATE(TEXT(H22,"00"),".",TEXT(J22,"000")),IF(B22="Subetapa",CONCATENATE(TEXT(H22,"00"),".",TEXT(J22,"000"),".",TEXT(L22,"000")),IF(B22="Serviço",CONCATENATE(TEXT(H22,"00"),".",TEXT(J22,"000"),".",TEXT(L22,"000"),".",TEXT(N22,"000")),""))))) | E22: =IF(B22="*","",IFERROR(IF(B22="SERVIÇO",D22,OFFSET(E22,-1,0)),"")) -> 01.001.002.001 | F22: =IF($B22="UNIDADE CONSTRUTIVA",OFFSET(F22,-1,0)+1,LARGE(F$10:F21,1)) -> 1 | G22: =IF(B22="*","",IF(B22="UNIDADE CONSTRUTIVA",S22,OFFSET(G22,-1,0))) -> GERENCIAMENTO TÉCNICO E ADMINISTRATIVO | H22: =IF(B22="UNIDADE CONSTRUTIVA",0,IF(B22="CÉLULA CONSTRUTIVA",OFFSET(H22,-1,0)+1,OFFSET(H22,-1,0))) -> 1 | I22: =IF(B22="*","",IF(B22="CÉLULA CONSTRUTIVA",S22,OFFSET(I22,-1,0))) -> GERENCIAMENTO TÉCNICO | J22: =IF(B22="CÉLULA CONSTRUTIVA",0,IF(B22="ETAPA",OFFSET(J22,-1,0)+1,OFFSET(J22,-1,0))) -> 1 | K22: =IF(B22="*","",IF(B22="ETAPA",S22,OFFSET(K22,-1,0))) -> ESTUDOS | PROJETOS | CONSULTORIAS | L22: =IF(B22="ETAPA",0,IF(B22="SUBETAPA",OFFSET(L22,-1,0)+1,OFFSET(L22,-1,0))) -> 2 | M22: =IF(B22="*","",IF(B22="SUBETAPA",S22,OFFSET(M22,-1,0))) -> Projetos | N22: =IF(B22="Subetapa",0,IF(B22="serviço",OFFSET(N22,-1,0)+1,OFFSET(N22,-1,0))) -> 1 | O22: =IF(B22="*","",IF(B22="SERVIÇO",S22,OFFSET(O22,-1,0))) -> Projeto Arquitetônico | P22: =IF(S22="","",IF(Orçamento!$B22="INSUMO",S22,"")) -> PROJETO ARQUITETONICO | Q22: =IF(B22="","",IF(B22="Serviço",S22,"")) | R22: =IF(B22="serviço",U22,OFFSET(R22,-1,0)) -> 1 | S22: PROJETO ARQUITETONICO | T22: =_xlfn.XLOOKUP(S22,Insumos!$A$3:$A$371,Insumos!$B$3:$B$371) -> VB | U22: =IF($B22="insumo",R22,"") -> 1 | V22: 1 | W22: =IFERROR(IF(B22="INSUMO",_xlfn.XLOOKUP(S22,Insumos!A:A,Insumos!C:C),""),"Inserir Preço") -> 40816 | X22: =IF(B22="Complemento do insumo",V22,IF(R22="","",IF(B22="serviço",R22,IF(OR(B22="insumo"),V22*R22,"")))) -> 1 | Y22: =IF(B22="insumo",W22*V22,IF(B22="serviço",SUMIFS(Y:Y,B:B,"insumo",E:E,E22,I:I,I22),"")) -> 40816 | Z22: =IFERROR(IF(B22="Unidade Construtiva",SUMIFS(Z:Z,B:B,"Célula Construtiva",G:G,G22),IF(B22="célula construtiva",SUMIFS(Z:Z,B:B,"Insumo",I:I,I22,G:G,G22),IF(B22="ETAPA",SUMIFS(Z:Z,B:B,"Insumo",K:K,K22,I:I,I22,G:G,G22),IF(B22="subetapa",SUMIFS(Z:Z,M:M,M22,B:B,"insumo",K:K,K22,I:I,I22,G:G,G22),IF(B22="complemento do insumo",V22*W22,IF(B22="INSUMO",R22*V22*W22,X22*Y22)))))),"") -> 40816 | AB22: =IF(B22="insumo",_xlfn.XLOOKUP(S22,Insumos!A:A,Insumos!D:D),"") -> Recebido Cliente | AC22: =IFERROR(IF(B22="","",Z22/SUMIF(B:B,"INSUMO",Z:Z)),0) -> 0.0058554273 | AE22: =IFERROR(IF(OR(Z22="",Z22=0),"",IF(AF22="","",IF(AF22="R$/mês",Z22/OBRA!$D$12,IF(AF22="R$/m²",Z22/OBRA!$D$10,IF(AF22="R$/apto",Orçamento!Z22/OBRA!$D$11,""))))),"") -> 21.004204 | AF22: R$/m²
B23: Serviço | C23: =IF(B23="INSUMO",COUNTIFS(B:B,"INSUMO",S:S,S23),IF(B23="SERVIÇO",COUNTIFS(B:B,"SERVIÇO",S:S,S23),"")) -> 1 | D23: =IF(B23="Unidade Construtiva",TEXT(F23,"00"),IF(B23="Célula Construtiva",TEXT(H23,"00"),IF(B23="Etapa",CONCATENATE(TEXT(H23,"00"),".",TEXT(J23,"000")),IF(B23="Subetapa",CONCATENATE(TEXT(H23,"00"),".",TEXT(J23,"000"),".",TEXT(L23,"000")),IF(B23="Serviço",CONCATENATE(TEXT(H23,"00"),".",TEXT(J23,"000"),".",TEXT(L23,"000"),".",TEXT(N23,"000")),""))))) -> 01.001.002.002 | E23: =IF(B23="*","",IFERROR(IF(B23="SERVIÇO",D23,OFFSET(E23,-1,0)),"")) -> 01.001.002.002 | F23: =IF($B23="UNIDADE CONSTRUTIVA",OFFSET(F23,-1,0)+1,LARGE(F$10:F22,1)) -> 1 | G23: =IF(B23="*","",IF(B23="UNIDADE CONSTRUTIVA",S23,OFFSET(G23,-1,0))) -> GERENCIAMENTO TÉCNICO E ADMINISTRATIVO | H23: =IF(B23="UNIDADE CONSTRUTIVA",0,IF(B23="CÉLULA CONSTRUTIVA",OFFSET(H23,-1,0)+1,OFFSET(H23,-1,0))) -> 1 | I23: =IF(B23="*","",IF(B23="CÉLULA CONSTRUTIVA",S23,OFFSET(I23,-1,0))) -> GERENCIAMENTO TÉCNICO | J23: =IF(B23="CÉLULA CONSTRUTIVA",0,IF(B23="ETAPA",OFFSET(J23,-1,0)+1,OFFSET(J23,-1,0))) -> 1 | K23: =IF(B23="*","",IF(B23="ETAPA",S23,OFFSET(K23,-1,0))) -> ESTUDOS | PROJETOS | CONSULTORIAS | L23: =IF(B23="ETAPA",0,IF(B23="SUBETAPA",OFFSET(L23,-1,0)+1,OFFSET(L23,-1,0))) -> 2 | M23: =IF(B23="*","",IF(B23="SUBETAPA",S23,OFFSET(M23,-1,0))) -> Projetos | N23: =IF(B23="Subetapa",0,IF(B23="serviço",OFFSET(N23,-1,0)+1,OFFSET(N23,-1,0))) -> 2 | O23: =IF(B23="*","",IF(B23="SERVIÇO",S23,OFFSET(O23,-1,0))) -> Projeto Estrutural | P23: =IF(S23="","",IF(Orçamento!$B23="INSUMO",S23,"")) | Q23: =IF(B23="","",IF(B23="Serviço",S23,"")) -> Projeto Estrutural | R23: =IF(B23="serviço",U23,OFFSET(R23,-1,0)) -> 1 | S23: Projeto Estrutural | T23: VB | U23: 1 | W23: =IFERROR(IF(B23="INSUMO",_xlfn.XLOOKUP(S23,Insumos!A:A,Insumos!C:C),""),"Inserir Preço") | X23: =IF(B23="Complemento do insumo",V23,IF(R23="","",IF(B23="serviço",R23,IF(OR(B23="insumo"),V23*R23,"")))) -> 1 | Y23: =IF(B23="insumo",W23*V23,IF(B23="serviço",SUMIFS(Y:Y,B:B,"insumo",E:E,E23,I:I,I23),"")) -> 29900 | Z23: =IFERROR(IF(B23="Unidade Construtiva",SUMIFS(Z:Z,B:B,"Célula Construtiva",G:G,G23),IF(B23="célula construtiva",SUMIFS(Z:Z,B:B,"Insumo",I:I,I23,G:G,G23),IF(B23="ETAPA",SUMIFS(Z:Z,B:B,"Insumo",K:K,K23,I:I,I23,G:G,G23),IF(B23="subetapa",SUMIFS(Z:Z,M:M,M23,B:B,"insumo",K:K,K23,I:I,I23,G:G,G23),IF(B23="complemento do insumo",V23*W23,IF(B23="INSUMO",R23*V23*W23,X23*Y23)))))),"") -> 29900 | AB23: =IF(B23="insumo",_xlfn.XLOOKUP(S23,Insumos!A:A,Insumos!D:D),"") | AC23: =IFERROR(IF(B23="","",Z23/SUMIF(B:B,"INSUMO",Z:Z)),0) -> 0.0042894276 | AE23: =IFERROR(IF(OR(Z23="",Z23=0),"",IF(AF23="","",IF(AF23="R$/mês",Z23/OBRA!$D$12,IF(AF23="R$/m²",Z23/OBRA!$D$10,IF(AF23="R$/apto",Orçamento!Z23/OBRA!$D$11,""))))),"") -> 15.386753 | AF23: R$/m²
B24: Insumo | C24: =IF(B24="INSUMO",COUNTIFS(B:B,"INSUMO",S:S,S24),IF(B24="SERVIÇO",COUNTIFS(B:B,"SERVIÇO",S:S,S24),"")) -> 1 | D24: =IF(B24="Unidade Construtiva",TEXT(F24,"00"),IF(B24="Célula Construtiva",TEXT(H24,"00"),IF(B24="Etapa",CONCATENATE(TEXT(H24,"00"),".",TEXT(J24,"000")),IF(B24="Subetapa",CONCATENATE(TEXT(H24,"00"),".",TEXT(J24,"000"),".",TEXT(L24,"000")),IF(B24="Serviço",CONCATENATE(TEXT(H24,"00"),".",TEXT(J24,"000"),".",TEXT(L24,"000"),".",TEXT(N24,"000")),""))))) | E24: =IF(B24="*","",IFERROR(IF(B24="SERVIÇO",D24,OFFSET(E24,-1,0)),"")) -> 01.001.002.002 | F24: =IF($B24="UNIDADE CONSTRUTIVA",OFFSET(F24,-1,0)+1,LARGE(F$10:F23,1)) -> 1 | G24: =IF(B24="*","",IF(B24="UNIDADE CONSTRUTIVA",S24,OFFSET(G24,-1,0))) -> GERENCIAMENTO TÉCNICO E ADMINISTRATIVO | H24: =IF(B24="UNIDADE CONSTRUTIVA",0,IF(B24="CÉLULA CONSTRUTIVA",OFFSET(H24,-1,0)+1,OFFSET(H24,-1,0))) -> 1 | I24: =IF(B24="*","",IF(B24="CÉLULA CONSTRUTIVA",S24,OFFSET(I24,-1,0))) -> GERENCIAMENTO TÉCNICO | J24: =IF(B24="CÉLULA CONSTRUTIVA",0,IF(B24="ETAPA",OFFSET(J24,-1,0)+1,OFFSET(J24,-1,0))) -> 1 | K24: =IF(B24="*","",IF(B24="ETAPA",S24,OFFSET(K24,-1,0))) -> ESTUDOS | PROJETOS | CONSULTORIAS | L24: =IF(B24="ETAPA",0,IF(B24="SUBETAPA",OFFSET(L24,-1,0)+1,OFFSET(L24,-1,0))) -> 2 | M24: =IF(B24="*","",IF(B24="SUBETAPA",S24,OFFSET(M24,-1,0))) -> Projetos | N24: =IF(B24="Subetapa",0,IF(B24="serviço",OFFSET(N24,-1,0)+1,OFFSET(N24,-1,0))) -> 2 | O24: =IF(B24="*","",IF(B24="SERVIÇO",S24,OFFSET(O24,-1,0))) -> Projeto Estrutural | P24: =IF(S24="","",IF(Orçamento!$B24="INSUMO",S24,"")) -> PROJETO ESTRUTURAL | Q24: =IF(B24="","",IF(B24="Serviço",S24,"")) | R24: =IF(B24="serviço",U24,OFFSET(R24,-1,0)) -> 1 | S24: PROJETO ESTRUTURAL | T24: =_xlfn.XLOOKUP(S24,Insumos!$A$3:$A$371,Insumos!$B$3:$B$371) -> VB | U24: =IF($B24="insumo",R24,"") -> 1 | V24: 1 | W24: =IFERROR(IF(B24="INSUMO",_xlfn.XLOOKUP(S24,Insumos!A:A,Insumos!C:C),""),"Inserir Preço") -> 29900 | X24: =IF(B24="Complemento do insumo",V24,IF(R24="","",IF(B24="serviço",R24,IF(OR(B24="insumo"),V24*R24,"")))) -> 1 | Y24: =IF(B24="insumo",W24*V24,IF(B24="serviço",SUMIFS(Y:Y,B:B,"insumo",E:E,E24,I:I,I24),"")) -> 29900 | Z24: =IFERROR(IF(B24="Unidade Construtiva",SUMIFS(Z:Z,B:B,"Célula Construtiva",G:G,G24),IF(B24="célula construtiva",SUMIFS(Z:Z,B:B,"Insumo",I:I,I24,G:G,G24),IF(B24="ETAPA",SUMIFS(Z:Z,B:B,"Insumo",K:K,K24,I:I,I24,G:G,G24),IF(B24="subetapa",SUMIFS(Z:Z,M:M,M24,B:B,"insumo",K:K,K24,I:I,I24,G:G,G24),IF(B24="complemento do insumo",V24*W24,IF(B24="INSUMO",R24*V24*W24,X24*Y24)))))),"") -> 29900 | AB24: =IF(B24="insumo",_xlfn.XLOOKUP(S24,Insumos!A:A,Insumos!D:D),"") -> Recebido Cliente | AC24: =IFERROR(IF(B24="","",Z24/SUMIF(B:B,"INSUMO",Z:Z)),0) -> 0.0042894276 | AE24: =IFERROR(IF(OR(Z24="",Z24=0),"",IF(AF24="","",IF(AF24="R$/mês",Z24/OBRA!$D$12,IF(AF24="R$/m²",Z24/OBRA!$D$10,IF(AF24="R$/apto",Orçamento!Z24/OBRA!$D$11,""))))),"") -> 15.386753 | AF24: R$/m²
B25: Serviço | C25: =IF(B25="INSUMO",COUNTIFS(B:B,"INSUMO",S:S,S25),IF(B25="SERVIÇO",COUNTIFS(B:B,"SERVIÇO",S:S,S25),"")) -> 1 | D25: =IF(B25="Unidade Construtiva",TEXT(F25,"00"),IF(B25="Célula Construtiva",TEXT(H25,"00"),IF(B25="Etapa",CONCATENATE(TEXT(H25,"00"),".",TEXT(J25,"000")),IF(B25="Subetapa",CONCATENATE(TEXT(H25,"00"),".",TEXT(J25,"000"),".",TEXT(L25,"000")),IF(B25="Serviço",CONCATENATE(TEXT(H25,"00"),".",TEXT(J25,"000"),".",TEXT(L25,"000"),".",TEXT(N25,"000")),""))))) -> 01.001.002.003 | E25: =IF(B25="*","",IFERROR(IF(B25="SERVIÇO",D25,OFFSET(E25,-1,0)),"")) -> 01.001.002.003 | F25: =IF($B25="UNIDADE CONSTRUTIVA",OFFSET(F25,-1,0)+1,LARGE(F$10:F24,1)) -> 1 | G25: =IF(B25="*","",IF(B25="UNIDADE CONSTRUTIVA",S25,OFFSET(G25,-1,0))) -> GERENCIAMENTO TÉCNICO E ADMINISTRATIVO | H25: =IF(B25="UNIDADE CONSTRUTIVA",0,IF(B25="CÉLULA CONSTRUTIVA",OFFSET(H25,-1,0)+1,OFFSET(H25,-1,0))) -> 1 | I25: =IF(B25="*","",IF(B25="CÉLULA CONSTRUTIVA",S25,OFFSET(I25,-1,0))) -> GERENCIAMENTO TÉCNICO | J25: =IF(B25="CÉLULA CONSTRUTIVA",0,IF(B25="ETAPA",OFFSET(J25,-1,0)+1,OFFSET(J25,-1,0))) -> 1 | K25: =IF(B25="*","",IF(B25="ETAPA",S25,OFFSET(K25,-1,0))) -> ESTUDOS | PROJETOS | CONSULTORIAS | L25: =IF(B25="ETAPA",0,IF(B25="SUBETAPA",OFFSET(L25,-1,0)+1,OFFSET(L25,-1,0))) -> 2 | M25: =IF(B25="*","",IF(B25="SUBETAPA",S25,OFFSET(M25,-1,0))) -> Projetos | N25: =IF(B25="Subetapa",0,IF(B25="serviço",OFFSET(N25,-1,0)+1,OFFSET(N25,-1,0))) -> 3 | O25: =IF(B25="*","",IF(B25="SERVIÇO",S25,OFFSET(O25,-1,0))) -> Projeto eletrico | P25: =IF(S25="","",IF(Orçamento!$B25="INSUMO",S25,"")) | Q25: =IF(B25="","",IF(B25="Serviço",S25,"")) -> Projeto eletrico | R25: =IF(B25="serviço",U25,OFFSET(R25,-1,0)) -> 1 | S25: Projeto eletrico | T25: VB | U25: 1 | W25: =IFERROR(IF(B25="INSUMO",_xlfn.XLOOKUP(S25,Insumos!A:A,Insumos!C:C),""),"Inserir Preço") | X25: =IF(B25="Complemento do insumo",V25,IF(R25="","",IF(B25="serviço",R25,IF(OR(B25="insumo"),V25*R25,"")))) -> 1 | Y25: =IF(B25="insumo",W25*V25,IF(B25="serviço",SUMIFS(Y:Y,B:B,"insumo",E:E,E25,I:I,I25),"")) -> 5936 | Z25: =IFERROR(IF(B25="Unidade Construtiva",SUMIFS(Z:Z,B:B,"Célula Construtiva",G:G,G25),IF(B25="célula construtiva",SUMIFS(Z:Z,B:B,"Insumo",I:I,I25,G:G,G25),IF(B25="ETAPA",SUMIFS(Z:Z,B:B,"Insumo",K:K,K25,I:I,I25,G:G,G25),IF(B25="subetapa",SUMIFS(Z:Z,M:M,M25,B:B,"insumo",K:K,K25,I:I,I25,G:G,G25),IF(B25="complemento do insumo",V25*W25,IF(B25="INSUMO",R25*V25*W25,X25*Y25)))))),"") -> 5936 | AB25: =IF(B25="insumo",_xlfn.XLOOKUP(S25,Insumos!A:A,Insumos!D:D),"") | AC25: =IFERROR(IF(B25="","",Z25/SUMIF(B:B,"INSUMO",Z:Z)),0) -> 0.00085157332 | AE25: =IFERROR(IF(OR(Z25="",Z25=0),"",IF(AF25="","",IF(AF25="R$/mês",Z25/OBRA!$D$12,IF(AF25="R$/m²",Z25/OBRA!$D$10,IF(AF25="R$/apto",Orçamento!Z25/OBRA!$D$11,""))))),"") -> 3.0547079 | AF25: R$/m²
