Workbook

Sheet ORÇAMENTO_EXECUTIVO
A1: ETAPA | B1: VALOR ORÇADO | C1: % | D1: VALOR / m²
A2: GERENCIAMENTO TÉCNICO E ADMINISTRATIVO | B2: =[1]Resumo!C2 -> 728402.37 | C2: =B2/$B$19 -> 0.10449596 | D2: =B2/ORÇAMENTO_EXECUTIVO!G$2 -> 374.84105 | F2: ÁREA CONSTRUÍDA | G2: 1943.23 | H2: m²
A3: MOVIMENTAÇÃO DE TERRA | B3: =[1]Resumo!C3 -> 145568.65 | C3: =B3/B$19 -> 0.020883149 | D3: =B3/ORÇAMENTO_EXECUTIVO!G$2 -> 74.910662
A4: INFRAESTRUTURA | B4: =[1]Resumo!C4 -> 502193.32 | C4: =B4/B$19 -> 0.072044211 | D4: =B4/ORÇAMENTO_EXECUTIVO!G$2 -> 258.43226 | F4: 0
A5: SUPRAESTRUTURA | B5: =[1]Resumo!C5 -> 1352591 | C5: =B5/B$19 -> 0.1940415 | D5: =B5/ORÇAMENTO_EXECUTIVO!G$2 -> 696.05294 | F5: =280000*F4 -> 0 | G5: Incorporação
A6: ALVENARIA | B6: =[1]Resumo!C6 -> 261393.66 | C6: =B6/B$19 -> 0.037499304 | D6: =B6/ORÇAMENTO_EXECUTIVO!G$2 -> 134.51504
A7: INSTALAÇÕES ELÉTRICAS, HIDRÁULICAS, GLP E PREVENTIVAS | B7: =[1]Resumo!C7 -> 641270.51 | C7: =B7/B$19 -> 0.091996102 | D7: =B7/ORÇAMENTO_EXECUTIVO!G$2 -> 330.00237
A8: EQUIPAMENTOS E SISTEMAS ESPECIAIS | B8: =[1]Resumo!C8 -> 323614.15 | C8: =B8/B$19 -> 0.0464254 | D8: =B8/ORÇAMENTO_EXECUTIVO!G$2 -> 166.53415
A9: IMPERMEABILIZAÇÃO | B9: =[1]Resumo!C9 -> 175140.61 | C9: =B9/B$19 -> 0.025125517 | D9: =B9/ORÇAMENTO_EXECUTIVO!G$2 -> 90.128606
A10: REVESTIMENTOS INTERNOS EM PAREDE | B10: =[1]Resumo!C10 -> 397235.17 | C10: =B10/B$19 -> 0.056987008 | D10: =B10/ORÇAMENTO_EXECUTIVO!G$2 -> 204.42005
A11: REVESTIMENTOS E ACABAMENTOS INTERNOS EM TETO | B11: =[1]Resumo!C11 -> 128940.66 | C11: =B11/B$19 -> 0.018497713 | D11: =B11/ORÇAMENTO_EXECUTIVO!G$2 -> 66.353781
A12: PISOS E PAVIMENTAÇÕES | B12: =[1]Resumo!C12 -> 446389.88 | C12: =B12/B$19 -> 0.064038698 | D12: =B12/ORÇAMENTO_EXECUTIVO!G$2 -> 229.71541
A13: PINTURA INTERNA | B13: =[1]Resumo!C13 -> 303208.12 | C13: =B13/B$19 -> 0.04349797 | D13: =B13/ORÇAMENTO_EXECUTIVO!G$2 -> 156.03306
A14: ESQUADRIAS, VIDROS E FERRAGENS | B14: =[1]Resumo!C14 -> 578274.83 | C14: =B14/B$19 -> 0.082958796 | D14: =B14/ORÇAMENTO_EXECUTIVO!G$2 -> 297.58435
A15: COBERTURA | B15: =[1]Resumo!C15 -> 38853.541 | C15: =B15/B$19 -> 0.0055738947 | D15: =B15/ORÇAMENTO_EXECUTIVO!G$2 -> 19.994309
A16: REVESTIMENTOS E ACABAMENTOS DE FACHADA | B16: =[1]Resumo!C16 -> 365385.57 | C16: =B16/B$19 -> 0.052417891 | D16: =B16/ORÇAMENTO_EXECUTIVO!G$2 -> 188.03002
A17: SERVIÇOS COMPLEMENTARES | B17: =[1]Resumo!C17 -> 442752.49 | C17: =B17/B$19 -> 0.063516881 | D17: =B17/ORÇAMENTO_EXECUTIVO!G$2 -> 227.84358
A18: IMPREVISTOS E CONTINGENCIAS | B18: =[1]Resumo!C18 -> 139412.54 | C18: =B18/B$19 -> 0.02 | D18: =B18/ORÇAMENTO_EXECUTIVO!G$2 -> 71.742686
A19: TOTAL | B19: =SUM(B2:B18) -> 6970627 | C19: =SUM(C2:C18) -> 1 | D19: =SUM(D2:D18) -> 3587.1343
A20: CUB/SC | B20: 2758.46 | C20: 45413 | D20: =ROUNDUP(+D19/B20,2) & " CUB" -> 1,31 CUB
A25: ETAPA | B25: VALOR ORÇADO R00 | C25: VALOR ORÇADO R01 | D25: Diferença R$ | E25: Diferença % | F25: % Orçado R01 | G25: VALOR / m²
A26: GERENCIAMENTO TÉCNICO E ADMINISTRATIVO | B26: 1269673.5 | C26: =ORÇAMENTO_EXECUTIVO!B2 -> 728402.37 | D26: =C26-B26 -> -541271.16 | E26: =(D26/B26) -> -0.42630735 | F26: =C26/$C$43 -> 0.10449596 | G26: =C26/ORÇAMENTO_EXECUTIVO!G$2 -> 374.84105
A27: MOVIMENTAÇÃO DE TERRA | B27: 40912.878 | C27: =ORÇAMENTO_EXECUTIVO!B3 -> 145568.65 | D27: =C27-B27 -> 104655.77 | E27: =(D27/B27) -> 2.5580153 | F27: =C27/$C$43 -> 0.020883149 | G27: =C27/ORÇAMENTO_EXECUTIVO!G$2 -> 74.910662
A28: INFRAESTRUTURA | B28: 356756.89 | C28: =ORÇAMENTO_EXECUTIVO!B4 -> 502193.32 | D28: =C28-B28 -> 145436.43 | E28: =(D28/B28) -> 0.40766257 | F28: =C28/$C$43 -> 0.072044211 | G28: =C28/ORÇAMENTO_EXECUTIVO!G$2 -> 258.43226
A29: SUPRAESTRUTURA | B29: 1486970.7 | C29: =ORÇAMENTO_EXECUTIVO!B5 -> 1352591 | D29: =C29-B29 -> -134379.74 | E29: =(D29/B29) -> -0.090371476 | F29: =C29/$C$43 -> 0.1940415 | G29: =C29/ORÇAMENTO_EXECUTIVO!G$2 -> 696.05294
A30: ALVENARIA | B30: 260075.2 | C30: =ORÇAMENTO_EXECUTIVO!B6 -> 261393.66 | D30: =C30-B30 -> 1318.4606 | E30: =(D30/B30) -> 0.0050695361 | F30: =C30/$C$43 -> 0.037499304 | G30: =C30/ORÇAMENTO_EXECUTIVO!G$2 -> 134.51504
A31: INSTALAÇÕES ELÉTRICAS, HIDRÁULICAS, GLP E PREVENTIVAS | B31: 634994.51 | C31: =ORÇAMENTO_EXECUTIVO!B7 -> 641270.51 | D31: =C31-B31 -> 6276 | E31: =(D31/B31) -> 0.00988355 | F31: =C31/$C$43 -> 0.091996102 | G31: =C31/ORÇAMENTO_EXECUTIVO!G$2 -> 330.00237
A32: EQUIPAMENTOS E SISTEMAS ESPECIAIS | B32: 331387.07 | C32: =ORÇAMENTO_EXECUTIVO!B8 -> 323614.15 | D32: =C32-B32 -> -7772.92 | E32: =(D32/B32) -> -0.023455713 | F32: =C32/$C$43 -> 0.0464254 | G32: =C32/ORÇAMENTO_EXECUTIVO!G$2 -> 166.53415
A33: IMPERMEABILIZAÇÃO | B33: 132506.86 | C33: =ORÇAMENTO_EXECUTIVO!B9 -> 175140.61 | D33: =C33-B33 -> 42633.748 | E33: =(D33/B33) -> 0.32174748 | F33: =C33/$C$43 -> 0.025125517 | G33: =C33/ORÇAMENTO_EXECUTIVO!G$2 -> 90.128606
A34: REVESTIMENTOS INTERNOS EM PAREDE | B34: 377413.3 | C34: =ORÇAMENTO_EXECUTIVO!B10 -> 397235.17 | D34: =C34-B34 -> 19821.878 | E34: =(D34/B34) -> 0.052520348 | F34: =C34/$C$43 -> 0.056987008 | G34: =C34/ORÇAMENTO_EXECUTIVO!G$2 -> 204.42005
A35: REVESTIMENTOS E ACABAMENTOS INTERNOS EM TETO | B35: 103795.89 | C35: =ORÇAMENTO_EXECUTIVO!B11 -> 128940.66 | D35: =C35-B35 -> 25144.771 | E35: =(D35/B35) -> 0.24225209 | F35: =C35/$C$43 -> 0.018497713 | G35: =C35/ORÇAMENTO_EXECUTIVO!G$2 -> 66.353781
A36: PISOS E PAVIMENTAÇÕES | B36: 436046.39 | C36: =ORÇAMENTO_EXECUTIVO!B12 -> 446389.88 | D36: =C36-B36 -> 10343.493 | E36: =(D36/B36) -> 0.023721083 | F36: =C36/$C$43 -> 0.064038698 | G36: =C36/ORÇAMENTO_EXECUTIVO!G$2 -> 229.71541
A37: PINTURA INTERNA | B37: 268226.5 | C37: =ORÇAMENTO_EXECUTIVO!B13 -> 303208.12 | D37: =C37-B37 -> 34981.625 | E37: =(D37/B37) -> 0.13041823 | F37: =C37/$C$43 -> 0.04349797 | G37: =C37/ORÇAMENTO_EXECUTIVO!G$2 -> 156.03306
... A42: IMPREVISTOS E CONTINGENCIAS | B42: 148661.5 | C42: =ORÇAMENTO_EXECUTIVO!B18 -> 139412.54 | D42: =C42-B42 -> -9248.9616 | E42: =(D42/B42) -> -0.062214908 | F42: =C42/$C$43 -> 0.02 | G42: =C42/ORÇAMENTO_EXECUTIVO!G$2 -> 71.742686
A43: TOTAL | B43: 7433075.1 | C43: =SUM(C26:C42) -> 6970627 | D43: =C43-B43 -> -462448.08 | E43: =(D43/B43) -> -0.062214908 | F43: 1 | G43: =SUM(G26:G42) -> 3587.1343
A44: CUB/SC | B44: 2758.46 | C44: 2758.46 | F44: 45413 | G44: =ROUNDUP(+G43/C44,2) & " CUB" -> 1,31 CUB

Sheet ANÁLISE_CUSTOS
A1: ETAPA | B1: OBRA | D1: OBRA SIMILAR | G1: =ORÇAMENTO_EXECUTIVO!$G$2 -> 1943.23 | H1: =G10*G1 -> 19682.211 | I1: =CÁLCULO_MÉDIAS!L6 -> MÉDIAS
B2: VALOR | C2: VALOR / m² | D2: VALOR / m² | I2: =CÁLCULO_MÉDIAS!L7 -> MÍNIMA | J2: =CÁLCULO_MÉDIAS!M7 -> MÁXIMA
A3: =ORÇAMENTO_EXECUTIVO!A2 -> GERENCIAMENTO TÉCNICO E ADMINISTRATIVO | B3: =ORÇAMENTO_EXECUTIVO!B2 -> 728402.37 | C3: =ORÇAMENTO_EXECUTIVO!D2 -> 374.84105 | D3: =FIXED(CÁLCULO_MÉDIAS!L8,2,FALSE)&" "&"-"&FIXED(CÁLCULO_MÉDIAS!M8,2,FALSE) -> 510,00 -550,00 | E3: {=IFERROR(_xlfn.IFS(F3>J3,"Maior",F3<I3,"Menor"),"ok")} -> Menor | F3: =ANÁLISE_CUSTOS!C3 -> 374.84105 | G3: {=_xlfn.IFS(E3="Maior",F3-J3,E3="Menor",F3-I3,E3="ok","")} -> -135.15895 | H3: Indorporação (sem fica 525/m²) | I3: =CÁLCULO_MÉDIAS!L8 -> 510 | J3: =CÁLCULO_MÉDIAS!M8 -> 550 | L3: Estudos e Projetos está em uma média de 2% do Custo no Caso de Incorporação somente ele está com 3,43% Elevando a Média/m² - Referência de incorporação de obras similares está em torno de 0,14% Custo da obra.
A4: =ORÇAMENTO_EXECUTIVO!A3 -> MOVIMENTAÇÃO DE TERRA | B4: =ORÇAMENTO_EXECUTIVO!B3 -> 145568.65 | C4: =ORÇAMENTO_EXECUTIVO!D3 -> 74.910662 | D4: =FIXED(CÁLCULO_MÉDIAS!L9,2,FALSE)&" "&"-"&FIXED(CÁLCULO_MÉDIAS!M9,2,FALSE) -> 16,00 -28,00 | E4: {=IFERROR(_xlfn.IFS(F4>J4,"Maior",F4<I4,"Menor"),"ok")} -> Maior | F4: =ANÁLISE_CUSTOS!C4 -> 74.910662 | G4: {=_xlfn.IFS(E4="Maior",F4-J4,E4="Menor",F4-I4,E4="ok","")} -> 46.910662 | H4: ok | I4: =CÁLCULO_MÉDIAS!L9 -> 16 | J4: =CÁLCULO_MÉDIAS!M9 -> 28
A5: =ORÇAMENTO_EXECUTIVO!A4 -> INFRAESTRUTURA | B5: =ORÇAMENTO_EXECUTIVO!B4 -> 502193.32 | C5: =ORÇAMENTO_EXECUTIVO!D4 -> 258.43226 | D5: =FIXED(CÁLCULO_MÉDIAS!L10,2,FALSE)&" "&"-"&FIXED(CÁLCULO_MÉDIAS!M10,2,FALSE) -> 160,00 -230,00 | E5: {=IFERROR(_xlfn.IFS(F5>J5,"Maior",F5<I5,"Menor"),"ok")} -> Maior | F5: =ANÁLISE_CUSTOS!C5 -> 258.43226 | G5: {=_xlfn.IFS(E5="Maior",F5-J5,E5="Menor",F5-I5,E5="ok","")} -> 28.432261 | H5: ok | I5: =CÁLCULO_MÉDIAS!L10 -> 160 | J5: =CÁLCULO_MÉDIAS!M10 -> 230
A6: =ORÇAMENTO_EXECUTIVO!A5 -> SUPRAESTRUTURA | B6: =ORÇAMENTO_EXECUTIVO!B5 -> 1352591 | C6: =ORÇAMENTO_EXECUTIVO!D5 -> 696.05294 | D6: =FIXED(CÁLCULO_MÉDIAS!L11,2,FALSE)&" "&"-"&FIXED(CÁLCULO_MÉDIAS!M11,2,FALSE) -> 610,00 -770,00 | E6: {=IFERROR(_xlfn.IFS(F6>J6,"Maior",F6<I6,"Menor"),"ok")} -> ok | F6: =ANÁLISE_CUSTOS!C6 -> 696.05294 | G6: {=_xlfn.IFS(E6="Maior",F6-J6,E6="Menor",F6-I6,E6="ok","")} | H6: ok | I6: =CÁLCULO_MÉDIAS!L11 -> 610 | J6: =CÁLCULO_MÉDIAS!M11 -> 770
A7: =ORÇAMENTO_EXECUTIVO!A6 -> ALVENARIA | B7: =ORÇAMENTO_EXECUTIVO!B6 -> 261393.66 | C7: =ORÇAMENTO_EXECUTIVO!D6 -> 134.51504 | D7: =FIXED(CÁLCULO_MÉDIAS!L12,2,FALSE)&" "&"-"&FIXED(CÁLCULO_MÉDIAS!M12,2,FALSE) -> 115,00 -135,00 | E7: {=IFERROR(_xlfn.IFS(F7>J7,"Maior",F7<I7,"Menor"),"ok")} -> ok | F7: =ANÁLISE_CUSTOS!C7 -> 134.51504 | G7: {=_xlfn.IFS(E7="Maior",F7-J7,E7="Menor",F7-I7,E7="ok","")} | H7: ok | I7: =CÁLCULO_MÉDIAS!L12 -> 115 | J7: =CÁLCULO_MÉDIAS!M12 -> 135
A8: =ORÇAMENTO_EXECUTIVO!A7 -> INSTALAÇÕES ELÉTRICAS, HIDRÁULICAS, GLP E PREVENTIVAS | B8: =ORÇAMENTO_EXECUTIVO!B7 -> 641270.51 | C8: =ORÇAMENTO_EXECUTIVO!D7 -> 330.00237 | D8: =FIXED(CÁLCULO_MÉDIAS!L13,2,FALSE)&" "&"-"&FIXED(CÁLCULO_MÉDIAS!M13,2,FALSE) -> 300,00 -330,00 | E8: {=IFERROR(_xlfn.IFS(F8>J8,"Maior",F8<I8,"Menor"),"ok")} -> Maior | F8: =ANÁLISE_CUSTOS!C8 -> 330.00237 | G8: {=_xlfn.IFS(E8="Maior",F8-J8,E8="Menor",F8-I8,E8="ok","")} -> 0.0023736292 | H8: ok | I8: =CÁLCULO_MÉDIAS!L13 -> 300 | J8: =CÁLCULO_MÉDIAS!M13 -> 330
A9: =ORÇAMENTO_EXECUTIVO!A8 -> EQUIPAMENTOS E SISTEMAS ESPECIAIS | B9: =ORÇAMENTO_EXECUTIVO!B8 -> 323614.15 | C9: =ORÇAMENTO_EXECUTIVO!D8 -> 166.53415 | D9: =FIXED(CÁLCULO_MÉDIAS!L14,2,FALSE)&" "&"-"&FIXED(CÁLCULO_MÉDIAS!M14,2,FALSE) -> 170,00 -210,00 | E9: {=IFERROR(_xlfn.IFS(F9>J9,"Maior",F9<I9,"Menor"),"ok")} -> Menor | F9: =ANÁLISE_CUSTOS!C9 -> 166.53415 | G9: {=_xlfn.IFS(E9="Maior",F9-J9,E9="Menor",F9-I9,E9="ok","")} -> -3.4658532 | H9: ok | I9: =CÁLCULO_MÉDIAS!L14 -> 170 | J9: =CÁLCULO_MÉDIAS!M14 -> 210 | L9: Obras referência tem em média 2 Elevadores no empreendimento, Na obra do Acácias tem 1 Elevador
A10: =ORÇAMENTO_EXECUTIVO!A9 -> IMPERMEABILIZAÇÃO | B10: =ORÇAMENTO_EXECUTIVO!B9 -> 175140.61 | C10: =ORÇAMENTO_EXECUTIVO!D9 -> 90.128606 | D10: =FIXED(CÁLCULO_MÉDIAS!L15,2,FALSE)&" "&"-"&FIXED(CÁLCULO_MÉDIAS!M15,2,FALSE) -> 50,00 -80,00 | E10: {=IFERROR(_xlfn.IFS(F10>J10,"Maior",F10<I10,"Menor"),"ok")} -> Maior | F10: =ANÁLISE_CUSTOS!C10 -> 90.128606 | G10: {=_xlfn.IFS(E10="Maior",F10-J10,E10="Menor",F10-I10,E10="ok","")} -> 10.128606 | H10: ok | I10: =CÁLCULO_MÉDIAS!L15 -> 50 | J10: =CÁLCULO_MÉDIAS!M15 -> 80
A11: REVESTIMENTOS INTERNOS EM PISO E PAREDE | B11: =[1]Resumo_Parede!$K$1 -> 399462.75 | C11: =B11/$G$1 -> 205.56637 | D11: =FIXED(CÁLCULO_MÉDIAS!L16,2,FALSE)&" "&"-"&FIXED(CÁLCULO_MÉDIAS!M16,2,FALSE) -> 160,00 -200,00 | E11: {=IFERROR(_xlfn.IFS(F11>J11,"Maior",F11<I11,"Menor"),"ok")} -> Maior | F11: =ANÁLISE_CUSTOS!C11 -> 205.56637 | G11: {=_xlfn.IFS(E11="Maior",F11-J11,E11="Menor",F11-I11,E11="ok","")} -> 5.5663746 | H11: ok | I11: =CÁLCULO_MÉDIAS!L16 -> 160 | J11: =CÁLCULO_MÉDIAS!M16 -> 200
A12: =ORÇAMENTO_EXECUTIVO!A11 -> REVESTIMENTOS E ACABAMENTOS INTERNOS EM TETO | B12: =ORÇAMENTO_EXECUTIVO!B11 -> 128940.66 | C12: =ORÇAMENTO_EXECUTIVO!D11 -> 66.353781 | D12: =FIXED(CÁLCULO_MÉDIAS!L17,2,FALSE)&" "&"-"&FIXED(CÁLCULO_MÉDIAS!M17,2,FALSE) -> 40,00 -70,00 | E12: {=IFERROR(_xlfn.IFS(F12>J12,"Maior",F12<I12,"Menor"),"ok")} -> ok | F12: =ANÁLISE_CUSTOS!C12 -> 66.353781 | G12: {=_xlfn.IFS(E12="Maior",F12-J12,E12="Menor",F12-I12,E12="ok","")} | H12: ok | I12: =CÁLCULO_MÉDIAS!L17 -> 40 | J12: =CÁLCULO_MÉDIAS!M17 -> 70
A13: ACABAMENTOS EM PISO E PAREDE | B13: =[1]Resumo_Parede!$K$2 -> 444162.31 | C13: =B13/$G$1 -> 228.56909 | D13: =FIXED(CÁLCULO_MÉDIAS!L18,2,FALSE)&" "&"-"&FIXED(CÁLCULO_MÉDIAS!M18,2,FALSE) -> 140,00 -230,00 | E13: {=IFERROR(_xlfn.IFS(F13>J13,"Maior",F13<I13,"Menor"),"ok")} -> ok | F13: =ANÁLISE_CUSTOS!C13 -> 228.56909 | G13: {=_xlfn.IFS(E13="Maior",F13-J13,E13="Menor",F13-I13,E13="ok","")} | H13: ok | I13: =CÁLCULO_MÉDIAS!L18 -> 140 | J13: =CÁLCULO_MÉDIAS!M18 -> 230
A14: =ORÇAMENTO_EXECUTIVO!A13 -> PINTURA INTERNA | B14: =ORÇAMENTO_EXECUTIVO!B13 -> 303208.12 | C14: =ORÇAMENTO_EXECUTIVO!D13 -> 156.03306 | D14: =FIXED(CÁLCULO_MÉDIAS!L19,2,FALSE)&" "&"-"&FIXED(CÁLCULO_MÉDIAS!M19,2,FALSE) -> 130,00 -160,00 | E14: {=IFERROR(_xlfn.IFS(F14>J14,"Maior",F14<I14,"Menor"),"ok")} -> ok | F14: =ANÁLISE_CUSTOS!C14 -> 156.03306 | G14: {=_xlfn.IFS(E14="Maior",F14-J14,E14="Menor",F14-I14,E14="ok","")} | H14: ok | I14: =CÁLCULO_MÉDIAS!L19 -> 130 | J14: =CÁLCULO_MÉDIAS!M19 -> 160
A15: =ORÇAMENTO_EXECUTIVO!A14 -> ESQUADRIAS, VIDROS E FERRAGENS | B15: =ORÇAMENTO_EXECUTIVO!B14 -> 578274.83 | C15: =ORÇAMENTO_EXECUTIVO!D14 -> 297.58435 | D15: =FIXED(CÁLCULO_MÉDIAS!L20,2,FALSE)&" "&"-"&FIXED(CÁLCULO_MÉDIAS!M20,2,FALSE) -> 280,00 -540,00 | E15: {=IFERROR(_xlfn.IFS(F15>J15,"Maior",F15<I15,"Menor"),"ok")} -> ok | F15: =ANÁLISE_CUSTOS!C15 -> 297.58435 | G15: {=_xlfn.IFS(E15="Maior",F15-J15,E15="Menor",F15-I15,E15="ok","")} | H15: ok | I15: =CÁLCULO_MÉDIAS!L20 -> 280 | J15: =CÁLCULO_MÉDIAS!M20 -> 540
A16: =ORÇAMENTO_EXECUTIVO!A15 -> COBERTURA | B16: =ORÇAMENTO_EXECUTIVO!B15 -> 38853.541 | C16: =ORÇAMENTO_EXECUTIVO!D15 -> 19.994309 | D16: =FIXED(CÁLCULO_MÉDIAS!L21,2,FALSE)&" "&"-"&FIXED(CÁLCULO_MÉDIAS!M21,2,FALSE) -> 14,00 -20,00 | E16: {=IFERROR(_xlfn.IFS(F16>J16,"Maior",F16<I16,"Menor"),"ok")} -> ok | F16: =ANÁLISE_CUSTOS!C16 -> 19.994309 | G16: {=_xlfn.IFS(E16="Maior",F16-J16,E16="Menor",F16-I16,E16="ok","")} | H16: ok | I16: =CÁLCULO_MÉDIAS!L21 -> 14 | J16: =CÁLCULO_MÉDIAS!M21 -> 20
A17: =ORÇAMENTO_EXECUTIVO!A16 -> REVESTIMENTOS E ACABAMENTOS DE FACHADA | B17: =ORÇAMENTO_EXECUTIVO!B16 -> 365385.57 | C17: =ORÇAMENTO_EXECUTIVO!D16 -> 188.03002 | D17: =FIXED(CÁLCULO_MÉDIAS!L22,2,FALSE)&" "&"-"&FIXED(CÁLCULO_MÉDIAS!M22,2,FALSE) -> 140,00 -190,00 | E17: {=IFERROR(_xlfn.IFS(F17>J17,"Maior",F17<I17,"Menor"),"ok")} -> ok | F17: =ANÁLISE_CUSTOS!C17 -> 188.03002 | G17: {=_xlfn.IFS(E17="Maior",F17-J17,E17="Menor",F17-I17,E17="ok","")} | H17: ok | I17: =CÁLCULO_MÉDIAS!L22 -> 140 | J17: =CÁLCULO_MÉDIAS!M22 -> 190
A18: =ORÇAMENTO_EXECUTIVO!A17 -> SERVIÇOS COMPLEMENTARES | B18: =ORÇAMENTO_EXECUTIVO!B17+ORÇAMENTO_EXECUTIVO!B18 -> 582165.03 | C18: =ORÇAMENTO_EXECUTIVO!D17+ORÇAMENTO_EXECUTIVO!D18 -> 299.58627 | D18: =FIXED(CÁLCULO_MÉDIAS!L23,2,FALSE)&" "&"-"&FIXED(CÁLCULO_MÉDIAS!M23,2,FALSE) -> 120,00 -230,00 | E18: {=IFERROR(_xlfn.IFS(F18>J18,"Maior",F18<I18,"Menor"),"ok")} -> Maior | F18: =ANÁLISE_CUSTOS!C18 -> 299.58627 | G18: {=_xlfn.IFS(E18="Maior",F18-J18,E18="Menor",F18-I18,E18="ok","")} -> 69.586271 | H18: ok | I18: =CÁLCULO_MÉDIAS!L23 -> 120 | J18: =CÁLCULO_MÉDIAS!M23 -> 230
A19: TOTAL | B19: =SUM(B3:B18) -> 6970627 | C19: =SUM(C3:C18) -> 3587.1343 | D19: =FIXED(CÁLCULO_MÉDIAS!L24,2,FALSE)&" "&"-"&FIXED(CÁLCULO_MÉDIAS!M24,2,FALSE) -> 2.955,00 -3.973,00 | I19: =CÁLCULO_MÉDIAS!L24 -> 2955 | J19: =CÁLCULO_MÉDIAS!M24 -> 3973
C20: =B19/38 -> 183437.55 | D20: 38
C21: =B19/(D21*D20) -> 7331.6368 | D21: 25.02
C22: =B19/G1 -> 3587.1343
B23: 2007.57
B24: 2461.35
B25: =B24/B23 -> 1.2260345
C28: 1.1023
A30: 900,00 - 1100 | B30: 900
A31: 25,00 - 30,00 | B31: 25
A32: 15,00 - 22,00 | B32: 15
A33: 150,00 - 200,00 | B33: 150
A34: 440,00 - 510,00 | B34: 440
A35: -
A36: 55,00 - 70,00 | B36: 55
A37: 170,00 - 200,00 | B37: 170
A38: 165,00 - 230,00 | B38: 165
A39: 40,00 - 70,00 | B39: 40
A40: 55,00 - 77,00 | B40: 55
A41: 35,00 - 50,00 | B41: 35
A42: 130,00 - 175,00 | B42: 130
A43: 35,00 - 65,00 | B43: 35
...

Sheet CÁLCULO_MÉDIAS
C3: DATA BASE | D3: 45139 | E3: DATA BASE | F3: 44682 | G3: DATA BASE | H3: 44927 | I3: DATA BASE | J3: 45017
C4: CUB/SC | D4: 2750.52 | E4: CUB | F4: 2470.83 | G4: CUB | H4: 2651.17 | I4: CUB/SC | J4: 2680.84
C6: Marine | E6: EZE - CANTO GRANDE | G6: NM - SUIÇA HOME | I6: SAK-AUS | L6: MÉDIAS
C7: VALOR / M2 | D7: INDEXADO | E7: VALOR / M2 | F7: INDEXADO | G7: VALOR / M2 | H7: INDEXADO | I7: VALOR / M2 | J7: INDEXADO | L7: MÍNIMA | M7: MÁXIMA
B8: GERENCIAMENTO TECNICO E ADMINISTRATIVO | C8: 521.7077 | D8: =ORÇAMENTO_EXECUTIVO!$B$20/CÁLCULO_MÉDIAS!D$4*C8 -> 523.21372 | E8: 428.3451 | F8: =ORÇAMENTO_EXECUTIVO!$B$20/CÁLCULO_MÉDIAS!F$4*E8 -> 478.20887 | G8: 507.78 | H8: =ORÇAMENTO_EXECUTIVO!$B$20/CÁLCULO_MÉDIAS!H$4*G8 -> 528.32931 | I8: 540.45029 | J8: =ORÇAMENTO_EXECUTIVO!$B$20/CÁLCULO_MÉDIAS!J$4*I8 -> 556.09828 | L8: 510 | M8: 550
B9: MOVIMENTAÇÃO DE TERRA | C9: 16.838659 | D9: =ORÇAMENTO_EXECUTIVO!$B$20/CÁLCULO_MÉDIAS!D$4*C9 -> 16.887267 | E9: 2.423133 | F9: =ORÇAMENTO_EXECUTIVO!$B$20/CÁLCULO_MÉDIAS!F$4*E9 -> 2.7052106 | G9: 27.52 | H9: =ORÇAMENTO_EXECUTIVO!$B$20/CÁLCULO_MÉDIAS!H$4*G9 -> 28.633705 | I9: 11.40893 | J9: =ORÇAMENTO_EXECUTIVO!$B$20/CÁLCULO_MÉDIAS!J$4*I9 -> 11.739259 | L9: 16 | M9: 28
B10: INFRAESTRUTURA | C10: 343.98464 | D10: =ORÇAMENTO_EXECUTIVO!$B$20/CÁLCULO_MÉDIAS!D$4*C10 -> 344.97763 | E10: 146.44487 | F10: =ORÇAMENTO_EXECUTIVO!$B$20/CÁLCULO_MÉDIAS!F$4*E10 -> 163.49256 | G10: 176.17907 | H10: =ORÇAMENTO_EXECUTIVO!$B$20/CÁLCULO_MÉDIAS!H$4*G10 -> 183.30884 | I10: 230.92547 | J10: =ORÇAMENTO_EXECUTIVO!$B$20/CÁLCULO_MÉDIAS!J$4*I10 -> 237.6116 | L10: 160 | M10: 230
B11: SUPRAESTRUTURA | C11: 484.52747 | D11: =ORÇAMENTO_EXECUTIVO!$B$20/CÁLCULO_MÉDIAS!D$4*C11 -> 485.92617 | E11: 506.89276 | F11: =ORÇAMENTO_EXECUTIVO!$B$20/CÁLCULO_MÉDIAS!F$4*E11 -> 565.90029 | G11: 601.70734 | H11: =ORÇAMENTO_EXECUTIVO!$B$20/CÁLCULO_MÉDIAS!H$4*G11 -> 626.05779 | I11: 769.34732 | J11: =ORÇAMENTO_EXECUTIVO!$B$20/CÁLCULO_MÉDIAS!J$4*I11 -> 791.62271 | L11: 610 | M11: 770
B12: ALVENARIA | C12: 117.11123 | D12: =ORÇAMENTO_EXECUTIVO!$B$20/CÁLCULO_MÉDIAS!D$4*C12 -> 117.4493 | E12: 125.20191 | F12: =ORÇAMENTO_EXECUTIVO!$B$20/CÁLCULO_MÉDIAS!F$4*E12 -> 139.7767 | G12: 128.62893 | H12: =ORÇAMENTO_EXECUTIVO!$B$20/CÁLCULO_MÉDIAS!H$4*G12 -> 133.83441 | I12: 125.31752 | J12: =ORÇAMENTO_EXECUTIVO!$B$20/CÁLCULO_MÉDIAS!J$4*I12 -> 128.94591 | L12: 115 | M12: 135
B13: INSTALAÇÕES ELÉTRICAS, HIDRÁULICAS, GLP E PREVENTIVAS | C13: 305.0752 | D13: =ORÇAMENTO_EXECUTIVO!$B$20/CÁLCULO_MÉDIAS!D$4*C13 -> 305.95587 | E13: 367.37491 | F13: =ORÇAMENTO_EXECUTIVO!$B$20/CÁLCULO_MÉDIAS!F$4*E13 -> 410.14113 | G13: 321.44125 | H13: =ORÇAMENTO_EXECUTIVO!$B$20/CÁLCULO_MÉDIAS!H$4*G13 -> 334.44963 | I13: 320.13388 | J13: =ORÇAMENTO_EXECUTIVO!$B$20/CÁLCULO_MÉDIAS!J$4*I13 -> 329.40291 | L13: 300 | M13: 330
B14: EQUIPAMENTOS E SISTEMAS ESPECIAIS | C14: 171.7823 | D14: =ORÇAMENTO_EXECUTIVO!$B$20/CÁLCULO_MÉDIAS!D$4*C14 -> 172.27819 | E14: 292.94778 | F14: =ORÇAMENTO_EXECUTIVO!$B$20/CÁLCULO_MÉDIAS!F$4*E14 -> 327.04992 | G14: 177.07278 | H14: =ORÇAMENTO_EXECUTIVO!$B$20/CÁLCULO_MÉDIAS!H$4*G14 -> 184.23873 | I14: 212.11556 | J14: =ORÇAMENTO_EXECUTIVO!$B$20/CÁLCULO_MÉDIAS!J$4*I14 -> 218.25707 | L14: 170 | M14: 210
B15: IMPERMEABILIZAÇÃO | C15: 66.939128 | D15: =ORÇAMENTO_EXECUTIVO!$B$20/CÁLCULO_MÉDIAS!D$4*C15 -> 67.132363 | E15: 49.030443 | F15: =ORÇAMENTO_EXECUTIVO!$B$20/CÁLCULO_MÉDIAS!F$4*E15 -> 54.73809 | G15: 128.04192 | H15: =ORÇAMENTO_EXECUTIVO!$B$20/CÁLCULO_MÉDIAS!H$4*G15 -> 133.22364 | I15: 61.388461 | J15: =ORÇAMENTO_EXECUTIVO!$B$20/CÁLCULO_MÉDIAS!J$4*I15 -> 63.165878 | L15: 50 | M15: 80
B16: REVESTIMENTOS INTERNOS EM PISO E PAREDE | C16: 163.27144 | D16: =ORÇAMENTO_EXECUTIVO!$B$20/CÁLCULO_MÉDIAS!D$4*C16 -> 163.74276 | E16: 179.25884 | F16: =ORÇAMENTO_EXECUTIVO!$B$20/CÁLCULO_MÉDIAS!F$4*E16 -> 200.12642 | G16: 192.52394 | H16: =ORÇAMENTO_EXECUTIVO!$B$20/CÁLCULO_MÉDIAS!H$4*G16 -> 200.31517 | I16: 166.08162 | J16: =ORÇAMENTO_EXECUTIVO!$B$20/CÁLCULO_MÉDIAS!J$4*I16 -> 170.89029 | L16: 160 | M16: 200
B17: REVESTIMENTOS E ACABAMENTOS INTERNOS EM TETO | C17: 41.996743 | D17: =ORÇAMENTO_EXECUTIVO!$B$20/CÁLCULO_MÉDIAS!D$4*C17 -> 42.117976 | E17: 114.72652 | F17: =ORÇAMENTO_EXECUTIVO!$B$20/CÁLCULO_MÉDIAS!F$4*E17 -> 128.08187 | G17: 66.141025 | H17: =ORÇAMENTO_EXECUTIVO!$B$20/CÁLCULO_MÉDIAS!H$4*G17 -> 68.817681 | I17: 70.692446 | J17: =ORÇAMENTO_EXECUTIVO!$B$20/CÁLCULO_MÉDIAS!J$4*I17 -> 72.739247 | L17: 40 | M17: 70
B18: ACABAMENTOS EM PISO E PAREDE | C18: 142.74532 | D18: =ORÇAMENTO_EXECUTIVO!$B$20/CÁLCULO_MÉDIAS!D$4*C18 -> 143.15739 | E18: 185.67447 | F18: =ORÇAMENTO_EXECUTIVO!$B$20/CÁLCULO_MÉDIAS!F$4*E18 -> 207.28888 | G18: 187.43824 | H18: =ORÇAMENTO_EXECUTIVO!$B$20/CÁLCULO_MÉDIAS!H$4*G18 -> 195.02367 | I18: 233.48763 | J18: =ORÇAMENTO_EXECUTIVO!$B$20/CÁLCULO_MÉDIAS!J$4*I18 -> 240.24794 | L18: 140 | M18: 230
B19: PINTURA INTERNA | C19: 142.71918 | D19: =ORÇAMENTO_EXECUTIVO!$B$20/CÁLCULO_MÉDIAS!D$4*C19 -> 143.13117 | E19: 147.81829 | F19: =ORÇAMENTO_EXECUTIVO!$B$20/CÁLCULO_MÉDIAS!F$4*E19 -> 165.02585 | G19: 135.47557 | H19: =ORÇAMENTO_EXECUTIVO!$B$20/CÁLCULO_MÉDIAS!H$4*G19 -> 140.95812 | I19: 147.78933 | J19: =ORÇAMENTO_EXECUTIVO!$B$20/CÁLCULO_MÉDIAS!J$4*I19 -> 152.06837 | L19: 130 | M19: 160
... B23: SERVIÇOS COMPLEMENTARES | C23: 241.24936 | D23: =ORÇAMENTO_EXECUTIVO!$B$20/CÁLCULO_MÉDIAS!D$4*C23 -> 241.94578 | E23: 222.14638 | F23: =ORÇAMENTO_EXECUTIVO!$B$20/CÁLCULO_MÉDIAS!F$4*E23 -> 248.0065 | G23: 81.265859 | H23: =ORÇAMENTO_EXECUTIVO!$B$20/CÁLCULO_MÉDIAS!H$4*G23 -> 84.554601 | I23: 249.08 | J23: =ORÇAMENTO_EXECUTIVO!$B$20/CÁLCULO_MÉDIAS!J$4*I23 -> 256.29177 | L23: 120 | M23: 230
B24: TOTAL | C24: =SUM(C8:C23) -> 3135.8856 | D24: =SUM(D8:D23) -> 3144.938 | E24: =SUM(E8:E23) -> 3580.102 | F24: =SUM(F8:F23) -> 3996.8627 | G24: =SUM(G8:G23) -> 3217.7697 | H24: =SUM(H8:H23) -> 3347.9894 | I24: =SUM(I8:I23) -> 3843.0093 | J24: =SUM(J8:J23) -> 3954.2783 | L24: =SUM(L8:L23) -> 2955 | M24: =SUM(M8:M23) -> 3973
