Workbook

Sheet PAINEL
A1: PAINEL DE CONTROLE
A4: Projeto: | B4: =DADOS_PROJETO!B2
A5: Área Construída: | B5: =DADOS_PROJETO!B6&" m²"
A6: Unidades: | B6: =DADOS_PROJETO!B7+DADOS_PROJETO!B8
A8: Custo Total: | B8: =CUSTOS_MACROGRUPO!G20
A9: Custo/m²: | B9: =CUSTOS_MACROGRUPO!G20/DADOS_PROJETO!B6
A10: Custo/Unidade: | B10: =CUSTOS_MACROGRUPO!G20/(DADOS_PROJETO!B7+DADOS_PROJETO!B8)
A12: CUB Atual: | B12: =DADOS_PROJETO!B19
A13: Fator CUB: | B13: =DADOS_PROJETO!B19/DADOS_PROJETO!B20
A15: Top 3 Macrogrupos:
A16: 1º | B16: =INDEX(CUSTOS_MACROGRUPO!B:B,MATCH(LARGE(CUSTOS_MACROGRUPO!H:H,1),CUSTOS_MACROGRUPO!H:H,0))&" ("&TEXT(LARGE(CUSTOS_MACROGRUPO!H:H,1),"0.0%")&")"
A17: 2º | B17: =INDEX(CUSTOS_MACROGRUPO!B:B,MATCH(LARGE(CUSTOS_MACROGRUPO!H:H,2),CUSTOS_MACROGRUPO!H:H,0))&" ("&TEXT(LARGE(CUSTOS_MACROGRUPO!H:H,2),"0.0%")&")"
A18: 3º | B18: =INDEX(CUSTOS_MACROGRUPO!B:B,MATCH(LARGE(CUSTOS_MACROGRUPO!H:H,3),CUSTOS_MACROGRUPO!H:H,0))&" ("&TEXT(LARGE(CUSTOS_MACROGRUPO!H:H,3),"0.0%")&")"

Sheet DADOS_PROJETO
A1: DADOS DO PROJETO
A2: Nome do Projeto | B2: Edifício Oxford — Mussi Empreendimentos
A3: Código | B3: OXFORD-MUSSI
A4: Cidade | B4: Itajaí/SC
A6: Área Construída (m²) | B6: 7500
A7: Unidades Residenciais | B7: 95
A8: Unidades Comerciais | B8: 2
A9: Número de Pavimentos | B9: 27
A10: Pavimentos Tipo | B10: 17
A11: Pavimentos Garagem | B11: 5
A12: Elevadores | B12: 2
A13: Vagas | B13: 136
A14: Área Terreno (m²) | B14: 1200
A15: Número de Subsolos | B15: 0
A17: Prazo (meses) | B17: 36
A19: CUB Atual (R$/m²) | B19: 3050
A20: CUB Base mar/2026 (R$/m²) | B20: 3050
A21: Data-base | B21: mar/2026

Sheet BRIEFING
A1: # | B1: Pergunta | C1: Resposta | D1: Macrogrupos Afetados
A2: Q1 | B2: Tipo de Fundação | C2: Hélice Contínua | D2: Infraestrutura
A3: Q2 | B3: Tipo de Laje | C3: Cubetas | D3: Supraestrutura
A4: Q3 | B4: Contenção | C4: Não | D4: Infraestrutura
A5: Q4 | B5: Subsolos | C5: 0 | D5: Mov. Terra, Infraestrutura, Impermeabilização
A6: Q5 | B6: Padrão | C6: Alto | D6: Rev. Int. Parede, Teto, Pisos, Pintura, Esquadrias, Fachada, Complementares
A7: Q6 | B7: Esquadria | C7: Pintura eletrostática | D7: Esquadrias
A8: Q7 | B8: Piso | C8: Porcelanato padrão | D8: Pisos
A9: Q8 | B9: Vedação | C9: Misto | D9: Alvenaria
A10: Q9 | B10: Forro | C10: Gesso liso | D10: Teto
A11: Q10 | B11: Fachada | C11: Misto | D11: Fachada
A12: Q11 | B12: MO Fachada | C12: Empreitada | D12: Fachada
... A26: Q25 | B26: Pressurização | C26: Sim | D26: Instalações

Sheet FATORES
A1: MATRIZ DE FATORES
A2: Macrogrupo | B2: Q1 | C2: Q2 | D2: Q3 | E2: Q4 | F2: Q5 | G2: Q6 | H2: Q7 | I2: Q8 | J2: Q9 | K2: Q10 | L2: Q11 | M2: Q12 | N2: Q13 | O2: Q14 | P2: Q15 | Q2: Q16 | R2: Q17 | S2: Q18 | T2: Q19 | U2: Q20 | V2: Q21 | W2: Q22 | X2: Q23 | Y2: Q24 | Z2: Q25 | AA2: Fator Briefing
A3: Gerenciamento | B3: =1 | C3: =1 | D3: =1 | E3: =1 | F3: =1 | G3: =1 | H3: =1 | I3: =1 | ... S3: =1 | T3: =IF(BRIEFING!$C$20="18",0.6,IF(BRIEFING!$C$20="24",0.75,IF(BRIEFING!$C$20="30",0.88,IF(BRIEFING!$C$20="36",1.0,IF(BRIEFING!$C$20="42",1.15,IF(BRIEFING!$C$20="48",1.3,1)))))) | U3: =IF(BRIEFING!$C$21="Interior SC",0.95,IF(BRIEFING!$C$21="Litoral SC",1.0,IF(BRIEFING!$C$21="Capital Floripa",1.05,IF(BRIEFING!$C$21="Litoral SP",1.15,IF(BRIEFING!$C$21="Capital SP-RJ",1.25,1))))) | V3: =1 | W3: =1 | X3: =1 | Y3: =1 | Z3: =1 | AA3: =PRODUCT(B3:Z3)
A4: Mov. Terra | B4: =1 | C4: =1 | D4: =1 | E4: =IF(BRIEFING!$C$5="0",1.0,IF(BRIEFING!$C$5="1",2.0,IF(BRIEFING!$C$5="2",3.5,IF(BRIEFING!$C$5="3+",5.0,1)))) | F4: =1 | G4: =1 | H4: =1 | I4: =1 | J4: =1 | K4: =1 | L4: =1 | M4: =1 | ... T4: =1 | U4: =IF(BRIEFING!$C$21="Interior SC",0.95,IF(BRIEFING!$C$21="Litoral SC",1.0,IF(BRIEFING!$C$21="Capital Floripa",1.05,IF(BRIEFING!$C$21="Litoral SP",1.15,IF(BRIEFING!$C$21="Capital SP-RJ",1.25,1))))) | V4: =1 | W4: =1 | X4: =1 | Y4: =1 | Z4: =1 | AA4: =PRODUCT(B4:Z4)
A5: Infraestrutura | B5: =IF(BRIEFING!$C$2="Hélice Contínua",1.0,IF(BRIEFING!$C$2="Estaca Franki",0.9,IF(BRIEFING!$C$2="Tubulão",1.15,IF(BRIEFING!$C$2="Sapata/Radier",0.75,IF(BRIEFING!$C$2="Estaca raiz",1.1,1))))) | C5: =1 | D5: =IF(BRIEFING!$C$4="Não",1.0,IF(BRIEFING!$C$4="Cortina de estacas",1.4,IF(BRIEFING!$C$4="Muro de arrimo",1.2,IF(BRIEFING!$C$4="Solo grampeado",1.3,IF(BRIEFING!$C$4="Tirantes",1.35,1))))) | E5: =IF(BRIEFING!$C$5="0",1.0,IF(BRIEFING!$C$5="1",1.2,IF(BRIEFING!$C$5="2",1.4,IF(BRIEFING!$C$5="3+",1.6,1)))) | F5: =1 | G5: =1 | H5: =1 | I5: =1 | J5: =1 | K5: =1 | L5: =1 | M5: =1 | ... T5: =1 | U5: =IF(BRIEFING!$C$21="Interior SC",0.95,IF(BRIEFING!$C$21="Litoral SC",1.0,IF(BRIEFING!$C$21="Capital Floripa",1.05,IF(BRIEFING!$C$21="Litoral SP",1.15,IF(BRIEFING!$C$21="Capital SP-RJ",1.25,1))))) | V5: =1 | W5: =1 | X5: =1 | Y5: =1 | Z5: =1 | AA5: =PRODUCT(B5:Z5)
A6: Supraestrutura | B6: =1 | C6: =IF(BRIEFING!$C$3="Cubetas",1.0,IF(BRIEFING!$C$3="Protendida",1.05,IF(BRIEFING!$C$3="Maciça",1.1,IF(BRIEFING!$C$3="Mista",1.03,IF(BRIEFING!$C$3="Treliçada",0.95,1))))) | D6: =1 | E6: =1 | F6: =1 | G6: =1 | H6: =1 | I6: =1 | J6: =1 | K6: =1 | ... T6: =1 | U6: =IF(BRIEFING!$C$21="Interior SC",0.95,IF(BRIEFING!$C$21="Litoral SC",1.0,IF(BRIEFING!$C$21="Capital Floripa",1.05,IF(BRIEFING!$C$21="Litoral SP",1.15,IF(BRIEFING!$C$21="Capital SP-RJ",1.25,1))))) | V6: =1 | W6: =1 | X6: =1 | Y6: =1 | Z6: =1 | AA6: =PRODUCT(B6:Z6)
A7: Alvenaria | B7: =1 | C7: =1 | D7: =1 | E7: =1 | F7: =1 | G7: =1 | H7: =1 | I7: =IF(BRIEFING!$C$9="Alvenaria",1.0,IF(BRIEFING!$C$9="Drywall",1.8,IF(BRIEFING!$C$9="Misto",1.3,1))) | J7: =1 | K7: =1 | L7: =1 | M7: =1 | N7: =1 | O7: =1 | P7: =1 | Q7: =1 | ... T7: =1 | U7: =IF(BRIEFING!$C$21="Interior SC",0.95,IF(BRIEFING!$C$21="Litoral SC",1.0,IF(BRIEFING!$C$21="Capital Floripa",1.05,IF(BRIEFING!$C$21="Litoral SP",1.15,IF(BRIEFING!$C$21="Capital SP-RJ",1.25,1))))) | V7: =1 | W7: =1 | X7: =1 | Y7: =1 | Z7: =1 | AA7: =PRODUCT(B7:Z7)
A8: Impermeabilização | B8: =1 | C8: =1 | D8: =1 | E8: =IF(BRIEFING!$C$5="0",1.0,IF(BRIEFING!$C$5="1",1.3,IF(BRIEFING!$C$5="2",1.6,IF(BRIEFING!$C$5="3+",1.9,1)))) | F8: =1 | G8: =1 | H8: =1 | I8: =1 | J8: =1 | K8: =1 | L8: =1 | M8: =1 | ... T8: =1 | U8: =IF(BRIEFING!$C$21="Interior SC",0.95,IF(BRIEFING!$C$21="Litoral SC",1.0,IF(BRIEFING!$C$21="Capital Floripa",1.05,IF(BRIEFING!$C$21="Litoral SP",1.15,IF(BRIEFING!$C$21="Capital SP-RJ",1.25,1))))) | V8: =1 | W8: =1 | X8: =1 | Y8: =1 | Z8: =1 | AA8: =PRODUCT(B8:Z8)
A9: Instalações | B9: =1 | C9: =1 | D9: =1 | E9: =1 | F9: =1 | G9: =1 | H9: =1 | I9: =1 | ... M9: =1 | N9: =IF(BRIEFING!$C$14="Gás individual",1.0,IF(BRIEFING!$C$14="Central",1.15,IF(BRIEFING!$C$14="Solar",1.2,IF(BRIEFING!$C$14="Bomba calor",1.25,IF(BRIEFING!$C$14="Sem",0.9,1))))) | O9: =1 | P9: =1 | Q9: =1 | R9: =1 | S9: =1 | T9: =1 | U9: =IF(BRIEFING!$C$21="Interior SC",0.95,IF(BRIEFING!$C$21="Litoral SC",1.0,IF(BRIEFING!$C$21="Capital Floripa",1.05,IF(BRIEFING!$C$21="Litoral SP",1.15,IF(BRIEFING!$C$21="Capital SP-RJ",1.25,1))))) | V9: =1 | W9: =1 | X9: =1 | Y9: =IF(BRIEFING!$C$25="Sim",1.05,IF(BRIEFING!$C$25="Não",1.0,1)) | Z9: =IF(BRIEFING!$C$26="Sim",1.08,IF(BRIEFING!$C$26="Não",1.0,1)) | AA9: =PRODUCT(B9:Z9)
A10: Sist. Especiais | B10: =1 | C10: =1 | D10: =1 | E10: =1 | F10: =1 | G10: =1 | H10: =1 | I10: =1 | ... N10: =1 | O10: =IF(BRIEFING!$C$15="Mínimo",0.85,IF(BRIEFING!$C$15="Básico",1.0,IF(BRIEFING!$C$15="Completo",1.3,IF(BRIEFING!$C$15="Premium",1.6,1)))) | P10: =IF(BRIEFING!$C$16="Sem",1.0,IF(BRIEFING!$C$16="Solar comum",1.1,IF(BRIEFING!$C$16="Solar completo",1.2,1))) | Q10: =1 | R10: =1 | S10: =1 | T10: =1 | U10: =IF(BRIEFING!$C$21="Interior SC",0.95,IF(BRIEFING!$C$21="Litoral SC",1.0,IF(BRIEFING!$C$21="Capital Floripa",1.05,IF(BRIEFING!$C$21="Litoral SP",1.15,IF(BRIEFING!$C$21="Capital SP-RJ",1.25,1))))) | V10: =IF(BRIEFING!$C$22="Sim",1.15,IF(BRIEFING!$C$22="Não",1.0,1)) | W10: =IF(BRIEFING!$C$23="Sim",1.1,IF(BRIEFING!$C$23="Não",1.0,1)) | X10: =IF(BRIEFING!$C$24="Sim",1.1,IF(BRIEFING!$C$24="Não",1.0,1)) | Y10: =1 | Z10: =1 | AA10: =PRODUCT(B10:Z10)
A11: Climatização | B11: =1 | C11: =1 | D11: =1 | E11: =1 | F11: =1 | G11: =1 | H11: =1 | I11: =1 | ... T11: =1 | U11: =IF(BRIEFING!$C$21="Interior SC",0.95,IF(BRIEFING!$C$21="Litoral SC",1.0,IF(BRIEFING!$C$21="Capital Floripa",1.05,IF(BRIEFING!$C$21="Litoral SP",1.15,IF(BRIEFING!$C$21="Capital SP-RJ",1.25,1))))) | V11: =1 | W11: =1 | X11: =1 | Y11: =1 | Z11: =1 | AA11: =PRODUCT(B11:Z11)
A12: Rev. Int. Parede | B12: =1 | C12: =1 | D12: =1 | E12: =1 | F12: =IF(BRIEFING!$C$6="Econômico",0.65,IF(BRIEFING!$C$6="Standard",0.8,IF(BRIEFING!$C$6="Alto",1.0,IF(BRIEFING!$C$6="Super Alto",1.2,IF(BRIEFING!$C$6="Luxo",1.45,1))))) | G12: =1 | H12: =1 | I12: =1 | J12: =1 | K12: =1 | L12: =1 | M12: =1 | N12: =1 | ... T12: =1 | U12: =IF(BRIEFING!$C$21="Interior SC",0.95,IF(BRIEFING!$C$21="Litoral SC",1.0,IF(BRIEFING!$C$21="Capital Floripa",1.05,IF(BRIEFING!$C$21="Litoral SP",1.15,IF(BRIEFING!$C$21="Capital SP-RJ",1.25,1))))) | V12: =1 | W12: =1 | X12: =1 | Y12: =1 | Z12: =1 | AA12: =PRODUCT(B12:Z12)
A13: Teto | B13: =1 | C13: =1 | D13: =1 | E13: =1 | F13: =IF(BRIEFING!$C$6="Econômico",0.7,IF(BRIEFING!$C$6="Standard",0.8,IF(BRIEFING!$C$6="Alto",1.0,IF(BRIEFING!$C$6="Super Alto",1.2,IF(BRIEFING!$C$6="Luxo",1.4,1))))) | G13: =1 | H13: =1 | I13: =1 | J13: =IF(BRIEFING!$C$10="Estucamento",0.8,IF(BRIEFING!$C$10="Gesso liso",1.0,IF(BRIEFING!$C$10="Gesso negativo",1.15,IF(BRIEFING!$C$10="Gesso sanca",1.2,IF(BRIEFING!$C$10="Mineral",1.1,1))))) | K13: =1 | L13: =1 | M13: =1 | N13: =1 | O13: =1 | P13: =1 | Q13: =1 | R13: =1 | ... T13: =1 | U13: =IF(BRIEFING!$C$21="Interior SC",0.95,IF(BRIEFING!$C$21="Litoral SC",1.0,IF(BRIEFING!$C$21="Capital Floripa",1.05,IF(BRIEFING!$C$21="Litoral SP",1.15,IF(BRIEFING!$C$21="Capital SP-RJ",1.25,1))))) | V13: =1 | W13: =1 | X13: =1 | Y13: =1 | Z13: =1 | AA13: =PRODUCT(B13:Z13)
A14: Pisos | B14: =1 | C14: =1 | D14: =1 | E14: =1 | F14: =IF(BRIEFING!$C$6="Econômico",0.6,IF(BRIEFING!$C$6="Standard",0.75,IF(BRIEFING!$C$6="Alto",1.0,IF(BRIEFING!$C$6="Super Alto",1.3,IF(BRIEFING!$C$6="Luxo",1.7,1))))) | G14: =1 | H14: =IF(BRIEFING!$C$8="Porcelanato padrão",1.0,IF(BRIEFING!$C$8="Cerâmica",0.75,IF(BRIEFING!$C$8="Vinílico",0.85,IF(BRIEFING!$C$8="Importado",1.5,IF(BRIEFING!$C$8="Mármore",2.0,1))))) | I14: =1 | J14: =1 | K14: =1 | L14: =1 | M14: =1 | N14: =1 | O14: =1 | P14: =1 | ... T14: =1 | U14: =IF(BRIEFING!$C$21="Interior SC",0.95,IF(BRIEFING!$C$21="Litoral SC",1.0,IF(BRIEFING!$C$21="Capital Floripa",1.05,IF(BRIEFING!$C$21="Litoral SP",1.15,IF(BRIEFING!$C$21="Capital SP-RJ",1.25,1))))) | V14: =1 | W14: =1 | X14: =1 | Y14: =1 | Z14: =1 | AA14: =PRODUCT(B14:Z14)
A15: Pintura | B15: =1 | C15: =1 | D15: =1 | E15: =1 | F15: =IF(BRIEFING!$C$6="Econômico",0.85,IF(BRIEFING!$C$6="Standard",0.9,IF(BRIEFING!$C$6="Alto",1.0,IF(BRIEFING!$C$6="Super Alto",1.1,IF(BRIEFING!$C$6="Luxo",1.2,1))))) | G15: =1 | H15: =1 | I15: =1 | J15: =1 | K15: =1 | L15: =1 | M15: =1 | N15: =1 | ... T15: =1 | U15: =IF(BRIEFING!$C$21="Interior SC",0.95,IF(BRIEFING!$C$21="Litoral SC",1.0,IF(BRIEFING!$C$21="Capital Floripa",1.05,IF(BRIEFING!$C$21="Litoral SP",1.15,IF(BRIEFING!$C$21="Capital SP-RJ",1.25,1))))) | V15: =1 | W15: =1 | X15: =1 | Y15: =1 | Z15: =1 | AA15: =PRODUCT(B15:Z15)
A16: Esquadrias | B16: =1 | C16: =1 | D16: =1 | E16: =1 | F16: =IF(BRIEFING!$C$6="Econômico",0.55,IF(BRIEFING!$C$6="Standard",0.7,IF(BRIEFING!$C$6="Alto",1.0,IF(BRIEFING!$C$6="Super Alto",1.35,IF(BRIEFING!$C$6="Luxo",1.6,1))))) | G16: =IF(BRIEFING!$C$7="Alumínio anodizado",1.0,IF(BRIEFING!$C$7="Pintura eletrostática",1.15,IF(BRIEFING!$C$7="PVC",0.9,IF(BRIEFING!$C$7="Alto desempenho",1.4,1)))) | H16: =1 | I16: =1 | J16: =1 | K16: =1 | L16: =1 | M16: =1 | N16: =1 | O16: =1 | ... T16: =1 | U16: =IF(BRIEFING!$C$21="Interior SC",0.95,IF(BRIEFING!$C$21="Litoral SC",1.0,IF(BRIEFING!$C$21="Capital Floripa",1.05,IF(BRIEFING!$C$21="Litoral SP",1.15,IF(BRIEFING!$C$21="Capital SP-RJ",1.25,1))))) | V16: =1 | W16: =1 | X16: =1 | Y16: =1 | Z16: =1 | AA16: =PRODUCT(B16:Z16)
A17: Louças e Metais | B17: =1 | C17: =1 | D17: =1 | E17: =1 | F17: =1 | G17: =1 | H17: =1 | I17: =1 | ... T17: =1 | U17: =IF(BRIEFING!$C$21="Interior SC",0.95,IF(BRIEFING!$C$21="Litoral SC",1.0,IF(BRIEFING!$C$21="Capital Floripa",1.05,IF(BRIEFING!$C$21="Litoral SP",1.15,IF(BRIEFING!$C$21="Capital SP-RJ",1.25,1))))) | V17: =1 | W17: =1 | X17: =1 | Y17: =1 | Z17: =1 | AA17: =PRODUCT(B17:Z17)
A18: Fachada | B18: =1 | C18: =1 | D18: =1 | E18: =1 | F18: =IF(BRIEFING!$C$6="Econômico",0.8,IF(BRIEFING!$C$6="Standard",0.85,IF(BRIEFING!$C$6="Alto",1.0,IF(BRIEFING!$C$6="Super Alto",1.25,IF(BRIEFING!$C$6="Luxo",1.5,1))))) | G18: =1 | H18: =1 | I18: =1 | J18: =1 | K18: =IF(BRIEFING!$C$11="Textura + pintura",1.0,IF(BRIEFING!$C$11="Cerâmica/Pastilha",1.4,IF(BRIEFING!$C$11="ACM",1.8,IF(BRIEFING!$C$11="Pele de vidro",2.5,IF(BRIEFING!$C$11="Misto",1.3,1))))) | L18: =IF(BRIEFING!$C$12="Equipe própria",1.0,IF(BRIEFING!$C$12="Empreitada",1.2,1)) | M18: =1 | N18: =1 | O18: =1 | P18: =1 | Q18: =1 | R18: =1 | S18: =1 | T18: =1 | U18: =IF(BRIEFING!$C$21="Interior SC",0.95,IF(BRIEFING!$C$21="Litoral SC",1.0,IF(BRIEFING!$C$21="Capital Floripa",1.05,IF(BRIEFING!$C$21="Litoral SP",1.15,IF(BRIEFING!$C$21="Capital SP-RJ",1.25,1))))) | V18: =1 | W18: =1 | X18: =1 | Y18: =1 | Z18: =1 | AA18: =PRODUCT(B18:Z18)
A19: Complementares | B19: =1 | C19: =1 | D19: =1 | E19: =1 | F19: =IF(BRIEFING!$C$6="Econômico",0.7,IF(BRIEFING!$C$6="Standard",0.85,IF(BRIEFING!$C$6="Alto",1.0,IF(BRIEFING!$C$6="Super Alto",1.2,IF(BRIEFING!$C$6="Luxo",1.5,1))))) | G19: =1 | H19: =1 | I19: =1 | J19: =1 | K19: =1 | L19: =1 | M19: =IF(BRIEFING!$C$13="Não",1.0,IF(BRIEFING!$C$13="Básica",1.1,IF(BRIEFING!$C$13="Completa",1.25,1))) | N19: =1 | O19: =1 | P19: =1 | Q19: =IF(BRIEFING!$C$17="Básico",0.7,IF(BRIEFING!$C$17="Completo",1.0,IF(BRIEFING!$C$17="Premium",1.4,1))) | R19: =IF(BRIEFING!$C$18="Sem",0.85,IF(BRIEFING!$C$18="Básico",1.0,IF(BRIEFING!$C$18="Elaborado",1.2,IF(BRIEFING!$C$18="Premium",1.5,1)))) | S19: =IF(BRIEFING!$C$19="Sem",0.85,IF(BRIEFING!$C$19="Básico",1.0,IF(BRIEFING!$C$19="Completo",1.25,IF(BRIEFING!$C$19="Decorado",1.5,1)))) | T19: =1 | U19: =IF(BRIEFING!$C$21="Interior SC",0.95,IF(BRIEFING!$C$21="Litoral SC",1.0,IF(BRIEFING!$C$21="Capital Floripa",1.05,IF(BRIEFING!$C$21="Litoral SP",1.15,IF(BRIEFING!$C$21="Capital SP-RJ",1.25,1))))) | V19: =1 | W19: =1 | X19: =1 | Y19: =1 | Z19: =1 | AA19: =PRODUCT(B19:Z19)
A20: Imprevistos | B20: =1 | C20: =1 | D20: =1 | E20: =1 | F20: =1 | G20: =1 | H20: =1 | I20: =1 | ... T20: =1 | U20: =IF(BRIEFING!$C$21="Interior SC",0.95,IF(BRIEFING!$C$21="Litoral SC",1.0,IF(BRIEFING!$C$21="Capital Floripa",1.05,IF(BRIEFING!$C$21="Litoral SP",1.15,IF(BRIEFING!$C$21="Capital SP-RJ",1.25,1))))) | V20: =1 | W20: =1 | X20: =1 | Y20: =1 | Z20: =1 | AA20: =PRODUCT(B20:Z20)

Sheet CUSTOS_MACROGRUPO
A1: # | B1: Macrogrupo | C1: Base R$/m² | D1: Fator CUB | E1: Fator Briefing | F1: R$/m² Ajustado | G1: Valor Total | H1: % | I1: Faixa Min | J1: Faixa Max | K1: Status
A2: 1 | B2: Gerenciamento | C2: 434.3 | D2: =DADOS_PROJETO!$B$19/DADOS_PROJETO!$B$20 | E2: =FATORES!$AA$3 | F2: =C2*D2*E2 | G2: =F2*DADOS_PROJETO!$B$6 | H2: =G2/SUM($G$2:$G$19) | I2: 221.6 | J2: 609.41 | K2: =IF(AND(F2>=I2,F2<=J2),"✓",IF(OR(F2<I2*0.8,F2>J2*1.2),"✗","⚠"))
A3: 2 | B3: Mov. Terra | C3: 17.62 | D3: =DADOS_PROJETO!$B$19/DADOS_PROJETO!$B$20 | E3: =FATORES!$AA$4 | F3: =C3*D3*E3 | G3: =F3*DADOS_PROJETO!$B$6 | H3: =G3/SUM($G$2:$G$19) | I3: 7.76 | J3: 66.48 | K3: =IF(AND(F3>=I3,F3<=J3),"✓",IF(OR(F3<I3*0.8,F3>J3*1.2),"✗","⚠"))
A4: 3 | B4: Infraestrutura | C4: 235.34 | D4: =DADOS_PROJETO!$B$19/DADOS_PROJETO!$B$20 | E4: =FATORES!$AA$5 | F4: =C4*D4*E4 | G4: =F4*DADOS_PROJETO!$B$6 | H4: =G4/SUM($G$2:$G$19) | I4: 132.96 | J4: 310.24 | K4: =IF(AND(F4>=I4,F4<=J4),"✓",IF(OR(F4<I4*0.8,F4>J4*1.2),"✗","⚠"))
A5: 4 | B5: Supraestrutura | C5: 768.5 | D5: =DADOS_PROJETO!$B$19/DADOS_PROJETO!$B$20 | E5: =FATORES!$AA$6 | F5: =C5*D5*E5 | G5: =F5*DADOS_PROJETO!$B$6 | H5: =G5/SUM($G$2:$G$19) | I5: 498.61 | J5: 1052.61 | K5: =IF(AND(F5>=I5,F5<=J5),"✓",IF(OR(F5<I5*0.8,F5>J5*1.2),"✗","⚠"))
A6: 5 | B6: Alvenaria | C6: 161.59 | D6: =DADOS_PROJETO!$B$19/DADOS_PROJETO!$B$20 | E6: =FATORES!$AA$7 | F6: =C6*D6*E6 | G6: =F6*DADOS_PROJETO!$B$6 | H6: =G6/SUM($G$2:$G$19) | I6: 66.48 | J6: 332.4 | K6: =IF(AND(F6>=I6,F6<=J6),"✓",IF(OR(F6<I6*0.8,F6>J6*1.2),"✗","⚠"))
A7: 6 | B7: Impermeabilização | C7: 58.92 | D7: =DADOS_PROJETO!$B$19/DADOS_PROJETO!$B$20 | E7: =FATORES!$AA$8 | F7: =C7*D7*E7 | G7: =F7*DADOS_PROJETO!$B$6 | H7: =G7/SUM($G$2:$G$19) | I7: 39.89 | J7: 95.29 | K7: =IF(AND(F7>=I7,F7<=J7),"✓",IF(OR(F7<I7*0.8,F7>J7*1.2),"✗","⚠"))
A8: 7 | B8: Instalações | C8: 387.67 | D8: =DADOS_PROJETO!$B$19/DADOS_PROJETO!$B$20 | E8: =FATORES!$AA$9 | F8: =C8*D8*E8 | G8: =F8*DADOS_PROJETO!$B$6 | H8: =G8/SUM($G$2:$G$19) | I8: 349.02 | J8: 554.01 | K8: =IF(AND(F8>=I8,F8<=J8),"✓",IF(OR(F8<I8*0.8,F8>J8*1.2),"✗","⚠"))
A9: 8 | B9: Sist. Especiais | C9: 186.83 | D9: =DADOS_PROJETO!$B$19/DADOS_PROJETO!$B$20 | E9: =FATORES!$AA$10 | F9: =C9*D9*E9 | G9: =F9*DADOS_PROJETO!$B$6 | H9: =G9/SUM($G$2:$G$19) | I9: 110.8 | J9: 443.21 | K9: =IF(AND(F9>=I9,F9<=J9),"✓",IF(OR(F9<I9*0.8,F9>J9*1.2),"✗","⚠"))
A10: 9 | B10: Climatização | C10: 45.46 | D10: =DADOS_PROJETO!$B$19/DADOS_PROJETO!$B$20 | E10: =FATORES!$AA$11 | F10: =C10*D10*E10 | G10: =F10*DADOS_PROJETO!$B$6 | H10: =G10/SUM($G$2:$G$19) | I10: 0 | J10: 88.64 | K10: =IF(AND(F10>=I10,F10<=J10),"✓",IF(OR(F10<I10*0.8,F10>J10*1.2),"✗","⚠"))
A11: 10 | B11: Rev. Int. Parede | C11: 183.15 | D11: =DADOS_PROJETO!$B$19/DADOS_PROJETO!$B$20 | E11: =FATORES!$AA$12 | F11: =C11*D11*E11 | G11: =F11*DADOS_PROJETO!$B$6 | H11: =G11/SUM($G$2:$G$19) | I11: 110.8 | J11: 265.92 | K11: =IF(AND(F11>=I11,F11<=J11),"✓",IF(OR(F11<I11*0.8,F11>J11*1.2),"✗","⚠"))
A12: 11 | B12: Teto | C12: 68.36 | D12: =DADOS_PROJETO!$B$19/DADOS_PROJETO!$B$20 | E12: =FATORES!$AA$13 | F12: =C12*D12*E12 | G12: =F12*DADOS_PROJETO!$B$6 | H12: =G12/SUM($G$2:$G$19) | I12: 49.86 | J12: 155.12 | K12: =IF(AND(F12>=I12,F12<=J12),"✓",IF(OR(F12<I12*0.8,F12>J12*1.2),"✗","⚠"))
A13: 12 | B13: Pisos | C13: 207.83 | D13: =DADOS_PROJETO!$B$19/DADOS_PROJETO!$B$20 | E13: =FATORES!$AA$14 | F13: =C13*D13*E13 | G13: =F13*DADOS_PROJETO!$B$6 | H13: =G13/SUM($G$2:$G$19) | I13: 138.5 | J13: 387.81 | K13: =IF(AND(F13>=I13,F13<=J13),"✓",IF(OR(F13<I13*0.8,F13>J13*1.2),"✗","⚠"))
A14: 13 | B14: Pintura | C14: 133.91 | D14: =DADOS_PROJETO!$B$19/DADOS_PROJETO!$B$20 | E14: =FATORES!$AA$15 | F14: =C14*D14*E14 | G14: =F14*DADOS_PROJETO!$B$6 | H14: =G14/SUM($G$2:$G$19) | I14: 106.37 | J14: 221.6 | K14: =IF(AND(F14>=I14,F14<=J14),"✓",IF(OR(F14<I14*0.8,F14>J14*1.2),"✗","⚠"))
A15: 14 | B15: Esquadrias | C15: 376.33 | D15: =DADOS_PROJETO!$B$19/DADOS_PROJETO!$B$20 | E15: =FATORES!$AA$16 | F15: =C15*D15*E15 | G15: =F15*DADOS_PROJETO!$B$6 | H15: =G15/SUM($G$2:$G$19) | I15: 221.6 | J15: 775.61 | K15: =IF(AND(F15>=I15,F15<=J15),"✓",IF(OR(F15<I15*0.8,F15>J15*1.2),"✗","⚠"))
A16: 15 | B16: Louças e Metais | C16: 29.2 | D16: =DADOS_PROJETO!$B$19/DADOS_PROJETO!$B$20 | E16: =FATORES!$AA$17 | F16: =C16*D16*E16 | G16: =F16*DADOS_PROJETO!$B$6 | H16: =G16/SUM($G$2:$G$19) | I16: 33.24 | J16: 132.96 | K16: =IF(AND(F16>=I16,F16<=J16),"✓",IF(OR(F16<I16*0.8,F16>J16*1.2),"✗","⚠"))
A17: 16 | B17: Fachada | C17: 137.45 | D17: =DADOS_PROJETO!$B$19/DADOS_PROJETO!$B$20 | E17: =FATORES!$AA$18 | F17: =C17*D17*E17 | G17: =F17*DADOS_PROJETO!$B$6 | H17: =G17/SUM($G$2:$G$19) | I17: 60.94 | J17: 304.7 | K17: =IF(AND(F17>=I17,F17<=J17),"✓",IF(OR(F17<I17*0.8,F17>J17*1.2),"✗","⚠"))
A18: 17 | B18: Complementares | C18: 195.93 | D18: =DADOS_PROJETO!$B$19/DADOS_PROJETO!$B$20 | E18: =FATORES!$AA$19 | F18: =C18*D18*E18 | G18: =F18*DADOS_PROJETO!$B$6 | H18: =G18/SUM($G$2:$G$19) | I18: 110.8 | J18: 554.01 | K18: =IF(AND(F18>=I18,F18<=J18),"✓",IF(OR(F18<I18*0.8,F18>J18*1.2),"✗","⚠"))
A19: 18 | B19: Imprevistos | C19: 57.64 | D19: =DADOS_PROJETO!$B$19/DADOS_PROJETO!$B$20 | E19: =FATORES!$AA$20 | F19: =C19*D19*E19 | G19: =F19*DADOS_PROJETO!$B$6 | H19: =G19/SUM($G$2:$G$19) | I19: 38.78 | J19: 132.96 | K19: =IF(AND(F19>=I19,F19<=J19),"✓",IF(OR(F19<I19*0.8,F19>J19*1.2),"✗","⚠"))
B20: TOTAL | G20: =SUM(G2:G19) | H20: 100.0%

Sheet ÍNDICES
A1: ÍNDICES DE REFERÊNCIA
A3: A. ÍNDICES ESTRUTURAIS POR TIPO DE LAJE
A4: Parâmetro | B4: Cubetas | C4: Protendida | D4: Maciça | E4: Treliçada
A5: Concreto (m³/m² AC) | B5: 0.22 | C5: 0.2 | D5: 0.25 | E5: 0.19
A6: Aço (kg/m³) | B6: 90 | C6: 110 | D6: 85 | E6: 80
A7: Forma (m²/m³) | B7: 10 | C7: 9 | D7: 11 | E7: 12
A10: B. ÍNDICES DE ACABAMENTOS
A11: Item | B11: Índice (m²/m² AC) | C11: Referência
A12: Chapisco interno | B12: 1.8 | C12: Área de parede interna
A13: Reboco interno | B13: 1.8 | C13: Idem
A14: Estucamento | B14: 1.5 | C14: Área pintável
A15: Cerâmico parede | B15: 0.3 | C15: BWCs + cozinhas
A16: Porcelanato parede | B16: 0.15 | C16: BWCs padrão alto
A17: Contrapiso | B17: 0.85 | C17: Áreas internas
A18: Porcelanato piso | B18: 0.55 | C18: Áreas secas
A19: Cerâmico piso | B19: 0.15 | C19: BWCs + A. serviço
A20: Rodapé | B20: 0.4 | C20: m/m² AC
A21: Forro gesso | B21: 0.7 | C21: Área de teto
A22: Pintura interna | B22: 2.2 | C22: Paredes + teto
A23: Textura externa | B23: 0.45 | C23: Fachada
... A25: Reboco externo | B25: 0.45 | C25: Fachada
A28: C. ÍNDICES DE INSTALAÇÕES
A29: Disciplina | B29: R$/m² típico | C29: % do grupo
A30: Hidrossanitárias | B30: 120 | C30: 0.33
A31: Elétricas | B31: 110 | C31: 0.3
A32: Preventivas | B32: 60 | C32: 0.16
A33: Gás | B33: 35 | C33: 0.1
A34: Telecom | B34: 40 | C34: 0.11
A37: D. VERBAS PARAMÉTRICAS
A38: Item | B38: R$/m² | C38: Observação
A39: Elevadores | B39: 50-80 | C39: Por elevador: R$ 250-400k
A40: Gerador | B40: 15-25 | C40: Prédio alto
A41: Pressurização | B41: 10-18 | C41: Se aplicável
A42: Automação básica | B42: 8-15 | C42: CFTV + interfone

Sheet ESTRUTURAL
A1: DETALHAMENTO ESTRUTURAL
A3: CONCRETO (45% da Supraestrutura)
A4: Elemento | B4: Peso % | C4: Qtd (m³) | D4: Un | E4: PU (R$/m³) | F4: Total (R$) | G4: R$/m² | H4: Índice
A5: Pilares | B5: 0.25 | C5: =0.055*DADOS_PROJETO!$B$6 | D5: m³ | E5: =IF(C5>0,F5/C5,0) | F5: =CUSTOS_MACROGRUPO!$G$5*0.45*B5 | G5: =F5/DADOS_PROJETO!$B$6 | H5: 0.055
A6: Vigas | B6: 0.3 | C6: =0.066*DADOS_PROJETO!$B$6 | D6: m³ | E6: =IF(C6>0,F6/C6,0) | F6: =CUSTOS_MACROGRUPO!$G$5*0.45*B6 | G6: =F6/DADOS_PROJETO!$B$6 | H6: 0.066
A7: Lajes | B7: 0.35 | C7: =0.077*DADOS_PROJETO!$B$6 | D7: m³ | E7: =IF(C7>0,F7/C7,0) | F7: =CUSTOS_MACROGRUPO!$G$5*0.45*B7 | G7: =F7/DADOS_PROJETO!$B$6 | H7: 0.077
A8: Escadas | B8: 0.1 | C8: =0.022*DADOS_PROJETO!$B$6 | D8: m³ | E8: =IF(C8>0,F8/C8,0) | F8: =CUSTOS_MACROGRUPO!$G$5*0.45*B8 | G8: =F8/DADOS_PROJETO!$B$6 | H8: 0.022
A9: TOTAL CONCRETO | C9: =SUM(C5:C8) | F9: =SUM(F5:F8) | G9: =F9/DADOS_PROJETO!$B$6 | H9: =C9/DADOS_PROJETO!$B$6
A11: AÇO (30% da Supraestrutura)
A12: Elemento | B12: Peso % | C12: Peso (kg) | D12: Un | E12: Taxa (kg/m³) | F12: Total (R$) | G12: R$/m²
A13: Pilares | B13: 0.25 | C13: =95*C5 | D13: kg | E13: 95 | F13: =CUSTOS_MACROGRUPO!$G$5*0.30*B13 | G13: =F13/DADOS_PROJETO!$B$6
A14: Vigas | B14: 0.3 | C14: =90*C6 | D14: kg | E14: 90 | F14: =CUSTOS_MACROGRUPO!$G$5*0.30*B14 | G14: =F14/DADOS_PROJETO!$B$6
A15: Lajes | B15: 0.35 | C15: =88*C7 | D15: kg | E15: 88 | F15: =CUSTOS_MACROGRUPO!$G$5*0.30*B15 | G15: =F15/DADOS_PROJETO!$B$6
A16: Escadas | B16: 0.1 | C16: =85*C8 | D16: kg | E16: 85 | F16: =CUSTOS_MACROGRUPO!$G$5*0.30*B16 | G16: =F16/DADOS_PROJETO!$B$6
A17: TOTAL AÇO | C17: =SUM(C13:C16) | F17: =SUM(F13:F16) | G17: =F17/DADOS_PROJETO!$B$6
A19: FORMA (25% da Supraestrutura)
A20: Tipo | B20: Peso % | C20: Área (m²) | D20: Un | F20: Total (R$) | G20: R$/m²
A21: Madeira/compensado pilares | B21: 0.3 | C21: =10*C9*B21 | D21: m² | F21: =CUSTOS_MACROGRUPO!$G$5*0.25*B21 | G21: =F21/DADOS_PROJETO!$B$6
A22: Madeira/compensado vigas | B22: 0.35 | C22: =10*C9*B22 | D22: m² | F22: =CUSTOS_MACROGRUPO!$G$5*0.25*B22 | G22: =F22/DADOS_PROJETO!$B$6
A23: Cubetas/forma lajes | B23: 0.35 | C23: =10*C9*B23 | D23: m² | F23: =CUSTOS_MACROGRUPO!$G$5*0.25*B23 | G23: =F23/DADOS_PROJETO!$B$6
A24: TOTAL FORMA | C24: =SUM(C21:C23) | F24: =SUM(F21:F23) | G24: =F24/DADOS_PROJETO!$B$6
A26: FUNDAÇÃO (85% da Infraestrutura)
A27: Item | B27: Peso % | F27: Total (R$) | G27: R$/m²
A28: Estacas (HC) | B28: 0.6 | F28: =CUSTOS_MACROGRUPO!$G$4*0.85*B28 | G28: =F28/DADOS_PROJETO!$B$6
A29: Blocos de coroamento | B29: 0.25 | F29: =CUSTOS_MACROGRUPO!$G$4*0.85*B29 | G29: =F29/DADOS_PROJETO!$B$6
A30: Vigas baldrame | B30: 0.15 | F30: =CUSTOS_MACROGRUPO!$G$4*0.85*B30 | G30: =F30/DADOS_PROJETO!$B$6
A31: TOTAL FUNDAÇÃO | F31: =SUM(F28:F30) | G31: =F31/DADOS_PROJETO!$B$6
A33: CONTENÇÃO (15% da Infraestrutura, se houver)
A34: Contenção | F34: =IF(BRIEFING!$C$4<>"Não",CUSTOS_MACROGRUPO!$G$4*0.15,0) | G34: =F34/DADOS_PROJETO!$B$6
A36: ÍNDICES CALCULADOS
A37: Concreto/AC (m³/m²) | F37: =C9/DADOS_PROJETO!$B$6
A38: Taxa Aço Global (kg/m³) | F38: =C17/C9
A39: Forma/AC (m²/m²) | F39: =C24/DADOS_PROJETO!$B$6

Sheet INSTALACOES
A1: DETALHAMENTO DE INSTALAÇÕES
A3: INSTALAÇÕES
A4: Disciplina | B4: Peso % | C4: Valor (R$) | D4: R$/m² | E4: MO 55% (R$) | F4: Material 45% (R$)
A5: Hidrossanitárias | B5: 0.33 | C5: =CUSTOS_MACROGRUPO!$G$8*B5 | D5: =C5/DADOS_PROJETO!$B$6 | E5: =C5*0.55 | F5: =C5*0.45
A6: Elétricas | B6: 0.3 | C6: =CUSTOS_MACROGRUPO!$G$8*B6 | D6: =C6/DADOS_PROJETO!$B$6 | E6: =C6*0.55 | F6: =C6*0.45
A7: Preventivas | B7: 0.16 | C7: =CUSTOS_MACROGRUPO!$G$8*B7 | D7: =C7/DADOS_PROJETO!$B$6 | E7: =C7*0.55 | F7: =C7*0.45
A8: Gás | B8: 0.1 | C8: =CUSTOS_MACROGRUPO!$G$8*B8 | D8: =C8/DADOS_PROJETO!$B$6 | E8: =C8*0.55 | F8: =C8*0.45
A9: Telecom | B9: 0.11 | C9: =CUSTOS_MACROGRUPO!$G$8*B9 | D9: =C9/DADOS_PROJETO!$B$6 | E9: =C9*0.55 | F9: =C9*0.45
A10: TOTAL INSTALAÇÕES | C10: =SUM(C5:C9) | D10: =C10/DADOS_PROJETO!$B$6 | E10: =SUM(E5:E9) | F10: =SUM(F5:F9)
A12: SISTEMAS ESPECIAIS
A13: Item | B13: Peso % | C13: Valor (R$) | D13: R$/m²
A14: Elevadores | B14: 0.4 | C14: =CUSTOS_MACROGRUPO!$G$9*B14 | D14: =C14/DADOS_PROJETO!$B$6
A15: Gerador | B15: 0.2 | C15: =CUSTOS_MACROGRUPO!$G$9*B15 | D15: =C15/DADOS_PROJETO!$B$6
A16: Automação/CFTV | B16: 0.2 | C16: =CUSTOS_MACROGRUPO!$G$9*B16 | D16: =C16/DADOS_PROJETO!$B$6
A17: Pressuriz./Outros | B17: 0.2 | C17: =CUSTOS_MACROGRUPO!$G$9*B17 | D17: =C17/DADOS_PROJETO!$B$6
A18: TOTAL SIST. ESPECIAIS | C18: =SUM(C14:C17) | D18: =C18/DADOS_PROJETO!$B$6

Sheet ACABAMENTOS
A1: DETALHAMENTO DE ACABAMENTOS
A3: REVESTIMENTOS DE PAREDE
A4: Item | B4: Qtd | C4: Un | D4: PU Material (R$) | E4: PU MO (R$) | F4: Total Material (R$) | G4: Total MO (R$) | H4: Total (R$)
A5: Chapisco interno | B5: =1.8*DADOS_PROJETO!$B$6 | C5: m² | D5: =IF(B5>0,F5/B5,0) | E5: =IF(B5>0,G5/B5,0) | F5: =CUSTOS_MACROGRUPO!$G$11*0.12*0.45 | G5: =CUSTOS_MACROGRUPO!$G$11*0.12*0.55 | H5: =F5+G5
A6: Reboco interno | B6: =1.8*DADOS_PROJETO!$B$6 | C6: m² | D6: =IF(B6>0,F6/B6,0) | E6: =IF(B6>0,G6/B6,0) | F6: =CUSTOS_MACROGRUPO!$G$11*0.35*0.45 | G6: =CUSTOS_MACROGRUPO!$G$11*0.35*0.55 | H6: =F6+G6
A7: Estucamento | B7: =1.5*DADOS_PROJETO!$B$6 | C7: m² | D7: =IF(B7>0,F7/B7,0) | E7: =IF(B7>0,G7/B7,0) | F7: =CUSTOS_MACROGRUPO!$G$11*0.25*0.45 | G7: =CUSTOS_MACROGRUPO!$G$11*0.25*0.55 | H7: =F7+G7
A8: Cerâmico parede | B8: =0.3*DADOS_PROJETO!$B$6 | C8: m² | D8: =IF(B8>0,F8/B8,0) | E8: =IF(B8>0,G8/B8,0) | F8: =CUSTOS_MACROGRUPO!$G$11*0.15*0.45 | G8: =CUSTOS_MACROGRUPO!$G$11*0.15*0.55 | H8: =F8+G8
A9: Porcelanato parede | B9: =0.15*DADOS_PROJETO!$B$6 | C9: m² | D9: =IF(B9>0,F9/B9,0) | E9: =IF(B9>0,G9/B9,0) | F9: =CUSTOS_MACROGRUPO!$G$11*0.13*0.45 | G9: =CUSTOS_MACROGRUPO!$G$11*0.13*0.55 | H9: =F9+G9
A10: TOTAL REV. PAREDE | F10: =SUM(F5:F9) | G10: =SUM(G5:G9) | H10: =F10+G10
A12: TETO
A13: Item | B13: Qtd | C13: Un | D13: PU Material (R$) | E13: PU MO (R$) | F13: Total Material (R$) | G13: Total MO (R$) | H13: Total (R$)
A14: Forro gesso acartonado | B14: =0.5*DADOS_PROJETO!$B$6 | C14: m² | D14: =IF(B14>0,F14/B14,0) | E14: =IF(B14>0,G14/B14,0) | F14: =CUSTOS_MACROGRUPO!$G$12*0.55*0.45 | G14: =CUSTOS_MACROGRUPO!$G$12*0.55*0.55 | H14: =F14+G14
A15: Forro gesso UR | B15: =0.2*DADOS_PROJETO!$B$6 | C15: m² | D15: =IF(B15>0,F15/B15,0) | E15: =IF(B15>0,G15/B15,0) | F15: =CUSTOS_MACROGRUPO!$G$12*0.3*0.45 | G15: =CUSTOS_MACROGRUPO!$G$12*0.3*0.55 | H15: =F15+G15
A16: Negativo/Tabica | B16: =0.1*DADOS_PROJETO!$B$6 | C16: m | D16: =IF(B16>0,F16/B16,0) | E16: =IF(B16>0,G16/B16,0) | F16: =CUSTOS_MACROGRUPO!$G$12*0.15*0.45 | G16: =CUSTOS_MACROGRUPO!$G$12*0.15*0.55 | H16: =F16+G16
A17: TOTAL TETO | F17: =SUM(F14:F16) | G17: =SUM(G14:G16) | H17: =F17+G17
A19: PISOS
A20: Item | B20: Qtd | C20: Un | D20: PU Material (R$) | E20: PU MO (R$) | F20: Total Material (R$) | G20: Total MO (R$) | H20: Total (R$)
A21: Contrapiso | B21: =0.85*DADOS_PROJETO!$B$6 | C21: m² | D21: =IF(B21>0,F21/B21,0) | E21: =IF(B21>0,G21/B21,0) | F21: =CUSTOS_MACROGRUPO!$G$13*0.2*0.45 | G21: =CUSTOS_MACROGRUPO!$G$13*0.2*0.55 | H21: =F21+G21
A22: Porcelanato piso | B22: =0.55*DADOS_PROJETO!$B$6 | C22: m² | D22: =IF(B22>0,F22/B22,0) | E22: =IF(B22>0,G22/B22,0) | F22: =CUSTOS_MACROGRUPO!$G$13*0.45*0.45 | G22: =CUSTOS_MACROGRUPO!$G$13*0.45*0.55 | H22: =F22+G22
A23: Cerâmico piso | B23: =0.15*DADOS_PROJETO!$B$6 | C23: m² | D23: =IF(B23>0,F23/B23,0) | E23: =IF(B23>0,G23/B23,0) | F23: =CUSTOS_MACROGRUPO!$G$13*0.1*0.45 | G23: =CUSTOS_MACROGRUPO!$G$13*0.1*0.55 | H23: =F23+G23
A24: Rodapé | B24: =0.4*DADOS_PROJETO!$B$6 | C24: m | D24: =IF(B24>0,F24/B24,0) | E24: =IF(B24>0,G24/B24,0) | F24: =CUSTOS_MACROGRUPO!$G$13*0.1*0.45 | G24: =CUSTOS_MACROGRUPO!$G$13*0.1*0.55 | H24: =F24+G24
A25: Soleira/peitoril | B25: =0.08*DADOS_PROJETO!$B$6 | C25: m² | D25: =IF(B25>0,F25/B25,0) | E25: =IF(B25>0,G25/B25,0) | F25: =CUSTOS_MACROGRUPO!$G$13*0.05*0.45 | G25: =CUSTOS_MACROGRUPO!$G$13*0.05*0.55 | H25: =F25+G25
A26: Outros | C26: m² | F26: =CUSTOS_MACROGRUPO!$G$13*0.1*0.45 | G26: =CUSTOS_MACROGRUPO!$G$13*0.1*0.55 | H26: =F26+G26
A27: TOTAL PISOS | F27: =SUM(F21:F26) | G27: =SUM(G21:G26) | H27: =F27+G27
A29: PINTURA
A30: Item | B30: Qtd | C30: Un | D30: PU Material (R$) | E30: PU MO (R$) | F30: Total Material (R$) | G30: Total MO (R$) | H30: Total (R$)
A31: Pintura parede (PVA/acrílica) | B31: =2.2*DADOS_PROJETO!$B$6 | C31: m² | D31: =IF(B31>0,F31/B31,0) | E31: =IF(B31>0,G31/B31,0) | F31: =CUSTOS_MACROGRUPO!$G$14*0.55*0.45 | G31: =CUSTOS_MACROGRUPO!$G$14*0.55*0.55 | H31: =F31+G31
A32: Pintura teto | B32: =0.7*DADOS_PROJETO!$B$6 | C32: m² | D32: =IF(B32>0,F32/B32,0) | E32: =IF(B32>0,G32/B32,0) | F32: =CUSTOS_MACROGRUPO!$G$14*0.25*0.45 | G32: =CUSTOS_MACROGRUPO!$G$14*0.25*0.55 | H32: =F32+G32
A33: Textura/Grafiato | B33: =0.15*DADOS_PROJETO!$B$6 | C33: m² | D33: =IF(B33>0,F33/B33,0) | E33: =IF(B33>0,G33/B33,0) | F33: =CUSTOS_MACROGRUPO!$G$14*0.1*0.45 | G33: =CUSTOS_MACROGRUPO!$G$14*0.1*0.55 | H33: =F33+G33
A34: Verniz/Epóxi | B34: =0.05*DADOS_PROJETO!$B$6 | C34: m² | D34: =IF(B34>0,F34/B34,0) | E34: =IF(B34>0,G34/B34,0) | F34: =CUSTOS_MACROGRUPO!$G$14*0.1*0.45 | G34: =CUSTOS_MACROGRUPO!$G$14*0.1*0.55 | H34: =F34+G34
A35: TOTAL PINTURA | F35: =SUM(F31:F34) | G35: =SUM(G31:G34) | H35: =F35+G35
A37: ESQUADRIAS
A38: Item | B38: Qtd | C38: Un | D38: PU Material (R$) | E38: PU MO (R$) | F38: Total Material (R$) | G38: Total MO (R$) | H38: Total (R$)
A39: Janelas alumínio | B39: =0.12*DADOS_PROJETO!$B$6 | C39: m² | D39: =IF(B39>0,F39/B39,0) | E39: =IF(B39>0,G39/B39,0) | F39: =CUSTOS_MACROGRUPO!$G$15*0.35*0.45 | G39: =CUSTOS_MACROGRUPO!$G$15*0.35*0.55 | H39: =F39+G39
A40: Portas internas | B40: =0.08*DADOS_PROJETO!$B$6 | C40: un | D40: =IF(B40>0,F40/B40,0) | E40: =IF(B40>0,G40/B40,0) | F40: =CUSTOS_MACROGRUPO!$G$15*0.25*0.45 | G40: =CUSTOS_MACROGRUPO!$G$15*0.25*0.55 | H40: =F40+G40
A41: Porta entrada | C41: un | F41: =CUSTOS_MACROGRUPO!$G$15*0.1*0.45 | G41: =CUSTOS_MACROGRUPO!$G$15*0.1*0.55 | H41: =F41+G41
A42: Vidros | B42: =0.15*DADOS_PROJETO!$B$6 | C42: m² | D42: =IF(B42>0,F42/B42,0) | E42: =IF(B42>0,G42/B42,0) | F42: =CUSTOS_MACROGRUPO!$G$15*0.2*0.45 | G42: =CUSTOS_MACROGRUPO!$G$15*0.2*0.55 | H42: =F42+G42
A43: Guarda-corpo | B43: =0.03*DADOS_PROJETO!$B$6 | C43: m² | D43: =IF(B43>0,F43/B43,0) | E43: =IF(B43>0,G43/B43,0) | F43: =CUSTOS_MACROGRUPO!$G$15*0.1*0.45 | G43: =CUSTOS_MACROGRUPO!$G$15*0.1*0.55 | H43: =F43+G43
A44: TOTAL ESQUADRIAS | F44: =SUM(F39:F43) | G44: =SUM(G39:G43) | H44: =F44+G44
A46: FACHADA
...

Sheet CI_DETALHADO
A1: CUSTOS INDIRETOS DETALHADOS
A3: PROJETOS E CONSULTORIAS (25%)
A4: Disciplina | B4: Peso % | C4: Valor (R$) | D4: R$/m²
A5: Arquitetônico | B5: 0.25 | C5: =CUSTOS_MACROGRUPO!$G$2*0.25*B5 | D5: =C5/DADOS_PROJETO!$B$6
A6: Estrutural | B6: 0.2 | C6: =CUSTOS_MACROGRUPO!$G$2*0.25*B6 | D6: =C6/DADOS_PROJETO!$B$6
A7: Elétrico | B7: 0.12 | C7: =CUSTOS_MACROGRUPO!$G$2*0.25*B7 | D7: =C7/DADOS_PROJETO!$B$6
A8: Hidrossanitário | B8: 0.12 | C8: =CUSTOS_MACROGRUPO!$G$2*0.25*B8 | D8: =C8/DADOS_PROJETO!$B$6
A9: Preventivo | B9: 0.08 | C9: =CUSTOS_MACROGRUPO!$G$2*0.25*B9 | D9: =C9/DADOS_PROJETO!$B$6
A10: Climatização | B10: 0.05 | C10: =CUSTOS_MACROGRUPO!$G$2*0.25*B10 | D10: =C10/DADOS_PROJETO!$B$6
A11: Paisagismo | B11: 0.05 | C11: =CUSTOS_MACROGRUPO!$G$2*0.25*B11 | D11: =C11/DADOS_PROJETO!$B$6
A12: Interiores | B12: 0.05 | C12: =CUSTOS_MACROGRUPO!$G$2*0.25*B12 | D12: =C12/DADOS_PROJETO!$B$6
A13: Fundações | B13: 0.03 | C13: =CUSTOS_MACROGRUPO!$G$2*0.25*B13 | D13: =C13/DADOS_PROJETO!$B$6
A14: Outros | B14: 0.05 | C14: =CUSTOS_MACROGRUPO!$G$2*0.25*B14 | D14: =C14/DADOS_PROJETO!$B$6
A15: TOTAL PROJETOS | C15: =SUM(C5:C14) | D15: =C15/DADOS_PROJETO!$B$6
A17: TAXAS E LICENÇAS (5%)
A18: Disciplina | B18: Peso % | C18: Valor (R$) | D18: R$/m²
A19: Alvará | B19: 0.25 | C19: =CUSTOS_MACROGRUPO!$G$2*0.05*B19 | D19: =C19/DADOS_PROJETO!$B$6
A20: ARTs/RRTs | B20: 0.2 | C20: =CUSTOS_MACROGRUPO!$G$2*0.05*B20 | D20: =C20/DADOS_PROJETO!$B$6
A21: Bombeiros | B21: 0.2 | C21: =CUSTOS_MACROGRUPO!$G$2*0.05*B21 | D21: =C21/DADOS_PROJETO!$B$6
A22: Habite-se | B22: 0.15 | C22: =CUSTOS_MACROGRUPO!$G$2*0.05*B22 | D22: =C22/DADOS_PROJETO!$B$6
A23: Registro Incorporação | B23: 0.1 | C23: =CUSTOS_MACROGRUPO!$G$2*0.05*B23 | D23: =C23/DADOS_PROJETO!$B$6
A24: Outras | B24: 0.1 | C24: =CUSTOS_MACROGRUPO!$G$2*0.05*B24 | D24: =C24/DADOS_PROJETO!$B$6
A25: TOTAL TAXAS | C25: =SUM(C19:C24) | D25: =C25/DADOS_PROJETO!$B$6
A27: EQUIPE ADM (40%)
A28: Função | B28: Peso % | C28: Valor (R$) | D28: Custo/mês (R$) | E28: Qtd
A29: Eng. Residente | B29: 0.3 | C29: =CUSTOS_MACROGRUPO!$G$2*0.40*B29 | D29: =C29/DADOS_PROJETO!$B$17 | E29: 1
A30: Mestre de Obras | B30: 0.25 | C30: =CUSTOS_MACROGRUPO!$G$2*0.40*B30 | D30: =C30/DADOS_PROJETO!$B$17 | E30: 1
A31: Almoxarife | B31: 0.12 | C31: =CUSTOS_MACROGRUPO!$G$2*0.40*B31 | D31: =C31/DADOS_PROJETO!$B$17 | E31: 1
A32: Téc. Segurança | B32: 0.12 | C32: =CUSTOS_MACROGRUPO!$G$2*0.40*B32 | D32: =C32/DADOS_PROJETO!$B$17 | E32: 1
A33: Admin. Obra | B33: 0.12 | C33: =CUSTOS_MACROGRUPO!$G$2*0.40*B33 | D33: =C33/DADOS_PROJETO!$B$17 | E33: 1
A34: Estagiários | B34: 0.09 | C34: =CUSTOS_MACROGRUPO!$G$2*0.40*B34 | D34: =C34/DADOS_PROJETO!$B$17 | E34: 2
A35: TOTAL EQUIPE ADM | C35: =SUM(C29:C34) | D35: =C35/DADOS_PROJETO!$B$17
A37: EPCs (15%)
A38: Disciplina | B38: Peso % | C38: Valor (R$) | D38: R$/m²
A39: Bandeja proteção | B39: 0.25 | C39: =CUSTOS_MACROGRUPO!$G$2*0.15*B39 | D39: =C39/DADOS_PROJETO!$B$6
A40: Guarda-corpo | B40: 0.25 | C40: =CUSTOS_MACROGRUPO!$G$2*0.15*B40 | D40: =C40/DADOS_PROJETO!$B$6
A41: Tela proteção | B41: 0.2 | C41: =CUSTOS_MACROGRUPO!$G$2*0.15*B41 | D41: =C41/DADOS_PROJETO!$B$6
A42: Linha de vida | B42: 0.15 | C42: =CUSTOS_MACROGRUPO!$G$2*0.15*B42 | D42: =C42/DADOS_PROJETO!$B$6
A43: Sinalização | B43: 0.1 | C43: =CUSTOS_MACROGRUPO!$G$2*0.15*B43 | D43: =C43/DADOS_PROJETO!$B$6
A44: Outros | B44: 0.05 | C44: =CUSTOS_MACROGRUPO!$G$2*0.15*B44 | D44: =C44/DADOS_PROJETO!$B$6
...

Sheet BENCHMARK
A1: BENCHMARK — PROJETOS DE REFERÊNCIA
A3: Projeto | B3: Cidade | C3: AC (m²) | D3: NP | E3: Prazo (meses) | F3: CUB (R$/m²) | G3: R$/m² Original | H3: CUB Ratio | I3: R$/m² Atual
A4: Maison Beach | B4: Floripa | C4: 12880 | D4: 25 | E4: 36 | F4: 2753 | G4: 3291 | H4: 1.2 | I4: =H4*DADOS_PROJETO!$B$19
A5: Catena | B5: Floripa | C5: 9242 | D5: 20 | E5: 30 | F5: 3009 | G5: 3376 | H5: 1.12 | I5: =H5*DADOS_PROJETO!$B$19
A6: Connect | B6: Itajaí | C6: 13144 | D6: 28 | E6: 36 | F6: 2900 | G6: 3150 | H6: 1.09 | I6: =H6*DADOS_PROJETO!$B$19
A7: Dlohn | B7: Blumenau | C7: 8500 | D7: 18 | E7: 24 | F7: 2800 | G7: 3080 | H7: 1.1 | I7: =H7*DADOS_PROJETO!$B$19
A8: Eternity | B8: Itajaí | C8: 11200 | D8: 22 | E8: 30 | F8: 2850 | G8: 3420 | H8: 1.2 | I8: =H8*DADOS_PROJETO!$B$19
A9: Lorenzo | B9: Itajaí | C9: 9800 | D9: 20 | E9: 28 | F9: 2780 | G9: 3190 | H9: 1.15 | I9: =H9*DADOS_PROJETO!$B$19
A10: Monolyt | B10: Floripa | C10: 18500 | D10: 32 | E10: 42 | F10: 2900 | G10: 3480 | H10: 1.2 | I10: =H10*DADOS_PROJETO!$B$19
A11: Cota365 | B11: Floripa | C11: 10500 | D11: 24 | E11: 30 | F11: 2850 | G11: 3250 | H11: 1.14 | I11: =H11*DADOS_PROJETO!$B$19
A13: ESTE PROJETO | B13: =DADOS_PROJETO!B4 | C13: =DADOS_PROJETO!B6 | D13: =DADOS_PROJETO!B9 | E13: =DADOS_PROJETO!B17 | F13: =DADOS_PROJETO!B19 | G13: =CUSTOS_MACROGRUPO!G20/DADOS_PROJETO!B6 | H13: =(CUSTOS_MACROGRUPO!G20/DADOS_PROJETO!B6)/DADOS_PROJETO!B19 | I13: =CUSTOS_MACROGRUPO!G20/DADOS_PROJETO!B6
A15: COMPARATIVO POR MACROGRUPO (R$/m²)
A16: Macrogrupo | B16: Média Base | C16: Este Projeto | D16: Diferença %
A17: Gerenciamento | B17: 421 | C17: =CUSTOS_MACROGRUPO!F2 | D17: =(C17-B17)/B17
A18: Infraestrutura | B18: 233 | C18: =CUSTOS_MACROGRUPO!F4 | D18: =(C18-B18)/B18
A19: Supraestrutura | B19: 753 | C19: =CUSTOS_MACROGRUPO!F5 | D19: =(C19-B19)/B19
A20: Instalações | B20: 388 | C20: =CUSTOS_MACROGRUPO!F8 | D20: =(C20-B20)/B20
A21: Pisos | B21: 199 | C21: =CUSTOS_MACROGRUPO!F13 | D21: =(C21-B21)/B21
A22: Esquadrias | B22: 366 | C22: =CUSTOS_MACROGRUPO!F15 | D22: =(C22-B22)/B22
A23: Fachada | B23: 177 | C23: =CUSTOS_MACROGRUPO!F17 | D23: =(C23-B23)/B23

Sheet ANÁLISE_PRODUTO
A1: ANÁLISE DE PRODUTO
A3: Indicador | B3: Este Projeto | C3: Faixa Típica | D3: Status
A4: AC/UR (m²/UR) | B4: =DADOS_PROJETO!B6/DADOS_PROJETO!B7 | C4: 90-160 | D4: =IF(AND(B4>=90,B4<=160),"OK","ATENÇÃO")
A5: Custo/UR (R$) | B5: =CUSTOS_MACROGRUPO!G20/DADOS_PROJETO!B7 | C5: —
A6: R$/m² (R$/m²) | B6: =CUSTOS_MACROGRUPO!G20/DADOS_PROJETO!B6 | C6: —
A7: CUB Ratio | B7: =(CUSTOS_MACROGRUPO!G20/DADOS_PROJETO!B6)/DADOS_PROJETO!B19 | C7: 1.00-1.50 | D7: =IF(AND(B7>=1,B7<=1.5),"OK",IF(B7>1.5,"ALTO","BAIXO"))
A8: Vagas/UR | B8: =DADOS_PROJETO!B13/DADOS_PROJETO!B7 | C8: 1.0-2.0 | D8: =IF(AND(B8>=1,B8<=2),"OK","ATENÇÃO")
A9: % Tipo (NPT/NP) | B9: =DADOS_PROJETO!B10/DADOS_PROJETO!B9 | C9: 60-80% | D9: =IF(AND(B9>=0.6,B9<=0.8),"OK","ATENÇÃO")
A10: Elevador/UR | B10: =DADOS_PROJETO!B12/DADOS_PROJETO!B7 | C10: 0.015-0.030 | D10: =IF(AND(B10>=0.015,B10<=0.03),"OK","ATENÇÃO")

Sheet ALERTAS
A1: ALERTAS E VALIDAÇÕES
A2: Macrogrupo | B2: R$/m² Calculado | C2: Faixa Esperada | D2: Status
A3: =CUSTOS_MACROGRUPO!B2 | B3: =CUSTOS_MACROGRUPO!F2 | C3: =CUSTOS_MACROGRUPO!I2&" - "&CUSTOS_MACROGRUPO!J2 | D3: =CUSTOS_MACROGRUPO!K2
A4: =CUSTOS_MACROGRUPO!B3 | B4: =CUSTOS_MACROGRUPO!F3 | C4: =CUSTOS_MACROGRUPO!I3&" - "&CUSTOS_MACROGRUPO!J3 | D4: =CUSTOS_MACROGRUPO!K3
A5: =CUSTOS_MACROGRUPO!B4 | B5: =CUSTOS_MACROGRUPO!F4 | C5: =CUSTOS_MACROGRUPO!I4&" - "&CUSTOS_MACROGRUPO!J4 | D5: =CUSTOS_MACROGRUPO!K4
A6: =CUSTOS_MACROGRUPO!B5 | B6: =CUSTOS_MACROGRUPO!F5 | C6: =CUSTOS_MACROGRUPO!I5&" - "&CUSTOS_MACROGRUPO!J5 | D6: =CUSTOS_MACROGRUPO!K5
A7: =CUSTOS_MACROGRUPO!B6 | B7: =CUSTOS_MACROGRUPO!F6 | C7: =CUSTOS_MACROGRUPO!I6&" - "&CUSTOS_MACROGRUPO!J6 | D7: =CUSTOS_MACROGRUPO!K6
A8: =CUSTOS_MACROGRUPO!B7 | B8: =CUSTOS_MACROGRUPO!F7 | C8: =CUSTOS_MACROGRUPO!I7&" - "&CUSTOS_MACROGRUPO!J7 | D8: =CUSTOS_MACROGRUPO!K7
A9: =CUSTOS_MACROGRUPO!B8 | B9: =CUSTOS_MACROGRUPO!F8 | C9: =CUSTOS_MACROGRUPO!I8&" - "&CUSTOS_MACROGRUPO!J8 | D9: =CUSTOS_MACROGRUPO!K8
A10: =CUSTOS_MACROGRUPO!B9 | B10: =CUSTOS_MACROGRUPO!F9 | C10: =CUSTOS_MACROGRUPO!I9&" - "&CUSTOS_MACROGRUPO!J9 | D10: =CUSTOS_MACROGRUPO!K9
A11: =CUSTOS_MACROGRUPO!B10 | B11: =CUSTOS_MACROGRUPO!F10 | C11: =CUSTOS_MACROGRUPO!I10&" - "&CUSTOS_MACROGRUPO!J10 | D11: =CUSTOS_MACROGRUPO!K10
A12: =CUSTOS_MACROGRUPO!B11 | B12: =CUSTOS_MACROGRUPO!F11 | C12: =CUSTOS_MACROGRUPO!I11&" - "&CUSTOS_MACROGRUPO!J11 | D12: =CUSTOS_MACROGRUPO!K11
A13: =CUSTOS_MACROGRUPO!B12 | B13: =CUSTOS_MACROGRUPO!F12 | C13: =CUSTOS_MACROGRUPO!I12&" - "&CUSTOS_MACROGRUPO!J12 | D13: =CUSTOS_MACROGRUPO!K12
A14: =CUSTOS_MACROGRUPO!B13 | B14: =CUSTOS_MACROGRUPO!F13 | C14: =CUSTOS_MACROGRUPO!I13&" - "&CUSTOS_MACROGRUPO!J13 | D14: =CUSTOS_MACROGRUPO!K13
... A20: =CUSTOS_MACROGRUPO!B19 | B20: =CUSTOS_MACROGRUPO!F19 | C20: =CUSTOS_MACROGRUPO!I19&" - "&CUSTOS_MACROGRUPO!J19 | D20: =CUSTOS_MACROGRUPO!K19

Sheet NOTAS
A1: PREMISSAS E LIMITAÇÕES
A3: SOBRE ESTE TEMPLATE:
A4: Este orçamento paramétrico foi desenvolvido pela Cartesian Engenharia para estimativas rápidas de custos de obras residenciais/comerciais.
A6: BASE DE CALIBRAÇÃO:
A7: - Mediana calibrada com 75 projetos reais executados entre 2022-2024
A8: - Valores calibrados a valor presente (mar/2026)
A9: - Faixas P10-P90 representam variação observada nos projetos da base
A11: COMO USAR:
A12: 1. Preencha DADOS_PROJETO com informações do empreendimento
A13: 2. Responda as 25 perguntas do BRIEFING (use os dropdowns)
A14: 3. Os custos em CUSTOS_MACROGRUPO são calculados automaticamente
A15: 4. Verifique ALERTAS para validar se os valores estão dentro das faixas esperadas
... A40: www.cartesianengenharia.com
