Workbook

Sheet CAPA
B2: ORÇAMENTO EXECUTIVO COMPLETO
B5: PROJETO: | C5: Oxford 600 Residence
B6: CLIENTE: | C6: Mussi Empreendimentos
B7: ENDEREÇO: | C7: Rua Uruguai / Rua Imbituba - Centro, Itajaí/SC
B8: DATA-BASE: | C8: março/2026
B9: RESPONSÁVEL TÉCNICO: | C9: Cartesian Engenharia
B10: BDI APLICADO: | C10: 25.0%
B11: DATA DO ORÇAMENTO: | C11: 13/03/2026
B12: VERSÃO: | C12: Completa - Todas as disciplinas por pavimento
B15: DISCIPLINAS INCLUÍDAS
C16: 1. Estrutura (por pavimento)
C17: 2. Hidrossanitário (por pavimento)
C18: 3. Elétrico (por pavimento)
C19: 4. PPCI (por pavimento)
C20: 5. Vedações (por pavimento)
C21: 6. Acabamentos (por pavimento)
C22: 7. Resumo Consolidado

Sheet 1. ESTRUTURA
A1: 1. ESTRUTURA - POR PAVIMENTO
A2: Item | B2: Pavimento | C2: Descrição | D2: Unidade | E2: Quantidade | F2: Custo Unit. (R$) | G2: Custo Total (R$)
B3: Térreo
A4: 1.1 | B4: Térreo | C4: Concreto fck 30 MPa | D4: m³ | E4: 341460 | F4: 750 | G4: =E4*F4
A5: 1.2 | B5: Térreo | C5: Aço CA-50 - Armadura | D5: kg | E5: 341.46 | F5: 7.5 | G5: =E5*F5
A6: Subtotal Térreo | G6: =SUM(G4:G5)
B8: Garagem 2
A9: 1.1 | B9: Garagem 2 | C9: Concreto fck 30 MPa | D9: m³ | E9: 175840 | F9: 750 | G9: =E9*F9
A10: 1.2 | B10: Garagem 2 | C10: Aço CA-50 - Armadura | D10: kg | E10: 175.84 | F10: 7.5 | G10: =E10*F10
A11: Subtotal Garagem 2 | G11: =SUM(G9:G10)
B13: 15º Pav (Tipo 10)
A14: 1.1 | B14: 15º Pav (Tipo 10) | C14: Concreto fck 30 MPa | D14: m³ | E14: 122450 | F14: 750 | G14: =E14*F14
A15: 1.2 | B15: 15º Pav (Tipo 10) | C15: Aço CA-50 - Armadura | D15: kg | E15: 122.45 | F15: 7.5 | G15: =E15*F15
A16: Subtotal 15º Pav (Tipo 10) | G16: =SUM(G14:G15)
B18: 16º Pav (Tipo 11)
A19: 1.1 | B19: 16º Pav (Tipo 11) | C19: Concreto fck 30 MPa | D19: m³ | E19: 122450 | F19: 750 | G19: =E19*F19
A20: 1.2 | B20: 16º Pav (Tipo 11) | C20: Aço CA-50 - Armadura | D20: kg | E20: 122.45 | F20: 7.5 | G20: =E20*F20
A21: Subtotal 16º Pav (Tipo 11) | G21: =SUM(G19:G20)
B23: 17º Pav (Tipo 12)
A24: 1.1 | B24: 17º Pav (Tipo 12) | C24: Concreto fck 30 MPa | D24: m³ | E24: 122450 | F24: 750 | G24: =E24*F24
A25: 1.2 | B25: 17º Pav (Tipo 12) | C25: Aço CA-50 - Armadura | D25: kg | E25: 122.45 | F25: 7.5 | G25: =E25*F25
A26: Subtotal 17º Pav (Tipo 12) | G26: =SUM(G24:G25)
B28: 18º Pav (Tipo 13)
A29: 1.1 | B29: 18º Pav (Tipo 13) | C29: Concreto fck 30 MPa | D29: m³ | E29: 122450 | F29: 750 | G29: =E29*F29
A30: 1.2 | B30: 18º Pav (Tipo 13) | C30: Aço CA-50 - Armadura | D30: kg | E30: 122.45 | F30: 7.5 | G30: =E30*F30
A31: Subtotal 18º Pav (Tipo 13) | G31: =SUM(G29:G30)
B33: 19º Pav (Tipo 14)
A34: 1.1 | B34: 19º Pav (Tipo 14) | C34: Concreto fck 30 MPa | D34: m³ | E34: 122450 | F34: 750 | G34: =E34*F34
A35: 1.2 | B35: 19º Pav (Tipo 14) | C35: Aço CA-50 - Armadura | D35: kg | E35: 122.45 | F35: 7.5 | G35: =E35*F35
A36: Subtotal 19º Pav (Tipo 14) | G36: =SUM(G34:G35)
B38: 20º Pav (Tipo 15)
A39: 1.1 | B39: 20º Pav (Tipo 15) | C39: Concreto fck 30 MPa | D39: m³ | E39: 122450 | F39: 750 | G39: =E39*F39
A40: 1.2 | B40: 20º Pav (Tipo 15) | C40: Aço CA-50 - Armadura | D40: kg | E40: 122.45 | F40: 7.5 | G40: =E40*F40
A41: Subtotal 20º Pav (Tipo 15) | G41: =SUM(G39:G40)
B43: 21º Pav (Tipo 16)
A44: 1.1 | B44: 21º Pav (Tipo 16) | C44: Concreto fck 30 MPa | D44: m³ | E44: 122450 | F44: 750 | G44: =E44*F44
A45: 1.2 | B45: 21º Pav (Tipo 16) | C45: Aço CA-50 - Armadura | D45: kg | E45: 122.45 | F45: 7.5 | G45: =E45*F45
A46: Subtotal 21º Pav (Tipo 16) | G46: =SUM(G44:G45)
B48: 22º Pav (Tipo 17)
A49: 1.1 | B49: 22º Pav (Tipo 17) | C49: Concreto fck 30 MPa | D49: m³ | E49: 122450 | F49: 750 | G49: =E49*F49
...

Sheet 2. HIDROSSANITÁRIO
A1: 2. HIDROSSANITÁRIO - POR PAVIMENTO
A2: Item | B2: Pavimento | C2: Descrição | D2: Unidade | E2: Quantidade | F2: Custo Unit. (R$) | G2: Custo Total (R$)
B3: Térreo
A4: 2.1 | B4: Térreo | C4: Tubulações PVC Esgoto DN 50mm | D4: m | E4: 85 | F4: 12 | G4: =E4*F4
A5: 2.2 | B5: Térreo | C5: Tubulações PVC Esgoto DN 100mm | D5: m | E5: 45 | F5: 22 | G5: =E5*F5
A6: 2.3 | B6: Térreo | C6: Joelhos e Conexões PVC 50mm | D6: pç | E6: 45 | F6: 2.5 | G6: =E6*F6
A7: 2.4 | B7: Térreo | C7: Caixas Sifonadas 150x150x50 | D7: pç | E7: 12 | F7: 45 | G7: =E7*F7
A8: Subtotal Térreo | G8: =SUM(G4:G7)
B10: Garagem 2
A11: 2.1 | B11: Garagem 2 | C11: Tubulações PVC Esgoto DN 50mm | D11: m | E11: 25.5 | F11: 12 | G11: =E11*F11
A12: 2.2 | B12: Garagem 2 | C12: Tubulações PVC Esgoto DN 100mm | D12: m | E12: 13.5 | F12: 22 | G12: =E12*F12
A13: 2.3 | B13: Garagem 2 | C13: Joelhos e Conexões PVC 50mm | D13: pç | E13: 13.5 | F13: 2.5 | G13: =E13*F13
A14: 2.4 | B14: Garagem 2 | C14: Caixas Sifonadas 150x150x50 | D14: pç | E14: 3.6 | F14: 45 | G14: =E14*F14
A15: Subtotal Garagem 2 | G15: =SUM(G11:G14)
B17: Garagem 3
A18: 2.1 | B18: Garagem 3 | C18: Tubulações PVC Esgoto DN 50mm | D18: m | E18: 25.5 | F18: 12 | G18: =E18*F18
A19: 2.2 | B19: Garagem 3 | C19: Tubulações PVC Esgoto DN 100mm | D19: m | E19: 13.5 | F19: 22 | G19: =E19*F19
A20: 2.3 | B20: Garagem 3 | C20: Joelhos e Conexões PVC 50mm | D20: pç | E20: 13.5 | F20: 2.5 | G20: =E20*F20
A21: 2.4 | B21: Garagem 3 | C21: Caixas Sifonadas 150x150x50 | D21: pç | E21: 3.6 | F21: 45 | G21: =E21*F21
A22: Subtotal Garagem 3 | G22: =SUM(G18:G21)
B24: Garagem 4
A25: 2.1 | B25: Garagem 4 | C25: Tubulações PVC Esgoto DN 50mm | D25: m | E25: 25.5 | F25: 12 | G25: =E25*F25
A26: 2.2 | B26: Garagem 4 | C26: Tubulações PVC Esgoto DN 100mm | D26: m | E26: 13.5 | F26: 22 | G26: =E26*F26
A27: 2.3 | B27: Garagem 4 | C27: Joelhos e Conexões PVC 50mm | D27: pç | E27: 13.5 | F27: 2.5 | G27: =E27*F27
A28: 2.4 | B28: Garagem 4 | C28: Caixas Sifonadas 150x150x50 | D28: pç | E28: 3.6 | F28: 45 | G28: =E28*F28
A29: Subtotal Garagem 4 | G29: =SUM(G25:G28)
B31: Garagem 5
A32: 2.1 | B32: Garagem 5 | C32: Tubulações PVC Esgoto DN 50mm | D32: m | E32: 25.5 | F32: 12 | G32: =E32*F32
A33: 2.2 | B33: Garagem 5 | C33: Tubulações PVC Esgoto DN 100mm | D33: m | E33: 13.5 | F33: 22 | G33: =E33*F33
A34: 2.3 | B34: Garagem 5 | C34: Joelhos e Conexões PVC 50mm | D34: pç | E34: 13.5 | F34: 2.5 | G34: =E34*F34
A35: 2.4 | B35: Garagem 5 | C35: Caixas Sifonadas 150x150x50 | D35: pç | E35: 3.6 | F35: 45 | G35: =E35*F35
A36: Subtotal Garagem 5 | G36: =SUM(G32:G35)
B38: Lazer (6º)
A39: 2.1 | B39: Lazer (6º) | C39: Tubulações PVC Esgoto DN 50mm | D39: m | E39: 102 | F39: 12 | G39: =E39*F39
A40: 2.2 | B40: Lazer (6º) | C40: Tubulações PVC Esgoto DN 100mm | D40: m | E40: 54 | F40: 22 | G40: =E40*F40
A41: 2.3 | B41: Lazer (6º) | C41: Joelhos e Conexões PVC 50mm | D41: pç | E41: 54 | F41: 2.5 | G41: =E41*F41
A42: 2.4 | B42: Lazer (6º) | C42: Caixas Sifonadas 150x150x50 | D42: pç | E42: 14.4 | F42: 45 | G42: =E42*F42
A43: Subtotal Lazer (6º) | G43: =SUM(G39:G42)
B45: 7º Pav (Tipo 2)
A46: 2.1 | B46: 7º Pav (Tipo 2) | C46: Tubulações PVC Esgoto DN 50mm | D46: m | E46: 85 | F46: 12 | G46: =E46*F46
...

Sheet 3. ELÉTRICO
A1: 3. ELÉTRICO - POR PAVIMENTO
A2: Item | B2: Pavimento | C2: Descrição | D2: Unidade | E2: Quantidade | F2: Custo Unit. (R$) | G2: Custo Total (R$)
B3: Térreo
A4: 3.1 | B4: Térreo | C4: Quadros de Distribuição | D4: un | E4: 4 | F4: 1200 | G4: =E4*F4
A5: 3.2 | B5: Térreo | C5: Disjuntores Monopolares | D5: un | E5: 35 | F5: 35 | G5: =E5*F5
A6: 3.3 | B6: Térreo | C6: Disjuntores Bipolares | D6: un | E6: 12 | F6: 65 | G6: =E6*F6
A7: 3.4 | B7: Térreo | C7: DRs Bipolares 30mA | D7: un | E7: 8 | F7: 180 | G7: =E7*F7
A8: 3.5 | B8: Térreo | C8: Eletrodutos PVC 25mm | D8: m | E8: 220 | F8: 8 | G8: =E8*F8
A9: 3.6 | B9: Térreo | C9: Cabos de Cobre 2,5mm² | D9: m | E9: 450 | F9: 4.5 | G9: =E9*F9
A10: Subtotal Térreo | G10: =SUM(G4:G9)
B12: Garagem 2
A13: 3.1 | B13: Garagem 2 | C13: Quadros de Distribuição | D13: un | E13: 1.6 | F13: 1200 | G13: =E13*F13
A14: 3.2 | B14: Garagem 2 | C14: Disjuntores Monopolares | D14: un | E14: 14 | F14: 35 | G14: =E14*F14
A15: 3.3 | B15: Garagem 2 | C15: Disjuntores Bipolares | D15: un | E15: 4.8 | F15: 65 | G15: =E15*F15
A16: 3.4 | B16: Garagem 2 | C16: DRs Bipolares 30mA | D16: un | E16: 3.2 | F16: 180 | G16: =E16*F16
A17: 3.5 | B17: Garagem 2 | C17: Eletrodutos PVC 25mm | D17: m | E17: 88 | F17: 8 | G17: =E17*F17
A18: 3.6 | B18: Garagem 2 | C18: Cabos de Cobre 2,5mm² | D18: m | E18: 180 | F18: 4.5 | G18: =E18*F18
A19: Subtotal Garagem 2 | G19: =SUM(G13:G18)
B21: Garagem 3
A22: 3.1 | B22: Garagem 3 | C22: Quadros de Distribuição | D22: un | E22: 1.6 | F22: 1200 | G22: =E22*F22
A23: 3.2 | B23: Garagem 3 | C23: Disjuntores Monopolares | D23: un | E23: 14 | F23: 35 | G23: =E23*F23
A24: 3.3 | B24: Garagem 3 | C24: Disjuntores Bipolares | D24: un | E24: 4.8 | F24: 65 | G24: =E24*F24
A25: 3.4 | B25: Garagem 3 | C25: DRs Bipolares 30mA | D25: un | E25: 3.2 | F25: 180 | G25: =E25*F25
A26: 3.5 | B26: Garagem 3 | C26: Eletrodutos PVC 25mm | D26: m | E26: 88 | F26: 8 | G26: =E26*F26
A27: 3.6 | B27: Garagem 3 | C27: Cabos de Cobre 2,5mm² | D27: m | E27: 180 | F27: 4.5 | G27: =E27*F27
A28: Subtotal Garagem 3 | G28: =SUM(G22:G27)
B30: Garagem 4
A31: 3.1 | B31: Garagem 4 | C31: Quadros de Distribuição | D31: un | E31: 1.6 | F31: 1200 | G31: =E31*F31
A32: 3.2 | B32: Garagem 4 | C32: Disjuntores Monopolares | D32: un | E32: 14 | F32: 35 | G32: =E32*F32
A33: 3.3 | B33: Garagem 4 | C33: Disjuntores Bipolares | D33: un | E33: 4.8 | F33: 65 | G33: =E33*F33
A34: 3.4 | B34: Garagem 4 | C34: DRs Bipolares 30mA | D34: un | E34: 3.2 | F34: 180 | G34: =E34*F34
A35: 3.5 | B35: Garagem 4 | C35: Eletrodutos PVC 25mm | D35: m | E35: 88 | F35: 8 | G35: =E35*F35
A36: 3.6 | B36: Garagem 4 | C36: Cabos de Cobre 2,5mm² | D36: m | E36: 180 | F36: 4.5 | G36: =E36*F36
A37: Subtotal Garagem 4 | G37: =SUM(G31:G36)
B39: Garagem 5
A40: 3.1 | B40: Garagem 5 | C40: Quadros de Distribuição | D40: un | E40: 1.6 | F40: 1200 | G40: =E40*F40
A41: 3.2 | B41: Garagem 5 | C41: Disjuntores Monopolares | D41: un | E41: 14 | F41: 35 | G41: =E41*F41
A42: 3.3 | B42: Garagem 5 | C42: Disjuntores Bipolares | D42: un | E42: 4.8 | F42: 65 | G42: =E42*F42
A43: 3.4 | B43: Garagem 5 | C43: DRs Bipolares 30mA | D43: un | E43: 3.2 | F43: 180 | G43: =E43*F43
A44: 3.5 | B44: Garagem 5 | C44: Eletrodutos PVC 25mm | D44: m | E44: 88 | F44: 8 | G44: =E44*F44
...

Sheet 4. PPCI
A1: 4. PPCI - POR PAVIMENTO
A2: Item | B2: Pavimento | C2: Descrição | D2: Unidade | E2: Quantidade | F2: Custo Unit. (R$) | G2: Custo Total (R$)
B3: Térreo
A4: 4.1 | B4: Térreo | C4: Hidrante DN 65 Completo | D4: un | E4: 1 | F4: 1800 | G4: =E4*F4
A5: 4.2 | B5: Térreo | C5: Detector de Fumaça Endereçável | D5: un | E5: 4 | F5: 380 | G5: =E5*F5
A6: Subtotal Térreo | G6: =SUM(G4:G5)
B8: Garagem 2
A9: 4.2 | B9: Garagem 2 | C9: Detector de Fumaça Endereçável | D9: un | E9: 6 | F9: 380 | G9: =E9*F9
A10: Subtotal Garagem 2 | G10: =SUM(G9:G9)
B12: Garagem 3
A13: 4.2 | B13: Garagem 3 | C13: Detector de Fumaça Endereçável | D13: un | E13: 6 | F13: 380 | G13: =E13*F13
A14: Subtotal Garagem 3 | G14: =SUM(G13:G13)
B16: Garagem 4
A17: 4.2 | B17: Garagem 4 | C17: Detector de Fumaça Endereçável | D17: un | E17: 6 | F17: 380 | G17: =E17*F17
A18: Subtotal Garagem 4 | G18: =SUM(G17:G17)
B20: Garagem 5
A21: 4.2 | B21: Garagem 5 | C21: Detector de Fumaça Endereçável | D21: un | E21: 6 | F21: 380 | G21: =E21*F21
A22: Subtotal Garagem 5 | G22: =SUM(G21:G21)
B24: Lazer (6º)
A25: 4.1 | B25: Lazer (6º) | C25: Hidrante DN 65 Completo | D25: un | E25: 1 | F25: 1800 | G25: =E25*F25
A26: 4.2 | B26: Lazer (6º) | C26: Detector de Fumaça Endereçável | D26: un | E26: 4 | F26: 380 | G26: =E26*F26
A27: Subtotal Lazer (6º) | G27: =SUM(G25:G26)
B29: 7º Pav (Tipo 2)
A30: 4.1 | B30: 7º Pav (Tipo 2) | C30: Hidrante DN 65 Completo | D30: un | E30: 1 | F30: 1800 | G30: =E30*F30
A31: 4.2 | B31: 7º Pav (Tipo 2) | C31: Detector de Fumaça Endereçável | D31: un | E31: 8 | F31: 380 | G31: =E31*F31
A32: Subtotal 7º Pav (Tipo 2) | G32: =SUM(G30:G31)
B34: 8º Pav (Tipo 3)
A35: 4.1 | B35: 8º Pav (Tipo 3) | C35: Hidrante DN 65 Completo | D35: un | E35: 1 | F35: 1800 | G35: =E35*F35
A36: 4.2 | B36: 8º Pav (Tipo 3) | C36: Detector de Fumaça Endereçável | D36: un | E36: 8 | F36: 380 | G36: =E36*F36
A37: Subtotal 8º Pav (Tipo 3) | G37: =SUM(G35:G36)
B39: 9º Pav (Tipo 4)
A40: 4.1 | B40: 9º Pav (Tipo 4) | C40: Hidrante DN 65 Completo | D40: un | E40: 1 | F40: 1800 | G40: =E40*F40
A41: 4.2 | B41: 9º Pav (Tipo 4) | C41: Detector de Fumaça Endereçável | D41: un | E41: 8 | F41: 380 | G41: =E41*F41
A42: Subtotal 9º Pav (Tipo 4) | G42: =SUM(G40:G41)
B44: 10º Pav (Tipo 5)
A45: 4.1 | B45: 10º Pav (Tipo 5) | C45: Hidrante DN 65 Completo | D45: un | E45: 1 | F45: 1800 | G45: =E45*F45
A46: 4.2 | B46: 10º Pav (Tipo 5) | C46: Detector de Fumaça Endereçável | D46: un | E46: 8 | F46: 380 | G46: =E46*F46
A47: Subtotal 10º Pav (Tipo 5) | G47: =SUM(G45:G46)
B49: 11º Pav (Tipo 6)
A50: 4.1 | B50: 11º Pav (Tipo 6) | C50: Hidrante DN 65 Completo | D50: un | E50: 1 | F50: 1800 | G50: =E50*F50
...

Sheet 5. VEDAÇÕES
A1: 5. VEDAÇÕES - POR PAVIMENTO
A2: Item | B2: Pavimento | C2: Descrição | D2: Unidade | E2: Quantidade | F2: Custo Unit. (R$) | G2: Custo Total (R$)
B3: Térreo
A4: 5.1 | B4: Térreo | C4: Alvenaria Bloco Cerâmico 14x19x29 | D4: m² | E4: 180 | F4: 35 | G4: =E4*F4
A5: 5.2 | B5: Térreo | C5: Chapisco | D5: m² | E5: 360 | F5: 8.5 | G5: =E5*F5
A6: 5.3 | B6: Térreo | C6: Reboco Paulista | D6: m² | E6: 360 | F6: 28 | G6: =E6*F6
A7: Subtotal Térreo | G7: =SUM(G4:G6)
B9: Garagem 2
A10: 5.1 | B10: Garagem 2 | C10: Alvenaria Bloco Cerâmico 14x19x29 | D10: m² | E10: 36 | F10: 35 | G10: =E10*F10
A11: 5.2 | B11: Garagem 2 | C11: Chapisco | D11: m² | E11: 72 | F11: 8.5 | G11: =E11*F11
A12: 5.3 | B12: Garagem 2 | C12: Reboco Paulista | D12: m² | E12: 72 | F12: 28 | G12: =E12*F12
A13: Subtotal Garagem 2 | G13: =SUM(G10:G12)
B15: Garagem 3
A16: 5.1 | B16: Garagem 3 | C16: Alvenaria Bloco Cerâmico 14x19x29 | D16: m² | E16: 36 | F16: 35 | G16: =E16*F16
A17: 5.2 | B17: Garagem 3 | C17: Chapisco | D17: m² | E17: 72 | F17: 8.5 | G17: =E17*F17
A18: 5.3 | B18: Garagem 3 | C18: Reboco Paulista | D18: m² | E18: 72 | F18: 28 | G18: =E18*F18
A19: Subtotal Garagem 3 | G19: =SUM(G16:G18)
B21: Garagem 4
A22: 5.1 | B22: Garagem 4 | C22: Alvenaria Bloco Cerâmico 14x19x29 | D22: m² | E22: 36 | F22: 35 | G22: =E22*F22
A23: 5.2 | B23: Garagem 4 | C23: Chapisco | D23: m² | E23: 72 | F23: 8.5 | G23: =E23*F23
A24: 5.3 | B24: Garagem 4 | C24: Reboco Paulista | D24: m² | E24: 72 | F24: 28 | G24: =E24*F24
A25: Subtotal Garagem 4 | G25: =SUM(G22:G24)
B27: Garagem 5
A28: 5.1 | B28: Garagem 5 | C28: Alvenaria Bloco Cerâmico 14x19x29 | D28: m² | E28: 36 | F28: 35 | G28: =E28*F28
A29: 5.2 | B29: Garagem 5 | C29: Chapisco | D29: m² | E29: 72 | F29: 8.5 | G29: =E29*F29
A30: 5.3 | B30: Garagem 5 | C30: Reboco Paulista | D30: m² | E30: 72 | F30: 28 | G30: =E30*F30
A31: Subtotal Garagem 5 | G31: =SUM(G28:G30)
B33: Lazer (6º)
A34: 5.1 | B34: Lazer (6º) | C34: Alvenaria Bloco Cerâmico 14x19x29 | D34: m² | E34: 180 | F34: 35 | G34: =E34*F34
A35: 5.2 | B35: Lazer (6º) | C35: Chapisco | D35: m² | E35: 360 | F35: 8.5 | G35: =E35*F35
A36: 5.3 | B36: Lazer (6º) | C36: Reboco Paulista | D36: m² | E36: 360 | F36: 28 | G36: =E36*F36
A37: Subtotal Lazer (6º) | G37: =SUM(G34:G36)
B39: 7º Pav (Tipo 2)
A40: 5.1 | B40: 7º Pav (Tipo 2) | C40: Alvenaria Bloco Cerâmico 14x19x29 | D40: m² | E40: 180 | F40: 35 | G40: =E40*F40
A41: 5.2 | B41: 7º Pav (Tipo 2) | C41: Chapisco | D41: m² | E41: 360 | F41: 8.5 | G41: =E41*F41
A42: 5.3 | B42: 7º Pav (Tipo 2) | C42: Reboco Paulista | D42: m² | E42: 360 | F42: 28 | G42: =E42*F42
A43: Subtotal 7º Pav (Tipo 2) | G43: =SUM(G40:G42)
B45: 8º Pav (Tipo 3)
A46: 5.1 | B46: 8º Pav (Tipo 3) | C46: Alvenaria Bloco Cerâmico 14x19x29 | D46: m² | E46: 180 | F46: 35 | G46: =E46*F46
A47: 5.2 | B47: 8º Pav (Tipo 3) | C47: Chapisco | D47: m² | E47: 360 | F47: 8.5 | G47: =E47*F47
...

Sheet 6. ACABAMENTOS
A1: 6. ACABAMENTOS - POR PAVIMENTO
A2: Item | B2: Pavimento | C2: Descrição | D2: Unidade | E2: Quantidade | F2: Custo Unit. (R$) | G2: Custo Total (R$)
B3: Térreo
A4: 6.1 | B4: Térreo | C4: Piso Cerâmico Padrão Alto | D4: m² | E4: 170 | F4: 48 | G4: =E4*F4
A5: 6.2 | B5: Térreo | C5: Pintura Látex Acrílica (paredes + teto) | D5: m² | E5: 765 | F5: 18 | G5: =E5*F5
A6: Subtotal Térreo | G6: =SUM(G4:G5)
B8: Garagem 2
A9: 6.1 | B9: Garagem 2 | C9: Piso Cerâmico Padrão Alto | D9: m² | E9: 136 | F9: 48 | G9: =E9*F9
A10: 6.2 | B10: Garagem 2 | C10: Pintura Látex Acrílica (paredes + teto) | D10: m² | E10: 612 | F10: 18 | G10: =E10*F10
A11: Subtotal Garagem 2 | G11: =SUM(G9:G10)
B13: Garagem 3
A14: 6.1 | B14: Garagem 3 | C14: Piso Cerâmico Padrão Alto | D14: m² | E14: 136 | F14: 48 | G14: =E14*F14
A15: 6.2 | B15: Garagem 3 | C15: Pintura Látex Acrílica (paredes + teto) | D15: m² | E15: 612 | F15: 18 | G15: =E15*F15
A16: Subtotal Garagem 3 | G16: =SUM(G14:G15)
B18: Garagem 4
A19: 6.1 | B19: Garagem 4 | C19: Piso Cerâmico Padrão Alto | D19: m² | E19: 136 | F19: 48 | G19: =E19*F19
A20: 6.2 | B20: Garagem 4 | C20: Pintura Látex Acrílica (paredes + teto) | D20: m² | E20: 612 | F20: 18 | G20: =E20*F20
A21: Subtotal Garagem 4 | G21: =SUM(G19:G20)
B23: Garagem 5
A24: 6.1 | B24: Garagem 5 | C24: Piso Cerâmico Padrão Alto | D24: m² | E24: 136 | F24: 48 | G24: =E24*F24
A25: 6.2 | B25: Garagem 5 | C25: Pintura Látex Acrílica (paredes + teto) | D25: m² | E25: 612 | F25: 18 | G25: =E25*F25
A26: Subtotal Garagem 5 | G26: =SUM(G24:G25)
B28: Lazer (6º)
A29: 6.1 | B29: Lazer (6º) | C29: Piso Cerâmico Padrão Alto | D29: m² | E29: 170 | F29: 48 | G29: =E29*F29
A30: 6.2 | B30: Lazer (6º) | C30: Pintura Látex Acrílica (paredes + teto) | D30: m² | E30: 765 | F30: 18 | G30: =E30*F30
A31: Subtotal Lazer (6º) | G31: =SUM(G29:G30)
B33: 7º Pav (Tipo 2)
A34: 6.1 | B34: 7º Pav (Tipo 2) | C34: Piso Cerâmico Padrão Alto | D34: m² | E34: 170 | F34: 48 | G34: =E34*F34
A35: 6.2 | B35: 7º Pav (Tipo 2) | C35: Pintura Látex Acrílica (paredes + teto) | D35: m² | E35: 765 | F35: 18 | G35: =E35*F35
A36: Subtotal 7º Pav (Tipo 2) | G36: =SUM(G34:G35)
B38: 8º Pav (Tipo 3)
A39: 6.1 | B39: 8º Pav (Tipo 3) | C39: Piso Cerâmico Padrão Alto | D39: m² | E39: 170 | F39: 48 | G39: =E39*F39
A40: 6.2 | B40: 8º Pav (Tipo 3) | C40: Pintura Látex Acrílica (paredes + teto) | D40: m² | E40: 765 | F40: 18 | G40: =E40*F40
A41: Subtotal 8º Pav (Tipo 3) | G41: =SUM(G39:G40)
B43: 9º Pav (Tipo 4)
A44: 6.1 | B44: 9º Pav (Tipo 4) | C44: Piso Cerâmico Padrão Alto | D44: m² | E44: 170 | F44: 48 | G44: =E44*F44
A45: 6.2 | B45: 9º Pav (Tipo 4) | C45: Pintura Látex Acrílica (paredes + teto) | D45: m² | E45: 765 | F45: 18 | G45: =E45*F45
A46: Subtotal 9º Pav (Tipo 4) | G46: =SUM(G44:G45)
B48: 10º Pav (Tipo 5)
A49: 6.1 | B49: 10º Pav (Tipo 5) | C49: Piso Cerâmico Padrão Alto | D49: m² | E49: 170 | F49: 48 | G49: =E49*F49
...

Sheet 7. RESUMO GERAL
A1: RESUMO GERAL - CONSOLIDADO
A2: Item | B2: Pavimento | C2: Descrição | D2: Unidade | E2: Quantidade | F2: Custo Unit. (R$) | G2: Custo Total (R$)
A3: 1 | C3: ESTRUTURA | G3: ='1. ESTRUTURA'!G1000
A5: 2 | C5: HIDROSSANITÁRIO | G5: ='2. HIDROSSANITÁRIO'!G1000
A7: 3 | C7: ELÉTRICO | G7: ='3. ELÉTRICO'!G1000
A9: 4 | C9: PPCI | G9: ='4. PPCI'!G1000
A11: 5 | C11: VEDAÇÕES | G11: ='5. VEDAÇÕES'!G1000
A13: 6 | C13: ACABAMENTOS | G13: ='6. ACABAMENTOS'!G1000
A16: TOTAL GERAL (SEM BDI) | G16: =G3+G5+G7+G9+G11+G13
A18: TOTAL COM BDI 25.0% | G18: =G16*(1+0.25)
