Workbook
Name \0: #REF!
Name \1: #REF!
Name \a: #REF!
Name \b: #REF!
Name \c: #REF!
Name \d: #REF!
Name \e: #REF!
Name \i: #REF!
Name \J: #REF!
Name \k: #REF!
Name \l: #N/A
Name \m: #REF!
Name \o: #REF!
Name \p: #REF!
Name \r: #REF!
Name \T: #REF!
Name \z: #REF!
Name ______ACR10: #REF!
Name ______ACR15: #REF!
Name ______acr20: #REF!
Name ______acr5: #REF!
Name ______ARQ1: #REF!
Name ______QT100: #REF!
Name ______QT2: #REF!
Name ______QT3: #REF!
Name ______QT4: #REF!
Name ______QT50: #REF!
Name ______QT75: #REF!
Name _____ACR10: #REF!
Name _____ACR15: #REF!
Name _____acr20: #REF!
Name _____acr5: #REF!
Name _____ARQ1: #REF!
Name _____QT100: #REF!
Name _____QT2: #REF!
Name _____QT3: #REF!
Name _____QT4: #REF!
Name _____QT50: #REF!
Name _____QT75: #REF!
Name ___ACR10: #REF!
Name ___ACR15: #REF!
Name ___acr20: #REF!
Name ___acr5: #REF!
Name ___ARQ1: #REF!
Name ___QT100: #REF!
Name ___QT2: #REF!
Name ___QT3: #REF!
Name ___QT4: #REF!
Name ___QT50: #REF!
Name ___QT75: #REF!
Name __ACR10: #REF!
Name __ACR15: #REF!
Name __acr20: #REF!
Name __acr5: #REF!
Name __ARQ1: #REF!
Name __Axe3: #REF!
Name __Axe4: #REF!
Name __htm2: #REF!
Name __htn2: #REF!
Name __iss2: #REF!

Sheet Planilha1
E2: Orçamento
A5: Obra | D5: 2 - Moradas do Atalaia - Custo Direto
A6: Unidade construtiva | D6: 2 - GERENCIAMENTO EXECUTIVO
A7: Tipo de obra | D7: 1 - Construção Civil
A8: Endereço da obra | D8: Rua Lila Heusi - Fazendinha - Itajaí/SC - 88306-023
A9: Versão do orçamento | D9: 2 - 15/09/2022 - 15:24:23 - Versão 2 do orçamento | L9: Data base | V9: 15/09/2022
A10: BDI | D10: não aplicado | L10: Encargos sociais | V10: não aplicado
A11: Preços expressos em | D11: R$ (REAL)
A13: Código | B13: Descrição | N13: Un. | Q13: Quantidade orçada | W13: Preço unitário | AC13: Preço total
A14: 01 | B14: MOVIMENTAÇÃO DE TERRA | AC14: 117226.62
A15: 01.001 | B15: MOVIMENTAÇÃO DE TERRA | AC15: 117226.62
A16: 01.001.001 | B16: Corte e aterro | AC16: 37350
A17: 01.001.001.001 | B17: Escavação Mecânica de Solo Exceto Rocha até 4m | N17: m3 | Q17: 747 | W17: 50 | AC17: 37350
A18: 01.001.002 | B18: Escavação e Reaterro de Valas | AC18: 65174.99
A19: 01.001.002.001 | B19: Escavação Mecânica de blocos, baldrames, sapatas e cortinas | N19: m3 | Q19: 1116.14 | W19: 50 | AC19: 55807
A20: 01.001.002.002 | B20: Reaterro Compactado de blocos, baldrames e sapatas | N20: m3 | Q20: 690.03 | W20: 13.5762 | AC20: 9367.99
A21: 01.001.003 | B21: Movimentação de bota - fora | AC21: 14701.63
A22: 01.001.003.001 | B22: Movimentação de terra para bota-fora de escavação | N22: m3 | Q22: 980.03 | W22: 15.0012 | AC22: 14701.63
A23: 02 | B23: CONTENÇÃO | AC23: 386506.36
A24: 02.001 | B24: CONTENÇÃO | AC24: 386506.36
A25: 02.001.001 | B25: Forma | AC25: 142926.93
A26: 02.001.001.001 | B26: Fabricação, montagem e desmontagem de fôrma para cortina de contenção, em chapa de madeira compensada plastificada, e = 20mm | N26: m2 | Q26: 610.01 | W26: 234.3026 | AC26: 142926.93
A27: 02.001.002 | B27: Armadura | AC27: 73313.8
A28: 02.001.002.001 | B28: Armação aço CA-60 ø 5mm para cortina de contenção em concreto armado (corte e dobra em indústria) | N28: kg | Q28: 1 | W28: 10.7041 | AC28: 10.7 | AF28: =SUM(Q28:V33)/Q35 -> 125.36532
A29: 02.001.002.002 | B29: Armação aço CA-50 ø 8mm para cortina de contenção em concreto armado (corte e dobra em indústria) | N29: kg | Q29: 903.45 | W29: 8.2 | AC29: 7408.29
A30: 02.001.002.003 | B30: Armação aço CA-50 ø 10mm para cortina de contenção em concreto armado (corte e dobra em indústria) | N30: kg | Q30: 2885.82 | W30: 7.751 | AC30: 22367.99
A31: 02.001.002.004 | B31: Armação aço CA-50 ø 12,5mm para cortina de contenção em concreto armado (corte e dobra em indústria) | N31: kg | Q31: 5303.27 | W31: 7.3202 | AC31: 38821
A32: 02.001.002.005 | B32: Armação aço CA-50 ø 16mm de cortina de contenção em concreto armado (corte e dobra em indústria) | N32: kg | Q32: 468.45 | W32: 7.2024 | AC32: 3373.96
A33: 02.001.002.006 | B33: Armação aço CA-50 ø 20mm de cortina de contenção em concreto armado (corte e dobra em indústria) | N33: kg | Q33: 183.91 | W33: 7.2419 | AC33: 1331.86
A34: 02.001.003 | B34: Concreto | AC34: 46360.4
A35: 02.001.003.001 | B35: Concretagem de cortina de contenção, através de bomba - lançamento, adensamento e acabamento, concreto Fck 35MPa | N35: m3 | Q35: 77.74 | W35: 596.352 | AC35: 46360.4
A36: 02.001.004 | B36: Mão de obra | AC36: 123905.23
A37: 02.001.004.001 | B37: Mão de obra para execução de cortina de contenção | N37: m2 | Q37: 610.01 | W37: 203.12 | AC37: 123905.23 | AF37: Custo indexado do Central Park
A38: 03 | B38: INFRAESTRUTURA | AC38: 1241122.3
A39: 03.001 | B39: FUNDAÇÃO PROFUNDA | AC39: 485558.05 | AF39: =AC39/ORÇAMENTO_EXECUTIVO!$N$3 -> 65.845701
A40: 03.001.001 | B40: Perfuração | AC40: 151056
A41: 03.001.001.001 | B41: Taxa de mobilização/desmobilização | N41: vb | Q41: 1 | W41: 10000 | AC41: 10000
A42: 03.001.001.002 | B42: Estacas Hélice 50cm | N42: m | Q42: 544 | W42: 95 | AC42: 51680
A43: 03.001.001.003 | B43: Estacas Hélice 60cm | N43: m | Q43: 784 | W43: 114 | AC43: 89376
A44: 03.001.002 | B44: Armadura | AC44: 71059.82
...

Sheet Relatório
E2: Orçamento
E3: Resumo por Células Construtivas
A6: Obra | D6: 2 - Moradas do Atalaia - Custo Direto
A7: Unidade construtiva | D7: 2 - GERENCIAMENTO EXECUTIVO
A8: Tipo de obra | D8: 1 - Construção Civil
A9: Endereço da obra | D9: Rua Lila Heusi - Fazendinha - Itajaí/SC - 88306-023
A10: Versão do orçamento | D10: 2 - 15/09/2022 - 15:24:23 - Versão 2 do orçamento | L10: Data base | V10: 15/09/2022
A11: BDI | D11: não aplicado | L11: Encargos sociais | V11: não aplicado
A12: Preços expressos em | D12: R$ (REAL)
A14: Código | C14: Descrição | X14: Preço total | AE14: % Total
A15: 01 | C15: MOVIMENTAÇÃO DE TERRA | X15: 117226.62 | AE15: =X15/$X$52 -> 0.0045656717
A16: 02 | C16: CONTENÇÃO | X16: 422085.8 | AE16: =X16/$X$52 -> 0.016439143
A17: 03 | C17: INFRAESTRUTURA | X17: 1278806.1 | AE17: =X17/$X$52 -> 0.049806171
A18: 04 | C18: SUPRAESTRUTURA | X18: 5154482.2 | AE18: =X18/$X$52 -> 0.20075367
A19: 05 | C19: PAREDES E PAINÉIS | X19: 910813.58 | AE19: =X19/$X$52 -> 0.035473818
A20: 06 | C20: IMPERMEABILIZAÇÃO E TRATAMENTOS | X20: 482376.84 | AE20: =X20/$X$52 -> 0.018787322 | AF20: =(X21+X22+X23) -> 2506878.9
A21: 07 | C21: SISTEMAS E INSTALAÇÕES HIDROSSANITÁRIAS E DRENAGEM | X21: 932074.24 | AE21: =X21/$X$52 -> 0.036301865 | AF21: =(X21+X22+X23)/ORÇAMENTO_EXECUTIVO!N3 -> 339.95358
A22: 08 | C22: SISTEMAS E INSTALAÇÕES ELÉTRICAS | X22: 1224359.4 | AE22: =X22/$X$52 -> 0.047685612
A23: 09 | C23: INSTALAÇÕES PREVENTIVAS E GLP | X23: 350445.22 | AE23: =X23/$X$52 -> 0.013648929
A24: 10 | C24: INSTALAÇÕES DE COMUNICAÇÕES | X24: 145376.22 | AE24: =X24/$X$52 -> 0.0056620254 | AF24: =X24/ORÇAMENTO_EXECUTIVO!$N$3 -> 19.714222
A25: 11 | C25: EQUIPAMENTOS E SISTEMAS ESPECIAIS | X25: 817781.32 | AE25: =X25/$X$52 -> 0.031850454 | AF25: =X25/ORÇAMENTO_EXECUTIVO!$N$3 -> 110.89793
A26: 12 | C26: CLIMATIZAÇÃO, EXAUSTÃO MECÂNICA E PRESSURIZAÇÃO | X26: 216600 | AE26: =X26/$X$52 -> 0.0084360062 | AF26: =X26/ORÇAMENTO_EXECUTIVO!$N$3 -> 29.372757
A27: 13 | C27: REVESTIMENTOS INTERNOS DE PAREDE | X27: 1159047.7 | AE27: =X27/$X$52 -> 0.045141892 | AF27: =X27/ORÇAMENTO_EXECUTIVO!$N$3 -> 157.17649
A28: 14 | C28: REVESTIMENTOS E ACABAMENTOS INTERNOS EM TETO | X28: 405459.35 | AE28: =X28/$X$52 -> 0.015791586 | AF28: =X28/ORÇAMENTO_EXECUTIVO!$N$3 -> 54.983652
A29: 15 | C29: PISOS E PAVIMENTAÇÕES | X29: 1762646.2 | AE29: =X29/$X$52 -> 0.068650481 | AF29: =X29/ORÇAMENTO_EXECUTIVO!$N$3 -> 239.02945
A30: 16 | C30: SISTEMAS DE PINTURA INTERNA | X30: 995637.62 | AE30: =X30/$X$52 -> 0.038777494 | AF30: =517.25794*(16.44+34) -> 26090.49 | AG30: =517.25794*(113.9188+40) -> 79615.721
A31: 17 | C31: ESQUADRIAS, VIDROS E FERRAGENS | X31: 3047560.2 | AE31: =X31/$X$52 -> 0.11869454 | AF31: =AF30/ORÇAMENTO_EXECUTIVO!$N$3 -> 3.538087 | AG31: =AG30/ORÇAMENTO_EXECUTIVO!$N$3 -> 10.796552
A32: 18 | C32: LOUÇAS E METAIS | X32: 217852.24 | AE32: =X32/$X$52 -> 0.0084847777 | AF32: =X32/ORÇAMENTO_EXECUTIVO!$N$3 -> 29.542572
A33: 19 | C33: COBERTURA | X33: 14404.72 | AE33: =X33/$X$52 -> 0.00056102635
A34: 20 | C34: REVESTIMENTOS E ACABAMENTOS EM FACHADA | X34: 420905.94 | AE34: =X34/$X$52 -> 0.016393191
A35: 21 | C35: SERVIÇOS COMPLEMENTARES E FINAIS | X35: 1488758.1 | AE35: =X35/$X$52 -> 0.057983253
A36: 22 | C36: IMPREVISTOS E CONTINGÊNCIAS | X36: =AF37 -> 699680.22 | AE36: =X36/$X$52 -> 0.027250723 | AF36: =SUM(X15:AD35,X48:AD50)*0.015 -> 374639.65 | AG36: ='Dif. Altura'!I16*1.015 -> 325040.57
A37: Total da unidade construtiva | X37: =SUM(X15:AD36) -> 22264380 | AE37: =SUM(AE15:AE36) -> 0.86713965 | AF37: =SUM(X15:AD35,X48:AD50,'Dif. Altura'!I16)*0.015+'Dif. Altura'!I16 -> 699680.22
A39: Obra | D39: 2 - Moradas do Atalaia - Custo Direto
A40: Unidade construtiva | D40: 3 - GERENCIAMENTE TÉCNICO E ADMINISTRATIVO
A41: Tipo de obra | D41: 1 - Construção Civil
A42: Endereço da obra | D42: Rua Lila Heusi - Fazendinha - Itajaí/SC - 88306-023
A43: Versão do orçamento | D43: 2 - 15/09/2022 - 15:24:23 - Versão 2 do orçamento | L43: Data base | V43: 15/09/2022
A44: BDI | D44: não aplicado | L44: Encargos sociais | V44: não aplicado
A45: Preços expressos em | D45: R$ (REAL)
...

Sheet ORÇAMENTO_EXECUTIVO
B1: PARAMETRICO | F1: EXECUTIVO | I1: DIFERENÇA | K1: JUSTIFICATIVA
A2: ETAPA | B2: VALOR ORÇADO | C2: VALOR INDEXADO | D2: % | E2: VALOR / m² | F2: VALOR ORÇADO | G2: % | H2: VALOR / m² | I2: DIFERENÇA | J2: %
A3: GERENCIAMENTO TÉCNICO E ADMINISTRATIVO | B3: 2289625.9 | C3: =B3*$F$22/$B$22 -> 2398506.6 | D3: =B3/B$21 -> 0.09585008 | E3: =B3/$B$23 -> 310 | F3: =Relatório!X51 -> 3411276.9 | G3: =F3/F$21 -> 0.13286035 | H3: =F3/ORÇAMENTO_EXECUTIVO!N$3 -> 462.59745 | I3: =F3-C3 -> 1012770.3 | J3: =-(1-F3/C3) -> 0.42225036 | L3: Considerado 310,00/m² no paramétrico | M3: ÁREA CONSTRUÍDA | N3: 7374.18 | O3: m²
A4: MOVIMENTAÇÃO DE TERRA | B4: 239687.72 | C4: =B4*$F$22/$B$22 -> 251085.82 | D4: =B4/B$21 -> 0.010033992 | E4: =B4/$B$23 -> 32.452111 | F4: =Relatório!X15 -> 117226.62 | G4: =F4/F$21 -> 0.0045656717 | H4: =F4/ORÇAMENTO_EXECUTIVO!N$3 -> 15.896902 | I4: =F4-C4 -> -133859.2 | J4: =-(1-F4/C4) -> -0.5331213 | M4: ÁREA CONSTRUÍDA | N4: 7374.18 | O4: m²
A5: CONTENÇÃO | B5: 0 | C5: 0 | F5: =Relatório!X16 -> 422085.8 | G5: =F5/F$21 -> 0.016439143 | H5: =F5/ORÇAMENTO_EXECUTIVO!N$3 -> 57.238337 | I5: =F5-C5 -> 422085.8 | J5: =IFERROR(-(1-F5/C5),1) -> 1
A6: INFRAESTRUTURA | B6: 1500018.3 | C6: =B6*$F$22/$B$22 -> 1571350.1 | D6: =B6/B$21 -> 0.06279492 | E6: =B6/$B$23 -> 203.09242 | F6: =Relatório!X17 -> 1278806.1 | G6: =F6/F$21 -> 0.049806171 | H6: =F6/ORÇAMENTO_EXECUTIVO!N$3 -> 173.41673 | I6: =F6-C6 -> -292543.91 | J6: =-(1-F6/C6) -> -0.18617361
A7: SUPRAESTRUTURA | B7: 4913547.8 | C7: =B7*$F$22/$B$22 -> 5147206.2 | D7: =B7/B$21 -> 0.20569471 | E7: =B7/$B$23 -> 665.26143 | F7: =Relatório!X18 -> 5154482.2 | G7: =F7/F$21 -> 0.20075367 | H7: =F7/ORÇAMENTO_EXECUTIVO!N$3 -> 698.99056 | I7: =F7-C7 -> 7275.9908 | J7: =-(1-F7/C7) -> 0.0014135806 | M7: ATALAIA | P7: LIBERATO | R7: GRAN TORINO | T7: RAVELLO | X7: THOZEN | Z7: SAN MARINO
A8: ALVENARIA | B8: 976885.48 | C8: =B8*$F$22/$B$22 -> 1023340.2 | D8: =B8/B$21 -> 0.040895131 | E8: =B8/$B$23 -> 132.26375 | F8: =Relatório!X19 -> 910813.58 | G8: =F8/F$21 -> 0.035473818 | H8: =F8/ORÇAMENTO_EXECUTIVO!N$3 -> 123.51388 | I8: =F8-C8 -> -112526.64 | J8: =-(1-F8/C8) -> -0.10996015 | M8: 8692.89 | O8: AREA FACH | P8: 8692.89 | R8: 7919.86 | T8: 9941.17 | X8: 7078.1 | Z8: 5064.42
A9: INSTALAÇÕES ELÉTRICAS, HIDRÁULICAS, GLP E PREVENTIVAS | B9: 2460414.2 | C9: =B9*$F$22/$B$22 -> 2577416.6 | D9: =B9/B$21 -> 0.10299975 | E9: =B9/$B$23 -> 333.1236 | F9: =SUM(Relatório!X21:AD24,Relatório!X32) -> 2870107.3 | G9: =F9/F$21 -> 0.11178321 | H9: =F9/ORÇAMENTO_EXECUTIVO!N$3 -> 389.21037 | I9: =F9-C9 -> 292690.73 | J9: =-(1-F9/C9) -> 0.11355973 | M9: 193128.65 | N9: =M9/$P$8 -> 22.216852 | O9: ARGAMASSADO | P9: 193128.65 | Q9: =P9/$P$8 -> 22.216852 | R9: 179830.77 | S9: =R9/$R$8 -> 22.706307 | T9: =[2]ORÇAMENTO_EXECUTIVO_COMENTADO!$F$500 -> 178294.88 | U9: =T9/$T$8 -> 17.935 | X9: 184222.97 | Y9: =X9/$X$8 -> 26.027178 | Z9: 93668 | AA9: =Z9/$Z$8 -> 18.495306
A10: EQUIPAMENTOS E SISTEMAS ESPECIAIS | B10: 1080588.4 | C10: =B10*$F$22/$B$22 -> 1131974.6 | D10: =B10/B$21 -> 0.045236421 | E10: =B10/$B$23 -> 146.30442 | F10: =Relatório!X26+Relatório!X25 -> 1034381.3 | G10: =F10/F$21 -> 0.04028646 | H10: =F10/ORÇAMENTO_EXECUTIVO!N$3 -> 140.27069 | I10: =F10-C10 -> -97593.247 | J10: =-(1-F10/C10) -> -0.086215053 | M10: 90826.803 | N10: =M10/$P$8 -> 10.448401 | O10: ACABAMENTOS | P10: 90826.803 | Q10: =P10/$P$8 -> 10.448401 | R10: 260753.97 | S10: =R10/$R$8 -> 32.924063 | T10: =[2]ORÇAMENTO_EXECUTIVO_COMENTADO!$F$501 -> 143344.88 | U10: =T10/$T$8 -> 14.419316 | X10: 432041.61 | Y10: =X10/$X$8 -> 61.039207 | Z10: 100631.15 | AA10: =Z10/$Z$8 -> 19.870222
A11: IMPERMEABILIZAÇÃO | B11: 412732.29 | C11: =B11*$F$22/$B$22 -> 432359.33 | D11: =B11/B$21 -> 0.017278117 | E11: =B11/$B$23 -> 55.881186 | F11: =Relatório!X20 -> 482376.84 | G11: =F11/F$21 -> 0.018787322 | H11: =F11/ORÇAMENTO_EXECUTIVO!N$3 -> 65.414302 | I11: =F11-C11 -> 50017.507 | J11: =-(1-F11/C11) -> 0.11568504 | M11: 813763.73 | N11: =M11/$P$8 -> 93.612565 | O11: MO | P11: 813763.73 | Q11: =P11/$P$8 -> 93.612565 | R11: 961385.87 | S11: =R11/$R$8 -> 121.38925 | T11: =[2]ORÇAMENTO_EXECUTIVO_COMENTADO!$F$510 -> 1818369 | U11: =T11/$T$8 -> 182.91298 | X11: 970056.14 | Y11: =X11/$X$8 -> 137.05036 | Z11: 425523.35 | AA11: =Z11/$Z$8 -> 84.022129
A12: REVESTIMENTOS INTERNOS EM PISO E PAREDE | B12: 1113794.8 | C12: =B12*$F$22/$B$22 -> 1166760.1 | D12: =B12/B$21 -> 0.046626533 | E12: =B12/$B$23 -> 150.80034 | F12: =SUMIF(Planilha1!AF:AF,1,Planilha1!AC:AC) -> 1137180.3 | G12: =F12/F$21 -> 0.044290211 | H12: =F12/ORÇAMENTO_EXECUTIVO!N$3 -> 154.21108 | I12: =F12-C12 -> -29579.804 | J12: =-(1-F12/C12) -> -0.025352088 | X12: TEXTURA
A13: REVESTIMENTOS E ACABAMENTOS INTERNOS EM TETO | B13: 860184.99 | C13: =B13*$F$22/$B$22 -> 901090.16 | D13: =B13/B$21 -> 0.036009725 | E13: =B13/$B$23 -> 116.46328 | F13: =Relatório!X28 -> 405459.35 | G13: =F13/F$21 -> 0.015791586 | H13: =F13/ORÇAMENTO_EXECUTIVO!N$3 -> 54.983652 | I13: =F13-C13 -> -495630.81 | J13: =-(1-F13/C13) -> -0.55003465 | M13: =N3 -> 7374.18 | O13: AREA | P13: 10520.39 | R13: 12518.96 | T13: 13434.29 | Y13: 10661.12 | AA13: 5233.02
A14: ACABAMENTOS EM PISO E PAREDE | B14: 1461063.4 | C14: =B14*$F$22/$B$22 -> 1530542.6 | D14: =B14/B$21 -> 0.061164158 | E14: =B14/$B$23 -> 197.81818 | F14: =SUMIF(Planilha1!AF:AF,2,Planilha1!AC:AC) -> 1784513.7 | G14: =F14/F$21 -> 0.069502162 | H14: =F14/ORÇAMENTO_EXECUTIVO!N$3 -> 241.99486 | I14: =F14-C14 -> 253971.02 | J14: =-(1-F14/C14) -> 0.16593528 | M14: 2161.52 | N14: =M14/M13 -> 0.29312005 | O14: CONCRETO | P14: 2161.52 | Q14: =P14/P13 -> 0.20546006 | R14: 2511.5 | S14: =R$14/R13 -> 0.20061571 | T14: 3305.65 | U14: =T14/T13 -> 0.24606064 | X14: 3222.12 | Y14: =X14/Y13 -> 0.30223091 | Z14: 1260.01 | AA14: =Z14/AA13 -> 0.24078066
A15: PINTURA INTERNA | B15: 876494.55 | C15: =B15*$F$22/$B$22 -> 918175.31 | D15: =B15/B$21 -> 0.036692489 | E15: =B15/$B$23 -> 118.67149 | F15: =Relatório!X30 -> 995637.62 | G15: =F15/F$21 -> 0.038777494 | H15: =F15/ORÇAMENTO_EXECUTIVO!N$3 -> 135.01672 | I15: =F15-C15 -> 77462.314 | J15: =-(1-F15/C15) -> 0.084365495 | M15: 171316.9 | N15: =M15/M14 -> 79.257606 | O15: AÇO | P15: 171316.9 | Q15: =P15/P14 -> 79.257606 | R15: 215788 | S15: =R15/R14 -> 85.919968 | T15: 327766.4 | U15: =T15/T14 -> 99.153389 | X15: 350367 | Y15: =X15/X14 -> 108.73804 | Z15: 87519 | AA15: =Z15/Z14 -> 69.458973
A16: ESQUADRIAS, VIDROS E FERRAGENS | B16: 2361298.1 | C16: =B16*$F$22/$B$22 -> 2473587.1 | D16: =B16/B$21 -> 0.098850477 | E16: =B16/$B$23 -> 319.70394 | F16: =Relatório!X31 -> 3047560.2 | G16: =F16/F$21 -> 0.11869454 | H16: =F16/ORÇAMENTO_EXECUTIVO!N$3 -> 413.27445 | I16: =F16-C16 -> 573973.11 | J16: =-(1-F16/C16) -> 0.23204079 | M16: 25304.58 | N16: =M16/M14 -> 11.706845 | O16: FORMA | P16: 25304.58 | Q16: =P16/P14 -> 11.706845 | R16: 26310.1 | S16: =R16/R14 -> 10.475851 | T16: 33585.725 | U16: =T16/T14 -> 10.160097
A17: COBERTURA | B17: 12000 | C17: =B17*$F$22/$B$22 -> 12570.647 | D17: =B17/B$21 -> 0.00050235323 | E17: =B17/$B$23 -> 1.6247196 | F17: =Relatório!X33 -> 14404.72 | G17: =F17/F$21 -> 0.00056102635 | H17: =F17/ORÇAMENTO_EXECUTIVO!N$3 -> 1.9533996 | I17: =F17-C17 -> 1834.0729 | J17: =-(1-F17/C17) -> 0.14590123
A18: REVESTIMENTOS E ACABAMENTOS DE FACHADA | B18: 667221.9 | C18: =B18*$F$22/$B$22 -> 698950.92 | D18: =B18/B$21 -> 0.027931756 | E18: =B18/$B$23 -> 90.337373 | F18: =Relatório!X34 -> 420905.94 | G18: =F18/F$21 -> 0.016393191 | H18: =F18/ORÇAMENTO_EXECUTIVO!N$3 -> 57.078338 | I18: =F18-C18 -> -278044.98 | J18: =-(1-F18/C18) -> -0.3978033 | M18: =[3]ORÇAMENTO_EXECUTIVO!$G$418 -> 1091325.7 | N18: =M18/$P$13 -> 103.73434 | O18: ELETRICA | P18: =[3]ORÇAMENTO_EXECUTIVO!$G$418 -> 1091325.7 | Q18: =P18/$P$13 -> 103.73434 | R18: =[4]ORÇAMENTO_EXECUTIVO!$F$495 -> 2000291.7 | S18: =R18/$N$3 -> 271.25615 | T18: =[5]ORÇAMENTO_EXECUTIVO_COMENTADO!$F$254 -> 2057578.1 | U18: =T18/$T$13 -> 153.15868 | X18: =[6]ORÇAMENTO_EXECUTIVO_COMENTADO!$F$303 -> 1419545.4 | Y18: =X18/$Y$13 -> 133.15162
A19: SERVIÇOS COMPLEMENTARES | B19: 2170877.9 | C19: =B19*$F$22/$B$22 -> 2274111.7 | D19: =B19/B$21 -> 0.090878961 | E19: =B19/$B$23 -> 293.92232 | F19: =Relatório!X35 -> 1488758.1 | G19: =F19/F$21 -> 0.057983253 | H19: =F19/ORÇAMENTO_EXECUTIVO!N$3 -> 201.88795 | I19: =F19-C19 -> -785353.59 | J19: =-(1-F19/C19) -> -0.34534521 | M19: =[3]ORÇAMENTO_EXECUTIVO!$G$512 -> 2062487.3 | N19: =M19/$P$13 -> 196.04666 | O19: HIDRAULICA | P19: =[3]ORÇAMENTO_EXECUTIVO!$G$512 -> 2062487.3 | Q19: =P19/$P$13 -> 196.04666 | R19: =[4]ORÇAMENTO_EXECUTIVO!$F$606 -> 1748574.5 | S19: =R19/$N$3 -> 237.12121 | T19: =[5]ORÇAMENTO_EXECUTIVO_COMENTADO!$F$238 -> 1461799.3 | U19: =T19/$T$13 -> 108.81106 | X19: =[6]ORÇAMENTO_EXECUTIVO_COMENTADO!$F$289 -> 778425.74 | Y19: =X19/$Y$13 -> 73.015381
A20: IMPREVISTOS E CONTINGENCIAS | B20: 491138.52 | C20: =B20*$F$22/$B$22 -> 514494.09 | D20: =B20/B$21 -> 0.020560419 | E20: =B20/$B$23 -> 66.496864 | F20: =Relatório!X36 -> 699680.22 | G20: =F20/F$21 -> 0.027250723 | H20: =F20/ORÇAMENTO_EXECUTIVO!N$3 -> 94.882444 | I20: =F20-C20 -> 185186.13 | J20: =-(1-F20/C20) -> 0.35993831 | M20: =[3]ORÇAMENTO_EXECUTIVO!$G$602 -> 311725.07 | N20: =M20/$P$13 -> 29.630562 | O20: PREVENTIVA | P20: =[3]ORÇAMENTO_EXECUTIVO!$G$602 -> 311725.07 | Q20: =P20/$P$13 -> 29.630562 | R20: =[4]ORÇAMENTO_EXECUTIVO!$F$704 -> 585043.91 | S20: =R20/$N$3 -> 79.336809 | T20: =[5]ORÇAMENTO_EXECUTIVO_COMENTADO!$F$274+[5]ORÇAMENTO_EXECUTIVO_COMENTADO!$F$286 -> 626453.64 | U20: =T20/$T$13 -> 46.630945 | X20: =[6]ORÇAMENTO_EXECUTIVO_COMENTADO!$F$330 -> 408416.91 | Y20: =X20/$Y$13 -> 38.309006
A21: TOTAL | B21: =SUM(B3:B20) -> 23887574 | C21: =SUM(C3:C20) -> 25023522 | D21: =SUM(D3:D20) -> 1 | E21: =SUM(E3:E20) -> 3234.2174 | F21: =SUM(F3:F20) -> 25675657 | G21: =SUM(G3:G20) -> 1 | H21: =SUM(H3:H20) -> 3481.8321 | I21: =SUM(I3:I20) -> 652134.77 | J21: =F21/C21-1 -> 0.026060871
A22: CUB/SC | B22: 2632.38 | D22: 44835 | E22: =+E21/B22 -> 1.2286286 | F22: 2757.56 | G22: 45383 | H22: =+H21/F22 -> 1.2626496 | M22: =[3]ORÇAMENTO_EXECUTIVO!$G$145+[3]ORÇAMENTO_EXECUTIVO!$G$169+[3]ORÇAMENTO_EXECUTIVO!$G$191+[3]ORÇAMENTO_EXECUTIVO!$G$212+[3]ORÇAMENTO_EXECUTIVO!$G$233+[3]ORÇAMENTO_EXECUTIVO!$G$254+[3]ORÇAMENTO_EXECUTIVO!$G$273+[3]ORÇAMENTO_EXECUTIVO!$G$289 -> 1448895.6 | N22: =M22/$P$13 -> 137.72261 | O22: FORMA | P22: =[3]ORÇAMENTO_EXECUTIVO!$G$145+[3]ORÇAMENTO_EXECUTIVO!$G$169+[3]ORÇAMENTO_EXECUTIVO!$G$191+[3]ORÇAMENTO_EXECUTIVO!$G$212+[3]ORÇAMENTO_EXECUTIVO!$G$233+[3]ORÇAMENTO_EXECUTIVO!$G$254+[3]ORÇAMENTO_EXECUTIVO!$G$273+[3]ORÇAMENTO_EXECUTIVO!$G$289 -> 1448895.6 | Q22: =P22/$P$13 -> 137.72261 | R22: =[4]ORÇAMENTO_EXECUTIVO!$F$165+[4]ORÇAMENTO_EXECUTIVO!$F$187+[4]ORÇAMENTO_EXECUTIVO!$F$211+[4]ORÇAMENTO_EXECUTIVO!$F$233+[4]ORÇAMENTO_EXECUTIVO!$F$255+[4]ORÇAMENTO_EXECUTIVO!$F$276+[4]ORÇAMENTO_EXECUTIVO!$F$297+[4]ORÇAMENTO_EXECUTIVO!$F$318+[4]ORÇAMENTO_EXECUTIVO!$F$338 -> 1363402.4 | S22: =R22/$R$13 -> 108.907 | T22: 689058.07 | U22: =T22/$T$13 -> 51.290992 | X22: =[6]ORÇAMENTO_EXECUTIVO_COMENTADO!$F$188+[6]ORÇAMENTO_EXECUTIVO_COMENTADO!$F$217 -> 660936.07 | Y22: =X22/$Y$13 -> 61.994994
B23: 7385.89 | F23: =F22/B22 -> 1.0475539 | M23: =[3]ORÇAMENTO_EXECUTIVO!$G$283+[3]ORÇAMENTO_EXECUTIVO!$G$266+[3]ORÇAMENTO_EXECUTIVO!$G$245+[3]ORÇAMENTO_EXECUTIVO!$G$224+[3]ORÇAMENTO_EXECUTIVO!$G$203+[3]ORÇAMENTO_EXECUTIVO!$G$182+[3]ORÇAMENTO_EXECUTIVO!$G$160+[3]ORÇAMENTO_EXECUTIVO!$G$137 -> 1147056.4 | N23: =M23/$P$13 -> 109.03173 | O23: ARMAÇÃO | P23: =[3]ORÇAMENTO_EXECUTIVO!$G$283+[3]ORÇAMENTO_EXECUTIVO!$G$266+[3]ORÇAMENTO_EXECUTIVO!$G$245+[3]ORÇAMENTO_EXECUTIVO!$G$224+[3]ORÇAMENTO_EXECUTIVO!$G$203+[3]ORÇAMENTO_EXECUTIVO!$G$182+[3]ORÇAMENTO_EXECUTIVO!$G$160+[3]ORÇAMENTO_EXECUTIVO!$G$137 -> 1147056.4 | Q23: =P23/$P$13 -> 109.03173 | R23: =[4]ORÇAMENTO_EXECUTIVO!$F$329+[4]ORÇAMENTO_EXECUTIVO!$F$309+[4]ORÇAMENTO_EXECUTIVO!$F$288+[4]ORÇAMENTO_EXECUTIVO!$F$267+[4]ORÇAMENTO_EXECUTIVO!$F$246+[4]ORÇAMENTO_EXECUTIVO!$F$224+[4]ORÇAMENTO_EXECUTIVO!$F$202+[4]ORÇAMENTO_EXECUTIVO!$F$178+[4]ORÇAMENTO_EXECUTIVO!$F$156 -> 1749205 | S23: =R23/$R$13 -> 139.72446 | T23: 2489883.9 | U23: =T23/$T$13 -> 185.33796 | X23: =[6]ORÇAMENTO_EXECUTIVO_COMENTADO!$F$226+[6]ORÇAMENTO_EXECUTIVO_COMENTADO!$F$197 -> 2678932.8 | Y23: =X23/$Y$13 -> 251.28062
F24: =F23*B21 -> 25023522 | M24: =[3]ORÇAMENTO_EXECUTIVO!$G$152+[3]ORÇAMENTO_EXECUTIVO!$G$154+[3]ORÇAMENTO_EXECUTIVO!$G$177+[3]ORÇAMENTO_EXECUTIVO!$G$197+[3]ORÇAMENTO_EXECUTIVO!$G$218+[3]ORÇAMENTO_EXECUTIVO!$G$239+[3]ORÇAMENTO_EXECUTIVO!$G$260+[3]ORÇAMENTO_EXECUTIVO!$G$278+[3]ORÇAMENTO_EXECUTIVO!$G$293 -> 1866626 | N24: =M24/$P$13 -> 177.42936 | O24: COCNRETO | P24: =[3]ORÇAMENTO_EXECUTIVO!$G$152+[3]ORÇAMENTO_EXECUTIVO!$G$154+[3]ORÇAMENTO_EXECUTIVO!$G$177+[3]ORÇAMENTO_EXECUTIVO!$G$197+[3]ORÇAMENTO_EXECUTIVO!$G$218+[3]ORÇAMENTO_EXECUTIVO!$G$239+[3]ORÇAMENTO_EXECUTIVO!$G$260+[3]ORÇAMENTO_EXECUTIVO!$G$278+[3]ORÇAMENTO_EXECUTIVO!$G$293 -> 1866626 | Q24: =P24/$P$13 -> 177.42936 | R24: =[4]ORÇAMENTO_EXECUTIVO!$F$170+[4]ORÇAMENTO_EXECUTIVO!$F$172+[4]ORÇAMENTO_EXECUTIVO!$F$195+[4]ORÇAMENTO_EXECUTIVO!$F$217+[4]ORÇAMENTO_EXECUTIVO!$F$239+[4]ORÇAMENTO_EXECUTIVO!$F$261+[4]ORÇAMENTO_EXECUTIVO!$F$282+[4]ORÇAMENTO_EXECUTIVO!$F$303+[4]ORÇAMENTO_EXECUTIVO!$F$324+[4]ORÇAMENTO_EXECUTIVO!$F$343 -> 1847471.4 | S24: =R24/$R$13 -> 147.57387 | T24: 1972646.6 | U24: =T24/$T$13 -> 146.83669 | X24: =[6]ORÇAMENTO_EXECUTIVO_COMENTADO!$F$207+[6]ORÇAMENTO_EXECUTIVO_COMENTADO!$F$236 -> 2023491.4 | Y24: =X24/$Y$13 -> 189.80101
A25: Rótulos de Linha | B25: Soma de %2 | M25: =[3]ORÇAMENTO_EXECUTIVO!$G$295+[3]ORÇAMENTO_EXECUTIVO!$G$280+[3]ORÇAMENTO_EXECUTIVO!$G$262+[3]ORÇAMENTO_EXECUTIVO!$G$241+[3]ORÇAMENTO_EXECUTIVO!$G$220+[3]ORÇAMENTO_EXECUTIVO!$G$199+[3]ORÇAMENTO_EXECUTIVO!$G$179+[3]ORÇAMENTO_EXECUTIVO!$G$156 -> 2364585.8 | N25: =M25/$P$13 -> 224.76218 | O25: MAO DE OBRA | P25: =[3]ORÇAMENTO_EXECUTIVO!$G$295+[3]ORÇAMENTO_EXECUTIVO!$G$280+[3]ORÇAMENTO_EXECUTIVO!$G$262+[3]ORÇAMENTO_EXECUTIVO!$G$241+[3]ORÇAMENTO_EXECUTIVO!$G$220+[3]ORÇAMENTO_EXECUTIVO!$G$199+[3]ORÇAMENTO_EXECUTIVO!$G$179+[3]ORÇAMENTO_EXECUTIVO!$G$156 -> 2364585.8 | Q25: =P25/$P$13 -> 224.76218 | R25: =[4]ORÇAMENTO_EXECUTIVO!$F$345+[4]ORÇAMENTO_EXECUTIVO!$F$326+[4]ORÇAMENTO_EXECUTIVO!$F$305+[4]ORÇAMENTO_EXECUTIVO!$F$284+[4]ORÇAMENTO_EXECUTIVO!$F$263+[4]ORÇAMENTO_EXECUTIVO!$F$242+[4]ORÇAMENTO_EXECUTIVO!$F$220+[4]ORÇAMENTO_EXECUTIVO!$F$198+[4]ORÇAMENTO_EXECUTIVO!$F$174 -> 3239820 | S25: =R25/$R$13 -> 258.79306 | T25: 2830171.1 | U25: =T25/$T$13 -> 210.66771 | X25: =[6]ORÇAMENTO_EXECUTIVO_COMENTADO!$F$240+[6]ORÇAMENTO_EXECUTIVO_COMENTADO!$F$214 -> 2665280 | Y25: =X25/$Y$13 -> 250
A26: SUPRAESTRUTURA | B26: 0.19774221 | O26: COMPLEMENTARES | T26: 600845.25 | U26: =T26/$T$13 -> 44.724749 | X26: =[6]ORÇAMENTO_EXECUTIVO_COMENTADO!$F$209+[6]ORÇAMENTO_EXECUTIVO_COMENTADO!$F$238 -> 532048.71 | Y26: =X26/$Y$13 -> 49.905518
A27: ESQUADRIAS, VIDROS E FERRAGENS | B27: 0.11621611
A28: GERENCIAMENTO TÉCNICO E ADMINISTRATIVO | B28: 0.11419499
A29: INSTALAÇÕES ELÉTRICAS, HIDRÁULICAS, GLP E PREVENTIVAS | B29: 0.11166839 | O29: FACHADA | P29: =P8 -> 8692.89 | R29: =R8 -> 7919.86 | X29: =X8 -> 7078.1 | Z29: =Z8 -> 5064.42
A30: ACABAMENTOS EM PISO E PAREDE | B30: 0.074009087 | O30: ESQUADRIAS | P30: 1347.94 | R30: 1521.6 | X30: 1768.6 | Z30: 932.582
A31: SERVIÇOS COMPLEMENTARES | B31: 0.061743225 | P31: =P30/P29 -> 0.15506236 | R31: =R30/R29 -> 0.19212461 | X31: =X30/X29 -> 0.24986932 | Z31: =Z30/Z29 -> 0.18414389
A32: INFRAESTRUTURA | B32: 0.051473031
A33: REVESTIMENTOS INTERNOS EM PISO E PAREDE | B33: 0.047162246 | O33: MANTA | R33: =[4]ORÇAMENTO_EXECUTIVO!$D$790+[4]ORÇAMENTO_EXECUTIVO!$D$836+[4]ORÇAMENTO_EXECUTIVO!$D$870+[4]ORÇAMENTO_EXECUTIVO!$D$886+[4]ORÇAMENTO_EXECUTIVO!$D$898 -> 837.72 | S33: =R33/N3 -> 0.11360178 | Z33: =[7]Sheet1!$K$1904+[7]Sheet1!$K$2018+[7]Sheet1!$K$2080 -> 795.91 | AA33: =Z33/AA13 -> 0.15209382
A34: EQUIPAMENTOS E SISTEMAS ESPECIAIS | B34: 0.042898869
A35: PINTURA INTERNA | B35: 0.041292052
A36: ALVENARIA | B36: 0.037774147
A37: IMPREVISTOS E CONTINGENCIAS | B37: 0.028059506
A38: IMPERMEABILIZAÇÃO | B38: 0.020005602
A39: REVESTIMENTOS E ACABAMENTOS DE FACHADA | B39: 0.017456221
A40: REVESTIMENTOS E ACABAMENTOS INTERNOS EM TETO | B40: 0.016815605
...

Sheet ANÁLISE_CUSTOS
A1: ETAPA | B1: ATALAIA - PARAMÉTRICO | D1: ATALAIA - EXECUTIVO | F1: DIFERENÇA | G1: OBRA SIMILAR | H1: OBRA SIMILAR - PARAMÉTRICO | I1: JUSTIFICATIVA | J1: Malaga
B2: VALOR | C2: VALOR / m² | D2: VALOR | E2: VALOR / m² | G2: VALOR / m² | H2: VALOR / m²
A3: =ORÇAMENTO_EXECUTIVO!A3 -> GERENCIAMENTO TÉCNICO E ADMINISTRATIVO | B3: =ORÇAMENTO_EXECUTIVO!B3 -> 2289625.9 | C3: =ORÇAMENTO_EXECUTIVO!E3 -> 310 | D3: =ORÇAMENTO_EXECUTIVO!F3 -> 3411276.9 | E3: =ORÇAMENTO_EXECUTIVO!H3 -> 462.59745 | F3: =D3-B3 -> 1121651 | G3: =FIXED(CÁLCULO_MÉDIAS!N8,2,FALSE)&" "&"-"&FIXED(CÁLCULO_MÉDIAS!O8,2,FALSE) -> 330,00 -380,00 | I3: OK
A4: =ORÇAMENTO_EXECUTIVO!A4 -> MOVIMENTAÇÃO DE TERRA | B4: =ORÇAMENTO_EXECUTIVO!B4 -> 239687.72 | C4: =ORÇAMENTO_EXECUTIVO!E4 -> 32.452111 | D4: =ORÇAMENTO_EXECUTIVO!F4 -> 117226.62 | E4: =ORÇAMENTO_EXECUTIVO!H4 -> 15.896902 | F4: =D4-B4 -> -122461.1 | G4: =FIXED(CÁLCULO_MÉDIAS!N9,2,FALSE)&" "&"-"&FIXED(CÁLCULO_MÉDIAS!O9,2,FALSE) -> 6,00 -20,00 | H4: 30,00 - 50,00 | I4: OK
A5: =ORÇAMENTO_EXECUTIVO!A5 -> CONTENÇÃO | B5: =ORÇAMENTO_EXECUTIVO!B5 -> 0 | C5: =ORÇAMENTO_EXECUTIVO!E5 -> 0 | D5: =ORÇAMENTO_EXECUTIVO!F5 -> 422085.8 | E5: =ORÇAMENTO_EXECUTIVO!H5 -> 57.238337 | F5: =D5-B5 -> 422085.8 | G5: 40,00 - 60,00 | I5: OK | J5: Solicitado pela Gi para inserir médias próximas...
A6: =ORÇAMENTO_EXECUTIVO!A6 -> INFRAESTRUTURA | B6: =ORÇAMENTO_EXECUTIVO!B6 -> 1500018.3 | C6: =ORÇAMENTO_EXECUTIVO!E6 -> 203.09242 | D6: =ORÇAMENTO_EXECUTIVO!F6 -> 1278806.1 | E6: =ORÇAMENTO_EXECUTIVO!H6 -> 173.41673 | F6: =D6-B6 -> -221212.15 | G6: =FIXED(CÁLCULO_MÉDIAS!N10,2,FALSE)&" "&"-"&FIXED(CÁLCULO_MÉDIAS!O10,2,FALSE) -> 160,00 -180,00 | H6: 180,00 - 240,00 | I6: OK
A7: =ORÇAMENTO_EXECUTIVO!A7 -> SUPRAESTRUTURA | B7: =ORÇAMENTO_EXECUTIVO!B7 -> 4913547.8 | C7: =ORÇAMENTO_EXECUTIVO!E7 -> 665.26143 | D7: =ORÇAMENTO_EXECUTIVO!F7 -> 5154482.2 | E7: =ORÇAMENTO_EXECUTIVO!H7 -> 698.99056 | F7: =D7-B7 -> 240934.47 | G7: =FIXED(CÁLCULO_MÉDIAS!N11,2,FALSE)&" "&"-"&FIXED(CÁLCULO_MÉDIAS!O11,2,FALSE) -> 640,00 -670,00 | H7: 630,00 - 680,00 | I7: OK
A8: =ORÇAMENTO_EXECUTIVO!A8 -> ALVENARIA | B8: =ORÇAMENTO_EXECUTIVO!B8 -> 976885.48 | C8: =ORÇAMENTO_EXECUTIVO!E8 -> 132.26375 | D8: =ORÇAMENTO_EXECUTIVO!F8 -> 910813.58 | E8: =ORÇAMENTO_EXECUTIVO!H8 -> 123.51388 | F8: =D8-B8 -> -66071.901 | G8: =FIXED(CÁLCULO_MÉDIAS!N12,2,FALSE)&" "&"-"&FIXED(CÁLCULO_MÉDIAS!O12,2,FALSE) -> 115,00 -150,00 | H8: 110,00 - 150,00 | I8: OK
A9: =ORÇAMENTO_EXECUTIVO!A9 -> INSTALAÇÕES ELÉTRICAS, HIDRÁULICAS, GLP E PREVENTIVAS | B9: =ORÇAMENTO_EXECUTIVO!B9 -> 2460414.2 | C9: =ORÇAMENTO_EXECUTIVO!E9 -> 333.1236 | D9: =ORÇAMENTO_EXECUTIVO!F9 -> 2870107.3 | E9: =ORÇAMENTO_EXECUTIVO!H9 -> 389.21037 | F9: =D9-B9 -> 409693.08 | G9: =FIXED(CÁLCULO_MÉDIAS!N13,2,FALSE)&" "&"-"&FIXED(CÁLCULO_MÉDIAS!O13,2,FALSE) -> 330,00 -350,00 | H9: 300,00 - 350,00 | I9: Obras similares com 2 banheiros/apto | AE9: DIFERENÇAS EM QUNATITATIVOS:
A10: =ORÇAMENTO_EXECUTIVO!A10 -> EQUIPAMENTOS E SISTEMAS ESPECIAIS | B10: =ORÇAMENTO_EXECUTIVO!B10 -> 1080588.4 | C10: =ORÇAMENTO_EXECUTIVO!E10 -> 146.30442 | D10: =ORÇAMENTO_EXECUTIVO!F10 -> 1034381.3 | E10: =ORÇAMENTO_EXECUTIVO!H10 -> 140.27069 | F10: =D10-B10 -> -46207.03 | G10: =FIXED(CÁLCULO_MÉDIAS!N14,2,FALSE)&" "&"-"&FIXED(CÁLCULO_MÉDIAS!O14,2,FALSE) -> 120,00 -165,00 | H10: 150,00 - 200,00 | I10: OK | AE10: PISOS - AREAS TECNICAS E LAJES APENAS COM CONTRAPISO, SEM REVESTIMENTO
A11: =ORÇAMENTO_EXECUTIVO!A11 -> IMPERMEABILIZAÇÃO | B11: =ORÇAMENTO_EXECUTIVO!B11 -> 412732.29 | C11: =ORÇAMENTO_EXECUTIVO!E11 -> 55.881186 | D11: =ORÇAMENTO_EXECUTIVO!F11 -> 482376.84 | E11: =ORÇAMENTO_EXECUTIVO!H11 -> 65.414302 | F11: =D11-B11 -> 69644.547 | G11: =FIXED(CÁLCULO_MÉDIAS!N15,2,FALSE)&" "&"-"&FIXED(CÁLCULO_MÉDIAS!O15,2,FALSE) -> 40,00 -75,00 | H11: 35,00 - 45,00 | I11: OK
A12: =ORÇAMENTO_EXECUTIVO!A12 -> REVESTIMENTOS INTERNOS EM PISO E PAREDE | B12: =ORÇAMENTO_EXECUTIVO!B12 -> 1113794.8 | C12: =ORÇAMENTO_EXECUTIVO!E12 -> 150.80034 | D12: =ORÇAMENTO_EXECUTIVO!F12 -> 1137180.3 | E12: =ORÇAMENTO_EXECUTIVO!H12 -> 154.21108 | F12: =D12-B12 -> 23385.508 | G12: =FIXED(CÁLCULO_MÉDIAS!N16,2,FALSE)&" "&"-"&FIXED(CÁLCULO_MÉDIAS!O16,2,FALSE) -> 140,00 -170,00 | H12: 140,00 - 160,00 | I12: OK
A13: =ORÇAMENTO_EXECUTIVO!A13 -> REVESTIMENTOS E ACABAMENTOS INTERNOS EM TETO | B13: =ORÇAMENTO_EXECUTIVO!B13 -> 860184.99 | C13: =ORÇAMENTO_EXECUTIVO!E13 -> 116.46328 | D13: =ORÇAMENTO_EXECUTIVO!F13 -> 405459.35 | E13: =ORÇAMENTO_EXECUTIVO!H13 -> 54.983652 | F13: =D13-B13 -> -454725.64 | G13: =FIXED(CÁLCULO_MÉDIAS!N17,2,FALSE)&" "&"-"&FIXED(CÁLCULO_MÉDIAS!O17,2,FALSE) -> 50,00 -65,00 | H13: 75,00 - 85,00 | I13: OK
A14: =ORÇAMENTO_EXECUTIVO!A14 -> ACABAMENTOS EM PISO E PAREDE | B14: =ORÇAMENTO_EXECUTIVO!B14 -> 1461063.4 | C14: =ORÇAMENTO_EXECUTIVO!E14 -> 197.81818 | D14: =ORÇAMENTO_EXECUTIVO!F14 -> 1784513.7 | E14: =ORÇAMENTO_EXECUTIVO!H14 -> 241.99486 | F14: =D14-B14 -> 323450.32 | G14: =FIXED(CÁLCULO_MÉDIAS!N18,2,FALSE)&" "&"-"&FIXED(CÁLCULO_MÉDIAS!O18,2,FALSE) -> 140,00 -210,00 | H14: 160,00 - 190,00 | I14: Porcelanato garagem + demarcação de vagas com piso cerâmico
A15: =ORÇAMENTO_EXECUTIVO!A15 -> PINTURA INTERNA | B15: =ORÇAMENTO_EXECUTIVO!B15 -> 876494.55 | C15: =ORÇAMENTO_EXECUTIVO!E15 -> 118.67149 | D15: =ORÇAMENTO_EXECUTIVO!F15 -> 995637.62 | E15: =ORÇAMENTO_EXECUTIVO!H15 -> 135.01672 | F15: =D15-B15 -> 119143.07 | G15: =FIXED(CÁLCULO_MÉDIAS!N19,2,FALSE)&" "&"-"&FIXED(CÁLCULO_MÉDIAS!O19,2,FALSE) -> 120,00 -150,00 | H15: 100,00 - 120,00
A16: =ORÇAMENTO_EXECUTIVO!A16 -> ESQUADRIAS, VIDROS E FERRAGENS | B16: =ORÇAMENTO_EXECUTIVO!B16 -> 2361298.1 | C16: =ORÇAMENTO_EXECUTIVO!E16 -> 319.70394 | D16: =ORÇAMENTO_EXECUTIVO!F16 -> 3047560.2 | E16: =ORÇAMENTO_EXECUTIVO!H16 -> 413.27445 | F16: =D16-B16 -> 686262.1 | G16: =FIXED(CÁLCULO_MÉDIAS!N20,2,FALSE)&" "&"-"&FIXED(CÁLCULO_MÉDIAS!O20,2,FALSE) -> 210,00 -335,00 | H16: 280,00 - 320,00 | I16: Alta densidade de esquadrias na fachada
A17: =ORÇAMENTO_EXECUTIVO!A17 -> COBERTURA | B17: =ORÇAMENTO_EXECUTIVO!B17 -> 12000 | C17: =ORÇAMENTO_EXECUTIVO!E17 -> 1.6247196 | D17: =ORÇAMENTO_EXECUTIVO!F17 -> 14404.72 | E17: =ORÇAMENTO_EXECUTIVO!H17 -> 1.9533996 | F17: =D17-B17 -> 2404.72 | G17: =FIXED(CÁLCULO_MÉDIAS!N21,2,FALSE)&" "&"-"&FIXED(CÁLCULO_MÉDIAS!O21,2,FALSE) -> 5,00 -12,00 | H17: 4,50 - 5,50 | I17: Não tem telha
A18: =ORÇAMENTO_EXECUTIVO!A18 -> REVESTIMENTOS E ACABAMENTOS DE FACHADA | B18: =ORÇAMENTO_EXECUTIVO!B18 -> 667221.9 | C18: =ORÇAMENTO_EXECUTIVO!E18 -> 90.337373 | D18: =ORÇAMENTO_EXECUTIVO!F18 -> 420905.94 | E18: =ORÇAMENTO_EXECUTIVO!H18 -> 57.078338 | F18: =D18-B18 -> -246315.96 | G18: =FIXED(CÁLCULO_MÉDIAS!N22,2,FALSE)&" "&"-"&FIXED(CÁLCULO_MÉDIAS!O22,2,FALSE) -> 100,00 -170,00 | H18: 80,00 - 120,00 | I18: Tratamento do concreto aparente e alta densidade de esquadrias | J18: Considerado concreto aparente (estucamento, 2x lixamento e verniz)
A19: =ORÇAMENTO_EXECUTIVO!A19 -> SERVIÇOS COMPLEMENTARES | B19: =ORÇAMENTO_EXECUTIVO!B19 -> 2170877.9 | C19: =ORÇAMENTO_EXECUTIVO!E19 -> 293.92232 | D19: =ORÇAMENTO_EXECUTIVO!F19 -> 1488758.1 | E19: =ORÇAMENTO_EXECUTIVO!H19 -> 201.88795 | F19: =D19-B19 -> -682119.82 | G19: =FIXED(CÁLCULO_MÉDIAS!N23,2,FALSE)&" "&"-"&FIXED(CÁLCULO_MÉDIAS!O23,2,FALSE) -> 157,00 -210,00 | H19: 280,00 - 350,00 | I19: OK | J19: Solicitado pela Gi para aumentarmos as médias devido ao porte do empreendimento
A20: =ORÇAMENTO_EXECUTIVO!A20 -> IMPREVISTOS E CONTINGENCIAS | B20: =ORÇAMENTO_EXECUTIVO!B20 -> 491138.52 | C20: =ORÇAMENTO_EXECUTIVO!E20 -> 66.496864 | D20: =ORÇAMENTO_EXECUTIVO!F20 -> 699680.22 | E20: =ORÇAMENTO_EXECUTIVO!H20 -> 94.882444 | F20: =D20-B20 -> 208541.7 | G20: - | H20: 80,00 - 120,00
A21: TOTAL | B21: =SUM(B3:B19) -> 23396436 | C21: =SUM(C3:C19) -> 3167.7206 | D21: =SUM(D3:D20) -> 25675657 | E21: =SUM(E3:E20) -> 3481.8321 | G21: =FIXED(CÁLCULO_MÉDIAS!N24,2,FALSE)&" "&"-"&FIXED(CÁLCULO_MÉDIAS!O24,2,FALSE) -> 2.663,00 -3.312,00 | H21: =FIXED(CÁLCULO_MÉDIAS!O24,2,FALSE)&" "&"-"&FIXED(CÁLCULO_MÉDIAS!P24,2,FALSE) -> 3.312,00 -0,00
A24: CONCRETO
A25: AÇO
A26: FORMA
AI504: =25/3 -> 8.3333333

Sheet CÁLCULO_MÉDIAS
C2: área | D2: 10520.39 | E2: área | F2: 12518.96 | G2: área | H2: 13434.29 | I2: área | J2: 8744.16 | K2: área | S2: área | U2: área | W2: área | Y2: área | AA2: área
C3: DATA BASE | D3: 45047 | E3: DATA BASE | F3: 45383 | G3: DATA BASE | H3: 45323 | I3: DATA BASE | J3: 44409 | K3: DATA BASE | S3: DATA BASE | T3: 44866 | U3: DATA BASE | V3: 44256 | W3: DATA BASE | X3: 44958 | Y3: DATA BASE | Z3: 45047 | AA3: DATA BASE | AB3: 45261 | AC3: DATA BASE | AD3: 44774
C4: CUB | D4: 2688.94 | E4: CUB | F4: 2757.56 | G4: CUB | H4: 2753.62 | I4: CUB | J4: 2307.92 | K4: CUB | M4: =170/J2 -> 0.019441547 | S4: CUB | T4: 2633.22 | U4: CUB | V4: 2140.56 | W4: CUB | X4: 2662.47 | Y4: CUB | Z4: 2688.94 | AA4: CUB | AB4: 2752.67 | AC4: CUB | AD4: 2572.55
F5: 254976.79 | G5: =F5/F2 -> 20.36725
C6: LIBERATO | E6: GRAN TORINO | G6: RAVELLO | I6: CENTRAL PARK | K6: BRAVA - VALLEY | N6: MÉDIAS | S6: DOM BOSCO | U6: SAN MARINO | W6: DOM | Y6: PAESSAGGIO | AA6: THOZEN | AC6: HABITAH
C7: VALOR / M2 | D7: INDEXADO | E7: VALOR / M2 | F7: INDEXADO | G7: VALOR / M2 | H7: INDEXADO | I7: VALOR / M2 | J7: INDEXADO | N7: MÍNIMA | O7: MÁXIMA | S7: VALOR / M2 | T7: INDEXADO | U7: VALOR / M2 | V7: INDEXADO | W7: VALOR / M2 | X7: INDEXADO | Y7: VALOR / M2 | Z7: INDEXADO | AA7: VALOR / M2 | AB7: INDEXADO | AC7: VALOR / M2 | AD7: INDEXADO
B8: GERENCIAMENTO TECNICO E ADMINISTRATIVO | C8: 212.04958 | D8: =(ORÇAMENTO_EXECUTIVO!$F$22/CÁLCULO_MÉDIAS!D$4)*C8 -> 217.46094 | E8: 336.40234 | F8: =(ORÇAMENTO_EXECUTIVO!$F$22/CÁLCULO_MÉDIAS!F$4)*E8 -> 336.40234 | G8: 387.84287 | H8: =(ORÇAMENTO_EXECUTIVO!$F$22/CÁLCULO_MÉDIAS!H$4)*G8 -> 388.39781 | N8: 330 | O8: 380 | S8: 330.18696 | T8: =(ORÇAMENTO_EXECUTIVO!$F$22/CÁLCULO_MÉDIAS!T$4)*S8 -> 345.77831 | U8: =53.76+152.58 -> 206.34 | V8: =(ORÇAMENTO_EXECUTIVO!$F$22/CÁLCULO_MÉDIAS!V$4)*U8 -> 265.81592 | W8: 425.96974 | X8: =(ORÇAMENTO_EXECUTIVO!$F$22/CÁLCULO_MÉDIAS!X$4)*W8 -> 441.18323 | Y8: =306.853550565509+12.39 -> 319.24355 | Z8: =(ORÇAMENTO_EXECUTIVO!$F$22/CÁLCULO_MÉDIAS!Z$4)*Y8 -> 327.39044 | AA8: 393.04915 | AB8: =(ORÇAMENTO_EXECUTIVO!$F$22/CÁLCULO_MÉDIAS!AB$4)*AA8 -> 393.74739 | AC8: 307.80119 | AD8: =(ORÇAMENTO_EXECUTIVO!$F$22/CÁLCULO_MÉDIAS!AD$4)*AC8 -> 329.93732
B9: MOVIMENTAÇÃO DE TERRA | C9: 0 | D9: =(ORÇAMENTO_EXECUTIVO!$F$22/CÁLCULO_MÉDIAS!D$4)*C9 -> 0 | E9: 0 | F9: =(ORÇAMENTO_EXECUTIVO!$F$22/CÁLCULO_MÉDIAS!F$4)*E9 -> 0 | G9: 6.8428238 | H9: =(ORÇAMENTO_EXECUTIVO!$F$22/CÁLCULO_MÉDIAS!H$4)*G9 -> 6.8526149 | I9: =169044.49/J2 -> 19.332273 | J9: =(ORÇAMENTO_EXECUTIVO!$F$22/CÁLCULO_MÉDIAS!J$4)*I9 -> 23.098679 | K9: =160858.17/L2 -> #DIV/0! | N9: 6 | O9: 20 | S9: 0 | T9: =(ORÇAMENTO_EXECUTIVO!$F$22/CÁLCULO_MÉDIAS!T$4)*S9 -> 0 | U9: 0 | V9: =(ORÇAMENTO_EXECUTIVO!$F$22/CÁLCULO_MÉDIAS!V$4)*U9 -> 0 | W9: 19.58779 | X9: =(ORÇAMENTO_EXECUTIVO!$F$22/CÁLCULO_MÉDIAS!X$4)*W9 -> 20.287367 | Y9: 26.515285 | Z9: =(ORÇAMENTO_EXECUTIVO!$F$22/CÁLCULO_MÉDIAS!Z$4)*Y9 -> 27.191938 | AA9: 17.922886 | AB9: =(ORÇAMENTO_EXECUTIVO!$F$22/CÁLCULO_MÉDIAS!AB$4)*AA9 -> 17.954725 | AC9: 0 | AD9: =(ORÇAMENTO_EXECUTIVO!$F$22/CÁLCULO_MÉDIAS!AD$4)*AC9 -> 0
B10: INFRAESTRUTURA | C10: 171.5507 | D10: =(ORÇAMENTO_EXECUTIVO!$F$22/CÁLCULO_MÉDIAS!D$4)*C10 -> 175.92856 | E10: 162.9 | F10: =(ORÇAMENTO_EXECUTIVO!$F$22/CÁLCULO_MÉDIAS!F$4)*E10 -> 162.9 | G10: 169.2913 | H10: =(ORÇAMENTO_EXECUTIVO!$F$22/CÁLCULO_MÉDIAS!H$4)*G10 -> 169.53353 | L10: =(ORÇAMENTO_EXECUTIVO!$F$22/CÁLCULO_MÉDIAS!L$4)*I10 -> #DIV/0! | N10: 160 | O10: 180 | S10: 138.77425 | T10: =(ORÇAMENTO_EXECUTIVO!$F$22/CÁLCULO_MÉDIAS!T$4)*S10 -> 145.32714 | U10: 203.75 | V10: =(ORÇAMENTO_EXECUTIVO!$F$22/CÁLCULO_MÉDIAS!V$4)*U10 -> 262.47937 | W10: 195.5904 | X10: =(ORÇAMENTO_EXECUTIVO!$F$22/CÁLCULO_MÉDIAS!X$4)*W10 -> 202.5759 | Y10: =268.371509227372+41.56 -> 309.93151 | Z10: =(ORÇAMENTO_EXECUTIVO!$F$22/CÁLCULO_MÉDIAS!Z$4)*Y10 -> 317.84076 | AA10: 227.46251 | AB10: =(ORÇAMENTO_EXECUTIVO!$F$22/CÁLCULO_MÉDIAS!AB$4)*AA10 -> 227.86658 | AC10: 145.26 | AD10: =(ORÇAMENTO_EXECUTIVO!$F$22/CÁLCULO_MÉDIAS!AD$4)*AC10 -> 155.70666
B11: SUPRAESTRUTURA | C11: 648.94588 | D11: =(ORÇAMENTO_EXECUTIVO!$F$22/CÁLCULO_MÉDIAS!D$4)*C11 -> 665.50656 | E11: 655 | F11: =(ORÇAMENTO_EXECUTIVO!$F$22/CÁLCULO_MÉDIAS!F$4)*E11 -> 655 | G11: 638.86 | H11: =(ORÇAMENTO_EXECUTIVO!$F$22/CÁLCULO_MÉDIAS!H$4)*G11 -> 639.77411 | N11: 640 | O11: 670 | S11: 440.21003 | T11: =(ORÇAMENTO_EXECUTIVO!$F$22/CÁLCULO_MÉDIAS!T$4)*S11 -> 460.99664 | U11: 516.11 | V11: =(ORÇAMENTO_EXECUTIVO!$F$22/CÁLCULO_MÉDIAS!V$4)*U11 -> 664.87475 | W11: 730.88829 | X11: =(ORÇAMENTO_EXECUTIVO!$F$22/CÁLCULO_MÉDIAS!X$4)*W11 -> 756.99193 | Y11: =424.075395917568+352.64 -> 776.7154 | Z11: =(ORÇAMENTO_EXECUTIVO!$F$22/CÁLCULO_MÉDIAS!Z$4)*Y11 -> 796.53667 | AA11: 753.33241 | AB11: =(ORÇAMENTO_EXECUTIVO!$F$22/CÁLCULO_MÉDIAS!AB$4)*AA11 -> 754.67067 | AC11: 684.09 | AD11: =(ORÇAMENTO_EXECUTIVO!$F$22/CÁLCULO_MÉDIAS!AD$4)*AC11 -> 733.28768
B12: ALVENARIA | C12: 146.27237 | D12: =(ORÇAMENTO_EXECUTIVO!$F$22/CÁLCULO_MÉDIAS!D$4)*C12 -> 150.00515 | E12: 122.73 | F12: =(ORÇAMENTO_EXECUTIVO!$F$22/CÁLCULO_MÉDIAS!F$4)*E12 -> 122.73 | G12: 117.55 | H12: =(ORÇAMENTO_EXECUTIVO!$F$22/CÁLCULO_MÉDIAS!H$4)*G12 -> 117.7182 | N12: 115 | O12: 150 | S12: 119.63619 | T12: =(ORÇAMENTO_EXECUTIVO!$F$22/CÁLCULO_MÉDIAS!T$4)*S12 -> 125.28538 | U12: 87.63 | V12: =(ORÇAMENTO_EXECUTIVO!$F$22/CÁLCULO_MÉDIAS!V$4)*U12 -> 112.88868 | W12: 119.11837 | X12: =(ORÇAMENTO_EXECUTIVO!$F$22/CÁLCULO_MÉDIAS!X$4)*W12 -> 123.37268 | Y12: =45.9182137373762+52.78 -> 98.698214 | Z12: =(ORÇAMENTO_EXECUTIVO!$F$22/CÁLCULO_MÉDIAS!Z$4)*Y12 -> 101.21693 | AA12: 120.12284 | AB12: =(ORÇAMENTO_EXECUTIVO!$F$22/CÁLCULO_MÉDIAS!AB$4)*AA12 -> 120.33624 | AC12: 102.26703 | AD12: =(ORÇAMENTO_EXECUTIVO!$F$22/CÁLCULO_MÉDIAS!AD$4)*AC12 -> 109.62177
B13: INSTALAÇÕES ELÉTRICAS, HIDRÁULICAS, GLP E PREVENTIVAS | C13: 329.41 | D13: =(ORÇAMENTO_EXECUTIVO!$F$22/CÁLCULO_MÉDIAS!D$4)*C13 -> 337.81633 | E13: 346.19 | F13: =(ORÇAMENTO_EXECUTIVO!$F$22/CÁLCULO_MÉDIAS!F$4)*E13 -> 346.19 | G13: 333.15 | H13: =(ORÇAMENTO_EXECUTIVO!$F$22/CÁLCULO_MÉDIAS!H$4)*G13 -> 333.62669 | N13: 330 | O13: 350 | S13: 241.53845 | T13: =(ORÇAMENTO_EXECUTIVO!$F$22/CÁLCULO_MÉDIAS!T$4)*S13 -> 252.94384 | U13: =115.12+96.69+17.4 -> 229.21 | V13: =(ORÇAMENTO_EXECUTIVO!$F$22/CÁLCULO_MÉDIAS!V$4)*U13 -> 295.27802 | W13: 311.09537 | X13: =(ORÇAMENTO_EXECUTIVO!$F$22/CÁLCULO_MÉDIAS!X$4)*W13 -> 322.20613 | Y13: =133.232025739994+119 -> 252.23203 | Z13: =(ORÇAMENTO_EXECUTIVO!$F$22/CÁLCULO_MÉDIAS!Z$4)*Y13 -> 258.66882 | AA13: 343.65138 | AB13: =(ORÇAMENTO_EXECUTIVO!$F$22/CÁLCULO_MÉDIAS!AB$4)*AA13 -> 344.26186 | AC13: 395.6489 | AD13: =(ORÇAMENTO_EXECUTIVO!$F$22/CÁLCULO_MÉDIAS!AD$4)*AC13 -> 424.10277
B14: EQUIPAMENTOS E SISTEMAS ESPECIAIS | C14: 156.76 | D14: =(ORÇAMENTO_EXECUTIVO!$F$22/CÁLCULO_MÉDIAS!D$4)*C14 -> 160.76041 | E14: 163.3 | F14: =(ORÇAMENTO_EXECUTIVO!$F$22/CÁLCULO_MÉDIAS!F$4)*E14 -> 163.3 | G14: 118.21 | H14: =(ORÇAMENTO_EXECUTIVO!$F$22/CÁLCULO_MÉDIAS!H$4)*G14 -> 118.37914 | N14: 120 | O14: 165 | S14: 125.58392 | T14: =(ORÇAMENTO_EXECUTIVO!$F$22/CÁLCULO_MÉDIAS!T$4)*S14 -> 131.51396 | U14: =126.98+36.9 -> 163.88 | V14: =(ORÇAMENTO_EXECUTIVO!$F$22/CÁLCULO_MÉDIAS!V$4)*U14 -> 211.11715 | W14: 234.95757 | X14: =(ORÇAMENTO_EXECUTIVO!$F$22/CÁLCULO_MÉDIAS!X$4)*W14 -> 243.34907 | Y14: 247.28447 | Z14: =(ORÇAMENTO_EXECUTIVO!$F$22/CÁLCULO_MÉDIAS!Z$4)*Y14 -> 253.59501 | AA14: 183.52385 | AB14: =(ORÇAMENTO_EXECUTIVO!$F$22/CÁLCULO_MÉDIAS!AB$4)*AA14 -> 183.84987 | AC14: 151.23889 | AD14: =(ORÇAMENTO_EXECUTIVO!$F$22/CÁLCULO_MÉDIAS!AD$4)*AC14 -> 162.11553
B15: IMPERMEABILIZAÇÃO | C15: 69.707842 | D15: =(ORÇAMENTO_EXECUTIVO!$F$22/CÁLCULO_MÉDIAS!D$4)*C15 -> 71.486741 | E15: 43.36 | F15: =(ORÇAMENTO_EXECUTIVO!$F$22/CÁLCULO_MÉDIAS!F$4)*E15 -> 43.36 | G15: 59.85 | H15: =(ORÇAMENTO_EXECUTIVO!$F$22/CÁLCULO_MÉDIAS!H$4)*G15 -> 59.935636 | N15: 40 | O15: 75 | S15: 28.96163 | T15: =(ORÇAMENTO_EXECUTIVO!$F$22/CÁLCULO_MÉDIAS!T$4)*S15 -> 30.329191 | U15: 46.01 | V15: =(ORÇAMENTO_EXECUTIVO!$F$22/CÁLCULO_MÉDIAS!V$4)*U15 -> 59.27203 | W15: 40.38554 | X15: =(ORÇAMENTO_EXECUTIVO!$F$22/CÁLCULO_MÉDIAS!X$4)*W15 -> 41.827908 | Y15: =21.1585217854063+29.7 -> 50.858522 | Z15: =(ORÇAMENTO_EXECUTIVO!$F$22/CÁLCULO_MÉDIAS!Z$4)*Y15 -> 52.156398 | AA15: 53.97562 | AB15: =(ORÇAMENTO_EXECUTIVO!$F$22/CÁLCULO_MÉDIAS!AB$4)*AA15 -> 54.071505 | AC15: 26.84 | AD15: =(ORÇAMENTO_EXECUTIVO!$F$22/CÁLCULO_MÉDIAS!AD$4)*AC15 -> 28.770251
B16: REVESTIMENTOS INTERNOS EM PISO E PAREDE | C16: 152.31227 | D16: =(ORÇAMENTO_EXECUTIVO!$F$22/CÁLCULO_MÉDIAS!D$4)*C16 -> 156.19918 | E16: 146.21 | F16: =(ORÇAMENTO_EXECUTIVO!$F$22/CÁLCULO_MÉDIAS!F$4)*E16 -> 146.21 | G16: 165.42 | H16: =(ORÇAMENTO_EXECUTIVO!$F$22/CÁLCULO_MÉDIAS!H$4)*G16 -> 165.65669 | N16: 140 | O16: 170 | S16: 234.72587 | T16: =(ORÇAMENTO_EXECUTIVO!$F$22/CÁLCULO_MÉDIAS!T$4)*S16 -> 245.80957 | U16: 107.18 | V16: =(ORÇAMENTO_EXECUTIVO!$F$22/CÁLCULO_MÉDIAS!V$4)*U16 -> 138.07381 | W16: 171.46501 | X16: =(ORÇAMENTO_EXECUTIVO!$F$22/CÁLCULO_MÉDIAS!X$4)*W16 -> 177.58888 | Y16: =61.5070901205645+125.46 -> 186.96709 | Z16: =(ORÇAMENTO_EXECUTIVO!$F$22/CÁLCULO_MÉDIAS!Z$4)*Y16 -> 191.73837 | AA16: 181.93322 | AB16: =(ORÇAMENTO_EXECUTIVO!$F$22/CÁLCULO_MÉDIAS!AB$4)*AA16 -> 182.25641 | AC16: 143.04 | AD16: =(ORÇAMENTO_EXECUTIVO!$F$22/CÁLCULO_MÉDIAS!AD$4)*AC16 -> 153.327
B17: REVESTIMENTOS E ACABAMENTOS INTERNOS EM TETO | C17: 54.81864 | D17: =(ORÇAMENTO_EXECUTIVO!$F$22/CÁLCULO_MÉDIAS!D$4)*C17 -> 56.217576 | E17: 60.1 | F17: =(ORÇAMENTO_EXECUTIVO!$F$22/CÁLCULO_MÉDIAS!F$4)*E17 -> 60.1 | G17: 56.68 | H17: =(ORÇAMENTO_EXECUTIVO!$F$22/CÁLCULO_MÉDIAS!H$4)*G17 -> 56.7611 | N17: 50 | O17: 65 | S17: 55.038679 | T17: =(ORÇAMENTO_EXECUTIVO!$F$22/CÁLCULO_MÉDIAS!T$4)*S17 -> 57.637592 | U17: 37.84 | V17: =(ORÇAMENTO_EXECUTIVO!$F$22/CÁLCULO_MÉDIAS!V$4)*U17 -> 48.74709 | W17: 82.252956 | X17: =(ORÇAMENTO_EXECUTIVO!$F$22/CÁLCULO_MÉDIAS!X$4)*W17 -> 85.190617 | Y17: =54.2873850783883+15.35 -> 69.637385 | Z17: =(ORÇAMENTO_EXECUTIVO!$F$22/CÁLCULO_MÉDIAS!Z$4)*Y17 -> 71.414486 | AA17: 55.010609 | AB17: =(ORÇAMENTO_EXECUTIVO!$F$22/CÁLCULO_MÉDIAS!AB$4)*AA17 -> 55.108333 | AC17: 70.155612 | AD17: =(ORÇAMENTO_EXECUTIVO!$F$22/CÁLCULO_MÉDIAS!AD$4)*AC17 -> 75.200991
B18: ACABAMENTOS EM PISO E PAREDE | C18: 189.37 | D18: =(ORÇAMENTO_EXECUTIVO!$F$22/CÁLCULO_MÉDIAS!D$4)*C18 -> 194.2026 | E18: 153.35 | F18: =(ORÇAMENTO_EXECUTIVO!$F$22/CÁLCULO_MÉDIAS!F$4)*E18 -> 153.35 | G18: 139.61 | H18: =(ORÇAMENTO_EXECUTIVO!$F$22/CÁLCULO_MÉDIAS!H$4)*G18 -> 139.80976 | N18: 140 | O18: 210 | S18: 165.18749 | T18: =(ORÇAMENTO_EXECUTIVO!$F$22/CÁLCULO_MÉDIAS!T$4)*S18 -> 172.9876 | U18: 111.36 | V18: =(ORÇAMENTO_EXECUTIVO!$F$22/CÁLCULO_MÉDIAS!V$4)*U18 -> 143.45867 | W18: 171.08275 | X18: =(ORÇAMENTO_EXECUTIVO!$F$22/CÁLCULO_MÉDIAS!X$4)*W18 -> 177.19296 | Y18: =128.113840140444+57.38 -> 185.49384 | Z18: =(ORÇAMENTO_EXECUTIVO!$F$22/CÁLCULO_MÉDIAS!Z$4)*Y18 -> 190.22752 | AA18: 148.70479 | AB18: =(ORÇAMENTO_EXECUTIVO!$F$22/CÁLCULO_MÉDIAS!AB$4)*AA18 -> 148.96895 | AC18: 167.78668 | AD18: =(ORÇAMENTO_EXECUTIVO!$F$22/CÁLCULO_MÉDIAS!AD$4)*AC18 -> 179.85339
B19: PINTURA INTERNA | C19: 125.38088 | D19: =(ORÇAMENTO_EXECUTIVO!$F$22/CÁLCULO_MÉDIAS!D$4)*C19 -> 128.58052 | E19: 149.59 | F19: =(ORÇAMENTO_EXECUTIVO!$F$22/CÁLCULO_MÉDIAS!F$4)*E19 -> 149.59 | G19: 136.5 | H19: =(ORÇAMENTO_EXECUTIVO!$F$22/CÁLCULO_MÉDIAS!H$4)*G19 -> 136.69531 | N19: 120 | O19: 150 | S19: 110.39979 | T19: =(ORÇAMENTO_EXECUTIVO!$F$22/CÁLCULO_MÉDIAS!T$4)*S19 -> 115.61284 | U19: 83.06 | V19: =(ORÇAMENTO_EXECUTIVO!$F$22/CÁLCULO_MÉDIAS!V$4)*U19 -> 107.00141 | W19: 131.71985 | X19: =(ORÇAMENTO_EXECUTIVO!$F$22/CÁLCULO_MÉDIAS!X$4)*W19 -> 136.42421 | Y19: =35.9030401086365+97.72 -> 133.62304 | Z19: =(ORÇAMENTO_EXECUTIVO!$F$22/CÁLCULO_MÉDIAS!Z$4)*Y19 -> 137.03301 | AA19: 173.39863 | AB19: =(ORÇAMENTO_EXECUTIVO!$F$22/CÁLCULO_MÉDIAS!AB$4)*AA19 -> 173.70667 | AC19: 81.300168 | AD19: =(ORÇAMENTO_EXECUTIVO!$F$22/CÁLCULO_MÉDIAS!AD$4)*AC19 -> 87.147029
B20: ESQUADRIAS, VIDROS E FERRAGENS | C20: 206.22 | D20: =(ORÇAMENTO_EXECUTIVO!$F$22/CÁLCULO_MÉDIAS!D$4)*C20 -> 211.4826 | E20: 288.61 | F20: =(ORÇAMENTO_EXECUTIVO!$F$22/CÁLCULO_MÉDIAS!F$4)*E20 -> 288.61 | G20: 223.84 | H20: =(ORÇAMENTO_EXECUTIVO!$F$22/CÁLCULO_MÉDIAS!H$4)*G20 -> 224.16028 | N20: 210 | O20: 335 | P20: ----------> | S20: 147.28733 | T20: =(ORÇAMENTO_EXECUTIVO!$F$22/CÁLCULO_MÉDIAS!T$4)*S20 -> 154.2422 | U20: 186.71 | V20: =(ORÇAMENTO_EXECUTIVO!$F$22/CÁLCULO_MÉDIAS!V$4)*U20 -> 240.52773 | W20: 323.47432 | X20: =(ORÇAMENTO_EXECUTIVO!$F$22/CÁLCULO_MÉDIAS!X$4)*W20 -> 335.02719 | Y20: =250.558807445514+9.23 -> 259.78881 | Z20: =(ORÇAMENTO_EXECUTIVO!$F$22/CÁLCULO_MÉDIAS!Z$4)*Y20 -> 266.41845 | AA20: 208.12266 | AB20: =(ORÇAMENTO_EXECUTIVO!$F$22/CÁLCULO_MÉDIAS!AB$4)*AA20 -> 208.49238 | AC20: 186.4553 | AD20: =(ORÇAMENTO_EXECUTIVO!$F$22/CÁLCULO_MÉDIAS!AD$4)*AC20 -> 199.8646
B21: COBERTURA | C21: 12.639948 | D21: =(ORÇAMENTO_EXECUTIVO!$F$22/CÁLCULO_MÉDIAS!D$4)*C21 -> 12.962511 | E21: 2.47 | F21: =(ORÇAMENTO_EXECUTIVO!$F$22/CÁLCULO_MÉDIAS!F$4)*E21 -> 2.47 | H21: =(ORÇAMENTO_EXECUTIVO!$F$22/CÁLCULO_MÉDIAS!H$4)*G21 -> 0 | N21: 5 | O21: 12 | S21: 0 | T21: =(ORÇAMENTO_EXECUTIVO!$F$22/CÁLCULO_MÉDIAS!T$4)*S21 -> 0 | U21: 12.08 | V21: =(ORÇAMENTO_EXECUTIVO!$F$22/CÁLCULO_MÉDIAS!V$4)*U21 -> 15.561967 | W21: 5.0049675 | X21: =(ORÇAMENTO_EXECUTIVO!$F$22/CÁLCULO_MÉDIAS!X$4)*W21 -> 5.1837197 | Y21: =2.57125170509111+1.44 -> 4.0112517 | Z21: =(ORÇAMENTO_EXECUTIVO!$F$22/CÁLCULO_MÉDIAS!Z$4)*Y21 -> 4.1136162 | AA21: 13.493415 | AB21: =(ORÇAMENTO_EXECUTIVO!$F$22/CÁLCULO_MÉDIAS!AB$4)*AA21 -> 13.517386 | AC21: 8.67 | AD21: =(ORÇAMENTO_EXECUTIVO!$F$22/CÁLCULO_MÉDIAS!AD$4)*AC21 -> 9.2935201
B22: REVESTIMENTOS E ACABAMENTOS DE FACHADA | C22: 102.99303 | D22: =(ORÇAMENTO_EXECUTIVO!$F$22/CÁLCULO_MÉDIAS!D$4)*C22 -> 105.62135 | E22: 114.53 | F22: =(ORÇAMENTO_EXECUTIVO!$F$22/CÁLCULO_MÉDIAS!F$4)*E22 -> 114.53 | G22: 162.49 | H22: =(ORÇAMENTO_EXECUTIVO!$F$22/CÁLCULO_MÉDIAS!H$4)*G22 -> 162.7225 | N22: 100 | O22: 170 | S22: 26.873962 | T22: =(ORÇAMENTO_EXECUTIVO!$F$22/CÁLCULO_MÉDIAS!T$4)*S22 -> 28.142944 | U22: 126.33 | V22: =(ORÇAMENTO_EXECUTIVO!$F$22/CÁLCULO_MÉDIAS!V$4)*U22 -> 162.74365 | W22: 165.68145 | X22: =(ORÇAMENTO_EXECUTIVO!$F$22/CÁLCULO_MÉDIAS!X$4)*W22 -> 171.59876 | Y22: =150.750039454126+64.44 -> 215.19004 | Z22: =(ORÇAMENTO_EXECUTIVO!$F$22/CÁLCULO_MÉDIAS!Z$4)*Y22 -> 220.68155 | AA22: 131.44434 | AB22: =(ORÇAMENTO_EXECUTIVO!$F$22/CÁLCULO_MÉDIAS!AB$4)*AA22 -> 131.67784 | AC22: 84.89 | AD22: =(ORÇAMENTO_EXECUTIVO!$F$22/CÁLCULO_MÉDIAS!AD$4)*AC22 -> 90.995032
B23: SERVIÇOS COMPLEMENTARES | C23: 116.34736 | D23: =(ORÇAMENTO_EXECUTIVO!$F$22/CÁLCULO_MÉDIAS!D$4)*C23 -> 119.31647 | E23: 157.2 | F23: =(ORÇAMENTO_EXECUTIVO!$F$22/CÁLCULO_MÉDIAS!F$4)*E23 -> 157.2 | G23: 165.48 | H23: =(ORÇAMENTO_EXECUTIVO!$F$22/CÁLCULO_MÉDIAS!H$4)*G23 -> 165.71678 | N23: 157 | O23: 210 | S23: 125.12904 | T23: =(ORÇAMENTO_EXECUTIVO!$F$22/CÁLCULO_MÉDIAS!T$4)*S23 -> 131.03761 | U23: 74.23 | V23: =(ORÇAMENTO_EXECUTIVO!$F$22/CÁLCULO_MÉDIAS!V$4)*U23 -> 95.626228 | W23: 142.84172 | X23: =(ORÇAMENTO_EXECUTIVO!$F$22/CÁLCULO_MÉDIAS!X$4)*W23 -> 147.9433 | Y23: =154.053109535665+12.4 -> 166.45311 | Z23: =(ORÇAMENTO_EXECUTIVO!$F$22/CÁLCULO_MÉDIAS!Z$4)*Y23 -> 170.70088 | AA23: 120.6576 | AB23: =(ORÇAMENTO_EXECUTIVO!$F$22/CÁLCULO_MÉDIAS!AB$4)*AA23 -> 120.87194 | AC23: 166.87012 | AD23: =(ORÇAMENTO_EXECUTIVO!$F$22/CÁLCULO_MÉDIAS!AD$4)*AC23 -> 178.87091
B24: TOTAL | C24: =SUM(C8:C23) -> 2694.7785 | D24: =SUM(D8:D23) -> 2763.5475 | E24: =SUM(E8:E23) -> 2901.9423 | F24: =SUM(F8:F23) -> 2901.9423 | G24: =SUM(G8:G23) -> 2881.617 | H24: =SUM(H8:H23) -> 2885.7401 | N24: =SUM(N8:N23) -> 2663 | O24: =SUM(O8:O23) -> 3312 | S24: =SUM(S8:S23) -> 2289.5336 | T24: =SUM(T8:T23) -> 2397.6448 | U24: =SUM(U8:U23) -> 2191.72 | V24: =SUM(V8:V23) -> 2823.4665 | W24: =SUM(W8:W23) -> 3271.1161 | X24: =SUM(X8:X23) -> 3387.9438 | Y24: =SUM(Y8:Y23) -> 3302.6435 | Z24: =SUM(Z8:Z23) -> 3386.9249 | ... AD24: =SUM(AD8:AD23) -> 2918.0945
U26: =U24/V4 -> 1.0239003

Sheet AREAS_PRIVATIVAS
A1: ETAPA | B1: VALOR ORÇADO | C1: % | D1: VALOR / m²
A2: GERENCIAMENTO TÉCNICO E ADMINISTRATIVO | B2: =ORÇAMENTO_EXECUTIVO!F3 -> 3411276.9 | C2: =B2/B$20 -> 0.13286035 | D2: =B2/AREAS_PRIVATIVAS!G$2 -> 631.53549 | F2: ÁREA PRIVATIVA | G2: 5401.56 | I2: m²
A3: MOVIMENTAÇÃO DE TERRA | B3: =ORÇAMENTO_EXECUTIVO!F4 -> 117226.62 | C3: =B3/B$20 -> 0.0045656717 | D3: =B3/AREAS_PRIVATIVAS!G$2 -> 21.702364
A4: CONTENÇÃO | B4: =ORÇAMENTO_EXECUTIVO!F5 -> 422085.8 | C4: =B4/B$20 -> 0.016439143 | D4: =B4/AREAS_PRIVATIVAS!G$2 -> 78.141463
A5: INFRAESTRUTURA | B5: =ORÇAMENTO_EXECUTIVO!F6 -> 1278806.1 | C5: =B5/B$20 -> 0.049806171 | D5: =B5/AREAS_PRIVATIVAS!G$2 -> 236.74756
A6: SUPRAESTRUTURA | B6: =ORÇAMENTO_EXECUTIVO!F7 -> 5154482.2 | C6: =B6/B$20 -> 0.20075367 | D6: =B6/AREAS_PRIVATIVAS!G$2 -> 954.25807
A7: ALVENARIA | B7: =ORÇAMENTO_EXECUTIVO!F8 -> 910813.58 | C7: =B7/B$20 -> 0.035473818 | D7: =B7/AREAS_PRIVATIVAS!G$2 -> 168.62047
A8: INSTALAÇÕES ELÉTRICAS, HIDRÁULICAS, GLP E PREVENTIVAS | B8: =ORÇAMENTO_EXECUTIVO!F9 -> 2870107.3 | C8: =B8/B$20 -> 0.11178321 | D8: =B8/AREAS_PRIVATIVAS!G$2 -> 531.34786
A9: EQUIPAMENTOS E SISTEMAS ESPECIAIS | B9: =ORÇAMENTO_EXECUTIVO!F10 -> 1034381.3 | C9: =B9/B$20 -> 0.04028646 | D9: =B9/AREAS_PRIVATIVAS!G$2 -> 191.49678 | E9: =#REF!/AREAS_PRIVATIVAS!G2 -> #REF!
A10: IMPERMEABILIZAÇÃO | B10: =ORÇAMENTO_EXECUTIVO!F11 -> 482376.84 | C10: =B10/B$20 -> 0.018787322 | D10: =B10/AREAS_PRIVATIVAS!G$2 -> 89.303246
A11: REVESTIMENTOS INTERNOS EM PISO E PAREDE | B11: =ORÇAMENTO_EXECUTIVO!F12 -> 1137180.3 | C11: =B11/B$20 -> 0.044290211 | D11: =B11/AREAS_PRIVATIVAS!G$2 -> 210.52812
A12: REVESTIMENTOS E ACABAMENTOS INTERNOS EM TETO | B12: =ORÇAMENTO_EXECUTIVO!F13 -> 405459.35 | C12: =B12/B$20 -> 0.015791586 | D12: =B12/AREAS_PRIVATIVAS!G$2 -> 75.06338
A13: ACABAMENTOS EM PISO E PAREDE | B13: =ORÇAMENTO_EXECUTIVO!F14 -> 1784513.7 | C13: =B13/B$20 -> 0.069502162 | D13: =B13/AREAS_PRIVATIVAS!G$2 -> 330.37005
A14: PINTURA INTERNA | B14: =ORÇAMENTO_EXECUTIVO!F15 -> 995637.62 | C14: =B14/B$20 -> 0.038777494 | D14: =B14/AREAS_PRIVATIVAS!G$2 -> 184.32409
A15: ESQUADRIAS, VIDROS E FERRAGENS | B15: =ORÇAMENTO_EXECUTIVO!F16 -> 3047560.2 | C15: =B15/B$20 -> 0.11869454 | D15: =B15/AREAS_PRIVATIVAS!G$2 -> 564.20001
A16: COBERTURA | B16: =ORÇAMENTO_EXECUTIVO!F17 -> 14404.72 | C16: =B16/B$20 -> 0.00056102635 | D16: =B16/AREAS_PRIVATIVAS!G$2 -> 2.6667703
A17: REVESTIMENTOS E ACABAMENTOS DE FACHADA | B17: =ORÇAMENTO_EXECUTIVO!F18 -> 420905.94 | C17: =B17/B$20 -> 0.016393191 | D17: =B17/AREAS_PRIVATIVAS!G$2 -> 77.923033
A18: SERVIÇOS COMPLEMENTARES | B18: =ORÇAMENTO_EXECUTIVO!F19 -> 1488758.1 | C18: =B18/B$20 -> 0.057983253 | D18: =B18/AREAS_PRIVATIVAS!G$2 -> 275.61632
A19: IMPREVISTOS E CONTINGENCIAS | B19: =ORÇAMENTO_EXECUTIVO!F20 -> 699680.22 | C19: =B19/B$20 -> 0.027250723 | D19: =B19/AREAS_PRIVATIVAS!G$2 -> 129.53299
A20: TOTAL | B20: =SUM(B2:B19) -> 25675657 | C20: =SUM(C2:C19) -> 1 | D20: =SUM(D2:D19) -> 4753.3781
A22: DESCRIÇÃO | B22: ÁREA (m²) | C22: QUANT. | D22: VALOR TOTAL | G22: DESCRIÇÃO | H22: ÁREA (m²) | I22: QUANT. | J22: VALOR TOTAL
A23: VALOR POR ÁREA PRIVATIVA (R$/m²) | B23: =SUMPRODUCT(B24:B31,C24:C31) -> 3352.72 | D23: =B20/AREAS_PRIVATIVAS!B23 -> 7658.1572 | G23: VALOR POR ÁREA PRIVATIVA (R$/m²) | H23: =SUM(H24:H29)*13+SUM(K24:K29) -> 9052.02 | J23: =ORÇAMENTO_EXECUTIVO!K21/AREAS_PRIVATIVAS!H23 -> 0
A24: Garden | B24: 98.78 | C24: 1 | D24: =B24*$D$23 -> 756472.77 | E24: 98.78 | G24: VALOR POR UNIDADE TIPO 01 | H24: 72.29 | I24: 6 | J24: =H24*$D$23 -> 553608.18 | K24: 86.29
A25: PB01 | B25: 78.65 | C25: 6 | D25: =B25*$D$23 -> 602314.06 | E25: 78.65 | G25: VALOR POR UNIDADE TIPO 02 | H25: 87.86 | I25: =6+6 -> 12 | J25: =H25*$D$23 -> 672845.69 | K25: 99.74
A26: PB02 | B26: 87.5 | C26: 21 | D26: =B26*$D$23 -> 670088.76 | E26: 87.5 | G26: VALOR POR UNIDADE TIPO 03 | H26: 96.26 | I26: 5 | J26: =H26*$D$23 -> 737174.21 | K26: 116.13
A27: PB02B | B27: 92.95 | C27: 1 | D27: =B27*$D$23 -> 711825.71 | E27: 92.95 | F27: =B23/ORÇAMENTO_EXECUTIVO!N3 -> 0.45465665 | G27: VALOR POR UNIDADE TIPO 04 | H27: 113.26 | I27: 4 | J27: =H27*$D$23 -> 867362.88 | K27: 102.55 | L27: =H23/ORÇAMENTO_EXECUTIVO!S3 -> #DIV/0!
A28: PB03 | B28: 115.03 | C28: 1 | D28: =B28*$D$23 -> 880917.82 | E28: 115.03 | G28: VALOR POR UNIDADE ESTÚDIO | H28: 46.51 | I28: 6 | J28: =H28*$D$23 -> 356180.89 | K28: 123.34
A29: PB03B | B29: 113.21 | C29: 3 | D29: =B29*$D$23 -> 866979.98 | E29: 113.21 | G29: VALOR POR UNIDADE GARDEN | H29: 239.51 | I29: 1 | J29: =H29*$D$23 -> 1834205.2
A30: Estúdio | B30: 45.73 | C30: 6 | D30: =B30*$D$23 -> 350207.53 | E30: 45.73
A31: Duplex | B31: 122.55 | C31: 1 | D31: =B31*D23 -> 938507.16 | E31: 122.55
A34: ÁREA DE LAZER | B34: 640.39

Sheet Dif. Altura
B1: CÁLCULO DA DIFERENÇA DE ALTURA DA REVISÃO DE PROJETO X VISUS
C2: Projeto atual | D2: Visus | E2: Diferença
B3: Subsolo | C3: 2.88 | D3: 2.88 | E3: =C3-D3 -> 0
B4: Térreo | C4: 2.88 | D4: 2.7 | E4: =C4-D4 -> 0.18
B5: Nível 1 | C5: 2.91 | D5: 2.7 | E5: =C5-D5 -> 0.21
B6: Nível 2 | C6: 3.42 | D6: 3.27 | E6: =C6-D6 -> 0.15
B7: Lazer | C7: 2.88 | D7: 2.7 | E7: =C7-D7 -> 0.18 | H7: 339.25 | I7: 2.79
B8: Tipo 1 A | C8: 2.87999 | D8: 2.7 | E8: =C8-D8 -> 0.17999 | H8: X | I8: =E23 -> 3.69989
B9: Tipo 1-B1 | C9: 2.87999 | D9: 2.7 | E9: =C9-D9 -> 0.17999
B10: Tipo 1-B2 | C10: 2.87999 | D10: 2.7 | E10: =C10-D10 -> 0.17999
B11: Tipo 1-B3 | C11: 2.87999 | D11: 2.7 | E11: =C11-D11 -> 0.17999
B12: Tipo 1-B4 | C12: 2.87999 | D12: 2.7 | E12: =C12-D12 -> 0.17999 | H12: A.C. | I12: =#REF! -> #REF!
B13: Tipo 1-B5 | C13: 2.87999 | D13: 2.7 | E13: =C13-D13 -> 0.17999 | H13: A.C. 1 PAV | I13: 339.25
B14: Tipo 2 A | C14: 2.87999 | D14: 2.7 | E14: =C14-D14 -> 0.17999 | H14: A.C. 1 PAV DIF. | I14: =(H7*I8)/I7 -> 449.88806
B15: Tipo 2-B1 | C15: 2.87999 | D15: 2.7 | E15: =C15-D15 -> 0.17999 | H15: CUSTO: | I15: =SUM(ORÇAMENTO_EXECUTIVO!H8,ORÇAMENTO_EXECUTIVO!H12,ORÇAMENTO_EXECUTIVO!H14,ORÇAMENTO_EXECUTIVO!H15,ORÇAMENTO_EXECUTIVO!H18) -> 711.81488
B16: Tipo 2-B2 | C16: 2.87999 | D16: 2.7 | E16: =C16-D16 -> 0.17999 | I16: =I15*I14 -> 320237.02
B17: Tipo 2-B3 | C17: 2.87999 | D17: 2.7 | E17: =C17-D17 -> 0.17999
B18: Tipo 3 | C18: 2.87999 | D18: 2.7 | E18: =C18-D18 -> 0.17999 | H18: 351532.73 | I18: 325040.57
B19: Ático | C19: 3.06 | D19: 3.06 | E19: =C19-D19 -> 0
B20: Casa de máquinas | C20: 2.62 | D20: 2.77 | E20: =C20-D20 -> -0.15
B21: Barrilete | C21: 1.85 | D21: 2.35 | E21: =C21+C22-D21 -> 1.15
B22: Caixa d'água | C22: 1.65
B23: TOTAL | C23: =SUM(C3:C22) -> 55.82989 | D23: =SUM(D3:D22) -> 52.13 | E23: =SUM(E3:E22) -> 3.69989 | F23: =E23-C24 -> 0.9083955
B24: MÉDIA | C24: =AVERAGE(C3:C22) -> 2.7914945
