Workbook
Name \0: #REF!
Name \0: #REF!
Name \0: #REF!
Name \0: #REF!
Name \0: #REF!
Name \1: #REF!
Name \1: #REF!
Name \a: #REF!
Name \a: #REF!
Name \a: #REF!
Name \a: #REF!
Name \b: #REF!
Name \b: #REF!
Name \c: #REF!
Name \c: #REF!
Name \d: #REF!
Name \d: #REF!
Name \e: #REF!
Name \e: #REF!
Name \i: #REF!
Name \i: #REF!
Name \J: #REF!
Name \J: #REF!
Name \k: #REF!
Name \k: #REF!
Name \l: #N/A
Name \m: #REF!
Name \m: #REF!
Name \m: #REF!
Name \m: #REF!
Name \o: #REF!
Name \o: #REF!
Name \p: #REF!
Name \p: #REF!
Name \r: #REF!
Name \r: #REF!
Name \T: #REF!
Name \T: #REF!
Name \z: #REF!
Name \z: #REF!
Name \z: #REF!
Name \z: #REF!
Name _: #REF!
Name _: #REF!
Name _: #REF!
Name _: #REF!
Name _: #REF!
Name _: #REF!
Name _\0: #REF!
Name _\0: #REF!
Name _\0: #REF!
Name _\0: #REF!
Name _\1: #REF!
Name _\1: #REF!
Name _\a: #REF!
Name _\a: #REF!
Name _\b: #REF!
Name _\b: #REF!
Name _\c: #REF!
Name _\c: #REF!

Sheet Obra 
C1: Projeto | D1: Colin Schroeder
C2: Empresa | D2: Grupo DUO
C3: Revisão | D3: R00
A4: QUADRO DE ÁREAS
B6: Descrição | C6: Unidade | E6: Quantidade | G6: Imagens
B7: MESES DE OBRA | C7: MÊS | E7: 42
B8: ÁREA DO TERRENO | C8: M² | E8: 1410.3
B9: ÁREA CONSTRUÍDA | C9: M² | E9: =SUM($E$15:$E$25) -> 6918.78
B10: NÚMERO DE UNIDADES HABITACIONAIS | C10: UN | E10: =1*2*15 -> 30
B11: NÚMERO DE UNIDADES COMERCIAIS | C11: UN
B12: ÁREA PRIVATIVA | C12: M²
B13: NÚMERO DE PAVIMENTOS | C13: UN | E13: 23
B15: 3º Subsolo | C15: M² | E15: 563.09
B16: 2º Subsolo | C16: M² | E16: 563.09
B17: 1º Subsolo | C17: M² | E17: 492.75
B18: Térreo | C18: M² | E18: 461.09
B19: 2º Pavimento | C19: M² | E19: 297.7
B20: Pavimentos Tipos (x15) | C20: M² | E20: =274.77*15 -> 4121.55 | G20: =E20/15 -> 274.77
B21: Cobertura | C21: M² | E21: 283.92
B22: Barrilete | C22: M² | E22: 39.73
B23: Reservatórios | C23: M² | E23: 39.73
B24: Urbanização | C24: M² | E24: 56.13
C25: M²
B31: ETAPA | C31: VALOR ORÇADO | D31: % | E31: VALOR / m²
B32: GERENCIAMENTO TÉCNICO E ADMINISTRATIVO | C32: ='Ger_Tec e Adm'!N122 -> 4773890.6 | D32: =C32/C$50 -> 0.16771847 | E32: =C32/$E$9 -> 689.99023
B33: MOVIMENTAÇÃO DE TERRA | C33: =Ger_Executivo!N8 -> 495334.16 | D33: =C33/C$50 -> 0.017402302 | E33: =C33/$E$9 -> 71.592703
B34: INFRAESTRUTURA | C34: =Ger_Executivo!N24 -> 1269914.5 | D34: =C34/C$50 -> 0.044615206 | E34: =C34/$E$9 -> 183.54601
B35: CONTENÇÃO | C35: =Ger_Executivo!N52 -> 1540547.1 | D35: =C35/C$50 -> 0.054123192 | E35: =C35/$E$9 -> 222.66167
B36: SUPRAESTRUTURA | C36: =Ger_Executivo!N71 -> 4631663.2 | D36: =C36/C$50 -> 0.16272167 | E36: =C36/$E$9 -> 669.43352
B37: ALVENARIA | C37: =Ger_Executivo!N85 -> 995637.47 | D37: =C37/C$50 -> 0.034979183 | E37: =C37/$E$9 -> 143.90362
B38: IMPERMEABILIZAÇÃO E TRATAMENTOS | C38: =Ger_Executivo!N102 -> 578916.37 | D38: =C38/C$50 -> 0.02033875 | E38: =C38/$E$9 -> 83.673187
B39: INSTALAÇÕES ELÉTRICAS, HIDRÁULICAS, GLP E PREVENTIVAS | C39: =Ger_Executivo!N127+Ger_Executivo!N139+Ger_Executivo!N155+Ger_Executivo!N167 -> 2103665.3 | D39: =C39/C$50 -> 0.073906913 | E39: =C39/$E$9 -> 304.05147
B40: EQUIPAMENTOS E SISTEMAS ESPECIAIS | C40: =Ger_Executivo!N173+Ger_Executivo!N180+Ger_Executivo!N187 -> 1243883.4 | D40: =C40/C$50 -> 0.04370067 | E40: =C40/$E$9 -> 179.78363
B41: REVESTIMENTOS INTERNOS DE PAREDE | C41: =Ger_Executivo!N196 -> 1432824 | D41: =C41/C$50 -> 0.050338616 | E41: =C41/$E$9 -> 207.092
B42: REVESTIMENTOS INTERNOS DE TETO | C42: =Ger_Executivo!N217 -> 674623.17 | D42: =C42/C$50 -> 0.023701164 | E42: =C42/$E$9 -> 97.506087
B43: PISOS E PAVIMENTAÇÕES | C43: =Ger_Executivo!N227 -> 1873726.3 | D43: =C43/C$50 -> 0.065828593 | E43: =C43/$E$9 -> 270.81744
B44: PINTURA INTERNA | C44: =Ger_Executivo!N256 -> 1176215 | D44: =C44/C$50 -> 0.041323312 | E44: =C44/$E$9 -> 170.00323
B45: ESQUADRIAS, VIDROS E FERRAGENS | C45: =Ger_Executivo!N278 -> 3144968.2 | D45: =C45/C$50 -> 0.11049043 | E45: =C45/$E$9 -> 454.55531
B46: LOUÇAS E METAIS | C46: =Ger_Executivo!N318 -> 197104.8 | D46: =C46/C$50 -> 0.0069247742 | E46: =C46/$E$9 -> 28.488375
B47: REVESTIMENTOS E ACABAMENTOS EM FACHADA | C47: =Ger_Executivo!N328 -> 1075313.7 | D47: =C47/C$50 -> 0.037778404 | E47: =C47/$E$9 -> 155.41956
...

Sheet EPCs
A1: Obra | B1: ='Obra '!D1 -> Colin Schroeder
A2: Empresa | B2: ='Obra '!D2 -> Grupo DUO
A3: Revisão | B3: ='Obra '!D3 -> R00 | K3: Guia pavimentos
A4: Equipamentos de proteção coletiva | K4: Pavimento | L4: Área | M4: Perímetro | N4: Pé Direito
A5: Bandejas de proteção
K6: 3º Subsolo | L6: ='Obra '!E15 -> 563.09 | M6: =27.51+26.97+17.98+24.77 -> 97.23 | N6: 2.82
B7: Descrição | C7: Unidade | D7: Quantidade | F7: Imagem formulário | K7: 2º Subsolo | L7: ='Obra '!E16 -> 563.09 | M7: =27.51+26.97+17.98+24.77 -> 97.23 | N7: 2.82
B8: Perímetro de projeção embasamento | C8: m | D8: =M9 -> 97.23 | K8: 1º Subsolo | L8: ='Obra '!E17 -> 492.75 | M8: =27.51+26.97+17.98+24.77 -> 97.23 | N8: 2.82
B9: Perímetro de projeção Primária tipo 1 | C9: m | K9: Térreo | L9: ='Obra '!E18 -> 461.09 | M9: =27.51+26.97+17.98+24.77 -> 97.23 | N9: 3.3
B10: Perímetro de projeção torre tipo 1 | C10: m | D10: =M10 -> 71.85 | K10: 2º Pavimento | L10: ='Obra '!E19 -> 297.7 | M10: =20.05+11.8+19.46+17.06+1.8+1.68 -> 71.85 | N10: 2.68 | O10: 43.856
B11: Bandeja de proteção primária | C11: m | D11: =D8+D9 -> 97.23 | K11: 3º Pavimento - Tipo | L11: ='Obra '!$E$20/15 -> 274.77 | M11: =20.05+11.8+19.46+17.06+1.8+1.68 -> 71.85 | N11: 2.68 | O11: 53.717
B12: Bandeja de proteção secundária | C12: m | D12: =D10 -> 71.85 | K12: 4º Pavimento - Tipo | L12: ='Obra '!$E$20/15 -> 274.77 | M12: =20.05+11.8+19.46+17.06+1.8+1.68 -> 71.85 | N12: 2.68
B13: * Considerado as informações do Projeto de Segurança | K13: 5º Pavimento - Tipo | L13: ='Obra '!$E$20/15 -> 274.77 | M13: =20.05+11.8+19.46+17.06+1.8+1.68 -> 71.85 | N13: 2.68
A14: Guarda - corpo de vãos | K14: 6º Pavimento - Tipo | L14: ='Obra '!$E$20/15 -> 274.77 | M14: =20.05+11.8+19.46+17.06+1.8+1.68 -> 71.85 | N14: 2.68
K15: 7º Pavimento - Tipo | L15: ='Obra '!$E$20/15 -> 274.77 | M15: =20.05+11.8+19.46+17.06+1.8+1.68 -> 71.85 | N15: 2.68
B16: Descrição | C16: Unidade | D16: Quantidade | F16: Imagem formulário | K16: 8º Pavimento - Tipo | L16: ='Obra '!$E$20/15 -> 274.77 | M16: =20.05+11.8+19.46+17.06+1.8+1.68 -> 71.85 | N16: 2.68
B17: Perímetro de vãos | C17: m | D17: =43.86+53.72*15+74.65 -> 924.31 | K17: 9º Pavimento - Tipo | L17: ='Obra '!$E$20/15 -> 274.77 | M17: =20.05+11.8+19.46+17.06+1.8+1.68 -> 71.85 | N17: 2.68
B18: Guarda - corpo de vãos | C18: m | D18: =D17 -> 924.31 | K18: 10º Pavimento - Tipo | L18: ='Obra '!$E$20/15 -> 274.77 | M18: =20.05+11.8+19.46+17.06+1.8+1.68 -> 71.85 | N18: 2.68
K19: 11º Pavimento - Tipo | L19: ='Obra '!$E$20/15 -> 274.77 | M19: =20.05+11.8+19.46+17.06+1.8+1.68 -> 71.85 | N19: 2.68
A20: Guarda - corpo de desforma | K20: 12º Pavimento - Tipo | L20: ='Obra '!$E$20/15 -> 274.77 | M20: =20.05+11.8+19.46+17.06+1.8+1.68 -> 71.85 | N20: 2.68
K21: 13º Pavimento - Tipo | L21: ='Obra '!$E$20/15 -> 274.77 | M21: =20.05+11.8+19.46+17.06+1.8+1.68 -> 71.85 | N21: 2.68
B22: Descrição | C22: Unidade | D22: Quantidade | F22: Imagem formulário | K22: 14º Pavimento - Tipo | L22: ='Obra '!$E$20/15 -> 274.77 | M22: =20.05+11.8+19.46+17.06+1.8+1.68 -> 71.85 | N22: 2.68
B23: Perímetro de projeção da torre | C23: m | D23: =M10 -> 71.85 | K23: 15º Pavimento - Tipo | L23: ='Obra '!$E$20/15 -> 274.77 | M23: =20.05+11.8+19.46+17.06+1.8+1.68 -> 71.85 | N23: 2.68
B24: Repetições de pavimentos** | C24: un | D24: 4 | K24: 16º Pavimento - Tipo | L24: ='Obra '!$E$20/15 -> 274.77 | M24: =20.05+11.8+19.46+17.06+1.8+1.68 -> 71.85 | N24: 2.68
B25: Proteção de periferia pós desforma torre | C25: m | D25: =(D23*D24) -> 287.4 | K25: 17º Pavimento - Tipo | L25: ='Obra '!$E$20/15 -> 274.77 | M25: =20.05+11.8+19.46+17.06+1.8+1.68 -> 71.85 | N25: 2.68
K26: Nível técnico | L26: =L25 -> 274.77 | N26: 1.44 | O26: NÃO CONSIDERADO ÁREA CONSTRUÍDA
A27: Fechamento removível de vãos em madeira | K27: Plano de cobertura | L27: ='Obra '!E21 -> 283.92 | N27: 3.1 | O27: 74.65
K28: Reservatórios | L28: ='Obra '!E22 -> 39.73 | N28: 3.95
B29: Descrição | C29: Unidade | D29: Quantidade | F29: Imagem formulário | K29: Cob. Reservatório | L29: =L28 -> 39.73 | N29: 1.7
B30: Área das portas de elevadores | C30: m2 | D30: =0.9*2.1 -> 1.89
B31: Quantidade de elevadores | C31: un | D31: 2
B32: Quantidade de portas de elevadores | C32: un | D32: 22
B33: Fechamento removível de vãos em madeira | C33: m2 | D33: =D30*D32 -> 41.58
B34: Área das portas de aptos | C34: m2
B35: Quantidade de aptos | C35: un
B36: =A27 -> Fechamento removível de vãos em madeira | C36: m2 | D36: =D34*D35 -> 0
A38: Fechamento removível de vãos de portas de entrada de apto em madeira
B40: Descrição | C40: Unidade | D40: Quantidade | F40: Imagem formulário
B41: Área das portas de entrada | C41: m2 | D41: =0.9*2.1 -> 1.89
B42: Quantidade de portas de entrada | C42: un | D42: =1+2*15 -> 31
...

Sheet CANTEIRO
A1: Obra | B1: ='Obra '!D1 -> Colin Schroeder
A2: Empresa | B2: ='Obra '!D2 -> Grupo DUO
A3: Revisão | B3: ='Obra '!D3 -> R00 | O3: Número de funcionários | S3: Produtividade média (h/m2)
A4: Instalações de canteiro | O4: Área construída | P4: 6601.277 | S4: A.C/prazo | T4: =P4/P5 -> 235.75989
A5: Instalações de canteiro | O5: Prazo da obra | P5: 28 | Q5: meses | S5: Pm | T5: 49 | U5: h/m2
O6: NF | P6: =ROUNDUP((P4*T5)/P5/180,) -> 65 | Q6: funcionários
B7: Descrição | C7: Unidade | D7: Quantidade | O7: Pavimentos | P7: 10
B8: Produtividade média | C8: m2 / mês | D8: ='Obra '!$E$9/'Obra '!$E$7 -> 164.73286 | O8: Equipe administrativa | P8: 5 | Q8: funcionários
B9: Pm | C9: h/m2 | D9: 49
B10: Numero de funcionários | C10: un | D10: =ROUNDUP((D9*'Obra '!$E$9)/'Obra '!$E$7/180,) -> 45
B11: Equipe administrativa | C11: un | D11: 5 | O11: Barracão interno | P11: =450+(P4-13000)/1000*16 -> 347.62043
B12: Pontos de água e esgoto | C12: un | D12: =ROUNDUP($D$10/20,0) -> 3 | E12: 20 funcionários/ponto | O12: Externo | P12: =P11*0.4 -> 139.04817
B13: Bebedouro | C13: un | D13: =ROUNDUP('Obra '!$E$13/5,0) -> 5 | E13: 1 / 5 pav.
B14: Ferramentas | C14: R$ | D14: =800*D10 -> 36000 | E14: 800,00/func. | P14: =SUM(P11:P13) -> 486.6686
B15: EPI | C15: R$ | D15: =500*(D10+D11)*ROUND('Obra '!E7/12,0) -> 100000 | E15: 500,00/func./ano
B16: Banheiro | C16: un | D16: =ROUNDUP($D$10/20,0) -> 3 | E16: 1/20 func | O16: Área refeitório | P16: 1 | Q16: m²/funcionários
P17: =P16*P6 -> 65 | Q17: m²
A18: Mobiliário de canteiro
O19: Área de vestiário | P19: 1.5 | Q19: m²/funcionários
B20: Descrição | C20: Unidade | D20: Quantidade | E20: Custo unitário | F20: Custo total | P20: =P19*P6 -> 97.5 | Q20: m²
B21: Cadeira | C21: un | D21: =ROUNDUP(D11*1.5,) -> 8 | E21: 200 | F21: =D21*E21 -> 1600
B22: Mesa | C22: un | D22: 1 | E22: 1000 | F22: =E22*D22 -> 1000
B23: Ar condicionado | C23: un | D23: 2 | E23: 5000 | F23: =E23*D23 -> 10000
B24: Armário | C24: m | D24: 4 | E24: 900 | F24: =E24*D24 -> 3600
B25: Escrivaninha | C25: un | D25: =D11 -> 5 | E25: 800 | F25: =E25*D25 -> 4000
B26: TOTAL | F26: =F23+F24+F25+F22+F21 -> 20200
B27: Descrição | C27: Unidade | D27: Quantidade | E27: Custo unitário | F27: Custo total
B28: Computador pessoal | C28: un | D28: =D11 -> 5 | E28: 6500 | F28: =D28*E28 -> 32500
B29: Impressora | C29: un | D29: 1 | E29: 2000 | F29: =E29*D29 -> 2000
B30: Roteador | C30: un | D30: 2 | E30: 500 | F30: =E30*D30 -> 1000
B31: TOTAL | F31: =+F28+F29+F30 -> 35500 | O31: Área sanitários | P31: =1*ROUNDUP(P6/20,) -> 4 | Q31: m²
A33: Instalações Provisórias (central de aço, formas, argamassa, almoxarifado geral, construções temporárias) | O33: área lavatório | P33: =0.6*ROUNDUP(P6/20,) -> 2.4 | Q33: m²
O34: Área de chuveiros | P34: =0.8*ROUNDUP(P6/10,) -> 5.6 | Q34: m²
B35: Descrição | C35: Unidade | D35: Será utilizado | E35: Quantidade | F35: Custo unitário | G35: Custo total
B36: Central de aço | C36: m2 | D36: Sim | E36: =IF(D36="Sim",15,0) -> 15 | F36: 115.4849 | G36: =IF(D36="sim",E36*F36,0) -> 1732.2735
B37: Central de fôrmas | C37: m2 | D37: Sim | E37: =IF(D37="Sim",15,0) -> 15 | F37: 115.4849 | G37: =IF(D37="sim",E37*F37,0) -> 1732.2735
B38: Central de Argamassa | C38: m2 | D38: Sim | E38: =IF(D38="Sim",15,0) -> 15 | F38: 115.4849 | G38: =IF(D38="sim",E38*F38,0) -> 1732.2735
B39: Armazenamento de cerâmicas* | C39: m2 | D39: Sim | E39: =IF(D39="não",0,ROUNDUP(3*'Obra '!$E$10/COUNTIFS($D$39:$D$47,"Sim"),)) -> 13 | F39: 201.22489 | G39: =IF(D39="sim",E39*F39,0) -> 2615.9236
B40: Armazenamento de placas degesso* | C40: m2 | D40: Não | E40: =IF(D40="não",0,ROUNDUP(3*'Obra '!$E$10/COUNTIFS($D$39:$D$47,"Sim"),)) -> 0 | F40: 201.22489 | G40: =IF(D40="sim",E40*F40,0) -> 0
B41: Armazenamento de blocos* | C41: m2 | D41: Sim | E41: =IF(D41="não",0,ROUNDUP(3*'Obra '!$E$10/COUNTIFS($D$39:$D$47,"Sim"),)) -> 13 | F41: 201.22489 | G41: =IF(D41="sim",E41*F41,0) -> 2615.9236
...

Sheet Ensaios 
C1: Projeto | D1: ='Obra '!D1 -> Colin Schroeder
C2: Empresa | D2: ='Obra '!D2 -> Grupo DUO
C3: Revisão | D3: ='Obra '!D3 -> R00
A4: ENSAIOS
A5: Item | B5: Descrição/Especificação | C5: Unid. | D5: V. Unit. (R$) | E5: Qtde. | F5: V. Total (R$) | G5: Observações
B6: CONTROLE TECNOLÓGICO - CONCRETO | F6: =SUM(F7:F12) -> 50780
A7: 1 | B7: Laudo e ART | C7: vb | D7: 1450 | E7: 1 | F7: =$D7*E7 -> 1450
A8: =A7+1 -> 2 | B8: Controle Tecnologico Infraestrutura - Coleta materiais da obra | C8: unid. | D8: 20 | E8: =ROUNDUP((Ger_Executivo!L34+Ger_Executivo!L48+Ger_Executivo!L49)/8,0)*4 -> 388 | F8: =$D8*E8 -> 7760 | G8: 4 CPs por caminhão betoneira de 8m³
A9: =A8+1 -> 3 | B9: Controle Tecnologico Contenção - Coleta materiais da obra | C9: unid. | D9: 20 | E9: =ROUNDUP((Ger_Executivo!L57+Ger_Executivo!L68)/8,0)*4 -> 292 | F9: =$D9*E9 -> 5840 | G9: 4 CPs por caminhão betoneira de 8m³
A10: =A9+1 -> 4 | B10: Controle Tecnologico Supraestrutura - Coleta materiais da obra | C10: unid. | D10: 20 | E10: =ROUNDUP((Ger_Executivo!L79)/8,0)*4 -> 764 | F10: =$D10*E10 -> 15280 | G10: 4 CPs por caminhão betoneira de 8m³
A11: =A8+1 -> 3 | B11: Controle Tecnológico - Ensaio de concreto endurecido/grouth - compressão simples / Detalhe: Concreto | C11: cps | D11: 12.5 | E11: =E8+E9+E10 -> 1444 | F11: =$D11*E11 -> 18050
A12: =A11+1 -> 4 | B12: Determinação do módulo de deformação tangente inicial (Eci) (módulo de elasticidade), Incluindo Avaliação Estática dos Resultados (NBR 8522 e NBR 12655) | C12: ensaio | D12: 480 | E12: =ROUNDUP('Obra '!E13/5,0) -> 5 | F12: =$D12*E12 -> 2400 | G12: A cada 5 pav. (e quando houver troca de fornecedor)
B13: ENSAIO PARA GUARDA-CORPO | F13: =F14 -> 4210
A14: 1 | B14: Ensaio de guarda-corpo Determinação do esforço horizontal, esforço vertical e Resistencia a impactos | C14: ensaios | D14: 4210 | E14: 1 | F14: =$D14*E14 -> 4210 | G14: 1 prototipo por projeto
B15: ENSAIOS PARA ARGAMASSA DE REVESTIMENTO (FACHADA) | F15: =F16 -> 1260
A16: 1 | B16: Ensaio de arrancamento de argamassa de revestimento Determinação da aderencia a tração | C16: ensaios | D16: 1260 | E16: 1 | F16: =$D16*E16 -> 1260 | G16: 1 ensaio por torre
B17: ENSAIO ARRANCAMENTO DE REBOCO | F17: =F18 -> 1260
A18: 1 | B18: Ensaio de arrancamento de argamassa de reboco Determinação da aderencia a tração | C18: ensaios | D18: 1260 | E18: 1 | F18: =$D18*E18 -> 1260 | G18: 1 ensaio por torre
B19: ENSAIO PARA REVESTIMENTOS CERÂMICOS | F19: =F20 -> 664.44444
A20: 1 | B20: Aderência em Revestimento Cerâmico Determinação da aderência a tração (NBR 13754) | C20: ensaios | D20: 664.44444 | E20: 1 | F20: =$D20*E20 -> 664.44444 | G20: Torre Alta: 1 ensaio por torre, por referência de produto
B21: ENSAIO PARA ANCORAGEM (GANHOS DA COBERTURA) | F21: =SUM(F22) -> 1680
A22: 1 | B22: Arrancamento de ganchos da cobertura Ensaio de Arrancamento | C22: ensaios | D22: 1680 | E22: 1 | F22: =$D22*E22 -> 1680 | G22: 1 ensaio por torre
C23: SUBTOTAL: | F23: =F6+F13+F15+F17+F19+F21 -> 59854.444

Sheet BASES
A1: Estimativas Custos Indiretos
A2: Empresa | B2: ='Obra '!$D$2 -> Grupo DUO
A3: Obra | B3: ='Obra '!$D$1 -> Colin Schroeder
A4: Prazo de Obra | B4: ='Obra '!$E$7 -> 42 | H4: 30 | J4: 42 | N4: 42 | P4: 36
A5: Cidade/Estado | B5: Porto Belo - SC | H5: Navegantes - SC | J5: Itajaí - SC | L5: Porto Belo - SC | N5: Florianópolis | P5: Florianópolis
A6: R$/m² | B6: =$E$11/$B$8 -> #REF! | H6: 591.53 | J6: 419.37 | L6: 442.78 | N6: 1179.5 | P6: 1188.19
A7: Área de Terreno | B7: ='Obra '!$E$8 -> 1410.3 | H7: 463.3 | J7: 463.3 | L7: 675 | N7: 1817.53 | P7: 2498.8
A8: Área Construída | B8: ='Obra '!$E$9 -> 6918.78 | H8: 4498.66 | J8: 8366.5 | L8: 7055.73 | N8: 7013.06 | P8: 5579.63
A9: N° pavimentos | B9: ='Obra '!$E$13 -> 23 | H9: 12 | J9: 17 | L9: 19 | N9: 5 | P9: 6
A10: Cub | B10: ='Obra '!C51 -> 3012.64 | H10: 2750.52 | J10: 2747.9 | L10: 2846.12 | N10: 2907.85 | P10: 2907.85
A11: Data Cub | B11: 45616 | D11: Total | E11: =SUMPRODUCT($D$12:$D$342,$E$12:$E$342) -> #REF! | H11: 45139 | J11: 45108 | L11: 45566 | N11: 45717 | P11: 45717
A12: Descrição | C12: Unidade | D12: Quantidade | E12: Valor (R$) | F12: Status do Custo | G12: Indice Médio | H12: Valor | I12: Referência | J12: Valor | K12: Referência | L12: Valor | M12: Referência | N12: Valor | O12: Referência | P12: Valor | Q12: Referência
A13: TEC 01 – ESTUDOS, PROJETOS, CONSULTORIAS, ENSAIOS E LAUDOS
A14: ESTUDOS | E14: =SUMPRODUCT(D15:D23,E15:E23) -> 10300
A15: Memorial descritivo | C15: vb | D15: 1 | F15: Não Solicitado | G15: =IFERROR(AVERAGEIFS($H15:$Q15,H$12:Q$12,"Referência"),"") | I15: =IF(H15=0,"",($B$10/H$10)*H15/H$8) | J15: 0 | K15: =IF(J15=0,"",($B$10/J$10)*J15/J$8) | L15: 0 | M15: =IF(L15=0,"",($B$10/L$10)*L15/L$8) | O15: =IF(N15=0,"",($B$10/N$10)*N15/N$8) | Q15: =IF(P15=0,"",($B$10/P$10)*P15/P$8)
A16: Levantamento topográfico | C16: vb | D16: 1 | E16: 1800 | F16: Recebido | G16: =IFERROR(AVERAGEIFS($H16:$Q16,H$12:Q$12,"Referência"),"") -> 2.2254635 | H16: 27500 | I16: =IF(H16=0,"",($B$10/H$10)*H16/H$8) -> 6.6954836 | J16: 3500 | K16: =IF(J16=0,"",($B$10/J$10)*J16/J$8) -> 0.45863854 | L16: 5000 | M16: =IF(L16=0,"",($B$10/L$10)*L16/L$8) -> 0.75010504 | O16: =IF(N16=0,"",($B$10/N$10)*N16/N$8) | P16: 5372.77 | Q16: =IF(P16=0,"",($B$10/P$10)*P16/P$8) -> 0.99762675
A17: Estudo geológico | C17: vb | D17: 1 | F17: Não Solicitado | G17: =IFERROR(AVERAGEIFS($H17:$Q17,H$12:Q$12,"Referência"),"") | H17: 0 | I17: =IF(H17=0,"",($B$10/H$10)*H17/H$8) | J17: 0 | K17: =IF(J17=0,"",($B$10/J$10)*J17/J$8) | L17: 0 | M17: =IF(L17=0,"",($B$10/L$10)*L17/L$8) | O17: =IF(N17=0,"",($B$10/N$10)*N17/N$8) | Q17: =IF(P17=0,"",($B$10/P$10)*P17/P$8)
A18: Estudo ambiental | C18: vb | D18: 1 | F18: Não Solicitado | G18: =IFERROR(AVERAGEIFS($H18:$Q18,H$12:Q$12,"Referência"),"") -> 1.477808 | H18: 0 | I18: =IF(H18=0,"",($B$10/H$10)*H18/H$8) | J18: 11964.095 | K18: =IF(J18=0,"",($B$10/J$10)*J18/J$8) -> 1.56777 | L18: 4000 | M18: =IF(L18=0,"",($B$10/L$10)*L18/L$8) -> 0.60008403 | N18: 15000 | O18: =IF(N18=0,"",($B$10/N$10)*N18/N$8) -> 2.2159448 | P18: 8226.07 | Q18: =IF(P18=0,"",($B$10/P$10)*P18/P$8) -> 1.5274332
A19: Sondagem do terreno | C19: vb | D19: 1 | E19: 8500 | F19: Recebido | G19: =IFERROR(AVERAGEIFS($H19:$Q19,H$12:Q$12,"Referência"),"") -> 2.1530271 | H19: 12933 | I19: =IF(H19=0,"",($B$10/H$10)*H19/H$8) -> 3.1488251 | J19: 5500 | K19: =IF(J19=0,"",($B$10/J$10)*J19/J$8) -> 0.7207177 | L19: 4800 | M19: =IF(L19=0,"",($B$10/L$10)*L19/L$8) -> 0.72010084 | N19: 24620.6 | O19: =IF(N19=0,"",($B$10/N$10)*N19/N$8) -> 3.6371927 | P19: 13670.14 | Q19: =IF(P19=0,"",($B$10/P$10)*P19/P$8) -> 2.5382991
A20: Projeto de canteiro | C20: vb | D20: 1 | F20: Não Solicitado | G20: =IFERROR(AVERAGEIFS($H20:$Q20,H$12:Q$12,"Referência"),"") -> 0.58236585 | H20: 0 | I20: =IF(H20=0,"",($B$10/H$10)*H20/H$8) | J20: 0 | K20: =IF(J20=0,"",($B$10/J$10)*J20/J$8) | L20: 5000 | M20: =IF(L20=0,"",($B$10/L$10)*L20/L$8) -> 0.75010504 | N20: 2709.3 | O20: =IF(N20=0,"",($B$10/N$10)*N20/N$8) -> 0.40024395 | P20: 3213.82 | Q20: =IF(P20=0,"",($B$10/P$10)*P20/P$8) -> 0.59674857
A21: Estudo de Análise Técnica de Projeto | C21: vb | D21: 1 | F21: Não Solicitado | G21: =IFERROR(AVERAGEIFS($H21:$Q21,H$12:Q$12,"Referência"),"") | H21: 0 | I21: =IF(H21=0,"",($B$10/H$10)*H21/H$8) | J21: 0 | K21: =IF(J21=0,"",($B$10/J$10)*J21/J$8) | L21: 0 | M21: =IF(L21=0,"",($B$10/L$10)*L21/L$8) | O21: =IF(N21=0,"",($B$10/N$10)*N21/N$8) | Q21: =IF(P21=0,"",($B$10/P$10)*P21/P$8)
A22: Estudo Rebaixamento de Lençol Freático | C22: vb | D22: 1 | F22: Não Solicitado | G22: =IFERROR(AVERAGEIFS($H22:$Q22,H$12:Q$12,"Referência"),"") | H22: 0 | I22: =IF(H22=0,"",($B$10/H$10)*H22/H$8) | J22: 0 | K22: =IF(J22=0,"",($B$10/J$10)*J22/J$8) | L22: 0 | M22: =IF(L22=0,"",($B$10/L$10)*L22/L$8) | O22: =IF(N22=0,"",($B$10/N$10)*N22/N$8) | Q22: =IF(P22=0,"",($B$10/P$10)*P22/P$8)
A23: Informações complementares de Estudos | C23: vb | D23: 1 | F23: Não Solicitado | G23: =IFERROR(AVERAGEIFS($H23:$Q23,H$12:Q$12,"Referência"),"") | H23: 0 | I23: =IF(H23=0,"",($B$10/H$10)*H23/H$8) | J23: 0 | K23: =IF(J23=0,"",($B$10/J$10)*J23/J$8) | L23: 0 | M23: =IF(L23=0,"",($B$10/L$10)*L23/L$8) | O23: =IF(N23=0,"",($B$10/N$10)*N23/N$8) | Q23: =IF(P23=0,"",($B$10/P$10)*P23/P$8)
A24: Projetos - Arquitetonico | E24: =SUMPRODUCT(D25:D31,E25:E31) -> 329231.36 | I24: =IF(H24=0,"",($B$10/H$10)*H24/H$8) | K24: =IF(J24=0,"",($B$10/J$10)*J24/J$8) | M24: =IF(L24=0,"",($B$10/L$10)*L24/L$8) | O24: =IF(N24=0,"",($B$10/N$10)*N24/N$8) | Q24: =IF(P24=0,"",($B$10/P$10)*P24/P$8)
A25: Legalização de incorporação | C25: vb | D25: 1 | F25: Não Solicitado | G25: =IFERROR(AVERAGEIFS($H25:$Q25,H$12:Q$12,"Referência"),"") -> 2.890017 | H25: 15500 | I25: =IF(H25=0,"",($B$10/H$10)*H25/H$8) -> 3.7738181 | J25: 15310 | K25: =IF(J25=0,"",($B$10/J$10)*J25/J$8) -> 2.006216 | L25: 0 | M25: =IF(L25=0,"",($B$10/L$10)*L25/L$8) | O25: =IF(N25=0,"",($B$10/N$10)*N25/N$8) | Q25: =IF(P25=0,"",($B$10/P$10)*P25/P$8)
A26: Projeto Arquitetônico | C26: vb | D26: 1 | F26: Não Solicitado | G26: =IFERROR(AVERAGEIFS($H26:$Q26,H$12:Q$12,"Referência"),"") -> 10.210643 | H26: 67500 | I26: =IF(H26=0,"",($B$10/H$10)*H26/H$8) -> 16.434369 | J26: 74000 | K26: =IF(J26=0,"",($B$10/J$10)*J26/J$8) -> 9.6969291 | L26: 30000 | M26: =IF(L26=0,"",($B$10/L$10)*L26/L$8) -> 4.5006302 | O26: =IF(N26=0,"",($B$10/N$10)*N26/N$8) | Q26: =IF(P26=0,"",($B$10/P$10)*P26/P$8)
A27: Projeto Arquitetônico legal - incluindo: executivo + interiores + fachada | C27: vb | D27: 1 | E27: 320000 | F27: Recebido | G27: =IFERROR(AVERAGEIFS($H27:$Q27,H$12:Q$12,"Referência"),"") -> 4.7594165 | H27: 0 | I27: =IF(H27=0,"",($B$10/H$10)*H27/H$8) | J27: 0 | K27: =IF(J27=0,"",($B$10/J$10)*J27/J$8) | L27: 31725 | M27: =IF(L27=0,"",($B$10/L$10)*L27/L$8) -> 4.7594165 | O27: =IF(N27=0,"",($B$10/N$10)*N27/N$8) | Q27: =IF(P27=0,"",($B$10/P$10)*P27/P$8)
A28: Projeto Arquitetônico Executivo | C28: vb | D28: 1 | F28: Não Solicitado | G28: =IFERROR(AVERAGEIFS($H28:$Q28,H$12:Q$12,"Referência"),"") -> 21.584563 | H28: 0 | I28: =IF(H28=0,"",($B$10/H$10)*H28/H$8) | J28: 0 | K28: =IF(J28=0,"",($B$10/J$10)*J28/J$8) | L28: 31725 | M28: =IF(L28=0,"",($B$10/L$10)*L28/L$8) -> 4.7594165 | N28: 260000 | O28: =IF(N28=0,"",($B$10/N$10)*N28/N$8) -> 38.40971 | Q28: =IF(P28=0,"",($B$10/P$10)*P28/P$8)
A29: Projeto Arquitetônico interiores | C29: vb | D29: 1 | F29: Não Solicitado | G29: =IFERROR(AVERAGEIFS($H29:$Q29,H$12:Q$12,"Referência"),"") -> 6.9367285 | H29: 34500 | I29: =IF(H29=0,"",($B$10/H$10)*H29/H$8) -> 8.3997886 | J29: 65550 | K29: =IF(J29=0,"",($B$10/J$10)*J29/J$8) -> 8.5896446 | L29: 14100 | M29: =IF(L29=0,"",($B$10/L$10)*L29/L$8) -> 2.1152962 | N29: 58500 | O29: =IF(N29=0,"",($B$10/N$10)*N29/N$8) -> 8.6421848 | Q29: =IF(P29=0,"",($B$10/P$10)*P29/P$8)
A30: Projeto arquitetônico de fachada | C30: vb | D30: 1 | F30: Não Solicitado | G30: =IFERROR(AVERAGEIFS($H30:$Q30,H$12:Q$12,"Referência"),"") -> 1.3342472 | H30: 6200 | I30: =IF(H30=0,"",($B$10/H$10)*H30/H$8) -> 1.5095272 | J30: 2884 | K30: =IF(J30=0,"",($B$10/J$10)*J30/J$8) -> 0.37791815 | L30: 14100 | M30: =IF(L30=0,"",($B$10/L$10)*L30/L$8) -> 2.1152962 | O30: =IF(N30=0,"",($B$10/N$10)*N30/N$8) | Q30: =IF(P30=0,"",($B$10/P$10)*P30/P$8)
A31: Projeto técnico de fachada | C31: vb | D31: 1 | E31: =G31*$B$8 -> 9231.3628 | F31: Estimado | G31: =IFERROR(AVERAGEIFS($H31:$Q31,H$12:Q$12,"Referência"),"") -> 1.3342472 | H31: 6200 | I31: =IF(H31=0,"",($B$10/H$10)*H31/H$8) -> 1.5095272 | J31: 2884 | K31: =IF(J31=0,"",($B$10/J$10)*J31/J$8) -> 0.37791815 | L31: 14100 | M31: =IF(L31=0,"",($B$10/L$10)*L31/L$8) -> 2.1152962 | O31: =IF(N31=0,"",($B$10/N$10)*N31/N$8) | Q31: =IF(P31=0,"",($B$10/P$10)*P31/P$8)
A32: Projetos - Estrutural | E32: =SUMPRODUCT(D33:D37,E33:E37) -> 70469.17 | I32: =IF(H32=0,"",($B$10/H$10)*H32/H$8) | K32: =IF(J32=0,"",($B$10/J$10)*J32/J$8) | M32: =IF(L32=0,"",($B$10/L$10)*L32/L$8) | O32: =IF(N32=0,"",($B$10/N$10)*N32/N$8) | Q32: =IF(P32=0,"",($B$10/P$10)*P32/P$8)
A33: Projeto de terraplanagem | C33: vb | F33: Não Solicitado | G33: =IFERROR(AVERAGEIFS($H33:$Q33,H$12:Q$12,"Referência"),"") -> 0.19655937 | I33: =IF(H33=0,"",($B$10/H$10)*H33/H$8) | J33: 1500 | K33: =IF(J33=0,"",($B$10/J$10)*J33/J$8) -> 0.19655937 | L33: 0 | M33: =IF(L33=0,"",($B$10/L$10)*L33/L$8) | O33: =IF(N33=0,"",($B$10/N$10)*N33/N$8) | Q33: =IF(P33=0,"",($B$10/P$10)*P33/P$8)
A34: Projeto de Fundações | B34: à atualizar | C34: vb | D34: 1 | E34: =G34*$B$8 -> 20568.443 | F34: Estimado | G34: =IFERROR(AVERAGEIFS($H34:$Q34,H$12:Q$12,"Referência"),"") -> 2.9728425 | H34: 0 | I34: =IF(H34=0,"",($B$10/H$10)*H34/H$8) | J34: 7635 | K34: =IF(J34=0,"",($B$10/J$10)*J34/J$8) -> 1.0004872 | L34: 8000 | M34: =IF(L34=0,"",($B$10/L$10)*L34/L$8) -> 1.2001681 | N34: 50000 | O34: =IF(N34=0,"",($B$10/N$10)*N34/N$8) -> 7.3864828 | P34: 12409.56 | Q34: =IF(P34=0,"",($B$10/P$10)*P34/P$8) -> 2.3042321
A35: Projeto estrutural | B35: à atualizar | C35: vb | D35: 1 | E35: =G35*$B$8 -> 49900.727 | F35: Estimado | G35: =IFERROR(AVERAGEIFS($H35:$Q35,H$12:Q$12,"Referência"),"") -> 7.2123592 | H35: 29341.44 | I35: =IF(H35=0,"",($B$10/H$10)*H35/H$8) -> 7.143823 | J35: 41100 | K35: =IF(J35=0,"",($B$10/J$10)*J35/J$8) -> 5.3857268 | L35: 58000 | M35: =IF(L35=0,"",($B$10/L$10)*L35/L$8) -> 8.7012184 | O35: =IF(N35=0,"",($B$10/N$10)*N35/N$8) | P35: 41030.73 | Q35: =IF(P35=0,"",($B$10/P$10)*P35/P$8) -> 7.6186686
A36: Projeto de estrutura metálica | C36: vb | F36: Não Solicitado | G36: =IFERROR(AVERAGEIFS($H36:$Q36,H$12:Q$12,"Referência"),"") | H36: 0 | I36: =IF(H36=0,"",($B$10/H$10)*H36/H$8) | J36: 0 | K36: =IF(J36=0,"",($B$10/J$10)*J36/J$8) | L36: 0 | M36: =IF(L36=0,"",($B$10/L$10)*L36/L$8) | O36: =IF(N36=0,"",($B$10/N$10)*N36/N$8) | Q36: =IF(P36=0,"",($B$10/P$10)*P36/P$8)
A37: Projeto de alvenaria estrutural | C37: vb | F37: Não Solicitado | G37: =IFERROR(AVERAGEIFS($H37:$Q37,H$12:Q$12,"Referência"),"") | H37: 0 | I37: =IF(H37=0,"",($B$10/H$10)*H37/H$8) | J37: 0 | K37: =IF(J37=0,"",($B$10/J$10)*J37/J$8) | L37: 0 | M37: =IF(L37=0,"",($B$10/L$10)*L37/L$8) | O37: =IF(N37=0,"",($B$10/N$10)*N37/N$8) | Q37: =IF(P37=0,"",($B$10/P$10)*P37/P$8)
A38: Projetos - Complementares | E38: =SUMPRODUCT(D39:D56,E39:E56) -> 114402.62 | I38: =IF(H38=0,"",($B$10/H$10)*H38/H$8) | K38: =IF(J38=0,"",($B$10/J$10)*J38/J$8) | M38: =IF(L38=0,"",($B$10/L$10)*L38/L$8) | O38: =IF(N38=0,"",($B$10/N$10)*N38/N$8) | Q38: =IF(P38=0,"",($B$10/P$10)*P38/P$8)
A39: Projeto elétrico/comunicação/telefonia/luminotécnico | C39: vb | D39: 1 | E39: 32200 | F39: Recebido | G39: =IFERROR(AVERAGEIFS($H39:$Q39,H$12:Q$12,"Referência"),"") -> 2.0501437 | H39: 9000 | I39: =IF(H39=0,"",($B$10/H$10)*H39/H$8) -> 2.1912492 | J39: 6000 | K39: =IF(J39=0,"",($B$10/J$10)*J39/J$8) -> 0.78623749 | L39: 21150 | M39: =IF(L39=0,"",($B$10/L$10)*L39/L$8) -> 3.1729443 | O39: =IF(N39=0,"",($B$10/N$10)*N39/N$8) | Q39: =IF(P39=0,"",($B$10/P$10)*P39/P$8)
A40: Projeto elétrico | C40: vb | D40: 1 | F40: Não Solicitado | G40: =IFERROR(AVERAGEIFS($H40:$Q40,H$12:Q$12,"Referência"),"") | H40: 0 | I40: =IF(H40=0,"",($B$10/H$10)*H40/H$8) | J40: 0 | K40: =IF(J40=0,"",($B$10/J$10)*J40/J$8) | L40: 0 | M40: =IF(L40=0,"",($B$10/L$10)*L40/L$8) | O40: =IF(N40=0,"",($B$10/N$10)*N40/N$8) | Q40: =IF(P40=0,"",($B$10/P$10)*P40/P$8)
...

Sheet Ger_Tec e Adm
G4: PROJETO: | I4: ='Obra '!D1 -> Colin Schroeder | O4: REVISÃO: | P4: DATA
G5: EMPRESA: | I5: ='Obra '!D2 -> Grupo DUO | O5: ='Obra '!D3 -> R00 | P5: 45551
A6: Unidade Construtiva | B6: Célula Construtiva | C6: Etapa | D6: Subetapa | E6: Serviço | G6: GERENCIAMENTO EXECUTIVO
A7: 0 | B7: 0 | C7: 0 | D7: 0 | E7: 0 | G7: Atalho | H7: NIVEL | I7: Item | J7: Descrição | K7: Unidade | L7: Quant. | M7: Preço un | N7: Total | O7: Considerações | P7: Situação
A8: =IF($H8="UNIDADE CONSTRUTIVA",OFFSET(A8,-1,0)+1,LARGE(A$3:A7,1)) -> 0 | B8: =IF(H8="UNIDADE CONSTRUTIVA",0,IF(H8="CÉLULA CONSTRUTIVA",OFFSET(B8,-1,0)+1,OFFSET(B8,-1,0))) -> 1 | C8: =IF(H8="CÉLULA CONSTRUTIVA",0,IF(H8="ETAPA",OFFSET(C8,-1,0)+1,OFFSET(C8,-1,0))) -> 0 | D8: =IF(H8="ETAPA",0,IF(H8="SUBETAPA",OFFSET(D8,-1,0)+1,OFFSET(D8,-1,0))) -> 0 | E8: =IF(H8="Subetapa",0,IF(H8="serviço",OFFSET(E8,-1,0)+1,OFFSET(E8,-1,0))) -> 0 | H8: CÉLULA CONSTRUTIVA | I8: =IF(H8="Unidade Construtiva",TEXT(A8,"00"),IF(H8="Célula Construtiva",TEXT(B8,"00"),IF(H8="Etapa",CONCATENATE(TEXT(B8,"00"),".",TEXT(C8,"000")),IF(H8="Subetapa",CONCATENATE(TEXT(B8,"00"),".",TEXT(C8,"000"),".",TEXT(D8,"000")),IF(H8="Serviço",CONCATENATE(TEXT(B8,"00"),".",TEXT(C8,"000"),".",TEXT(D8,"000"),".",TEXT(E8,"000")),""))))) -> 01 | J8: SERVIÇOS TÉCNICOS | N8: =IF(H8="Serviço",M8*L8,IF(H8="CÉLULA CONSTRUTIVA",SUMIFS($N$8:$N$419,$B$8:$B$419,B8,$H$8:$H$419,"Serviço"),IF(H8="ETAPA",SUMIFS($N$8:$N$419,$B$8:$B$419,B8,$C$8:$C$419,C8,$H$8:$H$419,"Serviço"),IF(H8="SUBETAPA",SUMIFS($N$8:$N$419,$B$8:$B$419,B8,$C$8:$C$419,C8,$D$8:$D$419,D8,$H$8:$H$419,"Serviço"),0)))) -> 2405432.1 | Q8: =N8/'Obra '!$C$32 -> 0.50387247
A9: =IF($H9="UNIDADE CONSTRUTIVA",OFFSET(A9,-1,0)+1,LARGE(A$3:A8,1)) -> 0 | B9: =IF(H9="UNIDADE CONSTRUTIVA",0,IF(H9="CÉLULA CONSTRUTIVA",OFFSET(B9,-1,0)+1,OFFSET(B9,-1,0))) -> 1 | C9: =IF(H9="CÉLULA CONSTRUTIVA",0,IF(H9="ETAPA",OFFSET(C9,-1,0)+1,OFFSET(C9,-1,0))) -> 1 | D9: =IF(H9="ETAPA",0,IF(H9="SUBETAPA",OFFSET(D9,-1,0)+1,OFFSET(D9,-1,0))) -> 0 | E9: =IF(H9="Subetapa",0,IF(H9="serviço",OFFSET(E9,-1,0)+1,OFFSET(E9,-1,0))) -> 0 | H9: ETAPA | I9: =IF(H9="Unidade Construtiva",TEXT(A9,"00"),IF(H9="Célula Construtiva",TEXT(B9,"00"),IF(H9="Etapa",CONCATENATE(TEXT(B9,"00"),".",TEXT(C9,"000")),IF(H9="Subetapa",CONCATENATE(TEXT(B9,"00"),".",TEXT(C9,"000"),".",TEXT(D9,"000")),IF(H9="Serviço",CONCATENATE(TEXT(B9,"00"),".",TEXT(C9,"000"),".",TEXT(D9,"000"),".",TEXT(E9,"000")),""))))) -> 01.001 | J9: ESTUDOS, PROJETOS, CONSULTORIA E ENSAIOS | N9: =IF(H9="Serviço",M9*L9,IF(H9="CÉLULA CONSTRUTIVA",SUMIFS($N$8:$N$419,$B$8:$B$419,B9,$H$8:$H$419,"Serviço"),IF(H9="ETAPA",SUMIFS($N$8:$N$419,$B$8:$B$419,B9,$C$8:$C$419,C9,$H$8:$H$419,"Serviço"),IF(H9="SUBETAPA",SUMIFS($N$8:$N$419,$B$8:$B$419,B9,$C$8:$C$419,C9,$D$8:$D$419,D9,$H$8:$H$419,"Serviço"),0)))) -> 772571.76 | Q9: =N9/'Obra '!$C$32 -> 0.16183273
A10: =IF($H10="UNIDADE CONSTRUTIVA",OFFSET(A10,-1,0)+1,LARGE(A$3:A9,1)) -> 0 | B10: =IF(H10="UNIDADE CONSTRUTIVA",0,IF(H10="CÉLULA CONSTRUTIVA",OFFSET(B10,-1,0)+1,OFFSET(B10,-1,0))) -> 1 | C10: =IF(H10="CÉLULA CONSTRUTIVA",0,IF(H10="ETAPA",OFFSET(C10,-1,0)+1,OFFSET(C10,-1,0))) -> 1 | D10: =IF(H10="ETAPA",0,IF(H10="SUBETAPA",OFFSET(D10,-1,0)+1,OFFSET(D10,-1,0))) -> 1 | E10: =IF(H10="Subetapa",0,IF(H10="serviço",OFFSET(E10,-1,0)+1,OFFSET(E10,-1,0))) -> 0 | H10: SUBETAPA | I10: =IF(H10="Unidade Construtiva",TEXT(A10,"00"),IF(H10="Célula Construtiva",TEXT(B10,"00"),IF(H10="Etapa",CONCATENATE(TEXT(B10,"00"),".",TEXT(C10,"000")),IF(H10="Subetapa",CONCATENATE(TEXT(B10,"00"),".",TEXT(C10,"000"),".",TEXT(D10,"000")),IF(H10="Serviço",CONCATENATE(TEXT(B10,"00"),".",TEXT(C10,"000"),".",TEXT(D10,"000"),".",TEXT(E10,"000")),""))))) -> 01.001.001 | J10: Estudos | N10: =IF(H10="Serviço",M10*L10,IF(H10="CÉLULA CONSTRUTIVA",SUMIFS($N$8:$N$419,$B$8:$B$419,B10,$H$8:$H$419,"Serviço"),IF(H10="ETAPA",SUMIFS($N$8:$N$419,$B$8:$B$419,B10,$C$8:$C$419,C10,$H$8:$H$419,"Serviço"),IF(H10="SUBETAPA",SUMIFS($N$8:$N$419,$B$8:$B$419,B10,$C$8:$C$419,C10,$D$8:$D$419,D10,$H$8:$H$419,"Serviço"),0)))) -> 10300 | Q10: =N10/'Obra '!$C$32 -> 0.0021575693
A11: =IF($H11="UNIDADE CONSTRUTIVA",OFFSET(A11,-1,0)+1,LARGE(A$3:A10,1)) -> 0 | B11: =IF(H11="UNIDADE CONSTRUTIVA",0,IF(H11="CÉLULA CONSTRUTIVA",OFFSET(B11,-1,0)+1,OFFSET(B11,-1,0))) -> 1 | C11: =IF(H11="CÉLULA CONSTRUTIVA",0,IF(H11="ETAPA",OFFSET(C11,-1,0)+1,OFFSET(C11,-1,0))) -> 1 | D11: =IF(H11="ETAPA",0,IF(H11="SUBETAPA",OFFSET(D11,-1,0)+1,OFFSET(D11,-1,0))) -> 1 | E11: =IF(H11="Subetapa",0,IF(H11="serviço",OFFSET(E11,-1,0)+1,OFFSET(E11,-1,0))) -> 1 | H11: SERVIÇO | I11: =IF(H11="Unidade Construtiva",TEXT(A11,"00"),IF(H11="Célula Construtiva",TEXT(B11,"00"),IF(H11="Etapa",CONCATENATE(TEXT(B11,"00"),".",TEXT(C11,"000")),IF(H11="Subetapa",CONCATENATE(TEXT(B11,"00"),".",TEXT(C11,"000"),".",TEXT(D11,"000")),IF(H11="Serviço",CONCATENATE(TEXT(B11,"00"),".",TEXT(C11,"000"),".",TEXT(D11,"000"),".",TEXT(E11,"000")),""))))) -> 01.001.001.001 | J11: Levantamento Topográfico | K11: =IFERROR(VLOOKUP(J11,BASES!$A$13:$E$342,3,FALSE),0) -> vb | L11: =IFERROR(VLOOKUP(J11,BASES!$A$13:$E$342,4,FALSE),0) -> 1 | M11: =IFERROR(VLOOKUP(J11,BASES!$A$13:$E$342,5,FALSE),0) -> 1800 | N11: =IF(H11="Serviço",M11*L11,IF(H11="CÉLULA CONSTRUTIVA",SUMIFS($N$8:$N$419,$B$8:$B$419,B11,$H$8:$H$419,"Serviço"),IF(H11="ETAPA",SUMIFS($N$8:$N$419,$B$8:$B$419,B11,$C$8:$C$419,C11,$H$8:$H$419,"Serviço"),IF(H11="SUBETAPA",SUMIFS($N$8:$N$419,$B$8:$B$419,B11,$C$8:$C$419,C11,$D$8:$D$419,D11,$H$8:$H$419,"Serviço"),0)))) -> 1800 | O11: =IF(VLOOKUP(J11,BASES!$A$13:$F$342,6,FALSE)="Recebido","Valor informado em formulário",IF(VLOOKUP(J11,BASES!$A$13:$F$342,6,FALSE)="Estimado","Estimado com base em índices históricos","Não solicitado")) -> Valor informado em formulário | P11: Lançado ERP
A12: =IF($H12="UNIDADE CONSTRUTIVA",OFFSET(A12,-1,0)+1,LARGE(A$3:A11,1)) -> 0 | B12: =IF(H12="UNIDADE CONSTRUTIVA",0,IF(H12="CÉLULA CONSTRUTIVA",OFFSET(B12,-1,0)+1,OFFSET(B12,-1,0))) -> 1 | C12: =IF(H12="CÉLULA CONSTRUTIVA",0,IF(H12="ETAPA",OFFSET(C12,-1,0)+1,OFFSET(C12,-1,0))) -> 1 | D12: =IF(H12="ETAPA",0,IF(H12="SUBETAPA",OFFSET(D12,-1,0)+1,OFFSET(D12,-1,0))) -> 1 | E12: =IF(H12="Subetapa",0,IF(H12="serviço",OFFSET(E12,-1,0)+1,OFFSET(E12,-1,0))) -> 2 | H12: SERVIÇO | I12: =IF(H12="Unidade Construtiva",TEXT(A12,"00"),IF(H12="Célula Construtiva",TEXT(B12,"00"),IF(H12="Etapa",CONCATENATE(TEXT(B12,"00"),".",TEXT(C12,"000")),IF(H12="Subetapa",CONCATENATE(TEXT(B12,"00"),".",TEXT(C12,"000"),".",TEXT(D12,"000")),IF(H12="Serviço",CONCATENATE(TEXT(B12,"00"),".",TEXT(C12,"000"),".",TEXT(D12,"000"),".",TEXT(E12,"000")),""))))) -> 01.001.001.002 | J12: Sondagem do terreno | K12: =IFERROR(VLOOKUP(J12,BASES!$A$13:$E$342,3,FALSE),0) -> vb | L12: =IFERROR(VLOOKUP(J12,BASES!$A$13:$E$342,4,FALSE),0) -> 1 | M12: =IFERROR(VLOOKUP(J12,BASES!$A$13:$E$342,5,FALSE),0) -> 8500 | N12: =IF(H12="Serviço",M12*L12,IF(H12="CÉLULA CONSTRUTIVA",SUMIFS($N$8:$N$419,$B$8:$B$419,B12,$H$8:$H$419,"Serviço"),IF(H12="ETAPA",SUMIFS($N$8:$N$419,$B$8:$B$419,B12,$C$8:$C$419,C12,$H$8:$H$419,"Serviço"),IF(H12="SUBETAPA",SUMIFS($N$8:$N$419,$B$8:$B$419,B12,$C$8:$C$419,C12,$D$8:$D$419,D12,$H$8:$H$419,"Serviço"),0)))) -> 8500 | O12: =IF(VLOOKUP(J12,BASES!$A$13:$F$342,6,FALSE)="Recebido","Valor informado em formulário",IF(VLOOKUP(J12,BASES!$A$13:$F$342,6,FALSE)="Estimado","Estimado com base em índices históricos","Não solicitado")) -> Valor informado em formulário | P12: Lançado ERP
A13: =IF($H13="UNIDADE CONSTRUTIVA",OFFSET(A13,-1,0)+1,LARGE(A$3:A12,1)) -> 0 | B13: =IF(H13="UNIDADE CONSTRUTIVA",0,IF(H13="CÉLULA CONSTRUTIVA",OFFSET(B13,-1,0)+1,OFFSET(B13,-1,0))) -> 1 | C13: =IF(H13="CÉLULA CONSTRUTIVA",0,IF(H13="ETAPA",OFFSET(C13,-1,0)+1,OFFSET(C13,-1,0))) -> 1 | D13: =IF(H13="ETAPA",0,IF(H13="SUBETAPA",OFFSET(D13,-1,0)+1,OFFSET(D13,-1,0))) -> 2 | E13: =IF(H13="Subetapa",0,IF(H13="serviço",OFFSET(E13,-1,0)+1,OFFSET(E13,-1,0))) -> 0 | H13: SUBETAPA | I13: =IF(H13="Unidade Construtiva",TEXT(A13,"00"),IF(H13="Célula Construtiva",TEXT(B13,"00"),IF(H13="Etapa",CONCATENATE(TEXT(B13,"00"),".",TEXT(C13,"000")),IF(H13="Subetapa",CONCATENATE(TEXT(B13,"00"),".",TEXT(C13,"000"),".",TEXT(D13,"000")),IF(H13="Serviço",CONCATENATE(TEXT(B13,"00"),".",TEXT(C13,"000"),".",TEXT(D13,"000"),".",TEXT(E13,"000")),""))))) -> 01.001.002 | J13: Projetos | N13: =IF(H13="Serviço",M13*L13,IF(H13="CÉLULA CONSTRUTIVA",SUMIFS($N$8:$N$419,$B$8:$B$419,B13,$H$8:$H$419,"Serviço"),IF(H13="ETAPA",SUMIFS($N$8:$N$419,$B$8:$B$419,B13,$C$8:$C$419,C13,$H$8:$H$419,"Serviço"),IF(H13="SUBETAPA",SUMIFS($N$8:$N$419,$B$8:$B$419,B13,$C$8:$C$419,C13,$D$8:$D$419,D13,$H$8:$H$419,"Serviço"),0)))) -> 552152.35 | Q13: =N13/'Obra '!$C$32 -> 0.11566087
A14: =IF($H14="UNIDADE CONSTRUTIVA",OFFSET(A14,-1,0)+1,LARGE(A$3:A13,1)) -> 0 | B14: =IF(H14="UNIDADE CONSTRUTIVA",0,IF(H14="CÉLULA CONSTRUTIVA",OFFSET(B14,-1,0)+1,OFFSET(B14,-1,0))) -> 1 | C14: =IF(H14="CÉLULA CONSTRUTIVA",0,IF(H14="ETAPA",OFFSET(C14,-1,0)+1,OFFSET(C14,-1,0))) -> 1 | D14: =IF(H14="ETAPA",0,IF(H14="SUBETAPA",OFFSET(D14,-1,0)+1,OFFSET(D14,-1,0))) -> 2 | E14: =IF(H14="Subetapa",0,IF(H14="serviço",OFFSET(E14,-1,0)+1,OFFSET(E14,-1,0))) -> 1 | H14: SERVIÇO | I14: =IF(H14="Unidade Construtiva",TEXT(A14,"00"),IF(H14="Célula Construtiva",TEXT(B14,"00"),IF(H14="Etapa",CONCATENATE(TEXT(B14,"00"),".",TEXT(C14,"000")),IF(H14="Subetapa",CONCATENATE(TEXT(B14,"00"),".",TEXT(C14,"000"),".",TEXT(D14,"000")),IF(H14="Serviço",CONCATENATE(TEXT(B14,"00"),".",TEXT(C14,"000"),".",TEXT(D14,"000"),".",TEXT(E14,"000")),""))))) -> 01.001.002.001 | J14: Projeto Arquitetônico legal - incluindo: executivo + interiores + fachada | K14: =IFERROR(VLOOKUP(J14,BASES!$A$13:$E$342,3,FALSE),0) -> vb | L14: =IFERROR(VLOOKUP(J14,BASES!$A$13:$E$342,4,FALSE),0) -> 1 | M14: =IFERROR(VLOOKUP(J14,BASES!$A$13:$E$342,5,FALSE),0) -> 320000 | N14: =IF(H14="Serviço",M14*L14,IF(H14="CÉLULA CONSTRUTIVA",SUMIFS($N$8:$N$419,$B$8:$B$419,B14,$H$8:$H$419,"Serviço"),IF(H14="ETAPA",SUMIFS($N$8:$N$419,$B$8:$B$419,B14,$C$8:$C$419,C14,$H$8:$H$419,"Serviço"),IF(H14="SUBETAPA",SUMIFS($N$8:$N$419,$B$8:$B$419,B14,$C$8:$C$419,C14,$D$8:$D$419,D14,$H$8:$H$419,"Serviço"),0)))) -> 320000 | O14: =IF(VLOOKUP(J14,BASES!$A$13:$F$342,6,FALSE)="Recebido","Valor informado em formulário",IF(VLOOKUP(J14,BASES!$A$13:$F$342,6,FALSE)="Estimado","Estimado com base em índices históricos","Não solicitado")) -> Valor informado em formulário | P14: Lançado ERP
A15: =IF($H15="UNIDADE CONSTRUTIVA",OFFSET(A15,-1,0)+1,LARGE(A$3:A14,1)) -> 0 | B15: =IF(H15="UNIDADE CONSTRUTIVA",0,IF(H15="CÉLULA CONSTRUTIVA",OFFSET(B15,-1,0)+1,OFFSET(B15,-1,0))) -> 1 | C15: =IF(H15="CÉLULA CONSTRUTIVA",0,IF(H15="ETAPA",OFFSET(C15,-1,0)+1,OFFSET(C15,-1,0))) -> 1 | D15: =IF(H15="ETAPA",0,IF(H15="SUBETAPA",OFFSET(D15,-1,0)+1,OFFSET(D15,-1,0))) -> 2 | E15: =IF(H15="Subetapa",0,IF(H15="serviço",OFFSET(E15,-1,0)+1,OFFSET(E15,-1,0))) -> 2 | H15: SERVIÇO | I15: =IF(H15="Unidade Construtiva",TEXT(A15,"00"),IF(H15="Célula Construtiva",TEXT(B15,"00"),IF(H15="Etapa",CONCATENATE(TEXT(B15,"00"),".",TEXT(C15,"000")),IF(H15="Subetapa",CONCATENATE(TEXT(B15,"00"),".",TEXT(C15,"000"),".",TEXT(D15,"000")),IF(H15="Serviço",CONCATENATE(TEXT(B15,"00"),".",TEXT(C15,"000"),".",TEXT(D15,"000"),".",TEXT(E15,"000")),""))))) -> 01.001.002.002 | J15: Projeto técnico de fachada | K15: =IFERROR(VLOOKUP(J15,BASES!$A$13:$E$342,3,FALSE),0) -> vb | L15: =IFERROR(VLOOKUP(J15,BASES!$A$13:$E$342,4,FALSE),0) -> 1 | M15: =IFERROR(VLOOKUP(J15,BASES!$A$13:$E$342,5,FALSE),0) -> 9231.3628 | N15: =IF(H15="Serviço",M15*L15,IF(H15="CÉLULA CONSTRUTIVA",SUMIFS($N$8:$N$419,$B$8:$B$419,B15,$H$8:$H$419,"Serviço"),IF(H15="ETAPA",SUMIFS($N$8:$N$419,$B$8:$B$419,B15,$C$8:$C$419,C15,$H$8:$H$419,"Serviço"),IF(H15="SUBETAPA",SUMIFS($N$8:$N$419,$B$8:$B$419,B15,$C$8:$C$419,C15,$D$8:$D$419,D15,$H$8:$H$419,"Serviço"),0)))) -> 9231.3628 | O15: =IF(VLOOKUP(J15,BASES!$A$13:$F$342,6,FALSE)="Recebido","Valor informado em formulário",IF(VLOOKUP(J15,BASES!$A$13:$F$342,6,FALSE)="Estimado","Estimado com base em índices históricos","Não solicitado")) -> Estimado com base em índices históricos | P15: Lançado ERP
A16: =IF($H16="UNIDADE CONSTRUTIVA",OFFSET(A16,-1,0)+1,LARGE(A$3:A15,1)) -> 0 | B16: =IF(H16="UNIDADE CONSTRUTIVA",0,IF(H16="CÉLULA CONSTRUTIVA",OFFSET(B16,-1,0)+1,OFFSET(B16,-1,0))) -> 1 | C16: =IF(H16="CÉLULA CONSTRUTIVA",0,IF(H16="ETAPA",OFFSET(C16,-1,0)+1,OFFSET(C16,-1,0))) -> 1 | D16: =IF(H16="ETAPA",0,IF(H16="SUBETAPA",OFFSET(D16,-1,0)+1,OFFSET(D16,-1,0))) -> 2 | E16: =IF(H16="Subetapa",0,IF(H16="serviço",OFFSET(E16,-1,0)+1,OFFSET(E16,-1,0))) -> 3 | H16: SERVIÇO | I16: =IF(H16="Unidade Construtiva",TEXT(A16,"00"),IF(H16="Célula Construtiva",TEXT(B16,"00"),IF(H16="Etapa",CONCATENATE(TEXT(B16,"00"),".",TEXT(C16,"000")),IF(H16="Subetapa",CONCATENATE(TEXT(B16,"00"),".",TEXT(C16,"000"),".",TEXT(D16,"000")),IF(H16="Serviço",CONCATENATE(TEXT(B16,"00"),".",TEXT(C16,"000"),".",TEXT(D16,"000"),".",TEXT(E16,"000")),""))))) -> 01.001.002.003 | J16: Projeto Estrutural | K16: =IFERROR(VLOOKUP(J16,BASES!$A$13:$E$342,3,FALSE),0) -> vb | L16: =IFERROR(VLOOKUP(J16,BASES!$A$13:$E$342,4,FALSE),0) -> 1 | M16: =IFERROR(VLOOKUP(J16,BASES!$A$13:$E$342,5,FALSE),0) -> 49900.727 | N16: =IF(H16="Serviço",M16*L16,IF(H16="CÉLULA CONSTRUTIVA",SUMIFS($N$8:$N$419,$B$8:$B$419,B16,$H$8:$H$419,"Serviço"),IF(H16="ETAPA",SUMIFS($N$8:$N$419,$B$8:$B$419,B16,$C$8:$C$419,C16,$H$8:$H$419,"Serviço"),IF(H16="SUBETAPA",SUMIFS($N$8:$N$419,$B$8:$B$419,B16,$C$8:$C$419,C16,$D$8:$D$419,D16,$H$8:$H$419,"Serviço"),0)))) -> 49900.727 | O16: =IF(VLOOKUP(J16,BASES!$A$13:$F$342,6,FALSE)="Recebido","Valor informado em formulário",IF(VLOOKUP(J16,BASES!$A$13:$F$342,6,FALSE)="Estimado","Estimado com base em índices históricos","Não solicitado")) -> Estimado com base em índices históricos | P16: Lançado ERP
A17: =IF($H17="UNIDADE CONSTRUTIVA",OFFSET(A17,-1,0)+1,LARGE(A$3:A16,1)) -> 0 | B17: =IF(H17="UNIDADE CONSTRUTIVA",0,IF(H17="CÉLULA CONSTRUTIVA",OFFSET(B17,-1,0)+1,OFFSET(B17,-1,0))) -> 1 | C17: =IF(H17="CÉLULA CONSTRUTIVA",0,IF(H17="ETAPA",OFFSET(C17,-1,0)+1,OFFSET(C17,-1,0))) -> 1 | D17: =IF(H17="ETAPA",0,IF(H17="SUBETAPA",OFFSET(D17,-1,0)+1,OFFSET(D17,-1,0))) -> 2 | E17: =IF(H17="Subetapa",0,IF(H17="serviço",OFFSET(E17,-1,0)+1,OFFSET(E17,-1,0))) -> 4 | H17: SERVIÇO | I17: =IF(H17="Unidade Construtiva",TEXT(A17,"00"),IF(H17="Célula Construtiva",TEXT(B17,"00"),IF(H17="Etapa",CONCATENATE(TEXT(B17,"00"),".",TEXT(C17,"000")),IF(H17="Subetapa",CONCATENATE(TEXT(B17,"00"),".",TEXT(C17,"000"),".",TEXT(D17,"000")),IF(H17="Serviço",CONCATENATE(TEXT(B17,"00"),".",TEXT(C17,"000"),".",TEXT(D17,"000"),".",TEXT(E17,"000")),""))))) -> 01.001.002.004 | J17: Projeto de Fundações | K17: =IFERROR(VLOOKUP(J17,BASES!$A$13:$E$342,3,FALSE),0) -> vb | L17: =IFERROR(VLOOKUP(J17,BASES!$A$13:$E$342,4,FALSE),0) -> 1 | M17: =IFERROR(VLOOKUP(J17,BASES!$A$13:$E$342,5,FALSE),0) -> 20568.443 | N17: =IF(H17="Serviço",M17*L17,IF(H17="CÉLULA CONSTRUTIVA",SUMIFS($N$8:$N$419,$B$8:$B$419,B17,$H$8:$H$419,"Serviço"),IF(H17="ETAPA",SUMIFS($N$8:$N$419,$B$8:$B$419,B17,$C$8:$C$419,C17,$H$8:$H$419,"Serviço"),IF(H17="SUBETAPA",SUMIFS($N$8:$N$419,$B$8:$B$419,B17,$C$8:$C$419,C17,$D$8:$D$419,D17,$H$8:$H$419,"Serviço"),0)))) -> 20568.443 | O17: =IF(VLOOKUP(J17,BASES!$A$13:$F$342,6,FALSE)="Recebido","Valor informado em formulário",IF(VLOOKUP(J17,BASES!$A$13:$F$342,6,FALSE)="Estimado","Estimado com base em índices históricos","Não solicitado")) -> Estimado com base em índices históricos | P17: Lançado ERP
A18: =IF($H18="UNIDADE CONSTRUTIVA",OFFSET(A18,-1,0)+1,LARGE(A$3:A17,1)) -> 0 | B18: =IF(H18="UNIDADE CONSTRUTIVA",0,IF(H18="CÉLULA CONSTRUTIVA",OFFSET(B18,-1,0)+1,OFFSET(B18,-1,0))) -> 1 | C18: =IF(H18="CÉLULA CONSTRUTIVA",0,IF(H18="ETAPA",OFFSET(C18,-1,0)+1,OFFSET(C18,-1,0))) -> 1 | D18: =IF(H18="ETAPA",0,IF(H18="SUBETAPA",OFFSET(D18,-1,0)+1,OFFSET(D18,-1,0))) -> 2 | E18: =IF(H18="Subetapa",0,IF(H18="serviço",OFFSET(E18,-1,0)+1,OFFSET(E18,-1,0))) -> 5 | H18: SERVIÇO | I18: =IF(H18="Unidade Construtiva",TEXT(A18,"00"),IF(H18="Célula Construtiva",TEXT(B18,"00"),IF(H18="Etapa",CONCATENATE(TEXT(B18,"00"),".",TEXT(C18,"000")),IF(H18="Subetapa",CONCATENATE(TEXT(B18,"00"),".",TEXT(C18,"000"),".",TEXT(D18,"000")),IF(H18="Serviço",CONCATENATE(TEXT(B18,"00"),".",TEXT(C18,"000"),".",TEXT(D18,"000"),".",TEXT(E18,"000")),""))))) -> 01.001.002.005 | J18: Projeto elétrico/comunicação/telefonia/luminotécnico | K18: =IFERROR(VLOOKUP(J18,BASES!$A$13:$E$342,3,FALSE),0) -> vb | L18: =IFERROR(VLOOKUP(J18,BASES!$A$13:$E$342,4,FALSE),0) -> 1 | M18: =IFERROR(VLOOKUP(J18,BASES!$A$13:$E$342,5,FALSE),0) -> 32200 | N18: =IF(H18="Serviço",M18*L18,IF(H18="CÉLULA CONSTRUTIVA",SUMIFS($N$8:$N$419,$B$8:$B$419,B18,$H$8:$H$419,"Serviço"),IF(H18="ETAPA",SUMIFS($N$8:$N$419,$B$8:$B$419,B18,$C$8:$C$419,C18,$H$8:$H$419,"Serviço"),IF(H18="SUBETAPA",SUMIFS($N$8:$N$419,$B$8:$B$419,B18,$C$8:$C$419,C18,$D$8:$D$419,D18,$H$8:$H$419,"Serviço"),0)))) -> 32200 | O18: =IF(VLOOKUP(J18,BASES!$A$13:$F$342,6,FALSE)="Recebido","Valor informado em formulário",IF(VLOOKUP(J18,BASES!$A$13:$F$342,6,FALSE)="Estimado","Estimado com base em índices históricos","Não solicitado")) -> Valor informado em formulário | P18: Lançado ERP
A19: =IF($H19="UNIDADE CONSTRUTIVA",OFFSET(A19,-1,0)+1,LARGE(A$3:A18,1)) -> 0 | B19: =IF(H19="UNIDADE CONSTRUTIVA",0,IF(H19="CÉLULA CONSTRUTIVA",OFFSET(B19,-1,0)+1,OFFSET(B19,-1,0))) -> 1 | C19: =IF(H19="CÉLULA CONSTRUTIVA",0,IF(H19="ETAPA",OFFSET(C19,-1,0)+1,OFFSET(C19,-1,0))) -> 1 | D19: =IF(H19="ETAPA",0,IF(H19="SUBETAPA",OFFSET(D19,-1,0)+1,OFFSET(D19,-1,0))) -> 2 | E19: =IF(H19="Subetapa",0,IF(H19="serviço",OFFSET(E19,-1,0)+1,OFFSET(E19,-1,0))) -> 6 | H19: SERVIÇO | I19: =IF(H19="Unidade Construtiva",TEXT(A19,"00"),IF(H19="Célula Construtiva",TEXT(B19,"00"),IF(H19="Etapa",CONCATENATE(TEXT(B19,"00"),".",TEXT(C19,"000")),IF(H19="Subetapa",CONCATENATE(TEXT(B19,"00"),".",TEXT(C19,"000"),".",TEXT(D19,"000")),IF(H19="Serviço",CONCATENATE(TEXT(B19,"00"),".",TEXT(C19,"000"),".",TEXT(D19,"000"),".",TEXT(E19,"000")),""))))) -> 01.001.002.006 | J19: Projeto hidrossanitário/drenagem/pluvial | K19: =IFERROR(VLOOKUP(J19,BASES!$A$13:$E$342,3,FALSE),0) -> vb | L19: =IFERROR(VLOOKUP(J19,BASES!$A$13:$E$342,4,FALSE),0) -> 1 | M19: =IFERROR(VLOOKUP(J19,BASES!$A$13:$E$342,5,FALSE),0) -> 22970 | N19: =IF(H19="Serviço",M19*L19,IF(H19="CÉLULA CONSTRUTIVA",SUMIFS($N$8:$N$419,$B$8:$B$419,B19,$H$8:$H$419,"Serviço"),IF(H19="ETAPA",SUMIFS($N$8:$N$419,$B$8:$B$419,B19,$C$8:$C$419,C19,$H$8:$H$419,"Serviço"),IF(H19="SUBETAPA",SUMIFS($N$8:$N$419,$B$8:$B$419,B19,$C$8:$C$419,C19,$D$8:$D$419,D19,$H$8:$H$419,"Serviço"),0)))) -> 22970 | O19: =IF(VLOOKUP(J19,BASES!$A$13:$F$342,6,FALSE)="Recebido","Valor informado em formulário",IF(VLOOKUP(J19,BASES!$A$13:$F$342,6,FALSE)="Estimado","Estimado com base em índices históricos","Não solicitado")) -> Valor informado em formulário | P19: Lançado ERP
A20: =IF($H20="UNIDADE CONSTRUTIVA",OFFSET(A20,-1,0)+1,LARGE(A$3:A19,1)) -> 0 | B20: =IF(H20="UNIDADE CONSTRUTIVA",0,IF(H20="CÉLULA CONSTRUTIVA",OFFSET(B20,-1,0)+1,OFFSET(B20,-1,0))) -> 1 | C20: =IF(H20="CÉLULA CONSTRUTIVA",0,IF(H20="ETAPA",OFFSET(C20,-1,0)+1,OFFSET(C20,-1,0))) -> 1 | D20: =IF(H20="ETAPA",0,IF(H20="SUBETAPA",OFFSET(D20,-1,0)+1,OFFSET(D20,-1,0))) -> 2 | E20: =IF(H20="Subetapa",0,IF(H20="serviço",OFFSET(E20,-1,0)+1,OFFSET(E20,-1,0))) -> 7 | H20: SERVIÇO | I20: =IF(H20="Unidade Construtiva",TEXT(A20,"00"),IF(H20="Célula Construtiva",TEXT(B20,"00"),IF(H20="Etapa",CONCATENATE(TEXT(B20,"00"),".",TEXT(C20,"000")),IF(H20="Subetapa",CONCATENATE(TEXT(B20,"00"),".",TEXT(C20,"000"),".",TEXT(D20,"000")),IF(H20="Serviço",CONCATENATE(TEXT(B20,"00"),".",TEXT(C20,"000"),".",TEXT(D20,"000"),".",TEXT(E20,"000")),""))))) -> 01.001.002.007 | J20: Projeto preventivo (PPCI - Plano de Prevenção e Proteção Contra Incêndios) e Gás | K20: =IFERROR(VLOOKUP(J20,BASES!$A$13:$E$342,3,FALSE),0) -> vb | L20: =IFERROR(VLOOKUP(J20,BASES!$A$13:$E$342,4,FALSE),0) -> 1 | M20: =IFERROR(VLOOKUP(J20,BASES!$A$13:$E$342,5,FALSE),0) -> 20675 | N20: =IF(H20="Serviço",M20*L20,IF(H20="CÉLULA CONSTRUTIVA",SUMIFS($N$8:$N$419,$B$8:$B$419,B20,$H$8:$H$419,"Serviço"),IF(H20="ETAPA",SUMIFS($N$8:$N$419,$B$8:$B$419,B20,$C$8:$C$419,C20,$H$8:$H$419,"Serviço"),IF(H20="SUBETAPA",SUMIFS($N$8:$N$419,$B$8:$B$419,B20,$C$8:$C$419,C20,$D$8:$D$419,D20,$H$8:$H$419,"Serviço"),0)))) -> 20675 | O20: =IF(VLOOKUP(J20,BASES!$A$13:$F$342,6,FALSE)="Recebido","Valor informado em formulário",IF(VLOOKUP(J20,BASES!$A$13:$F$342,6,FALSE)="Estimado","Estimado com base em índices históricos","Não solicitado")) -> Valor informado em formulário | P20: Lançado ERP
A21: =IF($H21="UNIDADE CONSTRUTIVA",OFFSET(A21,-1,0)+1,LARGE(A$3:A20,1)) -> 0 | B21: =IF(H21="UNIDADE CONSTRUTIVA",0,IF(H21="CÉLULA CONSTRUTIVA",OFFSET(B21,-1,0)+1,OFFSET(B21,-1,0))) -> 1 | C21: =IF(H21="CÉLULA CONSTRUTIVA",0,IF(H21="ETAPA",OFFSET(C21,-1,0)+1,OFFSET(C21,-1,0))) -> 1 | D21: =IF(H21="ETAPA",0,IF(H21="SUBETAPA",OFFSET(D21,-1,0)+1,OFFSET(D21,-1,0))) -> 2 | E21: =IF(H21="Subetapa",0,IF(H21="serviço",OFFSET(E21,-1,0)+1,OFFSET(E21,-1,0))) -> 8 | H21: SERVIÇO | I21: =IF(H21="Unidade Construtiva",TEXT(A21,"00"),IF(H21="Célula Construtiva",TEXT(B21,"00"),IF(H21="Etapa",CONCATENATE(TEXT(B21,"00"),".",TEXT(C21,"000")),IF(H21="Subetapa",CONCATENATE(TEXT(B21,"00"),".",TEXT(C21,"000"),".",TEXT(D21,"000")),IF(H21="Serviço",CONCATENATE(TEXT(B21,"00"),".",TEXT(C21,"000"),".",TEXT(D21,"000"),".",TEXT(E21,"000")),""))))) -> 01.001.002.008 | J21: Projeto de Impermeabilização | K21: =IFERROR(VLOOKUP(J21,BASES!$A$13:$E$342,3,FALSE),0) -> vb | L21: =IFERROR(VLOOKUP(J21,BASES!$A$13:$E$342,4,FALSE),0) -> 1 | M21: =IFERROR(VLOOKUP(J21,BASES!$A$13:$E$342,5,FALSE),0) -> 16004.243 | N21: =IF(H21="Serviço",M21*L21,IF(H21="CÉLULA CONSTRUTIVA",SUMIFS($N$8:$N$419,$B$8:$B$419,B21,$H$8:$H$419,"Serviço"),IF(H21="ETAPA",SUMIFS($N$8:$N$419,$B$8:$B$419,B21,$C$8:$C$419,C21,$H$8:$H$419,"Serviço"),IF(H21="SUBETAPA",SUMIFS($N$8:$N$419,$B$8:$B$419,B21,$C$8:$C$419,C21,$D$8:$D$419,D21,$H$8:$H$419,"Serviço"),0)))) -> 16004.243 | O21: =IF(VLOOKUP(J21,BASES!$A$13:$F$342,6,FALSE)="Recebido","Valor informado em formulário",IF(VLOOKUP(J21,BASES!$A$13:$F$342,6,FALSE)="Estimado","Estimado com base em índices históricos","Não solicitado")) -> Estimado com base em índices históricos | P21: Lançado ERP
A22: =IF($H22="UNIDADE CONSTRUTIVA",OFFSET(A22,-1,0)+1,LARGE(A$3:A21,1)) -> 0 | B22: =IF(H22="UNIDADE CONSTRUTIVA",0,IF(H22="CÉLULA CONSTRUTIVA",OFFSET(B22,-1,0)+1,OFFSET(B22,-1,0))) -> 1 | C22: =IF(H22="CÉLULA CONSTRUTIVA",0,IF(H22="ETAPA",OFFSET(C22,-1,0)+1,OFFSET(C22,-1,0))) -> 1 | D22: =IF(H22="ETAPA",0,IF(H22="SUBETAPA",OFFSET(D22,-1,0)+1,OFFSET(D22,-1,0))) -> 2 | E22: =IF(H22="Subetapa",0,IF(H22="serviço",OFFSET(E22,-1,0)+1,OFFSET(E22,-1,0))) -> 9 | H22: SERVIÇO | I22: =IF(H22="Unidade Construtiva",TEXT(A22,"00"),IF(H22="Célula Construtiva",TEXT(B22,"00"),IF(H22="Etapa",CONCATENATE(TEXT(B22,"00"),".",TEXT(C22,"000")),IF(H22="Subetapa",CONCATENATE(TEXT(B22,"00"),".",TEXT(C22,"000"),".",TEXT(D22,"000")),IF(H22="Serviço",CONCATENATE(TEXT(B22,"00"),".",TEXT(C22,"000"),".",TEXT(D22,"000"),".",TEXT(E22,"000")),""))))) -> 01.001.002.009 | J22: Projeto de segurança | K22: =IFERROR(VLOOKUP(J22,BASES!$A$13:$E$342,3,FALSE),0) -> vb | L22: =IFERROR(VLOOKUP(J22,BASES!$A$13:$E$342,4,FALSE),0) -> 1 | M22: =IFERROR(VLOOKUP(J22,BASES!$A$13:$E$342,5,FALSE),0) -> 4645.2833 | N22: =IF(H22="Serviço",M22*L22,IF(H22="CÉLULA CONSTRUTIVA",SUMIFS($N$8:$N$419,$B$8:$B$419,B22,$H$8:$H$419,"Serviço"),IF(H22="ETAPA",SUMIFS($N$8:$N$419,$B$8:$B$419,B22,$C$8:$C$419,C22,$H$8:$H$419,"Serviço"),IF(H22="SUBETAPA",SUMIFS($N$8:$N$419,$B$8:$B$419,B22,$C$8:$C$419,C22,$D$8:$D$419,D22,$H$8:$H$419,"Serviço"),0)))) -> 4645.2833 | O22: =IF(VLOOKUP(J22,BASES!$A$13:$F$342,6,FALSE)="Recebido","Valor informado em formulário",IF(VLOOKUP(J22,BASES!$A$13:$F$342,6,FALSE)="Estimado","Estimado com base em índices históricos","Não solicitado")) -> Estimado com base em índices históricos | P22: Lançado ERP
A23: =IF($H23="UNIDADE CONSTRUTIVA",OFFSET(A23,-1,0)+1,LARGE(A$3:A22,1)) -> 0 | B23: =IF(H23="UNIDADE CONSTRUTIVA",0,IF(H23="CÉLULA CONSTRUTIVA",OFFSET(B23,-1,0)+1,OFFSET(B23,-1,0))) -> 1 | C23: =IF(H23="CÉLULA CONSTRUTIVA",0,IF(H23="ETAPA",OFFSET(C23,-1,0)+1,OFFSET(C23,-1,0))) -> 1 | D23: =IF(H23="ETAPA",0,IF(H23="SUBETAPA",OFFSET(D23,-1,0)+1,OFFSET(D23,-1,0))) -> 2 | E23: =IF(H23="Subetapa",0,IF(H23="serviço",OFFSET(E23,-1,0)+1,OFFSET(E23,-1,0))) -> 10 | H23: SERVIÇO | I23: =IF(H23="Unidade Construtiva",TEXT(A23,"00"),IF(H23="Célula Construtiva",TEXT(B23,"00"),IF(H23="Etapa",CONCATENATE(TEXT(B23,"00"),".",TEXT(C23,"000")),IF(H23="Subetapa",CONCATENATE(TEXT(B23,"00"),".",TEXT(C23,"000"),".",TEXT(D23,"000")),IF(H23="Serviço",CONCATENATE(TEXT(B23,"00"),".",TEXT(C23,"000"),".",TEXT(D23,"000"),".",TEXT(E23,"000")),""))))) -> 01.001.002.010 | J23: Projeto de climatização/exaustão | K23: =IFERROR(VLOOKUP(J23,BASES!$A$13:$E$342,3,FALSE),0) -> vb | L23: =IFERROR(VLOOKUP(J23,BASES!$A$13:$E$342,4,FALSE),0) -> 1 | M23: =IFERROR(VLOOKUP(J23,BASES!$A$13:$E$342,5,FALSE),0) -> 29000 | N23: =IF(H23="Serviço",M23*L23,IF(H23="CÉLULA CONSTRUTIVA",SUMIFS($N$8:$N$419,$B$8:$B$419,B23,$H$8:$H$419,"Serviço"),IF(H23="ETAPA",SUMIFS($N$8:$N$419,$B$8:$B$419,B23,$C$8:$C$419,C23,$H$8:$H$419,"Serviço"),IF(H23="SUBETAPA",SUMIFS($N$8:$N$419,$B$8:$B$419,B23,$C$8:$C$419,C23,$D$8:$D$419,D23,$H$8:$H$419,"Serviço"),0)))) -> 29000 | O23: =IF(VLOOKUP(J23,BASES!$A$13:$F$342,6,FALSE)="Recebido","Valor informado em formulário",IF(VLOOKUP(J23,BASES!$A$13:$F$342,6,FALSE)="Estimado","Estimado com base em índices históricos","Não solicitado")) -> Valor informado em formulário | P23: Lançado ERP
A24: =IF($H24="UNIDADE CONSTRUTIVA",OFFSET(A24,-1,0)+1,LARGE(A$3:A23,1)) -> 0 | B24: =IF(H24="UNIDADE CONSTRUTIVA",0,IF(H24="CÉLULA CONSTRUTIVA",OFFSET(B24,-1,0)+1,OFFSET(B24,-1,0))) -> 1 | C24: =IF(H24="CÉLULA CONSTRUTIVA",0,IF(H24="ETAPA",OFFSET(C24,-1,0)+1,OFFSET(C24,-1,0))) -> 1 | D24: =IF(H24="ETAPA",0,IF(H24="SUBETAPA",OFFSET(D24,-1,0)+1,OFFSET(D24,-1,0))) -> 2 | E24: =IF(H24="Subetapa",0,IF(H24="serviço",OFFSET(E24,-1,0)+1,OFFSET(E24,-1,0))) -> 11 | H24: SERVIÇO | I24: =IF(H24="Unidade Construtiva",TEXT(A24,"00"),IF(H24="Célula Construtiva",TEXT(B24,"00"),IF(H24="Etapa",CONCATENATE(TEXT(B24,"00"),".",TEXT(C24,"000")),IF(H24="Subetapa",CONCATENATE(TEXT(B24,"00"),".",TEXT(C24,"000"),".",TEXT(D24,"000")),IF(H24="Serviço",CONCATENATE(TEXT(B24,"00"),".",TEXT(C24,"000"),".",TEXT(D24,"000"),".",TEXT(E24,"000")),""))))) -> 01.001.002.011 | J24: Projeto de irrigação | K24: =IFERROR(VLOOKUP(J24,BASES!$A$13:$E$342,3,FALSE),0) -> vb | L24: =IFERROR(VLOOKUP(J24,BASES!$A$13:$E$342,4,FALSE),0) -> 1 | M24: =IFERROR(VLOOKUP(J24,BASES!$A$13:$E$342,5,FALSE),0) -> 4912.3338 | N24: =IF(H24="Serviço",M24*L24,IF(H24="CÉLULA CONSTRUTIVA",SUMIFS($N$8:$N$419,$B$8:$B$419,B24,$H$8:$H$419,"Serviço"),IF(H24="ETAPA",SUMIFS($N$8:$N$419,$B$8:$B$419,B24,$C$8:$C$419,C24,$H$8:$H$419,"Serviço"),IF(H24="SUBETAPA",SUMIFS($N$8:$N$419,$B$8:$B$419,B24,$C$8:$C$419,C24,$D$8:$D$419,D24,$H$8:$H$419,"Serviço"),0)))) -> 4912.3338 | O24: =IF(VLOOKUP(J24,BASES!$A$13:$F$342,6,FALSE)="Recebido","Valor informado em formulário",IF(VLOOKUP(J24,BASES!$A$13:$F$342,6,FALSE)="Estimado","Estimado com base em índices históricos","Não solicitado")) -> Estimado com base em índices históricos | P24: Lançado ERP
A25: =IF($H25="UNIDADE CONSTRUTIVA",OFFSET(A25,-1,0)+1,LARGE(A$3:A24,1)) -> 0 | B25: =IF(H25="UNIDADE CONSTRUTIVA",0,IF(H25="CÉLULA CONSTRUTIVA",OFFSET(B25,-1,0)+1,OFFSET(B25,-1,0))) -> 1 | C25: =IF(H25="CÉLULA CONSTRUTIVA",0,IF(H25="ETAPA",OFFSET(C25,-1,0)+1,OFFSET(C25,-1,0))) -> 1 | D25: =IF(H25="ETAPA",0,IF(H25="SUBETAPA",OFFSET(D25,-1,0)+1,OFFSET(D25,-1,0))) -> 2 | E25: =IF(H25="Subetapa",0,IF(H25="serviço",OFFSET(E25,-1,0)+1,OFFSET(E25,-1,0))) -> 12 | H25: SERVIÇO | I25: =IF(H25="Unidade Construtiva",TEXT(A25,"00"),IF(H25="Célula Construtiva",TEXT(B25,"00"),IF(H25="Etapa",CONCATENATE(TEXT(B25,"00"),".",TEXT(C25,"000")),IF(H25="Subetapa",CONCATENATE(TEXT(B25,"00"),".",TEXT(C25,"000"),".",TEXT(D25,"000")),IF(H25="Serviço",CONCATENATE(TEXT(B25,"00"),".",TEXT(C25,"000"),".",TEXT(D25,"000"),".",TEXT(E25,"000")),""))))) -> 01.001.002.012 | J25: Projeto de Piscina | K25: =IFERROR(VLOOKUP(J25,BASES!$A$13:$E$342,3,FALSE),0) -> vb | L25: =IFERROR(VLOOKUP(J25,BASES!$A$13:$E$342,4,FALSE),0) -> 1 | M25: =IFERROR(VLOOKUP(J25,BASES!$A$13:$E$342,5,FALSE),0) -> 5300.5705 | N25: =IF(H25="Serviço",M25*L25,IF(H25="CÉLULA CONSTRUTIVA",SUMIFS($N$8:$N$419,$B$8:$B$419,B25,$H$8:$H$419,"Serviço"),IF(H25="ETAPA",SUMIFS($N$8:$N$419,$B$8:$B$419,B25,$C$8:$C$419,C25,$H$8:$H$419,"Serviço"),IF(H25="SUBETAPA",SUMIFS($N$8:$N$419,$B$8:$B$419,B25,$C$8:$C$419,C25,$D$8:$D$419,D25,$H$8:$H$419,"Serviço"),0)))) -> 5300.5705 | O25: =IF(VLOOKUP(J25,BASES!$A$13:$F$342,6,FALSE)="Recebido","Valor informado em formulário",IF(VLOOKUP(J25,BASES!$A$13:$F$342,6,FALSE)="Estimado","Estimado com base em índices históricos","Não solicitado")) -> Estimado com base em índices históricos | P25: Lançado ERP
A26: =IF($H26="UNIDADE CONSTRUTIVA",OFFSET(A26,-1,0)+1,LARGE(A$3:A25,1)) -> 0 | B26: =IF(H26="UNIDADE CONSTRUTIVA",0,IF(H26="CÉLULA CONSTRUTIVA",OFFSET(B26,-1,0)+1,OFFSET(B26,-1,0))) -> 1 | C26: =IF(H26="CÉLULA CONSTRUTIVA",0,IF(H26="ETAPA",OFFSET(C26,-1,0)+1,OFFSET(C26,-1,0))) -> 1 | D26: =IF(H26="ETAPA",0,IF(H26="SUBETAPA",OFFSET(D26,-1,0)+1,OFFSET(D26,-1,0))) -> 2 | E26: =IF(H26="Subetapa",0,IF(H26="serviço",OFFSET(E26,-1,0)+1,OFFSET(E26,-1,0))) -> 13 | H26: SERVIÇO | I26: =IF(H26="Unidade Construtiva",TEXT(A26,"00"),IF(H26="Célula Construtiva",TEXT(B26,"00"),IF(H26="Etapa",CONCATENATE(TEXT(B26,"00"),".",TEXT(C26,"000")),IF(H26="Subetapa",CONCATENATE(TEXT(B26,"00"),".",TEXT(C26,"000"),".",TEXT(D26,"000")),IF(H26="Serviço",CONCATENATE(TEXT(B26,"00"),".",TEXT(C26,"000"),".",TEXT(D26,"000"),".",TEXT(E26,"000")),""))))) -> 01.001.002.013 | J26: Projeto de Paisagismo | K26: =IFERROR(VLOOKUP(J26,BASES!$A$13:$E$342,3,FALSE),0) -> vb | L26: =IFERROR(VLOOKUP(J26,BASES!$A$13:$E$342,4,FALSE),0) -> 1 | M26: =IFERROR(VLOOKUP(J26,BASES!$A$13:$E$342,5,FALSE),0) -> 16744.39 | N26: =IF(H26="Serviço",M26*L26,IF(H26="CÉLULA CONSTRUTIVA",SUMIFS($N$8:$N$419,$B$8:$B$419,B26,$H$8:$H$419,"Serviço"),IF(H26="ETAPA",SUMIFS($N$8:$N$419,$B$8:$B$419,B26,$C$8:$C$419,C26,$H$8:$H$419,"Serviço"),IF(H26="SUBETAPA",SUMIFS($N$8:$N$419,$B$8:$B$419,B26,$C$8:$C$419,C26,$D$8:$D$419,D26,$H$8:$H$419,"Serviço"),0)))) -> 16744.39 | O26: =IF(VLOOKUP(J26,BASES!$A$13:$F$342,6,FALSE)="Recebido","Valor informado em formulário",IF(VLOOKUP(J26,BASES!$A$13:$F$342,6,FALSE)="Estimado","Estimado com base em índices históricos","Não solicitado")) -> Estimado com base em índices históricos | P26: Lançado ERP
A27: =IF($H27="UNIDADE CONSTRUTIVA",OFFSET(A27,-1,0)+1,LARGE(A$3:A26,1)) -> 0 | B27: =IF(H27="UNIDADE CONSTRUTIVA",0,IF(H27="CÉLULA CONSTRUTIVA",OFFSET(B27,-1,0)+1,OFFSET(B27,-1,0))) -> 1 | C27: =IF(H27="CÉLULA CONSTRUTIVA",0,IF(H27="ETAPA",OFFSET(C27,-1,0)+1,OFFSET(C27,-1,0))) -> 1 | D27: =IF(H27="ETAPA",0,IF(H27="SUBETAPA",OFFSET(D27,-1,0)+1,OFFSET(D27,-1,0))) -> 3 | E27: =IF(H27="Subetapa",0,IF(H27="serviço",OFFSET(E27,-1,0)+1,OFFSET(E27,-1,0))) -> 0 | H27: SUBETAPA | I27: =IF(H27="Unidade Construtiva",TEXT(A27,"00"),IF(H27="Célula Construtiva",TEXT(B27,"00"),IF(H27="Etapa",CONCATENATE(TEXT(B27,"00"),".",TEXT(C27,"000")),IF(H27="Subetapa",CONCATENATE(TEXT(B27,"00"),".",TEXT(C27,"000"),".",TEXT(D27,"000")),IF(H27="Serviço",CONCATENATE(TEXT(B27,"00"),".",TEXT(C27,"000"),".",TEXT(D27,"000"),".",TEXT(E27,"000")),""))))) -> 01.001.003 | J27: Consultorias | N27: =IF(H27="Serviço",M27*L27,IF(H27="CÉLULA CONSTRUTIVA",SUMIFS($N$8:$N$419,$B$8:$B$419,B27,$H$8:$H$419,"Serviço"),IF(H27="ETAPA",SUMIFS($N$8:$N$419,$B$8:$B$419,B27,$C$8:$C$419,C27,$H$8:$H$419,"Serviço"),IF(H27="SUBETAPA",SUMIFS($N$8:$N$419,$B$8:$B$419,B27,$C$8:$C$419,C27,$D$8:$D$419,D27,$H$8:$H$419,"Serviço"),0)))) -> 150264.96 | Q27: =N27/'Obra '!$C$32 -> 0.031476415
