Workbook
Name \0: #REF!
Name \0: #REF!
Name \0: #REF!
Name \0: #REF!
Name \0: #REF!
Name \0: #REF!
Name \1: #REF!
Name \1: #REF!
Name \1: #REF!
Name \1: #REF!
Name \1: #REF!
Name \a: #REF!
Name \a: #REF!
Name \a: #REF!
Name \a: #REF!
Name \a: #REF!
Name \a: #REF!
Name \b: #REF!
Name \b: #REF!
Name \b: #REF!
Name \b: #REF!
Name \b: #REF!
Name \c: #REF!
Name \c: #REF!
Name \c: #REF!
Name \c: #REF!
Name \c: #REF!
Name \d: #REF!
Name \d: #REF!
Name \d: #REF!
Name \d: #REF!
Name \d: #REF!
Name \e: #REF!
Name \e: #REF!
Name \e: #REF!
Name \e: #REF!
Name \e: #REF!
Name \i: #REF!
Name \i: #REF!
Name \i: #REF!
Name \i: #REF!
Name \i: #REF!
Name \J: #REF!
Name \J: #REF!
Name \J: #REF!
Name \J: #REF!
Name \J: #REF!
Name \k: #REF!
Name \k: #REF!
Name \k: #REF!
Name \k: #REF!
Name \k: #REF!
Name \l: #N/A
Name \m: #REF!
Name \m: #REF!
Name \m: #REF!
Name \m: #REF!
Name \m: #REF!
Name \m: #REF!
Name \o: #REF!

Sheet PROJETOS
B1: Projeto | C1: ='Obra '!D1 -> Caio Prado
B2: Empresa | C2: ='Obra '!D2 -> Indepy
B3: Revisão | C3: ='Obra '!D3 -> R00 - Larissa
A5: INFRAESTRUTURA
A6: PAVIMENTO | B6: DISCIPLINA
B7: ARQUITETURA | C7: FUNDAÇÕES | D7: OBSERVAÇÃO
A8: Fundação Profunda | C8: BRS_RDT_FUN_EX_001_R03
A20: Caminho: | B20: https://qicloud.com.br/root/caroline.nunes@cartesianengenharia.com#Obras/BRS-MOD_REDENTOR/Estrutura/04%20-%20PROJETO%20EXECUTIVO/PDF
A22: INSTALAÇÕES ELETRICAS
A23: PAVIMENTO | B23: DISCIPLINA
B24: ARQUITETURA | C24: ELETRICA | D24: OBSERVAÇÃO
A25: GERAL
A26: ='Obra '!$B$17 -> Subsolo
A27: ='Obra '!$B$18 -> Térreo
A28: ='Obra '!$B$19 -> 1º Pavimento - HMP
A29: ='Obra '!$B$20 -> 2º Pavimento - HMP
A30: ='Obra '!$B$21 -> 3º Pavimento - R2V / HMP
A31: ='Obra '!$B$22 -> 5º/ 7º/ 9º E 11º Pavimento - R2V
A32: ='Obra '!$B$23 -> 4º/ 6º/ 8º/ 10º E 12º Pavimento - R2V
A33: ='Obra '!$B$24 -> 13º Pavimento - LAZER
A34: ='Obra '!$B$25 -> 14º E 16º Pavimento - R2V
A35: ='Obra '!$B$26 -> 15º E 17º Pavimento - R2V
A36: ='Obra '!$B$27 -> 18º Pavimento - LAZER
A37: Caminho: | B37: 2.Projetos em andamento/Empresa/Obra/Escopo/Extração de quantitativos/Projetos Considerados

Sheet Obra 
C1: Projeto | D1: Caio Prado | E1: ENDEREÇO DA OBRA: | F1: R. Caio Prado, 207 - Consolação, São Paulo - SP, 01303-001
C2: Empresa | D2: Indepy | E2: CNPJ:
C3: Revisão | D3: R00 - Larissa | E3: ARQUIVO:
A4: QUADRO DE ÁREAS
B6: Descrição | C6: Unidade | E6: Quantidade | G6: Imagens
B7: MESES DE OBRA | C7: MÊS | E7: 36
B8: ÁREA DO TERRENO | C8: M² | E8: 981.06
B9: ÁREA CONSTRUÍDA | C9: M² | E9: 6938.39
B10: NÚMERO DE UNIDADES HABITACIONAIS | C10: UN | E10: 135
B11: NÚMERO DE UNIDADES COMERCIAIS | C11: UN | E11: 1
B12: ÁREA PRIVATIVA | C12: M² | E12: =SUM(E66:E115) -> 4392.6
B13: NÚMERO DE PAVIMENTOS | C13: UN | E13: 23
B14: ÁREA DE LAZER | C14: M² | E14: =MOBILIÁRIO!C7 -> 1901.04
B15: TOTAL DORMITÓRIOS | C15: UN | E15: 135
B17: Subsolo | C17: M² | E17: 243.84
B18: Térreo | C18: M² | E18: 615.57
B19: 1º Pavimento - HMP | C19: M² | E19: 380.61
B20: 2º Pavimento - HMP | C20: M² | E20: 478.98
B21: 3º Pavimento - R2V / HMP | C21: M² | E21: 412.99
B22: 5º/ 7º/ 9º E 11º Pavimento - R2V | C22: M² | E22: 1651.96
B23: 4º/ 6º/ 8º/ 10º E 12º Pavimento - R2V | C23: M² | E23: 1806.8
B24: 13º Pavimento - LAZER | C24: M² | E24: 294.68
B25: 14º E 16º Pavimento - R2V | C25: M² | E25: 445.2
B26: 15º E 17º Pavimento - R2V | C26: M² | E26: 389.26
B27: 18º Pavimento - LAZER | C27: M² | E27: 82.25
... B29: CX D'ÁGUA | C29: M² | E29: 69.05
B30: TOPO | C30: M²
B35: CARTESIAN
B36: ETAPA | C36: VALOR ORÇADO | D36: % | E36: VALOR / m²
B37: PAREDES E PAINÉIS | C37: =Ger_Executivo!N8 -> 2008722.2 | D37: =C37/C$48 -> 0.11881186 | E37: =C37/$E$9 -> 289.5084
B38: IMPERMEABILIZAÇÃO E TRATAMENTOS | C38: =Ger_Executivo!N28 -> 703992.08 | D38: =C38/C$48 -> 0.04163971 | E38: =C38/$E$9 -> 101.46332
B39: REVESTIMENTOS INTERNOS DE PAREDE | C39: =Ger_Executivo!N70 -> 1323971.4 | D39: =C39/C$48 -> 0.078310235 | E39: =C39/$E$9 -> 190.81825
B40: REVESTIMENTOS E ACABAMENTOS INTERNOS EM TETO | C40: =Ger_Executivo!N93 -> 695689.43 | D40: =C40/C$48 -> 0.041148625 | E40: =C40/$E$9 -> 100.26669
B41: PISOS E PAVIMENTAÇÕES | C41: =Ger_Executivo!N104 -> 1461780 | D41: =C41/C$48 -> 0.086461336 | E41: =C41/$E$9 -> 210.68
B42: SISTEMAS DE PINTURA INTERNA | C42: =Ger_Executivo!N141 -> 1340430.3 | D42: =C42/C$48 -> 0.079283744 | E42: =C42/$E$9 -> 193.19039
B43: ESQUADRIAS, VIDROS E FERRAGENS | C43: =Ger_Executivo!N163 -> 3691455.8 | D43: =C43/C$48 -> 0.21834215 | E43: =C43/$E$9 -> 532.03348
B44: LOUÇAS E METAIS | C44: =Ger_Executivo!N201 -> 326798.11 | D44: =C44/C$48 -> 0.019329448 | E44: =C44/$E$9 -> 47.099992
B45: REVESTIMENTOS E ACABAMENTOS EM FACHADA | C45: =Ger_Executivo!N211 -> 1898087.7 | D45: =C45/C$48 -> 0.11226805 | E45: =C45/$E$9 -> 273.56313
B46: SERVIÇOS COMPLEMENTARES E FINAIS | C46: =Ger_Executivo!N232 -> 3135402.8 | D46: =C46/C$48 -> 0.18545274 | E46: =C46/$E$9 -> 451.89198
B47: IMPREVISTOS E CONTINGÊNCIAS | C47: =Ger_Executivo!N254 -> 320418.31 | D47: =C47/C$48 -> 0.018952096 | E47: =C47/$E$9 -> 46.180498
...

Sheet Ger_Executivo
G4: PROJETO: | I4: ='Obra '!D1 -> Caio Prado | O4: REVISÃO: | P4: DATA
G5: EMPRESA: | I5: ='Obra '!D2 -> Indepy | O5: R00 | P5: 45980
A6: Unidade Construtiva | B6: Célula Construtiva | C6: Etapa | D6: Subetapa | E6: Serviço | G6: GERENCIAMENTO EXECUTIVO
A7: 0 | B7: 0 | C7: 0 | D7: 0 | E7: 0 | G7: Atalho | H7: NIVEL | I7: Item | J7: Descrição | K7: Unidade | L7: Quant. | M7: Preço un | N7: Total | O7: Considerações | P7: Situação
A8: =IF($H8="UNIDADE CONSTRUTIVA",OFFSET(A8,-1,0)+1,LARGE(A$3:A7,1)) -> 0 | B8: =IF(H8="UNIDADE CONSTRUTIVA",0,IF(H8="CÉLULA CONSTRUTIVA",OFFSET(B8,-1,0)+1,OFFSET(B8,-1,0))) -> 1 | C8: =IF(H8="CÉLULA CONSTRUTIVA",0,IF(H8="ETAPA",OFFSET(C8,-1,0)+1,OFFSET(C8,-1,0))) -> 0 | D8: =IF(H8="ETAPA",0,IF(H8="SUBETAPA",OFFSET(D8,-1,0)+1,OFFSET(D8,-1,0))) -> 0 | E8: =IF(H8="Subetapa",0,IF(H8="serviço",OFFSET(E8,-1,0)+1,OFFSET(E8,-1,0))) -> 0 | H8: CÉLULA CONSTRUTIVA | I8: =IF(H8="Unidade Construtiva",TEXT(A8,"00"),IF(H8="Célula Construtiva",TEXT(B8,"00"),IF(H8="Etapa",CONCATENATE(TEXT(B8,"00"),".",TEXT(C8,"000")),IF(H8="Subetapa",CONCATENATE(TEXT(B8,"00"),".",TEXT(C8,"000"),".",TEXT(D8,"000")),IF(H8="Serviço",CONCATENATE(TEXT(B8,"00"),".",TEXT(C8,"000"),".",TEXT(D8,"000"),".",TEXT(E8,"000")),""))))) -> 01 | J8: PAREDES E PAINÉIS | N8: =IF(H8="Serviço",M8*L8,IF(H8="CÉLULA CONSTRUTIVA",SUMIFS($N$8:$N$262,$B$8:$B$262,B8,$H$8:$H$262,"Serviço"),IF(H8="ETAPA",SUMIFS($N$8:$N$262,$B$8:$B$262,B8,$C$8:$C$262,C8,$H$8:$H$262,"Serviço"),IF(H8="SUBETAPA",SUMIFS($N$8:$N$262,$B$8:$B$262,B8,$C$8:$C$262,C8,$D$8:$D$262,D8,$H$8:$H$262,"Serviço"),0)))) -> 2008722.2 | O8: =N8/'Obra '!$E$9 -> 289.5084 | Q8: ALVENARIA
A9: =IF($H9="UNIDADE CONSTRUTIVA",OFFSET(A9,-1,0)+1,LARGE(A$3:A8,1)) -> 0 | B9: =IF(H9="UNIDADE CONSTRUTIVA",0,IF(H9="CÉLULA CONSTRUTIVA",OFFSET(B9,-1,0)+1,OFFSET(B9,-1,0))) -> 1 | C9: =IF(H9="CÉLULA CONSTRUTIVA",0,IF(H9="ETAPA",OFFSET(C9,-1,0)+1,OFFSET(C9,-1,0))) -> 1 | D9: =IF(H9="ETAPA",0,IF(H9="SUBETAPA",OFFSET(D9,-1,0)+1,OFFSET(D9,-1,0))) -> 0 | E9: =IF(H9="Subetapa",0,IF(H9="serviço",OFFSET(E9,-1,0)+1,OFFSET(E9,-1,0))) -> 0 | H9: ETAPA | I9: =IF(H9="Unidade Construtiva",TEXT(A9,"00"),IF(H9="Célula Construtiva",TEXT(B9,"00"),IF(H9="Etapa",CONCATENATE(TEXT(B9,"00"),".",TEXT(C9,"000")),IF(H9="Subetapa",CONCATENATE(TEXT(B9,"00"),".",TEXT(C9,"000"),".",TEXT(D9,"000")),IF(H9="Serviço",CONCATENATE(TEXT(B9,"00"),".",TEXT(C9,"000"),".",TEXT(D9,"000"),".",TEXT(E9,"000")),""))))) -> 01.001 | J9: VEDAÇÕES | N9: =IF(H9="Serviço",M9*L9,IF(H9="CÉLULA CONSTRUTIVA",SUMIFS($N$8:$N$262,$B$8:$B$262,B9,$H$8:$H$262,"Serviço"),IF(H9="ETAPA",SUMIFS($N$8:$N$262,$B$8:$B$262,B9,$C$8:$C$262,C9,$H$8:$H$262,"Serviço"),IF(H9="SUBETAPA",SUMIFS($N$8:$N$262,$B$8:$B$262,B9,$C$8:$C$262,C9,$D$8:$D$262,D9,$H$8:$H$262,"Serviço"),0)))) -> 2008722.2 | O9: =N9/'Obra '!$E$9 -> 289.5084
A10: =IF($H10="UNIDADE CONSTRUTIVA",OFFSET(A10,-1,0)+1,LARGE(A$3:A17,1)) -> 0 | B10: =IF(H10="UNIDADE CONSTRUTIVA",0,IF(H10="CÉLULA CONSTRUTIVA",OFFSET(B10,-1,0)+1,OFFSET(B10,-1,0))) -> 1 | C10: =IF(H10="CÉLULA CONSTRUTIVA",0,IF(H10="ETAPA",OFFSET(C10,-1,0)+1,OFFSET(C10,-1,0))) -> 1 | D10: =IF(H10="ETAPA",0,IF(H10="SUBETAPA",OFFSET(D10,-1,0)+1,OFFSET(D10,-1,0))) -> 1 | E10: =IF(H10="Subetapa",0,IF(H10="serviço",OFFSET(E10,-1,0)+1,OFFSET(E10,-1,0))) -> 0 | H10: SUBETAPA | I10: =IF(H10="Unidade Construtiva",TEXT(A10,"00"),IF(H10="Célula Construtiva",TEXT(B10,"00"),IF(H10="Etapa",CONCATENATE(TEXT(B10,"00"),".",TEXT(C10,"000")),IF(H10="Subetapa",CONCATENATE(TEXT(B10,"00"),".",TEXT(C10,"000"),".",TEXT(D10,"000")),IF(H10="Serviço",CONCATENATE(TEXT(B10,"00"),".",TEXT(C10,"000"),".",TEXT(D10,"000"),".",TEXT(E10,"000")),""))))) -> 01.001.001 | J10: Alvenaria de vedação com bocos de concreto | N10: =IF(H10="Serviço",M10*L10,IF(H10="CÉLULA CONSTRUTIVA",SUMIFS($N$8:$N$262,$B$8:$B$262,B10,$H$8:$H$262,"Serviço"),IF(H10="ETAPA",SUMIFS($N$8:$N$262,$B$8:$B$262,B10,$C$8:$C$262,C10,$H$8:$H$262,"Serviço"),IF(H10="SUBETAPA",SUMIFS($N$8:$N$262,$B$8:$B$262,B10,$C$8:$C$262,C10,$D$8:$D$262,D10,$H$8:$H$262,"Serviço"),0)))) -> 703546.68 | O10: =N10/'Obra '!$E$9 -> 101.39913
A11: =IF($H11="UNIDADE CONSTRUTIVA",OFFSET(A11,-1,0)+1,LARGE(A$3:A10,1)) -> 0 | B11: =IF(H11="UNIDADE CONSTRUTIVA",0,IF(H11="CÉLULA CONSTRUTIVA",OFFSET(B11,-1,0)+1,OFFSET(B11,-1,0))) -> 1 | C11: =IF(H11="CÉLULA CONSTRUTIVA",0,IF(H11="ETAPA",OFFSET(C11,-1,0)+1,OFFSET(C11,-1,0))) -> 1 | D11: =IF(H11="ETAPA",0,IF(H11="SUBETAPA",OFFSET(D11,-1,0)+1,OFFSET(D11,-1,0))) -> 1 | E11: =IF(H11="Subetapa",0,IF(H11="serviço",OFFSET(E11,-1,0)+1,OFFSET(E11,-1,0))) -> 1 | H11: SERVIÇO | I11: =IF(H11="Unidade Construtiva",TEXT(A11,"00"),IF(H11="Célula Construtiva",TEXT(B11,"00"),IF(H11="Etapa",CONCATENATE(TEXT(B11,"00"),".",TEXT(C11,"000")),IF(H11="Subetapa",CONCATENATE(TEXT(B11,"00"),".",TEXT(C11,"000"),".",TEXT(D11,"000")),IF(H11="Serviço",CONCATENATE(TEXT(B11,"00"),".",TEXT(C11,"000"),".",TEXT(D11,"000"),".",TEXT(E11,"000")),""))))) -> 01.001.001.001 | J11: Alvenaria de vedação de blocos de concreto de 09x19x39cm, com argamassa estabilizada | K11: m2 | L11: =ARQUITETURA!H13 -> 208.45 | M11: 46.3 | N11: =IF(H11="Serviço",M11*L11,IF(H11="CÉLULA CONSTRUTIVA",SUMIFS($N$8:$N$262,$B$8:$B$262,B11,$H$8:$H$262,"Serviço"),IF(H11="ETAPA",SUMIFS($N$8:$N$262,$B$8:$B$262,B11,$C$8:$C$262,C11,$H$8:$H$262,"Serviço"),IF(H11="SUBETAPA",SUMIFS($N$8:$N$262,$B$8:$B$262,B11,$C$8:$C$262,C11,$D$8:$D$262,D11,$H$8:$H$262,"Serviço"),0)))) -> 9651.235
A12: =IF($H12="UNIDADE CONSTRUTIVA",OFFSET(A12,-1,0)+1,LARGE(A$3:A11,1)) -> 0 | B12: =IF(H12="UNIDADE CONSTRUTIVA",0,IF(H12="CÉLULA CONSTRUTIVA",OFFSET(B12,-1,0)+1,OFFSET(B12,-1,0))) -> 1 | C12: =IF(H12="CÉLULA CONSTRUTIVA",0,IF(H12="ETAPA",OFFSET(C12,-1,0)+1,OFFSET(C12,-1,0))) -> 1 | D12: =IF(H12="ETAPA",0,IF(H12="SUBETAPA",OFFSET(D12,-1,0)+1,OFFSET(D12,-1,0))) -> 1 | E12: =IF(H12="Subetapa",0,IF(H12="serviço",OFFSET(E12,-1,0)+1,OFFSET(E12,-1,0))) -> 2 | H12: SERVIÇO | I12: =IF(H12="Unidade Construtiva",TEXT(A12,"00"),IF(H12="Célula Construtiva",TEXT(B12,"00"),IF(H12="Etapa",CONCATENATE(TEXT(B12,"00"),".",TEXT(C12,"000")),IF(H12="Subetapa",CONCATENATE(TEXT(B12,"00"),".",TEXT(C12,"000"),".",TEXT(D12,"000")),IF(H12="Serviço",CONCATENATE(TEXT(B12,"00"),".",TEXT(C12,"000"),".",TEXT(D12,"000"),".",TEXT(E12,"000")),""))))) -> 01.001.001.002 | J12: Alvenaria de vedação de blocos de concreto de 14x19x39cm, com argamassa estabilizada | K12: m2 | L12: =ARQUITETURA!H14 -> 1643 | M12: 49.1 | N12: =IF(H12="Serviço",M12*L12,IF(H12="CÉLULA CONSTRUTIVA",SUMIFS($N$8:$N$262,$B$8:$B$262,B12,$H$8:$H$262,"Serviço"),IF(H12="ETAPA",SUMIFS($N$8:$N$262,$B$8:$B$262,B12,$C$8:$C$262,C12,$H$8:$H$262,"Serviço"),IF(H12="SUBETAPA",SUMIFS($N$8:$N$262,$B$8:$B$262,B12,$C$8:$C$262,C12,$D$8:$D$262,D12,$H$8:$H$262,"Serviço"),0)))) -> 80671.3
A13: =IF($H13="UNIDADE CONSTRUTIVA",OFFSET(A13,-1,0)+1,LARGE(A$3:A12,1)) -> 0 | B13: =IF(H13="UNIDADE CONSTRUTIVA",0,IF(H13="CÉLULA CONSTRUTIVA",OFFSET(B13,-1,0)+1,OFFSET(B13,-1,0))) -> 1 | C13: =IF(H13="CÉLULA CONSTRUTIVA",0,IF(H13="ETAPA",OFFSET(C13,-1,0)+1,OFFSET(C13,-1,0))) -> 1 | D13: =IF(H13="ETAPA",0,IF(H13="SUBETAPA",OFFSET(D13,-1,0)+1,OFFSET(D13,-1,0))) -> 1 | E13: =IF(H13="Subetapa",0,IF(H13="serviço",OFFSET(E13,-1,0)+1,OFFSET(E13,-1,0))) -> 3 | H13: SERVIÇO | I13: =IF(H13="Unidade Construtiva",TEXT(A13,"00"),IF(H13="Célula Construtiva",TEXT(B13,"00"),IF(H13="Etapa",CONCATENATE(TEXT(B13,"00"),".",TEXT(C13,"000")),IF(H13="Subetapa",CONCATENATE(TEXT(B13,"00"),".",TEXT(C13,"000"),".",TEXT(D13,"000")),IF(H13="Serviço",CONCATENATE(TEXT(B13,"00"),".",TEXT(C13,"000"),".",TEXT(D13,"000"),".",TEXT(E13,"000")),""))))) -> 01.001.001.003 | J13: Alvenaria de vedação de blocos de concreto de 19x19x39cm, com argamassa estabilizada | K13: m2 | L13: =ARQUITETURA!H15 -> 2528.25 | M13: 64.22 | N13: =IF(H13="Serviço",M13*L13,IF(H13="CÉLULA CONSTRUTIVA",SUMIFS($N$8:$N$262,$B$8:$B$262,B13,$H$8:$H$262,"Serviço"),IF(H13="ETAPA",SUMIFS($N$8:$N$262,$B$8:$B$262,B13,$C$8:$C$262,C13,$H$8:$H$262,"Serviço"),IF(H13="SUBETAPA",SUMIFS($N$8:$N$262,$B$8:$B$262,B13,$C$8:$C$262,C13,$D$8:$D$262,D13,$H$8:$H$262,"Serviço"),0)))) -> 162364.21
A14: =IF($H14="UNIDADE CONSTRUTIVA",OFFSET(A14,-1,0)+1,LARGE(A$3:A9,1)) -> 0 | B14: =IF(H14="UNIDADE CONSTRUTIVA",0,IF(H14="CÉLULA CONSTRUTIVA",OFFSET(B14,-1,0)+1,OFFSET(B14,-1,0))) -> 1 | C14: =IF(H14="CÉLULA CONSTRUTIVA",0,IF(H14="ETAPA",OFFSET(C14,-1,0)+1,OFFSET(C14,-1,0))) -> 1 | D14: =IF(H14="ETAPA",0,IF(H14="SUBETAPA",OFFSET(D14,-1,0)+1,OFFSET(D14,-1,0))) -> 1 | E14: =IF(H14="Subetapa",0,IF(H14="serviço",OFFSET(E14,-1,0)+1,OFFSET(E14,-1,0))) -> 4 | H14: SERVIÇO | I14: =IF(H14="Unidade Construtiva",TEXT(A14,"00"),IF(H14="Célula Construtiva",TEXT(B14,"00"),IF(H14="Etapa",CONCATENATE(TEXT(B14,"00"),".",TEXT(C14,"000")),IF(H14="Subetapa",CONCATENATE(TEXT(B14,"00"),".",TEXT(C14,"000"),".",TEXT(D14,"000")),IF(H14="Serviço",CONCATENATE(TEXT(B14,"00"),".",TEXT(C14,"000"),".",TEXT(D14,"000"),".",TEXT(E14,"000")),""))))) -> 01.001.001.004 | J14: Alvenaria de vedação de Bloco concreto corta-fogo de 09x19x39cm, com argamassa estabilizada | K14: m2 | L14: =ARQUITETURA!H99 -> 87.04 | M14: 71.5 | N14: =IF(H14="Serviço",M14*L14,IF(H14="CÉLULA CONSTRUTIVA",SUMIFS($N$8:$N$262,$B$8:$B$262,B14,$H$8:$H$262,"Serviço"),IF(H14="ETAPA",SUMIFS($N$8:$N$262,$B$8:$B$262,B14,$C$8:$C$262,C14,$H$8:$H$262,"Serviço"),IF(H14="SUBETAPA",SUMIFS($N$8:$N$262,$B$8:$B$262,B14,$C$8:$C$262,C14,$D$8:$D$262,D14,$H$8:$H$262,"Serviço"),0)))) -> 6223.36 | O14: Da marca oterprem, conforme projeto acustico r03
A15: =IF($H15="UNIDADE CONSTRUTIVA",OFFSET(A15,-1,0)+1,LARGE(A$3:A14,1)) -> 0 | B15: =IF(H15="UNIDADE CONSTRUTIVA",0,IF(H15="CÉLULA CONSTRUTIVA",OFFSET(B15,-1,0)+1,OFFSET(B15,-1,0))) -> 1 | C15: =IF(H15="CÉLULA CONSTRUTIVA",0,IF(H15="ETAPA",OFFSET(C15,-1,0)+1,OFFSET(C15,-1,0))) -> 1 | D15: =IF(H15="ETAPA",0,IF(H15="SUBETAPA",OFFSET(D15,-1,0)+1,OFFSET(D15,-1,0))) -> 1 | E15: =IF(H15="Subetapa",0,IF(H15="serviço",OFFSET(E15,-1,0)+1,OFFSET(E15,-1,0))) -> 5 | H15: SERVIÇO | I15: =IF(H15="Unidade Construtiva",TEXT(A15,"00"),IF(H15="Célula Construtiva",TEXT(B15,"00"),IF(H15="Etapa",CONCATENATE(TEXT(B15,"00"),".",TEXT(C15,"000")),IF(H15="Subetapa",CONCATENATE(TEXT(B15,"00"),".",TEXT(C15,"000"),".",TEXT(D15,"000")),IF(H15="Serviço",CONCATENATE(TEXT(B15,"00"),".",TEXT(C15,"000"),".",TEXT(D15,"000"),".",TEXT(E15,"000")),""))))) -> 01.001.001.005 | J15: Alvenaria de vedação de Bloco concreto corta-fogo de 14x19x39cm, com argamassa estabilizada | K15: m2 | L15: =ARQUITETURA!H100 -> 1154.05 | M15: 99.5 | N15: =IF(H15="Serviço",M15*L15,IF(H15="CÉLULA CONSTRUTIVA",SUMIFS($N$8:$N$262,$B$8:$B$262,B15,$H$8:$H$262,"Serviço"),IF(H15="ETAPA",SUMIFS($N$8:$N$262,$B$8:$B$262,B15,$C$8:$C$262,C15,$H$8:$H$262,"Serviço"),IF(H15="SUBETAPA",SUMIFS($N$8:$N$262,$B$8:$B$262,B15,$C$8:$C$262,C15,$D$8:$D$262,D15,$H$8:$H$262,"Serviço"),0)))) -> 114827.98 | O15: Da marca oterprem, conforme projeto acustico r03
A16: =IF($H16="UNIDADE CONSTRUTIVA",OFFSET(A16,-1,0)+1,LARGE(A$3:A15,1)) -> 0 | B16: =IF(H16="UNIDADE CONSTRUTIVA",0,IF(H16="CÉLULA CONSTRUTIVA",OFFSET(B16,-1,0)+1,OFFSET(B16,-1,0))) -> 1 | C16: =IF(H16="CÉLULA CONSTRUTIVA",0,IF(H16="ETAPA",OFFSET(C16,-1,0)+1,OFFSET(C16,-1,0))) -> 1 | D16: =IF(H16="ETAPA",0,IF(H16="SUBETAPA",OFFSET(D16,-1,0)+1,OFFSET(D16,-1,0))) -> 1 | E16: =IF(H16="Subetapa",0,IF(H16="serviço",OFFSET(E16,-1,0)+1,OFFSET(E16,-1,0))) -> 6 | H16: SERVIÇO | I16: =IF(H16="Unidade Construtiva",TEXT(A16,"00"),IF(H16="Célula Construtiva",TEXT(B16,"00"),IF(H16="Etapa",CONCATENATE(TEXT(B16,"00"),".",TEXT(C16,"000")),IF(H16="Subetapa",CONCATENATE(TEXT(B16,"00"),".",TEXT(C16,"000"),".",TEXT(D16,"000")),IF(H16="Serviço",CONCATENATE(TEXT(B16,"00"),".",TEXT(C16,"000"),".",TEXT(D16,"000"),".",TEXT(E16,"000")),""))))) -> 01.001.001.006 | J16: Alvenaria de vedação de Bloco concreto corta-fogo com densidade acustica reforçada de 14x19x39cm, com argamassa estabilizada | K16: m2 | L16: =ARQUITETURA!H101 -> 2134.28 | M16: 148.5 | N16: =IF(H16="Serviço",M16*L16,IF(H16="CÉLULA CONSTRUTIVA",SUMIFS($N$8:$N$262,$B$8:$B$262,B16,$H$8:$H$262,"Serviço"),IF(H16="ETAPA",SUMIFS($N$8:$N$262,$B$8:$B$262,B16,$C$8:$C$262,C16,$H$8:$H$262,"Serviço"),IF(H16="SUBETAPA",SUMIFS($N$8:$N$262,$B$8:$B$262,B16,$C$8:$C$262,C16,$D$8:$D$262,D16,$H$8:$H$262,"Serviço"),0)))) -> 316940.58 | O16: Da marca oterprem, conforme projeto acustico r03
A17: =IF($H17="UNIDADE CONSTRUTIVA",OFFSET(A17,-1,0)+1,LARGE(A$3:A16,1)) -> 0 | B17: =IF(H17="UNIDADE CONSTRUTIVA",0,IF(H17="CÉLULA CONSTRUTIVA",OFFSET(B17,-1,0)+1,OFFSET(B17,-1,0))) -> 1 | C17: =IF(H17="CÉLULA CONSTRUTIVA",0,IF(H17="ETAPA",OFFSET(C17,-1,0)+1,OFFSET(C17,-1,0))) -> 1 | D17: =IF(H17="ETAPA",0,IF(H17="SUBETAPA",OFFSET(D17,-1,0)+1,OFFSET(D17,-1,0))) -> 1 | E17: =IF(H17="Subetapa",0,IF(H17="serviço",OFFSET(E17,-1,0)+1,OFFSET(E17,-1,0))) -> 7 | H17: SERVIÇO | I17: =IF(H17="Unidade Construtiva",TEXT(A17,"00"),IF(H17="Célula Construtiva",TEXT(B17,"00"),IF(H17="Etapa",CONCATENATE(TEXT(B17,"00"),".",TEXT(C17,"000")),IF(H17="Subetapa",CONCATENATE(TEXT(B17,"00"),".",TEXT(C17,"000"),".",TEXT(D17,"000")),IF(H17="Serviço",CONCATENATE(TEXT(B17,"00"),".",TEXT(C17,"000"),".",TEXT(D17,"000"),".",TEXT(E17,"000")),""))))) -> 01.001.001.007 | J17: Alvenaria de vedação de Bloco concreto corta-fogo de 19x19x39cm, com argamassa estabilizada | K17: m2 | L17: =ARQUITETURA!H102 -> 90.94 | M17: 141.5 | N17: =IF(H17="Serviço",M17*L17,IF(H17="CÉLULA CONSTRUTIVA",SUMIFS($N$8:$N$262,$B$8:$B$262,B17,$H$8:$H$262,"Serviço"),IF(H17="ETAPA",SUMIFS($N$8:$N$262,$B$8:$B$262,B17,$C$8:$C$262,C17,$H$8:$H$262,"Serviço"),IF(H17="SUBETAPA",SUMIFS($N$8:$N$262,$B$8:$B$262,B17,$C$8:$C$262,C17,$D$8:$D$262,D17,$H$8:$H$262,"Serviço"),0)))) -> 12868.01 | O17: Da marca oterprem, conforme projeto acustico r03
A18: =IF($H18="UNIDADE CONSTRUTIVA",OFFSET(A18,-1,0)+1,LARGE(A$3:A13,1)) -> 0 | B18: =IF(H18="UNIDADE CONSTRUTIVA",0,IF(H18="CÉLULA CONSTRUTIVA",OFFSET(B18,-1,0)+1,OFFSET(B18,-1,0))) -> 1 | C18: =IF(H18="CÉLULA CONSTRUTIVA",0,IF(H18="ETAPA",OFFSET(C18,-1,0)+1,OFFSET(C18,-1,0))) -> 1 | D18: =IF(H18="ETAPA",0,IF(H18="SUBETAPA",OFFSET(D18,-1,0)+1,OFFSET(D18,-1,0))) -> 2 | E18: =IF(H18="Subetapa",0,IF(H18="serviço",OFFSET(E18,-1,0)+1,OFFSET(E18,-1,0))) -> 0 | H18: SUBETAPA | I18: =IF(H18="Unidade Construtiva",TEXT(A18,"00"),IF(H18="Célula Construtiva",TEXT(B18,"00"),IF(H18="Etapa",CONCATENATE(TEXT(B18,"00"),".",TEXT(C18,"000")),IF(H18="Subetapa",CONCATENATE(TEXT(B18,"00"),".",TEXT(C18,"000"),".",TEXT(D18,"000")),IF(H18="Serviço",CONCATENATE(TEXT(B18,"00"),".",TEXT(C18,"000"),".",TEXT(D18,"000"),".",TEXT(E18,"000")),""))))) -> 01.001.002 | J18: Serviços complementares para alvenaria de vedação | N18: =IF(H18="Serviço",M18*L18,IF(H18="CÉLULA CONSTRUTIVA",SUMIFS($N$8:$N$262,$B$8:$B$262,B18,$H$8:$H$262,"Serviço"),IF(H18="ETAPA",SUMIFS($N$8:$N$262,$B$8:$B$262,B18,$C$8:$C$262,C18,$H$8:$H$262,"Serviço"),IF(H18="SUBETAPA",SUMIFS($N$8:$N$262,$B$8:$B$262,B18,$C$8:$C$262,C18,$D$8:$D$262,D18,$H$8:$H$262,"Serviço"),0)))) -> 290203.44
A19: =IF($H19="UNIDADE CONSTRUTIVA",OFFSET(A19,-1,0)+1,LARGE(A$3:A18,1)) -> 0 | B19: =IF(H19="UNIDADE CONSTRUTIVA",0,IF(H19="CÉLULA CONSTRUTIVA",OFFSET(B19,-1,0)+1,OFFSET(B19,-1,0))) -> 1 | C19: =IF(H19="CÉLULA CONSTRUTIVA",0,IF(H19="ETAPA",OFFSET(C19,-1,0)+1,OFFSET(C19,-1,0))) -> 1 | D19: =IF(H19="ETAPA",0,IF(H19="SUBETAPA",OFFSET(D19,-1,0)+1,OFFSET(D19,-1,0))) -> 2 | E19: =IF(H19="Subetapa",0,IF(H19="serviço",OFFSET(E19,-1,0)+1,OFFSET(E19,-1,0))) -> 1 | H19: SERVIÇO | I19: =IF(H19="Unidade Construtiva",TEXT(A19,"00"),IF(H19="Célula Construtiva",TEXT(B19,"00"),IF(H19="Etapa",CONCATENATE(TEXT(B19,"00"),".",TEXT(C19,"000")),IF(H19="Subetapa",CONCATENATE(TEXT(B19,"00"),".",TEXT(C19,"000"),".",TEXT(D19,"000")),IF(H19="Serviço",CONCATENATE(TEXT(B19,"00"),".",TEXT(C19,"000"),".",TEXT(D19,"000"),".",TEXT(E19,"000")),""))))) -> 01.001.002.001 | J19: Encunhamento de alvenaria de vedação com argamassa expansiva | K19: m | L19: =ARQUITETURA!H195 -> 4171.21 | M19: 14.7875 | N19: =IF(H19="Serviço",M19*L19,IF(H19="CÉLULA CONSTRUTIVA",SUMIFS($N$8:$N$262,$B$8:$B$262,B19,$H$8:$H$262,"Serviço"),IF(H19="ETAPA",SUMIFS($N$8:$N$262,$B$8:$B$262,B19,$C$8:$C$262,C19,$H$8:$H$262,"Serviço"),IF(H19="SUBETAPA",SUMIFS($N$8:$N$262,$B$8:$B$262,B19,$C$8:$C$262,C19,$D$8:$D$262,D19,$H$8:$H$262,"Serviço"),0)))) -> 61681.768
A20: =IF($H20="UNIDADE CONSTRUTIVA",OFFSET(A20,-1,0)+1,LARGE(A$3:A19,1)) -> 0 | B20: =IF(H20="UNIDADE CONSTRUTIVA",0,IF(H20="CÉLULA CONSTRUTIVA",OFFSET(B20,-1,0)+1,OFFSET(B20,-1,0))) -> 1 | C20: =IF(H20="CÉLULA CONSTRUTIVA",0,IF(H20="ETAPA",OFFSET(C20,-1,0)+1,OFFSET(C20,-1,0))) -> 1 | D20: =IF(H20="ETAPA",0,IF(H20="SUBETAPA",OFFSET(D20,-1,0)+1,OFFSET(D20,-1,0))) -> 2 | E20: =IF(H20="Subetapa",0,IF(H20="serviço",OFFSET(E20,-1,0)+1,OFFSET(E20,-1,0))) -> 2 | H20: SERVIÇO | I20: =IF(H20="Unidade Construtiva",TEXT(A20,"00"),IF(H20="Célula Construtiva",TEXT(B20,"00"),IF(H20="Etapa",CONCATENATE(TEXT(B20,"00"),".",TEXT(C20,"000")),IF(H20="Subetapa",CONCATENATE(TEXT(B20,"00"),".",TEXT(C20,"000"),".",TEXT(D20,"000")),IF(H20="Serviço",CONCATENATE(TEXT(B20,"00"),".",TEXT(C20,"000"),".",TEXT(D20,"000"),".",TEXT(E20,"000")),""))))) -> 01.001.002.002 | J20: Tela soldada para ligacao alvenaria/estrutura | K20: un | L20: =ROUNDUP(ARQUITETURA!H196,0) -> 3924 | M20: 4.1072 | N20: =IF(H20="Serviço",M20*L20,IF(H20="CÉLULA CONSTRUTIVA",SUMIFS($N$8:$N$262,$B$8:$B$262,B20,$H$8:$H$262,"Serviço"),IF(H20="ETAPA",SUMIFS($N$8:$N$262,$B$8:$B$262,B20,$C$8:$C$262,C20,$H$8:$H$262,"Serviço"),IF(H20="SUBETAPA",SUMIFS($N$8:$N$262,$B$8:$B$262,B20,$C$8:$C$262,C20,$D$8:$D$262,D20,$H$8:$H$262,"Serviço"),0)))) -> 16116.653
A21: =IF($H21="UNIDADE CONSTRUTIVA",OFFSET(A21,-1,0)+1,LARGE(A$3:A20,1)) -> 0 | B21: =IF(H21="UNIDADE CONSTRUTIVA",0,IF(H21="CÉLULA CONSTRUTIVA",OFFSET(B21,-1,0)+1,OFFSET(B21,-1,0))) -> 1 | C21: =IF(H21="CÉLULA CONSTRUTIVA",0,IF(H21="ETAPA",OFFSET(C21,-1,0)+1,OFFSET(C21,-1,0))) -> 1 | D21: =IF(H21="ETAPA",0,IF(H21="SUBETAPA",OFFSET(D21,-1,0)+1,OFFSET(D21,-1,0))) -> 2 | E21: =IF(H21="Subetapa",0,IF(H21="serviço",OFFSET(E21,-1,0)+1,OFFSET(E21,-1,0))) -> 3 | H21: SERVIÇO | I21: =IF(H21="Unidade Construtiva",TEXT(A21,"00"),IF(H21="Célula Construtiva",TEXT(B21,"00"),IF(H21="Etapa",CONCATENATE(TEXT(B21,"00"),".",TEXT(C21,"000")),IF(H21="Subetapa",CONCATENATE(TEXT(B21,"00"),".",TEXT(C21,"000"),".",TEXT(D21,"000")),IF(H21="Serviço",CONCATENATE(TEXT(B21,"00"),".",TEXT(C21,"000"),".",TEXT(D21,"000"),".",TEXT(E21,"000")),""))))) -> 01.001.002.003 | J21: Verga/contraverga de concreto, moldada in loco | K21: m | L21: =ARQUITETURA!H194+ARQUITETURA!H197+ARQUITETURA!H198 -> 2642.46 | M21: 80.381545 | N21: =IF(H21="Serviço",M21*L21,IF(H21="CÉLULA CONSTRUTIVA",SUMIFS($N$8:$N$262,$B$8:$B$262,B21,$H$8:$H$262,"Serviço"),IF(H21="ETAPA",SUMIFS($N$8:$N$262,$B$8:$B$262,B21,$C$8:$C$262,C21,$H$8:$H$262,"Serviço"),IF(H21="SUBETAPA",SUMIFS($N$8:$N$262,$B$8:$B$262,B21,$C$8:$C$262,C21,$D$8:$D$262,D21,$H$8:$H$262,"Serviço"),0)))) -> 212405.02
A22: =IF($H22="UNIDADE CONSTRUTIVA",OFFSET(A22,-1,0)+1,LARGE(A$3:A21,1)) -> 0 | B22: =IF(H22="UNIDADE CONSTRUTIVA",0,IF(H22="CÉLULA CONSTRUTIVA",OFFSET(B22,-1,0)+1,OFFSET(B22,-1,0))) -> 1 | C22: =IF(H22="CÉLULA CONSTRUTIVA",0,IF(H22="ETAPA",OFFSET(C22,-1,0)+1,OFFSET(C22,-1,0))) -> 1 | D22: =IF(H22="ETAPA",0,IF(H22="SUBETAPA",OFFSET(D22,-1,0)+1,OFFSET(D22,-1,0))) -> 3 | E22: =IF(H22="Subetapa",0,IF(H22="serviço",OFFSET(E22,-1,0)+1,OFFSET(E22,-1,0))) -> 0 | H22: SUBETAPA | I22: =IF(H22="Unidade Construtiva",TEXT(A22,"00"),IF(H22="Célula Construtiva",TEXT(B22,"00"),IF(H22="Etapa",CONCATENATE(TEXT(B22,"00"),".",TEXT(C22,"000")),IF(H22="Subetapa",CONCATENATE(TEXT(B22,"00"),".",TEXT(C22,"000"),".",TEXT(D22,"000")),IF(H22="Serviço",CONCATENATE(TEXT(B22,"00"),".",TEXT(C22,"000"),".",TEXT(D22,"000"),".",TEXT(E22,"000")),""))))) -> 01.001.003 | J22: Drywall | N22: =IF(H22="Serviço",M22*L22,IF(H22="CÉLULA CONSTRUTIVA",SUMIFS($N$8:$N$262,$B$8:$B$262,B22,$H$8:$H$262,"Serviço"),IF(H22="ETAPA",SUMIFS($N$8:$N$262,$B$8:$B$262,B22,$C$8:$C$262,C22,$H$8:$H$262,"Serviço"),IF(H22="SUBETAPA",SUMIFS($N$8:$N$262,$B$8:$B$262,B22,$C$8:$C$262,C22,$D$8:$D$262,D22,$H$8:$H$262,"Serviço"),0)))) -> 638363.57
A23: =IF($H23="UNIDADE CONSTRUTIVA",OFFSET(A23,-1,0)+1,LARGE(A$3:A22,1)) -> 0 | B23: =IF(H23="UNIDADE CONSTRUTIVA",0,IF(H23="CÉLULA CONSTRUTIVA",OFFSET(B23,-1,0)+1,OFFSET(B23,-1,0))) -> 1 | C23: =IF(H23="CÉLULA CONSTRUTIVA",0,IF(H23="ETAPA",OFFSET(C23,-1,0)+1,OFFSET(C23,-1,0))) -> 1 | D23: =IF(H23="ETAPA",0,IF(H23="SUBETAPA",OFFSET(D23,-1,0)+1,OFFSET(D23,-1,0))) -> 3 | E23: =IF(H23="Subetapa",0,IF(H23="serviço",OFFSET(E23,-1,0)+1,OFFSET(E23,-1,0))) -> 1 | H23: SERVIÇO | I23: =IF(H23="Unidade Construtiva",TEXT(A23,"00"),IF(H23="Célula Construtiva",TEXT(B23,"00"),IF(H23="Etapa",CONCATENATE(TEXT(B23,"00"),".",TEXT(C23,"000")),IF(H23="Subetapa",CONCATENATE(TEXT(B23,"00"),".",TEXT(C23,"000"),".",TEXT(D23,"000")),IF(H23="Serviço",CONCATENATE(TEXT(B23,"00"),".",TEXT(C23,"000"),".",TEXT(D23,"000"),".",TEXT(E23,"000")),""))))) -> 01.001.003.001 | J23: Parede Com Sistema Em Chapas De Gesso Para Drywall, Uso Interno, Montante 70mm, Com Uma Face Resistente a Umidade(RU/70) | K23: m2 | L23: =ARQUITETURA!H322+ARQUITETURA!H323 -> 3630.03 | M23: 128.62074 | N23: =IF(H23="Serviço",M23*L23,IF(H23="CÉLULA CONSTRUTIVA",SUMIFS($N$8:$N$262,$B$8:$B$262,B23,$H$8:$H$262,"Serviço"),IF(H23="ETAPA",SUMIFS($N$8:$N$262,$B$8:$B$262,B23,$C$8:$C$262,C23,$H$8:$H$262,"Serviço"),IF(H23="SUBETAPA",SUMIFS($N$8:$N$262,$B$8:$B$262,B23,$C$8:$C$262,C23,$D$8:$D$262,D23,$H$8:$H$262,"Serviço"),0)))) -> 466897.16
A24: =IF($H24="UNIDADE CONSTRUTIVA",OFFSET(A24,-1,0)+1,LARGE(A$3:A23,1)) -> 0 | B24: =IF(H24="UNIDADE CONSTRUTIVA",0,IF(H24="CÉLULA CONSTRUTIVA",OFFSET(B24,-1,0)+1,OFFSET(B24,-1,0))) -> 1 | C24: =IF(H24="CÉLULA CONSTRUTIVA",0,IF(H24="ETAPA",OFFSET(C24,-1,0)+1,OFFSET(C24,-1,0))) -> 1 | D24: =IF(H24="ETAPA",0,IF(H24="SUBETAPA",OFFSET(D24,-1,0)+1,OFFSET(D24,-1,0))) -> 3 | E24: =IF(H24="Subetapa",0,IF(H24="serviço",OFFSET(E24,-1,0)+1,OFFSET(E24,-1,0))) -> 2 | H24: SERVIÇO | I24: =IF(H24="Unidade Construtiva",TEXT(A24,"00"),IF(H24="Célula Construtiva",TEXT(B24,"00"),IF(H24="Etapa",CONCATENATE(TEXT(B24,"00"),".",TEXT(C24,"000")),IF(H24="Subetapa",CONCATENATE(TEXT(B24,"00"),".",TEXT(C24,"000"),".",TEXT(D24,"000")),IF(H24="Serviço",CONCATENATE(TEXT(B24,"00"),".",TEXT(C24,"000"),".",TEXT(D24,"000"),".",TEXT(E24,"000")),""))))) -> 01.001.003.002 | J24: Parede Com Sistema Em Chapas De Gesso Para Drywall, Uso Interno, Montante 70mm, Com Uma Face Resistente a Umidade(RU/70) - com tratamento de junta | K24: m2 | L24: =SUM(ARQUITETURA!F380:F459) -> 1305.21 | M24: 131.37074 | N24: =IF(H24="Serviço",M24*L24,IF(H24="CÉLULA CONSTRUTIVA",SUMIFS($N$8:$N$262,$B$8:$B$262,B24,$H$8:$H$262,"Serviço"),IF(H24="ETAPA",SUMIFS($N$8:$N$262,$B$8:$B$262,B24,$C$8:$C$262,C24,$H$8:$H$262,"Serviço"),IF(H24="SUBETAPA",SUMIFS($N$8:$N$262,$B$8:$B$262,B24,$C$8:$C$262,C24,$D$8:$D$262,D24,$H$8:$H$262,"Serviço"),0)))) -> 171466.41
A25: =IF($H25="UNIDADE CONSTRUTIVA",OFFSET(A25,-1,0)+1,LARGE(A$3:A23,1)) -> 0 | B25: =IF(H25="UNIDADE CONSTRUTIVA",0,IF(H25="CÉLULA CONSTRUTIVA",OFFSET(B25,-1,0)+1,OFFSET(B25,-1,0))) -> 1 | C25: =IF(H25="CÉLULA CONSTRUTIVA",0,IF(H25="ETAPA",OFFSET(C25,-1,0)+1,OFFSET(C25,-1,0))) -> 1 | D25: =IF(H25="ETAPA",0,IF(H25="SUBETAPA",OFFSET(D25,-1,0)+1,OFFSET(D25,-1,0))) -> 4 | E25: =IF(H25="Subetapa",0,IF(H25="serviço",OFFSET(E25,-1,0)+1,OFFSET(E25,-1,0))) -> 0 | H25: SUBETAPA | I25: =IF(H25="Unidade Construtiva",TEXT(A25,"00"),IF(H25="Célula Construtiva",TEXT(B25,"00"),IF(H25="Etapa",CONCATENATE(TEXT(B25,"00"),".",TEXT(C25,"000")),IF(H25="Subetapa",CONCATENATE(TEXT(B25,"00"),".",TEXT(C25,"000"),".",TEXT(D25,"000")),IF(H25="Serviço",CONCATENATE(TEXT(B25,"00"),".",TEXT(C25,"000"),".",TEXT(D25,"000"),".",TEXT(E25,"000")),""))))) -> 01.001.004 | J25: Mão de obra | N25: =IF(H25="Serviço",M25*L25,IF(H25="CÉLULA CONSTRUTIVA",SUMIFS($N$8:$N$262,$B$8:$B$262,B25,$H$8:$H$262,"Serviço"),IF(H25="ETAPA",SUMIFS($N$8:$N$262,$B$8:$B$262,B25,$C$8:$C$262,C25,$H$8:$H$262,"Serviço"),IF(H25="SUBETAPA",SUMIFS($N$8:$N$262,$B$8:$B$262,B25,$C$8:$C$262,C25,$D$8:$D$262,D25,$H$8:$H$262,"Serviço"),0)))) -> 376608.48
A26: =IF($H26="UNIDADE CONSTRUTIVA",OFFSET(A26,-1,0)+1,LARGE(A$3:A25,1)) -> 0 | B26: =IF(H26="UNIDADE CONSTRUTIVA",0,IF(H26="CÉLULA CONSTRUTIVA",OFFSET(B26,-1,0)+1,OFFSET(B26,-1,0))) -> 1 | C26: =IF(H26="CÉLULA CONSTRUTIVA",0,IF(H26="ETAPA",OFFSET(C26,-1,0)+1,OFFSET(C26,-1,0))) -> 1 | D26: =IF(H26="ETAPA",0,IF(H26="SUBETAPA",OFFSET(D26,-1,0)+1,OFFSET(D26,-1,0))) -> 4 | E26: =IF(H26="Subetapa",0,IF(H26="serviço",OFFSET(E26,-1,0)+1,OFFSET(E26,-1,0))) -> 1 | H26: SERVIÇO | I26: =IF(H26="Unidade Construtiva",TEXT(A26,"00"),IF(H26="Célula Construtiva",TEXT(B26,"00"),IF(H26="Etapa",CONCATENATE(TEXT(B26,"00"),".",TEXT(C26,"000")),IF(H26="Subetapa",CONCATENATE(TEXT(B26,"00"),".",TEXT(C26,"000"),".",TEXT(D26,"000")),IF(H26="Serviço",CONCATENATE(TEXT(B26,"00"),".",TEXT(C26,"000"),".",TEXT(D26,"000"),".",TEXT(E26,"000")),""))))) -> 01.001.004.001 | J26: Mão de obra para assentamento de blocos cerâmicos | K26: m2 | L26: =SUM(L14:L17) -> 3466.31 | M26: 48 | N26: =IF(H26="Serviço",M26*L26,IF(H26="CÉLULA CONSTRUTIVA",SUMIFS($N$8:$N$262,$B$8:$B$262,B26,$H$8:$H$262,"Serviço"),IF(H26="ETAPA",SUMIFS($N$8:$N$262,$B$8:$B$262,B26,$C$8:$C$262,C26,$H$8:$H$262,"Serviço"),IF(H26="SUBETAPA",SUMIFS($N$8:$N$262,$B$8:$B$262,B26,$C$8:$C$262,C26,$D$8:$D$262,D26,$H$8:$H$262,"Serviço"),0)))) -> 166382.88
A27: =IF($H27="UNIDADE CONSTRUTIVA",OFFSET(A27,-1,0)+1,LARGE(A$3:A26,1)) -> 0 | B27: =IF(H27="UNIDADE CONSTRUTIVA",0,IF(H27="CÉLULA CONSTRUTIVA",OFFSET(B27,-1,0)+1,OFFSET(B27,-1,0))) -> 1 | C27: =IF(H27="CÉLULA CONSTRUTIVA",0,IF(H27="ETAPA",OFFSET(C27,-1,0)+1,OFFSET(C27,-1,0))) -> 1 | D27: =IF(H27="ETAPA",0,IF(H27="SUBETAPA",OFFSET(D27,-1,0)+1,OFFSET(D27,-1,0))) -> 4 | E27: =IF(H27="Subetapa",0,IF(H27="serviço",OFFSET(E27,-1,0)+1,OFFSET(E27,-1,0))) -> 2 | H27: SERVIÇO | I27: =IF(H27="Unidade Construtiva",TEXT(A27,"00"),IF(H27="Célula Construtiva",TEXT(B27,"00"),IF(H27="Etapa",CONCATENATE(TEXT(B27,"00"),".",TEXT(C27,"000")),IF(H27="Subetapa",CONCATENATE(TEXT(B27,"00"),".",TEXT(C27,"000"),".",TEXT(D27,"000")),IF(H27="Serviço",CONCATENATE(TEXT(B27,"00"),".",TEXT(C27,"000"),".",TEXT(D27,"000"),".",TEXT(E27,"000")),""))))) -> 01.001.004.002 | J27: Mão de obra para assentamento de blocos concreto | K27: m2 | L27: =SUM(L11:L13) -> 4379.7 | M27: 48 | N27: =IF(H27="Serviço",M27*L27,IF(H27="CÉLULA CONSTRUTIVA",SUMIFS($N$8:$N$262,$B$8:$B$262,B27,$H$8:$H$262,"Serviço"),IF(H27="ETAPA",SUMIFS($N$8:$N$262,$B$8:$B$262,B27,$C$8:$C$262,C27,$H$8:$H$262,"Serviço"),IF(H27="SUBETAPA",SUMIFS($N$8:$N$262,$B$8:$B$262,B27,$C$8:$C$262,C27,$D$8:$D$262,D27,$H$8:$H$262,"Serviço"),0)))) -> 210225.6
A28: =IF($H28="UNIDADE CONSTRUTIVA",OFFSET(A28,-1,0)+1,LARGE(A$3:A27,1)) -> 0 | B28: =IF(H28="UNIDADE CONSTRUTIVA",0,IF(H28="CÉLULA CONSTRUTIVA",OFFSET(B28,-1,0)+1,OFFSET(B28,-1,0))) -> 2 | C28: =IF(H28="CÉLULA CONSTRUTIVA",0,IF(H28="ETAPA",OFFSET(C28,-1,0)+1,OFFSET(C28,-1,0))) -> 0 | D28: =IF(H28="ETAPA",0,IF(H28="SUBETAPA",OFFSET(D28,-1,0)+1,OFFSET(D28,-1,0))) -> 4 | E28: =IF(H28="Subetapa",0,IF(H28="serviço",OFFSET(E28,-1,0)+1,OFFSET(E28,-1,0))) -> 2 | H28: CÉLULA CONSTRUTIVA | I28: =IF(H28="Unidade Construtiva",TEXT(A28,"00"),IF(H28="Célula Construtiva",TEXT(B28,"00"),IF(H28="Etapa",CONCATENATE(TEXT(B28,"00"),".",TEXT(C28,"000")),IF(H28="Subetapa",CONCATENATE(TEXT(B28,"00"),".",TEXT(C28,"000"),".",TEXT(D28,"000")),IF(H28="Serviço",CONCATENATE(TEXT(B28,"00"),".",TEXT(C28,"000"),".",TEXT(D28,"000"),".",TEXT(E28,"000")),""))))) -> 02 | J28: IMPERMEABILIZAÇÃO E TRATAMENTOS | N28: =IF(H28="Serviço",M28*L28,IF(H28="CÉLULA CONSTRUTIVA",SUMIFS($N$8:$N$262,$B$8:$B$262,B28,$H$8:$H$262,"Serviço"),IF(H28="ETAPA",SUMIFS($N$8:$N$262,$B$8:$B$262,B28,$C$8:$C$262,C28,$H$8:$H$262,"Serviço"),IF(H28="SUBETAPA",SUMIFS($N$8:$N$262,$B$8:$B$262,B28,$C$8:$C$262,C28,$D$8:$D$262,D28,$H$8:$H$262,"Serviço"),0)))) -> 703992.08 | O28: =N28/'Obra '!$E$9 -> 101.46332 | Q28: IMPERMEABILIZAÇÃO
A29: =IF($H29="UNIDADE CONSTRUTIVA",OFFSET(A29,-1,0)+1,LARGE(A$3:A28,1)) -> 0 | B29: =IF(H29="UNIDADE CONSTRUTIVA",0,IF(H29="CÉLULA CONSTRUTIVA",OFFSET(B29,-1,0)+1,OFFSET(B29,-1,0))) -> 2 | C29: =IF(H29="CÉLULA CONSTRUTIVA",0,IF(H29="ETAPA",OFFSET(C29,-1,0)+1,OFFSET(C29,-1,0))) -> 1 | D29: =IF(H29="ETAPA",0,IF(H29="SUBETAPA",OFFSET(D29,-1,0)+1,OFFSET(D29,-1,0))) -> 0 | E29: =IF(H29="Subetapa",0,IF(H29="serviço",OFFSET(E29,-1,0)+1,OFFSET(E29,-1,0))) -> 2 | H29: ETAPA | I29: =IF(H29="Unidade Construtiva",TEXT(A29,"00"),IF(H29="Célula Construtiva",TEXT(B29,"00"),IF(H29="Etapa",CONCATENATE(TEXT(B29,"00"),".",TEXT(C29,"000")),IF(H29="Subetapa",CONCATENATE(TEXT(B29,"00"),".",TEXT(C29,"000"),".",TEXT(D29,"000")),IF(H29="Serviço",CONCATENATE(TEXT(B29,"00"),".",TEXT(C29,"000"),".",TEXT(D29,"000"),".",TEXT(E29,"000")),""))))) -> 02.001 | J29: IMPERMEABILIZAÇÃO E TRATAMENTOS | N29: =IF(H29="Serviço",M29*L29,IF(H29="CÉLULA CONSTRUTIVA",SUMIFS($N$8:$N$262,$B$8:$B$262,B29,$H$8:$H$262,"Serviço"),IF(H29="ETAPA",SUMIFS($N$8:$N$262,$B$8:$B$262,B29,$C$8:$C$262,C29,$H$8:$H$262,"Serviço"),IF(H29="SUBETAPA",SUMIFS($N$8:$N$262,$B$8:$B$262,B29,$C$8:$C$262,C29,$D$8:$D$262,D29,$H$8:$H$262,"Serviço"),0)))) -> 703992.08
A30: =IF($H30="UNIDADE CONSTRUTIVA",OFFSET(A30,-1,0)+1,LARGE(A$3:A29,1)) -> 0 | B30: =IF(H30="UNIDADE CONSTRUTIVA",0,IF(H30="CÉLULA CONSTRUTIVA",OFFSET(B30,-1,0)+1,OFFSET(B30,-1,0))) -> 2 | C30: =IF(H30="CÉLULA CONSTRUTIVA",0,IF(H30="ETAPA",OFFSET(C30,-1,0)+1,OFFSET(C30,-1,0))) -> 1 | D30: =IF(H30="ETAPA",0,IF(H30="SUBETAPA",OFFSET(D30,-1,0)+1,OFFSET(D30,-1,0))) -> 1 | E30: =IF(H30="Subetapa",0,IF(H30="serviço",OFFSET(E30,-1,0)+1,OFFSET(E30,-1,0))) -> 0 | H30: SUBETAPA | I30: =IF(H30="Unidade Construtiva",TEXT(A30,"00"),IF(H30="Célula Construtiva",TEXT(B30,"00"),IF(H30="Etapa",CONCATENATE(TEXT(B30,"00"),".",TEXT(C30,"000")),IF(H30="Subetapa",CONCATENATE(TEXT(B30,"00"),".",TEXT(C30,"000"),".",TEXT(D30,"000")),IF(H30="Serviço",CONCATENATE(TEXT(B30,"00"),".",TEXT(C30,"000"),".",TEXT(D30,"000"),".",TEXT(E30,"000")),""))))) -> 02.001.001 | J30: Regularização e proteção mecânica | N30: =IF(H30="Serviço",M30*L30,IF(H30="CÉLULA CONSTRUTIVA",SUMIFS($N$8:$N$262,$B$8:$B$262,B30,$H$8:$H$262,"Serviço"),IF(H30="ETAPA",SUMIFS($N$8:$N$262,$B$8:$B$262,B30,$C$8:$C$262,C30,$H$8:$H$262,"Serviço"),IF(H30="SUBETAPA",SUMIFS($N$8:$N$262,$B$8:$B$262,B30,$C$8:$C$262,C30,$D$8:$D$262,D30,$H$8:$H$262,"Serviço"),0)))) -> 58243.88
A31: =IF($H31="UNIDADE CONSTRUTIVA",OFFSET(A31,-1,0)+1,LARGE(A$3:A30,1)) -> 0 | B31: =IF(H31="UNIDADE CONSTRUTIVA",0,IF(H31="CÉLULA CONSTRUTIVA",OFFSET(B31,-1,0)+1,OFFSET(B31,-1,0))) -> 2 | C31: =IF(H31="CÉLULA CONSTRUTIVA",0,IF(H31="ETAPA",OFFSET(C31,-1,0)+1,OFFSET(C31,-1,0))) -> 1 | D31: =IF(H31="ETAPA",0,IF(H31="SUBETAPA",OFFSET(D31,-1,0)+1,OFFSET(D31,-1,0))) -> 1 | E31: =IF(H31="Subetapa",0,IF(H31="serviço",OFFSET(E31,-1,0)+1,OFFSET(E31,-1,0))) -> 1 | H31: SERVIÇO | I31: =IF(H31="Unidade Construtiva",TEXT(A31,"00"),IF(H31="Célula Construtiva",TEXT(B31,"00"),IF(H31="Etapa",CONCATENATE(TEXT(B31,"00"),".",TEXT(C31,"000")),IF(H31="Subetapa",CONCATENATE(TEXT(B31,"00"),".",TEXT(C31,"000"),".",TEXT(D31,"000")),IF(H31="Serviço",CONCATENATE(TEXT(B31,"00"),".",TEXT(C31,"000"),".",TEXT(D31,"000"),".",TEXT(E31,"000")),""))))) -> 02.001.001.001 | J31: Regularização de superfície para impermeabilização | K31: m2 | L31: =ARQUITETURA!H742 -> 2847.53 | M31: 7.0659 | N31: =IF(H31="Serviço",M31*L31,IF(H31="CÉLULA CONSTRUTIVA",SUMIFS($N$8:$N$262,$B$8:$B$262,B31,$H$8:$H$262,"Serviço"),IF(H31="ETAPA",SUMIFS($N$8:$N$262,$B$8:$B$262,B31,$C$8:$C$262,C31,$H$8:$H$262,"Serviço"),IF(H31="SUBETAPA",SUMIFS($N$8:$N$262,$B$8:$B$262,B31,$C$8:$C$262,C31,$D$8:$D$262,D31,$H$8:$H$262,"Serviço"),0)))) -> 20120.362 | O31: Considerado somente nos pisos que recebem impermeabilização
A32: =IF($H32="UNIDADE CONSTRUTIVA",OFFSET(A32,-1,0)+1,LARGE(A$3:A31,1)) -> 0 | B32: =IF(H32="UNIDADE CONSTRUTIVA",0,IF(H32="CÉLULA CONSTRUTIVA",OFFSET(B32,-1,0)+1,OFFSET(B32,-1,0))) -> 2 | C32: =IF(H32="CÉLULA CONSTRUTIVA",0,IF(H32="ETAPA",OFFSET(C32,-1,0)+1,OFFSET(C32,-1,0))) -> 1 | D32: =IF(H32="ETAPA",0,IF(H32="SUBETAPA",OFFSET(D32,-1,0)+1,OFFSET(D32,-1,0))) -> 1 | E32: =IF(H32="Subetapa",0,IF(H32="serviço",OFFSET(E32,-1,0)+1,OFFSET(E32,-1,0))) -> 2 | H32: SERVIÇO | I32: =IF(H32="Unidade Construtiva",TEXT(A32,"00"),IF(H32="Célula Construtiva",TEXT(B32,"00"),IF(H32="Etapa",CONCATENATE(TEXT(B32,"00"),".",TEXT(C32,"000")),IF(H32="Subetapa",CONCATENATE(TEXT(B32,"00"),".",TEXT(C32,"000"),".",TEXT(D32,"000")),IF(H32="Serviço",CONCATENATE(TEXT(B32,"00"),".",TEXT(C32,"000"),".",TEXT(D32,"000"),".",TEXT(E32,"000")),""))))) -> 02.001.001.002 | J32: Proteção mecânica de superfície com argamassa de cimento e areia, traço 1:3 E=5cm | K32: m2 | L32: =ARQUITETURA!H741 -> 772.38 | M32: 49.3585 | N32: =IF(H32="Serviço",M32*L32,IF(H32="CÉLULA CONSTRUTIVA",SUMIFS($N$8:$N$262,$B$8:$B$262,B32,$H$8:$H$262,"Serviço"),IF(H32="ETAPA",SUMIFS($N$8:$N$262,$B$8:$B$262,B32,$C$8:$C$262,C32,$H$8:$H$262,"Serviço"),IF(H32="SUBETAPA",SUMIFS($N$8:$N$262,$B$8:$B$262,B32,$C$8:$C$262,C32,$D$8:$D$262,D32,$H$8:$H$262,"Serviço"),0)))) -> 38123.518 | O32: Considerado somente nos pisos que recebem manta asfaltica
A33: =IF($H33="UNIDADE CONSTRUTIVA",OFFSET(A33,-1,0)+1,LARGE(A$3:A32,1)) -> 0 | B33: =IF(H33="UNIDADE CONSTRUTIVA",0,IF(H33="CÉLULA CONSTRUTIVA",OFFSET(B33,-1,0)+1,OFFSET(B33,-1,0))) -> 2 | C33: =IF(H33="CÉLULA CONSTRUTIVA",0,IF(H33="ETAPA",OFFSET(C33,-1,0)+1,OFFSET(C33,-1,0))) -> 1 | D33: =IF(H33="ETAPA",0,IF(H33="SUBETAPA",OFFSET(D33,-1,0)+1,OFFSET(D33,-1,0))) -> 2 | E33: =IF(H33="Subetapa",0,IF(H33="serviço",OFFSET(E33,-1,0)+1,OFFSET(E33,-1,0))) -> 0 | H33: SUBETAPA | I33: =IF(H33="Unidade Construtiva",TEXT(A33,"00"),IF(H33="Célula Construtiva",TEXT(B33,"00"),IF(H33="Etapa",CONCATENATE(TEXT(B33,"00"),".",TEXT(C33,"000")),IF(H33="Subetapa",CONCATENATE(TEXT(B33,"00"),".",TEXT(C33,"000"),".",TEXT(D33,"000")),IF(H33="Serviço",CONCATENATE(TEXT(B33,"00"),".",TEXT(C33,"000"),".",TEXT(D33,"000"),".",TEXT(E33,"000")),""))))) -> 02.001.002 | J33: Impermeabilização de fundação e contenção | N33: =IF(H33="Serviço",M33*L33,IF(H33="CÉLULA CONSTRUTIVA",SUMIFS($N$8:$N$262,$B$8:$B$262,B33,$H$8:$H$262,"Serviço"),IF(H33="ETAPA",SUMIFS($N$8:$N$262,$B$8:$B$262,B33,$C$8:$C$262,C33,$H$8:$H$262,"Serviço"),IF(H33="SUBETAPA",SUMIFS($N$8:$N$262,$B$8:$B$262,B33,$C$8:$C$262,C33,$D$8:$D$262,D33,$H$8:$H$262,"Serviço"),0)))) -> 8300.3378
A34: =IF($H34="UNIDADE CONSTRUTIVA",OFFSET(A34,-1,0)+1,LARGE(A$3:A33,1)) -> 0 | B34: =IF(H34="UNIDADE CONSTRUTIVA",0,IF(H34="CÉLULA CONSTRUTIVA",OFFSET(B34,-1,0)+1,OFFSET(B34,-1,0))) -> 2 | C34: =IF(H34="CÉLULA CONSTRUTIVA",0,IF(H34="ETAPA",OFFSET(C34,-1,0)+1,OFFSET(C34,-1,0))) -> 1 | D34: =IF(H34="ETAPA",0,IF(H34="SUBETAPA",OFFSET(D34,-1,0)+1,OFFSET(D34,-1,0))) -> 2 | E34: =IF(H34="Subetapa",0,IF(H34="serviço",OFFSET(E34,-1,0)+1,OFFSET(E34,-1,0))) -> 1 | H34: SERVIÇO | I34: =IF(H34="Unidade Construtiva",TEXT(A34,"00"),IF(H34="Célula Construtiva",TEXT(B34,"00"),IF(H34="Etapa",CONCATENATE(TEXT(B34,"00"),".",TEXT(C34,"000")),IF(H34="Subetapa",CONCATENATE(TEXT(B34,"00"),".",TEXT(C34,"000"),".",TEXT(D34,"000")),IF(H34="Serviço",CONCATENATE(TEXT(B34,"00"),".",TEXT(C34,"000"),".",TEXT(D34,"000"),".",TEXT(E34,"000")),""))))) -> 02.001.002.001 | J34: C4 - Argamassa polimérica rígida, estruturada com tela de poliéster nos pontos críticos (4,0 kg/m²) | K34: m2 | L34: =IMPERMEABILIZAÇÃO!B139 -> 209.84 | M34: 39.555556 | N34: =IF(H34="Serviço",M34*L34,IF(H34="CÉLULA CONSTRUTIVA",SUMIFS($N$8:$N$262,$B$8:$B$262,B34,$H$8:$H$262,"Serviço"),IF(H34="ETAPA",SUMIFS($N$8:$N$262,$B$8:$B$262,B34,$C$8:$C$262,C34,$H$8:$H$262,"Serviço"),IF(H34="SUBETAPA",SUMIFS($N$8:$N$262,$B$8:$B$262,B34,$C$8:$C$262,C34,$D$8:$D$262,D34,$H$8:$H$262,"Serviço"),0)))) -> 8300.3378
A35: =IF($H35="UNIDADE CONSTRUTIVA",OFFSET(A35,-1,0)+1,LARGE(A$3:A34,1)) -> 0 | B35: =IF(H35="UNIDADE CONSTRUTIVA",0,IF(H35="CÉLULA CONSTRUTIVA",OFFSET(B35,-1,0)+1,OFFSET(B35,-1,0))) -> 2 | C35: =IF(H35="CÉLULA CONSTRUTIVA",0,IF(H35="ETAPA",OFFSET(C35,-1,0)+1,OFFSET(C35,-1,0))) -> 1 | D35: =IF(H35="ETAPA",0,IF(H35="SUBETAPA",OFFSET(D35,-1,0)+1,OFFSET(D35,-1,0))) -> 3 | E35: =IF(H35="Subetapa",0,IF(H35="serviço",OFFSET(E35,-1,0)+1,OFFSET(E35,-1,0))) -> 0 | H35: SUBETAPA | I35: =IF(H35="Unidade Construtiva",TEXT(A35,"00"),IF(H35="Célula Construtiva",TEXT(B35,"00"),IF(H35="Etapa",CONCATENATE(TEXT(B35,"00"),".",TEXT(C35,"000")),IF(H35="Subetapa",CONCATENATE(TEXT(B35,"00"),".",TEXT(C35,"000"),".",TEXT(D35,"000")),IF(H35="Serviço",CONCATENATE(TEXT(B35,"00"),".",TEXT(C35,"000"),".",TEXT(D35,"000"),".",TEXT(E35,"000")),""))))) -> 02.001.003 | J35: Impermeabilização de lajes e terraços | N35: =IF(H35="Serviço",M35*L35,IF(H35="CÉLULA CONSTRUTIVA",SUMIFS($N$8:$N$262,$B$8:$B$262,B35,$H$8:$H$262,"Serviço"),IF(H35="ETAPA",SUMIFS($N$8:$N$262,$B$8:$B$262,B35,$C$8:$C$262,C35,$H$8:$H$262,"Serviço"),IF(H35="SUBETAPA",SUMIFS($N$8:$N$262,$B$8:$B$262,B35,$C$8:$C$262,C35,$D$8:$D$262,D35,$H$8:$H$262,"Serviço"),0)))) -> 144021.66
A36: =IF($H36="UNIDADE CONSTRUTIVA",OFFSET(A36,-1,0)+1,LARGE(A$3:A35,1)) -> 0 | B36: =IF(H36="UNIDADE CONSTRUTIVA",0,IF(H36="CÉLULA CONSTRUTIVA",OFFSET(B36,-1,0)+1,OFFSET(B36,-1,0))) -> 2 | C36: =IF(H36="CÉLULA CONSTRUTIVA",0,IF(H36="ETAPA",OFFSET(C36,-1,0)+1,OFFSET(C36,-1,0))) -> 1 | D36: =IF(H36="ETAPA",0,IF(H36="SUBETAPA",OFFSET(D36,-1,0)+1,OFFSET(D36,-1,0))) -> 3 | E36: =IF(H36="Subetapa",0,IF(H36="serviço",OFFSET(E36,-1,0)+1,OFFSET(E36,-1,0))) -> 1 | H36: SERVIÇO | I36: =IF(H36="Unidade Construtiva",TEXT(A36,"00"),IF(H36="Célula Construtiva",TEXT(B36,"00"),IF(H36="Etapa",CONCATENATE(TEXT(B36,"00"),".",TEXT(C36,"000")),IF(H36="Subetapa",CONCATENATE(TEXT(B36,"00"),".",TEXT(C36,"000"),".",TEXT(D36,"000")),IF(H36="Serviço",CONCATENATE(TEXT(B36,"00"),".",TEXT(C36,"000"),".",TEXT(D36,"000"),".",TEXT(E36,"000")),""))))) -> 02.001.003.001 | J36: C3 - Argamassa polimérica rígida, estruturada com tela de poliéster nos pontos críticos (3,0 kg/m²) | K36: m2 | L36: =SUMIFS(IMPERMEABILIZAÇÃO!B$13:B$145,IMPERMEABILIZAÇÃO!D$13:D$145,IMPERMEABILIZAÇÃO!$U$7,IMPERMEABILIZAÇÃO!E$13:E$145,Ger_Executivo!$I$35) -> 44.84 | M36: 29.666667 | N36: =IF(H36="Serviço",M36*L36,IF(H36="CÉLULA CONSTRUTIVA",SUMIFS($N$8:$N$262,$B$8:$B$262,B36,$H$8:$H$262,"Serviço"),IF(H36="ETAPA",SUMIFS($N$8:$N$262,$B$8:$B$262,B36,$C$8:$C$262,C36,$H$8:$H$262,"Serviço"),IF(H36="SUBETAPA",SUMIFS($N$8:$N$262,$B$8:$B$262,B36,$C$8:$C$262,C36,$D$8:$D$262,D36,$H$8:$H$262,"Serviço"),0)))) -> 1330.2533
A37: =IF($H37="UNIDADE CONSTRUTIVA",OFFSET(A37,-1,0)+1,LARGE(A$3:A36,1)) -> 0 | B37: =IF(H37="UNIDADE CONSTRUTIVA",0,IF(H37="CÉLULA CONSTRUTIVA",OFFSET(B37,-1,0)+1,OFFSET(B37,-1,0))) -> 2 | C37: =IF(H37="CÉLULA CONSTRUTIVA",0,IF(H37="ETAPA",OFFSET(C37,-1,0)+1,OFFSET(C37,-1,0))) -> 1 | D37: =IF(H37="ETAPA",0,IF(H37="SUBETAPA",OFFSET(D37,-1,0)+1,OFFSET(D37,-1,0))) -> 3 | E37: =IF(H37="Subetapa",0,IF(H37="serviço",OFFSET(E37,-1,0)+1,OFFSET(E37,-1,0))) -> 2 | H37: SERVIÇO | I37: =IF(H37="Unidade Construtiva",TEXT(A37,"00"),IF(H37="Célula Construtiva",TEXT(B37,"00"),IF(H37="Etapa",CONCATENATE(TEXT(B37,"00"),".",TEXT(C37,"000")),IF(H37="Subetapa",CONCATENATE(TEXT(B37,"00"),".",TEXT(C37,"000"),".",TEXT(D37,"000")),IF(H37="Serviço",CONCATENATE(TEXT(B37,"00"),".",TEXT(C37,"000"),".",TEXT(D37,"000"),".",TEXT(E37,"000")),""))))) -> 02.001.003.002 | J37: M44A - Manta asfáltica tipo IV, 4 mm A, com acabamento areia/areia aderida com asfalto oxidado (3,0 kg/m²) + banho de asfalto oxidado (2,0 kg/m²) | K37: m2 | L37: =SUMIFS(IMPERMEABILIZAÇÃO!B$13:B$145,IMPERMEABILIZAÇÃO!D$13:D$145,IMPERMEABILIZAÇÃO!$U$6,IMPERMEABILIZAÇÃO!E$13:E$145,Ger_Executivo!$I$35) -> 733.06 | M37: 108 | N37: =IF(H37="Serviço",M37*L37,IF(H37="CÉLULA CONSTRUTIVA",SUMIFS($N$8:$N$262,$B$8:$B$262,B37,$H$8:$H$262,"Serviço"),IF(H37="ETAPA",SUMIFS($N$8:$N$262,$B$8:$B$262,B37,$C$8:$C$262,C37,$H$8:$H$262,"Serviço"),IF(H37="SUBETAPA",SUMIFS($N$8:$N$262,$B$8:$B$262,B37,$C$8:$C$262,C37,$D$8:$D$262,D37,$H$8:$H$262,"Serviço"),0)))) -> 79170.48
A38: =IF($H38="UNIDADE CONSTRUTIVA",OFFSET(A38,-1,0)+1,LARGE(A$3:A37,1)) -> 0 | B38: =IF(H38="UNIDADE CONSTRUTIVA",0,IF(H38="CÉLULA CONSTRUTIVA",OFFSET(B38,-1,0)+1,OFFSET(B38,-1,0))) -> 2 | C38: =IF(H38="CÉLULA CONSTRUTIVA",0,IF(H38="ETAPA",OFFSET(C38,-1,0)+1,OFFSET(C38,-1,0))) -> 1 | D38: =IF(H38="ETAPA",0,IF(H38="SUBETAPA",OFFSET(D38,-1,0)+1,OFFSET(D38,-1,0))) -> 3 | E38: =IF(H38="Subetapa",0,IF(H38="serviço",OFFSET(E38,-1,0)+1,OFFSET(E38,-1,0))) -> 3 | H38: SERVIÇO | I38: =IF(H38="Unidade Construtiva",TEXT(A38,"00"),IF(H38="Célula Construtiva",TEXT(B38,"00"),IF(H38="Etapa",CONCATENATE(TEXT(B38,"00"),".",TEXT(C38,"000")),IF(H38="Subetapa",CONCATENATE(TEXT(B38,"00"),".",TEXT(C38,"000"),".",TEXT(D38,"000")),IF(H38="Serviço",CONCATENATE(TEXT(B38,"00"),".",TEXT(C38,"000"),".",TEXT(D38,"000"),".",TEXT(E38,"000")),""))))) -> 02.001.003.003 | J38: E3 - Membrana de polímero acrílico com cimento e fibras, estruturada com tela de poliéster nos pontos críticos (3,0 kg/m²) | K38: m2 | L38: =SUMIFS(IMPERMEABILIZAÇÃO!B$13:B$145,IMPERMEABILIZAÇÃO!D$13:D$145,IMPERMEABILIZAÇÃO!$U$4,IMPERMEABILIZAÇÃO!E$13:E$145,Ger_Executivo!$I$35) -> 565.63 | M38: 66 | N38: =IF(H38="Serviço",M38*L38,IF(H38="CÉLULA CONSTRUTIVA",SUMIFS($N$8:$N$262,$B$8:$B$262,B38,$H$8:$H$262,"Serviço"),IF(H38="ETAPA",SUMIFS($N$8:$N$262,$B$8:$B$262,B38,$C$8:$C$262,C38,$H$8:$H$262,"Serviço"),IF(H38="SUBETAPA",SUMIFS($N$8:$N$262,$B$8:$B$262,B38,$C$8:$C$262,C38,$D$8:$D$262,D38,$H$8:$H$262,"Serviço"),0)))) -> 37331.58
A39: =IF($H39="UNIDADE CONSTRUTIVA",OFFSET(A39,-1,0)+1,LARGE(A$3:A38,1)) -> 0 | B39: =IF(H39="UNIDADE CONSTRUTIVA",0,IF(H39="CÉLULA CONSTRUTIVA",OFFSET(B39,-1,0)+1,OFFSET(B39,-1,0))) -> 2 | C39: =IF(H39="CÉLULA CONSTRUTIVA",0,IF(H39="ETAPA",OFFSET(C39,-1,0)+1,OFFSET(C39,-1,0))) -> 1 | D39: =IF(H39="ETAPA",0,IF(H39="SUBETAPA",OFFSET(D39,-1,0)+1,OFFSET(D39,-1,0))) -> 3 | E39: =IF(H39="Subetapa",0,IF(H39="serviço",OFFSET(E39,-1,0)+1,OFFSET(E39,-1,0))) -> 4 | H39: SERVIÇO | I39: =IF(H39="Unidade Construtiva",TEXT(A39,"00"),IF(H39="Célula Construtiva",TEXT(B39,"00"),IF(H39="Etapa",CONCATENATE(TEXT(B39,"00"),".",TEXT(C39,"000")),IF(H39="Subetapa",CONCATENATE(TEXT(B39,"00"),".",TEXT(C39,"000"),".",TEXT(D39,"000")),IF(H39="Serviço",CONCATENATE(TEXT(B39,"00"),".",TEXT(C39,"000"),".",TEXT(D39,"000"),".",TEXT(E39,"000")),""))))) -> 02.001.003.004 | J39: M44A + M44AE2 - Manta asfáltica tipo IV, 4 mm + manta asfáltica tipo IV, 4 mm + banho de asfalto oxidado + membrana de polímero acrílico com cimento e fibras para combater eflorescência | K39: m2 | L39: =SUMIFS(IMPERMEABILIZAÇÃO!B$13:B$145,IMPERMEABILIZAÇÃO!D$13:D$145,IMPERMEABILIZAÇÃO!$U$15,IMPERMEABILIZAÇÃO!E$13:E$145,Ger_Executivo!$I$35) -> 3.64 | M39: 246 | N39: =IF(H39="Serviço",M39*L39,IF(H39="CÉLULA CONSTRUTIVA",SUMIFS($N$8:$N$262,$B$8:$B$262,B39,$H$8:$H$262,"Serviço"),IF(H39="ETAPA",SUMIFS($N$8:$N$262,$B$8:$B$262,B39,$C$8:$C$262,C39,$H$8:$H$262,"Serviço"),IF(H39="SUBETAPA",SUMIFS($N$8:$N$262,$B$8:$B$262,B39,$C$8:$C$262,C39,$D$8:$D$262,D39,$H$8:$H$262,"Serviço"),0)))) -> 895.44
A40: =IF($H40="UNIDADE CONSTRUTIVA",OFFSET(A40,-1,0)+1,LARGE(A$3:A39,1)) -> 0 | B40: =IF(H40="UNIDADE CONSTRUTIVA",0,IF(H40="CÉLULA CONSTRUTIVA",OFFSET(B40,-1,0)+1,OFFSET(B40,-1,0))) -> 2 | C40: =IF(H40="CÉLULA CONSTRUTIVA",0,IF(H40="ETAPA",OFFSET(C40,-1,0)+1,OFFSET(C40,-1,0))) -> 1 | D40: =IF(H40="ETAPA",0,IF(H40="SUBETAPA",OFFSET(D40,-1,0)+1,OFFSET(D40,-1,0))) -> 3 | E40: =IF(H40="Subetapa",0,IF(H40="serviço",OFFSET(E40,-1,0)+1,OFFSET(E40,-1,0))) -> 5 | H40: SERVIÇO | I40: =IF(H40="Unidade Construtiva",TEXT(A40,"00"),IF(H40="Célula Construtiva",TEXT(B40,"00"),IF(H40="Etapa",CONCATENATE(TEXT(B40,"00"),".",TEXT(C40,"000")),IF(H40="Subetapa",CONCATENATE(TEXT(B40,"00"),".",TEXT(C40,"000"),".",TEXT(D40,"000")),IF(H40="Serviço",CONCATENATE(TEXT(B40,"00"),".",TEXT(C40,"000"),".",TEXT(D40,"000"),".",TEXT(E40,"000")),""))))) -> 02.001.003.005 | J40: M44AR05 - Manta asfáltica tipo IV, 4 mm A, com acabamento areia/areia aderida com asfalto oxidado (3,0 kg/m²) + banho de asfalto oxidado (2,0 kg/m²) + pintura de proteção antirraiz sobre a proteção mecânica (0,5 L/m²) | K40: m2 | L40: =SUMIFS(IMPERMEABILIZAÇÃO!B$13:B$145,IMPERMEABILIZAÇÃO!D$13:D$145,IMPERMEABILIZAÇÃO!$U$14,IMPERMEABILIZAÇÃO!E$13:E$145,Ger_Executivo!$I$35) -> 11.53 | M40: 138 | N40: =IF(H40="Serviço",M40*L40,IF(H40="CÉLULA CONSTRUTIVA",SUMIFS($N$8:$N$262,$B$8:$B$262,B40,$H$8:$H$262,"Serviço"),IF(H40="ETAPA",SUMIFS($N$8:$N$262,$B$8:$B$262,B40,$C$8:$C$262,C40,$H$8:$H$262,"Serviço"),IF(H40="SUBETAPA",SUMIFS($N$8:$N$262,$B$8:$B$262,B40,$C$8:$C$262,C40,$D$8:$D$262,D40,$H$8:$H$262,"Serviço"),0)))) -> 1591.14
A41: =IF($H41="UNIDADE CONSTRUTIVA",OFFSET(A41,-1,0)+1,LARGE(A$3:A40,1)) -> 0 | B41: =IF(H41="UNIDADE CONSTRUTIVA",0,IF(H41="CÉLULA CONSTRUTIVA",OFFSET(B41,-1,0)+1,OFFSET(B41,-1,0))) -> 2 | C41: =IF(H41="CÉLULA CONSTRUTIVA",0,IF(H41="ETAPA",OFFSET(C41,-1,0)+1,OFFSET(C41,-1,0))) -> 1 | D41: =IF(H41="ETAPA",0,IF(H41="SUBETAPA",OFFSET(D41,-1,0)+1,OFFSET(D41,-1,0))) -> 3 | E41: =IF(H41="Subetapa",0,IF(H41="serviço",OFFSET(E41,-1,0)+1,OFFSET(E41,-1,0))) -> 6 | H41: SERVIÇO | I41: =IF(H41="Unidade Construtiva",TEXT(A41,"00"),IF(H41="Célula Construtiva",TEXT(B41,"00"),IF(H41="Etapa",CONCATENATE(TEXT(B41,"00"),".",TEXT(C41,"000")),IF(H41="Subetapa",CONCATENATE(TEXT(B41,"00"),".",TEXT(C41,"000"),".",TEXT(D41,"000")),IF(H41="Serviço",CONCATENATE(TEXT(B41,"00"),".",TEXT(C41,"000"),".",TEXT(D41,"000"),".",TEXT(E41,"000")),""))))) -> 02.001.003.006 | J41: M44AE2 - Manta asfáltica tipo IV, 4 mm A, com acabamento areia/areia aderida com asfalto oxidado (3,0 kg/m²) + banho de asfalto oxidado (2,0 kg/m²) + membrana de polímero acrílico com cimento e fibras para combater eflorescência (2,0 kg/m²) | K41: m2 | L41: =SUMIFS(IMPERMEABILIZAÇÃO!B$13:B$145,IMPERMEABILIZAÇÃO!D$13:D$145,IMPERMEABILIZAÇÃO!$U$12,IMPERMEABILIZAÇÃO!E$13:E$145,Ger_Executivo!$I$35) -> 59.81 | M41: 156 | N41: =IF(H41="Serviço",M41*L41,IF(H41="CÉLULA CONSTRUTIVA",SUMIFS($N$8:$N$262,$B$8:$B$262,B41,$H$8:$H$262,"Serviço"),IF(H41="ETAPA",SUMIFS($N$8:$N$262,$B$8:$B$262,B41,$C$8:$C$262,C41,$H$8:$H$262,"Serviço"),IF(H41="SUBETAPA",SUMIFS($N$8:$N$262,$B$8:$B$262,B41,$C$8:$C$262,C41,$D$8:$D$262,D41,$H$8:$H$262,"Serviço"),0)))) -> 9330.36
A42: =IF($H42="UNIDADE CONSTRUTIVA",OFFSET(A42,-1,0)+1,LARGE(A$3:A41,1)) -> 0 | B42: =IF(H42="UNIDADE CONSTRUTIVA",0,IF(H42="CÉLULA CONSTRUTIVA",OFFSET(B42,-1,0)+1,OFFSET(B42,-1,0))) -> 2 | C42: =IF(H42="CÉLULA CONSTRUTIVA",0,IF(H42="ETAPA",OFFSET(C42,-1,0)+1,OFFSET(C42,-1,0))) -> 1 | D42: =IF(H42="ETAPA",0,IF(H42="SUBETAPA",OFFSET(D42,-1,0)+1,OFFSET(D42,-1,0))) -> 3 | E42: =IF(H42="Subetapa",0,IF(H42="serviço",OFFSET(E42,-1,0)+1,OFFSET(E42,-1,0))) -> 7 | H42: SERVIÇO | I42: =IF(H42="Unidade Construtiva",TEXT(A42,"00"),IF(H42="Célula Construtiva",TEXT(B42,"00"),IF(H42="Etapa",CONCATENATE(TEXT(B42,"00"),".",TEXT(C42,"000")),IF(H42="Subetapa",CONCATENATE(TEXT(B42,"00"),".",TEXT(C42,"000"),".",TEXT(D42,"000")),IF(H42="Serviço",CONCATENATE(TEXT(B42,"00"),".",TEXT(C42,"000"),".",TEXT(D42,"000"),".",TEXT(E42,"000")),""))))) -> 02.001.003.007 | J42: I30 - Membrana acrílica, estruturada com tela de poliéster, nos pontos críticos (3,0 kg/m²) | K42: m2 | L42: =SUMIFS(IMPERMEABILIZAÇÃO!B$13:B$145,IMPERMEABILIZAÇÃO!D$13:D$145,IMPERMEABILIZAÇÃO!$U$11,IMPERMEABILIZAÇÃO!E$13:E$145,Ger_Executivo!$I$35) -> 1.92 | M42: 72 | N42: =IF(H42="Serviço",M42*L42,IF(H42="CÉLULA CONSTRUTIVA",SUMIFS($N$8:$N$262,$B$8:$B$262,B42,$H$8:$H$262,"Serviço"),IF(H42="ETAPA",SUMIFS($N$8:$N$262,$B$8:$B$262,B42,$C$8:$C$262,C42,$H$8:$H$262,"Serviço"),IF(H42="SUBETAPA",SUMIFS($N$8:$N$262,$B$8:$B$262,B42,$C$8:$C$262,C42,$D$8:$D$262,D42,$H$8:$H$262,"Serviço"),0)))) -> 138.24
A43: =IF($H43="UNIDADE CONSTRUTIVA",OFFSET(A43,-1,0)+1,LARGE(A$3:A42,1)) -> 0 | B43: =IF(H43="UNIDADE CONSTRUTIVA",0,IF(H43="CÉLULA CONSTRUTIVA",OFFSET(B43,-1,0)+1,OFFSET(B43,-1,0))) -> 2 | C43: =IF(H43="CÉLULA CONSTRUTIVA",0,IF(H43="ETAPA",OFFSET(C43,-1,0)+1,OFFSET(C43,-1,0))) -> 1 | D43: =IF(H43="ETAPA",0,IF(H43="SUBETAPA",OFFSET(D43,-1,0)+1,OFFSET(D43,-1,0))) -> 3 | E43: =IF(H43="Subetapa",0,IF(H43="serviço",OFFSET(E43,-1,0)+1,OFFSET(E43,-1,0))) -> 8 | H43: SERVIÇO | I43: =IF(H43="Unidade Construtiva",TEXT(A43,"00"),IF(H43="Célula Construtiva",TEXT(B43,"00"),IF(H43="Etapa",CONCATENATE(TEXT(B43,"00"),".",TEXT(C43,"000")),IF(H43="Subetapa",CONCATENATE(TEXT(B43,"00"),".",TEXT(C43,"000"),".",TEXT(D43,"000")),IF(H43="Serviço",CONCATENATE(TEXT(B43,"00"),".",TEXT(C43,"000"),".",TEXT(D43,"000"),".",TEXT(E43,"000")),""))))) -> 02.001.003.008 | J43: C4RQ - Argamassa polimérica rígida, com alta resistência química, estruturada com tela de poliéster nos pontos críticos (4,0 kg/m²) | K43: m2 | L43: =SUMIFS(IMPERMEABILIZAÇÃO!B$13:B$145,IMPERMEABILIZAÇÃO!D$13:D$145,IMPERMEABILIZAÇÃO!$U$10,IMPERMEABILIZAÇÃO!E$13:E$145,Ger_Executivo!$I$35) -> 47.53 | M43: 39.555556 | N43: =IF(H43="Serviço",M43*L43,IF(H43="CÉLULA CONSTRUTIVA",SUMIFS($N$8:$N$262,$B$8:$B$262,B43,$H$8:$H$262,"Serviço"),IF(H43="ETAPA",SUMIFS($N$8:$N$262,$B$8:$B$262,B43,$C$8:$C$262,C43,$H$8:$H$262,"Serviço"),IF(H43="SUBETAPA",SUMIFS($N$8:$N$262,$B$8:$B$262,B43,$C$8:$C$262,C43,$D$8:$D$262,D43,$H$8:$H$262,"Serviço"),0)))) -> 1880.0756
...

Sheet ARQUITETURA
A1: EMBASSAMENTO | B1: DADOS
A2: TORRE | B2: Titulo | C2: QUANTITATIVO
A3: ignorar | B3: Obra
B4: Cliente
B5: Cidade
B6: Endereço
B7: Descrição
B9: QUANTITATIVOS
B10: Item | C10: Descrição | D10: Unid. | E10: Quantidade | F10: OBSERVAÇÕES
B12: 1. | C12: Alvenaria de vedação com bocos de concreto | E12: =SUM(E14:E97) -> 4379.7 | H12: =SUM(H13:H18) -> 4379.7 | I12: =IF(H12=E12,"OKAY","REVER") -> OKAY | L12: =SUM(L13:L14) -> 0
A13: EMBASSAMENTO | B13: 1.1. | C13: 01_1º SUBSOLO 1 | G13: BLOCO DE CONCRETO 09 cm, | H13: =SUMIF($C:$C,G13,$E:$E) -> 208.45
A14: EMBASSAMENTO | B14: 1.1.1 | C14: BLOCO DE CONCRETO 14 cm, | D14: m² | E14: 130.61 | G14: BLOCO DE CONCRETO 14 cm, | H14: =SUMIF($C:$C,G14,$E:$E) -> 1643
A15: EMBASSAMENTO | B15: 1.1.2 | C15: BLOCO DE CONCRETO 19 cm, | D15: m² | E15: 143.39 | G15: BLOCO DE CONCRETO 19 cm, | H15: =SUMIF($C:$C,G15,$E:$E) -> 2528.25
A16: EMBASSAMENTO | B16: 1.2. | C16: 02_TÉRREO | H16: =SUMIF($C:$C,G16,$E:$E) -> 0
A17: EMBASSAMENTO | B17: 1.2.1 | C17: BLOCO DE CONCRETO 09 cm, | D17: m² | E17: 1.71 | H17: =SUMIF($C:$C,G17,$E:$E) -> 0
A18: EMBASSAMENTO | B18: 1.2.2 | C18: BLOCO DE CONCRETO 14 cm, | D18: m² | E18: 197.94 | H18: =SUMIF($C:$C,G18,$E:$E) -> 0
A19: EMBASSAMENTO | B19: 1.2.3 | C19: BLOCO DE CONCRETO 19 cm, | D19: m² | E19: 316.99 | J19: =SUM(J13:J18) -> 0
A20: TORRE | B20: 1.3. | C20: 03_1º PAVTO | G20: conferencia | H20: =H22+H30 -> 4379.7 | I20: =IF(H20=H12,"OKAY","REVER") -> OKAY
A21: TORRE | B21: 1.3.1 | C21: BLOCO DE CONCRETO 09 cm, | D21: m² | E21: 17.06
A22: TORRE | B22: 1.3.2 | C22: BLOCO DE CONCRETO 14 cm, | D22: m² | E22: 110.58 | G22: =$A$1 -> EMBASSAMENTO | H22: =SUM(H23:H28) -> 790.64
A23: TORRE | B23: 1.3.3 | C23: BLOCO DE CONCRETO 19 cm, | D23: m² | E23: 226.9 | G23: BLOCO DE CONCRETO 09 cm, | H23: =SUMIFS($E:$E,$C:$C,G23,$A:$A,$G$22) -> 1.71
A24: TORRE | B24: 1.4. | C24: 04_2º PAVTO | G24: BLOCO DE CONCRETO 14 cm, | H24: =SUMIFS($E:$E,$C:$C,G24,$A:$A,$G$22) -> 328.55
A25: TORRE | B25: 1.4.1 | C25: BLOCO DE CONCRETO 09 cm, | D25: m² | E25: 22.95 | G25: BLOCO DE CONCRETO 19 cm, | H25: =SUMIFS($E:$E,$C:$C,G25,$A:$A,$G$22) -> 460.38
A26: TORRE | B26: 1.4.2 | C26: BLOCO DE CONCRETO 14 cm, | D26: m² | E26: 106.04 | H26: =SUMIFS($E:$E,$C:$C,G26,$A:$A,$G$22) -> 0
A27: TORRE | B27: 1.4.3 | C27: BLOCO DE CONCRETO 19 cm, | D27: m² | E27: 159.89 | H27: =SUMIFS($E:$E,$C:$C,G27,$A:$A,$G$22) -> 0
A28: TORRE | B28: 1.5. | C28: 05_3º PAVTO | H28: =SUMIFS($E:$E,$C:$C,G28,$A:$A,$G$22) -> 0
A29: TORRE | B29: 1.5.1 | C29: BLOCO DE CONCRETO 09 cm, | D29: m² | E29: 13.49
A30: TORRE | B30: 1.5.2 | C30: BLOCO DE CONCRETO 14 cm, | D30: m² | E30: 79.5 | G30: =$A$2 -> TORRE | H30: =SUM(H31:H36) -> 3589.06
A31: TORRE | B31: 1.5.3 | C31: BLOCO DE CONCRETO 19 cm, | D31: m² | E31: 144.83 | G31: BLOCO DE CONCRETO 09 cm, | H31: =SUMIFS($E:$E,$C:$C,G31,$A:$A,$G$30) -> 206.74
A32: TORRE | B32: 1.6. | C32: 06_4º PAVTO | G32: BLOCO DE CONCRETO 14 cm, | H32: =SUMIFS($E:$E,$C:$C,G32,$A:$A,$G$30) -> 1314.45
A33: TORRE | B33: 1.6.1 | C33: BLOCO DE CONCRETO 09 cm, | D33: m² | E33: 5.4 | G33: BLOCO DE CONCRETO 19 cm, | H33: =SUMIFS($E:$E,$C:$C,G33,$A:$A,$G$30) -> 2067.87
A34: TORRE | B34: 1.6.2 | C34: BLOCO DE CONCRETO 14 cm, | D34: m² | E34: 84.52 | H34: =SUMIFS($E:$E,$C:$C,G34,$A:$A,$G$30) -> 0
A35: TORRE | B35: 1.6.3 | C35: BLOCO DE CONCRETO 19 cm, | D35: m² | E35: 88.67 | H35: =SUMIFS($E:$E,$C:$C,G35,$A:$A,$G$30) -> 0
A36: TORRE | B36: 1.7. | C36: 07_5º PAVTO | H36: =SUMIFS($E:$E,$C:$C,G36,$A:$A,$G$30) -> 0
A37: TORRE | B37: 1.7.1 | C37: BLOCO DE CONCRETO 09 cm, | D37: m² | E37: 12.06
A38: TORRE | B38: 1.7.2 | C38: BLOCO DE CONCRETO 14 cm, | D38: m² | E38: 80.25
A39: TORRE | B39: 1.7.3 | C39: BLOCO DE CONCRETO 19 cm, | D39: m² | E39: 91.11
A40: TORRE | B40: 1.8. | C40: 08_6º PAVTO
A41: TORRE | B41: 1.8.1 | C41: BLOCO DE CONCRETO 09 cm, | D41: m² | E41: 5.4
A42: TORRE | B42: 1.8.2 | C42: BLOCO DE CONCRETO 14 cm, | D42: m² | E42: 84.52
...

Sheet IMPERMEABILIZAÇÃO
B1: Projeto: | C1: ='Obra '!D1 -> Caio Prado
B2: Empresa: | C2: ='Obra '!D2 -> Indepy
B3: Revisão: | C3: ='Obra '!D3 -> R00 - Larissa | T3: EAP | U3: TIPO
A4: IMPERMEABILIZAÇÃO | T4: {=_xlfn.UNIQUE(_xlfn._xlws.FILTER(E13:E145,E13:E145<>""))} -> 02.001.005 | U4: {=_xlfn.UNIQUE(_xlfn._xlws.FILTER(D13:D145,D13:D145<>""))} -> E3 | V4: Membrana de polímero acrílico com cimento e fibras, estruturada com tela de poliéster nos pontos críticos (3,0 kg/m²) | W4: =U4&" - "&V4 -> E3 - Membrana de polímero acrílico com cimento e fibras, estruturada com tela de poliéster nos pontos críticos (3,0 kg/m²)
B5: REGULARIZAÇÃO | C5: PROTEÇÃO | D5: =U4 -> E3 | E5: =U5 -> I30EL | F5: =U6 -> M44A | G5: =U7 -> C3 | H5: =U8 -> C3E3 | I5: =U9 -> C4 | J5: =U10 -> C4RQ | K5: =U11 -> I30 | L5: =U12 -> M44AE2 | M5: =U13 -> E2 | N5: =U14 -> M44AR05 | O5: =U15 -> M44A + M44AE2 | T5: 02.001.003 | U5: I30EL | V5: Membrana de polímero acrílico, sem cimento (3,0 kg/m²), com resistência à alcalinidade, estruturada com tela de poliéster nos pontos críticos – Ref.: Sika Baucryl, MC DF9, Icopor HP, Procryl Imper | W5: =U5&" - "&V5 -> I30EL - Membrana de polímero acrílico, sem cimento (3,0 kg/m²), com resistência à alcalinidade, estruturada com tela de poliéster nos pontos críticos – Ref.: Sika Baucryl, MC DF9, Icopor HP, Procryl Imper
B6: m2 | C6: m2 | D6: m2 | E6: m2 | F6: m2 | G6: m2 | H6: m2 | I6: m2 | J6: m2 | K6: m2 | L6: m2 | M6: m2 | N6: m2 | O6: m2 | T6: 06.001.006 | U6: M44A | V6: Manta asfáltica tipo IV, 4 mm A, com acabamento areia/areia aderida com asfalto oxidado (3,0 kg/m²) + banho de asfalto oxidado (2,0 kg/m²) | W6: =U6&" - "&V6 -> M44A - Manta asfáltica tipo IV, 4 mm A, com acabamento areia/areia aderida com asfalto oxidado (3,0 kg/m²) + banho de asfalto oxidado (2,0 kg/m²)
