Workbook
Name \0: #REF!
Name \1: #REF!
Name \a: #REF!
Name \b: #REF!
Name \c: #REF!
Name \d: #REF!
Name \e: #REF!
Name \i: #REF!
Name \J: #REF!
Name \k: #REF!
Name \l: #N/A
Name \m: #REF!
Name \o: #REF!
Name \p: #REF!
Name \r: #REF!
Name \T: #REF!
Name \z: #REF!
Name _: #REF!
Name _\0: #REF!
Name _\1: #REF!
Name _\a: #REF!
Name _\b: #REF!
Name _\c: #REF!
Name _\d: #REF!
Name _\e: #REF!
Name _\i: #REF!
Name _\J: #REF!
Name _\k: #REF!
Name _\l: #N/A
Name _\m: #REF!
Name _\o: #REF!
Name _\p: #REF!
Name _\r: #REF!
Name _\T: #REF!
Name _\z: #REF!
Name __: #REF!
Name ______ACR10: #REF!
Name ______ACR15: #REF!
Name ______acr20: #REF!
Name ______acr5: #REF!
Name ______ARQ1: #REF!
Name ______QT100: #REF!
Name ______QT2: #REF!
Name ______QT3: #REF!
Name ______QT4: #REF!
Name ______QT50: #REF!
Name ______QT75: #REF!
Name _____ACR10: #REF!
Name _____ACR15: #REF!
Name _____acr20: #REF!
Name _____acr5: #REF!
Name _____ARQ1: #REF!
Name _____key2: #REF!
Name _____QT100: #REF!
Name _____QT2: #REF!
Name _____QT3: #REF!
Name _____QT4: #REF!
Name _____QT50: #REF!
Name _____QT75: #REF!
Name ____key2: #REF!

Sheet CAPA
A1: DADOS DO EMPREENDIMENTO
B2: Projeto: | C2: Electra Towers | E2: ENDEREÇO DA OBRA: | F2: Rua 254, 215, Meia Praia, Itapema/SC
B3: Empresa: | C3: Thozen Empreendimentos | E3: Cidade/ES: | F3: Itapema, SC
B4: Revisão: | C4: R00 | E4: CNPJ: | F4: 43.339.082/0001-06
B6: Pazo de Obra: | C6: 48 | E6: Nº Unid. Residenciais: | F6: 192 | I6: Imagens
B8: Área do Terreno: | C8: 2095.43 | E8: Nº Unid. Comerciais: | F8: 7
B10: Área Construída: | C10: 37893.89 | E10: Nº Pavimentos: | F10: 57
B12: Área Privativa: | C12: 22778.64 | E12: Total de Dormitórios: | F12: 576
B14: Área de Lazer: | C14: 1736.27 | E14: Nº Subsolos: | F14: 0
B16: Área Comercial: | C16: 500.04 | E16: Nº Vagas: | F16: 399
B18: Torre | C18: Pavimento | D18: Área | E18: Área Privativa | F18: Perímetro | G18: Pé direito
B19: Embasamento | C19: Térreo | D19: 1565.91 | E19: 0 | G19: 4.3
B20: Embasamento | C20: Garagem 01 | D20: 1736.27 | E20: 0
B21: Embasamento | C21: Garagem 02 | D21: 1736.27 | E21: 0
B22: Embasamento | C22: Garagem 03 | D22: 1736.27 | E22: 0
B23: Embasamento | C23: Garagem 04 | D23: 1736.27 | E23: 0
B24: Embasamento | C24: Garagem 05 | D24: 1736.27 | E24: 0
B25: Embasamento | C25: Pavimento diferenciado — Lazer | D25: 1736.27 | E25: 0 | G25: 3.6
B26: Torre A | C26: Pavimento tipo — Torre A (×24) | D26: 12720.48 | E26: 11382.72 | G26: 3.24
B27: Torre B | C27: Pavimento tipo — Torre B (×24) | D27: 12892.32 | E27: 11397.12 | G27: 3.24
B28: Cobertura | C28: Casa de Máquinas | D28: 176.26 | E28: 0
B29: Cobertura | C29: Reservatórios | D29: 121.3 | E29: 0
B37: Torre | C37: Pavimento | D37: Descrição | E37: Área | I37: ETAPA
B38: Áreas Comuns | C38: =_xlfn.XLOOKUP(D38,MOBILIÁRIO!C:C,MOBILIÁRIO!B:B) -> TÉRREO | D38: {=_xlfn.UNIQUE(_xlfn._xlws.FILTER(MOBILIÁRIO!C7:C316,MOBILIÁRIO!C7:C316<>""))} -> Hall Externo | E38: =_xlfn.XLOOKUP(D38,MOBILIÁRIO!C:C,MOBILIÁRIO!F:F) -> 12.33 | I38: GERENCIAMENTO TÉCNICO E ADMINISTRATIVO
B39: Áreas Comuns | C39: =_xlfn.XLOOKUP(D39,MOBILIÁRIO!C:C,MOBILIÁRIO!B:B) -> TÉRREO | D39: Hall Térreo | E39: =_xlfn.XLOOKUP(D39,MOBILIÁRIO!C:C,MOBILIÁRIO!F:F) -> 35.27 | I39: MOVIMENTAÇÃO DE TERRA
B40: Áreas Comuns | C40: =_xlfn.XLOOKUP(D40,MOBILIÁRIO!C:C,MOBILIÁRIO!B:B) -> TÉRREO | D40: Guarita | E40: =_xlfn.XLOOKUP(D40,MOBILIÁRIO!C:C,MOBILIÁRIO!F:F) -> 4.72 | I40: CONTENÇÃO
B41: Áreas Comuns | C41: =_xlfn.XLOOKUP(D41,MOBILIÁRIO!C:C,MOBILIÁRIO!B:B) -> TÉRREO | D41: Lavapés | E41: =_xlfn.XLOOKUP(D41,MOBILIÁRIO!C:C,MOBILIÁRIO!F:F) -> 1 | I41: INFRAESTRUTURA
B42: Áreas Comuns | C42: =_xlfn.XLOOKUP(D42,MOBILIÁRIO!C:C,MOBILIÁRIO!B:B) -> TÉRREO | D42: Lavabo Pne - Térreo | E42: =_xlfn.XLOOKUP(D42,MOBILIÁRIO!C:C,MOBILIÁRIO!F:F) -> 3.77 | I42: SUPRAESTRUTURA
B43: Áreas Comuns | C43: =_xlfn.XLOOKUP(D43,MOBILIÁRIO!C:C,MOBILIÁRIO!B:B) -> TÉRREO | D43: Bicicletário/Box | E43: =_xlfn.XLOOKUP(D43,MOBILIÁRIO!C:C,MOBILIÁRIO!F:F) -> 87.33 | I43: ALVENARIAS E VEDAÇÕES
B44: Áreas Comuns | C44: =_xlfn.XLOOKUP(D44,MOBILIÁRIO!C:C,MOBILIÁRIO!B:B) -> TÉRREO | D44: Antecâmara - Térreo | E44: =_xlfn.XLOOKUP(D44,MOBILIÁRIO!C:C,MOBILIÁRIO!F:F) -> 8.07 | I44: SISTEMAS E INSTALAÇÕES ELÉTRICAS
B45: Áreas Comuns | C45: =_xlfn.XLOOKUP(D45,MOBILIÁRIO!C:C,MOBILIÁRIO!B:B) -> 2º AO 5º PAVIMENTO - GARAGENS (X5) | D45: Antecâmara - Garagens (x5) | E45: =_xlfn.XLOOKUP(D45,MOBILIÁRIO!C:C,MOBILIÁRIO!F:F) -> 33.6 | I45: SISTEMAS E INSTALAÇÕES HIDROSSANITÁRIAS E DRENAGEM
B46: Áreas Comuns | C46: =_xlfn.XLOOKUP(D46,MOBILIÁRIO!C:C,MOBILIÁRIO!B:B) -> 4º PAVIMENTO - LAZER/GARAGENS | D46: Sala de massagem | E46: =_xlfn.XLOOKUP(D46,MOBILIÁRIO!C:C,MOBILIÁRIO!F:F) -> 7.47 | I46: INSTALAÇÕES PREVENTIVAS
B47: Áreas Comuns | C47: =_xlfn.XLOOKUP(D47,MOBILIÁRIO!C:C,MOBILIÁRIO!B:B) -> 4º PAVIMENTO - LAZER/GARAGENS | D47: Banheiro - Lazer/Garagem | E47: =_xlfn.XLOOKUP(D47,MOBILIÁRIO!C:C,MOBILIÁRIO!F:F) -> 3.91 | I47: INSTALAÇÕES DE GÁS
B48: Áreas Comuns | C48: =_xlfn.XLOOKUP(D48,MOBILIÁRIO!C:C,MOBILIÁRIO!B:B) -> 4º PAVIMENTO - LAZER/GARAGENS | D48: Lavabo - Lazer/Garagem | E48: =_xlfn.XLOOKUP(D48,MOBILIÁRIO!C:C,MOBILIÁRIO!F:F) -> 2.61 | I48: EQUIPAMENTOS E SISTEMAS ESPECIAIS
B49: Áreas Comuns | C49: =_xlfn.XLOOKUP(D49,MOBILIÁRIO!C:C,MOBILIÁRIO!B:B) -> 4º PAVIMENTO - LAZER/GARAGENS | D49: Lavabo Pne - Lazer/Garagem | E49: =_xlfn.XLOOKUP(D49,MOBILIÁRIO!C:C,MOBILIÁRIO!F:F) -> 4.33 | I49: CLIMATIZAÇÃO, EXAUSTÃO MECÂNICA
B50: Áreas Comuns | C50: =_xlfn.XLOOKUP(D50,MOBILIÁRIO!C:C,MOBILIÁRIO!B:B) -> 4º PAVIMENTO - LAZER/GARAGENS | D50: Circulação - Lazer/garagem | E50: =_xlfn.XLOOKUP(D50,MOBILIÁRIO!C:C,MOBILIÁRIO!F:F) -> 30.85 | I50: INSTALAÇÕES ESPECIAIS
... B63: Áreas Comuns | C63: =_xlfn.XLOOKUP(D63,MOBILIÁRIO!C:C,MOBILIÁRIO!B:B) -> 5º PAVIMENTO - LAZER | D63: Laje Verde | E63: =_xlfn.XLOOKUP(D63,MOBILIÁRIO!C:C,MOBILIÁRIO!F:F) -> 269.95 | I63: CUB/SC
B64: Áreas Comuns | C64: =_xlfn.XLOOKUP(D64,MOBILIÁRIO!C:C,MOBILIÁRIO!B:B) -> 5º PAVIMENTO - LAZER | D64: Brinquedoteca | E64: =_xlfn.XLOOKUP(D64,MOBILIÁRIO!C:C,MOBILIÁRIO!F:F) -> 16.32
B65: Áreas Comuns | C65: =_xlfn.XLOOKUP(D65,MOBILIÁRIO!C:C,MOBILIÁRIO!B:B) -> 5º PAVIMENTO - LAZER | D65: Game Center | E65: =_xlfn.XLOOKUP(D65,MOBILIÁRIO!C:C,MOBILIÁRIO!F:F) -> 13.09 | I65: DESCRIÇÃO
B66: Áreas Comuns | C66: =_xlfn.XLOOKUP(D66,MOBILIÁRIO!C:C,MOBILIÁRIO!B:B) -> 5º PAVIMENTO - LAZER | D66: Sala de Festas | E66: =_xlfn.XLOOKUP(D66,MOBILIÁRIO!C:C,MOBILIÁRIO!F:F) -> 93.46 | I66: VALOR POR ÁREA PRIVATIVA (R$/m²)
...

Sheet EAP
A1: EAP DE ORÇAMENTO
A3: Contrutora - Obra
A5: UNIDADE CONSTRUTIVA | B5: 1 | C5: GERENCIAMENTO TÉCNICO E ADMINISTRATIVO
A6: CÉLULA CONSTRUTIVA | B6: 1 | C6: SERVIÇOS TÉCNICOS
A7: ETAPA | B7: 1.001 | C7: ESTUDOS, PROJETOS E CONSULTORIAS
A8: Subetapa | B8: 01.001.001 | C8: Estudos
A9: Subetapa | B9: 01.001.002 | C9: Projetos
A10: Subetapa | B10: 01.001.003 | C10: Consultorias
A11: Subetapa | B11: 01.001.004 | C11: Ensaios
A12: ETAPA | B12: 1.002 | C12: TAXAS E DOCUMENTOS
A13: Subetapa | B13: 01.002.001 | C13: Licenciamentos, Taxas, Impostos, Aprovações e Seguros
A14: Subetapa | B14: 01.002.002 | C14: Documentos
A15: CÉLULA CONSTRUTIVA | B15: 2 | C15: SERVIÇOS INICIAIS
A16: ETAPA | B16: 2.001 | C16: SEGURANÇA, MEIO AMBIENTE, SAÚDE
A17: Subetapa | B17: 02.001.001 | C17: Segurança do trabalho
A18: Subetapa | B18: 02.001.002 | C18: Equipamentos de proteção
A19: Subetapa | B19: 02.001.003 | C19: Meio ambiente
A20: Subetapa | B20: 02.001.004 | C20: Saúde ocupacional
A21: ETAPA | B21: 2.002 | C21: ADMINISTRAÇÃO E CANTEIRO DE OBRA
A22: Subetapa | B22: 02.002.001 | C22: Equipe de Gestão e Apoio
A23: Subetapa | B23: 02.002.002 | C23: Operação inicial de canteiro
A24: Subetapa | B24: 02.002.003 | C24: Despesas de consumo e manutenção
A25: Subetapa | B25: 02.002.004 | C25: Instalações provisórias
A26: Subetapa | B26: 02.002.005 | C26: Ligações Provisórias
A27: ETAPA | B27: 2.003 | C27: SERVIÇOS PRELIMINARES
... A29: Subetapa | B29: 02.003.002 | C29: Limpeza de terreno
A30: CÉLULA CONSTRUTIVA | B30: 3 | C30: EQUIPAMENTOS
A31: ETAPA | B31: 3.001 | C31: EQUIPAMENTOS
A32: Subetapa | B32: 03.001.001 | C32: Equipamentos de Carga e Transporte
A33: Subetapa | B33: 03.001.002 | C33: Equipamentos de obra
A34: Subetapa | B34: 03.001.003 | C34: Balancins e Andaimes
A35: UNIDADE CONSTRUTIVA | B35: 2 | C35: GERENCIAMENTO EXECUTIVO
A36: CÉLULA CONSTRUTIVA | B36: 1 | C36: INFRAESTRUTURA
A37: ETAPA | B37: 1.001 | C37: MOVIMENTAÇÃO DE TERRA
A38: Subetapa | B38: 01.001.001 | C38: Corte e aterro
A39: Subetapa | B39: 01.001.002 | C39: Rebaixamento de lençol
A40: Subetapa | B40: 01.001.003 | C40: Escavação e Reaterro de Valas
A41: Subetapa | B41: 01.001.004 | C41: Lastro de estrutura de concreto
A42: Subetapa | B42: 01.001.005 | C42: Movimentação de bota - fora
A43: ETAPA | B43: 1.002 | C43: FUNDAÇÃO PROFUNDA
...

Sheet Resumo Estrutura
B1: Projeto: | C1: =CAPA!$C$2 -> Elizabeth II Royal Home
B2: Empresa: | C2: =CAPA!$C$3 -> Gessele
B3: Revisão: | C3: R00
A4: Item | B4: Disciplina | C4: EAP - Arquitetura | D4: Pavimento Proj. Estrutural | E4: Etapa | F4: Projetos | G4: Área Pavimento | H4: Mpa | I4: Concreto | J4: Forma Convencional | K4: Forma Convencional Fabricação | L4: Cubeta inteira | M4: Meia Cubeta | N4: Aço | O4: Ø5.0mm 0,154 kg/m | P4: Ø6.3mm 0,245 kg/m | Q4: Ø8.0mm 0,395 kg/m | R4: Ø10.0mm 0,617 kg/m | S4: Ø12.5mm 0,963 kg/m | T4: Ø16.0mm 1,578 kg/m | U4: Ø20.0mm 2,466 kg/m | V4: Ø25.0mm 3,853 kg/m | W4: Ø32.0mm 6,313 kg/m
A5: Torre | Q5: =Q81/SUM($O$81:$W$81) -> 0.069768384 | R5: =R81/SUM($O$81:$W$81) -> 0.079324587 | S5: =S81/SUM($O$81:$W$81) -> 0.089771623 | T5: =T81/SUM($O$81:$W$81) -> 0.030085844 | U5: =U81/SUM($O$81:$W$81) -> 0.11503887 | V5: =V81/SUM($O$81:$W$81) -> 0.54725462 | W5: =W81/SUM($O$81:$W$81) -> 0
A6: =A5 -> Torre | B6: Fundação | C6: Contenções | D6: Contenções | E6: Mureta guia | F6: PR-1248-00-CON-FO-01-R00 | H6: 50 | I6: ='Fund. Rasa | Contenção'!AG84 -> 11.390452 | J6: ='Fund. Rasa | Contenção'!AD84 -> 222.6272 | N6: =SUM(O6:W6) -> 711.9216 | P6: =(30*48+(1.02+1.07+0.07+0.02+0.07+0.17+0.12+0.07+0.02+0.07)*48*2/0.2)*0.245 -> 670.32 | S6: =0.45*48*2*0.963 -> 41.6016
A7: =A5 -> Torre | B7: Fundação | C7: Contenções | D7: Contenções | E7: Parede de Diafragma | H7: 50 | I7: 210 | J7: 1050 | N7: =SUM(O7:W7) -> 18250 | P7: 2282 | Q7: 77 | S7: 3884 | V7: 12007
A8: =A7 -> Torre | B8: Fundação | C8: Contenções | D8: Contenções | E8: Estroncas | F8: PR-1248-00-CON-FO-01-R00 | H8: 50 | I8: 8.4 | J8: 37.2 | N8: =SUM(O8:W8) -> 608.81818 | Q8: =(62+84.7)/1.1 -> 133.36364 | S8: =49.9/1.1 -> 45.363636 | U8: =473.1/1.1 -> 430.09091
A9: =A7 -> Torre | B9: Fundação | C9: Contenções | D9: Contenções | E9: Viga Coroamento | F9: PR-1248-00-CON-VI-01-R01 | H9: 50 | I9: 9.4 | J9: 45.6 | N9: =SUM(O9:W9) -> 2057.2727 | Q9: =858/1.1 -> 780 | T9: =1405/1.1 -> 1277.2727
D10: TOTAL - CONTENÇÃO | I10: =SUM(I7:I9) -> 227.8 | J10: =SUM(J7:J9) -> 1132.8 | K10: =SUM(K7:K9) -> 0 | L10: =SUM(L7:L9) -> 0 | M10: =SUM(M7:M9) -> 0 | N10: =SUM(N7:N9) -> 20916.091 | O10: =SUM(O7:O9) -> 0 | P10: =SUM(P7:P9) -> 2282 | ... W10: =SUM(W7:W9) -> 0
A11: =A5 -> Torre | B11: Fundação | C11: Fundação - Estacas | D11: Fundação | E11: Estacas | H11: 50 | I11: =Estacas!K7 -> 83.448555 | P11: =Estacas!M7 -> 6175 | U11: =Estacas!N7 -> 41456
D12: TOTAL - FUNDAÇÃO ESTACA | I12: =SUM(I11) -> 83.448555 | J12: =SUM(J11) -> 0 | K12: =SUM(K11) -> 0 | L12: =SUM(L11) -> 0 | M12: =SUM(M11) -> 0 | N12: =SUM(N11) -> 0 | O12: =SUM(O11) -> 0 | P12: =SUM(P11) -> 6175 | ... W12: =SUM(W11) -> 0
A13: =A5 -> Torre | B13: Fundação | C13: Fundação - Blocos | D13: Fundação | E13: Blocos | F13: PR-1248-00-FUN-AR-01-R01 | H13: 50 | I13: 658.5 | J13: 524.5 | N13: =SUM(O13:W13) -> 69835.455 | S13: =581/1.1 -> 528.18182 | T13: =8065/1.1 -> 7331.8182 | U13: =1450/1.1 -> 1318.1818 | V13: =66723/1.1 -> 60657.273
D14: TOTAL - FUNDAÇÃO BLOCOS | I14: =SUM(I13) -> 658.5 | J14: =SUM(J13) -> 524.5 | K14: =SUM(K13) -> 0 | L14: =SUM(L13) -> 0 | M14: =SUM(M13) -> 0 | N14: =SUM(N13) -> 69835.455 | O14: =SUM(O13) -> 0 | P14: =SUM(P13) -> 0 | ... W14: =SUM(W13) -> 0
A15: =A5 -> Torre | B15: Fundação | C15: Fundação - Vigas etc. | D15: Fundação | E15: Pilares | F15: PR-1248-00-FUN-AR-01-R01 | H15: 50 | I15: 18.7 | J15: 122.9 | N15: =SUM(O15:W15) -> 44086 | O15: =31 -> 31 | P15: =97+14+12 -> 123 | Q15: =83+15+1 -> 99 | R15: =4397+153+1118 -> 5668 | S15: =4398+60+195 -> 4653 | T15: =484+130 -> 614 | U15: =902 -> 902 | V15: =3332+1348 -> 4680 | W15: =27316 -> 27316
A16: =A5 -> Torre | B16: Fundação | C16: Fundação - Vigas etc. | D16: Fundação | E16: Vigas | H16: 50
A17: =A16 -> Torre | B17: Fundação | C17: Fundação - Vigas etc. | D17: Fundação | E17: Laje p/ equipamentos | F17: PR-1248-00-FUN-LA-01-R01 | H17: 50 | I17: =1.4*(1.19*2.325)+0.3*(4.2*4.2) -> 9.16545 | J17: =4.2*4*0.3+(1.19*2+2.325*2)*1.4 -> 14.882 | N17: =SUM(O17:W17) -> 829.90909 | S17: =(191.8+551.8)/1.1 -> 676 | T17: =169.3/1.1 -> 153.90909
A18: =A5 -> Torre | B18: Fundação | C18: Fundação - Vigas etc. | D18: Fundação | E18: Contrapiso | H18: 50 | N18: =SUM(O18:W18) -> 17 | O18: =11 -> 11 | R18: =6 -> 6
A19: =A5 -> Torre | B19: Fundação | C19: Fundação - Vigas etc. | D19: Fundação | E19: Cisternas | F19: PR-1248-01-CIS-FO-01-R02 | H19: 50 | I19: ='Cálculo de apoio'!D8 -> 23.18176 | J19: ='Cálculo de apoio'!E6 -> 28.95 | N19: =SUM(O19:W19) -> 3419.1818 | O19: ='Cálculo de apoio'!J8 -> 10 | P19: ='Cálculo de apoio'!K8 -> 7.2727273 | Q19: ='Cálculo de apoio'!L8 -> 883.63636 | R19: ='Cálculo de apoio'!M8 -> 1337.6364 | S19: ='Cálculo de apoio'!N8 -> 678.81818 | T19: ='Cálculo de apoio'!O8 -> 501.81818 | U19: ='Cálculo de apoio'!P8 -> 0 | V19: ='Cálculo de apoio'!Q8 -> 0
A20: =A5 -> Torre | B20: Fundação | C20: Fundação - Vigas etc. | D20: Fundação | E20: Dutos | H20: 50 | N20: =SUM(O20:W20) -> 0
C21: TOTAL - VIGAS BALDRAMES/PILARES DE ARRANQUE/CISTERNAS E DUTOS | I21: =SUM(I15:I20) -> 51.04721 | J21: =SUM(J15:J20) -> 166.732 | K21: =SUM(K15:K20) -> 0 | L21: =SUM(L15:L20) -> 0 | M21: =SUM(M15:M20) -> 0 | N21: =SUM(N15:N20) -> 48352.091 | O21: =SUM(O15:O20) -> 52 | P21: =SUM(P15:P20) -> 130.27273 | ... W21: =SUM(W15:W20) -> 27316
A22: =A20 -> Torre | B22: Supraestrutura | C22: Térreo | D22: Térreo | E22: Pilares | H22: 50 | K22: =J28*3 -> 1733.4 | N22: =SUM(O22:W22) -> 0
A23: =A22 -> Torre | B23: Supraestrutura | C23: Térreo | D23: Térreo | E23: Vigas | H23: 50 | I23: 106.6 | J23: 582.1 | K23: =J23*3 -> 1746.3 | N23: =SUM(O23:W23) -> 17598 | P23: 1364 | Q23: 1169 | R23: 2046 | S23: 1225 | T23: 1240 | U23: 3719 | V23: 6835
A24: =A23 -> Torre | B24: Supraestrutura | C24: Térreo | D24: Térreo | E24: Lajes | H24: 50 | I24: 97 | K24: =J30*3 -> 1261.185 | N24: =SUM(O24:W24) -> 4886.3636 | P24: =777.2/1.1+909.4/1.1+1201.9/1.1+1189.3/1.1 -> 3707.0909 | Q24: =673.2/1.1+292.6/1.1+267.4/1.1+64/1.1 -> 1179.2727
A25: =A24 -> Torre | B25: Supraestrutura | C25: Térreo | D25: Térreo | E25: Capiteis | H25: 50 | N25: =SUM(O25:W25) -> 0
A26: =A25 -> Torre | B26: Supraestrutura | C26: Térreo | D26: Térreo | E26: Lajes | H26: 50 | I26: 4.8 | J26: =(0.5816+0.5128+(3.01+2.65)*1.2+3.1+3.2*1.2)/1.6*4.8 -> 44.4792 | K26: =J32*3 -> 133.4376 | N26: =SUM(O26:W26) -> 302.54545 | P26: =10/1.1 -> 9.0909091 | Q26: 9 | R26: =55/1.1+36/1.1+25/1.1 -> 105.45455 | S26: 145 | T26: 34
D27: ="TOTAL - "&UPPER(C26) -> TOTAL - TÉRREO | I27: =SUM(I22:I26) -> 208.4 | J27: =SUM(J22:J26) -> 626.5792 | K27: =SUM(K22:K26) -> 4874.3226 | L27: =SUM(L22:L26) -> 0 | M27: =SUM(M22:M26) -> 0 | N27: =SUM(N22:N26) -> 22786.909 | O27: =SUM(O22:O26) -> 0 | P27: =SUM(P22:P26) -> 5080.1818 | ... W27: =SUM(W22:W26) -> 0
A28: =A5 -> Torre | B28: Supraestrutura | C28: Mezanino G1 | D28: Garagem G1 | E28: Pilares | H28: 50 | I28: 101.9 | J28: 577.8 | N28: =SUM(O28:W28) -> 45075 | P28: 311 | Q28: 278 | R28: 6542 | S28: 8103 | T28: 760 | U28: 629 | V28: 7983 | W28: 20469
A29: =A5 -> Torre | B29: Supraestrutura | C29: Mezanino G1 | D29: Garagem G1 | E29: Vigas | H29: 50 | I29: 37 | J29: 329.6 | N29: =SUM(O29:W29) -> 7215 | O29: 5 | P29: 449 | Q29: 632 | R29: 246 | S29: 964 | T29: 1526 | U29: 1632 | V29: 1761
A30: =A5 -> Torre | B30: Supraestrutura | C30: Mezanino G1 | D30: Garagem G1 | E30: Lajes | H30: 50 | I30: 101.3 | J30: =I30*4.15 -> 420.395 | N30: =SUM(O30:W30) -> 6276 | P30: 275 | Q30: 4210 | R30: 1216 | S30: 247 | T30: 328
A31: =A7 -> Torre | B31: Supraestrutura | C31: Mezanino G1 | D31: Garagem G1 | E31: Capiteis | H31: 50 | N31: =SUM(O31:W31) -> 580.90909 | P31: =7/1.1 -> 6.3636364 | Q31: =8/1.1 -> 7.2727273 | S31: =263/1.1 -> 239.09091 | T31: =361/1.1 -> 328.18182
A32: =A5 -> Torre | B32: Supraestrutura | C32: Mezanino G1 | D32: Garagem G1 | E32: Escadas | H32: 50 | I32: 4.8 | J32: =(0.5816+0.5128+(3.01+2.65)*1.2+3.1+3.2*1.2)/1.6*4.8 -> 44.4792 | N32: =SUM(O32:W32) -> 302.54545 | P32: =10/1.1 -> 9.0909091 | Q32: 9 | R32: =55/1.1+36/1.1+25/1.1 -> 105.45455 | S32: 145 | T32: 34
D33: ="TOTAL - "&UPPER(C32) -> TOTAL - MEZANINO G1 | I33: =SUM(I28:I32) -> 245 | J33: =SUM(J28:J32) -> 1372.2742 | K33: =SUM(K28:K32) -> 0 | L33: =SUM(L28:L32) -> 0 | M33: =SUM(M28:M32) -> 0 | N33: =SUM(N28:N32) -> 59449.455 | O33: =SUM(O28:O32) -> 5 | P33: =SUM(P28:P32) -> 1050.4545 | ... W33: =SUM(W28:W32) -> 20469
A34: =A5 -> Torre | B34: Supraestrutura | C34: G2 | D34: Garagem G2 | E34: Pilares | H34: 50 | I34: 73.8 | J34: 477.3 | N34: =SUM(O34:W34) -> 28668 | P34: 318 | Q34: 265 | R34: 3264 | S34: 4826 | T34: 604 | U34: 353 | V34: 5463 | W34: 13575
A35: =A5 -> Torre | B35: Supraestrutura | C35: G2 | D35: Garagem G2 | E35: Vigas | H35: 50 | I35: 31.8 | J35: 303.1 | N35: =SUM(O35:W35) -> 6621 | O35: 1 | P35: 500 | Q35: 693 | R35: 188 | S35: 866 | T35: 1890 | U35: 1043 | V35: 1440
A36: =A5 -> Torre | B36: Supraestrutura | C36: G2 | D36: Garagem G2 | E36: Lajes | H36: 50 | I36: 174.5 | J36: =I36*4.15 -> 724.175 | N36: =SUM(O36:W36) -> 11527 | P36: 705 | Q36: 7045 | R36: 3087 | S36: 63 | T36: 627
A37: =A7 -> Torre | B37: Supraestrutura | C37: G2 | D37: Garagem G2 | E37: Capiteis | H37: 50 | N37: =SUM(O37:W37) -> 1879.0909 | P37: =31/1.1 -> 28.181818 | Q37: =40/1.1 -> 36.363636 | R37: =333/1.1 -> 302.72727 | S37: =236/1.1 -> 214.54545 | T37: =1427/1.1 -> 1297.2727
A38: =A5 -> Torre | B38: Supraestrutura | C38: G2 | D38: Garagem G2 | E38: Escadas | H38: 50 | I38: 1.6 | J38: =(0.5816+0.5128+(3.01+2.65)*1.2+3.1+3.2*1.2)*1 -> 14.8264 | N38: =SUM(O38:W38) -> 106 | P38: 20 | Q38: 14 | R38: 72
D39: ="TOTAL - "&UPPER(C38) -> TOTAL - G2 | I39: =SUM(I34:I38) -> 281.7 | J39: =SUM(J34:J38) -> 1519.4014 | K39: =SUM(K34:K38) -> 0 | L39: =SUM(L34:L38) -> 0 | M39: =SUM(M34:M38) -> 0 | N39: =SUM(N34:N38) -> 48801.091 | O39: =SUM(O34:O38) -> 1 | P39: =SUM(P34:P38) -> 1571.1818 | ... W39: =SUM(W34:W38) -> 13575
A40: =A5 -> Torre | B40: Supraestrutura | C40: Mezanino G2 | D40: Garagem G3 | E40: Pilares | H40: 50 | I40: 79 | J40: 506.1 | N40: =SUM(O40:W40) -> 15968.154 | O40: =O$5*$N40 -> 89.875825 | P40: =P$5*$N40 -> 1008.0317 | Q40: =Q$5*$N40 -> 1114.0723 | R40: =R$5*$N40 -> 1266.6672 | S40: =S$5*$N40 -> 1433.4871 | T40: =T$5*$N40 -> 480.41538 | U40: =U$5*$N40 -> 1836.9584 | V40: =V$5*$N40 -> 8738.6458 | W40: =W$5*$N40 -> 0
...

Sheet Cálculo de apoio
E1: FUNDAÇÃO
A2: Pavimento | B2: Etapa | C2: Projeto | D2: Concreto | E2: Forma Convencional | F2: Forma Nervurada | G2: Cubeta inteira | H2: Meia Cubeta | I2: Total Aço kg | J2: Ø5.0mm 0,154 kg/m | K2: Ø6.3mm 0,245 kg/m | L2: Ø8.0mm 0,395 kg/m | M2: Ø10.0mm 0,617 kg/m | N2: Ø12.5mm 0,963 kg/m | O2: Ø16.0mm 1,578 kg/m | P2: Ø20.0mm 2,466 kg/m | Q2: Ø25.0mm 3,853 kg/m
A3: Fundação | B3: Vigas | C3: PR-1248-01-CIS-VI-01-R01 | D3: 12.7 | E3: 138.9 | I3: =SUM(J3:Q3) -> 2452.7273 | L3: =459/1.1 -> 417.27273 | M3: =1217/1.1 -> 1106.3636 | N3: =470/1.1 -> 427.27273 | O3: =552/1.1 -> 501.81818
A4: Fundação | B4: Pilares | C4: PR-1248-01-CIS-PI-01-R00 | D4: 0.7 | E4: 8.3 | I4: =SUM(J4:Q4) -> 177.27273 | K4: =8/1.1 -> 7.2727273 | L4: =49/1.1 -> 44.545455 | M4: =138/1.1 -> 125.45455
A5: Fundação | B5: Laje de fundo | C5: PR-1248-01-CIS-LA-01-R01 | D5: ='Fund. Rasa | Contenção'!AG75 -> 4.7376 | E5: ='Fund. Rasa | Contenção'!AD75 -> 0 | I5: =SUM(J5:Q5) -> 393.45455 | L5: =(93.6+73.8+78.1)/1.1 -> 223.18182 | M5: =49.9/1.1 -> 45.363636 | N5: =137.4/1.1 -> 124.90909
A6: Fundação | B6: Laje de cobertura | C6: PR-1248-01-CIS-LA-02-R01 | D6: ='Fund. Rasa | Contenção'!AG76 -> 4.632 | E6: ='Fund. Rasa | Contenção'!AD76 -> 28.95 | I6: =SUM(J6:Q6) -> 380.27273 | L6: =(71.2+1.8+68.3+77.2)/1.1 -> 198.63636 | M6: =60.5/1.1 -> 55 | N6: =139.3/1.1 -> 126.63636
A7: Fundação | B7: Pescoço Alçapão | C7: PR-1248-01-CIS-FO-01-R02 | D7: ='Fund. Rasa | Contenção'!AG73+'Fund. Rasa | Contenção'!AG74 -> 0.41216 | E7: ='Fund. Rasa | Contenção'!AD73+'Fund. Rasa | Contenção'!AD74 -> 5.152 | I7: =SUM(J7:Q7) -> 15.454545 | J7: =11/1.1 -> 10 | M7: =6/1.1 -> 5.4545455
A8: TÉRREO | B8: CISTERNA | C8: SOMATÓRIO | D8: =SUM(D3:D7) -> 23.18176 | E8: =SUM(E3:E7) -> 181.302 | F8: =SUM(F3:F7) -> 0 | G8: =SUM(G3:G7) -> 0 | H8: =SUM(H3:H7) -> 0 | I8: =SUM(I3:I7) -> 3419.1818 | J8: =SUM(J3:J7) -> 10 | K8: =SUM(K3:K7) -> 7.2727273 | ... Q8: =SUM(Q3:Q7) -> 0

Sheet Escoramento
A1: CLIENTE | B1: =CAPA!C2 -> Elizabeth II Royal Home
A2: OBRA | B2: =CAPA!C3 -> Gessele
A3: REVISÃO | B3: =CAPA!C4 -> R00
A4: PLANILHA DE ESCORAMENTO
A5: PAVIMENTO | B5: ÁREA | C5: R$ | D5: R$ | F5: ESCORAMENTO (PARA 1 MÊS)
C6: ESCOR. / m2 | D6: DIA / m2 | E6: DIAS CORRIDOS | F6: 1 | G6: 0.75 | H6: 0.5 | I6: 0.25 | J6: TRAV/MÊS / M2 | K6: TRAV.
A7: 1º PAVTO. TÉRREO | B7: 784.58 | C7: 12.606307 | D7: =C7/30 -> 0.42021022 | E7: 40 | F7: =(E7+7)*B7*D7 -> 15495.361 | G7: 0 | J7: 13.716359 | K7: =(J7*($E7)*B7)/30 -> 14348.775
A8: MEZANINO 1º PAVTO - GARAGEM. | B8: 801.15 | C8: 12.606307 | D8: =C8/30 -> 0.42021022 | E8: 50 | F8: =(E8+7)*B8*D8 -> 19189.131 | G8: =(B7*D7*0.75)*7 -> 1730.8648 | H8: =(B7*D7*0.5)*7 -> 1153.9099 | I8: =(B7*D7*0.25)*7 -> 576.95493 | J8: 19.6 | K8: =(J8*($E8)*B8)/30 -> 26170.9
A9: 2º PAVTO. - GARAGEM | B9: 878.5 | C9: 11.665145 | D9: =C9/30 -> 0.38883816 | E9: 50 | F9: =(E9+7)*B9*D9 -> 19470.876 | G9: =(B8*D8*0.75)*7 -> 1767.4199 | H9: =(B8*D8*0.5)*7 -> 1178.28 | I9: =(B8*D8*0.25)*7 -> 589.13998 | J9: 19.6 | K9: =(J9*($E9)*B9)/30 -> 28697.667
A10: MEZANINO 2º PAVTO - GARAGEM. | B10: 878.5 | C10: 11.665145 | D10: =C10/30 -> 0.38883816 | E10: 50 | F10: =(E10+7)*B10*D10 -> 19470.876 | G10: =(B9*D9*0.75)*7 -> 1793.3702 | H10: =(B9*D9*0.5)*7 -> 1195.5801 | I10: =(B9*D9*0.25)*7 -> 597.79006 | J10: 19.6 | K10: =(J10*($E10)*B10)/30 -> 28697.667
A11: 3º PAVTO. - GARAGEM | B11: 878.5 | C11: 11.665145 | D11: =C11/30 -> 0.38883816 | E11: 50 | F11: =(E11+7)*B11*D11 -> 19470.876 | G11: =(B10*D10*0.75)*7 -> 1793.3702 | H11: =(B10*D10*0.5)*7 -> 1195.5801 | I11: =(B10*D10*0.25)*7 -> 597.79006 | J11: 19.6 | K11: =(J11*($E11)*B11)/30 -> 28697.667
A12: MEZANINO 3º PAVTO - GARAGEM. | B12: 892.45 | C12: 11.665145 | D12: =C12/30 -> 0.38883816 | E12: 50 | F12: =(E12+7)*B12*D12 -> 19780.061 | G12: =(B11*D11*0.75)*7 -> 1793.3702 | H12: =(B11*D11*0.5)*7 -> 1195.5801 | I12: =(B11*D11*0.25)*7 -> 597.79006 | J12: 19.6 | K12: =(J12*($E12)*B12)/30 -> 29153.367
A13: 4º PAVTO. - GARAGEM/LAZER | B13: 892.45 | C13: 12.423854 | D13: =C13/30 -> 0.41412846 | E13: 45 | F13: =(E13+7)*B13*D13 -> 19218.625 | G13: =(B12*D12*0.75)*7 -> 1821.8477 | H13: =(B12*D12*0.5)*7 -> 1214.5652 | I13: =(B12*D12*0.25)*7 -> 607.28258 | J13: 15.057641 | K13: =(J13*($E13)*B13)/30 -> 20157.287
A14: 5º PAVTO. - LAZER | B14: 499.27 | C14: 12.423854 | D14: =C14/30 -> 0.41412846 | E14: 45 | F14: =(E14+7)*B14*D14 -> 10751.62 | G14: =(B13*D13*0.75)*7 -> 1940.3419 | H14: =(B13*D13*0.5)*7 -> 1293.5613 | I14: =(B13*D13*0.25)*7 -> 646.78065 | J14: 15.057641 | K14: =(J14*($E14)*B14)/30 -> 11276.742
A15: 6º PAVTO. - TIPO DIFERENCIADO | B15: 345.53 | C15: 17.010506 | D15: =C15/30 -> 0.56701686 | E15: 18 | F15: =(E15+7)*B15*D15 -> 4898.0334 | G15: =(B14*D14*0.75)*7 -> 1085.5001 | H15: =(B14*D14*0.5)*7 -> 723.6667 | I15: =(B14*D14*0.25)*7 -> 361.83335 | J15: 15.057641 | K15: =(J15*($E15)*B15)/30 -> 3121.7199
A16: 7º AO 14º PAVTO. - TIPO 8X | B16: 303.41 | C16: 17.010506 | D16: =C16/30 -> 0.56701686 | E16: 17 | F16: =(E16+7)*B16*D16 -> 4128.926 | G16: =(B15*D15*0.75)*7 -> 1028.587 | H16: =(B15*D15*0.5)*7 -> 685.72467 | I16: =(B15*D15*0.25)*7 -> 342.86234 | J16: 15.057641 | K16: =(J16*($E16)*B16)/30 -> 2588.8953
A17: 7º AO 14º PAVTO. - TIPO 8X | B17: 303.41 | C17: 17.010506 | D17: =C17/30 -> 0.56701686 | E17: 17 | F17: =(E17+7)*B17*D17 -> 4128.926 | G17: =(B16*D16*0.75)*7 -> 903.20257 | H17: =(B16*D16*0.5)*7 -> 602.13505 | I17: =(B16*D16*0.25)*7 -> 301.06752 | J17: 15.057641 | K17: =(J17*($E17)*B17)/30 -> 2588.8953
A18: 7º AO 14º PAVTO. - TIPO 8X | B18: 303.41 | C18: 17.010506 | D18: =C18/30 -> 0.56701686 | E18: 17 | F18: =(E18+7)*B18*D18 -> 4128.926 | G18: =(B17*D17*0.75)*7 -> 903.20257 | H18: =(B17*D17*0.5)*7 -> 602.13505 | I18: =(B17*D17*0.25)*7 -> 301.06752 | J18: 15.057641 | K18: =(J18*($E18)*B18)/30 -> 2588.8953
A19: 7º AO 14º PAVTO. - TIPO 8X | B19: 303.41 | C19: 17.010506 | D19: =C19/30 -> 0.56701686 | E19: 17 | F19: =(E19+7)*B19*D19 -> 4128.926 | G19: =(B18*D18*0.75)*7 -> 903.20257 | H19: =(B18*D18*0.5)*7 -> 602.13505 | I19: =(B18*D18*0.25)*7 -> 301.06752 | J19: 15.057641 | K19: =(J19*($E19)*B19)/30 -> 2588.8953
... A23: 7º AO 14º PAVTO. - TIPO 8X | B23: 303.41 | C23: 17.010506 | D23: =C23/30 -> 0.56701686 | E23: 17 | F23: =(E23+7)*B23*D23 -> 4128.926 | G23: =(B22*D22*0.75)*7 -> 903.20257 | H23: =(B22*D22*0.5)*7 -> 602.13505 | I23: =(B22*D22*0.25)*7 -> 301.06752 | J23: 15.057641 | K23: =(J23*($E23)*B23)/30 -> 2588.8953
A24: 15º AO 36º PAVTO. - PENTHOUSE | B24: 289.77136 | C24: 11.466294 | D24: =C24/30 -> 0.3822098 | E24: 17 | F24: =(E24+7)*B24*D24 -> 2658.0829 | G24: =(B16*D16*0.75)*7 -> 903.20257 | H24: =(B16*D16*0.5)*7 -> 602.13505 | I24: =(B16*D16*0.25)*7 -> 301.06752 | J24: 15.057641 | K24: =(J24*($E24)*B24)/30 -> 2472.5214
A25: 15º AO 36º PAVTO. - PENTHOUSE | B25: 289.77136 | C25: 11.466294 | D25: =C25/30 -> 0.3822098 | E25: 17 | F25: =(E25+7)*B25*D25 -> 2658.0829 | G25: =(B24*D24*0.75)*7 -> 581.45564 | H25: =(B24*D24*0.5)*7 -> 387.63709 | I25: =(B24*D24*0.25)*7 -> 193.81855 | J25: 15.057641 | K25: =(J25*($E25)*B25)/30 -> 2472.5214
A26: 15º AO 36º PAVTO. - PENTHOUSE | B26: 289.77136 | C26: 11.466294 | D26: =C26/30 -> 0.3822098 | E26: 17 | F26: =(E26+7)*B26*D26 -> 2658.0829 | G26: =(B25*D25*0.75)*7 -> 581.45564 | H26: =(B25*D25*0.5)*7 -> 387.63709 | I26: =(B25*D25*0.25)*7 -> 193.81855 | J26: 15.057641 | K26: =(J26*($E26)*B26)/30 -> 2472.5214
A27: 15º AO 36º PAVTO. - PENTHOUSE | B27: 289.77136 | C27: 11.466294 | D27: =C27/30 -> 0.3822098 | E27: 17 | F27: =(E27+7)*B27*D27 -> 2658.0829 | G27: =(B26*D26*0.75)*7 -> 581.45564 | H27: =(B26*D26*0.5)*7 -> 387.63709 | I27: =(B26*D26*0.25)*7 -> 193.81855 | J27: 15.057641 | K27: =(J27*($E27)*B27)/30 -> 2472.5214
A28: 15º AO 36º PAVTO. - PENTHOUSE | B28: 289.77136 | C28: 11.466294 | D28: =C28/30 -> 0.3822098 | E28: 17 | F28: =(E28+7)*B28*D28 -> 2658.0829 | G28: =(B27*D27*0.75)*7 -> 581.45564 | H28: =(B27*D27*0.5)*7 -> 387.63709 | I28: =(B27*D27*0.25)*7 -> 193.81855 | J28: 15.057641 | K28: =(J28*($E28)*B28)/30 -> 2472.5214
A29: 15º AO 36º PAVTO. - PENTHOUSE | B29: 289.77136 | C29: 11.466294 | D29: =C29/30 -> 0.3822098 | E29: 17 | F29: =(E29+7)*B29*D29 -> 2658.0829 | G29: =(B28*D28*0.75)*7 -> 581.45564 | H29: =(B28*D28*0.5)*7 -> 387.63709 | I29: =(B28*D28*0.25)*7 -> 193.81855 | J29: 15.057641 | K29: =(J29*($E29)*B29)/30 -> 2472.5214
A30: 15º AO 36º PAVTO. - PENTHOUSE | B30: 289.77136 | C30: 11.466294 | D30: =C30/30 -> 0.3822098 | E30: 17 | F30: =(E30+7)*B30*D30 -> 2658.0829 | G30: =(B29*D29*0.75)*7 -> 581.45564 | H30: =(B29*D29*0.5)*7 -> 387.63709 | I30: =(B29*D29*0.25)*7 -> 193.81855 | J30: 15.057641 | K30: =(J30*($E30)*B30)/30 -> 2472.5214
A31: 15º AO 36º PAVTO. - PENTHOUSE | B31: 289.77136 | C31: 11.466294 | D31: =C31/30 -> 0.3822098 | E31: 17 | F31: =(E31+7)*B31*D31 -> 2658.0829 | G31: =(B30*D30*0.75)*7 -> 581.45564 | H31: =(B30*D30*0.5)*7 -> 387.63709 | I31: =(B30*D30*0.25)*7 -> 193.81855 | J31: 15.057641 | K31: =(J31*($E31)*B31)/30 -> 2472.5214
A32: 15º AO 36º PAVTO. - PENTHOUSE | B32: 289.77136 | C32: 11.466294 | D32: =C32/30 -> 0.3822098 | E32: 17 | F32: =(E32+7)*B32*D32 -> 2658.0829 | G32: =(B31*D31*0.75)*7 -> 581.45564 | H32: =(B31*D31*0.5)*7 -> 387.63709 | I32: =(B31*D31*0.25)*7 -> 193.81855 | J32: 15.057641 | K32: =(J32*($E32)*B32)/30 -> 2472.5214
A33: 15º AO 36º PAVTO. - PENTHOUSE | B33: 289.77136 | C33: 11.466294 | D33: =C33/30 -> 0.3822098 | E33: 17 | F33: =(E33+7)*B33*D33 -> 2658.0829 | G33: =(B32*D32*0.75)*7 -> 581.45564 | H33: =(B32*D32*0.5)*7 -> 387.63709 | I33: =(B32*D32*0.25)*7 -> 193.81855 | J33: 15.057641 | K33: =(J33*($E33)*B33)/30 -> 2472.5214
A34: 15º AO 36º PAVTO. - PENTHOUSE | B34: 289.77136 | C34: 11.466294 | D34: =C34/30 -> 0.3822098 | E34: 17 | F34: =(E34+7)*B34*D34 -> 2658.0829 | G34: =(B33*D33*0.75)*7 -> 581.45564 | H34: =(B33*D33*0.5)*7 -> 387.63709 | I34: =(B33*D33*0.25)*7 -> 193.81855 | J34: 15.057641 | K34: =(J34*($E34)*B34)/30 -> 2472.5214
A35: 15º AO 36º PAVTO. - PENTHOUSE | B35: 289.77136 | C35: 11.466294 | D35: =C35/30 -> 0.3822098 | E35: 17 | F35: =(E35+7)*B35*D35 -> 2658.0829 | G35: =(B34*D34*0.75)*7 -> 581.45564 | H35: =(B34*D34*0.5)*7 -> 387.63709 | I35: =(B34*D34*0.25)*7 -> 193.81855 | J35: 15.057641 | K35: =(J35*($E35)*B35)/30 -> 2472.5214
A36: 15º AO 36º PAVTO. - PENTHOUSE | B36: 289.77136 | C36: 11.466294 | D36: =C36/30 -> 0.3822098 | E36: 17 | F36: =(E36+7)*B36*D36 -> 2658.0829 | G36: =(B35*D35*0.75)*7 -> 581.45564 | H36: =(B35*D35*0.5)*7 -> 387.63709 | I36: =(B35*D35*0.25)*7 -> 193.81855 | J36: 15.057641 | K36: =(J36*($E36)*B36)/30 -> 2472.5214
... A49: 40º PAVTO - BARRILETE | B49: 73.72 | C49: 17.010506 | D49: =C49/30 -> 0.56701686 | E49: 14 | F49: =(E49+7)*B49*D49 -> 877.81014 | G49: =(B48*D48*0.75)*7 -> 559.44048 | H49: =(B48*D48*0.5)*7 -> 372.96032 | I49: =(B48*D48*0.25)*7 -> 186.48016 | J49: 8.7500862 | K49: =(J49*($E49)*B49)/30 -> 301.0263
A50: 41º AO 42º PAVTO - COBERTURA/BARRILETE | B50: 73.72 | C50: 11.466551 | D50: =C50/30 -> 0.38221836 | E50: 14 | F50: =(E50+7)*B50*D50 -> 591.71989 | G50: =(B49*D49*0.75)*7 -> 219.45254 | H50: =(B49*D49*0.5)*7 -> 146.30169 | J50: 15.057978 | K50: =(J50*($E50)*B50)/30 -> 518.03459
A51: 43º PAVTO - RESERVATÓRIO | B51: 73.72 | C51: 78.097189 | D51: =C51/30 -> 2.6032396 | E51: 14 | F51: =(E51+7)*B51*D51 -> 4030.1274 | G51: =(B50*D50*0.75)*7 -> 147.92997 | H51: =(B50*D50*0.5)*7 -> 98.619981 | J51: 119.68702 | K51: =(J51*($E51)*B51)/30 -> 4117.5528
F52: =(E52+7)*B52*D52 -> 0 | G52: =(B51*D51*0.75)*7 -> 1007.5318 | H52: =(B51*D51*0.5)*7 -> 671.68789 | K52: =(J52*($E52)*B52)/30 -> 0
A54: ÍNDICE | G54: PREÇO DO CIMBRAMENTO POR M2 | K54: =SUM(F6:I52,K6:K52)/SUM(B5:B52) -> 36.16532
A55: Descrição | B55: R$ ESCOR. / m2 | C55: TRAV/MÊS / M2 | D55: DIAS CORRIDOS | G55: ART | K55: 1250
A56: Térreo | B56: 12.61 | C56: 13.72 | D56: 40 | G56: FRETE DE IDA | K56: =1100+450 -> 1550
...

Sheet Ger_Executivo_Manual
H4: PROJETO: | I4: Electra Towers | O4: REVISÃO: | P4: DATA
H5: EMPRESA: | I5: Thozen | O5: R00
A6: Unidade Construtiva | B6: Célula Construtiva | C6: Etapa | D6: Subetapa | E6: Serviço | G6: GERENCIAMENTO EXECUTIVO
A7: 0 | B7: 0 | C7: 0 | D7: 0 | E7: 0 | G7: EAP | H7: NIVEL | I7: Item | J7: Descrição | K7: Unidade | L7: Quant. | M7: Preço un | N7: Total | O7: Considerações | P7: Situação
A8: 0 | B8: 1 | C8: 0 | D8: 0 | E8: 0 | H8: CÉLULA CONSTRUTIVA | I8: 01 | J8: MOVIMENTAÇÃO DE TERRA
A9: 0 | B9: 1 | C9: 1 | D9: 0 | E9: 0 | H9: ETAPA | I9: 01.001 | J9: DEMOLIÇÕES, LIMPEZA DE TERRENO E LOCAÇÃO DE OBRA | N9: 26235.314 | O9: 1.5663183
A10: 0 | B10: 1 | C10: 1 | D10: 1 | E10: 0 | H10: SUBETAPA | I10: 01.001.001 | J10: Locação e gabarito de obra | N10: 26235.314 | O10: 1.5663183
A11: 0 | B11: 1 | C11: 1 | D11: 1 | E11: 1 | G11: MOVIMENTAÇÃO DE TERRA | H11: SERVIÇO | I11: 01.001.001.001 | J11: Locação da obra | K11: m2 | N11: 26235.314 | P11: Pendente
A12: 0 | B12: 1 | C12: 2 | D12: 0 | E12: 1 | H12: ETAPA | I12: 01.002 | J12: SERVIÇOS PRELIMINARES
A13: 0 | B13: 1 | C13: 2 | D13: 1 | E13: 0 | H13: SUBETAPA | I13: 01.002.001 | J13: Limpeza Permanente e Remoção entulho
A14: 0 | B14: 1 | C14: 2 | D14: 1 | E14: 1 | G14: MOVIMENTAÇÃO DE TERRA | H14: SERVIÇO | I14: 01.002.001.001 | J14: Limpeza da camada vegetal | K14: m2 | P14: Pendente
A15: 0 | B15: 1 | C15: 2 | D15: 1 | E15: 2 | G15: MOVIMENTAÇÃO DE TERRA | H15: SERVIÇO | I15: 01.002.001.002 | J15: Remoção de entulhos e resíduos | P15: Pendente
A16: 0 | B16: 1 | C16: 2 | D16: 2 | E16: 0 | H16: SUBETAPA | I16: 01.002.002 | J16: Mão de Obra de Canteiro
A17: 0 | B17: 1 | C17: 2 | D17: 2 | E17: 1 | G17: MOVIMENTAÇÃO DE TERRA | H17: SERVIÇO | I17: 01.002.002.001 | J17: Mão de Obra de Canteiro | K17: vb | P17: Pendente
A18: 0 | B18: 1 | C18: 3 | D18: 0 | E18: 1 | H18: ETAPA | I18: 01.003 | J18: SERVIÇOS DE TERRAPLANAGEM | N18: 271126.19 | O18: 16.186957
A19: 0 | B19: 1 | C19: 3 | D19: 1 | E19: 0 | H19: SUBETAPA | I19: 01.003.001 | J19: Mao de obra - movimentações de terra | N19: 271126.19 | O19: 16.186957
A20: 0 | B20: 1 | C20: 3 | D20: 1 | E20: 1 | G20: MOVIMENTAÇÃO DE TERRA | H20: SERVIÇO | I20: 01.003.001.001 | J20: Mão de obra movimentação de terra | K20: vb | N20: 233000 | P20: Pendente
A21: 0 | B21: 1 | C21: 4 | D21: 0 | E21: 2 | H21: ETAPA | I21: 01.004 | J21: SERVIÇO DE DRENAGEM | N21: 80000 | O21: 4.7762135
A22: 0 | B22: 1 | C22: 4 | D22: 1 | E22: 0 | H22: SUBETAPA | I22: 01.004.001 | J22: Drenagem | N22: 80000 | O22: 4.7762135
A23: 0 | B23: 1 | C23: 4 | D23: 1 | E23: 1 | G23: MOVIMENTAÇÃO DE TERRA | H23: SERVIÇO | I23: 01.004.001.001 | J23: Rebaixamento de Lençol freático | K23: vb | N23: 80000 | P23: Pendente
A24: 0 | B24: 2 | C24: 0 | D24: 1 | E24: 1 | H24: CÉLULA CONSTRUTIVA | I24: 02 | J24: CONTENÇÃO | N24: 772006.63 | O24: 46.090856
A25: 0 | B25: 2 | C25: 1 | D25: 0 | E25: 1 | H25: ETAPA | I25: 02.001 | J25: MURETA GUIA | N25: 18739.389 | O25: 1.1187915
A26: 0 | B26: 2 | C26: 1 | D26: 1 | E26: 0 | H26: SUBETAPA | I26: 02.001.001 | J26: Forma | N26: 6673.9436 | O26: 0.39845225
A27: 0 | B27: 2 | C27: 1 | D27: 1 | E27: 1 | G27: CONTENÇÃO | H27: SERVIÇO | I27: 02.001.001.001 | J27: Forma para infraestrutura em Tábuas de Madeira Serrada 2x reaproveitamento | K27: m2 | L27: 111.3136 | M27: 59.956229 | N27: 6673.9436 | P27: Pendente
A28: 0 | B28: 2 | C28: 1 | D28: 2 | E28: 0 | H28: SUBETAPA | I28: 02.001.002 | J28: Armadura | N28: 4318.7306 | O28: 0.25783974
A29: 0 | B29: 2 | C29: 1 | D29: 2 | E29: 1 | G29: CONTENÇÃO | H29: SERVIÇO | I29: 02.001.002.001 | J29: Armação aço CA-50 ø 6,3mm para Contenções (corte e dobra em obra) | K29: un | L29: 670.32 | M29: 6.0795674 | N29: 4075.2556 | P29: Pendente
A30: 0 | B30: 2 | C30: 1 | D30: 2 | E30: 2 | G30: CONTENÇÃO | H30: SERVIÇO | I30: 02.001.002.002 | J30: Armação aço CA-50 ø 12,5mm para Contenções (corte e dobra em obra) | K30: un | L30: 41.6016 | M30: 5.8525391 | N30: 243.47499 | P30: Pendente
A31: 0 | B31: 2 | C31: 1 | D31: 3 | E31: 0 | H31: SUBETAPA | I31: 02.001.003 | J31: Concreto | N31: 7746.7147 | O31: 0.46249954
A32: 0 | B32: 2 | C32: 1 | D32: 3 | E32: 1 | G32: CONTENÇÃO | H32: SERVIÇO | I32: 02.001.003.001 | J32: Concreto Usinado bombeável 50MPa para infraestrutura- incluindo serviço de bombeamento | K32: m3 | L32: 11.390452 | M32: 680.106 | N32: 7746.7147 | P32: Pendente
A33: 0 | B33: 2 | C33: 2 | D33: 0 | E33: 1 | H33: ETAPA | I33: 02.002 | J33: LAMELAS | PAREDE DIAFRAGMA | N33: 331865.23 | O33: 19.81324
A34: 0 | B34: 2 | C34: 2 | D34: 1 | E34: 0 | H34: SUBETAPA | I34: 02.002.001 | J34: Armadura | N34: 155967.97 | O34: 9.3117038
A35: 0 | B35: 2 | C35: 2 | D35: 1 | E35: 1 | G35: CONTENÇÃO | H35: SERVIÇO | I35: 02.002.001.001 | J35: Armação aço CA-50 ø 6,3mm para Contenções (corte e dobra em Indústria) | K35: un | L35: 2282 | M35: 8.964145 | N35: 20456.179 | P35: Pendente
A36: 0 | B36: 2 | C36: 2 | D36: 1 | E36: 2 | G36: CONTENÇÃO | H36: SERVIÇO | I36: 02.002.001.002 | J36: Armação aço CA-50 ø 8,0mm para Contenções (corte e dobra em Indústria) | K36: un | L36: 77 | M36: 8.964145 | N36: 690.23916 | P36: Pendente
A37: 0 | B37: 2 | C37: 2 | D37: 1 | E37: 3 | G37: CONTENÇÃO | H37: SERVIÇO | I37: 02.002.001.003 | J37: Armação aço CA-50 ø 12,5mm para Contenções (corte e dobra em Indústria) | K37: un | L37: 3884 | M37: 8.484145 | N37: 32952.419 | P37: Pendente
A38: 0 | B38: 2 | C38: 2 | D38: 1 | E38: 4 | G38: CONTENÇÃO | H38: SERVIÇO | I38: 02.002.001.004 | J38: Armação aço CA-50 ø 25,0mm para Contenções (corte e dobra em Indústria) | K38: un | L38: 12007 | M38: 8.484145 | N38: 101869.13 | P38: Pendente
A39: 0 | B39: 2 | C39: 2 | D39: 2 | E39: 0 | H39: SUBETAPA | I39: 02.002.002 | J39: Concreto | N39: 175897.26 | O39: 10.501536
A40: 0 | B40: 2 | C40: 2 | D40: 2 | E40: 1 | G40: CONTENÇÃO | H40: SERVIÇO | I40: 02.002.002.001 | J40: Concreto Usinado bombeável 50MPa com Penetron para infraestrutura- incluindo serviço de bombeamento | K40: m3 | L40: 210 | M40: 837.606 | N40: 175897.26 | P40: Pendente
A41: 0 | B41: 2 | C41: 3 | D41: 0 | E41: 1 | H41: ETAPA | I41: 02.003 | J41: VIGAS COROAMENTO | N41: 37645.991 | O41: 2.2475661
A42: 0 | B42: 2 | C42: 3 | D42: 1 | E42: 0 | H42: SUBETAPA | I42: 02.003.001 | J42: Forma | N42: 2482.1879 | O42: 0.14819324
A43: 0 | B43: 2 | C43: 3 | D43: 1 | E43: 1 | G43: CONTENÇÃO | H43: SERVIÇO | I43: 02.003.001.001 | J43: Forma para infraestrutura em Tábuas de Madeira Serrada 2x reaproveitamento | K43: m2 | L43: 41.4 | M43: 59.956229 | N43: 2482.1879 | P43: Pendente
...

Sheet Orçamento
A1: DADOS
A2: Titulo | B2: ORÇAMENTO
A3: Obra | B3: ELECTRA TOWERS
A4: Cliente | B4: THOZEN
A5: Cidade | B5: Porto Belo
A6: Endereço
A7: Descrição
A8: UF | B8: SC
A10: RESUMO
A11: Tipo | C11: Preço | E11: Observação
A12: Total | C12: 21718825 | E12: Geral da edificação
A13: Material | C13: 15467433
A14: Execução | C14: 6251392.4
A16: TABELA DE ORÇAMENTO
A17: Item | B17: Referência | C17: Tipo | D17: Código | E17: Descrição | F17: Unid. | G17: Quantidade | H17: Custo unitário | I17: Preço total | J17: % | K17: Observação
A19: 1. | E19: 03. PAREDES E PAINÉIS | I19: 1964071 | J19: 0.090431735
A20: 1.1. | E20: ARQ_Embasamento | I20: 228660.08 | J20: 0.010528198
A21: 1.1.1. | E21: 03.001. Alvenaria de vedação com blocos cerâmicos | I21: 133087.99 | J21: 0.006127771
A22: 1.1.1.1 | E22: BLOCO CERAMICO, 0,05 (Parede padrão) | F22: m² | G22: 35.77 | H22: 0 | I22: 0
A23: 1.1.1.2 | E23: BLOCO CERAMICO, 0,09 (Parede padrão) | F23: m² | G23: 171.98 | H23: 0 | I23: 0
A24: 1.1.1.3 | B24: Thozen - Electra | C24: COMPOSICAO | D24: 4825 | E24: Alvenaria de vedação de blocos cerâmicos furados na horizontal de 11,5x19x19cm (espessura 11,5cm) com argamassa industrializada de assentamento | F24: m2 | G24: 1262.88 | H24: 25.096 | I24: 31693.236 | J24: 0.0014592519
A25: 1.1.1.4 | B25: Thozen - Electra | C25: COMPOSICAO | D25: 4826 | E25: Alvenaria de vedação de blocos cerâmicos furados na horizontal de 14x19x19cm (espessura 14cm) com argamassa industrializada de assentamento | F25: m2 | G25: 1610.87 | H25: 40.7664 | I25: 65669.371 | J25: 0.0030236152
A26: 1.1.1.5 | B26: Thozen - Electra | C26: COMPOSICAO | D26: 90472 | E26: Alvenaria de vedação de blocos cerâmicos furados na horizontal de 19x19x19cm (espessura 19cm) com argamassa industrializada de assentamento | F26: m2 | G26: 631.36 | H26: 56.5848 | I26: 35725.379 | J26: 0.0016449039
A27: 1.1.2. | E27: 03.002. Alvenaria de vedação com blocos de concreto | I27: 0
A28: 1.1.2.1 | E28: BLOCO CONCRETO, 0,05 (Parede padrão) | F28: m² | G28: 1.49 | H28: 0 | I28: 0
A29: 1.1.2.2 | E29: BLOCO ANTI CHAMAS, 0,125 (Parede padrão) | F29: m² | G29: 252.44 | H29: 0 | I29: 0
A30: 1.1.2.3 | E30: BLOCO ANTI CHAMAS, 0,15 (Parede padrão) | F30: m² | G30: 774.4 | H30: 0 | I30: 0
A31: 1.1.3. | E31: 03.003. Serviços complementares para alvenaria de vedação | I31: 95572.097 | J31: 0.0044004266
A32: 1.1.3.1 | B32: Thozen - Electra | C32: COMPOSICAO | D32: 4831 | E32: Verga/contraverga de concreto, moldada in loco | F32: m | G32: 104.16 | H32: 43.712512 | I32: 4553.0952 | J32: 0.00020963819
A33: 1.1.3.2 | B33: Thozen - Electra | C33: COMPOSICAO | D33: 4828 | E33: Encunhamento de alvenaria de vedação com argamassa expansiva | F33: m | G33: 18470.23 | H33: 3.633798 | I33: 67117.085 | J33: 0.0030902724
A34: 1.1.3.3 | B34: Thozen - Electra | C34: COMPOSICAO | D34: 4829 | E34: Tela soldada para ligação alvenaria/estrutura | F34: m² | G34: 2370.59 | H34: 1.85 | I34: 4385.5915 | J34: 0.00020192582
A35: 1.1.3.4 | B35: Thozen - Electra | C35: COMPOSICAO | D35: 4831 | E35: Verga/contraverga de concreto, moldada in loco | F35: m | G35: 446.47 | H35: 43.712512 | I35: 19516.325 | J35: 0.00089859028
A36: 1.1.4. | E36: 03.005. Mão de obra | I36: 0
A37: 1.1.4.1 | E37: Mão de obra alvenaria cerâmica | F37: m² | G37: 4045.19 | H37: 0 | I37: 0
A38: 1.1.4.2 | E38: Mão de obra blocos sílico calcário (Parede padrão) | F38: m² | G38: 1028.33 | H38: 0 | I38: 0
A39: 1.1.5. | E39: Alvenaria de vedação com tijolo refratário | I39: 0
A40: 1.1.5.1 | E40: TIJOLO REFRATARIO, 0,016 (Parede padrão) | F40: m² | G40: 14.56 | H40: 0 | I40: 0
A41: 1.2. | E41: ARQ_Impermeab | I41: 45754.495 | J41: 0.0021066745
A42: 1.2.1. | E42: 03.003. Serviços complementares para alvenaria de vedação | I42: 45754.495 | J42: 0.0021066745
A43: 1.2.1.1 | B43: Thozen - Electra | C43: COMPOSICAO | D43: 4828 | E43: Encunhamento de alvenaria de vedação com argamassa expansiva | F43: m | G43: 12591.37 | H43: 3.633798 | I43: 45754.495 | J43: 0.0021066745
...

Sheet Composições
A1: DADOS
A2: Titulo | B2: ORÇAMENTO
A3: Obra | B3: ELECTRA TOWERS
A4: Cliente | B4: THOZEN
A5: Cidade | B5: Porto Belo
A6: Endereço
A7: Descrição
A8: UF | B8: SC
A11: TABELA DE COMPOSIÇÕES UTILIZADAS
A12: Código | B12: Referência | C12: Tipo | D12: Tipo | E12: Descrição | F12: Unid. | G12: Multiplicador | H12: Preço | J12: Ref. Tabela | K12: Ref. Código | L12: Justificativa | M12: Grupo de Serviço | N12: Serviço
H13: Unitário | I13: Total
A14: 4825 | B14: Thozen - Electra | D14: Original | E14: Alvenaria de vedação de blocos cerâmicos furados na horizontal de 11,5x19x19cm (espessura 11,5cm) com argamassa industrializada de assentamento | F14: m2 | I14: 25.096 | N14: BLOCOS | O14: =A14&B14&C14 -> 4825Thozen - Electra
A15: 194 | B15: Thozen - Electra | C15: INSUMO | D15: Original | E15: ARGAMASSA ESTABILIZADA PARA ASSENTAMENTO | F15: m3 | G15: 0.0125 | H15: 480 | I15: 6
A16: 228 | B16: Thozen - Electra | C16: INSUMO | D16: Original | E16: BLOCO CERÂMICO 11,5X19X19CM | F16: un | G16: 17.36 | H16: 1.1 | I16: 19.096
A17: 4826 | B17: Thozen - Electra | D17: Original | E17: Alvenaria de vedação de blocos cerâmicos furados na horizontal de 14x19x19cm (espessura 14cm) com argamassa industrializada de assentamento | F17: m2 | I17: 40.7664 | N17: BLOCOS | O17: =A17&B17&C17 -> 4826Thozen - Electra
A18: 194 | B18: Thozen - Electra | C18: INSUMO | D18: Original | E18: ARGAMASSA ESTABILIZADA PARA ASSENTAMENTO | F18: m3 | G18: 0.022 | H18: 480 | I18: 10.56
A19: 232 | B19: Thozen - Electra | C19: INSUMO | D19: Original | E19: BLOCO CERÂMICO 14X19X19CM | F19: un | G19: 17.36 | H19: 1.74 | I19: 30.2064
A20: 90472 | B20: Thozen - Electra | D20: Original | E20: Alvenaria de vedação de blocos cerâmicos furados na horizontal de 19x19x19cm (espessura 19cm) com argamassa industrializada de assentamento | F20: m2 | I20: 56.5848 | N20: BLOCOS | O20: =A20&B20&C20 -> 90472Thozen - Electra
A21: 194 | B21: Thozen - Electra | C21: INSUMO | D21: Original | E21: ARGAMASSA ESTABILIZADA PARA ASSENTAMENTO | F21: m3 | G21: 0.03 | H21: 480 | I21: 14.4
A22: 48433 | B22: Thozen - Electra | C22: INSUMO | D22: Original | E22: BLOCO CERÂMICO 19X19X19CM | F22: un | G22: 17.36 | H22: 2.43 | I22: 42.1848
A23: 4831 | B23: Thozen - Electra | D23: Original | E23: Verga/contraverga de concreto, moldada in loco | F23: m | I23: 43.712512 | O23: =A23&B23&C23 -> 4831Thozen - Electra
A24: 759 | B24: Thozen - Electra | C24: INSUMO | D24: Original | E24: CONCRETO USINADO FCK 20 MPA, SLUMP 14+/-2 | F24: m3 | G24: 0.0264 | H24: 450 | I24: 11.88
A25: 4800 | B25: Thozen - Electra | C25: INSUMO | D25: Original | E25: DESMOLDANTE DE FORMAS PARA CONCRETO | F25: l | G25: 0.007 | H25: 6.45 | I25: 0.04515
A26: 1412 | B26: Thozen - Electra | C26: INSUMO | D26: Original | E26: ESPAÇADOR PLÁSTICO | F26: un | G26: 6 | H26: 0.15 | I26: 0.9
A27: 2324 | B27: Thozen - Electra | C27: INSUMO | D27: Original | E27: PONTALETE 7,5X7,5 CM PINUS | F27: m3 | G27: 0.0012 | H27: 1310 | I27: 1.572
A28: 2362 | B28: Thozen - Electra | C28: INSUMO | D28: Original | E28: PREGO POLIDO COM CABEÇA 17X21 | F28: kg | G28: 0.0512 | H28: 10.91 | I28: 0.558592
A29: 2546 | B29: Thozen - Electra | C29: INSUMO | D29: Original | E29: SARRAFO 2,5X7,5 CM PINUS | F29: m3 | G29: 0.003171 | H29: 1300 | I29: 4.1223
A30: 2611 | B30: Thozen - Electra | C30: INSUMO | D30: Original | E30: TÁBUA 1"X12" 2,5X30CM PINUS | F30: m3 | G30: 0.011676 | H30: 1800 | I30: 21.0168
A31: 32 | B31: Thozen - Electra | C31: INSUMO | D31: Original | E31: AÇO CA-50 DIÂMETRO 6,30 MM | F31: kg | G31: 0.5243 | H31: 6.9 | I31: 3.61767
A32: 4828 | B32: Thozen - Electra | D32: Original | E32: Encunhamento de alvenaria de vedação com argamassa expansiva | F32: m | I32: 3.633798 | N32: ENCUNHAMENTO | O32: =A32&B32&C32 -> 4828Thozen - Electra
A33: 48435 | B33: Thozen - Electra | C33: INSUMO | D33: Original | E33: ARGAMASSA EXPANSIVA PARA ENCUNHAMENTO | F33: Kg | G33: 0.2154 | H33: 16.87 | I33: 3.633798
A34: 4829 | B34: Thozen - Electra | D34: Original | E34: Tela soldada para ligação alvenaria/estrutura | F34: m² | I34: 1.85 | O34: =A34&B34&C34 -> 4829Thozen - Electra
A35: 718 | B35: Thozen - Electra | C35: INSUMO | D35: Original | E35: CARTUCHO 22 - CARGA LEVE PARA FINCA PINO E POLVORA | F35: un | G35: 1 | H35: 0.3 | I35: 0.3
A36: 2260 | B36: Thozen - Electra | C36: INSUMO | D36: Original | E36: PINO LISO EM AÇO GALVANIZADO 1/2 X 22MM COM ARRUELA | F36: un | G36: 1 | H36: 0.3 | I36: 0.3
A37: 2901 | B37: Thozen - Electra | C37: INSUMO | D37: Original | E37: TELA DE ACO SOLDADA, FIO 1,24MM, MALHA 15X15MM | F37: m2 | G37: 0.5 | H37: 2.5 | I37: 1.25
A38: 4842 | B38: Thozen - Electra | D38: Original | E38: Impermeabilização com argamassa polimérica, 3 demãos | F38: m2 | I38: 36.225 | O38: =A38&B38&C38 -> 4842Thozen - Electra
A39: 202 | B39: Thozen - Electra | C39: INSUMO | D39: Original | E39: ARGAMASSA POLIMÉRICA IMPERMEABILIZANTE | F39: kg | G39: 3.15 | H39: 11.5 | I39: 36.225
A40: 90541 | B40: Thozen - Electra | D40: Original | E40: Chapisco adesivo aplicado em concreto, com desempenadeira dentada | F40: m2 | I40: 6.459 | N40: CHAPISCO | O40: =A40&B40&C40 -> 90541Thozen - Electra
A41: 197 | B41: Thozen - Electra | C41: INSUMO | D41: Original | E41: ARGAMASSA ESTABILIZADA PARA REBOCO | F41: m3 | G41: 0.0033 | H41: 480 | I41: 1.584
A42: 48481 | B42: Thozen - Electra | C42: INSUMO | D42: Original | E42: ADITIVO ADESIVO LÍQUIDO PARA ARGAMASSA | F42: L | G42: 0.625 | H42: 7.8 | I42: 4.875
...

Sheet Insumos (2)
A1: DADOS
A2: Titulo | B2: Tabela de insumos utilizados no projeto
A3: Obra | B3: ELECTRA TOWERS
A4: Cliente | B4: THOZEN
A5: Cidade | B5: Porto Belo
A6: Endereço
A7: Descrição
A8: UF | B8: SC
A11: INSUMOS UTILIZADOS
A12: Código | B12: Tabela | C12: Tipo | D12: Descrição | E12: Unid. | F12: Preço | G12: Origem custo | H12: Justificativa
A14: 194 | B14: Thozen - Electra | C14: Material | D14: ARGAMASSA ESTABILIZADA PARA ASSENTAMENTO | E14: m3 | F14: 480 | I14: =A14&B14 -> 194Thozen - Electra
A15: 228 | B15: Thozen - Electra | C15: Material | D15: BLOCO CERÂMICO 11,5X19X19CM | E15: un | F15: 1.1 | I15: =A15&B15 -> 228Thozen - Electra
A16: 232 | B16: Thozen - Electra | C16: Material | D16: BLOCO CERÂMICO 14X19X19CM | E16: un | F16: 1.74 | I16: =A16&B16 -> 232Thozen - Electra
A17: 48433 | B17: Thozen - Electra | C17: Material | D17: BLOCO CERÂMICO 19X19X19CM | E17: un | F17: 2.43 | I17: =A17&B17 -> 48433Thozen - Electra
A18: 759 | B18: Thozen - Electra | C18: Material | D18: CONCRETO USINADO FCK 20 MPA, SLUMP 14+/-2 | E18: m3 | F18: 450 | I18: =A18&B18 -> 759Thozen - Electra
A19: 4800 | B19: Thozen - Electra | C19: Material | D19: DESMOLDANTE DE FORMAS PARA CONCRETO | E19: l | F19: 6.45 | I19: =A19&B19 -> 4800Thozen - Electra
A20: 1412 | B20: Thozen - Electra | C20: Material | D20: ESPAÇADOR PLÁSTICO | E20: un | F20: 0.15 | I20: =A20&B20 -> 1412Thozen - Electra
A21: 2324 | B21: Thozen - Electra | C21: Material | D21: PONTALETE 7,5X7,5 CM PINUS | E21: m3 | F21: 1310 | I21: =A21&B21 -> 2324Thozen - Electra
A22: 2362 | B22: Thozen - Electra | C22: Material | D22: PREGO POLIDO COM CABEÇA 17X21 | E22: kg | F22: 10.91 | I22: =A22&B22 -> 2362Thozen - Electra
A23: 2546 | B23: Thozen - Electra | C23: Material | D23: SARRAFO 2,5X7,5 CM PINUS | E23: m3 | F23: 1300 | I23: =A23&B23 -> 2546Thozen - Electra
A24: 2611 | B24: Thozen - Electra | C24: Material | D24: TÁBUA 1"X12" 2,5X30CM PINUS | E24: m3 | F24: 1800 | I24: =A24&B24 -> 2611Thozen - Electra
A25: 32 | B25: Thozen - Electra | C25: Material | D25: AÇO CA-50 DIÂMETRO 6,30 MM | E25: kg | F25: 6.9 | G25: GERDAU | I25: =A25&B25 -> 32Thozen - Electra
A26: 48435 | B26: Thozen - Electra | C26: Material | D26: ARGAMASSA EXPANSIVA PARA ENCUNHAMENTO | E26: Kg | F26: 16.87 | I26: =A26&B26 -> 48435Thozen - Electra
A27: 718 | B27: Thozen - Electra | C27: Material | D27: CARTUCHO 22 - CARGA LEVE PARA FINCA PINO E POLVORA | E27: un | F27: 0.3 | I27: =A27&B27 -> 718Thozen - Electra
A28: 2260 | B28: Thozen - Electra | C28: Material | D28: PINO LISO EM AÇO GALVANIZADO 1/2 X 22MM COM ARRUELA | E28: un | F28: 0.3 | I28: =A28&B28 -> 2260Thozen - Electra
A29: 2901 | B29: Thozen - Electra | C29: Material | D29: TELA DE ACO SOLDADA, FIO 1,24MM, MALHA 15X15MM | E29: m2 | F29: 2.5 | I29: =A29&B29 -> 2901Thozen - Electra
A30: 202 | B30: Thozen - Electra | C30: Material | D30: ARGAMASSA POLIMÉRICA IMPERMEABILIZANTE | E30: kg | F30: 11.5 | I30: =A30&B30 -> 202Thozen - Electra
A31: 197 | B31: Thozen - Electra | C31: Material | D31: ARGAMASSA ESTABILIZADA PARA REBOCO | E31: m3 | F31: 480 | I31: =A31&B31 -> 197Thozen - Electra
A32: 48481 | B32: Thozen - Electra | C32: Material | D32: ADITIVO ADESIVO LÍQUIDO PARA ARGAMASSA | E32: L | F32: 7.8 | I32: =A32&B32 -> 48481Thozen - Electra
A33: 48373 | B33: Thozen - Electra | C33: Material | D33: CHAPISCO COLANTE 20KG | E33: Kg | F33: 1.31 | I33: =A33&B33 -> 48373Thozen - Electra
A34: 2154 | B34: Thozen - Electra | C34: Mao_obra | D34: MÃO DE OBRA PARA EXECUÇÃO DE CHAPISCO E REBOCO INTERNO EM PAREDES | E34: m2 | F34: 35 | I34: =A34&B34 -> 2154Thozen - Electra
A35: 193 | B35: Thozen - Electra | C35: Material | D35: ARGAMASSA COLANTE AC III | E35: kg | F35: 2.345 | I35: =A35&B35 -> 193Thozen - Electra
A36: 4881 | B36: Thozen - Electra | C36: Material | D36: ESPAÇADOR PARA REVESTIMENTO CERÂMICO TIPO CRUZETA 5 MM | E36: un | F36: 0.2 | I36: =A36&B36 -> 4881Thozen - Electra
A37: 4880 | B37: Thozen - Electra | C37: Material | D37: REJUNTE FLEXÍVEL | E37: m2 | F37: 2.0643 | I37: =A37&B37 -> 4880Thozen - Electra
... A61: 2552 | B61: Thozen - Electra | C61: Material | D61: SELADOR ACRÍLICO | E61: l | F61: 9.44 | I61: =A61&B61 -> 2552Thozen - Electra

Sheet PROJETOS
B1: GESTÃO DOS PROJETOS | J1: LEGENDA
A2: Obra | B2: Electra Towers (Rubens Alves) | J2: NÃO SE APLICA
A3: Empresa | B3: Thozen Empreendimentos | J3: PENDENTE
A4: Revisão | B4: R01 | J4: RECEBIDO
B5: PAVIMENTO | C5: DISCIPLINA | D5: PROJETOS | E5: CAMINHO | F5: STATUS | G5: OBSERVAÇÕES | J5: REVISADO
B7: ESTRUTURA
B8: TERRAPLENAGEM | C8: INFRAESTRUTURA | F8: NÃO SE APLICA
B9: MOVIMENTAÇÃO DE TERRA | C9: INFRAESTRUTURA | F9: PENDENTE
B10: FUNDAÇÃO PROFUNDA | C10: INFRAESTRUTURA | D10: 1203 - PREFORMAS - R20.DWG | E10: 01 ESTRUTURA/DWG | F10: RECEBIDO | G10: DWG Pré-formas Rev.20
B11: FUNDAÇÃO RASA | C11: INFRAESTRUTURA | D11: 1203 - THOZEN - RUBENS ALVES - BLOCOS+RAMPAS DE ACESSO - R26.ifc | E11: 01 ESTRUTURA/IFC | F11: RECEBIDO | G11: IFC Blocos + Rampas de Acesso Rev.26
B12: CONTENÇÃO | C12: INFRAESTRUTURA | F12: NÃO SE APLICA
B13: ÁREA – 1º PAVTO. (TÉRREO) | C13: SUPRAESTRUTURA | F13: RECEBIDO | G13: Coberto pelo IFC estrutural completo
B14: ÁREA – MEZANINO DO 1º PAVTO. | C14: SUPRAESTRUTURA | F14: RECEBIDO | G14: Coberto pelo IFC estrutural completo
B15: ÁREA – 2º PAVIMENTO | C15: SUPRAESTRUTURA | F15: RECEBIDO | G15: Coberto pelo IFC estrutural completo
B16: ÁREA – MEZANINO DO 2º PAVTO. | C16: SUPRAESTRUTURA | F16: RECEBIDO | G16: Coberto pelo IFC estrutural completo
B17: ÁREA – 3º PAVIMENTO | C17: SUPRAESTRUTURA | F17: RECEBIDO | G17: Coberto pelo IFC estrutural completo
B18: ÁREA – MEZANINO DO 3º PAVTO. | C18: SUPRAESTRUTURA | F18: RECEBIDO | G18: Coberto pelo IFC estrutural completo
B19: ÁREA – 4º PAVIMENTO GARAGEM/LAZER | C19: SUPRAESTRUTURA | F19: RECEBIDO | G19: Coberto pelo IFC estrutural completo
B20: ÁREA – 5º PAVIMENTO LAZER | C20: SUPRAESTRUTURA | F20: RECEBIDO | G20: Coberto pelo IFC estrutural completo
B21: ÁREA – 6º PAVIMENTO TIPO - DIFERENCIADO | C21: SUPRAESTRUTURA | F21: RECEBIDO | G21: Coberto pelo IFC estrutural completo
B22: ÁREA – 7º AO 14° PAVIMENTO TIPO - X8 | C22: SUPRAESTRUTURA | F22: RECEBIDO | G22: Coberto pelo IFC estrutural completo
B23: ÁREA – 15º AO 35° PAVIMENTO TIPO - X21 | C23: SUPRAESTRUTURA | F23: RECEBIDO | G23: Coberto pelo IFC estrutural completo
B24: ARQUITETURA
B25: TERRAPLENAGEM | C25: ARQUITETURA | F25: NÃO SE APLICA
B26: MOVIMENTAÇÃO DE TERRA | C26: ARQUITETURA | F26: NÃO SE APLICA
B27: FUNDAÇÃO PROFUNDA | C27: ARQUITETURA | F27: NÃO SE APLICA
B28: FUNDAÇÃO RASA | C28: ARQUITETURA | F28: NÃO SE APLICA
B29: CONTENÇÃO | C29: ARQUITETURA | F29: NÃO SE APLICA
B30: TÉRREO 01 | C30: ARQUITETURA | D30: RA_ARQ_EXE_01_TÉRREO_R02.dwg | E30: 02 ARQUITETURA/DWG | F30: RECEBIDO | G30: DWG Executivo Rev.02
B31: TÉRREO 02 | C31: ARQUITETURA | D31: RA_ARQ_EXE_10_CORTE1_R02.dwg + RA_ARQ_EXE_11_CORTE2_R02.dwg | E31: 02 ARQUITETURA/DWG | F31: RECEBIDO | G31: Cortes 1 e 2, Rev.02
B32: GARAGEM 01 | C32: ARQUITETURA | D32: RA_ARQ_EXE_02_G1_R02.dwg | E32: 02 ARQUITETURA/DWG | F32: RECEBIDO | G32: DWG Executivo Rev.02
B33: GARAGEM 02 | C33: ARQUITETURA | D33: RA_ARQ_EXE_03_G2_R02.dwg | E33: 02 ARQUITETURA/DWG | F33: RECEBIDO | G33: DWG Executivo Rev.02
B34: GARAGEM 03 | C34: ARQUITETURA | D34: RA_ARQ_EXE_04_G3_R02.dwg | E34: 02 ARQUITETURA/DWG | F34: RECEBIDO | G34: DWG Executivo Rev.02
B35: GARAGEM 04 | C35: ARQUITETURA | D35: RA_ARQ_EXE_05_G4_R02.dwg | E35: 02 ARQUITETURA/DWG | F35: RECEBIDO | G35: DWG Executivo Rev.02
B36: LAZER 01 | C36: ARQUITETURA | D36: RA_ARQ_EXE_06_G5_R02.dwg | E36: 02 ARQUITETURA/DWG | F36: RECEBIDO | G36: DWG Executivo Rev.02
B37: LAZER 02 | C37: ARQUITETURA | D37: RA_ARQ_EXE_07_LAZER_R02.dwg | E37: 02 ARQUITETURA/DWG | F37: RECEBIDO | G37: DWG Executivo Rev.02
B38: TIPO DIFERENCIADO 01 | C38: ARQUITETURA | D38: RA_ARQ_EXE_MODELAGEM EMBASAMENTO + COBERTURA_R08.ifc | E38: 02 ARQUITETURA/IFC | F38: RECEBIDO | G38: IFC Embasamento + Cobertura Rev.08
B39: TIPO DIFERENCIADO 02 | C39: ARQUITETURA | D39: RA_ARQ_EXE_MODELAGEM TIPO_R07.ifc | E39: 02 ARQUITETURA/IFC | F39: RECEBIDO | G39: IFC Tipo Rev.07
B40: TIPO (30x) | C40: ARQUITETURA | D40: RA_ARQ_EXE_08_TIPOS_R02.dwg | E40: 02 ARQUITETURA/DWG | F40: RECEBIDO | G40: DWG Executivo Rev.02
B41: DUPLEX INFERIOR (3x) | C41: ARQUITETURA | F41: NÃO SE APLICA
...

Sheet Ger_Tec e Adm
A4: PROJETO: | C4: Electra Towers | I4: REVISÃO: | J4: DATA
A5: EMPRESA: | C5: Thozen | I5: R00
A6: GERENCIAMENTO EXECUTIVO
A7: Atalho | B7: NIVEL | C7: Item | D7: Descrição | E7: Unidade | F7: Quant. | G7: Preço un | H7: Total | I7: Considerações | J7: Situação
B8: CÉLULA CONSTRUTIVA | C8: 01 | D8: SERVIÇOS TÉCNICOS | H8: =H9+H57 -> 3668982.5
B9: ETAPA | C9: 01.001 | D9: ESTUDOS, PROJETOS E CONSULTORIAS | H9: =H10+H20+H41+H46 -> 2273047.4 | J9: -
B10: SUBETAPA | C10: 01.001.001 | D10: Estudos | H10: =H11+H12+H13+H14+H15+H16+H17+H18+H19 -> 260925.31
B11: SERVIÇO | C11: 01.001.001.001 | D11: Memorial descritivo | E11: vb | F11: 1 | G11: 18386.35 | H11: =G11*F11 -> 18386.35 | I11: Estimado | J11: Lançado ERP
B12: SERVIÇO | C12: 01.001.001.002 | D12: Levantamento topográfico | E12: vb | F12: 1 | G12: 3000 | H12: =G12*F12 -> 3000 | I12: Recebido | J12: Lançado ERP
B13: SERVIÇO | C13: 01.001.001.003 | D13: Estudo geológico | E13: vb | F13: 1 | G13: 26930.408 | H13: =G13*F13 -> 26930.408 | I13: Estimado | J13: Lançado ERP
B14: SERVIÇO | C14: 01.001.001.004 | D14: Estudo ambiental | E14: vb | F14: 1 | G14: 4500 | H14: =G14*F14 -> 4500 | I14: Recebido | J14: Lançado ERP
B15: SERVIÇO | C15: 01.001.001.005 | D15: Sondagem do terreno | E15: vb | F15: 1 | G15: 7947.99 | H15: =G15*F15 -> 7947.99 | I15: Recebido | J15: Lançado ERP
B16: SERVIÇO | C16: 01.001.001.006 | D16: Projeto de canteiro | E16: vb | F16: 1 | G16: 11160.563 | H16: =G16*F16 -> 11160.563 | I16: Estimado | J16: Lançado ERP
B17: SERVIÇO | C17: 01.001.001.007 | D17: EFEG - Teste de Carga | E17: vb | F17: 1 | G17: 29000 | H17: =G17*F17 -> 29000 | I17: Recebido | J17: Lançado ERP
B18: SERVIÇO | C18: 01.001.001.008 | D18: Solugeot - Teste de Carga | E18: vb | F18: 1 | G18: 140000 | H18: =G18*F18 -> 140000 | I18: Recebido | J18: Lançado ERP
B19: SERVIÇO | C19: 01.001.001.009 | D19: Concreto - Teste de Carga | E19: vb | F19: 1 | G19: 20000 | H19: =G19*F19 -> 20000 | I19: Recebido | J19: Lançado ERP
B20: SUBETAPA | C20: 01.001.002 | D20: Projetos | H20: =H21+H22+H23+H24+H25+H26+H27+H28+H29+H30+H31+H32+H33+H34+H35+H36+H37+H38+H39+H40 -> 1205079.2
B21: SERVIÇO | C21: 01.001.002.001 | D21: Legalização de incorporação | E21: vb | F21: 1 | G21: 67351.993 | H21: =G21*F21 -> 67351.993 | I21: Estimado | J21: Lançado ERP
B22: SERVIÇO | C22: 01.001.002.002 | D22: Projeto arquitetônico legal | E22: vb | F22: 1 | G22: 237000 | H22: =G22*F22 -> 237000 | I22: Recebido - Considerado junto desse projeto os valores de projeto arquitetônico legal + hidráulico + preventivo + elétrico + arquitetônico | J22: Lançado ERP
B23: SERVIÇO | C23: 01.001.002.003 | D23: Projeto Arquitetônico interiores | E23: vb | F23: 1 | G23: 86773.378 | H23: =G23*F23 -> 86773.378 | I23: Estimado | J23: Lançado ERP
B24: SERVIÇO | C24: 01.001.002.004 | D24: Projeto arquitetônico de fachada | E24: vb | F24: 1 | G24: 58250 | H24: =G24*F24 -> 58250 | I24: Recebido | J24: Lançado ERP
B25: SERVIÇO | C25: 01.001.002.005 | D25: Projeto técnico de fachada | E25: vb | F25: 1 | G25: 75145.12 | H25: =G25*F25 -> 75145.12 | I25: Estimado | J25: Lançado ERP
B26: SERVIÇO | C26: 01.001.002.006 | D26: Projeto de terraplanagem | E26: vb | F26: 1 | G26: 6962.4358 | H26: =G26*F26 -> 6962.4358 | I26: Estimado | J26: Lançado ERP
B27: SERVIÇO | C27: 01.001.002.007 | D27: Projeto estrutural | E27: vb | F27: 1 | G27: 70000 | H27: =G27*F27 -> 70000 | I27: Recebido - Considerado junto desse projeto os valores de projeto estrutural e fundação | J27: Lançado ERP
B28: SERVIÇO | C28: 01.001.002.008 | D28: Projeto de automação | E28: vb | F28: 1 | G28: 96720.281 | H28: =G28*F28 -> 96720.281 | I28: Estimado | J28: Lançado ERP
B29: SERVIÇO | C29: 01.001.002.009 | D29: Projeto de irrigação | E29: vb | F29: 1 | G29: 39550.22 | H29: =G29*F29 -> 39550.22 | I29: Estimado | J29: Lançado ERP
B30: SERVIÇO | C30: 01.001.002.010 | D30: Projeto preventivo (PPCI - Plano de Prevenção e Proteção Contra Incêndios) e Gás | E30: vb | F30: 1 | G30: 27354.018 | H30: =G30*F30 -> 27354.018 | I30: Estimado - Considerado somente o projeto de gás, pois o ppci, conforme informado no formulario, esta nicluso no arquitetônico | J30: Lançado ERP
B31: SERVIÇO | C31: 01.001.002.011 | D31: Projeto de climatização/exaustão | E31: vb | F31: 1 | G31: 91124.893 | H31: =G31*F31 -> 91124.893 | I31: Estimado | J31: Lançado ERP
B32: SERVIÇO | C32: 01.001.002.012 | D32: Projeto de Segurança | E32: vb | F32: 1 | G32: 24827.001 | H32: =G32*F32 -> 24827.001 | I32: Estimado | J32: Lançado ERP
... B40: SERVIÇO | C40: 01.001.002.020 | D40: Projeto de Paisagismo | E40: vb | F40: 1 | G40: 36770.652 | H40: =G40*F40 -> 36770.652 | I40: Estimado | J40: Lançado ERP
