Workbook

Sheet RESUMO
A1: ORÇAMENTO EXECUTIVO - NOW RESIDENCE
A2: Empreendimento: NOW Residence - Itajaí/SC
A3: Área Construída: 13,054.00 m²
A4: Data: 11/03/2026
A6: # | B6: Macrogrupo | C6: Valor Total (R$) | D6: R$/m² | E6: % do Total | F6: Observações
A7: 01 | B7: Infraestrutura | C7: ='INFRAESTRUTURA'!F100 | D7: =C7/13054 | E7: =C7/$C$17
A8: 02 | B8: Supraestrutura | C8: ='SUPRAESTRUTURA'!F100 | D8: =C8/13054 | E8: =C8/$C$18
A9: 03 | B9: Paredes e Vedações | C9: ='PAREDES E VEDAÇÕES'!F100 | D9: =C9/13054 | E9: =C9/$C$19
A10: 04 | B10: Revestimentos | C10: ='REVESTIMENTOS'!F100 | D10: =C10/13054 | E10: =C10/$C$20
A11: 05 | B11: Esquadrias | C11: ='ESQUADRIAS'!F100 | D11: =C11/13054 | E11: =C11/$C$21
A12: 06 | B12: Instalações Elétricas | C12: ='INSTALAÇÕES ELÉTRICAS'!F100 | D12: =C12/13054 | E12: =C12/$C$22
A13: 07 | B13: Instalações Hidrossanitárias | C13: ='INSTALAÇÕES HIDROSSANITÁRIAS'!F100 | D13: =C13/13054 | E13: =C13/$C$23
A14: 08 | B14: Instalações Especiais | C14: ='INSTALAÇÕES ESPECIAIS'!F100 | D14: =C14/13054 | E14: =C14/$C$24
A15: 09 | B15: Complementares | C15: ='COMPLEMENTARES'!F100 | D15: =C15/13054 | E15: =C15/$C$25
A16: 10 | B16: Custos Indiretos | C16: ='CUSTOS INDIRETOS'!F100 | D16: =C16/13054 | E16: =C16/$C$26
C17: =SUM(C7:C16) | D17: =C17/13054 | E17: 100,00%

Sheet INFRAESTRUTURA
A1: INFRAESTRUTURA
A2: Item | B2: Descrição | C2: Unidade | D2: Quantidade | E2: Preço Unitário (R$) | F2: Total (R$)
A3: 1.1 | B3: Canteiro de obras (instalação completa) | C3: vb | D3: 1 | E3: 85000 | F3: =D3*E3
A4: 1.2 | B4: Limpeza do terreno | C4: m² | D4: 1800 | E4: 4.5 | F4: =D4*E4
A5: 1.3 | B5: Demolições | C5: m³ | D5: 350 | E5: 95 | F5: =D5*E5
A6: 1.4 | B6: Locação da obra com gabaritos | C6: m² | D6: 13054 | E6: 2.8 | F6: =D6*E6
A7: SUBTOTAL - Serviços Preliminares | F7: =SUM(F3:F6)
A9: 2.1 | B9: Escavação mecanizada (subsolos) | C9: m³ | D9: 12500 | E9: 28.5 | F9: =D9*E9
A10: 2.2 | B10: Transporte de material escavado (DMT 15km) | C10: m³×km | D10: 187500 | E10: 1.85 | F10: =D10*E10
A11: 2.3 | B11: Reaterro compactado | C11: m³ | D11: 2800 | E11: 42 | F11: =D11*E11
A12: 2.4 | B12: Contenção - cortina atirantada | C12: m² | D12: 850 | E12: 580 | F12: =D12*E12
A13: SUBTOTAL - Movimento de Terra | F13: =SUM(F9:F12)
A15: 3.1 | B15: Estaca hélice contínua Ø40cm (h=12m) | C15: m | D15: 1680 | E15: 185 | F15: =D15*E15
A16: 3.2 | B16: Estaca hélice contínua Ø50cm (h=15m) | C16: m | D16: 2250 | E16: 245 | F16: =D16*E16
A17: 3.3 | B17: Bloco de coroamento concreto fck 30 MPa | C17: m³ | D17: 320 | E17: 890 | F17: =D17*E17
A18: 3.4 | B18: Armadura CA-50 em blocos | C18: kg | D18: 28800 | E18: 9.8 | F18: =D18*E18
A19: 3.5 | B19: Vigas baldrame concreto fck 30 MPa | C19: m³ | D19: 85 | E19: 920 | F19: =D19*E19
A20: 3.6 | B20: Armadura CA-50 em baldrames | C20: kg | D20: 7650 | E20: 9.8 | F20: =D20*E20
A21: 3.7 | B21: Impermeabilização de blocos e baldrames | C21: m² | D21: 1250 | E21: 68 | F21: =D21*E21
A22: SUBTOTAL - Fundações | F22: =SUM(F15:F21)
A24: 4.1 | B24: Dreno francês (tubo perfurado Ø100mm + brita + manta) | C24: m | D24: 420 | E24: 95 | F24: =D24*E24
A25: 4.2 | B25: Poço de recalque 2,0 × 2,0 × 3,0m | C25: un | D25: 2 | E25: 12500 | F25: =D25*E25
A26: 4.3 | B26: Bomba submersível 3CV (dupla) | C26: cj | D26: 2 | E26: 8500 | F26: =D26*E26
A27: 4.4 | B27: Tubulação drenagem pluvial PVC Ø150mm | C27: m | D27: 350 | E27: 48 | F27: =D27*E27
A28: SUBTOTAL - Drenagem | F28: =SUM(F24:F27)
F100: =F24+F29+F35+F43

Sheet SUPRAESTRUTURA
A1: SUPRAESTRUTURA (ESTRUTURA DE CONCRETO)
A2: Item | B2: Descrição | C2: Unidade | D2: Quantidade | E2: Preço Unitário (R$) | F2: Total (R$)
A3: 1.1 | B3: Concreto usinado fck 30 MPa (lajes e vigas) | C3: m³ | D3: 1650 | E3: 520 | F3: =D3*E3
A4: 1.2 | B4: Concreto usinado fck 35 MPa (pilares) | C4: m³ | D4: 480 | E4: 560 | F4: =D4*E4
A5: 1.3 | B5: Concreto usinado fck 35 MPa protendido (lajes) | C5: m³ | D5: 220 | E5: 680 | F5: =D5*E5
A6: 1.4 | B6: Lançamento, adensamento e cura | C6: m³ | D6: 2350 | E6: 75 | F6: =D6*E6
A7: SUBTOTAL - Concreto | F7: =SUM(F3:F6)
A9: 2.1 | B9: Forma metálica para lajes (3 usos) | C9: m² | D9: 15650 | E9: 42 | F9: =D9*E9
A10: 2.2 | B10: Forma metálica para vigas (3 usos) | C10: m² | D10: 3200 | E10: 58 | F10: =D10*E10
A11: 2.3 | B11: Forma metálica para pilares (3 usos) | C11: m² | D11: 2850 | E11: 65 | F11: =D11*E11
A12: 2.4 | B12: Escoramento metálico (aluguel) | C12: m²×mês | D12: 78250 | E12: 4.5 | F12: =D12*E12
A13: SUBTOTAL - Formas | F13: =SUM(F9:F12)
A15: 3.1 | B15: Aço CA-50 Ø 6,3 a 10mm | C15: kg | D15: 85000 | E15: 9.2 | F15: =D15*E15
A16: 3.2 | B16: Aço CA-50 Ø 12,5 a 20mm | C16: kg | D16: 95000 | E16: 8.9 | F16: =D16*E16
A17: 3.3 | B17: Aço CA-50 Ø 25 a 32mm | C17: kg | D17: 18000 | E17: 9.5 | F17: =D17*E17
A18: 3.4 | B18: Tela soldada Q138 (lajes) | C18: kg | D18: 2000 | E18: 8.5 | F18: =D18*E18
A19: 3.5 | B19: Corte, dobra e montagem de armadura | C19: kg | D19: 200000 | E19: 2.8 | F19: =D19*E19
A20: SUBTOTAL - Armadura | F20: =SUM(F15:F19)
A22: 4.1 | B22: Cordoalha de protensão CP-190 RB | C22: kg | D22: 3500 | E22: 18.5 | F22: =D22*E22
A23: 4.2 | B23: Ancoragens e dispositivos de protensão | C23: un | D23: 180 | E23: 450 | F23: =D23*E23
A24: 4.3 | B24: Serviço de protensão (equipamento + mão de obra) | C24: un | D24: 180 | E24: 320 | F24: =D24*E24
A25: SUBTOTAL - Protensão | F25: =SUM(F22:F24)
F100: =F0+F6+F12+F25

Sheet PAREDES E VEDAÇÕES
A1: PAREDES E VEDAÇÕES
A2: Item | B2: Descrição | C2: Unidade | D2: Quantidade | E2: Preço Unitário (R$) | F2: Total (R$)
A3: 1.1 | B3: Alvenaria blocos cerâmicos 14×19×29cm (fachada) | C3: m² | D3: 8500 | E3: 68 | F3: =D3*E3
A4: 1.2 | B4: Vergas e contravergas pré-moldadas | C4: m | D4: 1850 | E4: 28 | F4: =D4*E4
A5: 1.3 | B5: Encunhamento com argamassa expansiva | C5: m | D5: 4250 | E5: 12.5 | F5: =D5*E5
A6: SUBTOTAL - Alvenaria Externa | F6: =SUM(F3:F5)
A8: 2.1 | B8: Drywall parede simples 10cm (vedação) | C8: m² | D8: 18500 | E8: 78 | F8: =D8*E8
A9: 2.2 | B9: Drywall parede hidráulica 15cm (banheiros) | C9: m² | D9: 4200 | E9: 95 | F9: =D9*E9
A10: 2.3 | B10: Drywall parede acústica c/ lã mineral | C10: m² | D10: 2800 | E10: 125 | F10: =D10*E10
A11: 2.4 | B11: Reforço estrutural em drywall (vergas) | C11: m | D11: 850 | E11: 35 | F11: =D11*E11
A12: SUBTOTAL - Drywall Interno | F12: =SUM(F8:F11)
A14: 3.1 | B14: Alvenaria blocos cerâmicos 9cm (áreas comuns) | C14: m² | D14: 1850 | E14: 58 | F14: =D14*E14
A15: 3.2 | B15: Alvenaria bloco sical (escadas/shafts) | C15: m² | D15: 680 | E15: 95 | F15: =D15*E15
A16: 3.3 | B16: Vergas e contravergas concreto armado | C16: m | D16: 350 | E16: 42 | F16: =D16*E16
A17: SUBTOTAL - Alvenaria Áreas Comuns | F17: =SUM(F14:F16)
F100: =SUM(F4,F9,F14)

Sheet REVESTIMENTOS
A1: REVESTIMENTOS
A2: Item | B2: Descrição | C2: Unidade | D2: Quantidade | E2: Preço Unitário (R$) | F2: Total (R$)
A3: 1.1 | B3: Contrapiso regularizado e=5cm | C3: m² | D3: 13054 | E3: 45 | F3: =D3*E3
A4: 1.2 | B4: Piso laminado AC4 salas/dormitórios | C4: m² | D4: 5800 | E4: 85 | F4: =D4*E4
A5: 1.3 | B5: Porcelanato 60×60cm PEI4 cozinhas/serviço | C5: m² | D5: 2200 | E5: 95 | F5: =D5*E5
A6: 1.4 | B6: Porcelanato 60×60cm PEI4 banheiros | C6: m² | D6: 1850 | E6: 105 | F6: =D6*E6
A7: 1.5 | B7: Porcelanato 80×80cm PEI5 áreas comuns | C7: m² | D7: 1650 | E7: 135 | F7: =D7*E7
A8: 1.6 | B8: Rodapé MDF/porcelanato h=7cm | C8: m | D8: 8500 | E8: 18 | F8: =D8*E8
A9: SUBTOTAL - Pisos Internos | F9: =SUM(F3:F8)
A11: 2.1 | B11: Massa corrida PVA + pintura acrílica fosca | C11: m² | D11: 28000 | E11: 35 | F11: =D11*E11
A12: 2.2 | B12: Cerâmica/porcelanato 30×60cm cozinhas | C12: m² | D12: 1850 | E12: 85 | F12: =D12*E12
A13: 2.3 | B13: Cerâmica/porcelanato 30×60cm banheiros (teto) | C13: m² | D13: 4200 | E13: 88 | F13: =D13*E13
A14: SUBTOTAL - Revestimentos Internos Paredes | F14: =SUM(F11:F13)
A16: 3.1 | B16: Tijolinho aparente 5,5×24cm | C16: m² | D16: 890 | E16: 185 | F16: =D16*E16
A17: 3.2 | B17: Ripado madeira cumaru/WPC | C17: m² | D17: 475 | E17: 320 | F17: =D17*E17
A18: 3.3 | B18: Peitoril concreto/granito c/ pingadeira | C18: m | D18: 800 | E18: 95 | F18: =D18*E18
A19: 3.4 | B19: Reboco + textura acrílica fachada | C19: m² | D19: 2400 | E19: 68 | F19: =D19*E19
A20: SUBTOTAL - Fachada | F20: =SUM(F16:F19)
A22: 4.1 | B22: Forro gesso acartonado liso + pintura | C22: m² | D22: 9500 | E22: 85 | F22: =D22*E22
A23: 4.2 | B23: Forro PVC áreas molhadas | C23: m² | D23: 850 | E23: 68 | F23: =D23*E23
A24: 4.3 | B24: Sanca de gesso para iluminação | C24: m | D24: 1200 | E24: 45 | F24: =D24*E24
A25: SUBTOTAL - Forros | F25: =SUM(F22:F24)
F100: =SUM(F10,F15,F21,F26)

Sheet ESQUADRIAS
A1: ESQUADRIAS
A2: Item | B2: Descrição | C2: Unidade | D2: Quantidade | E2: Preço Unitário (R$) | F2: Total (R$)
A3: 1.1 | B3: Porta correr alumínio 4 folhas 4,00×2,10m + vidro | C3: un | D3: 136 | E3: 3800 | F3: =D3*E3
A4: 1.2 | B4: Porta correr alumínio 2 folhas 2,00×2,10m + vidro | C4: un | D4: 136 | E4: 2200 | F4: =D4*E4
A5: 1.3 | B5: Janela correr alumínio 2 folhas 1,50×1,20m + vidro | C5: un | D5: 272 | E5: 850 | F5: =D5*E5
A6: 1.4 | B6: Janela basculante alumínio 0,80×0,60m + vidro | C6: un | D6: 204 | E6: 420 | F6: =D6*E6
A7: SUBTOTAL - Esquadrias Alumínio | F7: =SUM(F3:F6)
A9: 2.1 | B9: Porta entrada apto madeira 0,90×2,10m + fechadura seg. | C9: un | D9: 136 | E9: 1850 | F9: =D9*E9
A10: 2.2 | B10: Porta interna semi-oca 0,80×2,10m + fechadura | C10: un | D10: 408 | E10: 680 | F10: =D10*E10
A11: 2.3 | B11: Porta interna semi-oca 0,70×2,10m + fechadura | C11: un | D11: 272 | E11: 620 | F11: =D11*E11
A12: 2.4 | B12: Marcos e guarnições madeira/MDF | C12: cj | D12: 816 | E12: 180 | F12: =D12*E12
A13: SUBTOTAL - Portas Madeira | F13: =SUM(F9:F12)
A15: 3.1 | B15: Guarda-corpo vidro laminado 10mm h=1,05m + inox | C15: m | D15: 800 | E15: 580 | F15: =D15*E15
A16: 3.2 | B16: Guarda-corpo escadas aço tubular pintado | C16: m | D16: 185 | E16: 320 | F16: =D16*E16
A17: SUBTOTAL - Guarda-Corpos | F17: =SUM(F15:F16)
A19: 4.1 | B19: Portão garagem basculante motorizado 4,50×2,50m | C19: un | D19: 2 | E19: 8500 | F19: =D19*E19
A20: 4.2 | B20: Porta corta-fogo P-90 c/ barra antipânico | C20: un | D20: 6 | E20: 4200 | F20: =D20*E20
A21: 4.3 | B21: Gradil metálico tubular pintado | C21: m² | D21: 45 | E21: 420 | F21: =D21*E21
A22: SUBTOTAL - Portas Especiais | F22: =SUM(F19:F21)
F100: =SUM(F8,F14,F18,F23)

Sheet INSTALAÇÕES ELÉTRICAS
A1: INSTALAÇÕES ELÉTRICAS
A2: Item | B2: Descrição | C2: Unidade | D2: Quantidade | E2: Preço Unitário (R$) | F2: Total (R$)
A3: 1.1 | B3: Subestação transformador a seco 630 kVA | C3: un | D3: 1 | E3: 185000 | F3: =D3*E3
A4: 1.2 | B4: Quadro geral baixa tensão (QGD) | C4: un | D4: 1 | E4: 45000 | F4: =D4*E4
A5: 1.3 | B5: Ramal entrada média tensão 13,8kV | C5: m | D5: 35 | E5: 850 | F5: =D5*E5
A6: SUBTOTAL - Entrada e Transformação | F6: =SUM(F3:F5)
A8: 2.1 | B8: Quadro distribuição 40×60×12cm c/ disjuntores | C8: un | D8: 68 | E8: 1200 | F8: =D8*E8
A9: 2.2 | B9: Quadro distribuição 60×80×12cm c/ disjuntores | C9: un | D9: 34 | E9: 2200 | F9: =D9*E9
A10: 2.3 | B10: Quadro distribuição 30×30×12cm c/ disjuntores | C10: un | D10: 12 | E10: 850 | F10: =D10*E10
A11: 2.4 | B11: Quadros diversos (QD01, QMC, QGE, QF) | C11: un | D11: 105 | E11: 680 | F11: =D11*E11
A12: SUBTOTAL - Quadros Elétricos | F12: =SUM(F8:F11)
A14: 3.1 | B14: Eletroduto PVC flexível Ø3/4" | C14: m | D14: 58740 | E14: 4.2 | F14: =D14*E14
A15: 3.2 | B15: Eletroduto PVC rígido Ø1" | C15: m | D15: 26108 | E15: 8.5 | F15: =D15*E15
A16: 3.3 | B16: Eletroduto PVC rígido Ø1.1/4" | C16: m | D16: 19581 | E16: 12 | F16: =D16*E16
A17: 3.4 | B17: Eletrocalha 100×50mm c/ acessórios | C17: m | D17: 850 | E17: 45 | F17: =D17*E17
A18: 3.5 | B18: Caixa octogonal 4×4" (luz) | C18: un | D18: 3500 | E18: 8.5 | F18: =D18*E18
A19: 3.6 | B19: Caixa retangular 4×2" (tomada/interruptor) | C19: un | D19: 6200 | E19: 6.8 | F19: =D19*E19
A20: SUBTOTAL - Eletrodutos e Caixas | F20: =SUM(F14:F19)
A22: 4.1 | B22: Cabo flexível 1,5mm² (iluminação) | C22: m | D22: 95000 | E22: 1.85 | F22: =D22*E22
A23: 4.2 | B23: Cabo flexível 2,5mm² (TUG) | C23: m | D23: 145000 | E23: 2.8 | F23: =D23*E23
A24: 4.3 | B24: Cabo flexível 4,0mm² (TUE) | C24: m | D24: 52000 | E24: 4.5 | F24: =D24*E24
A25: 4.4 | B25: Cabo flexível 6,0mm² | C25: m | D25: 26000 | E25: 6.2 | F25: =D25*E25
A26: 4.5 | B26: Cabo flexível 10,0mm² | C26: m | D26: 13000 | E26: 9.8 | F26: =D26*E26
A27: 4.6 | B27: Cabo flexível 16,0mm² | C27: m | D27: 7800 | E27: 15.5 | F27: =D27*E27
A28: SUBTOTAL - Cabos Condutores | F28: =SUM(F22:F27)
A30: 5.1 | B30: Ponto de luz c/ lâmpada LED 9W | C30: un | D30: 3500 | E30: 85 | F30: =D30*E30
A31: 5.2 | B31: Tomada 2P+T 10A padrão brasileiro | C31: un | D31: 2500 | E31: 35 | F31: =D31*E31
A32: 5.3 | B32: Tomada 2P+T 20A (TUE) | C32: un | D32: 1440 | E32: 48 | F32: =D32*E32
A33: 5.4 | B33: Interruptor simples/paralelo/intermediário | C33: un | D33: 2220 | E33: 28 | F33: =D33*E33
A34: SUBTOTAL - Pontos de Utilização | F34: =SUM(F30:F33)
F100: =SUM(F7,F13,F21,F29,F35)

Sheet INSTALAÇÕES HIDROSSANITÁRIAS
A1: INSTALAÇÕES HIDROSSANITÁRIAS
A2: Item | B2: Descrição | C2: Unidade | D2: Quantidade | E2: Preço Unitário (R$) | F2: Total (R$)
A3: 1.1 | B3: Reservatório superior fibra 75m³ | C3: un | D3: 2 | E3: 28000 | F3: =D3*E3
A4: 1.2 | B4: Reservatório inferior concreto 75m³ | C4: un | D4: 2 | E4: 45000 | F4: =D4*E4
A5: 1.3 | B5: Conjunto pressurizador 7,5CV | C5: un | D5: 1 | E5: 18500 | F5: =D5*E5
A6: 1.4 | B6: Bomba recalque 5CV (dupla) | C6: cj | D6: 1 | E6: 12000 | F6: =D6*E6
A7: 1.5 | B7: Tubulação PVC DN 100mm | C7: m | D7: 95 | E7: 85 | F7: =D7*E7
A8: 1.6 | B8: Tubulação PVC DN 50mm | C8: m | D8: 1300 | E8: 32 | F8: =D8*E8
A9: 1.7 | B9: Tubulação PVC/PEX DN 25mm | C9: m | D9: 13000 | E9: 18 | F9: =D9*E9
A10: 1.8 | B10: Tubulação PVC/PEX DN 20mm | C10: m | D10: 26000 | E10: 14.5 | F10: =D10*E10
A11: 1.9 | B11: Registros, válvulas e conexões | C11: vb | D11: 1 | E11: 85000 | F11: =D11*E11
A12: SUBTOTAL - Água Fria | F12: =SUM(F3:F11)
A14: 2.1 | B14: Tubulação PVC esgoto Ø100mm | C14: m | D14: 6500 | E14: 38 | F14: =D14*E14
A15: 2.2 | B15: Tubulação PVC esgoto Ø75mm | C15: m | D15: 3900 | E15: 28 | F15: =D15*E15
A16: 2.3 | B16: Tubulação PVC esgoto Ø50mm | C16: m | D16: 7800 | E16: 18 | F16: =D16*E16
A17: 2.4 | B17: Tubulação PVC esgoto Ø40mm | C17: m | D17: 13000 | E17: 12 | F17: =D17*E17
A18: 2.5 | B18: Caixa sifonada 100×150×50mm | C18: un | D18: 884 | E18: 45 | F18: =D18*E18
A19: 2.6 | B19: Caixa de inspeção 60×60cm | C19: un | D19: 35 | E19: 280 | F19: =D19*E19
A20: 2.7 | B20: Bomba submersível esgoto 3CV (dupla) | C20: cj | D20: 1 | E20: 15000 | F20: =D20*E20
A21: SUBTOTAL - Esgoto Sanitário | F21: =SUM(F14:F20)
A23: 3.1 | B23: Tubulação PVC Ø150mm (prumadas) | C23: m | D23: 650 | E23: 62 | F23: =D23*E23
A24: 3.2 | B24: Tubulação PVC Ø100mm (coletores) | C24: m | D24: 1950 | E24: 42 | F24: =D24*E24
A25: 3.3 | B25: Calha chapa galvanizada #24 | C25: m | D25: 280 | E25: 85 | F25: =D25*E25
A26: 3.4 | B26: Ralos pluviais DN 100mm | C26: un | D26: 189 | E26: 65 | F26: =D26*E26
A27: 3.5 | B27: Caixa de areia 80×80cm | C27: un | D27: 6 | E27: 420 | F27: =D27*E27
A28: SUBTOTAL - Águas Pluviais | F28: =SUM(F23:F27)
A30: 4.1 | B30: Aquecedor elétrico 60L | C30: un | D30: 85 | E30: 980 | F30: =D30*E30
A31: 4.2 | B31: Aquecedor gás 12L/min | C31: un | D31: 51 | E31: 1850 | F31: =D31*E31
A32: 4.3 | B32: Tubulação cobre/PEX DN 25mm | C32: m | D32: 5200 | E32: 28 | F32: =D32*E32
A33: 4.4 | B33: Tubulação cobre/PEX DN 20mm | C33: m | D33: 7800 | E33: 22 | F33: =D33*E33
A34: SUBTOTAL - Água Quente | F34: =SUM(F30:F33)
A36: 5.1 | B36: Tanque GLP 1.900kg P190 | C36: un | D36: 2 | E36: 18500 | F36: =D36*E36
A37: 5.2 | B37: Regulador pressão 1º estágio 90kg/h | C37: un | D37: 2 | E37: 2800 | F37: =D37*E37
A38: 5.3 | B38: Regulador pressão 2º estágio 45kg/h | C38: un | D38: 17 | E38: 850 | F38: =D38*E38
A39: 5.4 | B39: Tubulação cobre DN 32mm (prumadas) | C39: m | D39: 650 | E39: 42 | F39: =D39*E39
A40: 5.5 | B40: Tubulação cobre DN 20mm (ramais) | C40: m | D40: 2600 | E40: 28 | F40: =D40*E40
A41: 5.6 | B41: Tubulação cobre DN 15mm (sub-ramais) | C41: m | D41: 3900 | E41: 22 | F41: =D41*E41
A42: SUBTOTAL - Gás GLP | F42: =SUM(F36:F41)
A44: 6.1 | B44: Bacia sanitária c/ caixa acoplada | C44: un | D44: 272 | E44: 520 | F44: =D44*E44
A45: 6.2 | B45: Lavatório suspenso c/ coluna | C45: un | D45: 272 | E45: 380 | F45: =D45*E45
...

Sheet INSTALAÇÕES ESPECIAIS
A1: INSTALAÇÕES ESPECIAIS
A2: Item | B2: Descrição | C2: Unidade | D2: Quantidade | E2: Preço Unitário (R$) | F2: Total (R$)
A3: 1.1 | B3: Sistema de hidrantes e mangotinhos completo | C3: un | D3: 1 | E3: 185000 | F3: =D3*E3
A4: 1.2 | B4: Reservatório incêndio 40m³ | C4: un | D4: 1 | E4: 35000 | F4: =D4*E4
A5: 1.3 | B5: Casa bombas incêndio (principal + jockey) | C5: cj | D5: 1 | E5: 65000 | F5: =D5*E5
A6: 1.4 | B6: Sistema detecção/alarme de incêndio | C6: un | D6: 1 | E6: 48000 | F6: =D6*E6
A7: 1.5 | B7: Extintores portáteis (AP, PQS, CO2) | C7: un | D7: 85 | E7: 320 | F7: =D7*E7
A8: 1.6 | B8: Iluminação emergência (luminárias autônomas) | C8: un | D8: 180 | E8: 280 | F8: =D8*E8
A9: 1.7 | B9: Sinalização fotoluminescente | C9: cj | D9: 1 | E9: 12000 | F9: =D9*E9
A10: 1.8 | B10: Portas corta-fogo P-90 c/ barra antipânico | C10: un | D10: 6 | E10: 4200 | F10: =D10*E10
A11: SUBTOTAL - PPCI | F11: =SUM(F3:F10)
A13: 2.1 | B13: Elevador social 800kg 1,5m/s (2 un) | C13: cj | D13: 2 | E13: 185000 | F13: =D13*E13
A14: 2.2 | B14: Elevador emergência 800kg 1,0m/s | C14: un | D14: 1 | E14: 220000 | F14: =D14*E14
A15: 2.3 | B15: Casa de máquinas (estrutura + acabamento) | C15: un | D15: 1 | E15: 45000 | F15: =D15*E15
A16: SUBTOTAL - Elevadores | F16: =SUM(F13:F15)
A18: 3.1 | B18: Infraestrutura cabeamento estruturado | C18: un | D18: 1 | E18: 28000 | F18: =D18*E18
A19: 3.2 | B19: Rede interna telefonia + internet | C19: un | D19: 136 | E19: 850 | F19: =D19*E19
A20: 3.3 | B20: Antena coletiva TV + distribuição | C20: un | D20: 1 | E20: 18500 | F20: =D20*E20
A21: 3.4 | B21: Infraestrutura automação residencial | C21: un | D21: 136 | E21: 450 | F21: =D21*E21
A22: SUBTOTAL - Telecomunicações | F22: =SUM(F18:F21)
A24: 4.1 | B24: Sistema CFTV (câmeras IP + NVR) | C24: un | D24: 1 | E24: 42000 | F24: =D24*E24
A25: 4.2 | B25: Câmeras IP Full HD | C25: un | D25: 28 | E25: 850 | F25: =D25*E25
A26: 4.3 | B26: Sistema controle acesso (portaria + garagens) | C26: un | D26: 1 | E26: 28000 | F26: =D26*E26
A27: 4.4 | B27: Vídeo porteiro (central + ramais) | C27: cj | D27: 1 | E27: 35000 | F27: =D27*E27
A28: SUBTOTAL - CFTV e Controle Acesso | F28: =SUM(F24:F27)
F100: =SUM(F12,F17,F23,F29)

Sheet COMPLEMENTARES
A1: COMPLEMENTARES
A2: Item | B2: Descrição | C2: Unidade | D2: Quantidade | E2: Preço Unitário (R$) | F2: Total (R$)
A3: 1.1 | B3: Impermeabilização banheiros (manta/polimérico) | C3: m² | D3: 4200 | E3: 85 | F3: =D3*E3
A4: 1.2 | B4: Impermeabilização cozinhas/áreas serviço | C4: m² | D4: 2200 | E4: 68 | F4: =D4*E4
A5: 1.3 | B5: Impermeabilização piscina (manta 4mm) | C5: m² | D5: 120 | E5: 180 | F5: =D5*E5
A6: 1.4 | B6: Impermeabilização laje cobertura (manta 4mm) | C6: m² | D6: 450 | E6: 165 | F6: =D6*E6
A7: 1.5 | B7: Impermeabilização reservatórios | C7: m² | D7: 280 | E7: 125 | F7: =D7*E7
A8: 1.6 | B8: Impermeabilização jardineiras fachada | C8: m² | D8: 85 | E8: 145 | F8: =D8*E8
A9: SUBTOTAL - Impermeabilização | F9: =SUM(F3:F8)
A11: 2.1 | B11: Projeto paisagismo executivo | C11: vb | D11: 1 | E11: 18000 | F11: =D11*E11
A12: 2.2 | B12: Grama natural esmeralda + plantio | C12: m² | D12: 280 | E12: 35 | F12: =D12*E12
A13: 2.3 | B13: Plantas ornamentais (palmeiras, arbustos) | C13: un | D13: 180 | E13: 220 | F13: =D13*E13
A14: 2.4 | B14: Sistema irrigação automatizado | C14: un | D14: 1 | E14: 12500 | F14: =D14*E14
A15: 2.5 | B15: Iluminação jardim (balizadores LED) | C15: un | D15: 45 | E15: 280 | F15: =D15*E15
A16: SUBTOTAL - Paisagismo | F16: =SUM(F11:F15)
A18: 3.1 | B18: Piscina estrutura + revestimento pastilha | C18: m² | D18: 38 | E18: 2800 | F18: =D18*E18
A19: 3.2 | B19: Deck madeira plástica WPC | C19: m² | D19: 68 | E19: 420 | F19: =D19*E19
A20: 3.3 | B20: Iluminação subaquática LED RGB | C20: un | D20: 8 | E20: 850 | F20: =D20*E20
A21: 3.4 | B21: Sistema filtragem e tratamento | C21: cj | D21: 1 | E21: 18500 | F21: =D21*E21
A22: 3.5 | B22: Playground (piso EPDM + brinquedos) | C22: cj | D22: 1 | E22: 45000 | F22: =D22*E22
A23: 3.6 | B23: Equipamentos academia | C23: cj | D23: 1 | E23: 85000 | F23: =D23*E23
A24: 3.7 | B24: Sauna seca (estrutura + acabamento) | C24: un | D24: 1 | E24: 28000 | F24: =D24*E24
A25: SUBTOTAL - Piscina e Lazer | F25: =SUM(F18:F24)
A27: 4.1 | B27: Limpeza fina pós-obra (unidades) | C27: m² | D27: 13054 | E27: 8.5 | F27: =D27*E27
A28: 4.2 | B28: Limpeza vidros e esquadrias | C28: m² | D28: 4500 | E28: 12 | F28: =D28*E28
A29: 4.3 | B29: Polimento pisos porcelanato | C29: m² | D29: 2800 | E29: 18 | F29: =D29*E29
A30: 4.4 | B30: Retirada entulho e resíduos finais | C30: m³ | D30: 85 | E30: 95 | F30: =D30*E30
A31: SUBTOTAL - Limpeza Final | F31: =SUM(F27:F30)
F100: =SUM(F10,F17,F26,F32)

Sheet CUSTOS INDIRETOS
A1: CUSTOS INDIRETOS
A2: Item | B2: Descrição | C2: Unidade | D2: Quantidade | E2: Preço Unitário (R$) | F2: Total (R$)
A3: 1.1 | B3: Engenheiro residente (30 meses) | C3: mês | D3: 30 | E3: 18500 | F3: =D3*E3
A4: 1.2 | B4: Mestre de obras (30 meses) | C4: mês | D4: 30 | E4: 8500 | F4: =D4*E4
A5: 1.3 | B5: Técnico segurança trabalho (30 meses) | C5: mês | D5: 30 | E5: 7200 | F5: =D5*E5
A6: 1.4 | B6: Auxiliar administrativo (30 meses) | C6: mês | D6: 30 | E6: 4500 | F6: =D6*E6
A7: 1.5 | B7: Estagiário engenharia (24 meses) | C7: mês | D7: 24 | E7: 2200 | F7: =D7*E7
A8: SUBTOTAL - Administração Obra | F8: =SUM(F3:F7)
A10: 2.1 | B10: Manutenção canteiro (água, luz, telefone) | C10: mês | D10: 30 | E10: 4800 | F10: =D10*E10
A11: 2.2 | B11: Aluguel grua (torre) 30 meses | C11: mês | D11: 30 | E11: 28000 | F11: =D11*E11
A12: 2.3 | B12: Elevador cremalheira (24 meses) | C12: mês | D12: 24 | E12: 12500 | F12: =D12*E12
A13: 2.4 | B13: Betoneira, serra, vibrador (diversos) | C13: vb | D13: 1 | E13: 45000 | F13: =D13*E13
A14: 2.5 | B14: Ferramentas e EPI | C14: vb | D14: 1 | E14: 28000 | F14: =D14*E14
A15: SUBTOTAL - Canteiro e Equipamentos | F15: =SUM(F10:F14)
A17: 3.1 | B17: Projeto estrutural executivo | C17: vb | D17: 1 | E17: 95000 | F17: =D17*E17
A18: 3.2 | B18: Projetos instalações (elétrica, hidro, gás) | C18: vb | D18: 1 | E18: 85000 | F18: =D18*E18
A19: 3.3 | B19: Projeto PPCI + AVCB | C19: vb | D19: 1 | E19: 28000 | F19: =D19*E19
A20: 3.4 | B20: Coordenação BIM e compatibilização | C20: vb | D20: 1 | E20: 48000 | F20: =D20*E20
A21: 3.5 | B21: Consultoria geotécnica (sondagem + fundações) | C21: vb | D21: 1 | E21: 22000 | F21: =D21*E21
A22: 3.6 | B22: Consultoria estrutura (acompanhamento protensão) | C22: vb | D22: 1 | E22: 18000 | F22: =D22*E22
A23: SUBTOTAL - Projetos e Consultorias | F23: =SUM(F17:F22)
A25: 4.1 | B25: Taxa aprovação prefeitura (habite-se) | C25: vb | D25: 1 | E25: 28000 | F25: =D25*E25
A26: 4.2 | B26: Taxa AVCB corpo de bombeiros | C26: vb | D26: 1 | E26: 8500 | F26: =D26*E26
A27: 4.3 | B27: ART/RRT projetos e execução | C27: vb | D27: 1 | E27: 12000 | F27: =D27*E27
A28: 4.4 | B28: Seguro obra (risco engenharia) | C28: vb | D28: 1 | E28: 95000 | F28: =D28*E28
A29: 4.5 | B29: Ensaios tecnológicos (concreto, solo, aço) | C29: vb | D29: 1 | E29: 38000 | F29: =D29*E29
A30: SUBTOTAL - Taxas e Seguros | F30: =SUM(F25:F29)
F100: =SUM(F9,F16,F24,F31)
