Workbook
Name \0: #REF!
Name \0: #REF!
Name \1: #REF!
Name \a: #REF!
Name \a: #REF!
Name \b: #REF!
Name \c: #REF!
Name \d: #REF!
Name \e: #REF!
Name \i: #REF!
Name \J: #REF!
Name \k: #REF!
Name \l: #N/A
Name \m: #REF!
Name \m: #REF!
Name \o: #REF!
Name \p: #REF!
Name \r: #REF!
Name \T: #REF!
Name \z: #REF!
Name _: #REF!
Name _: #REF!
Name _: #REF!
Name _: #REF!
Name _: #REF!
Name _: #REF!
Name _\0: #REF!
Name _\1: #REF!
Name _\a: #REF!
Name _\b: #REF!
Name _\c: #REF!
Name _\d: #REF!
Name _\e: #REF!
Name _\i: #REF!
Name _\J: #REF!
Name _\k: #REF!
Name _\l: #N/A
Name _\m: #REF!
Name _\o: #REF!
Name _\p: #REF!
Name _\r: #REF!
Name _\T: #REF!
Name _\z: #REF!
Name __: #REF!
Name __: #REF!
Name __: #REF!
Name __: #REF!
Name __: #REF!
Name __: #REF!
Name ______ACR10: #REF!
Name ______ACR10: #REF!
Name ______ACR10: #REF!
Name ______ACR10: #REF!
Name ______ACR10: #REF!
Name ______ACR10: #REF!
Name ______ACR10: #REF!
Name ______ACR15: #REF!
Name ______ACR15: #REF!
Name ______ACR15: #REF!
Name ______ACR15: #REF!

Sheet Obra 
C1: Projeto | D1: Aquos Oasis Home
C2: Empresa | D2: Blue Heaven
C3: Revisão | D3: R02
A4: QUADRO DE ÁREAS
B6: Descrição | C6: Unidade | E6: Quantidade | G6: Imagens
B7: MESES DE OBRA | C7: MÊS | E7: 36
B8: ÁREA DO TERRENO | C8: M² | E8: 4960
B9: ÁREA CONSTRUÍDA | C9: M² | E9: 9522.33
B10: NÚMERO DE UNIDADES HABITACIONAIS | C10: UN | E10: 12
B11: NÚMERO DE UNIDADES COMERCIAIS | C11: UN | E11: 0
B12: ÁREA PRIVATIVA | C12: M²
B13: TAXA DE ADMINISTRAÇÃO | C13: % | E13: 8
B14: NÚMERO DE PAVIMENTOS | C14: UN | E14: 4
B16: ETAPA | C16: VALOR ORÇADO | D16: % | E16: VALOR / m²
B17: PROJETOS, GERENCIAMENTO TÉCNICO E ADMINISTRATIVO | C17: ='PROJETOS E GERENCIAMENTO TÉCNIC'!N139 -> 15741908 | D17: =C17/C$35 -> 0.21878717 | E17: =C17/$E$9 -> 1653.1572
B18: MOVIMENTAÇÃO DE TERRA | C18: ='GERENCIAMENTO EXECUTIVO'!N8 -> 916556.25 | D18: =C18/C$35 -> 0.012738656 | E18: =C18/$E$9 -> 96.253359
B19: INFRAESTRUTURA | C19: ='GERENCIAMENTO EXECUTIVO'!N21 -> 3853368.6 | D19: =C19/C$35 -> 0.053555617 | E19: =C19/$E$9 -> 404.66657
B20: CONTENÇÃO | C20: ='GERENCIAMENTO EXECUTIVO'!N44 -> 1690469.1 | D20: =C20/C$35 -> 0.023494798 | E20: =C20/$E$9 -> 177.52684
B21: SUPRAESTRUTURA | C21: ='GERENCIAMENTO EXECUTIVO'!N75 -> 16111863 | D21: =C21/C$35 -> 0.22392894 | E21: =C21/$E$9 -> 1692.0084
B22: ALVENARIA | C22: ='GERENCIAMENTO EXECUTIVO'!N95 -> 1740103.1 | D22: =C22/C$35 -> 0.024184631 | E22: =C22/$E$9 -> 182.73922
B23: INSTALAÇÕES ELÉTRICAS, HIDRÁULICAS, GLP E PREVENTIVAS | C23: ='GERENCIAMENTO EXECUTIVO'!N143+'GERENCIAMENTO EXECUTIVO'!N154+'GERENCIAMENTO EXECUTIVO'!N170+'GERENCIAMENTO EXECUTIVO'!N175 -> 2919086.7 | D23: =C23/C$35 -> 0.040570604 | E23: =C23/$E$9 -> 306.55172
B24: EQUIPAMENTOS E SISTEMAS ESPECIAIS | C24: ='GERENCIAMENTO EXECUTIVO'!N180+'GERENCIAMENTO EXECUTIVO'!N188+'GERENCIAMENTO EXECUTIVO'!N205 -> 4931746 | D24: =C24/C$35 -> 0.068543326 | E24: =C24/$E$9 -> 517.91379
B25: IMPERMEABILIZAÇÃO | C25: ='GERENCIAMENTO EXECUTIVO'!N124 -> 492633.42 | D25: =C25/C$35 -> 0.0068468111 | E25: =C25/$E$9 -> 51.734546
B26: REVESTIMENTOS INTERNOS DE PAREDE | C26: ='GERENCIAMENTO EXECUTIVO'!N215 -> 2845090.3 | D26: =C26/C$35 -> 0.039542173 | E26: =C26/$E$9 -> 298.7809
B27: ACABAMENTOS INTERNOS EM TETO | C27: ='GERENCIAMENTO EXECUTIVO'!N230 -> 410937.08 | D27: =C27/C$35 -> 0.0057113636 | E27: =C27/$E$9 -> 43.155098
B28: PISOS E PAVIMENTAÇÕES | C28: ='GERENCIAMENTO EXECUTIVO'!N241 -> 3371304 | D28: =C28/C$35 -> 0.046855696 | E28: =C28/$E$9 -> 354.04192
B29: PINTURA INTERNA | C29: ='GERENCIAMENTO EXECUTIVO'!N285 -> 1519511.5 | D29: =C29/C$35 -> 0.021118762 | E29: =C29/$E$9 -> 159.57349
B30: ESQUADRIAS, VIDROS E FERRAGENS | C30: ='GERENCIAMENTO EXECUTIVO'!N301 -> 7296949.6 | D30: =C30/C$35 -> 0.10141585 | E30: =C30/$E$9 -> 766.29875
B31: LOUÇAS E METAIS | C31: ='GERENCIAMENTO EXECUTIVO'!N338 -> 118662.06 | D31: =C31/C$35 -> 0.0016492115 | E31: =C31/$E$9 -> 12.461452
B32: REVESTIMENTOS E ACABAMENTOS DE FACHADA | C32: ='GERENCIAMENTO EXECUTIVO'!N342 -> 4023627.8 | D32: =C32/C$35 -> 0.055921947 | E32: =C32/$E$9 -> 422.54657
B33: SERVIÇOS COMPLEMENTARES | C33: ='GERENCIAMENTO EXECUTIVO'!N357 -> 2864831.5 | D33: =C33/C$35 -> 0.039816544 | E33: =C33/$E$9 -> 300.85405
B34: IMPREVISTOS E CONTINGÊNCIAS | C34: ='GERENCIAMENTO EXECUTIVO'!N375 -> 1102134.8 | D34: =C34/C$35 -> 0.015317899 | E34: =C34/$E$9 -> 115.74213
B35: TOTAL | C35: =SUM(C17:C34) -> 71950782 | D35: =SUM(D17:D34) -> 1 | E35: =SUM(E17:E34) -> 7556.006
B36: CUB/SC | C36: 2887.91 | D36: 45658 | E36: =ROUND(+E35/C36,2)&" CUB" -> 2,62 CUB
B38: Tx adm | C38: 65409802 | D38: custo total sem taxa adm
C39: =C38*0.1 -> 6540980.2 | D39: custo taxa adm
C41: =C38+C39 -> 71950782 | D41: conferencia

Sheet Comparativo
C1: PRELIMINAR - R02 | F1: PRELIMINAR - R01 | I1: PRELIMINAR - R00 | L1: DIFERENÇA | N1: PARAMÉTRICO - R01 | Q1: PARAMÉTRICO - R01 | T1: DIFERENÇA
B2: ETAPA | C2: VALOR ORÇADO | D2: % | E2: VALOR / m² | F2: VALOR ORÇADO | G2: % | H2: VALOR / m² | I2: VALOR ORÇADO | J2: % | K2: VALOR / m² | L2: VALOR ORÇADO | M2: VALOR / m² | N2: VALOR ORÇADO | O2: % | P2: VALOR / m² | Q2: VALOR ORÇADO | R2: % | S2: VALOR / m² | T2: VALOR ORÇADO | U2: VALOR / m²
B3: GERENCIAMENTO TÉCNICO E ADMINISTRATIVO | C3: ='Obra '!$C17 -> 15741908 | D3: =C3/C$20 -> 0.21878717 | E3: =C3/Comparativo!$AA$4 -> 1653.1572 | F3: 14366827 | G3: =F3/F$20 -> 0.20444574 | H3: =F3/Comparativo!$AA$4 -> 1508.7512 | I3: 14918807 | J3: =I3/I$20 -> 0.22069607 | K3: =I3/Comparativo!$AA$4 -> 1566.7181 | L3: =C3-F3 -> 1375081.4 | M3: =E3-H3 -> 144.40598 | N3: 14269425 | O3: =N3/N$20 -> 0.20812141 | P3: =N3/Comparativo!$AA$4 -> 1498.5224 | Q3: 14269425 | R3: =Q3/Q$20 -> 0.20812141 | S3: =Q3/Comparativo!$AA$4 -> 1498.5224 | T3: =C3-Q3 -> 1472483.4 | U3: =E3-P3 -> 154.63477 | V3: acrescimo de consumos com indice do Monolyt | Z3: ÁREA CONSTRUÍDA | AA3: 7191.64 | AB3: m²
B4: MOVIMENTAÇÃO DE TERRA | C4: ='Obra '!$C18 -> 916556.25 | D4: =C4/C$20 -> 0.012738656 | E4: =C4/Comparativo!$AA$4 -> 96.253359 | F4: 880794.46 | G4: =F4/F$20 -> 0.01253406 | H4: =F4/Comparativo!$AA$4 -> 92.497788 | I4: 880794.46 | J4: =I4/I$20 -> 0.01302972 | K4: =I4/Comparativo!$AA$4 -> 92.497788 | L4: =C4-F4 -> 35761.793 | M4: =E4-H4 -> 3.7555717 | N4: 1578343.1 | O4: =N4/N$20 -> 0.023020338 | P4: =N4/Comparativo!$AA$4 -> 165.75177 | Q4: 1578343.1 | R4: =Q4/Q$20 -> 0.023020338 | S4: =Q4/Comparativo!$AA$4 -> 165.75177 | T4: =C4-Q4 -> -661786.85 | U4: =E4-P4 -> -69.498415 | V4: atualização de valores | W4: =H4-P4 -> -73.253987 | Z4: ÁREA CONSTRUÍDA | AA4: ='Obra '!E9 -> 9522.33 | AB4: m²
B5: INFRAESTRUTURA | C5: ='Obra '!$C19 -> 3853368.6 | D5: =C5/C$20 -> 0.053555617 | E5: =C5/Comparativo!$AA$4 -> 404.66657 | F5: 3809832.8 | G5: =F5/F$20 -> 0.054215457 | H5: =F5/Comparativo!$AA$4 -> 400.0946 | I5: 3809832.8 | J5: =I5/I$20 -> 0.056359408 | K5: =I5/Comparativo!$AA$4 -> 400.0946 | L5: =C5-F5 -> 43535.785 | M5: =E5-H5 -> 4.5719677 | N5: 3113525.3 | O5: =N5/N$20 -> 0.045411169 | P5: =N5/Comparativo!$AA$4 -> 326.97095 | Q5: 3113525.3 | R5: =Q5/Q$20 -> 0.045411169 | S5: =Q5/Comparativo!$AA$4 -> 326.97095 | T5: =C5-Q5 -> 739843.32 | U5: =E5-P5 -> 77.695619 | V5: aumento MO, atualização de valores | W5: =H5-P5 -> 73.123651
B6: CONTENÇÕES | C6: ='Obra '!$C20 -> 1690469.1 | D6: =C6/C$20 -> 0.023494798 | E6: =C6/Comparativo!$AA$4 -> 177.52684 | F6: 1403308.1 | G6: =F6/F$20 -> 0.01996964 | H6: =F6/Comparativo!$AA$4 -> 147.37025 | I6: 2418636 | J6: =I6/I$20 -> 0.035779232 | K6: =I6/Comparativo!$AA$4 -> 253.99624 | L6: =C6-F6 -> 287160.99 | M6: =E6-H6 -> 30.156589 | N6: 2144584.6 | O6: =N6/N$20 -> 0.031279044 | P6: =N6/Comparativo!$AA$4 -> 225.21637 | Q6: 2144584.6 | R6: =Q6/Q$20 -> 0.031279044 | S6: =Q6/Comparativo!$AA$4 -> 225.21637 | T6: =C6-Q6 -> -454115.52 | U6: =E6-P6 -> -47.689538 | V6: atualização de valores | W6: =H6-P6 -> -77.846127
B7: SUPRAESTRUTURA | C7: ='Obra '!$C21 -> 16111863 | D7: =C7/C$20 -> 0.22392894 | E7: =C7/Comparativo!$AA$4 -> 1692.0084 | F7: 16118062 | G7: =F7/F$20 -> 0.22936652 | H7: =F7/Comparativo!$AA$4 -> 1692.6594 | I7: 14605082 | J7: =I7/I$20 -> 0.2160551 | K7: =I7/Comparativo!$AA$4 -> 1533.7719 | L7: =C7-F7 -> -6199.0266 | M7: =E7-H7 -> -0.65099892 | N7: 13677682 | O7: =N7/N$20 -> 0.19949077 | P7: =N7/Comparativo!$AA$4 -> 1436.3798 | Q7: 13677682 | R7: =Q7/Q$20 -> 0.19949077 | S7: =Q7/Comparativo!$AA$4 -> 1436.3798 | T7: =C7-Q7 -> 2434180.1 | U7: =E7-P7 -> 255.62862 | V7: aumento MO, atualização de valores | W7: =H7-P7 -> 256.27962
B8: ALVENARIA | C8: ='Obra '!$C22 -> 1740103.1 | D8: =C8/C$20 -> 0.024184631 | E8: =C8/Comparativo!$AA$4 -> 182.73922 | F8: 1740103.1 | G8: =F8/F$20 -> 0.024762369 | H8: =F8/Comparativo!$AA$4 -> 182.73922 | I8: 1740103.1 | J8: =I8/I$20 -> 0.025741597 | K8: =I8/Comparativo!$AA$4 -> 182.73922 | L8: =C8-F8 -> 0 | M8: =E8-H8 -> 0 | N8: 2332924.3 | O8: =N8/N$20 -> 0.034026003 | P8: =N8/Comparativo!$AA$4 -> 244.99511 | Q8: 2332924.3 | R8: =Q8/Q$20 -> 0.034026003 | S8: =Q8/Comparativo!$AA$4 -> 244.99511 | T8: =C8-Q8 -> -592821.21 | U8: =E8-P8 -> -62.255898 | V8: sem vergase redução da margem de insegurança | W8: =H8-P8 -> -62.255898
B9: INSTALAÇÕES ELÉTRICAS, HIDRÁULICAS, GLP E PREVENTIVAS | C9: ='Obra '!$C23+'Obra '!$C$31 -> 3037748.7 | D9: =C9/C$20 -> 0.042219815 | E9: =C9/Comparativo!$AA$4 -> 319.01318 | F9: 3037748.7 | G9: =F9/F$20 -> 0.043228389 | H9: =F9/Comparativo!$AA$4 -> 319.01318 | I9: 3037748.7 | J9: =I9/I$20 -> 0.044937857 | K9: =I9/Comparativo!$AA$4 -> 319.01318 | L9: =C9-F9 -> 0 | M9: =E9-H9 -> 0 | N9: 3037748.7 | O9: =N9/N$20 -> 0.044305958 | P9: =N9/Comparativo!$AA$4 -> 319.01318 | Q9: 3037748.7 | R9: =Q9/Q$20 -> 0.044305958 | S9: =Q9/Comparativo!$AA$4 -> 319.01318 | T9: =C9-Q9 -> 0 | U9: =E9-P9 -> 0 | W9: =H9-P9 -> 0
B10: EQUIPAMENTOS E SISTEMAS ESPECIAIS | C10: ='Obra '!$C24 -> 4931746 | D10: =C10/C$20 -> 0.068543326 | E10: =C10/Comparativo!$AA$4 -> 517.91379 | F10: 4650959.9 | G10: =F10/F$20 -> 0.066185034 | H10: =F10/Comparativo!$AA$4 -> 488.42666 | I10: 4691058.4 | J10: =I10/I$20 -> 0.069395506 | K10: =I10/Comparativo!$AA$4 -> 492.63767 | L10: =C10-F10 -> 280786.11 | M10: =E10-H10 -> 29.487123 | N10: 5378764.3 | O10: =N10/N$20 -> 0.078449973 | P10: =N10/Comparativo!$AA$4 -> 564.858 | Q10: 5378764.3 | R10: =Q10/Q$20 -> 0.078449973 | S10: =Q10/Comparativo!$AA$4 -> 564.858 | T10: =C10-Q10 -> -447018.29 | U10: =E10-P10 -> -46.944213 | V10: redução sistema de placas fotovoltaicas e dos equipamentos de piscina | W10: =H10-P10 -> -76.431336
B11: IMPERMEABILIZAÇÃO | C11: ='Obra '!$C25 -> 492633.42 | D11: =C11/C$20 -> 0.0068468111 | E11: =C11/Comparativo!$AA$4 -> 51.734546 | F11: 574441.25 | G11: =F11/F$20 -> 0.0081745306 | H11: =F11/Comparativo!$AA$4 -> 60.325703 | I11: 574441.25 | J11: =I11/I$20 -> 0.0084977926 | K11: =I11/Comparativo!$AA$4 -> 60.325703 | L11: =C11-F11 -> -81807.834 | M11: =E11-H11 -> -8.5911572 | N11: 673400.79 | O11: =N11/N$20 -> 0.0098216376 | P11: =N11/Comparativo!$AA$4 -> 70.718069 | Q11: 673400.79 | R11: =Q11/Q$20 -> 0.0098216376 | S11: =Q11/Comparativo!$AA$4 -> 70.718069 | T11: =C11-Q11 -> -180767.37 | U11: =E11-P11 -> -18.983523 | V11: retirada proteção mecânica (sem manta) | W11: =H11-P11 -> -10.392366
B12: REVESTIMENTOS INTERNOS EM PISO E PAREDE | C12: ='GERENCIAMENTO EXECUTIVO'!$N$217+'GERENCIAMENTO EXECUTIVO'!$N$226+'GERENCIAMENTO EXECUTIVO'!$N$227+'GERENCIAMENTO EXECUTIVO'!$N$243+'GERENCIAMENTO EXECUTIVO'!$N$249+'GERENCIAMENTO EXECUTIVO'!$N$271+'GERENCIAMENTO EXECUTIVO'!$N$273+'GERENCIAMENTO EXECUTIVO'!$N$274 -> 1160008.4 | D12: =C12/C$20 -> 0.016122248 | E12: =C12/Comparativo!$AA$4 -> 121.8198 | F12: 1006855.1 | G12: =F12/F$20 -> 0.014327954 | H12: =F12/Comparativo!$AA$4 -> 105.73621 | I12: 1075574.7 | J12: =I12/I$20 -> 0.015911132 | K12: =I12/Comparativo!$AA$4 -> 112.95289 | L12: =C12-F12 -> 153153.29 | M12: =E12-H12 -> 16.083594 | N12: 1214241.2 | O12: =N12/N$20 -> 0.017709864 | P12: =N12/Comparativo!$AA$4 -> 127.51513 | Q12: 1214241.2 | R12: =Q12/Q$20 -> 0.017709864 | S12: =Q12/Comparativo!$AA$4 -> 127.51513 | T12: =C12-Q12 -> -54232.773 | U12: =E12-P12 -> -5.6953259 | V12: Redução area com polimento | W12: =H12-P12 -> -21.77892
B13: REVESTIMENTOS E ACABAMENTOS INTERNOS EM TETO | C13: ='Obra '!$C27 -> 410937.08 | D13: =C13/C$20 -> 0.0057113636 | E13: =C13/Comparativo!$AA$4 -> 43.155098 | F13: 356580.66 | G13: =F13/F$20 -> 0.0050742866 | H13: =F13/Comparativo!$AA$4 -> 37.446787 | I13: 356580.66 | J13: =I13/I$20 -> 0.0052749494 | K13: =I13/Comparativo!$AA$4 -> 37.446787 | L13: =C13-F13 -> 54356.419 | M13: =E13-H13 -> 5.7083108 | N13: 1084571.2 | O13: =N13/N$20 -> 0.015818612 | P13: =N13/Comparativo!$AA$4 -> 113.89767 | Q13: 1084571.2 | R13: =Q13/Q$20 -> 0.015818612 | S13: =Q13/Comparativo!$AA$4 -> 113.89767 | T13: =C13-Q13 -> -673634.15 | U13: =E13-P13 -> -70.742575 | V13: redução significativa de area de forro de gesso (metade) | W13: =H13-P13 -> -76.450886
B14: ACABAMENTOS EM PISO E PAREDE | C14: ='GERENCIAMENTO EXECUTIVO'!$N$215+'GERENCIAMENTO EXECUTIVO'!$N$241-C12 -> 5056385.9 | D14: =C14/C$20 -> 0.070275621 | E14: =C14/Comparativo!$AA$4 -> 531.00301 | F14: 5557176.6 | G14: =F14/F$20 -> 0.079080863 | H14: =F14/Comparativo!$AA$4 -> 583.5942 | I14: 2784069.5 | J14: =I14/I$20 -> 0.041185144 | K14: =I14/Comparativo!$AA$4 -> 292.37272 | L14: =C14-F14 -> -500790.66 | M14: =E14-H14 -> -52.591189 | N14: 2874782.4 | O14: =N14/N$20 -> 0.041929073 | P14: =N14/Comparativo!$AA$4 -> 301.89905 | Q14: 2874782.4 | R14: =Q14/Q$20 -> 0.041929073 | S14: =Q14/Comparativo!$AA$4 -> 301.89905 | T14: =C14-Q14 -> 2181603.5 | U14: =E14-P14 -> 229.10396 | V14: redução metade da verba de ceramica em parede, redução de rodape | W14: =H14-P14 -> 281.69515
B15: PINTURA INTERNA | C15: ='Obra '!$C29 -> 1519511.5 | D15: =C15/C$20 -> 0.021118762 | E15: =C15/Comparativo!$AA$4 -> 159.57349 | F15: 1561624.6 | G15: =F15/F$20 -> 0.022222548 | H15: =F15/Comparativo!$AA$4 -> 163.99606 | I15: 1561624.6 | J15: =I15/I$20 -> 0.023101339 | K15: =I15/Comparativo!$AA$4 -> 163.99606 | L15: =C15-F15 -> -42113.143 | M15: =E15-H15 -> -4.4225671 | N15: 1310024.8 | O15: =N15/N$20 -> 0.019106881 | P15: =N15/Comparativo!$AA$4 -> 137.57397 | Q15: 1310024.8 | R15: =Q15/Q$20 -> 0.019106881 | S15: =Q15/Comparativo!$AA$4 -> 137.57397 | T15: =C15-Q15 -> 209486.68 | U15: =E15-P15 -> 21.999519 | W15: =H15-P15 -> 26.422086
B16: ESQUADRIAS, VIDROS E FERRAGENS | C16: ='Obra '!$C30 -> 7296949.6 | D16: =C16/C$20 -> 0.10141585 | E16: =C16/Comparativo!$AA$4 -> 766.29875 | F16: 7296949.6 | G16: =F16/F$20 -> 0.10383854 | H16: =F16/Comparativo!$AA$4 -> 766.29875 | I16: 7296949.6 | J16: =I16/I$20 -> 0.10794483 | K16: =I16/Comparativo!$AA$4 -> 766.29875 | L16: =C16-F16 -> 0 | M16: =E16-H16 -> 0 | N16: 5968290.6 | O16: =N16/N$20 -> 0.087048291 | P16: =N16/Comparativo!$AA$4 -> 626.76788 | Q16: 5968290.6 | R16: =Q16/Q$20 -> 0.087048291 | S16: =Q16/Comparativo!$AA$4 -> 626.76788 | T16: =C16-Q16 -> 1328659 | U16: =E16-P16 -> 139.53087 | V16: aumento especificações de portas inicialmente previstas (madeira), ajueste de especificação de guarda-corpo | W16: =H16-P16 -> 139.53087
B17: REVESTIMENTOS E ACABAMENTOS DE FACHADA | C17: ='Obra '!$C32 -> 4023627.8 | D17: =C17/C$20 -> 0.055921947 | E17: =C17/Comparativo!$AA$4 -> 422.54657 | F17: 3870693.4 | G17: =F17/F$20 -> 0.055081528 | H17: =F17/Comparativo!$AA$4 -> 406.48596 | I17: 3870693.4 | J17: =I17/I$20 -> 0.057259728 | K17: =I17/Comparativo!$AA$4 -> 406.48596 | L17: =C17-F17 -> 152934.41 | M17: =E17-H17 -> 16.060608 | N17: 3928648.5 | O17: =N17/N$20 -> 0.057299847 | P17: =N17/Comparativo!$AA$4 -> 412.57219 | Q17: 3928648.5 | R17: =Q17/Q$20 -> 0.057299847 | S17: =Q17/Comparativo!$AA$4 -> 412.57219 | T17: =C17-Q17 -> 94979.299 | U17: =E17-P17 -> 9.9743759 | W17: =H17-P17 -> -6.086232
B18: SERVIÇOS COMPLEMENTARES | C18: ='Obra '!$C33 -> 2864831.5 | D18: =C18/C$20 -> 0.039816544 | E18: =C18/Comparativo!$AA$4 -> 300.85405 | F18: 2943939.6 | G18: =F18/F$20 -> 0.041893447 | H18: =F18/Comparativo!$AA$4 -> 309.16168 | I18: 2943939.6 | J18: =I18/I$20 -> 0.043550124 | K18: =I18/Comparativo!$AA$4 -> 309.16168 | L18: =C18-F18 -> -79108.04 | M18: =E18-H18 -> -8.3076348 | N18: 3979047.5 | O18: =N18/N$20 -> 0.058034923 | P18: =N18/Comparativo!$AA$4 -> 417.86491 | Q18: 3979047.5 | R18: =Q18/Q$20 -> 0.058034923 | S18: =Q18/Comparativo!$AA$4 -> 417.86491 | T18: =C18-Q18 -> -1114216 | U18: =E18-P18 -> -117.01086 | V18: inclusão de calçadas e passeios, realocação de montantes (cercas) | W18: =H18-P18 -> -108.70322
B19: IMPREVISTOS E CONTINGENCIAS | C19: ='Obra '!$C34 -> 1102134.8 | D19: =C19/C$20 -> 0.015317899 | E19: =C19/Comparativo!$AA$4 -> 115.74213 | F19: 1096181.4 | G19: =F19/F$20 -> 0.015599103 | H19: =F19/Comparativo!$AA$4 -> 115.11693 | I19: 1032942.6 | J19: =I19/I$20 -> 0.015280469 | K19: =I19/Comparativo!$AA$4 -> 108.47582 | L19: =C19-F19 -> 5953.4022 | M19: =E19-H19 -> 0.62520435 | N19: 1996980.1 | O19: =N19/N$20 -> 0.029126214 | P19: =N19/Comparativo!$AA$4 -> 209.71549 | Q19: 1996980.1 | R19: =Q19/Q$20 -> 0.029126214 | S19: =Q19/Comparativo!$AA$4 -> 209.71549 | T19: =C19-Q19 -> -894845.34 | U19: =E19-P19 -> -93.97336 | W19: =H19-P19 -> -94.598564
B20: TOTAL | C20: =SUM(C3:C19) -> 71950782 | D20: =SUM(D3:D19) -> 1 | E20: =SUM(E3:E19) -> 7556.006 | F20: =SUM(F3:F19) -> 70272078 | G20: =SUM(G3:G19) -> 1 | H20: =SUM(H3:H19) -> 7379.7146 | I20: =SUM(I3:I19) -> 67598879 | J20: =SUM(J3:J19) -> 1 | ... U20: =SUM(U3:U19) -> 355.77404
B21: CUB/SC | C21: 2887.91 | D21: 45658 | E21: =ROUND(+E20/C21,2)&" CUB" -> 2,62 CUB | F21: 2887.91 | G21: 45658 | H21: =ROUND(+H20/F21,2)&" CUB" -> 2,56 CUB | I21: 2887.91 | J21: 45658 | K21: =ROUND(+K20/I21,2)&" CUB" -> 2,46 CUB | M21: =ROUND(E22-H22,2)&" CUB" -> 0,06 CUB | N21: 2811.86 | O21: 45505 | P21: =ROUND(+P20/N21,2)&" CUB" -> 2,56 CUB | Q21: 2811.86 | R21: 45505 | S21: =ROUND(+S20/Q21,2)&" CUB" -> 2,56 CUB | U21: =ROUND(E22-P22,3)&" CUB" -> 0,056 CUB
E22: =+E20/C21 -> 2.6164271 | H22: =+H20/F21 -> 2.5553825 | K22: =+K20/I21 -> 2.4581739 | P22: =+P20/N21 -> 2.5606652
V23: =U20/P20 -> 0.049411469

Sheet EPCs
A1: Obra | B1: ='Obra '!D1 -> Aquos Oasis Home
A2: Empresa | B2: ='Obra '!D2 -> Blue Heaven
A3: Revisão | B3: ='Obra '!D3 -> R02
A4: Equipamentos de proteção coletiva
A5: Bandejas de proteção
B7: Descrição | C7: Unidade | D7: Quantidade | F7: Imagem formulário
B8: Perímetro de projeção torre 1 | C8: m | D8: 239.41
B9: Perímetro de projeção torre 2 | C9: m | D9: =120.7527+112.7021 -> 233.4548
B10: Número de montagens de bandeja primária | C10: un | D10: 1
B11: Bandeja de proteção primária | C11: m | D11: =D8+D9 -> 472.8648
B12: Bandeja de proteção secundária | C12: m | D12: 0
A14: Guarda - corpo de vãos
B16: Descrição | C16: Unidade | D16: Quantidade | F16: Imagem formulário
B17: Perímetro de vãos | C17: m | D17: =ARQ!D66+ARQ!D67 -> 1268.99
B18: Guarda - corpo de vãos | C18: m | D18: =D17 -> 1268.99
A20: Guarda - corpo de desforma
B22: Descrição | C22: Unidade | D22: Quantidade | F22: Imagem formulário
B23: Perímetro de projeção da torre | C23: m | D23: =D8+D9 -> 472.8648
B24: Repetições de pavimentos** | C24: un | D24: 3
B25: Proteção de periferia pós desforma torre | C25: m | D25: =(D23*D24) -> 1418.5944
A27: Fechamento removível de vãos em madeira
B29: Descrição | C29: Unidade | D29: Quantidade | F29: Imagem formulário
B30: Área das portas de elevadores | C30: m2 | D30: 2.4
B31: Quantidade de elevadores | C31: m2 | D31: 7
B32: Quantidade de portas de elevadores | C32: un | D32: =D31*'Obra '!E14 -> 28
B33: Fechamento removível de vãos em madeira | C33: m2 | D33: =D30*D32 -> 67.2
B34: Área das portas de aptos | C34: m2
B35: Quantidade de aptos | C35: un
B36: =A27 -> Fechamento removível de vãos em madeira | C36: m2 | D36: =D34*D35 -> 0
A38: Tela fachadeira
B40: Descrição | C40: Unidade | D40: Quantidade | F40: Imagem formulário
B41: Area da fachada | C41: m² | D41: =(D11+D12)*16.93 -> 8005.6011
B42: =A38 -> Tela fachadeira | C42: m2 | D42: =D41 -> 8005.6011
A44: SLQA
B46: Descrição | C46: Unidade | D46: Quantidade | F46: Imagem formulário
B47: Perímetro de projeção da torre | C47: m | D47: =D8+D9 -> 472.8648
B48: Altura de cobrimento da tela | C48: un | D48: 0
B49: =A44 -> SLQA | C49: m | D49: =D47*D48 -> 0
A52: Tapume
B54: Descrição | C54: Unidade | D54: Quantidade | F54: Imagem formulário
...

Sheet CANTEIRO
A1: Obra | B1: ='Obra '!D1 -> Aquos Oasis Home
A2: Empresa | B2: ='Obra '!D2 -> Blue Heaven
A3: Revisão | B3: ='Obra '!D3 -> R02
A4: Instalações de canteiro
A5: Instalações de canteiro
B7: Descrição | C7: Unidade | D7: Quantidade
B8: Produtividade média | C8: m2 / mês | D8: ='Obra '!$E$9/'Obra '!$E$7 -> 264.50917
B9: Pm | C9: h/m2 | D9: 49
B10: Numero de funcionários | C10: un | D10: =ROUNDUP((D9*'Obra '!$E$9)/'Obra '!$E$7/180,) -> 73
B11: Equipe administrativa | C11: un | D11: 5 | E11: Considerado | F11: Engenheiro, mestre, almoxarife, estagiário
B12: Pontos de água e esgoto | C12: un | D12: =ROUNDUP($D$10/20,0) -> 4 | E12: 20 funcionários/ponto
B13: Bebedouro | C13: un | D13: =ROUNDUP('Obra '!$E$14/5,0) -> 1 | E13: 1 / 5 pav.
B14: Ferramentas | C14: R$ | D14: =800*D10 -> 58400 | E14: 800,00/func. | F14: Empreitada
B15: EPI | C15: R$ | D15: =500*D10 -> 36500 | E15: 500,00/func. | F15: Empreitada
B16: Banheiro | C16: un | D16: =ROUNDUP($D$10/20,0) -> 4 | E16: 1/20 func
A18: Mobiliário de canteiro
B20: Descrição | C20: Unidade | D20: Quantidade | E20: Custo unitário | F20: Custo total
B21: Cadeira | C21: un | D21: =ROUNDUP(D11*1.5,) -> 8 | E21: 200 | F21: =D21*E21 -> 1600
B22: Mesa | C22: un | D22: 1 | E22: 1000 | F22: =E22*D22 -> 1000
B23: Ar condicionado | C23: un | D23: 2 | E23: 5000 | F23: =E23*D23 -> 10000
B24: Armário | C24: m | D24: 4 | E24: 900 | F24: =E24*D24 -> 3600
B25: Escrivaninha | C25: un | D25: =D11 -> 5 | E25: 800 | F25: =E25*D25 -> 4000
B26: TOTAL | F26: =F23+F24+F25+F22+F21 -> 20200
B27: Descrição | C27: Unidade | D27: Quantidade | E27: Custo unitário | F27: Custo total
B28: Computador pessoal | C28: un | D28: 3 | E28: 6500 | F28: =D28*E28 -> 19500
B29: Impressora | C29: un | D29: 1 | E29: 2000 | F29: =E29*D29 -> 2000
B30: Roteador | C30: un | D30: 2 | E30: 500 | F30: =E30*D30 -> 1000
B31: TOTAL | F31: =+F28+F29+F30 -> 22500

Sheet Ensaios
C1: Projeto | D1: ='Obra '!D1 -> Aquos Oasis Home
C2: Empresa | D2: ='Obra '!D2 -> Blue Heaven
C3: Revisão | D3: R02
A4: ENSAIOS
A5: Item | B5: Descrição/Especificação | C5: Unid. | D5: V. Unit. (R$) | E5: Qtde. | F5: V. Total (R$) | G5: Observações
B6: CONTROLE TECNOLÓGICO - CONCRETO
A7: 1 | B7: Laudo e ART | C7: vb | D7: 1450 | E7: 1 | F7: =$D7*E7 -> 1450
A8: =A7+1 -> 2 | B8: Controle Tecnologico Infraestrutura - Coleta materiais da obra | C8: unid. | D8: 20 | E8: =ROUNDUP(('GERENCIAMENTO EXECUTIVO'!L58+'GERENCIAMENTO EXECUTIVO'!L32+'GERENCIAMENTO EXECUTIVO'!L39)/8,0)*4 -> 680 | F8: =$D8*E8 -> 13600 | G8: 4 CPs por caminhão betoneira de 8m³
A9: =A8+1 -> 3 | B9: Controle Tecnologico Contenção - Coleta materiais da obra | C9: unid. | D9: 20 | E9: =ROUNDUP(('GERENCIAMENTO EXECUTIVO'!L58+'GERENCIAMENTO EXECUTIVO'!L59+'GERENCIAMENTO EXECUTIVO'!L70)/8,0)*4 -> 292 | F9: =$D9*E9 -> 5840 | G9: 4 CPs por caminhão betoneira de 8m³
A10: =A9+1 -> 4 | B10: Controle Tecnologico Supraestrutura - Coleta materiais da obra | C10: unid. | D10: 20 | E10: =ROUNDUP(('GERENCIAMENTO EXECUTIVO'!L87)/8,0)*4 -> 1092 | F10: =$D10*E10 -> 21840 | G10: 4 CPs por caminhão betoneira de 8m³
A11: =A8+1 -> 3 | B11: Controle Tecnológico - Ensaio de concreto endurecido/grouth - compressão simples / Detalhe: Concreto | C11: cps | D11: 12.5 | E11: =E8+E9+E10 -> 2064 | F11: =$D11*E11 -> 25800
A12: =A11+1 -> 4 | B12: Determinação do módulo de deformação tangente inicial (Eci) (módulo de elasticidade), Incluindo Avaliação Estática dos Resultados (NBR 8522 e NBR 12655) | C12: ensaio | D12: 480 | E12: 4 | F12: =$D12*E12 -> 1920 | G12: A cada 5 pav. (e quando houver troca de fornecedor) - 1 por torre
C13: SUBTOTAL: | F13: =SUM(F7:F12) -> 70450

Sheet PROJETOS E GERENCIAMENTO TÉCNIC
G4: PROJETO: | I4: ='Obra '!D1 -> Aquos Oasis Home | O4: REVISÃO: | P4: DATA
G5: EMPRESA: | I5: ='Obra '!D2 -> Blue Heaven | O5: ='Obra '!D3 -> R02 | P5: 45897
A6: Unidade Construtiva | B6: Célula Construtiva | C6: Etapa | D6: Subetapa | E6: Serviço | G6: PROJETOS E GERENCIAMENTO TÉCNICO
A7: 0 | B7: 0 | C7: 0 | D7: 0 | E7: 0 | G7: Atalho | H7: NIVEL | I7: Item | J7: Descrição | K7: Unidade | L7: Quant. | M7: Preço un | N7: Total | O7: Considerações | P7: Situação
A8: =IF($H8="UNIDADE CONSTRUTIVA",OFFSET(A8,-1,0)+1,LARGE(A$3:A7,1)) -> 0 | B8: =IF(H8="UNIDADE CONSTRUTIVA",0,IF(H8="CÉLULA CONSTRUTIVA",OFFSET(B8,-1,0)+1,OFFSET(B8,-1,0))) -> 1 | C8: =IF(H8="CÉLULA CONSTRUTIVA",0,IF(H8="ETAPA",OFFSET(C8,-1,0)+1,OFFSET(C8,-1,0))) -> 0 | D8: =IF(H8="ETAPA",0,IF(H8="SUBETAPA",OFFSET(D8,-1,0)+1,OFFSET(D8,-1,0))) -> 0 | E8: =IF(H8="Subetapa",0,IF(H8="serviço",OFFSET(E8,-1,0)+1,OFFSET(E8,-1,0))) -> 0 | H8: CÉLULA CONSTRUTIVA | I8: 01 | J8: PROJETOS E GERENCIAMENTO TÉCNICO | N8: =IF(H8="CÉLULA CONSTRUTIVA",SUMIFS($N$8:$N$398,$B$8:$B$398,B8,$H$8:$H$398,"ETAPA"),0) -> 1723947.3
A9: =IF($H9="UNIDADE CONSTRUTIVA",OFFSET(A9,-1,0)+1,LARGE(A$3:A8,1)) -> 0 | B9: =IF(H9="UNIDADE CONSTRUTIVA",0,IF(H9="CÉLULA CONSTRUTIVA",OFFSET(B9,-1,0)+1,OFFSET(B9,-1,0))) -> 1 | C9: =IF(H9="CÉLULA CONSTRUTIVA",0,IF(H9="ETAPA",OFFSET(C9,-1,0)+1,OFFSET(C9,-1,0))) -> 1 | D9: =IF(H9="ETAPA",0,IF(H9="SUBETAPA",OFFSET(D9,-1,0)+1,OFFSET(D9,-1,0))) -> 0 | E9: =IF(H9="Subetapa",0,IF(H9="serviço",OFFSET(E9,-1,0)+1,OFFSET(E9,-1,0))) -> 0 | H9: ETAPA | I9: =IF(H9="Unidade Construtiva",TEXT(A9,"00"),IF(H9="Célula Construtiva",TEXT(B9,"00"),IF(H9="Etapa",CONCATENATE(TEXT(B9,"00"),".",TEXT(C9,"000")),IF(H9="Subetapa",CONCATENATE(TEXT(B9,"00"),".",TEXT(C9,"000"),".",TEXT(D9,"000")),IF(H9="Serviço",CONCATENATE(TEXT(B9,"00"),".",TEXT(C9,"000"),".",TEXT(D9,"000"),".",TEXT(E9,"000")),""))))) -> 01.001 | J9: ESTUDOS, PROJETOS E CONSULTORIAS | N9: =N10+N18+N36+N40 -> 1416855.3
A10: =IF($H10="UNIDADE CONSTRUTIVA",OFFSET(A10,-1,0)+1,LARGE(A$3:A9,1)) -> 0 | B10: =IF(H10="UNIDADE CONSTRUTIVA",0,IF(H10="CÉLULA CONSTRUTIVA",OFFSET(B10,-1,0)+1,OFFSET(B10,-1,0))) -> 1 | C10: =IF(H10="CÉLULA CONSTRUTIVA",0,IF(H10="ETAPA",OFFSET(C10,-1,0)+1,OFFSET(C10,-1,0))) -> 1 | D10: =IF(H10="ETAPA",0,IF(H10="SUBETAPA",OFFSET(D10,-1,0)+1,OFFSET(D10,-1,0))) -> 1 | E10: =IF(H10="Subetapa",0,IF(H10="serviço",OFFSET(E10,-1,0)+1,OFFSET(E10,-1,0))) -> 0 | H10: SUBETAPA | I10: =IF(H10="Unidade Construtiva",TEXT(A10,"00"),IF(H10="Célula Construtiva",TEXT(B10,"00"),IF(H10="Etapa",CONCATENATE(TEXT(B10,"00"),".",TEXT(C10,"000")),IF(H10="Subetapa",CONCATENATE(TEXT(B10,"00"),".",TEXT(C10,"000"),".",TEXT(D10,"000")),IF(H10="Serviço",CONCATENATE(TEXT(B10,"00"),".",TEXT(C10,"000"),".",TEXT(D10,"000"),".",TEXT(E10,"000")),""))))) -> 01.001.001 | J10: Estudos | N10: =SUM(N11:N17) -> 126080.21
A11: =IF($H11="UNIDADE CONSTRUTIVA",OFFSET(A11,-1,0)+1,LARGE(A$3:A10,1)) -> 0 | B11: =IF(H11="UNIDADE CONSTRUTIVA",0,IF(H11="CÉLULA CONSTRUTIVA",OFFSET(B11,-1,0)+1,OFFSET(B11,-1,0))) -> 1 | C11: =IF(H11="CÉLULA CONSTRUTIVA",0,IF(H11="ETAPA",OFFSET(C11,-1,0)+1,OFFSET(C11,-1,0))) -> 1 | D11: =IF(H11="ETAPA",0,IF(H11="SUBETAPA",OFFSET(D11,-1,0)+1,OFFSET(D11,-1,0))) -> 1 | E11: =IF(H11="Subetapa",0,IF(H11="serviço",OFFSET(E11,-1,0)+1,OFFSET(E11,-1,0))) -> 1 | H11: SERVIÇO | I11: =IF(H11="Unidade Construtiva",TEXT(A11,"00"),IF(H11="Célula Construtiva",TEXT(B11,"00"),IF(H11="Etapa",CONCATENATE(TEXT(B11,"00"),".",TEXT(C11,"000")),IF(H11="Subetapa",CONCATENATE(TEXT(B11,"00"),".",TEXT(C11,"000"),".",TEXT(D11,"000")),IF(H11="Serviço",CONCATENATE(TEXT(B11,"00"),".",TEXT(C11,"000"),".",TEXT(D11,"000"),".",TEXT(E11,"000")),""))))) -> 01.001.001.001 | J11: Memorial Descritivo | K11: vb | L11: 1 | M11: =0.8*'Obra '!$E$9 -> 7617.864 | N11: =L11*M11 -> 7617.864 | O11: Distribuição solicitada em analise R01 | P11: Finalizado
A12: =IF($H12="UNIDADE CONSTRUTIVA",OFFSET(A12,-1,0)+1,LARGE(A$3:A11,1)) -> 0 | B12: =IF(H12="UNIDADE CONSTRUTIVA",0,IF(H12="CÉLULA CONSTRUTIVA",OFFSET(B12,-1,0)+1,OFFSET(B12,-1,0))) -> 1 | C12: =IF(H12="CÉLULA CONSTRUTIVA",0,IF(H12="ETAPA",OFFSET(C12,-1,0)+1,OFFSET(C12,-1,0))) -> 1 | D12: =IF(H12="ETAPA",0,IF(H12="SUBETAPA",OFFSET(D12,-1,0)+1,OFFSET(D12,-1,0))) -> 1 | E12: =IF(H12="Subetapa",0,IF(H12="serviço",OFFSET(E12,-1,0)+1,OFFSET(E12,-1,0))) -> 2 | H12: SERVIÇO | I12: =IF(H12="Unidade Construtiva",TEXT(A12,"00"),IF(H12="Célula Construtiva",TEXT(B12,"00"),IF(H12="Etapa",CONCATENATE(TEXT(B12,"00"),".",TEXT(C12,"000")),IF(H12="Subetapa",CONCATENATE(TEXT(B12,"00"),".",TEXT(C12,"000"),".",TEXT(D12,"000")),IF(H12="Serviço",CONCATENATE(TEXT(B12,"00"),".",TEXT(C12,"000"),".",TEXT(D12,"000"),".",TEXT(E12,"000")),""))))) -> 01.001.001.002 | J12: Levantamento topográfioo | K12: vb | L12: 1 | M12: =2.45*'Obra '!E8 -> 12152 | N12: =L12*M12 -> 12152 | O12: Distribuição solicitada em analise R01 | P12: Finalizado
A13: =IF($H13="UNIDADE CONSTRUTIVA",OFFSET(A13,-1,0)+1,LARGE(A$3:A12,1)) -> 0 | B13: =IF(H13="UNIDADE CONSTRUTIVA",0,IF(H13="CÉLULA CONSTRUTIVA",OFFSET(B13,-1,0)+1,OFFSET(B13,-1,0))) -> 1 | C13: =IF(H13="CÉLULA CONSTRUTIVA",0,IF(H13="ETAPA",OFFSET(C13,-1,0)+1,OFFSET(C13,-1,0))) -> 1 | D13: =IF(H13="ETAPA",0,IF(H13="SUBETAPA",OFFSET(D13,-1,0)+1,OFFSET(D13,-1,0))) -> 1 | E13: =IF(H13="Subetapa",0,IF(H13="serviço",OFFSET(E13,-1,0)+1,OFFSET(E13,-1,0))) -> 3 | H13: SERVIÇO | I13: =IF(H13="Unidade Construtiva",TEXT(A13,"00"),IF(H13="Célula Construtiva",TEXT(B13,"00"),IF(H13="Etapa",CONCATENATE(TEXT(B13,"00"),".",TEXT(C13,"000")),IF(H13="Subetapa",CONCATENATE(TEXT(B13,"00"),".",TEXT(C13,"000"),".",TEXT(D13,"000")),IF(H13="Serviço",CONCATENATE(TEXT(B13,"00"),".",TEXT(C13,"000"),".",TEXT(D13,"000"),".",TEXT(E13,"000")),""))))) -> 01.001.001.003 | J13: Estudo Geológico | K13: vb | L13: 1 | M13: 20810 | N13: =L13*M13 -> 20810 | O13: Distribuição solicitada em analise R01 | P13: Finalizado
A14: =IF($H14="UNIDADE CONSTRUTIVA",OFFSET(A14,-1,0)+1,LARGE(A$3:A13,1)) -> 0 | B14: =IF(H14="UNIDADE CONSTRUTIVA",0,IF(H14="CÉLULA CONSTRUTIVA",OFFSET(B14,-1,0)+1,OFFSET(B14,-1,0))) -> 1 | C14: =IF(H14="CÉLULA CONSTRUTIVA",0,IF(H14="ETAPA",OFFSET(C14,-1,0)+1,OFFSET(C14,-1,0))) -> 1 | D14: =IF(H14="ETAPA",0,IF(H14="SUBETAPA",OFFSET(D14,-1,0)+1,OFFSET(D14,-1,0))) -> 1 | E14: =IF(H14="Subetapa",0,IF(H14="serviço",OFFSET(E14,-1,0)+1,OFFSET(E14,-1,0))) -> 4 | H14: SERVIÇO | I14: =IF(H14="Unidade Construtiva",TEXT(A14,"00"),IF(H14="Célula Construtiva",TEXT(B14,"00"),IF(H14="Etapa",CONCATENATE(TEXT(B14,"00"),".",TEXT(C14,"000")),IF(H14="Subetapa",CONCATENATE(TEXT(B14,"00"),".",TEXT(C14,"000"),".",TEXT(D14,"000")),IF(H14="Serviço",CONCATENATE(TEXT(B14,"00"),".",TEXT(C14,"000"),".",TEXT(D14,"000"),".",TEXT(E14,"000")),""))))) -> 01.001.001.004 | J14: Estudo Ambiental | K14: vb | L14: 1 | M14: 38843 | N14: =L14*M14 -> 38843 | O14: Distribuição solicitada em analise R01 | P14: Finalizado
A15: =IF($H15="UNIDADE CONSTRUTIVA",OFFSET(A15,-1,0)+1,LARGE(A$3:A13,1)) -> 0 | B15: =IF(H15="UNIDADE CONSTRUTIVA",0,IF(H15="CÉLULA CONSTRUTIVA",OFFSET(B15,-1,0)+1,OFFSET(B15,-1,0))) -> 1 | C15: =IF(H15="CÉLULA CONSTRUTIVA",0,IF(H15="ETAPA",OFFSET(C15,-1,0)+1,OFFSET(C15,-1,0))) -> 1 | D15: =IF(H15="ETAPA",0,IF(H15="SUBETAPA",OFFSET(D15,-1,0)+1,OFFSET(D15,-1,0))) -> 1 | E15: =IF(H15="Subetapa",0,IF(H15="serviço",OFFSET(E15,-1,0)+1,OFFSET(E15,-1,0))) -> 5 | H15: SERVIÇO | I15: =IF(H15="Unidade Construtiva",TEXT(A15,"00"),IF(H15="Célula Construtiva",TEXT(B15,"00"),IF(H15="Etapa",CONCATENATE(TEXT(B15,"00"),".",TEXT(C15,"000")),IF(H15="Subetapa",CONCATENATE(TEXT(B15,"00"),".",TEXT(C15,"000"),".",TEXT(D15,"000")),IF(H15="Serviço",CONCATENATE(TEXT(B15,"00"),".",TEXT(C15,"000"),".",TEXT(D15,"000"),".",TEXT(E15,"000")),""))))) -> 01.001.001.005 | J15: Estudo acústico | K15: vb | L15: 1 | M15: 22000 | N15: =L15*M15 -> 22000 | O15: Distribuição solicitada em analise R01 | P15: Finalizado
A16: =IF($H16="UNIDADE CONSTRUTIVA",OFFSET(A16,-1,0)+1,LARGE(A$3:A14,1)) -> 0 | B16: =IF(H16="UNIDADE CONSTRUTIVA",0,IF(H16="CÉLULA CONSTRUTIVA",OFFSET(B16,-1,0)+1,OFFSET(B16,-1,0))) -> 1 | C16: =IF(H16="CÉLULA CONSTRUTIVA",0,IF(H16="ETAPA",OFFSET(C16,-1,0)+1,OFFSET(C16,-1,0))) -> 1 | D16: =IF(H16="ETAPA",0,IF(H16="SUBETAPA",OFFSET(D16,-1,0)+1,OFFSET(D16,-1,0))) -> 1 | E16: =IF(H16="Subetapa",0,IF(H16="serviço",OFFSET(E16,-1,0)+1,OFFSET(E16,-1,0))) -> 6 | H16: SERVIÇO | I16: =IF(H16="Unidade Construtiva",TEXT(A16,"00"),IF(H16="Célula Construtiva",TEXT(B16,"00"),IF(H16="Etapa",CONCATENATE(TEXT(B16,"00"),".",TEXT(C16,"000")),IF(H16="Subetapa",CONCATENATE(TEXT(B16,"00"),".",TEXT(C16,"000"),".",TEXT(D16,"000")),IF(H16="Serviço",CONCATENATE(TEXT(B16,"00"),".",TEXT(C16,"000"),".",TEXT(D16,"000"),".",TEXT(E16,"000")),""))))) -> 01.001.001.006 | J16: Estudo luminotecnico | K16: vb | L16: 1 | M16: =2*'Obra '!$E$9 -> 19044.66 | N16: =L16*M16 -> 19044.66 | O16: Distribuição solicitada em analise R01 | P16: Finalizado
A17: =IF($H17="UNIDADE CONSTRUTIVA",OFFSET(A17,-1,0)+1,LARGE(A$3:A14,1)) -> 0 | B17: =IF(H17="UNIDADE CONSTRUTIVA",0,IF(H17="CÉLULA CONSTRUTIVA",OFFSET(B17,-1,0)+1,OFFSET(B17,-1,0))) -> 1 | C17: =IF(H17="CÉLULA CONSTRUTIVA",0,IF(H17="ETAPA",OFFSET(C17,-1,0)+1,OFFSET(C17,-1,0))) -> 1 | D17: =IF(H17="ETAPA",0,IF(H17="SUBETAPA",OFFSET(D17,-1,0)+1,OFFSET(D17,-1,0))) -> 1 | E17: =IF(H17="Subetapa",0,IF(H17="serviço",OFFSET(E17,-1,0)+1,OFFSET(E17,-1,0))) -> 7 | H17: SERVIÇO | I17: =IF(H17="Unidade Construtiva",TEXT(A17,"00"),IF(H17="Célula Construtiva",TEXT(B17,"00"),IF(H17="Etapa",CONCATENATE(TEXT(B17,"00"),".",TEXT(C17,"000")),IF(H17="Subetapa",CONCATENATE(TEXT(B17,"00"),".",TEXT(C17,"000"),".",TEXT(D17,"000")),IF(H17="Serviço",CONCATENATE(TEXT(B17,"00"),".",TEXT(C17,"000"),".",TEXT(D17,"000"),".",TEXT(E17,"000")),""))))) -> 01.001.001.007 | J17: Sondagem do terreno | K17: vb | L17: 1 | M17: =28063.42*0.2 -> 5612.684 | N17: =L17*M17 -> 5612.684 | O17: Distribuição solicitada em analise R01 | P17: Finalizado
A18: =IF($H18="UNIDADE CONSTRUTIVA",OFFSET(A18,-1,0)+1,LARGE(A$3:A10,1)) -> 0 | B18: =IF(H18="UNIDADE CONSTRUTIVA",0,IF(H18="CÉLULA CONSTRUTIVA",OFFSET(B18,-1,0)+1,OFFSET(B18,-1,0))) -> 1 | C18: =IF(H18="CÉLULA CONSTRUTIVA",0,IF(H18="ETAPA",OFFSET(C18,-1,0)+1,OFFSET(C18,-1,0))) -> 1 | D18: =IF(H18="ETAPA",0,IF(H18="SUBETAPA",OFFSET(D18,-1,0)+1,OFFSET(D18,-1,0))) -> 2 | E18: =IF(H18="Subetapa",0,IF(H18="serviço",OFFSET(E18,-1,0)+1,OFFSET(E18,-1,0))) -> 0 | H18: SUBETAPA | I18: =IF(H18="Unidade Construtiva",TEXT(A18,"00"),IF(H18="Célula Construtiva",TEXT(B18,"00"),IF(H18="Etapa",CONCATENATE(TEXT(B18,"00"),".",TEXT(C18,"000")),IF(H18="Subetapa",CONCATENATE(TEXT(B18,"00"),".",TEXT(C18,"000"),".",TEXT(D18,"000")),IF(H18="Serviço",CONCATENATE(TEXT(B18,"00"),".",TEXT(C18,"000"),".",TEXT(D18,"000"),".",TEXT(E18,"000")),""))))) -> 01.001.002 | J18: Projetos | N18: =SUM(N19:N35) -> 959892.33
A19: =IF($H19="UNIDADE CONSTRUTIVA",OFFSET(A19,-1,0)+1,LARGE(A$3:A18,1)) -> 0 | B19: =IF(H19="UNIDADE CONSTRUTIVA",0,IF(H19="CÉLULA CONSTRUTIVA",OFFSET(B19,-1,0)+1,OFFSET(B19,-1,0))) -> 1 | C19: =IF(H19="CÉLULA CONSTRUTIVA",0,IF(H19="ETAPA",OFFSET(C19,-1,0)+1,OFFSET(C19,-1,0))) -> 1 | D19: =IF(H19="ETAPA",0,IF(H19="SUBETAPA",OFFSET(D19,-1,0)+1,OFFSET(D19,-1,0))) -> 2 | E19: =IF(H19="Subetapa",0,IF(H19="serviço",OFFSET(E19,-1,0)+1,OFFSET(E19,-1,0))) -> 1 | H19: SERVIÇO | I19: =IF(H19="Unidade Construtiva",TEXT(A19,"00"),IF(H19="Célula Construtiva",TEXT(B19,"00"),IF(H19="Etapa",CONCATENATE(TEXT(B19,"00"),".",TEXT(C19,"000")),IF(H19="Subetapa",CONCATENATE(TEXT(B19,"00"),".",TEXT(C19,"000"),".",TEXT(D19,"000")),IF(H19="Serviço",CONCATENATE(TEXT(B19,"00"),".",TEXT(C19,"000"),".",TEXT(D19,"000"),".",TEXT(E19,"000")),""))))) -> 01.001.002.001 | J19: Terraplenagem | K19: vb | L19: 1 | M19: 4500 | N19: =L19*M19 -> 4500 | O19: Atualizado confrome email enviado em 2/10/2024 | P19: Finalizado
A20: =IF($H20="UNIDADE CONSTRUTIVA",OFFSET(A20,-1,0)+1,LARGE(A$3:A19,1)) -> 0 | B20: =IF(H20="UNIDADE CONSTRUTIVA",0,IF(H20="CÉLULA CONSTRUTIVA",OFFSET(B20,-1,0)+1,OFFSET(B20,-1,0))) -> 1 | C20: =IF(H20="CÉLULA CONSTRUTIVA",0,IF(H20="ETAPA",OFFSET(C20,-1,0)+1,OFFSET(C20,-1,0))) -> 1 | D20: =IF(H20="ETAPA",0,IF(H20="SUBETAPA",OFFSET(D20,-1,0)+1,OFFSET(D20,-1,0))) -> 2 | E20: =IF(H20="Subetapa",0,IF(H20="serviço",OFFSET(E20,-1,0)+1,OFFSET(E20,-1,0))) -> 2 | H20: SERVIÇO | I20: =IF(H20="Unidade Construtiva",TEXT(A20,"00"),IF(H20="Célula Construtiva",TEXT(B20,"00"),IF(H20="Etapa",CONCATENATE(TEXT(B20,"00"),".",TEXT(C20,"000")),IF(H20="Subetapa",CONCATENATE(TEXT(B20,"00"),".",TEXT(C20,"000"),".",TEXT(D20,"000")),IF(H20="Serviço",CONCATENATE(TEXT(B20,"00"),".",TEXT(C20,"000"),".",TEXT(D20,"000"),".",TEXT(E20,"000")),""))))) -> 01.001.002.002 | J20: Topografia | K20: vb | L20: 1 | M20: 6000 | N20: =L20*M20 -> 6000 | O20: Atualizado confrome email enviado em 2/10/2024 | P20: Finalizado
A21: =IF($H21="UNIDADE CONSTRUTIVA",OFFSET(A21,-1,0)+1,LARGE(A$3:A20,1)) -> 0 | B21: =IF(H21="UNIDADE CONSTRUTIVA",0,IF(H21="CÉLULA CONSTRUTIVA",OFFSET(B21,-1,0)+1,OFFSET(B21,-1,0))) -> 1 | C21: =IF(H21="CÉLULA CONSTRUTIVA",0,IF(H21="ETAPA",OFFSET(C21,-1,0)+1,OFFSET(C21,-1,0))) -> 1 | D21: =IF(H21="ETAPA",0,IF(H21="SUBETAPA",OFFSET(D21,-1,0)+1,OFFSET(D21,-1,0))) -> 2 | E21: =IF(H21="Subetapa",0,IF(H21="serviço",OFFSET(E21,-1,0)+1,OFFSET(E21,-1,0))) -> 3 | H21: SERVIÇO | I21: =IF(H21="Unidade Construtiva",TEXT(A21,"00"),IF(H21="Célula Construtiva",TEXT(B21,"00"),IF(H21="Etapa",CONCATENATE(TEXT(B21,"00"),".",TEXT(C21,"000")),IF(H21="Subetapa",CONCATENATE(TEXT(B21,"00"),".",TEXT(C21,"000"),".",TEXT(D21,"000")),IF(H21="Serviço",CONCATENATE(TEXT(B21,"00"),".",TEXT(C21,"000"),".",TEXT(D21,"000"),".",TEXT(E21,"000")),""))))) -> 01.001.002.003 | J21: Sondagem rotativa | K21: vb | L21: 1 | M21: 28637.89 | N21: =L21*M21 -> 28637.89 | O21: Atualizado confrome email enviado em 2/10/2024 | P21: Finalizado
A22: =IF($H22="UNIDADE CONSTRUTIVA",OFFSET(A22,-1,0)+1,LARGE(A$3:A21,1)) -> 0 | B22: =IF(H22="UNIDADE CONSTRUTIVA",0,IF(H22="CÉLULA CONSTRUTIVA",OFFSET(B22,-1,0)+1,OFFSET(B22,-1,0))) -> 1 | C22: =IF(H22="CÉLULA CONSTRUTIVA",0,IF(H22="ETAPA",OFFSET(C22,-1,0)+1,OFFSET(C22,-1,0))) -> 1 | D22: =IF(H22="ETAPA",0,IF(H22="SUBETAPA",OFFSET(D22,-1,0)+1,OFFSET(D22,-1,0))) -> 2 | E22: =IF(H22="Subetapa",0,IF(H22="serviço",OFFSET(E22,-1,0)+1,OFFSET(E22,-1,0))) -> 4 | H22: SERVIÇO | I22: =IF(H22="Unidade Construtiva",TEXT(A22,"00"),IF(H22="Célula Construtiva",TEXT(B22,"00"),IF(H22="Etapa",CONCATENATE(TEXT(B22,"00"),".",TEXT(C22,"000")),IF(H22="Subetapa",CONCATENATE(TEXT(B22,"00"),".",TEXT(C22,"000"),".",TEXT(D22,"000")),IF(H22="Serviço",CONCATENATE(TEXT(B22,"00"),".",TEXT(C22,"000"),".",TEXT(D22,"000"),".",TEXT(E22,"000")),""))))) -> 01.001.002.004 | J22: Sondagem SPT | K22: vb | L22: 1 | M22: 7553.32 | N22: =L22*M22 -> 7553.32 | O22: Atualizado confrome email enviado em 2/10/2024 | P22: Finalizado
A23: =IF($H23="UNIDADE CONSTRUTIVA",OFFSET(A23,-1,0)+1,LARGE(A$3:A21,1)) -> 0 | B23: =IF(H23="UNIDADE CONSTRUTIVA",0,IF(H23="CÉLULA CONSTRUTIVA",OFFSET(B23,-1,0)+1,OFFSET(B23,-1,0))) -> 1 | C23: =IF(H23="CÉLULA CONSTRUTIVA",0,IF(H23="ETAPA",OFFSET(C23,-1,0)+1,OFFSET(C23,-1,0))) -> 1 | D23: =IF(H23="ETAPA",0,IF(H23="SUBETAPA",OFFSET(D23,-1,0)+1,OFFSET(D23,-1,0))) -> 2 | E23: =IF(H23="Subetapa",0,IF(H23="serviço",OFFSET(E23,-1,0)+1,OFFSET(E23,-1,0))) -> 5 | H23: SERVIÇO | I23: =IF(H23="Unidade Construtiva",TEXT(A23,"00"),IF(H23="Célula Construtiva",TEXT(B23,"00"),IF(H23="Etapa",CONCATENATE(TEXT(B23,"00"),".",TEXT(C23,"000")),IF(H23="Subetapa",CONCATENATE(TEXT(B23,"00"),".",TEXT(C23,"000"),".",TEXT(D23,"000")),IF(H23="Serviço",CONCATENATE(TEXT(B23,"00"),".",TEXT(C23,"000"),".",TEXT(D23,"000"),".",TEXT(E23,"000")),""))))) -> 01.001.002.005 | J23: Imagens 3D Filme | K23: vb | L23: 1 | M23: 49300 | N23: =L23*M23 -> 49300 | O23: Atualizado confrome email enviado em 2/10/2024 | P23: Finalizado
A24: =IF($H24="UNIDADE CONSTRUTIVA",OFFSET(A24,-1,0)+1,LARGE(A$3:A23,1)) -> 0 | B24: =IF(H24="UNIDADE CONSTRUTIVA",0,IF(H24="CÉLULA CONSTRUTIVA",OFFSET(B24,-1,0)+1,OFFSET(B24,-1,0))) -> 1 | C24: =IF(H24="CÉLULA CONSTRUTIVA",0,IF(H24="ETAPA",OFFSET(C24,-1,0)+1,OFFSET(C24,-1,0))) -> 1 | D24: =IF(H24="ETAPA",0,IF(H24="SUBETAPA",OFFSET(D24,-1,0)+1,OFFSET(D24,-1,0))) -> 2 | E24: =IF(H24="Subetapa",0,IF(H24="serviço",OFFSET(E24,-1,0)+1,OFFSET(E24,-1,0))) -> 6 | H24: SERVIÇO | I24: =IF(H24="Unidade Construtiva",TEXT(A24,"00"),IF(H24="Célula Construtiva",TEXT(B24,"00"),IF(H24="Etapa",CONCATENATE(TEXT(B24,"00"),".",TEXT(C24,"000")),IF(H24="Subetapa",CONCATENATE(TEXT(B24,"00"),".",TEXT(C24,"000"),".",TEXT(D24,"000")),IF(H24="Serviço",CONCATENATE(TEXT(B24,"00"),".",TEXT(C24,"000"),".",TEXT(D24,"000"),".",TEXT(E24,"000")),""))))) -> 01.001.002.006 | J24: Estudo Geofísico | K24: vb | L24: 1 | M24: 18927.87 | N24: =L24*M24 -> 18927.87 | O24: Atualizado confrome email enviado em 2/10/2024 | P24: Finalizado
A25: =IF($H25="UNIDADE CONSTRUTIVA",OFFSET(A25,-1,0)+1,LARGE(A$3:A24,1)) -> 0 | B25: =IF(H25="UNIDADE CONSTRUTIVA",0,IF(H25="CÉLULA CONSTRUTIVA",OFFSET(B25,-1,0)+1,OFFSET(B25,-1,0))) -> 1 | C25: =IF(H25="CÉLULA CONSTRUTIVA",0,IF(H25="ETAPA",OFFSET(C25,-1,0)+1,OFFSET(C25,-1,0))) -> 1 | D25: =IF(H25="ETAPA",0,IF(H25="SUBETAPA",OFFSET(D25,-1,0)+1,OFFSET(D25,-1,0))) -> 2 | E25: =IF(H25="Subetapa",0,IF(H25="serviço",OFFSET(E25,-1,0)+1,OFFSET(E25,-1,0))) -> 7 | H25: SERVIÇO | I25: =IF(H25="Unidade Construtiva",TEXT(A25,"00"),IF(H25="Célula Construtiva",TEXT(B25,"00"),IF(H25="Etapa",CONCATENATE(TEXT(B25,"00"),".",TEXT(C25,"000")),IF(H25="Subetapa",CONCATENATE(TEXT(B25,"00"),".",TEXT(C25,"000"),".",TEXT(D25,"000")),IF(H25="Serviço",CONCATENATE(TEXT(B25,"00"),".",TEXT(C25,"000"),".",TEXT(D25,"000"),".",TEXT(E25,"000")),""))))) -> 01.001.002.007 | J25: Fundações Contenção | K25: vb | L25: 1 | M25: 13000 | N25: =L25*M25 -> 13000 | O25: Atualizado confrome email enviado em 2/10/2024 | P25: Finalizado
A26: =IF($H26="UNIDADE CONSTRUTIVA",OFFSET(A26,-1,0)+1,LARGE(A$3:A25,1)) -> 0 | B26: =IF(H26="UNIDADE CONSTRUTIVA",0,IF(H26="CÉLULA CONSTRUTIVA",OFFSET(B26,-1,0)+1,OFFSET(B26,-1,0))) -> 1 | C26: =IF(H26="CÉLULA CONSTRUTIVA",0,IF(H26="ETAPA",OFFSET(C26,-1,0)+1,OFFSET(C26,-1,0))) -> 1 | D26: =IF(H26="ETAPA",0,IF(H26="SUBETAPA",OFFSET(D26,-1,0)+1,OFFSET(D26,-1,0))) -> 2 | E26: =IF(H26="Subetapa",0,IF(H26="serviço",OFFSET(E26,-1,0)+1,OFFSET(E26,-1,0))) -> 8 | H26: SERVIÇO | I26: =IF(H26="Unidade Construtiva",TEXT(A26,"00"),IF(H26="Célula Construtiva",TEXT(B26,"00"),IF(H26="Etapa",CONCATENATE(TEXT(B26,"00"),".",TEXT(C26,"000")),IF(H26="Subetapa",CONCATENATE(TEXT(B26,"00"),".",TEXT(C26,"000"),".",TEXT(D26,"000")),IF(H26="Serviço",CONCATENATE(TEXT(B26,"00"),".",TEXT(C26,"000"),".",TEXT(D26,"000"),".",TEXT(E26,"000")),""))))) -> 01.001.002.008 | J26: Estudo Hidrogeológico | K26: vb | L26: 1 | M26: 6873.25 | N26: =L26*M26 -> 6873.25 | O26: Atualizado confrome email enviado em 2/10/2024 | P26: Finalizado
A27: =IF($H27="UNIDADE CONSTRUTIVA",OFFSET(A27,-1,0)+1,LARGE(A$3:A26,1)) -> 0 | B27: =IF(H27="UNIDADE CONSTRUTIVA",0,IF(H27="CÉLULA CONSTRUTIVA",OFFSET(B27,-1,0)+1,OFFSET(B27,-1,0))) -> 1 | C27: =IF(H27="CÉLULA CONSTRUTIVA",0,IF(H27="ETAPA",OFFSET(C27,-1,0)+1,OFFSET(C27,-1,0))) -> 1 | D27: =IF(H27="ETAPA",0,IF(H27="SUBETAPA",OFFSET(D27,-1,0)+1,OFFSET(D27,-1,0))) -> 2 | E27: =IF(H27="Subetapa",0,IF(H27="serviço",OFFSET(E27,-1,0)+1,OFFSET(E27,-1,0))) -> 9 | H27: SERVIÇO | I27: =IF(H27="Unidade Construtiva",TEXT(A27,"00"),IF(H27="Célula Construtiva",TEXT(B27,"00"),IF(H27="Etapa",CONCATENATE(TEXT(B27,"00"),".",TEXT(C27,"000")),IF(H27="Subetapa",CONCATENATE(TEXT(B27,"00"),".",TEXT(C27,"000"),".",TEXT(D27,"000")),IF(H27="Serviço",CONCATENATE(TEXT(B27,"00"),".",TEXT(C27,"000"),".",TEXT(D27,"000"),".",TEXT(E27,"000")),""))))) -> 01.001.002.009 | J27: Luminotécnico | K27: vb | L27: 1 | M27: 54400 | N27: =L27*M27 -> 54400 | O27: Atualizado confrome email enviado em 2/10/2024 | P27: Finalizado
A28: =IF($H28="UNIDADE CONSTRUTIVA",OFFSET(A28,-1,0)+1,LARGE(A$3:A27,1)) -> 0 | B28: =IF(H28="UNIDADE CONSTRUTIVA",0,IF(H28="CÉLULA CONSTRUTIVA",OFFSET(B28,-1,0)+1,OFFSET(B28,-1,0))) -> 1 | C28: =IF(H28="CÉLULA CONSTRUTIVA",0,IF(H28="ETAPA",OFFSET(C28,-1,0)+1,OFFSET(C28,-1,0))) -> 1 | D28: =IF(H28="ETAPA",0,IF(H28="SUBETAPA",OFFSET(D28,-1,0)+1,OFFSET(D28,-1,0))) -> 2 | E28: =IF(H28="Subetapa",0,IF(H28="serviço",OFFSET(E28,-1,0)+1,OFFSET(E28,-1,0))) -> 10 | H28: SERVIÇO | I28: =IF(H28="Unidade Construtiva",TEXT(A28,"00"),IF(H28="Célula Construtiva",TEXT(B28,"00"),IF(H28="Etapa",CONCATENATE(TEXT(B28,"00"),".",TEXT(C28,"000")),IF(H28="Subetapa",CONCATENATE(TEXT(B28,"00"),".",TEXT(C28,"000"),".",TEXT(D28,"000")),IF(H28="Serviço",CONCATENATE(TEXT(B28,"00"),".",TEXT(C28,"000"),".",TEXT(D28,"000"),".",TEXT(E28,"000")),""))))) -> 01.001.002.010 | J28: Energia Renovável | K28: vb | L28: 1 | M28: 8500 | N28: =L28*M28 -> 8500 | O28: Atualizado confrome email enviado em 2/10/2024 | P28: Finalizado
A29: =IF($H29="UNIDADE CONSTRUTIVA",OFFSET(A29,-1,0)+1,LARGE(A$3:A28,1)) -> 0 | B29: =IF(H29="UNIDADE CONSTRUTIVA",0,IF(H29="CÉLULA CONSTRUTIVA",OFFSET(B29,-1,0)+1,OFFSET(B29,-1,0))) -> 1 | C29: =IF(H29="CÉLULA CONSTRUTIVA",0,IF(H29="ETAPA",OFFSET(C29,-1,0)+1,OFFSET(C29,-1,0))) -> 1 | D29: =IF(H29="ETAPA",0,IF(H29="SUBETAPA",OFFSET(D29,-1,0)+1,OFFSET(D29,-1,0))) -> 2 | E29: =IF(H29="Subetapa",0,IF(H29="serviço",OFFSET(E29,-1,0)+1,OFFSET(E29,-1,0))) -> 11 | H29: SERVIÇO | I29: =IF(H29="Unidade Construtiva",TEXT(A29,"00"),IF(H29="Célula Construtiva",TEXT(B29,"00"),IF(H29="Etapa",CONCATENATE(TEXT(B29,"00"),".",TEXT(C29,"000")),IF(H29="Subetapa",CONCATENATE(TEXT(B29,"00"),".",TEXT(C29,"000"),".",TEXT(D29,"000")),IF(H29="Serviço",CONCATENATE(TEXT(B29,"00"),".",TEXT(C29,"000"),".",TEXT(D29,"000"),".",TEXT(E29,"000")),""))))) -> 01.001.002.011 | J29: Drywall | K29: vb | L29: 1 | M29: 18000 | N29: =L29*M29 -> 18000 | O29: Atualizado confrome email enviado em 2/10/2024 | P29: Finalizado
A30: =IF($H30="UNIDADE CONSTRUTIVA",OFFSET(A30,-1,0)+1,LARGE(A$3:A29,1)) -> 0 | B30: =IF(H30="UNIDADE CONSTRUTIVA",0,IF(H30="CÉLULA CONSTRUTIVA",OFFSET(B30,-1,0)+1,OFFSET(B30,-1,0))) -> 1 | C30: =IF(H30="CÉLULA CONSTRUTIVA",0,IF(H30="ETAPA",OFFSET(C30,-1,0)+1,OFFSET(C30,-1,0))) -> 1 | D30: =IF(H30="ETAPA",0,IF(H30="SUBETAPA",OFFSET(D30,-1,0)+1,OFFSET(D30,-1,0))) -> 2 | E30: =IF(H30="Subetapa",0,IF(H30="serviço",OFFSET(E30,-1,0)+1,OFFSET(E30,-1,0))) -> 12 | H30: SERVIÇO | I30: =IF(H30="Unidade Construtiva",TEXT(A30,"00"),IF(H30="Célula Construtiva",TEXT(B30,"00"),IF(H30="Etapa",CONCATENATE(TEXT(B30,"00"),".",TEXT(C30,"000")),IF(H30="Subetapa",CONCATENATE(TEXT(B30,"00"),".",TEXT(C30,"000"),".",TEXT(D30,"000")),IF(H30="Serviço",CONCATENATE(TEXT(B30,"00"),".",TEXT(C30,"000"),".",TEXT(D30,"000"),".",TEXT(E30,"000")),""))))) -> 01.001.002.012 | J30: Paisagismo | K30: vb | L30: 1 | M30: 154000 | N30: =L30*M30 -> 154000 | O30: Atualizado confrome email enviado em 2/10/2024 | P30: Finalizado
A31: =IF($H31="UNIDADE CONSTRUTIVA",OFFSET(A31,-1,0)+1,LARGE(A$3:A30,1)) -> 0 | B31: =IF(H31="UNIDADE CONSTRUTIVA",0,IF(H31="CÉLULA CONSTRUTIVA",OFFSET(B31,-1,0)+1,OFFSET(B31,-1,0))) -> 1 | C31: =IF(H31="CÉLULA CONSTRUTIVA",0,IF(H31="ETAPA",OFFSET(C31,-1,0)+1,OFFSET(C31,-1,0))) -> 1 | D31: =IF(H31="ETAPA",0,IF(H31="SUBETAPA",OFFSET(D31,-1,0)+1,OFFSET(D31,-1,0))) -> 2 | E31: =IF(H31="Subetapa",0,IF(H31="serviço",OFFSET(E31,-1,0)+1,OFFSET(E31,-1,0))) -> 13 | H31: SERVIÇO | I31: =IF(H31="Unidade Construtiva",TEXT(A31,"00"),IF(H31="Célula Construtiva",TEXT(B31,"00"),IF(H31="Etapa",CONCATENATE(TEXT(B31,"00"),".",TEXT(C31,"000")),IF(H31="Subetapa",CONCATENATE(TEXT(B31,"00"),".",TEXT(C31,"000"),".",TEXT(D31,"000")),IF(H31="Serviço",CONCATENATE(TEXT(B31,"00"),".",TEXT(C31,"000"),".",TEXT(D31,"000"),".",TEXT(E31,"000")),""))))) -> 01.001.002.013 | J31: Aprovativo | K31: vb | L31: 1 | M31: 10200 | N31: =L31*M31 -> 10200 | O31: Atualizado confrome email enviado em 2/10/2024 | P31: Finalizado
A32: =IF($H32="UNIDADE CONSTRUTIVA",OFFSET(A32,-1,0)+1,LARGE(A$3:A31,1)) -> 0 | B32: =IF(H32="UNIDADE CONSTRUTIVA",0,IF(H32="CÉLULA CONSTRUTIVA",OFFSET(B32,-1,0)+1,OFFSET(B32,-1,0))) -> 1 | C32: =IF(H32="CÉLULA CONSTRUTIVA",0,IF(H32="ETAPA",OFFSET(C32,-1,0)+1,OFFSET(C32,-1,0))) -> 1 | D32: =IF(H32="ETAPA",0,IF(H32="SUBETAPA",OFFSET(D32,-1,0)+1,OFFSET(D32,-1,0))) -> 2 | E32: =IF(H32="Subetapa",0,IF(H32="serviço",OFFSET(E32,-1,0)+1,OFFSET(E32,-1,0))) -> 14 | H32: SERVIÇO | I32: =IF(H32="Unidade Construtiva",TEXT(A32,"00"),IF(H32="Célula Construtiva",TEXT(B32,"00"),IF(H32="Etapa",CONCATENATE(TEXT(B32,"00"),".",TEXT(C32,"000")),IF(H32="Subetapa",CONCATENATE(TEXT(B32,"00"),".",TEXT(C32,"000"),".",TEXT(D32,"000")),IF(H32="Serviço",CONCATENATE(TEXT(B32,"00"),".",TEXT(C32,"000"),".",TEXT(D32,"000"),".",TEXT(E32,"000")),""))))) -> 01.001.002.014 | J32: Executivo | K32: vb | L32: 1 | M32: 330000 | N32: =L32*M32 -> 330000 | O32: Atualizado confrome email enviado em 2/10/2024 | P32: Finalizado
A33: =IF($H33="UNIDADE CONSTRUTIVA",OFFSET(A33,-1,0)+1,LARGE(A$3:A32,1)) -> 0 | B33: =IF(H33="UNIDADE CONSTRUTIVA",0,IF(H33="CÉLULA CONSTRUTIVA",OFFSET(B33,-1,0)+1,OFFSET(B33,-1,0))) -> 1 | C33: =IF(H33="CÉLULA CONSTRUTIVA",0,IF(H33="ETAPA",OFFSET(C33,-1,0)+1,OFFSET(C33,-1,0))) -> 1 | D33: =IF(H33="ETAPA",0,IF(H33="SUBETAPA",OFFSET(D33,-1,0)+1,OFFSET(D33,-1,0))) -> 2 | E33: =IF(H33="Subetapa",0,IF(H33="serviço",OFFSET(E33,-1,0)+1,OFFSET(E33,-1,0))) -> 15 | H33: SERVIÇO | I33: =IF(H33="Unidade Construtiva",TEXT(A33,"00"),IF(H33="Célula Construtiva",TEXT(B33,"00"),IF(H33="Etapa",CONCATENATE(TEXT(B33,"00"),".",TEXT(C33,"000")),IF(H33="Subetapa",CONCATENATE(TEXT(B33,"00"),".",TEXT(C33,"000"),".",TEXT(D33,"000")),IF(H33="Serviço",CONCATENATE(TEXT(B33,"00"),".",TEXT(C33,"000"),".",TEXT(D33,"000"),".",TEXT(E33,"000")),""))))) -> 01.001.002.015 | J33: Complementares ( ELE, MEC HIDRO, EST, PPCI) | K33: vb | L33: 1 | M33: 170000 | N33: =L33*M33 -> 170000 | O33: Atualizado confrome email enviado em 2/10/2024 | P33: Finalizado
A34: =IF($H34="UNIDADE CONSTRUTIVA",OFFSET(A34,-1,0)+1,LARGE(A$3:A33,1)) -> 0 | B34: =IF(H34="UNIDADE CONSTRUTIVA",0,IF(H34="CÉLULA CONSTRUTIVA",OFFSET(B34,-1,0)+1,OFFSET(B34,-1,0))) -> 1 | C34: =IF(H34="CÉLULA CONSTRUTIVA",0,IF(H34="ETAPA",OFFSET(C34,-1,0)+1,OFFSET(C34,-1,0))) -> 1 | D34: =IF(H34="ETAPA",0,IF(H34="SUBETAPA",OFFSET(D34,-1,0)+1,OFFSET(D34,-1,0))) -> 2 | E34: =IF(H34="Subetapa",0,IF(H34="serviço",OFFSET(E34,-1,0)+1,OFFSET(E34,-1,0))) -> 16 | H34: SERVIÇO | I34: =IF(H34="Unidade Construtiva",TEXT(A34,"00"),IF(H34="Célula Construtiva",TEXT(B34,"00"),IF(H34="Etapa",CONCATENATE(TEXT(B34,"00"),".",TEXT(C34,"000")),IF(H34="Subetapa",CONCATENATE(TEXT(B34,"00"),".",TEXT(C34,"000"),".",TEXT(D34,"000")),IF(H34="Serviço",CONCATENATE(TEXT(B34,"00"),".",TEXT(C34,"000"),".",TEXT(D34,"000"),".",TEXT(E34,"000")),""))))) -> 01.001.002.016 | J34: Interiores | K34: vb | L34: 1 | M34: 60000 | N34: =L34*M34 -> 60000 | O34: Atualizado confrome email enviado em 2/10/2024 | P34: Finalizado
A35: =IF($H35="UNIDADE CONSTRUTIVA",OFFSET(A35,-1,0)+1,LARGE(A$3:A34,1)) -> 0 | B35: =IF(H35="UNIDADE CONSTRUTIVA",0,IF(H35="CÉLULA CONSTRUTIVA",OFFSET(B35,-1,0)+1,OFFSET(B35,-1,0))) -> 1 | C35: =IF(H35="CÉLULA CONSTRUTIVA",0,IF(H35="ETAPA",OFFSET(C35,-1,0)+1,OFFSET(C35,-1,0))) -> 1 | D35: =IF(H35="ETAPA",0,IF(H35="SUBETAPA",OFFSET(D35,-1,0)+1,OFFSET(D35,-1,0))) -> 2 | E35: =IF(H35="Subetapa",0,IF(H35="serviço",OFFSET(E35,-1,0)+1,OFFSET(E35,-1,0))) -> 17 | H35: SERVIÇO | I35: =IF(H35="Unidade Construtiva",TEXT(A35,"00"),IF(H35="Célula Construtiva",TEXT(B35,"00"),IF(H35="Etapa",CONCATENATE(TEXT(B35,"00"),".",TEXT(C35,"000")),IF(H35="Subetapa",CONCATENATE(TEXT(B35,"00"),".",TEXT(C35,"000"),".",TEXT(D35,"000")),IF(H35="Serviço",CONCATENATE(TEXT(B35,"00"),".",TEXT(C35,"000"),".",TEXT(D35,"000"),".",TEXT(E35,"000")),""))))) -> 01.001.002.017 | J35: Sustentabilidade | K35: vb | L35: 1 | M35: 20000 | N35: =L35*M35 -> 20000 | O35: Distribuição solicitada em analise R01 | P35: Finalizado
A36: =IF($H36="UNIDADE CONSTRUTIVA",OFFSET(A36,-1,0)+1,LARGE(A$3:A34,1)) -> 0 | B36: =IF(H36="UNIDADE CONSTRUTIVA",0,IF(H36="CÉLULA CONSTRUTIVA",OFFSET(B36,-1,0)+1,OFFSET(B36,-1,0))) -> 1 | C36: =IF(H36="CÉLULA CONSTRUTIVA",0,IF(H36="ETAPA",OFFSET(C36,-1,0)+1,OFFSET(C36,-1,0))) -> 1 | D36: =IF(H36="ETAPA",0,IF(H36="SUBETAPA",OFFSET(D36,-1,0)+1,OFFSET(D36,-1,0))) -> 3 | E36: =IF(H36="Subetapa",0,IF(H36="serviço",OFFSET(E36,-1,0)+1,OFFSET(E36,-1,0))) -> 0 | H36: SUBETAPA | I36: =IF(H36="Unidade Construtiva",TEXT(A36,"00"),IF(H36="Célula Construtiva",TEXT(B36,"00"),IF(H36="Etapa",CONCATENATE(TEXT(B36,"00"),".",TEXT(C36,"000")),IF(H36="Subetapa",CONCATENATE(TEXT(B36,"00"),".",TEXT(C36,"000"),".",TEXT(D36,"000")),IF(H36="Serviço",CONCATENATE(TEXT(B36,"00"),".",TEXT(C36,"000"),".",TEXT(D36,"000"),".",TEXT(E36,"000")),""))))) -> 01.001.003 | J36: Consultorias | N36: =SUM(N37:N39) -> 203539.2
A37: =IF($H37="UNIDADE CONSTRUTIVA",OFFSET(A37,-1,0)+1,LARGE(A$3:A35,1)) -> 0 | B37: =IF(H37="UNIDADE CONSTRUTIVA",0,IF(H37="CÉLULA CONSTRUTIVA",OFFSET(B37,-1,0)+1,OFFSET(B37,-1,0))) -> 1 | C37: =IF(H37="CÉLULA CONSTRUTIVA",0,IF(H37="ETAPA",OFFSET(C37,-1,0)+1,OFFSET(C37,-1,0))) -> 1 | D37: =IF(H37="ETAPA",0,IF(H37="SUBETAPA",OFFSET(D37,-1,0)+1,OFFSET(D37,-1,0))) -> 3 | E37: =IF(H37="Subetapa",0,IF(H37="serviço",OFFSET(E37,-1,0)+1,OFFSET(E37,-1,0))) -> 1 | H37: SERVIÇO | I37: =IF(H37="Unidade Construtiva",TEXT(A37,"00"),IF(H37="Célula Construtiva",TEXT(B37,"00"),IF(H37="Etapa",CONCATENATE(TEXT(B37,"00"),".",TEXT(C37,"000")),IF(H37="Subetapa",CONCATENATE(TEXT(B37,"00"),".",TEXT(C37,"000"),".",TEXT(D37,"000")),IF(H37="Serviço",CONCATENATE(TEXT(B37,"00"),".",TEXT(C37,"000"),".",TEXT(D37,"000"),".",TEXT(E37,"000")),""))))) -> 01.001.003.001 | J37: Orçamento e Planejamento | K37: vb | L37: 1 | M37: =5819+3082+5878.8+13524+6090.4+2921 -> 37315.2 | N37: =L37*M37 -> 37315.2 | O37: Atualizado conforme contrado Cartesian | P37: Finalizado
A38: =IF($H38="UNIDADE CONSTRUTIVA",OFFSET(A38,-1,0)+1,LARGE(A$3:A37,1)) -> 0 | B38: =IF(H38="UNIDADE CONSTRUTIVA",0,IF(H38="CÉLULA CONSTRUTIVA",OFFSET(B38,-1,0)+1,OFFSET(B38,-1,0))) -> 1 | C38: =IF(H38="CÉLULA CONSTRUTIVA",0,IF(H38="ETAPA",OFFSET(C38,-1,0)+1,OFFSET(C38,-1,0))) -> 1 | D38: =IF(H38="ETAPA",0,IF(H38="SUBETAPA",OFFSET(D38,-1,0)+1,OFFSET(D38,-1,0))) -> 3 | E38: =IF(H38="Subetapa",0,IF(H38="serviço",OFFSET(E38,-1,0)+1,OFFSET(E38,-1,0))) -> 2 | H38: SERVIÇO | I38: =IF(H38="Unidade Construtiva",TEXT(A38,"00"),IF(H38="Célula Construtiva",TEXT(B38,"00"),IF(H38="Etapa",CONCATENATE(TEXT(B38,"00"),".",TEXT(C38,"000")),IF(H38="Subetapa",CONCATENATE(TEXT(B38,"00"),".",TEXT(C38,"000"),".",TEXT(D38,"000")),IF(H38="Serviço",CONCATENATE(TEXT(B38,"00"),".",TEXT(C38,"000"),".",TEXT(D38,"000"),".",TEXT(E38,"000")),""))))) -> 01.001.003.002 | J38: Consultoria de concreto | K38: vb | L38: 1 | M38: =4*'Obra '!E8 -> 19840 | N38: =L38*M38 -> 19840 | O38: Revisão solicitada em analise R02 | P38: Finalizado
A39: =IF($H39="UNIDADE CONSTRUTIVA",OFFSET(A39,-1,0)+1,LARGE(A$3:A37,1)) -> 0 | B39: =IF(H39="UNIDADE CONSTRUTIVA",0,IF(H39="CÉLULA CONSTRUTIVA",OFFSET(B39,-1,0)+1,OFFSET(B39,-1,0))) -> 1 | C39: =IF(H39="CÉLULA CONSTRUTIVA",0,IF(H39="ETAPA",OFFSET(C39,-1,0)+1,OFFSET(C39,-1,0))) -> 1 | D39: =IF(H39="ETAPA",0,IF(H39="SUBETAPA",OFFSET(D39,-1,0)+1,OFFSET(D39,-1,0))) -> 3 | E39: =IF(H39="Subetapa",0,IF(H39="serviço",OFFSET(E39,-1,0)+1,OFFSET(E39,-1,0))) -> 3 | H39: SERVIÇO | I39: =IF(H39="Unidade Construtiva",TEXT(A39,"00"),IF(H39="Célula Construtiva",TEXT(B39,"00"),IF(H39="Etapa",CONCATENATE(TEXT(B39,"00"),".",TEXT(C39,"000")),IF(H39="Subetapa",CONCATENATE(TEXT(B39,"00"),".",TEXT(C39,"000"),".",TEXT(D39,"000")),IF(H39="Serviço",CONCATENATE(TEXT(B39,"00"),".",TEXT(C39,"000"),".",TEXT(D39,"000"),".",TEXT(E39,"000")),""))))) -> 01.001.003.003 | J39: Outros | K39: vb | L39: 1 | M39: =203539.2-M38-M37 -> 146384 | N39: =L39*M39 -> 146384 | O39: Custo complementar para valor de email enviado em 2/10/2024 | P39: Finalizado
A40: =IF($H40="UNIDADE CONSTRUTIVA",OFFSET(A40,-1,0)+1,LARGE(A$3:A36,1)) -> 0 | B40: =IF(H40="UNIDADE CONSTRUTIVA",0,IF(H40="CÉLULA CONSTRUTIVA",OFFSET(B40,-1,0)+1,OFFSET(B40,-1,0))) -> 1 | C40: =IF(H40="CÉLULA CONSTRUTIVA",0,IF(H40="ETAPA",OFFSET(C40,-1,0)+1,OFFSET(C40,-1,0))) -> 1 | D40: =IF(H40="ETAPA",0,IF(H40="SUBETAPA",OFFSET(D40,-1,0)+1,OFFSET(D40,-1,0))) -> 4 | E40: =IF(H40="Subetapa",0,IF(H40="serviço",OFFSET(E40,-1,0)+1,OFFSET(E40,-1,0))) -> 0 | H40: SUBETAPA | I40: =IF(H40="Unidade Construtiva",TEXT(A40,"00"),IF(H40="Célula Construtiva",TEXT(B40,"00"),IF(H40="Etapa",CONCATENATE(TEXT(B40,"00"),".",TEXT(C40,"000")),IF(H40="Subetapa",CONCATENATE(TEXT(B40,"00"),".",TEXT(C40,"000"),".",TEXT(D40,"000")),IF(H40="Serviço",CONCATENATE(TEXT(B40,"00"),".",TEXT(C40,"000"),".",TEXT(D40,"000"),".",TEXT(E40,"000")),""))))) -> 01.001.004 | J40: Ensaios e Laudos | N40: =SUM(N41:N48) -> 127343.59
A41: =IF($H41="UNIDADE CONSTRUTIVA",OFFSET(A41,-1,0)+1,LARGE(A$3:A37,1)) -> 0 | B41: =IF(H41="UNIDADE CONSTRUTIVA",0,IF(H41="CÉLULA CONSTRUTIVA",OFFSET(B41,-1,0)+1,OFFSET(B41,-1,0))) -> 1 | C41: =IF(H41="CÉLULA CONSTRUTIVA",0,IF(H41="ETAPA",OFFSET(C41,-1,0)+1,OFFSET(C41,-1,0))) -> 1 | D41: =IF(H41="ETAPA",0,IF(H41="SUBETAPA",OFFSET(D41,-1,0)+1,OFFSET(D41,-1,0))) -> 4 | E41: =IF(H41="Subetapa",0,IF(H41="serviço",OFFSET(E41,-1,0)+1,OFFSET(E41,-1,0))) -> 1 | H41: SERVIÇO | I41: =IF(H41="Unidade Construtiva",TEXT(A41,"00"),IF(H41="Célula Construtiva",TEXT(B41,"00"),IF(H41="Etapa",CONCATENATE(TEXT(B41,"00"),".",TEXT(C41,"000")),IF(H41="Subetapa",CONCATENATE(TEXT(B41,"00"),".",TEXT(C41,"000"),".",TEXT(D41,"000")),IF(H41="Serviço",CONCATENATE(TEXT(B41,"00"),".",TEXT(C41,"000"),".",TEXT(D41,"000"),".",TEXT(E41,"000")),""))))) -> 01.001.004.001 | J41: Laudo de vizinhança | K41: vb | L41: 1 | M41: =0.17*'Obra '!$E$9 -> 1618.7961 | N41: =L41*M41 -> 1618.7961 | O41: Valor estimado com base em obras com característica e porte similares. | P41: Finalizado
A42: =IF($H42="UNIDADE CONSTRUTIVA",OFFSET(A42,-1,0)+1,LARGE(A$3:A41,1)) -> 0 | B42: =IF(H42="UNIDADE CONSTRUTIVA",0,IF(H42="CÉLULA CONSTRUTIVA",OFFSET(B42,-1,0)+1,OFFSET(B42,-1,0))) -> 1 | C42: =IF(H42="CÉLULA CONSTRUTIVA",0,IF(H42="ETAPA",OFFSET(C42,-1,0)+1,OFFSET(C42,-1,0))) -> 1 | D42: =IF(H42="ETAPA",0,IF(H42="SUBETAPA",OFFSET(D42,-1,0)+1,OFFSET(D42,-1,0))) -> 4 | E42: =IF(H42="Subetapa",0,IF(H42="serviço",OFFSET(E42,-1,0)+1,OFFSET(E42,-1,0))) -> 2 | H42: SERVIÇO | I42: =IF(H42="Unidade Construtiva",TEXT(A42,"00"),IF(H42="Célula Construtiva",TEXT(B42,"00"),IF(H42="Etapa",CONCATENATE(TEXT(B42,"00"),".",TEXT(C42,"000")),IF(H42="Subetapa",CONCATENATE(TEXT(B42,"00"),".",TEXT(C42,"000"),".",TEXT(D42,"000")),IF(H42="Serviço",CONCATENATE(TEXT(B42,"00"),".",TEXT(C42,"000"),".",TEXT(D42,"000"),".",TEXT(E42,"000")),""))))) -> 01.001.004.002 | J42: Controle tecnológico do concreto | K42: vb | L42: 1 | M42: =Ensaios!F13 -> 70450 | N42: =L42*M42 -> 70450 | O42: Valor determinado conforme aba "Ensaios" | P42: Finalizado
A43: =IF($H43="UNIDADE CONSTRUTIVA",OFFSET(A43,-1,0)+1,LARGE(A$3:A41,1)) -> 0 | B43: =IF(H43="UNIDADE CONSTRUTIVA",0,IF(H43="CÉLULA CONSTRUTIVA",OFFSET(B43,-1,0)+1,OFFSET(B43,-1,0))) -> 1 | C43: =IF(H43="CÉLULA CONSTRUTIVA",0,IF(H43="ETAPA",OFFSET(C43,-1,0)+1,OFFSET(C43,-1,0))) -> 1 | D43: =IF(H43="ETAPA",0,IF(H43="SUBETAPA",OFFSET(D43,-1,0)+1,OFFSET(D43,-1,0))) -> 4 | E43: =IF(H43="Subetapa",0,IF(H43="serviço",OFFSET(E43,-1,0)+1,OFFSET(E43,-1,0))) -> 3 | H43: SERVIÇO | I43: =IF(H43="Unidade Construtiva",TEXT(A43,"00"),IF(H43="Célula Construtiva",TEXT(B43,"00"),IF(H43="Etapa",CONCATENATE(TEXT(B43,"00"),".",TEXT(C43,"000")),IF(H43="Subetapa",CONCATENATE(TEXT(B43,"00"),".",TEXT(C43,"000"),".",TEXT(D43,"000")),IF(H43="Serviço",CONCATENATE(TEXT(B43,"00"),".",TEXT(C43,"000"),".",TEXT(D43,"000"),".",TEXT(E43,"000")),""))))) -> 01.001.004.003 | J43: Ensaios de prova de carga de fundação | K43: vb | L43: 1 | M43: =0.45*'Obra '!$E$9 -> 4285.0485 | N43: =L43*M43 -> 4285.0485 | O43: Valor estimado com base em obras com característica e porte similares. | P43: Finalizado
...

Sheet GERENCIAMENTO EXECUTIVO
G4: PROJETO: | I4: ='PROJETOS E GERENCIAMENTO TÉCNIC'!I4 -> Aquos Oasis Home | O4: REVISÃO: | P4: DATA
G5: EMPRESA: | I5: ='PROJETOS E GERENCIAMENTO TÉCNIC'!I5 -> Blue Heaven | O5: R01 | P5: 45798
