Workbook
Name \0: #REF!
Name \0: #REF!
Name \0: #REF!
Name \0: #REF!
Name \0: #REF!
Name \0: #REF!
Name \0: #REF!
Name \0: #REF!
Name \1: #REF!
Name \a: #REF!
Name \a: #REF!
Name \b: #REF!
Name \c: #REF!
Name \d: #REF!
Name \e: #REF!
Name \i: #REF!
Name \J: #REF!
Name \k: #REF!
Name \l: #N/A
Name \m: #REF!
Name \m: #REF!
Name \m: #REF!
Name \o: #REF!
Name \p: #REF!
Name \r: #REF!
Name \T: #REF!
Name \z: #REF!
Name \z: #REF!
Name ______ACR10: #REF!
Name ______ACR10: #REF!
Name ______ACR15: #REF!
Name ______ACR15: #REF!
Name ______acr20: #REF!
Name ______acr20: #REF!
Name ______acr5: #REF!
Name ______ARQ1: #REF!
Name ______QT100: #REF!
Name ______QT2: #REF!
Name ______QT3: #REF!
Name ______QT4: #REF!
Name ______QT50: #REF!
Name ______QT75: #REF!
Name _____ACR10: #REF!
Name _____ACR10: #REF!
Name _____ACR15: #REF!
Name _____ACR15: #REF!
Name _____acr20: #REF!
Name _____acr20: #REF!
Name _____acr5: #REF!
Name _____ARQ1: #REF!
Name _____QT100: #REF!
Name _____QT2: #REF!
Name _____QT3: #REF!
Name _____QT4: #REF!
Name _____QT50: #REF!
Name _____QT75: #REF!
Name ___ACR10: #REF!
Name ___ACR15: #REF!
Name ___acr20: #REF!
Name ___acr5: #REF!

Sheet DADOS_INICIAIS
A1: Obra | B1: 2cinco4
A2: Empresa | B2: H Empreendimentos
A3: Revisão | B3: R00
A4: Arquitetura base | B4: 01 - Implantação e Situação - R1
A5: DADOS OBRA
B7: Descrição | C7: Identificador | D7: Unidade | E7: Quantidade
B8: ÁREA DO TERRENO | C8: AT | D8: M2 | E8: 1127.1
B9: ÁREA TOTAL CONSTRUÍDA | C9: AC | D9: M2 | E9: 11218.19
B10: UNIDADES RESIDENCIAIS | C10: UR | D10: UN | E10: =1+1+21+21 -> 44
B11: Dormitórios | C11: dorm | D11: UN
B12: Banheiros | C12: ban | D12: UN
B13: UNIDADES COMERCIAIS | C13: UC | D13: UN | E13: 9
B14: Churrasqueiras | C14: CHU | D14: UN | E14: ='SISTEMAS ESPECIAIS'!B10 -> 46
B15: NÚMERO TOTAL DE PAVIMENTOS | C15: NP | D15: UN | E15: 27
B16: NÚMERO DE PAVIMENTOS TIPO | C16: NPT | D16: UN | E16: 21
B17: NÚMERO DE PAVIMENTOS TIPO DIFERENCIADOS | C17: NPD | D17: UN | E17: 1
B18: NÚMERO DE PAVIMENTOS DUPLEX | C18: ND | D18: UN | E18: 0
B19: ÁREA DE PROJEÇÃO DA TORRE | C19: APT | D19: M2 | E19: 309.43
B20: PERÍMETRO DE PROJEÇÃO DA TORRE | C20: PPT | D20: M | E20: 76.88
B21: ÁREA DE LAZER | C21: AL | D21: M2 | E21: ='PISO E TETO'!K44 -> 730.7647
B22: ÁREA DO EMBASAMENTO | C22: AE | D22: M2 | E22: =981.89+1032.93+1000.62+891.77 -> 3907.21
B23: ÁREA DE SUBSOLOS | C23: S | D23: M2
B24: NÚMERO DE SUBSOLOS | C24: NS | D24: UN
B25: ÁREA DE PROJEÇÃO DO EMBASAMENTO | C25: APE | D25: M2 | E25: 981.89
B26: PERÍMETRO DE PROJEÇÃO DE EMBAMENTO | C26: PE | D26: M | E26: 161.88
B27: NÚMERO DE PAVIMENTOS DE EMBASAMENTO | C27: NE | D27: UN | E27: 4
B29: ETAPA | C29: VALOR ORÇADO | D29: % | E29: VALOR / m²
B30: GERENCIAMENTO TÉCNICO E ADMINISTRATIVO | C30: =[4]CUSTOS_INDIRETOS!$F$71 -> 3445019.2 | D30: =C30/C$47 -> 0.08882588 | E30: =C30/$E$9 -> 307.09225
B31: MOVIMENTAÇÃO DE TERRA | C31: =[5]Obra!$F$33*E25 -> 234238.69 | D31: =C31/C$47 -> 0.0060395766 | E31: =C31/$E$9 -> 20.880257 | F31: Indice de custos do praticado no Atlantia
B32: INFRAESTRUTURA | C32: =[5]Obra!$F$34*E25 -> 2050375.7 | D32: =C32/C$47 -> 0.052866592 | E32: =C32/$E$9 -> 182.77242 | F32: Indice de custos do praticado no Atlantia
B33: SUPRAESTRUTURA | C33: =SUPRAESTRUTURA!G62 -> 7413979.3 | D33: =C33/C$47 -> 0.19116098 | E33: =C33/$E$9 -> 660.88908
B34: ALVENARIA | C34: =ALVENARIA!G32 -> 1725490.5 | D34: =C34/C$47 -> 0.044489799 | E34: =C34/$E$9 -> 153.81184
B35: INSTALAÇÕES ELÉTRICAS, HIDRÁULICAS, GLP E PREVENTIVAS | C35: =INSTALAÇÕES!D35 -> 3668348.1 | D35: =C35/C$47 -> 0.094584161 | E35: =C35/$E$9 -> 327
B36: EQUIPAMENTOS E SISTEMAS ESPECIAIS | C36: ='SISTEMAS ESPECIAIS'!D44 -> 2414994.7 | D36: =C36/C$47 -> 0.062267876 | E36: =C36/$E$9 -> 215.2749 | G36: 0.78055556
B37: REVESTIMENTOS ARGAMASSADOS PISO E PAREDE | C37: ='Rev. Internos Piso e Parede'!G25 -> 2253068.9 | D37: =C37/C$47 -> 0.058092805 | E37: =C37/$E$9 -> 200.84068 | G37: 0.83472222
B38: REVESTIMENTOS E ACABAMENTOS EM TETO | C38: =TETO!G16 -> 826117.54 | D38: =C38/C$47 -> 0.021300496 | E38: =C38/$E$9 -> 73.640894 | G38: =G37-G36 -> 0.054166667
B39: IMPERMEABILIZAÇÃO | C39: =IMPERMEABILIZAÇÃO!G22 -> 823317.79 | D39: =C39/C$47 -> 0.021228307 | E39: =C39/$E$9 -> 73.391321
B40: ACABAMENTOS INTERNOS EM PISO E PAREDE | C40: ='Acabamentos de Piso e Parede'!G30 -> 2239442.9 | D40: =C40/C$47 -> 0.057741474 | E40: =C40/$E$9 -> 199.62605
B41: PINTURA INTERNA | C41: ='PINTURA INTERNA'!G20 -> 1922071.8 | D41: =C41/C$47 -> 0.049558422 | E41: =C41/$E$9 -> 171.33528
B42: REVESTIMENTOS E ACABAMENTOS DE FACHADA | C42: ='Rev. Fachada'!G35 -> 1723630.3 | D42: =C42/C$47 -> 0.044441836 | E42: =C42/$E$9 -> 153.64603
...

Sheet Custos Serviços
A1: Rateio do Custo Global | H1: Orçamento
A2: Descrição | B2: % Serviço | C2: % Acumulado | D2: Orçado | E2: Orçado Acum. | G2: Custo Unitário
A3: Gerenciamento Administrativo | B3: 0.0412 | C3: =B3 -> 0.0412 | D3: =B3*$D$146 -> 383513.68 | E3: =C3*$E$146 -> 383513.68 | G3: =D3 -> 383513.68 | J3: =SUM(I4:I7)-D3 -> -9252.8799
A4: Mao De Obra Instalacoes De Canteiro | B4: 1 | C4: =B3-SUM(C5:C7) -> 0.017928314 | D4: =C4*$D$146 -> 166887.22 | H4: Mao De Obra Instalacoes De Canteiro | I4: =[5]Ger_Administrativo!$N$100 -> 162860.8 | J4: =I4/$E$146 -> 0.017495764
A5: Ferramentas/equipamentos | B5: 1 | C5: 0.0039630119 | D5: =C5*$D$146 -> 36890.031 | H5: Ferramentas/equipamentos | I5: =[5]Ger_Administrativo!$N$104 -> 36000 | J5: =I5/$E$146 -> 0.0038673979
A6: Locação Balancim | B6: 1 | C6: 0.016842801 | D6: =C6*$D$146 -> 156782.63 | H6: Locação Balancim | I6: =[5]Ger_Administrativo!N115 -> 153000 | J6: =I6/$E$146 -> 0.016436441
A7: Montagem/Deslocamento/Desmontagem Balancim | B7: 1 | C7: 0.0024658741 | D7: =C7*$D$146 -> 22953.797 | H7: Montagem/Deslocamento/Desmontagem Balancim | I7: =[5]Ger_Administrativo!N116 -> 22400 | J7: =I7/$E$146 -> 0.0024063809
A8: Fundações | B8: 0.055 | C8: =B8+C3 -> 0.0962 | D8: =B8*$D$146 -> 511972.15 | E8: =C8*$E$146 -> 895485.83 | G8: =D8/[5]Ger_Executivo!L19 -> 363.02357 | H8: Mão de obra para execução de fundação rasa e profunda | I8: =[5]Ger_Executivo!N19 -> 499620 | J8: =I8-D8 -> -12352.146
A9: Supraestrutura | B9: 0.33 | C9: =B9+C8 -> 0.4262 | D9: =B9*$D$146 -> 3071832.9 | E9: =C9*$E$146 -> 3967318.7 | G9: =SUM($D$11:$D$20)/SUM(B11:B20) -> 236.77214 | H9: Mão de obra para execução de supraestrutura de concreto armado | I9: =[5]Ger_Executivo!N47 -> 2964109.2 | J9: =(I9+I10)-D9 -> -74112.873
A10: 1º PAVIMENTO - TÉRREO - Contrapiso Armado | B10: =[5]Ger_Executivo!L48 -> 1390.37 | C10: 0.0037 | D10: =C10*$D$146 -> 34441.763 | G10: =D10/B10 -> 24.771653 | H10: Mão de Obra Polimento de piso | I10: =[5]Ger_Executivo!N48 -> 33610.8
A11: 1º PAVIMENTO - TÉRREO | B11: =[5]Obra!$E$15 -> 918.44 | C11: =B11/SUM($B$11:$B$20)*($B$9-$C$10) -> 0.023361339 | D11: =C11*$D$146 -> 217461
A12: 2º PAVIMENTO - GARAGEM 01 | B12: =[5]Obra!$E$16 -> 1045.47 | C12: =B12/SUM($B$11:$B$20)*($B$9-$C$10) -> 0.026592461 | D12: =C12*$D$146 -> 247538.17
A13: 3º PAVIMENTO - GARAGEM 02 | B13: =[5]Obra!$E$17 -> 1045.47 | C13: =B13/SUM($B$11:$B$20)*($B$9-$C$10) -> 0.026592461 | D13: =C13*$D$146 -> 247538.17
A14: 4º PAVIMENTO - GARAGEM 03 | B14: =[5]Obra!$E$18 -> 1045.47 | C14: =B14/SUM($B$11:$B$20)*($B$9-$C$10) -> 0.026592461 | D14: =C14*$D$146 -> 247538.17
A15: 5º PAVIMENTO - GARAGEM 04 | B15: =[5]Obra!$E$19 -> 1051.41 | C15: =B15/SUM($B$11:$B$20)*($B$9-$C$10) -> 0.02674355 | D15: =C15*$D$146 -> 248944.59
A16: 7º PAVIMENTO - TIPO1 X1 | B16: =[5]Obra!$E$20 -> 545.33 | C16: =B16/SUM($B$11:$B$20)*($B$9-$C$10) -> 0.013870954 | D16: =C16*$D$146 -> 129118.95
A17: 8º PAVIMENTO - TIPO2 X11 | B17: =[5]Obra!$E$21 -> 5998.63 | C17: =B17/SUM($B$11:$B$20)*($B$9-$C$10) -> 0.1525805 | D17: =C17*$D$146 -> 1420308.4
A18: 9º PAVIMENTO - TIPO3 X1 | B18: =[5]Obra!$E$22 -> 557.79 | C18: =B18/SUM($B$11:$B$20)*($B$9-$C$10) -> 0.014187885 | D18: =C18*$D$146 -> 132069.13
A19: 19º PAVIMENTO - ROOFTOP | B19: =[5]Obra!$E$23 -> 546.39 | C19: =B19/SUM($B$11:$B$20)*($B$9-$C$10) -> 0.013897916 | D19: =C19*$D$146 -> 129369.93
A20: 19º PAVIMENTO - TÉCNICO | B20: =[5]Obra!$E$24+[5]Obra!$E$25 -> 73.93 | C20: =B20/SUM($B$11:$B$20)*($B$9-$C$10) -> 0.0018804754 | D20: =C20*$D$146 -> 17504.564
A21: Alvenarias e Vedações | B21: 0.09 | C21: =B21+C9 -> 0.5162 | D21: =B21*$D$146 -> 837772.6 | E21: =C21*$E$146 -> 4805091.3 | G21: =D21/SUM(B22:B31) -> 62.773821 | H21: Mão de obra para assentamento de blocos cerâmicos | I21: =[5]Ger_Executivo!$N$63 -> 720815.55 | J21: =SUM(I21:I23)-D21 -> -20212.602
A22: 1º PAVIMENTO - TÉRREO | B22: =SUM('[5]ARQ. PAV'!I2:J2)-0.01 -> 1126.88 | C22: =B22/SUM($B$22:$B$31)*$B$21 -> 0.0075992826 | D22: =C22*$D$146 -> 70738.564 | H22: Mão de obra para assentamento de blocos de Refratário | I22: =[5]Ger_Executivo!$N$64 -> 19998.185
A23: 2º PAVIMENTO - GARAGEM 01 | B23: =SUM('[5]ARQ. PAV'!I3:J3) -> 279.97 | C23: =B23/SUM($B$22:$B$31)*$B$21 -> 0.0018880193 | D23: =C23*$D$146 -> 17574.787 | H23: Mão de obra para assentamento de blocos de silico calcarios | I23: =[5]Ger_Executivo!$N$65 -> 76746.267
A24: 3º PAVIMENTO - GARAGEM 02 | B24: =SUM('[5]ARQ. PAV'!I4:J4) -> 242.28 | C24: =B24/SUM($B$22:$B$31)*$B$21 -> 0.0016338512 | D24: =C24*$D$146 -> 15208.841
A25: 4º PAVIMENTO - GARAGEM 03 | B25: =SUM('[5]ARQ. PAV'!I5:J5) -> 241.76 | C25: =B25/SUM($B$22:$B$31)*$B$21 -> 0.0016303445 | D25: =C25*$D$146 -> 15176.199
A26: 5º PAVIMENTO - GARAGEM 04 | B26: =SUM('[5]ARQ. PAV'!I6:J6) -> 436.35 | C26: =B26/SUM($B$22:$B$31)*$B$21 -> 0.002942591 | D26: =C26*$D$146 -> 27391.357
A27: 7º PAVIMENTO - TIPO1 X1 | B27: =SUM('[5]ARQ. PAV'!I7:J7) -> 784.74161 | C27: =B27/SUM($B$22:$B$31)*$B$21 -> 0.0052920216 | D27: =C27*$D$146 -> 49261.23
A28: 8º PAVIMENTO - TIPO2 X11 | B28: =SUM('[5]ARQ. PAV'!I8:J8) -> 8620.6577 | C28: =B28/SUM($B$22:$B$31)*$B$21 -> 0.058134685 | D28: =C28*$D$146 -> 541151.63
A29: 9º PAVIMENTO - TIPO3 X1 | B29: =SUM('[5]ARQ. PAV'!I9:J9) -> 782.82161 | C29: =B29/SUM($B$22:$B$31)*$B$21 -> 0.0052790737 | D29: =C29*$D$146 -> 49140.704
A30: 19º PAVIMENTO - ROOFTOP | B30: =SUM('[5]ARQ. PAV'!I10:J10) -> 490.22046 | C30: =B30/SUM($B$22:$B$31)*$B$21 -> 0.0033058745 | D30: =C30*$D$146 -> 30773.012
A31: 19º PAVIMENTO - TÉCNICO | B31: =SUM('[5]ARQ. PAV'!I11:J11) -> 340.21 | C31: =B31/SUM($B$22:$B$31)*$B$21 -> 0.0022942566 | D31: =C31*$D$146 -> 21356.282
A32: =LOWER("IMPERMEABILIZAÇÃO E TRATAMENTOS") -> impermeabilização e tratamentos | B32: 0.02 | C32: =B32+C21 -> 0.5362 | D32: =B32*$D$146 -> 186171.69 | E32: =C32*$E$146 -> 4991263
A33: Mão de obra para regularização de superfície | B33: 4313.3967 | C33: =B32*0.9 -> 0.018 | D33: =C33*$D$146 -> 167554.52 | G33: =D33/B33 -> 38.845145 | H33: Mão de obra para regularização de superfície | I33: =SUM([5]Ger_Executivo!N90:N91) -> 181680.76 | J33: =SUM(I33:I34)-D32 -> -4490.9311
A34: Mão de obra para proteção mecânica | B34: 376.91 | C34: =B32*0.1 -> 0.002 | D34: =C34*$D$146 -> 18617.169 | G34: =D34/B34 -> 49.394203 | H34: Mão de obra para proteção mecânica
A35: Revestimentos de Argamassas (internos) | B35: 0.2188 | C35: =B35+C32 -> 0.755 | D35: =B35*$D$146 -> 2036718.3 | E35: =C35*$E$146 -> 7027981.3
A36: Internos Parede | B36: =$B$35*$G$38 -> 0.13318356 | D36: =SUM(D37:D46) -> 1239750.4 | G36: =D36/SUM(B37:B46) -> 48.65613 | H36: Mão de obra execução de massa única em paredes interna, incluindo chapisco | I36: =[5]Ger_Executivo!N197 -> 1209839.5 | J36: =I36-D36 -> -29910.958
A37: 1º PAVIMENTO - TÉRREO | B37: =SUM('[5]ARQ. PAV'!M2:N2) -> 2243.47 | C37: =B37/SUM($B$37:$B$46)*$B$36 -> 0.011726656 | D37: =C37*$D$146 -> 109158.57
A38: 2º PAVIMENTO - GARAGEM 01 | B38: =SUM('[5]ARQ. PAV'!M3:N3) -> 638.76 | C38: =B38/SUM($B$37:$B$46)*$B$36 -> 0.0033388095 | D38: =C38*$D$146 -> 31079.59 | G38: =1-SUM(G39:G41) -> 0.6087
A39: 3º PAVIMENTO - GARAGEM 02 | B39: =SUM('[5]ARQ. PAV'!M4:N4) -> 574.56 | C39: =B39/SUM($B$37:$B$46)*$B$36 -> 0.003003235 | D39: =C39*$D$146 -> 27955.866 | G39: =0.03-0.0005 -> 0.0295
A40: 4º PAVIMENTO - GARAGEM 03 | B40: =SUM('[5]ARQ. PAV'!M5:N5) -> 553.45 | C40: =B40/SUM($B$37:$B$46)*$B$36 -> 0.0028928926 | D40: =C40*$D$146 -> 26928.735 | G40: 0.0618
...

Sheet MOVIMENTAÇÃO_DE_TERRA
A2: MOVIMENTAÇÃO DE TERRA
A3: Data | B3: 45727
A4: Arquivo base | B4: -
A6: ESCAVAÇÃO VERTICAL DE SUBSOLO
A8: Descrição | B8: Área de subsolo (m2) | C8: Altura do subsolo (m) | D8: Volume total de escavação (m3) | E8: Preço unitário de escavação (R$ / m3) | F8: Valor total | G8: Observação
A9: Escavação | B9: 0 | C9: 6 | D9: =(C9*B9) -> 0 | E9: 2.66 | F9: =E9*D9*1.1 -> 0
A10: Movimentação de bota-fora | D10: =D9*1.3 -> 0 | E10: 45.45 | F10: =E10*D10*1.1 -> 0 | G10: 30% de empolamento
A11: TOTAL | F11: =SUM(F9:F10) -> 0
A13: REBAIXAMENTO DE LENÇOL FREÁTICO
A15: Descrição | B15: Quantidade (dias) | E15: Preço unitário de rebaixamento (R$ / dias) | F15: Valor total | G15: Observação
A16: Rebaixamento de lençol | B16: 0 | E16: 200 | F16: =B16*E16*1.1 -> 0 | G16: Sem rebaixamento
A17: TOTAL | F17: =SUM(F16:F16) -> 0
A19: ESCAVAÇÃO E REATERRO DE VALAS
A21: Descrição | B21: Parâmetro | D21: Volume total de escavação (m3) | E21: Preço unitário (R$ / m3) | F21: Valor total | G21: Observação
A22: Escavação mecanizada para blocos e baldrames | B22: 1.3 | C22: m³ / Vol infra | D22: =B22*INFRAESTRUTURA!D29 -> 293.58511 | E22: 36.36 | F22: =E22*D22*1.1 -> 11742.23
A23: Reaterro para blocos e baldrames | B23: 0.6 | C23: m³ / Vol Escavação | D23: =D22-INFRAESTRUTURA!D29 -> 67.75041 | E23: 14.55 | F23: =E23*D23*1.1 -> 1084.3453
A24: Movimentação de bota-fora | B24: 1.3 | D24: =(D22-D23)*B24 -> 293.58511 | E24: 45.45 | F24: =E24*D24*1.1 -> 14677.788
A25: Movimentação de terra das estacas | B25: 1 | C25: m³ | D25: =INFRAESTRUTURA!D19 -> 964.31187 | E25: 68.18 | F25: =E25*D25*1.1 -> 72321.461
A26: TOTAL | F26: =SUM(F22:F25) -> 99825.824
A28: REGULARIZAÇÃO E APILOAMENTO DE FUNDO DE VALAS
A30: Descrição | B30: Parâmetro | D30: Área de lastro (m²) | E30: Preço unitário (R$ / m2) | F30: Valor total | G30: Observação
A31: Lastro de concreto magto e=10cm | B31: 0.8 | C31: m² / APE | D31: =B31*DADOS_INICIAIS!E25 -> 785.512 | E31: =370*0.1 -> 37 | F31: =E31*D31*1.1 -> 31970.338 | H31: =F31/DADOS_INICIAIS!E25 -> 32.56
A32: TOTAL | F32: =SUM(F31:F31) -> 31970.338
A34: TOTAL MOVIMENTAÇÃO DE TERRA | F34: =F11+F17+F26+F32 -> 131796.16 | G34: =F34/DADOS_INICIAIS!E9 -> 11.748434
F35: =F34/DADOS_INICIAIS!E25 -> 134.22701

Sheet CONTENÇÕES
A3: CONTENÇÃO
A4: Data
A5: Arquivo base
A7: CORTINA DE ESTACAS
A9: Descrição | B9: Parâmetro | D9: Quantidade | F9: Preço unitário | G9: Valor total
A10: Número de Estacas | B10: 0.15 | C10: un / APE | D10: =B10*DADOS_INICIAIS!E25 -> 147.2835 | E10: un
A11: Estaca Hélice Continua Diâmetro 40 | B11: 0.1 | D11: =B11*$D$10 -> 14.72835 | E11: un
B12: 20 | C12: m/un | D12: =B12*D11 -> 294.567 | E12: m | G12: =F12*D12 -> 0
A13: Estaca Hélice Continua Diâmetro 50 | B13: 0.5 | D13: =B13*$D$10 -> 73.64175 | E13: un
B14: 20 | C14: m/un | D14: =B14*D13 -> 1472.835 | E14: m | G14: =F14*D14 -> 0
A15: Estaca Hélice Continua Diâmetro 60 | B15: 0.4 | C15: un / APE | D15: =B15*$D$10 -> 58.9134 | E15: un
B16: 20 | C16: m/un | D16: =B16*D15 -> 1178.268 | E16: m | G16: =F16*D16 -> 0
A17: Concreto | B17: =(PI()*0.4^2)/4*D14+(PI()*0.5^2)/4*D16+(PI()*0.6^2)/4*D12 -> 499.72114 | C17: un / APE | D17: =(PI()*0.4^2)/4*D14+(PI()*0.5^2)/4*D16+(PI()*0.6^2)/4*D12 -> 499.72114 | E17: m³ | G17: =F17*D17 -> 0
A18: Armação 6,3mm | B18: 1.6575131 | C18: kg / m³ | D18: =B18*D17 -> 828.29435 | E18: kg | G18: =F18*D18 -> 0
A19: Armação 16mm | B19: 10.178338 | C19: kg / m³ | D19: =B19*D17 -> 5086.3305 | E19: kg | G19: =F19*D19 -> 0
A20: Mobilização | B20: 1 | C20: vb | D20: 1 | E20: vb | G20: =F20*D20 -> 0
A21: TOTAL | G21: =SUM(G10:G20) -> 0
A23: PAREDE DE CONCRETO
A25: Descrição | B25: Parâmetro | D25: Quantidade | F25: Preço unitário | G25: Valor total
A26: Fabricação, montagem e desmontagem de forma para blocos e baldrames resinado | B26: 2.1 | C26: m² / APE | D26: =B26*DADOS_INICIAIS!E25 -> 2061.969 | E26: m² | G26: =F26*D26 -> 0
A27: Concreto | B27: 0.65 | C27: m³ / APE | D27: =B27*DADOS_INICIAIS!E25 -> 638.2285 | E27: m³ | G27: =F27*D27 -> 0
A28: Armação | B28: 110 | C28: kg / m³ | D28: =B28*D27 -> 70205.135 | E28: kg | G28: =F28*D28 -> 0
A29: Mão de obra | B29: =SUPRAESTRUTURA!B15*1.5 -> 360 | C29: R$ / APE | D29: =DADOS_INICIAIS!E25 -> 981.89 | E29: m² | F29: =B29 -> 360 | G29: =F29*D29 -> 353480.4
A30: TOTAL | G30: =SUM(G26:G29) -> 353480.4
A33: PAREDE DIAFRAGMA
A35: Descrição | B35: Parâmetro | D35: Quantidade | F35: Preço unitário | G35: Valor total
A36: Fabricação, montagem e desmontagem de forma para blocos e baldrames resinado | B36: 2.1 | C36: m² / APE | D36: =B36*DADOS_INICIAIS!E35 -> 686.7 | E36: m² | G36: =F36*D36 -> 0
A37: Concreto | B37: 0.65 | C37: m³ / APE | D37: =B37*DADOS_INICIAIS!E35 -> 212.55 | E37: m³ | G37: =F37*D37 -> 0
A38: Armação | B38: 110 | C38: kg / m³ | D38: =B38*D37 -> 23380.5 | E38: kg | G38: =F38*D38 -> 0
A39: Mão de obra | B39: =SUPRAESTRUTURA!B69*1.5 -> 0 | C39: R$ / APE | D39: =DADOS_INICIAIS!E35 -> 327 | E39: m² | F39: =B39 -> 0 | G39: =F39*D39 -> 0
A40: TOTAL | G40: =SUM(G36:G39) -> 0
A46: TOTAL INFRAESTRUTURA | G46: =G21+G30 -> 353480.4 | H46: =G46/DADOS_INICIAIS!E9 -> 31.509575

Sheet INFRAESTRUTURA
A3: INFRAESTRUTURA
A4: Data | B4: 45727
A5: Arquivo base | B5: -
A7: FUNDAÇÃO PROFUNDA
A9: Descrição | B9: Parâmetro | D9: Quantidade | F9: Preço unitário | G9: Valor total | H9: Observação
A10: Número de Estacas | B10: 0.15 | C10: un / APE | D10: =ROUNDUP(B10*DADOS_INICIAIS!$E$25,0) -> 148 | E10: un
A11: Estaca Hélice Continua Diâmetro 40 | B11: 0 | D11: =ROUNDUP(B11*$D$10,0) -> 0 | E11: un
B12: 28 | C12: m/un | D12: =B12*D11 -> 0 | E12: m | F12: 70 | G12: =F12*D12*1.1 -> 0 | H12: Profundidade de SPT
A13: Estaca Hélice Continua Diâmetro 50 | B13: 0.6 | D13: =ROUNDUP(B13*D10,0) -> 89 | E13: un
B14: 28 | C14: m/un | D14: =B14*D13 -> 2492 | E14: m | F14: 90 | G14: =F14*D14*1.1 -> 246708 | H14: Profundidade de SPT
A15: Estaca Hélice Continua Diâmetro 60 | B15: 0.4 | C15: un / APE | D15: =ROUNDUP(B15*$D$10,0) -> 60 | E15: un
B16: 28 | C16: m/un | D16: =B16*D15 -> 1680 | E16: m | F16: 105 | G16: =F16*D16*1.1 -> 194040 | H16: Profundidade de SPT
A17: Estaca Hélice Continua Diâmetro 80 | B17: 0 | C17: un / APE | D17: =ROUNDUP(B17*$D$10,0) -> 0 | E17: un
B18: 30 | C18: m/un | D18: =B18*D17 -> 0 | E18: m | F18: 120 | G18: =F18*D18*1.1 -> 0
A19: Concreto (40 Mpa) | B19: 1.3 | C19: perda | D19: =(PI()*((0.4^2)/4)*D12+PI()*((0.5^2)/4)*D14+PI()*((0.6^2)/4)*D16) -> 964.31187 | E19: m³ | F19: =(535+45+(1.67*0.6))*B19 -> 755.3026 | G19: =F19*D19*1.1 -> 801181.98
A20: Armação | B20: 12 | C20: kg / m³ | D20: =B20*D19 -> 11571.742 | E20: kg | F20: 7.62 | G20: =F20*D20*1.1 -> 96994.345
A21: Mobilização | B21: 1 | C21: vb | D21: 1 | E21: vb | F21: 12500 | G21: =F21*D21*1.1 -> 13750
A22: Apoio e arrasamento de estacas | D22: =D10 -> 148 | E22: un | F22: 300 | G22: =F22*D22*1 -> 44400
A23: TOTAL | G23: =SUM(G10:G22) -> 1397074.3
G24: =G23/981.89 -> 1422.842
A25: FUNDAÇÃO RASA
A27: Descrição | B27: Parâmetro | D27: Quantidade | F27: Preço unitário | G27: Valor total | H27: Observação
A28: Fabricação, montagem e desmontagem de forma para blocos e baldrames resinado | B28: 0.76 | C28: m² / APE | D28: =B28*DADOS_INICIAIS!E25 -> 746.2364 | E28: m² | F28: 68 | G28: =F28*D28*1.1 -> 55818.483
A29: Concreto (40 Mpa) | B29: 0.23 | C29: m³ / APE | D29: =B29*DADOS_INICIAIS!E25 -> 225.8347 | E29: m³ | F29: =(535+45+(1.67*0.6))*1.05 -> 610.0521 | G29: =F29*D29*1.1 -> 151548.03
A30: Armação | B30: 90 | C30: kg / m³ | D30: =B30*D29 -> 20325.123 | E30: kg | F30: 7.62 | G30: =F30*D30*1.1 -> 170365.18
A31: Laje de subpressão | B31: 1 | C31: m² / APE | D31: =B31*DADOS_INICIAIS!E25 -> 981.89 | E31: m² | F31: =D39+D40+D41 -> 172.44521 | G31: =F31*D31*1.1 -> 186254.45
A32: Mão de obra | B32: =SUPRAESTRUTURA!B15*1.5 -> 360 | C32: R$ / APE | D32: =DADOS_INICIAIS!E25 -> 981.89 | E32: m² | F32: =B32 -> 360 | G32: =F32*D32*1.1 -> 388828.44
A33: TOTAL | G33: =SUM(G28:G32) -> 952814.58
A36: TOTAL INFRAESTRUTURA | G36: =G23+G33 -> 2349888.9 | H36: =G36/DADOS_INICIAIS!E9 -> 209.47131
H38: =H36/1.1 -> 190.42846
B39: concreto | C39: =0.1 -> 0.1 | D39: =C39*F29 -> 61.00521
B40: aço | C40: =C39*120 -> 12 | D40: =C40*F30 -> 91.44
B41: mo | C41: 1 | D41: =C41*20 -> 20

Sheet CONTENÇÃO
A3: INFRAESTRUTURA
A4: Data | B4: 45719
A5: Arquivo base | B5: -
A7: CORTINA DE ESTACAS
A9: Descrição | B9: Parâmetro | D9: Quantidade | F9: Preço unitário | G9: Valor total | H9: Observação
A10: Número de Estacas | E10: un | H10: Base obra Trindade Parkside
A11: Estaca Hélice Continua Diâmetro 40 | E11: un
E12: m | F12: 70 | G12: =F12*D12*1.1 -> 0
A13: Estaca Hélice Continua Diâmetro 50 | E13: un
E14: m | F14: 90 | G14: =F14*D14*1.1 -> 0
A15: Estaca Hélice Continua Diâmetro 60 | E15: un
E16: m | F16: 105 | G16: =F16*D16*1.1 -> 0
A17: Estaca Hélice Continua Diâmetro 80 | E17: un
E18: m | F18: 120 | G18: =F18*D18*1.1 -> 0
A19: Concreto (40 Mpa) | E19: m³ | F19: =535+45 -> 580 | G19: =F19*D19*B19*1.1 -> 0
A20: Armação | E20: kg | F20: 7.62 | G20: =F20*D20*1.1 -> 0
A21: Mobilização | E21: vb | F21: 12500 | G21: =F21*D21*1.1 -> 0
A22: Apoio e arrasamento de estacas | E22: un | F22: 300 | G22: =F22*D22*1 -> 0
A23: TOTAL | G23: =SUM(G10:G22) -> 0
A25: PAREDE DE CONCRETO
A27: Descrição | B27: Parâmetro | D27: Quantidade | F27: Preço unitário | G27: Valor total | H27: Observação
A28: Comprimento do muro | D28: =DADOS_INICIAIS!E26 -> 161.88 | E28: m | H28: =D28*D29 -> 1456.92
A29: Altura do muro | D29: =6+3 -> 9 | E29: m
A30: Execução de mureta guia | D30: =D28 -> 161.88 | E30: m | F30: 710 | G30: =F30*D30*1.1 -> 126428.28
A31: Serviço especializado parede diafragma | D31: =D28*D29 -> 1456.92 | E31: m² | F31: 270 | G31: =F31*D31 -> 393368.4
A32: Mobilização para parede diagragma | D32: 1 | E32: vb | F32: 18000 | G32: =F32 -> 18000
A33: Armação | B33: 112 | C33: kg / m³ | D33: =B33*D34 -> 48952.512 | E33: kg | F33: 7.62 | G33: =F33*D33 -> 373018.14
A34: Concreto (30 Mpa) COM CRISTALIZANTE | B34: 0.3 | C34: espessura | D34: =B34*D29*D28 -> 437.076 | E34: m³ | F34: =(535*1.22+45+(1.67*0.6))*1.05 -> 733.6371 | G34: =F34*D34*1.05 -> 336687.93
A35: Tratamento em juntas de concretagem com fita hidroexpansiva | D35: =ROUNDUP(D28/1.25,0)*6 -> 780 | E35: m | F35: 41.5 | G35: =F35*D35*1.1 -> 35607
A36: TOTAL | G36: =SUM(G28:G35) -> 1283109.7
A39: TOTAL CONTENÇÃO | G39: =G23+G36 -> 1283109.7 | H39: =G39/DADOS_INICIAIS!E9 -> 114.37761
H41: =H39/1.1 -> 103.97964

Sheet SUPRAESTRUTURA
A3: SUPRAESTRUTURA
A4: Data | B4: 45472
A5: Arquivo base | B5: -
A7: SUPRAESTRUTURA - LAJE MACIÇA
A9: Descrição | B9: Parâmetro | D9: Quantidade | F9: Preço unitário | G9: Valor total | H9: Observação
A10: Fabricação forma | B10: 3 | C10: Jogos | D10: =(D11/DADOS_INICIAIS!$E$15)*B10 -> 3116.1639 | E10: m² | F10: 110 | G10: =F10*D10*1.1 -> 377055.83
A11: Montagem de forma | B11: 2.5 | C11: m² / AC | D11: =B11*DADOS_INICIAIS!$E$9 -> 28045.475 | E11: m² | F11: 2.5 | G11: =F11*D11*1.1 -> 77125.056
A12: Escoramento | B12: 4 | C12: un / AE | D12: =ROUNDUP(B12*DADOS_INICIAIS!$E$25*B10,0) -> 11783 | E12: un | F12: =17 -> 17 | G12: =F12*D12*1.1 -> 220342.1
A13: Concreto | B13: 0.22 | C13: m³ / AC | D13: =B13*DADOS_INICIAIS!$E$9 -> 2468.0018 | E13: m³ | F13: =(535+45+(1.67*0.6))*1.05 -> 610.0521 | G13: =F13*D13*1.05*1.1 -> 1738979.2
A14: Armadura Convencional para Estrutura | B14: 110 | C14: kg / m³ | D14: =D13*B14 -> 271480.2 | E14: kg | F14: 7.62 | G14: =F14*D14*1.1 -> 2275547
A15: Mão de obra - estrutura em concreto armado | B15: 240 | C15: R$ / AC | D15: =DADOS_INICIAIS!$E$9 -> 11218.19 | E15: m² | F15: =B15 -> 240 | G15: =F15*D15*1.1 -> 2961602.2
A16: Perfuração de vigas | B16: 5300 | C16: R$ / NP | D16: 1 | E16: vb | F16: =B16*DADOS_INICIAIS!$E$15 -> 143100 | G16: =F16*D16*1.1 -> 157410 | H16: Coeficiente originário do Gran Torino (R$ 160,00/un) | I16: Nova utiliza a verba de 1.500,00 por pav
A17: TOTAL | G17: =SUM(G10:G16) -> 7808061.3 | K17: =4160+1440+1120+2880+4800+91680+4000 -> 110080 | L17: =K17/21 -> 5241.9048
A19: SUPRAESTRUTURA - LAJE CUBETAS
A21: Descrição | B21: Parâmetro | D21: Quantidade | F21: Preço unitário | G21: Valor total | H21: Observação
A22: Fabricação forma | B22: 3 | C22: Jogos | D22: =(D23/DADOS_INICIAIS!$E$15)*B22 -> 2617.5777 | E22: m² | F22: 110 | G22: =F22*D22*1.1 -> 316726.9
A23: Montagem de forma | B23: 2.1 | C23: m² / AC | D23: =B23*DADOS_INICIAIS!$E$9 -> 23558.199 | E23: m² | F23: 2.5 | G23: =F23*D23*1.1 -> 64785.047 | J23: Datas Atlantia
A24: Escoramento | B24: 0.28 | C24: um/m² | D24: =4*DADOS_INICIAIS!E19*SUPRAESTRUTURA!B22 -> 3713.16 | E24: un | F24: 11.51 | G24: =F24*D24*1.1 -> 47012.319 | J24: 45909 | K24: fim da estrutra
A25: Cubetas | D25: 10 | E25: mês | F25: =H25*0.45*30 -> 12541.5 | G25: =F25*D25*1.1 -> 137956.5 | H25: =ROUNDUP(DADOS_INICIAIS!E19*B22,0) -> 929 | J25: 45607 | K25: inicioda estrutra
A26: Concreto | B26: 0.28 | C26: m³ / AC | D26: =B26*DADOS_INICIAIS!$E$9 -> 3141.0932 | E26: m³ | F26: =(535+45+(1.67*0.6))*1.05 -> 610.0521 | G26: =F26*D26*1.1 -> 2107853.6 | H26: Indice Atlantia | J26: =J24-J25 -> 302
A27: Armadura Convencional para Estrutura | B27: 75 | C27: kg / m³ | D27: =D26*B27 -> 235581.99 | E27: kg | F27: 5.95 | G27: =F27*D27*1.1 -> 1541884.1 | H27: Indice Atlantia | J27: =J26/30 -> 10.066667
A28: Mão de obra - estrutura em concreto armado | B28: 240 | C28: R$ / AC | D28: =DADOS_INICIAIS!$E$9 -> 11218.19 | E28: m² | G28: ='Custos Serviços'!D9 -> 3071832.9 | H28: Mo empreitada Atlantia
A29: Perfuração de vigas | B29: =5300*0.8 -> 4240 | C29: R$ / NP | D29: 1 | E29: vb | F29: =B29*DADOS_INICIAIS!$E$15 -> 114480 | G29: =F29*D29*1.1 -> 125928 | H29: Coeficiente originário do Gran Torino (R$ 160,00/un)
A30: TOTAL | G30: =SUM(G22:G29) -> 7413979.3
A32: SUPRAESTRUTURA - LAJE TRELIÇADA
A34: Descrição | B34: Parâmetro | D34: Quantidade | F34: Preço unitário | G34: Valor total | H34: Observação
A35: Fabricação forma | B35: 2 | C35: Jogos | D35: =(D36/DADOS_INICIAIS!$E$15)*B35 -> 11.45525 | E35: m² | F35: 85 | G35: =F35*D35*1.1 -> 1071.0659
A36: Montagem de forma | B36: 2.1 | C36: m² / AC | D36: =B36*DADOS_INICIAIS!E38 -> 154.64588 | E36: m² | F36: 1.5 | G36: =F36*D36*1.1 -> 255.1657
A37: Escoramento - Torre | B37: 2 | C37: un / APT*NPT | D37: =B37*DADOS_INICIAIS!E44*DADOS_INICIAIS!E42 -> 7637.4619 | E37: un | F37: 17 | G37: =F37*D37*1.1 -> 142820.54
A38: Escoramento - Embasamento | B38: 2 | C38: un / AE | D38: =B38*DADOS_INICIAIS!E46 -> 183.50366 | E38: un | F38: 17 | G38: =F38*D38*1.1 -> 3431.5185
A39: Cubetas | B39: 25 | C39: R$ / AC | D39: =B39*DADOS_INICIAIS!E38 -> 1841.0223 | E39: m³ | F39: =B39 -> 25 | G39: =F39*D39*1.1 -> 50628.114
A40: Concreto | B40: 0.25 | C40: m³ / AC | D40: =B40*DADOS_INICIAIS!E38 -> 18.410223 | E40: m³ | F40: =575 -> 575 | G40: =F40*D40*1.05*1.1 -> 12226.69
A41: Armadura Convencional para Estrutura | B41: 110 | C41: kg / m³ | D41: =D40*B41 -> 2025.1246 | E41: kg | F41: 7.25 | G41: =F41*D41*1.1 -> 16150.368
A42: Mão de obra - estrutura em concreto armado | B42: 240 | C42: R$ / AC | D42: =DADOS_INICIAIS!E38 -> 73.640894 | E42: m² | F42: =B42 -> 240 | G42: =F42*D42*1.1 -> 19441.196
A43: Perfuração de vigas | B43: 5300 | C43: R$ / NP | D43: 1 | E43: vb | F43: =B43*DADOS_INICIAIS!E41 -> 908077.01 | G43: =F43*D43*1.1 -> 998884.71 | H43: Coeficiente originário do Gran Torino (R$ 160,00/un)
A44: TOTAL | G44: =SUM(G35:G43) -> 1244909.4
A46: SUPRAESTRUTURA - LAJE PROTENDIDA
A48: Descrição | B48: Parâmetro | D48: Quantidade | F48: Preço unitário | G48: Valor total | H48: Observação
A49: Fabricação forma | B49: 3 | C49: Jogos | D49: =(D50/DADOS_INICIAIS!$E$15)*B49 -> 2617.5777 | E49: m² | F49: 110 | G49: =F49*D49*1.1 -> 316726.9
A50: Montagem de forma | B50: 2.1 | C50: m² / AC | D50: =B50*DADOS_INICIAIS!$E$9 -> 23558.199 | E50: m² | F50: 2.5 | G50: =F50*D50*1.1 -> 64785.047
...

Sheet ALVENARIA
A3: PAREDES E PAINÉIS
A4: Data | B4: 45469
A5: Arquivo base | B5: -
A7: ALVENARIA
A9: Descrição | B9: Parâmetro | D9: Quantidade | F9: Preço unitário | G9: Valor total | H9: Observação
A10: Alvenaria externa | B10: 0.92 | C10: m² / AC | D10: =B10*DADOS_INICIAIS!$E$9 -> 10320.735 | E10: m² | F10: 45 | G10: =F10*D10*1.1 -> 510876.37 | H10: =G10/D10 -> 49.5 | I10: =(D10+#REF!+#REF!+#REF!+#REF!)/DADOS_INICIAIS!E9 -> #REF!
A11: Alvenaria silico calcario | B11: 0.1 | C11: m² / AC | D11: =B11*DADOS_INICIAIS!$E$9 -> 1121.819 | E11: m² | F11: 70 | G11: =F11*D11*1.1 -> 86380.063 | I11: =(D11+#REF!+#REF!+#REF!+#REF!)/DADOS_INICIAIS!E10 -> #REF!
A12: Alvenaria refratárias | B12: 1.75 | C12: m² * CHU | D12: =B12*DADOS_INICIAIS!$E$14 -> 80.5 | E12: m² | F12: 75 | G12: =F12*D12*1.1 -> 6641.25 | H12: apenas mat
A13: Serviços complementares | B13: 12.5 | C13: R$ / m² | D13: =D10 -> 10320.735 | E13: m² | F13: 25 | G13: =F13*D13*1.1 -> 283820.21
A14: Mão de obra | B14: 35 | C14: R$ / m² | E14: m² | F14: 35 | G14: ='Custos Serviços'!D21 -> 837772.6
A15: TOTAL | G15: =SUM(G10:G14) -> 1725490.5 | K15: =4160+1440+1120+2880+4800+91680+4000 -> 110080 | L15: =K15/21 -> 5241.9048
A17: ALVENARIA - DRYWALL | G17: =G14/D14 -> #DIV/0!
A19: Descrição | B19: Parâmetro | D19: Quantidade | F19: Preço unitário | G19: Valor total | H19: Observação
A20: Alvenaria embasamento | B20: 1 | C20: m² / AE | D20: =B20*DADOS_INICIAIS!$E$22 -> 3907.21 | E20: m² | F20: 45 | G20: =F20*D20*1.1 -> 193406.9
A21: Alvenaria lazer | B21: 0.4 | C21: m² / AL | D21: =B21*DADOS_INICIAIS!$E$21 -> 292.30588 | E21: m² | F21: 45 | G21: =F21*D21*1.1 -> 14469.141
A22: Alvenaria tipo | B22: 1.65 | C22: m² / APT*(NPT+2ND) | D22: =B22*(DADOS_INICIAIS!$E$19*(DADOS_INICIAIS!$E$16+DADOS_INICIAIS!$E$17))*0.4 -> 4492.9236 | E22: m² | F22: 45 | G22: =F22*D22*1.1 -> 222399.72
A23: Drywall tipo | B23: 1.65 | C23: m² / APT*(NPT+2ND) | D23: =B23*(DADOS_INICIAIS!$E$19*(DADOS_INICIAIS!$E$16+DADOS_INICIAIS!$E$17))*0.6 -> 6739.3854 | E23: m² | F23: 220 | G23: =F23*D23*1.1 -> 1630931.3 | J23: =D23/(D27+D23) -> 0.37601868
A24: Alvenaria escadas | B24: 0.2 | C24: m² / AC | D24: =B24*DADOS_INICIAIS!$E$9 -> 2243.638 | E24: m² | F24: 70 | G24: =F24*D24*1.1 -> 172760.13 | J24: =1-J23 -> 0.62398132
A25: Alvenaria cobertura / reservatório | B25: 0.8 | C25: m² / APT | D25: =B25*DADOS_INICIAIS!$E$19 -> 247.544 | E25: m³ | F25: 45 | G25: =F25*D25*1.1 -> 12253.428
A26: Alvenaria refratárias | B26: 1.75 | C26: m² * CHU | D26: ='SISTEMAS ESPECIAIS'!B10 -> 46 | E26: un | F26: 210 | G26: =F26*D26*1.1 -> 10626
A27: Serviços complementares | B27: 12.5 | C27: R$ / m² | D27: =D21+D22+D20+D24+D25 -> 11183.621 | E27: m² | F27: =B27 -> 12.5 | G27: =F27*D27*1.1 -> 153774.8
A28: Mão de obra | B28: 35 | C28: R$ / m² | D28: =D21+D22+D20+D24+D25 -> 11183.621 | E28: m² | F28: 35 | G28: =F28*D28*1.1 -> 430569.43
A29: TOTAL | G29: =SUM(G20:G28) -> 2841190.8
G30: =G14/(D10+D11) -> 73.215527
A32: TOTAL ALVENARIA | G32: =G15 -> 1725490.5 | H32: =G32/DADOS_INICIAIS!E9 -> 153.81184
B34: =D10+D11 -> 11442.554
B35: =B34-[6]CÁLCULOS!$C$16 -> -0.0012362222 | C35: =24000/(568+874+1996+1144) -> 5.2378874 | G35: =G32/1.1 -> 1568627.7 | H35: =G35/DADOS_INICIAIS!E9 -> 139.82895

Sheet INSTALAÇÕES
A2: INSTALAÇÕES
A4: INSTALAÇÕES ELÉTRICAS
A6: Descrição | B6: Parâmetro | D6: Valor total
A7: Entrada de Energia | B7: 13 | C7: R$ / AC | D7: =B7*DADOS_INICIAIS!$E$9 -> 145836.47
A8: Eletrodutos e Eletrocalhas | B8: 12 | C8: R$ / AC | D8: =B8*DADOS_INICIAIS!$E$9 -> 134618.28
A9: Cabos e Fiações | B9: 15 | C9: R$ / AC | D9: =B9*DADOS_INICIAIS!$E$9 -> 168272.85
A10: Quadros e Disjuntores | B10: 10 | C10: R$ / AC | D10: =B10*DADOS_INICIAIS!$E$9 -> 112181.9
A11: Acabamentos Elétricos | B11: 10 | C11: R$ / AC | D11: =B11*DADOS_INICIAIS!$E$9 -> 112181.9
A12: Equipamentos e Iluminação | B12: 12 | C12: R$ / AC | D12: =B12*DADOS_INICIAIS!$E$9 -> 134618.28
A13: Mão de Obra para Instalações Elétricas | B13: 50 | C13: R$ / AC | D13: =B13*DADOS_INICIAIS!$E$9 -> 560909.5 | E13: =D13/DADOS_INICIAIS!$E$9 -> 50
A14: TOTAL | D14: =SUM(D7:D13) -> 1368619.2
A16: INSTALAÇÕES HIDROSSANITÁRIAS
A18: Descrição | B18: Parâmetro | D18: Valor total
A19: Instalações de Água Fria | B19: 25 | C19: R$ / AC | D19: =B19*DADOS_INICIAIS!$E$9 -> 280454.75
A20: Instalações de Água Quente | B20: 20 | C20: R$ / AC | D20: =B20*DADOS_INICIAIS!$E$9 -> 224363.8
A21: Instalações de Águas Pluviais | B21: 12 | C21: R$ / AC | D21: =B21*DADOS_INICIAIS!$E$9 -> 134618.28
A22: Instalações Sanitárias | B22: 16 | C22: R$ / AC | D22: =B22*DADOS_INICIAIS!$E$9 -> 179491.04
A23: Louças e Metais | B23: 45 | C23: R$ / AC | D23: =B23*DADOS_INICIAIS!$E$9 -> 504818.55
A24: Mão de Obra para Instalações Hidráulicas | B24: 45 | C24: R$ / AC | D24: =B24*DADOS_INICIAIS!$E$9 -> 504818.55 | E24: =D24/DADOS_INICIAIS!$E$9 -> 45
A25: TOTAL | D25: =SUM(D19:D24) -> 1828565
A27: INSTALAÇÕES PREVENTIVAS E GLP
A29: Descrição | B29: Parâmetro | D29: Valor total
A30: Instalações Preventivas | B30: 15 | C30: R$ / AC | D30: =B30*DADOS_INICIAIS!$E$9 -> 168272.85
A31: Instalações de GLP | B31: 22 | C31: R$ / AC | D31: =B31*DADOS_INICIAIS!$E$9 -> 246800.18
A32: Instalações de Proteção e Aterramento - SPDA | B32: 5 | C32: R$ / AC | D32: =B32*DADOS_INICIAIS!$E$9 -> 56090.95
A33: TOTAL | D33: =SUM(D30:D32) -> 471163.98
A35: TOTAL INSTALAÇÕES | D35: =D14+D25+D33 -> 3668348.1 | E35: =D35/DADOS_INICIAIS!E9 -> 327
E37: =E35/1.1 -> 297.27273

Sheet SISTEMAS ESPECIAIS
A2: SISTEMAS ESPECIAIS
A4: CLIMATIZAÇÃO, EXAUSTÃO MECÂNICA E PRESSURIZAÇÃO
A6: Descrição | B6: Quantidade | C6: Preço Unitário | D6: Valor total | G6: TERREO | H6: G1 | I6: G2 | J6: G3 | K6: TIPO DIF | L6: TIPO 21 | M6: ROOFTOP
A7: Infraestrutura para Instalação de Ar Condicionado | B7: =SUM(G7:M7) -> 288 | C7: 1200 | D7: =B7*C7*1.1 -> 380160 | G7: =9+1 -> 10 | H7: 5 | I7: 2 | J7: 2 | K7: =6*2 -> 12 | L7: =K7*21 -> 252 | M7: 5
A8: Instalação de Ar Condicionado | B8: =SUM(G8:M8) -> 14 | C8: 5000 | D8: =B8*C8*1.1 -> 77000 | G8: 0 | H8: =H7 -> 5 | I8: =I7 -> 2 | J8: =J7 -> 2 | K8: 0 | L8: =K8*21 -> 0 | M8: =M7 -> 5
A9: Ventokit | B9: =SUM(G9:M9) -> 58 | C9: 900 | D9: =B9*C9*1.1 -> 57420 | G9: =9 -> 9 | H9: 2 | I9: 1 | J9: 1 | K9: =1*2 -> 2 | L9: =K9*21 -> 42 | M9: 1
A10: Churrasqueiras | B10: =SUM(G10:M10) -> 46 | C10: 2600 | D10: =B10*C10*1.1 -> 131560 | G10: 0 | H10: 1 | I10: 1 | J10: 0 | K10: =1*2 -> 2 | L10: =K10*21 -> 42 | M10: 0
A11: Pressurização de escada | B11: =DADOS_INICIAIS!E9 -> 11218.19 | C11: 11 | D11: =B11*C11*1.1 -> 135740.1
A12: TOTAL | D12: =SUM(D7:D11) -> 781880.1
A14: COMUNICAÇÃO
A16: Descrição | B16: Parâmetro | D16: Valor total
A17: CFTV | B17: 2 | C17: R$ / AC | D17: =B17*DADOS_INICIAIS!$E$9*1.05 -> 23558.199
A18: Interfone | B18: 5 | C18: R$ / AC | D18: =B18*DADOS_INICIAIS!$E$9*1.05 -> 58895.498
A19: TV e internet | B19: 4.5 | C19: R$ / AC | D19: =B19*DADOS_INICIAIS!$E$9*1.05 -> 53005.948
A20: Automação, telecomunicação e sistemas de segurança | B20: 5.5 | C20: R$ / AC | D20: =B20*DADOS_INICIAIS!$E$9*1.05 -> 64785.047
A21: TOTAL | D21: =SUM(D17:D20) -> 200244.69
A23: EQUIPAMENTOS
A25: Descrição | B25: Quantidade | C25: Preço Unitário | D25: Valor total
A26: Elevadores | B26: 1 | C26: 195000 | D26: =B26*C26*1.05 -> 204750 | E26: 4 paradas
A27: Elevadores | B27: 2 | C27: =17750*DADOS_INICIAIS!E15 -> 479250 | D27: =B27*C27*1.1 -> 1054350
A28: Plataforma elevatória | C28: 42750 | D28: =B28*C28*1.1 -> 0 | E28: inox
A29: Grupo de geradores | B29: 1 | C29: 19800 | D29: =B29*C29*1.05 -> 20790
A30: Bombas | B30: 1 | D30: =B30*C30*1.1 -> 0
A31: Infra de carro elétrico | B31: 3 | C31: 590 | D31: =B31*C31 -> 1770
A32: Equipamento de piscina | B32: 1 | C32: 27500 | D32: =B32*C32*1.1 -> 30250
A33: Equipamento de sauna | B33: 1 | C33: 7980 | D33: =B33*C33*1.1 -> 8778
A34: Equipamento de spa | B34: 2 | C34: =19700/2 -> 9850
A35: Sistema de placas solares | C35: 1150 | D35: =B35*C35*1.1 -> 0
A36: TOTAL | D36: =SUM(D26:D35) -> 1320688
A38: OUTROS SISTEMAS ESPECIAIS
A40: Descrição | B40: Parâmetro | D40: Valor total
A41: Outros sistemas | B41: 10 | C41: R$ / AC | D41: =B41*DADOS_INICIAIS!E9 -> 112181.9
A42: TOTAL | D42: =SUM(D41:D41) -> 112181.9
A44: TOTAL SISTEMAS ESPECIAIS | D44: =D12+D21+D36+D42 -> 2414994.7 | E44: =D44/DADOS_INICIAIS!E9 -> 215.2749

Sheet IMPERMEABILIZAÇÃO
A3: IMPERMEABILIZAÇÃO
A4: Data | B4: 45471
A5: Arquivo base | B5: -
A7: IMPERMEABILIZAÇÃO
A9: Descrição | B9: Parâmetro | D9: Quantidade | F9: Preço unitário | G9: Valor total | H9: Observação
A10: Regularização de Superfície | B10: 25 | C10: R$ / m² | D10: =D16+D17+D18 -> 4862.4766 | E10: m² | F10: 7 | G10: =F10*D10*1.1 -> 37441.07
A11: Proteção Mecânica | B11: 28 | C11: R$ / m² | D11: =D18+D17 -> 1497.0196 | E11: m² | F11: 50 | G11: =F11*D11*1.1 -> 82336.079
A12: MO reg e prot | B12: 28 | C12: R$ / m² | D12: 1 | E12: vb | F12: ='Custos Serviços'!D32 -> 186171.69 | G12: =F12*D12 -> 186171.69
A13: Poço do elevador | B13: 45 | C13: R$ / m² | D13: =(3.51+3.8+2.94)+(1.7*4*1.8)+(1.75*2+2*2)*1.8*2 -> 49.49 | E13: m² | F13: =36+30 -> 66 | G13: =F13*D13*1.1 -> 3592.974
A14: Baldrames | B14: 30 | C14: R$ / m² | D14: =INFRAESTRUTURA!D28 -> 746.2364 | E14: m² | F14: =25+39 -> 64 | G14: =F14*D14*1.1 -> 52535.043
A15: Ralos | B15: 2 | C15: R$ / AC | D15: 1 | E15: vb | F15: =B15*DADOS_INICIAIS!$E$9 -> 22436.38 | G15: =F15*D15*1.1 -> 24680.018 | H15: =G15/I15 -> #DIV/0!
A16: Impermeabilizações cimenticias | B16: 0.3 | C16: m² / AC | D16: =B16*DADOS_INICIAIS!E9 -> 3365.457 | E16: m² | F16: =40+30 -> 70 | G16: =F16*D16*1.1 -> 259140.19
A17: Impermeabilizações com manta asfaltica | B17: =D17/DADOS_INICIAIS!E9 -> 0.083445735 | C17: m² / AC | D17: =('PISO E TETO'!M17-'PISO E TETO'!M35)*1.3 -> 936.11011 | E17: m² | F17: =50+48 -> 98 | G17: =F17*D17*1.1 -> 100912.67 | H17: Terraços e áreas externas
A18: Impermeabilizações com manta asfalticafloreiras | B18: 0.05 | C18: m² / AC | D18: =B18*DADOS_INICIAIS!E9 -> 560.9095 | E18: m² | F18: =50+48 -> 98 | G18: =F18*D18*1.1 -> 60466.044
A19: Impermeabilização de peitoril | B19: 1.3 | C19: R$ / AC | D19: 1 | E19: vb | F19: =B19*DADOS_INICIAIS!$E$9 -> 14583.647 | G19: =F19*D19*1.1 -> 16042.012 | H19: =G19/I19 -> #DIV/0!
A20: TOTAL | G20: =SUM(G10:G19) -> 823317.79 | K20: =4160+1440+1120+2880+4800+91680+4000 -> 110080 | L20: =K20/21 -> 5241.9048
A22: TOTAL IMPERMEABILIZAÇÃO | G22: =G20 -> 823317.79 | H22: =G22/DADOS_INICIAIS!E9 -> 73.391321
H25: =H22/1.1 -> 66.719383
C26: =3.36*(141*2+10) -> 981.12
C27: =1.5*2.1*(141*2+10) -> 919.8
C28: =C26+C27 -> 1900.92 | D28: só banheiro
C29: =4*1.5*56 -> 336 | D29: cozinha
A32: IMPERMEABILIZAÇÃO
A34: Descrição | B34: Parâmetro | D34: Quantidade | F34: Preço unitário | G34: Valor total | H34: Observação
A35: Regularização de Superfície | B35: 25 | C35: R$ / m² | D35: 6235.376 | E35: m² | F35: =5+20 -> 25 | G35: =F35*D35*1.1 -> 171472.84
A36: Poço do elevador | B36: 45 | C36: R$ / m² | D36: 37.806 | E36: m² | F36: =41 -> 41 | G36: =F36*D36*1.1 -> 1705.0506
A37: Baldrames | B37: 30 | C37: R$ / m² | D37: 1131.0624 | E37: m² | F37: =15+38 -> 53 | G37: =F37*D37*1.1 -> 65940.938
A38: Ralos | B38: 1 | C38: R$ / AC | D38: 1 | E38: vb | F38: =B38*DADOS_INICIAIS!$E$9 -> 11218.19 | G38: =F38*D38*1.1 -> 12340.009 | H38: =G38/I38 -> #DIV/0!
A39: Impermeabilizações cimenticias | B39: 0.3 | C39: m² / AC | D39: 3944.334 | E39: m² | F39: =40+30 -> 70 | G39: =F39*D39*1.1 -> 303713.72
A40: Impermeabilizações com manta asfaltica | B40: =D40/DADOS_INICIAIS!E33 -> 3.4666059 | C40: m² / AC | D40: 2291.042 | E40: m² | F40: =50+48 -> 98 | G40: =F40*D40*1.1 -> 246974.33
A41: Impermeabilizações com manta asfalticafloreiras | C41: m² / AC | E41: m² | F41: =50+48 -> 98 | G41: =F41*D41*1.1 -> 0
A42: Impermeabilização de peitoril | B42: 1.2 | C42: R$ / AC | D42: 1 | E42: vb | F42: =B42*DADOS_INICIAIS!$E$9 -> 13461.828 | G42: =F42*D42*1.1 -> 14808.011 | H42: =G42/I42 -> #DIV/0!
A43: Proteção Mecânica | B43: 28 | C43: R$ / m² | D43: 2291.042 | E43: m² | F43: =35+22 -> 57 | G43: =F43*D43*1.1 -> 143648.33
A44: TOTAL | G44: =SUM(G35:G43) -> 960603.23 | K44: =4160+1440+1120+2880+4800+91680+4000 -> 110080 | L44: =K44/21 -> 5241.9048

Sheet PISO E TETO
A1: Obra | B1: =DADOS_INICIAIS!B1 -> 2cinco4
A2: Empresa | B2: =DADOS_INICIAIS!B2 -> H Empreendimentos
A3: Revisão | B3: R00
A4: Data | B4: 45825
A5: LEVANTAMENTO QUANTITATIVO
A7: REVESTIMENTOS E ACABAMENTOS DE PISO E TETO
B9: LEVANTAMENTO DE PROJETO | L9: CONTRAPISO
B10: Pavimento | C10: Ambiente | D10: Área (m²) | E10: Material | F10: Contrapiso (Sim/Não) | G10: Forro | H10: Repetição | I10: Total | L10: Revestimento | M10: Área total
B11: TERREO | C11: SALA 01 | D11: 92.47 | E11: PORCELANATO | F11: Sim | G11: Gesso | H11: 1 | I11: =H11*Table_2[[#This Row],[Área (m²)]] -> 92.47 | L11: Contrapiso | M11: =SUMIF(F:F,"Sim",I:I) -> 7152.5749
B12: TERREO | C12: SALA 02 | D12: 84.94 | E12: PORCELANATO | F12: Sim | G12: Gesso | H12: 1 | I12: =H12*Table_2[[#This Row],[Área (m²)]] -> 84.94 | L12: Manta acústica | M12: =SUM(I78:I105) -> 6627.424
B13: TERREO | C13: SALA 03 | D13: 97.08 | E13: PORCELANATO | F13: Sim | G13: Gesso | H13: 1 | I13: =H13*Table_2[[#This Row],[Área (m²)]] -> 97.08 | L13: FORRO
B14: TERREO | C14: SALA 04 | D14: 69.17 | E14: PORCELANATO | F14: Sim | G14: Gesso | H14: 1 | I14: =H14*Table_2[[#This Row],[Área (m²)]] -> 69.17 | L14: Revestimento | M14: Área total
B15: TERREO | C15: SALA 05 | D15: 68.62 | E15: PORCELANATO | F15: Sim | G15: Gesso | H15: 1 | I15: =H15*Table_2[[#This Row],[Área (m²)]] -> 68.62 | L15: Estucamento | M15: =SUMIF(G:G,L15,I:I) -> 3253.1564
B16: TERREO | C16: SALA 06 | D16: 72.35 | E16: PORCELANATO | F16: Sim | G16: Gesso | H16: 1 | I16: =H16*Table_2[[#This Row],[Área (m²)]] -> 72.35 | L16: Gesso | M16: =SUMIF(G:G,L16,I:I) -> 6909.312
B17: TERREO | C17: SALA 07 | D17: 50.73 | E17: PORCELANATO | F17: Sim | G17: Gesso | H17: 1 | I17: =H17*Table_2[[#This Row],[Área (m²)]] -> 50.73 | L17: - | M17: =SUMIF(G:G,L17,I:I) -> 1253.2311
B18: TERREO | C18: SALA 08 | D18: 50.17 | E18: PORCELANATO | F18: Sim | G18: Gesso | H18: 1 | I18: =H18*Table_2[[#This Row],[Área (m²)]] -> 50.17
B19: TERREO | C19: SALA 09 | D19: 53.07 | E19: PORCELANATO | F19: Sim | G19: Gesso | H19: 1 | I19: =H19*Table_2[[#This Row],[Área (m²)]] -> 53.07
B20: TERREO | C20: LAVABO SALAS | D20: =3+2.93+2.93+2.91+2.93+3.85+3.75+2.99 -> 25.29 | E20: PORCELANATO | F20: Sim | G20: Gesso | H20: 1 | I20: =H20*Table_2[[#This Row],[Área (m²)]] -> 25.29
B21: TERREO | C21: PASSEIO/ACESSO TRAS coberto | D21: =12.52*(5) -> 62.6 | E21: Paver | F21: Não | G21: Gesso | H21: 1 | I21: =H21*Table_2[[#This Row],[Área (m²)]] -> 62.6 | L21: ACABAMENTOS
B22: TERREO | C22: PASSEIO/ACESSO TRAS | D22: =12.52*(1.5) -> 18.78 | E22: Paver | F22: Não | G22: - | H22: 1 | I22: =H22*Table_2[[#This Row],[Área (m²)]] -> 18.78 | L22: Material | M22: Área total
B23: TERREO | C23: PASSEIO/ACESSO FRENTE coberto | D23: =37*1.5 -> 55.5 | E23: Paver | F23: Não | G23: Gesso | H23: 1 | I23: =H23*Table_2[[#This Row],[Área (m²)]] -> 55.5 | L23: PORCELANATO | M23: =SUMIF(E:E,L23,I:I) -> 723.20493
B24: TERREO | C24: PASSEIO/ACESSO FRENTE | D24: =37*2.5 -> 92.5 | E24: Paver | F24: Não | G24: - | H24: 1 | I24: =H24*Table_2[[#This Row],[Área (m²)]] -> 92.5 | L24: Paver | M24: =SUMIF(E:E,L24,I:I) -> 229.38
B25: TERREO | C25: LIXEIRA | D25: 4.11 | E25: CERAMICA | F25: Sim | G25: Estucamento | H25: 1 | I25: =H25*Table_2[[#This Row],[Área (m²)]] -> 4.11 | L25: CERAMICA | M25: =SUMIF(E:E,L25,I:I) -> 5.07
B26: TERREO | C26: CENTRAL DE GÁS | D26: 0.96 | E26: CERAMICA | F26: Sim | G26: Estucamento | H26: 1 | I26: =H26*Table_2[[#This Row],[Área (m²)]] -> 0.96 | L26: PORCELANATO AC | M26: =SUMIF(E:E,L26,I:I) -> 513.39
B27: TERREO | C27: ACESSO HALL | D27: =4.98*1.5 -> 7.47 | E27: PORCELANATO AC | F27: Sim | G27: Gesso | H27: 1 | I27: =H27*Table_2[[#This Row],[Área (m²)]] -> 7.47 | L27: CIMENTADO + EPOXI | M27: =SUMIF(E:E,L27,I:I) -> 6.24
B28: TERREO | C28: HALL DE ENTRADA | D28: 20.36 | E28: PORCELANATO AC | F28: Sim | G28: Gesso | H28: 1 | I28: =H28*Table_2[[#This Row],[Área (m²)]] -> 20.36 | L28: CIMENTADO | M28: =SUMIF(E:E,L28,I:I) -> 26.54
B29: TERREO | C29: CIRCULAÇÃO | D29: =11.85+40.89 -> 52.74 | E29: PORCELANATO | F29: Sim | G29: Estucamento | H29: 1 | I29: =H29*Table_2[[#This Row],[Área (m²)]] -> 52.74 | L29: CIMENTADO + RESINA | M29: =SUMIF(E:E,L29,I:I) -> 1301.9714
B30: TERREO | C30: RAMPA CIRC | D30: =2.95*1.5*1.061 -> 4.694925 | E30: PORCELANATO | F30: Sim | G30: Estucamento | H30: 1 | I30: =H30*Table_2[[#This Row],[Área (m²)]] -> 4.694925 | L30: POLIMENTO + RESINA | M30: =SUMIF(E:E,L30,I:I) -> 1854.02
B31: TERREO | C31: LAVAPÉS | D31: =1.88 -> 1.88 | E31: PORCELANATO | F31: Sim | G31: Estucamento | H31: 1 | I31: =H31*Table_2[[#This Row],[Área (m²)]] -> 1.88 | L31: EMORRACHADO | M31: =SUMIF(E:E,L31,I:I) -> 32.63
B32: TERREO | C32: BICICLETÁRIO | D32: 6.24 | E32: CIMENTADO + EPOXI | F32: Sim | G32: Estucamento | H32: 1 | I32: =H32*Table_2[[#This Row],[Área (m²)]] -> 6.24 | L32: PATILHA | M32: =SUMIF(E:E,L32,I:I) -> 130.99
B33: TERREO | C33: DEPOSITO | D33: 26.54 | E33: CIMENTADO | F33: Não | G33: Estucamento | H33: 1 | I33: =H33*Table_2[[#This Row],[Área (m²)]] -> 26.54 | L33: CIMENTO QUEIMADO | M33: =SUMIF(E:E,L33,I:I) -> 4.2447
B34: TERREO | C34: RAMPA GARAGEM | D34: =3.89*(13*1.157+4.59+2.67*1.099+5.95*1.158+2.5*1.052) -> 124.81232 | E34: CIMENTADO + RESINA | F34: Não | G34: Estucamento | H34: 1 | I34: =H34*Table_2[[#This Row],[Área (m²)]] -> 124.81232 | L34: - | M34: =SUMIF(E:E,L34,I:I) -> 45.7
B35: TERREO | C35: ANTECAMARA 1 | D35: 5.14 | E35: CIMENTADO + RESINA | F35: Não | G35: Estucamento | H35: 1 | I35: =H35*Table_2[[#This Row],[Área (m²)]] -> 5.14 | L35: LAJE IMPERM | M35: =SUMIF(E:E,L35,I:I) -> 533.1464
B36: TERREO | C36: ESCADA 1 | D36: =11.54+20*1.2*0.18 -> 15.86 | E36: CIMENTADO + RESINA | F36: Não | G36: Estucamento | H36: 1 | I36: =H36*Table_2[[#This Row],[Área (m²)]] -> 15.86 | L36: PORCELANATO AP | M36: =SUMIF(E:E,L36,I:I) -> 4007.3
B37: TERREO | C37: ESCADA 2 | D37: =9.27+21*1.2*0.18 -> 13.806 | E37: CIMENTADO + RESINA | F37: Não | G37: Estucamento | H37: 1 | I37: =H37*Table_2[[#This Row],[Área (m²)]] -> 13.806 | L37: VINILICO | M37: =SUMIF(E:E,L37,I:I) -> 1725.88
B38: G1 | C38: CIRCULAÇÃO + VAGAS | D38: =107.72+8*25+99.49+8*25+12.5 -> 619.71 | E38: POLIMENTO + RESINA | F38: Não | G38: Estucamento | H38: 1 | I38: =H38*Table_2[[#This Row],[Área (m²)]] -> 619.71 | L38: MADEIRA | M38: =SUMIF(E:E,L38,I:I) -> 7.87
B39: G1 | C39: RAMPA GARAGEM | D39: =3.89*(1.68*1.089+6.1*1.1869+1.7*1.088)+3.89*(2.6*1.0615+5.95*1.0893+2.65*1.089) -> 89.650088 | E39: CIMENTADO + RESINA | F39: Não | G39: Estucamento | H39: 4 | I39: =H39*Table_2[[#This Row],[Área (m²)]] -> 358.60035 | L39: COBERTURA | M39: =SUMIF(E:E,L39,I:I) -> 268.122
B40: G1 | C40: ESCADA GARAGEM | D40: =8*1.25*(0.18+0.27) -> 4.5 | E40: CIMENTADO + RESINA | F40: Não | G40: Estucamento | H40: 1 | I40: =H40*Table_2[[#This Row],[Área (m²)]] -> 4.5
B41: G1 | C41: ANTECAMARA 1 | D41: 6.58 | E41: CIMENTADO + RESINA | F41: Não | G41: Estucamento | H41: 1 | I41: =H41*Table_2[[#This Row],[Área (m²)]] -> 6.58
B42: G1 | C42: ESCADA 1 | D42: =11.39+17*1.2*0.18 -> 15.062 | E42: CIMENTADO + RESINA | F42: Não | G42: Estucamento | H42: 1 | I42: =H42*Table_2[[#This Row],[Área (m²)]] -> 15.062
...

Sheet Rev. Internos Piso e Parede
A2: ORÇAMENTO PARAMÉTRICO GERENCIAMENTO EXECUTIVO
A7: Cliente
A8: Obra
A9: Data | B9: 45471
A10: Revisão | B10: R00
A12: REVESTIMENTOS INTERNOS EM PISO E PAREDE
A14: Descrição | B14: Quantidade | D14: Parâmetro | F14: Referência | G14: Valor total
A15: Polimento de concreto | B15: ='PISO E TETO'!M30 -> 1854.02 | C15: m² | E15: R$ / m² | F15: Média | G15: =D15*B15*1.1 -> 0 | H15: =G15/B15 -> 0 | I15: =172.7*B15 -> 320189.25
A16: Piso alisado | B16: ='PISO E TETO'!M28+'PISO E TETO'!M27+'PISO E TETO'!M29+'PISO E TETO'!M33 -> 1338.9961 | C16: m² | D16: 12 | E16: R$ / m² | F16: Média | G16: =D16*B16*1.1 -> 17674.749
A17: Piso ranhurado | C17: m² | D17: =28 -> 28 | E17: R$ / m² | F17: Média | G17: =D17*B17*1.1 -> 0
A18: Contrapiso | B18: ='PISO E TETO'!M11 -> 7152.5749 | C18: m² | D18: 32 | E18: m² / AC | F18: Média | G18: =B18*D18*1.1 -> 251770.64
A19: Manta acústica | B19: ='PISO E TETO'!M12 -> 6627.424 | C19: m² | D19: 26 | E19: m² / AC | F19: Média | G19: =B19*D19*1.1 -> 189544.33 | J19: =G19/B19 -> 28.6 | K19: =G19/DADOS_INICIAIS!E9 -> 16.896159
A20: Mao de obra piso | G20: ='Custos Serviços'!D69 -> 611015.48
A21: Chapisco | B21: =ALVENARIA!D13*2-'Rev. Fachada'!B15 -> 12432.695 | C21: m² | D21: 7.5 | E21: R$ / m² | F21: Média | G21: =B21*D21*1.1 -> 102569.74
A22: Reboco | B22: =B21 -> 12432.695 | C22: m² | D22: 16 | E22: R$ / m² | F22: Média | G22: =B22*D22*1.1 -> 218815.44
A23: Estucamento | B23: =0.15*DADOS_INICIAIS!E9 -> 1682.7285 | C23: m² | D23: 2.5 | E23: R$ / m² | F23: Média | G23: =B23*D23*1.1 -> 4627.5034
A24: Mao de obra argamassado | G24: ='Custos Serviços'!D35-'Custos Serviços'!D36+'Custos Serviços'!D47 -> 857051.05 | H24: =G24/B22 -> 68.935258
A25: TOTAL | G25: =SUM(G15:G24) -> 2253068.9
A28: TOTAL REVESTIMENTOS | G28: =G25 -> 2253068.9 | H28: =G28/DADOS_INICIAIS!E9 -> 200.84068

Sheet TETO
A3: REVESTIMENTOS E ACABAMENTOS DE TETO
A4: Data | B4: 45471
A5: Arquivo base | B5: -
A7: GESSO
A9: Descrição | B9: Parâmetro | D9: Quantidade | F9: Preço unitário | G9: Valor total | H9: Observação
A10: Forro gesso mineral | B10: =D10/DADOS_INICIAIS!E9 -> 0.72761676 | C10: m² / AC | D10: ='PISO E TETO'!M16+'PISO E TETO'!M17 -> 8162.5431 | E10: m² | F10: 75 | G10: =F10*D10*1.1 -> 673409.81
A11: Negativo | B11: 1.2 | C11: m / FORRO | D11: =(D10)*B11 -> 9795.0517 | E11: m | G11: =F11*D11*1.1 -> 0
A12: Estucamento | B12: =D12/DADOS_INICIAIS!E9 -> 0.28998942 | C12: m² / AC | D12: ='PISO E TETO'!M15 -> 3253.1564 | E12: m² | F12: 7.5 | G12: =F12*D12*1.1 -> 26838.54
A13: MO Estucamento | G13: ='Custos Serviços'!D58 -> 125869.19
A14: TOTAL | G14: =SUM(G10:G13) -> 826117.54 | H14: =G14/DADOS_INICIAIS!$E$9 -> 73.640894 | K14: =4160+1440+1120+2880+4800+91680+4000 -> 110080 | L14: =K14/21 -> 5241.9048
A16: TOTAL FORRO | G16: =G14 -> 826117.54 | H16: =G16/DADOS_INICIAIS!E9 -> 73.640894
G18: =#REF!/DADOS_INICIAIS!E9 -> #REF!
H19: =H16/1.1 -> 66.946267

Sheet Acabamentos de Piso e Parede
A2: ORÇAMENTO PARAMÉTRICO GERENCIAMENTO EXECUTIVO
A7: Cliente
A8: Obra
A9: Data | B9: 45471
A10: Revisão | B10: R00
A12: ACABAMENTOS EM PISO E PAREDE
A14: Descrição | B14: Quantidade | D14: Parâmetro | F14: Referência | G14: Valor total
A15: Porcelanato | B15: ='PISO E TETO'!M23 -> 723.20493 | C15: m² | D15: 85 | E15: R$ / m² | F15: Média | G15: =+D15*B15*1.1 -> 67619.66
A16: Porcelanato AC | B16: ='PISO E TETO'!M26 -> 513.39 | C16: m² | D16: 150 | E16: R$ / m² | F16: Média | G16: =+D16*B16*1.1 -> 84709.35
A17: Porcelanato AP | B17: ='PISO E TETO'!M36 -> 4007.3 | C17: m² | D17: 85 | E17: R$ / m² | F17: Média | G17: =+D17*B17*1.1 -> 374682.55
A18: Ceramica | B18: ='PISO E TETO'!M25 -> 5.07 | C18: m² | D18: 60 | E18: R$ / m² | F18: Média | G18: =+D18*B18*1.1 -> 334.62
A19: Piscina | B19: ='PISO E TETO'!M32 -> 130.99 | C19: m² | D19: =180+50 -> 230 | E19: R$ / m² | F19: Média | G19: =+D19*B19*1.1 -> 33140.47
A20: Paver | B20: ='PISO E TETO'!M24 -> 229.38 | C20: m² | D20: 150 | E20: R$ / m² | F20: Média | G20: =+D20*B20*1.1 -> 37847.7
A21: Vinilico | B21: ='PISO E TETO'!M37 -> 1725.88 | C21: m² | D21: 150 | E21: R$ / m² | F21: Média | G21: =+D21*B21*1.1 -> 284770.2
A22: Emborrachado | B22: ='PISO E TETO'!M31 -> 32.63 | C22: m² | D22: 350 | E22: R$ / m² | F22: Média | G22: =+D22*B22*1.1 -> 12562.55
A23: Deck | C23: m² | D23: =768+40 -> 808 | E23: R$ / m² | F23: Média | G23: =+D23*B23*1.1 -> 0
A24: Madeira sauna | B24: ='PISO E TETO'!M38 -> 7.87 | C24: m² | D24: =985.2 -> 985.2 | E24: R$ / m² | F24: Média | G24: =+D24*B24*1.1 -> 8528.8764
A25: Rodapés | B25: 1 | C25: vb | D25: 12 | E25: R$ / AC | F25: Média | G25: =D25*DADOS_INICIAIS!$E$9*1.1 -> 148080.11
A26: Soleiras | B26: 1 | C26: vb | D26: 0.35 | E26: R$ / AC | F26: Média | G26: =D26*DADOS_INICIAIS!$E$9*1.1 -> 4319.0032
A27: Peitoris | B27: 1 | C27: vb | D27: 1.5 | E27: R$ / AC | F27: Média | G27: =D27*DADOS_INICIAIS!$E$9*1.1 -> 18510.014
A28: Revestimentos de Parede | B28: =0.15*DADOS_INICIAIS!E9*0.25 -> 420.68212 | C28: m² | D28: 62 | E28: R$ / AC | F28: Média | G28: =D28*B28*1.1 -> 28690.521 | H28: apenas box
A29: Mao de obra acabamentos | G29: ='Custos Serviços'!D84 -> 1135647.3
G30: =SUM(G15:G29) -> 2239442.9
B33: =0.9*2+1.3 -> 3.1 | C33: =B33*3*2 -> 18.6 | D33: Office e family | E33: =C33*(DADOS_INICIAIS!$E$16+DADOS_INICIAIS!$E$17) -> 409.2
C34: =B33*2*2 -> 12.4 | D34: Gourmet e Style | E34: =C34*(DADOS_INICIAIS!$E$16+DADOS_INICIAIS!$E$17) -> 272.8

Sheet PINTURA INTERNA
A3: PINTURA INTERNA
A4: Data | B4: 45457
A5: Arquivo base | B5: -
A7: PINTURA INTERNA
A9: Descrição | B9: Parâmetro | D9: Quantidade | F9: Preço unitário | G9: Valor total | H9: Observação
A10: Pintura piso epoxi | B10: 110 | C10: R$ / m² | D10: ='PISO E TETO'!M30*0.1+'PISO E TETO'!M27 -> 191.642 | E10: m² | F10: =80+30 -> 110 | G10: =F10*D10*1.1 -> 23188.682 | H10: Vagas e bicicleta
A11: Pintura piso resina | B11: 110 | C11: R$ / m² | D11: ='PISO E TETO'!M29+'PISO E TETO'!M30 -> 3155.9914 | E11: m² | F11: 30 | G11: =F11*D11*1.1 -> 104147.72
A12: Pintura acrílica antiderrapante | B12: 65 | C12: R$ / m² | E12: m² | G12: =F12*D12*1.1 -> 0
A13: Textura escadas | B13: 25 | C13: R$ / AC | D13: =0.45*DADOS_INICIAIS!$E$9 -> 5048.1855 | E13: m² | F13: =6+28 -> 34 | G13: =F13*D13*1.1 -> 188802.14 | H13: =H10*0.2+TETO!D12 -> #VALUE!
A14: Textura Teto | B14: 25 | C14: R$ / AC | D14: =TETO!D12 -> 3253.1564 | E14: m² | F14: =F13 -> 34 | G14: =F14*D14*1.1 -> 121668.05 | H14: =H12*0.2+TETO!D14 -> 0
A15: Pintura Interna Tetos | B15: =90*0.9 -> 81 | C15: R$ / AC | D15: =TETO!D10 -> 8162.5431 | E15: m² | F15: =21+28 -> 49 | G15: =F15*D15*1.1 -> 439961.07
A16: Pintura Interna massa acrilica (banheiros) | B16: =90*0.9 -> 81 | C16: R$ / AC | D16: =0.15*DADOS_INICIAIS!E9-'Acabamentos de Piso e Parede'!B28 -> 1262.0464 | E16: m² | F16: =49+2 -> 51 | G16: =F16*D16*1.1 -> 70800.802
A17: Pintura Interna | B17: =90*0.9 -> 81 | C17: R$ / AC | D17: =1.61*DADOS_INICIAIS!$E$9 -> 18061.286 | E17: m² | F17: =F15 -> 49 | G17: =F17*D17*1.1 -> 973503.31
A18: TOTAL | G18: =SUM(G10:G17) -> 1922071.8 | K18: =4160+1440+1120+2880+4800+91680+4000 -> 110080 | L18: =K18/21 -> 5241.9048
A20: PINTURA INTERNA | G20: =G18 -> 1922071.8 | H20: =G20/DADOS_INICIAIS!E9 -> 171.33528
H22: =H20/1.1 -> 155.75935

Sheet COBERTURA
A2: COBERTURA
A3: Data | B3: 45543
A4: Arquivo base | B4: -
A6: TELHADO
A8: Descrição | B8: Parâmetro | D8: Quantidade | F8: Preço unitário | G8: Valor total | H8: Observação
A9: Estrutura e telhamento | D9: ='PISO E TETO'!M35+'PISO E TETO'!M39 -> 801.2684 | E9: m² | F9: 160 | G9: =F9*D9*1.1 -> 141023.24
A10: MO cobertura | D10: 1 | E10: vb | F10: ='Custos Serviços'!D82 -> 83777.26 | G10: =F10*D10 -> 83777.26
A11: Serviços complementares | D11: =D9 -> 801.2684 | E11: m² | F11: 30 | G11: =F11*D11*1.1 -> 26441.857
A12: Pergolados | D12: =7.33*(3+0.15+0.65)*2 -> 55.708 | E12: m² | F12: 450 | G12: =F12*D12*1.1 -> 27575.46
A13: Passarelas | G13: =F13*D13*1.1 -> 0
A14: TOTAL | G14: =SUM(G9:G13) -> 278817.82
A16: TOTAL COMPLEMENTARES | G16: =G14 -> 278817.82 | H16: =G16/DADOS_INICIAIS!$E$9 -> 24.854082

Sheet ESQUADRIAS
A3: ESQUADRIAS
A4: Data | B4: 45460
A5: Arquivo base | B5: -
A7: ESQUADRIAS
A9: Descrição | B9: Parâmetro | D9: Quantidade | G9: Valor total | H9: Observação
A10: Esquadrias de Alumínio | B10: 0.16 | C10: m² / AC | D10: =B10*DADOS_INICIAIS!E9 -> 1794.9104 | E10: m² | F10: 1100 | G10: =F10*D10*1.1 -> 2171841.6 | H10: praticamente toda aa rea da torre | I10: =G10/D10 -> 1210
A11: Pele de vidro | B11: 0.08 | C11: m² / AC | D11: =B11*DADOS_INICIAIS!E9 -> 897.4552 | E11: m² | F11: 950 | G11: =F11*D11*1.1 -> 937840.68
A12: Brise de fachada | D12: =37*(14-3.92) -> 372.96 | E12: m² | F12: =1350 -> 1350 | G12: =F12*D12*1.1 -> 553845.6
A13: Portão de alumínio | D13: 1 | E13: un | F13: 18000 | G13: =F13*D13*1.1 -> 19800
A14: Guarda-corpo - vidro | D14: =H30*1.1 -> 382.074 | E14: m² | F14: =850/1.1 -> 772.72727 | G14: =F14*D14*1.1 -> 324762.9
A15: Gradil area tecnica | D15: =H29*1.1 -> 33.451 | E15: m² | F15: =810/1.1 -> 736.36364 | G15: =F15*D15*1.1 -> 27095.31
A16: Serralherias | B16: 2 | C16: R$ / AC | D16: 1 | E16: vb | F16: =B16*DADOS_INICIAIS!$E$9 -> 22436.38 | G16: =F16*D16*1.1 -> 24680.018
A17: PCF | D17: =60+2 -> 62 | E17: un | F17: =1060+140 -> 1200 | G17: =F17*D17*1.1 -> 81840
A18: Corrimão madeira | D18: =(2.95*2+3.75)*1.2*DADOS_INICIAIS!E15+((5.35-1.2)*2+(2.05+0.9)*2)*1.2*4 -> 380.82 | E18: m | F18: 85 | G18: =F18*D18*1.1 -> 35606.67
A19: Corrimão comercial | E19: m | F19: 650 | G19: =F19*D19*1.1 -> 0
A20: Fechadura Biometrica | D20: =DADOS_INICIAIS!E10 -> 44 | E20: un | F20: 1250 | G20: =F20*D20*1.1 -> 60500
A21: Esquadrias de Madeira | D21: =46+186+135+42 -> 409 | E21: un | F21: =850+120 -> 970 | G21: =F21*D21*1.1 -> 436403
A22: TOTAL | G22: =SUM(G10:G21) -> 4674215.8 | K22: =4160+1440+1120+2880+4800+91680+4000 -> 110080 | L22: =K22/21 -> 5241.9048
A24: TOTAL ESQUADRIAS | G24: =G22 -> 4674215.8 | H24: =G24/DADOS_INICIAIS!E9 -> 416.66399
B28: G1 | C28: G2 | D28: G3 | E28: TIPO DIF | F28: TIPO (X21) | G28: ROOFTOP
A29: BRISE TEC | E29: =2.5+(2.5+0.65) -> 5.65 | G29: =22.16+1.25+1.35 -> 24.76 | H29: =SUM(B29:G29) -> 30.41
A30: GC SACADA | B30: 12.52 | C30: 12.52 | D30: =10.19 -> 10.19 | E30: =7.33+6.24 -> 13.57 | F30: =E30*21 -> 284.97 | G30: =E30 -> 13.57 | H30: =SUM(B30:G30) -> 347.34
D36: Esquadrias 32mm | E36: =[7]ESQUADRIAS!$G$10 -> 2468001.8
D37: Esquadrias 25mm | E37: =G10 -> 2171841.6

Sheet Rev. Fachada
A2: ORÇAMENTO PARAMÉTRICO GERENCIAMENTO EXECUTIVO
A7: Cliente
A8: Obra
A9: Data | B9: 45543
A10: Revisão | B10: R00
A12: REVESTIMENTOS ARGAMASSADOS
A14: Descrição | B14: Quantidade | D14: Parâmetro | F14: Referência | G14: Valor total
A15: Chapisco e reboco | B15: =L25 -> 8208.7744 | C15: m² | D15: 36 | E15: R$ / m² | F15: - | G15: =B15*D15*1.1 -> 325067.47
A16: Tratamento | B16: =K22*(DADOS_INICIAIS!E15-DADOS_INICIAIS!E27)+K20*DADOS_INICIAIS!E27 -> 2415.76 | C16: m | D16: 2.5 | E16: R$ / m² | F16: - | G16: =B16*D16*1.1 -> 6643.34
A17: Mão de obra | B17: =B15 -> 8208.7744 | C17: m² | E17: R$ / m² | F17: - | G17: ='Custos Serviços'!D80 -> 698143.83
A18: TOTAL | G18: =SUM(G15:G17) -> 1029854.6
A20: PINTURA | J20: EMBASAMENTO | K20: =DADOS_INICIAIS!E26 -> 161.88 | L20: =14+1.1 -> 15.1
A22: Descrição | B22: Quantidade | D22: Parâmetro | F22: Referência | G22: Valor total | J22: TORRE 1 | K22: =DADOS_INICIAIS!E20 -> 76.88 | L22: =85.28-14 -> 71.28
A23: Textura | B23: =B15 -> 8208.7744 | C23: m² | D23: 28 | E23: R$ / m² | F23: - | G23: =B23*D23*1.1 -> 252830.25 | H23: =G23/B23 -> 30.8 | J23: RESERV | K23: =5.35*2+9.4*2 -> 29.5 | L23: =94.92-85.28 -> 9.64
A24: Mo Tetxura | B24: =B23 -> 8208.7744 | D24: 42 | F24: - | G24: =B24*D24*1.1 -> 379245.38 | H24: =G24/B24 -> 46.2
A25: TOTAL | G25: =SUM(G23:G24) -> 632075.63 | L25: =K20*L20+K22*L22+K23*L23+K21*L21 -> 8208.7744
A27: ACABAMENTOS ESPECIAIS | L27: =L25*0.95 -> 7798.3357
A29: Descrição | B29: Quantidade | D29: Parâmetro | F29: Referência | G29: Valor total | L29: =L25/DADOS_INICIAIS!E9 -> 0.73173787
A30: Acabamentos especiais (pedras e etc) | B30: 1 | C30: vb | D30: 5 | E30: R$ / m² | F30: - | G30: =D30*DADOS_INICIAIS!E9*1.1 -> 61700.045 | L30: =L27/DADOS_INICIAIS!E9 -> 0.69515097
A31: MO acabamentos especiais | C31: M² | D31: 600 | E31: R$ / m² | F31: -
G32: =SUM(G30:G31) -> 61700.045
J33: =25.78*2 -> 51.56
A35: TOTAL FACHADA | G35: =G25+G18+G32 -> 1723630.3 | H35: =G35/DADOS_INICIAIS!E9 -> 153.64603
B36: =0.07*DADOS_INICIAIS!$E$9 -> 785.2733 | H36: =H35/1.1 -> 139.67821

Sheet COMPLEMENTARES
A2: COMPLEMENTARES
A3: Data | B3: 45460
A4: Arquivo base | B4: -
A6: SERVIÇOS COMPLEMENTARES
A8: Descrição | B8: Parâmetro | D8: Quantidade | F8: Valor total
A9: Móveis e decoração | B9: 1500 | C9: R$ / AL | D9: =DADOS_INICIAIS!E21 -> 730.7647 | E9: m² | F9: =D9*B9*1.1 -> 1205761.8
A10: Comunicação visual | B10: 10 | C10: R$ / AC | D10: =B10*DADOS_INICIAIS!$E$9 -> 112181.9 | E10: vb | F10: =D10*1.1 -> 123400.09
