Workbook
Name \0: #REF!
Name \a: #REF!
Name \m: #REF!
Name aa: #REF!
Name aa: #REF!
Name aaaa: '[1]M.O.'!#REF!
Name angelo: [2]Geral!#REF!
Name area: #REF!
Name area: #REF!
Name aux: #REF!
Name aux: #REF!
Name BDA: #REF!
Name BDA: #REF!
Name BDI: #REF!
Name ca: #REF!
Name Capa: #REF!
Name cronograma: #REF!
Name cronograma: #REF!
Name D: #REF!
Name direto: #REF!
Name DRE: #REF!
Name ea: #REF!
Name FFFFFFF: #REF!
Name FFFFFFF: #REF!
Name item_1: #REF!
Name item_1: #REF!
Name LS: '[1]M.O.'!#REF!
Name LS: '[1]M.O.'!#REF!
Name MENU: #REF!
Name MENU: #REF!
Name MENU1: #REF!
Name MENU1: #REF!
Name MENU2: #REF!
Name MENU2: #REF!
Name MENU3: #REF!
Name MENU4: #REF!
Name MENU5: #REF!
Name MENU6: #REF!
Name mo: #REF!
Name OAE: #REF!
Name ParamValues1: [3]ParamValues!$A$1:$A$39
Name PAV: #REF!
Name PAV: #REF!
Name pr: #REF!
Name pr: #REF!
Name PRE: #REF!
Name PRE: #REF!
Name Print_Area_MI: #REF!
Name qe: #REF!
Name qee: #REF!
Name reforsu: #REF!
Name ren: #REF!
Name REV: #REF!
Name sa: #REF!
Name SEG: #REF!
Name SIH: #REF!
Name SIV: #REF!
Name ss: #REF!
Name susref: #REF!
Name tania: #REF!

Sheet Marine
A1: ORÇAMENTO EXECUTIVO
A2: Obra | B2: MARINE
A3: Empresa | B3: AMALFI
A4: Revisão | B4: R00 | F4: AC | G4: 4498.66
A5: Data | B5: 45322 | F5: APE | G5: 479.88
A6: ORÇAMENTO EXECUTIVO MARINE - R00 | G6: OBSERVAÇÕES
A7: Código | B7: Descrição | C7: Un. | D7: Quantidade orçada | E7: Preço unitário | F7: Preço total | G7: Considerações | H7: Quantitativos
A8: 01 | B8: CUSTOS INDIRETOS | F8: =F9+F74+F144 -> 2346985.5 | G8: OS CUSTOS INDIRETOS FORAM LANÇADOS SEGUINDO FORMULÁRIO DE CUSTOS INDIRETOS PREENCHIDO EM 19/06/2023 PELO ENGENHEIRO VINÍCIUS
A9: 01.01 | B9: SERVIÇOS TECNICOS | F9: =F10+F55 -> 387573.05 | G9: =F8-[4]ORÇAMENTO_EXECUTIVO_COMENTADO!$G$8 -> 63318.936
A10: 01.01.001 | B10: ESTUDOS-PROJETOS-CONSULTORIAS | F10: =F11+F17+F42+F51 -> 304289.7
A11: 01.01.001.0001 | B11: Estudos | F11: =SUM(F12:F16) -> 40433.9
A12: 01.01.001.0001.00001 | B12: Levantamento Topográfico | C12: VB | D12: 1 | E12: 27500 | F12: =E12*D12 -> 27500 | G12: Contrato ALFAPLAN TOPOGRAFIA - Incluido medição do terreno. Locação do gabarito e locação dos pilares.
A13: 01.01.001.0001.00002 | B13: Sondagem de Percussão | C13: VB | D13: 1 | E13: 12933.9 | F13: =E13*D13 -> 12933.9 | G13: Contrato com SOLO SONDAGEM.
A14: 01.01.001.0001.00003 | B14: Estudo ambiental | C14: VB | D14: 0 | E14: 1500 | F14: =E14*D14 -> 0 | G14: EXCLUIR
A15: 01.01.001.0001.00004 | B15: Memorial Descritivo | C15: VB | D15: 0 | E15: 2138 | F15: =E15*D15 -> 0 | G15: EXCLUIR
A16: 01.01.001.0001.00005 | B16: Estudo Geológico | C16: VB | D16: 0 | E16: 3122 | F16: =E16*D16 -> 0 | G16: EXCLUIR
A17: 01.01.001.0002 | B17: Projetos | F17: =SUM(F18:F41) -> 166779.75
A18: 01.01.001.0002.00001 | B18: Legalização e incorporação | C18: VB | D18: 1 | E18: 15500 | F18: =E18*D18 -> 15500 | G18: Despachante Marcos contratado pela Amalfi
A19: 01.01.001.0002.00002 | B19: Projetos Arquitetura | C19: VB | D19: 1 | E19: 67500 | F19: =E19*D19 -> 67500 | G19: Estará junto com Projetos de ARQ, HID e PCI no contrato da M&N Arquitetura
A20: 01.01.001.0002.00003 | B20: Projeto De Interiores | C20: VB | D20: 1 | E20: 34500 | F20: =E20*D20 -> 34500
A21: 01.01.001.0002.00004 | B21: Projetos Fachadas | C21: VB | D21: 1 | E21: 6200 | F21: =E21*D21 -> 6200 | G21: Valor de acordo com contrato Aetos
A22: 01.01.001.0002.00005 | B22: Projetos Fundação | C22: VB | D22: 0 | E22: 5000 | F22: =E22*D22 -> 0 | G22: EXCLUIR
A23: 01.01.001.0002.00006 | B23: Projetos Estrutura | C23: VB | D23: 1 | E23: 29341.44 | F23: =E23*D23 -> 29341.44 | G23: Valor de acordo com contrato CFA.
A24: 01.01.001.0002.00007 | B24: Projetos Elétricos | C24: VB | D24: 1 | E24: 9000 | F24: =E24*D24 -> 9000 | G24: Valode acordo com contrato PROCAUTI
A25: 01.01.001.0002.00008 | B25: Projetos de terraplanagem | C25: VB | E25: 980 | F25: =E25*D25 -> 0 | G25: EXCLUIR
A26: 01.01.001.0002.00009 | B26: Projetos comunicação e dados | C26: VB | E26: 1000 | F26: =E26*D26 -> 0 | G26: EXCLUIR
A27: 01.01.001.0002.00010 | B27: Projetos Luminotecnico | C27: VB | E27: 1000 | F27: =E27*D27 -> 0 | G27: EXCLUIR
A28: 01.01.001.0002.00011 | B28: Projetos de telefonia | C28: VB | E28: 1000 | F28: =E28*D28 -> 0 | G28: EXCLUIR
A29: 01.01.001.0002.00012 | B29: Projetos Hidráulicos | C29: VB | E29: 20000 | F29: =E29*D29 -> 0 | G29: EXCLUIR
A30: 01.01.001.0002.00013 | B30: Projetos Incêndio | C30: VB | E30: 21000 | F30: =E30*D30 -> 0 | G30: EXCLUIR
A31: 01.01.001.0002.00014 | B31: Projetos Ar Condicionado | C31: VB | E31: 1000 | F31: =E31*D31 -> 0 | G31: EXCLUIR
A32: 01.01.001.0002.00015 | B32: Projetos Segurança | C32: VB | D32: 1 | E32: 4000 | F32: =E32*D32 -> 4000 | G32: Conforme contratos de PGR e PCMSO e laudos da SPS
A33: 01.01.001.0002.00016 | B33: Projeto Impermeabilização | C33: VB | E33: 5000 | F33: =E33*D33 -> 0 | G33: EXCLUIR
A34: 01.01.001.0002.00017 | B34: Projeto De Esquadrias | C34: VB | E34: 14280 | F34: =E34*D34 -> 0 | G34: EXCLUIR
A35: 01.01.001.0002.00018 | B35: Projetos Isolamento Acústico | C35: VB | E35: 7000 | F35: =E35*D35 -> 0 | G35: EXCLUIR
A36: 01.01.001.0002.00019 | B36: Projetos de sonorização | C36: VB | E36: 7000 | F36: =E36*D36 -> 0 | G36: EXCLUIR
A37: 01.01.001.0002.00020 | B37: Projetos Piscinas | C37: VB | E37: 1000 | F37: =E37*D37 -> 0 | G37: EXCLUIR
A38: 01.01.001.0002.00021 | B38: Projetos Comunicação Visual | C38: VB | E38: 1000 | F38: =E38*D38 -> 0 | G38: EXCLUIR
A39: 01.01.001.0002.00022 | B39: Projetos Paisagismo | C39: VB | E39: 1000 | F39: =E39*D39 -> 0 | G39: EXCLUIR
A40: 01.01.001.0002.00028 | B40: Projetos de Exaustão | C40: VB | E40: 2000 | F40: =E40*D40 -> 0 | G40: EXCLUIR
...

Sheet Ravello
A1: ORÇAMENTO EXECUTIVO
A2: Obra | B2: RAVELLO | F2: AT | G2: 1412.41
A3: Empresa | B3: AMALFI | F3: AC | G3: 13434.29
A4: Revisão | B4: R00 | F4: APE | G4: 1023.93
A5: Data | B5: 45351
A6: ORÇAMENTO EXECUTIVO RAVELLO - R00
A7: Código | B7: Descrição | C7: Un. | D7: Quantidade orçada | E7: Preço unitário | F7: Preço total
A8: 02 | B8: CUSTOS DIRETOS | F8: =F9+F15+F36+F62+F86+F110+F126+F146+F158+F164+F174+F185+F196+F217+F234+F276+F306+F355+F367+F387 -> 34082879
A9: 02.01 | B9: MOVIMENTAÇÃO DE TERRA | F9: =F10 -> 91928.48
A10: 02.01.001 | B10: MOVIMENTAÇÃO DE TERRA | F10: =F11+F13 -> 91928.48
A11: 02.01.001.0001 | B11: Movimentação de terra | F11: =F12 -> 88500
A12: 02.01.001.0001.00002 | B12: Escavação Mecânica com Bota Fora de blocos e baldrames | C12: VB | D12: 1 | E12: 88500 | F12: =E12*D12 -> 88500 | G12: =F12/G4 -> 86.43169
A13: 02.01.001.0002 | B13: Lastro de brita | F13: =F14 -> 3428.48
A14: 02.01.001.0002.00001 | B14: Lastro de Brita e=10cm | C14: M2 | D14: 389.6 | E14: 8.8 | F14: =E14*D14 -> 3428.48 | G14: =D14/G4 -> 0.38049476
A15: 02.02 | B15: INFRAESTRUTURA | F15: =F16+F19 -> 2274308.4
A16: 02.02.001 | B16: FUNDAÇÃO PROFUNDA | F16: =F17 -> 949000 | G16: =F16/$G$3 -> 70.640131
A17: 02.02.001.0001 | B17: Fundação profunda | F17: =F18 -> 949000
A18: 02.02.001.0001.00001 | B18: Execução de estacas | C18: VB | D18: 1 | E18: 949000 | F18: =E18*D18 -> 949000
A19: 02.02.002 | B19: FUNDAÇÃO RASA | F19: =F20+F22+F32+F34 -> 1325308.4 | G19: =F19/$G$3 -> 98.651168
A20: 02.02.002.0001 | B20: Forma | F20: =F21 -> 113398.5
A21: 02.02.002.0001.00001 | B21: Fabricacao e montagem de forma para bloco de fundacao - em madeira serrada | C21: M2 | D21: 2128.44 | E21: 53.2778 | F21: 113398.5
A22: 02.02.002.0002 | B22: Armadura | F22: =SUM(F23:F31) -> 451418.81
A23: 02.02.002.0002.00001 | B23: Armacao aco CA-60 ø 5.0mm para infraestrutura corte e dobra em obra | C23: KG | D23: 2937.6 | E23: 8.4179 | F23: 24728.54
A24: 02.02.002.0002.00002 | B24: Armacao aco CA-50 ø 6.3mm para infraestrutura corte e dobra em obra | C24: KG | D24: 798.3 | E24: 0.4869 | F24: 388.7242
A25: 02.02.002.0002.00003 | B25: Armacao aco CA-50 ø 8.0mm para infraestrutura corte e dobra em obra | C25: KG | D25: 1896 | E25: 7.6699 | F25: 14542.206
A26: 02.02.002.0002.00004 | B26: Armacao aco CA-50 ø 10.0mm para infraestrutura corte e dobra em obra | C26: KG | D26: 6541 | E26: 7.3399 | F26: 48010.548
A27: 02.02.002.0002.00005 | B27: Armacao aco CA-50 ø 12.5mm para infraestrutura corte e dobra em obra | C27: KG | D27: 6299 | E27: 7.0099 | F27: 44155.612
A28: 02.02.002.0002.00006 | B28: Armacao aco CA-50 ø 16.0mm para infraestrutura corte e dobra em obra | C28: KG | D28: 10249 | E28: 7.0099 | F28: 71844.875
A29: 02.02.002.0002.00007 | B29: Armacao aco CA-50 ø 20.0mm para infraestrutura corte e dobra em obra | C29: KG | D29: 24674 | E29: 7.1419 | F29: 176220.23
A30: 02.02.002.0002.00008 | B30: Armacao aco CA-50 ø 25.0mm para infraestrutura corte e dobra em obra | C30: KG | D30: 5076 | E30: 7.1419 | F30: 36252.487
A31: 02.02.002.0002.00009 | B31: Armação aco com tela TQ 138 | C31: KG | D31: 2937.6 | E31: 12.0083 | F31: 35275.592
A32: 02.02.002.0003 | B32: Concreto | F32: =F33 -> 304905.83
A33: 02.02.002.0003.00001 | B33: Concreto usinado bombeavel - para infraestrutura - Fck 35MPa - Brita 0 SLUMP = 12 +/- 2 incluindo servico de bombeamento | C33: M3 | D33: 509.45 | E33: 598.5 | F33: =E33*D33 -> 304905.83
A34: 02.02.002.0004 | B34: Mão de obra | F34: =F35 -> 455585.26
A35: 02.02.002.0004.00001 | B35: Mao de obra para execucacao de infraestrutura de concreto armado (inclusindo blocos-baldrames-contenções-cisterna-dutos) | C35: VB | D35: 1 | E35: 455585.26 | F35: 455585.26
A36: 02.03 | B36: SUPRAESTRUTURA | F36: =F37 -> 8742671.4 | G36: =F36/$G$3 -> 650.77287
A37: 02.03.001 | B37: SUPRAESTRUTURA | F37: =F38+F41+F51+F53+F58+F60 -> 8742671.4
A38: 02.03.001.0001 | B38: Forma | F38: =F39+F40 -> 689058.07 | G38: =F38/$G$3 -> 51.290992
A39: 02.03.001.0001.00001 | B39: Fabricação de Fôrma Para Estruturas de Concreto Armado - em Chapa de Madeira Compensada Plastificada - E=18mm | C39: M2 | D39: =2.5*1109.21*2+2.5*(7467/15)*2 -> 8035.05 | E39: 83.977571 | F39: =E39*D39 -> 674763.98
A40: 02.03.001.0001.00005 | B40: Montagem e desmontagem de fôrma para Estruturas de Concreto Armado - em chapa de madeira compensada plastificada | C40: M2 | D40: =2.5*[5]OBRA!D10 -> 33585.725 | E40: 0.4256 | F40: =E40*D40 -> 14294.085
...

Sheet Dados Gerais
A2: ORÇAMENTO PARAMÉTRICO GERENCIAMENTO EXECUTIVO
A7: Cliente | B7: Amalfi
A8: Obra | B8: San Felicce
A9: Data | B9: 45747
A10: Revisão | B10: R00
A12: Descrição | B12: Identificador | C12: Informação
A13: Área do terreno | B13: AT | C13: 953.88 | D13: m² | F13: Pavimento | G13: Area (m²) | H13: Correção Amalfi (m²) | I13: diferença
A14: Área total construída | B14: AC | C14: =H21 -> 7456.95 | D14: m² | F14: TERREO | G14: 1946.79 | H14: 821.97
A15: N° total de pavimentos | B15: NP | C15: 13 | D15: un | F15: G1 | G15: 776.7 | H15: 761.33
A16: N° de pavimentos tipo | B16: NPT | C16: 9 | D16: un | F16: G2+LAZER | G16: 776.7 | H16: 756.19
A17: N° de pavimentos tipo diferenciado | B17: NPD | C17: 0 | D17: un | F17: TIPO (x9) | G17: =558.43 -> 558.43 | H17: 4907.25
A18: N° de pavimentos duplex | B18: ND | C18: 0 | D18: un | F18: COBERTURA | G18: =558.43 -> 558.43 | H18: 72.31
A19: Área Lazer | B19: AL | C19: =44.72+32.53+60.94+13.13+3.07+1.34+1.85+23.07+78.72+5.12+6.38+12.59+1.84+2.05+1.86+10.01+3.51+6.06 -> 308.79 | D19: m² | F19: BARRILETE | G19: 69.87 | H19: 68.95
A20: Locação da obra | B20: LC | C20: 129.29 | D20: m | F20: RESERVATÓRIO + TAMPA | G20: =69.87*2 -> 139.74 | H20: 68.95
A21: Área de projeção da torre | B21: APT | C21: =H17/9 -> 545.25 | D21: m² | G21: =SUM(G14:G16)+G17*9+G18+G19+G20 -> 9294.1 | H21: =SUM(H14:H20) -> 7456.95 | I21: =G21-H21 -> 1837.15
A22: Perímetro de projeção da torre | B22: PPT | C22: 109.27 | D22: m
A23: Área de subsolos | B23: AS | C23: 0 | D23: m²
A24: N° de subsolos | B24: NS | C24: 0 | D24: un
A25: Área do embasamento | B25: AE | C25: =H14+H15+H16 -> 2339.49 | D25: m²
A26: Área de projeção do embasamento | B26: APE | C26: =H15 -> 761.33 | D26: m²
A27: Perímetro de projeção embasamento | B27: PPE | C27: 121.18 | D27: m
A28: N° de pavimentos de embasamento | B28: NPE | C28: 3 | D28: un
A32: TERREO

Sheet Movimentação de Terra
A2: ORÇAMENTO PARAMÉTRICO GERENCIAMENTO EXECUTIVO
A7: Cliente | B7: Amalfi
A8: Obra | B8: San Felicce
A9: Data | B9: 45397
A10: Revisão | B10: R00 | J10: =6*30*200 -> 36000
A12: REBAIXAMENTO DE LENÇOL
A14: Descrição | B14: Quantidade | D14: Parâmetro | F14: Referência | G14: Valor total
A15: Rebaixamento de Lençol | B15: ='Dados Gerais'!C26 -> 761.33 | C15: m² | D15: 30 | E15: R$ / m² | F15: Média | G15: =D15*B15 -> 22839.9 | I15: =G15/'Dados Gerais'!$C$26 -> 30 | J15: 40 dias d erebaixamento
A16: TOTAL | G16: =SUM(G15:G15) -> 22839.9 | J16: 200,00 por dia
J17: =40*200 -> 8000
A19: ESCAVAÇÃO E REATERRO DE VALAS
A21: Descrição | B21: Quantidade | D21: Parâmetro | F21: Referência | G21: Valor total
A22: Escavação mecanizada para blocos e baldrames | B22: =D22*'Dados Gerais'!C26 -> 913.596 | C22: m³ | D22: 1.2 | E22: m³ / APE | F22: Média | G22: =+ROUNDUP((B22*80),0) -> 73088 | J22: =G22/'Dados Gerais'!$C$14 -> 9.8013263
A23: Reaterro para blocos e baldrames | B23: =D23*B22 -> 548.1576 | C23: m³ | D23: 0.6 | E23: m³ | F23: Média | G23: =+ROUNDUP((B23*30),0) -> 16445 | J23: =G23/'Dados Gerais'!$C$14 -> 2.2053252
A24: TOTAL | G24: =SUM(G22:G23) -> 89533 | I24: =G24/'Dados Gerais'!$C$26 -> 117.60078
A27: REGULARIZAÇÃO E APILOAMENTO DE FUNDO DE VALAS
A29: Descrição | B29: Quantidade | D29: Parâmetro | F29: Referência | G29: Valor total
A30: Lastro de BRITA | B30: =D30*'Dados Gerais'!C26 -> 304.532 | C30: m² | D30: 0.4 | E30: m² / APE | F30: Média | G30: =ROUNDUP((B30*8.8),0) -> 2680 | I30: =G30/'Dados Gerais'!$C$26 -> 3.5201555 | J30: =G30/'Dados Gerais'!$C$14 -> 0.35939627
A31: TOTAL | G31: =SUM(G30:G30) -> 2680
A34: TOTAL MOVIMENTAÇÃO DE TERRA | G34: =G16+G24+G31 -> 115052.9 | H34: =G34/'Dados Gerais'!C14 -> 15.428949

Sheet Infraestrutura
A2: ORÇAMENTO PARAMÉTRICO GERENCIAMENTO EXECUTIVO
A7: Cliente | B7: Amalfi
A8: Obra | B8: San Felicce
A9: Data | B9: 45397
A10: Revisão | B10: R00
A12: FUNDAÇÃO PROFUNDA
A14: Descrição | B14: Quantidade | D14: Parâmetro | F14: Referência | G14: Valor total
A15: Número de Estacas | B15: 102 | C15: un | D15: =B15/'Dados Gerais'!C26 -> 0.13397607 | E15: un / APE | F15: Média | G15: 0 | K15: Total estacas
A16: Estaca Hélice Continua Diâmetro 60 | B16: =D16*B15 -> 102 | C16: un | D16: 1 | E16: % | F16: Média | G16: 0 | J16: MARINE | K16: 413.02235 | L16: R$/m | M16: =63/Marine!G5 -> 0.13128282 | N16: =[8]ESTACAS!$D$19/[8]ESTACAS!$F$13 -> 3.3465079 | O16: KG/M
A17: Estaca Hélice Continua Diâmetro 60 | B17: =D17*B16 -> 2142 | C17: m | D17: 21 | E17: m / un | F17: Média | G17: =ROUNDUP((B17*100),0) -> 214200 | J17: RAVELLO | K17: 253.74332 | L17: R$/m
A18: Armação 6,3mm | B18: =D18*B20 -> 1514.0906 | C18: kg | D18: 2.5 | E18: kg / m³ | F18: Média | G18: =+ROUNDUP((B18*7.67),0) -> 11614
A19: Armação 16mm | B19: =D19*B20 -> 6661.9985 | C19: kg | D19: 11 | E19: kg / m³ | F19: Média | G19: =+ROUNDUP((B19*7.34),0) -> 48900
A20: Concreto | B20: =(PI()*0.6^2)/4*B17 -> 605.63623 | C20: m³ | D20: =535+35 -> 570 | E20: R$ / m³ | F20: Média | G20: =+ROUNDUP((B20*D20),0)*1.3 -> 448776.9
A21: Mobilização | B21: 1 | C21: vb | D21: 15000 | E21: vb | F21: Média | G21: =+ROUNDUP((B21*D21),0) -> 15000
A22: TOTAL | G22: =SUM(G15:G21) -> 738490.9 | H22: =G22/B17 -> 344.76699
A25: FUNDAÇÃO RASA
A27: Descrição | B27: Quantidade | D27: Parâmetro | F27: Referência | G27: Valor total
A28: Fabricação, montagem e desmontagem de forma para blocos e baldrames resinado | B28: =D28*'Dados Gerais'!C26 -> 380.665 | C28: m² | D28: 0.5 | E28: m² / APE | F28: Média | G28: =+B28*50 -> 19033.25
A29: Armação | B29: =B30*D29 -> 45679.8 | C29: kg | D29: 100 | E29: kg / m³ | F29: Média | G29: =+ROUNDUP((B29*7.34),0) -> 335290
A30: Concreto | B30: ='Dados Gerais'!C26*Infraestrutura!D30 -> 456.798 | C30: m³ | D30: 0.6 | E30: m³ / APE | F30: Média | G30: =+B30*(535+35)*1.05 -> 273393.6
A31: Mão de obra | B31: ='Dados Gerais'!C26 -> 761.33 | C31: m² | D31: 450 | E31: R$ / APE | F31: Média
A32: TOTAL | G32: =SUM(G28:G31) -> 627716.85
A36: TOTAL INFRAESTRUTURA | G36: =G22+G32 -> 1366207.8 | H36: =G36/'Dados Gerais'!C14 -> 183.21267

Sheet Supraestrutura
A2: ORÇAMENTO PARAMÉTRICO GERENCIAMENTO EXECUTIVO
A7: Cliente | B7: Amalfi
A8: Obra | B8: San Felicce
A9: Data | B9: 45397
A10: Revisão | B10: R00
A12: SUPRAESTRUTURA
A14: Descrição | B14: Quantidade | D14: Parâmetro | F14: Referência | G14: Valor total
A15: Fabricação forma | B15: =B16/D15 -> 1864.2375 | C15: m² | D15: 8 | E15: Reutilizações | F15: Média | G15: =+B15*85 -> 158460.19
A16: Montagem de forma | B16: =D16*'Dados Gerais'!C14 -> 14913.9 | C16: m² | D16: 2 | E16: m² / AC | F16: Média | G16: =+B16*1.5 -> 22370.85
A17: Escoramento - Torre | B17: ='Dados Gerais'!C21*'Dados Gerais'!C16 -> 4907.25 | C17: m² | D17: 45 | E17: R$ / m² | F17: Média | G17: =+B17*D17*0.5 -> 110413.12
A18: Escoramento - Embasamento | B18: =+'Dados Gerais'!C25 -> 2339.49 | C18: m² | D18: 45 | E18: R$ / m² | F18: Média | G18: =+B18*D18 -> 105277.05
A19: Cubetas | B19: =B17+B18 -> 7246.74 | C19: m² | D19: 24 | E19: R$ / m² | F19: Média | G19: =+B19*D19 -> 173921.76
A20: Armadura Convencional para Estrutura | B20: =D20*B21 -> 188660.84 | C20: kg | D20: 110 | E20: kg / m³ | F20: Média | G20: =+B20*7.25 -> 1367791.1
A21: Concreto | B21: =D21*'Dados Gerais'!C14 -> 1715.0985 | C21: m³ | D21: 0.23 | E21: m³ / AC | F21: Média | G21: =+B21*575*1.05 -> 1035490.7
A22: Mão de obra - estrutura em concreto armado | B22: ='Dados Gerais'!C14 -> 7456.95 | C22: m² | D22: 200 | E22: R$ / m² | F22: Média | G22: =+B22*D22 -> 1491390
A23: TOTAL | G23: =SUM(G15:G22) -> 4465114.7
A26: TOTAL SUPRAESTRUTURA | G26: =G23 -> 4465114.7 | H26: =G26/'Dados Gerais'!C14 -> 598.78566
A29: SUPRAESTRUTURA
A31: Descrição | B31: Quantidade | D31: Parâmetro | F31: Referência | G31: Valor total
A32: Fabricação forma | B32: =B33/D32 -> 1957.4494 | C32: m² | D32: 8 | E32: Reutilizações | F32: Média | G32: =+B32*85 -> 166383.2
A33: Montagem de forma | B33: =D33*'Dados Gerais'!C14 -> 15659.595 | C33: m² | D33: 2.1 | E33: m² / AC | F33: Média | G33: =+B33*1.5 -> 23489.393
A34: Escoramento - Torre | B34: ='Dados Gerais'!C21*'Dados Gerais'!C16 -> 4907.25 | C34: m² | D34: 45 | E34: R$ / m² | F34: Média | G34: =+B34*D34*0.5 -> 110413.12
A35: Escoramento - Embasamento | B35: =+'Dados Gerais'!C25 -> 2339.49 | C35: m² | D35: 45 | E35: R$ / m² | F35: Média | G35: =+B35*D35 -> 105277.05
A36: Armadura Convencional para Estrutura | B36: =D36*B37 -> 134225.1 | C36: kg | D36: 90 | E36: kg / m³ | F36: Média | G36: =+B36*7.25 -> 973131.98
A37: Concreto | B37: =D37*'Dados Gerais'!C14 -> 1491.39 | C37: m³ | D37: 0.2 | E37: m³ / AC | F37: Média | G37: =+B37*575*1.05 -> 900426.71
A38: Mão de obra - estrutura em concreto armado | B38: ='Dados Gerais'!C14 -> 7456.95 | C38: m² | D38: 240 | E38: R$ / m² | F38: Média | G38: =+B38*D38 -> 1789668
A39: TOTAL | G39: =SUM(G32:G38) -> 4068789.5

Sheet Alvenaria
A2: ORÇAMENTO PARAMÉTRICO GERENCIAMENTO EXECUTIVO
A7: Cliente | B7: Amalfi
A8: Obra | B8: San Felicce
A9: Data | B9: 45397
A10: Revisão | B10: R00
A12: ALVENARIA
B13: =SUM(B15:B19,B21) -> 9621.8691 | C13: =B13/'Dados Gerais'!C14 -> 1.2903223
A14: Descrição | B14: Quantidade | D14: Parâmetro | F14: Referência | G14: Valor total | J14: alvenaria lazer | K14: 124.1 | L14: m | M14: =K14/K16 -> 0.61323319
A15: Alvenaria embasamento | B15: =D15*('Dados Gerais'!C25-B16) -> 1810.3281 | C15: m² | D15: 0.8 | E15: m² / AE | F15: Média | G15: =+B15*30 -> 54309.842 | J15: drywall lazer | K15: 78.27 | L15: m | M15: =K15/K16 -> 0.38676681
A16: Alvenaria lazer | B16: =D16*'Dados Gerais'!C19*0.62 -> 76.57992 | C16: m² | D16: 0.4 | E16: m² / AL | F16: Média | G16: =+B16*30 -> 2297.3976 | J16: lin | K16: =SUM(K14:K15) -> 202.37
A17: Drywall lazer | B17: =D17*'Dados Gerais'!C19*0.38 -> 46.93608 | C17: m² | D17: 0.4 | E17: m² / AL | F17: Média | G17: =+B17*220 -> 10325.938
A18: Alvenaria tipo | B18: =D18*'Dados Gerais'!C21*'Dados Gerais'!C16*0.56 -> 4122.09 | C18: m² | D18: 1.5 | E18: m² / APT*(NPT+2ND) | F18: Média | G18: =+B18*30 -> 123662.7 | J18: alvenaria tipo | K18: 183.81 | L18: m | M18: =K18/K20 -> 1
A19: Drywall tipo | B19: =D18*'Dados Gerais'!C21*'Dados Gerais'!C16*0.44 -> 3238.785 | C19: m² | D19: 1.5 | E19: m² / APT*(NPT+2ND) | F19: Média | G19: =+B19*220 -> 712532.7
A20: Alvenaria escadas | B20: =D20*'Dados Gerais'!C14 -> 1267.6815 | C20: m² | D20: 0.17 | E20: m² / AC | F20: Média | G20: =+B20*60 -> 76060.89 | K20: =SUM(K18:K18) -> 183.81
A21: Alvenaria cobertura / reservatório | B21: =D21*'Dados Gerais'!C21 -> 327.15 | C21: m² | D21: 0.6 | E21: m² / APT | F21: Média | G21: =+B21*30 -> 9814.5
A22: Alvenaria refratárias | B22: ='Sistemas especiais'!B18 -> 47 | C22: un | D22: 1.75 | E22: m² / un | F22: Média | G22: =+B22*210 -> 9870 | K22: =K20+K16 -> 386.18 | L22: =(K15+#REF!)/K22 -> #REF!
A23: Serviços complementares | B23: =B15+B16+B18+B20+B21 -> 7603.8295 | C23: m² | D23: 7.5 | E23: R$ / m² | F23: Média | G23: =+B23*D23 -> 57028.721
A24: Mão de obra | B24: =B16+B18+B20+B21+B15 -> 7603.8295 | C24: m² | D24: 65 | E24: R$ / m² | F24: Média | G24: =+B24*D24 -> 494248.92
A25: TOTAL | G25: =SUM(G15:G24) -> 1550151.6
A28: TOTAL ALVENARIA | G28: =G25 -> 1550151.6 | H28: =G28/'Dados Gerais'!C14 -> 207.88011
E30: =(B15+B16+B18+B21)/'Dados Gerais'!$C$14 -> 0.84969699

Sheet Instalações
A2: ORÇAMENTO PARAMÉTRICO GERENCIAMENTO EXECUTIVO
A7: Cliente | B7: Amalfi
A8: Obra | B8: San Felicce
A9: Data | B9: 45397
A10: Revisão | B10: R00
A12: INSTALAÇÕES ELÉTRICAS
A14: Descrição | B14: Quantidade | D14: Parâmetro | F14: Referência | G14: Valor total
A15: Entrada de Energia | B15: 1 | C15: vb | D15: 5 | E15: R$ / AC | F15: Média | G15: =+D15*'Dados Gerais'!$C$14 -> 37284.75
A16: Eletrodutos e Eletrocalhas | B16: 1 | C16: vb | D16: 10 | E16: R$ / AC | F16: Média | G16: =+D16*'Dados Gerais'!$C$14 -> 74569.5
A17: Cabos e Fiações | B17: 1 | C17: vb | D17: 30 | E17: R$ / AC | F17: Média | G17: =+D17*'Dados Gerais'!$C$14 -> 223708.5
A18: Quadros e Disjuntores | B18: 1 | C18: vb | D18: 25 | E18: R$ / AC | F18: Média | G18: =+D18*'Dados Gerais'!$C$14 -> 186423.75
A19: Acabamentos Elétricos | B19: 1 | C19: vb | D19: 15 | E19: R$ / AC | F19: Média
A20: Equipamentos e Iluminação | B20: 1 | C20: vb | D20: 2 | E20: R$ / AC | F20: Média | G20: =+D20*'Dados Gerais'!$C$14 -> 14913.9
A21: Mão de Obra para Instalações Elétricas | B21: 1 | C21: vb | D21: 55 | E21: R$ / AC | F21: Média | G21: =+D21*'Dados Gerais'!$C$14 -> 410132.25
A22: TOTAL | G22: =SUM(G15:G21) -> 947032.65
A24: INSTALAÇÕES HIDROSSANITÁRIAS | J24: Esgoto
J25: Caixa de reclaque esgoto | P25: 1 | R25: 1145.2341 | S25: =R25*P25 -> 1145.2341
A26: Descrição | B26: Quantidade | D26: Parâmetro | F26: Referência | G26: Valor total | J26: MOTOBOMBA SHENEIDER BCS-350 (vazão 8,4m³/altura de operação 7 m.c.a.).1CV | N26: un | P26: 2 | R26: 5650.8 | S26: =R26*P26 -> 11301.6
A27: Instalações de Água Fria | B27: 1 | C27: vb | D27: 20 | E27: R$ / AC | F27: Média | G27: =+D27*'Dados Gerais'!$C$14 -> 149139
A28: Instalações de Água Quente | B28: 1 | C28: vb | D28: 10 | E28: R$ / AC | F28: Média | G28: =+D28*'Dados Gerais'!$C$14 -> 74569.5 | J28: Drenagem
A29: Instalações de Águas Pluviais | B29: 1 | C29: vb | D29: 10 | E29: R$ / AC | F29: Média | G29: =+D29*'Dados Gerais'!$C$14 -> 74569.5 | J29: QUADRO COMANDO BOMBA - Quadro Elevatório de Drenagem Pluvial, 2x1CV/380V | N29: un | P29: 4 | R29: 9116 | S29: =R29*P29 -> 36464
A30: Instalações Sanitárias | B30: 1 | C30: vb | D30: 15 | E30: R$ / AC | F30: Média | G30: =+D30*'Dados Gerais'!$C$14 -> 111854.25 | J30: Filtro de água Pluvial - FV1 | N30: un | P30: =2*4 -> 8 | R30: 1430 | S30: =R30*P30 -> 11440
A31: Louças e Metais | B31: 1 | C31: vb | D31: 20 | E31: R$ / AC | F31: Média | G31: =+D31*'Dados Gerais'!$C$14 -> 149139 | J31: MOTOBOMBA BRAVA DV-05 (vazão 5,3m³/altura operação 12 m.c.a.).1,2CV | N31: un | P31: =2*4 -> 8 | R31: 2100 | S31: =R31*P31 -> 16800
A32: Sistema de tratamento de esgoto | B32: 1 | C32: vb | D32: 20.5617 | E32: R$ / AC | F32: Média | G32: =+D32*'Dados Gerais'!$C$14 -> 153327.57
A33: Mão de Obra para Instalações Hidráulicas | B33: 1 | C33: vb | D33: 55 | E33: R$ / AC | F33: Média | G33: =+D33*'Dados Gerais'!$C$14 -> 410132.25 | S33: =SUM(S25:S31) -> 77150.834
A34: TOTAL | G34: =SUM(G27:G33) -> 1122731.1
A37: INSTALAÇÕES PREVENTIVAS E GLP
A39: Descrição | B39: Quantidade | D39: Parâmetro | F39: Referência | G39: Valor total
A40: Instalações Preventivas | B40: 1 | C40: vb | D40: 15 | E40: R$ / AC | F40: Média | G40: =+D40*'Dados Gerais'!$C$14 -> 111854.25
A41: Instalações de GLP | B41: 1 | C41: vb | D41: 10 | E41: R$ / AC | F41: Média | G41: =+D41*'Dados Gerais'!$C$14 -> 74569.5
A42: Instalações de Proteção e Aterramento - SPDA | B42: 1 | C42: vb | D42: 20 | E42: R$ / AC | F42: Média | G42: =+D42*'Dados Gerais'!$C$14 -> 149139
A43: TOTAL | G43: =SUM(G40:G42) -> 335562.75
A46: TOTAL INSTALAÇÕES | G46: =G22+G34+G43 -> 2405326.5 | H46: =G46/'Dados Gerais'!C14 -> 322.5617

Sheet Sistemas especiais
A2: ORÇAMENTO PARAMÉTRICO GERENCIAMENTO EXECUTIVO
A7: Cliente | B7: Amalfi
A8: Obra | B8: San Felicce
A9: Data | B9: 45397
A10: Revisão | B10: R00
A12: CLIMATIZAÇÃO, EXAUSTÃO MECÂNICA E PRESSURIZAÇÃO
A14: Descrição | B14: Quantidade | D14: Parâmetro | F14: Referência | G14: Valor total | J14: PRIVATIVA | K14: AREAS COMUNS
A15: Infraestrutura para Instalação de Ar Condicionado | B15: =(J15+K15) -> 160 | C15: un | D15: 1000 | E15: R$ / un | F15: Média | G15: =D15*B15 -> 160000 | J15: =9*17 -> 153 | K15: =3+4 -> 7 | M15: =8+7+17*15 -> 270
A16: Instalação de Ar Condicionado | B16: =K15 -> 7 | C16: un | D16: 4000 | E16: R$ / un | F16: Média | G16: =D16*B16 -> 28000
A17: Ventokit | B17: =(J17+K17) -> 42 | C17: un | D17: 350 | E17: R$ / un | F17: Média | G17: =+B17*D17 -> 14700 | J17: =4*9 -> 36 | K17: =2+2+2 -> 6
A18: Churrasqueiras | B18: =(J18+K18) -> 47 | C18: un | D18: 4500 | E18: R$ / un | F18: Média | G18: =+B18*D18 -> 211500 | J18: =5*9 -> 45 | K18: =2 -> 2
A19: TOTAL | G19: =SUM(G15:G18) -> 414200 | H19: =G19/'Dados Gerais'!$C$14 -> 55.545498
A21: COMUNICAÇÃO
A23: Descrição | B23: Quantidade | D23: Parâmetro | F23: Referência | G23: Valor total
A24: CFTV | B24: 1 | C24: vb | D24: 1 | E24: R$ / AC | F24: Média | G24: =+D24*'Dados Gerais'!$C$14 -> 7456.95
A25: Interfone | B25: 1 | C25: vb | D25: 2 | E25: R$ / AC | F25: Média | G25: =+D25*'Dados Gerais'!$C$14 -> 14913.9
A26: TV e internet | B26: 1 | C26: vb | D26: 6 | E26: R$ / AC | F26: Média | G26: =+D26*'Dados Gerais'!$C$14 -> 44741.7
A27: Automação, telecomunicação e sistemas de segurança | B27: 1 | C27: vb | D27: 2 | E27: R$ / AC | F27: Média
A28: TOTAL | G28: =SUM(G24:G27) -> 67112.55 | H28: =G28/'Dados Gerais'!$C$14 -> 9
A30: OUTROS SISTEMAS ESPECIAIS
A32: Descrição | B32: Quantidade | D32: Parâmetro | F32: Referência | G32: Valor total
A33: Outros sistemas | B33: 1 | C33: vb | D33: 20 | E33: R$ / AC | F33: Média | G33: =+D33*'Dados Gerais'!C14 -> 149139
A34: TOTAL | G34: =SUM(G33:G33) -> 149139
A37: EQUIPAMENTOS
A39: Descrição | B39: Quantidade | D39: Parâmetro | F39: Referência | G39: Valor total
A40: Elevadores | B40: 2 | C40: un | D40: 226000 | E40: R$ / un | F40: Média | G40: =B40*D40 -> 452000
A41: Grupo de geradores | B41: 1 | C41: un | D41: 80000 | E41: R$ | F41: Média
A42: Subestação | B42: 1 | C42: un | D42: 250000 | E42: R$ | F42: Média
A43: Infra de carro elétrico | B43: =1*5*9 -> 45 | C43: un | D43: 500 | E43: R$ / un | F43: Média
A44: Instalação carro elétrico | B44: 1 | C44: un | D44: 10000 | E44: R$ / un | F44: Média
A45: Sistema de placas fotovoltaicas | B45: =11.63*16.25 -> 188.9875 | C45: m2 | D45: 810 | E45: R$ / m² (telhado) | F45: Média
A46: Equipamentos para Piscina | B46: 1 | C46: un | D46: 50000 | E46: R$ | F46: Média | G46: =+B46*D46 -> 50000
A47: TOTAL | G47: =SUM(G40:G46) -> 502000 | H47: =G47/'Dados Gerais'!$C$14 -> 67.319749
A50: TOTAL SISTEMAS ESPECIAIS | G50: =G19+G34+G47+G28 -> 1132451.6 | H50: =G50/'Dados Gerais'!C14 -> 151.86525

Sheet Impermeabilização
A2: ORÇAMENTO PARAMÉTRICO GERENCIAMENTO EXECUTIVO
A7: Cliente | B7: Amalfi
A8: Obra | B8: San Felicce
A9: Data | B9: 45397
A10: Revisão | B10: R00
A12: IMPERMEABILIZAÇÃO
A14: Descrição | B14: Quantidade | D14: Parâmetro | F14: Referência | G14: Valor total
A15: Regularização de Superfície | B15: =B19+B20 -> 3780 | C15: m² | D15: 25 | E15: R$ / m² | F15: Média | G15: =+B15*D15 -> 94500
A16: Poço do elevador | B16: =3.33*2+7.3*1.8*2 -> 32.94 | C16: m² | D16: 45 | E16: R$ / m² | F16: Média | G16: =+B16*D16 -> 1482.3
A17: Baldrames | B17: =Infraestrutura!B28 -> 380.665 | C17: m² | D17: 30 | E17: R$ / m² | F17: Média | G17: =+B17*D17 -> 11419.95
A18: Ralos | B18: 1 | C18: vb | D18: 0.4 | E18: R$ / AC | F18: Média | G18: =D18*'Dados Gerais'!C14 -> 2982.78
A19: Impermeabilizações cimenticias | B19: =D19*'Dados Gerais'!C14 -> 2982.78 | C19: m² | D19: 0.4 | E19: m² / AC | F19: Média | G19: =+B19*105 -> 313191.9
A20: Impermeabilizações com manta asfaltica | B20: =('Dados Gerais'!G18+60.55+10.1+11.01+12.85+5.06+6.35)*1.2 -> 797.22 | C20: m² | D20: 0.18 | E20: m² / AC | F20: Média | G20: =+B20*120 -> 95666.4
A21: Impermeabilização de peitoril | B21: 1 | C21: vb | D21: 1 | E21: R$ / AC | F21: Média | G21: =+D21*'Dados Gerais'!$C$14 -> 7456.95
A22: Proteção Mecânica | B22: =B20 -> 797.22 | C22: m² | D22: 28 | E22: R$ / m² | F22: Média | G22: =D22*B22 -> 22322.16
A23: TOTAL | G23: =SUM(G15:G22) -> 549022.44
A26: TOTAL IMPERMEABILIZAÇÃO | G26: =G23 -> 549022.44 | H26: =G26/'Dados Gerais'!C14 -> 73.625603

Sheet Rev. Internos Piso e Parede
A2: ORÇAMENTO PARAMÉTRICO GERENCIAMENTO EXECUTIVO
A7: Cliente | B7: Amalfi
A8: Obra | B8: San Felicce
A9: Data | B9: 45397
A10: Revisão | B10: R00
A12: REVESTIMENTOS INTERNOS EM PISO E PAREDE
J13: =SUM(G15:G18) -> 428546.45
A14: Descrição | B14: Quantidade | D14: Parâmetro | F14: Referência | G14: Valor total | J14: =G20+G21 -> 150062.43
A15: Piso de concreto lapidado | B15: ='Acabamentos de Piso e Parede'!H31+'Acabamentos de Piso e Parede'!H32+'Acabamentos de Piso e Parede'!H33+'Acabamentos de Piso e Parede'!H34+'Acabamentos de Piso e Parede'!H35 -> 1581.2 | C15: m² | D15: 157 | E15: R$ / m² | F15: Média | G15: =D15*B15 -> 248248.4
A16: Piso de concreto alisado ranhurado | B16: ='Acabamentos de Piso e Parede'!I31+'Acabamentos de Piso e Parede'!I32+'Acabamentos de Piso e Parede'!I33+'Acabamentos de Piso e Parede'!I34+'Acabamentos de Piso e Parede'!I35 -> 237.7 | C16: m² | D16: 30 | E16: R$ / m² | F16: Média | G16: =D16*B16 -> 7131
A17: Contrapiso | B17: =SUM('Acabamentos de Piso e Parede'!B31:G35)-'Acabamentos de Piso e Parede'!D31+'Acabamentos de Piso e Parede'!M33 -> 4809.72 | C17: m² | D17: =B17/'Dados Gerais'!C14 -> 0.64499829 | E17: m² / AC | F17: Média | G17: =+B17*25 -> 120243
A18: Manta acústica | B18: ='Acabamentos de Piso e Parede'!B34+'Acabamentos de Piso e Parede'!G34 -> 3528.27 | C18: m² | D18: =B18/'Dados Gerais'!C14 -> 0.47315189 | E18: m² / AC | F18: Média | G18: =+B18*15 -> 52924.05
A19: Mão de obra contrapiso | B19: =B17 -> 4809.72 | G19: =B19*24 -> 115433.28
A20: Chapisco | B20: =Alvenaria!B23*2-'Rev. Fachada'!B15 -> 10349.133 | C20: m² | D20: 2.1 | E20: m² / AC | F20: Média | G20: =+B20*2.5 -> 25872.832
A21: Reboco | B21: =B20 -> 10349.133 | C21: m² | D21: 2.1 | E21: m² / AC | F21: Média | G21: =B21*12 -> 124189.59
A22: Mão de obra reboco | B22: =B20 -> 10349.133 | C22: m² | E22: m² / AC | F22: Média | G22: =B22*45 -> 465710.98
A23: TOTAL | G23: =SUM(G15:G21) -> 694042.16
A26: TOTAL REVESTIMENTOS | G26: =G23 -> 694042.16 | H26: =G26/'Dados Gerais'!C14 -> 93.073194
B29: =Alvenaria!B23*2-'Rev. Fachada'!B15 -> 10349.133

Sheet Acabamentos de Teto
A2: ORÇAMENTO PARAMÉTRICO GERENCIAMENTO EXECUTIVO
A7: Cliente | B7: Amalfi
A8: Obra | B8: San Felicce
A9: Data | B9: 45397
A10: Revisão | B10: R00
A12: ACABAMENTOS DE TETO
A14: Descrição | B14: Quantidade | D14: Parâmetro | F14: Referência | G14: Valor total
A15: Forro de gesso acartonado | B15: =+'Dados Gerais'!C14*D15 -> 5219.865 | C15: m² | D15: 0.7 | E15: m² / AC | F15: Média | G15: =+B15*110 -> 574185.15
A16: Negativo | B16: =B15*1.2 -> 6263.838 | C16: m | D16: =B16/'Dados Gerais'!$C$14 -> 0.84 | E16: m / AC | F16: Média | G16: =+B16*22 -> 137804.44
A17: Estucamento | B17: =D17*'Dados Gerais'!$C$14 -> 1491.39 | C17: m² | D17: 0.2 | E17: R$ / AC | F17: Média | G17: =B17*24 -> 35793.36
A18: Chapisco e reboco | B18: =D18*'Dados Gerais'!$C$14 -> 0 | C18: m² | D18: 0 | E18: R$ / AC | F18: Média | G18: =B18*91 -> 0
A19: TOTAL | G19: =SUM(G15:G18) -> 747782.95
A22: TOTAL TETO | G22: =G19 -> 747782.95 | H22: =G22/'Dados Gerais'!C14 -> 100.28

Sheet Acabamentos de Piso e Parede
A2: ORÇAMENTO PARAMÉTRICO GERENCIAMENTO EXECUTIVO
A7: Cliente | B7: Amalfi
A8: Obra | B8: San Felicce
A9: Data | B9: 45397
A10: Revisão | B10: R00
A12: ACABAMENTOS EM PISO E PAREDE
A14: Descrição | B14: Quantidade | D14: Parâmetro | F14: Referência | G14: Valor total
A15: Porcelanato | B15: =SUM(B31:B34)+SUM(F31:F35)+C31 -> 3217.69 | C15: m² | D15: =70+85 -> 155 | E15: R$ / m² | F15: Média | G15: =+D15*B15 -> 498741.95 | I15: =SUM(G15:G20)+G21/2 -> 979686.75 | K15: =I15+'Rev. Internos Piso e Parede'!J13 -> 1408233.2 | L15: PISO
A16: Piso vinilico | B16: =SUM(G31:G35) -> 1285.83 | C16: m² | D16: 130 | E16: R$ / m² | F16: Média | G16: =+D16*B16 -> 167157.9 | I16: =G22 -> 372847.5 | K16: =I16+'Rev. Internos Piso e Parede'!J14 -> 522909.93 | L16: PAREDE
A17: Piscina | B17: =5.12+6.38+12.59+9.35*0.5+10.64*0.2+15.32*1.5 -> 53.873 | C17: m² | D17: 250 | E17: R$ / m² | F17: Média | G17: =+D17*B17 -> 13468.25
A18: Emborrachado | B18: =SUM(E31:E35) -> 45.68 | C18: m² | D18: 310 | E18: R$ / m² | F18: Média | G18: =+D18*B18 -> 14160.8
A19: Paver | B19: =SUM(D31:D35) -> 190.85 | C19: m² | D19: 210 | E19: R$ / m² | F19: Média | G19: =+D19*B19 -> 40078.5
A20: Rodapés | B20: 1 | C20: vb | D20: 18 | E20: R$ / AC | F20: Média | G20: =+D20*'Dados Gerais'!$C$14 -> 134225.1
A21: Soleiras e peitoris | B21: 1 | C21: vb | D21: 30 | E21: R$ / AC | F21: Média | G21: =+D21*'Dados Gerais'!$C$14 -> 223708.5
A22: Revestimentos de Parede | B22: 1 | C22: vb | D22: =30+20 -> 50 | E22: R$ / AC | F22: Média | G22: =+D22*'Dados Gerais'!$C$14 -> 372847.5
A23: =20*40 -> 800 | G23: =SUM(G15:G22) -> 1464388.5
A26: TOTAL ACABAMENTOS | G26: =G23 -> 1464388.5 | H26: =G26/'Dados Gerais'!C14 -> 196.37902 | M26: =93.57+88.12+77.13+107.7+90.62 -> 457.14
L27: QUARTO | M27: =13.61+9.94+11.26+10.54+14+10.65+13.2+14.02+9.35+11.26+14.32+10.72 -> 142.87
L28: BANHEIRO | M28: =3.71+3.81+2+1.91+3.47+3.47+3.76+3.8+1.91+3.66+3.64+1.8+3.66+3.67 -> 44.27
L29: LIVNG E CIRCULAÇÃO | M29: =30.02+1.42+26.1+4.86+16.15+1.72+25.53+1.45+21.62+3.14 -> 132.01
B30: PORCELANATO | C30: CERAMICA | D30: PAVER | E30: EMBORRACHADO | F30: ANTIDERRAPANTE | G30: VINILICO | H30: ALISADO | I30: RANHURARDO | L30: COZINHA E AREA DE SERVIÇO | M30: =7.72+11+9.41+8.95+7.19+2.99 -> 47.26
A31: TERREO | B31: =0.89+51.22+12.62+27.48 -> 92.21 | C31: =9.17+16.31+2.96+2+2 -> 32.44 | D31: =113.16+77.69 -> 190.85 | H31: =4.31+336.97+201.17 -> 542.45 | I31: =30.44 -> 30.44 | L31: SACADA E AREA TECNICA | M31: =5.76+8.95+7.62+10.94+1.41+9.64+3.02+8.04+2.69+2.44+6.01 -> 66.52
A32: G1 | B32: =6.24 -> 6.24 | H32: =623.54 -> 623.54 | I32: =88.41 -> 88.41
A33: G2+LAZER | B33: =23.07+6.64+44.72+3.07+1.34+1.85+60.94 -> 141.63 | E33: =32.53+13.15 -> 45.68 | F33: =78.72+1.84+2.05+1.86+10.01+6.06+3.51 -> 104.05 | H33: =323.2+9.09 -> 332.29 | I33: =30.44+88.41 -> 118.85 | L33: ESCADA | M33: =(5.31+12.35+1.25*0.18*18)*12 -> 260.52
A34: TIPO | B34: =(25.62+M28+M29+M30)*9 -> 2242.44 | F34: =M31*9 -> 598.68 | G34: =M27*9 -> 1285.83 | I34: =0 -> 0
A35: COBERTURA | H35: =20.1+62.82 -> 82.92 | I35: =0 -> 0

Sheet Pintura Interna
A2: ORÇAMENTO PARAMÉTRICO GERENCIAMENTO EXECUTIVO
A7: Cliente | B7: Amalfi
A8: Obra | B8: Tramonti
A9: Data | B9: 45352
A10: Revisão | B10: R00
A12: PINTURA INTERNA - OPÇÃO 1
A14: Descrição | B14: Quantidade | D14: Parâmetro | F14: Referência | G14: Valor total
A15: Pintura piso epoxi | B15: =('Acabamentos de Piso e Parede'!H31+'Acabamentos de Piso e Parede'!H32+'Acabamentos de Piso e Parede'!H33)*0.02 -> 29.9656 | C15: m2 | D15: 90 | E15: R$ / m² | F15: Média | G15: =+D15*B15 -> 2696.904 | H15: apenas vagas
A16: Pintura acrílica antiderrapante | B16: ='Acabamentos de Piso e Parede'!M33+'Acabamentos de Piso e Parede'!H35 -> 343.44 | C16: m2 | D16: 65 | E16: R$ / m² | F16: Média | G16: =+D16*B16 -> 22323.6
A17: Textura escadas | B17: 1 | C17: vb | D17: 8 | E17: R$ / AC | F17: Média | G17: =+D17*'Dados Gerais'!$C$14 -> 59655.6
A18: Pintura Interna | B18: 1 | C18: vb | D18: 24 | E18: R$ / AC | F18: Média | G18: =+D18*'Dados Gerais'!$C$14 -> 178966.8
A19: Mão deo obra pintura e textura | B19: 1 | C19: vb | D19: 105 | E19: R$ / AC | F19: Média | G19: =+D19*'Dados Gerais'!$C$14 -> 782979.75
A20: TOTAL | G20: =SUM(G15:G18) -> 263642.9
A23: TOTAL PINTURA | G23: =G20 -> 263642.9 | H23: =G23/'Dados Gerais'!C14 -> 35.355327

Sheet Esquadrias
A2: ORÇAMENTO PARAMÉTRICO GERENCIAMENTO EXECUTIVO
A7: Cliente | B7: Amalfi
A8: Obra | B8: Tramonti
A9: Data | B9: 45352
A10: Revisão | B10: R00
A12: ESQUADRIAS
A14: Descrição | B14: Quantidade | D14: Parâmetro | F14: Referência | G14: Valor total
A15: Esquadrias de Alumínio | B15: =0.18*'Dados Gerais'!$C$14 -> 1342.251 | C15: m² | D15: 741.32624 | E15: R$ / m² | F15: Média | G15: =D15*B15 -> 995045.89
A16: PCF | B16: =12*2 -> 24 | C16: un | D16: 1150 | E16: R$ / un | F16: Média | G16: =D16*B16 -> 27600
A17: Serralherias | B17: 1 | C17: vb | D17: 3 | E17: R$ / AC | F17: Média | G17: =D17*B17*'Dados Gerais'!C14 -> 22370.85
A18: Guarda-corpo - vidro | B18: =B34 -> 391.14 | C18: m² | D18: 727.37 | E18: R$ / m² | F18: Média | G18: =+D18*B18 -> 284503.5
A19: Gradil | B19: =B31*9*1.1 -> 229.482 | C19: m | D19: 671.38 | E19: R$ / m² | F19: Média | G19: =+D19*B19 -> 154069.63
A20: Corrimão madeira | B20: =(4.64+13.3)*1.1*12 -> 236.808 | C20: m | D20: =60.5*3 -> 181.5 | E20: R$ / m² | F20: Média | G20: =+D20*B20 -> 42980.652
A21: Portão de alumínio | B21: 2 | C21: un | D21: 18000 | E21: R$ / un | F21: Média | G21: =+D21*B21 -> 36000
A22: Esquadrias de Madeira | B22: =3+6+(7+6+5+7+6)*9 -> 288 | C22: un | D22: 900 | E22: R$ / un | F22: Média | G22: =D22*B22 -> 259200
A23: TOTAL | G23: =SUM(G15:G22) -> 1821770.5
A26: TOTAL ESQUADRIAS | G26: =G23 -> 1821770.5 | H26: =G26/'Dados Gerais'!C14 -> 244.30505
C29: 626.24
B30: TIPO
A31: GRADIL | B31: =1.28+8.98+4.07+5.11+3.74 -> 23.18
A32: GUARDA COPRO | B32: =3.39+5.26+13.11+9.8 -> 31.56 | C32: 41.91
B34: =(B32*9+C32)*1.2 -> 391.14

Sheet Auxiliar
A2: 2 Portões acesso garagem - Área: 9,2m² x 2 = 18,4m² | B2: 2 | C2: portão | D2: 18.4
A3: 2 portas corta-fogo 1 folha | B3: 2 | C3: pcf
A4: 1 porta de correr alumínio 2 folhas – Área: 3,465m² | B4: 1 | C4: porta alumínio | D4: 3.465
A5: 1 porta de correr alumínio 2 folhas – Área: 1,7325m² | B5: 1 | C5: porta alumínio | D5: 1.7325 | G5: Guarda alumínio | H5: =SUMIF(C:C,G5,D:D) -> 400.5221
A6: 2 portas de abrir alumínio 2 folhas – Área: 2,6376m² x 2 = 5,2752m² | B6: 2 | C6: porta alumínio | D6: 5.2752 | G6: janela | H6: =SUMIF(C:C,G6,D:D) -> 1895.06
A7: 1 porta de abrir alumínio 2 folhas – Área: 4,1916m² | B7: 1 | C7: porta alumínio | D7: 4.1916 | G7: madeira | H7: =SUMIF(C:C,G7,B:B) -> 218
A8: 1 porta pivotante | B8: 1 | C8: pivotante | G8: pcf | H8: =SUMIF(C:C,G8,B:B) -> 60
A9: 19 portas de abrir madeira 1 folha | B9: 19 | C9: madeira | G9: pivotante | H9: =SUMIF(C:C,G9,B:B) -> 1
A10: 3 portas de abrir vidro 1 folha – Área: 2,1m² x 3 = 6,3m² | B10: 3 | C10: porta alumínio | D10: 6.3 | G10: porta alumínio | H10: =SUMIF(C:C,G10,D:D) -> 46.62
A11: 2 portas de abrir vidro 1 folha – Área: 1,89m² x 2 = 3,78m² | B11: 2 | C11: porta alumínio | D11: 3.78 | G11: portão | H11: =SUMIF(C:C,G11,B:B) -> 2
A12: 1 porta de abrir alumínio 1 folha – Área: 2,0076m² | B12: 1 | C12: porta alumínio | D12: 2.0076 | G12: gradil | H12: =SUMIF(C:C,G12,D:D) -> 113.88
A13: Janelas – Área: 3,75 + 4,875 + 2,5 + 1,1 + 1,2 + 5,5402 + 4,4874 = 23,4526m² | C13: janela | D13: 23.4526 | G13: Brise | H13: 109.3146
A14: Muro de vidro – Área: 7,0774 + 5,485 + 3,43 + 4,8138 = 20,8062m² | C14: Guarda alumínio | D14: 20.8062
A15: 8 portas corta-fogo 1 folha | B15: 8 | C15: pcf
A16: Janelas – Area: (1,1 + 1,2 + 28,7391) x 4 = 124,1564m² | C16: janela | D16: 124.1564
A17: 2 portas corta-fogo 1 folha | B17: 2 | C17: pcf
A18: 2 portas de abrir alumínio 1 folha – Área: 1,47m² x 2 = 2,94m² | B18: 2 | C18: porta alumínio | D18: 2.94
A19: 2 portas de abrir vidro 1 folha – Área: 1,89m² x 2 = 3,78m² | B19: 2 | C19: porta alumínio | D19: 3.78
A20: 5 portas de abrir madeira 1 folha | B20: 5 | C20: madeira
A21: 1 janela-porta de correr vidro – Área: 14,7348m² | B21: 1 | C21: janela | D21: 14.7348
A22: Janelas – Área: 1,2894 + 1,2894 + 23,46 + 1,854 + 5,562 + 5,562 + 1,854 + 1,854 + 1,1 + 1,2 = 45,0248m² | C22: janela | D22: 45.0248
A23: Guarda corpo vidro – Área: 7,5299 + 5,7955 + 6,5555 = 19,8809m² | C23: Guarda alumínio | D23: 19.8809
A24: 38 portas corta-fogo 1 folha | B24: 38 | C24: pcf
A25: 171 portas de abrir madeira 1 folha | B25: 171 | C25: madeira
A26: 19 porta de abrir alumínio 1 folha – Área: 1,26m² x 19 = 23,94m² | B26: 19 | C26: porta alumínio | D26: 23.94
A27: 19 janela-porta de correr vidro 5 folhas - Área: 25,4205m² x 19 = 482,9895m² | B27: 19 | C27: janela | D27: 482.9895
A28: 19 janela-porta de correr vidro 5 folhas - Área: 17,8284m² x 19 = 338,7396m² | B28: 19 | C28: janela | D28: 338.7396
A29: Janelas – Área: 1,1 + 1,1 + 1,2 + 1,92 + 0,36 + 2,781 + 2,781 + 1,854 + 1,854 + 5,562 + 5,562 + 1,854 = 27,928m² x 19 = 530,632m² | C29: janela | D29: 530.632
A30: Guarda corpo metálico – Área: 4,745m² x 19 = 90,155m² - Perímetro: 3,65m x 19 = 69,35m | C30: gradil | D30: 90.155
A31: Guarda corpo vidro – Área: 15,645m² x 19 = 297,255m² - Perímetro: 14,9m x 19 = 283,1m | C31: Guarda alumínio | D31: 297.255
A32: 2 portas corta-fogo 1 folha | B32: 2 | C32: pcf
A33: 2 portas de abrir madeira 1 folha | B33: 2 | C33: madeira
A34: 1 porta de abrir alumínio 1 folha – Área: 1,26m² | B34: 1 | C34: porta alumínio | D34: 1.26
A35: 1 janela-porta de correr vidro 3 folhas - Área: 15,21m² | B35: 1 | C35: janela | D35: 15.21
A36: 1 janela-porta de correr vidro 5 folhas - Área: 25,4205m² | B36: 1 | C36: janela | D36: 25.4205
A37: 1 janela-porta de correr vidro 5 folhas - Área: 17,8284m² | B37: 1 | C37: janela | D37: 17.8284
A38: Janelas – Área: 1,1 + 1,2 + 1,1 + 1,92 + 0,36 + 2,781 + 2,781 + 1,854 + 1,854 + 5,562 + 5,562 + 1,854 = 27,928m² | C38: janela | D38: 27.928
A39: Guarda corpo metálico – Área: 4,745m² - Perímetro: 3,65m | C39: gradil | D39: 4.745
A40: Guarda corpo vidro – Área: 15,645m² - Perímetro: 14,9m | C40: Guarda alumínio | D40: 15.645
A41: 2 portas corta-fogo 1 folha | B41: 2 | C41: pcf
...

Sheet Rev. Fachada
A2: ORÇAMENTO PARAMÉTRICO GERENCIAMENTO EXECUTIVO
A7: Cliente | B7: Amalfi
A8: Obra | B8: Tramonti
A9: Data | B9: 45352
A10: Revisão | B10: R00
A12: REVESTIMENTOS ARGAMASSADOS
A14: Descrição | B14: Quantidade | D14: Parâmetro | F14: Referência | G14: Valor total
A15: Chapisco e reboco | B15: =K19*L19+K20*L20+K21*L21 -> 4858.5261 | C15: m² | D15: 18 | E15: R$ / m² | F15: - | G15: =B15*D15 -> 87453.47
A16: Mão de obra | B16: =B15 -> 4858.5261 | C16: m² | D16: 115 | E16: R$ / m² | F16: - | G16: =B16*D16 -> 558730.5
A17: TOTAL | G17: =SUM(G15:G16) -> 646183.97
A19: PINTURA | J19: EMBASAMENTO | K19: ='Dados Gerais'!C27 -> 121.18 | L19: 9.42
J20: TORRE | K20: ='Dados Gerais'!C22 -> 109.27 | L20: 31.95
A21: Descrição | B21: Quantidade | D21: Parâmetro | F21: Referência | G21: Valor total | J21: RESERV | K21: 33.96 | L21: 6.65
A22: Microtextura | B22: =B15 -> 4858.5261 | C22: m² | D22: =30+42 -> 72 | E22: R$ / m² | F22: - | G22: =+B22*D22 -> 349813.88
A23: TOTAL | G23: =SUM(G22) -> 349813.88
A25: ACABAMENTOS ESPECIAIS
A27: Descrição | B27: Quantidade | D27: Parâmetro | F27: Referência | G27: Valor total
A28: Revestimentos especiais | B28: 1 | C28: vb | D28: 40 | E28: R$ / m² | F28: - | G28: =B28*D28*'Dados Gerais'!C14 -> 298278
G29: =SUM(G28:G28) -> 298278
J30: =25.78*2 -> 51.56
A32: TOTAL FACHADA | G32: =G29+G23+G17 -> 1294275.9 | H32: =G32/'Dados Gerais'!C14 -> 173.56638

Sheet Complementares
A2: ORÇAMENTO PARAMÉTRICO GERENCIAMENTO EXECUTIVO
A7: Cliente | B7: Amalfi
A8: Obra | B8: Tramonti
A9: Data | B9: 45352
A10: Revisão | B10: R00
A12: SERVIÇOS COMPLEMENTARES
A14: Descrição | B14: Quantidade | D14: Parâmetro | F14: Referência | G14: Valor total
A15: Móveis e decoração | B15: 1 | C15: vb | D15: 1750 | E15: R$ / AL | F15: Média | G15: =200*'Dados Gerais'!C14 -> 1491390 | J15: Alinterna | K15: ='Dados Gerais'!C19 -> 308.79
A16: Comunicação visual | B16: 1 | C16: vb | D16: 3 | E16: R$ / AC | F16: Média | G16: =B16*D16*'Dados Gerais'!$C$14 -> 22370.85
A17: Paisagismo | B17: 1 | C17: vb | D17: 5 | E17: R$ / AC | F17: Média | G17: =B17*D17*'Dados Gerais'!$C$14 -> 37284.75 | K17: =K15/'Dados Gerais'!C14 -> 0.041409692
A18: Ligações definitivas | B18: 1 | C18: vb | D18: 10 | E18: R$ / AC | F18: Média | G18: =B18*D18*'Dados Gerais'!$C$14 -> 74569.5
A19: desmobilização | B19: 1 | C19: vb | D19: 1 | E19: R$ / AC | F19: Média | G19: =B19*D19*'Dados Gerais'!$C$14 -> 7456.95
A20: Limpeza | B20: 1 | C20: vb | D20: 15 | E20: R$ / AC | F20: Média | G20: =B20*D20*'Dados Gerais'!$C$14 -> 111854.25
A21: TOTAL4 | G21: =SUM(G15:G20) -> 1744926.3
A24: TOTAL COMPLEMENTARES | G24: =G21 -> 1744926.3 | H24: =G24/'Dados Gerais'!C14 -> 234
