Workbook

Sheet PRAZO
B2: ORÇAMENTO PARAMÉTRICO | ESTIMATIVA DE PRAZO
B4: BD EMPREENDIMENTOS - JARDIM CAMPECHE
B7: SERVIÇOS | C7: M1 | D7: M2 | E7: M3 | F7: M4 | G7: M5 | H7: M6 | I7: M7 | J7: M8 | K7: M9 | L7: M10 | M7: M11 | N7: M12 | O7: M13 | P7: M14 | Q7: M15 | R7: M16 | S7: M17 | T7: M18 | U7: M19 | V7: M20 | W7: M21 | X7: M22 | Y7: M23 | Z7: M24 | AA7: M25 | AB7: M26 | AC7: M27 | AD7: M28 | AE7: M29 | AF7: M30 | AG7: M31 | AH7: M32 | AI7: M33 | AJ7: M34 | AK7: M35 | AL7: M36
B8: MOVIMENTAÇÃO DE TERRA | C8: 1 | D8: 2 | E8: 3 | F8: 4 | AM8: =COUNTA(C8:AL8) -> 4
B9: INFRAESTRUTURA + CONTENÇÃO | D9: 2 | E9: 3 | F9: 4 | G9: 5 | H9: 6 | AM9: =COUNTA(C9:AL9) -> 5
B10: SUPRAESTRUTURA | I10: 1 | J10: 2 | K10: 3 | L10: 3 | M10: 4 | N10: 5 | O10: 6 | P10: 7 | Q10: 8 | R10: 8.5833333 | S10: 9.4333333 | AM10: =COUNTA(C10:AL10) -> 11
B11: ALVENARIA | L11: 1 | M11: 2 | N11: 3 | O11: 4 | P11: 5 | Q11: 6 | R11: 7 | S11: 8 | T11: 8 | U11: 9.5555556 | V11: 10.488889 | AM11: =COUNTA(C11:AL11) -> 11
B12: INSTALAÇÕES ELÉTRICAS, HIDRÁULICAS, GLP E PREVENTIVAS | M12: 1 | N12: 2 | O12: 3 | P12: 4 | Q12: 5 | R12: 6 | S12: 7 | T12: 8 | U12: 9 | V12: 10 | W12: 1 | X12: 10 | Y12: 1 | AM12: =COUNTA(C12:AL12) -> 13
B13: EQUIPAMENTOS E SISTEMAS ESPECIAIS | X13: 1 | Y13: 2 | Z13: 3 | AA13: 4 | AB13: 5 | AC13: 6 | AD13: 7 | AE13: 8 | AF13: 9 | AM13: =COUNTA(C13:AL13) -> 9
B14: IMPERMEABILIZAÇÃO | P14: 1 | Q14: 2 | R14: 3 | S14: 4 | T14: 5 | U14: 6 | V14: 7 | W14: 8 | X14: 9 | Y14: 10 | Z14: 10 | AA14: 10 | AM14: =COUNTA(C14:AL14) -> 12
B15: REVESTIMENTOS INTERNOS EM PISO E PAREDE | N15: 1 | O15: 2 | P15: 3 | Q15: 4 | R15: 5 | S15: 6 | T15: 7 | U15: 8 | V15: 9 | W15: 10 | X15: 9 | AM15: =COUNTA(C15:AL15) -> 11
B16: REVESTIMENTOS E ACABAMENTOS INTERNOS EM TETO | Q16: 1 | R16: 2 | S16: 3 | T16: 4 | U16: 5 | V16: 6 | W16: 7 | X16: 8 | Y16: 9 | Z16: 10 | AA16: 10 | AM16: =COUNTA(C16:AL16) -> 11
B17: ACABAMENTOS EM PISO E PAREDE | P17: 1 | Q17: 2 | R17: 3 | S17: 4 | T17: 5 | U17: 6 | V17: 7 | W17: 8 | X17: 9 | Y17: 10 | Z17: 1 | AA17: 2 | AB17: 3 | AC17: 4 | AD17: 5 | AE17: 6 | AF17: 6 | AM17: =COUNTA(C17:AL17) -> 17
B18: PINTURA INTERNA | R18: 1 | S18: 2 | T18: 3 | U18: 4 | V18: 5 | W18: 6 | X18: 7 | Y18: 8 | Z18: 9 | AA18: 10 | AB18: 1 | AC18: 2 | AD18: 3 | AE18: 4 | AF18: 5 | AG18: 4 | AH18: 4 | AI18: 4 | AM18: =COUNTA(C18:AL18) -> 18
B19: ESQUADRIAS, VIDROS E FERRAGENS | AB19: 3 | AC19: 4 | AD19: 5 | AE19: 6 | AF19: 6 | AG19: 6 | AH19: 6 | AM19: =COUNTA(C19:AL19) -> 7
B20: REVESTIMENTOS E ACABAMENTOS DE FACHADA | W20: 1 | X20: 2 | Y20: 3 | Z20: 4 | AA20: 5 | AB20: 6 | AC20: 7 | AD20: 8 | AE20: 7 | AF20: 8 | AM20: =COUNTA(C20:AL20) -> 10
B21: SERVIÇOS COMPLEMENTARES | AG21: 1 | AH21: 1 | AI21: 2 | AJ21: 3 | AK21: 4 | AL21: 5 | AM21: =COUNTA(C21:AL21) -> 6

Sheet DISTRIBUIÇÃO CUSTO
B2: ORÇAMENTO PARAMÉTRICO | DISTRIBUIÇÃO MENSAL DE CUSTOS
B4: BD EMPREENDIMENTOS - JARDIM CAMPECHE
B7: ETAPA | C7: VALOR ORÇADO | D7: % | E7: VALOR / m² | F7: % Distribuído | H7: M1 | J7: M2 | L7: M3 | N7: M4 | P7: M5 | R7: M6 | T7: M7 | V7: M8 | X7: M9 | Z7: M10 | AB7: M11 | AD7: M12 | AF7: M13 | AH7: M14 | AJ7: M15 | AL7: M16 | AN7: M17 | AP7: M18 | AR7: M19 | AT7: M20 | AV7: M21 | AX7: M22 | AZ7: M23 | BB7: M24 | BD7: M25 | BF7: M26 | BH7: M27 | BJ7: M28 | BL7: M29 | BN7: M30 | BP7: M31 | BR7: M32 | BT7: M33 | BV7: M34 | BX7: M35 | BZ7: M36
H8: % | I8: R$ | J8: % | K8: R$ | L8: % | M8: R$ | N8: % | O8: R$ | P8: % | Q8: R$ | R8: % | S8: R$ | T8: % | U8: R$ | V8: % | W8: R$ | X8: % | Y8: R$ | Z8: % | AA8: R$ | AB8: % | AC8: R$ | AD8: % | AE8: R$ | AF8: % | AG8: R$ | AH8: % | AI8: R$ | AJ8: % | AK8: R$ | AL8: % | AM8: R$ | AN8: % | AO8: R$ | AP8: % | AQ8: R$ | AR8: % | AS8: R$ | AT8: % | AU8: R$ | AV8: % | AW8: R$ | AX8: % | AY8: R$ | AZ8: % | BA8: R$ | BB8: % | BC8: R$ | BD8: % | BE8: R$ | BF8: % | BG8: R$ | BH8: % | BI8: R$ | BJ8: % | BK8: R$ | BL8: % | BM8: R$ | BN8: % | BO8: R$ | BP8: % | BQ8: R$ | BR8: % | BS8: R$ | BT8: % | BU8: R$ | BV8: % | BW8: R$ | BX8: % | BY8: R$ | BZ8: % | CA8: R$
B9: GERENCIAMENTO TÉCNICO E ADMINISTRATIVO | C9: 2551044.1 | D9: =C9/$C$26 -> 0.12298689 | E9: =C9/'DISTRIBUIÇÃO CUSTO'!C$30 -> 702.22917 | F9: =SUMIFS($H9:$CA9,$H$8:$CA$8,"%") -> 1 | H9: 0.122 | I9: =$C9*H9 -> 311227.38 | J9: 0.122 | K9: =$C9*J9 -> 311227.38 | L9: 0.122 | M9: =$C9*L9 -> 311227.38 | N9: 0.0926 | O9: =$C9*N9 -> 236226.68 | P9: 0.0926 | Q9: =$C9*P9 -> 236226.68 | R9: 0.0926 | S9: =$C9*R9 -> 236226.68 | T9: =(1-($H$9+$J$9+$L$9+$N$9+$P$9+$R$9))/30 -> 0.011873333 | U9: =$C9*T9 -> 30289.397 | V9: =(1-($H$9+$J$9+$L$9+$N$9+$P$9+$R$9))/30 -> 0.011873333 | W9: =$C9*V9 -> 30289.397 | X9: =(1-($H$9+$J$9+$L$9+$N$9+$P$9+$R$9))/30 -> 0.011873333 | Y9: =$C9*X9 -> 30289.397 | Z9: =(1-($H$9+$J$9+$L$9+$N$9+$P$9+$R$9))/30 -> 0.011873333 | AA9: =$C9*Z9 -> 30289.397 | AB9: =(1-($H$9+$J$9+$L$9+$N$9+$P$9+$R$9))/30 -> 0.011873333 | AC9: =$C9*AB9 -> 30289.397 | AD9: =(1-($H$9+$J$9+$L$9+$N$9+$P$9+$R$9))/30 -> 0.011873333 | AE9: =$C9*AD9 -> 30289.397 | AF9: =(1-($H$9+$J$9+$L$9+$N$9+$P$9+$R$9))/30 -> 0.011873333 | AG9: =$C9*AF9 -> 30289.397 | AH9: =(1-($H$9+$J$9+$L$9+$N$9+$P$9+$R$9))/30 -> 0.011873333 | AI9: =$C9*AH9 -> 30289.397 | AJ9: =(1-($H$9+$J$9+$L$9+$N$9+$P$9+$R$9))/30 -> 0.011873333 | AK9: =$C9*AJ9 -> 30289.397 | AL9: =(1-($H$9+$J$9+$L$9+$N$9+$P$9+$R$9))/30 -> 0.011873333 | AM9: =$C9*AL9 -> 30289.397 | AN9: =(1-($H$9+$J$9+$L$9+$N$9+$P$9+$R$9))/30 -> 0.011873333 | AO9: =$C9*AN9 -> 30289.397 | AP9: =(1-($H$9+$J$9+$L$9+$N$9+$P$9+$R$9))/30 -> 0.011873333 | AQ9: =$C9*AP9 -> 30289.397 | AR9: =(1-($H$9+$J$9+$L$9+$N$9+$P$9+$R$9))/30 -> 0.011873333 | AS9: =$C9*AR9 -> 30289.397 | AT9: =(1-($H$9+$J$9+$L$9+$N$9+$P$9+$R$9))/30 -> 0.011873333 | AU9: =$C9*AT9 -> 30289.397 | AV9: =(1-($H$9+$J$9+$L$9+$N$9+$P$9+$R$9))/30 -> 0.011873333 | AW9: =$C9*AV9 -> 30289.397 | AX9: =(1-($H$9+$J$9+$L$9+$N$9+$P$9+$R$9))/30 -> 0.011873333 | AY9: =$C9*AX9 -> 30289.397 | AZ9: =(1-($H$9+$J$9+$L$9+$N$9+$P$9+$R$9))/30 -> 0.011873333 | BA9: =$C9*AZ9 -> 30289.397 | BB9: =(1-($H$9+$J$9+$L$9+$N$9+$P$9+$R$9))/30 -> 0.011873333 | BC9: =$C9*BB9 -> 30289.397 | BD9: =(1-($H$9+$J$9+$L$9+$N$9+$P$9+$R$9))/30 -> 0.011873333 | BE9: =$C9*BD9 -> 30289.397 | BF9: =(1-($H$9+$J$9+$L$9+$N$9+$P$9+$R$9))/30 -> 0.011873333 | BG9: =$C9*BF9 -> 30289.397 | BH9: =(1-($H$9+$J$9+$L$9+$N$9+$P$9+$R$9))/30 -> 0.011873333 | BI9: =$C9*BH9 -> 30289.397 | BJ9: =(1-($H$9+$J$9+$L$9+$N$9+$P$9+$R$9))/30 -> 0.011873333 | BK9: =$C9*BJ9 -> 30289.397 | BL9: =(1-($H$9+$J$9+$L$9+$N$9+$P$9+$R$9))/30 -> 0.011873333 | BM9: =$C9*BL9 -> 30289.397 | BN9: =(1-($H$9+$J$9+$L$9+$N$9+$P$9+$R$9))/30 -> 0.011873333 | BO9: =$C9*BN9 -> 30289.397 | BP9: =(1-($H$9+$J$9+$L$9+$N$9+$P$9+$R$9))/30 -> 0.011873333 | BQ9: =$C9*BP9 -> 30289.397 | BR9: =(1-($H$9+$J$9+$L$9+$N$9+$P$9+$R$9))/30 -> 0.011873333 | BS9: =$C9*BR9 -> 30289.397 | BT9: =(1-($H$9+$J$9+$L$9+$N$9+$P$9+$R$9))/30 -> 0.011873333 | BU9: =$C9*BT9 -> 30289.397 | BV9: =(1-($H$9+$J$9+$L$9+$N$9+$P$9+$R$9))/30 -> 0.011873333 | BW9: =$C9*BV9 -> 30289.397 | BX9: =(1-($H$9+$J$9+$L$9+$N$9+$P$9+$R$9))/30 -> 0.011873333 | BY9: =$C9*BX9 -> 30289.397 | BZ9: =(1-($H$9+$J$9+$L$9+$N$9+$P$9+$R$9))/30 -> 0.011873333 | CA9: =$C9*BZ9 -> 30289.397
B10: MOVIMENTAÇÃO DE TERRA | C10: 309991.74 | D10: =C10/$C$26 -> 0.014944829 | E10: =C10/'DISTRIBUIÇÃO CUSTO'!C$30 -> 85.331822 | F10: =SUMIFS($H10:$CA10,$H$8:$CA$8,"%") -> 1 | H10: =IF(PRAZO!C8>0,1/PRAZO!$AM8,0) -> 0.25 | I10: =$C10*H10 -> 77497.934 | J10: =IF(PRAZO!D8>0,1/PRAZO!$AM8,0) -> 0.25 | K10: =$C10*J10 -> 77497.934 | L10: =IF(PRAZO!E8>0,1/PRAZO!$AM8,0) -> 0.25 | M10: =$C10*L10 -> 77497.934 | N10: =IF(PRAZO!F8>0,1/PRAZO!$AM8,0) -> 0.25 | O10: =$C10*N10 -> 77497.934 | P10: =IF(PRAZO!G8>0,1/PRAZO!$AM8,0) -> 0 | Q10: =$C10*P10 -> 0 | R10: =IF(PRAZO!H8>0,1/PRAZO!$AM8,0) -> 0 | S10: =$C10*R10 -> 0 | T10: =IF(PRAZO!I8>0,1/PRAZO!$AM8,0) -> 0 | U10: =$C10*T10 -> 0 | V10: =IF(PRAZO!J8>0,1/PRAZO!$AM8,0) -> 0 | W10: =$C10*V10 -> 0 | X10: =IF(PRAZO!K8>0,1/PRAZO!$AM8,0) -> 0 | Y10: =$C10*X10 -> 0 | Z10: =IF(PRAZO!L8>0,1/PRAZO!$AM8,0) -> 0 | AA10: =$C10*Z10 -> 0 | AB10: =IF(PRAZO!M8>0,1/PRAZO!$AM8,0) -> 0 | AC10: =$C10*AB10 -> 0 | AD10: =IF(PRAZO!N8>0,1/PRAZO!$AM8,0) -> 0 | AE10: =$C10*AD10 -> 0 | AF10: =IF(PRAZO!O8>0,1/PRAZO!$AM8,0) -> 0 | AG10: =$C10*AF10 -> 0 | AH10: =IF(PRAZO!P8>0,1/PRAZO!$AM8,0) -> 0 | AI10: =$C10*AH10 -> 0 | AJ10: =IF(PRAZO!Q8>0,1/PRAZO!$AM8,0) -> 0 | AK10: =$C10*AJ10 -> 0 | AL10: =IF(PRAZO!R8>0,1/PRAZO!$AM8,0) -> 0 | AM10: =$C10*AL10 -> 0 | AN10: =IF(PRAZO!S8>0,1/PRAZO!$AM8,0) -> 0 | AO10: =$C10*AN10 -> 0 | AP10: =IF(PRAZO!T8>0,1/PRAZO!$AM8,0) -> 0 | AQ10: =$C10*AP10 -> 0 | AR10: =IF(PRAZO!U8>0,1/PRAZO!$AM8,0) -> 0 | AS10: =$C10*AR10 -> 0 | AT10: =IF(PRAZO!V8>0,1/PRAZO!$AM8,0) -> 0 | AU10: =$C10*AT10 -> 0 | AV10: =IF(PRAZO!W8>0,1/PRAZO!$AM8,0) -> 0 | AW10: =$C10*AV10 -> 0 | AX10: =IF(PRAZO!X8>0,1/PRAZO!$AM8,0) -> 0 | AY10: =$C10*AX10 -> 0 | AZ10: =IF(PRAZO!Y8>0,1/PRAZO!$AM8,0) -> 0 | BA10: =$C10*AZ10 -> 0 | BB10: =IF(PRAZO!Z8>0,1/PRAZO!$AM8,0) -> 0 | BC10: =$C10*BB10 -> 0 | BD10: =IF(PRAZO!AA8>0,1/PRAZO!$AM8,0) -> 0 | BE10: =$C10*BD10 -> 0 | BF10: =IF(PRAZO!AB8>0,1/PRAZO!$AM8,0) -> 0 | BG10: =$C10*BF10 -> 0 | BH10: =IF(PRAZO!AC8>0,1/PRAZO!$AM8,0) -> 0 | BI10: =$C10*BH10 -> 0 | BJ10: =IF(PRAZO!AD8>0,1/PRAZO!$AM8,0) -> 0 | BK10: =$C10*BJ10 -> 0 | BL10: =IF(PRAZO!AE8>0,1/PRAZO!$AM8,0) -> 0 | BM10: =$C10*BL10 -> 0 | BN10: =IF(PRAZO!AF8>0,1/PRAZO!$AM8,0) -> 0 | BO10: =$C10*BN10 -> 0 | BP10: =IF(PRAZO!AG8>0,1/PRAZO!$AM8,0) -> 0 | BQ10: =$C10*BP10 -> 0 | BR10: =IF(PRAZO!AH8>0,1/PRAZO!$AM8,0) -> 0 | BS10: =$C10*BR10 -> 0 | BT10: =IF(PRAZO!AI8>0,1/PRAZO!$AM8,0) -> 0 | BU10: =$C10*BT10 -> 0 | BV10: =IF(PRAZO!AJ8>0,1/PRAZO!$AM8,0) -> 0 | BW10: =$C10*BV10 -> 0 | BX10: =IF(PRAZO!AK8>0,1/PRAZO!$AM8,0) -> 0 | BY10: =$C10*BX10 -> 0 | BZ10: =IF(PRAZO!AL8>0,1/PRAZO!$AM8,0) -> 0 | CA10: =$C10*BZ10 -> 0
B11: INFRAESTRUTURA + CONTENÇÃO | C11: 1671107.7 | D11: =C11/$C$26 -> 0.080564792 | E11: =C11/'DISTRIBUIÇÃO CUSTO'!C$30 -> 460.00796 | F11: =SUMIFS($H11:$CA11,$H$8:$CA$8,"%") -> 1 | H11: =IF(PRAZO!C9>0,1/PRAZO!$AM9,0) -> 0 | I11: =$C11*H11 -> 0 | J11: =IF(PRAZO!D9>0,1/PRAZO!$AM9,0) -> 0.2 | K11: =$C11*J11 -> 334221.54 | L11: =IF(PRAZO!E9>0,1/PRAZO!$AM9,0) -> 0.2 | M11: =$C11*L11 -> 334221.54 | N11: =IF(PRAZO!F9>0,1/PRAZO!$AM9,0) -> 0.2 | O11: =$C11*N11 -> 334221.54 | P11: =IF(PRAZO!G9>0,1/PRAZO!$AM9,0) -> 0.2 | Q11: =$C11*P11 -> 334221.54 | R11: =IF(PRAZO!H9>0,1/PRAZO!$AM9,0) -> 0.2 | S11: =$C11*R11 -> 334221.54 | T11: =IF(PRAZO!I9>0,1/PRAZO!$AM9,0) -> 0 | U11: =$C11*T11 -> 0 | V11: =IF(PRAZO!J9>0,1/PRAZO!$AM9,0) -> 0 | W11: =$C11*V11 -> 0 | X11: =IF(PRAZO!K9>0,1/PRAZO!$AM9,0) -> 0 | Y11: =$C11*X11 -> 0 | Z11: =IF(PRAZO!L9>0,1/PRAZO!$AM9,0) -> 0 | AA11: =$C11*Z11 -> 0 | AB11: =IF(PRAZO!M9>0,1/PRAZO!$AM9,0) -> 0 | AC11: =$C11*AB11 -> 0 | AD11: =IF(PRAZO!N9>0,1/PRAZO!$AM9,0) -> 0 | AE11: =$C11*AD11 -> 0 | AF11: =IF(PRAZO!O9>0,1/PRAZO!$AM9,0) -> 0 | AG11: =$C11*AF11 -> 0 | AH11: =IF(PRAZO!P9>0,1/PRAZO!$AM9,0) -> 0 | AI11: =$C11*AH11 -> 0 | AJ11: =IF(PRAZO!Q9>0,1/PRAZO!$AM9,0) -> 0 | AK11: =$C11*AJ11 -> 0 | AL11: =IF(PRAZO!R9>0,1/PRAZO!$AM9,0) -> 0 | AM11: =$C11*AL11 -> 0 | AN11: =IF(PRAZO!S9>0,1/PRAZO!$AM9,0) -> 0 | AO11: =$C11*AN11 -> 0 | AP11: =IF(PRAZO!T9>0,1/PRAZO!$AM9,0) -> 0 | AQ11: =$C11*AP11 -> 0 | AR11: =IF(PRAZO!U9>0,1/PRAZO!$AM9,0) -> 0 | AS11: =$C11*AR11 -> 0 | AT11: =IF(PRAZO!V9>0,1/PRAZO!$AM9,0) -> 0 | AU11: =$C11*AT11 -> 0 | AV11: =IF(PRAZO!W9>0,1/PRAZO!$AM9,0) -> 0 | AW11: =$C11*AV11 -> 0 | AX11: =IF(PRAZO!X9>0,1/PRAZO!$AM9,0) -> 0 | AY11: =$C11*AX11 -> 0 | AZ11: =IF(PRAZO!Y9>0,1/PRAZO!$AM9,0) -> 0 | BA11: =$C11*AZ11 -> 0 | BB11: =IF(PRAZO!Z9>0,1/PRAZO!$AM9,0) -> 0 | BC11: =$C11*BB11 -> 0 | BD11: =IF(PRAZO!AA9>0,1/PRAZO!$AM9,0) -> 0 | BE11: =$C11*BD11 -> 0 | BF11: =IF(PRAZO!AB9>0,1/PRAZO!$AM9,0) -> 0 | BG11: =$C11*BF11 -> 0 | BH11: =IF(PRAZO!AC9>0,1/PRAZO!$AM9,0) -> 0 | BI11: =$C11*BH11 -> 0 | BJ11: =IF(PRAZO!AD9>0,1/PRAZO!$AM9,0) -> 0 | BK11: =$C11*BJ11 -> 0 | BL11: =IF(PRAZO!AE9>0,1/PRAZO!$AM9,0) -> 0 | BM11: =$C11*BL11 -> 0 | BN11: =IF(PRAZO!AF9>0,1/PRAZO!$AM9,0) -> 0 | BO11: =$C11*BN11 -> 0 | BP11: =IF(PRAZO!AG9>0,1/PRAZO!$AM9,0) -> 0 | BQ11: =$C11*BP11 -> 0 | BR11: =IF(PRAZO!AH9>0,1/PRAZO!$AM9,0) -> 0 | BS11: =$C11*BR11 -> 0 | BT11: =IF(PRAZO!AI9>0,1/PRAZO!$AM9,0) -> 0 | BU11: =$C11*BT11 -> 0 | BV11: =IF(PRAZO!AJ9>0,1/PRAZO!$AM9,0) -> 0 | BW11: =$C11*BV11 -> 0 | BX11: =IF(PRAZO!AK9>0,1/PRAZO!$AM9,0) -> 0 | BY11: =$C11*BX11 -> 0 | BZ11: =IF(PRAZO!AL9>0,1/PRAZO!$AM9,0) -> 0 | CA11: =$C11*BZ11 -> 0
B12: SUPRAESTRUTURA | C12: 2901220.5 | D12: =C12/$C$26 -> 0.13986903 | E12: =C12/'DISTRIBUIÇÃO CUSTO'!C$30 -> 798.62267 | F12: =SUMIFS($H12:$CA12,$H$8:$CA$8,"%") -> 1 | H12: =IF(PRAZO!C10>0,1/PRAZO!$AM10,0) -> 0 | I12: =$C12*H12 -> 0 | J12: =IF(PRAZO!D10>0,1/PRAZO!$AM10,0) -> 0 | K12: =$C12*J12 -> 0 | L12: =IF(PRAZO!E10>0,1/PRAZO!$AM10,0) -> 0 | M12: =$C12*L12 -> 0 | N12: =IF(PRAZO!F10>0,1/PRAZO!$AM10,0) -> 0 | O12: =$C12*N12 -> 0 | P12: =IF(PRAZO!G10>0,1/PRAZO!$AM10,0) -> 0 | Q12: =$C12*P12 -> 0 | R12: =IF(PRAZO!H10>0,1/PRAZO!$AM10,0) -> 0 | S12: =$C12*R12 -> 0 | T12: =IF(PRAZO!I10>0,1/PRAZO!$AM10,0) -> 0.090909091 | U12: =$C12*T12 -> 263747.31 | V12: =IF(PRAZO!J10>0,1/PRAZO!$AM10,0) -> 0.090909091 | W12: =$C12*V12 -> 263747.31 | X12: =IF(PRAZO!K10>0,1/PRAZO!$AM10,0) -> 0.090909091 | Y12: =$C12*X12 -> 263747.31 | Z12: =IF(PRAZO!L10>0,1/PRAZO!$AM10,0) -> 0.090909091 | AA12: =$C12*Z12 -> 263747.31 | AB12: =IF(PRAZO!M10>0,1/PRAZO!$AM10,0) -> 0.090909091 | AC12: =$C12*AB12 -> 263747.31 | AD12: =IF(PRAZO!N10>0,1/PRAZO!$AM10,0) -> 0.090909091 | AE12: =$C12*AD12 -> 263747.31 | AF12: =IF(PRAZO!O10>0,1/PRAZO!$AM10,0) -> 0.090909091 | AG12: =$C12*AF12 -> 263747.31 | AH12: =IF(PRAZO!P10>0,1/PRAZO!$AM10,0) -> 0.090909091 | AI12: =$C12*AH12 -> 263747.31 | AJ12: =IF(PRAZO!Q10>0,1/PRAZO!$AM10,0) -> 0.090909091 | AK12: =$C12*AJ12 -> 263747.31 | AL12: =IF(PRAZO!R10>0,1/PRAZO!$AM10,0) -> 0.090909091 | AM12: =$C12*AL12 -> 263747.31 | AN12: =IF(PRAZO!S10>0,1/PRAZO!$AM10,0) -> 0.090909091 | AO12: =$C12*AN12 -> 263747.31 | AP12: =IF(PRAZO!T10>0,1/PRAZO!$AM10,0) -> 0 | AQ12: =$C12*AP12 -> 0 | AR12: =IF(PRAZO!U10>0,1/PRAZO!$AM10,0) -> 0 | AS12: =$C12*AR12 -> 0 | AT12: =IF(PRAZO!V10>0,1/PRAZO!$AM10,0) -> 0 | AU12: =$C12*AT12 -> 0 | AV12: =IF(PRAZO!W10>0,1/PRAZO!$AM10,0) -> 0 | AW12: =$C12*AV12 -> 0 | AX12: =IF(PRAZO!X10>0,1/PRAZO!$AM10,0) -> 0 | AY12: =$C12*AX12 -> 0 | AZ12: =IF(PRAZO!Y10>0,1/PRAZO!$AM10,0) -> 0 | BA12: =$C12*AZ12 -> 0 | BB12: =IF(PRAZO!Z10>0,1/PRAZO!$AM10,0) -> 0 | BC12: =$C12*BB12 -> 0 | BD12: =IF(PRAZO!AA10>0,1/PRAZO!$AM10,0) -> 0 | BE12: =$C12*BD12 -> 0 | BF12: =IF(PRAZO!AB10>0,1/PRAZO!$AM10,0) -> 0 | BG12: =$C12*BF12 -> 0 | BH12: =IF(PRAZO!AC10>0,1/PRAZO!$AM10,0) -> 0 | BI12: =$C12*BH12 -> 0 | BJ12: =IF(PRAZO!AD10>0,1/PRAZO!$AM10,0) -> 0 | BK12: =$C12*BJ12 -> 0 | BL12: =IF(PRAZO!AE10>0,1/PRAZO!$AM10,0) -> 0 | BM12: =$C12*BL12 -> 0 | BN12: =IF(PRAZO!AF10>0,1/PRAZO!$AM10,0) -> 0 | BO12: =$C12*BN12 -> 0 | BP12: =IF(PRAZO!AG10>0,1/PRAZO!$AM10,0) -> 0 | BQ12: =$C12*BP12 -> 0 | BR12: =IF(PRAZO!AH10>0,1/PRAZO!$AM10,0) -> 0 | BS12: =$C12*BR12 -> 0 | BT12: =IF(PRAZO!AI10>0,1/PRAZO!$AM10,0) -> 0 | BU12: =$C12*BT12 -> 0 | BV12: =IF(PRAZO!AJ10>0,1/PRAZO!$AM10,0) -> 0 | BW12: =$C12*BV12 -> 0 | BX12: =IF(PRAZO!AK10>0,1/PRAZO!$AM10,0) -> 0 | BY12: =$C12*BX12 -> 0 | BZ12: =IF(PRAZO!AL10>0,1/PRAZO!$AM10,0) -> 0 | CA12: =$C12*BZ12 -> 0
B13: ALVENARIA | C13: 529588.5 | D13: =C13/$C$26 -> 0.02553168 | E13: =C13/'DISTRIBUIÇÃO CUSTO'!C$30 -> 145.7805 | F13: =SUMIFS($H13:$CA13,$H$8:$CA$8,"%") -> 1 | H13: =IF(PRAZO!C11>0,1/PRAZO!$AM11,0) -> 0 | I13: =$C13*H13 -> 0 | J13: =IF(PRAZO!D11>0,1/PRAZO!$AM11,0) -> 0 | K13: =$C13*J13 -> 0 | L13: =IF(PRAZO!E11>0,1/PRAZO!$AM11,0) -> 0 | M13: =$C13*L13 -> 0 | N13: =IF(PRAZO!F11>0,1/PRAZO!$AM11,0) -> 0 | O13: =$C13*N13 -> 0 | P13: =IF(PRAZO!G11>0,1/PRAZO!$AM11,0) -> 0 | Q13: =$C13*P13 -> 0 | R13: =IF(PRAZO!H11>0,1/PRAZO!$AM11,0) -> 0 | S13: =$C13*R13 -> 0 | T13: =IF(PRAZO!I11>0,1/PRAZO!$AM11,0) -> 0 | U13: =$C13*T13 -> 0 | V13: =IF(PRAZO!J11>0,1/PRAZO!$AM11,0) -> 0 | W13: =$C13*V13 -> 0 | X13: =IF(PRAZO!K11>0,1/PRAZO!$AM11,0) -> 0 | Y13: =$C13*X13 -> 0 | Z13: =IF(PRAZO!L11>0,1/PRAZO!$AM11,0) -> 0.090909091 | AA13: =$C13*Z13 -> 48144.409 | AB13: =IF(PRAZO!M11>0,1/PRAZO!$AM11,0) -> 0.090909091 | AC13: =$C13*AB13 -> 48144.409 | AD13: =IF(PRAZO!N11>0,1/PRAZO!$AM11,0) -> 0.090909091 | AE13: =$C13*AD13 -> 48144.409 | AF13: =IF(PRAZO!O11>0,1/PRAZO!$AM11,0) -> 0.090909091 | AG13: =$C13*AF13 -> 48144.409 | AH13: =IF(PRAZO!P11>0,1/PRAZO!$AM11,0) -> 0.090909091 | AI13: =$C13*AH13 -> 48144.409 | AJ13: =IF(PRAZO!Q11>0,1/PRAZO!$AM11,0) -> 0.090909091 | AK13: =$C13*AJ13 -> 48144.409 | AL13: =IF(PRAZO!R11>0,1/PRAZO!$AM11,0) -> 0.090909091 | AM13: =$C13*AL13 -> 48144.409 | AN13: =IF(PRAZO!S11>0,1/PRAZO!$AM11,0) -> 0.090909091 | AO13: =$C13*AN13 -> 48144.409 | AP13: =IF(PRAZO!T11>0,1/PRAZO!$AM11,0) -> 0.090909091 | AQ13: =$C13*AP13 -> 48144.409 | AR13: =IF(PRAZO!U11>0,1/PRAZO!$AM11,0) -> 0.090909091 | AS13: =$C13*AR13 -> 48144.409 | AT13: =IF(PRAZO!V11>0,1/PRAZO!$AM11,0) -> 0.090909091 | AU13: =$C13*AT13 -> 48144.409 | AV13: =IF(PRAZO!W11>0,1/PRAZO!$AM11,0) -> 0 | AW13: =$C13*AV13 -> 0 | AX13: =IF(PRAZO!X11>0,1/PRAZO!$AM11,0) -> 0 | AY13: =$C13*AX13 -> 0 | AZ13: =IF(PRAZO!Y11>0,1/PRAZO!$AM11,0) -> 0 | BA13: =$C13*AZ13 -> 0 | BB13: =IF(PRAZO!Z11>0,1/PRAZO!$AM11,0) -> 0 | BC13: =$C13*BB13 -> 0 | BD13: =IF(PRAZO!AA11>0,1/PRAZO!$AM11,0) -> 0 | BE13: =$C13*BD13 -> 0 | BF13: =IF(PRAZO!AB11>0,1/PRAZO!$AM11,0) -> 0 | BG13: =$C13*BF13 -> 0 | BH13: =IF(PRAZO!AC11>0,1/PRAZO!$AM11,0) -> 0 | BI13: =$C13*BH13 -> 0 | BJ13: =IF(PRAZO!AD11>0,1/PRAZO!$AM11,0) -> 0 | BK13: =$C13*BJ13 -> 0 | BL13: =IF(PRAZO!AE11>0,1/PRAZO!$AM11,0) -> 0 | BM13: =$C13*BL13 -> 0 | BN13: =IF(PRAZO!AF11>0,1/PRAZO!$AM11,0) -> 0 | BO13: =$C13*BN13 -> 0 | BP13: =IF(PRAZO!AG11>0,1/PRAZO!$AM11,0) -> 0 | BQ13: =$C13*BP13 -> 0 | BR13: =IF(PRAZO!AH11>0,1/PRAZO!$AM11,0) -> 0 | BS13: =$C13*BR13 -> 0 | BT13: =IF(PRAZO!AI11>0,1/PRAZO!$AM11,0) -> 0 | BU13: =$C13*BT13 -> 0 | BV13: =IF(PRAZO!AJ11>0,1/PRAZO!$AM11,0) -> 0 | BW13: =$C13*BV13 -> 0 | BX13: =IF(PRAZO!AK11>0,1/PRAZO!$AM11,0) -> 0 | BY13: =$C13*BX13 -> 0 | BZ13: =IF(PRAZO!AL11>0,1/PRAZO!$AM11,0) -> 0 | CA13: =$C13*BZ13 -> 0
B14: INSTALAÇÕES ELÉTRICAS, HIDRÁULICAS, GLP E PREVENTIVAS | C14: 1372645.9 | D14: =C14/$C$26 -> 0.066175826 | E14: =C14/'DISTRIBUIÇÃO CUSTO'!C$30 -> 377.85 | F14: =SUMIFS($H14:$CA14,$H$8:$CA$8,"%") -> 1 | H14: =IF(PRAZO!C12>0,1/PRAZO!$AM12,0) -> 0 | I14: =$C14*H14 -> 0 | J14: =IF(PRAZO!D12>0,1/PRAZO!$AM12,0) -> 0 | K14: =$C14*J14 -> 0 | L14: =IF(PRAZO!E12>0,1/PRAZO!$AM12,0) -> 0 | M14: =$C14*L14 -> 0 | N14: =IF(PRAZO!F12>0,1/PRAZO!$AM12,0) -> 0 | O14: =$C14*N14 -> 0 | P14: =IF(PRAZO!G12>0,1/PRAZO!$AM12,0) -> 0 | Q14: =$C14*P14 -> 0 | R14: =IF(PRAZO!H12>0,1/PRAZO!$AM12,0) -> 0 | S14: =$C14*R14 -> 0 | T14: =IF(PRAZO!I12>0,1/PRAZO!$AM12,0) -> 0 | U14: =$C14*T14 -> 0 | V14: =IF(PRAZO!J12>0,1/PRAZO!$AM12,0) -> 0 | W14: =$C14*V14 -> 0 | X14: =IF(PRAZO!K12>0,1/PRAZO!$AM12,0) -> 0 | Y14: =$C14*X14 -> 0 | Z14: =IF(PRAZO!L12>0,1/PRAZO!$AM12,0) -> 0 | AA14: =$C14*Z14 -> 0 | AB14: =IF(PRAZO!M12>0,1/PRAZO!$AM12,0) -> 0.076923077 | AC14: =$C14*AB14 -> 105588.15 | AD14: =IF(PRAZO!N12>0,1/PRAZO!$AM12,0) -> 0.076923077 | AE14: =$C14*AD14 -> 105588.15 | AF14: =IF(PRAZO!O12>0,1/PRAZO!$AM12,0) -> 0.076923077 | AG14: =$C14*AF14 -> 105588.15 | AH14: =IF(PRAZO!P12>0,1/PRAZO!$AM12,0) -> 0.076923077 | AI14: =$C14*AH14 -> 105588.15 | AJ14: =IF(PRAZO!Q12>0,1/PRAZO!$AM12,0) -> 0.076923077 | AK14: =$C14*AJ14 -> 105588.15 | AL14: =IF(PRAZO!R12>0,1/PRAZO!$AM12,0) -> 0.076923077 | AM14: =$C14*AL14 -> 105588.15 | AN14: =IF(PRAZO!S12>0,1/PRAZO!$AM12,0) -> 0.076923077 | AO14: =$C14*AN14 -> 105588.15 | AP14: =IF(PRAZO!T12>0,1/PRAZO!$AM12,0) -> 0.076923077 | AQ14: =$C14*AP14 -> 105588.15 | AR14: =IF(PRAZO!U12>0,1/PRAZO!$AM12,0) -> 0.076923077 | AS14: =$C14*AR14 -> 105588.15 | AT14: =IF(PRAZO!V12>0,1/PRAZO!$AM12,0) -> 0.076923077 | AU14: =$C14*AT14 -> 105588.15 | AV14: =IF(PRAZO!W12>0,1/PRAZO!$AM12,0) -> 0.076923077 | AW14: =$C14*AV14 -> 105588.15 | AX14: =IF(PRAZO!X12>0,1/PRAZO!$AM12,0) -> 0.076923077 | AY14: =$C14*AX14 -> 105588.15 | AZ14: =IF(PRAZO!Y12>0,1/PRAZO!$AM12,0) -> 0.076923077 | BA14: =$C14*AZ14 -> 105588.15 | BB14: =IF(PRAZO!Z12>0,1/PRAZO!$AM12,0) -> 0 | BC14: =$C14*BB14 -> 0 | BD14: =IF(PRAZO!AA12>0,1/PRAZO!$AM12,0) -> 0 | BE14: =$C14*BD14 -> 0 | BF14: =IF(PRAZO!AB12>0,1/PRAZO!$AM12,0) -> 0 | BG14: =$C14*BF14 -> 0 | BH14: =IF(PRAZO!AC12>0,1/PRAZO!$AM12,0) -> 0 | BI14: =$C14*BH14 -> 0 | BJ14: =IF(PRAZO!AD12>0,1/PRAZO!$AM12,0) -> 0 | BK14: =$C14*BJ14 -> 0 | BL14: =IF(PRAZO!AE12>0,1/PRAZO!$AM12,0) -> 0 | BM14: =$C14*BL14 -> 0 | BN14: =IF(PRAZO!AF12>0,1/PRAZO!$AM12,0) -> 0 | BO14: =$C14*BN14 -> 0 | BP14: =IF(PRAZO!AG12>0,1/PRAZO!$AM12,0) -> 0 | BQ14: =$C14*BP14 -> 0 | BR14: =IF(PRAZO!AH12>0,1/PRAZO!$AM12,0) -> 0 | BS14: =$C14*BR14 -> 0 | BT14: =IF(PRAZO!AI12>0,1/PRAZO!$AM12,0) -> 0 | BU14: =$C14*BT14 -> 0 | BV14: =IF(PRAZO!AJ12>0,1/PRAZO!$AM12,0) -> 0 | BW14: =$C14*BV14 -> 0 | BX14: =IF(PRAZO!AK12>0,1/PRAZO!$AM12,0) -> 0 | BY14: =$C14*BX14 -> 0 | BZ14: =IF(PRAZO!AL12>0,1/PRAZO!$AM12,0) -> 0 | CA14: =$C14*BZ14 -> 0
B15: EQUIPAMENTOS E SISTEMAS ESPECIAIS | C15: 697857.62 | D15: =C15/$C$26 -> 0.033644003 | E15: =C15/'DISTRIBUIÇÃO CUSTO'!C$30 -> 192.10016 | F15: =SUMIFS($H15:$CA15,$H$8:$CA$8,"%") -> 1 | H15: =IF(PRAZO!C13>0,1/PRAZO!$AM13,0) -> 0 | I15: =$C15*H15 -> 0 | J15: =IF(PRAZO!D13>0,1/PRAZO!$AM13,0) -> 0 | K15: =$C15*J15 -> 0 | L15: =IF(PRAZO!E13>0,1/PRAZO!$AM13,0) -> 0 | M15: =$C15*L15 -> 0 | N15: =IF(PRAZO!F13>0,1/PRAZO!$AM13,0) -> 0 | O15: =$C15*N15 -> 0 | P15: =IF(PRAZO!G13>0,1/PRAZO!$AM13,0) -> 0 | Q15: =$C15*P15 -> 0 | R15: =IF(PRAZO!H13>0,1/PRAZO!$AM13,0) -> 0 | S15: =$C15*R15 -> 0 | T15: =IF(PRAZO!I13>0,1/PRAZO!$AM13,0) -> 0 | U15: =$C15*T15 -> 0 | V15: =IF(PRAZO!J13>0,1/PRAZO!$AM13,0) -> 0 | W15: =$C15*V15 -> 0 | X15: =IF(PRAZO!K13>0,1/PRAZO!$AM13,0) -> 0 | Y15: =$C15*X15 -> 0 | Z15: =IF(PRAZO!L13>0,1/PRAZO!$AM13,0) -> 0 | AA15: =$C15*Z15 -> 0 | AB15: =IF(PRAZO!M13>0,1/PRAZO!$AM13,0) -> 0 | AC15: =$C15*AB15 -> 0 | AD15: =IF(PRAZO!N13>0,1/PRAZO!$AM13,0) -> 0 | AE15: =$C15*AD15 -> 0 | AF15: =IF(PRAZO!O13>0,1/PRAZO!$AM13,0) -> 0 | AG15: =$C15*AF15 -> 0 | AH15: =IF(PRAZO!P13>0,1/PRAZO!$AM13,0) -> 0 | AI15: =$C15*AH15 -> 0 | AJ15: =IF(PRAZO!Q13>0,1/PRAZO!$AM13,0) -> 0 | AK15: =$C15*AJ15 -> 0 | AL15: =IF(PRAZO!R13>0,1/PRAZO!$AM13,0) -> 0 | AM15: =$C15*AL15 -> 0 | AN15: =IF(PRAZO!S13>0,1/PRAZO!$AM13,0) -> 0 | AO15: =$C15*AN15 -> 0 | AP15: =IF(PRAZO!T13>0,1/PRAZO!$AM13,0) -> 0 | AQ15: =$C15*AP15 -> 0 | AR15: =IF(PRAZO!U13>0,1/PRAZO!$AM13,0) -> 0 | AS15: =$C15*AR15 -> 0 | AT15: =IF(PRAZO!V13>0,1/PRAZO!$AM13,0) -> 0 | AU15: =$C15*AT15 -> 0 | AV15: =IF(PRAZO!W13>0,1/PRAZO!$AM13,0) -> 0 | AW15: =$C15*AV15 -> 0 | AX15: =IF(PRAZO!X13>0,1/PRAZO!$AM13,0) -> 0.11111111 | AY15: =$C15*AX15 -> 77539.735 | AZ15: =IF(PRAZO!Y13>0,1/PRAZO!$AM13,0) -> 0.11111111 | BA15: =$C15*AZ15 -> 77539.735 | BB15: =IF(PRAZO!Z13>0,1/PRAZO!$AM13,0) -> 0.11111111 | BC15: =$C15*BB15 -> 77539.735 | BD15: =IF(PRAZO!AA13>0,1/PRAZO!$AM13,0) -> 0.11111111 | BE15: =$C15*BD15 -> 77539.735 | BF15: =IF(PRAZO!AB13>0,1/PRAZO!$AM13,0) -> 0.11111111 | BG15: =$C15*BF15 -> 77539.735 | BH15: =IF(PRAZO!AC13>0,1/PRAZO!$AM13,0) -> 0.11111111 | BI15: =$C15*BH15 -> 77539.735 | BJ15: =IF(PRAZO!AD13>0,1/PRAZO!$AM13,0) -> 0.11111111 | BK15: =$C15*BJ15 -> 77539.735 | BL15: =IF(PRAZO!AE13>0,1/PRAZO!$AM13,0) -> 0.11111111 | BM15: =$C15*BL15 -> 77539.735 | BN15: =IF(PRAZO!AF13>0,1/PRAZO!$AM13,0) -> 0.11111111 | BO15: =$C15*BN15 -> 77539.735 | BP15: =IF(PRAZO!AG13>0,1/PRAZO!$AM13,0) -> 0 | BQ15: =$C15*BP15 -> 0 | BR15: =IF(PRAZO!AH13>0,1/PRAZO!$AM13,0) -> 0 | BS15: =$C15*BR15 -> 0 | BT15: =IF(PRAZO!AI13>0,1/PRAZO!$AM13,0) -> 0 | BU15: =$C15*BT15 -> 0 | BV15: =IF(PRAZO!AJ13>0,1/PRAZO!$AM13,0) -> 0 | BW15: =$C15*BV15 -> 0 | BX15: =IF(PRAZO!AK13>0,1/PRAZO!$AM13,0) -> 0 | BY15: =$C15*BX15 -> 0 | BZ15: =IF(PRAZO!AL13>0,1/PRAZO!$AM13,0) -> 0 | CA15: =$C15*BZ15 -> 0
B16: IMPERMEABILIZAÇÃO | C16: 292179.89 | D16: =C16/$C$26 -> 0.014086113 | E16: =C16/'DISTRIBUIÇÃO CUSTO'!C$30 -> 80.428733 | F16: =SUMIFS($H16:$CA16,$H$8:$CA$8,"%") -> 1 | H16: =IF(PRAZO!C14>0,1/PRAZO!$AM14,0) -> 0 | I16: =$C16*H16 -> 0 | J16: =IF(PRAZO!D14>0,1/PRAZO!$AM14,0) -> 0 | K16: =$C16*J16 -> 0 | L16: =IF(PRAZO!E14>0,1/PRAZO!$AM14,0) -> 0 | M16: =$C16*L16 -> 0 | N16: =IF(PRAZO!F14>0,1/PRAZO!$AM14,0) -> 0 | O16: =$C16*N16 -> 0 | P16: =IF(PRAZO!G14>0,1/PRAZO!$AM14,0) -> 0 | Q16: =$C16*P16 -> 0 | R16: =IF(PRAZO!H14>0,1/PRAZO!$AM14,0) -> 0 | S16: =$C16*R16 -> 0 | T16: =IF(PRAZO!I14>0,1/PRAZO!$AM14,0) -> 0 | U16: =$C16*T16 -> 0 | V16: =IF(PRAZO!J14>0,1/PRAZO!$AM14,0) -> 0 | W16: =$C16*V16 -> 0 | X16: =IF(PRAZO!K14>0,1/PRAZO!$AM14,0) -> 0 | Y16: =$C16*X16 -> 0 | Z16: =IF(PRAZO!L14>0,1/PRAZO!$AM14,0) -> 0 | AA16: =$C16*Z16 -> 0 | AB16: =IF(PRAZO!M14>0,1/PRAZO!$AM14,0) -> 0 | AC16: =$C16*AB16 -> 0 | AD16: =IF(PRAZO!N14>0,1/PRAZO!$AM14,0) -> 0 | AE16: =$C16*AD16 -> 0 | AF16: =IF(PRAZO!O14>0,1/PRAZO!$AM14,0) -> 0 | AG16: =$C16*AF16 -> 0 | AH16: =IF(PRAZO!P14>0,1/PRAZO!$AM14,0) -> 0.083333333 | AI16: =$C16*AH16 -> 24348.324 | AJ16: =IF(PRAZO!Q14>0,1/PRAZO!$AM14,0) -> 0.083333333 | AK16: =$C16*AJ16 -> 24348.324 | AL16: =IF(PRAZO!R14>0,1/PRAZO!$AM14,0) -> 0.083333333 | AM16: =$C16*AL16 -> 24348.324 | AN16: =IF(PRAZO!S14>0,1/PRAZO!$AM14,0) -> 0.083333333 | AO16: =$C16*AN16 -> 24348.324 | AP16: =IF(PRAZO!T14>0,1/PRAZO!$AM14,0) -> 0.083333333 | AQ16: =$C16*AP16 -> 24348.324 | AR16: =IF(PRAZO!U14>0,1/PRAZO!$AM14,0) -> 0.083333333 | AS16: =$C16*AR16 -> 24348.324 | AT16: =IF(PRAZO!V14>0,1/PRAZO!$AM14,0) -> 0.083333333 | AU16: =$C16*AT16 -> 24348.324 | AV16: =IF(PRAZO!W14>0,1/PRAZO!$AM14,0) -> 0.083333333 | AW16: =$C16*AV16 -> 24348.324 | AX16: =IF(PRAZO!X14>0,1/PRAZO!$AM14,0) -> 0.083333333 | AY16: =$C16*AX16 -> 24348.324 | AZ16: =IF(PRAZO!Y14>0,1/PRAZO!$AM14,0) -> 0.083333333 | BA16: =$C16*AZ16 -> 24348.324 | BB16: =IF(PRAZO!Z14>0,1/PRAZO!$AM14,0) -> 0.083333333 | BC16: =$C16*BB16 -> 24348.324 | BD16: =IF(PRAZO!AA14>0,1/PRAZO!$AM14,0) -> 0.083333333 | BE16: =$C16*BD16 -> 24348.324 | BF16: =IF(PRAZO!AB14>0,1/PRAZO!$AM14,0) -> 0 | BG16: =$C16*BF16 -> 0 | BH16: =IF(PRAZO!AC14>0,1/PRAZO!$AM14,0) -> 0 | BI16: =$C16*BH16 -> 0 | BJ16: =IF(PRAZO!AD14>0,1/PRAZO!$AM14,0) -> 0 | BK16: =$C16*BJ16 -> 0 | BL16: =IF(PRAZO!AE14>0,1/PRAZO!$AM14,0) -> 0 | BM16: =$C16*BL16 -> 0 | BN16: =IF(PRAZO!AF14>0,1/PRAZO!$AM14,0) -> 0 | BO16: =$C16*BN16 -> 0 | BP16: =IF(PRAZO!AG14>0,1/PRAZO!$AM14,0) -> 0 | BQ16: =$C16*BP16 -> 0 | BR16: =IF(PRAZO!AH14>0,1/PRAZO!$AM14,0) -> 0 | BS16: =$C16*BR16 -> 0 | BT16: =IF(PRAZO!AI14>0,1/PRAZO!$AM14,0) -> 0 | BU16: =$C16*BT16 -> 0 | BV16: =IF(PRAZO!AJ14>0,1/PRAZO!$AM14,0) -> 0 | BW16: =$C16*BV16 -> 0 | BX16: =IF(PRAZO!AK14>0,1/PRAZO!$AM14,0) -> 0 | BY16: =$C16*BX16 -> 0 | BZ16: =IF(PRAZO!AL14>0,1/PRAZO!$AM14,0) -> 0 | CA16: =$C16*BZ16 -> 0
B17: REVESTIMENTOS INTERNOS EM PISO E PAREDE | C17: 808212.99 | D17: =C17/$C$26 -> 0.038964282 | E17: =C17/'DISTRIBUIÇÃO CUSTO'!C$30 -> 222.47783 | F17: =SUMIFS($H17:$CA17,$H$8:$CA$8,"%") -> 1 | H17: =IF(PRAZO!C15>0,1/PRAZO!$AM15,0) -> 0 | I17: =$C17*H17 -> 0 | J17: =IF(PRAZO!D15>0,1/PRAZO!$AM15,0) -> 0 | K17: =$C17*J17 -> 0 | L17: =IF(PRAZO!E15>0,1/PRAZO!$AM15,0) -> 0 | M17: =$C17*L17 -> 0 | N17: =IF(PRAZO!F15>0,1/PRAZO!$AM15,0) -> 0 | O17: =$C17*N17 -> 0 | P17: =IF(PRAZO!G15>0,1/PRAZO!$AM15,0) -> 0 | Q17: =$C17*P17 -> 0 | R17: =IF(PRAZO!H15>0,1/PRAZO!$AM15,0) -> 0 | S17: =$C17*R17 -> 0 | T17: =IF(PRAZO!I15>0,1/PRAZO!$AM15,0) -> 0 | U17: =$C17*T17 -> 0 | V17: =IF(PRAZO!J15>0,1/PRAZO!$AM15,0) -> 0 | W17: =$C17*V17 -> 0 | X17: =IF(PRAZO!K15>0,1/PRAZO!$AM15,0) -> 0 | Y17: =$C17*X17 -> 0 | Z17: =IF(PRAZO!L15>0,1/PRAZO!$AM15,0) -> 0 | AA17: =$C17*Z17 -> 0 | AB17: =IF(PRAZO!M15>0,1/PRAZO!$AM15,0) -> 0 | AC17: =$C17*AB17 -> 0 | AD17: =IF(PRAZO!N15>0,1/PRAZO!$AM15,0) -> 0.090909091 | AE17: =$C17*AD17 -> 73473.909 | AF17: =IF(PRAZO!O15>0,1/PRAZO!$AM15,0) -> 0.090909091 | AG17: =$C17*AF17 -> 73473.909 | AH17: =IF(PRAZO!P15>0,1/PRAZO!$AM15,0) -> 0.090909091 | AI17: =$C17*AH17 -> 73473.909 | AJ17: =IF(PRAZO!Q15>0,1/PRAZO!$AM15,0) -> 0.090909091 | AK17: =$C17*AJ17 -> 73473.909 | AL17: =IF(PRAZO!R15>0,1/PRAZO!$AM15,0) -> 0.090909091 | AM17: =$C17*AL17 -> 73473.909 | AN17: =IF(PRAZO!S15>0,1/PRAZO!$AM15,0) -> 0.090909091 | AO17: =$C17*AN17 -> 73473.909 | AP17: =IF(PRAZO!T15>0,1/PRAZO!$AM15,0) -> 0.090909091 | AQ17: =$C17*AP17 -> 73473.909 | AR17: =IF(PRAZO!U15>0,1/PRAZO!$AM15,0) -> 0.090909091 | AS17: =$C17*AR17 -> 73473.909 | AT17: =IF(PRAZO!V15>0,1/PRAZO!$AM15,0) -> 0.090909091 | AU17: =$C17*AT17 -> 73473.909 | AV17: =IF(PRAZO!W15>0,1/PRAZO!$AM15,0) -> 0.090909091 | AW17: =$C17*AV17 -> 73473.909 | AX17: =IF(PRAZO!X15>0,1/PRAZO!$AM15,0) -> 0.090909091 | AY17: =$C17*AX17 -> 73473.909 | AZ17: =IF(PRAZO!Y15>0,1/PRAZO!$AM15,0) -> 0 | BA17: =$C17*AZ17 -> 0 | BB17: =IF(PRAZO!Z15>0,1/PRAZO!$AM15,0) -> 0 | BC17: =$C17*BB17 -> 0 | BD17: =IF(PRAZO!AA15>0,1/PRAZO!$AM15,0) -> 0 | BE17: =$C17*BD17 -> 0 | BF17: =IF(PRAZO!AB15>0,1/PRAZO!$AM15,0) -> 0 | BG17: =$C17*BF17 -> 0 | BH17: =IF(PRAZO!AC15>0,1/PRAZO!$AM15,0) -> 0 | BI17: =$C17*BH17 -> 0 | BJ17: =IF(PRAZO!AD15>0,1/PRAZO!$AM15,0) -> 0 | BK17: =$C17*BJ17 -> 0 | BL17: =IF(PRAZO!AE15>0,1/PRAZO!$AM15,0) -> 0 | BM17: =$C17*BL17 -> 0 | BN17: =IF(PRAZO!AF15>0,1/PRAZO!$AM15,0) -> 0 | BO17: =$C17*BN17 -> 0 | BP17: =IF(PRAZO!AG15>0,1/PRAZO!$AM15,0) -> 0 | BQ17: =$C17*BP17 -> 0 | BR17: =IF(PRAZO!AH15>0,1/PRAZO!$AM15,0) -> 0 | BS17: =$C17*BR17 -> 0 | BT17: =IF(PRAZO!AI15>0,1/PRAZO!$AM15,0) -> 0 | BU17: =$C17*BT17 -> 0 | BV17: =IF(PRAZO!AJ15>0,1/PRAZO!$AM15,0) -> 0 | BW17: =$C17*BV17 -> 0 | BX17: =IF(PRAZO!AK15>0,1/PRAZO!$AM15,0) -> 0 | BY17: =$C17*BX17 -> 0 | BZ17: =IF(PRAZO!AL15>0,1/PRAZO!$AM15,0) -> 0 | CA17: =$C17*BZ17 -> 0
B18: REVESTIMENTOS E ACABAMENTOS INTERNOS EM TETO | C18: 299766.44 | D18: =C18/$C$26 -> 0.014451864 | E18: =C18/'DISTRIBUIÇÃO CUSTO'!C$30 -> 82.517092 | F18: =SUMIFS($H18:$CA18,$H$8:$CA$8,"%") -> 1 | H18: =IF(PRAZO!C16>0,1/PRAZO!$AM16,0) -> 0 | I18: =$C18*H18 -> 0 | J18: =IF(PRAZO!D16>0,1/PRAZO!$AM16,0) -> 0 | K18: =$C18*J18 -> 0 | L18: =IF(PRAZO!E16>0,1/PRAZO!$AM16,0) -> 0 | M18: =$C18*L18 -> 0 | N18: =IF(PRAZO!F16>0,1/PRAZO!$AM16,0) -> 0 | O18: =$C18*N18 -> 0 | P18: =IF(PRAZO!G16>0,1/PRAZO!$AM16,0) -> 0 | Q18: =$C18*P18 -> 0 | R18: =IF(PRAZO!H16>0,1/PRAZO!$AM16,0) -> 0 | S18: =$C18*R18 -> 0 | T18: =IF(PRAZO!I16>0,1/PRAZO!$AM16,0) -> 0 | U18: =$C18*T18 -> 0 | V18: =IF(PRAZO!J16>0,1/PRAZO!$AM16,0) -> 0 | W18: =$C18*V18 -> 0 | X18: =IF(PRAZO!K16>0,1/PRAZO!$AM16,0) -> 0 | Y18: =$C18*X18 -> 0 | Z18: =IF(PRAZO!L16>0,1/PRAZO!$AM16,0) -> 0 | AA18: =$C18*Z18 -> 0 | AB18: =IF(PRAZO!M16>0,1/PRAZO!$AM16,0) -> 0 | AC18: =$C18*AB18 -> 0 | AD18: =IF(PRAZO!N16>0,1/PRAZO!$AM16,0) -> 0 | AE18: =$C18*AD18 -> 0 | AF18: =IF(PRAZO!O16>0,1/PRAZO!$AM16,0) -> 0 | AG18: =$C18*AF18 -> 0 | AH18: =IF(PRAZO!P16>0,1/PRAZO!$AM16,0) -> 0 | AI18: =$C18*AH18 -> 0 | AJ18: =IF(PRAZO!Q16>0,1/PRAZO!$AM16,0) -> 0.090909091 | AK18: =$C18*AJ18 -> 27251.495 | AL18: =IF(PRAZO!R16>0,1/PRAZO!$AM16,0) -> 0.090909091 | AM18: =$C18*AL18 -> 27251.495 | AN18: =IF(PRAZO!S16>0,1/PRAZO!$AM16,0) -> 0.090909091 | AO18: =$C18*AN18 -> 27251.495 | AP18: =IF(PRAZO!T16>0,1/PRAZO!$AM16,0) -> 0.090909091 | AQ18: =$C18*AP18 -> 27251.495 | AR18: =IF(PRAZO!U16>0,1/PRAZO!$AM16,0) -> 0.090909091 | AS18: =$C18*AR18 -> 27251.495 | AT18: =IF(PRAZO!V16>0,1/PRAZO!$AM16,0) -> 0.090909091 | AU18: =$C18*AT18 -> 27251.495 | AV18: =IF(PRAZO!W16>0,1/PRAZO!$AM16,0) -> 0.090909091 | AW18: =$C18*AV18 -> 27251.495 | AX18: =IF(PRAZO!X16>0,1/PRAZO!$AM16,0) -> 0.090909091 | AY18: =$C18*AX18 -> 27251.495 | AZ18: =IF(PRAZO!Y16>0,1/PRAZO!$AM16,0) -> 0.090909091 | BA18: =$C18*AZ18 -> 27251.495 | BB18: =IF(PRAZO!Z16>0,1/PRAZO!$AM16,0) -> 0.090909091 | BC18: =$C18*BB18 -> 27251.495 | BD18: =IF(PRAZO!AA16>0,1/PRAZO!$AM16,0) -> 0.090909091 | BE18: =$C18*BD18 -> 27251.495 | BF18: =IF(PRAZO!AB16>0,1/PRAZO!$AM16,0) -> 0 | BG18: =$C18*BF18 -> 0 | BH18: =IF(PRAZO!AC16>0,1/PRAZO!$AM16,0) -> 0 | BI18: =$C18*BH18 -> 0 | BJ18: =IF(PRAZO!AD16>0,1/PRAZO!$AM16,0) -> 0 | BK18: =$C18*BJ18 -> 0 | BL18: =IF(PRAZO!AE16>0,1/PRAZO!$AM16,0) -> 0 | BM18: =$C18*BL18 -> 0 | BN18: =IF(PRAZO!AF16>0,1/PRAZO!$AM16,0) -> 0 | BO18: =$C18*BN18 -> 0 | BP18: =IF(PRAZO!AG16>0,1/PRAZO!$AM16,0) -> 0 | BQ18: =$C18*BP18 -> 0 | BR18: =IF(PRAZO!AH16>0,1/PRAZO!$AM16,0) -> 0 | BS18: =$C18*BR18 -> 0 | BT18: =IF(PRAZO!AI16>0,1/PRAZO!$AM16,0) -> 0 | BU18: =$C18*BT18 -> 0 | BV18: =IF(PRAZO!AJ16>0,1/PRAZO!$AM16,0) -> 0 | BW18: =$C18*BV18 -> 0 | BX18: =IF(PRAZO!AK16>0,1/PRAZO!$AM16,0) -> 0 | BY18: =$C18*BX18 -> 0 | BZ18: =IF(PRAZO!AL16>0,1/PRAZO!$AM16,0) -> 0 | CA18: =$C18*BZ18 -> 0
B19: ACABAMENTOS EM PISO E PAREDE | C19: 918707.13 | D19: =C19/$C$26 -> 0.04429125 | E19: =C19/'DISTRIBUIÇÃO CUSTO'!C$30 -> 252.89369 | F19: =SUMIFS($H19:$CA19,$H$8:$CA$8,"%") -> 1 | H19: =IF(PRAZO!C17>0,1/PRAZO!$AM17,0) -> 0 | I19: =$C19*H19 -> 0 | J19: =IF(PRAZO!D17>0,1/PRAZO!$AM17,0) -> 0 | K19: =$C19*J19 -> 0 | L19: =IF(PRAZO!E17>0,1/PRAZO!$AM17,0) -> 0 | M19: =$C19*L19 -> 0 | N19: =IF(PRAZO!F17>0,1/PRAZO!$AM17,0) -> 0 | O19: =$C19*N19 -> 0 | P19: =IF(PRAZO!G17>0,1/PRAZO!$AM17,0) -> 0 | Q19: =$C19*P19 -> 0 | R19: =IF(PRAZO!H17>0,1/PRAZO!$AM17,0) -> 0 | S19: =$C19*R19 -> 0 | T19: =IF(PRAZO!I17>0,1/PRAZO!$AM17,0) -> 0 | U19: =$C19*T19 -> 0 | V19: =IF(PRAZO!J17>0,1/PRAZO!$AM17,0) -> 0 | W19: =$C19*V19 -> 0 | X19: =IF(PRAZO!K17>0,1/PRAZO!$AM17,0) -> 0 | Y19: =$C19*X19 -> 0 | Z19: =IF(PRAZO!L17>0,1/PRAZO!$AM17,0) -> 0 | AA19: =$C19*Z19 -> 0 | AB19: =IF(PRAZO!M17>0,1/PRAZO!$AM17,0) -> 0 | AC19: =$C19*AB19 -> 0 | AD19: =IF(PRAZO!N17>0,1/PRAZO!$AM17,0) -> 0 | AE19: =$C19*AD19 -> 0 | AF19: =IF(PRAZO!O17>0,1/PRAZO!$AM17,0) -> 0 | AG19: =$C19*AF19 -> 0 | AH19: =IF(PRAZO!P17>0,1/PRAZO!$AM17,0) -> 0.058823529 | AI19: =$C19*AH19 -> 54041.596 | AJ19: =IF(PRAZO!Q17>0,1/PRAZO!$AM17,0) -> 0.058823529 | AK19: =$C19*AJ19 -> 54041.596 | AL19: =IF(PRAZO!R17>0,1/PRAZO!$AM17,0) -> 0.058823529 | AM19: =$C19*AL19 -> 54041.596 | AN19: =IF(PRAZO!S17>0,1/PRAZO!$AM17,0) -> 0.058823529 | AO19: =$C19*AN19 -> 54041.596 | AP19: =IF(PRAZO!T17>0,1/PRAZO!$AM17,0) -> 0.058823529 | AQ19: =$C19*AP19 -> 54041.596 | AR19: =IF(PRAZO!U17>0,1/PRAZO!$AM17,0) -> 0.058823529 | AS19: =$C19*AR19 -> 54041.596 | AT19: =IF(PRAZO!V17>0,1/PRAZO!$AM17,0) -> 0.058823529 | AU19: =$C19*AT19 -> 54041.596 | AV19: =IF(PRAZO!W17>0,1/PRAZO!$AM17,0) -> 0.058823529 | AW19: =$C19*AV19 -> 54041.596 | AX19: =IF(PRAZO!X17>0,1/PRAZO!$AM17,0) -> 0.058823529 | AY19: =$C19*AX19 -> 54041.596 | AZ19: =IF(PRAZO!Y17>0,1/PRAZO!$AM17,0) -> 0.058823529 | BA19: =$C19*AZ19 -> 54041.596 | BB19: =IF(PRAZO!Z17>0,1/PRAZO!$AM17,0) -> 0.058823529 | BC19: =$C19*BB19 -> 54041.596 | BD19: =IF(PRAZO!AA17>0,1/PRAZO!$AM17,0) -> 0.058823529 | BE19: =$C19*BD19 -> 54041.596 | BF19: =IF(PRAZO!AB17>0,1/PRAZO!$AM17,0) -> 0.058823529 | BG19: =$C19*BF19 -> 54041.596 | BH19: =IF(PRAZO!AC17>0,1/PRAZO!$AM17,0) -> 0.058823529 | BI19: =$C19*BH19 -> 54041.596 | BJ19: =IF(PRAZO!AD17>0,1/PRAZO!$AM17,0) -> 0.058823529 | BK19: =$C19*BJ19 -> 54041.596 | BL19: =IF(PRAZO!AE17>0,1/PRAZO!$AM17,0) -> 0.058823529 | BM19: =$C19*BL19 -> 54041.596 | BN19: =IF(PRAZO!AF17>0,1/PRAZO!$AM17,0) -> 0.058823529 | BO19: =$C19*BN19 -> 54041.596 | BP19: =IF(PRAZO!AG17>0,1/PRAZO!$AM17,0) -> 0 | BQ19: =$C19*BP19 -> 0 | BR19: =IF(PRAZO!AH17>0,1/PRAZO!$AM17,0) -> 0 | BS19: =$C19*BR19 -> 0 | BT19: =IF(PRAZO!AI17>0,1/PRAZO!$AM17,0) -> 0 | BU19: =$C19*BT19 -> 0 | BV19: =IF(PRAZO!AJ17>0,1/PRAZO!$AM17,0) -> 0 | BW19: =$C19*BV19 -> 0 | BX19: =IF(PRAZO!AK17>0,1/PRAZO!$AM17,0) -> 0 | BY19: =$C19*BX19 -> 0 | BZ19: =IF(PRAZO!AL17>0,1/PRAZO!$AM17,0) -> 0 | CA19: =$C19*BZ19 -> 0
B20: PINTURA INTERNA | C20: 678657.63 | D20: =C20/$C$26 -> 0.032718364 | E20: =C20/'DISTRIBUIÇÃO CUSTO'!C$30 -> 186.81496 | F20: =SUMIFS($H20:$CA20,$H$8:$CA$8,"%") -> 1 | H20: =IF(PRAZO!C18>0,1/PRAZO!$AM18,0) -> 0 | I20: =$C20*H20 -> 0 | J20: =IF(PRAZO!D18>0,1/PRAZO!$AM18,0) -> 0 | K20: =$C20*J20 -> 0 | L20: =IF(PRAZO!E18>0,1/PRAZO!$AM18,0) -> 0 | M20: =$C20*L20 -> 0 | N20: =IF(PRAZO!F18>0,1/PRAZO!$AM18,0) -> 0 | O20: =$C20*N20 -> 0 | P20: =IF(PRAZO!G18>0,1/PRAZO!$AM18,0) -> 0 | Q20: =$C20*P20 -> 0 | R20: =IF(PRAZO!H18>0,1/PRAZO!$AM18,0) -> 0 | S20: =$C20*R20 -> 0 | T20: =IF(PRAZO!I18>0,1/PRAZO!$AM18,0) -> 0 | U20: =$C20*T20 -> 0 | V20: =IF(PRAZO!J18>0,1/PRAZO!$AM18,0) -> 0 | W20: =$C20*V20 -> 0 | X20: =IF(PRAZO!K18>0,1/PRAZO!$AM18,0) -> 0 | Y20: =$C20*X20 -> 0 | Z20: =IF(PRAZO!L18>0,1/PRAZO!$AM18,0) -> 0 | AA20: =$C20*Z20 -> 0 | AB20: =IF(PRAZO!M18>0,1/PRAZO!$AM18,0) -> 0 | AC20: =$C20*AB20 -> 0 | AD20: =IF(PRAZO!N18>0,1/PRAZO!$AM18,0) -> 0 | AE20: =$C20*AD20 -> 0 | AF20: =IF(PRAZO!O18>0,1/PRAZO!$AM18,0) -> 0 | AG20: =$C20*AF20 -> 0 | AH20: =IF(PRAZO!P18>0,1/PRAZO!$AM18,0) -> 0 | AI20: =$C20*AH20 -> 0 | AJ20: =IF(PRAZO!Q18>0,1/PRAZO!$AM18,0) -> 0 | AK20: =$C20*AJ20 -> 0 | AL20: =IF(PRAZO!R18>0,1/PRAZO!$AM18,0) -> 0.055555556 | AM20: =$C20*AL20 -> 37703.202 | AN20: =IF(PRAZO!S18>0,1/PRAZO!$AM18,0) -> 0.055555556 | AO20: =$C20*AN20 -> 37703.202 | AP20: =IF(PRAZO!T18>0,1/PRAZO!$AM18,0) -> 0.055555556 | AQ20: =$C20*AP20 -> 37703.202 | AR20: =IF(PRAZO!U18>0,1/PRAZO!$AM18,0) -> 0.055555556 | AS20: =$C20*AR20 -> 37703.202 | AT20: =IF(PRAZO!V18>0,1/PRAZO!$AM18,0) -> 0.055555556 | AU20: =$C20*AT20 -> 37703.202 | AV20: =IF(PRAZO!W18>0,1/PRAZO!$AM18,0) -> 0.055555556 | AW20: =$C20*AV20 -> 37703.202 | AX20: =IF(PRAZO!X18>0,1/PRAZO!$AM18,0) -> 0.055555556 | AY20: =$C20*AX20 -> 37703.202 | AZ20: =IF(PRAZO!Y18>0,1/PRAZO!$AM18,0) -> 0.055555556 | BA20: =$C20*AZ20 -> 37703.202 | BB20: =IF(PRAZO!Z18>0,1/PRAZO!$AM18,0) -> 0.055555556 | BC20: =$C20*BB20 -> 37703.202 | BD20: =IF(PRAZO!AA18>0,1/PRAZO!$AM18,0) -> 0.055555556 | BE20: =$C20*BD20 -> 37703.202 | BF20: =IF(PRAZO!AB18>0,1/PRAZO!$AM18,0) -> 0.055555556 | BG20: =$C20*BF20 -> 37703.202 | BH20: =IF(PRAZO!AC18>0,1/PRAZO!$AM18,0) -> 0.055555556 | BI20: =$C20*BH20 -> 37703.202 | BJ20: =IF(PRAZO!AD18>0,1/PRAZO!$AM18,0) -> 0.055555556 | BK20: =$C20*BJ20 -> 37703.202 | BL20: =IF(PRAZO!AE18>0,1/PRAZO!$AM18,0) -> 0.055555556 | BM20: =$C20*BL20 -> 37703.202 | BN20: =IF(PRAZO!AF18>0,1/PRAZO!$AM18,0) -> 0.055555556 | BO20: =$C20*BN20 -> 37703.202 | BP20: =IF(PRAZO!AG18>0,1/PRAZO!$AM18,0) -> 0.055555556 | BQ20: =$C20*BP20 -> 37703.202 | BR20: =IF(PRAZO!AH18>0,1/PRAZO!$AM18,0) -> 0.055555556 | BS20: =$C20*BR20 -> 37703.202 | BT20: =IF(PRAZO!AI18>0,1/PRAZO!$AM18,0) -> 0.055555556 | BU20: =$C20*BT20 -> 37703.202 | BV20: =IF(PRAZO!AJ18>0,1/PRAZO!$AM18,0) -> 0 | BW20: =$C20*BV20 -> 0 | BX20: =IF(PRAZO!AK18>0,1/PRAZO!$AM18,0) -> 0 | BY20: =$C20*BX20 -> 0 | BZ20: =IF(PRAZO!AL18>0,1/PRAZO!$AM18,0) -> 0 | CA20: =$C20*BZ20 -> 0
B21: ESQUADRIAS, VIDROS E FERRAGENS | C21: 1379827.4 | D21: =C21/$C$26 -> 0.066522046 | E21: =C21/'DISTRIBUIÇÃO CUSTO'!C$30 -> 379.82685 | F21: =SUMIFS($H21:$CA21,$H$8:$CA$8,"%") -> 1 | H21: =IF(PRAZO!C19>0,1/PRAZO!$AM19,0) -> 0 | I21: =$C21*H21 -> 0 | J21: =IF(PRAZO!D19>0,1/PRAZO!$AM19,0) -> 0 | K21: =$C21*J21 -> 0 | L21: =IF(PRAZO!E19>0,1/PRAZO!$AM19,0) -> 0 | M21: =$C21*L21 -> 0 | N21: =IF(PRAZO!F19>0,1/PRAZO!$AM19,0) -> 0 | O21: =$C21*N21 -> 0 | P21: =IF(PRAZO!G19>0,1/PRAZO!$AM19,0) -> 0 | Q21: =$C21*P21 -> 0 | R21: =IF(PRAZO!H19>0,1/PRAZO!$AM19,0) -> 0 | S21: =$C21*R21 -> 0 | T21: =IF(PRAZO!I19>0,1/PRAZO!$AM19,0) -> 0 | U21: =$C21*T21 -> 0 | V21: =IF(PRAZO!J19>0,1/PRAZO!$AM19,0) -> 0 | W21: =$C21*V21 -> 0 | X21: =IF(PRAZO!K19>0,1/PRAZO!$AM19,0) -> 0 | Y21: =$C21*X21 -> 0 | Z21: =IF(PRAZO!L19>0,1/PRAZO!$AM19,0) -> 0 | AA21: =$C21*Z21 -> 0 | AB21: =IF(PRAZO!M19>0,1/PRAZO!$AM19,0) -> 0 | AC21: =$C21*AB21 -> 0 | AD21: =IF(PRAZO!N19>0,1/PRAZO!$AM19,0) -> 0 | AE21: =$C21*AD21 -> 0 | AF21: =IF(PRAZO!O19>0,1/PRAZO!$AM19,0) -> 0 | AG21: =$C21*AF21 -> 0 | AH21: =IF(PRAZO!P19>0,1/PRAZO!$AM19,0) -> 0 | AI21: =$C21*AH21 -> 0 | AJ21: =IF(PRAZO!Q19>0,1/PRAZO!$AM19,0) -> 0 | AK21: =$C21*AJ21 -> 0 | AL21: =IF(PRAZO!R19>0,1/PRAZO!$AM19,0) -> 0 | AM21: =$C21*AL21 -> 0 | AN21: =IF(PRAZO!S19>0,1/PRAZO!$AM19,0) -> 0 | AO21: =$C21*AN21 -> 0 | AP21: =IF(PRAZO!T19>0,1/PRAZO!$AM19,0) -> 0 | AQ21: =$C21*AP21 -> 0 | AR21: =IF(PRAZO!U19>0,1/PRAZO!$AM19,0) -> 0 | AS21: =$C21*AR21 -> 0 | AT21: =IF(PRAZO!V19>0,1/PRAZO!$AM19,0) -> 0 | AU21: =$C21*AT21 -> 0 | AV21: =IF(PRAZO!W19>0,1/PRAZO!$AM19,0) -> 0 | AW21: =$C21*AV21 -> 0 | AX21: =IF(PRAZO!X19>0,1/PRAZO!$AM19,0) -> 0 | AY21: =$C21*AX21 -> 0 | AZ21: =IF(PRAZO!Y19>0,1/PRAZO!$AM19,0) -> 0 | BA21: =$C21*AZ21 -> 0 | BB21: =IF(PRAZO!Z19>0,1/PRAZO!$AM19,0) -> 0 | BC21: =$C21*BB21 -> 0 | BD21: =IF(PRAZO!AA19>0,1/PRAZO!$AM19,0) -> 0 | BE21: =$C21*BD21 -> 0 | BF21: =IF(PRAZO!AB19>0,1/PRAZO!$AM19,0) -> 0.14285714 | BG21: =$C21*BF21 -> 197118.2 | BH21: =IF(PRAZO!AC19>0,1/PRAZO!$AM19,0) -> 0.14285714 | BI21: =$C21*BH21 -> 197118.2 | BJ21: =IF(PRAZO!AD19>0,1/PRAZO!$AM19,0) -> 0.14285714 | BK21: =$C21*BJ21 -> 197118.2 | BL21: =IF(PRAZO!AE19>0,1/PRAZO!$AM19,0) -> 0.14285714 | BM21: =$C21*BL21 -> 197118.2 | BN21: =IF(PRAZO!AF19>0,1/PRAZO!$AM19,0) -> 0.14285714 | BO21: =$C21*BN21 -> 197118.2 | BP21: =IF(PRAZO!AG19>0,1/PRAZO!$AM19,0) -> 0.14285714 | BQ21: =$C21*BP21 -> 197118.2 | BR21: =IF(PRAZO!AH19>0,1/PRAZO!$AM19,0) -> 0.14285714 | BS21: =$C21*BR21 -> 197118.2 | BT21: =IF(PRAZO!AI19>0,1/PRAZO!$AM19,0) -> 0 | BU21: =$C21*BT21 -> 0 | BV21: =IF(PRAZO!AJ19>0,1/PRAZO!$AM19,0) -> 0 | BW21: =$C21*BV21 -> 0 | BX21: =IF(PRAZO!AK19>0,1/PRAZO!$AM19,0) -> 0 | BY21: =$C21*BX21 -> 0 | BZ21: =IF(PRAZO!AL19>0,1/PRAZO!$AM19,0) -> 0 | CA21: =$C21*BZ21 -> 0
... B23: SERVIÇOS COMPLEMENTARES | C23: 965572.17 | D23: =C23/$C$26 -> 0.046550632 | E23: =C23/'DISTRIBUIÇÃO CUSTO'!C$30 -> 265.79429 | F23: =SUMIFS($H23:$CA23,$H$8:$CA$8,"%") -> 1 | H23: =IF(PRAZO!C21>0,1/PRAZO!$AM21,0) -> 0 | I23: =$C23*H23 -> 0 | J23: =IF(PRAZO!D21>0,1/PRAZO!$AM21,0) -> 0 | K23: =$C23*J23 -> 0 | L23: =IF(PRAZO!E21>0,1/PRAZO!$AM21,0) -> 0 | M23: =$C23*L23 -> 0 | N23: =IF(PRAZO!F21>0,1/PRAZO!$AM21,0) -> 0 | O23: =$C23*N23 -> 0 | P23: =IF(PRAZO!G21>0,1/PRAZO!$AM21,0) -> 0 | Q23: =$C23*P23 -> 0 | R23: =IF(PRAZO!H21>0,1/PRAZO!$AM21,0) -> 0 | S23: =$C23*R23 -> 0 | T23: =IF(PRAZO!I21>0,1/PRAZO!$AM21,0) -> 0 | U23: =$C23*T23 -> 0 | V23: =IF(PRAZO!J21>0,1/PRAZO!$AM21,0) -> 0 | W23: =$C23*V23 -> 0 | X23: =IF(PRAZO!K21>0,1/PRAZO!$AM21,0) -> 0 | Y23: =$C23*X23 -> 0 | Z23: =IF(PRAZO!L21>0,1/PRAZO!$AM21,0) -> 0 | AA23: =$C23*Z23 -> 0 | AB23: =IF(PRAZO!M21>0,1/PRAZO!$AM21,0) -> 0 | AC23: =$C23*AB23 -> 0 | AD23: =IF(PRAZO!N21>0,1/PRAZO!$AM21,0) -> 0 | AE23: =$C23*AD23 -> 0 | AF23: =IF(PRAZO!O21>0,1/PRAZO!$AM21,0) -> 0 | AG23: =$C23*AF23 -> 0 | AH23: =IF(PRAZO!P21>0,1/PRAZO!$AM21,0) -> 0 | AI23: =$C23*AH23 -> 0 | AJ23: =IF(PRAZO!Q21>0,1/PRAZO!$AM21,0) -> 0 | AK23: =$C23*AJ23 -> 0 | AL23: =IF(PRAZO!R21>0,1/PRAZO!$AM21,0) -> 0 | AM23: =$C23*AL23 -> 0 | AN23: =IF(PRAZO!S21>0,1/PRAZO!$AM21,0) -> 0 | AO23: =$C23*AN23 -> 0 | AP23: =IF(PRAZO!T21>0,1/PRAZO!$AM21,0) -> 0 | AQ23: =$C23*AP23 -> 0 | AR23: =IF(PRAZO!U21>0,1/PRAZO!$AM21,0) -> 0 | AS23: =$C23*AR23 -> 0 | AT23: =IF(PRAZO!V21>0,1/PRAZO!$AM21,0) -> 0 | AU23: =$C23*AT23 -> 0 | AV23: =IF(PRAZO!W21>0,1/PRAZO!$AM21,0) -> 0 | AW23: =$C23*AV23 -> 0 | AX23: =IF(PRAZO!X21>0,1/PRAZO!$AM21,0) -> 0 | AY23: =$C23*AX23 -> 0 | AZ23: =IF(PRAZO!Y21>0,1/PRAZO!$AM21,0) -> 0 | BA23: =$C23*AZ23 -> 0 | BB23: =IF(PRAZO!Z21>0,1/PRAZO!$AM21,0) -> 0 | BC23: =$C23*BB23 -> 0 | BD23: =IF(PRAZO!AA21>0,1/PRAZO!$AM21,0) -> 0 | BE23: =$C23*BD23 -> 0 | BF23: =IF(PRAZO!AB21>0,1/PRAZO!$AM21,0) -> 0 | BG23: =$C23*BF23 -> 0 | BH23: =IF(PRAZO!AC21>0,1/PRAZO!$AM21,0) -> 0 | BI23: =$C23*BH23 -> 0 | BJ23: =IF(PRAZO!AD21>0,1/PRAZO!$AM21,0) -> 0 | BK23: =$C23*BJ23 -> 0 | BL23: =IF(PRAZO!AE21>0,1/PRAZO!$AM21,0) -> 0 | BM23: =$C23*BL23 -> 0 | BN23: =IF(PRAZO!AF21>0,1/PRAZO!$AM21,0) -> 0 | BO23: =$C23*BN23 -> 0 | BP23: =IF(PRAZO!AG21>0,1/PRAZO!$AM21,0) -> 0.16666667 | BQ23: =$C23*BP23 -> 160928.69 | BR23: =IF(PRAZO!AH21>0,1/PRAZO!$AM21,0) -> 0.16666667 | BS23: =$C23*BR23 -> 160928.69 | BT23: =IF(PRAZO!AI21>0,1/PRAZO!$AM21,0) -> 0.16666667 | BU23: =$C23*BT23 -> 160928.69 | BV23: =IF(PRAZO!AJ21>0,1/PRAZO!$AM21,0) -> 0.16666667 | BW23: =$C23*BV23 -> 160928.69 | BX23: =IF(PRAZO!AK21>0,1/PRAZO!$AM21,0) -> 0.16666667 | BY23: =$C23*BX23 -> 160928.69 | BZ23: =IF(PRAZO!AL21>0,1/PRAZO!$AM21,0) -> 0.16666667 | CA23: =$C23*BZ23 -> 160928.69
B24: IMPREVISTOS E CONTINGENCIAS | C24: 269860.85 | D24: =C24/$C$26 -> 0.013010103 | E24: =C24/'DISTRIBUIÇÃO CUSTO'!C$30 -> 74.284941 | F24: =SUMIFS($H24:$CA24,$H$8:$CA$8,"%") -> 1 | H24: =1/36 -> 0.027777778 | I24: =$C24*H24 -> 7496.1347 | J24: =1/36 -> 0.027777778 | K24: =$C24*J24 -> 7496.1347 | L24: =1/36 -> 0.027777778 | M24: =$C24*L24 -> 7496.1347 | N24: =1/36 -> 0.027777778 | O24: =$C24*N24 -> 7496.1347 | P24: =1/36 -> 0.027777778 | Q24: =$C24*P24 -> 7496.1347 | R24: =1/36 -> 0.027777778 | S24: =$C24*R24 -> 7496.1347 | T24: =1/36 -> 0.027777778 | U24: =$C24*T24 -> 7496.1347 | V24: =1/36 -> 0.027777778 | W24: =$C24*V24 -> 7496.1347 | X24: =1/36 -> 0.027777778 | Y24: =$C24*X24 -> 7496.1347 | Z24: =1/36 -> 0.027777778 | AA24: =$C24*Z24 -> 7496.1347 | AB24: =1/36 -> 0.027777778 | AC24: =$C24*AB24 -> 7496.1347 | AD24: =1/36 -> 0.027777778 | AE24: =$C24*AD24 -> 7496.1347 | AF24: =1/36 -> 0.027777778 | AG24: =$C24*AF24 -> 7496.1347 | AH24: =1/36 -> 0.027777778 | AI24: =$C24*AH24 -> 7496.1347 | AJ24: =1/36 -> 0.027777778 | AK24: =$C24*AJ24 -> 7496.1347 | AL24: =1/36 -> 0.027777778 | AM24: =$C24*AL24 -> 7496.1347 | AN24: =1/36 -> 0.027777778 | AO24: =$C24*AN24 -> 7496.1347 | AP24: =1/36 -> 0.027777778 | AQ24: =$C24*AP24 -> 7496.1347 | AR24: =1/36 -> 0.027777778 | AS24: =$C24*AR24 -> 7496.1347 | AT24: =1/36 -> 0.027777778 | AU24: =$C24*AT24 -> 7496.1347 | AV24: =1/36 -> 0.027777778 | AW24: =$C24*AV24 -> 7496.1347 | AX24: =1/36 -> 0.027777778 | AY24: =$C24*AX24 -> 7496.1347 | AZ24: =1/36 -> 0.027777778 | BA24: =$C24*AZ24 -> 7496.1347 | BB24: =1/36 -> 0.027777778 | BC24: =$C24*BB24 -> 7496.1347 | BD24: =1/36 -> 0.027777778 | BE24: =$C24*BD24 -> 7496.1347 | BF24: =1/36 -> 0.027777778 | BG24: =$C24*BF24 -> 7496.1347 | BH24: =1/36 -> 0.027777778 | BI24: =$C24*BH24 -> 7496.1347 | BJ24: =1/36 -> 0.027777778 | BK24: =$C24*BJ24 -> 7496.1347 | BL24: =1/36 -> 0.027777778 | BM24: =$C24*BL24 -> 7496.1347 | BN24: =1/36 -> 0.027777778 | BO24: =$C24*BN24 -> 7496.1347 | BP24: =1/36 -> 0.027777778 | BQ24: =$C24*BP24 -> 7496.1347 | BR24: =1/36 -> 0.027777778 | BS24: =$C24*BR24 -> 7496.1347 | BT24: =1/36 -> 0.027777778 | BU24: =$C24*BT24 -> 7496.1347 | BV24: =1/36 -> 0.027777778 | BW24: =$C24*BV24 -> 7496.1347 | BX24: =1/36 -> 0.027777778 | BY24: =$C24*BX24 -> 7496.1347 | BZ24: =1/36 -> 0.027777778 | CA24: =$C24*BZ24 -> 7496.1347
B25: ENXOVAL | C25: 4428459.8 | D25: =C25/$C$26 -> 0.21349787 | E25: =C25/'DISTRIBUIÇÃO CUSTO'!C$30 -> 1219.0278 | F25: =SUMIFS($H25:$CA25,$H$8:$CA$8,"%") -> 1 | H25: =1/36 -> 0.027777778 | I25: =$C25*H25 -> 123012.77 | J25: =1/36 -> 0.027777778 | K25: =$C25*J25 -> 123012.77 | L25: =1/36 -> 0.027777778 | M25: =$C25*L25 -> 123012.77 | N25: =1/36 -> 0.027777778 | O25: =$C25*N25 -> 123012.77 | P25: =1/36 -> 0.027777778 | Q25: =$C25*P25 -> 123012.77 | R25: =1/36 -> 0.027777778 | S25: =$C25*R25 -> 123012.77 | T25: =1/36 -> 0.027777778 | U25: =$C25*T25 -> 123012.77 | V25: =1/36 -> 0.027777778 | W25: =$C25*V25 -> 123012.77 | X25: =1/36 -> 0.027777778 | Y25: =$C25*X25 -> 123012.77 | Z25: =1/36 -> 0.027777778 | AA25: =$C25*Z25 -> 123012.77 | AB25: =1/36 -> 0.027777778 | AC25: =$C25*AB25 -> 123012.77 | AD25: =1/36 -> 0.027777778 | AE25: =$C25*AD25 -> 123012.77 | AF25: =1/36 -> 0.027777778 | AG25: =$C25*AF25 -> 123012.77 | AH25: =1/36 -> 0.027777778 | AI25: =$C25*AH25 -> 123012.77 | AJ25: =1/36 -> 0.027777778 | AK25: =$C25*AJ25 -> 123012.77 | AL25: =1/36 -> 0.027777778 | AM25: =$C25*AL25 -> 123012.77 | AN25: =1/36 -> 0.027777778 | AO25: =$C25*AN25 -> 123012.77 | AP25: =1/36 -> 0.027777778 | AQ25: =$C25*AP25 -> 123012.77 | AR25: =1/36 -> 0.027777778 | AS25: =$C25*AR25 -> 123012.77 | AT25: =1/36 -> 0.027777778 | AU25: =$C25*AT25 -> 123012.77 | AV25: =1/36 -> 0.027777778 | AW25: =$C25*AV25 -> 123012.77 | AX25: =1/36 -> 0.027777778 | AY25: =$C25*AX25 -> 123012.77 | AZ25: =1/36 -> 0.027777778 | BA25: =$C25*AZ25 -> 123012.77 | BB25: =1/36 -> 0.027777778 | BC25: =$C25*BB25 -> 123012.77 | BD25: =1/36 -> 0.027777778 | BE25: =$C25*BD25 -> 123012.77 | BF25: =1/36 -> 0.027777778 | BG25: =$C25*BF25 -> 123012.77 | BH25: =1/36 -> 0.027777778 | BI25: =$C25*BH25 -> 123012.77 | BJ25: =1/36 -> 0.027777778 | BK25: =$C25*BJ25 -> 123012.77 | BL25: =1/36 -> 0.027777778 | BM25: =$C25*BL25 -> 123012.77 | BN25: =1/36 -> 0.027777778 | BO25: =$C25*BN25 -> 123012.77 | BP25: =1/36 -> 0.027777778 | BQ25: =$C25*BP25 -> 123012.77 | BR25: =1/36 -> 0.027777778 | BS25: =$C25*BR25 -> 123012.77 | BT25: =1/36 -> 0.027777778 | BU25: =$C25*BT25 -> 123012.77 | BV25: =1/36 -> 0.027777778 | BW25: =$C25*BV25 -> 123012.77 | BX25: =1/36 -> 0.027777778 | BY25: =$C25*BX25 -> 123012.77 | BZ25: =1/36 -> 0.027777778 | CA25: =$C25*BZ25 -> 123012.77
B26: TOTAL | C26: =SUM(C9:C25) -> 20742407 | D26: =SUM(D9:D24) -> 0.78650213 | E26: =SUM(E9:E25) -> 5709.789 | F26: {=soma} -> #NAME? | I26: =SUM(I9:I25) -> 519234.22 | K26: =SUM(K9:K25) -> 853455.76 | M26: =SUM(M9:M25) -> 853455.76 | O26: =SUM(O9:O25) -> 778455.07 | Q26: =SUM(Q9:Q25) -> 700957.13 | S26: =SUM(S9:S25) -> 700957.13 | U26: =SUM(U9:U25) -> 424545.62 | W26: =SUM(W9:W25) -> 424545.62 | Y26: =SUM(Y9:Y25) -> 424545.62 | AA26: =SUM(AA9:AA25) -> 472690.03 | AC26: =SUM(AC9:AC25) -> 578278.17 | AE26: =SUM(AE9:AE25) -> 651752.08 | AG26: =SUM(AG9:AG25) -> 651752.08 | AI26: =SUM(AI9:AI25) -> 730142 | AK26: =SUM(AK9:AK25) -> 757393.5 | AM26: =SUM(AM9:AM25) -> 795096.7 | AO26: =SUM(AO9:AO25) -> 795096.7 | AQ26: =SUM(AQ9:AQ25) -> 531349.38 | AS26: =SUM(AS9:AS25) -> 531349.38 | AU26: =SUM(AU9:AU25) -> 531349.38 | AW26: =SUM(AW9:AW25) -> 549975.66 | AY26: =SUM(AY9:AY25) -> 627515.4 | BA26: =SUM(BA9:BA25) -> 554041.49 | BC26: =SUM(BC9:BC25) -> 448453.34 | BE26: =SUM(BE9:BE25) -> 448453.34 | BG26: =SUM(BG9:BG25) -> 593971.72 | BI26: =SUM(BI9:BI25) -> 593971.72 | BK26: =SUM(BK9:BK25) -> 593971.72 | BM26: =SUM(BM9:BM25) -> 593971.72 | BO26: =SUM(BO9:BO25) -> 593971.72 | BQ26: =SUM(BQ9:BQ25) -> 556548.39 | BS26: =SUM(BS9:BS25) -> 556548.39 | BU26: =SUM(BU9:BU25) -> 359430.2 | BW26: =SUM(BW9:BW25) -> 321727 | BY26: =SUM(BY9:BY25) -> 321727 | CA26: =SUM(CA9:CA25) -> 321727 | CB26: SOMA TOTAL
B27: CUB/SC | C27: 3012.64 | D27: 46023 | E27: =+E26/C27 -> 1.8952776 | I27: =I26/$C$26 -> 0.025032496 | K27: =K26/$C$26 -> 0.041145454 | M27: =M26/$C$26 -> 0.041145454 | O27: =O26/$C$26 -> 0.03752964 | Q27: =Q26/$C$26 -> 0.033793432 | S27: =S26/$C$26 -> 0.033793432 | U27: =U26/$C$26 -> 0.020467519 | W27: =W26/$C$26 -> 0.020467519 | Y27: =Y26/$C$26 -> 0.020467519 | AA27: =AA26/$C$26 -> 0.022788581 | AC27: =AC26/$C$26 -> 0.027879029 | AE27: =AE26/$C$26 -> 0.031421237 | AG27: =AG26/$C$26 -> 0.031421237 | AI27: =AI26/$C$26 -> 0.035200447 | AK27: =AK26/$C$26 -> 0.036514253 | AM27: =AM26/$C$26 -> 0.03833194 | AO27: =AO26/$C$26 -> 0.03833194 | AQ27: =AQ26/$C$26 -> 0.025616573 | AS27: =AS26/$C$26 -> 0.025616573 | AU27: =AU26/$C$26 -> 0.025616573 | AW27: =AW26/$C$26 -> 0.026514553 | AY27: =AY26/$C$26 -> 0.030252776 | BA27: =BA26/$C$26 -> 0.026710569 | BC27: =BC26/$C$26 -> 0.021620121 | BE27: =BE26/$C$26 -> 0.021620121 | BG27: =BG26/$C$26 -> 0.028635621 | BI27: =BI26/$C$26 -> 0.028635621 | BK27: =BK26/$C$26 -> 0.028635621 | BM27: =BM26/$C$26 -> 0.028635621 | BO27: =BO26/$C$26 -> 0.028635621 | BQ27: =BQ26/$C$26 -> 0.026831428 | BS27: =BS26/$C$26 -> 0.026831428 | BU27: =BU26/$C$26 -> 0.017328278 | BW27: =BW26/$C$26 -> 0.015510591 | BY27: =BY26/$C$26 -> 0.015510591 | CA27: =CA26/$C$26 -> 0.015510591 | CB27: =SUM(I26:CA26) -> 20742407
C29: ÁREA CONSTRUÍDA | E29: Prazo de obra | CB29: =$C$26 -> 20742407
C30: 3632.78 | D30: m² | E30: 36
C31: Mês | D31: %
C32: M1 | D32: =I27 -> 0.025032496
C33: M2 | D33: =K27 -> 0.041145454
C34: M3 | D34: =M27 -> 0.041145454
C35: M4 | D35: =O27 -> 0.03752964
C36: M5 | D36: =Q27 -> 0.033793432
C37: M6 | D37: =S27 -> 0.033793432
C38: M7 | D38: =U27 -> 0.020467519
C39: M8 | D39: =W27 -> 0.020467519
C40: M9 | D40: =Y27 -> 0.020467519
C41: M10 | D41: =AA27 -> 0.022788581
C42: M11 | D42: =AC27 -> 0.027879029
C43: M12 | D43: =AE27 -> 0.031421237
C44: M13 | D44: =AG27 -> 0.031421237
C45: M14 | D45: =AI27 -> 0.035200447
C46: M15 | D46: =AK27 -> 0.036514253
...

Sheet Planilha1
B2: A | C2: 10 | D2: ="a"&B2 -> aA | E2: 23 | F2: ="=b"&B2&27 -> =bA27 | G2: 36 | H2: ="=c"&B2&"27" -> =cA27 | I2: 49 | J2: ="=d"&B2&"27" -> =dA27 | K2: 62 | L2: ="=e"&B2&"27" -> =eA27 | M2: 75 | N2: ="=f"&B2&"27" -> =fA27 | O2: 88 | P2: ="=g"&B2&"27" -> =gA27
B3: B | D3: ="a"&B3 -> aB | F3: ="=b"&B3&27 -> =bB27 | H3: ="=c"&B3&"27" -> =cB27 | J3: ="=d"&B3&"27" -> =dB27 | L3: ="=e"&B3&"27" -> =eB27 | N3: ="=f"&B3&"27" -> =fB27 | P3: ="=g"&B3&"27" -> =gB27
B4: c | C4: =C2+1 -> 11 | D4: ="a"&B4 -> ac | E4: =E2+1 -> 24 | F4: ="=b"&B4&27 -> =bc27 | G4: =G2+1 -> 37 | H4: ="=c"&B4&"27" -> =cc27 | I4: =I2+1 -> 50 | J4: ="=d"&B4&"27" -> =dc27 | K4: =K2+1 -> 63 | L4: ="=e"&B4&"27" -> =ec27 | M4: =M2+1 -> 76 | N4: ="=f"&B4&"27" -> =fc27 | O4: =O2+1 -> 89 | P4: ="=g"&B4&"27" -> =gc27
B5: d | D5: ="a"&B5 -> ad | F5: ="=b"&B5&27 -> =bd27 | H5: ="=c"&B5&"27" -> =cd27 | J5: ="=d"&B5&"27" -> =dd27 | L5: ="=e"&B5&"27" -> =ed27 | N5: ="=f"&B5&"27" -> =fd27 | P5: ="=g"&B5&"27" -> =gd27
B6: e | C6: =C4+1 -> 12 | D6: ="a"&B6 -> ae | E6: =E4+1 -> 25 | F6: ="=b"&B6&27 -> =be27 | G6: =G4+1 -> 38 | H6: ="=c"&B6&"27" -> =ce27 | I6: =I4+1 -> 51 | J6: ="=d"&B6&"27" -> =de27 | K6: =K4+1 -> 64 | L6: ="=e"&B6&"27" -> =ee27 | M6: =M4+1 -> 77 | N6: ="=f"&B6&"27" -> =fe27 | O6: =O4+1 -> 90 | P6: ="=g"&B6&"27" -> =ge27
B7: f | D7: ="a"&B7 -> af | F7: ="=b"&B7&27 -> =bf27 | H7: ="=c"&B7&"27" -> =cf27 | J7: ="=d"&B7&"27" -> =df27 | L7: ="=e"&B7&"27" -> =ef27 | N7: ="=f"&B7&"27" -> =ff27 | P7: ="=g"&B7&"27" -> =gf27
B8: g | C8: =C6+1 -> 13 | D8: ="a"&B8 -> ag | E8: =E6+1 -> 26 | F8: ="=b"&B8&27 -> =bg27 | G8: =G6+1 -> 39 | H8: ="=c"&B8&"27" -> =cg27 | I8: =I6+1 -> 52 | J8: ="=d"&B8&"27" -> =dg27 | K8: =K6+1 -> 65 | L8: ="=e"&B8&"27" -> =eg27 | M8: =M6+1 -> 78 | N8: ="=f"&B8&"27" -> =fg27 | O8: =O6+1 -> 91 | P8: ="=g"&B8&"27" -> =gg27
B9: h | D9: ="a"&B9 -> ah | F9: ="=b"&B9&27 -> =bh27 | H9: ="=c"&B9&"27" -> =ch27 | J9: ="=d"&B9&"27" -> =dh27 | L9: ="=e"&B9&"27" -> =eh27 | N9: ="=f"&B9&"27" -> =fh27 | P9: ="=g"&B9&"27" -> =gh27
A10: 1 | B10: i | C10: =C8+1 -> 14 | D10: ="a"&B10 -> ai | E10: =E8+1 -> 27 | F10: ="=b"&B10&27 -> =bi27 | G10: =G8+1 -> 40 | H10: ="=c"&B10&"27" -> =ci27 | I10: =I8+1 -> 53 | J10: ="=d"&B10&"27" -> =di27 | K10: =K8+1 -> 66 | L10: ="=e"&B10&"27" -> =ei27 | M10: =M8+1 -> 79 | N10: ="=f"&B10&"27" -> =fi27 | O10: =O8+1 -> 92 | P10: ="=g"&B10&"27" -> =gi27
B11: j | D11: ="a"&B11 -> aj | F11: ="=b"&B11&27 -> =bj27 | H11: ="=c"&B11&"27" -> =cj27 | J11: ="=d"&B11&"27" -> =dj27 | L11: ="=e"&B11&"27" -> =ej27 | N11: ="=f"&B11&"27" -> =fj27 | P11: ="=g"&B11&"27" -> =gj27
A12: =A10+1 -> 2 | B12: k | C12: =C10+1 -> 15 | D12: ="a"&B12 -> ak | E12: =E10+1 -> 28 | F12: ="=b"&B12&27 -> =bk27 | G12: =G10+1 -> 41 | H12: ="=c"&B12&"27" -> =ck27 | I12: =I10+1 -> 54 | J12: ="=d"&B12&"27" -> =dk27 | K12: =K10+1 -> 67 | L12: ="=e"&B12&"27" -> =ek27 | M12: =M10+1 -> 80 | N12: ="=f"&B12&"27" -> =fk27 | O12: =O10+1 -> 93 | P12: ="=g"&B12&"27" -> =gk27
B13: l | D13: ="a"&B13 -> al | F13: ="=b"&B13&27 -> =bl27 | H13: ="=c"&B13&"27" -> =cl27 | J13: ="=d"&B13&"27" -> =dl27 | L13: ="=e"&B13&"27" -> =el27 | N13: ="=f"&B13&"27" -> =fl27 | P13: ="=g"&B13&"27" -> =gl27
A14: =A12+1 -> 3 | B14: m | C14: =C12+1 -> 16 | D14: ="a"&B14 -> am | E14: =E12+1 -> 29 | F14: ="=b"&B14&27 -> =bm27 | G14: =G12+1 -> 42 | H14: ="=c"&B14&"27" -> =cm27 | I14: =I12+1 -> 55 | J14: ="=d"&B14&"27" -> =dm27 | K14: =K12+1 -> 68 | L14: ="=e"&B14&"27" -> =em27 | M14: =M12+1 -> 81 | N14: ="=f"&B14&"27" -> =fm27 | O14: =O12+1 -> 94 | P14: ="=g"&B14&"27" -> =gm27
B15: n | D15: ="a"&B15 -> an | F15: ="=b"&B15&27 -> =bn27 | H15: ="=c"&B15&"27" -> =cn27 | J15: ="=d"&B15&"27" -> =dn27 | L15: ="=e"&B15&"27" -> =en27 | N15: ="=f"&B15&"27" -> =fn27 | P15: ="=g"&B15&"27" -> =gn27
A16: =A14+1 -> 4 | B16: o | C16: =C14+1 -> 17 | D16: ="a"&B16 -> ao | E16: =E14+1 -> 30 | F16: ="=b"&B16&27 -> =bo27 | G16: =G14+1 -> 43 | H16: ="=c"&B16&"27" -> =co27 | I16: =I14+1 -> 56 | J16: ="=d"&B16&"27" -> =do27 | K16: =K14+1 -> 69 | L16: ="=e"&B16&"27" -> =eo27 | M16: =M14+1 -> 82 | N16: ="=f"&B16&"27" -> =fo27 | O16: =O14+1 -> 95 | P16: ="=g"&B16&"27" -> =go27
B17: p | D17: ="a"&B17 -> ap | F17: ="=b"&B17&27 -> =bp27 | H17: ="=c"&B17&"27" -> =cp27 | J17: ="=d"&B17&"27" -> =dp27 | L17: ="=e"&B17&"27" -> =ep27 | N17: ="=f"&B17&"27" -> =fp27 | P17: ="=g"&B17&"27" -> =gp27
A18: =A16+1 -> 5 | B18: q | C18: =C16+1 -> 18 | D18: ="a"&B18 -> aq | E18: =E16+1 -> 31 | F18: ="=b"&B18&27 -> =bq27 | G18: =G16+1 -> 44 | H18: ="=c"&B18&"27" -> =cq27 | I18: =I16+1 -> 57 | J18: ="=d"&B18&"27" -> =dq27 | K18: =K16+1 -> 70 | L18: ="=e"&B18&"27" -> =eq27 | M18: =M16+1 -> 83 | N18: ="=f"&B18&"27" -> =fq27 | O18: =O16+1 -> 96 | P18: ="=g"&B18&"27" -> =gq27
B19: r | D19: ="a"&B19 -> ar | F19: ="=b"&B19&27 -> =br27 | H19: ="=c"&B19&"27" -> =cr27 | J19: ="=d"&B19&"27" -> =dr27 | L19: ="=e"&B19&"27" -> =er27 | N19: ="=f"&B19&"27" -> =fr27 | P19: ="=g"&B19&"27" -> =gr27
A20: =A18+1 -> 6 | B20: s | C20: =C18+1 -> 19 | D20: ="a"&B20 -> as | E20: =E18+1 -> 32 | F20: ="=b"&B20&27 -> =bs27 | G20: =G18+1 -> 45 | H20: ="=c"&B20&"27" -> =cs27 | I20: =I18+1 -> 58 | J20: ="=d"&B20&"27" -> =ds27 | K20: =K18+1 -> 71 | L20: ="=e"&B20&"27" -> =es27 | M20: =M18+1 -> 84 | N20: ="=f"&B20&"27" -> =fs27 | O20: =O18+1 -> 97 | P20: ="=g"&B20&"27" -> =gs27
B21: t | D21: ="a"&B21 -> at | F21: ="=b"&B21&27 -> =bt27 | H21: ="=c"&B21&"27" -> =ct27 | J21: ="=d"&B21&"27" -> =dt27 | L21: ="=e"&B21&"27" -> =et27 | N21: ="=f"&B21&"27" -> =ft27 | P21: ="=g"&B21&"27" -> =gt27
A22: =A20+1 -> 7 | B22: u | C22: =C20+1 -> 20 | D22: ="a"&B22 -> au | E22: =E20+1 -> 33 | F22: ="=b"&B22&27 -> =bu27 | G22: =G20+1 -> 46 | H22: ="=c"&B22&"27" -> =cu27 | I22: =I20+1 -> 59 | J22: ="=d"&B22&"27" -> =du27 | K22: =K20+1 -> 72 | L22: ="=e"&B22&"27" -> =eu27 | M22: =M20+1 -> 85 | N22: ="=f"&B22&"27" -> =fu27 | O22: =O20+1 -> 98 | P22: ="=g"&B22&"27" -> =gu27
B23: v | D23: ="a"&B23 -> av | F23: ="=b"&B23&27 -> =bv27 | H23: ="=c"&B23&"27" -> =cv27 | J23: ="=d"&B23&"27" -> =dv27 | L23: ="=e"&B23&"27" -> =ev27 | N23: ="=f"&B23&"27" -> =fv27 | P23: ="=g"&B23&"27" -> =gv27
A24: =A22+1 -> 8 | B24: w | C24: =C22+1 -> 21 | D24: ="a"&B24 -> aw | E24: =E22+1 -> 34 | F24: ="=b"&B24&27 -> =bw27 | G24: =G22+1 -> 47 | H24: ="=c"&B24&"27" -> =cw27 | I24: =I22+1 -> 60 | J24: ="=d"&B24&"27" -> =dw27 | K24: =K22+1 -> 73 | L24: ="=e"&B24&"27" -> =ew27 | M24: =M22+1 -> 86 | N24: ="=f"&B24&"27" -> =fw27 | O24: =O22+1 -> 99 | P24: ="=g"&B24&"27" -> =gw27
B25: x | D25: ="a"&B25 -> ax | F25: ="=b"&B25&27 -> =bx27 | H25: ="=c"&B25&"27" -> =cx27 | J25: ="=d"&B25&"27" -> =dx27 | L25: ="=e"&B25&"27" -> =ex27 | N25: ="=f"&B25&"27" -> =fx27 | P25: ="=g"&B25&"27" -> =gx27
A26: =A24+1 -> 9 | B26: y | C26: =C24+1 -> 22 | D26: ="a"&B26 -> ay | E26: =E24+1 -> 35 | F26: ="=b"&B26&27 -> =by27 | G26: =G24+1 -> 48 | H26: ="=c"&B26&"27" -> =cy27 | I26: =I24+1 -> 61 | J26: ="=d"&B26&"27" -> =dy27 | K26: =K24+1 -> 74 | L26: ="=e"&B26&"27" -> =ey27 | M26: =M24+1 -> 87 | N26: ="=f"&B26&"27" -> =fy27 | O26: =O24+1 -> 100 | P26: ="=g"&B26&"27" -> =gy27
B27: z | D27: ="a"&B27 -> az | F27: ="=b"&B27&27 -> =bz27 | H27: ="=c"&B27&"27" -> =cz27 | J27: ="=d"&B27&"27" -> =dz27 | L27: ="=e"&B27&"27" -> =ez27 | N27: ="=f"&B27&"27" -> =fz27 | P27: ="=g"&B27&"27" -> =gz27

Sheet CURVA PARAMÉTRICA
B2: CURVA S | % PARAMÉTRICO
B5: BD EMPREENDIMENTOS - JARDIM CAMPECHE
B8: Mês | C8: % AVANÇO | D8: % AVANÇO Acumulado | E8: Valor Planejado | F8: Valor Planejado Acumulado
B9: 1 | C9: ='DISTRIBUIÇÃO CUSTO'!D32 -> 0.025032496 | D9: =C9 -> 0.025032496 | E9: =C9*$F$45 -> 519234.22 | F9: =E9 -> 519234.22
