Workbook
Name \0: #REF!
Name \a: #REF!
Name \m: #REF!
Name aa: #REF!
Name aa: #REF!
Name aa: #REF!
Name aa: #REF!
Name aaaa: #REF!
Name aaaa: #REF!
Name aaaa: #REF!
Name aaaa: #REF!
Name angelo: #REF!
Name angelo: #REF!
Name angelo: #REF!
Name area: #REF!
Name aux: #REF!
Name aux: #REF!
Name aux: #REF!
Name BDA: #REF!
Name BDA: #REF!
Name BDA: #REF!
Name BDI: #REF!
Name BDI: #REF!
Name BDI: #REF!
Name ca: #REF!
Name ca: #REF!
Name ca: #REF!
Name Capa: #REF!
Name Capa: #REF!
Name Capa: #REF!
Name cronograma: #REF!
Name cronograma: #REF!
Name cronograma: #REF!
Name D: #REF!
Name D: #REF!
Name D: #REF!
Name direto: #REF!
Name direto: #REF!
Name direto: #REF!
Name DRE: #REF!
Name DRE: #REF!
Name DRE: #REF!
Name ea: #REF!
Name ea: #REF!
Name ea: #REF!
Name eee: {#N/A,#N/A,FALSE,"ET-CAPA";#N/A,#N/A,FALSE,"ET-PAG1";#N/A,#N/A,FALSE,"ET-PAG2";#N/A,#N/A,FALSE,"ET-PAG3";#N/A,#N/A,FALSE,"ET-PAG4";#N/A,#N/A,FALSE,"ET-PAG5"}
Name eee: {#N/A,#N/A,FALSE,"ET-CAPA";#N/A,#N/A,FALSE,"ET-PAG1";#N/A,#N/A,FALSE,"ET-PAG2";#N/A,#N/A,FALSE,"ET-PAG3";#N/A,#N/A,FALSE,"ET-PAG4";#N/A,#N/A,FALSE,"ET-PAG5"}
Name eee: {#N/A,#N/A,FALSE,"ET-CAPA";#N/A,#N/A,FALSE,"ET-PAG1";#N/A,#N/A,FALSE,"ET-PAG2";#N/A,#N/A,FALSE,"ET-PAG3";#N/A,#N/A,FALSE,"ET-PAG4";#N/A,#N/A,FALSE,"ET-PAG5"}
Name eee: {#N/A,#N/A,FALSE,"ET-CAPA";#N/A,#N/A,FALSE,"ET-PAG1";#N/A,#N/A,FALSE,"ET-PAG2";#N/A,#N/A,FALSE,"ET-PAG3";#N/A,#N/A,FALSE,"ET-PAG4";#N/A,#N/A,FALSE,"ET-PAG5"}
Name FFFFFFF: #REF!
Name FFFFFFF: #REF!
Name item_1: #REF!
Name item_1: #REF!
Name item_1: #REF!
Name LS: #REF!
Name LS: #REF!
Name LS: #REF!
Name MENU: #REF!
Name MENU: #REF!
Name MENU: #REF!

Sheet OBRA
A1: Obra | B1: Jardim Campeche
A2: Empresa | B2: BD Empreendimentos
A3: Revisão | B3: R00
A4: DADOS OBRA
A6: ARQUITETURA
B8: Descrição | C8: Unidade | D8: Quantidade
B9: ÁREA DO TERRENO | C9: M2 | D9: 866.65
B10: ÁREA CONSTRUÍDA | C10: M2 | D10: 3632.78
B11: NÚMERO DE UNIDADES HABITACIONAIS | C11: UN | D11: 20
B12: MESES DE OBRA | C12: MÊS | D12: 36
B13: NÚMERO DE PAVIMENTOS | C13: UN | D13: 7
B15: ETAPA | C15: VALOR TOTAL | D15: % | E15: VALOR / m²
B16: GERENCIAMENTO TÉCNICO E ADMINISTRATIVO | C16: =GERENCIAMENTO_EXECUTIVO!F14 -> 2551044.1 | D16: =C16/$C$38 -> 0.12298689 | E16: =C16/$D$10 -> 702.22917
B17: MOVIMENTAÇÃO DE TERRA | C17: =GERENCIAMENTO_EXECUTIVO!F17 -> 309991.74 | D17: =C17/$C$38 -> 0.014944829 | E17: =C17/$D$10 -> 85.331822
B18: CONTENÇÃO | C18: =GERENCIAMENTO_EXECUTIVO!F43 -> 692136.72 | D18: =C18/$C$38 -> 0.033368197 | E18: =C18/$D$10 -> 190.52536
B19: INFRAESTRUTURA | C19: =GERENCIAMENTO_EXECUTIVO!F29 -> 978970.99 | D19: =C19/$C$38 -> 0.047196595 | E19: =C19/$D$10 -> 269.4826
B20: SUPRAESTRUTURA | C20: =GERENCIAMENTO_EXECUTIVO!F52 -> 2901220.5 | D20: =C20/$C$38 -> 0.13986903 | E20: =C20/$D$10 -> 798.62267
B21: ALVENARIA | C21: =GERENCIAMENTO_EXECUTIVO!F62 -> 529588.5 | D21: =C21/$C$38 -> 0.02553168 | E21: =C21/$D$10 -> 145.7805
B22: INSTALAÇÕES ELÉTRICAS, HIDRÁULICAS, GLP E PREVENTIVAS | C22: =GERENCIAMENTO_EXECUTIVO!F72 -> 1372645.9 | D22: =C22/$C$38 -> 0.066175826 | E22: =C22/$D$10 -> 377.85
B23: EQUIPAMENTOS E SISTEMAS ESPECIAIS | C23: =GERENCIAMENTO_EXECUTIVO!F92 -> 697857.62 | D23: =C23/$C$38 -> 0.033644003 | E23: =C23/$D$10 -> 192.10016
B24: IMPERMEABILIZAÇÃO | C24: =GERENCIAMENTO_EXECUTIVO!F111 -> 292179.89 | D24: =C24/$C$38 -> 0.014086113 | E24: =C24/$D$10 -> 80.428733
B25: REVESTIMENTOS INTERNOS EM PISO E PAREDE | C25: =GERENCIAMENTO_EXECUTIVO!F121 -> 808212.99 | D25: =C25/$C$38 -> 0.038964282 | E25: =C25/$D$10 -> 222.47783
B26: REVESTIMENTOS E ACABAMENTOS INTERNOS EM TETO | C26: =GERENCIAMENTO_EXECUTIVO!F140 -> 299766.44 | D26: =C26/$C$38 -> 0.014451864 | E26: =C26/$D$10 -> 82.517092
B27: ACABAMENTOS EM PISO E PAREDE | C27: =GERENCIAMENTO_EXECUTIVO!F130 -> 918707.13 | D27: =C27/$C$38 -> 0.04429125 | E27: =C27/$D$10 -> 252.89369
B28: PINTURA INTERNA | C28: =GERENCIAMENTO_EXECUTIVO!F145 -> 678657.63 | D28: =C28/$C$38 -> 0.032718364 | E28: =C28/$D$10 -> 186.81496
B29: ESQUADRIAS, VIDROS E FERRAGENS | C29: =GERENCIAMENTO_EXECUTIVO!F152 -> 1379827.4 | D29: =C29/$C$38 -> 0.066522046 | E29: =C29/$D$10 -> 379.82685
B30: COBERTURA | C30: 0 | D30: =C30/$C$38 -> 0 | E30: =C30/$D$10 -> 0
B31: REVESTIMENTOS E ACABAMENTOS DE FACHADA | C31: =GERENCIAMENTO_EXECUTIVO!F167 -> 667706.88 | D31: =C31/$C$38 -> 0.032190424 | E31: =C31/$D$10 -> 183.80053
B32: SERVIÇOS COMPLEMENTARES | C32: =GERENCIAMENTO_EXECUTIVO!F176 -> 965572.17 | D32: =C32/$C$38 -> 0.046550632 | E32: =C32/$D$10 -> 265.79429
B33: IMPREVISTOS E CONTINGENCIAS | C33: =SUM(C17:C32)*0.02 -> 269860.85 | D33: =C33/$C$38 -> 0.013010103 | E33: =C33/$D$10 -> 74.284941
B34: SUBTOTAL | C34: =SUM(C16:C33) -> 16313947 | D34: =SUM(D16:D33) -> 0.78650213 | E34: =SUM(E16:E33) -> 4490.7612
B35: CUB/SC | C35: 3012.64 | D35: 46023 | E35: =ROUND(E34/C35,2)&" CUB" -> 1,49 CUB
B36: MOBILIARIO PRIVATIVO | C36: =[1]COMPLEMENTARES!$F$9 -> 4428459.8 | D36: =C36/$C$38 -> 0.21349787 | E36: =C36/$D$10 -> 1219.0278
B37: SUBTOTAL | C37: =C36 -> 4428459.8 | D37: =D36 -> 0.21349787 | E37: =E36 -> 1219.0278
B38: TOTAL | C38: =C37+C34 -> 20742407 | D38: =D37+D34 -> 1 | E38: =E37+E34 -> 5709.789
B39: CUB/SC | C39: 3012.64 | D39: 46023 | E39: =ROUND(+E38/C39,2)&" CUB" -> 1,9 CUB

Sheet CANTEIRO
A1: Obra | B1: =OBRA!B1 -> Jardim Campeche
A2: Empresa | B2: =OBRA!B2 -> BD Empreendimentos
A3: Revisão | B3: =OBRA!B3 -> R00
A4: LEVANTAMENTO QUANTITATIVO
A6: Instalações de canteiro
A8: Instalações de canteiro
B10: Descrição | C10: Unidade | D10: Quantidade
B11: Produtividade média | C11: m2 / mês | D11: =OBRA!D10/OBRA!D12 -> 100.91056
B12: Pm | C12: h/m2 | D12: 49
B13: Numero de funcionários | C13: un | D13: =ROUNDUP((D12*OBRA!D10)/OBRA!D12/180,) -> 28
B14: Equipe administrativa | C14: un | D14: 4
B15: Pontos de água e esgoto | C15: un | D15: =ROUNDUP($D$13/20,0) -> 2 | E15: 20 funcionários/ponto
B16: Bebedouro | C16: un | D16: =ROUNDUP(OBRA!$D$13/5,0) -> 2 | E16: 1 / 5 pav.
B17: Ferramentas | C17: R$ | D17: =800*D13 -> 22400 | E17: 800,00/func.
B18: EPI | C18: R$ | D18: =500*(D13+D14)*OBRA!D12/12 -> 48000 | E18: 500,00/func.
B19: Banheiro | C19: un | D19: =ROUNDUP($D$13/20,0) -> 2 | E19: 1/20 func
A21: Mobiliário de canteiro
B23: Descrição | C23: Unidade | D23: Quantidade | E23: Custo unitário | F23: Custo total
B24: Cadeira | C24: un | D24: =D28*1.5 -> 6 | E24: 200 | F24: =D24*E24 -> 1200
B25: Mesa | C25: un | D25: 1 | E25: 1000 | F25: =E25*D25 -> 1000
B26: Ar condicionado | C26: un | D26: 1 | E26: 5000 | F26: =E26*D26 -> 5000
B27: Armário | C27: m | D27: 2 | E27: 900 | F27: =E27*D27 -> 1800
B28: Escrivaninha | C28: un | D28: =D14 -> 4 | E28: 800 | F28: =E28*D28 -> 3200
B29: TOTAL | F29: =F26+F27+F28+F25+F24 -> 12200
B30: Descrição | C30: Unidade | D30: Quantidade | E30: Custo unitário | F30: Custo total
B31: Computador pessoal | C31: un | D31: =D14/2 -> 2 | E31: 6000 | F31: =D31*E31 -> 12000
B32: Impressora | C32: un | D32: 1 | E32: 2000 | F32: =E32*D32 -> 2000
B33: Roteador | C33: un | D33: 1 | E33: 500 | F33: =E33*D33 -> 500
B34: TOTAL | F34: =+F31+F32+F33 -> 14500

Sheet EPCs
A1: Obra | B1: =OBRA!B1 -> Jardim Campeche
A2: Empresa | B2: =OBRA!B2 -> BD Empreendimentos
A3: Revisão | B3: =OBRA!B3 -> R00
A4: LEVANTAMENTO QUANTITATIVO
A6: Equipamentos de proteção coletiva
A8: Bandejas de proteção
B10: Descrição | C10: Unidade | D10: Quantidade
B11: Perímetro de projeção embasamneto | C11: m | D11: 123.46
B12: Perímetro de projeção torre | C12: m | D12: 116.66
B13: Bandeja de proteção primária | C13: m | D13: =D11 -> 123.46
B14: Bandeja de proteção secundária | C14: m | D14: =D12 -> 116.66
A16: Guarda - corpo de desforma
B18: Descrição | C18: Unidade | D18: Quantidade
B19: Perímetro de projeção da torre | C19: m | D19: =D12 -> 116.66
B20: Repetições de pavimentos** | C20: un | D20: 4
B21: Proteção de periferia pós desforma torre | C21: m | D21: =(D19*D20) -> 466.64
A23: Guarda-corpo de vãos
B25: Descrição | C25: Unidade | D25: Quantidade
B26: Comprimento de futuros guarda-copro de alumínio | C26: m | D26: 194.45
B27: Tela fachadeira | C27: m | D27: =D26 -> 194.45
A29: Tela fachadeira
B31: Descrição | C31: Unidade | D31: Quantidade
B32: Perimetro da torre | C32: m | D32: =D12 -> 116.66
B33: Altura da torre | C33: m | D33: 24.84
B34: Tela fachadeira | C34: m2 | D34: =D32*D33 -> 2897.8344
A36: Fechamento removível de vãos em madeira
B38: Descrição | C38: Unidade | D38: Quantidade
B39: Área das portas de elevadores | C39: m2 | D39: =0.9*2.4 -> 2.16
B40: Quantidade de elevadores | C40: un | D40: 1
B41: Quantidade de portas de elevadores | C41: un | D41: =D40*OBRA!D13 -> 7
B42: Fechamento removível de vãos em madeira | C42: m2 | D42: =D39*D41 -> 15.12
A44: Tapume
B46: Descrição | C46: Unidade | D46: Quantidade
B47: Perímetro de encontro com pavimentação | C47: m | D47: =20+34 -> 54
B48: Altura do tapume | C48: m | D48: 2.4
B49: Cobertura para proteção de pedestres | C49: m2 | D49: =D48*D47 -> 129.6

Sheet CUSTOS_INDIRETOS
A1: ORÇAMENTO PARAMÉTRICO - CUSTOS INDIRETOS
A7: Cliente | B7: =OBRA!B1 -> Jardim Campeche
A8: Obra | B8: =OBRA!B2 -> BD Empreendimentos
A9: Data | B9: 45690
A10: Versão | B10: =OBRA!B3 -> R00
A12: GERENCIAMENTO TÉCNICO
A13: Código | B13: Descrição | C13: Un. | D13: Quantidade orçada | E13: Preço unitário | F13: Preço total
A14: 01 | B14: GERENCIAMENTO TÉCNICO | F14: =F15+F20 -> 408539.86
A15: 01.001 | B15: ESTUDOS, PROJETOS E CONSULTORIAS | F15: =F16+F17+F18+F19 -> 310726.94
A16: 01.001.001 | B16: Estudos | F16: 18489.05
A17: 01.001.002 | B17: Projetos | F17: 208534.22
A18: 01.001.003 | B18: Consultorias | F18: 59535.622
A19: 01.001.004 | B19: Ensaios e Laudos | F19: 24168.053
A20: 01.002 | B20: TAXAS E DOCUMENTOS | F20: =SUM(F21:F23) -> 97812.916
A21: 01.002.001 | B21: Seguros | F21: 32356.334
A22: 01.002.002 | B22: Licenciamentos, Taxas, Impostos | F22: 50089.728
A23: 01.002.003 | B23: Documentos | F23: 15366.854
A24: 02 | B24: GERENCIAMENTO ADMINISTRATIVO | F24: =F25+F39+F58 -> 2142504.2
A25: 02.001 | B25: SEGURANÇA, MEIO AMBIENTE E SAÚDE | F25: =F26+F28+F38 -> 337318.93
A26: 02.001.001 | B26: Segurança do Trabalho | F26: =F27 -> 43200
A27: 02.001.001.001 | B27: Serviço de segurança do trabalho terceirizado | C27: mes | D27: =OBRA!D12 -> 36 | E27: 1200 | F27: =E27*D27 -> 43200
A28: 02.001.002 | B28: Equipamentos de proteção | F28: =SUM(F29:F37) -> 266909.01
A29: 02.001.002.001 | B29: Bandeja de proteção primária | C29: m | D29: =EPCs!D13 -> 123.46 | E29: 243.95615 | F29: =E29*D29 -> 30118.826
A30: 02.001.002.001 | B30: Bandeja de proteção secundária | C30: m | D30: =EPCs!D14 -> 116.66 | E30: 115.533 | F30: =E30*D30 -> 13478.08
A31: 02.001.002.002 | B31: Guarda corpo em laje pós - desforma | C31: m | D31: =EPCs!D21 -> 466.64 | E31: 41.842177 | F31: =E31*D31 -> 19525.233
A32: 02.001.002.003 | B32: Gurada-corpo de vãos com régua de pinus 2,5x15cm | C32: m | D32: =EPCs!D27 -> 194.45 | E32: 21.879 | F32: =E32*D32 -> 4254.3715
A33: 02.001.002.004 | B33: Fechamento removível de vãos de porta de elevador em madeira | C33: m2 | D33: =EPCs!D42 -> 15.12 | E33: 36.257575 | F33: =E33*D33 -> 548.21454
A34: 02.001.002.005 | B34: Tela fachadeira | C34: m2 | D34: =EPCs!D34 -> 2897.8344 | E34: 7.8 | F34: =E34*D34 -> 22603.108
A35: 02.001.002.006 | B35: Varal de seguranca com cabo de aco | C35: m | D35: =D31 -> 466.64 | E35: 268.4 | F35: =E35*D35 -> 125246.18
A36: 02.001.002.007 | B36: Sinalização com placa indicativa fixada na estrutura | C36: vb | D36: 1 | E36: 3135 | F36: =E36*D36 -> 3135
A37: 02.001.002.008 | B37: Equipamentos de proteção individual | C37: vb | D37: 1 | E37: =CANTEIRO!D18 -> 48000 | F37: =E37*D37 -> 48000
A38: 02.001.003 | B38: Meio Ambiente | F38: 27209.918
A39: 02.002 | B39: ADMINISTRAÇÃO E CANTEIRO DE OBRA | F39: =F40+F47+F49+F57 -> 1502849
A40: 02.002.001 | B40: Equipe de Gestão e Apoio | F40: =SUM(F41:F46) -> 1106201.9
A41: 02.002.001.001 | B41: Engenheiro Civil | C41: mes | D41: =OBRA!$D$12 -> 36 | E41: 6600 | F41: =E41*D41 -> 237600
A42: 02.002.001.002 | B42: Mestre Geral | C42: mes | D42: =OBRA!$D$12 -> 36 | E42: 7500 | F42: =E42*D42 -> 270000
A43: 02.002.001.003 | B43: Auxiliar de Engenharia | C43: mes | D43: =OBRA!$D$12 -> 36 | E43: 5500 | F43: =E43*D43 -> 198000
A44: 02.002.001.003 | B44: Operador de Guincho | C44: mes | D44: =D62 -> 13 | E44: 3500 | F44: =E44*D44 -> 45500
A45: 02.002.001.007 | B45: Equipe de apoio | C45: mes | D45: =OBRA!$D$12 -> 36 | E45: 4776.5 | F45: =E45*D45 -> 171954
A46: 02.002.001.009 | B46: Serviço de vigilância | C46: mes | D46: =OBRA!$D$12 -> 36 | E46: 5087.4407 | F46: =E46*D46 -> 183147.86
...

Sheet GERENCIAMENTO_EXECUTIVO
A1: ORÇAMENTO PARAMÉTRICO - GERENCIAMENTO EXECUTIVO
A7: Cliente | B7: =OBRA!B2 -> BD Empreendimentos
A8: Obra | B8: =OBRA!B1 -> Jardim Campeche
A9: Data | B9: 46055
A10: Versão | B10: =OBRA!B3 -> R00
A12: GERENCIAMENTO EXECUTIVO
A13: CÓDIGO | B13: ITEM | C13: Quantidade | D13: Unidade | E13: Custo unitário | F13: Valor Orçado | G13: Considerações
A14: 1 | B14: GERENCIAMENTO TÉCNICO E ADMINISTRATIVO | F14: =F15 -> 2551044.1
A15: 1.1 | B15: GERENCIAMENTO TÉCNICO E ADMINISTRATIVO | F15: =F16 -> 2551044.1
A16: 1.1.1 | B16: Gerenciamento técnico e administrativo | C16: 1 | D16: vb | E16: =F16/C16 -> 2551044.1 | F16: =CUSTOS_INDIRETOS!F72 -> 2551044.1 | G16: Conforme aba "custos_indiretos"
A17: 2 | B17: MOVIMENTAÇÃO DE TERRA | F17: =F21+F23+F18 -> 309991.74
A18: 2.1 | B18: ESCAVAÇÃO VERTICAL DE SUBSOLO | F18: =SUM(F19:F20) -> 223131.87
A19: 2.1.1 | B19: Escavação mecanizada | C19: 2125.278 | D19: m³ | E19: =F19/C19 -> 39.996 | F19: 85002.619
A20: 2.1.2 | B20: Movimentação de bota-fora | C20: 2762.8614 | D20: m³ | E20: =F20/C20 -> 49.995 | F20: 138129.26
A21: 2.2 | B21: REBAIXAMENTO DE LENÇOL | F21: =SUM(F22:F22) -> 33000
A22: 2.2.1 | B22: Rebaixamento provisório de lençol | C22: 4 | D22: mês | E22: =F22/C22 -> 8250 | F22: 33000 | G22: Rebaixameno de lençol provisório considerando período de execução da fundação
A23: 2.3 | B23: MOVIMENTAÇÃO DE VALAS | F23: =SUM(F24:F28) -> 53859.863
A24: 2.3.1 | B24: Escavação mecanizada para blocos e baldrames | C24: 175.279 | D24: m³ | E24: =F24/C24 -> 39.996 | F24: 7010.4589
A25: 2.3.2 | B25: Reaterro para blocos e baldrames | C25: 40.449 | D25: m³ | E25: =F25/C25 -> 16.005 | F25: 647.38625
A26: 2.3.3 | B26: Movimentação de bota-fora | C26: 175.279 | D26: m³ | E26: =F26/C26 -> 49.995 | F26: 8763.0736
A27: 2.3.4 | B27: Movimentação de terra das estacas | C27: 206.52045 | D27: m³ | E27: =F27/C27 -> 74.998 | F27: 15488.62
A28: 2.3.5 | B28: Lastro de concreto magro | C28: 539.32 | D28: m² | E28: =F28/C28 -> 40.7 | F28: 21950.324
A29: 3 | B29: INFRAESTRUTURA | F29: =F30+F37 -> 978970.99
A30: 3.1 | B30: FUNDAÇÃO PROFUNDA | F30: =SUM(F31:F36) -> 336886.63
A31: 3.1.1 | B31: Estaca Hélice Continua Diâmetro 40 | C31: 495 | D31: m | E31: =F31/C31 -> 77 | F31: 38115
A32: 3.1.2 | B32: Estaca Hélice Continua Diâmetro 50 | C32: 735 | D32: m | E32: =F32/C32 -> 99 | F32: 72765
A33: 3.1.3 | B33: Concreto (40 Mpa) | C33: 206.52045 | D33: m³ | E33: =F33/C33 -> 830.83286 | F33: 171583.97 | G33: Consideração de concreto com bombeamento + 30% de perda devido a compressão da estaca hélice no solo
A34: 3.1.4 | B34: Armação | C34: 2478.2454 | D34: kg | E34: =F34/C34 -> 8.382 | F34: 20772.653
A35: 3.1.5 | B35: Mobilização de equipamentos | C35: 1 | D35: vb | E35: =F35/C35 -> 9350 | F35: 9350
A36: 3.1.6 | B36: Apoio e arrasamento de estacas | C36: 81 | D36: un | E36: =F36/C36 -> 300 | F36: 24300
A37: 3.2 | B37: FUNDAÇÃO RASA | F37: =SUM(F38:F42) -> 642084.37
A38: 3.2.1 | B38: Fabricação, montagem e desmontagem de forma para blocos e baldrames resinado | C38: 370.7825 | D38: m² | E38: =F38/C38 -> 74.8 | F38: 27734.531 | G38: Forma de madeira serrada sem reutilização
A39: 3.2.2 | B39: Armação | C39: 134.83 | D39: kg | E39: =F39/C39 -> 671.05731 | F39: 90478.657
A40: 3.2.3 | B40: Concreto | C40: 8089.8 | D40: m³ | E40: =F40/C40 -> 8.382 | F40: 67808.704
A41: 3.2.4 | B41: Piso de concreto armado | C41: 674.15 | D41: m² | E41: =F41/C41 -> 198 | F41: 133481.7
A42: 3.2.4 | B42: Mão de obra | C42: 674.15 | D42: m² | E42: =F42/C42 -> 478.5 | F42: 322580.78 | G42: Valor estimado por área de projeção do embasamento
A43: 4 | B43: CONTENÇÃO | F43: =F44 -> 692136.72
A44: 4.1 | B44: PAREDE DIAFRAGMA | F44: =SUM(F45:F51) -> 692136.72
A45: 4.1.1 | B45: Fabricação, montagem e desmontagem de forma - resinado | C45: 553.632 | D45: m² | E45: =F45/C45 -> 74.8 | F45: 41411.674
A46: 4.1.2 | B46: Concreto | C46: 191 | D46: m³ | E46: =F46/C46 -> 830.84607 | F46: 158691.6
...

Sheet MÃO DE OBRA
A1: ETAPA | B1: VALOR TOTAL | C1: SERVIÇOS | D1: EMPEITEIRO | E1: % | F1: VALOR / m²
A2: GERENCIAMENTO TÉCNICO E ADMINISTRATIVO | B2: =OBRA!C16 -> 2551044.1 | C2: =B2-D2 -> 2379090.1 | D2: =CUSTOS_INDIRETOS!F45 -> 171954 | E2: =B2/$B$23 -> 0.12298689 | F2: =SUM(C2:D2)/$I$2 -> 702.22917 | H2: ÁREA CONSTRUÍDA | I2: =[2]ORÇAMENTO_PARAMÉTRICO!G2 -> 3632.78 | J2: m²
A3: MOVIMENTAÇÃO DE TERRA | B3: =OBRA!C17 -> 309991.74 | C3: =B3 -> 309991.74 | D3: 0 | E3: =B3/$B$23 -> 0.014944829 | F3: =SUM(C3:D3)/$I$2 -> 85.331822
A4: CONTENÇÃO | B4: =OBRA!C18 -> 692136.72 | C4: =B4-D4 -> 422366.77 | D4: =GERENCIAMENTO_EXECUTIVO!F49+GERENCIAMENTO_EXECUTIVO!F50 -> 269769.95 | E4: =B4/$B$23 -> 0.033368197 | F4: =SUM(C4:D4)/$I$2 -> 190.52536
A5: INFRAESTRUTURA | B5: =OBRA!C19 -> 978970.99 | C5: =B5-D5 -> 632090.22 | D5: =GERENCIAMENTO_EXECUTIVO!F42+GERENCIAMENTO_EXECUTIVO!F36 -> 346880.78 | E5: =B5/$B$23 -> 0.047196595 | F5: =SUM(C5:D5)/$I$2 -> 269.4826
A6: SUPRAESTRUTURA | B6: =OBRA!C20 -> 2901220.5 | C6: =B6-D6 -> 1795039 | D6: =GERENCIAMENTO_EXECUTIVO!F61 -> 1106181.5 | E6: =B6/$B$23 -> 0.13986903 | F6: =SUM(C6:D6)/$I$2 -> 798.62267
A7: ALVENARIA | B7: =OBRA!C21 -> 529588.5 | C7: =B7-D7 -> 295519.38 | D7: =GERENCIAMENTO_EXECUTIVO!F71 -> 234069.12 | E7: =B7/$B$23 -> 0.02553168 | F7: =SUM(C7:D7)/$I$2 -> 145.7805
A8: INSTALAÇÕES ELÉTRICAS, HIDRÁULICAS, GLP E PREVENTIVAS | B8: =OBRA!C22 -> 1372645.9 | C8: =B8-D8 -> 1372645.9 | D8: 0 | E8: =B8/$B$23 -> 0.066175826 | F8: =SUM(C8:D8)/$I$2 -> 377.85
A9: EQUIPAMENTOS E SISTEMAS ESPECIAIS | B9: =OBRA!C23 -> 697857.62 | C9: =B9 -> 697857.62 | D9: 0 | E9: =B9/$B$23 -> 0.033644003 | F9: =SUM(C9:D9)/$I$2 -> 192.10016
A10: IMPERMEABILIZAÇÃO | B10: =OBRA!C24 -> 292179.89 | C10: =B10 -> 292179.89 | D10: 0 | E10: =B10/$B$23 -> 0.014086113 | F10: =SUM(C10:D10)/$I$2 -> 80.428733
A11: REVESTIMENTOS INTERNOS EM PISO E PAREDE | B11: =OBRA!C25 -> 808212.99 | C11: =B11-D11 -> 366455 | D11: ='[1]Rev. Internos Piso e Parede'!$L$21 -> 441757.99 | E11: =B11/$B$23 -> 0.038964282 | F11: =SUM(C11:D11)/$I$2 -> 222.47783
A12: REVESTIMENTOS E ACABAMENTOS INTERNOS EM TETO | B12: =OBRA!C26 -> 299766.44 | C12: =B12-D12 -> 284308.24 | D12: =[1]TETO!$M$12 -> 15458.2 | E12: =B12/$B$23 -> 0.014451864 | F12: =SUM(C12:D12)/$I$2 -> 82.517092
A13: ACABAMENTOS EM PISO E PAREDE | B13: =OBRA!C27 -> 918707.13 | C13: =B13-D13 -> 563446.07 | D13: ='[1]Acabamentos de Piso e Parede'!$L$24 -> 355261.06 | E13: =B13/$B$23 -> 0.04429125 | F13: =SUM(C13:D13)/$I$2 -> 252.89369
A14: PINTURA INTERNA | B14: =OBRA!C28 -> 678657.63 | C14: =B14-D14 -> 273839.5 | D14: ='[1]PINTURA INTERNA'!$L$15 -> 404818.14 | E14: =B14/$B$23 -> 0.032718364 | F14: =SUM(C14:D14)/$I$2 -> 186.81496
A15: ESQUADRIAS, VIDROS E FERRAGENS | B15: =OBRA!C29 -> 1379827.4 | C15: =B15-D15 -> 1339627.4 | D15: =[1]ESQUADRIAS!$L$21 -> 40200 | E15: =B15/$B$23 -> 0.066522046 | F15: =SUM(C15:D15)/$I$2 -> 379.82685
A16: COBERTURA | B16: =OBRA!C30 -> 0 | C16: 0 | D16: 0 | E16: =B16/$B$23 -> 0 | F16: =SUM(C16:D16)/$I$2 -> 0
A17: REVESTIMENTOS E ACABAMENTOS DE FACHADA | B17: =OBRA!C31 -> 667706.88 | C17: =B17-D17 -> 304281.79 | D17: ='[1]Rev. Fachada'!$L$35 -> 363425.08 | E17: =B17/$B$23 -> 0.032190424 | F17: =SUM(C17:D17)/$I$2 -> 183.80053
A18: SERVIÇOS COMPLEMENTARES | B18: =OBRA!C32 -> 965572.17 | C18: =B18 -> 965572.17 | D18: 0 | E18: =B18/$B$23 -> 0.046550632 | F18: =SUM(C18:D18)/$I$2 -> 265.79429
A19: IMPREVISTOS E CONTINGENCIAS | B19: =OBRA!C33 -> 269860.85 | C19: =B19 -> 269860.85 | D19: =[3]RESUMO!$C$20 -> 0 | E19: =B19/$B$23 -> 0.013010103 | F19: =SUM(C19:D19)/$I$2 -> 74.284941
A20: SUBTOTAL | B20: =SUM(B2:B19) -> 16313947 | C20: =SUM(C2:C19) -> 12564172 | D20: =SUM(D2:D19) -> 3749775.8 | E20: =SUM(E2:E19) -> 0.78650213 | F20: =SUM(F2:F19) -> 4490.7612
A21: MOBILIARIO PRIVATIVO | B21: =OBRA!C36 -> 4428459.8 | C21: =B21 -> 4428459.8 | D21: =[3]RESUMO!C22 -> 0 | E21: =B21/$B$23 -> 0.21349787 | F21: =SUM(C21:D21)/$I$2 -> 1219.0278
A22: SUBTOTAL | B22: =SUM(B21:B21) -> 4428459.8 | C22: =SUM(C21:C21) -> 4428459.8 | D22: =SUM(D21:D21) -> 0 | E22: =E20+E21 -> 1 | F22: =SUM(F21:F21) -> 1219.0278
A23: TOTAL | B23: =SUM(B2:B22)/2 -> 20742407 | C23: =SUM(C2:C22)/2 -> 16992631 | D23: =SUM(D2:D22)/2 -> 3749775.8 | F23: =SUM(F2:F22)/2 -> 5709.789
D24: =D20/I2 -> 1032.2056
D25: =D20/I2/[2]ORÇAMENTO_PARAMÉTRICO!B25 -> 0.34262494 | F25: =D20/I2 -> 1032.2056

Sheet COMPARATIVOS
A1: CÓDIGO | B1: ITEM | C1: Quantidade | D1: Uni | E1: Custo unitário | F1: Valor Orçado | G1: Valor Orçado por Area Construida
A2: 5.1 | B2: LAJE NERVURADA | F2: =SUM(F3:F10) -> 2901220.5 | G2: =F2/OBRA!$D$10 -> 798.62267
A3: 5.1.1 | B3: Fabricação forma | C3: 1556.9057 | D3: m² | E3: =F3/C3 -> 121 | F3: 188385.59
A4: 5.1.2 | B4: Montagem de forma | C4: 5449.17 | D4: m² | E4: =F4/C4 -> 2.75 | F4: 14985.218
A5: 5.1.3 | B5: Escoramento | C5: 5079.52 | D5: kg | E5: =F5/C5 -> 35.2 | F5: 178799.1
A6: 5.1.4 | B6: Cubetas | C6: 1270 | D6: m³ | E6: =F6/C6 -> 79.2 | F6: 100584
A7: 5.1.5 | B7: Concreto | C7: 908.195 | D7: un | E7: =F7/C7 -> 671.05731 | F7: 609450.89
A8: 5.1.6 | B8: Armadura Convencional para Estrutura | C8: 81737.55 | D8: kg | E8: =F8/C8 -> 8.382 | F8: 685124.14
A9: 5.1.7 | B9: Perfuração de vigas | C9: 1 | D9: vb | E9: =F9/C9 -> 17710 | F9: 17710
A10: 5.1.8 | B10: Mão de obra - estrutura em concreto armado | C10: 16217.01 | D10: m² | E10: =F10/C10 -> 68.211188 | F10: 1106181.5
A11: 5.2 | B11: LAJE MACIÇA | F11: =SUM(F12:F18) -> 3110208.5 | G11: =F11/OBRA!$D$10 -> 856.15107
A12: 5.2.1 | B12: Fabricação forma | C12: 2594.8429 | D12: m² | E12: =F12/C12 -> 121 | F12: 313975.99
A13: 5.2.2 | B13: Montagem de forma | C13: 9081.95 | D13: m² | E13: =F13/C13 -> 2.75 | F13: 24975.362
A14: 5.2.3 | B14: Escoramento | C14: 3809.64 | D14: um | E14: =F14/C14 -> 35.2 | F14: 134099.33
A15: 5.2.4 | B15: Concreto | C15: 980.8506 | D15: m³ | E15: =F15/C15 -> 704.61018 | F15: 691117.31
A16: 5.2.5 | B16: Armadura Convencional para Estrutura | C16: 98085.06 | D16: kg | E16: =F16/C16 -> 8.382 | F16: 822148.97
A17: 5.2.6 | B17: Perfuração de vigas | C17: 3632.78 | D17: m² | E17: =F17/C17 -> 4.8750544 | F17: 17710
A18: 5.2.7 | B18: Mão de obra - estrutura em concreto armado | C18: 3632.78 | D18: m² | E18: =F18/C18 -> 304.5 | F18: 1106181.5
A19: 5.3 | B19: LAJE PROTENDIDA | F19: =SUM(F20:F29) -> 2816475.8 | G19: =F19/OBRA!$D$10 -> 775.29491
A20: 5.3.1 | B20: Fabricação forma | C20: 2179.668 | D20: m² | E20: =F20/C20 -> 121 | F20: 263739.83
A21: 5.3.2 | B21: Montagem de forma | C21: 7628.838 | D21: m² | E21: =F21/C21 -> 2.75 | F21: 20979.305
A22: 5.3.3 | B22: Escoramento | C22: 3809.64 | D22: un | E22: =F22/C22 -> 35.2 | F22: 134099.33
A23: 5.3.4 | B23: Protensão - lajes - materiais | C23: 2976.83 | D23: m² | E23: =F23/C23 -> 13.53 | F23: 40276.51
A24: 5.3.5 | B24: Protensão - lajes - cabos | C24: 5655.977 | D24: kg | E24: =F24/C24 -> 16.83 | F24: 95190.093
A25: 5.3.6 | B25: Protensão - lajes - serviços | C25: 7 | D25: pav | E25: =F25/C25 -> 10450 | F25: 73150
A26: 5.3.7 | B26: Concreto | C26: 908.195 | D26: m³ | E26: =F26/C26 -> 669.9 | F26: 608399.83
A27: 5.3.8 | B27: Armadura Convencional para Estrutura | C27: 54491.7 | D27: kg | E27: =F27/C27 -> 8.382 | F27: 456749.43
A28: 5.3.9 | B28: Perfuração de vigas | C28: 1 | D28: vb | E28: =F28/C28 -> 17710 | F28: 17710
A29: 5.3.10 | B29: Mão de obra - estrutura em concreto armado | C29: 16217.01 | D29: m² | E29: =F29/C29 -> 68.211188 | F29: 1106181.5
