Workbook
Name \0: #REF!
Name \0: #REF!
Name \0: #REF!
Name \0: #REF!
Name \0: #REF!
Name \0: #REF!
Name \0: #REF!
Name \0: #REF!
Name \1: #REF!
Name \a: #REF!
Name \a: #REF!
Name \a: #REF!
Name \b: #REF!
Name \c: #REF!
Name \d: #REF!
Name \e: #REF!
Name \i: #REF!
Name \J: #REF!
Name \k: #REF!
Name \l: #N/A
Name \m: #REF!
Name \m: #REF!
Name \m: #REF!
Name \o: #REF!
Name \o: #REF!
Name \p: #REF!
Name \r: #REF!
Name \T: #REF!
Name \z: #REF!
Name \z: #REF!
Name _\0: #REF!
Name _\1: #REF!
Name _\a: #REF!
Name _\b: #REF!
Name _\c: #REF!
Name _\d: #REF!
Name _\e: #REF!
Name _\i: #REF!
Name _\J: #REF!
Name _\k: #REF!
Name _\l: #N/A
Name _\m: #REF!
Name _\o: #REF!
Name _\p: #REF!
Name _\r: #REF!
Name _\T: #REF!
Name _\z: #REF!
Name ______ACR10: #REF!
Name ______ACR10: #REF!
Name ______ACR15: #REF!
Name ______ACR15: #REF!
Name ______acr20: #REF!
Name ______acr20: #REF!
Name ______acr5: #REF!
Name ______ARQ1: #REF!
Name ______QT100: #REF!
Name ______QT2: #REF!
Name ______QT3: #REF!
Name ______QT4: #REF!
Name ______QT50: #REF!

Sheet Obra 
C1: DADOS DO EMPREENDIMENTO
B2: Projeto: | C2: Jardim Campeche | E2: ENDEREÇO DA OBRA:
B3: Empresa: | C3: BD Empreendimentos | E3: Cidade/ES: | F3: Florianópolis /SC
B4: Revisão: | C4: R00 -Patricia | E4: CNPJ:
B6: Pazo de Obra: | E6: Nº Unid. Residenciais: | F6: =SUM(O21:O31) -> 20 | H6: Nº Elevadores: | I6: 1 | K6: Imagens
B8: Área do Terreno: | C8: 866.65 | E8: Nº Unid. Comerciais: | F8: 2
B10: Área Construída: | C10: =SUM($D$21:$D$31) -> 3632.78 | E10: Nº Pavimentos: | F10: 7
B12: Área Privativa: | C12: =SUM($E$21:$E$30) -> 2064.55 | E12: Total de Dormitórios: | F12: =SUM(J20:J31) -> 42
B14: Área de Lazer: | C14: =SUM(E38:E51) -> 473.79 | E14: Nº Subsolos: | F14: 1
B16: Área Comercial: | C16: =E22 -> 90.37 | E16: Nº Vagas: | F16: 22
B18: Nº Banheiros: | C18: =SUM(H20:H31) -> 51 | E18: Nº Churrasqueiras: | F18: =SUM(I20:I31) -> 21
B20: Torre | C20: Pavimento | D20: Área | E20: Área Privativa | F20: Perímetro | G20: Pé direito | H20: Banheiros | I20: Churrasqueira | J20: Quartos | K20: Ventokit | L20: Ar - Condicionado Ponto | M20: Ar - Condicionado Equipamento | N20: Ralos | O20: Nº Unidades
B21: Torre A | C21: SUBSOLO 01 | D21: 655.95 | F21: 115.34 | G21: =2.52+0.72 -> 3.24
B22: Torre A | C22: 1º PAV-TÉRREO | D22: 674.15 | E22: =45.52+44.85 -> 90.37 | F22: 123.46 | G22: =7.2-0.72 -> 6.48 | H22: =2+2 -> 4 | I22: 1 | K22: =H22 -> 4 | L22: =2+3+4 -> 9 | M22: =L22-2 -> 7 | N22: =H22+4 -> 8
B23: Torre A | C23: 1º PAV-MEZANINO | D23: 104.52 | H23: 1 | K23: 1 | L23: 2 | M23: 2
B24: Torre A | C24: 2º PAVIMENTO | D24: 634.94 | E24: =92.14+63.85+119.55+105.43+111.13+98.03 -> 590.13 | F24: 120.7 | G24: =10.26-7.2 -> 3.06 | H24: =3+1+2+3+3+2 -> 14 | I24: 6 | J24: =2+1+2+3+2+2 -> 12 | K24: =1+1+2+1+2 -> 7 | L24: =J24+O24 -> 18 | N24: =H24+O24*2 -> 26 | O24: 6
B25: Torre A | C25: 3º PAVIMENTO | D25: 519.18 | E25: =76.63+48.72+87.05+76.92+86.68+97.95 -> 473.95 | F25: 116.66 | G25: =13.32-10.26 -> 3.06 | H25: =3+1+2+3+3+2 -> 14 | I25: 6 | J25: =2+1+2+3+2+2 -> 12 | K25: =1+1+2+1+2 -> 7 | L25: =J25+O25 -> 18 | N25: =H25+O25*2 -> 26 | O25: 6
B26: Torre A | C26: 4º PAVIMENTO | D26: 519.18 | E26: =76.63+48.72+87.05+76.92+86.68+97.95 -> 473.95 | F26: =F25 -> 116.66 | G26: =16.38-13.32 -> 3.06 | H26: =3+1+2+3+3+2 -> 14 | I26: 6 | J26: =2+1+2+3+2+2 -> 12 | K26: =1+1+2+1+2 -> 7 | L26: =J26+O26 -> 18 | N26: =H26+O26*2 -> 26 | O26: 6
B27: Torre A | C27: COBERTURA APTOS | D27: 466.78 | E27: =227.07+209.08 -> 436.15 | F27: 103.15 | G27: =19.44-16.38 -> 3.06 | H27: =2*2 -> 4 | I27: 2 | J27: =3*2 -> 6 | L27: =J27+2*2 -> 10 | N27: =H27+O27*3 -> 10 | O27: 2
B28: Torre A | C28: BARRILETE | D28: 32.4 | F28: 24.7 | G28: =22.5-19.44 -> 3.06 | N28: =4 -> 4
B29: Torre A | C29: RESERVATÓRIO | D29: 25.68 | F29: 20.1 | G29: =25.56-22.5 -> 3.06
B30: Torre A
G32: =SUM(G22:G29) -> 24.84
B33: Torre | C33: Pavimento | D33: Descrição | E33: Área | F33: =F25*G32 -> 2897.8344 | G33: QUADRO DE ÁREAS
B34: Torre A | C34: SUBSOLO 01 | D34: GARAGEM | E34: 531
B35: Torre A | C35: SUBSOLO 01 | D35: DEPÓSITO | E35: 9.12
B36: Torre A | C36: 1º PAV-TÉRREO | D36: GARAGEM VISITANTES | E36: 114.4
B37: Torre A | C37: 1º PAV-TÉRREO | D37: DEP LIXO | E37: 5.81
B38: Torre A | C38: 1º PAV-TÉRREO | D38: ACESSO PRAIA | E38: 3.86
B39: Torre A | C39: 1º PAV-TÉRREO | D39: HALL | E39: 32.94
B40: Torre A | C40: 1º PAV-TÉRREO | D40: LOCKER | E40: 4.06
B41: Torre A | C41: 1º PAV-TÉRREO | D41: SALA DE FESTAS | E41: 77.49
B42: Torre A | C42: 1º PAV-TÉRREO | D42: AREA DE LAZER | E42: 150.56
B43: Torre A | C43: 1º PAV-TÉRREO | D43: BRINQUEDOTECA | E43: 26.01
B44: Torre A | C44: 1º PAV-TÉRREO | D44: SALA DE JOGOS | E44: 35.56
B45: Torre A | C45: 1º PAV-TÉRREO | D45: BANHEIROS | E45: =3.24+3.24 -> 6.48
B46: Torre A | C46: 1º PAV-TÉRREO | D46: PISCINA | E46: 63.05
B47: Torre A | C47: 1º PAV-MEZANINO | D47: CIRCULAÇÃO | E47: 16.24
B48: Torre A | C48: 1º PAV-MEZANINO | D48: WC | E48: 3.24
B49: Torre A | C49: 1º PAV-TÉRREO | D49: SAUNA | E49: 6.7
...

Sheet DADOS_INICIAIS
A1: Obra | B1: ='Obra '!C2 -> Jardim Campeche
A2: Empresa | B2: ='Obra '!C3 -> BD Empreendimentos
A3: Revisão | B3: R00
A4: Arquitetura base
A5: DADOS OBRA
B7: Descrição | C7: Identificador | D7: Unidade | E7: Quantidade
B8: ÁREA DO TERRENO | C8: AT | D8: M2 | E8: ='Obra '!C8 -> 866.65
B9: ÁREA TOTAL CONSTRUÍDA | C9: AC | D9: M2 | E9: ='Obra '!C10 -> 3632.78
B10: UNIDADES RESIDENCIAIS | C10: UR | D10: UN | E10: ='Obra '!F6 -> 20
B11: Dormitórios | C11: dorm | D11: UN | E11: ='Obra '!F12 -> 42
B12: Banheiros | C12: ban | D12: UN | E12: ='Obra '!$C$18 -> 51
B13: UNIDADES COMERCIAIS | C13: UC | D13: UN | E13: ='Obra '!$F$8 -> 2
B14: Churrasqueiras | C14: CHU | D14: UN | E14: ='Obra '!$F$18 -> 21
B15: NÚMERO TOTAL DE PAVIMENTOS | C15: NP | D15: UN | E15: ='Obra '!$F$10 -> 7
B16: NÚMERO DE PAVIMENTOS TIPO | C16: NPT | D16: UN | E16: =COUNTA('Obra '!C24:C27) -> 4
B17: NÚMERO DE PAVIMENTOS TIPO DIFERENCIADOS | C17: NPD | D17: UN | E17: 1
B18: NÚMERO DE PAVIMENTOS DUPLEX | C18: ND | D18: UN | E18: 0
B19: ÁREA DE PROJEÇÃO DA TORRE | C19: APT | D19: M2 | E19: ='Obra '!D24 -> 634.94
B20: PERÍMETRO DE PROJEÇÃO DA TORRE | C20: PPT | D20: M | E20: ='Obra '!F24 -> 120.7
B21: ÁREA DE LAZER | C21: AL | D21: M2 | E21: ='Obra '!$C$14 -> 473.79
B22: ÁREA DO EMBASAMENTO | C22: AE | D22: M2 | E22: ='Obra '!D22 -> 674.15
B23: ÁREA DE SUBSOLOS | C23: S | D23: M2 | E23: ='Obra '!D21 -> 655.95
B24: NÚMERO DE SUBSOLOS | C24: NS | D24: UN | E24: ='Obra '!F14 -> 1
B25: ÁREA DE PROJEÇÃO DO EMBASAMENTO | C25: APE | D25: M2 | E25: =E22 -> 674.15
B26: PERÍMETRO DE PROJEÇÃO DE EMBAMENTO | C26: PE | D26: M | E26: ='Obra '!F22 -> 123.46
B27: NÚMERO DE PAVIMENTOS DE EMBASAMENTO | C27: NE | D27: UN | E27: 1

Sheet MOVIMENTAÇÃO_DE_TERRA
A2: MOVIMENTAÇÃO DE TERRA
A3: Data | B3: 45472
A4: Arquivo base | B4: -
A6: ESCAVAÇÃO VERTICAL DE SUBSOLO
A8: Descrição | B8: Área de subsolo (m) | C8: Altura do subsolo (m) | D8: Volume total de escavação (m3) | E8: Preço unitário de escavação (R$ / m3) | F8: Valor total | G8: Observação
A9: Escavação | B9: =DADOS_INICIAIS!E23 -> 655.95 | C9: ='Obra '!G21 -> 3.24 | D9: =C9*B9 -> 2125.278 | E9: 36.36 | F9: =E9*D9*1.1 -> 85002.619
A10: Movimentação de bota-fora | D10: =D9*1.3 -> 2762.8614 | E10: 45.45 | F10: =E10*D10*1.1 -> 138129.26
A11: TOTAL | F11: =SUM(F9:F10) -> 223131.87
A13: REBAIXAMENTO DE LENÇOL FREÁTICO
A15: Descrição | B15: Quantidade (dias) | E15: Preço unitário de rebaixamento (R$ / dias) | F15: Valor total | G15: Observação
A16: Rebaixamento de lençol | B16: =4*30 -> 120 | E16: 250 | F16: =B16*E16*1.1 -> 33000 | G16: 4 meses
A17: TOTAL | F17: =SUM(F16:F16) -> 33000
A19: ESCAVAÇÃO E REATERRO DE VALAS
A21: Descrição | B21: Parâmetro | D21: Volume total de escavação (m3) | E21: Preço unitário (R$ / m3) | F21: Valor total | G21: Observação
A22: Escavação mecanizada para blocos e baldrames | B22: 1.3 | C22: m³ / Vol infra | D22: =B22*INFRAESTRUTURA!D29 -> 175.279 | E22: 36.36 | F22: =E22*D22*1.1 -> 7010.4589
A23: Reaterro para blocos e baldrames | B23: 0.6 | C23: m³ / Vol Escavação | D23: =D22-INFRAESTRUTURA!D29 -> 40.449 | E23: 14.55 | F23: =E23*D23*1.1 -> 647.38625
A24: Movimentação de bota-fora | B24: 1.3 | D24: =(D22-D23)*B24 -> 175.279 | E24: 45.45 | F24: =E24*D24*1.1 -> 8763.0736
A25: Movimentação de terra das estacas | B25: 1 | C25: m³ | D25: =INFRAESTRUTURA!D19 -> 206.52045 | E25: 68.18 | F25: =E25*D25*1.1 -> 15488.62
A26: TOTAL | F26: =SUM(F22:F25) -> 31909.539
A28: REGULARIZAÇÃO E APILOAMENTO DE FUNDO DE VALAS
A30: Descrição | B30: Parâmetro | D30: Área de lastro (m²) | E30: Preço unitário (R$ / m2) | F30: Valor total | G30: Observação
A31: Lastro de concreto magto e=5cm | B31: 0.8 | C31: m² / APE | D31: =B31*DADOS_INICIAIS!E25 -> 539.32 | E31: =370*0.1 -> 37 | F31: =E31*D31*1.1 -> 21950.324 | G31: Definição trazida do Celebration da Passe | H31: =F31/DADOS_INICIAIS!E25 -> 32.56
A32: TOTAL | F32: =SUM(F31:F31) -> 21950.324
A34: TOTAL MOVIMENTAÇÃO DE TERRA | F34: =F11+F17+F26+F32 -> 309991.74 | G34: =F34/DADOS_INICIAIS!E9 -> 85.331822

Sheet INFRAESTRUTURA
A3: INFRAESTRUTURA
A4: Data | B4: 45472
A5: Arquivo base | B5: -
A7: FUNDAÇÃO PROFUNDA
A9: Descrição | B9: Parâmetro | D9: Quantidade | F9: Preço unitário | G9: Valor total | H9: Observação | I9: MT | J9: MT Total | K9: MO | L9: MO Total
A10: Número de Estacas | B10: 0.12 | C10: un / APE | D10: =ROUNDUP(B10*DADOS_INICIAIS!$E$25,0) -> 81 | E10: un | H10: Base obra Trindade Parkside | J10: =I10*$D10 -> 0 | L10: =K10*$D10 -> 0
A11: Estaca Hélice Continua Diâmetro 40 | B11: 0.4 | D11: =ROUNDUP(B11*$D$10,0) -> 33 | E11: un | J11: =I11*$D11 -> 0 | L11: =K11*$D11 -> 0
B12: 15 | C12: m/un | D12: =B12*D11 -> 495 | E12: m | F12: 70 | G12: =F12*D12*1.1 -> 38115 | J12: =I12*$D12 -> 0 | L12: =K12*$D12 -> 0
A13: Estaca Hélice Continua Diâmetro 50 | B13: 0.6 | D13: =ROUNDUP(B13*D10,0) -> 49 | E13: un | J13: =I13*$D13 -> 0 | L13: =K13*$D13 -> 0
B14: 15 | C14: m/un | D14: =B14*D13 -> 735 | E14: m | F14: 90 | G14: =F14*D14*1.1 -> 72765 | I14: =F14*1.1 -> 99 | J14: =I14*$D14 -> 72765 | L14: =K14*$D14 -> 0
A15: Estaca Hélice Continua Diâmetro 60 | B15: 0 | C15: un / APE | D15: =ROUNDUP(B15*$D$10,0) -> 0 | E15: un | J15: =I15*$D15 -> 0 | L15: =K15*$D15 -> 0
B16: 15 | C16: m/un | D16: =B16*D15 -> 0 | E16: m | F16: 105 | G16: =F16*D16*1.1 -> 0 | I16: =F16*1.1 -> 115.5 | J16: =I16*$D16 -> 0 | L16: =K16*$D16 -> 0
A17: Estaca Hélice Continua Diâmetro 80 | B17: 0 | C17: un / APE | D17: =ROUNDUP(B17*$D$10,0) -> 0 | E17: un | J17: =I17*$D17 -> 0 | L17: =K17*$D17 -> 0
B18: 15 | C18: m/un | D18: =B18*D17 -> 0 | E18: m | F18: 120 | G18: =F18*D18*1.1 -> 0 | J18: =I18*$D18 -> 0 | L18: =K18*$D18 -> 0
A19: Concreto (40 Mpa) | B19: 1.3 | C19: perda | D19: =(PI()*((0.4^2)/4)*D12+PI()*((0.5^2)/4)*D14+PI()*((0.6^2)/4)*D16) -> 206.52045 | E19: m³ | F19: =(535+45+(1.67*0.6))*B19 -> 755.3026 | G19: =F19*D19*1.1 -> 171583.97 | I19: =F19*1.1 -> 830.83286 | J19: =I19*$D19 -> 171583.97 | L19: =K19*$D19 -> 0
A20: Armação | B20: 12 | C20: kg / m³ | D20: =B20*D19 -> 2478.2454 | E20: kg | F20: 7.62 | G20: =F20*D20*1.1 -> 20772.653 | I20: =F20*1.1 -> 8.382 | J20: =I20*$D20 -> 20772.653 | L20: =K20*$D20 -> 0
A21: Mobilização | B21: 1 | C21: vb | D21: 1 | E21: vb | F21: 8500 | G21: =F21*D21*1.1 -> 9350 | I21: =F21*1.1 -> 9350 | J21: =I21*$D21 -> 9350 | L21: =K21*$D21 -> 0
A22: Apoio e arrasamento de estacas | D22: =D10 -> 81 | E22: un | F22: 300 | G22: =F22*D22*1 -> 24300 | J22: =I22*$D22 -> 0 | K22: =F22 -> 300 | L22: =K22*$D22 -> 24300
A23: TOTAL | G23: =SUM(G10:G22) -> 336886.63 | J23: =SUM(J10:J22) -> 274471.63 | L23: =SUM(L10:L22) -> 24300
A25: FUNDAÇÃO RASA
A27: Descrição | B27: Parâmetro | D27: Quantidade | F27: Preço unitário | G27: Valor total | H27: Observação | I27: MT | J27: MT Total | K27: MO | L27: MO Total
A28: Fabricação, montagem e desmontagem de forma para blocos e baldrames resinado | B28: 0.55 | C28: m² / APE | D28: =B28*DADOS_INICIAIS!E25 -> 370.7825 | E28: m² | F28: 68 | G28: =F28*D28*1.1 -> 27734.531 | I28: =F28*1.1 -> 74.8 | J28: =I28*$D28 -> 27734.531
A29: Concreto (40 Mpa) | B29: 0.2 | C29: m³ / APE | D29: =B29*DADOS_INICIAIS!E25 -> 134.83 | E29: m³ | F29: =(535+45+(1.67*0.6))*1.05 -> 610.0521 | G29: =F29*D29*1.1 -> 90478.657 | I29: =F29*1.1 -> 671.05731 | J29: =I29*$D29 -> 90478.657
A30: Armação | B30: 60 | C30: kg / m³ | D30: =B30*D29 -> 8089.8 | E30: kg | F30: 7.62 | G30: =F30*D30*1.1 -> 67808.704 | I30: =F30*1.1 -> 8.382 | J30: =I30*$D30 -> 67808.704
A31: Piso de concreto armado | B31: 1 | C31: m² / APE | D31: =B31*DADOS_INICIAIS!E25 -> 674.15 | E31: m² | F31: 180 | G31: =F31*D31*1.1 -> 133481.7 | I31: =F31*1.1 -> 198 | J31: =I31*$D31 -> 133481.7
A32: Mão de obra | B32: =SUPRAESTRUTURA!B28*1.5 -> 435 | C32: R$ / APE | D32: =DADOS_INICIAIS!E25 -> 674.15 | E32: m² | F32: =B32 -> 435 | G32: =F32*D32*1.1 -> 322580.78 | K32: =F32*1.1 -> 478.5 | L32: =K32*$D32 -> 322580.78
A33: TOTAL | G33: =SUM(G28:G32) -> 642084.37 | J33: =SUM(J28:J32) -> 319503.59 | L33: =SUM(L28:L32) -> 322580.78
A36: TOTAL INFRAESTRUTURA | G36: =G23+G33 -> 978970.99 | H36: =G36/DADOS_INICIAIS!E9 -> 269.4826
H38: =H36/1.1 -> 244.98418

Sheet CONTENÇÕES
J2: Perímetro | K2: Altura | L2: Espessura | M2: Repetição | N2: Forma | O2: Concreto
A3: CONTENÇÃO | I3: Contenção | J3: ='Obra '!F21 -> 115.34 | K3: ='Obra '!G21*2 -> 6.48 | L3: 0.2 | M3: 1 | O3: =J3*K3*L3*M3 -> 149.48064
A4: Data | I4: Viga de coroamento | J4: =J3 -> 115.34 | K4: 0.4 | L4: 0.4 | M4: 1 | N4: =J4*K4*2*M4 -> 92.272 | O4: =J4*K4*L4*M4 -> 18.4544
A5: Arquivo base | I5: Mureta guia | J5: =J4 -> 115.34 | K5: 1 | L5: 0.1 | M5: 2 | N5: =J5*K5*2*M5 -> 461.36 | O5: =J5*K5*L5*M5 -> 23.068
J6: =J3*K3 -> 747.4032 | N6: =SUM(N3:N5) -> 553.632 | O6: =SUM(O3:O5) -> 191.00304
A7: CORTINA DE ESTACAS
A9: Descrição | B9: Parâmetro | D9: Quantidade | F9: Preço unitário | G9: Valor total
A10: Número de Estacas | B10: 0.15 | C10: un / APE | D10: =B10*DADOS_INICIAIS!E25 -> 101.1225 | E10: un
A11: Estaca Hélice Continua Diâmetro 40 | B11: 0.1 | D11: =B11*$D$10 -> 10.11225 | E11: un
B12: 20 | C12: m/un | D12: =B12*D11 -> 202.245 | E12: m | G12: =F12*D12 -> 0
A13: Estaca Hélice Continua Diâmetro 50 | B13: 0.5 | D13: =B13*$D$10 -> 50.56125 | E13: un
B14: 20 | C14: m/un | D14: =B14*D13 -> 1011.225 | E14: m | G14: =F14*D14 -> 0
A15: Estaca Hélice Continua Diâmetro 60 | B15: 0.4 | C15: un / APE | D15: =B15*$D$10 -> 40.449 | E15: un
B16: 20 | C16: m/un | D16: =B16*D15 -> 808.98 | E16: m | G16: =F16*D16 -> 0
A17: Concreto | B17: =(PI()*0.4^2)/4*D14+(PI()*0.5^2)/4*D16+(PI()*0.6^2)/4*D12 -> 343.10056 | C17: un / APE | D17: =(PI()*0.4^2)/4*D14+(PI()*0.5^2)/4*D16+(PI()*0.6^2)/4*D12 -> 343.10056 | E17: m³ | G17: =F17*D17 -> 0
A18: Armação 6,3mm | B18: 1.6575131 | C18: kg / m³ | D18: =B18*D17 -> 568.69368 | E18: kg | G18: =F18*D18 -> 0
A19: Armação 16mm | B19: 10.178338 | C19: kg / m³ | D19: =B19*D17 -> 3492.1933 | E19: kg | G19: =F19*D19 -> 0
A20: Mobilização | B20: 1 | C20: vb | D20: 1 | E20: vb | G20: =F20*D20 -> 0
A21: TOTAL | G21: =SUM(G10:G20) -> 0
A23: PAREDE DE CONCRETO
A25: Descrição | B25: Parâmetro | D25: Quantidade | F25: Preço unitário | G25: Valor total
A26: Fabricação, montagem e desmontagem de forma para blocos e baldrames resinado | B26: 2.1 | C26: m² / APE | D26: =B26*DADOS_INICIAIS!E25 -> 1415.715 | E26: m² | G26: =F26*D26 -> 0
A27: Concreto | B27: 0.65 | C27: m³ / APE | D27: =B27*DADOS_INICIAIS!E25 -> 438.1975 | E27: m³ | G27: =F27*D27 -> 0
A28: Armação | B28: 110 | C28: kg / m³ | D28: =B28*D27 -> 48201.725 | E28: kg | G28: =F28*D28 -> 0
A29: Mão de obra | B29: =SUPRAESTRUTURA!B15*1.5 -> 435 | C29: R$ / APE | D29: =DADOS_INICIAIS!E25 -> 674.15 | E29: m² | F29: =B29 -> 435 | G29: =F29*D29 -> 293255.25
A30: TOTAL | G30: =SUM(G26:G29) -> 293255.25
A33: PAREDE DE CONCRETO
A35: Descrição | B35: Parâmetro | D35: Quantidade | F35: Preço unitário | G35: Valor total | H35: MT | I35: MT Total | J35: MO | K35: MO Total
A36: Fabricação, montagem e desmontagem de forma para blocos e baldrames resinado | B36: 2.1 | C36: m² / APE | D36: =N6 -> 553.632 | E36: m² | F36: 68 | G36: =F36*D36*1.1 -> 41411.674 | H36: =F36*1.1 -> 74.8 | I36: =H36*$D36 -> 41411.674
A37: Concreto apoio | C37: m³ / APE | D37: =O4+O5 -> 41.5224 | E37: m³ | F37: =(535+45+(1.67*0.6))*1.3 -> 755.3026 | G37: =F37*D37*1.1 -> 34498.174 | H37: =F37*1.1 -> 830.83286 | I37: =H37*$D37 -> 34498.174
A38: Concreto lamela | C38: m³ / APE | D38: =O3 -> 149.48064 | E38: m³ | F38: =(535+45+(1.67*0.6))*1.3 -> 755.3026 | G38: =F38*D38*1.1 -> 124193.43 | H38: =F38*1.1 -> 830.83286 | I38: =H38*$D38 -> 124193.43
A39: Armação | B39: 110 | C39: kg / m³ | D39: =B39*(D38+D37) -> 21010.334 | E39: kg | F39: 7.62 | G39: =F39*D39*1.1 -> 176108.62 | H39: =F39*1.1 -> 8.382 | I39: =H39*$D39 -> 176108.62
A40: Mobilização | B40: =SUPRAESTRUTURA!B67*1.5 -> 0 | C40: R$ / APE | D40: 1 | E40: vb | F40: 650 | G40: =F40*D40*1.1 -> 715 | H40: =F40*1.1 -> 715 | I40: =H40*$D40 -> 715 | K40: =J40*$D40 -> 0
A41: Mão de obra apoio | B41: =SUPRAESTRUTURA!B68*1.5 -> 0 | C41: R$ / APE | D41: =J6 -> 747.4032 | E41: m³ | F41: 100 | G41: =F41*D41*1.1 -> 82214.352 | I41: =H41*$D41 -> 0 | J41: =F41*1.1 -> 110 | K41: =J41*$D41 -> 82214.352
A42: Mão de obra diagrafma | B42: =SUPRAESTRUTURA!B68*1.5 -> 0 | C42: R$ / APE | D42: =J6 -> 747.4032 | E42: m³ | F42: 228.13 | G42: =F42*D42*1.1 -> 187555.6 | H42: =F42*1.1 -> 250.943 | I42: =H42*$D42 -> 187555.6 | K42: =J42*$D42 -> 0
A43: Tratamento de juntas | B43: =SUPRAESTRUTURA!B69*1.5 -> 0 | C43: R$ / APE | D43: =J6 -> 747.4032 | E43: m³ | F43: 55.27 | G43: =F43*D43*1.1 -> 45439.872 | H43: =F43*1.1 -> 60.797 | I43: =H43*$D43 -> 45439.872 | K43: =J43*$D43 -> 0
A44: TOTAL | G44: =SUM(G36:G43) -> 692136.72 | I44: =SUM(I36:I43) -> 609922.37 | K44: =SUM(K36:K43) -> 82214.352
A50: TOTAL INFRAESTRUTURA | G50: =G44 -> 692136.72 | H50: =G50/DADOS_INICIAIS!E9 -> 190.52536

Sheet SUPRAESTRUTURA
A3: SUPRAESTRUTURA
A4: Data | B4: 45472
A5: Arquivo base | B5: -
G6: =8-2+1 -> 7
A7: SUPRAESTRUTURA - LAJE MACIÇA
A9: Descrição | B9: Parâmetro | D9: Quantidade | F9: Preço unitário | G9: Valor total | H9: Observação
A10: Fabricação forma | B10: 2 | C10: Jogos | D10: =(D11/DADOS_INICIAIS!$E$15)*B10 -> 2594.8429 | E10: m² | F10: 110 | G10: =F10*D10*1.1 -> 313975.99
A11: Montagem de forma | B11: 2.5 | C11: m² / AC | D11: =B11*DADOS_INICIAIS!$E$9 -> 9081.95 | E11: m² | F11: 2.5 | G11: =F11*D11*1.1 -> 24975.362
A12: Escoramento | B12: 3 | C12: un / AE | D12: =B12*'Obra '!$D$24*B10 -> 3809.64 | E12: um | F12: =4*8 -> 32 | G12: =F12*D12*1.1 -> 134099.33
A13: Concreto | B13: 0.27 | C13: m³ / AC | D13: =B13*DADOS_INICIAIS!$E$9 -> 980.8506 | E13: m³ | F13: =(535+45+(1.67*0.6))*1.05 -> 610.0521 | G13: =F13*D13*1.05*1.1 -> 691117.31
A14: Armadura Convencional para Estrutura | B14: 100 | C14: kg / m³ | D14: =D13*B14 -> 98085.06 | E14: kg | F14: 7.62 | G14: =F14*D14*1.1 -> 822148.97
A15: Mão de obra - estrutura em concreto armado | B15: 290 | C15: R$ / AC | D15: =DADOS_INICIAIS!$E$9 -> 3632.78 | E15: m² | F15: =B15 -> 290 | G15: =F15*D15*1.05 -> 1106181.5
A16: Perfuração de vigas | B16: 2300 | C16: R$ / NP | D16: 1 | E16: vb | F16: =B16*DADOS_INICIAIS!$E$15 -> 16100 | G16: =F16*D16*1.1 -> 17710 | I16: Nova utiliza a verba de 1.500,00 por pav
A17: TOTAL | G17: =SUM(G10:G16) -> 3110208.5 | K17: =4160+1440+1120+2880+4800+91680+4000 -> 110080 | L17: =K17/21 -> 5241.9048
G18: =G17/'Obra '!$C$10 -> 856.15107
A19: SUPRAESTRUTURA - LAJE CUBETAS
A21: Descrição | B21: Parâmetro | D21: Quantidade | F21: Preço unitário | G21: Valor total | H21: Observação
A22: Fabricação forma | B22: 2 | C22: Jogos | D22: =(D23/DADOS_INICIAIS!$E$15)*B22 -> 1556.9057 | E22: m² | F22: 110 | G22: =F22*D22*1.1 -> 188385.59
A23: Montagem de forma | B23: 1.5 | C23: m² / AC | D23: =B23*DADOS_INICIAIS!$E$9 -> 5449.17 | E23: m² | F23: 2.5 | G23: =F23*D23*1.1 -> 14985.218
A24: Escoramento | B24: 4 | C24: un / APT*NPT | D24: =B24*'Obra '!D24*B22 -> 5079.52 | E24: um | F24: =4*8 -> 32 | G24: =F24*D24*1.1 -> 178799.1 | I24: 8 meses
A25: Cubetas | B25: 25 | C25: R$ / AC | D25: =H25 -> 1270 | E25: un | F25: =0.3*30*8 -> 72 | G25: =F25*D25*1.1 -> 100584 | H25: =ROUNDUP(DADOS_INICIAIS!E19*B22,0) -> 1270 | I25: 8 meses
A26: Concreto | B26: 0.25 | C26: m³ / AC | D26: =B26*DADOS_INICIAIS!$E$9 -> 908.195 | E26: m³ | F26: =(535+45+(1.67*0.6))*1.05 -> 610.0521 | G26: =F26*D26*1.1 -> 609450.89
A27: Armadura Convencional para Estrutura | B27: 90 | C27: kg / m³ | D27: =D26*B27 -> 81737.55 | E27: kg | F27: 7.62 | G27: =F27*D27*1.1 -> 685124.14
A28: Mão de obra - estrutura em concreto armado | B28: 290 | C28: R$ / AC | D28: =DADOS_INICIAIS!$E$9 -> 3632.78 | E28: m² | F28: =B28 -> 290 | G28: =F28*D28*1.05 -> 1106181.5
A29: Perfuração de vigas | B29: 2300 | C29: R$ / NP | D29: 1 | E29: vb | F29: =B29*DADOS_INICIAIS!$E$15 -> 16100 | G29: =F29*D29*1.1 -> 17710
A30: TOTAL | G30: =SUM(G22:G29) -> 2901220.5
G31: =G30/'Obra '!$C$10 -> 798.62267
A32: SUPRAESTRUTURA - LAJE TRELIÇADA
A34: Descrição | B34: Parâmetro | D34: Quantidade | F34: Preço unitário | G34: Valor total | H34: Observação
A35: Fabricação forma | B35: 2 | C35: Jogos | D35: =(D36/DADOS_INICIAIS!$E$15)*B35 -> 0 | E35: m² | F35: 85 | G35: =F35*D35*1.1 -> 0
A36: Montagem de forma | B36: 2.1 | C36: m² / AC | D36: =B36*DADOS_INICIAIS!E38 -> 0 | E36: m² | F36: 1.5 | G36: =F36*D36*1.1 -> 0
A37: Escoramento - Torre | B37: 2 | C37: un / APT*NPT | D37: =B37*DADOS_INICIAIS!E47*DADOS_INICIAIS!E44 -> 0 | E37: un | F37: 17 | G37: =F37*D37*1.1 -> 0
A38: Escoramento - Embasamento | B38: 2 | C38: un / AE | D38: =B38*DADOS_INICIAIS!E50 -> 0 | E38: un | F38: 17 | G38: =F38*D38*1.1 -> 0
A39: Cubetas | B39: 25 | C39: R$ / AC | D39: =B39*DADOS_INICIAIS!E38 -> 0 | E39: m³ | F39: =B39 -> 25 | G39: =F39*D39*1.1 -> 0
A40: Concreto | B40: 0.25 | C40: m³ / AC | D40: =B40*DADOS_INICIAIS!E38 -> 0 | E40: m³ | F40: =575 -> 575 | G40: =F40*D40*1.05*1.1 -> 0
A41: Armadura Convencional para Estrutura | B41: 110 | C41: kg / m³ | D41: =D40*B41 -> 0 | E41: kg | F41: 7.25 | G41: =F41*D41*1.1 -> 0
A42: Mão de obra - estrutura em concreto armado | B42: 240 | C42: R$ / AC | D42: =DADOS_INICIAIS!E38 -> 0 | E42: m² | F42: =B42 -> 240 | G42: =F42*D42*1.1 -> 0
A43: Perfuração de vigas | B43: 5300 | C43: R$ / NP | D43: 1 | E43: vb | F43: =B43*DADOS_INICIAIS!E43 -> 0 | G43: =F43*D43*1.1 -> 0 | H43: Coeficiente originário do Gran Torino (R$ 160,00/un)
A44: TOTAL | G44: =SUM(G35:G43) -> 0
A46: SUPRAESTRUTURA - LAJE PROTENDIDA
...

Sheet ALVENARIA
A3: PAREDES E PAINÉIS
A4: Data | B4: 45469
A5: Arquivo base | B5: -
A7: ALVENARIA
A9: Descrição | B9: Parâmetro | D9: Quantidade | F9: Preço unitário | G9: Valor total | H9: Observação | I9: MT | J9: MT Total | K9: MO | L9: MO Total
A10: Bloco de 09 | B10: 0.6 | C10: m² / AE | D10: =ARQUITETURA!D48 -> 128.07 | E10: m² | F10: 30.92 | G10: =F10*D10*1 -> 3959.9244 | I10: =F10 -> 30.92 | J10: =I10*$D10 -> 3959.9244 | L10: =K10*$D10 -> 0
A11: Bloco de 11,5 | B11: 0.6 | C11: m² / AE | D11: =ARQUITETURA!D49 -> 328.73 | E11: m² | F11: 35.67 | G11: =F11*D11*1 -> 11725.799 | I11: =F11 -> 35.67 | J11: =I11*$D11 -> 11725.799 | L11: =K11*$D11 -> 0
A12: Bloco de 14 | B12: 0.8 | C12: m² / AL | D12: =ARQUITETURA!D50+ARQUITETURA!D51 -> 4419.64 | E12: m² | F12: 41.18 | G12: =F12*D12*1 -> 182000.78 | I12: =F12 -> 41.18 | J12: =I12*$D12 -> 182000.78 | L12: =K12*$D12 -> 0
A13: Bloco de 19 | B13: 0.8 | C13: m² / AL | E13: m² | F13: 53.02 | G13: =F13*D13*1 -> 0 | I13: =F13 -> 53.02 | J13: =I13*$D13 -> 0 | L13: =K13*$D13 -> 0
A14: Alvenaria escadas | B14: 0.18 | C14: m² / AC | E14: m² | F14: 82.96 | G14: =F14*D14*1 -> 0 | I14: =F14 -> 82.96 | J14: =I14*$D14 -> 0 | L14: =K14*$D14 -> 0
A15: Alvenaria refratárias | B15: 1.75 | C15: m² * CHU | D15: ='Obra '!F18*B15 -> 36.75 | E15: m² | F15: 310 | G15: =F15*D15*1.1 -> 12531.75 | I15: =F15 -> 310 | J15: =I15*$D15 -> 11392.5 | L15: =K15*$D15 -> 0
A16: Cobogó | D16: =864*0.24*0.24 -> 49.7664 | E16: m² | F16: 309.525 | G16: =F16*D16*1.1 -> 16944.339 | I16: =F16 -> 309.525 | J16: =I16*$D16 -> 15403.945 | L16: =K16*$D16 -> 0
A17: Drywall tipo RU | B17: 1.65 | C17: m² / APT*(NPT+2ND) | E17: m² | F17: 270 | G17: =F17*D17*1 -> 0 | I17: =F17 -> 270 | J17: =I17*$D17 -> 0 | L17: =K17*$D17 -> 0 | M17: Terceiro
A18: Drywall tipo ST | B18: 1.65 | C18: m² / APT*(NPT+2ND) | D18: =ARQUITETURA!D54 -> 45.99 | E18: m² | F18: 250 | G18: =F18*D18*1 -> 11497.5 | I18: =F18 -> 250 | J18: =I18*$D18 -> 11497.5 | L18: =K18*$D18 -> 0 | M18: Terceiro
A19: Serviços complementares | B19: 12.5 | C19: R$ / m² | D19: =SUM(D10:D14) -> 4876.44 | E19: m² | F19: 10.6 | G19: =F19*D19*1.1 -> 56859.29 | I19: =F19 -> 10.6 | J19: =I19*$D19 -> 51690.264 | L19: =K19*$D19 -> 0
A20: Mão de obra | B20: 35 | C20: R$ / m² | D20: =SUM(D10:D14) -> 4876.44 | E20: m² | F20: 48 | G20: =F20*D20*1 -> 234069.12 | J20: =I20*$D20 -> 0 | K20: =F20 -> 48 | L20: =K20*$D20 -> 234069.12 | M20: Emp
A21: TOTAL | G21: =SUM(G10:G20) -> 529588.5
A23: ALVENARIA - DRYWALL
A25: Descrição | B25: Parâmetro | D25: Quantidade | F25: Preço unitário | G25: Valor total | H25: Observação
A26: Alvenaria embasamento | B26: 1 | C26: m² / AE | D26: =B26*DADOS_INICIAIS!$E$22 -> 674.15 | E26: m² | F26: 45 | G26: =F26*D26*1.1 -> 33370.425
A27: Alvenaria lazer | B27: 0.4 | C27: m² / AL | D27: =B27*DADOS_INICIAIS!$E$21 -> 189.516 | E27: m² | F27: 45 | G27: =F27*D27*1.1 -> 9381.042
A28: Alvenaria tipo | B28: 1.65 | C28: m² / APT*(NPT+2ND) | D28: =B28*(DADOS_INICIAIS!$E$19*(DADOS_INICIAIS!$E$16+DADOS_INICIAIS!$E$17))*0.4 -> 2095.302 | E28: m² | F28: 45 | G28: =F28*D28*1.1 -> 103717.45
A29: Drywall tipo | B29: 1.65 | C29: m² / APT*(NPT+2ND) | D29: =B29*(DADOS_INICIAIS!$E$19*(DADOS_INICIAIS!$E$16+DADOS_INICIAIS!$E$17))*0.6 -> 3142.953 | E29: m² | F29: 220 | G29: =F29*D29*1.1 -> 760594.63 | J29: =D29/(D33+D29) -> 0.42840366
A30: Alvenaria escadas | B30: 0.2 | C30: m² / AC | D30: =B30*DADOS_INICIAIS!$E$9 -> 726.556 | E30: m² | F30: 70 | G30: =F30*D30*1.1 -> 55944.812 | J30: =1-J29 -> 0.57159634
A31: Alvenaria cobertura / reservatório | B31: 0.8 | C31: m² / APT | D31: =B31*DADOS_INICIAIS!$E$19 -> 507.952 | E31: m³ | F31: 45 | G31: =F31*D31*1.1 -> 25143.624
A32: Alvenaria refratárias | B32: 1.75 | C32: m² * CHU | D32: ='SISTEMAS ESPECIAIS'!B10 -> 21 | E32: un | F32: 210 | G32: =F32*D32*1.1 -> 4851
A33: Serviços complementares | B33: 12.5 | C33: R$ / m² | D33: =D27+D28+D26+D30+D31 -> 4193.476 | E33: m² | F33: =B33 -> 12.5 | G33: =F33*D33*1.1 -> 57660.295
A34: Mão de obra | B34: 35 | C34: R$ / m² | D34: =D27+D28+D26+D30+D31 -> 4193.476 | E34: m² | F34: 35 | G34: =F34*D34*1.1 -> 161448.83
A35: TOTAL | G35: =SUM(G26:G34) -> 1212112.1
A38: TOTAL ALVENARIA | G38: =G21 -> 529588.5 | H38: =G38/DADOS_INICIAIS!E9 -> 145.7805
G41: =G38/1.1 -> 481444.09 | H41: =G41/DADOS_INICIAIS!E9 -> 132.52773

Sheet IMPERMEABILIZAÇÃO
A3: IMPERMEABILIZAÇÃO
A4: Data | B4: 45471
A5: Arquivo base | B5: -
A7: IMPERMEBAILIZAÇÃO
A9: Descrição | B9: Parâmetro | D9: Quantidade | F9: Preço unitário | G9: Valor total | H9: Observação
A10: Regularização de Superfície | B10: 25 | C10: R$ / m² | D10: =D14+D15 -> 1624.665 | E10: m² | F10: =7.69+25 -> 32.69 | G10: =F10*D10*1.1 -> 58421.329 | I10: Terceiro
A11: Poço do elevador | B11: 45 | C11: R$ / m² | D11: =(3.24+(7.2)*1.8) -> 16.2 | E11: m² | F11: 41 | G11: =F11*D11*1.1 -> 730.62 | I11: Terceiro
A12: Baldrames | B12: 30 | C12: R$ / m² | D12: =INFRAESTRUTURA!D28 -> 370.7825 | E12: m² | F12: 35 | G12: =F12*D12*1.1 -> 14275.126 | I12: Terceiro
A13: Ralos | D13: =SUM('Obra '!N21:N31) -> 100 | E13: un | F13: 80 | G13: =F13*D13*1.1 -> 8800 | I13: Terceiro
A14: Impermeabilizações cimenticias | B14: 0.25 | C14: m² / AC | D14: =B14*DADOS_INICIAIS!E9 -> 908.195 | E14: m² | F14: 60 | G14: =F14*D14*1.1 -> 59940.87 | I14: Terceiro
A15: Impermeabilizações com manta asfaltica | B15: 0.11 | C15: m² / AC | D15: ='Obra '!D27+'Obra '!D22*0.2+'Acabamentos de Piso e Parede'!B18 -> 716.47 | E15: m² | F15: 110 | G15: =F15*D15*1.1 -> 86692.87 | I15: Terceiro
A16: Impermeabilização de peitoril | B16: 0.6 | C16: R$ / AC | D16: 1 | E16: vb | F16: =B16*DADOS_INICIAIS!$E$9 -> 2179.668 | G16: =F16*D16*1.1 -> 2397.6348 | I16: Terceiro
A17: Proteção Mecânica | B17: 28 | C17: R$ / m² | D17: =D15 -> 716.47 | E17: m² | F17: =42.3+35 -> 77.3 | G17: =F17*D17*1.1 -> 60921.444 | I17: Terceiro
A18: TOTAL | G18: =SUM(G10:G17) -> 292179.89
A20: TOTAL IMPERMEABILIZAÇÃO | G20: =G18 -> 292179.89 | H20: =G20/DADOS_INICIAIS!E9 -> 80.428733
H23: =H20/1.1 -> 73.11703
F24: =SUM('Obra '!N21:N31) -> 100

Sheet INSTALAÇÕES
A2: INSTALAÇÕES
A4: INSTALAÇÕES ELÉTRICAS
A6: Descrição | B6: Parâmetro | D6: Valor total
A7: Entrada de Energia | B7: 5.5 | C7: R$ / AC | D7: =B7*DADOS_INICIAIS!$E$9*1.1 -> 21978.319
A8: Eletrodutos e Eletrocalhas | B8: 10 | C8: R$ / AC | D8: =B8*DADOS_INICIAIS!$E$9*1.1 -> 39960.58
A9: Cabos e Fiações | B9: 30 | C9: R$ / AC | D9: =B9*DADOS_INICIAIS!$E$9*1.1 -> 119881.74
A10: Quadros e Disjuntores | B10: 18 | C10: R$ / AC | D10: =B10*DADOS_INICIAIS!$E$9*1.1 -> 71929.044
A11: Acabamentos Elétricos | B11: 15 | C11: R$ / AC | D11: =B11*DADOS_INICIAIS!$E$9*1.1 -> 59940.87
A12: Equipamentos e Iluminação | B12: 15 | C12: R$ / AC | D12: =B12*DADOS_INICIAIS!$E$9*1.1 -> 59940.87
A13: Mão de Obra para Instalações Elétricas | B13: 60 | C13: R$ / AC | D13: =B13*DADOS_INICIAIS!$E$9*1.1 -> 239763.48
A14: TOTAL | D14: =SUM(D7:D13) -> 613394.9 | E14: =D14/'Obra '!$C$10 -> 168.85
A16: INSTALAÇÕES HIDROSSANITÁRIAS
A18: Descrição | B18: Parâmetro | D18: Valor total
A19: Instalações de Água Fria | B19: 25 | C19: R$ / AC | D19: =B19*DADOS_INICIAIS!$E$9*1.1 -> 99901.45
A20: Instalações de Água Quente | B20: 20 | C20: R$ / AC | D20: =B20*DADOS_INICIAIS!$E$9*1.1 -> 79921.16
A21: Instalações de Águas Pluviais | B21: 10 | C21: R$ / AC | D21: =B21*DADOS_INICIAIS!$E$9*1.1 -> 39960.58
A22: Instalações Sanitárias | B22: 15 | C22: R$ / AC | D22: =B22*DADOS_INICIAIS!$E$9*1.1 -> 59940.87
A23: Louças e Metais | B23: 22 | C23: R$ / AC | D23: =B23*DADOS_INICIAIS!$E$9*1.1 -> 87913.276
A24: Mão de Obra para Instalações Hidráulicas | B24: 55 | C24: R$ / AC | D24: =B24*DADOS_INICIAIS!$E$9*1.1 -> 219783.19
A25: TOTAL | D25: =SUM(D19:D24) -> 587420.53 | E25: =D25/'Obra '!$C$10 -> 161.7
A27: INSTALAÇÕES PREVENTIVAS E GLP
A29: Descrição | B29: Parâmetro | D29: Valor total
A30: Instalações Preventivas | B30: 20 | C30: R$ / AC | D30: =B30*DADOS_INICIAIS!$E$9*1.1 -> 79921.16 | E30: =D30/'Obra '!$C$10 -> 22
A31: Instalações Sprinklers | B31: =95+35 -> 130 | C31: R$ / AC | D31: =B31*DADOS_INICIAIS!$E$9*1.1*0 -> 0 | E31: =D31/'Obra '!$C$10 -> 0 | F31: Estimado com Base no Redentor
A32: Instalações de GLP | B32: 15 | C32: R$ / AC | D32: =B32*DADOS_INICIAIS!$E$9*1.1 -> 59940.87 | E32: =D32/'Obra '!$C$10 -> 16.5
A33: Instalações de Proteção e Aterramento - SPDA | B33: 8 | C33: R$ / AC | D33: =B33*DADOS_INICIAIS!$E$9*1.1 -> 31968.464 | E33: =D33/'Obra '!$C$10 -> 8.8
A34: TOTAL | D34: =SUM(D30:D33) -> 171830.49 | H34: =D34*0.4 -> 68732.198
A36: TOTAL INSTALAÇÕES | D36: =D14+D25+D34 -> 1372645.9 | E36: =D36/DADOS_INICIAIS!E9 -> 377.85
E38: =E36/1.1 -> 343.5

Sheet SISTEMAS ESPECIAIS
A2: SISTEMAS ESPECIAIS
A4: CLIMATIZAÇÃO, EXAUSTÃO MECÂNICA E PRESSURIZAÇÃO
A6: Descrição | B6: Quantidade | C6: Preço Unitário | D6: Valor total
A7: Infraestrutura para Instalação de Ar Condicionado | B7: =SUM('Obra '!L21:L31) -> 75 | C7: 1200 | D7: =B7*C7*1.1 -> 99000
A8: Instalação de Ar Condicionado | B8: =SUM('Obra '!M21:M31) -> 9 | C8: 5000 | D8: =B8*C8*1.1 -> 49500
A9: Ventokit | B9: =SUM('Obra '!K21:K31) -> 26 | C9: 900 | D9: =B9*C9*1.1 -> 25740
A10: Churrasqueiras | B10: ='Obra '!F18 -> 21 | C10: 2600 | D10: =B10*C10*1.1 -> 60060
A11: TOTAL | D11: =SUM(D7:D10) -> 234300
A13: COMUNICAÇÃO
A15: Descrição | B15: Parâmetro | D15: Valor total
A16: CFTV | B16: 1.5 | C16: R$ / AC | D16: =B16*DADOS_INICIAIS!$E$9*1.1 -> 5994.087
A17: Interfone | B17: 2 | C17: R$ / AC | D17: =B17*DADOS_INICIAIS!$E$9*1.1 -> 7992.116
A18: TV e internet | B18: 4 | C18: R$ / AC | D18: =B18*DADOS_INICIAIS!$E$9*1.1 -> 15984.232
A19: Automação, telecomunicação e sistemas de segurança | B19: 5 | C19: R$ / AC | D19: =B19*DADOS_INICIAIS!$E$9*1.1 -> 19980.29
A20: TOTAL | D20: =SUM(D16:D19) -> 49950.725
A22: EQUIPAMENTOS
A24: Descrição | B24: Quantidade | C24: Preço Unitário | D24: Valor total
A25: Elevadores | B25: 1 | C25: =266000/12*7 -> 155166.67 | D25: =B25*C25*1.1 -> 170683.33
A26: Grupo de geradores | B26: 0 | C26: 60000 | D26: =B26*C26*1.1 -> 0
A27: Pressurização de escada | B27: 0 | C27: =26.4*DADOS_INICIAIS!E9 -> 95905.392 | D27: =B27*C27*1.1 -> 0
A28: Bombas | B28: 1 | C28: 10000 | D28: =B28*C28*1.1 -> 11000
A29: Infra de carro elétrico | B29: 0 | C29: 560 | D29: =B29*C29*1.1 -> 0
A30: Equipamento Carro Elétrico | B30: 0 | C30: 43000 | D30: =B30*C30*1.1 -> 0
A31: Equipamento de piscina | B31: 1 | C31: =39684-15000 -> 24684 | D31: =B31*C31*1.1 -> 27152.4
A32: Subestação de Energia | B32: 0 | C32: 238000 | D32: =B32*C32*1.1 -> 0
A33: Estaçao de tratamento de esgoto | B33: 1 | C33: 105000 | D33: =B33*C33*1.1 -> 115500
A34: Sauna | B34: 1 | C34: 8500 | D34: =B34*C34*1.1 -> 9350
A35: Spa | C35: 15000 | D35: =B35*C35*1.1 -> 0
A36: Sistema de aquecimento | B36: 0 | C36: =55*DADOS_INICIAIS!E9 -> 199802.9 | D36: =B36*C36 -> 0
A37: TOTAL | D37: =SUM(D25:D36) -> 333685.73
A39: OUTROS SISTEMAS ESPECIAIS
A41: Descrição | B41: Parâmetro | D41: Valor total
A42: Outros sistemas | B42: 20 | C42: R$ / AC | D42: =B42*DADOS_INICIAIS!E9*1.1 -> 79921.16
A43: TOTAL | D43: =SUM(D42:D42) -> 79921.16
A45: TOTAL SISTEMAS ESPECIAIS | D45: =D11+D20+D37+D43 -> 697857.62 | E45: =D45/DADOS_INICIAIS!E9 -> 192.10016

Sheet ARQUITETURA
A1: DADOS
A2: Titulo | B2: QUANTITATIVO
A3: Obra
A4: Cliente
A5: Cidade
A6: Endereço
A7: Descrição
A9: QUANTITATIVOS
A10: Item | B10: Descrição | C10: Unid. | D10: Quantidade
A12: 1. | B12: GERAL CORRIMAO
A13: 1.1. | B13: Corrimão
A14: 1.1.1 | B14: Guarda-corpo:GUARDACORPO AR CONDICIONADO | C14: m | D14: 58.85
A15: 1.1.2 | B15: Guarda-corpo:GUARDACORPO SACADA | C15: m | D15: 135.6
A16: 2. | B16: GERAL ESCADAS
A17: 2.1. | B17: Escada
A18: 2.1.1 | B18: Escada moldada no local:D_18x28 | C18: m²
A19: 3. | B19: GERAL FORRO
A20: 3.1. | B20: Revestimento
A21: 3.1.1 | B21: Forro básico:D_Película | C21: m² | D21: 147.09
A22: 4. | B22: GERAL JANELAS
A23: 4.1. | B23: Janela | G23: =SUM(G24:G37) -> 377.7302
A24: 4.1.1 | B24: JANELA _1F+FIXA:JANELA _1F+FIXA_120x200 | C24: un | D24: 3 | E24: 1.2 | F24: 2 | G24: =F24*D24*E24 -> 7.2
A25: 4.1.2 | B25: JANELA _1F+FIXA:JANELA _1F+FIXA_60x130 | C25: un | D25: 14 | E25: 0.6 | F25: 1.3 | G25: =F25*D25*E25 -> 10.92
A26: 4.1.3 | B26: JANELA _1F+FIXA:JANELA _1F+FIXA_60x200 | C26: un | D26: 6 | E26: 0.6 | F26: 2 | G26: =F26*D26*E26 -> 7.2
A27: 4.1.4 | B27: JANELA _1F:JANELA _1F_240x60 | C27: un | D27: 7 | E27: 2.4 | F27: 0.6 | G27: =F27*D27*E27 -> 10.08
A28: 4.1.5 | B28: JANELA _1F:JANELA _1F_60x80 | C28: un | D28: 5 | E28: 0.6 | F28: 0.8 | G28: =F28*D28*E28 -> 2.4
A29: 4.1.6 | B29: JANELA _1F:JANELA _1F_80x243 | C29: un | D29: 6 | E29: 0.8 | F29: 1.94 | G29: =F29*D29*E29 -> 9.312
A30: 4.1.7 | B30: JANELA _2F+FIXA:JANELA _2F+FIXA_240x194 | C30: un | D30: 15 | E30: 2.4 | F30: 2.43 | G30: =F30*D30*E30 -> 87.48
A31: 4.1.8 | B31: JANELA _2F:JANELA _2F_200X243 | C31: un | D31: 4 | E31: 2 | F31: 1.3 | G31: =F31*D31*E31 -> 10.4
A32: 4.1.9 | B32: JANELA _2F:JANELA _2F_240x130 | C32: un | D32: 17 | E32: 2.4 | F32: 2.43 | G32: =F32*D32*E32 -> 99.144
A33: 4.1.10 | B33: JANELA _2F:JANELA _2F_240x243 | C33: un | D33: 22 | E33: 2.4 | F33: 0.6 | G33: =F33*D33*E33 -> 31.68
A34: 4.1.11 | B34: JANELA _2F:JANELA _2F_240x60 | C34: un | D34: 2 | E34: 2.4 | F34: 2.43 | G34: =F34*D34*E34 -> 11.664
A35: 4.1.12 | B35: JANELA _3F:JANELA _3F_338x243 | C35: un | D35: 3 | E35: 3.38 | F35: 2.43 | G35: =F35*D35*E35 -> 24.6402
... A37: 4.1.14 | B37: JANELA _3F:JANELA _3F_420x243 | C37: un | D37: 3 | E37: 4.2 | F37: 2.43 | G37: =F37*D37*E37 -> 30.618
A38: 5. | B38: GERAL LANCE ESCADAS
A39: 5.1. | B39: Lance de escada
A40: 5.1.1 | B40: Lance monolítico:10 mm Tread 10 mm Riser | C40: m² | D40: 57.74
A41: 6. | B41: GERAL MEMBRO
A42: 6.1. | B42: Membro
A43: 6.1.1 | B43: Montante retangular:D_3x0.5 Metal_PRETO | C43: m² | D43: 3.42
...

Sheet Rev. Internos Piso e Parede
A2: ORÇAMENTO PARAMÉTRICO GERENCIAMENTO EXECUTIVO
A7: Cliente
A8: Obra
A9: Data | B9: 45471
A10: Revisão | B10: R00
A12: REVESTIMENTOS INTERNOS EM PISO E PAREDE
A14: Descrição | B14: Quantidade | D14: Parâmetro | F14: Referência | G14: Valor total | I14: MT | J14: MT Total | K14: MO | L14: MO Total
A15: Polimento de concreto | B15: =ARQUITETURA!D64 -> 653.55 | C15: m² | D15: 16.5 | E15: R$ / m² | F15: Média | G15: =D15*B15*1.1 -> 11861.932 | J15: =I15*$B15 -> 0 | L15: =K15*$B15 -> 0
A16: Piso alisado | B16: =12.08*'Obra '!F10 -> 84.56 | C16: m² | D16: 25 | E16: R$ / m² | F16: Média | G16: =D16*B16*1.1 -> 2325.4 | H16: escada | J16: =I16*$B16 -> 0 | L16: =K16*$B16 -> 0
A17: Contrapiso | B17: =ARQUITETURA!D68+ARQUITETURA!D67 -> 3894.56 | C17: m² | D17: =B17/DADOS_INICIAIS!E9 -> 1.0720605 | E17: m² / AC | F17: Média | G17: =+B17*65*1.05 -> 265803.72 | I17: =65*1.05-K17 -> 28.25 | J17: =I17*$B17 -> 110021.32 | K17: 40 | L17: =K17*$B17 -> 155782.4
A18: Manta acústica | B18: ='Obra '!C12 -> 2064.55 | C18: m² | D18: =B18/DADOS_INICIAIS!E9 -> 0.56831132 | E18: m² / AC | F18: Média | G18: =+B18*26*1.05 -> 56362.215 | I18: =26*1.05 -> 27.3 | J18: =I18*$B18 -> 56362.215 | L18: =K18*$B18 -> 0
A19: Chapisco | B19: =ALVENARIA!D20*2-('Rev. Fachada'!B15) -> 8170.7312 | C19: m² | D19: =B19/DADOS_INICIAIS!E9 -> 2.2491676 | E19: m² / AC | F19: Média | G19: =+B19*5*1.05 -> 42896.339 | I19: =5*1.05 -> 5.25 | J19: =I19*$B19 -> 42896.339 | L19: =K19*$B19 -> 0
A20: Reboco | B20: =B19 -> 8170.7312 | C20: m² | D20: =B20/DADOS_INICIAIS!E9 -> 2.2491676 | E20: m² / AC | F20: Média | G20: =50*B20*1.05 -> 428963.39 | I20: =50*1.05-K20 -> 17.5 | J20: =I20*$B20 -> 142987.8 | K20: 35 | L20: =K20*$B20 -> 285975.59
A21: TOTAL | G21: =SUM(G15:G20) -> 808212.99 | L21: =L20+L17 -> 441757.99
A24: TOTAL REVESTIMENTOS | G24: =G21 -> 808212.99 | H24: =G24/DADOS_INICIAIS!E9 -> 222.47783
H26: =H24/1.1 -> 202.25257

Sheet TETO
A3: REVESTIMENTOS E ACABAMENTOS DE TETO
A4: Data | B4: 45471
A5: Arquivo base | B5: -
A7: ALVENARIA
A9: Descrição | B9: Parâmetro | D9: Quantidade | F9: Preço unitário | G9: Valor total | H9: Observação | J9: MT | K9: MT Total | L9: MO | M9: MO Total
A10: Forro gesso Acartonado ST | B10: 0.6 | C10: m² / AC | D10: ='Obra '!C14+'Obra '!C12-D11 -> 2338.42 | E10: m² | F10: 110 | G10: =F10*D10*1 -> 257226.2 | J10: =F10*1 -> 110 | K10: =J10*$D10 -> 257226.2 | M10: =L10*$D10 -> 0
A11: Forro gesso Acartonado RU | B11: 0.6 | C11: m² / AC | D11: ='Obra '!C18*3.92 -> 199.92 | E11: m² | F11: 120 | G11: =F11*D11*1 -> 23990.4 | J11: =F11*1 -> 120 | K11: =J11*$D11 -> 23990.4 | M11: =L11*$D11 -> 0
A12: Estucamento | B12: 0.2 | C12: m² / AC | D12: ='Obra '!D21+'Obra '!D28+'Rev. Internos Piso e Parede'!B16 -> 772.91 | E12: m² | F12: 24 | G12: =F12*D12*1 -> 18549.84 | H12: Garagem, barrilete e escadas | J12: =F12*1-L12 -> 4 | K12: =J12*$D12 -> 3091.64 | L12: 20 | M12: =L12*$D12 -> 15458.2
A13: Tratamento de concreto Aparente | B13: 1.2 | C13: m / FORRO | E13: m² | F13: 47 | G13: =F13*D13*1 -> 0 | J13: =F13*1-L13 -> 17 | K13: =J13*$D13 -> 0 | L13: 30 | M13: =L13*$D13 -> 0
A14: TOTAL | G14: =SUM(G10:G13) -> 299766.44
A16: TOTAL FORRO | G16: =G14 -> 299766.44 | H16: =G16/DADOS_INICIAIS!E9 -> 82.517092

Sheet Acabamentos de Piso e Parede
A2: ORÇAMENTO PARAMÉTRICO GERENCIAMENTO EXECUTIVO
A7: Cliente
A8: Obra
A9: Data | B9: 45471
A10: Revisão | B10: R00
A12: ACABAMENTOS EM PISO E PAREDE
A14: Descrição | B14: Quantidade | D14: Parâmetro | F14: Referência | G14: Valor total | I14: MT | J14: MT Total | K14: MO | L14: MO Total
A15: Piso Cerâmico Garagens | C15: m² | D15: =40*1.1+1.75*8.5+8*0.5+60 -> 122.875 | E15: R$ / m² | F15: Média | G15: =+D15*B15*1 -> 0 | I15: =40*1.1+1.75*8.5+8*0.5 -> 62.875 | J15: =I15*$B15 -> 0 | K15: =60 -> 60 | L15: =K15*$B15 -> 0 | M15: Emp
A16: Piso Cerâmico halls, Circulaçõa, áreas Comuns e banheiros unidades | B16: =TETO!D11+TETO!D10 -> 2538.34 | C16: m² | D16: =55*1.1+1.75*8.5+8*0.5+60 -> 139.375 | E16: R$ / m² | F16: Média | G16: =+D16*B16*1.05 -> 371470.19 | I16: =55*1.1+1.75*8.5+8*0.5 -> 79.375 | J16: =I16*$B16 -> 201480.74 | K16: =60 -> 60 | L16: =K16*$B16 -> 152300.4 | M16: Emp
A17: Vinilico | C17: m² | D17: 160 | E17: R$ / m² | F17: Média | G17: =+D17*B17*1 -> 0 | I17: 160 | J17: =I17*$B17 -> 0 | L17: =K17*$B17 -> 0 | M17: Terceirizado
A18: Piscina | B18: =63.05+(3.14+1.63+12.5)*2*1.5 -> 114.86 | C18: m² | D18: =110*1.1+1.8*8.5+9*0.5+60 -> 200.8 | E18: R$ / m² | F18: Média | G18: =+D18*B18*1 -> 23063.888 | I18: =110*1.1+1.8*8.5+9*0.5 -> 140.8 | J18: =I18*$B18 -> 16172.288 | K18: =60 -> 60 | L18: =K18*$B18 -> 6891.6 | M18: Emp
A19: Ladrilho Hidraulico Rampa | B19: =ARQUITETURA!D65+ARQUITETURA!D66 -> 137.66 | C19: m² | D19: 60 | E19: R$ / m² | F19: Média | G19: =+D19*B19*1.05 -> 8672.58 | I19: 30 | J19: =I19*$B19 -> 4129.8 | K19: 30 | L19: =K19*$B19 -> 4129.8 | M19: Emp
A20: Paver | B20: =ARQUITETURA!D70 -> 679.88 | C20: m² | D20: 60 | E20: R$ / m² | F20: Média | G20: =+D20*B20*1.05 -> 42832.44 | I20: 30 | J20: =I20*$B20 -> 20396.4 | K20: 30 | L20: =K20*$B20 -> 20396.4 | M20: Emp
A21: Rodapés | B21: =SUM(B15:B17)*1.2 -> 3046.008 | C21: m | D21: =35+20 -> 55 | E21: R$ / AC | F21: Média | G21: =D21*B21*1.05 -> 175906.96 | I21: 35 | J21: =I21*$B21 -> 106610.28 | K21: 20 | L21: =K21*$B21 -> 60920.16 | M21: Emp
A22: Soleiras e peitoris | B22: 1 | C22: vb | D22: 20 | E22: R$ / AC | F22: Média | G22: =D22*DADOS_INICIAIS!$E$9*1.1 -> 79921.16 | J22: =G22*0.6 -> 47952.696 | L22: =G22*0.4 -> 31968.464
A23: Revestimentos de Parede | B23: =(2.8*2+1.4*2)*3.06*'Obra '!C18 -> 1310.904 | C23: m2 | D23: =65*1.1+1.75*8.5+8*0.5+60 -> 150.375 | E23: R$ / AC | F23: Média | G23: =D23*B23*1.1 -> 216839.91 | I23: =65*1.1+1.75*8.5+8*0.5 -> 90.375 | J23: =I23*$B23 -> 118472.95 | K23: 60 | L23: =K23*$B23 -> 78654.24 | M23: Emp
A24: =20*40 -> 800 | G24: =SUM(G15:G23) -> 918707.13 | L24: =SUM(L15:L23) -> 355261.06
A27: TOTAL ACABAMENTOS | G27: =G24 -> 918707.13 | H27: =G27/DADOS_INICIAIS!E9 -> 252.89369
H29: =H27/1.1 -> 229.90335

Sheet PINTURA INTERNA
A3: PINTURA INTERNA
A4: Data | B4: 45457
A5: Arquivo base | B5: -
A7: ALVENARIA
A9: Descrição | B9: Parâmetro | D9: Quantidade | F9: Preço unitário | G9: Valor total | H9: Observação | I9: MT | J9: MT Total | K9: MO | L9: MO Total
A10: Pintura piso epoxi | B10: 110 | C10: R$ / m² | D10: ='Rev. Internos Piso e Parede'!B15 -> 653.55 | E10: m² | F10: 110 | G10: =F10*D10*1.1 -> 79079.55
A11: Pintura acrílica antiderrapante | B11: 65 | C11: R$ / m² | D11: ='Rev. Internos Piso e Parede'!B16 -> 84.56 | E11: m² | F11: 65 | G11: =F11*D11*1.1 -> 6046.04
A12: Textura estucamento | B12: 26 | C12: R$ / AC | D12: =TETO!D12 -> 772.91 | E12: m² | F12: =12+35 -> 47 | G12: =F12*D12*1 -> 36326.77 | I12: 12 | J12: =I12*$D12 -> 9274.92 | K12: 35 | L12: =K12*$D12 -> 27051.85 | M12: Emp
A13: Pintura Interna Paredes | D13: ='Rev. Internos Piso e Parede'!B20-'Acabamentos de Piso e Parede'!B23+ALVENARIA!D18 -> 6905.8172 | E13: m² | F13: =19+40 -> 59 | G13: =F13*D13 -> 407443.21 | I13: 19 | J13: =I13*$D13 -> 131210.53 | K13: 40 | L13: =K13*$D13 -> 276232.69 | M13: Emp
A14: Pintura Interna Teto | D14: =TETO!D10+TETO!D11 -> 2538.34 | E14: m² | F14: =F13 -> 59 | G14: =F14*D14 -> 149762.06 | I14: 19 | J14: =I14*$D14 -> 48228.46 | K14: 40 | L14: =K14*$D14 -> 101533.6 | M14: Emp
A15: TOTAL | G15: =SUM(G10:G14) -> 678657.63 | L15: =SUM(L10:L14) -> 404818.14
A17: TOTAL IMPERMEABILIZAÇÃO | G17: =G15 -> 678657.63 | H17: =G17/DADOS_INICIAIS!E9 -> 186.81496
H19: =H17/1.1 -> 169.83178
G22: =4160+1440+1120+2880+4800+91680+4000 -> 110080 | H22: =G22/21 -> 5241.9048

Sheet ESQUADRIAS
A3: ESQUADRIAS
A4: Data | B4: 45460
A5: Arquivo base | B5: -
A7: ESQUADRIAS
A9: Descrição | B9: Parâmetro | D9: Quantidade | G9: Valor total | H9: Observação | I9: MT | J9: MT Total | K9: MO | L9: MO Total
A10: Esquadrias de Alumínio | B10: 0.2 | C10: m² / AC | D10: =ARQUITETURA!G23 -> 377.7302 | E10: m² | F10: 1290 | G10: =F10*D10*1 -> 487271.96 | I10: =F10 -> 1290 | J10: =I10*$D10 -> 487271.96 | L10: =K10*$D10 -> 0 | M10: Terceiro
A11: Pele de vidro | D11: =ARQUITETURA!D74-D14 -> 376.17 | E11: m² | F11: 980 | G11: =F11*D11*1 -> 368646.6 | H11: lojas | I11: =F11 -> 980 | J11: =I11*$D11 -> 368646.6 | L11: =K11*$D11 -> 0 | M11: Terceiro
A12: Brise | D12: =(0.96)*'Obra '!G22 -> 6.2208 | E12: m² | F12: 950 | G12: =F12*D12*1 -> 5909.76 | I12: =F12 -> 950 | J12: =I12*$D12 -> 5909.76 | L12: =K12*$D12 -> 0 | M12: Terceiro
A13: Portão de alumínio ripado | D13: 2 | E13: un | F13: 16000 | G13: =F13*D13*1 -> 32000 | I13: =F13 -> 16000 | J13: =I13*$D13 -> 32000 | L13: =K13*$D13 -> 0 | M13: Terceiro
A14: Guarda-corpo - vidro | D14: =ARQUITETURA!D15*0.95 -> 128.82 | E14: m² | F14: =750*1.1 -> 825 | G14: =F14*D14*1 -> 106276.5 | I14: =F14 -> 825 | J14: =I14*$D14 -> 106276.5 | L14: =K14*$D14 -> 0 | M14: Terceiro
A15: Gradil | D15: =ARQUITETURA!D14*1 -> 58.85 | E15: m² | F15: 610 | G15: =F15*D15*1 -> 35898.5 | I15: =F15 -> 610 | J15: =I15*$D15 -> 35898.5 | L15: =K15*$D15 -> 0 | M15: Terceiro
A16: Serralherias | B16: 5 | C16: R$ / AC | D16: 1 | E16: vb | F16: =B16*DADOS_INICIAIS!$E$9 -> 18163.9 | G16: =F16*D16*1.1 -> 19980.29 | I16: =F16*1.1 -> 19980.29 | J16: =I16*$D16 -> 19980.29 | L16: =K16*$D16 -> 0 | M16: Emp
A17: PCF | D17: =ARQUITETURA!D77 -> 9 | E17: un | F17: 1750 | G17: =F17*D17*1 -> 15750 | I17: =F17-K17 -> 1450 | J17: =I17*$D17 -> 13050 | K17: 300 | L17: =K17*$D17 -> 2700 | M17: Emp
A18: Corrimão madeira | D18: =(7.36*2+2.64+2*2.24)*'Obra '!F10*1.2 -> 183.456 | E18: m | F18: 85 | G18: =F18*D18*1 -> 15593.76 | I18: =F18 -> 85 | J18: =I18*$D18 -> 15593.76 | L18: =K18*$D18 -> 0 | M18: Terceiro
A19: Fechadura Biometrica | D19: =DADOS_INICIAIS!E10 -> 20 | E19: un | F19: 1500 | G19: =F19*D19*1 -> 30000 | H19: Fechadura consideraeda no Coline é de 1500,00 | I19: =F19 -> 1500 | J19: =I19*$D19 -> 30000 | L19: =K19*$D19 -> 0 | M19: Terceiro
A20: Esquadrias de Madeira | D20: =ARQUITETURA!D78+ARQUITETURA!D79+ARQUITETURA!D80+ARQUITETURA!D81 -> 125 | E20: un | F20: 2100 | G20: =F20*D20*1 -> 262500 | I20: =F20-K20 -> 1800 | J20: =I20*$D20 -> 225000 | K20: 300 | L20: =K20*$D20 -> 37500 | M20: Emp
A21: TOTAL | G21: =SUM(G10:G20) -> 1379827.4 | L21: =SUM(L10:L20) -> 40200
A23: TOTAL ESQUADRIAS | G23: =G21 -> 1379827.4 | H23: =G23/DADOS_INICIAIS!E9 -> 379.82685

Sheet COBERTURA
A2: COBERTURA
A3: Data | B3: 45460
A4: Arquivo base | B4: -
A6: TELHADO
A8: Descrição | B8: Parâmetro | D8: Quantidade | F8: Preço unitário | G8: Valor total | H8: Observação
A9: Estrutura e telhamento | D9: 266.19 | E9: m² | F9: 500 | G9: =F9*D9*1.1 -> 146404.5
A10: Serviços complementares | D10: =D9 -> 266.19 | E10: m² | F10: 45 | G10: =F10*D10*1.1 -> 13176.405
A11: Pergolados | G11: =F11*D11*1.1 -> 0
A12: Passarelas | G12: =F12*D12*1.1 -> 0
A13: TOTAL | G13: =SUM(G9:G12) -> 159580.9
A15: TOTAL COMPLEMENTARES | G15: =G13 -> 159580.9 | H15: =G15/DADOS_INICIAIS!$E$9 -> 43.92804

Sheet Rev. Fachada
A2: ORÇAMENTO PARAMÉTRICO GERENCIAMENTO EXECUTIVO
A7: Cliente | B7: Passe
A8: Obra | B8: Connect
A9: Data | B9: 45460
A10: Revisão | B10: R00
A12: REVESTIMENTOS ARGAMASSADOS
A14: Descrição | B14: Quantidade | D14: Parâmetro | F14: Referência | G14: Valor total | I14: MT | J14: MT Total | K14: MO | L14: MO Total | O14: Versão Sem Fachada Ventilada Com Textura Comum
A15: Chapisco e reboco | B15: ='Obra '!F22*'Obra '!G22+'Obra '!F24*'Obra '!G24+'Obra '!F25*'Obra '!G25+'Obra '!F26*'Obra '!G26+'Obra '!F27*'Obra '!G27+'Obra '!F28*'Obra '!G28+'Obra '!F29*'Obra '!G29-ESQUADRIAS!D10-ESQUADRIAS!D11 -> 1582.1488 | C15: m² | D15: =25+80 -> 105 | E15: R$ / m² | F15: - | G15: =B15*D15*1.05 -> 174431.91 | I15: 25 | J15: =I15*$B15 -> 39553.72 | K15: 80 | L15: =K15*$B15 -> 126571.9 | M15: Emp | O15: Descrição | P15: Qtdade | Q15: Custo Unit | R15: Custo Total
A16: Chapisco e reboco abas | B16: =B17*0.6*2 -> 750.516 | C16: m² | D16: =25+80 -> 105 | E16: R$ / m² | F16: - | G16: =B16*D16*1.05 -> 82744.389 | I16: 25 | J16: =I16*$B16 -> 18762.9 | K16: 80 | L16: =K16*$B16 -> 60041.28 | M16: Emp | O16: Descrição | P16: Qtdade | Q16: Custo Unit | R16: Custo Total
A17: Trtamento de friso | B17: =SUM('Obra '!F22:F29) -> 625.43 | C17: m | D17: 5 | E17: R$ / m² | F17: - | G17: =B17*D17*1.1 -> 3439.865 | O17: Chapisco e reboco | P17: =B15 -> 1582.1488 | Q17: =D15*1.1 -> 115.5 | R17: =Q17*P17 -> 182738.19
A18: TOTAL | G18: =SUM(G15:G17) -> 260616.16 | O18: Textura | P18: =P17 -> 1582.1488 | Q18: =D24*1.1 -> 99 | R18: =Q18*P18 -> 156632.73
R19: =SUM(R17:R18) -> 339370.92 | S19: =R19/DADOS_INICIAIS!$E$9 -> 93.419067
A20: PINTURA
A22: Descrição | B22: Quantidade | D22: Parâmetro | F22: Referência | G22: Valor total
A23: Selador | B23: =B16+B15*0.3 -> 1225.1606 | C23: m² | D23: =0.16*17+20 -> 22.72 | E23: R$ / m² | F23: - | G23: =B23*D23*1 -> 27835.65 | H23: =4/8 -> 0.5 | I23: =0.16*17 -> 2.72 | J23: =I23*$B23 -> 3332.4369 | K23: 20 | L23: =K23*$B23 -> 24503.213 | M23: Emp
A24: Textura | B24: =B23 -> 1225.1606 | C24: m² | D24: =30+60 -> 90 | E24: R$ / m² | F24: - | G24: =B24*D24*1 -> 110264.46 | H24: =1/8 -> 0.125 | I24: 25 | J24: =I24*$B24 -> 30629.016 | K24: 52 | L24: =K24*$B24 -> 63708.353 | M24: Emp
A25: Pastilha | B25: =B15*0.3 -> 474.64464 | C25: m² | D25: =110*1.1+1.8*8.5+9*0.5+80 -> 220.8 | E25: R$ / m² | F25: - | G25: =B25*D25*1.1 -> 115281.69 | H25: =4/8 -> 0.5 | K25: 80 | L25: =K25*$B25 -> 37971.571 | M25: Emp
A26: Porcelanato amadeirado | B26: =B15*0.4 -> 632.85952 | C26: m² | D26: =D25 -> 220.8 | E26: R$ / m² | F26: - | G26: =B26*D26*1.1 -> 153708.92 | K26: 80 | L26: =K26*$B26 -> 50628.762 | M26: Terceiro
A27: TOTAL | G27: =SUM(G23:G26) -> 407090.72
A29: ACABAMENTOS ESPECIAIS
A31: Descrição | B31: Quantidade | D31: Parâmetro | F31: Referência | G31: Valor total
A32: FACHADA VENTILADA COM PORCELANATO | C32: m² | D32: =702+200 -> 902 | E32: R$ / m² | F32: - | G32: =B32*D32*1 -> 0 | I32: =D32 -> 902 | J32: =I32*$B32 -> 0 | L32: =K32*$B32 -> 0 | M32: Terceiro
A33: ACM embasamento | C33: m² | D33: 850 | E33: R$ / m² | F33: - | G33: =B33*D33*1.1 -> 0
A34: Led vertical | C34: m | D34: 120 | E34: R$ / m | F34: - | G34: =B34*D34*1.1 -> 0
A35: Brise Amadeirado embasamento | C35: m² | D35: 1800 | E35: R$ / m² | F35: - | G35: =B35*D35*1.1 -> 0 | L35: =SUM(L15:L32) -> 363425.08
G36: =SUM(G32:G35) -> 0
A39: TOTAL FACHADA | G39: =G27+G18+G36 -> 667706.88 | H39: =G39/DADOS_INICIAIS!$E$9 -> 183.80053
H40: =H39/1.1 -> 167.09139

Sheet COMPLEMENTARES
A2: COMPLEMENTARES
A3: Data | B3: 45460
A4: Arquivo base | B4: -
A6: SERVIÇOS COMPLEMENTARES
A8: Descrição | B8: Parâmetro | D8: Quantidade | F8: Valor total
A9: Móveis e decoração INTERNO | B9: 1950 | C9: R$ / AL | D9: ='Obra '!C12 -> 2064.55 | E9: m² | F9: =D9*B9*1.1 -> 4428459.8
A10: Móveis e decoração | B10: 1500 | C10: R$ / AL | D10: =DADOS_INICIAIS!E21 -> 473.79 | E10: m² | F10: =D10*B10*1.1 -> 781753.5
A11: Comunicação visual | B11: 10 | C11: R$ / AC | D11: =B11*DADOS_INICIAIS!$E$9 -> 36327.8 | E11: vb | F11: =D11*1.1 -> 39960.58
A12: Paisagismo | B12: 12 | C12: R$ / AC | D12: =B12*DADOS_INICIAIS!$E$9 -> 43593.36 | E12: vb | F12: =D12*1.1 -> 47952.696
A13: Ligações definitivas | B13: 4 | C13: R$ / AC | D13: =B13*DADOS_INICIAIS!$E$9 -> 14531.12 | E13: vb | F13: =D13*1.1 -> 15984.232
A14: Desmobilização | B14: 5 | C14: R$ / AC | D14: =B14*DADOS_INICIAIS!$E$9 -> 18163.9 | E14: vb | F14: =D14*1.1 -> 19980.29
A15: Limpeza | B15: 15 | C15: R$ / AC | D15: =B15*DADOS_INICIAIS!$E$9 -> 54491.7 | E15: vb | F15: =D15*1.1 -> 59940.87
A16: TOTAL | F16: =SUM(F10:F15) -> 965572.17
A18: TOTAL COMPLEMENTARES | F18: =F16 -> 965572.17 | G18: =F18/DADOS_INICIAIS!$E$9 -> 265.79429

Sheet Auxiliar
A2: 2 Portões acesso garagem - Área: 9,2m² x 2 = 18,4m² | B2: 2 | C2: portão | D2: 18.4
A3: 2 portas corta-fogo 1 folha | B3: 2 | C3: pcf
A4: 1 porta de correr alumínio 2 folhas – Área: 3,465m² | B4: 1 | C4: porta alumínio | D4: 3.465
A5: 1 porta de correr alumínio 2 folhas – Área: 1,7325m² | B5: 1 | C5: porta alumínio | D5: 1.7325 | G5: Guarda alumínio | H5: =SUMIF(C:C,G5,D:D) -> 400.5221
A6: 2 portas de abrir alumínio 2 folhas – Área: 2,6376m² x 2 = 5,2752m² | B6: 2 | C6: porta alumínio | D6: 5.2752 | G6: janela | H6: =SUMIF(C:C,G6,D:D) -> 1895.06
A7: 1 porta de abrir alumínio 2 folhas – Área: 4,1916m² | B7: 1 | C7: porta alumínio | D7: 4.1916 | G7: madeira | H7: =SUMIF(C:C,G7,B:B) -> 218
A8: 1 porta pivotante | B8: 1 | C8: pivotante | G8: pcf | H8: =SUMIF(C:C,G8,B:B) -> 60
A9: 19 portas de abrir madeira 1 folha | B9: 19 | C9: madeira | G9: pivotante | H9: =SUMIF(C:C,G9,B:B) -> 1
A10: 3 portas de abrir vidro 1 folha – Área: 2,1m² x 3 = 6,3m² | B10: 3 | C10: porta alumínio | D10: 6.3 | G10: porta alumínio | H10: =SUMIF(C:C,G10,D:D) -> 46.62
A11: 2 portas de abrir vidro 1 folha – Área: 1,89m² x 2 = 3,78m² | B11: 2 | C11: porta alumínio | D11: 3.78 | G11: portão | H11: =SUMIF(C:C,G11,B:B) -> 2
A12: 1 porta de abrir alumínio 1 folha – Área: 2,0076m² | B12: 1 | C12: porta alumínio | D12: 2.0076 | G12: gradil | H12: =SUMIF(C:C,G12,D:D) -> 113.88
A13: Janelas – Área: 3,75 + 4,875 + 2,5 + 1,1 + 1,2 + 5,5402 + 4,4874 = 23,4526m² | C13: janela | D13: 23.4526 | G13: Brise | H13: 109.3146
A14: Muro de vidro – Área: 7,0774 + 5,485 + 3,43 + 4,8138 = 20,8062m² | C14: Guarda alumínio | D14: 20.8062
A15: 8 portas corta-fogo 1 folha | B15: 8 | C15: pcf
A16: Janelas – Area: (1,1 + 1,2 + 28,7391) x 4 = 124,1564m² | C16: janela | D16: 124.1564
A17: 2 portas corta-fogo 1 folha | B17: 2 | C17: pcf
A18: 2 portas de abrir alumínio 1 folha – Área: 1,47m² x 2 = 2,94m² | B18: 2 | C18: porta alumínio | D18: 2.94
A19: 2 portas de abrir vidro 1 folha – Área: 1,89m² x 2 = 3,78m² | B19: 2 | C19: porta alumínio | D19: 3.78
A20: 5 portas de abrir madeira 1 folha | B20: 5 | C20: madeira
A21: 1 janela-porta de correr vidro – Área: 14,7348m² | B21: 1 | C21: janela | D21: 14.7348
A22: Janelas – Área: 1,2894 + 1,2894 + 23,46 + 1,854 + 5,562 + 5,562 + 1,854 + 1,854 + 1,1 + 1,2 = 45,0248m² | C22: janela | D22: 45.0248
A23: Guarda corpo vidro – Área: 7,5299 + 5,7955 + 6,5555 = 19,8809m² | C23: Guarda alumínio | D23: 19.8809
A24: 38 portas corta-fogo 1 folha | B24: 38 | C24: pcf
A25: 171 portas de abrir madeira 1 folha | B25: 171 | C25: madeira
A26: 19 porta de abrir alumínio 1 folha – Área: 1,26m² x 19 = 23,94m² | B26: 19 | C26: porta alumínio | D26: 23.94
A27: 19 janela-porta de correr vidro 5 folhas - Área: 25,4205m² x 19 = 482,9895m² | B27: 19 | C27: janela | D27: 482.9895
A28: 19 janela-porta de correr vidro 5 folhas - Área: 17,8284m² x 19 = 338,7396m² | B28: 19 | C28: janela | D28: 338.7396
A29: Janelas – Área: 1,1 + 1,1 + 1,2 + 1,92 + 0,36 + 2,781 + 2,781 + 1,854 + 1,854 + 5,562 + 5,562 + 1,854 = 27,928m² x 19 = 530,632m² | C29: janela | D29: 530.632
A30: Guarda corpo metálico – Área: 4,745m² x 19 = 90,155m² - Perímetro: 3,65m x 19 = 69,35m | C30: gradil | D30: 90.155
A31: Guarda corpo vidro – Área: 15,645m² x 19 = 297,255m² - Perímetro: 14,9m x 19 = 283,1m | C31: Guarda alumínio | D31: 297.255
A32: 2 portas corta-fogo 1 folha | B32: 2 | C32: pcf
A33: 2 portas de abrir madeira 1 folha | B33: 2 | C33: madeira
A34: 1 porta de abrir alumínio 1 folha – Área: 1,26m² | B34: 1 | C34: porta alumínio | D34: 1.26
A35: 1 janela-porta de correr vidro 3 folhas - Área: 15,21m² | B35: 1 | C35: janela | D35: 15.21
A36: 1 janela-porta de correr vidro 5 folhas - Área: 25,4205m² | B36: 1 | C36: janela | D36: 25.4205
A37: 1 janela-porta de correr vidro 5 folhas - Área: 17,8284m² | B37: 1 | C37: janela | D37: 17.8284
A38: Janelas – Área: 1,1 + 1,2 + 1,1 + 1,92 + 0,36 + 2,781 + 2,781 + 1,854 + 1,854 + 5,562 + 5,562 + 1,854 = 27,928m² | C38: janela | D38: 27.928
A39: Guarda corpo metálico – Área: 4,745m² - Perímetro: 3,65m | C39: gradil | D39: 4.745
A40: Guarda corpo vidro – Área: 15,645m² - Perímetro: 14,9m | C40: Guarda alumínio | D40: 15.645
A41: 2 portas corta-fogo 1 folha | B41: 2 | C41: pcf
...
