Workbook
Name \0: #REF!
Name \0: #REF!
Name \0: #REF!
Name \0: #REF!
Name \0: #REF!
Name \0: #REF!
Name \0: #REF!
Name \a: #REF!
Name \a: #REF!
Name \m: #REF!
Name \m: #REF!
Name aa: #REF!
Name aa: #REF!
Name aaaa: '[1]M.O.'!#REF!
Name aaaa: '[1]M.O.'!#REF!
Name aaaa: '[1]M.O.'!#REF!
Name aaaa: '[1]M.O.'!#REF!
Name aaaa: '[1]M.O.'!#REF!
Name aaaa: '[1]M.O.'!#REF!
Name aaaa: '[1]M.O.'!#REF!
Name angelo: [2]Geral!#REF!
Name angelo: [2]Geral!#REF!
Name angelo: [2]Geral!#REF!
Name angelo: [2]Geral!#REF!
Name angelo: [2]Geral!#REF!
Name angelo: [2]Geral!#REF!
Name angelo: [2]Geral!#REF!
Name area: #REF!
Name aux: #REF!
Name aux: #REF!
Name aux: #REF!
Name aux: #REF!
Name aux: #REF!
Name aux: #REF!
Name aux: #REF!
Name BDA: #REF!
Name BDA: #REF!
Name BDI: #REF!
Name ca: #REF!
Name Capa: #REF!
Name cronograma: #REF!
Name D: #REF!
Name direto: #REF!
Name DRE: #REF!
Name ea: #REF!
Name FFFFFFF: #REF!
Name FFFFFFF: #REF!
Name FFFFFFF: #REF!
Name FFFFFFF: #REF!
Name FFFFFFF: #REF!
Name FFFFFFF: #REF!
Name FFFFFFF: #REF!
Name item_1: #REF!
Name item_1: #REF!
Name item_1: #REF!
Name item_1: #REF!
Name item_1: #REF!
Name item_1: #REF!
Name item_1: #REF!
Name LS: '[1]M.O.'!#REF!

Sheet DADOS_INICIAIS
A1: Obra | B1: Zapata
A2: Empresa | B2: Ckock
A3: Revisão | B3: R00
A4: Arquitetura base | B4: HPSC0457
A5: DADOS OBRA
B7: Descrição | C7: Identificador | D7: Unidade | E7: Quantidade
B8: ÁREA DO TERRENO | C8: AT | D8: M2 | E8: 622.9
B9: ÁREA TOTAL CONSTRUÍDA | C9: AC | D9: M2 | E9: 7532.89
B10: UNIDADES RESIDENCIAIS | C10: UR | D10: UN | E10: 36
B11: Dormitórios | C11: dorm | D11: UN | E11: 90
B12: Banheiros | C12: ban | D12: UN | E12: =E10*2 -> 72
B13: UNIDADES COMERCIAIS | C13: UC | D13: UN | E13: 2
B14: Churrasqueiras | C14: CHU | D14: UN | E14: =E10+1 -> 37 | F14: Aptos e 1 no lazer
B15: NÚMERO TOTAL DE PAVIMENTOS | C15: NP | D15: UN | E15: 24
B16: NÚMERO DE PAVIMENTOS TIPO | C16: NPT | D16: UN | E16: 18
B17: NÚMERO DE PAVIMENTOS TIPO DIFERENCIADOS | C17: NPD | D17: UN | E17: 0
B18: NÚMERO DE PAVIMENTOS DUPLEX | C18: ND | D18: UN | E18: 0
B19: ÁREA DE PROJEÇÃO DA TORRE | C19: APT | D19: M2 | E19: 233.81
B20: PERÍMETRO DE PROJEÇÃO DA TORRE | C20: PPT | D20: M | E20: =11.56*2+17.81*2 -> 58.74
B21: ÁREA DE LAZER | C21: AL | D21: M2 | E21: 504.89
B22: ÁREA DO EMBASAMENTO | C22: AE | D22: M2 | E22: =503.36+549.79*5 -> 3252.31
B23: ÁREA DE SUBSOLOS | C23: S | D23: M2 | E23: 0
B24: NÚMERO DE SUBSOLOS | C24: NS | D24: UN | E24: 0
B25: ÁREA DE PROJEÇÃO DO EMBASAMENTO | C25: APE | D25: M2 | E25: 503.36
B26: PERÍMETRO DE PROJEÇÃO DE EMBAMENTO | C26: PE | D26: M | E26: =29.21+21.25+21.26+29.3 -> 101.02
B27: NÚMERO DE PAVIMENTOS DE EMBASAMENTO | C27: NE | D27: UN | E27: 6

Sheet MOVIMENTAÇÃO_DE_TERRA
A2: MOVIMENTAÇÃO DE TERRA
A3: Data | B3: 45472
A4: Arquivo base | B4: -
A6: ESCAVAÇÃO VERTICAL DE SUBSOLO
A8: Descrição | B8: Área de subsolo (m) | C8: Altura do subsolo (m) | D8: Volume total de escavação (m3) | E8: Preço unitário de escavação (R$ / m3) | F8: Valor total | G8: Observação
A9: Escavação | B9: =DADOS_INICIAIS!E23 -> 0 | D9: =C9*B9 -> 0 | E9: 0 | F9: =E9*D9*1.1 -> 0
A10: TOTAL | F10: =SUM(F9:F9) -> 0
A12: REBAIXAMENTO DE LENÇOL FREÁTICO
A14: Descrição | B14: Quantidade (dias) | E14: Preço unitário de rebaixamento (R$ / dias) | F14: Valor total | G14: Observação
A15: Rebaixamento de lençol | B15: =4*30 -> 120 | E15: 200 | F15: =B15*E15*1.1 -> 26400 | G15: 4 meses
A16: TOTAL | F16: =SUM(F15:F15) -> 26400
A18: ESCAVAÇÃO E REATERRO DE VALAS
A20: Descrição | B20: Parâmetro | D20: Volume total de escavação (m3) | E20: Preço unitário (R$ / m3) | F20: Valor total | G20: Observação
A21: Escavação mecanizada para blocos e baldrames | B21: 1.3 | C21: m³ / Vol infra | D21: =B21*INFRAESTRUTURA!D29 -> 425.3392 | E21: 36.36 | F21: =E21*D21*1.1 -> 17011.867
A22: Reaterro para blocos e baldrames | B22: 0.6 | C22: m³ / Vol Escavação | D22: =D21-INFRAESTRUTURA!D29 -> 98.1552 | E22: 14.55 | F22: =E22*D22*1.1 -> 1570.974
A23: Movimentação de bota-fora | B23: 1.3 | D23: =(D21-D22)*B23 -> 425.3392 | E23: 45.45 | F23: =E23*D23*1.1 -> 21264.833
A24: Movimentação de terra das estacas | B24: 1 | C24: m³ | D24: =INFRAESTRUTURA!D19 -> 569.50792 | E24: 68.18 | F24: =E24*D24*1.1 -> 42711.955
A25: TOTAL | F25: =SUM(F21:F24) -> 82559.629
A27: REGULARIZAÇÃO E APILOAMENTO DE FUNDO DE VALAS
A29: Descrição | B29: Parâmetro | D29: Área de lastro (m²) | E29: Preço unitário (R$ / m2) | F29: Valor total | G29: Observação
A30: Lastro de concreto magto e=5cm | B30: 0.8 | C30: m² / APE | D30: =B30*DADOS_INICIAIS!E25 -> 402.688 | E30: =370*0.1 -> 37 | F30: =E30*D30*1.1 -> 16389.402 | G30: Definição trazida do Celebration da Passe | H30: =F30/DADOS_INICIAIS!E25 -> 32.56
A31: TOTAL | F31: =SUM(F30:F30) -> 16389.402
A33: TOTAL MOVIMENTAÇÃO DE TERRA | F33: =F10+F16+F25+F31 -> 125349.03 | G33: =F33/DADOS_INICIAIS!E9 -> 16.640231

Sheet CONTENÇÕES
A3: CONTENÇÃO
A4: Data
A5: Arquivo base
A7: CORTINA DE ESTACAS
A9: Descrição | B9: Parâmetro | D9: Quantidade | F9: Preço unitário | G9: Valor total
A10: Número de Estacas | B10: 0.15 | C10: un / APE | D10: =B10*DADOS_INICIAIS!E25 -> 75.504 | E10: un
A11: Estaca Hélice Continua Diâmetro 40 | B11: 0.1 | D11: =B11*$D$10 -> 7.5504 | E11: un
B12: 20 | C12: m/un | D12: =B12*D11 -> 151.008 | E12: m | G12: =F12*D12 -> 0
A13: Estaca Hélice Continua Diâmetro 50 | B13: 0.5 | D13: =B13*$D$10 -> 37.752 | E13: un
B14: 20 | C14: m/un | D14: =B14*D13 -> 755.04 | E14: m | G14: =F14*D14 -> 0
A15: Estaca Hélice Continua Diâmetro 60 | B15: 0.4 | C15: un / APE | D15: =B15*$D$10 -> 30.2016 | E15: un
B16: 20 | C16: m/un | D16: =B16*D15 -> 604.032 | E16: m | G16: =F16*D16 -> 0
A17: Concreto | B17: =(PI()*0.4^2)/4*D14+(PI()*0.5^2)/4*D16+(PI()*0.6^2)/4*D12 -> 256.17904 | C17: un / APE | D17: =(PI()*0.4^2)/4*D14+(PI()*0.5^2)/4*D16+(PI()*0.6^2)/4*D12 -> 256.17904 | E17: m³ | G17: =F17*D17 -> 0
A18: Armação 6,3mm | B18: 1.6575131 | C18: kg / m³ | D18: =B18*D17 -> 424.62011 | E18: kg | G18: =F18*D18 -> 0
A19: Armação 16mm | B19: 10.178338 | C19: kg / m³ | D19: =B19*D17 -> 2607.4767 | E19: kg | G19: =F19*D19 -> 0
A20: Mobilização | B20: 1 | C20: vb | D20: 1 | E20: vb | G20: =F20*D20 -> 0
A21: TOTAL | G21: =SUM(G10:G20) -> 0
A23: PAREDE DE CONCRETO
A25: Descrição | B25: Parâmetro | D25: Quantidade | F25: Preço unitário | G25: Valor total
A26: Fabricação, montagem e desmontagem de forma para blocos e baldrames resinado | B26: 2.1 | C26: m² / APE | D26: =B26*DADOS_INICIAIS!E25 -> 1057.056 | E26: m² | G26: =F26*D26 -> 0
A27: Concreto | B27: 0.65 | C27: m³ / APE | D27: =B27*DADOS_INICIAIS!E25 -> 327.184 | E27: m³ | G27: =F27*D27 -> 0
A28: Armação | B28: 110 | C28: kg / m³ | D28: =B28*D27 -> 35990.24 | E28: kg | G28: =F28*D28 -> 0
A29: Mão de obra | B29: =SUPRAESTRUTURA!B15*1.5 -> 360 | C29: R$ / APE | D29: =DADOS_INICIAIS!E25 -> 503.36 | E29: m² | F29: =B29 -> 360 | G29: =F29*D29 -> 181209.6
A30: TOTAL | G30: =SUM(G26:G29) -> 181209.6
A33: PAREDE DIAFRAGMA
A35: Descrição | B35: Parâmetro | D35: Quantidade | F35: Preço unitário | G35: Valor total
A36: Fabricação, montagem e desmontagem de forma para blocos e baldrames resinado | B36: 2.1 | C36: m² / APE | D36: =B36*DADOS_INICIAIS!E35 -> 0 | E36: m² | G36: =F36*D36 -> 0
A37: Concreto | B37: 0.65 | C37: m³ / APE | D37: =B37*DADOS_INICIAIS!E35 -> 0 | E37: m³ | G37: =F37*D37 -> 0
A38: Armação | B38: 110 | C38: kg / m³ | D38: =B38*D37 -> 0 | E38: kg | G38: =F38*D38 -> 0
A39: Mão de obra | B39: =SUPRAESTRUTURA!B71*1.5 -> 0 | C39: R$ / APE | D39: =DADOS_INICIAIS!E35 -> 0 | E39: m² | F39: =B39 -> 0 | G39: =F39*D39 -> 0
A40: TOTAL | G40: =SUM(G36:G39) -> 0
A46: TOTAL INFRAESTRUTURA | G46: =G21+G30 -> 181209.6 | H46: =G46/DADOS_INICIAIS!E9 -> 24.055787

Sheet INFRAESTRUTURA
A3: INFRAESTRUTURA
A4: Data | B4: 45472
A5: Arquivo base | B5: -
A7: FUNDAÇÃO PROFUNDA | H7: Proposta para o zapata de 685mil já com o concreto, Não considerado a armação nesse custo
A9: Descrição | B9: Parâmetro | D9: Quantidade | F9: Preço unitário | G9: Valor total | H9: Observação
A10: Número de Estacas | B10: 0.15 | C10: un / APE | D10: =ROUNDUP(B10*DADOS_INICIAIS!$E$25,0) -> 76 | E10: un | H10: Base obra Trindade Parkside
A11: Estaca Hélice Continua Diâmetro 40 | B11: 0 | D11: =ROUNDUP(B11*$D$10,0) -> 0 | E11: un
B12: 32 | C12: m/un | D12: =B12*D11 -> 0 | E12: m | F12: 70 | G12: =F12*D12*1.1 -> 0
A13: Estaca Hélice Continua Diâmetro 50 | B13: 0.6 | D13: =ROUNDUP(B13*D10,0) -> 46 | E13: un
B14: 32 | C14: m/un | D14: =B14*D13 -> 1472 | E14: m | F14: 60.55 | G14: =F14*D14*1.1 -> 98042.56
A15: Estaca Hélice Continua Diâmetro 60 | B15: 0.4 | C15: un / APE | D15: =ROUNDUP(B15*$D$10,0) -> 31 | E15: un
B16: 32 | C16: m/un | D16: =B16*D15 -> 992 | E16: m | F16: 70.8 | G16: =F16*D16*1.1 -> 77256.96
A17: Estaca Hélice Continua Diâmetro 80 | B17: 0 | C17: un / APE | D17: =ROUNDUP(B17*$D$10,0) -> 0 | E17: un
B18: 32 | C18: m/un | D18: =B18*D17 -> 0 | E18: m | F18: 120 | G18: =F18*D18*1.1 -> 0
A19: Concreto (40 Mpa) | B19: 1.3 | C19: perda | D19: =(PI()*((0.4^2)/4)*D12+PI()*((0.5^2)/4)*D14+PI()*((0.6^2)/4)*D16) -> 569.50792 | E19: m³ | F19: =(535+45+(1.67*0.6))*B19 -> 755.3026 | G19: =F19*D19*1.1 -> 473165.89
A20: Mobilização | B20: 1 | C20: vb | D20: 1 | E20: vb | F20: 12500 | G20: =F20*D20*1.1 -> 13750
A21: Apoio e arrasamento de estacas | D21: =D10 -> 76 | E21: un | F21: 300 | G21: =F21*D21*1 -> 22800
A22: Armação | B22: 12 | C22: kg / m³ | D22: =B22*D19 -> 6834.095 | E22: kg | F22: 7.62 | G22: =F22*D22*1.1 -> 57283.384
A23: TOTAL | G23: =SUM(G10:G22) -> 742298.8
A25: FUNDAÇÃO RASA
A27: Descrição | B27: Parâmetro | D27: Quantidade | F27: Preço unitário | G27: Valor total | H27: Observação
A28: Fabricação, montagem e desmontagem de forma para blocos e baldrames resinado | B28: 1.1 | C28: m² / APE | D28: =B28*DADOS_INICIAIS!E25 -> 553.696 | E28: m² | F28: 68 | G28: =F28*D28*1.1 -> 41416.461
A29: Concreto (40 Mpa) | B29: 0.65 | C29: m³ / APE | D29: =B29*DADOS_INICIAIS!E25 -> 327.184 | E29: m³ | F29: =(535+45+(1.67*0.6))*1.05 -> 610.0521 | G29: =F29*D29*1.1 -> 219559.21
A30: Armação | B30: 80 | C30: kg / m³ | D30: =B30*D29 -> 26174.72 | E30: kg | F30: 7.62 | G30: =F30*D30*1.1 -> 219396.5 | H30: Base obra Trindade Parkside
A31: Piso de concreto armado | B31: 1 | C31: m² / APE | D31: =B31*DADOS_INICIAIS!E25 -> 503.36 | E31: m² | F31: 180 | G31: =F31*D31*1.1 -> 99665.28
A32: Mão de obra | B32: =SUPRAESTRUTURA!B30*1.5 -> 420 | C32: R$ / APE | D32: =DADOS_INICIAIS!E25 -> 503.36 | E32: m² | F32: =B32 -> 420 | G32: =F32*D32*1.1 -> 232552.32
A33: TOTAL | G33: =SUM(G28:G32) -> 812589.78
A36: TOTAL INFRAESTRUTURA | G36: =G23+G33 -> 1554888.6 | H36: =G36/DADOS_INICIAIS!E9 -> 206.41329
H38: =H36/1.1 -> 187.64844

Sheet SUPRAESTRUTURA
A3: SUPRAESTRUTURA
A4: Data | B4: 45472
A5: Arquivo base | B5: -
A7: SUPRAESTRUTURA - LAJE MACIÇA
A9: Descrição | B9: Parâmetro | D9: Quantidade | F9: Preço unitário | G9: Valor total | H9: Observação
A10: Fabricação forma | B10: 3 | C10: Jogos | D10: =(D11/DADOS_INICIAIS!$E$15)*B10 -> 2354.0281 | E10: m² | F10: 110 | G10: =F10*D10*1.1 -> 284837.4
A11: Montagem de forma | B11: 2.5 | C11: m² / AC | D11: =B11*DADOS_INICIAIS!$E$9 -> 18832.225 | E11: m² | F11: 2.5 | G11: =F11*D11*1.1 -> 51788.619
A12: Escoramento | B12: 4 | C12: un / AE | D12: =ROUNDUP(B12*DADOS_INICIAIS!$E$25*B10,0) -> 6041 | E12: un | F12: =17 -> 17 | G12: =F12*D12*1.1 -> 112966.7
A13: Concreto | B13: 0.22 | C13: m³ / AC | D13: =B13*DADOS_INICIAIS!$E$9 -> 1657.2358 | E13: m³ | F13: =535+45 -> 580 | G13: =F13*D13*1.05*1.1 -> 1110182.3
A14: Armadura Convencional para Estrutura | B14: 110 | C14: kg / m³ | D14: =D13*B14 -> 182295.94 | E14: kg | F14: 7.62 | G14: =F14*D14*1.1 -> 1528004.6
A15: Mão de obra - estrutura em concreto armado | B15: 240 | C15: R$ / AC | D15: =DADOS_INICIAIS!$E$9 -> 7532.89 | E15: m² | F15: =B15 -> 240 | G15: =F15*D15*1.1 -> 1988683
A16: Perfuração de vigas | B16: 5300 | C16: R$ / NP | D16: 1 | E16: vb | F16: =B16*DADOS_INICIAIS!$E$15 -> 127200 | G16: =F16*D16*1.1 -> 139920 | H16: Coeficiente originário do Gran Torino (R$ 160,00/un) | I16: Nova utiliza a verba de 1.500,00 por pav
A17: TOTAL | G17: =SUM(G10:G16) -> 5216382.5 | K17: =4160+1440+1120+2880+4800+91680+4000 -> 110080 | L17: =K17/21 -> 5241.9048
A19: SUPRAESTRUTURA - LAJE CUBETAS PROTENDIDAS
A21: Descrição | B21: Parâmetro | D21: Quantidade | F21: Preço unitário | G21: Valor total | H21: Observação
A22: Fabricação forma | B22: 3 | C22: Jogos | D22: =(D23/DADOS_INICIAIS!$E$15)*B22 -> 1035.7724 | E22: m² | F22: 110 | G22: =F22*D22*1.1 -> 125328.46
A23: Montagem de forma | B23: 1.1 | C23: m² / AC | D23: =B23*DADOS_INICIAIS!$E$9 -> 8286.179 | E23: m² | F23: 2.5 | G23: =F23*D23*1.1 -> 22786.992
A24: Escoramento | C24: un / APT*NPT | D24: =DADOS_INICIAIS!$E$9-DADOS_INICIAIS!$E$25 -> 7029.53 | E24: m² | F24: 22 | G24: =F24*D24*1.1 -> 170114.63 | I24: Custos connect executivo
A25: Cubetas | B25: 25 | C25: R$ / AC | D25: =DADOS_INICIAIS!$E$9-DADOS_INICIAIS!$E$25 -> 7029.53 | E25: m² | F25: 15 | G25: =F25*D25*1.1 -> 115987.25 | H25: =ROUNDUP(DADOS_INICIAIS!E19*B22,0) -> 702 | I25: Custos connect executivo
A26: Protensão - lajes - materiais | D26: =DADOS_INICIAIS!$E$9-DADOS_INICIAIS!$E$25-48.02-23.98 -> 6957.53 | E26: m² | F26: 11.5 | G26: =F26*D26*1.1 -> 88012.755 | I26: Custos connect executivo
A27: Protensão - lajes - serviços | D27: =D26 -> 6957.53 | E27: m² | F27: 11.5 | G27: =F27*D27*1.1 -> 88012.755 | I27: Custos connect executivo
A28: Concreto | B28: 0.25 | C28: m³ / AC | D28: =B28*DADOS_INICIAIS!$E$9 -> 1883.2225 | E28: m³ | F28: =(535+45+(1.67*0.6))*1.05 -> 610.0521 | G28: =F28*D28*1.1 -> 1263750.2
A29: Armadura Convencional para Estrutura | B29: 100 | C29: kg / m³ | D29: =D28*B29 -> 188322.25 | E29: kg | F29: 7.62 | G29: =F29*D29*1.1 -> 1578517.1
A30: Mão de obra - estrutura em concreto armado | B30: 280 | C30: R$ / AC | D30: =DADOS_INICIAIS!$E$9 -> 7532.89 | E30: m² | F30: =B30 -> 280 | G30: =F30*D30*1.1 -> 2320130.1
A31: Perfuração de vigas | B31: 2300 | C31: R$ / NP | D31: 1 | E31: vb | F31: =B31*DADOS_INICIAIS!$E$15 -> 55200 | G31: =F31*D31*1.1 -> 60720 | H31: Coeficiente originário do Gran Torino (R$ 160,00/un)
A32: TOTAL | G32: =SUM(G22:G31) -> 5833360.3
A34: SUPRAESTRUTURA - LAJE TRELIÇADA
A36: Descrição | B36: Parâmetro | D36: Quantidade | F36: Preço unitário | G36: Valor total | H36: Observação
A37: Fabricação forma | B37: 2 | C37: Jogos | D37: =(D38/DADOS_INICIAIS!$E$15)*B37 -> 0 | E37: m² | F37: 85 | G37: =F37*D37*1.1 -> 0
A38: Montagem de forma | B38: 2.1 | C38: m² / AC | D38: =B38*DADOS_INICIAIS!E38 -> 0 | E38: m² | F38: 1.5 | G38: =F38*D38*1.1 -> 0
A39: Escoramento - Torre | B39: 2 | C39: un / APT*NPT | D39: =B39*DADOS_INICIAIS!E47*DADOS_INICIAIS!E44 -> 0 | E39: un | F39: 17 | G39: =F39*D39*1.1 -> 0
A40: Escoramento - Embasamento | B40: 2 | C40: un / AE | D40: =B40*DADOS_INICIAIS!E50 -> 0 | E40: un | F40: 17 | G40: =F40*D40*1.1 -> 0
A41: Cubetas | B41: 25 | C41: R$ / AC | D41: =B41*DADOS_INICIAIS!E38 -> 0 | E41: m³ | F41: =B41 -> 25 | G41: =F41*D41*1.1 -> 0
A42: Concreto | B42: 0.25 | C42: m³ / AC | D42: =B42*DADOS_INICIAIS!E38 -> 0 | E42: m³ | F42: =575 -> 575 | G42: =F42*D42*1.05*1.1 -> 0
A43: Armadura Convencional para Estrutura | B43: 110 | C43: kg / m³ | D43: =D42*B43 -> 0 | E43: kg | F43: 7.25 | G43: =F43*D43*1.1 -> 0
A44: Mão de obra - estrutura em concreto armado | B44: 240 | C44: R$ / AC | D44: =DADOS_INICIAIS!E38 -> 0 | E44: m² | F44: =B44 -> 240 | G44: =F44*D44*1.1 -> 0
A45: Perfuração de vigas | B45: 5300 | C45: R$ / NP | D45: 1 | E45: vb | F45: =B45*DADOS_INICIAIS!E43 -> 0 | G45: =F45*D45*1.1 -> 0 | H45: Coeficiente originário do Gran Torino (R$ 160,00/un)
A46: TOTAL | G46: =SUM(G37:G45) -> 0
A48: SUPRAESTRUTURA - LAJE PROTENDIDA
A50: Descrição | B50: Parâmetro | D50: Quantidade | F50: Preço unitário | G50: Valor total | H50: Observação
...

Sheet ALVENARIA
A3: PAREDES E PAINÉIS
A4: Data | B4: 45469
A5: Arquivo base | B5: -
A7: ALVENARIA
A9: Descrição | B9: Parâmetro | D9: Quantidade | F9: Preço unitário | G9: Valor total | H9: Observação
A10: Alvenaria externa | B10: 0.6 | C10: m² / AE | D10: =B10*DADOS_INICIAIS!$E$9 -> 4519.734 | E10: m² | F10: 45 | G10: =F10*D10*1.1 -> 223726.83
A11: Alvenaria internas | B11: 0.8 | C11: m² / AL | D11: =B11*DADOS_INICIAIS!$E$9 -> 6026.312 | E11: m² | F11: 45 | G11: =F11*D11*1.1 -> 298302.44
A12: Alvenaria escadas | B12: 0.18 | C12: m² / AC | D12: =B12*DADOS_INICIAIS!$E$9 -> 1355.9202 | E12: m² | F12: 75 | G12: =F12*D12*1.05*1.1 -> 117456.59
A13: Alvenaria refratárias | B13: 1.75 | C13: m² * CHU | D13: =B13*DADOS_INICIAIS!$E$14 -> 64.75 | E13: m² | F13: 310 | G13: =F13*D13*1.1 -> 22079.75
A14: Serviços complementares | B14: 12.5 | C14: R$ / m² | D14: =SUM(D10:D12) -> 11901.966 | E14: m² | F14: 6.5 | G14: =F14*D14*1.1 -> 85099.058
A15: Mão de obra | B15: 35 | C15: R$ / m² | D15: =SUM(D10:D12) -> 11901.966 | E15: m² | F15: 36 | G15: =F15*D15*1.1 -> 471317.86
A16: TOTAL | G16: =SUM(G10:G15) -> 1217982.5 | K16: =4160+1440+1120+2880+4800+91680+4000 -> 110080 | L16: =K16/21 -> 5241.9048
A18: ALVENARIA - DRYWALL
A20: Descrição | B20: Parâmetro | D20: Quantidade | F20: Preço unitário | G20: Valor total | H20: Observação
A21: Alvenaria embasamento | B21: 1 | C21: m² / AE | D21: =B21*DADOS_INICIAIS!$E$22 -> 3252.31 | E21: m² | F21: 45 | G21: =F21*D21*1.1 -> 160989.35
A22: Alvenaria lazer | B22: 0.4 | C22: m² / AL | D22: =B22*DADOS_INICIAIS!$E$21 -> 201.956 | E22: m² | F22: 45 | G22: =F22*D22*1.1 -> 9996.822
A23: Alvenaria tipo | B23: 1.65 | C23: m² / APT*(NPT+2ND) | D23: =B23*(DADOS_INICIAIS!$E$19*(DADOS_INICIAIS!$E$16+DADOS_INICIAIS!$E$17))*0.4 -> 2777.6628 | E23: m² | F23: 45 | G23: =F23*D23*1.1 -> 137494.31
A24: Drywall tipo | B24: 1.65 | C24: m² / APT*(NPT+2ND) | D24: =B24*(DADOS_INICIAIS!$E$19*(DADOS_INICIAIS!$E$16+DADOS_INICIAIS!$E$17))*0.6 -> 4166.4942 | E24: m² | F24: 220 | G24: =F24*D24*1.1 -> 1008291.6 | J24: =D24/(D28+D24) -> 0.34456478
A25: Alvenaria escadas | B25: 0.2 | C25: m² / AC | D25: =B25*DADOS_INICIAIS!$E$9 -> 1506.578 | E25: m² | F25: 70 | G25: =F25*D25*1.1 -> 116006.51 | J25: =1-J24 -> 0.65543522
A26: Alvenaria cobertura / reservatório | B26: 0.8 | C26: m² / APT | D26: =B26*DADOS_INICIAIS!$E$19 -> 187.048 | E26: m³ | F26: 45 | G26: =F26*D26*1.1 -> 9258.876
A27: Alvenaria refratárias | B27: 1.75 | C27: m² * CHU | D27: ='SISTEMAS ESPECIAIS'!B10 -> 37 | E27: un | F27: 210 | G27: =F27*D27*1.1 -> 8547
A28: Serviços complementares | B28: 12.5 | C28: R$ / m² | D28: =D22+D23+D21+D25+D26 -> 7925.5548 | E28: m² | F28: =B28 -> 12.5 | G28: =F28*D28*1.1 -> 108976.38
A29: Mão de obra | B29: 35 | C29: R$ / m² | D29: =D22+D23+D21+D25+D26 -> 7925.5548 | E29: m² | F29: 35 | G29: =F29*D29*1.1 -> 305133.86
A30: TOTAL | G30: =SUM(G21:G29) -> 1864694.7
A33: TOTAL ALVENARIA | G33: =G16 -> 1217982.5 | H33: =G33/DADOS_INICIAIS!E9 -> 161.68861
G36: =G33/1.1 -> 1107256.8 | H36: =G36/DADOS_INICIAIS!E9 -> 146.98965

Sheet INSTALAÇÕES
A2: INSTALAÇÕES
A4: INSTALAÇÕES ELÉTRICAS
A6: Descrição | B6: Parâmetro | D6: Valor total
A7: Entrada de Energia | B7: 5.5 | C7: R$ / AC | D7: =B7*DADOS_INICIAIS!$E$9*1.1 -> 45573.985
A8: Eletrodutos e Eletrocalhas | B8: 10 | C8: R$ / AC | D8: =B8*DADOS_INICIAIS!$E$9*1.1 -> 82861.79
A9: Cabos e Fiações | B9: 30 | C9: R$ / AC | D9: =B9*DADOS_INICIAIS!$E$9*1.1 -> 248585.37
A10: Quadros e Disjuntores | B10: 18 | C10: R$ / AC | D10: =B10*DADOS_INICIAIS!$E$9*1.1 -> 149151.22
A11: Acabamentos Elétricos | B11: 15 | C11: R$ / AC | D11: =B11*DADOS_INICIAIS!$E$9*1.1 -> 124292.69
A12: Equipamentos e Iluminação | B12: 15 | C12: R$ / AC | D12: =B12*DADOS_INICIAIS!$E$9*1.1 -> 124292.69
A13: Mão de Obra para Instalações Elétricas | B13: 60 | C13: R$ / AC | D13: =B13*DADOS_INICIAIS!$E$9*1.1 -> 497170.74
A14: TOTAL | D14: =SUM(D7:D13) -> 1271928.5
A16: INSTALAÇÕES HIDROSSANITÁRIAS
A18: Descrição | B18: Parâmetro | D18: Valor total
A19: Instalações de Água Fria | B19: 25 | C19: R$ / AC | D19: =B19*DADOS_INICIAIS!$E$9*1.1 -> 207154.48
A20: Instalações de Água Quente | B20: 20 | C20: R$ / AC | D20: =B20*DADOS_INICIAIS!$E$9*1.1 -> 165723.58
A21: Instalações de Águas Pluviais | B21: 10 | C21: R$ / AC | D21: =B21*DADOS_INICIAIS!$E$9*1.1 -> 82861.79
A22: Instalações Sanitárias | B22: 15 | C22: R$ / AC | D22: =B22*DADOS_INICIAIS!$E$9*1.1 -> 124292.69
A23: Louças e Metais | B23: 20 | C23: R$ / AC | D23: =B23*DADOS_INICIAIS!$E$9*1.1 -> 165723.58
A24: Mão de Obra para Instalações Hidráulicas | B24: 55 | C24: R$ / AC | D24: =B24*DADOS_INICIAIS!$E$9*1.1 -> 455739.85
A25: TOTAL | D25: =SUM(D19:D24) -> 1201496
A27: INSTALAÇÕES PREVENTIVAS E GLP
A29: Descrição | B29: Parâmetro | D29: Valor total
A30: Instalações Preventivas | B30: 20 | C30: R$ / AC | D30: =B30*DADOS_INICIAIS!$E$9*1.1 -> 165723.58
A31: Instalações de GLP | B31: 13 | C31: R$ / AC | D31: =B31*DADOS_INICIAIS!$E$9*1.1 -> 107720.33
A32: Instalações de Proteção e Aterramento - SPDA | B32: 8 | C32: R$ / AC | D32: =B32*DADOS_INICIAIS!$E$9*1.1 -> 66289.432
A33: TOTAL | D33: =SUM(D30:D32) -> 339733.34
A35: TOTAL INSTALAÇÕES | D35: =D14+D25+D33 -> 2813157.8 | E35: =D35/DADOS_INICIAIS!E9 -> 373.45
E37: =E35/1.1 -> 339.5

Sheet SISTEMAS ESPECIAIS
A2: SISTEMAS ESPECIAIS
A4: CLIMATIZAÇÃO, EXAUSTÃO MECÂNICA E PRESSURIZAÇÃO
A6: Descrição | B6: Quantidade | C6: Preço Unitário | D6: Valor total | G6: TERREO | H6: LAZER | I6: TIPO
A7: Infraestrutura para Instalação de Ar Condicionado | B7: =4.5*DADOS_INICIAIS!E10 -> 162 | C7: 1200 | D7: =B7*C7*1.1 -> 213840 | G7: =1+3 -> 4 | H7: =5 -> 5 | I7: =(3+1)*2 -> 8
A8: Instalação de Ar Condicionado | B8: 4 | C8: 5000 | D8: =B8*C8*1.1 -> 22000 | G8: 1 | H8: =H7 -> 5 | I8: 0
A9: Ventokit | B9: =DADOS_INICIAIS!E10 -> 36 | C9: 900 | D9: =B9*C9*1.1 -> 35640 | E9: Previsto um lavabo enclausurado por unidade | G9: 0 | H9: =2+2 -> 4 | I9: =1*2 -> 2
A10: Churrasqueiras | B10: =DADOS_INICIAIS!E10+1 -> 37 | C10: 2600 | D10: =B10*C10*1.1 -> 105820 | E10: 1 por unidade mais um no lazer | G10: 0 | H10: =1+1 -> 2 | I10: 2
A11: TOTAL | D11: =SUM(D7:D10) -> 377300
A13: COMUNICAÇÃO
A15: Descrição | B15: Parâmetro | D15: Valor total
A16: CFTV | B16: 1.5 | C16: R$ / AC | D16: =B16*DADOS_INICIAIS!$E$9*1.1 -> 12429.269
A17: Interfone | B17: 2 | C17: R$ / AC | D17: =B17*DADOS_INICIAIS!$E$9*1.1 -> 16572.358
A18: TV e internet | B18: 4 | C18: R$ / AC | D18: =B18*DADOS_INICIAIS!$E$9*1.1 -> 33144.716
A19: Automação, telecomunicação e sistemas de segurança | B19: 5 | C19: R$ / AC | D19: =B19*DADOS_INICIAIS!$E$9*1.1 -> 41430.895
A20: TOTAL | D20: =SUM(D16:D19) -> 103577.24
A22: EQUIPAMENTOS
A24: Descrição | B24: Quantidade | C24: Preço Unitário | D24: Valor total
A25: Elevadores | B25: 2 | C25: =(768900/2) -> 384450 | D25: =B25*C25*1.1 -> 845790
A26: Grupo de geradores | B26: 1 | C26: 42000 | D26: =B26*C26*1.1 -> 46200
A27: Pressurização de escada | B27: 1 | C27: =26.4*DADOS_INICIAIS!E9 -> 198868.3 | D27: =B27*C27*1.1 -> 218755.13
A28: Bombas | B28: 1 | C28: 10000 | D28: =B28*C28*1.1 -> 11000
A29: Infra de carro elétrico | C29: 560 | D29: =B29*C29*1.1 -> 0
A30: Equipamento de piscina | B30: 1 | C30: 36831 | D30: =B30*C30*1.1 -> 40514.1
A31: Sauna | C31: 8500 | D31: =B31*C31*1.1 -> 0
A32: Spa | C32: 15000 | D32: =B32*C32*1.1 -> 0
A33: Sistema de aquecimento | B33: 0 | C33: =55*DADOS_INICIAIS!E9 -> 414308.95 | D33: =B33*C33 -> 0
A34: TOTAL | D34: =SUM(D25:D33) -> 1162259.2
A36: OUTROS SISTEMAS ESPECIAIS
A38: Descrição | B38: Parâmetro | D38: Valor total
A39: Outros sistemas | B39: 20 | C39: R$ / AC | D39: =B39*DADOS_INICIAIS!E9*1.1 -> 165723.58
A40: TOTAL | D40: =SUM(D39:D39) -> 165723.58
A42: TOTAL SISTEMAS ESPECIAIS | D42: =D11+D20+D34+D40 -> 1808860 | E42: =D42/DADOS_INICIAIS!E9 -> 240.1283

Sheet IMPERMEABILIZAÇÃO
A3: IMPERMEABILIZAÇÃO
A4: Data | B4: 45471
A5: Arquivo base | B5: -
A7: ALVENARIA
A9: Descrição | B9: Parâmetro | D9: Quantidade | F9: Preço unitário | G9: Valor total | H9: Observação
A10: Regularização de Superfície | B10: 25 | C10: R$ / m² | D10: =D14+D15 -> 2711.8404 | E10: m² | F10: 22 | G10: =F10*D10*1.1 -> 65626.538
A11: Poço do elevador | B11: 45 | C11: R$ / m² | D11: =(3.24+(7.2)*1.8)*2 -> 32.4 | E11: m² | F11: 41 | G11: =F11*D11*1.1 -> 1461.24
A12: Baldrames | B12: 30 | C12: R$ / m² | D12: =INFRAESTRUTURA!D28 -> 553.696 | E12: m² | F12: 35 | G12: =F12*D12*1.1 -> 21317.296
A13: Ralos | B13: 1 | C13: R$ / AC | D13: 1 | E13: vb | F13: =B13*DADOS_INICIAIS!$E$9 -> 7532.89 | G13: =F13*D13*1.1 -> 8286.179
A14: Impermeabilizações cimenticias | B14: 0.25 | C14: m² / AC | D14: =B14*DADOS_INICIAIS!E9 -> 1883.2225 | E14: m² | F14: 60 | G14: =F14*D14*1.1 -> 124292.69
A15: Impermeabilizações com manta asfaltica | B15: 0.11 | C15: m² / AC | D15: =B15*DADOS_INICIAIS!E9 -> 828.6179 | E15: m² | F15: 110 | G15: =F15*D15*1.1 -> 100262.77
A16: Impermeabilização de peitoril | B16: 0.6 | C16: R$ / AC | D16: 1 | E16: vb | F16: =B16*DADOS_INICIAIS!$E$9 -> 4519.734 | G16: =F16*D16*1.1 -> 4971.7074
A17: Proteção Mecânica | B17: 28 | C17: R$ / m² | D17: =D15 -> 828.6179 | E17: m² | F17: 28 | G17: =F17*D17*1.1 -> 25521.431
A18: TOTAL | G18: =SUM(G10:G17) -> 351739.84 | K18: =4160+1440+1120+2880+4800+91680+4000 -> 110080 | L18: =K18/21 -> 5241.9048
A20: TOTAL IMPERMEABILIZAÇÃO | G20: =G18 -> 351739.84 | H20: =G20/DADOS_INICIAIS!E9 -> 46.693877
H23: =H20/1.1 -> 42.448979

Sheet Rev. Internos Piso e Parede
A2: ORÇAMENTO PARAMÉTRICO GERENCIAMENTO EXECUTIVO
A7: Cliente
A8: Obra
A9: Data | B9: 45471
A10: Revisão | B10: R00
A12: REVESTIMENTOS INTERNOS EM PISO E PAREDE
A14: Descrição | B14: Quantidade | D14: Parâmetro | F14: Referência | G14: Valor total
A15: Polimento de concreto | B15: =549.79*4*0.8 -> 1759.328 | C15: m² | D15: 16.5 | E15: R$ / m² | F15: Média | G15: =D15*B15*1.1 -> 31931.803
A16: Piso alisado | B16: =DADOS_INICIAIS!E9*0.05 -> 376.6445 | C16: m² | D16: 25 | E16: R$ / m² | F16: Média | G16: =D16*B16*1.1 -> 10357.724
A17: Contrapiso | B17: =DADOS_INICIAIS!E9*0.62 -> 4670.3918 | C17: m² | D17: =B17/DADOS_INICIAIS!E9 -> 0.62 | E17: m² / AC | F17: Média | G17: =+B17*65*1.1 -> 333933.01 | H17: =B17+B16+B15 -> 6806.3643 | I17: =H17/DADOS_INICIAIS!E9 -> 0.90355286
A18: Manta acústica | C18: m² | D18: =B18/DADOS_INICIAIS!E9 -> 0 | E18: m² / AC | F18: Média | G18: =+B18*25*1.1 -> 0
A19: Chapisco | B19: =ALVENARIA!D15*2-'Rev. Fachada'!B15 -> 18987.67 | C19: m² | D19: =B19/DADOS_INICIAIS!E9 -> 2.5206356 | E19: m² / AC | F19: Média | G19: =+B19*5*1.1 -> 104432.19
A20: Reboco | B20: =B19 -> 18987.67 | C20: m² | D20: =B20/DADOS_INICIAIS!E9 -> 2.5206356 | E20: m² / AC | F20: Média | G20: =50*B20*1.1 -> 1044321.9
A21: TOTAL | G21: =SUM(G15:G20) -> 1524976.6
A24: TOTAL REVESTIMENTOS | G24: =G21 -> 1524976.6 | H24: =G24/DADOS_INICIAIS!E9 -> 202.44244
H26: =H24/1.1 -> 184.03858

Sheet TETO
A3: REVESTIMENTOS E ACABAMENTOS DE TETO
A4: Data | B4: 45471
A5: Arquivo base | B5: -
A7: ALVENARIA
A9: Descrição | B9: Parâmetro | D9: Quantidade | F9: Preço unitário | G9: Valor total | H9: Observação
A10: Forro gesso mineral | B10: 0.6 | C10: m² / AC | D10: =B10*DADOS_INICIAIS!E9 -> 4519.734 | E10: m² | F10: 65 | G10: =F10*D10*1.1 -> 323160.98
A11: Negativo | B11: 1.2 | C11: m / FORRO | D11: =(D10)*B11 -> 5423.6808 | E11: m² | F11: 22 | G11: =F11*D11*1.1 -> 131253.08
A12: Estucamento | B12: 0.2 | C12: m² / AC | D12: =B12*DADOS_INICIAIS!E9 -> 1506.578 | E12: m² | F12: 24 | G12: =F12*D12*1.1 -> 39773.659
A13: TOTAL | G13: =SUM(G10:G12) -> 494187.72 | K13: =4160+1440+1120+2880+4800+91680+4000 -> 110080 | L13: =K13/21 -> 5241.9048
A15: TOTAL FORRO | G15: =G13 -> 494187.72 | H15: =G15/DADOS_INICIAIS!E9 -> 65.604
H18: =H15/1.1 -> 59.64

Sheet Acabamentos de Piso e Parede
A2: ORÇAMENTO PARAMÉTRICO GERENCIAMENTO EXECUTIVO
A7: Cliente
A8: Obra
A9: Data | B9: 45471
A10: Revisão | B10: R00
A12: ACABAMENTOS EM PISO E PAREDE
A14: Descrição | B14: Quantidade | D14: Parâmetro | F14: Referência | G14: Valor total
A15: Porcelanato | B15: ='Rev. Internos Piso e Parede'!B17*0.6 -> 2802.2351 | C15: m² | D15: =40*1.1+2.25+48 -> 94.25 | E15: R$ / m² | F15: Média | G15: =+D15*B15*1.1 -> 290521.72
A16: Vinilico | B16: ='Rev. Internos Piso e Parede'!B17*0.4 -> 1868.1567 | C16: m² | D16: 125 | E16: R$ / m² | F16: Média | G16: =+D16*B16*1.1 -> 256871.55
A17: Piscina | B17: 144.9 | C17: m² | D17: =110+2.25+50 -> 162.25 | E17: R$ / m² | F17: Média | G17: =+D17*B17*1.1 -> 25861.028
A18: Grama sintetica | B18: 50 | C18: m² | D18: 210 | E18: R$ / m² | F18: Média | G18: =+D18*B18*1.1 -> 11550
A19: Paver | B19: =29.3*2.07+293*4*0.5 -> 646.651 | C19: m² | D19: 60 | E19: R$ / m² | F19: Média | G19: =+D19*B19*1.1 -> 42678.966
A20: Rodapés | B20: 1 | C20: vb | D20: 30 | E20: R$ / AC | F20: Média | G20: =D20*DADOS_INICIAIS!$E$9*1.1 -> 248585.37
A21: Soleiras e peitoris | B21: 1 | C21: vb | D21: 20 | E21: R$ / AC | F21: Média | G21: =D21*DADOS_INICIAIS!$E$9*1.1 -> 165723.58
A22: Revestimentos de Parede | B22: 1 | C22: vb | D22: 50 | E22: R$ / AC | F22: Média | G22: =D22*DADOS_INICIAIS!$E$9*1.1 -> 414308.95
A23: =20*40 -> 800 | G23: =SUM(G15:G22) -> 1456101.2
A26: TOTAL ACABAMENTOS | G26: =G23 -> 1456101.2 | H26: =G26/DADOS_INICIAIS!E9 -> 193.29914
H28: =H26/1.1 -> 175.72649

Sheet PINTURA INTERNA
A3: PINTURA INTERNA
A4: Data | B4: 45457
A5: Arquivo base | B5: -
A7: ALVENARIA
A9: Descrição | B9: Parâmetro | D9: Quantidade | F9: Preço unitário | G9: Valor total | H9: Observação
A10: Pintura piso epoxi | B10: 110 | C10: R$ / m² | D10: ='Rev. Internos Piso e Parede'!B15 -> 1759.328 | E10: m² | F10: 110 | G10: =F10*D10*1.1 -> 212878.69
A11: Pintura acrílica antiderrapante | B11: 65 | C11: R$ / m² | D11: ='Rev. Internos Piso e Parede'!B16 -> 376.6445 | E11: m² | F11: 65 | G11: =F11*D11*1.1 -> 26930.082
A12: Textura escadas | B12: 25 | C12: R$ / AC | D12: 1 | E12: vb | F12: =B12*DADOS_INICIAIS!$E$9 -> 188322.25 | G12: =F12*D12*1.1 -> 207154.48
A13: Pintura Interna | B13: 75 | C13: R$ / AC | D13: 1 | E13: vb | F13: =B13*DADOS_INICIAIS!$E$9 -> 564966.75 | G13: =F13*D13*1.1 -> 621463.43
A14: TOTAL | G14: =SUM(G10:G13) -> 1068426.7 | K14: =4160+1440+1120+2880+4800+91680+4000 -> 110080 | L14: =K14/21 -> 5241.9048
A16: TOTAL IMPERMEABILIZAÇÃO | G16: =G14 -> 1068426.7 | H16: =G16/DADOS_INICIAIS!E9 -> 141.8349
H18: =H16/1.1 -> 128.94081

Sheet ESQUADRIAS
A3: ESQUADRIAS
A4: Data | B4: 45460
A5: Arquivo base | B5: -
A7: ESQUADRIAS
A9: Descrição | B9: Parâmetro | D9: Quantidade | G9: Valor total | H9: Observação
A10: Esquadrias de Alumínio | B10: 0.2 | C10: m² / AC | D10: =B10*DADOS_INICIAIS!E9 -> 1506.578 | E10: m² | F10: 1250 | G10: =F10*D10*1.1 -> 2071544.8 | H10: =G10/DADOS_INICIAIS!E9 -> 275
A11: Pele de vidro | D11: =(29.3/2)*3.2 -> 46.88 | E11: m² | F11: 950 | G11: =F11*D11*1.1 -> 48989.6 | H11: lojas
A12: Portão de alumínio | D12: 1 | E12: un | F12: 16000 | G12: =F12*D12*1.1 -> 17600
A13: Guarda-corpo - vidro | D13: =29.2+(17.81/4)*18 -> 109.345 | E13: m | F13: =750*1.1 -> 825 | G13: =F13*D13*1.1 -> 99230.588
A14: Gradil | E14: m² | F14: 610 | G14: =F14*D14*1.1 -> 0
A15: Serralherias | B15: 5 | C15: R$ / AC | D15: 1 | E15: vb | F15: =B15*DADOS_INICIAIS!$E$9 -> 37664.45 | G15: =F15*D15*1.1 -> 41430.895
A16: PCF | D16: =2*DADOS_INICIAIS!E15 -> 48 | E16: un | F16: 1750 | G16: =F16*D16*1.1 -> 92400
A17: Corrimão madeira | D17: =((2.5+3.75+3.55+2.38+1.08*4)*1.2*DADOS_INICIAIS!E15) -> 475.2 | E17: m | F17: 85 | G17: =F17*D17*1.1 -> 44431.2
A18: Fechadura Biometrica | D18: =DADOS_INICIAIS!E10 -> 36 | E18: un | F18: 1500 | G18: =F18*D18*1.1 -> 59400
A19: Esquadrias de Madeira | D19: =2+(6*DADOS_INICIAIS!E10) -> 218 | E19: un | F19: 2100 | G19: =F19*D19*1.1 -> 503580
A20: TOTAL | G20: =SUM(G10:G19) -> 2978607 | K20: =4160+1440+1120+2880+4800+91680+4000 -> 110080 | L20: =K20/21 -> 5241.9048
A22: TOTAL ESQUADRIAS | G22: =G20 -> 2978607 | H22: =G22/DADOS_INICIAIS!E9 -> 395.41358

Sheet COBERTURA
A2: COBERTURA
A3: Data | B3: 45460
A4: Arquivo base | B4: -
A6: TELHADO
A8: Descrição | B8: Parâmetro | D8: Quantidade | F8: Preço unitário | G8: Valor total | H8: Observação
A9: Estrutura e telhamento | D9: 266.19 | E9: m² | F9: 500 | G9: =F9*D9*1.1 -> 146404.5
A10: Serviços complementares | D10: =D9 -> 266.19 | E10: m² | F10: 45 | G10: =F10*D10*1.1 -> 13176.405
A11: Pergolados | G11: =F11*D11*1.1 -> 0
A12: Passarelas | G12: =F12*D12*1.1 -> 0
A13: TOTAL | G13: =SUM(G9:G12) -> 159580.9
A15: TOTAL COMPLEMENTARES | G15: =G13 -> 159580.9 | H15: =G15/DADOS_INICIAIS!$E$9 -> 21.184553

Sheet Rev. Fachada
A2: ORÇAMENTO PARAMÉTRICO GERENCIAMENTO EXECUTIVO
A7: Cliente | B7: Passe
A8: Obra | B8: Connect
A9: Data | B9: 45460
A10: Revisão | B10: R00
A12: REVESTIMENTOS ARGAMASSADOS
A14: Descrição | B14: Quantidade | D14: Parâmetro | F14: Referência | G14: Valor total
A15: Chapisco e reboco | B15: =(K19*L19+K20*L20+K21*L21-ESQUADRIAS!D10) -> 4816.262 | C15: m² | D15: =25+70 -> 95 | E15: R$ / m² | F15: - | G15: =B15*D15*1.1 -> 503299.38
A16: Trtamento de friso | B16: =K19*3+K20*18 -> 1571.844 | C16: m | D16: 5 | E16: R$ / m² | F16: - | G16: =B16*D16*1.1 -> 8645.142
A17: TOTAL | G17: =SUM(G15:G16) -> 511944.52
A19: PINTURA | J19: EMBASAMENTO | K19: =DADOS_INICIAIS!E26 -> 101.02 | L19: =3.2*5+1.2 -> 17.2
J20: TORRE 1 | K20: =DADOS_INICIAIS!E20*1.2 -> 70.488 | L20: =3.2*19+1.2 -> 62
A21: Descrição | B21: Quantidade | D21: Parâmetro | F21: Referência | G21: Valor total | J21: RESERV | K21: 33.6 | L21: =6.4 -> 6.4
A22: Textura | B22: =B15-(29.3*L19)-B23 -> 3349.0496 | C22: m² | D22: =25+52 -> 77 | E22: R$ / m² | F22: - | G22: =B22*D22*1.1 -> 283664.5 | L22: =K19*L19+K20*L20+K21*L21 -> 6322.84
A23: Patilha | B23: =B15*0.2 -> 963.2524 | C23: m² | D23: =110+2.25+65 -> 177.25 | E23: R$ / m² | F23: - | G23: =B23*D23*1.1 -> 187810.14 | L23: =K20*L20+K21*L21+K22*L22 -> 4585.296
A24: TOTAL | G24: =SUM(G22:G23) -> 471474.64
A26: ACABAMENTOS ESPECIAIS
A28: Descrição | B28: Quantidade | D28: Parâmetro | F28: Referência | G28: Valor total
A29: ACM embasamento | B29: =29.3*2*1.4 -> 82.04 | C29: m² | D29: 850 | E29: R$ / m² | F29: - | G29: =B29*D29*1.1 -> 76707.4
A30: Led vertical | B30: =L19+L20 -> 79.2 | C30: m | D30: 120 | E30: R$ / m | F30: - | G30: =B30*D30*1.1 -> 10454.4
A31: Brise Amadeirado embasamento | B31: =29.3*3.2+(10*6.4/2) -> 125.76 | C31: m² | D31: 1800 | E31: R$ / m² | F31: - | G31: =B31*D31*1.1 -> 249004.8
G32: =SUM(G29:G31) -> 336166.6
J33: =25.78*2 -> 51.56
A35: TOTAL FACHADA | G35: =G24+G17+G32 -> 1319585.8 | H35: =G35/DADOS_INICIAIS!E9 -> 175.17656
H36: =H35/1.1 -> 159.25142

Sheet COMPLEMENTARES
A2: COMPLEMENTARES
A3: Data | B3: 45460
A4: Arquivo base | B4: -
A6: SERVIÇOS COMPLEMENTARES
A8: Descrição | B8: Parâmetro | D8: Quantidade | F8: Valor total
A9: Móveis e decoração | B9: 1500 | C9: R$ / AL | D9: =DADOS_INICIAIS!E21 -> 504.89 | E9: m² | F9: =D9*B9*1.1 -> 833068.5
A10: Comunicação visual | B10: 10 | C10: R$ / AC | D10: =B10*DADOS_INICIAIS!$E$9 -> 75328.9 | E10: vb | F10: =D10*1.1 -> 82861.79
A11: Paisagismo | B11: 28 | C11: R$ / AC | D11: =B11*DADOS_INICIAIS!$E$9 -> 210920.92 | E11: vb | F11: =D11*1.1 -> 232013.01 | G11: parede verde
A12: Ligações definitivas | B12: 4 | C12: R$ / AC | D12: =B12*DADOS_INICIAIS!$E$9 -> 30131.56 | E12: vb | F12: =D12*1.1 -> 33144.716
A13: Desmobilização | B13: 5 | C13: R$ / AC | D13: =B13*DADOS_INICIAIS!$E$9 -> 37664.45 | E13: vb | F13: =D13*1.1 -> 41430.895
A14: Limpeza | B14: 15 | C14: R$ / AC | D14: =B14*DADOS_INICIAIS!$E$9 -> 112993.35 | E14: vb | F14: =D14*1.1 -> 124292.69
A15: TOTAL | F15: =SUM(F9:F14) -> 1346811.6
A17: TOTAL COMPLEMENTARES | F17: =F15 -> 1346811.6 | G17: =F17/DADOS_INICIAIS!$E$9 -> 178.79082

Sheet Auxiliar
A2: 2 Portões acesso garagem - Área: 9,2m² x 2 = 18,4m² | B2: 2 | C2: portão | D2: 18.4
A3: 2 portas corta-fogo 1 folha | B3: 2 | C3: pcf
A4: 1 porta de correr alumínio 2 folhas – Área: 3,465m² | B4: 1 | C4: porta alumínio | D4: 3.465
A5: 1 porta de correr alumínio 2 folhas – Área: 1,7325m² | B5: 1 | C5: porta alumínio | D5: 1.7325 | G5: Guarda alumínio | H5: =SUMIF(C:C,G5,D:D) -> 400.5221
A6: 2 portas de abrir alumínio 2 folhas – Área: 2,6376m² x 2 = 5,2752m² | B6: 2 | C6: porta alumínio | D6: 5.2752 | G6: janela | H6: =SUMIF(C:C,G6,D:D) -> 1895.06
A7: 1 porta de abrir alumínio 2 folhas – Área: 4,1916m² | B7: 1 | C7: porta alumínio | D7: 4.1916 | G7: madeira | H7: =SUMIF(C:C,G7,B:B) -> 218
A8: 1 porta pivotante | B8: 1 | C8: pivotante | G8: pcf | H8: =SUMIF(C:C,G8,B:B) -> 60
A9: 19 portas de abrir madeira 1 folha | B9: 19 | C9: madeira | G9: pivotante | H9: =SUMIF(C:C,G9,B:B) -> 1
A10: 3 portas de abrir vidro 1 folha – Área: 2,1m² x 3 = 6,3m² | B10: 3 | C10: porta alumínio | D10: 6.3 | G10: porta alumínio | H10: =SUMIF(C:C,G10,D:D) -> 46.62
A11: 2 portas de abrir vidro 1 folha – Área: 1,89m² x 2 = 3,78m² | B11: 2 | C11: porta alumínio | D11: 3.78 | G11: portão | H11: =SUMIF(C:C,G11,B:B) -> 2
A12: 1 porta de abrir alumínio 1 folha – Área: 2,0076m² | B12: 1 | C12: porta alumínio | D12: 2.0076 | G12: gradil | H12: =SUMIF(C:C,G12,D:D) -> 113.88
A13: Janelas – Área: 3,75 + 4,875 + 2,5 + 1,1 + 1,2 + 5,5402 + 4,4874 = 23,4526m² | C13: janela | D13: 23.4526 | G13: Brise | H13: 109.3146
A14: Muro de vidro – Área: 7,0774 + 5,485 + 3,43 + 4,8138 = 20,8062m² | C14: Guarda alumínio | D14: 20.8062
A15: 8 portas corta-fogo 1 folha | B15: 8 | C15: pcf
A16: Janelas – Area: (1,1 + 1,2 + 28,7391) x 4 = 124,1564m² | C16: janela | D16: 124.1564
A17: 2 portas corta-fogo 1 folha | B17: 2 | C17: pcf
A18: 2 portas de abrir alumínio 1 folha – Área: 1,47m² x 2 = 2,94m² | B18: 2 | C18: porta alumínio | D18: 2.94
A19: 2 portas de abrir vidro 1 folha – Área: 1,89m² x 2 = 3,78m² | B19: 2 | C19: porta alumínio | D19: 3.78
A20: 5 portas de abrir madeira 1 folha | B20: 5 | C20: madeira
A21: 1 janela-porta de correr vidro – Área: 14,7348m² | B21: 1 | C21: janela | D21: 14.7348
A22: Janelas – Área: 1,2894 + 1,2894 + 23,46 + 1,854 + 5,562 + 5,562 + 1,854 + 1,854 + 1,1 + 1,2 = 45,0248m² | C22: janela | D22: 45.0248
A23: Guarda corpo vidro – Área: 7,5299 + 5,7955 + 6,5555 = 19,8809m² | C23: Guarda alumínio | D23: 19.8809
A24: 38 portas corta-fogo 1 folha | B24: 38 | C24: pcf
A25: 171 portas de abrir madeira 1 folha | B25: 171 | C25: madeira
A26: 19 porta de abrir alumínio 1 folha – Área: 1,26m² x 19 = 23,94m² | B26: 19 | C26: porta alumínio | D26: 23.94
A27: 19 janela-porta de correr vidro 5 folhas - Área: 25,4205m² x 19 = 482,9895m² | B27: 19 | C27: janela | D27: 482.9895
A28: 19 janela-porta de correr vidro 5 folhas - Área: 17,8284m² x 19 = 338,7396m² | B28: 19 | C28: janela | D28: 338.7396
A29: Janelas – Área: 1,1 + 1,1 + 1,2 + 1,92 + 0,36 + 2,781 + 2,781 + 1,854 + 1,854 + 5,562 + 5,562 + 1,854 = 27,928m² x 19 = 530,632m² | C29: janela | D29: 530.632
A30: Guarda corpo metálico – Área: 4,745m² x 19 = 90,155m² - Perímetro: 3,65m x 19 = 69,35m | C30: gradil | D30: 90.155
A31: Guarda corpo vidro – Área: 15,645m² x 19 = 297,255m² - Perímetro: 14,9m x 19 = 283,1m | C31: Guarda alumínio | D31: 297.255
A32: 2 portas corta-fogo 1 folha | B32: 2 | C32: pcf
A33: 2 portas de abrir madeira 1 folha | B33: 2 | C33: madeira
A34: 1 porta de abrir alumínio 1 folha – Área: 1,26m² | B34: 1 | C34: porta alumínio | D34: 1.26
A35: 1 janela-porta de correr vidro 3 folhas - Área: 15,21m² | B35: 1 | C35: janela | D35: 15.21
A36: 1 janela-porta de correr vidro 5 folhas - Área: 25,4205m² | B36: 1 | C36: janela | D36: 25.4205
A37: 1 janela-porta de correr vidro 5 folhas - Área: 17,8284m² | B37: 1 | C37: janela | D37: 17.8284
A38: Janelas – Área: 1,1 + 1,2 + 1,1 + 1,92 + 0,36 + 2,781 + 2,781 + 1,854 + 1,854 + 5,562 + 5,562 + 1,854 = 27,928m² | C38: janela | D38: 27.928
A39: Guarda corpo metálico – Área: 4,745m² - Perímetro: 3,65m | C39: gradil | D39: 4.745
A40: Guarda corpo vidro – Área: 15,645m² - Perímetro: 14,9m | C40: Guarda alumínio | D40: 15.645
A41: 2 portas corta-fogo 1 folha | B41: 2 | C41: pcf
...
