Workbook
Name \0: #REF!
Name \0: #REF!
Name \0: #REF!
Name \1: #REF!
Name \1: #REF!
Name \a: #REF!
Name \a: #REF!
Name \b: #REF!
Name \c: #REF!
Name \d: #REF!
Name \e: #REF!
Name \i: #REF!
Name \J: #REF!
Name \k: #REF!
Name \l: #N/A
Name \m: #REF!
Name \m: #REF!
Name \o: #REF!
Name \p: #REF!
Name \r: #REF!
Name \T: #REF!
Name \z: #REF!
Name ______ACR10: #REF!
Name ______ACR15: #REF!
Name ______acr20: #REF!
Name ______acr5: #REF!
Name ______ARQ1: #REF!
Name ______QT100: #REF!
Name ______QT2: #REF!
Name ______QT3: #REF!
Name ______QT4: #REF!
Name ______QT50: #REF!
Name ______QT75: #REF!
Name _____ACR10: #REF!
Name _____ACR15: #REF!
Name _____acr20: #REF!
Name _____acr5: #REF!
Name _____ARQ1: #REF!
Name _____QT100: #REF!
Name _____QT2: #REF!
Name _____QT3: #REF!
Name _____QT4: #REF!
Name _____QT50: #REF!
Name _____QT75: #REF!
Name ___ACR10: #REF!
Name ___ACR15: #REF!
Name ___acr20: #REF!
Name ___acr5: #REF!
Name ___ARQ1: #REF!
Name ___QT100: #REF!
Name ___QT2: #REF!
Name ___QT3: #REF!
Name ___QT4: #REF!
Name ___QT50: #REF!
Name ___QT75: #REF!
Name __ACR10: #REF!
Name __ACR15: #REF!
Name __acr20: #REF!
Name __acr5: #REF!
Name __ARQ1: #REF!

Sheet OBRA
A1: ESTUDO DE VIABILIDADE
A7: Cliente | B7: HOTEL COLLINE
A8: Obra | B8: HOTEL COLLINE - MIGUEL PEREIRA - RIO DE JANEIRO
A9: Data | B9: 45824
A10: Versão | B10: R01
B13: Descrição | C13: Identificador | D13: Unidade | E13: Hotel | F13: Residencial | G13: Quantidade Total
B14: ÁREA DO TERRENO | C14: AT | D14: M2 | G14: 6049.17
B15: ÁREA TOTAL CONSTRUÍDA | C15: AC | D15: M2 | E15: =SUM(E16:E26) -> 6049.17 | F15: =SUM(F16:F26) -> 21510.28 | G15: =SUM(G16:G26) -> 27559.45
B16: SUBSOLO / TERREO | D16: M2 | E16: 1662.34 | F16: 2365.57 | G16: =F16+E16 -> 4027.91
B17: TÉRREO/ GARAGEM 1 | D17: M2 | E17: =1147.74+527.82 -> 1675.56 | F17: 2339.03 | G17: =F17+E17 -> 4014.59
B18: 1º PAVIMENTO / GARAGEM 2 | D18: M2 | E18: =812.7+31.66 -> 844.36 | F18: 2514.32 | G18: =F18+E18 -> 3358.68
B19: 2º PAVIMENTO / LAZER | D19: M2 | E19: =900.46+243.83 -> 1144.29 | F19: 2513.4 | G19: =F19+E19 -> 3657.69
B20: SUBTELHADO / 5º PAV. DIFERENCIADO TORRE I E II (X1) | D20: M2 | E20: =691.7+30.92 -> 722.62 | F20: 699.84 | G20: =F20+E20 -> 1422.46
B21: 6º AO 18º PAV. DIFERENCIADO TORRE I E II (X13) | D21: M2 | F21: 9097.92 | G21: =F21+E21 -> 9097.92
B22: DUPLEX INFERIOR TORRE I E II | D22: M2 | F22: 699.84 | G22: =F22+E22 -> 699.84
B23: DUPLEX SUPERIOR TORRE I E II | D23: M2 | F23: 693.56 | G23: =F23+E23 -> 693.56
B24: INSPEÇÃO TORRE I E II | D24: M2 | F24: 303.24 | G24: =F24+E24 -> 303.24
B25: CASA DE MÁQUINAS TORRE I E II | D25: M2 | F25: 150.18 | G25: =F25+E25 -> 150.18
B26: CAIXA D'AGUA TORRE I E II | D26: M2 | F26: 133.38 | G26: =F26+E26 -> 133.38
B27: UNIDADES RESIDENCIAIS | C27: UR | D27: UN | E27: 36 | F27: 60 | G27: =F27+E27 -> 96
B28: Dormitórios | C28: dorm | D28: UN | E28: =E27 -> 36 | G28: =F28+E28 -> 36
B29: Banheiros | C29: ban | D29: UN | G29: =F29+E29 -> 0
B30: UNIDADES COMERCIAIS | C30: UC | D30: UN | G30: =F30+E30 -> 0
B31: Churrasqueiras | C31: CHU | D31: UN | F31: 60 | G31: =F31+E31 -> 60
B32: NÚMERO TOTAL DE PAVIMENTOS | C32: NP | D32: UN | E32: 5 | F32: 23 | G32: =F32+E32 -> 28
B33: NÚMERO DE PAVIMENTOS TIPO | C33: NPT | D33: UN | E33: 0 | F33: 13 | G33: =F33+E33 -> 13
B34: NÚMERO DE PAVIMENTOS TIPO DIFERENCIADOS | C34: NPD | D34: UN | E34: 3 | F34: 1 | G34: =F34+E34 -> 4
B35: NÚMERO DE PAVIMENTOS DUPLEX | C35: ND | D35: UN | E35: 0 | F35: 1 | G35: =F35+E35 -> 1
B36: ÁREA DE PROJEÇÃO DA TORRE | C36: APT | D36: M2 | E36: 1021.82 | F36: =369.45*2 -> 738.9 | G36: =F36+E36 -> 1760.72
B37: PERÍMETRO DE PROJEÇÃO DA TORRE | C37: PPT | D37: M | E37: 151.474 | F37: =101.4*2 -> 202.8 | G37: =F37+E37 -> 354.274
B38: ÁREA DE LAZER | C38: AL | D38: M2 | E38: 0 | F38: =F20 -> 699.84 | G38: =F38+E38 -> 699.84
B39: ÁREA DO EMBASAMENTO | C39: AE | D39: M2 | E39: =E17 -> 1675.56 | F39: =F17+F18+F19 -> 7366.75 | G39: =F39+E39 -> 9042.31
B40: ÁREA DE SUBSOLOS | C40: S | D40: M2 | E40: =E16 -> 1662.34 | F40: 0 | G40: =F40+E40 -> 1662.34
B41: NÚMERO DE SUBSOLOS | C41: NS | D41: UN | E41: 1 | F41: 0 | G41: =F41+E41 -> 1
B42: ÁREA DE PROJEÇÃO DO EMBASAMENTO | C42: APE | D42: M2 | E42: 2087.28 | F42: 2365.57 | G42: =F42+E42 -> 4452.85
B43: PERÍMETRO DE PROJEÇÃO DE EMBAMENTO | C43: PE | D43: M | E43: 226.19 | F43: 223.43 | G43: =F43+E43 -> 449.62
B44: NÚMERO DE PAVIMENTOS DE EMBASAMENTO | C44: NE | D44: UN | E44: 1 | F44: 3 | G44: =F44+E44 -> 4
B45: PRAZO HOTEL | C45: PM | D45: mês | E45: 24
B46: PRAZO RESIDENCIAL | C46: P1 | D46: mês | F46: 36
B47: PRAZO DE OBRA TOTAL (INICIO AO FIM) | C47: PR | D47: mês | G47: =F46 -> 36
...

Sheet RESUMOS
A1: HOTEL | B1: R00 | E1: R01 | H1: DIFERENÇA
A2: ETAPA | B2: VALOR ORÇADO | C2: % | D2: VALOR / m² | E2: VALOR ORÇADO | F2: % | G2: VALOR / m² | H2: VALOR ORÇADO | I2: % | J2: VALOR / m²
A3: MOVIMENTAÇÃO DE TERRA | B3: =[4]HOTEL!$L$5 -> 137245.95 | C3: =B3/B$18 -> 0.0033071137 | D3: =B3/RESUMOS!M$3 -> 22.688394 | E3: =HOTEL!L5 -> 137245.95 | F3: =E3/E$18 -> 0.0032933654 | G3: =E3/RESUMOS!M$3 -> 22.688394 | H3: =E3-B3 -> 0 | I3: =H3/B3 -> 0 | J3: =H3/RESUMOS!M$3 -> 0 | L3: ÁREA CONSTRUÍDA HOTEL | M3: =[5]OBRA!$E$15 -> 6049.17 | N3: m²
A4: INFRAESTRUTURA | B4: =[4]HOTEL!$L$22 -> 2200957.6 | C4: =B4/B$18 -> 0.053034839 | D4: =B4/RESUMOS!M$3 -> 363.84457 | E4: =HOTEL!L22 -> 2200957.6 | F4: =E4/E$18 -> 0.052814363 | G4: =E4/RESUMOS!M$3 -> 363.84457 | H4: =E4-B4 -> 0 | I4: =H4/B4 -> 0 | J4: =H4/RESUMOS!M$3 -> 0 | L4: ÁREA CONSTRUÍDA RESIDENCIAL | M4: =[5]OBRA!$F$15 -> 21510.28 | N4: m²
A5: SUPRAESTRUTURA | B5: =[4]HOTEL!$L$40 -> 4644536.7 | C5: =B5/B$18 -> 0.11191595 | D5: =B5/RESUMOS!M$3 -> 767.79735 | E5: =HOTEL!L40 -> 4644536.7 | F5: =E5/E$18 -> 0.11145069 | G5: =E5/RESUMOS!M$3 -> 767.79735 | H5: =E5-B5 -> 0 | I5: =H5/B5 -> 0 | J5: =H5/RESUMOS!M$3 -> 0 | M5: =M3+M4 -> 27559.45
A6: PAREDES E PAINÉIS | B6: =[4]HOTEL!$L$54 -> 2943440.9 | C6: =B6/B$18 -> 0.070925907 | D6: =B6/RESUMOS!M$3 -> 486.58591 | E6: =HOTEL!L54 -> 2968837.7 | F6: =E6/E$18 -> 0.071240478 | G6: =E6/RESUMOS!M$3 -> 490.7843 | H6: =E6-B6 -> 25396.8 | I6: =H6/B6 -> 0.0086282691 | J6: =H6/RESUMOS!M$3 -> 4.1983942
A7: INSTALAÇÕES ELÉTRICAS, HIDRÁULICAS, GLP E PREVENTIVAS | B7: =[4]HOTEL!$L$107+[4]HOTEL!$L$130+[4]HOTEL!$L$153+[4]HOTEL!$L$167+[4]HOTEL!$L$366 -> 3789528.2 | C7: =B7/B$18 -> 0.091313444 | D7: =B7/RESUMOS!M$3 -> 626.45424 | E7: =HOTEL!L108+HOTEL!L131+HOTEL!L154+HOTEL!L168+HOTEL!L369 -> 3789528.2 | F7: =E7/E$18 -> 0.090933836 | G7: =E7/RESUMOS!M$3 -> 626.45424 | H7: =E7-B7 -> 0 | I7: =H7/B7 -> 0 | J7: =H7/RESUMOS!M$3 -> 0
A8: EQUIPAMENTOS E SISTEMAS ESPECIAIS | B8: =[4]HOTEL!$L$179+[4]HOTEL!$L$190+[4]HOTEL!$L$209 -> 6534261.9 | C8: =B8/B$18 -> 0.15745125 | D8: =B8/RESUMOS!M$3 -> 1080.1915 | E8: =HOTEL!L180+HOTEL!L191+HOTEL!L210 -> 6534261.9 | F8: =E8/E$18 -> 0.1567967 | G8: =E8/RESUMOS!M$3 -> 1080.1915 | H8: =E8-B8 -> 0 | I8: =H8/B8 -> 0 | J8: =H8/RESUMOS!M$3 -> 0
A9: IMPERMEABILIZAÇÃO | B9: =[4]HOTEL!$L$73 -> 493452.25 | C9: =B9/B$18 -> 0.011890352 | D9: =B9/RESUMOS!M$3 -> 81.573546 | E9: =HOTEL!L74 -> 493452.25 | F9: =E9/E$18 -> 0.011840921 | G9: =E9/RESUMOS!M$3 -> 81.573546 | H9: =E9-B9 -> 0 | I9: =H9/B9 -> 0 | J9: =H9/RESUMOS!M$3 -> 0
A10: REVESTIMENTOS INTERNOS DE PAREDE | B10: =[4]HOTEL!$L$224 -> 2569648.4 | C10: =B10/B$18 -> 0.061918907 | D10: =B10/RESUMOS!M$3 -> 424.79355 | E10: =HOTEL!L225 -> 2569648.4 | F10: =E10/E$18 -> 0.061661498 | G10: =E10/RESUMOS!M$3 -> 424.79355 | H10: =E10-B10 -> 0 | I10: =H10/B10 -> 0 | J10: =H10/RESUMOS!M$3 -> 0
A11: REVESTIMENTOS E ACABAMENTOS INTERNOS EM TETO | B11: =[4]HOTEL!$L$248 -> 855037.86 | C11: =B11/B$18 -> 0.020603212 | D11: =B11/RESUMOS!M$3 -> 141.34796 | E11: =HOTEL!L249 -> 831199.77 | F11: =E11/E$18 -> 0.019945539 | G11: =E11/RESUMOS!M$3 -> 137.40724 | H11: =E11-B11 -> -23838.089 | I11: =H11/B11 -> -0.027879571 | J11: =H11/RESUMOS!M$3 -> -3.9407206
A12: PISOS E PAVIMENTAÇÕES | B12: =[4]HOTEL!$L$261 -> 3227702.4 | C12: =B12/B$18 -> 0.077775544 | D12: =B12/RESUMOS!M$3 -> 533.57773 | E12: =HOTEL!L264 -> 3231121.7 | F12: =E12/E$18 -> 0.077534267 | G12: =E12/RESUMOS!M$3 -> 534.14298 | H12: =E12-B12 -> 3419.3378 | I12: =H12/B12 -> 0.0010593721 | J12: =H12/RESUMOS!M$3 -> 0.56525735
A13: PINTURA INTERNA | B13: =[4]HOTEL!$L$300 -> 890994.12 | C13: =B13/B$18 -> 0.021469623 | D13: =B13/RESUMOS!M$3 -> 147.29196 | E13: =HOTEL!L303 -> 890237.65 | F13: =E13/E$18 -> 0.021362217 | G13: =E13/RESUMOS!M$3 -> 147.16691 | H13: =E13-B13 -> -756.4711 | I13: =H13/B13 -> -0.00084901918 | J13: =H13/RESUMOS!M$3 -> -0.1250537
A14: ESQUADRIAS, VIDROS E FERRAGENS | B14: =[4]HOTEL!$L$319 -> 10001040 | C14: =B14/B$18 -> 0.24098763 | D14: =B14/RESUMOS!M$3 -> 1653.2913 | E14: =HOTEL!L322 -> 10170063 | F14: =E14/E$18 -> 0.24404169 | G14: =E14/RESUMOS!M$3 -> 1681.2328 | H14: =E14-B14 -> 169023.14 | I14: =H14/B14 -> 0.016900556 | J14: =H14/RESUMOS!M$3 -> 27.941543
A15: COBERTURA | B15: =[4]HOTEL!$L$377 -> 1393694.5 | C15: =B15/B$18 -> 0.033582819 | D15: =B15/RESUMOS!M$3 -> 230.39433 | E15: =HOTEL!L380 -> 1393694.5 | F15: =E15/E$18 -> 0.033443209 | G15: =E15/RESUMOS!M$3 -> 230.39433 | H15: =E15-B15 -> 0 | I15: =H15/B15 -> 0 | J15: =H15/RESUMOS!M$3 -> 0
A16: REVESTIMENTOS E ACABAMENTOS DE FACHADA | B16: =[4]HOTEL!$L$395 -> 1254677.7 | C16: =B16/B$18 -> 0.030233035 | D16: =B16/RESUMOS!M$3 -> 207.41319 | E16: =HOTEL!L398 -> 1254677.7 | F16: =E16/E$18 -> 0.03010735 | G16: =E16/RESUMOS!M$3 -> 207.41319 | H16: =E16-B16 -> 0 | I16: =H16/B16 -> 0 | J16: =H16/RESUMOS!M$3 -> 0
A17: SERVIÇOS COMPLEMENTARES | B17: =[4]HOTEL!$L$425 -> 564003.74 | C17: =B17/B$18 -> 0.013590379 | D17: =B17/RESUMOS!M$3 -> 93.23655 | E17: =HOTEL!L428 -> 564003.74 | F17: =E17/E$18 -> 0.013533881 | G17: =E17/RESUMOS!M$3 -> 93.23655 | H17: =E17-B17 -> 0 | I17: =H17/B17 -> 0 | J17: =H17/RESUMOS!M$3 -> 0
A18: TOTAL | B18: =SUM(B3:B17) -> 41500222 | C18: =SUM(C3:C17) -> 1 | D18: =SUM(D3:D17) -> 6860.4821 | E18: =SUM(E3:E17) -> 41673467 | F18: =SUM(F3:F17) -> 1 | G18: =SUM(G3:G17) -> 6889.1215 | H18: =SUM(H3:H17) -> 173244.72 | I18: =SUM(I3:I17) -> -0.0021403928 | J18: =SUM(J3:J17) -> 28.63942
A19: CUB/RJ | B19: 2303.36 | C19: 45717 | D19: =+D18/B19 -> 2.9784671 | E19: 2303.36 | F19: 45717 | G19: =+G18/E19 -> 2.9909009 | H19: =H18/B18 -> 0.0041745492 | J19: =+J18/E19 -> 0.012433758
A21: RESIDENCIAL | B21: R00 | E21: R01 | H21: DIFERENÇA
A22: ETAPA | B22: VALOR ORÇADO | C22: % | D22: VALOR / m² | E22: VALOR ORÇADO | F22: % | G22: VALOR / m² | H22: VALOR ORÇADO | I22: % | J22: VALOR / m²
A23: MOVIMENTAÇÃO DE TERRA | B23: =[4]RESIDENCIAL!$L$5 -> 150402.2 | C23: =B23/B$38 -> 0.00172833 | D23: =B23/RESUMOS!M$4 -> 6.9921082 | E23: =RESIDENCIAL!L5 -> 150402.2 | F23: =E23/E$38 -> 0.0017183605 | G23: =E23/RESUMOS!M$4 -> 6.9921082 | H23: =E23-B23 -> 0 | I23: =H23/B23 -> 0 | J23: =H23/RESUMOS!M$4 -> 0
A24: INFRAESTRUTURA | B24: =[4]RESIDENCIAL!$L$22 -> 4184719.8 | C24: =B24/B$38 -> 0.048088237 | D24: =B24/RESUMOS!M$4 -> 194.54511 | E24: =RESIDENCIAL!L22 -> 4184719.8 | F24: =E24/E$38 -> 0.04781085 | G24: =E24/RESUMOS!M$4 -> 194.54511 | H24: =E24-B24 -> 0 | I24: =H24/B24 -> 0 | J24: =H24/RESUMOS!M$4 -> 0
A25: SUPRAESTRUTURA | B25: =[4]RESIDENCIAL!$L$40 -> 15149858 | C25: =B25/B$38 -> 0.17409288 | D25: =B25/RESUMOS!M$4 -> 704.30778 | E25: =RESIDENCIAL!L40 -> 15149858 | F25: =E25/E$38 -> 0.17308866 | G25: =E25/RESUMOS!M$4 -> 704.30778 | H25: =E25-B25 -> 0 | I25: =H25/B25 -> 0 | J25: =H25/RESUMOS!M$4 -> 0
A26: PAREDES E PAINÉIS | B26: =[4]RESIDENCIAL!$L$54 -> 6993312.5 | C26: =B26/B$38 -> 0.080362864 | D26: =B26/RESUMOS!M$4 -> 325.1149 | E26: =RESIDENCIAL!L54 -> 6993312.5 | F26: =E26/E$38 -> 0.079899307 | G26: =E26/RESUMOS!M$4 -> 325.1149 | H26: =E26-B26 -> 0 | I26: =H26/B26 -> 0 | J26: =H26/RESUMOS!M$4 -> 0
A27: INSTALAÇÕES ELÉTRICAS, HIDRÁULICAS, GLP E PREVENTIVAS | B27: =[4]RESIDENCIAL!$L$108+[4]RESIDENCIAL!$L$132+[4]RESIDENCIAL!$L$155+[4]RESIDENCIAL!$L$169+[4]RESIDENCIAL!$L$379 -> 9279749.7 | C27: =B27/B$38 -> 0.1066372 | D27: =B27/RESUMOS!M$4 -> 431.40999 | E27: =RESIDENCIAL!L108+RESIDENCIAL!L132+RESIDENCIAL!L155+RESIDENCIAL!L169+RESIDENCIAL!L382 -> 9279749.7 | F27: =E27/E$38 -> 0.10602208 | G27: =E27/RESUMOS!M$4 -> 431.40999 | H27: =E27-B27 -> 0 | I27: =H27/B27 -> 0 | J27: =H27/RESUMOS!M$4 -> 0
A28: EQUIPAMENTOS E SISTEMAS ESPECIAIS | B28: =[4]RESIDENCIAL!$L$181+[4]RESIDENCIAL!$L$192+[4]RESIDENCIAL!$L$211 -> 4796558.1 | C28: =B28/B$38 -> 0.055119107 | D28: =B28/RESUMOS!M$4 -> 222.9891 | E28: =RESIDENCIAL!L181+RESIDENCIAL!L192+RESIDENCIAL!L212 -> 5166429.3 | F28: =E28/E$38 -> 0.05902698 | G28: =E28/RESUMOS!M$4 -> 240.1842 | H28: =E28-B28 -> 369871.22 | I28: =H28/B28 -> 0.077111798 | J28: =H28/RESUMOS!M$4 -> 17.195091
A29: IMPERMEABILIZAÇÃO | B29: =[4]RESIDENCIAL!$L$74 -> 1276413.3 | C29: =B29/B$38 -> 0.01466776 | D29: =B29/RESUMOS!M$4 -> 59.33969 | E29: =RESIDENCIAL!L74 -> 1276413.3 | F29: =E29/E$38 -> 0.014583152 | G29: =E29/RESUMOS!M$4 -> 59.33969 | H29: =E29-B29 -> 0 | I29: =H29/B29 -> 0 | J29: =H29/RESUMOS!M$4 -> 0
A30: REVESTIMENTOS INTERNOS DE PAREDE | B30: =[4]RESIDENCIAL!$L$230 -> 2958539.7 | C30: =B30/B$38 -> 0.033997726 | D30: =B30/RESUMOS!M$4 -> 137.54073 | E30: =RESIDENCIAL!L231 -> 2958539.7 | F30: =E30/E$38 -> 0.033801617 | G30: =E30/RESUMOS!M$4 -> 137.54073 | H30: =E30-B30 -> 0 | I30: =H30/B30 -> 0 | J30: =H30/RESUMOS!M$4 -> 0
A31: REVESTIMENTOS E ACABAMENTOS INTERNOS EM TETO | B31: =[4]RESIDENCIAL!$L$254 -> 2340465.1 | C31: =B31/B$38 -> 0.026895191 | D31: =B31/RESUMOS!M$4 -> 108.80682 | E31: =RESIDENCIAL!L255 -> 2442171.8 | F31: =E31/E$38 -> 0.027902061 | G31: =E31/RESUMOS!M$4 -> 113.5351 | H31: =E31-B31 -> 101706.72 | I31: =H31/B31 -> 0.043455774 | J31: =H31/RESUMOS!M$4 -> 4.7282844
A32: PISOS E PAVIMENTAÇÕES | B32: =[4]RESIDENCIAL!$L$272 -> 7298340.6 | C32: =B32/B$38 -> 0.08386806 | D32: =B32/RESUMOS!M$4 -> 339.29547 | E32: =RESIDENCIAL!L275 -> 7331642.3 | F32: =E32/E$38 -> 0.083764759 | G32: =E32/RESUMOS!M$4 -> 340.84365 | H32: =E32-B32 -> 33301.671 | I32: =H32/B32 -> 0.00456291 | J32: =H32/RESUMOS!M$4 -> 1.5481747
A33: PINTURA INTERNA | B33: =[4]RESIDENCIAL!$L$313 -> 3699799.5 | C33: =B33/B$38 -> 0.04251583 | D33: =B33/RESUMOS!M$4 -> 172.00146 | E33: =RESIDENCIAL!L316 -> 3699799.5 | F33: =E33/E$38 -> 0.042270586 | G33: =E33/RESUMOS!M$4 -> 172.00146 | H33: =E33-B33 -> 0 | I33: =H33/B33 -> 0 | J33: =H33/RESUMOS!M$4 -> 0
A34: ESQUADRIAS, VIDROS E FERRAGENS | B34: =[4]RESIDENCIAL!$L$332 -> 17129486 | C34: =B34/B$38 -> 0.19684156 | D34: =B34/RESUMOS!M$4 -> 796.33953 | E34: =RESIDENCIAL!L335 -> 17129486 | F34: =E34/E$38 -> 0.19570612 | G34: =E34/RESUMOS!M$4 -> 796.33953 | H34: =E34-B34 -> 0 | I34: =H34/B34 -> 0 | J34: =H34/RESUMOS!M$4 -> 0
A35: COBERTURA | B35: =[4]RESIDENCIAL!$L$390 -> 1138286.1 | C35: =B35/B$38 -> 0.013080486 | D35: =B35/RESUMOS!M$4 -> 52.918235 | E35: =RESIDENCIAL!L393 -> 1138286.1 | F35: =E35/E$38 -> 0.013005034 | G35: =E35/RESUMOS!M$4 -> 52.918235 | H35: =E35-B35 -> 0 | I35: =H35/B35 -> 0 | J35: =H35/RESUMOS!M$4 -> 0
A36: REVESTIMENTOS E ACABAMENTOS DE FACHADA | B36: =[4]RESIDENCIAL!$L$408 -> 3653145 | C36: =B36/B$38 -> 0.041979705 | D36: =B36/RESUMOS!M$4 -> 169.83252 | E36: =RESIDENCIAL!L411 -> 3653145 | F36: =E36/E$38 -> 0.041737553 | G36: =E36/RESUMOS!M$4 -> 169.83252 | H36: =E36-B36 -> 0 | I36: =H36/B36 -> 0 | J36: =H36/RESUMOS!M$4 -> 0
A37: SERVIÇOS COMPLEMENTARES | B37: =[4]RESIDENCIAL!$L$442 -> 6972618.1 | C37: =B37/B$38 -> 0.080125056 | D37: =B37/RESUMOS!M$4 -> 324.15283 | E37: =RESIDENCIAL!L445 -> 6972618.1 | F37: =E37/E$38 -> 0.079662871 | G37: =E37/RESUMOS!M$4 -> 324.15283 | H37: =E37-B37 -> 0 | I37: =H37/B37 -> 0 | J37: =H37/RESUMOS!M$4 -> 0
A38: TOTAL | B38: =SUM(B23:B37) -> 87021693 | C38: =SUM(C23:C37) -> 1 | D38: =SUM(D23:D37) -> 4045.5863 | E38: =SUM(E23:E37) -> 87526573 | F38: =SUM(F23:F37) -> 1 | G38: =SUM(G23:G37) -> 4069.0578 | H38: =SUM(H23:H37) -> 504879.61 | I38: =SUM(I23:I37) -> 0.12513048 | J38: =SUM(J23:J37) -> 23.47155
A39: CUB/RJ | B39: 2303.36 | C39: 45717 | D39: =+D38/B39 -> 1.7563847 | E39: 2303.36 | F39: 45717 | G39: =+G38/E39 -> 1.7665748 | H39: =H38/B38 -> 0.0058017672 | J39: =+J38/E39 -> 0.010190135
A41: TOTAL | B41: R00 | E41: R01 | H41: DIFERENÇA
A42: ETAPA | B42: VALOR ORÇADO | C42: % | D42: VALOR / m² | E42: VALOR ORÇADO | F42: % | G42: VALOR / m² | H42: VALOR ORÇADO | I42: % | J42: VALOR / m²
...

Sheet CUB
A1: Relação de custos excluindo etapas não contabilizadas pelo CUB
B2: HOTEL | E2: RESIDENCIAL | H2: TOTAL
A3: ETAPA | B3: VALOR ORÇADO | C3: % | D3: VALOR / m² | E3: VALOR ORÇADO | F3: % | G3: VALOR / m² | H3: VALOR ORÇADO | I3: % | J3: VALOR / m²
A4: MOVIMENTAÇÃO DE TERRA | B4: 137245.95 | C4: =B4/B$19 -> 0.004076226 | D4: =B4/CUB!O$4 -> 22.688394 | E4: 150402.2 | F4: =E4/E$19 -> 0.0020346285 | G4: =E4/CUB!O$5 -> 6.9921082 | H4: =E4+B4 -> 287648.16 | I4: =H4/H$19 -> 0.0026735318 | J4: =H4/CUB!O$6 -> 10.437369 | N4: ÁREA CONSTRUÍDA HOTEL | O4: =[5]OBRA!$E$15 -> 6049.17 | P4: m²
A5: INFRAESTRUTURA | B5: 2200957.6 | C5: =B5/B$19 -> 0.06536878 | D5: =B5/CUB!O$4 -> 363.84457 | E5: 4184719.8 | F5: =E5/E$19 -> 0.05661054 | G5: =E5/CUB!O$5 -> 194.54511 | H5: =E5+B5 -> 6385677.5 | I5: =H5/H$19 -> 0.059351369 | J5: =H5/CUB!O$6 -> 231.70555 | N5: ÁREA CONSTRUÍDA RESIDENCIAL | O5: =[5]OBRA!$F$15 -> 21510.28 | P5: m²
A6: SUPRAESTRUTURA | B6: 4644536.7 | C6: =B6/B$19 -> 0.13794346 | D6: =B6/CUB!O$4 -> 767.79735 | E6: 15149858 | F6: =E6/E$19 -> 0.20494601 | G6: =E6/CUB!O$5 -> 704.30778 | H6: =E6+B6 -> 19794394 | I6: =H6/H$19 -> 0.18397804 | J6: =H6/CUB!O$6 -> 718.24344 | O6: =O4+O5 -> 27559.45
A7: PAREDES E PAINÉIS | B7: 2968837.7 | C7: =B7/B$19 -> 0.088174937 | D7: =B7/CUB!O$4 -> 490.7843 | E7: 6993312.5 | F7: =E7/E$19 -> 0.094604948 | G7: =E7/CUB!O$5 -> 325.1149 | H7: =E7+B7 -> 9962150.2 | I7: =H7/H$19 -> 0.092592722 | J7: =H7/CUB!O$6 -> 361.47856
A8: INSTALAÇÕES ELÉTRICAS, HIDRÁULICAS, GLP E PREVENTIVAS | B8: 2884186 | C8: =B8/B$19 -> 0.085660769 | D8: =B8/CUB!O$4 -> 476.79037 | E8: 7800237.6 | F8: =E8/E$19 -> 0.10552096 | G8: =E8/CUB!O$5 -> 362.62836 | H8: =E8+B8 -> 10684424 | I8: =H8/H$19 -> 0.099305856 | J8: =H8/CUB!O$6 -> 387.68639
A9: EQUIPAMENTOS E SISTEMAS ESPECIAIS | B9: 0 | C9: =B9/B$19 -> 0 | D9: =B9/CUB!O$4 -> 0 | E9: 13200 | F9: =E9/E$19 -> 0.0001785685 | G9: =E9/CUB!O$5 -> 0.61366007 | H9: =E9+B9 -> 13200 | I9: =H9/H$19 -> 0.00012268676 | J9: =H9/CUB!O$6 -> 0.47896457
A10: IMPERMEABILIZAÇÃO | B10: 493452.25 | C10: =B10/B$19 -> 0.014655608 | D10: =B10/CUB!O$4 -> 81.573546 | E10: 1276413.3 | F10: =E10/E$19 -> 0.017267213 | G10: =E10/CUB!O$5 -> 59.33969 | H10: =E10+B10 -> 1769865.6 | I10: =H10/H$19 -> 0.01644993 | J10: =H10/CUB!O$6 -> 64.219917
A11: REVESTIMENTOS INTERNOS DE PAREDE | B11: 2569648.4 | C11: =B11/B$19 -> 0.076318954 | D11: =B11/CUB!O$4 -> 424.79355 | E11: 2958539.7 | F11: =E11/E$19 -> 0.040022877 | G11: =E11/CUB!O$5 -> 137.54073 | H11: =E11+B11 -> 5528188.1 | I11: =H11/H$19 -> 0.051381476 | J11: =H11/CUB!O$6 -> 200.59138
A12: REVESTIMENTOS E ACABAMENTOS INTERNOS EM TETO | B12: 831199.77 | C12: =B12/B$19 -> 0.024686761 | D12: =B12/CUB!O$4 -> 137.40724 | E12: 2442171.8 | F12: =E12/E$19 -> 0.033037496 | G12: =E12/CUB!O$5 -> 113.5351 | H12: =E12+B12 -> 3273371.6 | I12: =H12/H$19 -> 0.030424193 | J12: =H12/CUB!O$6 -> 118.77492
A13: PISOS E PAVIMENTAÇÕES | B13: 3231121.7 | C13: =B13/B$19 -> 0.095964812 | D13: =B13/CUB!O$4 -> 534.14298 | E13: 7331642.3 | F13: =E13/E$19 -> 0.099181844 | G13: =E13/CUB!O$5 -> 340.84365 | H13: =E13+B13 -> 10562764 | I13: =H13/H$19 -> 0.098175097 | J13: =H13/CUB!O$6 -> 383.27194
A14: PINTURA INTERNA | B14: 890237.65 | C14: =B14/B$19 -> 0.026440195 | D14: =B14/CUB!O$4 -> 147.16691 | E14: 3699799.5 | F14: =E14/E$19 -> 0.050050579 | G14: =E14/CUB!O$5 -> 172.00146 | H14: =E14+B14 -> 4590037.2 | I14: =H14/H$19 -> 0.042661878 | J14: =H14/CUB!O$6 -> 166.55039
A15: ESQUADRIAS, VIDROS E FERRAGENS | B15: 10170063 | C15: =B15/B$19 -> 0.30205244 | D15: =B15/CUB!O$4 -> 1681.2328 | E15: 17129486 | F15: =E15/E$19 -> 0.23172626 | G15: =E15/CUB!O$5 -> 796.33953 | H15: =E15+B15 -> 27299549 | I15: =H15/H$19 -> 0.25373434 | J15: =H15/CUB!O$6 -> 990.56946
A16: COBERTURA | B16: 1393694.5 | C16: =B16/B$19 -> 0.04139294 | D16: =B16/CUB!O$4 -> 230.39433 | E16: 1138286.1 | F16: =E16/E$19 -> 0.015398639 | G16: =E16/CUB!O$5 -> 52.918235 | H16: =E16+B16 -> 2531980.5 | I16: =H16/H$19 -> 0.02353337 | J16: =H16/CUB!O$6 -> 91.873405
A17: REVESTIMENTOS E ACABAMENTOS DE FACHADA | B17: 1254677.7 | C17: =B17/B$19 -> 0.03726412 | D17: =B17/CUB!O$4 -> 207.41319 | E17: 3653145 | F17: =E17/E$19 -> 0.04941944 | G17: =E17/CUB!O$5 -> 169.83252 | H17: =E17+B17 -> 4907822.7 | I17: =H17/H$19 -> 0.04561552 | J17: =H17/CUB!O$6 -> 178.0813
A18: SERVIÇOS COMPLEMENTARES | B18: 0 | C18: =B18/B$19 -> 0 | D18: =B18/CUB!O$4 -> 0 | E18: 0 | F18: =E18/E$19 -> 0 | G18: =E18/CUB!O$5 -> 0 | H18: =E18+B18 -> 0 | I18: =H18/H$19 -> 0 | J18: =H18/CUB!O$6 -> 0
A19: TOTAL | B19: =SUM(B4:B18) -> 33669859 | C19: =SUM(C4:C18) -> 1 | D19: =SUM(D4:D18) -> 5566.0296 | E19: =SUM(E4:E18) -> 73921214 | F19: =SUM(F4:F18) -> 1 | G19: =SUM(G4:G18) -> 3436.5528 | H19: =SUM(H4:H18) -> 1.0759107e+08 | I19: =SUM(I4:I18) -> 1 | J19: =SUM(J4:J18) -> 3903.963
A20: CUB/RJ | B20: 2303.36 | C20: 45717 | D20: =+D19/B20 -> 2.4164827 | E20: 2303.36 | F20: 45717 | G20: =+G19/E20 -> 1.4919738 | H20: 2303.36 | I20: 45717 | J20: =+J19/H20 -> 1.6948992
D21: =1-D20/RESUMOS!$G$19 -> 0.19205524 | G21: =1-G20/RESUMOS!$G$39 -> 0.15544262 | J21: =1-J20/RESUMOS!$G$60 -> 0.24658527
A22: Equipamentos não contemplados pelo CUB em edifícios residenciais de médio a alto padrão:
A23: Sistemas de Transporte Vertical
A24: Elevadores (social e de serviço)
A25: Plataformas elevatórias (acessibilidade, se houver)
A26: Elevadores de emergência ou gerador-reserva para elevadores
A27: Sistemas Elétricos e de Automação
A28: Gerador de emergência (diesel ou gás)
A29: Quadros elétricos especiais (QGBT, QTA, QTM, etc.)
A30: Sistema de automação predial (BMS)
A31: Medidores individuais de água, gás e energia
A32: Infraestrutura para carregamento de carro elétrico
A33: Sistemas de Segurança Contra Incêndio
... A67: Estação compacta de tratamento de esgoto (ETE)

Sheet INDIRETOS
G1: ORÇAMENTO DE VIABILIDADE - INDIRETOS
J2: GERAL | M2: OBSERVAÇÕES | P2: Clientes possuem opção de fazer 3 suites ou 2 suites + 2 demi-suites - padrão 4 suites
A3: Unidade Construtiva | B3: Célula Construtiva | C3: Etapa | D3: Subetapa | E3: Serviço | G3: Hotel Colline de France - Rio de Janeiro | J3: Quantidade | K3: Unidade | L3: Custo
A4: =IF($G4="UNIDADE CONSTRUTIVA",1,LARGE(A$3:A3,1)) -> 1 | B4: =IF(G4="UNIDADE CONSTRUTIVA",0,IF(G4="CÉLULA CONSTRUTIVA",OFFSET(B4,-1,0)+1,OFFSET(B4,-1,0))) -> 0 | C4: =IF(G4="CÉLULA CONSTRUTIVA",0,IF(G4="ETAPA",OFFSET(C4,-1,0)+1,OFFSET(C4,-1,0))) -> Etapa | D4: =IF(G4="ETAPA",0,IF(G4="SUBETAPA",OFFSET(D4,-1,0)+1,OFFSET(D4,-1,0))) -> Subetapa | E4: =IF(G4="Subetapa",0,IF(G4="serviço",OFFSET(E4,-1,0)+1,OFFSET(E4,-1,0))) -> Serviço | G4: UNIDADE CONSTRUTIVA | H4: =IF(G4="Unidade Construtiva",TEXT(A4,"00"),IF(G4="Célula Construtiva",TEXT(B4,"00"),IF(G4="Etapa",CONCATENATE(TEXT(B4,"00"),".",TEXT(C4,"000")),IF(G4="Subetapa",CONCATENATE(TEXT(B4,"00"),".",TEXT(C4,"000"),".",TEXT(D4,"000")),IF(G4="Serviço",CONCATENATE(TEXT(B4,"00"),".",TEXT(C4,"000"),".",TEXT(D4,"000"),".",TEXT(E4,"000")),""))))) -> 01 | I4: GERENCIAMENTO TÉCNICO E ADMINISTRATIVO | L4: =L5+L14+L68 -> 13604538
A5: =IF($G5="UNIDADE CONSTRUTIVA",OFFSET(A5,0,0)+1,LARGE(A$3:A4,1)) -> 1 | B5: =IF(G5="UNIDADE CONSTRUTIVA",0,IF(G5="CÉLULA CONSTRUTIVA",OFFSET(B5,-1,0)+1,OFFSET(B5,-1,0))) -> 1 | C5: =IF(G5="CÉLULA CONSTRUTIVA",0,IF(G5="ETAPA",OFFSET(C5,-1,0)+1,OFFSET(C5,-1,0))) -> 0 | D5: =IF(G5="ETAPA",0,IF(G5="SUBETAPA",OFFSET(D5,-1,0)+1,OFFSET(D5,-1,0))) -> Subetapa | E5: =IF(G5="Subetapa",0,IF(G5="serviço",OFFSET(E5,-1,0)+1,OFFSET(E5,-1,0))) -> Serviço | G5: CÉLULA CONSTRUTIVA | H5: =IF(G5="Unidade Construtiva",TEXT(A5,"00"),IF(G5="Célula Construtiva",TEXT(B5,"00"),IF(G5="Etapa",CONCATENATE(TEXT(B5,"00"),".",TEXT(C5,"000")),IF(G5="Subetapa",CONCATENATE(TEXT(B5,"00"),".",TEXT(C5,"000"),".",TEXT(D5,"000")),IF(G5="Serviço",CONCATENATE(TEXT(B5,"00"),".",TEXT(C5,"000"),".",TEXT(D5,"000"),".",TEXT(E5,"000")),""))))) -> 01 | I5: SERVIÇOS TÉCNICOS | L5: =L6+L11 -> 4293333.3
A6: =IF($G6="UNIDADE CONSTRUTIVA",OFFSET(A6,0,0)+1,LARGE(A$3:A5,1)) -> 1 | B6: =IF(G6="UNIDADE CONSTRUTIVA",0,IF(G6="CÉLULA CONSTRUTIVA",OFFSET(B6,-1,0)+1,OFFSET(B6,-1,0))) -> 1 | C6: =IF(G6="CÉLULA CONSTRUTIVA",0,IF(G6="ETAPA",OFFSET(C6,-1,0)+1,OFFSET(C6,-1,0))) -> 1 | D6: =IF(G6="ETAPA",0,IF(G6="SUBETAPA",OFFSET(D6,-1,0)+1,OFFSET(D6,-1,0))) -> 0 | E6: =IF(G6="Subetapa",0,IF(G6="serviço",OFFSET(E6,-1,0)+1,OFFSET(E6,-1,0))) -> Serviço | G6: ETAPA | H6: =IF(G6="Unidade Construtiva",TEXT(A6,"00"),IF(G6="Célula Construtiva",TEXT(B6,"00"),IF(G6="Etapa",CONCATENATE(TEXT(B6,"00"),".",TEXT(C6,"000")),IF(G6="Subetapa",CONCATENATE(TEXT(B6,"00"),".",TEXT(C6,"000"),".",TEXT(D6,"000")),IF(G6="Serviço",CONCATENATE(TEXT(B6,"00"),".",TEXT(C6,"000"),".",TEXT(D6,"000"),".",TEXT(E6,"000")),""))))) -> 01.001 | I6: ESTUDOS, PROJETOS E CONSULTORIAS | L6: =SUM(L7:L10) -> 1480076.3
A7: =IF($G7="UNIDADE CONSTRUTIVA",OFFSET(A7,0,0)+1,LARGE(A$3:A6,1)) -> 1 | B7: =IF(G7="UNIDADE CONSTRUTIVA",0,IF(G7="CÉLULA CONSTRUTIVA",OFFSET(B7,-1,0)+1,OFFSET(B7,-1,0))) -> 1 | C7: =IF(G7="CÉLULA CONSTRUTIVA",0,IF(G7="ETAPA",OFFSET(C7,-1,0)+1,OFFSET(C7,-1,0))) -> 1 | D7: =IF(G7="ETAPA",0,IF(G7="SUBETAPA",OFFSET(D7,-1,0)+1,OFFSET(D7,-1,0))) -> 1 | E7: =IF(G7="Subetapa",0,IF(G7="serviço",OFFSET(E7,-1,0)+1,OFFSET(E7,-1,0))) -> 0 | G7: Subetapa | H7: =IF(G7="Unidade Construtiva",TEXT(A7,"00"),IF(G7="Célula Construtiva",TEXT(B7,"00"),IF(G7="Etapa",CONCATENATE(TEXT(B7,"00"),".",TEXT(C7,"000")),IF(G7="Subetapa",CONCATENATE(TEXT(B7,"00"),".",TEXT(C7,"000"),".",TEXT(D7,"000")),IF(G7="Serviço",CONCATENATE(TEXT(B7,"00"),".",TEXT(C7,"000"),".",TEXT(D7,"000"),".",TEXT(E7,"000")),""))))) -> 01.001.001 | I7: Estudos | J7: 1 | K7: vb | L7: 54376.895 | M7: Custo do hotel
A8: =IF($G8="UNIDADE CONSTRUTIVA",OFFSET(A8,0,0)+1,LARGE(A$3:A7,1)) -> 1 | B8: =IF(G8="UNIDADE CONSTRUTIVA",0,IF(G8="CÉLULA CONSTRUTIVA",OFFSET(B8,-1,0)+1,OFFSET(B8,-1,0))) -> 1 | C8: =IF(G8="CÉLULA CONSTRUTIVA",0,IF(G8="ETAPA",OFFSET(C8,-1,0)+1,OFFSET(C8,-1,0))) -> 1 | D8: =IF(G8="ETAPA",0,IF(G8="SUBETAPA",OFFSET(D8,-1,0)+1,OFFSET(D8,-1,0))) -> 2 | E8: =IF(G8="Subetapa",0,IF(G8="serviço",OFFSET(E8,-1,0)+1,OFFSET(E8,-1,0))) -> 0 | G8: Subetapa | H8: =IF(G8="Unidade Construtiva",TEXT(A8,"00"),IF(G8="Célula Construtiva",TEXT(B8,"00"),IF(G8="Etapa",CONCATENATE(TEXT(B8,"00"),".",TEXT(C8,"000")),IF(G8="Subetapa",CONCATENATE(TEXT(B8,"00"),".",TEXT(C8,"000"),".",TEXT(D8,"000")),IF(G8="Serviço",CONCATENATE(TEXT(B8,"00"),".",TEXT(C8,"000"),".",TEXT(D8,"000"),".",TEXT(E8,"000")),""))))) -> 01.001.002 | I8: Projetos | J8: 1 | K8: vb | L8: 1256710.9 | M8: Custo do hotel
A9: =IF($G9="UNIDADE CONSTRUTIVA",OFFSET(A9,0,0)+1,LARGE(A$3:A8,1)) -> 1 | B9: =IF(G9="UNIDADE CONSTRUTIVA",0,IF(G9="CÉLULA CONSTRUTIVA",OFFSET(B9,-1,0)+1,OFFSET(B9,-1,0))) -> 1 | C9: =IF(G9="CÉLULA CONSTRUTIVA",0,IF(G9="ETAPA",OFFSET(C9,-1,0)+1,OFFSET(C9,-1,0))) -> 1 | D9: =IF(G9="ETAPA",0,IF(G9="SUBETAPA",OFFSET(D9,-1,0)+1,OFFSET(D9,-1,0))) -> 3 | E9: =IF(G9="Subetapa",0,IF(G9="serviço",OFFSET(E9,-1,0)+1,OFFSET(E9,-1,0))) -> 0 | G9: Subetapa | H9: =IF(G9="Unidade Construtiva",TEXT(A9,"00"),IF(G9="Célula Construtiva",TEXT(B9,"00"),IF(G9="Etapa",CONCATENATE(TEXT(B9,"00"),".",TEXT(C9,"000")),IF(G9="Subetapa",CONCATENATE(TEXT(B9,"00"),".",TEXT(C9,"000"),".",TEXT(D9,"000")),IF(G9="Serviço",CONCATENATE(TEXT(B9,"00"),".",TEXT(C9,"000"),".",TEXT(D9,"000"),".",TEXT(E9,"000")),""))))) -> 01.001.003 | I9: Consultorias | J9: 1 | K9: vb | L9: 119868.78 | M9: Custo do hotel
A10: =IF($G10="UNIDADE CONSTRUTIVA",OFFSET(A10,0,0)+1,LARGE(A$3:A9,1)) -> 1 | B10: =IF(G10="UNIDADE CONSTRUTIVA",0,IF(G10="CÉLULA CONSTRUTIVA",OFFSET(B10,-1,0)+1,OFFSET(B10,-1,0))) -> 1 | C10: =IF(G10="CÉLULA CONSTRUTIVA",0,IF(G10="ETAPA",OFFSET(C10,-1,0)+1,OFFSET(C10,-1,0))) -> 1 | D10: =IF(G10="ETAPA",0,IF(G10="SUBETAPA",OFFSET(D10,-1,0)+1,OFFSET(D10,-1,0))) -> 4 | E10: =IF(G10="Subetapa",0,IF(G10="serviço",OFFSET(E10,-1,0)+1,OFFSET(E10,-1,0))) -> 0 | G10: Subetapa | H10: =IF(G10="Unidade Construtiva",TEXT(A10,"00"),IF(G10="Célula Construtiva",TEXT(B10,"00"),IF(G10="Etapa",CONCATENATE(TEXT(B10,"00"),".",TEXT(C10,"000")),IF(G10="Subetapa",CONCATENATE(TEXT(B10,"00"),".",TEXT(C10,"000"),".",TEXT(D10,"000")),IF(G10="Serviço",CONCATENATE(TEXT(B10,"00"),".",TEXT(C10,"000"),".",TEXT(D10,"000"),".",TEXT(E10,"000")),""))))) -> 01.001.004 | I10: Ensaios | J10: 1 | K10: vb | L10: 49119.741
A11: =IF($G11="UNIDADE CONSTRUTIVA",OFFSET(A11,0,0)+1,LARGE(A$3:A10,1)) -> 1 | B11: =IF(G11="UNIDADE CONSTRUTIVA",0,IF(G11="CÉLULA CONSTRUTIVA",OFFSET(B11,-1,0)+1,OFFSET(B11,-1,0))) -> 1 | C11: =IF(G11="CÉLULA CONSTRUTIVA",0,IF(G11="ETAPA",OFFSET(C11,-1,0)+1,OFFSET(C11,-1,0))) -> 2 | D11: =IF(G11="ETAPA",0,IF(G11="SUBETAPA",OFFSET(D11,-1,0)+1,OFFSET(D11,-1,0))) -> 0 | E11: =IF(G11="Subetapa",0,IF(G11="serviço",OFFSET(E11,-1,0)+1,OFFSET(E11,-1,0))) -> 0 | G11: ETAPA | H11: =IF(G11="Unidade Construtiva",TEXT(A11,"00"),IF(G11="Célula Construtiva",TEXT(B11,"00"),IF(G11="Etapa",CONCATENATE(TEXT(B11,"00"),".",TEXT(C11,"000")),IF(G11="Subetapa",CONCATENATE(TEXT(B11,"00"),".",TEXT(C11,"000"),".",TEXT(D11,"000")),IF(G11="Serviço",CONCATENATE(TEXT(B11,"00"),".",TEXT(C11,"000"),".",TEXT(D11,"000"),".",TEXT(E11,"000")),""))))) -> 01.002 | I11: TAXAS E DOCUMENTOS | L11: =L12+L13 -> 2813257
A12: =IF($G12="UNIDADE CONSTRUTIVA",OFFSET(A12,0,0)+1,LARGE(A$3:A11,1)) -> 1 | B12: =IF(G12="UNIDADE CONSTRUTIVA",0,IF(G12="CÉLULA CONSTRUTIVA",OFFSET(B12,-1,0)+1,OFFSET(B12,-1,0))) -> 1 | C12: =IF(G12="CÉLULA CONSTRUTIVA",0,IF(G12="ETAPA",OFFSET(C12,-1,0)+1,OFFSET(C12,-1,0))) -> 2 | D12: =IF(G12="ETAPA",0,IF(G12="SUBETAPA",OFFSET(D12,-1,0)+1,OFFSET(D12,-1,0))) -> 1 | E12: =IF(G12="Subetapa",0,IF(G12="serviço",OFFSET(E12,-1,0)+1,OFFSET(E12,-1,0))) -> 0 | G12: Subetapa | H12: =IF(G12="Unidade Construtiva",TEXT(A12,"00"),IF(G12="Célula Construtiva",TEXT(B12,"00"),IF(G12="Etapa",CONCATENATE(TEXT(B12,"00"),".",TEXT(C12,"000")),IF(G12="Subetapa",CONCATENATE(TEXT(B12,"00"),".",TEXT(C12,"000"),".",TEXT(D12,"000")),IF(G12="Serviço",CONCATENATE(TEXT(B12,"00"),".",TEXT(C12,"000"),".",TEXT(D12,"000"),".",TEXT(E12,"000")),""))))) -> 01.002.001 | I12: Licenciamentos, Taxas, Impostos, Aprovações e Seguros | J12: 1 | K12: vb | L12: 2685165.1 | M12: Contemplando taxas de aprovações, alvaras e seguros, incluindo outorga onerosa
A13: =IF($G13="UNIDADE CONSTRUTIVA",OFFSET(A13,0,0)+1,LARGE(A$3:A12,1)) -> 1 | B13: =IF(G13="UNIDADE CONSTRUTIVA",0,IF(G13="CÉLULA CONSTRUTIVA",OFFSET(B13,-1,0)+1,OFFSET(B13,-1,0))) -> 1 | C13: =IF(G13="CÉLULA CONSTRUTIVA",0,IF(G13="ETAPA",OFFSET(C13,-1,0)+1,OFFSET(C13,-1,0))) -> 2 | D13: =IF(G13="ETAPA",0,IF(G13="SUBETAPA",OFFSET(D13,-1,0)+1,OFFSET(D13,-1,0))) -> 2 | E13: =IF(G13="Subetapa",0,IF(G13="serviço",OFFSET(E13,-1,0)+1,OFFSET(E13,-1,0))) -> 0 | G13: Subetapa | H13: =IF(G13="Unidade Construtiva",TEXT(A13,"00"),IF(G13="Célula Construtiva",TEXT(B13,"00"),IF(G13="Etapa",CONCATENATE(TEXT(B13,"00"),".",TEXT(C13,"000")),IF(G13="Subetapa",CONCATENATE(TEXT(B13,"00"),".",TEXT(C13,"000"),".",TEXT(D13,"000")),IF(G13="Serviço",CONCATENATE(TEXT(B13,"00"),".",TEXT(C13,"000"),".",TEXT(D13,"000"),".",TEXT(E13,"000")),""))))) -> 01.002.002 | I13: Documentos | J13: 1 | K13: vb | L13: 128091.91 | M13: Memorias e etc.
A14: =IF($G14="UNIDADE CONSTRUTIVA",OFFSET(A14,0,0)+1,LARGE(A$3:A13,1)) -> 1 | B14: =IF(G14="UNIDADE CONSTRUTIVA",0,IF(G14="CÉLULA CONSTRUTIVA",OFFSET(B14,-1,0)+1,OFFSET(B14,-1,0))) -> 2 | C14: =IF(G14="CÉLULA CONSTRUTIVA",0,IF(G14="ETAPA",OFFSET(C14,-1,0)+1,OFFSET(C14,-1,0))) -> 0 | D14: =IF(G14="ETAPA",0,IF(G14="SUBETAPA",OFFSET(D14,-1,0)+1,OFFSET(D14,-1,0))) -> 2 | E14: =IF(G14="Subetapa",0,IF(G14="serviço",OFFSET(E14,-1,0)+1,OFFSET(E14,-1,0))) -> 0 | G14: CÉLULA CONSTRUTIVA | H14: =IF(G14="Unidade Construtiva",TEXT(A14,"00"),IF(G14="Célula Construtiva",TEXT(B14,"00"),IF(G14="Etapa",CONCATENATE(TEXT(B14,"00"),".",TEXT(C14,"000")),IF(G14="Subetapa",CONCATENATE(TEXT(B14,"00"),".",TEXT(C14,"000"),".",TEXT(D14,"000")),IF(G14="Serviço",CONCATENATE(TEXT(B14,"00"),".",TEXT(C14,"000"),".",TEXT(D14,"000"),".",TEXT(E14,"000")),""))))) -> 02 | I14: SERVIÇOS INICIAIS | L14: =L15+L37+L65 -> 6315344
A15: =IF($G15="UNIDADE CONSTRUTIVA",OFFSET(A15,0,0)+1,LARGE(A$3:A14,1)) -> 1 | B15: =IF(G15="UNIDADE CONSTRUTIVA",0,IF(G15="CÉLULA CONSTRUTIVA",OFFSET(B15,-1,0)+1,OFFSET(B15,-1,0))) -> 2 | C15: =IF(G15="CÉLULA CONSTRUTIVA",0,IF(G15="ETAPA",OFFSET(C15,-1,0)+1,OFFSET(C15,-1,0))) -> 1 | D15: =IF(G15="ETAPA",0,IF(G15="SUBETAPA",OFFSET(D15,-1,0)+1,OFFSET(D15,-1,0))) -> 0 | E15: =IF(G15="Subetapa",0,IF(G15="serviço",OFFSET(E15,-1,0)+1,OFFSET(E15,-1,0))) -> 0 | G15: ETAPA | H15: =IF(G15="Unidade Construtiva",TEXT(A15,"00"),IF(G15="Célula Construtiva",TEXT(B15,"00"),IF(G15="Etapa",CONCATENATE(TEXT(B15,"00"),".",TEXT(C15,"000")),IF(G15="Subetapa",CONCATENATE(TEXT(B15,"00"),".",TEXT(C15,"000"),".",TEXT(D15,"000")),IF(G15="Serviço",CONCATENATE(TEXT(B15,"00"),".",TEXT(C15,"000"),".",TEXT(D15,"000"),".",TEXT(E15,"000")),""))))) -> 02.001 | I15: SEGURANÇA, MEIO AMBIENTE, SAÚDE | L15: =SUM(L16:L36)/2 -> 1572839.3
A16: =IF($G16="UNIDADE CONSTRUTIVA",OFFSET(A16,0,0)+1,LARGE(A$3:A15,1)) -> 1 | B16: =IF(G16="UNIDADE CONSTRUTIVA",0,IF(G16="CÉLULA CONSTRUTIVA",OFFSET(B16,-1,0)+1,OFFSET(B16,-1,0))) -> 2 | C16: =IF(G16="CÉLULA CONSTRUTIVA",0,IF(G16="ETAPA",OFFSET(C16,-1,0)+1,OFFSET(C16,-1,0))) -> 1 | D16: =IF(G16="ETAPA",0,IF(G16="SUBETAPA",OFFSET(D16,-1,0)+1,OFFSET(D16,-1,0))) -> 1 | E16: =IF(G16="Subetapa",0,IF(G16="serviço",OFFSET(E16,-1,0)+1,OFFSET(E16,-1,0))) -> 0 | G16: Subetapa | H16: =IF(G16="Unidade Construtiva",TEXT(A16,"00"),IF(G16="Célula Construtiva",TEXT(B16,"00"),IF(G16="Etapa",CONCATENATE(TEXT(B16,"00"),".",TEXT(C16,"000")),IF(G16="Subetapa",CONCATENATE(TEXT(B16,"00"),".",TEXT(C16,"000"),".",TEXT(D16,"000")),IF(G16="Serviço",CONCATENATE(TEXT(B16,"00"),".",TEXT(C16,"000"),".",TEXT(D16,"000"),".",TEXT(E16,"000")),""))))) -> 02.001.001 | I16: Segurança do trabalho | L16: =L17 -> 252000
A17: =IF($G17="UNIDADE CONSTRUTIVA",OFFSET(A17,0,0)+1,LARGE(A$3:A16,1)) -> 1 | B17: =IF(G17="UNIDADE CONSTRUTIVA",0,IF(G17="CÉLULA CONSTRUTIVA",OFFSET(B17,-1,0)+1,OFFSET(B17,-1,0))) -> 2 | C17: =IF(G17="CÉLULA CONSTRUTIVA",0,IF(G17="ETAPA",OFFSET(C17,-1,0)+1,OFFSET(C17,-1,0))) -> 1 | D17: =IF(G17="ETAPA",0,IF(G17="SUBETAPA",OFFSET(D17,-1,0)+1,OFFSET(D17,-1,0))) -> 1 | E17: =IF(G17="Subetapa",0,IF(G17="serviço",OFFSET(E17,-1,0)+1,OFFSET(E17,-1,0))) -> 1 | G17: Serviço | H17: =IF(G17="Unidade Construtiva",TEXT(A17,"00"),IF(G17="Célula Construtiva",TEXT(B17,"00"),IF(G17="Etapa",CONCATENATE(TEXT(B17,"00"),".",TEXT(C17,"000")),IF(G17="Subetapa",CONCATENATE(TEXT(B17,"00"),".",TEXT(C17,"000"),".",TEXT(D17,"000")),IF(G17="Serviço",CONCATENATE(TEXT(B17,"00"),".",TEXT(C17,"000"),".",TEXT(D17,"000"),".",TEXT(E17,"000")),""))))) -> 02.001.001.001 | I17: Serviço de segurança do trabalho terceirizado | J17: 36 | K17: mes | L17: 252000 | M17: (consideração de dois técnicos com 3.500/mês de cada)
A18: =IF($G18="UNIDADE CONSTRUTIVA",OFFSET(A18,0,0)+1,LARGE(A$3:A16,1)) -> 1 | B18: =IF(G18="UNIDADE CONSTRUTIVA",0,IF(G18="CÉLULA CONSTRUTIVA",OFFSET(B18,-1,0)+1,OFFSET(B18,-1,0))) -> 2 | C18: =IF(G18="CÉLULA CONSTRUTIVA",0,IF(G18="ETAPA",OFFSET(C18,-1,0)+1,OFFSET(C18,-1,0))) -> 1 | D18: =IF(G18="ETAPA",0,IF(G18="SUBETAPA",OFFSET(D18,-1,0)+1,OFFSET(D18,-1,0))) -> 2 | E18: =IF(G18="Subetapa",0,IF(G18="serviço",OFFSET(E18,-1,0)+1,OFFSET(E18,-1,0))) -> 0 | G18: Subetapa | H18: =IF(G18="Unidade Construtiva",TEXT(A18,"00"),IF(G18="Célula Construtiva",TEXT(B18,"00"),IF(G18="Etapa",CONCATENATE(TEXT(B18,"00"),".",TEXT(C18,"000")),IF(G18="Subetapa",CONCATENATE(TEXT(B18,"00"),".",TEXT(C18,"000"),".",TEXT(D18,"000")),IF(G18="Serviço",CONCATENATE(TEXT(B18,"00"),".",TEXT(C18,"000"),".",TEXT(D18,"000"),".",TEXT(E18,"000")),""))))) -> 02.001.002 | I18: Equipamentos de proteção - GERAL | L18: =SUM(L19:L20) -> 118315.4
A19: =IF($G19="UNIDADE CONSTRUTIVA",OFFSET(A19,0,0)+1,LARGE(A$3:A17,1)) -> 1 | B19: =IF(G19="UNIDADE CONSTRUTIVA",0,IF(G19="CÉLULA CONSTRUTIVA",OFFSET(B19,-1,0)+1,OFFSET(B19,-1,0))) -> 2 | C19: =IF(G19="CÉLULA CONSTRUTIVA",0,IF(G19="ETAPA",OFFSET(C19,-1,0)+1,OFFSET(C19,-1,0))) -> 1 | D19: =IF(G19="ETAPA",0,IF(G19="SUBETAPA",OFFSET(D19,-1,0)+1,OFFSET(D19,-1,0))) -> 2 | E19: =IF(G19="Subetapa",0,IF(G19="serviço",OFFSET(E19,-1,0)+1,OFFSET(E19,-1,0))) -> 1 | G19: Serviço | H19: =IF(G19="Unidade Construtiva",TEXT(A19,"00"),IF(G19="Célula Construtiva",TEXT(B19,"00"),IF(G19="Etapa",CONCATENATE(TEXT(B19,"00"),".",TEXT(C19,"000")),IF(G19="Subetapa",CONCATENATE(TEXT(B19,"00"),".",TEXT(C19,"000"),".",TEXT(D19,"000")),IF(G19="Serviço",CONCATENATE(TEXT(B19,"00"),".",TEXT(C19,"000"),".",TEXT(D19,"000"),".",TEXT(E19,"000")),""))))) -> 02.001.002.001 | I19: Sinalização com placa indicativa fixada na estrutura | J19: 1 | K19: vb | L19: 30315.395
A20: =IF($G20="UNIDADE CONSTRUTIVA",OFFSET(A20,0,0)+1,LARGE(A$3:A18,1)) -> 1 | B20: =IF(G20="UNIDADE CONSTRUTIVA",0,IF(G20="CÉLULA CONSTRUTIVA",OFFSET(B20,-1,0)+1,OFFSET(B20,-1,0))) -> 2 | C20: =IF(G20="CÉLULA CONSTRUTIVA",0,IF(G20="ETAPA",OFFSET(C20,-1,0)+1,OFFSET(C20,-1,0))) -> 1 | D20: =IF(G20="ETAPA",0,IF(G20="SUBETAPA",OFFSET(D20,-1,0)+1,OFFSET(D20,-1,0))) -> 2 | E20: =IF(G20="Subetapa",0,IF(G20="serviço",OFFSET(E20,-1,0)+1,OFFSET(E20,-1,0))) -> 2 | G20: Serviço | H20: =IF(G20="Unidade Construtiva",TEXT(A20,"00"),IF(G20="Célula Construtiva",TEXT(B20,"00"),IF(G20="Etapa",CONCATENATE(TEXT(B20,"00"),".",TEXT(C20,"000")),IF(G20="Subetapa",CONCATENATE(TEXT(B20,"00"),".",TEXT(C20,"000"),".",TEXT(D20,"000")),IF(G20="Serviço",CONCATENATE(TEXT(B20,"00"),".",TEXT(C20,"000"),".",TEXT(D20,"000"),".",TEXT(E20,"000")),""))))) -> 02.001.002.002 | I20: Equipamentos de proteção individual | J20: 1 | K20: vb | L20: 88000
A21: =IF($G21="UNIDADE CONSTRUTIVA",OFFSET(A21,0,0)+1,LARGE(A$3:A19,1)) -> 1 | B21: =IF(G21="UNIDADE CONSTRUTIVA",0,IF(G21="CÉLULA CONSTRUTIVA",OFFSET(B21,-1,0)+1,OFFSET(B21,-1,0))) -> 2 | C21: =IF(G21="CÉLULA CONSTRUTIVA",0,IF(G21="ETAPA",OFFSET(C21,-1,0)+1,OFFSET(C21,-1,0))) -> 1 | D21: =IF(G21="ETAPA",0,IF(G21="SUBETAPA",OFFSET(D21,-1,0)+1,OFFSET(D21,-1,0))) -> 3 | E21: =IF(G21="Subetapa",0,IF(G21="serviço",OFFSET(E21,-1,0)+1,OFFSET(E21,-1,0))) -> 0 | G21: Subetapa | H21: =IF(G21="Unidade Construtiva",TEXT(A21,"00"),IF(G21="Célula Construtiva",TEXT(B21,"00"),IF(G21="Etapa",CONCATENATE(TEXT(B21,"00"),".",TEXT(C21,"000")),IF(G21="Subetapa",CONCATENATE(TEXT(B21,"00"),".",TEXT(C21,"000"),".",TEXT(D21,"000")),IF(G21="Serviço",CONCATENATE(TEXT(B21,"00"),".",TEXT(C21,"000"),".",TEXT(D21,"000"),".",TEXT(E21,"000")),""))))) -> 02.001.003 | I21: Equipamentos de proteção - HOTEL | L21: =SUM(L22:L27) -> 420021.29
A22: =IF($G22="UNIDADE CONSTRUTIVA",OFFSET(A22,0,0)+1,LARGE(A$3:A20,1)) -> 1 | B22: =IF(G22="UNIDADE CONSTRUTIVA",0,IF(G22="CÉLULA CONSTRUTIVA",OFFSET(B22,-1,0)+1,OFFSET(B22,-1,0))) -> 2 | C22: =IF(G22="CÉLULA CONSTRUTIVA",0,IF(G22="ETAPA",OFFSET(C22,-1,0)+1,OFFSET(C22,-1,0))) -> 1 | D22: =IF(G22="ETAPA",0,IF(G22="SUBETAPA",OFFSET(D22,-1,0)+1,OFFSET(D22,-1,0))) -> 3 | E22: =IF(G22="Subetapa",0,IF(G22="serviço",OFFSET(E22,-1,0)+1,OFFSET(E22,-1,0))) -> 1 | G22: Serviço | H22: =IF(G22="Unidade Construtiva",TEXT(A22,"00"),IF(G22="Célula Construtiva",TEXT(B22,"00"),IF(G22="Etapa",CONCATENATE(TEXT(B22,"00"),".",TEXT(C22,"000")),IF(G22="Subetapa",CONCATENATE(TEXT(B22,"00"),".",TEXT(C22,"000"),".",TEXT(D22,"000")),IF(G22="Serviço",CONCATENATE(TEXT(B22,"00"),".",TEXT(C22,"000"),".",TEXT(D22,"000"),".",TEXT(E22,"000")),""))))) -> 02.001.003.001 | I22: Bandeja de proteção primária | J22: 226.19 | K22: m | L22: 66574.503
A23: =IF($G23="UNIDADE CONSTRUTIVA",OFFSET(A23,0,0)+1,LARGE(A$3:A21,1)) -> 1 | B23: =IF(G23="UNIDADE CONSTRUTIVA",0,IF(G23="CÉLULA CONSTRUTIVA",OFFSET(B23,-1,0)+1,OFFSET(B23,-1,0))) -> 2 | C23: =IF(G23="CÉLULA CONSTRUTIVA",0,IF(G23="ETAPA",OFFSET(C23,-1,0)+1,OFFSET(C23,-1,0))) -> 1 | D23: =IF(G23="ETAPA",0,IF(G23="SUBETAPA",OFFSET(D23,-1,0)+1,OFFSET(D23,-1,0))) -> 3 | E23: =IF(G23="Subetapa",0,IF(G23="serviço",OFFSET(E23,-1,0)+1,OFFSET(E23,-1,0))) -> 2 | G23: Serviço | H23: =IF(G23="Unidade Construtiva",TEXT(A23,"00"),IF(G23="Célula Construtiva",TEXT(B23,"00"),IF(G23="Etapa",CONCATENATE(TEXT(B23,"00"),".",TEXT(C23,"000")),IF(G23="Subetapa",CONCATENATE(TEXT(B23,"00"),".",TEXT(C23,"000"),".",TEXT(D23,"000")),IF(G23="Serviço",CONCATENATE(TEXT(B23,"00"),".",TEXT(C23,"000"),".",TEXT(D23,"000"),".",TEXT(E23,"000")),""))))) -> 02.001.003.002 | I23: Bandeja de proteção secundária | J23: 226.19 | K23: m | L23: 47513.471
A24: =IF($G24="UNIDADE CONSTRUTIVA",OFFSET(A24,0,0)+1,LARGE(A$3:A19,1)) -> 1 | B24: =IF(G24="UNIDADE CONSTRUTIVA",0,IF(G24="CÉLULA CONSTRUTIVA",OFFSET(B24,-1,0)+1,OFFSET(B24,-1,0))) -> 2 | C24: =IF(G24="CÉLULA CONSTRUTIVA",0,IF(G24="ETAPA",OFFSET(C24,-1,0)+1,OFFSET(C24,-1,0))) -> 1 | D24: =IF(G24="ETAPA",0,IF(G24="SUBETAPA",OFFSET(D24,-1,0)+1,OFFSET(D24,-1,0))) -> 3 | E24: =IF(G24="Subetapa",0,IF(G24="serviço",OFFSET(E24,-1,0)+1,OFFSET(E24,-1,0))) -> 3 | G24: Serviço | H24: =IF(G24="Unidade Construtiva",TEXT(A24,"00"),IF(G24="Célula Construtiva",TEXT(B24,"00"),IF(G24="Etapa",CONCATENATE(TEXT(B24,"00"),".",TEXT(C24,"000")),IF(G24="Subetapa",CONCATENATE(TEXT(B24,"00"),".",TEXT(C24,"000"),".",TEXT(D24,"000")),IF(G24="Serviço",CONCATENATE(TEXT(B24,"00"),".",TEXT(C24,"000"),".",TEXT(D24,"000"),".",TEXT(E24,"000")),""))))) -> 02.001.003.003 | I24: Guarda corpo em laje pós - desforma | J24: 904.76 | K24: m | L24: 44333.24
A25: =IF($G25="UNIDADE CONSTRUTIVA",OFFSET(A25,0,0)+1,LARGE(A$3:A18,1)) -> 1 | B25: =IF(G25="UNIDADE CONSTRUTIVA",0,IF(G25="CÉLULA CONSTRUTIVA",OFFSET(B25,-1,0)+1,OFFSET(B25,-1,0))) -> 2 | C25: =IF(G25="CÉLULA CONSTRUTIVA",0,IF(G25="ETAPA",OFFSET(C25,-1,0)+1,OFFSET(C25,-1,0))) -> 1 | D25: =IF(G25="ETAPA",0,IF(G25="SUBETAPA",OFFSET(D25,-1,0)+1,OFFSET(D25,-1,0))) -> 3 | E25: =IF(G25="Subetapa",0,IF(G25="serviço",OFFSET(E25,-1,0)+1,OFFSET(E25,-1,0))) -> 4 | G25: Serviço | H25: =IF(G25="Unidade Construtiva",TEXT(A25,"00"),IF(G25="Célula Construtiva",TEXT(B25,"00"),IF(G25="Etapa",CONCATENATE(TEXT(B25,"00"),".",TEXT(C25,"000")),IF(G25="Subetapa",CONCATENATE(TEXT(B25,"00"),".",TEXT(C25,"000"),".",TEXT(D25,"000")),IF(G25="Serviço",CONCATENATE(TEXT(B25,"00"),".",TEXT(C25,"000"),".",TEXT(D25,"000"),".",TEXT(E25,"000")),""))))) -> 02.001.003.004 | I25: Fechamento removível de vãos de porta de elevador em madeira | J25: 33 | K25: m2 | L25: 656.37
A26: =IF($G26="UNIDADE CONSTRUTIVA",OFFSET(A26,0,0)+1,LARGE(A$3:A19,1)) -> 1 | B26: =IF(G26="UNIDADE CONSTRUTIVA",0,IF(G26="CÉLULA CONSTRUTIVA",OFFSET(B26,-1,0)+1,OFFSET(B26,-1,0))) -> 2 | C26: =IF(G26="CÉLULA CONSTRUTIVA",0,IF(G26="ETAPA",OFFSET(C26,-1,0)+1,OFFSET(C26,-1,0))) -> 1 | D26: =IF(G26="ETAPA",0,IF(G26="SUBETAPA",OFFSET(D26,-1,0)+1,OFFSET(D26,-1,0))) -> 3 | E26: =IF(G26="Subetapa",0,IF(G26="serviço",OFFSET(E26,-1,0)+1,OFFSET(E26,-1,0))) -> 5 | G26: Serviço | H26: =IF(G26="Unidade Construtiva",TEXT(A26,"00"),IF(G26="Célula Construtiva",TEXT(B26,"00"),IF(G26="Etapa",CONCATENATE(TEXT(B26,"00"),".",TEXT(C26,"000")),IF(G26="Subetapa",CONCATENATE(TEXT(B26,"00"),".",TEXT(C26,"000"),".",TEXT(D26,"000")),IF(G26="Serviço",CONCATENATE(TEXT(B26,"00"),".",TEXT(C26,"000"),".",TEXT(D26,"000"),".",TEXT(E26,"000")),""))))) -> 02.001.003.005 | I26: Varal de segurança com cabo de aço | J26: 904.76 | K26: m | L26: 220761.44
A27: =IF($G27="UNIDADE CONSTRUTIVA",OFFSET(A27,0,0)+1,LARGE(A$3:A20,1)) -> 1 | B27: =IF(G27="UNIDADE CONSTRUTIVA",0,IF(G27="CÉLULA CONSTRUTIVA",OFFSET(B27,-1,0)+1,OFFSET(B27,-1,0))) -> 2 | C27: =IF(G27="CÉLULA CONSTRUTIVA",0,IF(G27="ETAPA",OFFSET(C27,-1,0)+1,OFFSET(C27,-1,0))) -> 1 | D27: =IF(G27="ETAPA",0,IF(G27="SUBETAPA",OFFSET(D27,-1,0)+1,OFFSET(D27,-1,0))) -> 3 | E27: =IF(G27="Subetapa",0,IF(G27="serviço",OFFSET(E27,-1,0)+1,OFFSET(E27,-1,0))) -> 6 | G27: Serviço | H27: =IF(G27="Unidade Construtiva",TEXT(A27,"00"),IF(G27="Célula Construtiva",TEXT(B27,"00"),IF(G27="Etapa",CONCATENATE(TEXT(B27,"00"),".",TEXT(C27,"000")),IF(G27="Subetapa",CONCATENATE(TEXT(B27,"00"),".",TEXT(C27,"000"),".",TEXT(D27,"000")),IF(G27="Serviço",CONCATENATE(TEXT(B27,"00"),".",TEXT(C27,"000"),".",TEXT(D27,"000"),".",TEXT(E27,"000")),""))))) -> 02.001.003.006 | I27: Tela fachadeira reforçada com impressão digital | J27: 2678.8177 | K27: m2 | L27: 40182.265
A28: =IF($G28="UNIDADE CONSTRUTIVA",OFFSET(A28,0,0)+1,LARGE(A$3:A26,1)) -> 1 | B28: =IF(G28="UNIDADE CONSTRUTIVA",0,IF(G28="CÉLULA CONSTRUTIVA",OFFSET(B28,-1,0)+1,OFFSET(B28,-1,0))) -> 2 | C28: =IF(G28="CÉLULA CONSTRUTIVA",0,IF(G28="ETAPA",OFFSET(C28,-1,0)+1,OFFSET(C28,-1,0))) -> 1 | D28: =IF(G28="ETAPA",0,IF(G28="SUBETAPA",OFFSET(D28,-1,0)+1,OFFSET(D28,-1,0))) -> 4 | E28: =IF(G28="Subetapa",0,IF(G28="serviço",OFFSET(E28,-1,0)+1,OFFSET(E28,-1,0))) -> 0 | G28: Subetapa | H28: =IF(G28="Unidade Construtiva",TEXT(A28,"00"),IF(G28="Célula Construtiva",TEXT(B28,"00"),IF(G28="Etapa",CONCATENATE(TEXT(B28,"00"),".",TEXT(C28,"000")),IF(G28="Subetapa",CONCATENATE(TEXT(B28,"00"),".",TEXT(C28,"000"),".",TEXT(D28,"000")),IF(G28="Serviço",CONCATENATE(TEXT(B28,"00"),".",TEXT(C28,"000"),".",TEXT(D28,"000"),".",TEXT(E28,"000")),""))))) -> 02.001.004 | I28: Equipamentos de proteção - RESIDENCIAL | L28: =SUM(L29:L34) -> 613917.5
A29: =IF($G29="UNIDADE CONSTRUTIVA",OFFSET(A29,0,0)+1,LARGE(A$3:A27,1)) -> 1 | B29: =IF(G29="UNIDADE CONSTRUTIVA",0,IF(G29="CÉLULA CONSTRUTIVA",OFFSET(B29,-1,0)+1,OFFSET(B29,-1,0))) -> 2 | C29: =IF(G29="CÉLULA CONSTRUTIVA",0,IF(G29="ETAPA",OFFSET(C29,-1,0)+1,OFFSET(C29,-1,0))) -> 1 | D29: =IF(G29="ETAPA",0,IF(G29="SUBETAPA",OFFSET(D29,-1,0)+1,OFFSET(D29,-1,0))) -> 4 | E29: =IF(G29="Subetapa",0,IF(G29="serviço",OFFSET(E29,-1,0)+1,OFFSET(E29,-1,0))) -> 1 | G29: Serviço | H29: =IF(G29="Unidade Construtiva",TEXT(A29,"00"),IF(G29="Célula Construtiva",TEXT(B29,"00"),IF(G29="Etapa",CONCATENATE(TEXT(B29,"00"),".",TEXT(C29,"000")),IF(G29="Subetapa",CONCATENATE(TEXT(B29,"00"),".",TEXT(C29,"000"),".",TEXT(D29,"000")),IF(G29="Serviço",CONCATENATE(TEXT(B29,"00"),".",TEXT(C29,"000"),".",TEXT(D29,"000"),".",TEXT(E29,"000")),""))))) -> 02.001.004.001 | I29: Bandeja de proteção primária | J29: 426.23 | K29: m | L29: 125452.28
A30: =IF($G30="UNIDADE CONSTRUTIVA",OFFSET(A30,0,0)+1,LARGE(A$3:A28,1)) -> 1 | B30: =IF(G30="UNIDADE CONSTRUTIVA",0,IF(G30="CÉLULA CONSTRUTIVA",OFFSET(B30,-1,0)+1,OFFSET(B30,-1,0))) -> 2 | C30: =IF(G30="CÉLULA CONSTRUTIVA",0,IF(G30="ETAPA",OFFSET(C30,-1,0)+1,OFFSET(C30,-1,0))) -> 1 | D30: =IF(G30="ETAPA",0,IF(G30="SUBETAPA",OFFSET(D30,-1,0)+1,OFFSET(D30,-1,0))) -> 4 | E30: =IF(G30="Subetapa",0,IF(G30="serviço",OFFSET(E30,-1,0)+1,OFFSET(E30,-1,0))) -> 2 | G30: Serviço | H30: =IF(G30="Unidade Construtiva",TEXT(A30,"00"),IF(G30="Célula Construtiva",TEXT(B30,"00"),IF(G30="Etapa",CONCATENATE(TEXT(B30,"00"),".",TEXT(C30,"000")),IF(G30="Subetapa",CONCATENATE(TEXT(B30,"00"),".",TEXT(C30,"000"),".",TEXT(D30,"000")),IF(G30="Serviço",CONCATENATE(TEXT(B30,"00"),".",TEXT(C30,"000"),".",TEXT(D30,"000"),".",TEXT(E30,"000")),""))))) -> 02.001.004.002 | I30: Bandeja de proteção secundária | J30: 202.8 | K30: m | L30: 42600.168
A31: =IF($G31="UNIDADE CONSTRUTIVA",OFFSET(A31,0,0)+1,LARGE(A$3:A26,1)) -> 1 | B31: =IF(G31="UNIDADE CONSTRUTIVA",0,IF(G31="CÉLULA CONSTRUTIVA",OFFSET(B31,-1,0)+1,OFFSET(B31,-1,0))) -> 2 | C31: =IF(G31="CÉLULA CONSTRUTIVA",0,IF(G31="ETAPA",OFFSET(C31,-1,0)+1,OFFSET(C31,-1,0))) -> 1 | D31: =IF(G31="ETAPA",0,IF(G31="SUBETAPA",OFFSET(D31,-1,0)+1,OFFSET(D31,-1,0))) -> 4 | E31: =IF(G31="Subetapa",0,IF(G31="serviço",OFFSET(E31,-1,0)+1,OFFSET(E31,-1,0))) -> 3 | G31: Serviço | H31: =IF(G31="Unidade Construtiva",TEXT(A31,"00"),IF(G31="Célula Construtiva",TEXT(B31,"00"),IF(G31="Etapa",CONCATENATE(TEXT(B31,"00"),".",TEXT(C31,"000")),IF(G31="Subetapa",CONCATENATE(TEXT(B31,"00"),".",TEXT(C31,"000"),".",TEXT(D31,"000")),IF(G31="Serviço",CONCATENATE(TEXT(B31,"00"),".",TEXT(C31,"000"),".",TEXT(D31,"000"),".",TEXT(E31,"000")),""))))) -> 02.001.004.003 | I31: Guarda corpo em laje pós - desforma | J31: 811.2 | K31: m | L31: 39748.8
A32: =IF($G32="UNIDADE CONSTRUTIVA",OFFSET(A32,0,0)+1,LARGE(A$3:A25,1)) -> 1 | B32: =IF(G32="UNIDADE CONSTRUTIVA",0,IF(G32="CÉLULA CONSTRUTIVA",OFFSET(B32,-1,0)+1,OFFSET(B32,-1,0))) -> 2 | C32: =IF(G32="CÉLULA CONSTRUTIVA",0,IF(G32="ETAPA",OFFSET(C32,-1,0)+1,OFFSET(C32,-1,0))) -> 1 | D32: =IF(G32="ETAPA",0,IF(G32="SUBETAPA",OFFSET(D32,-1,0)+1,OFFSET(D32,-1,0))) -> 4 | E32: =IF(G32="Subetapa",0,IF(G32="serviço",OFFSET(E32,-1,0)+1,OFFSET(E32,-1,0))) -> 4 | G32: Serviço | H32: =IF(G32="Unidade Construtiva",TEXT(A32,"00"),IF(G32="Célula Construtiva",TEXT(B32,"00"),IF(G32="Etapa",CONCATENATE(TEXT(B32,"00"),".",TEXT(C32,"000")),IF(G32="Subetapa",CONCATENATE(TEXT(B32,"00"),".",TEXT(C32,"000"),".",TEXT(D32,"000")),IF(G32="Serviço",CONCATENATE(TEXT(B32,"00"),".",TEXT(C32,"000"),".",TEXT(D32,"000"),".",TEXT(E32,"000")),""))))) -> 02.001.004.004 | I32: Fechamento removível de vãos de porta de elevador em madeira | J32: 303.6 | K32: m2 | L32: 6038.604
A33: =IF($G33="UNIDADE CONSTRUTIVA",OFFSET(A33,0,0)+1,LARGE(A$3:A26,1)) -> 1 | B33: =IF(G33="UNIDADE CONSTRUTIVA",0,IF(G33="CÉLULA CONSTRUTIVA",OFFSET(B33,-1,0)+1,OFFSET(B33,-1,0))) -> 2 | C33: =IF(G33="CÉLULA CONSTRUTIVA",0,IF(G33="ETAPA",OFFSET(C33,-1,0)+1,OFFSET(C33,-1,0))) -> 1 | D33: =IF(G33="ETAPA",0,IF(G33="SUBETAPA",OFFSET(D33,-1,0)+1,OFFSET(D33,-1,0))) -> 4 | E33: =IF(G33="Subetapa",0,IF(G33="serviço",OFFSET(E33,-1,0)+1,OFFSET(E33,-1,0))) -> 5 | G33: Serviço | H33: =IF(G33="Unidade Construtiva",TEXT(A33,"00"),IF(G33="Célula Construtiva",TEXT(B33,"00"),IF(G33="Etapa",CONCATENATE(TEXT(B33,"00"),".",TEXT(C33,"000")),IF(G33="Subetapa",CONCATENATE(TEXT(B33,"00"),".",TEXT(C33,"000"),".",TEXT(D33,"000")),IF(G33="Serviço",CONCATENATE(TEXT(B33,"00"),".",TEXT(C33,"000"),".",TEXT(D33,"000"),".",TEXT(E33,"000")),""))))) -> 02.001.004.005 | I33: Varal de segurança com cabo de aço | J33: 811.2 | K33: m | L33: 197932.8
A34: =IF($G34="UNIDADE CONSTRUTIVA",OFFSET(A34,0,0)+1,LARGE(A$3:A27,1)) -> 1 | B34: =IF(G34="UNIDADE CONSTRUTIVA",0,IF(G34="CÉLULA CONSTRUTIVA",OFFSET(B34,-1,0)+1,OFFSET(B34,-1,0))) -> 2 | C34: =IF(G34="CÉLULA CONSTRUTIVA",0,IF(G34="ETAPA",OFFSET(C34,-1,0)+1,OFFSET(C34,-1,0))) -> 1 | D34: =IF(G34="ETAPA",0,IF(G34="SUBETAPA",OFFSET(D34,-1,0)+1,OFFSET(D34,-1,0))) -> 4 | E34: =IF(G34="Subetapa",0,IF(G34="serviço",OFFSET(E34,-1,0)+1,OFFSET(E34,-1,0))) -> 6 | G34: Serviço | H34: =IF(G34="Unidade Construtiva",TEXT(A34,"00"),IF(G34="Célula Construtiva",TEXT(B34,"00"),IF(G34="Etapa",CONCATENATE(TEXT(B34,"00"),".",TEXT(C34,"000")),IF(G34="Subetapa",CONCATENATE(TEXT(B34,"00"),".",TEXT(C34,"000"),".",TEXT(D34,"000")),IF(G34="Serviço",CONCATENATE(TEXT(B34,"00"),".",TEXT(C34,"000"),".",TEXT(D34,"000"),".",TEXT(E34,"000")),""))))) -> 02.001.004.006 | I34: Tela fachadeira reforçada com impressão digital | J34: 13476.324 | K34: m2 | L34: 202144.86
A35: =IF($G35="UNIDADE CONSTRUTIVA",OFFSET(A35,0,0)+1,LARGE(A$3:A18,1)) -> 1 | B35: =IF(G35="UNIDADE CONSTRUTIVA",0,IF(G35="CÉLULA CONSTRUTIVA",OFFSET(B35,-1,0)+1,OFFSET(B35,-1,0))) -> 2 | C35: =IF(G35="CÉLULA CONSTRUTIVA",0,IF(G35="ETAPA",OFFSET(C35,-1,0)+1,OFFSET(C35,-1,0))) -> 1 | D35: =IF(G35="ETAPA",0,IF(G35="SUBETAPA",OFFSET(D35,-1,0)+1,OFFSET(D35,-1,0))) -> 5 | E35: =IF(G35="Subetapa",0,IF(G35="serviço",OFFSET(E35,-1,0)+1,OFFSET(E35,-1,0))) -> 0 | G35: Subetapa | H35: =IF(G35="Unidade Construtiva",TEXT(A35,"00"),IF(G35="Célula Construtiva",TEXT(B35,"00"),IF(G35="Etapa",CONCATENATE(TEXT(B35,"00"),".",TEXT(C35,"000")),IF(G35="Subetapa",CONCATENATE(TEXT(B35,"00"),".",TEXT(C35,"000"),".",TEXT(D35,"000")),IF(G35="Serviço",CONCATENATE(TEXT(B35,"00"),".",TEXT(C35,"000"),".",TEXT(D35,"000"),".",TEXT(E35,"000")),""))))) -> 02.001.005 | I35: Meio ambiente | L35: =L36 -> 168585.11
A36: =IF($G36="UNIDADE CONSTRUTIVA",OFFSET(A36,0,0)+1,LARGE(A$3:A19,1)) -> 1 | B36: =IF(G36="UNIDADE CONSTRUTIVA",0,IF(G36="CÉLULA CONSTRUTIVA",OFFSET(B36,-1,0)+1,OFFSET(B36,-1,0))) -> 2 | C36: =IF(G36="CÉLULA CONSTRUTIVA",0,IF(G36="ETAPA",OFFSET(C36,-1,0)+1,OFFSET(C36,-1,0))) -> 1 | D36: =IF(G36="ETAPA",0,IF(G36="SUBETAPA",OFFSET(D36,-1,0)+1,OFFSET(D36,-1,0))) -> 5 | E36: =IF(G36="Subetapa",0,IF(G36="serviço",OFFSET(E36,-1,0)+1,OFFSET(E36,-1,0))) -> 1 | G36: Serviço | H36: =IF(G36="Unidade Construtiva",TEXT(A36,"00"),IF(G36="Célula Construtiva",TEXT(B36,"00"),IF(G36="Etapa",CONCATENATE(TEXT(B36,"00"),".",TEXT(C36,"000")),IF(G36="Subetapa",CONCATENATE(TEXT(B36,"00"),".",TEXT(C36,"000"),".",TEXT(D36,"000")),IF(G36="Serviço",CONCATENATE(TEXT(B36,"00"),".",TEXT(C36,"000"),".",TEXT(D36,"000"),".",TEXT(E36,"000")),""))))) -> 02.001.005.001 | I36: Meio ambiente | J36: 1 | K36: vb | L36: 168585.11
A37: =IF($G37="UNIDADE CONSTRUTIVA",OFFSET(A37,0,0)+1,LARGE(A$3:A35,1)) -> 1 | B37: =IF(G37="UNIDADE CONSTRUTIVA",0,IF(G37="CÉLULA CONSTRUTIVA",OFFSET(B37,-1,0)+1,OFFSET(B37,-1,0))) -> 2 | C37: =IF(G37="CÉLULA CONSTRUTIVA",0,IF(G37="ETAPA",OFFSET(C37,-1,0)+1,OFFSET(C37,-1,0))) -> 2 | D37: =IF(G37="ETAPA",0,IF(G37="SUBETAPA",OFFSET(D37,-1,0)+1,OFFSET(D37,-1,0))) -> 0 | E37: =IF(G37="Subetapa",0,IF(G37="serviço",OFFSET(E37,-1,0)+1,OFFSET(E37,-1,0))) -> 1 | G37: ETAPA | H37: =IF(G37="Unidade Construtiva",TEXT(A37,"00"),IF(G37="Célula Construtiva",TEXT(B37,"00"),IF(G37="Etapa",CONCATENATE(TEXT(B37,"00"),".",TEXT(C37,"000")),IF(G37="Subetapa",CONCATENATE(TEXT(B37,"00"),".",TEXT(C37,"000"),".",TEXT(D37,"000")),IF(G37="Serviço",CONCATENATE(TEXT(B37,"00"),".",TEXT(C37,"000"),".",TEXT(D37,"000"),".",TEXT(E37,"000")),""))))) -> 02.002 | I37: ADMINISTRAÇÃO E CANTEIRO DE OBRA | L37: =SUM(L38:L64)/2 -> 4742504.7
A38: =IF($G38="UNIDADE CONSTRUTIVA",OFFSET(A38,0,0)+1,LARGE(A$3:A37,1)) -> 1 | B38: =IF(G38="UNIDADE CONSTRUTIVA",0,IF(G38="CÉLULA CONSTRUTIVA",OFFSET(B38,-1,0)+1,OFFSET(B38,-1,0))) -> 2 | C38: =IF(G38="CÉLULA CONSTRUTIVA",0,IF(G38="ETAPA",OFFSET(C38,-1,0)+1,OFFSET(C38,-1,0))) -> 2 | D38: =IF(G38="ETAPA",0,IF(G38="SUBETAPA",OFFSET(D38,-1,0)+1,OFFSET(D38,-1,0))) -> 1 | E38: =IF(G38="Subetapa",0,IF(G38="serviço",OFFSET(E38,-1,0)+1,OFFSET(E38,-1,0))) -> 0 | G38: Subetapa | H38: =IF(G38="Unidade Construtiva",TEXT(A38,"00"),IF(G38="Célula Construtiva",TEXT(B38,"00"),IF(G38="Etapa",CONCATENATE(TEXT(B38,"00"),".",TEXT(C38,"000")),IF(G38="Subetapa",CONCATENATE(TEXT(B38,"00"),".",TEXT(C38,"000"),".",TEXT(D38,"000")),IF(G38="Serviço",CONCATENATE(TEXT(B38,"00"),".",TEXT(C38,"000"),".",TEXT(D38,"000"),".",TEXT(E38,"000")),""))))) -> 02.002.001 | I38: Equipe de Gestão e Apoio - HOTEL | L38: =SUM(L39:L44) -> 1185234.2
A39: =IF($G39="UNIDADE CONSTRUTIVA",OFFSET(A39,0,0)+1,LARGE(A$3:A32,1)) -> 1 | B39: =IF(G39="UNIDADE CONSTRUTIVA",0,IF(G39="CÉLULA CONSTRUTIVA",OFFSET(B39,-1,0)+1,OFFSET(B39,-1,0))) -> 2 | C39: =IF(G39="CÉLULA CONSTRUTIVA",0,IF(G39="ETAPA",OFFSET(C39,-1,0)+1,OFFSET(C39,-1,0))) -> 2 | D39: =IF(G39="ETAPA",0,IF(G39="SUBETAPA",OFFSET(D39,-1,0)+1,OFFSET(D39,-1,0))) -> 1 | E39: =IF(G39="Subetapa",0,IF(G39="serviço",OFFSET(E39,-1,0)+1,OFFSET(E39,-1,0))) -> 1 | G39: Serviço | H39: =IF(G39="Unidade Construtiva",TEXT(A39,"00"),IF(G39="Célula Construtiva",TEXT(B39,"00"),IF(G39="Etapa",CONCATENATE(TEXT(B39,"00"),".",TEXT(C39,"000")),IF(G39="Subetapa",CONCATENATE(TEXT(B39,"00"),".",TEXT(C39,"000"),".",TEXT(D39,"000")),IF(G39="Serviço",CONCATENATE(TEXT(B39,"00"),".",TEXT(C39,"000"),".",TEXT(D39,"000"),".",TEXT(E39,"000")),""))))) -> 02.002.001.001 | I39: Engenheiro civil pleno | J39: 24 | K39: mes | L39: 288000
A40: =IF($G40="UNIDADE CONSTRUTIVA",OFFSET(A40,0,0)+1,LARGE(A$3:A33,1)) -> 1 | B40: =IF(G40="UNIDADE CONSTRUTIVA",0,IF(G40="CÉLULA CONSTRUTIVA",OFFSET(B40,-1,0)+1,OFFSET(B40,-1,0))) -> 2 | C40: =IF(G40="CÉLULA CONSTRUTIVA",0,IF(G40="ETAPA",OFFSET(C40,-1,0)+1,OFFSET(C40,-1,0))) -> 2 | D40: =IF(G40="ETAPA",0,IF(G40="SUBETAPA",OFFSET(D40,-1,0)+1,OFFSET(D40,-1,0))) -> 1 | E40: =IF(G40="Subetapa",0,IF(G40="serviço",OFFSET(E40,-1,0)+1,OFFSET(E40,-1,0))) -> 2 | G40: Serviço | H40: =IF(G40="Unidade Construtiva",TEXT(A40,"00"),IF(G40="Célula Construtiva",TEXT(B40,"00"),IF(G40="Etapa",CONCATENATE(TEXT(B40,"00"),".",TEXT(C40,"000")),IF(G40="Subetapa",CONCATENATE(TEXT(B40,"00"),".",TEXT(C40,"000"),".",TEXT(D40,"000")),IF(G40="Serviço",CONCATENATE(TEXT(B40,"00"),".",TEXT(C40,"000"),".",TEXT(D40,"000"),".",TEXT(E40,"000")),""))))) -> 02.002.001.002 | I40: Almoxarife | J40: 24 | K40: mes | L40: 102106.75
...

Sheet HOTEL
G1: ORÇAMENTO DE VIABILIDADE - HOTEL
J2: HOTEL | M2: OBSERVAÇÕES | P2: Clientes possuem opção de fazer 3 suites ou 2 suites + 2 demi-suites - padrão 4 suites
A3: Unidade Construtiva | B3: Célula Construtiva | C3: Etapa | D3: Subetapa | E3: Serviço | G3: Hotel Colline de France - Rio de Janeiro | J3: Quantidade | K3: Unidade | L3: Custo
A4: =IF($G4="UNIDADE CONSTRUTIVA",2,LARGE(A$3:A3,1)) -> 2 | B4: =IF(G4="UNIDADE CONSTRUTIVA",0,IF(G4="CÉLULA CONSTRUTIVA",OFFSET(B4,-1,0)+1,OFFSET(B4,-1,0))) -> 0 | C4: =IF(G4="CÉLULA CONSTRUTIVA",0,IF(G4="ETAPA",OFFSET(C4,-1,0)+1,OFFSET(C4,-1,0))) -> Etapa | D4: =IF(G4="ETAPA",0,IF(G4="SUBETAPA",OFFSET(D4,-1,0)+1,OFFSET(D4,-1,0))) -> Subetapa | E4: =IF(G4="Subetapa",0,IF(G4="serviço",OFFSET(E4,-1,0)+1,OFFSET(E4,-1,0))) -> Serviço | G4: UNIDADE CONSTRUTIVA | H4: =IF(G4="Unidade Construtiva",TEXT(A4,"00"),IF(G4="Célula Construtiva",TEXT(B4,"00"),IF(G4="Etapa",CONCATENATE(TEXT(B4,"00"),".",TEXT(C4,"000")),IF(G4="Subetapa",CONCATENATE(TEXT(B4,"00"),".",TEXT(C4,"000"),".",TEXT(D4,"000")),IF(G4="Serviço",CONCATENATE(TEXT(B4,"00"),".",TEXT(C4,"000"),".",TEXT(D4,"000"),".",TEXT(E4,"000")),""))))) -> 02 | I4: GERENCIAMENTO EXECUTIVO | L4: =L5+L22+L40+L54+L74+L108+L131+L154++L168+L180+L191+L210+L225+L249+L264+L303+L322+L369+L380+L398+L428 -> 41673467
A5: =IF($G5="UNIDADE CONSTRUTIVA",OFFSET(A5,0,0)+1,LARGE(A$3:A4,1)) -> 2 | B5: =IF(G5="UNIDADE CONSTRUTIVA",0,IF(G5="CÉLULA CONSTRUTIVA",OFFSET(B5,-1,0)+1,OFFSET(B5,-1,0))) -> 1 | C5: =IF(G5="CÉLULA CONSTRUTIVA",0,IF(G5="ETAPA",OFFSET(C5,-1,0)+1,OFFSET(C5,-1,0))) -> 0 | D5: =IF(G5="ETAPA",0,IF(G5="SUBETAPA",OFFSET(D5,-1,0)+1,OFFSET(D5,-1,0))) -> Subetapa | E5: =IF(G5="Subetapa",0,IF(G5="serviço",OFFSET(E5,-1,0)+1,OFFSET(E5,-1,0))) -> Serviço | G5: CÉLULA CONSTRUTIVA | H5: =IF(G5="Unidade Construtiva",TEXT(A5,"00"),IF(G5="Célula Construtiva",TEXT(B5,"00"),IF(G5="Etapa",CONCATENATE(TEXT(B5,"00"),".",TEXT(C5,"000")),IF(G5="Subetapa",CONCATENATE(TEXT(B5,"00"),".",TEXT(C5,"000"),".",TEXT(D5,"000")),IF(G5="Serviço",CONCATENATE(TEXT(B5,"00"),".",TEXT(C5,"000"),".",TEXT(D5,"000"),".",TEXT(E5,"000")),""))))) -> 01 | I5: MOVIMENTAÇÃO DE TERRA | L5: =L6 -> 137245.95
A6: =IF($G6="UNIDADE CONSTRUTIVA",OFFSET(A6,0,0)+1,LARGE(A$3:A5,1)) -> 2 | B6: =IF(G6="UNIDADE CONSTRUTIVA",0,IF(G6="CÉLULA CONSTRUTIVA",OFFSET(B6,-1,0)+1,OFFSET(B6,-1,0))) -> 1 | C6: =IF(G6="CÉLULA CONSTRUTIVA",0,IF(G6="ETAPA",OFFSET(C6,-1,0)+1,OFFSET(C6,-1,0))) -> 1 | D6: =IF(G6="ETAPA",0,IF(G6="SUBETAPA",OFFSET(D6,-1,0)+1,OFFSET(D6,-1,0))) -> 0 | E6: =IF(G6="Subetapa",0,IF(G6="serviço",OFFSET(E6,-1,0)+1,OFFSET(E6,-1,0))) -> Serviço | G6: ETAPA | H6: =IF(G6="Unidade Construtiva",TEXT(A6,"00"),IF(G6="Célula Construtiva",TEXT(B6,"00"),IF(G6="Etapa",CONCATENATE(TEXT(B6,"00"),".",TEXT(C6,"000")),IF(G6="Subetapa",CONCATENATE(TEXT(B6,"00"),".",TEXT(C6,"000"),".",TEXT(D6,"000")),IF(G6="Serviço",CONCATENATE(TEXT(B6,"00"),".",TEXT(C6,"000"),".",TEXT(D6,"000"),".",TEXT(E6,"000")),""))))) -> 01.001 | I6: MOVIMENTAÇÃO DE TERRA | L6: =SUM(L7:L20)/2 -> 137245.95
