Workbook
Name \0: #REF!
Name \0: #REF!
Name \0: #REF!
Name \0: #REF!
Name \0: #REF!
Name \0: #REF!
Name \0: #REF!
Name \1: #REF!
Name \a: #REF!
Name \a: #REF!
Name \b: #REF!
Name \c: #REF!
Name \d: #REF!
Name \e: #REF!
Name \i: #REF!
Name \J: #REF!
Name \k: #REF!
Name \l: #N/A
Name \m: #REF!
Name \m: #REF!
Name \o: #REF!
Name \p: #REF!
Name \r: #REF!
Name \T: #REF!
Name \z: #REF!
Name ______ACR10: #REF!
Name ______ACR15: #REF!
Name ______acr20: #REF!
Name ______acr5: #REF!
Name ______ARQ1: #REF!
Name ______QT100: #REF!
Name ______QT2: #REF!
Name ______QT3: #REF!
Name ______QT4: #REF!
Name ______QT50: #REF!
Name ______QT75: #REF!
Name _____ACR10: #REF!
Name _____ACR15: #REF!
Name _____acr20: #REF!
Name _____acr5: #REF!
Name _____ARQ1: #REF!
Name _____QT100: #REF!
Name _____QT2: #REF!
Name _____QT3: #REF!
Name _____QT4: #REF!
Name _____QT50: #REF!
Name _____QT75: #REF!
Name ___ACR10: #REF!
Name ___ACR15: #REF!
Name ___acr20: #REF!
Name ___acr5: #REF!
Name ___ARQ1: #REF!
Name ___QT100: #REF!
Name ___QT2: #REF!
Name ___QT3: #REF!
Name ___QT4: #REF!
Name ___QT50: #REF!
Name ___QT75: #REF!
Name __ACR10: #REF!
Name __ACR15: #REF!

Sheet DADOS_INICIAIS
A1: Obra | B1: Hotel e Residencial Colline
A2: Empresa | B2: Colline - Miguel Pereira
A3: Revisão | B3: R00
A4: Arquitetura base | B4: PLANTA SITUAÇÃO HOTEL COLLINE e PLANTA SITUACAO RESIDENCIAL COLLINE
A5: DADOS OBRA
B7: Descrição | C7: Identificador | D7: Unidade | E7: Hotel | F7: Residencial | G7: Quantidade Total
B8: ÁREA DO TERRENO | C8: AT | D8: M2 | G8: 6049.17
B9: ÁREA TOTAL CONSTRUÍDA | C9: AC | D9: M2 | E9: =SUM(E10:E20) -> 6049.17 | F9: =SUM(F10:F20) -> 21510.28 | G9: =SUM(G10:G20) -> 27559.45
B10: SUBSOLO / TERREO | D10: M2 | E10: 1662.34 | F10: 2365.57 | G10: =F10+E10 -> 4027.91
B11: TÉRREO/ GARAGEM 1 | D11: M2 | E11: =1147.74+527.82 -> 1675.56 | F11: 2339.03 | G11: =F11+E11 -> 4014.59
B12: 1º PAVIMENTO / GARAGEM 2 | D12: M2 | E12: =812.7+31.66 -> 844.36 | F12: 2514.32 | G12: =F12+E12 -> 3358.68
B13: 2º PAVIMENTO / LAZER | D13: M2 | E13: =900.46+243.83 -> 1144.29 | F13: 2513.4 | G13: =F13+E13 -> 3657.69
B14: SUBTELHADO / 5º PAV. DIFERENCIADO TORRE I E II (X1) | D14: M2 | E14: =691.7+30.92 -> 722.62 | F14: 699.84 | G14: =F14+E14 -> 1422.46
B15: 6º AO 18º PAV. DIFERENCIADO TORRE I E II (X13) | D15: M2 | F15: 9097.92 | G15: =F15+E15 -> 9097.92
B16: DUPLEX INFERIOR TORRE I E II | D16: M2 | F16: 699.84 | G16: =F16+E16 -> 699.84
B17: DUPLEX SUPERIOR TORRE I E II | D17: M2 | F17: 693.56 | G17: =F17+E17 -> 693.56
B18: INSPEÇÃO TORRE I E II | D18: M2 | F18: 303.24 | G18: =F18+E18 -> 303.24
B19: CASA DE MÁQUINAS TORRE I E II | D19: M2 | F19: 150.18 | G19: =F19+E19 -> 150.18
B20: CAIXA D'AGUA TORRE I E II | D20: M2 | F20: 133.38 | G20: =F20+E20 -> 133.38
B21: UNIDADES RESIDENCIAIS | C21: UR | D21: UN | E21: 36 | F21: 60 | G21: =F21+E21 -> 96 | H21: =G9-G33-G32 -> 16003.74
B22: Dormitórios | C22: dorm | D22: UN | E22: =E21 -> 36 | G22: =F22+E22 -> 36
B23: Banheiros | C23: ban | D23: UN | G23: =F23+E23 -> 0
B24: UNIDADES COMERCIAIS | C24: UC | D24: UN | G24: =F24+E24 -> 0
B25: Churrasqueiras | C25: CHU | D25: UN | F25: 60 | G25: =F25+E25 -> 60
B26: NÚMERO TOTAL DE PAVIMENTOS | C26: NP | D26: UN | E26: 5 | F26: 23 | G26: =F26+E26 -> 28
B27: NÚMERO DE PAVIMENTOS TIPO | C27: NPT | D27: UN | E27: 0 | F27: 13 | G27: =F27+E27 -> 13
B28: NÚMERO DE PAVIMENTOS TIPO DIFERENCIADOS | C28: NPD | D28: UN | E28: 3 | F28: 1 | G28: =F28+E28 -> 4
B29: NÚMERO DE PAVIMENTOS DUPLEX | C29: ND | D29: UN | E29: 0 | F29: 1 | G29: =F29+E29 -> 1
B30: ÁREA DE PROJEÇÃO DA TORRE | C30: APT | D30: M2 | E30: 1021.82 | F30: =369.45*2 -> 738.9 | G30: =F30+E30 -> 1760.72
B31: PERÍMETRO DE PROJEÇÃO DA TORRE | C31: PPT | D31: M | E31: 151.474 | F31: =101.4*2 -> 202.8 | G31: =F31+E31 -> 354.274
B32: ÁREA DE LAZER | C32: AL | D32: M2 | E32: 0 | F32: =F13 -> 2513.4 | G32: =F32+E32 -> 2513.4
B33: ÁREA DO EMBASAMENTO | C33: AE | D33: M2 | E33: =E11 -> 1675.56 | F33: =F11+F12+F13 -> 7366.75 | G33: =F33+E33 -> 9042.31
B34: ÁREA DE SUBSOLOS | C34: S | D34: M2 | E34: =E10 -> 1662.34 | F34: 0 | G34: =F34+E34 -> 1662.34
B35: NÚMERO DE SUBSOLOS | C35: NS | D35: UN | E35: 1 | F35: 0 | G35: =F35+E35 -> 1
B36: ÁREA DE PROJEÇÃO DO EMBASAMENTO | C36: APE | D36: M2 | E36: 2087.28 | F36: 2365.57 | G36: =F36+E36 -> 4452.85 | H36: =G36/G9 -> 0.16157253
B37: PERÍMETRO DE PROJEÇÃO DE EMBAMENTO | C37: PE | D37: M | E37: 226.19 | F37: 223.43 | G37: =F37+E37 -> 449.62
B38: NÚMERO DE PAVIMENTOS DE EMBASAMENTO | C38: NE | D38: UN | E38: 1 | F38: 3 | G38: =F38+E38 -> 4

Sheet MOVIMENTAÇÃO_DE_TERRA
A2: MOVIMENTAÇÃO DE TERRA
A3: Data | B3: 45780
A4: Arquivo base | B4: -
A6: ESCAVAÇÃO VERTICAL DE SUBSOLO
A8: Descrição | B8: Área de subsolo (m) | C8: Altura do subsolo (m) | D8: Volume total de escavação (m3) | E8: Preço unitário de escavação (R$ / m3) | F8: Valor total | G8: Observação
A9: Escavação | E9: 0 | F9: =E9*D9*1.1 -> 0
A10: Aterro | D10: =8.45*2*15 -> 253.5 | E10: 0 | F10: =E10*D10*1.1 -> 0 | G10: "subsolo" na verdade aterrado na frente do terreno para rampas
A11: TOTAL | F11: =SUM(F9:F9) -> 0
A13: REBAIXAMENTO DE LENÇOL FREÁTICO
A15: Descrição | B15: Quantidade (dias) | E15: Preço unitário de rebaixamento (R$ / dias) | F15: Valor total | G15: Observação
A16: Rebaixamento de lençol | B16: 0 | E16: 200 | F16: =B16*E16*1.1 -> 0
A17: TOTAL | F17: =SUM(F16:F16) -> 0
A19: ESCAVAÇÃO E REATERRO DE VALAS
A21: Descrição | B21: Parâmetro | D21: Volume total de escavação (m3) | E21: Preço unitário (R$ / m3) | F21: Valor total | G21: Observação
A22: Escavação mecanizada para blocos e baldrames | B22: 1.3 | C22: m³ / Vol infra | D22: =B22*'INFRAESTRUTURA '!D29 -> 1194.336 | E22: 36.36 | F22: =E22*D22*1.1 -> 47768.663
A23: Reaterro para blocos e baldrames | B23: 0.6 | C23: m³ / Vol Escavação | D23: =D22-'INFRAESTRUTURA '!D29 -> 275.616 | E23: 14.55 | F23: =E23*D23*1.1 -> 4411.2341
A24: Movimentação de bota-fora | B24: 1.3 | D24: =(D22-D23)*B24 -> 1194.336 | E24: 45.45 | F24: =E24*D24*1.1 -> 59710.828
A25: Movimentação de terra das estacas | B25: 1 | C25: m³ | D25: ='INFRAESTRUTURA '!D19 -> 0 | E25: 20 | F25: =E25*D25*1.1 -> 0
A26: TOTAL | F26: =SUM(F22:F25) -> 111890.73
A28: REGULARIZAÇÃO E APILOAMENTO DE FUNDO DE VALAS
A30: Descrição | B30: Parâmetro | D30: Área de lastro (m²) | E30: Preço unitário (R$ / m2) | F30: Valor total | G30: Observação
A31: Lastro de concreto magto e=5cm | B31: 0.8 | C31: m² / APE | D31: =B31*DADOS_INICIAIS!F36 -> 1892.456 | E31: =370*0.05 -> 18.5 | F31: =E31*D31*1.1 -> 38511.48 | H31: =F31/DADOS_INICIAIS!G36 -> 8.648726
A32: TOTAL | F32: =SUM(F31:F31) -> 38511.48
A34: TOTAL MOVIMENTAÇÃO DE TERRA | F34: =F11+F17+F26+F32 -> 150402.2 | G34: =F34/DADOS_INICIAIS!F9 -> 6.9921082

Sheet CONTENÇÕES
A3: CONTENÇÃO
A4: Data
A5: Arquivo base
A7: CORTINA DE ESTACAS
A9: Descrição | B9: Parâmetro | D9: Quantidade | F9: Preço unitário | G9: Valor total
A10: Número de Estacas | B10: 0.15 | C10: un / APE | D10: =B10*DADOS_INICIAIS!G36 -> 667.9275 | E10: un
A11: Estaca Hélice Continua Diâmetro 40 | B11: 0.1 | D11: =B11*$D$10 -> 66.79275 | E11: un
B12: 20 | C12: m/un | D12: =B12*D11 -> 1335.855 | E12: m | G12: =F12*D12 -> 0
A13: Estaca Hélice Continua Diâmetro 50 | B13: 0.5 | D13: =B13*$D$10 -> 333.96375 | E13: un
B14: 20 | C14: m/un | D14: =B14*D13 -> 6679.275 | E14: m | G14: =F14*D14 -> 0
A15: Estaca Hélice Continua Diâmetro 60 | B15: 0.4 | C15: un / APE | D15: =B15*$D$10 -> 267.171 | E15: un
B16: 20 | C16: m/un | D16: =B16*D15 -> 5343.42 | E16: m | G16: =F16*D16 -> 0
A17: Concreto | B17: =(PI()*0.4^2)/4*D14+(PI()*0.5^2)/4*D16+(PI()*0.6^2)/4*D12 -> 2266.2246 | C17: un / APE | D17: =(PI()*0.4^2)/4*D14+(PI()*0.5^2)/4*D16+(PI()*0.6^2)/4*D12 -> 2266.2246 | E17: m³ | G17: =F17*D17 -> 0
A18: Armação 6,3mm | B18: 1.6575131 | C18: kg / m³ | D18: =B18*D17 -> 3756.297 | E18: kg | G18: =F18*D18 -> 0
A19: Armação 16mm | B19: 10.178338 | C19: kg / m³ | D19: =B19*D17 -> 23066.399 | E19: kg | G19: =F19*D19 -> 0
A20: Mobilização | B20: 1 | C20: vb | D20: 1 | E20: vb | G20: =F20*D20 -> 0
A21: TOTAL | G21: =SUM(G10:G20) -> 0
A23: PAREDE DE CONCRETO
A25: Descrição | B25: Parâmetro | D25: Quantidade | F25: Preço unitário | G25: Valor total
A26: Fabricação, montagem e desmontagem de forma para blocos e baldrames resinado | B26: 2.1 | C26: m² / APE | D26: =B26*DADOS_INICIAIS!G36 -> 9350.985 | E26: m² | G26: =F26*D26 -> 0
A27: Concreto | B27: 0.65 | C27: m³ / APE | D27: =B27*DADOS_INICIAIS!G36 -> 2894.3525 | E27: m³ | G27: =F27*D27 -> 0
A28: Armação | B28: 110 | C28: kg / m³ | D28: =B28*D27 -> 318378.78 | E28: kg | G28: =F28*D28 -> 0
A29: Mão de obra | B29: =SUPRAESTRUTURA!B15*1.5 -> 315 | C29: R$ / APE | D29: =DADOS_INICIAIS!G36 -> 4452.85 | E29: m² | F29: =B29 -> 315 | G29: =F29*D29 -> 1402647.8
A30: TOTAL | G30: =SUM(G26:G29) -> 1402647.8
A33: PAREDE DIAFRAGMA
A35: Descrição | B35: Parâmetro | D35: Quantidade | F35: Preço unitário | G35: Valor total
A36: Fabricação, montagem e desmontagem de forma para blocos e baldrames resinado | B36: 2.1 | C36: m² / APE | D36: =B36*DADOS_INICIAIS!G46 -> 0 | E36: m² | G36: =F36*D36 -> 0
A37: Concreto | B37: 0.65 | C37: m³ / APE | D37: =B37*DADOS_INICIAIS!G46 -> 0 | E37: m³ | G37: =F37*D37 -> 0
A38: Armação | B38: 110 | C38: kg / m³ | D38: =B38*D37 -> 0 | E38: kg | G38: =F38*D38 -> 0
A39: Mão de obra | B39: =SUPRAESTRUTURA!B74*1.5 -> 0 | C39: R$ / APE | D39: =DADOS_INICIAIS!G46 -> 0 | E39: m² | F39: =B39 -> 0 | G39: =F39*D39 -> 0
A40: TOTAL | G40: =SUM(G36:G39) -> 0
A46: TOTAL INFRAESTRUTURA | G46: =G21+G30 -> 1402647.8 | H46: =G46/DADOS_INICIAIS!G9 -> 50.895346

Sheet INFRAESTRUTURA 
A3: INFRAESTRUTURA
A4: Data | B4: 45780
A5: Arquivo base | B5: RMP-FUN-EX-0002-TABELAS-R02
A7: FUNDAÇÃO PROFUNDA
A9: Descrição | B9: Parâmetro | D9: Quantidade | F9: Preço unitário | G9: Valor total | H9: Observação
A10: Número de Estacas | B10: =D10/[4]DADOS_INICIAIS!E36 -> 0.17151508 | C10: un / APE | D10: =D11+D13+D15+D17 -> 358 | E10: un | H10: Quantitativos trazidos de preliminar de fundação
A11: Estaca Pre-moldada cravada 20X20 | B11: =D11/D10 -> 0.12569832 | D11: 45 | E11: un
B12: 15 | C12: m/un | D12: =B12*D11 -> 675 | E12: m | F12: 158.15 | G12: =F12*D12*1.1 -> 117426.38
A13: Estaca Pre-moldada cravada 30X30 | B13: =D13/D10 -> 0.29888268 | D13: 107 | E13: un
B14: 15 | C14: m/un | D14: =B14*D13 -> 1605 | E14: m | F14: =F12*1.3 -> 205.595 | G14: =F14*D14*1.1 -> 362977.97
A15: Estaca Pre-moldada centrifugada 50cm | B15: =D15/D12 -> 0.28444444 | D15: =206-D17 -> 192 | E15: un
B16: 15 | C16: m/un | D16: =B16*D15 -> 2880 | E16: m | F16: =356.72*1.15 -> 410.228 | G16: =F16*D16*1.1 -> 1299602.3
A17: Estaca Pre-moldada centrifugada 42cm | B17: =D17/D14 -> 0.0087227414 | D17: =14 -> 14 | E17: un
B18: 8 | C18: m/un | D18: =B18*D17 -> 112 | E18: m | F18: =356.72*1.15 -> 410.228 | G18: =F18*D18*1.1 -> 50540.09
A19: Concreto (25 Mpa) | B19: 1.1 | C19: perda | E19: m³ | F19: =510+44 -> 554 | G19: =F19*D19*B19*1.1 -> 0
A20: Armação | C20: kg / m³ | E20: kg | F20: 7.62 | G20: =F20*D20*1.1 -> 0
A21: Mobilização | B21: 1 | C21: vb | D21: 1 | E21: vb | F21: 14500 | G21: =F21*D21*1.1 -> 15950
A22: Apoio e arrasamento de estacas | E22: un | F22: 300 | G22: =F22*D22*1 -> 0
A23: TOTAL | G23: =SUM(G10:G22) -> 1846496.7
G24: =G23/(D12+D14+D16+D18) -> 350.24597
A25: FUNDAÇÃO RASA
A27: Descrição | B27: Parâmetro | D27: Quantidade | F27: Preço unitário | G27: Valor total | H27: Observação
A28: Fabricação, montagem e desmontagem de forma para blocos e baldrames resinado | B28: =D28/[4]DADOS_INICIAIS!E36 -> 1.0015858 | C28: m² / APE | D28: =9.82+1366.63+714.14 -> 2090.59 | E28: m² | F28: 68 | G28: =F28*D28*1.1 -> 156376.13
A29: Concreto (40 Mpa) | B29: =D29/[4]DADOS_INICIAIS!E36 -> 0.44015178 | C29: m³ / APE | D29: =0.94+263.4+129.64+524.74 -> 918.72 | E29: m³ | F29: =514+44 -> 558 | G29: =F29*D29*1.05*1.1 -> 592105.85
A30: Armação | B30: 100 | C30: kg / m³ | D30: =B30*D29 -> 91872 | E30: kg | F30: 7.62 | G30: =F30*D30*1.1 -> 770071.1
A31: Mão de obra | B31: =[4]SUPRAESTRUTURA!B15*1.5 -> 315 | C31: R$ / APE | D31: =DADOS_INICIAIS!F10 -> 2365.57 | E31: m² | F31: =B31 -> 315 | G31: =F31*D31*1.1 -> 819670.01
A32: TOTAL | G32: =SUM(G28:G31) -> 2338223.1
A35: TOTAL INFRAESTRUTURA | G35: =G32+G23 -> 4184719.8 | H35: =G35/DADOS_INICIAIS!F9 -> 194.54511

Sheet SUPRAESTRUTURA
A3: SUPRAESTRUTURA
A4: Data | B4: 45780
A5: Arquivo base | B5: -
A7: SUPRAESTRUTURA - LAJE MACIÇA
A9: Descrição | B9: Parâmetro | D9: Quantidade | F9: Preço unitário | G9: Valor total | H9: Observação
A10: Fabricação forma | B10: 4 | C10: Jogos | D10: =(D11/DADOS_INICIAIS!F26)*B10 -> 7366.6852 | E10: m² | F10: 110 | G10: =F10*D10*1.1 -> 891368.91
A11: Montagem de forma | B11: 2.5 | C11: m² / AC | D11: =[5]Sheet1!$D$92 -> 42358.44 | E11: m² | F11: 2.5 | G11: =F11*D11*1.1 -> 116485.71 | H11: Quantidade de resumo
A12: Escoramento | B12: 4 | C12: un / AE | D12: =ROUNDUP(B12*DADOS_INICIAIS!F12*B10,0) -> 40230 | E12: un | F12: =17 -> 17 | G12: =F12*D12*1.1 -> 752301
A13: Concreto | B13: 0.2 | C13: m³ / AC | D13: =[5]Sheet1!$C$92 -> 5653.83 | E13: m³ | F13: =514+44 -> 558 | G13: =F13*D13*1.05*1.1 -> 3643836.9 | H13: Quantidade de resumo
A14: Armadura Convencional para Estrutura | B14: 100 | C14: kg / m³ | D14: =D13*B14 -> 565383 | E14: kg | F14: 7.62 | G14: =F14*D14*1.1 -> 4739040.3
A15: Mão de obra - estrutura em concreto armado | B15: 210 | C15: R$ / AC | D15: =DADOS_INICIAIS!F9 -> 21510.28 | E15: m² | F15: 210 | G15: =F15*D15*1.1 -> 4968874.7
A16: Perfuração de vigas | B16: 1500 | C16: R$ / NP | D16: 1 | E16: vb | F16: =B16*DADOS_INICIAIS!F26 -> 34500 | G16: =F16*D16*1.1 -> 37950 | H16: Coeficiente originário do Gran Torino (R$ 160,00/un) | I16: Nova utiliza a verba de 1.500,00 por pav
A17: TOTAL | G17: =SUM(G10:G16) -> 15149858 | K17: =4160+1440+1120+2880+4800+91680+4000 -> 110080 | L17: =K17/21 -> 5241.9048
A19: SUPRAESTRUTURA - LAJE CUBETAS PROTENDIDAS
A21: Descrição | B21: Parâmetro | D21: Quantidade | F21: Preço unitário | G21: Valor total | H21: Observação
A22: Fabricação forma | B22: 2 | C22: Jogos | D22: =(D23/DADOS_INICIAIS!$G$26)*B22 -> 4133.9175 | E22: m² | F22: 110 | G22: =F22*D22*1.1 -> 500204.02
A23: Montagem de forma | B23: 2.1 | C23: m² / AC | D23: =B23*DADOS_INICIAIS!$G$9 -> 57874.845 | E23: m² | F23: 2.5 | G23: =F23*D23*1.1 -> 159155.82
A24: Escoramento | B24: 3 | C24: un / APT*NPT | D24: =ROUNDUP(B24*DADOS_INICIAIS!$G$36*B22,0) -> 26718 | E24: un | F24: =17 -> 17 | G24: =F24*D24*1.1 -> 499626.6
A25: Cubetas | B25: 25 | C25: R$ / AC | D25: 1 | E25: vb | F25: =B25*DADOS_INICIAIS!$G$9 -> 688986.25 | G25: =F25*D25*1.1 -> 757884.88
A26: Protensão - lajes - materiais | B26: =12.3*0.8 -> 9.84 | C26: RS / m² | D26: =(DADOS_INICIAIS!$G$27+DADOS_INICIAIS!$G$28)*DADOS_INICIAIS!$G$30+DADOS_INICIAIS!$G$33 -> 38974.55 | E26: m² | F26: =B26 -> 9.84 | G26: =F26*D26*1.1 -> 421860.53
A27: Protensão - lajes - cabos | B27: =2.83*0.8 -> 2.264 | C27: kg / m² | D27: =B27*D26 -> 88238.381 | E27: kg | F27: 12.3 | G27: =F27*D27*1.1 -> 1193865.3
A28: Protensão - lajes - serviços | B28: 9000 | C28: und / pav | D28: =DADOS_INICIAIS!G26 -> 28 | E28: pav | F28: =B28 -> 9000 | G28: =F28*D28*1.1 -> 277200
A29: Concreto | B29: 0.18 | C29: m³ / AC | D29: =B29*DADOS_INICIAIS!$G$9 -> 4960.701 | E29: m³ | F29: =535+45 -> 580 | G29: =F29*D29*1.05*1.1 -> 3323173.6
A30: Cristalizante (reservatorios) | B30: 0.2 | D30: =B30*D29 -> 992.1402 | E30: m³ | F30: =1.22*F29-F29 -> 127.6 | G30: =F30*D30*1.05*1.1 -> 146219.64
A31: Armadura Convencional para Estrutura | B31: 110 | C31: kg / m³ | D31: =D29*B31-D27 -> 457438.73 | E31: kg | F31: 7.62 | G31: =F31*D31*1.1 -> 3834251.4
A32: Mão de obra - estrutura em concreto armado | B32: 240 | C32: R$ / AC | D32: =DADOS_INICIAIS!$G$9 -> 27559.45 | E32: m² | F32: =B32 -> 240 | G32: =F32*D32*1.1 -> 7275694.8
A33: Perfuração de vigas | B33: 5300 | C33: R$ / NP | D33: 1 | E33: vb | F33: =B33*DADOS_INICIAIS!$G$26 -> 148400 | G33: =F33*D33*1.1 -> 163240 | H33: Coeficiente originário do Gran Torino (R$ 160,00/un)
A34: TOTAL | G34: =SUM(G22:G33) -> 18552377
A36: SUPRAESTRUTURA - LAJE TRELIÇADA
A38: Descrição | B38: Parâmetro | D38: Quantidade | F38: Preço unitário | G38: Valor total | H38: Observação
A39: Fabricação forma | B39: 2 | C39: Jogos | D39: =(D40/DADOS_INICIAIS!$G$26)*B39 -> 0 | E39: m² | F39: 85 | G39: =F39*D39*1.1 -> 0
A40: Montagem de forma | B40: 2.1 | C40: m² / AC | D40: =B40*DADOS_INICIAIS!G49 -> 0 | E40: m² | F40: 1.5 | G40: =F40*D40*1.1 -> 0
A41: Escoramento - Torre | B41: 2 | C41: un / APT*NPT | D41: =B41*DADOS_INICIAIS!G58*DADOS_INICIAIS!G55 -> 0 | E41: un | F41: 17 | G41: =F41*D41*1.1 -> 0
A42: Escoramento - Embasamento | B42: 2 | C42: un / AE | D42: =B42*DADOS_INICIAIS!G61 -> 0 | E42: un | F42: 17 | G42: =F42*D42*1.1 -> 0
A43: Cubetas | B43: 25 | C43: R$ / AC | D43: =B43*DADOS_INICIAIS!G49 -> 0 | E43: m³ | F43: =B43 -> 25 | G43: =F43*D43*1.1 -> 0
A44: Concreto | B44: 0.25 | C44: m³ / AC | D44: =B44*DADOS_INICIAIS!G49 -> 0 | E44: m³ | F44: =575 -> 575 | G44: =F44*D44*1.05*1.1 -> 0
A45: Armadura Convencional para Estrutura | B45: 110 | C45: kg / m³ | D45: =D44*B45 -> 0 | E45: kg | F45: 7.25 | G45: =F45*D45*1.1 -> 0
A46: Mão de obra - estrutura em concreto armado | B46: 240 | C46: R$ / AC | D46: =DADOS_INICIAIS!G49 -> 0 | E46: m² | F46: =B46 -> 240 | G46: =F46*D46*1.1 -> 0
A47: Perfuração de vigas | B47: 5300 | C47: R$ / NP | D47: 1 | E47: vb | F47: =B47*DADOS_INICIAIS!G54 -> 0 | G47: =F47*D47*1.1 -> 0 | H47: Coeficiente originário do Gran Torino (R$ 160,00/un)
A48: TOTAL | G48: =SUM(G39:G47) -> 0
...

Sheet ALVENARIA
A3: PAREDES E PAINÉIS
A4: Data | B4: 45780
A5: Arquivo base | B5: -
A7: ALVENARIA
A9: Descrição | B9: Parâmetro | D9: Quantidade | F9: Preço unitário | G9: Valor total | H9: Observação
A10: Alvenaria externo | B10: =D10/DADOS_INICIAIS!F9 -> 0.6265062 | C10: m² / AE | D10: =DADOS_INICIAIS!F31*(65.14-14.84)+DADOS_INICIAIS!F37*(14.84-0.18) -> 13476.324 | E10: m² | F10: 48 | G10: =F10*D10*1.1 -> 711549.9
A11: Alvenaria escadas resistente á fogo (sical) | B11: 0.2 | C11: m² / AC | D11: =B11*DADOS_INICIAIS!F9 -> 4302.056 | E11: m² | F11: 70 | G11: =F11*D11*1.05*1.1 -> 347821.23
A12: Alvenaria refratárias | B12: 1.75 | C12: m² * CHU | D12: =B12*DADOS_INICIAIS!$F$25 -> 105 | E12: un | F12: 310 | G12: =F12*D12*B12*1.1 -> 62658.75
A13: Drywall | B13: 0.9 | C13: m² / AC | D13: =B13*DADOS_INICIAIS!$F$9 -> 19359.252 | E13: m² | F13: 191.17 | G13: =F13*D13*1.1 -> 4070999 | H13: 2ST/90/ST+RU
A14: Serviços complementares | B14: 12.5 | C14: R$ / m² | D14: =D10+D11 -> 17778.38 | E14: m² | F14: =B14 -> 12.5 | G14: =F14*D14*1.1 -> 244452.72
A15: Mão de obra | B15: 35 | C15: R$ / m² | D15: =D10+D11 -> 17778.38 | E15: m² | F15: 36 | G15: =F15*D15*1.1 -> 704023.84
A16: Mão de obra DRYWALL | B16: 40 | C16: R$ / m² | D16: =D13 -> 19359.252 | E16: m² | F16: 40 | G16: =F16*D16*1.1 -> 851807.09
A17: TOTAL | G17: =SUM(G10:G16) -> 6993312.5 | K17: =4160+1440+1120+2880+4800+91680+4000 -> 110080 | L17: =K17/21 -> 5241.9048
A19: ALVENARIA - DRTWALL
A21: Descrição | B21: Parâmetro | D21: Quantidade | F21: Preço unitário | G21: Valor total | H21: Observação
A22: Alvenaria embasamento | B22: 1 | C22: m² / AE | D22: =B22*DADOS_INICIAIS!$G$33 -> 9042.31 | E22: m² | F22: 45 | G22: =F22*D22*1.1 -> 447594.34
A23: Alvenaria lazer | B23: 0.4 | C23: m² / AL | D23: =B23*DADOS_INICIAIS!$G$32 -> 1005.36 | E23: m² | F23: 45 | G23: =F23*D23*1.1 -> 49765.32
A24: Alvenaria tipo | B24: 1.62 | C24: m² / APT*(NPT+2ND) | D24: =B24*(DADOS_INICIAIS!$G$30*(DADOS_INICIAIS!$G$27+DADOS_INICIAIS!$G$28))*0.3 -> 14547.069 | E24: un | F24: 45 | G24: =F24*D24*1.1 -> 720079.9
A25: Drywall tipo | B25: 1.65 | C25: m² / APT*(NPT+2ND) | D25: =B25*(DADOS_INICIAIS!$G$30*(DADOS_INICIAIS!$G$27+DADOS_INICIAIS!$G$28))*0.7 -> 34571.737 | F25: 220 | G25: =F25*D25*1.1 -> 8366360.4 | J25: =D25/(D30+D25) -> 0.52312509
A26: Alvenaria escadas | B26: 0.2 | C26: m² / AC | D26: =B26*DADOS_INICIAIS!$G$9 -> 5511.89 | E26: un | F26: 70 | G26: =F26*D26*1.1 -> 424415.53 | J26: =1-J25 -> 0.47687491
A27: Alvenaria cobertura / reservatório | B27: 0.8 | C27: m² / APT | D27: =B27*DADOS_INICIAIS!$G$30 -> 1408.576 | E27: m³ | F27: 45 | G27: =F27*D27*1.1 -> 69724.512
A28: Alvenaria refratárias | B28: 1.75 | C28: m² * CHU | D28: ='SISTEMAS ESPECIAIS'!B14 -> 62 | E28: un | F28: 210
A29: Churrasqueiras pré-moldadas | D29: =D28 -> 62 | E29: un | F29: 1800 | G29: =F29*D29*1.1 -> 122760
A30: Serviços complementares | B30: 12.5 | C30: R$ / m² | D30: =D23+D24+D22+D26+D27 -> 31515.205 | E30: kg | F30: =B30 -> 12.5 | G30: =F30*D30*1.1 -> 433334.06
A31: Mão de obra | B31: 35 | C31: R$ / m² | D31: =D23+D24+D22+D26+D27 -> 31515.205 | E31: m² | F31: 35 | G31: =F31*D31*1.1 -> 1213335.4
A32: TOTAL | G32: =SUM(G22:G31) -> 11847369
A35: TOTAL ALVENARIA | G35: =G17 -> 6993312.5 | H35: =G35/DADOS_INICIAIS!F9 -> 325.1149
D38: =D15*2 -> 35556.76 | G38: =G35/1.1 -> 6357556.9 | H38: =G38/DADOS_INICIAIS!G9 -> 230.68519
A40: 1496.49
C44: 4139 | D44: =C44/#REF! -> #REF!

Sheet INSTALAÇÕES
A2: INSTALAÇÕES
A4: INSTALAÇÕES ELÉTRICAS
A6: Descrição | B6: Parâmetro | D6: Valor total
A7: Entrada de Energia | B7: 5.5 | C7: R$ / AC | D7: =B7*DADOS_INICIAIS!$F$9*1.1 -> 130137.19
A8: Eletrodutos e Eletrocalhas | B8: 18 | C8: R$ / AC | D8: =B8*DADOS_INICIAIS!$F$9*1.1 -> 425903.54
A9: Cabos e Fiações | B9: 30 | C9: R$ / AC | D9: =B9*DADOS_INICIAIS!$F$9*1.1 -> 709839.24
A10: Quadros e Disjuntores | B10: 15 | C10: R$ / AC | D10: =B10*DADOS_INICIAIS!$F$9*1.1 -> 354919.62
A11: Acabamentos Elétricos | B11: 12 | C11: R$ / AC | D11: =B11*DADOS_INICIAIS!$F$9*1.1 -> 283935.7
A12: Equipamentos e Iluminação | B12: 5 | C12: R$ / AC | D12: =B12*DADOS_INICIAIS!$F$9*1.1 -> 118306.54
A13: Grupo de geradores | B13: 1 | C13: 185000 | D13: =B13*C13 -> 185000
A14: Subestação | B14: 1 | C14: 310000 | D14: =B14*C14 -> 310000
A15: Infra de carro elétrico | B15: =DADOS_INICIAIS!F21 -> 60 | C15: 547 | D15: =B15*C15*1.1 -> 36102
A16: Equipamento d ecarro eletrico | B16: 0 | C16: 10500 | D16: =B16*C16*1.1 -> 0
A17: Mão de Obra para Instalações Elétricas | B17: 65 | C17: R$ / AC | D17: =B17*DADOS_INICIAIS!$F$9*1.1 -> 1537985
A18: TOTAL | D18: =SUM(D7:D17) -> 4092128.9
A20: INSTALAÇÕES HIDROSSANITÁRIAS
A22: Descrição | B22: Parâmetro | D22: Valor total
A23: Instalações de Água Fria | B23: 22 | C23: R$ / AC | D23: =B23*DADOS_INICIAIS!$F$9*1.1 -> 520548.78
A24: Instalações de Água Quente | B24: 20 | C24: R$ / AC | D24: =B24*DADOS_INICIAIS!$F$9*1.1 -> 473226.16
A25: Instalações de Águas Pluviais | B25: 10 | C25: R$ / AC | D25: =B25*DADOS_INICIAIS!$F$9*1.1 -> 236613.08
A26: Instalações Sanitárias | B26: 17 | C26: R$ / AC | D26: =B26*DADOS_INICIAIS!$F$9*1.1 -> 402242.24
A27: Hidrometro | B27: 1 | C27: R$ / AC | D27: =B27*DADOS_INICIAIS!$F$9*1.1 -> 23661.308
A28: Acumulador (boiler) 2500L | C28: 30000 | D28: =B28*C28*1.1 -> 0
A29: Trataamento de esgoto | C29: 110000 | D29: =B29*C29*1.1 -> 0
A30: Bombas de pressurização | B30: =2*2 -> 4 | C30: 22500 | D30: =B30*C30*1.1 -> 99000 | E30: agua fria
A31: Bombas de reclque | B31: =2 -> 2 | C31: 6800 | D31: =B31*C31*1.1 -> 14960
A32: Estação redutora de pressão | B32: 4 | C32: 5240 | D32: =B32*C32*1.1 -> 23056
A33: Mão de Obra para Instalações Hidráulicas | B33: 55 | C33: R$ / AC | D33: =B33*DADOS_INICIAIS!$F$9*1.1 -> 1301371.9
A34: TOTAL | D34: =SUM(D23:D33) -> 3094679.5
A36: LOUÇAS E METAIS
A38: Descrição | B38: Parâmetro | D38: Valor total
A39: Louças | B39: 20 | C39: R$ / AC | D39: =SUM(D40:D41) -> 400062.75
A40: Bacia | B40: =3*2*2*14+4*2*2+2*2*2+15+7 -> 214 | C40: 1683.1111 | D40: =B40*C40 -> 360185.77
A41: Cuba | B41: =15+7 -> 22 | C41: 1812.59 | D41: =B41*C41 -> 39876.98
A42: Metais | B42: 16 | C42: R$ / AC | D42: =B42*DADOS_INICIAIS!$F$9*1.1 -> 378580.93
A43: Bancadas, pias e divisórias | B43: =15+7 -> 22 | C43: 3500 | D43: =B43*C43 -> 77000 | F43: =1.3*0.55*38 -> 27.17
A44: Mão de obra | B44: 10 | C44: R$ / AC | D44: =B44*DADOS_INICIAIS!$F$9*1.1 -> 236613.08 | F44: =F43*1.5 -> 40.755 | G44: =F44*2500 -> 101887.5
A45: TOTAL | D45: =SUM(D40:D44) -> 1092256.8 | E45: =D45/DADOS_INICIAIS!$F$9 -> 50.778361
A47: INSTALAÇÕES PREVENTIVAS E GLP
A49: Descrição | B49: Parâmetro | D49: Valor total
...

Sheet SISTEMAS ESPECIAIS
A2: SISTEMAS ESPECIAIS
A4: CLIMATIZAÇÃO, EXAUSTÃO MECÂNICA E PRESSURIZAÇÃO
A6: Descrição | B6: Quantidade | C6: Preço Unitário | D6: Valor total | G6: TERREO | H6: G1 | I6: G2 | J6: LAZER | K6: TIPO DIF | L6: TIPO (X13) | M6: D INF | N6: D SUP
A7: Infraestrutura para Instalação de Ar Condicionado | B7: =SUM(G7:N7) -> 455 | C7: 1500 | D7: =B7*C7*1.1 -> 750750 | G7: =3+3 -> 6 | H7: 0 | I7: 0 | J7: =7+7+1+2 -> 17 | K7: =7*2*2 -> 28 | L7: =K7*13 -> 364 | M7: =6*2*2 -> 24 | N7: =4*2*2 -> 16
A8: Instalação de Ar Condicionado split | B8: =SUM(G8:N8) -> 4 | C8: 3000 | D8: =B8*C8*1.1 -> 13200 | G8: 3 | H8: 0 | I8: 0 | J8: 1 | K8: 0 | L8: =K8*13 -> 0 | M8: 0 | N8: 0
A9: Instalação de Ar Condicionado cassete | B9: =SUM(G9:N9) -> 16 | C9: 14400 | D9: =B9*C9*1.1 -> 253440 | G9: 0 | H9: 0 | I9: 0 | J9: =14+2 -> 16 | K9: 0 | L9: =K9*13 -> 0 | M9: 0 | N9: 0
A10: Ventokit | B10: =SUM(G10:N10) -> 10 | C10: 900 | D10: =B10*C10*1.1 -> 9900 | G10: 10 | H10: 0 | I10: 0 | J10: 0 | K10: 0 | L10: =K10*13 -> 0 | M10: 0 | N10: 0
A11: VAE? | B11: =SUM(G11:N11) -> 44 | C11: 2500 | D11: =B11*C11*1.1 -> 121000 | G11: 4 | H11: 0 | I11: 0 | J11: 8 | K11: =1*2 -> 2 | L11: =K11*13 -> 26 | M11: =1*2 -> 2 | N11: =1*2 -> 2
A12: Exaustão garagem | B12: =SUM(G12:N12) -> 45 | C12: 2300 | D12: =B12*C12*1.1 -> 113850 | G12: =4+7 -> 11 | H12: 17 | I12: 17 | J12: 0 | K12: 0 | L12: =K12*13 -> 0 | M12: 0 | N12: 0
A13: Coifa | B13: =SUM(G13:N13) -> 60 | C13: 950 | D13: =B13*C13*1.1 -> 62700 | G13: 0 | H13: 0 | I13: 0 | J13: 0 | K13: =2*2 -> 4 | L13: =K13*13 -> 52 | M13: 0 | N13: =2*2 -> 4
A14: Churrasqueiras | B14: =SUM(G14:N14) -> 62 | C14: 4200 | D14: =B14*C14*1.1 -> 286440 | G14: 0 | H14: 0 | I14: 0 | J14: =1+1 -> 2 | K14: =2*2 -> 4 | L14: =K14*13 -> 52 | M14: 0 | N14: =2*2 -> 4
A15: TOTAL | D15: =SUM(D7:D14) -> 1611280 | G15: 9mil btu | J15: 30mil btu
J16: 1 DE 9mil btu
A17: COMUNICAÇÃO
A19: Descrição | B19: Parâmetro | D19: Valor total
A20: CFTV | B20: 4 | C20: R$ / AC | D20: =B20*DADOS_INICIAIS!$F$9*1.1 -> 94645.232
A21: Interfone | B21: 3 | C21: R$ / AC | D21: =B21*DADOS_INICIAIS!$F$9*1.1 -> 70983.924
A22: TV e internet | B22: 5 | C22: R$ / AC | D22: =B22*DADOS_INICIAIS!$F$9*1.1 -> 118306.54
A23: Automação, telecomunicação e sistemas de segurança | B23: 10 | C23: R$ / AC | D23: =B23*DADOS_INICIAIS!$F$9*1.1 -> 236613.08
A24: TOTAL | D24: =SUM(D20:D23) -> 520548.78
A26: EQUIPAMENTOS
A28: Descrição | B28: Quantidade | C28: Preço Unitário | D28: Valor total
A29: Elevadores sociais | B29: 4 | C29: =326782.5*1.2 -> 392139 | D29: =B29*C29*1.1 -> 1725411.6 | E29: 25 PARADAS
A30: Elevadores | B30: 2 | C30: 326782.5 | D30: =B30*C30*1.1 -> 718921.5 | E30: 25 PARADAS
A31: Equipamentos para Sauna | B31: 2 | C31: 8500 | D31: =B31*C31*1.1 -> 18700
A32: Equipamentos para Espelho dagua | B32: 0 | C32: 25000 | D32: =B32*C32*1.1 -> 0
A33: Equipamentos para Chafariz | B33: 0 | C33: 12000 | D33: =B33*C33*1.1 -> 0
A34: Hidromassagem | B34: 2 | C34: 24980 | D34: =B34*C34*1.1 -> 54956
A35: Pontos de hidro provativa | B35: =2*2*2 -> 8 | C35: 150
A36: Aquciemento de piso | B36: =(AMBIENTES!J85+AMBIENTES!J88+AMBIENTES!J103+AMBIENTES!J105+AMBIENTES!J115+AMBIENTES!J124+AMBIENTES!J135+AMBIENTES!J144+AMBIENTES!J153+AMBIENTES!J161+AMBIENTES!J173+AMBIENTES!J185)*0.8 -> 649.608 | C36: 280 | D36: =B36*C36*1.1 -> 200079.26
A37: Equipamentos para Piscina privativa | B37: =2*2 -> 4 | C37: =25000+2*C35 -> 25300 | D37: =B37*C37*1.1 -> 111320
A38: Pontos de hidro | B38: =10+6 -> 16 | C38: 150 | D38: =B38*C38*1.1 -> 2640
A39: Equipamentos para Piscina | B39: 5 | C39: =36831.3 -> 36831.3 | D39: =B39*C39*1.1 -> 202572.15
A40: TOTAL | D40: =SUM(D29:D39) -> 3034600.5
A42: OUTROS SISTEMAS ESPECIAIS
A44: Descrição | B44: Parâmetro | D44: Valor total
A45: Outros sistemas | B45: 30 | C45: R$ / AC
A46: TOTAL | D46: =SUM(D45:D45) -> 0
A48: TOTAL SISTEMAS ESPECIAIS | D48: =D15+D24+D40+D46 -> 5166429.3 | E48: =D48/DADOS_INICIAIS!F9 -> 240.1842

Sheet IMPERMEABILIZAÇÃO
A3: IMPERMEABILIZAÇÃO
A4: Data | B4: 45780
A5: Arquivo base | B5: -
A7: ALVENARIA
A9: Descrição | B9: Parâmetro | D9: Quantidade | F9: Preço unitário | G9: Valor total | H9: Observação
A10: Regularização de Superfície | B10: 25 | C10: R$ / m² | D10: =D14+D15 -> 9952.204 | E10: m² | F10: 22 | G10: =F10*D10*1.1 -> 240843.34
A11: Poço do elevador | B11: 45 | C11: R$ / m² | D11: =(((4.14)+(2.05+2.1)*2*1.8)*3)*2 -> 114.48 | E11: m² | F11: 41 | G11: =F11*D11*1.1 -> 5163.048
A12: Baldrames | B12: 30 | C12: R$ / m² | D12: ='INFRAESTRUTURA '!D28 -> 2090.59 | E12: m² | F12: 35 | G12: =F12*D12*1.1 -> 80487.715
A13: Ralos | B13: 0.4 | C13: R$ / AC | D13: 1 | E13: vb | F13: =B13*DADOS_INICIAIS!F9 -> 8604.112 | G13: =F13*D13*1.1 -> 9464.5232
A14: Impermeabilizações cimenticias | B14: 0.35 | C14: m² / AC | D14: =B14*DADOS_INICIAIS!F9 -> 7528.598 | E14: m² | F14: 60 | G14: =F14*D14 -> 451715.88
A15: Impermeabilizações com manta asfaltica | B15: 0.1 | C15: m² / AC | D15: =DADOS_INICIAIS!F36-DADOS_INICIAIS!F30+AMBIENTES!F106+AMBIENTES!F117+AMBIENTES!F137+AMBIENTES!F146+AMBIENTES!J184+AMBIENTES!J186+AMBIENTES!J187+AMBIENTES!J188+AMBIENTES!J197+AMBIENTES!J198 -> 2423.606 | E15: m² | F15: 150 | G15: =F15*D15*1.1 -> 399894.99
A16: Impermeabilização de peitoril | B16: 0.6 | C16: R$ / AC | D16: 1 | E16: vb | F16: =B16*DADOS_INICIAIS!F9 -> 12906.168 | G16: =F16*D16*1.1 -> 14196.785
A17: Proteção Mecânica | B17: 28 | C17: R$ / m² | D17: =D15 -> 2423.606 | E17: m² | F17: 28 | G17: =F17*D17*1.1 -> 74647.065
A18: TOTAL | G18: =SUM(G10:G17) -> 1276413.3 | K18: =4160+1440+1120+2880+4800+91680+4000 -> 110080 | L18: =K18/21 -> 5241.9048
A20: TOTAL IMPERMEABILIZAÇÃO | G20: =G18 -> 1276413.3 | H20: =G20/DADOS_INICIAIS!F9 -> 59.33969
H23: =H20/1.1 -> 53.945173

Sheet AMBIENTES
A1: Obra
A2: Empresa
A3: Revisão
A4: Data
A5: LEVANTAMENTO QUANTITATIVO
A7: REVESTIMENTOS E ACABAMENTOS DE PISO
B9: LEVANTAMENTO DE PROJETO | L9: CONTRAPISO
B10: Pavimento | C10: Local | D10: Piso | E10: Teto | F10: Área (m²) | G10: Contrapiso (Sim/Não) | H10: Isolamento | I10: Repetição | J10: Total | L10: Revestimento | M10: Área total
B11: TÉRREO | C11: Acesso social torre 1 | D11: Porcelanato AC | E11: Estuccamento fachada | F11: 21.91 | G11: Sim | H11: - | I11: 1 | J11: =F11*I11 -> 21.91 | L11: Contrapiso | M11: =SUMIF(G:G,"Sim",J:J) -> 12434.35
B12: TÉRREO | C12: Rampa de pedestre torre 1 | D12: Porcelanato AC | E12: Estuccamento fachada | F12: 9.33 | G12: Sim | H12: - | I12: 1 | J12: =F12*I12 -> 9.33 | L12: Manta acústica | M12: =SUMIF(H:H,"Sim",J:J) -> 6407.3
B13: TÉRREO | C13: Acesso serviço torre 1 | D13: Porcelanato AC | E13: Estuccamento fachada | F13: =4.09+3*1.25*0.18 -> 4.765 | G13: Sim | H13: - | I13: 1 | J13: =F13*I13 -> 4.765
B14: TÉRREO | C14: Antecamara 1 | D14: Porcelanato | E14: Estuccamento | F14: 6.3 | G14: Sim | H14: - | I14: 1 | J14: =F14*I14 -> 6.3 | L14: PISO
B15: TÉRREO | C15: Escada 1 | D15: Porcelanato | E15: Reboco | F15: =17.3+20*1.25*0.175 -> 21.675 | G15: Sim | H15: - | I15: 1 | J15: =F15*I15 -> 21.675 | L15: Material | M15: Área total
B16: TÉRREO | C16: Cicrulação serv | D16: Porcelanato | E16: Gesso | F16: 13.82 | G16: Sim | H16: - | I16: 1 | J16: =F16*I16 -> 13.82 | L16: Porcelanato AC | M16: =SUMIF(D:D,L16,J:J) -> 1810.7604
A17: =IF(C16="*&APTO&*","OK","") | B17: TÉRREO | C17: Ciruculação social | D17: Porcelanato AC | E17: Gesso | F17: 23.64 | G17: Sim | H17: - | I17: 1 | J17: =F17*I17 -> 23.64 | L17: Porcelanato | M17: =SUMIF(D:D,L17,J:J) -> 2081.78
B18: TÉRREO | C18: Hal social | D18: Porcelanato AC | E18: Gesso | F18: 42.17 | G18: Sim | H18: - | I18: 1 | J18: =F18*I18 -> 42.17 | L18: Cimentado | M18: =SUMIF(D:D,L18,J:J) -> 36.93
B19: TÉRREO | C19: Gurarita | D19: Porcelanato | E19: Gesso | F19: 6.67 | G19: Sim | H19: - | I19: 1 | J19: =F19*I19 -> 6.67 | L19: Ladrilho hidraulico | M19: =SUMIF(D:D,L19,J:J) -> 193.2353
B20: TÉRREO | C20: Lavabo guarita | D20: Porcelanato | E20: Gesso | F20: 2.16 | G20: Sim | H20: - | I20: 1 | J20: =F20*I20 -> 2.16 | L20: Polido | M20: =SUMIF(D:D,L20,J:J) -> 5830.06
B21: TÉRREO | C21: Circ banheiros | D21: Porcelanato AC | E21: Gesso | F21: 3.68 | G21: Sim | H21: - | I21: 1 | J21: =F21*I21 -> 3.68 | L21: Vinilico | M21: =SUMIF(D:D,L21,J:J) -> 3468.56
B22: TÉRREO | C22: WC e lavabo | D22: Porcelanato AC | E22: Gesso | F22: =3.6+2.57 -> 6.17 | G22: Sim | H22: - | I22: 1 | J22: =F22*I22 -> 6.17 | L22: Patilha | M22: =SUMIF(D:D,L22,J:J) -> 289.548
B23: TÉRREO | C23: Circ deposito | D23: Porcelanato | E23: Gesso | F23: 42.56 | G23: Sim | H23: - | I23: 1 | J23: =F23*I23 -> 42.56 | L23: Madeira | M23: =SUMIF(D:D,L23,J:J) -> 14.64
B24: TÉRREO | C24: Sala funcionarios | D24: Porcelanato | E24: Gesso | F24: 10.1 | G24: Sim | H24: - | I24: 1 | J24: =F24*I24 -> 10.1 | L24: Emborrachado | M24: =SUMIF(D:D,L24,J:J) -> 390.49
B25: TÉRREO | C25: BWC funcionarios | D25: Porcelanato | E25: Gesso | F25: 3.51 | G25: Sim | H25: - | I25: 1 | J25: =F25*I25 -> 3.51 | L25: - | M25: =SUMIF(D:D,L25,J:J) -> 811.4
B26: TÉRREO | C26: Depositos | D26: Porcelanato | E26: Estuccamento | F26: =9.58+14.69 -> 24.27 | G26: Sim | H26: - | I26: 1 | J26: =F26*I26 -> 24.27 | L26: Porcelanato AP | M26: =SUMIF(D:D,L26,J:J) -> 3692.774
B27: TÉRREO | C27: Lixeira | D27: Porcelanato | E27: Estuccamento | F27: 19.62 | G27: Sim | H27: - | I27: 1 | J27: =F27*I27 -> 19.62 | L27: Pastilha | M27: =SUMIF(D:D,L27,J:J) -> 137.952
B28: TÉRREO | C28: Gerador | D28: Porcelanato | E28: Estuccamento | F28: 24.69 | G28: Sim | H28: - | I28: 1 | J28: =F28*I28 -> 24.69 | M28: =SUMIF(D:D,L28,J:J) -> 0
B29: TÉRREO | C29: Trafo | D29: Cimentado | E29: Estuccamento | F29: 26.85 | G29: Não | H29: - | I29: 1 | J29: =F29*I29 -> 26.85 | M29: =SUMIF(D:D,L29,J:J) -> 0
B30: TÉRREO | C30: Gás | D30: Cimentado | E30: Gesso | F30: 10.08 | G30: Não | H30: - | I30: 1 | J30: =F30*I30 -> 10.08 | L30: TETO
B31: TÉRREO | C31: Rampa veículos | D31: Ladrilho hidraulico | E31: Gesso | F31: =32.67*1.09 -> 35.6103 | G31: Sim | H31: - | I31: 1 | J31: =F31*I31 -> 35.6103 | L31: Material | M31: Área total
B32: TÉRREO | C32: Estacionamento | D32: Polido | E32: Gesso | F32: 1297.44 | G32: Não | H32: - | I32: 1 | J32: =F32*I32 -> 1297.44 | L32: Gesso | M32: =SUMIF(E:E,L32,J:J) -> 14653.235
B33: TÉRREO | C33: Rampa prox pav | D33: Ladrilho hidraulico | E33: Gesso | F33: =56.1*1.25 -> 70.125 | G33: Sim | H33: - | I33: 1 | J33: =F33*I33 -> 70.125 | L33: Estuccamento | M33: =SUMIF(E:E,L33,J:J) -> 461.67
B34: TÉRREO | C34: Sla comercial 1 | D34: Porcelanato | E34: Gesso | F34: 67.5 | G34: Sim | H34: - | I34: 1 | J34: =F34*I34 -> 67.5 | L34: - | M34: =SUMIF(E:E,L34,J:J) -> 2568.4044
B35: TÉRREO | C35: Lavabo sala 1 | D35: Porcelanato | E35: Gesso | F35: 3.42 | G35: Sim | H35: - | I35: 1 | J35: =F35*I35 -> 3.42 | L35: Estuccamento fachada | M35: =SUMIF(E:E,L35,J:J) -> 106.48
B36: TÉRREO | C36: Sala comercial 2 | D36: Porcelanato | E36: Gesso | F36: 114.86 | G36: Sim | H36: - | I36: 1 | J36: =F36*I36 -> 114.86 | L36: Madeira | M36: =SUMIF(E:E,L36,J:J) -> 14.64
B37: TÉRREO | C37: Lavabo sala 2 | D37: Porcelanato | E37: Gesso | F37: 3.6 | G37: Sim | H37: - | I37: 1 | J37: =F37*I37 -> 3.6 | L37: Reboco | M37: =SUMIF(E:E,L37,J:J) -> 953.7
B38: TÉRREO | C38: Sla comercial 3 | D38: Porcelanato | E38: Gesso | F38: 114.5 | G38: Sim | H38: - | I38: 1 | J38: =F38*I38 -> 114.5
B39: TÉRREO | C39: Lavabo sala 3 | D39: Porcelanato | E39: Gesso | F39: 3.6 | G39: Sim | H39: - | I39: 1 | J39: =F39*I39 -> 3.6
B40: TÉRREO | C40: Acesso social torre 1 | D40: Porcelanato AC | E40: Estuccamento fachada | F40: 56.43 | G40: Sim | H40: - | I40: 1 | J40: =F40*I40 -> 56.43
B41: TÉRREO | C41: Rampa de pedestre torre 1 | D41: Porcelanato AC | E41: Estuccamento fachada | F41: 9.33 | G41: Sim | H41: - | I41: 1 | J41: =F41*I41 -> 9.33
B42: TÉRREO | C42: Acesso serviço torre 1 | D42: Porcelanato AC | E42: Estuccamento fachada | F42: =4.04+3*1.25*0.18 -> 4.715 | G42: Sim | H42: - | I42: 1 | J42: =F42*I42 -> 4.715
...

Sheet Rev. Internos Piso e Parede
A2: ORÇAMENTO PARAMÉTRICO GERENCIAMENTO EXECUTIVO
A7: Cliente | B7: Amalfi
A8: Obra | B8: San Felicce
A9: Data | B9: 45397
A10: Revisão | B10: R00
A12: REVESTIMENTOS INTERNOS EM PISO E PAREDE
J13: =SUM(G15:G19) -> 2557030.7
A14: Descrição | B14: Quantidade | D14: Parâmetro | F14: Referência | G14: Valor total | J14: =G20+G21+G22 -> 1153702.8
A15: Polimento de concreto | B15: =AMBIENTES!M20 -> 5830.06 | C15: m² | D15: =(16.5+550*0.1)*1.3 -> 92.95 | E15: R$ / m² | F15: Média | G15: =D15*B15*1.1 -> 596094.48
A16: Piso alisado | B16: =AMBIENTES!M18 -> 36.93 | C16: m² | D16: 25 | E16: R$ / m² | F16: Média | G16: =D16*B16*1.1 -> 1015.575
A17: Contrapiso | B17: =AMBIENTES!M11 -> 12434.35 | C17: m² | D17: =B17/DADOS_INICIAIS!G9 -> 0.4511828 | E17: m² / AC | F17: Média | G17: =+B17*(100.41-35)*1.1 -> 894663.9
A18: Manta acústica | B18: =AMBIENTES!M12 -> 6407.3 | C18: m² | D18: =B18/DADOS_INICIAIS!G9 -> 0.23249013 | E18: m² / AC | F18: Média | G18: =+B18*25*1.1 -> 176200.75
A19: mo Contrapiso | B19: =B17 -> 12434.35 | C19: m² | D19: 35 | E19: m² / AC | F19: Média | G19: =+B19*65*1.1 -> 889056
A20: Chapisco | B20: =ALVENARIA!D10+ALVENARIA!D11*2 -> 22080.436 | C20: m² | D20: 2 | E20: m² / AC | F20: Média | G20: =+B20*5*1.1 -> 121442.4 | J20: =J14+'Acabamentos de Piso e Parede'!K34 -> 2958539.7
A21: Reboco | B21: =B20 -> 22080.436 | C21: m² | D21: 2 | E21: m² / AC | F21: Média | G21: =17*B21*1.1 -> 412904.15
A22: mo reboco | B22: =B20 -> 22080.436 | C22: m² | D22: =3.5+22 -> 25.5 | E22: R$ | F22: Média | G22: =+B22*D22*1.1 -> 619356.22
A23: TOTAL | G23: =SUM(G15:G22) -> 3710733.5
A26: TOTAL REVESTIMENTOS | G26: =G23 -> 3710733.5 | H26: =G26/DADOS_INICIAIS!F9 -> 172.50977
H28: =H26/1.1 -> 156.82706
B29: =B20+'Rev. Fachada'!B15 -> 35556.76
B36: =B20-'Acabamentos de Piso e Parede'!K40 -> 15769.14
B37: =ALVENARIA!D13*2 -> 38718.504

Sheet TETO
A3: REVESTIMENTOS E ACABAMENTOS DE TETO
A4: Data | B4: 45457
A5: Arquivo base | B5: -
A7: ALVENARIA
A9: Descrição | B9: Parâmetro | D9: Quantidade | F9: Preço unitário | G9: Valor total | H9: Observação
A10: Forro acartonado | B10: 0.8 | C10: m² / AC | D10: =AMBIENTES!M32-D11 -> 14546.635 | E10: m² | F10: 115 | G10: =F10*D10*1.1 -> 1840149.4
A11: Forro com isolamento | B11: 0.8 | C11: m² / AC | D11: =AMBIENTES!J73 -> 106.6 | E11: m² | F11: =120+20 -> 140 | G11: =F11*D11*1.1 -> 16416.4
A12: Negativo | B12: 1.2 | C12: m / FORRO | D12: =D10*B12 -> 17455.962 | E12: m² | F12: 22 | G12: =F12*D12*1.1 -> 422434.29
A13: Molduras | B13: 1.2 | C13: m / FORRO | D13: =SUMIFS(AMBIENTES!J11:J198,AMBIENTES!B11:B198,AMBIENTES!$B$95,AMBIENTES!E11:E198,AMBIENTES!$E$85)*B13 -> 1084.512 | E13: m | F13: =35*1.2 -> 42 | G13: =F13*D13*1.1 -> 50104.454
A14: Forro madeira | C14: m² / AC | D14: 7.32 | E14: m² | F14: 579 | G14: =F14*D14*1.1 -> 4662.108
A15: Porcelanato | C15: m² / AC | D15: 7.32 | E15: m² | F15: 1000 | G15: =F15*D15*1.1 -> 8052
A16: mo Porcelanato teto | C16: m² / AC | D16: =D15 -> 7.32 | E16: m² | F16: 110 | G16: =F16*D16*1.1 -> 885.72
A17: Estucamento | B17: 0.1 | C17: m² / AC | D17: =AMBIENTES!M33 -> 461.67 | E17: m² | F17: 4 | G17: =F17*D17*1.1 -> 2031.348
A18: MO Estucamento | B18: 0.1 | C18: m² / AC | D18: =D17 -> 461.67 | E18: m² | F18: 24 | G18: =F18*D18*1.1 -> 12188.088
A19: Chapisco e reboco | C19: m² / AC | D19: =AMBIENTES!M35+AMBIENTES!M37+D15 -> 1067.5 | E19: m² | F19: =7.5+28 -> 35.5 | G19: =F19*D19*1.05*1.1 -> 43770.169
A20: MO Chapisco e reboco | C20: m² / AC | D20: =D19 -> 1067.5 | E20: m² | F20: 34 | G20: =F20*D20*1.05*1.1 -> 41920.725
A21: TOTAL | G21: =SUM(G10:G20) -> 2442614.7 | K21: =4160+1440+1120+2880+4800+91680+4000 -> 110080 | L21: =K21/21 -> 5241.9048
A23: TOTAL IMPERMEABILIZAÇÃO | G23: =G21 -> 2442614.7 | H23: =G23/DADOS_INICIAIS!F9 -> 113.55569
H26: =H23/1.1 -> 103.23244

Sheet Acabamentos de Piso e Parede
A2: ORÇAMENTO PARAMÉTRICO GERENCIAMENTO EXECUTIVO
A7: Cliente | B7: Amalfi
A8: Obra | B8: San Felicce
A9: Data | B9: 45397
A10: Revisão | B10: R00
A12: ACABAMENTOS EM PISO E PAREDE
A14: Descrição | B14: Quantidade | D14: Parâmetro | F14: Referência | G14: Valor total
A15: Porcelanato | B15: =AMBIENTES!M17 -> 2081.78 | C15: m² | D15: 126.05 | E15: R$ | F15: Média | G15: =+D15*B15*1.1 -> 288649.21
A16: Porcelanato ap | B16: =AMBIENTES!M26 -> 3692.774 | C16: m² | D16: 142.38 | E16: R$ | F16: Média | G16: =+D16*B16*1.1 -> 578354.88
A17: Porcelanato ac | B17: =AMBIENTES!M16 -> 1810.7604 | C17: m² | D17: 142.38 | E17: R$ | F17: Média | G17: =+D17*B17*1.1 -> 283597.67
A18: Piso vinilico - mat e mo | B18: =AMBIENTES!M21 -> 3468.56 | C18: m² | D18: 377 | E18: R$ | F18: Média | G18: =+D18*B18*1.1 -> 1438411.8
A19: Mármore | C19: m² | D19: 1856 | E19: R$ | F19: Média | G19: =+D19*B19*1.1 -> 0
A20: Piso elevadores | B20: =4.14*3*2 -> 24.84 | C20: m² | D20: 1856 | E20: R$ | F20: Média | G20: =+D20*B20*1.1 -> 50713.344
A21: Carpete- mat e mo | C21: m² | D21: 298 | E21: R$ | F21: Média | G21: =+D21*B21*1.1 -> 0
A22: Piscina | B22: =AMBIENTES!M22+AMBIENTES!M27 -> 427.5 | C22: m² | D22: 149.82 | E22: R$ | F22: Média | G22: =+D22*B22*1.1 -> 70452.855
A23: Madeira - mat e mo | B23: =AMBIENTES!M23 -> 14.64 | C23: m² | D23: 437.8 | E23: R$ | F23: Média | G23: =+D23*B23*1.1 -> 7050.3312
A24: Emborrachado - mat e mo | B24: =AMBIENTES!M24 -> 390.49 | C24: m² | D24: 230 | E24: R$ | F24: Média | G24: =+D24*B24*1.1 -> 98793.97
A25: Ladrilho hidaraulico | B25: =AMBIENTES!M19 -> 193.2353 | C25: m² | D25: 180 | E25: R$ | F25: Média | G25: =+D25*B25*1.1 -> 38260.589
A26: mo pedra | B26: =B20 -> 24.84 | C26: m² | D26: 42 | E26: R$ | F26: Média | G26: =+D26*B26*1.1 -> 1147.608
A27: mo porcelanato | B27: =B15+B17+B16 -> 7585.3144 | C27: m² | D27: 42 | E27: R$ | F27: Média | G27: =+D27*B27*1.1 -> 350441.53
A28: mo pastilha | B28: =B22 -> 427.5 | C28: m² | D28: 48 | E28: R$ | F28: Média | G28: =+D28*B28*1.1 -> 22572
A29: Rodapés porcelanato | B29: =(B15+B17+B16)*1.2 -> 9102.3773 | C29: m | D29: 19.92 | E29: R$ | F29: Média | G29: =+D29*B29*1.1 -> 199451.29 | I29: =K35+'Rev. Internos Piso e Parede'!J13 -> 7331642.3
A30: Rodapés poliestireno | B30: =(B23+B18)*1.2 -> 4179.84 | C30: m | D30: 93.23 | E30: R$ | F30: Média | G30: =+D30*B30*1.1 -> 428655.13
A31: Mo rodape | B31: =B29+B30 -> 13282.217 | C31: m | D31: 22 | E31: R$ | F31: Média | G31: =+D31*B31*1.1 -> 321429.66
A32: Soleiras | B32: =ESQUADRIAS!D26*0.8+ESQUADRIAS!D12*1.6*0.5 -> 4930.8236 | C32: m | D32: =110-D33 -> 98 | E32: R$ | F32: Média | G32: =+D32*B32*1.1 -> 531542.79
A33: mo Soleiras | B33: =B32 -> 4930.8236 | C33: m | D33: 12 | E33: R$ | F33: Média | G33: =+D33*B33*1.1 -> 65086.872
A34: peitoris | B34: =ESQUADRIAS!D12*1.5*0.5 -> 4042.8971 | C34: m | D34: =65-D35 -> 53 | E34: R$ | F34: Média | G34: =+D34*B34*1.1 -> 235700.9 | J34: ACAB PAREDE | K34: =SUM(G34:G36) -> 1804836.9
A35: mo peitoris | B35: =B34 -> 4042.8971 | C35: m | D35: 12 | E35: R$ | F35: Média | G35: =+D35*B35*1.1 -> 53366.242 | J35: ACAB PISO | K35: =G37-K34 -> 4774611.5
A36: Revestimentos de Parede | B36: 1 | C36: vb | D36: 50 | E36: R$ / AC | F36: Média | G36: =D36*DADOS_INICIAIS!$G$9*1.1*B36 -> 1515769.8
A37: =20*40 -> 800 | G37: =SUM(G15:G36) -> 6579448.4
A40: TOTAL ACABAMENTOS | G40: =G37 -> 6579448.4 | H40: =G40/DADOS_INICIAIS!F9 -> 305.87461 | J40: =32.24*3.2*2*2*14 -> 5777.408 | K40: =J40+J41+J42 -> 6311.296 | L40: =K40*'[4]Acabamentos de Piso e Parede'!$D$36 -> 1325372.2
J41: =(7.98+8.1+9.3)*3.2*2*2 -> 324.864
H42: =H40/1.1 -> 278.06782 | J42: =(7.98+8.35)*3.2*2*2 -> 209.024
A43: PORCELANATO | B43: 2612.64
A44: CERAMICA | B44: 29.99
A45: CARPETE | B45: 181.54
A46: PISO ALISADO | B46: 6243.04
A47: VINILICO | B47: 4526.15
A48: PISO RANHURADO | B48: 280.79
A49: PAVER | B49: 134.39
...

Sheet ESQUADRIAS
A3: ESQUADRIAS
A4: Data | B4: 45460
A5: Arquivo base | B5: -
A7: ESQUADRIAS
B8: =D12/DADOS_INICIAIS!F9 -> 0.25060248
A9: Descrição | B9: Parâmetro | D9: Quantidade | F9: Preço unitário | G9: Valor total | H9: Observação
A10: Contramarco | D10: =(D12+D13+D14)*1.2 -> 7096.8054 | E10: m | F10: =66.02-F11 -> 44.02 | G10: =F10*D10*1.1 -> 343641.51 | H10: =G10/DADOS_INICIAIS!G7 -> #VALUE! | I10: =(G10+G11+G12)/D12 -> 1884.713
A11: mo Contramarco | D11: =D10 -> 7096.8054 | E11: m | F11: 22 | G11: =F11*D11*1.1 -> 171742.69 | H11: =G11/DADOS_INICIAIS!G8 -> 28.391117
A12: Esquadrias de PVC | B12: 0.15 | C12: m² / AC | D12: =ALVENARIA!D10*0.4 -> 5390.5295 | E12: m² | F12: =3252.91593471596/2 -> 1626.458 | G12: =F12*D12*1.1 -> 9644216.7 | H12: =G12/DADOS_INICIAIS!G9 -> 349.94228 | J12: =G10+G11+G12+G13+G14+G16+G17+G18+G19+G25 -> 14557684
A13: Esquadrias de PVC arredondadas | D13: =3.05*8.7*6+3.05*5.5*(9+6) -> 410.835 | E13: m² | F13: 3252.9159 | G13: =F13*D13*1.1 -> 1470052.9 | H13: =G13/DADOS_INICIAIS!G10 -> 364.96667 | J13: =G20+G21+G22 -> 401688.8
A14: Pele de vidro | D14: =(10.26+2.84+13.84+8.26)*3.2 -> 112.64 | E14: m² | F14: 1100 | G14: =F14*D14*1.1 -> 136294.4 | H14: =G14/DADOS_INICIAIS!G11 -> 33.949768
A15: Brise de madeira | E15: m² | F15: 1500 | G15: =F15*D15*1.1 -> 0
A16: Portão de alumínio | D16: 1 | E16: un | F16: 18000 | G16: =F16*D16*1.1 -> 19800
A17: Guarda-corpo - vidro | D17: =DADOS_INICIAIS!F37 -> 223.43 | E17: m | F17: =950*1.1 -> 1045 | G17: =F17*D17*1.1 -> 256832.79 | H17: Lazer
A18: Gradil | D18: =25.97*2*(13+1+1)+62.76*2 -> 904.62 | E18: m | F18: =3053.33333333333*0.8 -> 2442.6667 | G18: =F18*D18*1.1 -> 2430653.6
A19: Corrimão inox | D19: =3*2*2+13.52*1.1*2*2+(1.33*2+2+1.4*2+1.74*2)*1.2+(1.7+1.25*1.2)*6 -> 103.816 | E19: m | F19: 150 | G19: =F19*D19*1.1 -> 17129.64
A20: Corrimão escada de emergencia (metalico) | D20: =(2.585+1.25*2+2.24*4*1.2)*2*DADOS_INICIAIS!F26 -> 728.502 | E20: m | F20: 120 | G20: =F20*D20*1.1 -> 96162.264
A21: Serralherias | B21: 5 | C21: R$ / AC | D21: 1 | E21: vb | F21: =B21*DADOS_INICIAIS!F9 -> 107551.4 | G21: =F21*D21*1.1 -> 118306.54
A22: PCF | D22: =2*2*DADOS_INICIAIS!F26 -> 92 | E22: un | F22: 1850 | G22: =F22*D22*1.1 -> 187220
A23: Corrimão metálico | E23: m | F23: 120 | G23: =F23*D23*1.1 -> 0
A24: Fechadura biométrica | D24: =DADOS_INICIAIS!F21 -> 60 | E24: un | F24: 1445.1706 | G24: =F24*D24*1.1 -> 95381.257
A25: Portas aluminio | D25: =1*2*2*14+1*1*1+10+5 -> 72 | E25: un | F25: 850 | G25: =F25*D25*1.1 -> 67320
A26: Esquadrias de Madeira | D26: =12*2*2*14+8*2*2+5*2*2+22+27 -> 773 | E26: un | F26: 2300 | G26: =F26*D26*1.1 -> 1955690
A27: MO portas | D27: =D26 -> 773 | E27: un | F27: 140 | G27: =F27*D27*1.1 -> 119042
A28: TOTAL | G28: =SUM(G10:G27) -> 17129486 | K28: =4160+1440+1120+2880+4800+91680+4000 -> 110080 | L28: =K28/21 -> 5241.9048
A30: TOTAL ESQUADRIAS | G30: =G28 -> 17129486 | H30: =G30/DADOS_INICIAIS!F9 -> 796.33953
C32: PELE DE VIDO | D32: area | E32: BRISE
B33: TERREO -2 | C33: =57.14*2+22.5 -> 136.78 | D33: =C33*6.22 -> 850.7716
B34: TERREO -1 | D34: =16.97+94.95+752.7875+96.26+75.8068 -> 1036.7743 | E34: =146.42*2 -> 292.84
B35: SOBRELOJS -2 | C35: =29.94*2 -> 59.88 | D35: =C35*7.14 -> 427.5432
B36: SOBRELOJS -1 | D36: =495.794+2.54+58.36 -> 556.694 | E36: =129.2*2 -> 258.4
D37: =SUM(D33:D36) -> 2871.7831 | E37: =SUM(E33:E36) -> 551.24

Sheet PINTURA INTERNA
A3: PINTURA INTERNA
A4: Data | B4: 45457
A5: Arquivo base | B5: -
A7: ALVENARIA
L8: 70543.726
A9: Descrição | B9: Parâmetro | D9: Quantidade | F9: Preço unitário | G9: Valor total | H9: Observação | L9: =L8/D10 -> 121
A10: Pintura piso epoxi | B10: 25 | C10: R$ / m² | D10: ='Rev. Internos Piso e Parede'!B15*0.1 -> 583.006 | E10: m² | F10: 110 | G10: =F10*D10*1.1 -> 70543.726 | H10: Apenas pintura de faixas | I10: =G10/D10 -> 121 | L10: =L9+'Rev. Internos Piso e Parede'!D15 -> 213.95
A11: Pintura acrílica antiderrapante | B11: 45 | C11: R$ / m² | E11: m² | F11: 65 | G11: =F11*D11*1.1 -> 0
A12: Textura escadas | B12: 15 | C12: R$ / AC | D12: =ALVENARIA!D11*2 -> 8604.112 | E12: m² | F12: =1.2+6.87 -> 8.07 | G12: =F12*D12*1.1 -> 76378.702
A13: mo Textura escadas | B13: 50 | C13: R$ / AC | D13: =D12 -> 8604.112 | E13: m² | F13: 20 | G13: =F13*D13*1.1 -> 189290.46
A14: Textura teto | B14: 15 | C14: R$ / AC | D14: =TETO!D17+TETO!D19 -> 1529.17 | E14: m² | F14: =1.2+6.87 -> 8.07 | G14: =F14*D14*1.1 -> 13574.442
A15: mo Textura teto | B15: 50 | C15: R$ / AC | D15: =D14 -> 1529.17 | E15: m² | F15: =22 -> 22 | G15: =F15*D15*1.1 -> 37005.914
A16: Pintura Interna paredes | B16: 15 | C16: R$ / AC | D16: ='Rev. Internos Piso e Parede'!B20+ALVENARIA!D13*2-'Acabamentos de Piso e Parede'!K40 -> 54487.644 | E16: m² | F16: =1.2+3.2+6.74 -> 11.14 | G16: =F16*D16*1.1 -> 667691.59
A17: MOPintura Interna paredes | B17: 50 | C17: R$ / AC | D17: =D16 -> 54487.644 | E17: m² | F17: =32 -> 32 | G17: =F17*D17*1.1 -> 1917965.1
A18: Pintura Interna teto | B18: 15 | C18: R$ / AC | D18: =TETO!D10+TETO!D11 -> 14653.235 | E18: m² | F18: =1.2+3.2+6.74 -> 11.14 | G18: =F18*D18*1.1 -> 179560.75
A19: mo Pintura Interna teto | B19: 50 | C19: R$ / AC | D19: =D18 -> 14653.235 | E19: m² | F19: =34 -> 34 | G19: =F19*D19*1.1 -> 548031
A20: TOTAL | G20: =SUM(G10:G19) -> 3700041.6 | K20: =4160+1440+1120+2880+4800+91680+4000 -> 110080 | L20: =K20/21 -> 5241.9048
A22: TOTAL IMPERMEABILIZAÇÃO | G22: =G20 -> 3700041.6 | H22: =G22/DADOS_INICIAIS!F9 -> 172.01271
H24: =H22/1.1 -> 156.37519

Sheet COBERTURA
A2: COBERTURA
A3: Data | B3: 45460
A4: Arquivo base | B4: -
A6: TELHADO
A8: Descrição | B8: Parâmetro | D8: Quantidade | F8: Preço unitário | G8: Valor total | H8: Observação
A9: Estrutura metálica cobertura | D9: =DADOS_INICIAIS!F30-118.37 -> 620.53 | E9: m² | F9: =52*4.2*0.6 -> 131.04 | G9: =F9*D9*1.1 -> 89445.676 | H9: Composição de telhado ceramico (30%=16,7º) multiplicado por 3,35 para ter 56º de inclinação | J9: =56/16.7 -> 3.3532934
A10: Telhamento Shingle | D10: =D9*(1+3.35) -> 2699.3055 | E10: m² | F10: =197.99 -> 197.99 | G10: =F10*D10*1.1 -> 587879.05 | H10: Area inclinada | J10: =70/16.7 -> 4.1916168
A11: Serviços complementares | D11: =D9 -> 620.53 | E11: m² | F11: 90 | G11: =F11*D11*1.1 -> 61432.47
A12: Mo ocbertura | D12: =D11 -> 620.53 | E12: m² | F12: =G12/D12 -> 643.851 | G12: =(F10/0.6)*0.4*D10+52*3.35*0.4*D9 -> 399528.86
A13: Pergolados metalicos | E13: m² | F13: 350 | G13: =F13*D13*1.1 -> 0 | J13: =300 -> 300
A14: Pergolados madeira | E14: m² | F14: 280 | G14: =F14*D14*1.1 -> 0
A15: Passarelas | G15: =F15*D15*1.1 -> 0
A16: Estrutura metálica cobertura | E16: m2 | F16: 800 | G16: =F16*D16*1.1 -> 0
A17: Moldura ACM metálica | E17: m | F17: 52.5 | G17: =F17*D17*1.1 -> 0
A18: TOTAL | G18: =SUM(G9:G17) -> 1138286.1
A20: TOTAL COMPLEMENTARES | G20: =G18 -> 1138286.1 | H20: =G20/DADOS_INICIAIS!F9 -> 52.918235

Sheet Rev. Fachada
A2: ORÇAMENTO PARAMÉTRICO GERENCIAMENTO EXECUTIVO
A7: Cliente | B7: Passe
A8: Obra | B8: Connect
A9: Data | B9: 45460
A10: Revisão | B10: R00
A12: REVESTIMENTOS ARGAMASSADOS
A14: Descrição | B14: Quantidade | D14: Parâmetro | F14: Referência | G14: Valor total
A15: Chapisco | B15: =ALVENARIA!D10 -> 13476.324 | C15: m² | D15: 7.5 | E15: R$ / m² | F15: - | G15: =B15*D15*1.1 -> 111179.67 | L15: =12.96*6.28-5.32*5.9 -> 50.0008 | M15: =L15*2 -> 100.0016
A16: Reboco | B16: =B15 -> 13476.324 | C16: m² | D16: 17 | E16: R$ / m² | F16: - | G16: =B16*D16*1.1 -> 252007.26 | L16: =(6.15+32.9+2.2+1.8)*3.52 -> 151.536 | M16: =L16 -> 151.536
A17: Mão de obra | B17: =B15 -> 13476.324 | C17: m² | D17: 65 | E17: R$ / m² | F17: - | G17: =B17*D17*1.1 -> 963557.15
A18: Chapisco e reboco molduras (pilares e paredes) | B18: =(K18+K19+K20+K21)*2+M15+M16 -> 1847.1016 | C18: m² | D18: =(D15+D16)*1.4 -> 34.3 | E18: R$ / m² | F18: - | G18: =B18*D18*1.1 -> 69691.143 | I18: =0.7+0.7 -> 1.4 | J18: =I18*2*2 -> 5.6 | K18: =J18*47.26 -> 264.656
A19: mo Chapisco e reboco molduras (pilares e paredes) | B19: =B18 -> 1847.1016 | C19: m² | D19: =D17*2 -> 130 | E19: R$ / m² | F19: - | G19: =B19*D19*1.1 -> 264135.53 | I19: =0.7+1.1 -> 1.8 | J19: =I19*2 -> 3.6 | K19: =J19*47.26 -> 170.136
A20: Tratamento de frisos | B20: =DADOS_INICIAIS!F31*16+DADOS_INICIAIS!F37*4 -> 4138.52 | C20: m | D20: 5 | E20: R$ / m² | G20: =B20*D20*1.1 -> 22761.86 | I20: =0.8+2 -> 2.8 | J20: =I20*2 -> 5.6 | K20: =J20*58 -> 324.8
A21: TOTAL | G21: =SUM(G15:G20) -> 1683332.6 | I21: =0.8*2+9.8 -> 11.4 | J21: =I21*3.35 -> 38.19 | K21: =J21 -> 38.19
A23: PINTURA | J23: EMBASAMENTO | K23: =31.7+39.98 -> 71.68 | L23: 10
A25: Descrição | B25: Quantidade | D25: Parâmetro | F25: Referência | G25: Valor total
A26: Textura | B26: =B15 -> 13476.324 | C26: m² | D26: 25 | E26: R$ / m² | F26: - | G26: =B26*D26*1.1 -> 370598.9
A27: Pintura pilares e paredes | B27: =B18 -> 1847.1016 | C27: m² | D27: =8*1.2 -> 9.6 | E27: R$ / m² | F27: - | G27: =B27*D27*1.1 -> 19505.393
A28: Pintura molduras | B28: =SUM(I37:I58) -> 2013.9954 | C28: m² | D28: =8*1.5 -> 12 | E28: R$ / m² | F28: - | G28: =B28*D28*1.1 -> 26584.739
A29: Mão de obra textura | B29: =B26 -> 13476.324 | C29: m² | D29: 52 | E29: R$ / m² | F29: - | G29: =B29*D29*1.1 -> 770845.72
A30: Mão de obra pintura molduras | B30: =B28 -> 2013.9954 | C30: m² | D30: =40*5 -> 200 | E30: R$ / m² | F30: - | G30: =B30*D30*1.1 -> 443078.99
A31: Mão de obra pintura pilares e paredes | B31: =B27 -> 1847.1016 | C31: m² | D31: =40*2 -> 80 | E31: R$ / m² | F31: - | G31: =B31*D31*1.1 -> 162544.94
A32: TOTAL | G32: =SUM(G26:G31) -> 1793158.7
A34: ACABAMENTOS ESPECIAIS
A36: Descrição | B36: Quantidade | D36: Parâmetro | F36: Referência | G36: Valor total
A37: Janelas curvas | B37: =9+6+4*2 -> 23 | C37: m | D37: 45 | E37: R$ | F37: - | G37: =B37*D37*1.1 -> 1138.5 | H37: =B37*0.16 -> 3.68 | I37: =H37*1.5 -> 5.52
A38: Beiral | B38: =DADOS_INICIAIS!F37*3+(2.6+2.11+5.4+1.65+1.55+7.75+75.62+2.05+4.82+2*0.7+9.8+1.05+(9.91+1.18+2.1)*3+4.8*2+21.36)+(((5.4+1.64)*2+(2*1.15+2.9)*2+(2*2.5+13.15))*14+((2*2.5+13.15)+(5.4+1.64)*2)+((3.92+11.12+0.9)*2+17.57+2*1.97)+(16.44*2+9.15*2+2.6*4)+(3.15+9.8+1.04+0.8+5.56)*2*3)*2 -> 2588.86 | C38: m | D38: 38 | E38: R$ | F38: - | G38: =B38*D38*1.1 -> 108214.35 | H38: =B38*0.5 -> 1294.43 | I38: =H38*1.5 -> 1941.645
A39: Detalhes unitarios | B39: 2 | C39: un | D39: =1080*2 -> 2160 | E39: R$ | F39: - | G39: =B39*D39*1.1 -> 4752
A40: Sinetes | B40: 9 | C40: un | D40: 85 | E40: R$ | F40: - | G40: =B40*D40*1.1 -> 841.5 | H40: =B40*0.42*0.42 -> 1.5876 | I40: =H40*4 -> 6.3504
A41: Revestimento pilar | B41: =5.6*B42 -> 33.6 | C41: m | D41: 52 | E41: R$ | G41: =B41*D41*1.1 -> 1921.92 | H41: =B41*0.6*2 -> 40.32 | I41: =H41*1.5 -> 60.48
A42: Base pilar | B42: =3*2 -> 6 | C42: un | D42: 90 | E42: R$ | G42: =B42*D42*1.1 -> 594
A43: mo Detalhes e molduras | B43: 1 | C43: vb | D43: =0.4*(SUM(G37:G42)) -> 46984.907 | E43: R$ | F43: - | G43: =B43*D43*1.1 -> 51683.398
A44: Detalhe portão | B44: 2 | C44: un | D44: =B45*210 -> 5212.2 | E44: R$ | F44: - | G44: =D44*1.1 -> 5733.42 | H44: peça que imita marmore
A45: mo Detalhe portão | B45: =B44*7.3*1.7 -> 24.82 | C45: m² | D45: 65 | E45: R$ | F45: - | G45: =B45*D45*1.1 -> 1774.63 | H45: peça que imita marmore
G46: =SUM(G37:G45) -> 176653.72
J47: =25.78*2 -> 51.56
A49: TOTAL FACHADA | G49: =G32+G21+G46 -> 3653145 | H49: =G49/DADOS_INICIAIS!F9 -> 169.83252
H50: =H49/1.1 -> 154.3932

Sheet COMPLEMENTARES
A2: COMPLEMENTARES
A3: Data | B3: 45460
A4: Arquivo base | B4: -
A6: SERVIÇOS COMPLEMENTARES
A8: Descrição | B8: Parâmetro | D8: Quantidade | F8: Valor total
A9: Calçadas e Passeios | B9: 180 | C9: R$ / m2 | D9: =143.17*2.1 -> 300.657 | E9: m² | F9: =D9*B9*1.1 -> 59530.086
A10: Móveis e decoração | B10: 1800 | C10: R$ / AL | D10: =DADOS_INICIAIS!F32 -> 2513.4 | E10: m² | F10: =D10*B10*1.1 -> 4976532
A11: Comunicação visual | B11: 10 | C11: R$ / AC | D11: =B11*DADOS_INICIAIS!$F$9 -> 215102.8 | E11: R$ | F11: =D11*1.1 -> 236613.08
A12: Paisagismo | B12: 12 | C12: R$ / AC | D12: =B12*DADOS_INICIAIS!$F$9 -> 258123.36 | E12: R$ | F12: =D12*1.1 -> 283935.7
A13: Irrigação, iluminação e mobiliário externo | B13: 15 | C13: R$ / AC | D13: =B13*DADOS_INICIAIS!$F$9 -> 322654.2 | E13: R$ | F13: =D13*1.1 -> 354919.62
A14: Playground | B14: =(172734.56/111.47)*0.6 -> 929.76349 | C14: R$ / m2 | D14: 310.97 | E14: m2 | F14: =D14*B14*1.1 -> 318041.41
A15: Pet place | B15: =(172734.56/111.47)*0.8*0.6 -> 743.81079 | C15: R$ / m2 | D15: 79.52 | E15: m2 | F15: =D15*B15*1.1 -> 65062.617
A16: Quadra poliesportiva | B16: 550 | C16: R$ / m² | D16: =9.4*4.8 -> 45.12 | E16: m2 | F16: =D16*B16*1.1 -> 27297.6
A17: Ligações definitivas | B17: 4 | C17: R$ / AC | D17: =B17*DADOS_INICIAIS!$F$9 -> 86041.12 | E17: R$ | F17: =D17*1.1 -> 94645.232
A18: Desmobilização | B18: 3.5 | C18: R$ / AC | D18: =B18*DADOS_INICIAIS!$F$9 -> 75285.98 | E18: R$ | F18: =D18*1.1 -> 82814.578
A19: Limpeza | B19: 20 | C19: R$ / AC | D19: =B19*DADOS_INICIAIS!$F$9 -> 430205.6 | E19: R$ | F19: =D19*1.1 -> 473226.16
A20: TOTAL | F20: =SUM(F9:F19) -> 6972618.1
A22: TOTAL COMPLEMENTARES | F22: =F20 -> 6972618.1 | G22: =F22/DADOS_INICIAIS!F9 -> 324.15283

Sheet Auxiliar
A2: 2 Portões acesso garagem - Área: 9,2m² x 2 = 18,4m² | B2: 2 | C2: portão | D2: 18.4
A3: 2 portas corta-fogo 1 folha | B3: 2 | C3: pcf
A4: 1 porta de correr alumínio 2 folhas – Área: 3,465m² | B4: 1 | C4: porta alumínio | D4: 3.465
A5: 1 porta de correr alumínio 2 folhas – Área: 1,7325m² | B5: 1 | C5: porta alumínio | D5: 1.7325 | G5: Guarda alumínio | H5: =SUMIF(C:C,G5,D:D) -> 400.5221
A6: 2 portas de abrir alumínio 2 folhas – Área: 2,6376m² x 2 = 5,2752m² | B6: 2 | C6: porta alumínio | D6: 5.2752 | G6: janela | H6: =SUMIF(C:C,G6,D:D) -> 1895.06
A7: 1 porta de abrir alumínio 2 folhas – Área: 4,1916m² | B7: 1 | C7: porta alumínio | D7: 4.1916 | G7: madeira | H7: =SUMIF(C:C,G7,B:B) -> 218
A8: 1 porta pivotante | B8: 1 | C8: pivotante | G8: pcf | H8: =SUMIF(C:C,G8,B:B) -> 60
A9: 19 portas de abrir madeira 1 folha | B9: 19 | C9: madeira | G9: pivotante | H9: =SUMIF(C:C,G9,B:B) -> 1
A10: 3 portas de abrir vidro 1 folha – Área: 2,1m² x 3 = 6,3m² | B10: 3 | C10: porta alumínio | D10: 6.3 | G10: porta alumínio | H10: =SUMIF(C:C,G10,D:D) -> 46.62
A11: 2 portas de abrir vidro 1 folha – Área: 1,89m² x 2 = 3,78m² | B11: 2 | C11: porta alumínio | D11: 3.78 | G11: portão | H11: =SUMIF(C:C,G11,B:B) -> 2
A12: 1 porta de abrir alumínio 1 folha – Área: 2,0076m² | B12: 1 | C12: porta alumínio | D12: 2.0076 | G12: gradil | H12: =SUMIF(C:C,G12,D:D) -> 113.88
A13: Janelas – Área: 3,75 + 4,875 + 2,5 + 1,1 + 1,2 + 5,5402 + 4,4874 = 23,4526m² | C13: janela | D13: 23.4526 | G13: Brise | H13: 109.3146
A14: Muro de vidro – Área: 7,0774 + 5,485 + 3,43 + 4,8138 = 20,8062m² | C14: Guarda alumínio | D14: 20.8062
A15: 8 portas corta-fogo 1 folha | B15: 8 | C15: pcf
A16: Janelas – Area: (1,1 + 1,2 + 28,7391) x 4 = 124,1564m² | C16: janela | D16: 124.1564
A17: 2 portas corta-fogo 1 folha | B17: 2 | C17: pcf
A18: 2 portas de abrir alumínio 1 folha – Área: 1,47m² x 2 = 2,94m² | B18: 2 | C18: porta alumínio | D18: 2.94
A19: 2 portas de abrir vidro 1 folha – Área: 1,89m² x 2 = 3,78m² | B19: 2 | C19: porta alumínio | D19: 3.78
A20: 5 portas de abrir madeira 1 folha | B20: 5 | C20: madeira
A21: 1 janela-porta de correr vidro – Área: 14,7348m² | B21: 1 | C21: janela | D21: 14.7348
A22: Janelas – Área: 1,2894 + 1,2894 + 23,46 + 1,854 + 5,562 + 5,562 + 1,854 + 1,854 + 1,1 + 1,2 = 45,0248m² | C22: janela | D22: 45.0248
A23: Guarda corpo vidro – Área: 7,5299 + 5,7955 + 6,5555 = 19,8809m² | C23: Guarda alumínio | D23: 19.8809
A24: 38 portas corta-fogo 1 folha | B24: 38 | C24: pcf
A25: 171 portas de abrir madeira 1 folha | B25: 171 | C25: madeira
A26: 19 porta de abrir alumínio 1 folha – Área: 1,26m² x 19 = 23,94m² | B26: 19 | C26: porta alumínio | D26: 23.94
A27: 19 janela-porta de correr vidro 5 folhas - Área: 25,4205m² x 19 = 482,9895m² | B27: 19 | C27: janela | D27: 482.9895
A28: 19 janela-porta de correr vidro 5 folhas - Área: 17,8284m² x 19 = 338,7396m² | B28: 19 | C28: janela | D28: 338.7396
A29: Janelas – Área: 1,1 + 1,1 + 1,2 + 1,92 + 0,36 + 2,781 + 2,781 + 1,854 + 1,854 + 5,562 + 5,562 + 1,854 = 27,928m² x 19 = 530,632m² | C29: janela | D29: 530.632
A30: Guarda corpo metálico – Área: 4,745m² x 19 = 90,155m² - Perímetro: 3,65m x 19 = 69,35m | C30: gradil | D30: 90.155
