Workbook
Name \0: #REF!
Name \0: #REF!
Name \0: #REF!
Name \0: #REF!
Name \0: #REF!
Name \0: #REF!
Name \0: #REF!
Name \1: #REF!
Name \a: #REF!
Name \a: #REF!
Name \b: #REF!
Name \c: #REF!
Name \d: #REF!
Name \e: #REF!
Name \i: #REF!
Name \J: #REF!
Name \k: #REF!
Name \l: #N/A
Name \m: #REF!
Name \m: #REF!
Name \o: #REF!
Name \p: #REF!
Name \r: #REF!
Name \T: #REF!
Name \z: #REF!
Name ______ACR10: #REF!
Name ______ACR15: #REF!
Name ______acr20: #REF!
Name ______acr5: #REF!
Name ______ARQ1: #REF!
Name ______QT100: #REF!
Name ______QT2: #REF!
Name ______QT3: #REF!
Name ______QT4: #REF!
Name ______QT50: #REF!
Name ______QT75: #REF!
Name _____ACR10: #REF!
Name _____ACR15: #REF!
Name _____acr20: #REF!
Name _____acr5: #REF!
Name _____ARQ1: #REF!
Name _____QT100: #REF!
Name _____QT2: #REF!
Name _____QT3: #REF!
Name _____QT4: #REF!
Name _____QT50: #REF!
Name _____QT75: #REF!
Name ___ACR10: #REF!
Name ___ACR15: #REF!
Name ___acr20: #REF!
Name ___acr5: #REF!
Name ___ARQ1: #REF!
Name ___QT100: #REF!
Name ___QT2: #REF!
Name ___QT3: #REF!
Name ___QT4: #REF!
Name ___QT50: #REF!
Name ___QT75: #REF!
Name __ACR10: #REF!
Name __ACR15: #REF!

Sheet DADOS_INICIAIS
A1: Obra | B1: Hotel e Residencial Colline
A2: Empresa | B2: Colline - Miguel Pereira
A3: Revisão | B3: R00
A4: Arquitetura base | B4: PLANTA SITUAÇÃO HOTEL COLLINE e PLANTA SITUACAO RESIDENCIAL COLLINE
A5: DADOS OBRA
B7: Descrição | C7: Identificador | D7: Unidade | E7: Hotel | F7: Residencial | G7: Quantidade Total
B8: ÁREA DO TERRENO | C8: AT | D8: M2 | G8: 6049.17
B9: ÁREA TOTAL CONSTRUÍDA | C9: AC | D9: M2 | E9: =SUM(E10:E20) -> 6049.17 | F9: =SUM(F10:F20) -> 21510.28 | G9: =SUM(G10:G20) -> 27559.45
B10: SUBSOLO / TERREO | D10: M2 | E10: 1662.34 | F10: 2365.57 | G10: =F10+E10 -> 4027.91
B11: TÉRREO/ GARAGEM 1 | D11: M2 | E11: =1147.74+527.82 -> 1675.56 | F11: 2339.03 | G11: =F11+E11 -> 4014.59
B12: 1º PAVIMENTO / GARAGEM 2 | D12: M2 | E12: =812.7+31.66 -> 844.36 | F12: 2514.32 | G12: =F12+E12 -> 3358.68
B13: 2º PAVIMENTO / LAZER | D13: M2 | E13: =900.46+243.83 -> 1144.29 | F13: 2513.4 | G13: =F13+E13 -> 3657.69
B14: SUBTELHADO / 5º PAV. DIFERENCIADO TORRE I E II (X1) | D14: M2 | E14: =691.7+30.92 -> 722.62 | F14: 699.84 | G14: =F14+E14 -> 1422.46
B15: 6º AO 18º PAV. DIFERENCIADO TORRE I E II (X13) | D15: M2 | F15: 9097.92 | G15: =F15+E15 -> 9097.92
B16: DUPLEX INFERIOR TORRE I E II | D16: M2 | F16: 699.84 | G16: =F16+E16 -> 699.84
B17: DUPLEX SUPERIOR TORRE I E II | D17: M2 | F17: 693.56 | G17: =F17+E17 -> 693.56
B18: INSPEÇÃO TORRE I E II | D18: M2 | F18: 303.24 | G18: =F18+E18 -> 303.24
B19: CASA DE MÁQUINAS TORRE I E II | D19: M2 | F19: 150.18 | G19: =F19+E19 -> 150.18
B20: CAIXA D'AGUA TORRE I E II | D20: M2 | F20: 133.38 | G20: =F20+E20 -> 133.38
B21: UNIDADES RESIDENCIAIS | C21: UR | D21: UN | E21: 36 | F21: 60 | G21: =F21+E21 -> 96 | H21: =G9-G33-G32 -> 17817.3
B22: Dormitórios | C22: dorm | D22: UN | E22: =E21 -> 36 | G22: =F22+E22 -> 36
B23: Banheiros | C23: ban | D23: UN | G23: =F23+E23 -> 0
B24: UNIDADES COMERCIAIS | C24: UC | D24: UN | G24: =F24+E24 -> 0
B25: Churrasqueiras | C25: CHU | D25: UN | F25: 60 | G25: =F25+E25 -> 60
B26: NÚMERO TOTAL DE PAVIMENTOS | C26: NP | D26: UN | E26: 5 | F26: 23 | G26: =F26+E26 -> 28
B27: NÚMERO DE PAVIMENTOS TIPO | C27: NPT | D27: UN | E27: 0 | F27: 13 | G27: =F27+E27 -> 13
B28: NÚMERO DE PAVIMENTOS TIPO DIFERENCIADOS | C28: NPD | D28: UN | E28: 3 | F28: 1 | G28: =F28+E28 -> 4
B29: NÚMERO DE PAVIMENTOS DUPLEX | C29: ND | D29: UN | E29: 0 | F29: 1 | G29: =F29+E29 -> 1
B30: ÁREA DE PROJEÇÃO DA TORRE | C30: APT | D30: M2 | E30: 1021.82 | F30: =369.45*2 -> 738.9 | G30: =F30+E30 -> 1760.72
B31: PERÍMETRO DE PROJEÇÃO DA TORRE | C31: PPT | D31: M | E31: 151.474 | F31: =101.4*2 -> 202.8 | G31: =F31+E31 -> 354.274
B32: ÁREA DE LAZER | C32: AL | D32: M2 | E32: 0 | F32: =F14 -> 699.84 | G32: =F32+E32 -> 699.84
B33: ÁREA DO EMBASAMENTO | C33: AE | D33: M2 | E33: =E11 -> 1675.56 | F33: =F11+F12+F13 -> 7366.75 | G33: =F33+E33 -> 9042.31
B34: ÁREA DE SUBSOLOS | C34: S | D34: M2 | E34: =E10 -> 1662.34 | F34: 0 | G34: =F34+E34 -> 1662.34
B35: NÚMERO DE SUBSOLOS | C35: NS | D35: UN | E35: 1 | F35: 0 | G35: =F35+E35 -> 1
B36: ÁREA DE PROJEÇÃO DO EMBASAMENTO | C36: APE | D36: M2 | E36: 2087.28 | F36: 2365.57 | G36: =F36+E36 -> 4452.85 | H36: =G36/G9 -> 0.16157253
B37: PERÍMETRO DE PROJEÇÃO DE EMBAMENTO | C37: PE | D37: M | E37: 226.19 | F37: 223.43 | G37: =F37+E37 -> 449.62
B38: NÚMERO DE PAVIMENTOS DE EMBASAMENTO | C38: NE | D38: UN | E38: 1 | F38: 3 | G38: =F38+E38 -> 4

Sheet MOVIMENTAÇÃO_DE_TERRA
A2: MOVIMENTAÇÃO DE TERRA
A3: Data | B3: 45756
A4: Arquivo base | B4: -
A6: ESCAVAÇÃO VERTICAL DE SUBSOLO
A8: Descrição | B8: Área de subsolo (m) | C8: Altura do subsolo (m) | D8: Volume total de escavação (m3) | E8: Preço unitário de escavação (R$ / m3) | F8: Valor total | G8: Observação
A9: Escavação | E9: 0 | F9: =E9*D9*1.1 -> 0
A10: Aterro | D10: =5.22*2*15*1.3 -> 203.58 | E10: =9.09 -> 9.09 | F10: =E10*D10*1.1 -> 2035.5964 | G10: "subsolo" na verdade aterrado na frente do terreno para rampas
A11: TOTAL | F11: =SUM(F9:F10) -> 2035.5964
A13: REBAIXAMENTO DE LENÇOL FREÁTICO
A15: Descrição | B15: Quantidade (dias) | E15: Preço unitário de rebaixamento (R$ / dias) | F15: Valor total | G15: Observação
A16: Rebaixamento de lençol | B16: 0 | E16: 200 | F16: =B16*E16*1.1 -> 0
A17: TOTAL | F17: =SUM(F16:F16) -> 0
A19: ESCAVAÇÃO E REATERRO DE VALAS
A21: Descrição | B21: Parâmetro | D21: Volume total de escavação (m3) | E21: Preço unitário (R$ / m3) | F21: Valor total | G21: Observação
A22: Escavação mecanizada para blocos e baldrames | B22: 1.3 | C22: m³ / Vol infra | D22: =B22*INFRAESTRUTURA!D29 -> 810.693 | E22: 36.36 | F22: =E22*D22*1.1 -> 32424.477
A23: Reaterro para blocos e baldrames | B23: 0.6 | C23: m³ / Vol Escavação | D23: =D22-INFRAESTRUTURA!D29 -> 187.083 | E23: 14.55 | F23: =E23*D23*1.1 -> 2994.2634
A24: Movimentação de bota-fora | B24: 1.3 | D24: =(D22-D23-D10)*B24 -> 546.039 | E24: 45.45 | F24: =E24*D24*1.1 -> 27299.22
A25: Movimentação de terra das estacas | B25: 1 | C25: m³ | D25: =INFRAESTRUTURA!D19 -> 0 | E25: 20 | F25: =E25*D25*1.1 -> 0
A26: TOTAL | F26: =SUM(F22:F25) -> 62717.96
A28: REGULARIZAÇÃO E APILOAMENTO DE FUNDO DE VALAS
A30: Descrição | B30: Parâmetro | D30: Área de lastro (m²) | E30: Preço unitário (R$ / m2) | F30: Valor total | G30: Observação
A31: Lastro de concreto magto e=5cm | B31: 0.8 | C31: m² / APE | D31: =B31*DADOS_INICIAIS!G36 -> 3562.28 | E31: =370*0.05 -> 18.5 | F31: =E31*D31*1.1 -> 72492.398 | H31: =F31/DADOS_INICIAIS!G36 -> 16.28
A32: TOTAL | F32: =SUM(F31:F31) -> 72492.398
A34: TOTAL MOVIMENTAÇÃO DE TERRA | F34: =F11+F17+F26+F32 -> 137245.95 | G34: =F34/DADOS_INICIAIS!E9 -> 22.688394

Sheet CONTENÇÕES
A3: CONTENÇÃO
A4: Data
A5: Arquivo base
A7: CORTINA DE ESTACAS
A9: Descrição | B9: Parâmetro | D9: Quantidade | F9: Preço unitário | G9: Valor total
A10: Número de Estacas | B10: 0.15 | C10: un / APE | D10: =B10*DADOS_INICIAIS!G36 -> 667.9275 | E10: un
A11: Estaca Hélice Continua Diâmetro 40 | B11: 0.1 | D11: =B11*$D$10 -> 66.79275 | E11: un
B12: 20 | C12: m/un | D12: =B12*D11 -> 1335.855 | E12: m | G12: =F12*D12 -> 0
A13: Estaca Hélice Continua Diâmetro 50 | B13: 0.5 | D13: =B13*$D$10 -> 333.96375 | E13: un
B14: 20 | C14: m/un | D14: =B14*D13 -> 6679.275 | E14: m | G14: =F14*D14 -> 0
A15: Estaca Hélice Continua Diâmetro 60 | B15: 0.4 | C15: un / APE | D15: =B15*$D$10 -> 267.171 | E15: un
B16: 20 | C16: m/un | D16: =B16*D15 -> 5343.42 | E16: m | G16: =F16*D16 -> 0
A17: Concreto | B17: =(PI()*0.4^2)/4*D14+(PI()*0.5^2)/4*D16+(PI()*0.6^2)/4*D12 -> 2266.2246 | C17: un / APE | D17: =(PI()*0.4^2)/4*D14+(PI()*0.5^2)/4*D16+(PI()*0.6^2)/4*D12 -> 2266.2246 | E17: m³ | G17: =F17*D17 -> 0
A18: Armação 6,3mm | B18: 1.6575131 | C18: kg / m³ | D18: =B18*D17 -> 3756.297 | E18: kg | G18: =F18*D18 -> 0
A19: Armação 16mm | B19: 10.178338 | C19: kg / m³ | D19: =B19*D17 -> 23066.399 | E19: kg | G19: =F19*D19 -> 0
A20: Mobilização | B20: 1 | C20: vb | D20: 1 | E20: vb | G20: =F20*D20 -> 0
A21: TOTAL | G21: =SUM(G10:G20) -> 0
A23: PAREDE DE CONCRETO
A25: Descrição | B25: Parâmetro | D25: Quantidade | F25: Preço unitário | G25: Valor total
A26: Fabricação, montagem e desmontagem de forma para blocos e baldrames resinado | B26: 2.1 | C26: m² / APE | D26: =B26*DADOS_INICIAIS!G36 -> 9350.985 | E26: m² | G26: =F26*D26 -> 0
A27: Concreto | B27: 0.65 | C27: m³ / APE | D27: =B27*DADOS_INICIAIS!G36 -> 2894.3525 | E27: m³ | G27: =F27*D27 -> 0
A28: Armação | B28: 110 | C28: kg / m³ | D28: =B28*D27 -> 318378.78 | E28: kg | G28: =F28*D28 -> 0
A29: Mão de obra | B29: =SUPRAESTRUTURA!B15*1.5 -> 315 | C29: R$ / APE | D29: =DADOS_INICIAIS!G36 -> 4452.85 | E29: m² | F29: =B29 -> 315 | G29: =F29*D29 -> 1402647.8
A30: TOTAL | G30: =SUM(G26:G29) -> 1402647.8
A33: PAREDE DIAFRAGMA
A35: Descrição | B35: Parâmetro | D35: Quantidade | F35: Preço unitário | G35: Valor total
A36: Fabricação, montagem e desmontagem de forma para blocos e baldrames resinado | B36: 2.1 | C36: m² / APE | D36: =B36*DADOS_INICIAIS!G46 -> 0 | E36: m² | G36: =F36*D36 -> 0
A37: Concreto | B37: 0.65 | C37: m³ / APE | D37: =B37*DADOS_INICIAIS!G46 -> 0 | E37: m³ | G37: =F37*D37 -> 0
A38: Armação | B38: 110 | C38: kg / m³ | D38: =B38*D37 -> 0 | E38: kg | G38: =F38*D38 -> 0
A39: Mão de obra | B39: =SUPRAESTRUTURA!B74*1.5 -> 918.39196 | C39: R$ / APE | D39: =DADOS_INICIAIS!G46 -> 0 | E39: m² | F39: =B39 -> 918.39196 | G39: =F39*D39 -> 0
A40: TOTAL | G40: =SUM(G36:G39) -> 0
A46: TOTAL INFRAESTRUTURA | G46: =G21+G30 -> 1402647.8 | H46: =G46/DADOS_INICIAIS!G9 -> 50.895346

Sheet INFRAESTRUTURA (2)
A3: INFRAESTRUTURA
A4: Data | B4: 45756
A5: Arquivo base | B5: RMP-FUN-EX-0002-TABELAS-R02
A7: FUNDAÇÃO PROFUNDA
F8: 158.15
A9: Descrição | B9: Parâmetro | D9: Quantidade | F9: Preço unitário | G9: Valor total | H9: Observação
A10: Número de Estacas | B10: =D10/DADOS_INICIAIS!E36 -> 0.13079223 | C10: un / APE | D10: =D11+D13 -> 273 | E10: un | H10: Quantitativos trazidos de preliminar de fundação
A11: Estaca Pre-moldada cravada 30X30 | B11: =D11/D10 -> 0.84615385 | D11: 231 | E11: un
B12: =D12/D11 -> 12.311688 | C12: m/un | D12: 2844 | E12: m | F12: =F8*1.3 -> 205.595 | G12: =F12*D12*1.1 -> 643183.4
A13: Estaca Pre-moldada cravada 20X20 | B13: =D13/D12 -> 0.014767932 | D13: 42 | E13: un
B14: =D14/D13 -> 12.428571 | C14: m/un | D14: 522 | E14: m | F14: 158.15 | G14: =F14*D14*1.1 -> 90809.73
A15: Concreto (25 Mpa) | B15: 1.1 | C15: perda | E15: m³ | F15: =510+44 -> 554 | G15: =F15*D15*B15*1.1 -> 0
A16: Armação | C16: kg / m³ | E16: kg | F16: 7.62 | G16: =F16*D16*1.1 -> 0
A17: Mobilização | B17: 1 | C17: vb | D17: 1 | E17: vb | F17: 14500 | G17: =F17*D17*1.1 -> 15950
A18: Apoio e arrasamento de estacas | E18: un | F18: 300 | G18: =F18*D18*1 -> 0
A19: TOTAL | G19: =SUM(G10:G18) -> 749943.13
G20: =G19/(D12+D14) -> 222.7995
A21: FUNDAÇÃO RASA
A23: Descrição | B23: Parâmetro | D23: Quantidade | F23: Preço unitário | G23: Valor total | H23: Observação
A24: Fabricação, montagem e desmontagem de forma para blocos e baldrames resinado | B24: =D24/DADOS_INICIAIS!E36 -> 1.021449 | C24: m² / APE | D24: =371.23+345.11+222.65+40.45+1152.61 -> 2132.05 | E24: m² | F24: 68 | G24: =F24*D24*1.1 -> 159477.34
A25: Concreto (40 Mpa) | B25: =D25/DADOS_INICIAIS!E36 -> 0.29876682 | C25: m³ / APE | D25: =150.8+26.52+19.92+299.54+8.28+118.55 -> 623.61 | E25: m³ | F25: =514+44 -> 558 | G25: =F25*D25*1.05*1.1 -> 401910.41
A26: Armação | B26: 60 | C26: kg / m³ | D26: =B26*D25 -> 37416.6 | E26: kg | F26: 7.62 | G26: =F26*D26*1.1 -> 313625.94
A27: Mão de obra | B27: =SUPRAESTRUTURA!B15*1.5 -> 315 | C27: R$ / APE | D27: =DADOS_INICIAIS!E10 -> 1662.34 | E27: m² | F27: =B27 -> 315 | G27: =F27*D27*1.1 -> 576000.81
A28: TOTAL | G28: =SUM(G24:G27) -> 1451014.5
A31: TOTAL INFRAESTRUTURA | G31: =G28+G19 -> 2200957.6 | H31: =G31/DADOS_INICIAIS!E9 -> 363.84457

Sheet INFRAESTRUTURA
A3: INFRAESTRUTURA
A4: Data | B4: 45756
A5: Arquivo base | B5: RMP-FUN-EX-0002-TABELAS-R02
A7: FUNDAÇÃO PROFUNDA
A9: Descrição | B9: Parâmetro | D9: Quantidade | F9: Preço unitário | G9: Valor total | H9: Observação
A10: Número de Estacas | B10: =D10/DADOS_INICIAIS!E36 -> 0.17151508 | C10: un / APE | D10: =D11+D13+D15+D17 -> 358 | E10: un | H10: Quantitativos trazidos de preliminar de fundação
A11: Estaca Pre-moldada cravada 20X20 | B11: =D11/D10 -> 0.12569832 | D11: 45 | E11: un
B12: 15 | C12: m/un | D12: =B12*D11 -> 675 | E12: m | F12: 158.15 | G12: =F12*D12*1.1 -> 117426.38
A13: Estaca Pre-moldada cravada 30X30 | B13: =D13/D10 -> 0.29888268 | D13: 107 | E13: un
B14: 15 | C14: m/un | D14: =B14*D13 -> 1605 | E14: m | F14: =F12*1.3 -> 205.595 | G14: =F14*D14*1.1 -> 362977.97
A15: Estaca Pre-moldada centrifugada 50cm | B15: =D15/D12 -> 0.28444444 | D15: =206-D17 -> 192 | E15: un
B16: 15 | C16: m/un | D16: =B16*D15 -> 2880 | E16: m | F16: =356.72*1.15 -> 410.228 | G16: =F16*D16*1.1 -> 1299602.3
A17: Estaca Pre-moldada centrifugada 42cm | B17: =D17/D14 -> 0.0087227414 | D17: =14 -> 14 | E17: un
B18: 8 | C18: m/un | D18: =B18*D17 -> 112 | E18: m | F18: =356.72*1.15 -> 410.228 | G18: =F18*D18*1.1 -> 50540.09
A19: Concreto (25 Mpa) | B19: 1.1 | C19: perda | E19: m³ | F19: =510+44 -> 554 | G19: =F19*D19*B19*1.1 -> 0
A20: Armação | C20: kg / m³ | E20: kg | F20: 7.62 | G20: =F20*D20*1.1 -> 0
A21: Mobilização | B21: 1 | C21: vb | D21: 1 | E21: vb | F21: 14500 | G21: =F21*D21*1.1 -> 15950
A22: Apoio e arrasamento de estacas | E22: un | F22: 300 | G22: =F22*D22*1 -> 0
A23: TOTAL | G23: =SUM(G10:G22) -> 1846496.7
G24: =G23/(D12+D14+D16+D18) -> 350.24597
A25: FUNDAÇÃO RASA
A27: Descrição | B27: Parâmetro | D27: Quantidade | F27: Preço unitário | G27: Valor total | H27: Observação
A28: Fabricação, montagem e desmontagem de forma para blocos e baldrames resinado | B28: =D28/DADOS_INICIAIS!E36 -> 1.021449 | C28: m² / APE | D28: =371.23+345.11+222.65+40.45+1152.61 -> 2132.05 | E28: m² | F28: 68 | G28: =F28*D28*1.1 -> 159477.34
A29: Concreto (40 Mpa) | B29: =D29/DADOS_INICIAIS!E36 -> 0.29876682 | C29: m³ / APE | D29: =150.8+26.52+19.92+299.54+8.28+118.55 -> 623.61 | E29: m³ | F29: =514+44 -> 558 | G29: =F29*D29*1.05*1.1 -> 401910.41
A30: Armação | B30: 60 | C30: kg / m³ | D30: =B30*D29 -> 37416.6 | E30: kg | F30: 7.62 | G30: =F30*D30*1.1 -> 313625.94
A31: Mão de obra | B31: =SUPRAESTRUTURA!B15*1.5 -> 315 | C31: R$ / APE | D31: =DADOS_INICIAIS!E10 -> 1662.34 | E31: m² | F31: =B31 -> 315 | G31: =F31*D31*1.1 -> 576000.81
A32: TOTAL | G32: =SUM(G28:G31) -> 1451014.5
A35: TOTAL INFRAESTRUTURA | G35: =G32+G23 -> 3297511.2 | H35: =G35/DADOS_INICIAIS!E9 -> 545.11797

Sheet SUPRAESTRUTURA
A3: SUPRAESTRUTURA
A4: Data | B4: 45756
A5: Arquivo base | B5: -
A7: SUPRAESTRUTURA - LAJE MACIÇA
A9: Descrição | B9: Parâmetro | D9: Quantidade | F9: Preço unitário | G9: Valor total | H9: Observação
A10: Fabricação forma | B10: 2 | C10: Jogos | D10: =(D11/DADOS_INICIAIS!E26)*B10 -> 4551.524 | E10: m² | F10: 110 | G10: =F10*D10*1.1 -> 550734.4
A11: Montagem de forma | B11: 2.5 | C11: m² / AC | D11: =6.88+15.94+8.6+141.97+161.2+157.87+744.64+181.2+508.58+25.53+893.38+216.42+267.92+25.53+1072.41+245.8+431.37+112.73+823.2+350.74+487.68+325.65+57.98+2204.14+688.53+1222.92 -> 11378.81 | E11: m² | F11: 2.5 | G11: =F11*D11*1.1 -> 31291.728 | H11: Quantidade de resumo
A12: Escoramento | B12: 4 | C12: un / AE | D12: =ROUNDUP(B12*DADOS_INICIAIS!E12*B10,0) -> 6755 | E12: un | F12: =17 -> 17 | G12: =F12*D12*1.1 -> 126318.5
A13: Concreto | B13: 0.2 | C13: m³ / AC | D13: =0.63+0.93+1.24+16.42+11.16+16.66+172.03+19.64+65.34+2.55+228.39+21.45+30.21+2.55+241.94+25.64+50.84+11.27+184.98+37.51+62.06+34.91+5.8+341.53+78.12+145.22 -> 1809.02 | E13: m³ | F13: =514+44 -> 558 | G13: =F13*D13*1.05*1.1 -> 1165895.3 | H13: Quantidade de resumo
A14: Armadura Convencional para Estrutura | B14: 90 | C14: kg / m³ | D14: =D13*B14 -> 162811.8 | E14: kg | F14: 7.62 | G14: =F14*D14*1.1 -> 1364688.5
A15: Mão de obra - estrutura em concreto armado | B15: 210 | C15: R$ / AC | D15: =DADOS_INICIAIS!E9 -> 6049.17 | E15: m² | F15: 210 | G15: =F15*D15*1.1 -> 1397358.3
A16: Perfuração de vigas | B16: 1500 | C16: R$ / NP | D16: 1 | E16: vb | F16: =B16*DADOS_INICIAIS!E26 -> 7500 | G16: =F16*D16*1.1 -> 8250 | H16: Coeficiente originário do Gran Torino (R$ 160,00/un) | I16: Nova utiliza a verba de 1.500,00 por pav
A17: TOTAL | G17: =SUM(G10:G16) -> 4644536.7 | K17: =4160+1440+1120+2880+4800+91680+4000 -> 110080 | L17: =K17/21 -> 5241.9048
A19: SUPRAESTRUTURA - LAJE CUBETAS PROTENDIDAS
A21: Descrição | B21: Parâmetro | D21: Quantidade | F21: Preço unitário | G21: Valor total | H21: Observação
A22: Fabricação forma | B22: 2 | C22: Jogos | D22: =(D23/DADOS_INICIAIS!$G$26)*B22 -> 4133.9175 | E22: m² | F22: 110 | G22: =F22*D22*1.1 -> 500204.02
A23: Montagem de forma | B23: 2.1 | C23: m² / AC | D23: =B23*DADOS_INICIAIS!$G$9 -> 57874.845 | E23: m² | F23: 2.5 | G23: =F23*D23*1.1 -> 159155.82
A24: Escoramento | B24: 3 | C24: un / APT*NPT | D24: =ROUNDUP(B24*DADOS_INICIAIS!$G$36*B22,0) -> 26718 | E24: un | F24: =17 -> 17 | G24: =F24*D24*1.1 -> 499626.6
A25: Cubetas | B25: 25 | C25: R$ / AC | D25: 1 | E25: vb | F25: =B25*DADOS_INICIAIS!$G$9 -> 688986.25 | G25: =F25*D25*1.1 -> 757884.88
A26: Protensão - lajes - materiais | B26: =12.3*0.8 -> 9.84 | C26: RS / m² | D26: =(DADOS_INICIAIS!$G$27+DADOS_INICIAIS!$G$28)*DADOS_INICIAIS!$G$30+DADOS_INICIAIS!$G$33 -> 38974.55 | E26: m² | F26: =B26 -> 9.84 | G26: =F26*D26*1.1 -> 421860.53
A27: Protensão - lajes - cabos | B27: =2.83*0.8 -> 2.264 | C27: kg / m² | D27: =B27*D26 -> 88238.381 | E27: kg | F27: 12.3 | G27: =F27*D27*1.1 -> 1193865.3
A28: Protensão - lajes - serviços | B28: 9000 | C28: und / pav | D28: =DADOS_INICIAIS!G26 -> 28 | E28: pav | F28: =B28 -> 9000 | G28: =F28*D28*1.1 -> 277200
A29: Concreto | B29: 0.18 | C29: m³ / AC | D29: =B29*DADOS_INICIAIS!$G$9 -> 4960.701 | E29: m³ | F29: =535+45 -> 580 | G29: =F29*D29*1.05*1.1 -> 3323173.6
A30: Cristalizante (reservatorios) | B30: 0.2 | D30: =B30*D29 -> 992.1402 | E30: m³ | F30: =1.22*F29-F29 -> 127.6 | G30: =F30*D30*1.05*1.1 -> 146219.64
A31: Armadura Convencional para Estrutura | B31: 110 | C31: kg / m³ | D31: =D29*B31-D27 -> 457438.73 | E31: kg | F31: 7.62 | G31: =F31*D31*1.1 -> 3834251.4
A32: Mão de obra - estrutura em concreto armado | B32: 240 | C32: R$ / AC | D32: =DADOS_INICIAIS!$G$9 -> 27559.45 | E32: m² | F32: =B32 -> 240 | G32: =F32*D32*1.1 -> 7275694.8
A33: Perfuração de vigas | B33: 5300 | C33: R$ / NP | D33: 1 | E33: vb | F33: =B33*DADOS_INICIAIS!$G$26 -> 148400 | G33: =F33*D33*1.1 -> 163240 | H33: Coeficiente originário do Gran Torino (R$ 160,00/un)
A34: TOTAL | G34: =SUM(G22:G33) -> 18552377
A36: SUPRAESTRUTURA - LAJE TRELIÇADA
A38: Descrição | B38: Parâmetro | D38: Quantidade | F38: Preço unitário | G38: Valor total | H38: Observação
A39: Fabricação forma | B39: 2 | C39: Jogos | D39: =(D40/DADOS_INICIAIS!$G$26)*B39 -> 0 | E39: m² | F39: 85 | G39: =F39*D39*1.1 -> 0
A40: Montagem de forma | B40: 2.1 | C40: m² / AC | D40: =B40*DADOS_INICIAIS!G49 -> 0 | E40: m² | F40: 1.5 | G40: =F40*D40*1.1 -> 0
A41: Escoramento - Torre | B41: 2 | C41: un / APT*NPT | D41: =B41*DADOS_INICIAIS!G58*DADOS_INICIAIS!G55 -> 0 | E41: un | F41: 17 | G41: =F41*D41*1.1 -> 0
A42: Escoramento - Embasamento | B42: 2 | C42: un / AE | D42: =B42*DADOS_INICIAIS!G61 -> 0 | E42: un | F42: 17 | G42: =F42*D42*1.1 -> 0
A43: Cubetas | B43: 25 | C43: R$ / AC | D43: =B43*DADOS_INICIAIS!G49 -> 0 | E43: m³ | F43: =B43 -> 25 | G43: =F43*D43*1.1 -> 0
A44: Concreto | B44: 0.25 | C44: m³ / AC | D44: =B44*DADOS_INICIAIS!G49 -> 0 | E44: m³ | F44: =575 -> 575 | G44: =F44*D44*1.05*1.1 -> 0
A45: Armadura Convencional para Estrutura | B45: 110 | C45: kg / m³ | D45: =D44*B45 -> 0 | E45: kg | F45: 7.25 | G45: =F45*D45*1.1 -> 0
A46: Mão de obra - estrutura em concreto armado | B46: 240 | C46: R$ / AC | D46: =DADOS_INICIAIS!G49 -> 0 | E46: m² | F46: =B46 -> 240 | G46: =F46*D46*1.1 -> 0
A47: Perfuração de vigas | B47: 5300 | C47: R$ / NP | D47: 1 | E47: vb | F47: =B47*DADOS_INICIAIS!G54 -> 0 | G47: =F47*D47*1.1 -> 0 | H47: Coeficiente originário do Gran Torino (R$ 160,00/un)
A48: TOTAL | G48: =SUM(G39:G47) -> 0
...

Sheet ALVENARIA
A3: PAREDES E PAINÉIS
A4: Data | B4: 45457
A5: Arquivo base | B5: -
A7: ALVENARIA
A9: Descrição | B9: Parâmetro | D9: Quantidade | F9: Preço unitário | G9: Valor total | H9: Observação
A10: Alvenaria externo | B10: =D10/DADOS_INICIAIS!E9 -> 0.44284054 | C10: m² / AC | D10: =DADOS_INICIAIS!E31*19.65*0.9 -> 2678.8177 | E10: m² | F10: 54 | G10: =F10*D10*1.1 -> 159121.77
A11: Alvenaria escadas resistente á fogo (sical) | B11: 0.2 | C11: m² / AC | D11: =DADOS_INICIAIS!E9*ALVENARIA!B11 -> 1209.834 | E11: m² | F11: 70 | G11: =F11*D11*1.05*1.1 -> 97815.079
A12: Alvenaria refratárias | B12: 1.75 | C12: m² * CHU | D12: =B12*DADOS_INICIAIS!E25 -> 0 | E12: un | F12: 210 | G12: =F12*D12*1.1 -> 0
A13: Drywall entre quartos | B13: 0.44 | C13: m² / AC | D13: =B13*DADOS_INICIAIS!E9 -> 2661.6348 | E13: m² | F13: =Planilha1!G70 -> 486.62458 | G13: =F13*D13*1.1 -> 1424738.6 | H13: (2PERF/VID/70/PERF/70/VID/2PERF)
A14: Drywall interno | B14: 0.28 | C14: m² / AC | D14: =B14*DADOS_INICIAIS!E9 -> 1693.7676 | E14: m² | F14: 191.17 | G14: =F14*D14*1.1 -> 356177.31 | H14: 2ST/90/ST+RU
A15: Drywall paredes externas internas | B15: 0.28 | C15: m² / AC | D15: =D10 -> 2678.8177 | E15: m² | F15: =Planilha1!G30 -> 109.71219 | G15: =F15*D15*1.1 -> 323288.86 | H15: (48/VID/PERF)
A16: Drywall shafts | B16: 0.28 | C16: m² / AC | D16: =22.67*3.5*5 -> 396.725 | E16: un | F16: =Planilha1!G30 -> 109.71219 | G16: =F16*D16*1.1 -> 47878.126 | H16: (48/VID/PERF)
A17: Serviços complementares | B17: 12.5 | C17: R$ / m² | D17: =D10+D11 -> 3888.6517 | E17: m² | F17: =B17 -> 12.5 | G17: =F17*D17*1.1 -> 53468.961
A18: Elemento pre-moldado | B18: 12.5 | C18: R$ / m² | D18: =0.8*1.2*(DADOS_INICIAIS!E22+1) -> 35.52 | E18: m² | F18: 650 | G18: =F18*D18*1.1 -> 25396.8
A19: Mão de obra | B19: 35 | C19: R$ / m² | D19: =D10+D11 -> 3888.6517 | E19: m² | F19: 36 | G19: =F19*D19*1.1 -> 153990.61
A20: Mão de obra drywall | B20: 35 | C20: R$ / m² | D20: =SUM(D13:D16) -> 7430.9451 | E20: m² | F20: 40 | G20: =F20*D20*1.1 -> 326961.58
A21: TOTAL | G21: =SUM(G10:G20) -> 2968837.7 | K21: =4160+1440+1120+2880+4800+91680+4000 -> 110080 | L21: =K21/21 -> 5241.9048
A23: ALVENARIA - DRTWALL
A25: Descrição | B25: Parâmetro | D25: Quantidade | F25: Preço unitário | G25: Valor total | H25: Observação
A26: Alvenaria embasamento | B26: 1 | C26: m² / AE | D26: =B26*DADOS_INICIAIS!$G$33 -> 9042.31 | E26: m² | F26: 45 | G26: =F26*D26*1.1 -> 447594.34
A27: Alvenaria lazer | B27: 0.4 | C27: m² / AL | D27: =B27*DADOS_INICIAIS!$G$32 -> 279.936 | E27: m² | F27: 45 | G27: =F27*D27*1.1 -> 13856.832
A28: Alvenaria tipo | B28: 1.62 | C28: m² / APT*(NPT+2ND) | D28: =B28*(DADOS_INICIAIS!$G$30*(DADOS_INICIAIS!$G$27+DADOS_INICIAIS!$G$28))*0.3 -> 14547.069 | E28: un | F28: 45 | G28: =F28*D28*1.1 -> 720079.9
A29: Drywall tipo | B29: 1.65 | C29: m² / APT*(NPT+2ND) | D29: =B29*(DADOS_INICIAIS!$G$30*(DADOS_INICIAIS!$G$27+DADOS_INICIAIS!$G$28))*0.7 -> 34571.737 | F29: 220 | G29: =F29*D29*1.1 -> 8366360.4 | J29: =D29/(D34+D29) -> 0.52893106
A30: Alvenaria escadas | B30: 0.2 | C30: m² / AC | D30: =B30*DADOS_INICIAIS!$G$9 -> 5511.89 | E30: un | F30: 70 | G30: =F30*D30*1.1 -> 424415.53 | J30: =1-J29 -> 0.47106894
A31: Alvenaria cobertura / reservatório | B31: 0.8 | C31: m² / APT | D31: =B31*DADOS_INICIAIS!$G$30 -> 1408.576 | E31: m³ | F31: 45 | G31: =F31*D31*1.1 -> 69724.512
A32: Alvenaria refratárias | B32: 1.75 | C32: m² * CHU | D32: ='SISTEMAS ESPECIAIS'!B14 -> 0 | E32: un | F32: 210
A33: Churrasqueiras pré-moldadas | D33: =D32 -> 0 | E33: un | F33: 1800 | G33: =F33*D33*1.1 -> 0
A34: Serviços complementares | B34: 12.5 | C34: R$ / m² | D34: =D27+D28+D26+D30+D31 -> 30789.781 | E34: kg | F34: =B34 -> 12.5 | G34: =F34*D34*1.1 -> 423359.48
A35: Mão de obra | B35: 35 | C35: R$ / m² | D35: =D27+D28+D26+D30+D31 -> 30789.781 | E35: m² | F35: 35 | G35: =F35*D35*1.1 -> 1185406.6
A36: TOTAL | G36: =SUM(G26:G35) -> 11650798
A39: TOTAL ALVENARIA | G39: =G21 -> 2968837.7 | H39: =G39/DADOS_INICIAIS!E9 -> 490.7843
G42: =G39/1.1 -> 2698943.4 | H42: =G42/DADOS_INICIAIS!G9 -> 97.931684
F45: TERREO | G45: =167.23*3.5 -> 585.305
F46: PAV 1 E 2 | G46: =B52*2 -> 1030.12
F47: COB | G47: =B52 -> 515.06
C48: 4139 | D48: =C48/INFRAESTRUTURA!D8 -> #DIV/0!
D50: =DADOS_INICIAIS!E9*1.4 -> 8468.838
A51: TOTAL PAV | B51: =380.69*3.5 -> 1332.415 | D51: =D50-D11 -> 7259.004
A52: EXT | B52: =147.16*3.5 -> 515.06 | C52: =B52/B51 -> 0.38656124 | D52: =D51*C52 -> 2806.0496
A53: DRY EXT | B53: =B51-B52-B54 -> 505.19 | C53: =B53/B51 -> 0.37915364 | D53: =D51*C53 -> 2752.2778
...

Sheet INSTALAÇÕES
A2: INSTALAÇÕES
A4: INSTALAÇÕES ELÉTRICAS
A6: Descrição | B6: Parâmetro | D6: Valor total
A7: Entrada de Energia | B7: 8 | C7: R$ / AC | D7: =B7*DADOS_INICIAIS!$E$9*1.1 -> 53232.696
A8: Eletrodutos e Eletrocalhas | B8: =23-2 -> 21 | C8: R$ / AC | D8: =B8*DADOS_INICIAIS!$E$9*1.1 -> 139735.83
A9: Cabos e Fiações | B9: 80 | C9: R$ / AC | D9: =B9*DADOS_INICIAIS!$E$9*1.1 -> 532326.96
A10: Quadros e Disjuntores | B10: 42 | C10: R$ / AC | D10: =B10*DADOS_INICIAIS!$E$9*1.1 -> 279471.65
A11: Acabamentos Elétricos | B11: 8 | C11: R$ / AC | D11: =B11*DADOS_INICIAIS!$E$9*1.1 -> 53232.696
A12: Equipamentos e Iluminação | B12: 20 | C12: R$ / AC | D12: =B12*DADOS_INICIAIS!$E$9*1.1 -> 133081.74
A13: Grupo de geradores | B13: 1 | C13: 185000 | D13: =B13*C13 -> 185000
A14: Infra de carro elétrico | B14: 12 | C14: 547 | D14: =B14*C14*1.1 -> 7220.4
A15: Equipamento d ecarro eletrico | B15: 6 | C15: 10500 | D15: =B15*C15*1.1 -> 69300
A16: Mão de Obra para Instalações Elétricas | B16: 58 | C16: R$ / AC | D16: =B16*DADOS_INICIAIS!$E$9*1.1 -> 385937.05
A17: TOTAL | D17: =SUM(D7:D16) -> 1838539
A19: INSTALAÇÕES HIDROSSANITÁRIAS
A21: Descrição | B21: Parâmetro | D21: Valor total
A22: Instalações de Água Fria | B22: =25-B26 -> 22 | C22: R$ / AC | D22: =B22*DADOS_INICIAIS!$E$9*1.1 -> 146389.91
A23: Instalações de Água Quente | B23: 20 | C23: R$ / AC | D23: =B23*DADOS_INICIAIS!$E$9*1.1 -> 133081.74
A24: Instalações de Águas Pluviais | B24: 10 | C24: R$ / AC | D24: =B24*DADOS_INICIAIS!$E$9*1.1 -> 66540.87
A25: Instalações Sanitárias | B25: 15 | C25: R$ / AC | D25: =B25*DADOS_INICIAIS!$E$9*1.1 -> 99811.305
A26: Hidrometro | B26: 3 | C26: R$ / AC | D26: =B26*DADOS_INICIAIS!$E$9*1.1 -> 19962.261
A27: Acumulador (boiler) 2500L | B27: 2 | C27: 30000 | D27: =B27*C27*1.1 -> 66000
A28: Trataamento de esgoto | B28: 1 | C28: 110000 | D28: =B28*C28*1.1 -> 121000
A29: Bombas de pressurização | B29: 2 | C29: 8300 | D29: =B29*C29*1.1 -> 18260 | E29: agua fria
A30: Bombas de calor | B30: 4 | C30: 2000 | D30: =B30*C30*1.1 -> 8800 | E30: agua quente e fria
A31: Cisternas e reservatorios | B31: =4+2 -> 6 | C31: 5240 | D31: =B31*C31*1.1 -> 34584
A32: Aquecedores a gás | B32: 2 | C32: 5822 | D32: =B32*C32*1.1 -> 12808.4
A33: Mão de Obra para Instalações Hidráulicas | B33: 60 | C33: R$ / AC | D33: =B33*DADOS_INICIAIS!$E$9*1.1 -> 399245.22
A34: TOTAL | D34: =SUM(D22:D33) -> 1126483.7
A36: LOUÇAS E METAIS
A38: Descrição | B38: Parâmetro | D38: Valor total
A39: Louças | B39: 20 | C39: R$ / AC | D39: =SUM(D40:D41) -> 100986.66
A40: Bacia | B40: 60 | C40: 1683.1111 | D40: =B40*C40 -> 100986.66
A41: Cuba | B41: 59 | C41: 1812.59
A42: Metais | B42: 30 | C42: R$ / AC | D42: =B42*DADOS_INICIAIS!$E$9*1.1 -> 199622.61
A43: Bancadas, pias e divisórias | B43: 16 | C43: R$ / AC | F43: =1.3*0.55*38 -> 27.17
A44: Mão de obra | B44: 10 | C44: R$ / AC | D44: =B44*DADOS_INICIAIS!$E$9*1.1 -> 66540.87 | F44: =F43*1.5 -> 40.755 | G44: =F44*2500 -> 101887.5
A45: TOTAL | D45: =SUM(D40:D44) -> 367150.14 | E45: =D45/DADOS_INICIAIS!E9 -> 60.694301
A47: INSTALAÇÕES PREVENTIVAS E GLP
A49: Descrição | B49: Parâmetro | D49: Valor total
...

Sheet SISTEMAS ESPECIAIS
A2: SISTEMAS ESPECIAIS
A4: CLIMATIZAÇÃO, EXAUSTÃO MECÂNICA E PRESSURIZAÇÃO
A6: Descrição | B6: Quantidade | C6: Preço Unitário | D6: Valor total | G6: SUBSOLO | H6: TERREO | I6: 1 PV | J6: 2 PAV | K6: 3PAV | L6: COB
A7: Infraestrutura para Instalação de Ar Condicionado VRF | B7: =DADOS_INICIAIS!E9 -> 6049.17 | C7: 210 | D7: =B7*C7*1.1 -> 1397358.3 | G7: 14 | H7: =1+17 -> 18 | I7: =17 -> 17 | J7: 18 | K7: 18
A8: Instalação de Ar Condicionado - evaporadoras | B8: =SUM(G8:O8) -> 85 | C8: 2582 | D8: =B8*C8*1.1 -> 241417 | G8: 14 | H8: =1+17 -> 18 | I8: =17 -> 17 | J8: 18 | K8: 18
A9: Instalação de Ar Condicionado - condensadoras | B9: 16 | C9: =132780 -> 132780 | D9: =B9*C9*1.1 -> 2336928
A10: UTA | B10: 4 | C10: 32915 | D10: =B10*C10*1.1 -> 144826
A11: Exaustão cozinhas | B11: 1 | C11: =603450 -> 603450 | D11: =B11*C11*1.1 -> 663795
A12: Exaustão banheiros | B12: =DADOS_INICIAIS!E21+2 -> 38 | C12: 1100 | D12: =B12*C12*1.1 -> 45980
A13: Hydrokit | B13: 5 | C13: =D13/B13 -> 38500 | D13: 192500
A14: Churrasqueiras | B14: 0 | C14: 2600 | D14: =B14*C14*1.1 -> 0
A15: TOTAL | D15: =SUM(D7:D14) -> 5022804.3
A17: COMUNICAÇÃO
A19: Descrição | B19: Parâmetro | D19: Valor total
A20: CFTV | B20: 10 | C20: R$ / AC | D20: =B20*DADOS_INICIAIS!E9*1.1 -> 66540.87
A21: Interfone | B21: 4 | C21: R$ / AC | D21: =B21*DADOS_INICIAIS!E9*1.1 -> 26616.348
A22: Controle de acesso | B22: 2 | C22: R$ / AC | D22: =B22*[4]DADOS_INICIAIS!$E$11*1.1 -> 32325.524
A23: TV e internet | B23: 6 | C23: R$ / AC | D23: =B23*DADOS_INICIAIS!E9*1.1 -> 39924.522
A24: Automação, telecomunicação e sistemas de segurança | B24: 4 | C24: R$ / AC | D24: =B24*DADOS_INICIAIS!E9*1.1 -> 26616.348
A25: TOTAL | D25: =SUM(D20:D24) -> 192023.61
A27: EQUIPAMENTOS
A29: Descrição | B29: Quantidade | C29: Preço Unitário | D29: Valor total
A30: Elevadores | B30: 3 | C30: 151569.28 | D30: =B30*C30*1.1 -> 500178.62 | E30: 4 PARADAS
A31: Subestação | B31: 0 | C31: 350000 | D31: =B31*C31*1.1 -> 0
A32: Escada pressurizada | B32: 0 | C32: =50*DADOS_INICIAIS!G9 -> 1377972.5 | D32: =B32*C32*1.1 -> 0
A33: Equipamentos para Sauna | B33: 1 | C33: 8500 | D33: =B33*C33*1.1 -> 9350
A34: Banheira de imersão | B34: 27 | C34: 9320 | D34: =B34*C34*1.1 -> 276804
A35: Hidromassagem | B35: 2 | C35: 24980 | D35: =B35*C35*1.1 -> 54956
A36: Equipamentos para Espelho dagua | B36: 1 | C36: 25000 | D36: =B36*C36*1.1 -> 27500
A37: Chafariz | B37: 1 | C37: 110000 | D37: =B37*C37 -> 110000
A38: Aspiração central | B38: =DADOS_INICIAIS!E9 -> 6049.17 | C38: 21.5 | D38: =B38*C38*1.1 -> 143062.87
A39: Aquecimento de piso | B39: =(AMBIENTES!K39+AMBIENTES!K83+AMBIENTES!K86+AMBIENTES!K89+AMBIENTES!K91+AMBIENTES!K94+AMBIENTES!K97+AMBIENTES!K100+AMBIENTES!K103+AMBIENTES!K105+AMBIENTES!K108+AMBIENTES!K119+AMBIENTES!K122+AMBIENTES!K125+AMBIENTES!K127+AMBIENTES!K130+AMBIENTES!K133+AMBIENTES!K134+AMBIENTES!K142+AMBIENTES!K145+AMBIENTES!K148+AMBIENTES!K150+AMBIENTES!K153+AMBIENTES!K156+AMBIENTES!K165+AMBIENTES!K167+AMBIENTES!K169+AMBIENTES!K171+AMBIENTES!K174+AMBIENTES!K176+AMBIENTES!K179+AMBIENTES!K181)*0.8 -> 188.064 | C39: 280 | D39: =B39*C39*1.1 -> 57923.712
A40: Equipamentos para Piscina | B40: 2 | C40: =36831.3+C41*9 -> 38181.3 | D40: =B40*C40*1.1 -> 83998.86
A41: Pontos de hidro | B41: =8+10+2 -> 20 | C41: 150 | D41: =B41*C41*1.1 -> 3300
A42: Equipamentos para Piscina privativa | B42: 2 | C42: =25000+2*C41 -> 25300 | D42: =B42*C42*1.1 -> 55660
A43: TOTAL | D43: =SUM(D30:D42)-D41 -> 1319434.1
A45: OUTROS SISTEMAS ESPECIAIS
A47: Descrição | B47: Parâmetro | D47: Valor total
A48: Outros sistemas | B48: 30 | C48: R$ / AC | D48: =B48*DADOS_INICIAIS!E9*1.1 -> 199622.61
A49: TOTAL | D49: =SUM(D48:D48) -> 199622.61
...

Sheet IMPERMEABILIZAÇÃO
A3: IMPERMEABILIZAÇÃO
A4: Data | B4: 45457
A5: Arquivo base | B5: -
A7: ALVENARIA
A9: Descrição | B9: Parâmetro | D9: Quantidade | F9: Preço unitário | G9: Valor total | H9: Observação
A10: Regularização de Superfície | B10: 25 | C10: R$ / m² | D10: =D14+D15 -> 2949.0932 | E10: m² | F10: 22 | G10: =F10*D10*1.1 -> 71368.055
A11: Poço do elevador | B11: 45 | C11: R$ / m² | D11: =((2.15*2.15)+(2.15+2.15)*2*1.8)*3 -> 60.3075 | E11: m² | F11: 41 | G11: =F11*D11*1.1 -> 2719.8683
A12: Baldrames | B12: 30 | C12: R$ / m² | D12: =INFRAESTRUTURA!D28 -> 2132.05 | E12: m² | F12: 35 | G12: =F12*D12*1.1 -> 82083.925
A13: Ralos | B13: 0.4 | C13: R$ / AC | D13: 1 | E13: vb | F13: =B13*DADOS_INICIAIS!E9 -> 2419.668 | G13: =F13*D13*1.1 -> 2661.6348
A14: Impermeabilizações cimenticias | B14: 0.3 | C14: m² / AC | D14: =B14*DADOS_INICIAIS!$E$9 -> 1814.751 | E14: m² | F14: 60 | G14: =F14*D14 -> 108885.06
A15: Impermeabilizações com manta asfaltica | B15: 0.1 | C15: m² / AC | D15: =AMBIENTES!K46+AMBIENTES!K47+AMBIENTES!K48+AMBIENTES!K69+AMBIENTES!K115+AMBIENTES!K139+AMBIENTES!K140+AMBIENTES!K188 -> 1134.3422 | E15: m² | F15: 150 | G15: =F15*D15*1.1 -> 187166.46
A16: Impermeabilização de peitoril | B16: 0.6 | C16: R$ / AC | D16: 1 | E16: vb | F16: =B16*DADOS_INICIAIS!E9 -> 3629.502 | G16: =F16*D16*1.1 -> 3992.4522
A17: Cristalização elementos aparentes | E17: m3 | F17: 60 | G17: =F17*D17*1.1 -> 0
A18: Proteção Mecânica | B18: 28 | C18: R$ / m² | D18: =D15 -> 1134.3422 | E18: m² | F18: 28 | G18: =F18*D18*1.1 -> 34937.74
A19: TOTAL | G19: =SUM(G10:G18) -> 493815.2 | K19: =4160+1440+1120+2880+4800+91680+4000 -> 110080 | L19: =K19/21 -> 5241.9048
A21: TOTAL IMPERMEABILIZAÇÃO | G21: =G19 -> 493815.2 | H21: =G21/DADOS_INICIAIS!E9 -> 81.633546
H24: =H21/1.1 -> 74.212315

Sheet Planilha1
C1: (ST/90/RU)
C2: Descrição | D2: Unidade | E2: Quantidade | F2: Preço unitário | G2: Preço Total
C3: PLACA / CHAPA DE GESSO ACARTONADO, RESISTENTE A UMIDADE (RU), COR VERDE, E = 12,5 MM, 1200 X 2400 MM (L X C) | D3: m2 | E3: 1.053 | F3: 13.92 | G3: =F3*E3 -> 14.65776
C4: PLACA / CHAPA DE GESSO ACARTONADO, STANDARD (ST), COR BRANCA, E = 12,5 MM, 1200 X 2400 MM (L X C) | D4: m2 | E4: 1.053 | F4: 9.5417 | G4: =F4*E4 -> 10.04741
C5: PINO DE ACO COM ARRUELA CONICA, DIAMETRO ARRUELA = *23* MM E COMP HASTE = *27* MM (ACAOINDIRETA) | D5: um | E5: 4.95 | F5: 0.504 | G5: =F5*E5 -> 2.4948
C6: MASSA DE REJUNTE EM PO PARA DRYWALL, A BASE DE GESSO, SECAGEM RAPIDA, PARA TRATAMENTO DE JUNTAS DE CHAPA DE GESSO (NECESSITA ADICAO DE AGUA) | D6: kg | E6: 1.0978 | F6: 2.173 | G6: =F6*E6 -> 2.3855194
C7: FITA DE PAPEL MICROPERFURADO, 50 X 150 MM, PARA TRATAMENTO DE JUNTAS DE CHAPA DE GESSO PARA DRYWALL | D7: m2 | E7: 2.5027 | F7: 0.28 | G7: =F7*E7 -> 0.700756
C8: FITA DE PAPEL REFORCADA COM LAMINA DE METAL PARA REFORCO DE CANTOS DE CHAPA DE GESSO PARA DRYWALL | D8: m2 | E8: 1.4815 | F8: 10 | G8: =F8*E8 -> 14.815
C9: PARAFUSO DRY WALL, EM ACO FOSFATIZADO, CABECA TROMBETA E PONTA AGULHA (TA), COMPRIMENTO 25 MM | D9: um | E9: 20.1868 | F9: 0.09 | G9: =F9*E9 -> 1.816812
C10: PARAFUSO DRY WALL, EM ACO ZINCADO, CABECA LENTILHA E PONTA BROCA (LB), LARGURA 4,2 MM, COMPRIMENTO 13 MM | D10: um | E10: 0.4803 | F10: 0.2 | G10: =F10*E10 -> 0.09606
C11: PARAFUSO DRY WALL, EM ACO FOSFATIZADO, CABECA TROMBETA E PONTA AGULHA (TA), COMPRIMENTO 45 MM | D11: um | E11: 20.1868 | F11: 0.19 | G11: =F11*E11 -> 3.835492
C12: LÂ DE VIDRO PARA ISOLAMENTO 50mm | D12: m2 | E12: 1.1 | F12: 118.73 | G12: =F12*E12 -> 130.603
C13: PERFIL GUIA, FORMATO U, EM ACO ZINCADO, PARA ESTRUTURA PAREDE DRYWALL, E = 0,5 MM, 90 X 3000 MM (L X C) | D13: m | E13: 1.5248 | F13: 16.8 | G13: =F13*E13 -> 25.61664
C14: PERFIL MONTANTE, FORMATO C, EM ACO ZINCADO, PARA ESTRUTURA PAREDE DRYWALL, E = 0,5 MM, 90 X 3000 MM (L X C) | D14: m | E14: 4.0011 | F14: 18.09 | G14: =F14*E14 -> 72.379899
G15: =SUM(G3:G14) -> 279.44915
C17: (48/VID/PERF)
C18: Descrição | D18: Unidade | E18: Quantidade | F18: Preço unitário | G18: Preço Total
C19: PLACA / CHAPA DE GESSO ACARTONADO, PERFORMA, COR BRANCA, E = 12,5 MM, 1200 X 2400 MM (L X C) | D19: m2 | E19: 1.053 | F19: 32 | G19: =F19*E19 -> 33.696
C20: PINO DE ACO COM ARRUELA CONICA, DIAMETRO ARRUELA = *23* MM E COMP HASTE = *27* MM (ACAOINDIRETA) | D20: um | E20: 4.95 | F20: 0.504 | G20: =F20*E20 -> 2.4948
C21: MASSA DE REJUNTE EM PO PARA DRYWALL, A BASE DE GESSO, SECAGEM RAPIDA, PARA TRATAMENTO DE JUNTAS DE CHAPA DE GESSO (NECESSITA ADICAO DE AGUA) | D21: kg | E21: 0.5489 | F21: 2.173 | G21: =F21*E21 -> 1.1927597
C22: FITA DE PAPEL MICROPERFURADO, 50 X 150 MM, PARA TRATAMENTO DE JUNTAS DE CHAPA DE GESSO PARA DRYWALL | D22: m2 | E22: 1.25135 | F22: 0.28 | G22: =F22*E22 -> 0.350378
C23: FITA DE PAPEL REFORCADA COM LAMINA DE METAL PARA REFORCO DE CANTOS DE CHAPA DE GESSO PARA DRYWALL | D23: m2 | E23: 0.79255 | F23: 10 | G23: =F23*E23 -> 7.9255
C24: PARAFUSO DRY WALL, EM ACO FOSFATIZADO, CABECA TROMBETA E PONTA AGULHA (TA), COMPRIMENTO 25 MM | D24: um | E24: 10.0934 | F24: 0.09 | G24: =F24*E24 -> 0.908406
C25: PARAFUSO DRY WALL, EM ACO ZINCADO, CABECA LENTILHA E PONTA BROCA (LB), LARGURA 4,2 MM, COMPRIMENTO 13 MM | D25: um | E25: 0.27205 | F25: 0.2 | G25: =F25*E25 -> 0.05441
C26: LÂ DE VIDRO PARA ISOLAMENTO 50mm | D26: m2 | E26: 1.1 | F26: 20 | G26: =F26*E26 -> 22
C27: PERFIL GUIA, FORMATO U, EM ACO ZINCADO, PARA ESTRUTURA PAREDE DRYWALL, E = 0,5 MM, 48 X 3000 MM (L X C) | D27: m | E27: 1.8234 | F27: 5.1666 | G27: =F27*E27 -> 9.4207784
C28: PERFIL MONTANTE, FORMATO C, EM ACO ZINCADO, PARA ESTRUTURA PAREDE DRYWALL, E = 0,5 MM, 9048 X 3000 MM (L X C) | D28: m | E28: 4.0011 | F28: 5.73 | G28: =F28*E28 -> 22.926303
C29: BANDA ACUSTICA | D29: m | E29: 0.57142857 | F29: 15.3 | G29: =F29*E29 -> 8.7428571
G30: =SUM(G19:G29) -> 109.71219
C32: (PERF/VID/48/VID/PERF)
C33: Descrição | D33: Unidade | E33: Quantidade | F33: Preço unitário | G33: Preço Total
C34: PLACA / CHAPA DE GESSO ACARTONADO, PERFORMA, COR BRANCA, E = 12,5 MM, 1200 X 2400 MM (L X C) | D34: m2 | E34: =E3+E4 -> 2.106 | F34: 32 | G34: =F34*E34 -> 67.392
C35: PINO DE ACO COM ARRUELA CONICA, DIAMETRO ARRUELA = *23* MM E COMP HASTE = *27* MM (ACAOINDIRETA) | D35: um | E35: =E5 -> 4.95 | F35: 0.504 | G35: =F35*E35 -> 2.4948
C36: MASSA DE REJUNTE EM PO PARA DRYWALL, A BASE DE GESSO, SECAGEM RAPIDA, PARA TRATAMENTO DE JUNTAS DE CHAPA DE GESSO (NECESSITA ADICAO DE AGUA) | D36: kg | E36: =E6 -> 1.0978 | F36: 2.173 | G36: =F36*E36 -> 2.3855194
C37: FITA DE PAPEL MICROPERFURADO, 50 X 150 MM, PARA TRATAMENTO DE JUNTAS DE CHAPA DE GESSO PARA DRYWALL | D37: m2 | E37: =E7 -> 2.5027 | F37: 0.28 | G37: =F37*E37 -> 0.700756
C38: FITA DE PAPEL REFORCADA COM LAMINA DE METAL PARA REFORCO DE CANTOS DE CHAPA DE GESSO PARA DRYWALL | D38: m2 | E38: =E8 -> 1.4815 | F38: 10 | G38: =F38*E38 -> 14.815
C39: PARAFUSO DRY WALL, EM ACO FOSFATIZADO, CABECA TROMBETA E PONTA AGULHA (TA), COMPRIMENTO 25 MM | D39: um | E39: =E9 -> 20.1868 | F39: 0.09 | G39: =F39*E39 -> 1.816812
C40: PARAFUSO DRY WALL, EM ACO ZINCADO, CABECA LENTILHA E PONTA BROCA (LB), LARGURA 4,2 MM, COMPRIMENTO 13 MM | D40: um | E40: =E10 -> 0.4803 | F40: 0.2 | G40: =F40*E40 -> 0.09606
C41: PARAFUSO DRY WALL, EM ACO FOSFATIZADO, CABECA TROMBETA E PONTA AGULHA (TA), COMPRIMENTO 45 MM | D41: um | E41: =E11 -> 20.1868 | F41: 0.19 | G41: =F41*E41 -> 3.835492
C42: LÂ DE VIDRO PARA ISOLAMENTO 50mm | D42: m2 | E42: =1.1*2 -> 2.2 | F42: 20 | G42: =F42*E42 -> 44
...

Sheet AMBIENTES
A1: Obra
A2: Empresa
A3: Revisão
A4: Data
A5: LEVANTAMENTO QUANTITATIVO
A7: REVESTIMENTOS E ACABAMENTOS DE PISO
B9: LEVANTAMENTO DE PROJETO | M9: CONTRAPISO
B10: Pavimento | C10: Local | D10: Piso | E10: Teto | F10: Isolamento teto | G10: Área (m²) | H10: Contrapiso (Sim/Não) | I10: Acustico | J10: Repetição | K10: Total | M10: Revestimento | N10: Área total
B11: SUBSOLO | C11: Reservatorios/boiler | D11: Polido | E11: Estucamento | F11: - | G11: =513.06-G12 -> 509.06 | H11: Sim | I11: - | J11: 1 | K11: =G11*J11 -> 509.06 | M11: Contrapiso | N11: =SUMIF(H:H,"Sim",K:K) -> 5971.6072 | O11: =N11/#REF! -> #REF!
B12: SUBSOLO | C12: Casa de maquinas | D12: Polido | E12: Estucamento | F12: - | G12: 4 | H12: Sim | I12: - | J12: 1 | K12: =G12*J12 -> 4 | M12: OND | N12: =SUMIF(I:I,M12,K:K) -> 595.94
B13: SUBSOLO | C13: Estacionamento | D13: Polido | E13: Estucamento | F13: - | G13: 463.69 | H13: Não | I13: - | J13: 1 | K13: =G13*J13 -> 463.69 | M13: CIMENT | N13: =SUMIF(I:I,M13,K:K) -> 170.03
B14: SUBSOLO | C14: Rouparia | D14: Porcelanato | E14: Gesso | F14: - | G14: 73.15 | H14: Sim | I14: - | J14: 1 | K14: =G14*J14 -> 73.15 | M14: FLUT | N14: =SUMIF(I:I,M14,K:K) -> 1489.32
B15: SUBSOLO | C15: Roupa suja | D15: Porcelanato | E15: Gesso | F15: - | G15: 3.85 | H15: Sim | I15: - | J15: 1 | K15: =G15*J15 -> 3.85 | M15: FLUT+PU | N15: =SUMIF(I:I,M15,K:K) -> 434.65
B16: SUBSOLO | C16: Telecom | D16: Porcelanato | E16: Estucamento | F16: - | G16: 8.45 | H16: Sim | I16: - | J16: 1 | K16: =G16*J16 -> 8.45
A17: =IF(C16="*&APTO&*","OK","") | B17: SUBSOLO | C17: Eletrica | D17: Porcelanato | E17: Gesso | F17: - | G17: 10.96 | H17: Sim | I17: - | J17: 1 | K17: =G17*J17 -> 10.96 | M17: PISO
B18: SUBSOLO | C18: Administração | D18: Porcelanato | E18: Gesso | F18: - | G18: =37.43*2 -> 74.86 | H18: Sim | I18: - | J18: 1 | K18: =G18*J18 -> 74.86 | M18: Material | N18: Área total
B19: SUBSOLO | C19: Circulação | D19: Porcelanato AC | E19: Gesso | F19: - | G19: 64.74 | H19: Sim | I19: - | J19: 1 | K19: =G19*J19 -> 64.74 | M19: Polido | N19: =SUMIF(D:D,M19,K:K) -> 1061.22
B20: SUBSOLO | C20: Area tecnica | D20: Porcelanato | E20: Gesso | F20: - | G20: 30.62 | H20: Sim | I20: - | J20: 1 | K20: =G20*J20 -> 30.62 | M20: Porcelanato | N20: =SUMIF(D:D,M20,K:K) -> 1073.97
B21: SUBSOLO | C21: Almoxarifado | D21: Porcelanato | E21: Gesso | F21: - | G21: 62.62 | H21: Sim | I21: - | J21: 1 | K21: =G21*J21 -> 62.62 | M21: Porcelanato AC | N21: =SUMIF(D:D,M21,K:K) -> 1749.34
B22: SUBSOLO | C22: Recebimento | D22: Porcelanato | E22: Gesso | F22: - | G22: 6.27 | H22: Sim | I22: - | J22: 1 | K22: =G22*J22 -> 6.27 | M22: Basalto | N22: =SUMIF(D:D,M22,K:K) -> 1401.186
B23: SUBSOLO | C23: Manipulação | D23: Porcelanato | E23: Gesso | F23: - | G23: =6.31+6.32 -> 12.63 | H23: Sim | I23: - | J23: 1 | K23: =G23*J23 -> 12.63 | M23: Vinilico | N23: =SUMIF(D:D,M23,K:K) -> 1379.64
B24: SUBSOLO | C24: Circulação serviço | D24: Porcelanato | E24: Gesso | F24: - | G24: 72.26 | H24: Sim | I24: - | J24: 1 | K24: =G24*J24 -> 72.26 | M24: Madeira | N24: =SUMIF(D:D,M24,K:K) -> 9.25
B25: SUBSOLO | C25: Camara de congelados | D25: Porcelanato | E25: Estucamento | F25: - | G25: =6.78+6.94+6.78 -> 20.5 | H25: Sim | I25: - | J25: 1 | K25: =G25*J25 -> 20.5 | M25: Pastilha | N25: =SUMIF(D:D,M25,K:K) -> 173.0322
B26: SUBSOLO | C26: Vestiarios | D26: Porcelanato | E26: Gesso | F26: - | G26: =26.45+19.48 -> 45.93 | H26: Sim | I26: - | J26: 1 | K26: =G26*J26 -> 45.93 | M26: Mármore | N26: =SUMIF(D:D,M26,K:K) -> 16.443
B27: SUBSOLO | C27: Funcionarios | D27: Porcelanato | E27: Gesso | F27: - | G27: 36.84 | H27: Sim | I27: - | J27: 1 | K27: =G27*J27 -> 36.84 | M27: Pintura | N27: =SUMIF(D:D,M27,K:K) -> 37.314
B28: SUBSOLO | C28: Controle | D28: Porcelanato | E28: Gesso | F28: - | G28: 5.83 | H28: Sim | I28: - | J28: 1 | K28: =G28*J28 -> 5.83 | M28: Carpete | N28: =SUMIF(D:D,M28,K:K) -> 525.01
B29: SUBSOLO | C29: Cozinha | D29: Porcelanato | E29: Gesso | F29: - | G29: =31.32+2.64+8.27 -> 42.23 | H29: Sim | I29: - | J29: 1 | K29: =G29*J29 -> 42.23 | M29: Cimentado | N29: =SUMIF(D:D,M29,K:K) -> 0
B30: SUBSOLO | C30: Apoio e praça de garçons | D30: Porcelanato | E30: Gesso | F30: - | G30: =13+9.33 -> 22.33 | H30: Sim | I30: - | J30: 1 | K30: =G30*J30 -> 22.33 | M30: - | N30: =SUMIF(D:D,M30,K:K) -> 323.98
B31: SUBSOLO | C31: Foyer | D31: Porcelanato AC | E31: Gesso | F31: - | G31: =14.45 -> 14.45 | H31: Sim | I31: - | J31: 1 | K31: =G31*J31 -> 14.45 | N31: =SUMIF(D:D,M31,K:K) -> 0
B32: SUBSOLO | C32: Restaurante | D32: Porcelanato AC | E32: Gesso | F32: - | G32: 172.63 | H32: Sim | I32: - | J32: 1 | K32: =G32*J32 -> 172.63 | N32: =SUMIF(D:D,M32,K:K) -> 0
B33: SUBSOLO | C33: WC restaurante | D33: Porcelanato AC | E33: Gesso | F33: - | G33: =10.48+10.48+4.26 -> 25.22 | H33: Sim | I33: - | J33: 1 | K33: =G33*J33 -> 25.22 | M33: TETO
B34: SUBSOLO | C34: Recepção | D34: Porcelanato AC | E34: Gesso | F34: - | G34: 25.88 | H34: Sim | I34: - | J34: 1 | K34: =G34*J34 -> 25.88 | M34: Material | N34: Área total
B35: SUBSOLO | C35: Circ | D35: Porcelanato AC | E35: Gesso | F35: - | G35: 5.16 | H35: Sim | I35: - | J35: 1 | K35: =G35*J35 -> 5.16 | M35: Gesso | N35: =SUMIF(E:E,M35,K:K) -> 4034.83
B36: SUBSOLO | C36: Atendimento | D36: Porcelanato AC | E36: Gesso | F36: - | G36: 24.85 | H36: Sim | I36: - | J36: 1 | K36: =G36*J36 -> 24.85 | M36: Estucamento | N36: =SUMIF(E:E,M36,K:K) -> 1255.163
B37: SUBSOLO | C37: Lavabo | D37: Porcelanato AC | E37: Gesso | F37: - | G37: 2.8 | H37: Sim | I37: - | J37: 1 | K37: =G37*J37 -> 2.8 | M37: - | N37: =SUMIF(E:E,M37,K:K) -> 2460.3922
B38: SUBSOLO | C38: Massagem | D38: Porcelanato AC | E38: Gesso | F38: - | G38: =23.28+23.15 -> 46.43 | H38: Sim | I38: - | J38: 1 | K38: =G38*J38 -> 46.43 | N38: =SUMIF(E:E,M38,K:K) -> 0
B39: SUBSOLO | C39: Banho | D39: Porcelanato AC | E39: Gesso | F39: - | G39: =5.94+5.92 -> 11.86 | H39: Sim | I39: - | J39: 1 | K39: =G39*J39 -> 11.86 | M39: Isol | N39: =SUMIF(F:F,M39,K:K) -> 494.27
B40: SUBSOLO | C40: Escada PF - pisada | D40: Basalto | E40: Estucamento | F40: - | G40: =5.42+22*1.2*0.27 -> 12.548 | H40: Sim | I40: - | J40: 1 | K40: =G40*J40 -> 12.548 | M40: Absor | N40: =SUMIF(F:F,M40,K:K) -> 465.14
B41: SUBSOLO | C41: Escada PF - espelho | D41: Pintura | E41: Estucamento | F41: - | G41: =22*1.2*0.18 -> 4.752 | H41: Sim | I41: - | J41: 1 | K41: =G41*J41 -> 4.752 | M41: Absor | N41: =SUMIF(F:F,M41,K:K) -> 465.14
B42: SUBSOLO | C42: Antecamara | D42: Porcelanato | E42: Estucamento | F42: - | G42: 3.19 | H42: Sim | I42: - | J42: 1 | K42: =G42*J42 -> 3.19
...

Sheet Rev. Internos Piso e Parede
A2: ORÇAMENTO PARAMÉTRICO GERENCIAMENTO EXECUTIVO
A7: Cliente | B7: Amalfi
A8: Obra | B8: San Felicce
A9: Data | B9: 45397
A10: Revisão | B10: R00
A12: REVESTIMENTOS INTERNOS EM PISO E PAREDE
J13: =SUM(G15:G18) -> 522962.8
A14: Descrição | B14: Quantidade | D14: Parâmetro | F14: Referência | G14: Valor total | J14: =G23+G24 -> 58555.966
A15: Polimento de concreto | B15: =AMBIENTES!N19 -> 1061.22 | C15: m² | D15: =35 -> 35 | E15: R$ / m² | F15: Média | G15: =D15*B15*1.1 -> 40856.97
A16: Piso alisado | B16: =AMBIENTES!N29 -> 0 | C16: m² | D16: 25 | E16: R$ / m² | F16: Média | G16: =D16*B16*1.1 -> 0
A17: Contrapiso | B17: =AMBIENTES!N11 -> 5971.6072 | C17: m² | D17: =100.41-35 -> 65.41 | E17: R$ | F17: Média | G17: =D17*B17*1.1 -> 429663.11
A18: Manta acústica ondulada | B18: =AMBIENTES!N12 -> 595.94 | C18: m² | D18: 80 | E18: R$ | F18: Média | G18: =+B18*D18*1.1 -> 52442.72
A19: Lâ de vidro + cimenticia | B19: =AMBIENTES!N13 -> 170.03 | C19: m² | D19: =Planilha1!G54 -> 185.986 | E19: R$ | F19: Média | G19: =+B19*D19*1.1 -> 34785.52
A20: Manta flutuante | B20: =AMBIENTES!N14 -> 1489.32 | C20: m² | D20: =25 -> 25 | E20: R$ | F20: Média | G20: =+B20*D20*1.1 -> 40956.3
A21: Manta flutuante + PU | B21: =AMBIENTES!N15 -> 434.65 | C21: m² | D21: =25+43.08 -> 68.08 | E21: R$ | F21: Média | G21: =+B21*D21*1.1 -> 32550.069
A22: mo contrapiso | B22: =B17 -> 5971.6072 | C22: m² | D22: 35 | E22: R$ | F22: Média | G22: =+B22*D22*1.1 -> 229906.88
A23: Chapisco | B23: =ALVENARIA!D11*2 -> 2419.668 | C23: m² | D23: 5 | E23: R$ | F23: Média | G23: =+B23*D23*1.1 -> 13308.174
A24: Reboco | B24: =B23 -> 2419.668 | C24: m² | D24: 17 | E24: R$ | F24: Média | G24: =+B24*D24*1.1 -> 45247.792
A25: Estucamento | B25: =2.1*3.5*10 -> 73.5 | C25: m² | D25: =3.5 -> 3.5 | E25: R$ | F25: Média | G25: =+B25*D25*1.1 -> 282.975
A26: mo reboco | B26: =B24 -> 2419.668 | C26: m² | D26: =3.5+22 -> 25.5 | E26: R$ | F26: Média | G26: =+B26*D26*1.1 -> 67871.687
A27: mo Estucamento | B27: =B25 -> 73.5 | C27: m² | D27: 34 | E27: R$ | F27: Média | G27: =+B27*D27*1.1 -> 2748.9 | J27: REVET PAREDE | K27: =SUM(G23:G27) -> 129459.53 | L27: =K27+'Acabamentos de Piso e Parede'!K34 -> 2569648.4
A28: TOTAL | G28: =SUM(G15:G27) -> 990621.09 | J28: REVET PISO | K28: =G28-K27 -> 861161.57
A31: TOTAL REVESTIMENTOS | G31: =G28 -> 990621.09 | H31: =G31/DADOS_INICIAIS!E9 -> 163.76149
H33: =H31/1.1 -> 148.87408
B34: =B23+'Rev. Fachada'!B15 -> 5098.4857

Sheet TETO
A3: REVESTIMENTOS E ACABAMENTOS DE TETO
A4: Data | B4: 45457
A5: Arquivo base | B5: -
A7: ALVENARIA
A9: Descrição | B9: Parâmetro | D9: Quantidade | F9: Preço unitário | G9: Valor total | H9: Observação
A10: Forro mineral | B10: 0.8 | C10: m² / AC | D10: =AMBIENTES!N35-D13-D12 -> 3075.42 | E10: m² | F10: 60 | G10: =F10*D10*1.1 -> 202977.72
A11: Forro RF | B11: 0.8 | C11: m² / AC | D11: =9.45*5 -> 47.25 | E11: m² | F11: 60 | G11: =F11*D11*1.1 -> 3118.5
A12: Forro com isolamento | B12: 0.8 | C12: m² / AC | D12: =AMBIENTES!N39 -> 494.27 | E12: m² | F12: =F10+20 -> 80 | G12: =F12*D12*1.1 -> 43495.76
A13: Forro absorvedor | B13: 0.8 | C13: m² / AC | D13: =AMBIENTES!N41 -> 465.14 | E13: m² | F13: =160+20 -> 180 | G13: =F13*D13*1.1 -> 92097.72
A14: Molduras | B14: 1.2 | C14: m / FORRO | D14: =(D10+D12+D13)*B14*2 -> 9683.592 | E14: m | F14: =35*1.2 -> 42 | G14: =F14*D14*1.1 -> 447381.95
A15: Roseta iluminação | D15: =ROUND(DADOS_INICIAIS!E21*1.2,0) -> 43 | E15: um | F15: 85 | G15: =F15*D15*1.1 -> 4020.5
A16: Estucamento | B16: 0.1 | C16: m² / AC | D16: =AMBIENTES!N36-D11-D18 -> 1161.363 | E16: m² | F16: 4 | G16: =F16*D16*1.1 -> 5109.9972
A17: mo Estucamento | B17: 0.1 | C17: m² / AC | D17: =D16 -> 1161.363 | E17: m² | F17: 22 | G17: =F17*D17*1.1 -> 28104.985
A18: Chapisco e reboco | B18: =1-B10-B16 -> 0.1 | C18: m² / AC | D18: =18.76*5-D11 -> 46.55 | E18: m² | F18: =91-26 -> 65 | G18: =F18*D18*1.05*1.1 -> 3494.7413
A19: mo Chapisco e reboco | B19: =1-B11-B17 -> 0.1 | C19: m² / AC | D19: =D18 -> 46.55 | E19: m² | F19: 26 | G19: =F19*D19*1.05*1.1 -> 1397.8965
A20: TOTAL | G20: =SUM(G10:G19) -> 831199.77 | K20: =4160+1440+1120+2880+4800+91680+4000 -> 110080 | L20: =K20/21 -> 5241.9048
A22: TOTAL IMPERMEABILIZAÇÃO | G22: =G20 -> 831199.77 | H22: =G22/DADOS_INICIAIS!E9 -> 137.40724
H25: =H22/1.1 -> 124.91568

Sheet Acabamentos de Piso e Parede
A2: ORÇAMENTO PARAMÉTRICO GERENCIAMENTO EXECUTIVO
A7: Cliente | B7: Amalfi
A8: Obra | B8: San Felicce
A9: Data | B9: 45397
A10: Revisão | B10: R00
A12: ACABAMENTOS EM PISO E PAREDE
A14: Descrição | B14: Quantidade | D14: Parâmetro | F14: Referência | G14: Valor total
A15: Porcelanato | B15: =AMBIENTES!N20 -> 1073.97 | C15: m² | D15: 126.05 | E15: R$ | F15: Média | G15: =+D15*B15*1.1 -> 148911.31
A16: Porcelanato ac | B16: =AMBIENTES!N21+AMBIENTES!N24 -> 1758.59 | C16: m² | D16: 142.38 | E16: R$ | F16: Média | G16: =+D16*B16*1.1 -> 275426.85
A17: Piso vinilico - mat e mo | B17: =AMBIENTES!N23 -> 1379.64 | C17: m² | D17: 377 | E17: R$ | F17: Média | G17: =+D17*B17*1.1 -> 572136.71
A18: Mármore | B18: =AMBIENTES!N26 -> 16.443 | C18: m² | D18: 1856 | E18: R$ | F18: Média | G18: =+D18*B18*1.1 -> 33570.029
A19: Piso elevadores | B19: =1.82*3 -> 5.46 | C19: m² | D19: 1856 | E19: R$ | F19: Média | G19: =+D19*B19*1.1 -> 11147.136
A20: Carpete- mat e mo | B20: =AMBIENTES!N28 -> 525.01 | C20: m² | D20: 298 | E20: R$ | F20: Média | G20: =+D20*B20*1.1 -> 172098.28
A21: Piscina | B21: =AMBIENTES!N25 -> 173.0322 | C21: m² | D21: 149.82 | E21: R$ | F21: Média | G21: =+D21*B21*1.1 -> 28516.053
A22: Madeira | C22: m² | D22: 450 | E22: R$ | F22: Média | G22: =+D22*B22*1.1 -> 0
A23: Basalto | B23: =AMBIENTES!N22 -> 1401.186 | C23: m² | D23: 199 | E23: R$ | F23: Média | G23: =+D23*B23*1.1 -> 306719.62
A24: Ladrilho hidaraulico | B24: 0 | C24: m² | D24: 180 | E24: R$ | F24: Média | G24: =+D24*B24*1.1 -> 0
A25: mo marmore | B25: =B18+B19 -> 21.903 | C25: m² | D25: 42 | E25: R$ | F25: Média | G25: =+D25*B25*1.1 -> 1011.9186
A26: mo porcelanato | B26: =B15+B16 -> 2832.56 | C26: m² | D26: 42 | E26: R$ | F26: Média | G26: =+D26*B26*1.1 -> 130864.27
A27: mo pastilha | B27: =B16+B17 -> 3138.23 | C27: m² | D27: 48 | E27: R$ | F27: Média | G27: =+D27*B27*1.1 -> 165698.54
A28: mo basalto | B28: =B23 -> 1401.186 | C28: m² | D28: 45 | E28: R$ | F28: Média | G28: =+D28*B28*1.1 -> 69358.707
A29: Rodapés porcelaato | B29: =(B15+B16)*1.2 -> 3399.072 | C29: m | D29: 19.92 | E29: R$ | F29: Média | G29: =+D29*B29*1.1 -> 74480.466
A30: Rodapés poliestireno | B30: =(B20+B17)*1.2 -> 2285.58 | C30: m | D30: 93.23 | E30: R$ | F30: Média | G30: =+D30*B30*1.1 -> 234393.09
A31: Mo rodape | B31: =B29+B30 -> 5684.652 | C31: m | D31: 22 | E31: R$ | F31: Média | G31: =+D31*B31*1.1 -> 137568.58
A32: Soleiras | B32: =(ESQUADRIAS!D26+DADOS_INICIAIS!E21)*0.9 -> 66.6 | C32: m | D32: =110-D33 -> 98 | E32: R$ | F32: Média | G32: =+D32*B32*1.1 -> 7179.48
A33: mo Soleiras | B33: =B32 -> 66.6 | C33: m | D33: 12 | E33: R$ | F33: Média | G33: =+D33*B33*1.1 -> 879.12
A34: peitoris | B34: =ESQUADRIAS!D12/3.15 -> 680.33465 | C34: m | D34: =65-D35 -> 53 | E34: R$ | F34: Média | G34: =+D34*B34*1.1 -> 39663.51 | J34: ACAB PAREDE | K34: =SUM(G34:G43) -> 2440188.9
A35: mo peitoris | B35: =B34 -> 680.33465 | C35: m | D35: 12 | E35: R$ | F35: Média | G35: =+D35*B35*1.1 -> 8980.4174 | J35: ACAB PISO | K35: =G44-K34 -> 2369960.1
A36: Revestimentos de Parede (marmore) | B36: =ALVENARIA!D14*2 -> 3387.5352 | C36: m² | D36: =210 -> 210 | E36: R$ | F36: Média | G36: =D36*1.1*B36 -> 782520.63 | H36: =G36/DADOS_INICIAIS!E9 -> 129.36 | K36: =K35+'Rev. Internos Piso e Parede'!K28 -> 3231121.7 | L36: pisos e pav
A37: mo Revestimentos de Parede | B37: =B36 -> 3387.5352 | C37: m² | D37: =45 -> 45 | E37: R$ | F37: Média | G37: =D37*1.1*B37 -> 167682.99
A38: Papel de parede | B38: ='PINTURA INTERNA'!D16*0.1 -> 1178.6347 | C38: m² | D38: 180.7 | E38: R$ | F38: Média | G38: =D38*1.1*B38 -> 234277.23 | H38: 10% das paredes pintadas recebem papal de parede
A39: Boiserie | B39: =1.76*'PINTURA INTERNA'!D16*0.3 -> 6223.1915 | C39: m | D39: 24 | E39: R$ | F39: Média | G39: =D39*1.1*B39 -> 164292.25 | H39: 30% das paredes pintadas recebem boiserie
A40: mo Boiserie | B40: =1.76*'PINTURA INTERNA'!D17*0.3 -> 6223.1915 | C40: m | D40: 22 | E40: R$ | F40: Média | G40: =D40*1.1*B40 -> 150601.23 | H40: 30% das paredes pintadas recebem boiserie
A41: Base banheira | B41: =3.8*'SISTEMAS ESPECIAIS'!B34 -> 102.6 | C41: m2 | D41: =1950+3200/B41+2500/B41 -> 2005.5556 | E41: R$ | F41: Média | G41: =D41*1.1*B41 -> 226347
A42: Pilar café - mármore | B42: =2*PI()*1.3*3.2 -> 26.138051 | C42: m2 | D42: =1950+3200/B42+2500/B42 -> 2168.0729 | E42: R$ | F42: Média | G42: =D42*1.1*B42 -> 62336.119
A43: Lareiras | B43: =DADOS_INICIAIS!E21+2 -> 38 | C43: un | D43: 14437.5 | E43: R$ | F43: Média | G43: =D43*1.1*B43 -> 603487.5
A44: =20*40 -> 800 | G44: =SUM(G15:G43) -> 4810149 | H44: restante possui janela ou movel
A47: TOTAL ACABAMENTOS | G47: =G44 -> 4810149 | H47: =G47/#REF! -> #REF!
H49: =H47/1.1 -> #REF!
A50: PORCELANATO | B50: 2612.64
...

Sheet PINTURA INTERNA
A3: PINTURA INTERNA
A4: Data | B4: 45457
A5: Arquivo base | B5: -
A7: ALVENARIA
A9: Descrição | B9: Parâmetro | D9: Quantidade | F9: Preço unitário | G9: Valor total | H9: Observação
A10: Pintura piso epoxi | B10: 25 | C10: R$ / m² | D10: =AMBIENTES!N19*0.1 -> 106.122 | E10: m² | F10: 110 | G10: =F10*D10*1.1 -> 12840.762 | H10: Apenas pintura de faixas
A11: Pintura acrílica antiderrapante | B11: 45 | C11: R$ / m² | D11: ='Rev. Internos Piso e Parede'!B16 -> 0 | E11: m² | F11: 65 | G11: =F11*D11*1.1 -> 0
A12: Textura escadas | B12: 15 | C12: R$ / AC | D12: =ALVENARIA!D11*2+'Rev. Internos Piso e Parede'!B25 -> 2493.168 | E12: m² | F12: =1.2+6.87 -> 8.07 | G12: =F12*D12*1.1 -> 22131.852
A13: mo Textura escadas | B13: 15 | C13: R$ / AC | D13: =D12 -> 2493.168 | E13: m² | F13: 20 | G13: =F13*D13*1.1 -> 54849.696
A14: Textura teto | B14: 15 | C14: R$ / AC | D14: =TETO!D16 -> 1161.363 | E14: m² | F14: =1.2+6.87 -> 8.07 | G14: =F14*D14*1.1 -> 10309.419
A15: mo Textura teto | B15: 15 | C15: R$ / AC | D15: =D14 -> 1161.363 | E15: m² | F15: =22 -> 22 | G15: =F15*D15*1.1 -> 28104.985
A16: Pintura Interna paredes | B16: 50 | C16: R$ / AC | D16: =(ALVENARIA!D13+ALVENARIA!D14)*2+ALVENARIA!D15+ALVENARIA!D16 -> 11786.347 | E16: m² | F16: =1.2+3.2+6.74 -> 11.14 | G16: =F16*D16*1.1 -> 144429.9
A17: MO Pintura Interna paredes | B17: 50 | C17: R$ / AC | D17: =D16 -> 11786.347 | E17: m² | F17: =32 -> 32 | G17: =F17*D17*1.1 -> 414879.43
A18: Pintura Interna teto | B18: 50 | C18: R$ / AC | D18: =TETO!D10+TETO!D12+TETO!D13+TETO!D11 -> 4082.08 | E18: m² | F18: =1.2+3.2+6.74 -> 11.14 | G18: =F18*D18*1.1 -> 50021.808
A19: mo Pintura Interna teto | B19: 50 | C19: R$ / AC | D19: =D18 -> 4082.08 | E19: m² | F19: =34 -> 34 | G19: =F19*D19*1.1 -> 152669.79
A20: TOTAL | G20: =SUM(G10:G19) -> 890237.65 | K20: =4160+1440+1120+2880+4800+91680+4000 -> 110080 | L20: =K20/21 -> 5241.9048
A22: TOTAL IMPERMEABILIZAÇÃO | G22: =G20 -> 890237.65 | H22: =G22/DADOS_INICIAIS!E9 -> 147.16691
H24: =H22/1.1 -> 133.7881

Sheet ESQUADRIAS
A3: ESQUADRIAS
A4: Data | B4: 45460
A5: Arquivo base | B5: -
A7: ESQUADRIAS
A9: Descrição | B9: Parâmetro | D9: Quantidade | F9: Preço unitário | G9: Valor total | H9: Observação
A10: Contramarco | D10: =(D12+D13)*1.2 -> 3085.998 | E10: m | F10: =66.02-F11 -> 44.02 | G10: =F10*D10*1.1 -> 149430.19
A11: mo Contramarco | D11: =D10 -> 3085.998 | E11: m | F11: 22 | G11: =F11*D11*1.1 -> 74681.151 | J11: =G10+G11+G12+G13+G14+G18+G19+G20+G25+G21+G24 -> 8625256.4
A12: Esquadrias de Alumínio fachada | B12: 0.15 | C12: m² / AC | D12: =ALVENARIA!D10*0.8 -> 2143.0542 | E12: m² | F12: =G12/D12 -> 3252.9159 | G12: 6971175 | J12: =G26+G27+G28+G29+G30+G31+G32 -> 1102483.4
A13: Esquadrias de Alumínio internas | D13: =D12*0.2 -> 428.61083 | E13: m² | F13: =G13/D13 -> 1462.1072 | G13: 626675 | J13: =G23+G15+G16+G22+G17 -> 442323.43
A14: Portão de alumínio | D14: 1 | E14: un | F14: 18000 | G14: =F14*D14*1.1 -> 19800
A15: Portão de aço veiculos | D15: 2 | E15: un | F15: 18600 | G15: =F15*D15*1.1 -> 40920
A16: Portão de aço pedestres | D16: 2 | E16: un | F16: 7515 | G16: =F16*D16*1.1 -> 16533
A17: Gradil externo | D17: =27.5+28.3+51.51+53.34 -> 160.65 | E17: m | F17: =G17/D17 -> 2061.9359 | G17: 331250 | J17: 2154.34 | K17: 150
A18: Gradil sacada | D18: =(2*0.9+2.25)*(10+8) -> 72.9 | E18: m | F18: =12366/(2.25+2*0.9) -> 3053.3333 | G18: =F18*D18*1.1 -> 244846.8 | J18: 2154.34 | K18: 150
A19: Gradil interno | D19: =2.45+10.2+1.35*2+28 -> 43.35 | E19: m | F19: =G19/D19 -> 7641.2918 | G19: 331250 | J19: 2154.34 | K19: 150
A20: Guarda corpo balustre | D20: =7.7+2.2*2+3*4+11.3*4+3.1*5+2*5+13.3*2+11.15 -> 132.55 | E20: m | F20: =G20/D20 -> 1310.3546 | G20: 173687.5 | J20: 2916.12 | K20: =(#REF!/#REF!)*J20 -> #REF!
A21: Corrimão inox | D21: =2.5*2 -> 5 | E21: m | F21: 150 | G21: =F21*D21*1.1 -> 825
A22: Serralherias | B22: 5 | C22: R$ / AC | D22: 1 | E22: vb | F22: =B22*DADOS_INICIAIS!E9 -> 30245.85 | G22: =F22*D22*1.1 -> 33270.435
A23: PCF | D23: =10 -> 10 | E23: un | F23: 1850 | G23: =F23*D23*1.1 -> 20350
A24: Corrimão metálico (inox) | D24: =((3.7*2+2.6*2)*1.2+2.3)*5+(3.9+3.2+2.16*2)*1.2+2.17 -> 102.974 | E24: m | F24: 150 | G24: =F24*D24*1.1 -> 16990.71
A25: Portas aluminio | D25: =11+1+2+2+1 -> 17 | E25: un | F25: 850 | G25: =F25*D25*1.1 -> 15895
A26: Esquadrias de Madeira Isolantes | D26: =DADOS_INICIAIS!E21+2 -> 38 | E26: un | F26: 9662.1 | G26: =F26*D26*1.1 -> 403875.78
A27: Esquadrias de Madeira | D27: =D29+3+5+2+6+6+1+9+1+1+2+1 -> 73 | E27: un | F27: 6725.26 | G27: =F27*D27*1.1 -> 540038.38
A28: Esquadrias de Madeira correr | D28: =2+2 -> 4 | E28: un | F28: 11863 | G28: =F28*D28*1.1 -> 52197.2
A29: Fechadura biométrica | D29: =DADOS_INICIAIS!E21 -> 36 | E29: un | F29: =G29/D29 -> 1445.1706 | G29: =52026.14 -> 52026.14 | H29: Conforme porposta Onity, prevendo todos os equipamentos e licença
A30: Fechadura esquadria interna | D30: =D27+D26-D29 -> 75 | E30: un | F30: 394.66 | G30: =F30*D30*1.1 -> 32559.45
A31: Fechadura correr | D31: =2+2 -> 4 | E31: un | F31: =425+213.97 -> 638.97 | G31: =F31*D31*1.1 -> 2811.468 | H31: Fecho + puxador
A32: MO portas | D32: =SUM(D26:D28) -> 115 | E32: un | F32: 150 | G32: =F32*D32*1.1 -> 18975 | H32: Fecho + puxador
A33: TOTAL | G33: =SUM(G10:G32) -> 10170063 | K33: =4160+1440+1120+2880+4800+91680+4000 -> 110080 | L33: =K33/21 -> 5241.9048
A35: TOTAL ESQUADRIAS | G35: =G33 -> 10170063 | H35: =G35/DADOS_INICIAIS!E9 -> 1681.2328
