Workbook

Sheet DISTRIBUIÇÃO PRAZO
B2: ORÇAMENTO PARAMÉTRICO | ESTIMATIVA DE PRAZO
B4: Colline de France
B7: HOTEL
B8: SERVIÇO | C8: M1 | D8: M2 | E8: M3 | F8: M4 | G8: M5 | H8: M6 | I8: M7 | J8: M8 | K8: M9 | L8: M10 | M8: M11 | N8: M12 | O8: M13 | P8: M14 | Q8: M15 | R8: M16 | S8: M17 | T8: M18 | U8: M19 | V8: M20 | W8: M21 | X8: M22 | Y8: M23 | Z8: M24 | AA8: M25 | AB8: M26 | AC8: M27 | AD8: M28 | AE8: M29 | AF8: M30 | AG8: M31 | AH8: M32 | AI8: M33 | AJ8: M34 | AK8: M35 | AL8: M36 | AM8: M37 | AN8: M38 | AO8: M39 | AP8: M40 | AQ8: M41 | AR8: M42
I9: M1 | J9: M2 | K9: M3 | L9: M4 | M9: M5 | N9: M6 | O9: M7 | P9: M8 | Q9: M9 | R9: M10 | S9: M11 | T9: M12 | U9: M13 | V9: M14 | W9: M15 | X9: M16 | Y9: M17 | Z9: M18 | AA9: M19 | AB9: M20 | AC9: M21 | AD9: M22 | AE9: M23 | AF9: M24
C10: 45658 | D10: 45689 | E10: 45717 | F10: 45748 | G10: 45778 | H10: 45809 | I10: 45839 | J10: 45870 | K10: 45901 | L10: 45931 | M10: 45962 | N10: 45992 | O10: 46023 | P10: 46054 | Q10: 46082 | R10: 46113 | S10: 46143 | T10: 46174 | U10: 46204 | V10: 46235 | W10: 46266 | X10: 46296 | Y10: 46327 | Z10: 46357 | AA10: 46388 | AB10: 46419 | AC10: 46447 | AD10: 46478 | AE10: 46508 | AF10: 46539 | AG10: 46569 | AH10: 46600 | AI10: 46631 | AJ10: 46661 | AK10: 46692 | AL10: 46722 | AM10: 46753 | AN10: 46784 | AO10: 46813 | AP10: 46844 | AQ10: 46874 | AR10: 47543
B11: MOVIMENTAÇÃO DE TERRA
B12: INFRAESTRUTURA | I12: 1 | J12: 2 | K12: 3
B13: SUPRAESTRUTURA | L13: 1 | M13: 2 | N13: 3 | O13: 4 | P13: 5 | Q13: 6 | R13: 7 | S13: 8
A14: SUPRAESTRUTURA - TORRE 2 | B14: ALVENARIA | N14: 1 | O14: 1 | P14: 1 | Q14: 1 | R14: 1 | S14: 1 | T14: 1 | U14: 2
B15: INSTALAÇÕES ELÉTRICAS, HIDRÁULICAS, GLP E PREVENTIVAS | O15: 1 | P15: 1 | Q15: 1 | R15: 1 | S15: 1 | T15: 1 | U15: 1 | V15: 1 | W15: 2
B16: EQUIPAMENTOS E SISTEMAS ESPECIAIS | V16: 1 | W16: 2 | X16: 3 | Y16: 4
B17: IMPERMEABILIZAÇÃO | Q17: 1 | R17: 1 | S17: 1 | T17: 1 | U17: 1 | V17: 1 | W17: 1 | X17: 1 | Y17: 1 | Z17: 1
B18: REVESTIMENTOS INTERNOS EM PISO E PAREDE | P18: 1 | Q18: 1 | R18: 1 | S18: 1 | T18: 1 | U18: 1 | V18: 1 | W18: 1 | X18: 1 | Y18: 1
B19: REVESTIMENTOS E ACABAMENTOS INTERNOS EM TETO | S19: 1 | T19: 1 | U19: 1 | V19: 1 | W19: 1 | X19: 1 | Y19: 1 | Z19: 1 | AA19: 1
B20: ACABAMENTOS EM PISO E PAREDE | R20: 1 | S20: 1 | T20: 1 | U20: 1 | V20: 1 | W20: 1 | X20: 1 | Y20: 1 | Z20: 1 | AA20: 1 | AB20: 1
B21: PINTURA INTERNA | T21: 1 | U21: 1 | V21: 1 | W21: 1 | X21: 1 | Y21: 1 | Z21: 1 | AA21: 1 | AB21: 1 | AC21: 1 | AD21: 1 | AE21: 1
B22: ESQUADRIAS, VIDROS E FERRAGENS | W22: 1 | X22: 2 | Y22: 3 | Z22: 4 | AA22: 5 | AB22: 6 | AC22: 7 | AD22: 8
B23: COBERTURA | X23: 1 | Y23: 2 | Z23: 3 | AA23: 4
B24: REVESTIMENTOS E ACABAMENTOS DE FACHADA | T24: 1 | U24: 2 | V24: 3 | W24: 4 | X24: 5 | Y24: 6 | Z24: 7 | AA24: 8
B25: SERVIÇOS COMPLEMENTARES | Y25: 6 | Z25: 6 | AA25: 6 | AB25: 7 | AC25: 8 | AD25: 9 | AE25: 10 | AF25: 11
B27: TORRES
B28: SERVIÇO | C28: M1 | D28: M2 | E28: M3 | F28: M4 | G28: M5 | H28: M6 | I28: M7 | J28: M8 | K28: M9 | L28: M10 | M28: M11 | N28: M12 | O28: M13 | P28: M14 | Q28: M15 | R28: M16 | S28: M17 | T28: M18 | U28: M19 | V28: M20 | W28: M21 | X28: M22 | Y28: M23 | Z28: M24 | AA28: M25 | AB28: M26 | AC28: M27 | AD28: M28 | AE28: M29 | AF28: M30 | AG28: M31 | AH28: M32 | AI28: M33 | AJ28: M34 | AK28: M35 | AL28: M36 | AM28: M37 | AN28: M38 | AO28: M39 | AP28: M40 | AQ28: M41 | AR28: M42
I29: M1 | J29: M2 | K29: M3 | L29: M4 | M29: M5 | N29: M6 | O29: M7 | P29: M8 | Q29: M9 | R29: M10 | S29: M11 | T29: M12 | U29: M13 | V29: M14 | W29: M15 | X29: M16 | Y29: M17 | Z29: M18 | AA29: M19 | AB29: M20 | AC29: M21 | AD29: M22 | AE29: M23 | AF29: M24 | AG29: M25 | AH29: M26 | AI29: M27 | AJ29: M28 | AK29: M29 | AL29: M30 | AM29: M31 | AN29: M32 | AO29: M33 | AP29: M34 | AQ29: M35 | AR29: M36
C30: =C10 -> 45658 | D30: =D10 -> 45689 | E30: =E10 -> 45717 | F30: =F10 -> 45748 | G30: =G10 -> 45778 | H30: =H10 -> 45809 | I30: =I10 -> 45839 | J30: =J10 -> 45870 | ... AR30: =AR10 -> 47543
B31: MOVIMENTAÇÃO DE TERRA
B32: INFRAESTRUTURA | I32: 1 | J32: 2 | K32: 3 | L32: 4
B33: SUPRAESTRUTURA - EMBASAMENTO
B34: SUPRAESTRUTURA - TORRE 1 | V34: 1 | W34: 2 | X34: 3 | Y34: 4 | Z34: 5 | AA34: 6 | AB34: 7 | AC34: 8 | AD34: 9
B35: SUPRAESTRUTURA - TORRE 2 | V35: 1 | W35: 2 | X35: 3 | Y35: 4 | Z35: 5 | AA35: 6 | AB35: 7 | AC35: 8 | AD35: 9
B36: ALVENARIA | R36: 1 | S36: 1 | T36: 1 | U36: 1 | V36: 1 | W36: 1 | X36: 1 | Y36: 1 | Z36: 1 | AA36: 1 | AB36: 1 | AC36: 1 | AD36: 1 | AE36: 1 | AF36: 2
B37: INSTALAÇÕES ELÉTRICAS, HIDRÁULICAS, GLP E PREVENTIVAS | T37: 2 | U37: 2 | V37: 2 | W37: 2 | X37: 2 | Y37: 2 | Z37: 2 | AA37: 2 | AB37: 2 | AC37: 2 | AD37: 2 | AE37: 2 | AF37: 2 | AG37: 2
B38: EQUIPAMENTOS E SISTEMAS ESPECIAIS | AG38: 1 | AH38: 2 | AI38: 3 | AJ38: 4 | AK38: 5
B39: IMPERMEABILIZAÇÃO | V39: 2 | W39: 2 | X39: 2 | Y39: 2 | Z39: 2 | AA39: 2 | AB39: 2 | AC39: 2 | AD39: 2 | AE39: 2 | AF39: 2 | AG39: 2 | AH39: 2 | AI39: 2
B40: REVESTIMENTOS INTERNOS EM PISO E PAREDE | U40: 2 | V40: 2 | W40: 2 | X40: 2 | Y40: 2 | Z40: 2 | AA40: 2 | AB40: 2 | AC40: 2 | AD40: 2 | AE40: 2 | AF40: 2 | AG40: 2 | AH40: 2
B41: REVESTIMENTOS E ACABAMENTOS INTERNOS EM TETO | X41: 2 | Y41: 2 | Z41: 2 | AA41: 2 | AB41: 2 | AC41: 2 | AD41: 2 | AE41: 2 | AF41: 2 | AG41: 2 | AH41: 2 | AI41: 2 | AJ41: 2
B42: ACABAMENTOS EM PISO E PAREDE | W42: 2 | X42: 2 | Y42: 2 | Z42: 2 | AA42: 2 | AB42: 2 | AC42: 2 | AD42: 2 | AE42: 2 | AF42: 2 | AG42: 2 | AH42: 2 | AI42: 2 | AJ42: 2 | AK42: 2 | AL42: 2 | AM42: 2
B43: PINTURA INTERNA | Y43: 2 | Z43: 2 | AA43: 2 | AB43: 2 | AC43: 2 | AD43: 2 | AE43: 2 | AF43: 2 | AG43: 2 | AH43: 2 | AI43: 2 | AJ43: 2 | AK43: 2 | AL43: 2 | AM43: 2 | AN43: 2 | AO43: 2 | AP43: 2
B44: ESQUADRIAS, VIDROS E FERRAGENS | AH44: 2 | AI44: 3 | AJ44: 4 | AK44: 5 | AL44: 6 | AM44: 7 | AN44: 8 | AO44: 9
B45: COBERTURA | AK45: 9 | AL45: 10 | AM45: 11
...

Sheet DISTRIBUIÇÃO CUSTO
B2: ORÇAMENTO PARAMÉTRICO | DISTRIBUIÇÃO MENSAL DE CUSTOS
B7: ETAPA | C7: VALOR ORÇADO | D7: % | E7: VALOR / m² | G7: M1 | I7: M2 | K7: M3 | M7: M4 | O7: M5 | Q7: M6 | S7: M7 | U7: M8 | W7: M9 | Y7: M10 | AA7: M11 | AC7: M12 | AE7: M13 | AG7: M14 | AI7: M15 | AK7: M16 | AM7: M17 | AO7: M18 | AQ7: M19 | AS7: M20 | AU7: M21 | AW7: M22 | AY7: M23 | BA7: M24 | BC7: M25 | BE7: M26 | BG7: M27 | BI7: M28 | BK7: M29 | BM7: M30 | BO7: M31 | BQ7: M32 | BS7: M33 | BU7: M34 | BW7: M35 | BY7: M36 | CA7: M37 | CC7: M38 | CE7: M39 | CG7: M40 | CI7: M41 | CK7: M42 | CM7: M43 | CO7: M44 | CQ7: M45 | CS7: M46 | CU7: M47 | CW7: M48 | CY7: M49 | DA7: M50 | DC7: M51 | DE7: M52 | DG7: M53 | DI7: M54 | DK7: M55 | DM7: M56 | DO7: M57 | DQ7: M58 | DS7: M59 | DU7: M60 | DW7: M61 | DY7: M62 | EA7: M63
G8: % | H8: R$ | I8: % | J8: R$ | K8: % | L8: R$ | M8: % | N8: R$ | O8: % | P8: R$ | Q8: % | R8: R$ | S8: % | T8: R$ | U8: % | V8: R$ | W8: % | X8: R$ | Y8: % | Z8: R$ | AA8: % | AB8: R$ | AC8: % | AD8: R$ | AE8: % | AF8: R$ | AG8: % | AH8: R$ | AI8: % | AJ8: R$ | AK8: % | AL8: R$ | AM8: % | AN8: R$ | AO8: % | AP8: R$ | AQ8: % | AR8: R$ | AS8: % | AT8: R$ | AU8: % | AV8: R$ | AW8: % | AX8: R$ | AY8: % | AZ8: R$ | BA8: % | BB8: R$ | BC8: % | BD8: R$ | BE8: % | BF8: R$ | BG8: % | BH8: R$ | BI8: % | BJ8: R$ | BK8: % | BL8: R$ | BM8: % | BN8: R$ | BO8: % | BP8: R$ | BQ8: % | BR8: R$ | BS8: % | BT8: R$ | BU8: % | BV8: R$ | BW8: % | BX8: R$ | BY8: % | BZ8: R$ | CA8: % | CB8: R$ | CC8: % | CD8: R$ | CE8: % | CF8: R$ | CG8: % | CH8: R$ | CI8: % | CJ8: R$ | CK8: % | CL8: R$ | CM8: % | CN8: R$ | CO8: % | CP8: R$ | CQ8: % | CR8: R$ | CS8: % | CT8: R$ | CU8: % | CV8: R$ | CW8: % | CX8: R$ | CY8: % | CZ8: R$ | DA8: % | DB8: R$ | DC8: % | DD8: R$ | DE8: % | DF8: R$ | DG8: % | DH8: R$ | DI8: % | DJ8: R$ | DK8: % | DL8: R$ | DM8: % | DN8: R$ | DO8: % | DP8: R$ | DQ8: % | DR8: R$ | DS8: % | DT8: R$ | DU8: % | DV8: R$ | DW8: % | DX8: R$ | DY8: % | DZ8: R$ | EA8: % | EB8: R$
D9: =C9/$C$26 -> #DIV/0! | E9: =C9/'DISTRIBUIÇÃO CUSTO'!C$31 -> #DIV/0! | H9: =$C9*G9 -> 0 | J9: =$C9*I9 -> 0 | L9: =$C9*K9 -> 0 | N9: =$C9*M9 -> 0 | P9: =$C9*O9 -> 0 | R9: =$C9*Q9 -> 0 | T9: =$C9*S9 -> 0 | V9: =$C9*U9 -> 0 | X9: =$C9*W9 -> 0 | Z9: =$C9*Y9 -> 0 | AB9: =$C9*AA9 -> 0 | AD9: =$C9*AC9 -> 0 | AF9: =$C9*AE9 -> 0 | AH9: =$C9*AG9 -> 0 | AJ9: =$C9*AI9 -> 0 | AL9: =$C9*AK9 -> 0 | AN9: =$C9*AM9 -> 0 | AP9: =$C9*AO9 -> 0 | AR9: =$C9*AQ9 -> 0 | AT9: =$C9*AS9 -> 0 | AV9: =$C9*AU9 -> 0 | AX9: =$C9*AW9 -> 0 | AZ9: =$C9*AY9 -> 0 | BB9: =$C9*BA9 -> 0 | BD9: =$C9*BC9 -> 0 | BF9: =$C9*BE9 -> 0 | BH9: =$C9*BG9 -> 0 | BJ9: =$C9*BI9 -> 0 | BL9: =$C9*BK9 -> 0 | BN9: =$C9*BM9 -> 0 | BP9: =$C9*BO9 -> 0 | BR9: =$C9*BQ9 -> 0 | BT9: =$C9*BS9 -> 0 | BV9: =$C9*BU9 -> 0 | BX9: =$C9*BW9 -> 0 | BZ9: =$C9*BY9 -> 0 | CB9: =$C9*CA9 -> 0 | CD9: =$C9*CC9 -> 0 | CF9: =$C9*CE9 -> 0 | CH9: =$C9*CG9 -> 0 | CJ9: =$C9*CI9 -> 0 | CL9: =$C9*CK9 -> 0 | CN9: =$C9*CM9 -> 0 | CP9: =$C9*CO9 -> 0 | CR9: =$C9*CQ9 -> 0 | CT9: =$C9*CS9 -> 0 | CV9: =$C9*CU9 -> 0 | CX9: =$C9*CW9 -> 0 | CZ9: =$C9*CY9 -> 0 | DB9: =$C9*DA9 -> 0 | DD9: =$C9*DC9 -> 0 | DF9: =$C9*DE9 -> 0 | DH9: =$C9*DG9 -> 0 | DJ9: =$C9*DI9 -> 0 | DL9: =$C9*DK9 -> 0 | DN9: =$C9*DM9 -> 0 | DP9: =$C9*DO9 -> 0 | DR9: =$C9*DQ9 -> 0 | DT9: =$C9*DS9 -> 0 | DV9: =$C9*DU9 -> 0 | DX9: =$C9*DW9 -> 0 | DZ9: =$C9*DY9 -> 0 | EB9: =$C9*EA9 -> 0
D10: =C10/$C$26 -> #DIV/0! | E10: =C10/'DISTRIBUIÇÃO CUSTO'!C$31 -> #DIV/0! | H10: =$C10*G10 -> 0 | J10: =$C10*I10 -> 0 | L10: =$C10*K10 -> 0 | N10: =$C10*M10 -> 0 | P10: =$C10*O10 -> 0 | R10: =$C10*Q10 -> 0 | T10: =$C10*S10 -> 0 | V10: =$C10*U10 -> 0 | X10: =$C10*W10 -> 0 | Z10: =$C10*Y10 -> 0 | AB10: =$C10*AA10 -> 0 | AD10: =$C10*AC10 -> 0 | AF10: =$C10*AE10 -> 0 | AH10: =$C10*AG10 -> 0 | AJ10: =$C10*AI10 -> 0 | AL10: =$C10*AK10 -> 0 | AN10: =$C10*AM10 -> 0 | AP10: =$C10*AO10 -> 0 | AR10: =$C10*AQ10 -> 0 | AT10: =$C10*AS10 -> 0 | AV10: =$C10*AU10 -> 0 | AX10: =$C10*AW10 -> 0 | AZ10: =$C10*AY10 -> 0 | BB10: =$C10*BA10 -> 0 | BD10: =$C10*BC10 -> 0 | BF10: =$C10*BE10 -> 0 | BH10: =$C10*BG10 -> 0 | BJ10: =$C10*BI10 -> 0 | BL10: =$C10*BK10 -> 0 | BN10: =$C10*BM10 -> 0 | BP10: =$C10*BO10 -> 0 | BR10: =$C10*BQ10 -> 0 | BT10: =$C10*BS10 -> 0 | BV10: =$C10*BU10 -> 0 | BX10: =$C10*BW10 -> 0 | BZ10: =$C10*BY10 -> 0 | CB10: =$C10*CA10 -> 0 | CD10: =$C10*CC10 -> 0 | CF10: =$C10*CE10 -> 0 | CH10: =$C10*CG10 -> 0 | CJ10: =$C10*CI10 -> 0 | CL10: =$C10*CK10 -> 0 | CN10: =$C10*CM10 -> 0 | CP10: =$C10*CO10 -> 0 | CR10: =$C10*CQ10 -> 0 | CT10: =$C10*CS10 -> 0 | CV10: =$C10*CU10 -> 0 | CX10: =$C10*CW10 -> 0 | CZ10: =$C10*CY10 -> 0 | DB10: =$C10*DA10 -> 0 | DD10: =$C10*DC10 -> 0 | DF10: =$C10*DE10 -> 0 | DH10: =$C10*DG10 -> 0 | DJ10: =$C10*DI10 -> 0 | DL10: =$C10*DK10 -> 0 | DN10: =$C10*DM10 -> 0 | DP10: =$C10*DO10 -> 0 | DR10: =$C10*DQ10 -> 0 | DT10: =$C10*DS10 -> 0 | DV10: =$C10*DU10 -> 0 | DX10: =$C10*DW10 -> 0 | DZ10: =$C10*DY10 -> 0 | EB10: =$C10*EA10 -> 0
D11: =C11/$C$26 -> #DIV/0! | E11: =C11/'DISTRIBUIÇÃO CUSTO'!C$31 -> #DIV/0! | H11: =$C11*G11 -> 0 | J11: =$C11*I11 -> 0 | L11: =$C11*K11 -> 0 | N11: =$C11*M11 -> 0 | P11: =$C11*O11 -> 0 | R11: =$C11*Q11 -> 0 | T11: =$C11*S11 -> 0 | V11: =$C11*U11 -> 0 | X11: =$C11*W11 -> 0 | Z11: =$C11*Y11 -> 0 | AB11: =$C11*AA11 -> 0 | AD11: =$C11*AC11 -> 0 | AF11: =$C11*AE11 -> 0 | AH11: =$C11*AG11 -> 0 | AJ11: =$C11*AI11 -> 0 | AL11: =$C11*AK11 -> 0 | AN11: =$C11*AM11 -> 0 | AP11: =$C11*AO11 -> 0 | AR11: =$C11*AQ11 -> 0 | AT11: =$C11*AS11 -> 0 | AV11: =$C11*AU11 -> 0 | AX11: =$C11*AW11 -> 0 | AZ11: =$C11*AY11 -> 0 | BB11: =$C11*BA11 -> 0 | BD11: =$C11*BC11 -> 0 | BF11: =$C11*BE11 -> 0 | BH11: =$C11*BG11 -> 0 | BJ11: =$C11*BI11 -> 0 | BL11: =$C11*BK11 -> 0 | BN11: =$C11*BM11 -> 0 | BP11: =$C11*BO11 -> 0 | BR11: =$C11*BQ11 -> 0 | BT11: =$C11*BS11 -> 0 | BV11: =$C11*BU11 -> 0 | BX11: =$C11*BW11 -> 0 | BZ11: =$C11*BY11 -> 0 | CB11: =$C11*CA11 -> 0 | CD11: =$C11*CC11 -> 0 | CF11: =$C11*CE11 -> 0 | CH11: =$C11*CG11 -> 0 | CJ11: =$C11*CI11 -> 0 | CL11: =$C11*CK11 -> 0 | CN11: =$C11*CM11 -> 0 | CP11: =$C11*CO11 -> 0 | CR11: =$C11*CQ11 -> 0 | CT11: =$C11*CS11 -> 0 | CV11: =$C11*CU11 -> 0 | CX11: =$C11*CW11 -> 0 | CZ11: =$C11*CY11 -> 0 | DB11: =$C11*DA11 -> 0 | DD11: =$C11*DC11 -> 0 | DF11: =$C11*DE11 -> 0 | DH11: =$C11*DG11 -> 0 | DJ11: =$C11*DI11 -> 0 | DL11: =$C11*DK11 -> 0 | DN11: =$C11*DM11 -> 0 | DP11: =$C11*DO11 -> 0 | DR11: =$C11*DQ11 -> 0 | DT11: =$C11*DS11 -> 0 | DV11: =$C11*DU11 -> 0 | DX11: =$C11*DW11 -> 0 | DZ11: =$C11*DY11 -> 0 | EB11: =$C11*EA11 -> 0
D12: =C12/$C$26 -> #DIV/0! | E12: =C12/'DISTRIBUIÇÃO CUSTO'!C$31 -> #DIV/0! | H12: =$C12*G12 -> 0 | J12: =$C12*I12 -> 0 | L12: =$C12*K12 -> 0 | N12: =$C12*M12 -> 0 | P12: =$C12*O12 -> 0 | R12: =$C12*Q12 -> 0 | T12: =$C12*S12 -> 0 | V12: =$C12*U12 -> 0 | X12: =$C12*W12 -> 0 | Z12: =$C12*Y12 -> 0 | AB12: =$C12*AA12 -> 0 | AD12: =$C12*AC12 -> 0 | AF12: =$C12*AE12 -> 0 | AH12: =$C12*AG12 -> 0 | AJ12: =$C12*AI12 -> 0 | AL12: =$C12*AK12 -> 0 | AN12: =$C12*AM12 -> 0 | AP12: =$C12*AO12 -> 0 | AR12: =$C12*AQ12 -> 0 | AT12: =$C12*AS12 -> 0 | AV12: =$C12*AU12 -> 0 | AX12: =$C12*AW12 -> 0 | AZ12: =$C12*AY12 -> 0 | BB12: =$C12*BA12 -> 0 | BD12: =$C12*BC12 -> 0 | BF12: =$C12*BE12 -> 0 | BH12: =$C12*BG12 -> 0 | BJ12: =$C12*BI12 -> 0 | BL12: =$C12*BK12 -> 0 | BN12: =$C12*BM12 -> 0 | BP12: =$C12*BO12 -> 0 | BR12: =$C12*BQ12 -> 0 | BT12: =$C12*BS12 -> 0 | BV12: =$C12*BU12 -> 0 | BX12: =$C12*BW12 -> 0 | BZ12: =$C12*BY12 -> 0 | CB12: =$C12*CA12 -> 0 | CD12: =$C12*CC12 -> 0 | CF12: =$C12*CE12 -> 0 | CH12: =$C12*CG12 -> 0 | CJ12: =$C12*CI12 -> 0 | CL12: =$C12*CK12 -> 0 | CN12: =$C12*CM12 -> 0 | CP12: =$C12*CO12 -> 0 | CR12: =$C12*CQ12 -> 0 | CT12: =$C12*CS12 -> 0 | CV12: =$C12*CU12 -> 0 | CX12: =$C12*CW12 -> 0 | CZ12: =$C12*CY12 -> 0 | DB12: =$C12*DA12 -> 0 | DD12: =$C12*DC12 -> 0 | DF12: =$C12*DE12 -> 0 | DH12: =$C12*DG12 -> 0 | DJ12: =$C12*DI12 -> 0 | DL12: =$C12*DK12 -> 0 | DN12: =$C12*DM12 -> 0 | DP12: =$C12*DO12 -> 0 | DR12: =$C12*DQ12 -> 0 | DT12: =$C12*DS12 -> 0 | DV12: =$C12*DU12 -> 0 | DX12: =$C12*DW12 -> 0 | DZ12: =$C12*DY12 -> 0 | EB12: =$C12*EA12 -> 0
D13: =C13/$C$26 -> #DIV/0! | E13: =C13/'DISTRIBUIÇÃO CUSTO'!C$31 -> #DIV/0! | H13: =$C13*G13 -> 0 | J13: =$C13*I13 -> 0 | L13: =$C13*K13 -> 0 | N13: =$C13*M13 -> 0 | P13: =$C13*O13 -> 0 | R13: =$C13*Q13 -> 0 | T13: =$C13*S13 -> 0 | V13: =$C13*U13 -> 0 | X13: =$C13*W13 -> 0 | Z13: =$C13*Y13 -> 0 | AB13: =$C13*AA13 -> 0 | AD13: =$C13*AC13 -> 0 | AF13: =$C13*AE13 -> 0 | AH13: =$C13*AG13 -> 0 | AJ13: =$C13*AI13 -> 0 | AL13: =$C13*AK13 -> 0 | AN13: =$C13*AM13 -> 0 | AP13: =$C13*AO13 -> 0 | AR13: =$C13*AQ13 -> 0 | AT13: =$C13*AS13 -> 0 | AV13: =$C13*AU13 -> 0 | AX13: =$C13*AW13 -> 0 | AZ13: =$C13*AY13 -> 0 | BB13: =$C13*BA13 -> 0 | BD13: =$C13*BC13 -> 0 | BF13: =$C13*BE13 -> 0 | BH13: =$C13*BG13 -> 0 | BJ13: =$C13*BI13 -> 0 | BL13: =$C13*BK13 -> 0 | BN13: =$C13*BM13 -> 0 | BP13: =$C13*BO13 -> 0 | BR13: =$C13*BQ13 -> 0 | BT13: =$C13*BS13 -> 0 | BV13: =$C13*BU13 -> 0 | BX13: =$C13*BW13 -> 0 | BZ13: =$C13*BY13 -> 0 | CB13: =$C13*CA13 -> 0 | CD13: =$C13*CC13 -> 0 | CF13: =$C13*CE13 -> 0 | CH13: =$C13*CG13 -> 0 | CJ13: =$C13*CI13 -> 0 | CL13: =$C13*CK13 -> 0 | CN13: =$C13*CM13 -> 0 | CP13: =$C13*CO13 -> 0 | CR13: =$C13*CQ13 -> 0 | CT13: =$C13*CS13 -> 0 | CV13: =$C13*CU13 -> 0 | CX13: =$C13*CW13 -> 0 | CZ13: =$C13*CY13 -> 0 | DB13: =$C13*DA13 -> 0 | DD13: =$C13*DC13 -> 0 | DF13: =$C13*DE13 -> 0 | DH13: =$C13*DG13 -> 0 | DJ13: =$C13*DI13 -> 0 | DL13: =$C13*DK13 -> 0 | DN13: =$C13*DM13 -> 0 | DP13: =$C13*DO13 -> 0 | DR13: =$C13*DQ13 -> 0 | DT13: =$C13*DS13 -> 0 | DV13: =$C13*DU13 -> 0 | DX13: =$C13*DW13 -> 0 | DZ13: =$C13*DY13 -> 0 | EB13: =$C13*EA13 -> 0
D14: =C14/$C$26 -> #DIV/0! | E14: =C14/'DISTRIBUIÇÃO CUSTO'!C$31 -> #DIV/0! | H14: =$C14*G14 -> 0 | J14: =$C14*I14 -> 0 | L14: =$C14*K14 -> 0 | N14: =$C14*M14 -> 0 | P14: =$C14*O14 -> 0 | R14: =$C14*Q14 -> 0 | T14: =$C14*S14 -> 0 | V14: =$C14*U14 -> 0 | X14: =$C14*W14 -> 0 | Z14: =$C14*Y14 -> 0 | AB14: =$C14*AA14 -> 0 | AD14: =$C14*AC14 -> 0 | AF14: =$C14*AE14 -> 0 | AH14: =$C14*AG14 -> 0 | AJ14: =$C14*AI14 -> 0 | AL14: =$C14*AK14 -> 0 | AN14: =$C14*AM14 -> 0 | AP14: =$C14*AO14 -> 0 | AR14: =$C14*AQ14 -> 0 | AT14: =$C14*AS14 -> 0 | AV14: =$C14*AU14 -> 0 | AX14: =$C14*AW14 -> 0 | AZ14: =$C14*AY14 -> 0 | BB14: =$C14*BA14 -> 0 | BD14: =$C14*BC14 -> 0 | BF14: =$C14*BE14 -> 0 | BH14: =$C14*BG14 -> 0 | BJ14: =$C14*BI14 -> 0 | BL14: =$C14*BK14 -> 0 | BN14: =$C14*BM14 -> 0 | BP14: =$C14*BO14 -> 0 | BR14: =$C14*BQ14 -> 0 | BT14: =$C14*BS14 -> 0 | BV14: =$C14*BU14 -> 0 | BX14: =$C14*BW14 -> 0 | BZ14: =$C14*BY14 -> 0 | CB14: =$C14*CA14 -> 0 | CD14: =$C14*CC14 -> 0 | CF14: =$C14*CE14 -> 0 | CH14: =$C14*CG14 -> 0 | CJ14: =$C14*CI14 -> 0 | CL14: =$C14*CK14 -> 0 | CN14: =$C14*CM14 -> 0 | CP14: =$C14*CO14 -> 0 | CR14: =$C14*CQ14 -> 0 | CT14: =$C14*CS14 -> 0 | CV14: =$C14*CU14 -> 0 | CX14: =$C14*CW14 -> 0 | CZ14: =$C14*CY14 -> 0 | DB14: =$C14*DA14 -> 0 | DD14: =$C14*DC14 -> 0 | DF14: =$C14*DE14 -> 0 | DH14: =$C14*DG14 -> 0 | DJ14: =$C14*DI14 -> 0 | DL14: =$C14*DK14 -> 0 | DN14: =$C14*DM14 -> 0 | DP14: =$C14*DO14 -> 0 | DR14: =$C14*DQ14 -> 0 | DT14: =$C14*DS14 -> 0 | DV14: =$C14*DU14 -> 0 | DX14: =$C14*DW14 -> 0 | DZ14: =$C14*DY14 -> 0 | EB14: =$C14*EA14 -> 0
D15: =C15/$C$26 -> #DIV/0! | E15: =C15/'DISTRIBUIÇÃO CUSTO'!C$31 -> #DIV/0! | H15: =$C15*G15 -> 0 | J15: =$C15*I15 -> 0 | L15: =$C15*K15 -> 0 | N15: =$C15*M15 -> 0 | P15: =$C15*O15 -> 0 | R15: =$C15*Q15 -> 0 | T15: =$C15*S15 -> 0 | V15: =$C15*U15 -> 0 | X15: =$C15*W15 -> 0 | Z15: =$C15*Y15 -> 0 | AB15: =$C15*AA15 -> 0 | AD15: =$C15*AC15 -> 0 | AF15: =$C15*AE15 -> 0 | AH15: =$C15*AG15 -> 0 | AJ15: =$C15*AI15 -> 0 | AL15: =$C15*AK15 -> 0 | AN15: =$C15*AM15 -> 0 | AP15: =$C15*AO15 -> 0 | AR15: =$C15*AQ15 -> 0 | AT15: =$C15*AS15 -> 0 | AV15: =$C15*AU15 -> 0 | AX15: =$C15*AW15 -> 0 | AZ15: =$C15*AY15 -> 0 | BB15: =$C15*BA15 -> 0 | BD15: =$C15*BC15 -> 0 | BF15: =$C15*BE15 -> 0 | BH15: =$C15*BG15 -> 0 | BJ15: =$C15*BI15 -> 0 | BL15: =$C15*BK15 -> 0 | BN15: =$C15*BM15 -> 0 | BP15: =$C15*BO15 -> 0 | BR15: =$C15*BQ15 -> 0 | BT15: =$C15*BS15 -> 0 | BV15: =$C15*BU15 -> 0 | BX15: =$C15*BW15 -> 0 | BZ15: =$C15*BY15 -> 0 | CB15: =$C15*CA15 -> 0 | CD15: =$C15*CC15 -> 0 | CF15: =$C15*CE15 -> 0 | CH15: =$C15*CG15 -> 0 | CJ15: =$C15*CI15 -> 0 | CL15: =$C15*CK15 -> 0 | CN15: =$C15*CM15 -> 0 | CP15: =$C15*CO15 -> 0 | CR15: =$C15*CQ15 -> 0 | CT15: =$C15*CS15 -> 0 | CV15: =$C15*CU15 -> 0 | CX15: =$C15*CW15 -> 0 | CZ15: =$C15*CY15 -> 0 | DB15: =$C15*DA15 -> 0 | DD15: =$C15*DC15 -> 0 | DF15: =$C15*DE15 -> 0 | DH15: =$C15*DG15 -> 0 | DJ15: =$C15*DI15 -> 0 | DL15: =$C15*DK15 -> 0 | DN15: =$C15*DM15 -> 0 | DP15: =$C15*DO15 -> 0 | DR15: =$C15*DQ15 -> 0 | DT15: =$C15*DS15 -> 0 | DV15: =$C15*DU15 -> 0 | DX15: =$C15*DW15 -> 0 | DZ15: =$C15*DY15 -> 0 | EB15: =$C15*EA15 -> 0
D16: =C16/$C$26 -> #DIV/0! | E16: =C16/'DISTRIBUIÇÃO CUSTO'!C$31 -> #DIV/0! | H16: =$C16*G16 -> 0 | J16: =$C16*I16 -> 0 | L16: =$C16*K16 -> 0 | N16: =$C16*M16 -> 0 | P16: =$C16*O16 -> 0 | R16: =$C16*Q16 -> 0 | T16: =$C16*S16 -> 0 | V16: =$C16*U16 -> 0 | X16: =$C16*W16 -> 0 | Z16: =$C16*Y16 -> 0 | AB16: =$C16*AA16 -> 0 | AD16: =$C16*AC16 -> 0 | AF16: =$C16*AE16 -> 0 | AH16: =$C16*AG16 -> 0 | AJ16: =$C16*AI16 -> 0 | AL16: =$C16*AK16 -> 0 | AN16: =$C16*AM16 -> 0 | AP16: =$C16*AO16 -> 0 | AR16: =$C16*AQ16 -> 0 | AT16: =$C16*AS16 -> 0 | AV16: =$C16*AU16 -> 0 | AX16: =$C16*AW16 -> 0 | AZ16: =$C16*AY16 -> 0 | BB16: =$C16*BA16 -> 0 | BD16: =$C16*BC16 -> 0 | BF16: =$C16*BE16 -> 0 | BH16: =$C16*BG16 -> 0 | BJ16: =$C16*BI16 -> 0 | BL16: =$C16*BK16 -> 0 | BN16: =$C16*BM16 -> 0 | BP16: =$C16*BO16 -> 0 | BR16: =$C16*BQ16 -> 0 | BT16: =$C16*BS16 -> 0 | BV16: =$C16*BU16 -> 0 | BX16: =$C16*BW16 -> 0 | BZ16: =$C16*BY16 -> 0 | CB16: =$C16*CA16 -> 0 | CD16: =$C16*CC16 -> 0 | CF16: =$C16*CE16 -> 0 | CH16: =$C16*CG16 -> 0 | CJ16: =$C16*CI16 -> 0 | CL16: =$C16*CK16 -> 0 | CN16: =$C16*CM16 -> 0 | CP16: =$C16*CO16 -> 0 | CR16: =$C16*CQ16 -> 0 | CT16: =$C16*CS16 -> 0 | CV16: =$C16*CU16 -> 0 | CX16: =$C16*CW16 -> 0 | CZ16: =$C16*CY16 -> 0 | DB16: =$C16*DA16 -> 0 | DD16: =$C16*DC16 -> 0 | DF16: =$C16*DE16 -> 0 | DH16: =$C16*DG16 -> 0 | DJ16: =$C16*DI16 -> 0 | DL16: =$C16*DK16 -> 0 | DN16: =$C16*DM16 -> 0 | DP16: =$C16*DO16 -> 0 | DR16: =$C16*DQ16 -> 0 | DT16: =$C16*DS16 -> 0 | DV16: =$C16*DU16 -> 0 | DX16: =$C16*DW16 -> 0 | DZ16: =$C16*DY16 -> 0 | EB16: =$C16*EA16 -> 0
D17: =C17/$C$26 -> #DIV/0! | E17: =C17/'DISTRIBUIÇÃO CUSTO'!C$31 -> #DIV/0! | H17: =$C17*G17 -> 0 | J17: =$C17*I17 -> 0 | L17: =$C17*K17 -> 0 | N17: =$C17*M17 -> 0 | P17: =$C17*O17 -> 0 | R17: =$C17*Q17 -> 0 | T17: =$C17*S17 -> 0 | V17: =$C17*U17 -> 0 | X17: =$C17*W17 -> 0 | Z17: =$C17*Y17 -> 0 | AB17: =$C17*AA17 -> 0 | AD17: =$C17*AC17 -> 0 | AF17: =$C17*AE17 -> 0 | AH17: =$C17*AG17 -> 0 | AJ17: =$C17*AI17 -> 0 | AL17: =$C17*AK17 -> 0 | AN17: =$C17*AM17 -> 0 | AP17: =$C17*AO17 -> 0 | AR17: =$C17*AQ17 -> 0 | AT17: =$C17*AS17 -> 0 | AV17: =$C17*AU17 -> 0 | AX17: =$C17*AW17 -> 0 | AZ17: =$C17*AY17 -> 0 | BB17: =$C17*BA17 -> 0 | BD17: =$C17*BC17 -> 0 | BF17: =$C17*BE17 -> 0 | BH17: =$C17*BG17 -> 0 | BJ17: =$C17*BI17 -> 0 | BL17: =$C17*BK17 -> 0 | BN17: =$C17*BM17 -> 0 | BP17: =$C17*BO17 -> 0 | BR17: =$C17*BQ17 -> 0 | BT17: =$C17*BS17 -> 0 | BV17: =$C17*BU17 -> 0 | BX17: =$C17*BW17 -> 0 | BZ17: =$C17*BY17 -> 0 | CB17: =$C17*CA17 -> 0 | CD17: =$C17*CC17 -> 0 | CF17: =$C17*CE17 -> 0 | CH17: =$C17*CG17 -> 0 | CJ17: =$C17*CI17 -> 0 | CL17: =$C17*CK17 -> 0 | CN17: =$C17*CM17 -> 0 | CP17: =$C17*CO17 -> 0 | CR17: =$C17*CQ17 -> 0 | CT17: =$C17*CS17 -> 0 | CV17: =$C17*CU17 -> 0 | CX17: =$C17*CW17 -> 0 | CZ17: =$C17*CY17 -> 0 | DB17: =$C17*DA17 -> 0 | DD17: =$C17*DC17 -> 0 | DF17: =$C17*DE17 -> 0 | DH17: =$C17*DG17 -> 0 | DJ17: =$C17*DI17 -> 0 | DL17: =$C17*DK17 -> 0 | DN17: =$C17*DM17 -> 0 | DP17: =$C17*DO17 -> 0 | DR17: =$C17*DQ17 -> 0 | DT17: =$C17*DS17 -> 0 | DV17: =$C17*DU17 -> 0 | DX17: =$C17*DW17 -> 0 | DZ17: =$C17*DY17 -> 0 | EB17: =$C17*EA17 -> 0
D18: =C18/$C$26 -> #DIV/0! | E18: =C18/'DISTRIBUIÇÃO CUSTO'!C$31 -> #DIV/0! | H18: =$C18*G18 -> 0 | J18: =$C18*I18 -> 0 | L18: =$C18*K18 -> 0 | N18: =$C18*M18 -> 0 | P18: =$C18*O18 -> 0 | R18: =$C18*Q18 -> 0 | T18: =$C18*S18 -> 0 | V18: =$C18*U18 -> 0 | X18: =$C18*W18 -> 0 | Z18: =$C18*Y18 -> 0 | AB18: =$C18*AA18 -> 0 | AD18: =$C18*AC18 -> 0 | AF18: =$C18*AE18 -> 0 | AH18: =$C18*AG18 -> 0 | AJ18: =$C18*AI18 -> 0 | AL18: =$C18*AK18 -> 0 | AN18: =$C18*AM18 -> 0 | AP18: =$C18*AO18 -> 0 | AR18: =$C18*AQ18 -> 0 | AT18: =$C18*AS18 -> 0 | AV18: =$C18*AU18 -> 0 | AX18: =$C18*AW18 -> 0 | AZ18: =$C18*AY18 -> 0 | BB18: =$C18*BA18 -> 0 | BD18: =$C18*BC18 -> 0 | BF18: =$C18*BE18 -> 0 | BH18: =$C18*BG18 -> 0 | BJ18: =$C18*BI18 -> 0 | BL18: =$C18*BK18 -> 0 | BN18: =$C18*BM18 -> 0 | BP18: =$C18*BO18 -> 0 | BR18: =$C18*BQ18 -> 0 | BT18: =$C18*BS18 -> 0 | BV18: =$C18*BU18 -> 0 | BX18: =$C18*BW18 -> 0 | BZ18: =$C18*BY18 -> 0 | CB18: =$C18*CA18 -> 0 | CD18: =$C18*CC18 -> 0 | CF18: =$C18*CE18 -> 0 | CH18: =$C18*CG18 -> 0 | CJ18: =$C18*CI18 -> 0 | CL18: =$C18*CK18 -> 0 | CN18: =$C18*CM18 -> 0 | CP18: =$C18*CO18 -> 0 | CR18: =$C18*CQ18 -> 0 | CT18: =$C18*CS18 -> 0 | CV18: =$C18*CU18 -> 0 | CX18: =$C18*CW18 -> 0 | CZ18: =$C18*CY18 -> 0 | DB18: =$C18*DA18 -> 0 | DD18: =$C18*DC18 -> 0 | DF18: =$C18*DE18 -> 0 | DH18: =$C18*DG18 -> 0 | DJ18: =$C18*DI18 -> 0 | DL18: =$C18*DK18 -> 0 | DN18: =$C18*DM18 -> 0 | DP18: =$C18*DO18 -> 0 | DR18: =$C18*DQ18 -> 0 | DT18: =$C18*DS18 -> 0 | DV18: =$C18*DU18 -> 0 | DX18: =$C18*DW18 -> 0 | DZ18: =$C18*DY18 -> 0 | EB18: =$C18*EA18 -> 0
D19: =C19/$C$26 -> #DIV/0! | E19: =C19/'DISTRIBUIÇÃO CUSTO'!C$31 -> #DIV/0! | H19: =$C19*G19 -> 0 | J19: =$C19*I19 -> 0 | L19: =$C19*K19 -> 0 | N19: =$C19*M19 -> 0 | P19: =$C19*O19 -> 0 | R19: =$C19*Q19 -> 0 | T19: =$C19*S19 -> 0 | V19: =$C19*U19 -> 0 | X19: =$C19*W19 -> 0 | Z19: =$C19*Y19 -> 0 | AB19: =$C19*AA19 -> 0 | AD19: =$C19*AC19 -> 0 | AF19: =$C19*AE19 -> 0 | AH19: =$C19*AG19 -> 0 | AJ19: =$C19*AI19 -> 0 | AL19: =$C19*AK19 -> 0 | AN19: =$C19*AM19 -> 0 | AP19: =$C19*AO19 -> 0 | AR19: =$C19*AQ19 -> 0 | AT19: =$C19*AS19 -> 0 | AV19: =$C19*AU19 -> 0 | AX19: =$C19*AW19 -> 0 | AZ19: =$C19*AY19 -> 0 | BB19: =$C19*BA19 -> 0 | BD19: =$C19*BC19 -> 0 | BF19: =$C19*BE19 -> 0 | BH19: =$C19*BG19 -> 0 | BJ19: =$C19*BI19 -> 0 | BL19: =$C19*BK19 -> 0 | BN19: =$C19*BM19 -> 0 | BP19: =$C19*BO19 -> 0 | BR19: =$C19*BQ19 -> 0 | BT19: =$C19*BS19 -> 0 | BV19: =$C19*BU19 -> 0 | BX19: =$C19*BW19 -> 0 | BZ19: =$C19*BY19 -> 0 | CB19: =$C19*CA19 -> 0 | CD19: =$C19*CC19 -> 0 | CF19: =$C19*CE19 -> 0 | CH19: =$C19*CG19 -> 0 | CJ19: =$C19*CI19 -> 0 | CL19: =$C19*CK19 -> 0 | CN19: =$C19*CM19 -> 0 | CP19: =$C19*CO19 -> 0 | CR19: =$C19*CQ19 -> 0 | CT19: =$C19*CS19 -> 0 | CV19: =$C19*CU19 -> 0 | CX19: =$C19*CW19 -> 0 | CZ19: =$C19*CY19 -> 0 | DB19: =$C19*DA19 -> 0 | DD19: =$C19*DC19 -> 0 | DF19: =$C19*DE19 -> 0 | DH19: =$C19*DG19 -> 0 | DJ19: =$C19*DI19 -> 0 | DL19: =$C19*DK19 -> 0 | DN19: =$C19*DM19 -> 0 | DP19: =$C19*DO19 -> 0 | DR19: =$C19*DQ19 -> 0 | DT19: =$C19*DS19 -> 0 | DV19: =$C19*DU19 -> 0 | DX19: =$C19*DW19 -> 0 | DZ19: =$C19*DY19 -> 0 | EB19: =$C19*EA19 -> 0
D20: =C20/$C$26 -> #DIV/0! | E20: =C20/'DISTRIBUIÇÃO CUSTO'!C$31 -> #DIV/0! | H20: =$C20*G20 -> 0 | J20: =$C20*I20 -> 0 | L20: =$C20*K20 -> 0 | N20: =$C20*M20 -> 0 | P20: =$C20*O20 -> 0 | R20: =$C20*Q20 -> 0 | T20: =$C20*S20 -> 0 | V20: =$C20*U20 -> 0 | X20: =$C20*W20 -> 0 | Z20: =$C20*Y20 -> 0 | AB20: =$C20*AA20 -> 0 | AD20: =$C20*AC20 -> 0 | AF20: =$C20*AE20 -> 0 | AH20: =$C20*AG20 -> 0 | AJ20: =$C20*AI20 -> 0 | AL20: =$C20*AK20 -> 0 | AN20: =$C20*AM20 -> 0 | AP20: =$C20*AO20 -> 0 | AR20: =$C20*AQ20 -> 0 | AT20: =$C20*AS20 -> 0 | AV20: =$C20*AU20 -> 0 | AX20: =$C20*AW20 -> 0 | AZ20: =$C20*AY20 -> 0 | BB20: =$C20*BA20 -> 0 | BD20: =$C20*BC20 -> 0 | BF20: =$C20*BE20 -> 0 | BH20: =$C20*BG20 -> 0 | BJ20: =$C20*BI20 -> 0 | BL20: =$C20*BK20 -> 0 | BN20: =$C20*BM20 -> 0 | BP20: =$C20*BO20 -> 0 | BR20: =$C20*BQ20 -> 0 | BT20: =$C20*BS20 -> 0 | BV20: =$C20*BU20 -> 0 | BX20: =$C20*BW20 -> 0 | BZ20: =$C20*BY20 -> 0 | CB20: =$C20*CA20 -> 0 | CD20: =$C20*CC20 -> 0 | CF20: =$C20*CE20 -> 0 | CH20: =$C20*CG20 -> 0 | CJ20: =$C20*CI20 -> 0 | CL20: =$C20*CK20 -> 0 | CN20: =$C20*CM20 -> 0 | CP20: =$C20*CO20 -> 0 | CR20: =$C20*CQ20 -> 0 | CT20: =$C20*CS20 -> 0 | CV20: =$C20*CU20 -> 0 | CX20: =$C20*CW20 -> 0 | CZ20: =$C20*CY20 -> 0 | DB20: =$C20*DA20 -> 0 | DD20: =$C20*DC20 -> 0 | DF20: =$C20*DE20 -> 0 | DH20: =$C20*DG20 -> 0 | DJ20: =$C20*DI20 -> 0 | DL20: =$C20*DK20 -> 0 | DN20: =$C20*DM20 -> 0 | DP20: =$C20*DO20 -> 0 | DR20: =$C20*DQ20 -> 0 | DT20: =$C20*DS20 -> 0 | DV20: =$C20*DU20 -> 0 | DX20: =$C20*DW20 -> 0 | DZ20: =$C20*DY20 -> 0 | EB20: =$C20*EA20 -> 0
... D24: =C24/$C$26 -> #DIV/0! | E24: =C24/'DISTRIBUIÇÃO CUSTO'!C$31 -> #DIV/0! | H24: =$C24*G24 -> 0 | J24: =$C24*I24 -> 0 | L24: =$C24*K24 -> 0 | N24: =$C24*M24 -> 0 | P24: =$C24*O24 -> 0 | R24: =$C24*Q24 -> 0 | T24: =$C24*S24 -> 0 | V24: =$C24*U24 -> 0 | X24: =$C24*W24 -> 0 | Z24: =$C24*Y24 -> 0 | AB24: =$C24*AA24 -> 0 | AD24: =$C24*AC24 -> 0 | AF24: =$C24*AE24 -> 0 | AH24: =$C24*AG24 -> 0 | AJ24: =$C24*AI24 -> 0 | AL24: =$C24*AK24 -> 0 | AN24: =$C24*AM24 -> 0 | AP24: =$C24*AO24 -> 0 | AR24: =$C24*AQ24 -> 0 | AT24: =$C24*AS24 -> 0 | AV24: =$C24*AU24 -> 0 | AX24: =$C24*AW24 -> 0 | AZ24: =$C24*AY24 -> 0 | BB24: =$C24*BA24 -> 0 | BD24: =$C24*BC24 -> 0 | BF24: =$C24*BE24 -> 0 | BH24: =$C24*BG24 -> 0 | BJ24: =$C24*BI24 -> 0 | BL24: =$C24*BK24 -> 0 | BN24: =$C24*BM24 -> 0 | BP24: =$C24*BO24 -> 0 | BR24: =$C24*BQ24 -> 0 | BT24: =$C24*BS24 -> 0 | BV24: =$C24*BU24 -> 0 | BX24: =$C24*BW24 -> 0 | BZ24: =$C24*BY24 -> 0 | CB24: =$C24*CA24 -> 0 | CD24: =$C24*CC24 -> 0 | CF24: =$C24*CE24 -> 0 | CH24: =$C24*CG24 -> 0 | CJ24: =$C24*CI24 -> 0 | CL24: =$C24*CK24 -> 0 | CN24: =$C24*CM24 -> 0 | CP24: =$C24*CO24 -> 0 | CR24: =$C24*CQ24 -> 0 | CT24: =$C24*CS24 -> 0 | CV24: =$C24*CU24 -> 0 | CX24: =$C24*CW24 -> 0 | CZ24: =$C24*CY24 -> 0 | DB24: =$C24*DA24 -> 0 | DD24: =$C24*DC24 -> 0 | DF24: =$C24*DE24 -> 0 | DH24: =$C24*DG24 -> 0 | DJ24: =$C24*DI24 -> 0 | DL24: =$C24*DK24 -> 0 | DN24: =$C24*DM24 -> 0 | DP24: =$C24*DO24 -> 0 | DR24: =$C24*DQ24 -> 0 | DT24: =$C24*DS24 -> 0 | DV24: =$C24*DU24 -> 0 | DX24: =$C24*DW24 -> 0 | DZ24: =$C24*DY24 -> 0 | EB24: =$C24*EA24 -> 0
D25: =C25/$C$26 -> #DIV/0! | E25: =C25/'DISTRIBUIÇÃO CUSTO'!C$31 -> #DIV/0! | G25: =100%/$E$31 -> #DIV/0! | H25: =$C25*G25 -> #DIV/0! | I25: =100%/$E$31 -> #DIV/0! | J25: =$C25*I25 -> #DIV/0! | K25: =100%/$E$31 -> #DIV/0! | L25: =$C25*K25 -> #DIV/0! | M25: =100%/$E$31 -> #DIV/0! | N25: =$C25*M25 -> #DIV/0! | O25: =100%/$E$31 -> #DIV/0! | P25: =$C25*O25 -> #DIV/0! | Q25: =100%/$E$31 -> #DIV/0! | R25: =$C25*Q25 -> #DIV/0! | S25: =100%/$E$31 -> #DIV/0! | T25: =$C25*S25 -> #DIV/0! | U25: =100%/$E$31 -> #DIV/0! | V25: =$C25*U25 -> #DIV/0! | W25: =100%/$E$31 -> #DIV/0! | X25: =$C25*W25 -> #DIV/0! | Y25: =100%/$E$31 -> #DIV/0! | Z25: =$C25*Y25 -> #DIV/0! | AA25: =100%/$E$31 -> #DIV/0! | AB25: =$C25*AA25 -> #DIV/0! | AC25: =100%/$E$31 -> #DIV/0! | AD25: =$C25*AC25 -> #DIV/0! | AE25: =100%/$E$31 -> #DIV/0! | AF25: =$C25*AE25 -> #DIV/0! | AG25: =100%/$E$31 -> #DIV/0! | AH25: =$C25*AG25 -> #DIV/0! | AI25: =100%/$E$31 -> #DIV/0! | AJ25: =$C25*AI25 -> #DIV/0! | AK25: =100%/$E$31 -> #DIV/0! | AL25: =$C25*AK25 -> #DIV/0! | AM25: =100%/$E$31 -> #DIV/0! | AN25: =$C25*AM25 -> #DIV/0! | AO25: =100%/$E$31 -> #DIV/0! | AP25: =$C25*AO25 -> #DIV/0! | AQ25: =100%/$E$31 -> #DIV/0! | AR25: =$C25*AQ25 -> #DIV/0! | AS25: =100%/$E$31 -> #DIV/0! | AT25: =$C25*AS25 -> #DIV/0! | AU25: =100%/$E$31 -> #DIV/0! | AV25: =$C25*AU25 -> #DIV/0! | AW25: =100%/$E$31 -> #DIV/0! | AX25: =$C25*AW25 -> #DIV/0! | AY25: =100%/$E$31 -> #DIV/0! | AZ25: =$C25*AY25 -> #DIV/0! | BA25: =100%/$E$31 -> #DIV/0! | BB25: =$C25*BA25 -> #DIV/0! | BC25: =100%/$E$31 -> #DIV/0! | BD25: =$C25*BC25 -> #DIV/0! | BE25: =100%/$E$31 -> #DIV/0! | BF25: =$C25*BE25 -> #DIV/0! | BG25: =100%/$E$31 -> #DIV/0! | BH25: =$C25*BG25 -> #DIV/0! | BI25: =100%/$E$31 -> #DIV/0! | BJ25: =$C25*BI25 -> #DIV/0! | BK25: =100%/$E$31 -> #DIV/0! | BL25: =$C25*BK25 -> #DIV/0! | BM25: =100%/$E$31 -> #DIV/0! | BN25: =$C25*BM25 -> #DIV/0! | BO25: =100%/$E$31 -> #DIV/0! | BP25: =$C25*BO25 -> #DIV/0! | BQ25: =100%/$E$31 -> #DIV/0! | BR25: =$C25*BQ25 -> #DIV/0! | BS25: =100%/$E$31 -> #DIV/0! | BT25: =$C25*BS25 -> #DIV/0! | BU25: =100%/$E$31 -> #DIV/0! | BV25: =$C25*BU25 -> #DIV/0! | BW25: =100%/$E$31 -> #DIV/0! | BX25: =$C25*BW25 -> #DIV/0! | BY25: =100%/$E$31 -> #DIV/0! | BZ25: =$C25*BY25 -> #DIV/0! | CA25: =100%/$E$31 -> #DIV/0! | CB25: =$C25*CA25 -> #DIV/0! | CC25: =100%/$E$31 -> #DIV/0! | CD25: =$C25*CC25 -> #DIV/0! | CE25: =100%/$E$31 -> #DIV/0! | CF25: =$C25*CE25 -> #DIV/0! | CG25: =100%/$E$31 -> #DIV/0! | CH25: =$C25*CG25 -> #DIV/0! | CI25: =100%/$E$31 -> #DIV/0! | CJ25: =$C25*CI25 -> #DIV/0! | CK25: =100%/$E$31 -> #DIV/0! | CL25: =$C25*CK25 -> #DIV/0! | CM25: =100%/$E$31 -> #DIV/0! | CN25: =$C25*CM25 -> #DIV/0! | CO25: =100%/$E$31 -> #DIV/0! | CP25: =$C25*CO25 -> #DIV/0! | CQ25: =100%/$E$31 -> #DIV/0! | CR25: =$C25*CQ25 -> #DIV/0! | CS25: =100%/$E$31 -> #DIV/0! | CT25: =$C25*CS25 -> #DIV/0! | CU25: =100%/$E$31 -> #DIV/0! | CV25: =$C25*CU25 -> #DIV/0! | CW25: =100%/$E$31 -> #DIV/0! | CX25: =$C25*CW25 -> #DIV/0! | CY25: =100%/$E$31 -> #DIV/0! | CZ25: =$C25*CY25 -> #DIV/0! | DA25: =100%/$E$31 -> #DIV/0! | DB25: =$C25*DA25 -> #DIV/0! | DC25: =100%/$E$31 -> #DIV/0! | DD25: =$C25*DC25 -> #DIV/0! | DE25: =100%/$E$31 -> #DIV/0! | DF25: =$C25*DE25 -> #DIV/0! | DG25: =100%/$E$31 -> #DIV/0! | DH25: =$C25*DG25 -> #DIV/0! | DI25: =100%/$E$31 -> #DIV/0! | DJ25: =$C25*DI25 -> #DIV/0! | DK25: =100%/$E$31 -> #DIV/0! | DL25: =$C25*DK25 -> #DIV/0! | DM25: =100%/$E$31 -> #DIV/0! | DN25: =$C25*DM25 -> #DIV/0! | DO25: =100%/$E$31 -> #DIV/0! | DP25: =$C25*DO25 -> #DIV/0! | DQ25: =100%/$E$31 -> #DIV/0! | DR25: =$C25*DQ25 -> #DIV/0! | DS25: =100%/$E$31 -> #DIV/0! | DT25: =$C25*DS25 -> #DIV/0! | DU25: =100%/$E$31 -> #DIV/0! | DV25: =$C25*DU25 -> #DIV/0! | DW25: =100%/$E$31 -> #DIV/0! | DX25: =$C25*DW25 -> #DIV/0! | DY25: =100%/$E$31 -> #DIV/0! | DZ25: =$C25*DY25 -> #DIV/0! | EA25: =100%/$E$31 -> #DIV/0! | EB25: =$C25*EA25 -> #DIV/0!
B26: TOTAL | C26: =SUM(C9:C25) -> 0 | D26: =SUM(D9:D25) -> #DIV/0! | E26: =SUM(E9:E25) -> #DIV/0! | H26: =SUM(H9:H25) -> #DIV/0! | J26: =SUM(J9:J25) -> #DIV/0! | L26: =SUM(L9:L25) -> #DIV/0! | N26: =SUM(N9:N25) -> #DIV/0! | P26: =SUM(P9:P25) -> #DIV/0! | R26: =SUM(R9:R25) -> #DIV/0! | T26: =SUM(T9:T25) -> #DIV/0! | V26: =SUM(V9:V25) -> #DIV/0! | X26: =SUM(X9:X25) -> #DIV/0! | Z26: =SUM(Z9:Z25) -> #DIV/0! | AB26: =SUM(AB9:AB25) -> #DIV/0! | AD26: =SUM(AD9:AD25) -> #DIV/0! | AF26: =SUM(AF9:AF25) -> #DIV/0! | AH26: =SUM(AH9:AH25) -> #DIV/0! | AJ26: =SUM(AJ9:AJ25) -> #DIV/0! | AL26: =SUM(AL9:AL25) -> #DIV/0! | AN26: =SUM(AN9:AN25) -> #DIV/0! | AP26: =SUM(AP9:AP25) -> #DIV/0! | AR26: =SUM(AR9:AR25) -> #DIV/0! | AT26: =SUM(AT9:AT25) -> #DIV/0! | AV26: =SUM(AV9:AV25) -> #DIV/0! | AX26: =SUM(AX9:AX25) -> #DIV/0! | AZ26: =SUM(AZ9:AZ25) -> #DIV/0! | BB26: =SUM(BB9:BB25) -> #DIV/0! | BD26: =SUM(BD9:BD25) -> #DIV/0! | BF26: =SUM(BF9:BF25) -> #DIV/0! | BH26: =SUM(BH9:BH25) -> #DIV/0! | BJ26: =SUM(BJ9:BJ25) -> #DIV/0! | BL26: =SUM(BL9:BL25) -> #DIV/0! | BN26: =SUM(BN9:BN25) -> #DIV/0! | BP26: =SUM(BP9:BP25) -> #DIV/0! | BR26: =SUM(BR9:BR25) -> #DIV/0! | BT26: =SUM(BT9:BT25) -> #DIV/0! | BV26: =SUM(BV9:BV25) -> #DIV/0! | BX26: =SUM(BX9:BX25) -> #DIV/0! | BZ26: =SUM(BZ9:BZ25) -> #DIV/0! | CB26: =SUM(CB9:CB25) -> #DIV/0! | CD26: =SUM(CD9:CD25) -> #DIV/0! | CF26: =SUM(CF9:CF25) -> #DIV/0! | CH26: =SUM(CH9:CH25) -> #DIV/0! | CJ26: =SUM(CJ9:CJ25) -> #DIV/0! | CL26: =SUM(CL9:CL25) -> #DIV/0! | CN26: =SUM(CN9:CN25) -> #DIV/0! | CP26: =SUM(CP9:CP25) -> #DIV/0! | CR26: =SUM(CR9:CR25) -> #DIV/0! | CT26: =SUM(CT9:CT25) -> #DIV/0! | CV26: =SUM(CV9:CV25) -> #DIV/0! | CX26: =SUM(CX9:CX25) -> #DIV/0! | CZ26: =SUM(CZ9:CZ25) -> #DIV/0! | DB26: =SUM(DB9:DB25) -> #DIV/0! | DD26: =SUM(DD9:DD25) -> #DIV/0! | DF26: =SUM(DF9:DF25) -> #DIV/0! | DH26: =SUM(DH9:DH25) -> #DIV/0! | DJ26: =SUM(DJ9:DJ25) -> #DIV/0! | DL26: =SUM(DL9:DL25) -> #DIV/0! | DN26: =SUM(DN9:DN25) -> #DIV/0! | DP26: =SUM(DP9:DP25) -> #DIV/0! | DR26: =SUM(DR9:DR25) -> #DIV/0! | DT26: =SUM(DT9:DT25) -> #DIV/0! | DV26: =SUM(DV9:DV25) -> #DIV/0! | DX26: =SUM(DX9:DX25) -> #DIV/0! | DZ26: =SUM(DZ9:DZ25) -> #DIV/0! | EB26: =SUM(EB9:EB25) -> #DIV/0! | EC26: SOMA TOTAL
B27: CUB/SC | C27: 2752.67 | D27: 45261 | E27: =+E26/C27 -> #DIV/0! | H27: =H26/$C$26 -> #DIV/0! | J27: =J26/$C$26 -> #DIV/0! | L27: =L26/$C$26 -> #DIV/0! | N27: =N26/$C$26 -> #DIV/0! | P27: =P26/$C$26 -> #DIV/0! | R27: =R26/$C$26 -> #DIV/0! | T27: =T26/$C$26 -> #DIV/0! | V27: =V26/$C$26 -> #DIV/0! | X27: =X26/$C$26 -> #DIV/0! | Z27: =Z26/$C$26 -> #DIV/0! | AB27: =AB26/$C$26 -> #DIV/0! | AD27: =AD26/$C$26 -> #DIV/0! | AF27: =AF26/$C$26 -> #DIV/0! | AH27: =AH26/$C$26 -> #DIV/0! | AJ27: =AJ26/$C$26 -> #DIV/0! | AL27: =AL26/$C$26 -> #DIV/0! | AN27: =AN26/$C$26 -> #DIV/0! | AP27: =AP26/$C$26 -> #DIV/0! | AR27: =AR26/$C$26 -> #DIV/0! | AT27: =AT26/$C$26 -> #DIV/0! | AV27: =AV26/$C$26 -> #DIV/0! | AX27: =AX26/$C$26 -> #DIV/0! | AZ27: =AZ26/$C$26 -> #DIV/0! | BB27: =BB26/$C$26 -> #DIV/0! | BD27: =BD26/$C$26 -> #DIV/0! | BF27: =BF26/$C$26 -> #DIV/0! | BH27: =BH26/$C$26 -> #DIV/0! | BJ27: =BJ26/$C$26 -> #DIV/0! | BL27: =BL26/$C$26 -> #DIV/0! | BN27: =BN26/$C$26 -> #DIV/0! | BP27: =BP26/$C$26 -> #DIV/0! | BR27: =BR26/$C$26 -> #DIV/0! | BT27: =BT26/$C$26 -> #DIV/0! | BV27: =BV26/$C$26 -> #DIV/0! | BX27: =BX26/$C$26 -> #DIV/0! | BZ27: =BZ26/$C$26 -> #DIV/0! | CB27: =CB26/$C$26 -> #DIV/0! | CD27: =CD26/$C$26 -> #DIV/0! | CF27: =CF26/$C$26 -> #DIV/0! | CH27: =CH26/$C$26 -> #DIV/0! | CJ27: =CJ26/$C$26 -> #DIV/0! | CL27: =CL26/$C$26 -> #DIV/0! | CN27: =CN26/$C$26 -> #DIV/0! | CP27: =CP26/$C$26 -> #DIV/0! | CR27: =CR26/$C$26 -> #DIV/0! | CT27: =CT26/$C$26 -> #DIV/0! | CV27: =CV26/$C$26 -> #DIV/0! | CX27: =CX26/$C$26 -> #DIV/0! | CZ27: =CZ26/$C$26 -> #DIV/0! | DB27: =DB26/$C$26 -> #DIV/0! | DD27: =DD26/$C$26 -> #DIV/0! | DF27: =DF26/$C$26 -> #DIV/0! | DH27: =DH26/$C$26 -> #DIV/0! | DJ27: =DJ26/$C$26 -> #DIV/0! | DL27: =DL26/$C$26 -> #DIV/0! | DN27: =DN26/$C$26 -> #DIV/0! | DP27: =DP26/$C$26 -> #DIV/0! | DR27: =DR26/$C$26 -> #DIV/0! | DT27: =DT26/$C$26 -> #DIV/0! | DV27: =DV26/$C$26 -> #DIV/0! | DX27: =DX26/$C$26 -> #DIV/0! | DZ27: =DZ26/$C$26 -> #DIV/0! | EB27: =EB26/$C$26 -> #DIV/0! | EC27: =SUM(H26:EB26) -> #DIV/0!
C30: ÁREA CONSTRUÍDA | E30: Prazo de obra
D31: m²

Sheet CURVA TEÓRICA
B2: CURVA S | % TEÓRICA
B8: Mês | C8: % AVANÇO | D8: % AVANÇO Acumulado | E8: Valor Planejado | F8: Valor Planejado Acumulado
B9: 1 | D9: =C9 -> 0 | E9: =C9*$F$72 -> 0 | F9: =E9 -> 0
B10: 2 | D10: =C10+D9 -> 0 | E10: =C10*$F$72 -> 0 | F10: =F9+E10 -> 0
B11: 3 | D11: =C11+D10 -> 0 | E11: =C11*$F$72 -> 0 | F11: =F10+E11 -> 0
B12: 4 | D12: =C12+D11 -> 0 | E12: =C12*$F$72 -> 0 | F12: =F11+E12 -> 0
B13: 5 | D13: =C13+D12 -> 0 | E13: =C13*$F$72 -> 0 | F13: =F12+E13 -> 0
B14: 6 | D14: =C14+D13 -> 0 | E14: =C14*$F$72 -> 0 | F14: =F13+E14 -> 0
B15: 7 | D15: =C15+D14 -> 0 | E15: =C15*$F$72 -> 0 | F15: =F14+E15 -> 0
B16: 8 | D16: =C16+D15 -> 0 | E16: =C16*$F$72 -> 0 | F16: =F15+E16 -> 0
B17: 9 | D17: =C17+D16 -> 0 | E17: =C17*$F$72 -> 0 | F17: =F16+E17 -> 0
B18: 10 | D18: =C18+D17 -> 0 | E18: =C18*$F$72 -> 0 | F18: =F17+E18 -> 0
B19: 11 | D19: =C19+D18 -> 0 | E19: =C19*$F$72 -> 0 | F19: =F18+E19 -> 0
B20: 12 | D20: =C20+D19 -> 0 | E20: =C20*$F$72 -> 0 | F20: =F19+E20 -> 0
B21: 13 | D21: =C21+D20 -> 0 | E21: =C21*$F$72 -> 0 | F21: =F20+E21 -> 0
... B71: 63 | D71: =C71+D70 -> 0 | E71: =C71*$F$72 -> 0 | F71: =F70+E71 -> 0
E72: Total | F72: ='DISTRIBUIÇÃO CUSTO'!C26 -> 0
