Workbook
Name aa: #REF!
Name aa: #REF!
Name aaaa: '[1]M.O.'!#REF!
Name aaaa: '[1]M.O.'!#REF!
Name angelo: [2]Geral!#REF!
Name angelo: [2]Geral!#REF!
Name area: #REF!
Name area: #REF!
Name aux: #REF!
Name aux: #REF!
Name BDA: #REF!
Name BDI: #REF!
Name ca: #REF!
Name Capa: #REF!
Name cronograma: #REF!
Name D: #REF!
Name direto: #REF!
Name DRE: #REF!
Name ea: #REF!
Name eee: {#N/A,#N/A,FALSE,"ET-CAPA";#N/A,#N/A,FALSE,"ET-PAG1";#N/A,#N/A,FALSE,"ET-PAG2";#N/A,#N/A,FALSE,"ET-PAG3";#N/A,#N/A,FALSE,"ET-PAG4";#N/A,#N/A,FALSE,"ET-PAG5"}
Name eee: {#N/A,#N/A,FALSE,"ET-CAPA";#N/A,#N/A,FALSE,"ET-PAG1";#N/A,#N/A,FALSE,"ET-PAG2";#N/A,#N/A,FALSE,"ET-PAG3";#N/A,#N/A,FALSE,"ET-PAG4";#N/A,#N/A,FALSE,"ET-PAG5"}
Name FFFFFFF: #REF!
Name item_1: #REF!
Name LS: '[1]M.O.'!#REF!
Name MENU: #REF!
Name MENU: #REF!
Name MENU1: #REF!
Name MENU2: #REF!
Name MENU3: #REF!
Name MENU4: #REF!
Name MENU5: #REF!
Name MENU6: #REF!
Name mo: #REF!
Name OAE: #REF!
Name ParamValues1: [3]ParamValues!$A$1:$A$39
Name PAV: #REF!
Name pr: #REF!
Name PRE: #REF!
Name Print_Area_MI: #REF!
Name qe: #REF!
Name qee: #REF!
Name reforsu: #REF!
Name ren: #REF!
Name REV: #REF!
Name sa: #REF!
Name SEG: #REF!
Name SIH: #REF!
Name SIV: #REF!
Name ss: #REF!
Name susref: #REF!
Name tania: #REF!
Name tc: #REF!
Name titulos: #REF!
Name TOT: #REF!
Name Total: #REF!
Name TRP: #REF!
Name u: {#N/A,#N/A,FALSE,"ET-CAPA";#N/A,#N/A,FALSE,"ET-PAG1";#N/A,#N/A,FALSE,"ET-PAG2";#N/A,#N/A,FALSE,"ET-PAG3";#N/A,#N/A,FALSE,"ET-PAG4";#N/A,#N/A,FALSE,"ET-PAG5"}
Name u: {#N/A,#N/A,FALSE,"ET-CAPA";#N/A,#N/A,FALSE,"ET-PAG1";#N/A,#N/A,FALSE,"ET-PAG2";#N/A,#N/A,FALSE,"ET-PAG3";#N/A,#N/A,FALSE,"ET-PAG4";#N/A,#N/A,FALSE,"ET-PAG5"}
Name wrn.GERAL.: {#N/A,#N/A,FALSE,"ET-CAPA";#N/A,#N/A,FALSE,"ET-PAG1";#N/A,#N/A,FALSE,"ET-PAG2";#N/A,#N/A,FALSE,"ET-PAG3";#N/A,#N/A,FALSE,"ET-PAG4";#N/A,#N/A,FALSE,"ET-PAG5"}
Name wrn.GERAL.: {#N/A,#N/A,FALSE,"ET-CAPA";#N/A,#N/A,FALSE,"ET-PAG1";#N/A,#N/A,FALSE,"ET-PAG2";#N/A,#N/A,FALSE,"ET-PAG3";#N/A,#N/A,FALSE,"ET-PAG4";#N/A,#N/A,FALSE,"ET-PAG5"}

Sheet a. COMPARATIVOS OBRAS
A1: COMPARATIVO DE PRAZO DE OBRAS SEMELHANTES
A2: OBRA 1 | D2: OBRA 2 | G2: OBRA 3 | J2: OBRA PARAMÉTRICO
A3: DURAÇÃO | D3: DURAÇÃO | G3: DURAÇÃO | J3: DURAÇÃO
A4: Linha de base: | B4: -- meses | D4: Linha de base: | E4: -- meses | G4: Linha de base: | H4: -- meses | J4: Linha de base: | K4: -- meses
A5: Meta: | B5: -- meses | D5: Meta: | E5: -- meses | G5: Meta: | H5: -- meses | J5: Meta: | K5: -- meses
A6: ESPECIFICAÇÕES DE PROJETO | D6: ESPECIFICAÇÕES DE PROJETO | G6: ESPECIFICAÇÕES DE PROJETO | J6: ESPECIFICAÇÕES DE PROJETO
A7: Área Total | D7: Área Total | G7: Área Total | J7: Área Total
A8: área/pav embasamento = | B8: aprox --- m² | D8: área/pav embasamento = | E8: aprox --- m² | G8: área/pav embasamento = | H8: aprox --- m² | J8: área/pav embasamento = | K8: aprox --- m²
A9: área/pav tipo = | B9: aprox --- m² | D9: área/pav tipo = | E9: aprox --- m² | G9: área/pav tipo = | H9: aprox --- m² | J9: área/pav tipo = | K9: aprox --- m²
A10: Nº PAVIMENTOS | B10: -- | D10: Nº PAVIMENTOS | E10: -- | G10: Nº PAVIMENTOS | H10: -- | J10: Nº PAVIMENTOS | K10: --
A11: ESPECIFICAÇÕES DE PAVIMENTOS | D11: ESPECIFICAÇÕES DE PAVIMENTOS | G11: ESPECIFICAÇÕES DE PAVIMENTOS | J11: ESPECIFICAÇÕES DE PAVIMENTOS
A12: 1º - térreo
A13: 2º ao 4º - 3 pavs garagem
A14: 5º Lazer
A15: 6º - Tipo Dif
A16: 7º ao 20º - Tipo
A17: Técnicos

Sheet b. Fundação
D3: DIMENSIONAMENTO DE PRAZO - FUNDAÇÃO PROFUNDA, BLOCOS E BALDRAMES
B7: HOTEL
B8: Estacas Hélice Contínua | I8: Estaca pre-moldada cravada
C9: Estacas
B10: Etapa | C10: Quantidade | D10: Profundidade (m) | E10: Total (m) | F10: Duração (Dias) | G10: Total (dias) | H10: Meses
B11: Fase 1 | C11: 273 | D11: 13 | E11: =C11*D11 -> 3549 | F11: =ROUNDUP((E11/$D$13),0) -> 30 | G11: =F11*D14 -> 36 | H11: =G11/22 -> 1.6363636
B13: Índice (m/dia) | D13: 120
B14: Coeficiente de chuva | D14: 1.2
B17: Etapa | C17: Forma (m²) | D17: Concreto (m³) | E17: Aço (Kg) | F17: Armador | G17: Carpinteiro | H17: Formas (Dias) | I17: Armação (dias) | J17: Concreto (dias) | K17: Duração Total | L17: Meses
B18: Blocos e Baldrames | C18: 2132.05 | D18: 623.61 | E18: 37416.6 | F18: 10 | G18: 10 | H18: =ROUNDUP((C18*$D$20)/(8.8*G18),0) -> 51 | I18: =ROUNDUP((E18*$D$22)/(8.8*F18),0) -> 19 | J18: =ROUNDUP((D18*$D$21)/8.8,0) -> 1 | K18: =I18+J18+H18 -> 71 | L18: =K18/22 -> 3.2272727
K19: =K18*D23 -> 85.2 | L19: =K19/22 -> 3.8727273
B20: Montagem de formas (Hh/m²): | D20: 2.08
B21: Concretagem (h/m³): | D21: 0.013253012
B22: RUP Armação (Hh/kg) | D22: 0.044
B23: Coeficiente de chuva | D23: 1.2
B25: RESIDENCIAL
B26: Estacas Hélice Contínua | I26: Estaca pre-moldada cravada
C27: Estacas
B28: Etapa | C28: Quantidade | D28: Profundidade (m) | E28: Total (m) | F28: Duração (Dias) | G28: Total (dias) | H28: Meses
B29: Fase 1 | C29: 358 | D29: 15 | E29: =C29*D29 -> 5370 | F29: =ROUNDUP((E29/$D$13),0) -> 45 | G29: =F29*D32 -> 54 | H29: =G29/22 -> 2.4545455
B31: Índice (m/dia) | D31: 120
B32: Coeficiente de chuva | D32: 1.2
B35: Etapa | C35: Forma (m²) | D35: Concreto (m³) | E35: Aço (Kg) | F35: Armador | G35: Carpinteiro | H35: Formas (Dias) | I35: Armação (dias) | J35: Concreto (dias) | K35: Duração Total | L35: Meses
B36: Blocos e Baldrames | C36: 2090.59 | D36: 918.72 | E36: 91872 | F36: 10 | G36: 10 | H36: =ROUNDUP((C36*$D$20)/(8.8*G36),0) -> 50 | I36: =ROUNDUP((E36*$D$22)/(8.8*F36),0) -> 46 | J36: =ROUNDUP((D36*$D$21)/8.8,0) -> 2 | K36: =I36+J36+H36 -> 98 | L36: =K36/22 -> 4.4545455
K37: =K36*D41 -> 117.6 | L37: =K37/22 -> 5.3454545
B38: Montagem de formas (Hh/m²): | D38: 2.08
B39: Concretagem (h/m³): | D39: 0.013253012
B40: RUP Armação (Hh/kg) | D40: 0.044
B41: Coeficiente de chuva | D41: 1.2

Sheet c. Supraestrutura HOTEL
D3: DIMENSIONAMENTO DE PRAZO - SUPRAESTRUTURA
B7: Pavimento | C7: Área do Pavimento | D7: Forma (m²) | E7: RUP (Hh/m²) | F7: RUP (m²/dia) | G7: Duração | H7: Carpinteiro | I7: Armador | J7: Servente | K7: Total Equipe
B8: Reservatorio | D8: =C8*$C$15 -> 0 | E8: 1.6 | F8: =8.8/E8 -> 5.5 | G8: 6 | H8: =ROUNDUP((D8*E8)/(G8*8.8),0) -> 0 | I8: =ROUNDUP(H8/2,0) -> 0 | J8: =ROUNDUP(H8/4,0) -> 0 | K8: =J8+I8+H8 -> 0 | L8: =G8/22 -> 0.27272727
B9: Subtelhado | C9: 722.62 | D9: =C9*$C$15 -> 1806.55 | E9: 1.21 | F9: =8.8/E9 -> 7.2727273 | G9: 12 | H9: =ROUNDUP((D9*E9)/(G9*8.8),0) -> 21 | I9: =ROUNDUP(H9/2,0) -> 11 | J9: =ROUNDUP(H9/4,0) -> 6 | K9: =J9+I9+H9 -> 38 | L9: =G9/22 -> 0.54545455
B10: Pav 2 | C10: 1144.29 | D10: =C10*$C$15 -> 2860.725 | E10: 1.21 | F10: =8.8/E10 -> 7.2727273 | G10: 18 | H10: =ROUNDUP((D10*E10)/(G10*8.8),0) -> 22 | I10: =ROUNDUP(H10/2,0) -> 11 | J10: =ROUNDUP(H10/4,0) -> 6 | K10: =J10+I10+H10 -> 39 | L10: =G10/22 -> 0.81818182
B11: pav 1 | C11: 844.36 | D11: =C11*$C$15 -> 2110.9 | E11: 1.21 | F11: =8.8/E11 -> 7.2727273 | G11: 14 | H11: =ROUNDUP((D11*E11)/(G11*8.8),0) -> 21 | I11: =ROUNDUP(H11/2,0) -> 11 | J11: =ROUNDUP(H11/4,0) -> 6 | K11: =J11+I11+H11 -> 38 | L11: =G11/22 -> 0.63636364
B12: Terreo | C12: 1675.56 | D12: =C12*$C$15 -> 4188.9 | E12: 2.01 | F12: =8.8/E12 -> 4.3781095 | G12: 44 | H12: =ROUNDUP((D12*E12)/(G12*8.8),0) -> 22 | I12: =ROUNDUP(H12/2,0) -> 11 | J12: =ROUNDUP(H12/4,0) -> 6 | K12: =J12+I12+H12 -> 39 | L12: =G12/22 -> 2
B13: Subsolo | C13: 1662.34 | D13: =C13*$C$15 -> 4155.85 | E13: 2.01 | F13: =8.8/E13 -> 4.3781095 | G13: 44 | H13: =ROUNDUP((D13*E13)/(G13*8.8),0) -> 22 | I13: =ROUNDUP(H13/2,0) -> 11 | J13: =ROUNDUP(H13/4,0) -> 6 | K13: =J13+I13+H13 -> 39 | L13: =G13/22 -> 2
C14: =SUM(C8:C13) -> 6049.17
B15: FATOR MULT (X) | C15: 2.5 | F15: Total Dias | G15: =SUM(G8:G13) -> 138 | H15: Total Meses | I15: =G15/22 -> 6.2727273
B16: RUP
B17: Garagens | C17: 2.2
B18: Lazer | C18: 2.01
B19: Tipo Dif | C19: 1.21
B20: Tipo | C20: 1.17
B21: Técnicos | C21: 1.6

Sheet c. Supraestrutura RESID
D3: DIMENSIONAMENTO DE PRAZO - SUPRAESTRUTURA
B7: Pavimento | C7: Área do Pavimento | D7: Forma (m²) | E7: RUP (Hh/m²) | F7: RUP (m²/dia) | G7: Duração | H7: Carpinteiro | I7: Armador | J7: Servente | K7: Total Equipe
B8: Reservatorio | C8: 133.38 | D8: =C8*$C$32 -> 333.45 | E8: 1.6 | F8: =8.8/E8 -> 5.5 | G8: 6 | H8: =ROUNDUP((D8*E8)/(G8*8.8),0) -> 11 | I8: =ROUNDUP(H8/2,0) -> 6 | J8: =ROUNDUP(H8/4,0) -> 3 | K8: =J8+I8+H8 -> 20 | L8: =G8/22 -> 0.27272727
B9: Casa de maquinas | C9: 150.18 | D9: =C9*$C$32 -> 375.45 | E9: 1.6 | F9: =8.8/E9 -> 5.5 | G9: 7 | H9: =ROUNDUP((D9*E9)/(G9*8.8),0) -> 10 | I9: =ROUNDUP(H9/2,0) -> 5 | J9: =ROUNDUP(H9/4,0) -> 3 | K9: =J9+I9+H9 -> 18 | L9: =G9/22 -> 0.31818182
B10: Inspeção | C10: 303.24 | D10: =C10*$C$32 -> 758.1 | E10: 1.6 | F10: =8.8/E10 -> 5.5 | G10: 13 | H10: =ROUNDUP((D10*E10)/(G10*8.8),0) -> 11 | I10: =ROUNDUP(H10/2,0) -> 6 | J10: =ROUNDUP(H10/4,0) -> 3 | K10: =J10+I10+H10 -> 20 | L10: =G10/22 -> 0.59090909
B11: Duplex sup | C11: 693.56 | D11: =C11*$C$32 -> 1733.9 | E11: 1.21 | F11: =8.8/E11 -> 7.2727273 | G11: 11 | H11: =ROUNDUP((D11*E11)/(G11*8.8),0) -> 22 | I11: =ROUNDUP(H11/2,0) -> 11 | J11: =ROUNDUP(H11/4,0) -> 6 | K11: =J11+I11+H11 -> 39 | L11: =G11/22 -> 0.5
B12: Duplex inf | C12: 699.84 | D12: =C12*$C$32 -> 1749.6 | E12: 1.21 | F12: =8.8/E12 -> 7.2727273 | G12: 11 | H12: =ROUNDUP((D12*E12)/(G12*8.8),0) -> 22 | I12: =ROUNDUP(H12/2,0) -> 11 | J12: =ROUNDUP(H12/4,0) -> 6 | K12: =J12+I12+H12 -> 39 | L12: =G12/22 -> 0.5
B13: Tipo | C13: 699.84 | D13: =C13*$C$32 -> 1749.6 | E13: 1.17 | F13: =8.8/E13 -> 7.5213675 | G13: 11 | H13: =ROUNDUP((D13*E13)/(G13*8.8),0) -> 22 | I13: =ROUNDUP(H13/2,0) -> 11 | J13: =ROUNDUP(H13/4,0) -> 6 | K13: =J13+I13+H13 -> 39 | L13: =G13/22 -> 0.5
B14: Tipo | C14: 699.84 | D14: =C14*$C$32 -> 1749.6 | E14: 1.17 | F14: =8.8/E14 -> 7.5213675 | G14: 11 | H14: =ROUNDUP((D14*E14)/(G14*8.8),0) -> 22 | I14: =ROUNDUP(H14/2,0) -> 11 | J14: =ROUNDUP(H14/4,0) -> 6 | K14: =J14+I14+H14 -> 39 | L14: =G14/22 -> 0.5
B15: Tipo | C15: 699.84 | D15: =C15*$C$32 -> 1749.6 | E15: 1.17 | F15: =8.8/E15 -> 7.5213675 | G15: 11 | H15: =ROUNDUP((D15*E15)/(G15*8.8),0) -> 22 | I15: =ROUNDUP(H15/2,0) -> 11 | J15: =ROUNDUP(H15/4,0) -> 6 | K15: =J15+I15+H15 -> 39 | L15: =G15/22 -> 0.5
B16: Tipo | C16: 699.84 | D16: =C16*$C$32 -> 1749.6 | E16: 1.17 | F16: =8.8/E16 -> 7.5213675 | G16: 11 | H16: =ROUNDUP((D16*E16)/(G16*8.8),0) -> 22 | I16: =ROUNDUP(H16/2,0) -> 11 | J16: =ROUNDUP(H16/4,0) -> 6 | K16: =J16+I16+H16 -> 39 | L16: =G16/22 -> 0.5
B17: Tipo | C17: 699.84 | D17: =C17*$C$32 -> 1749.6 | E17: 1.17 | F17: =8.8/E17 -> 7.5213675 | G17: 11 | H17: =ROUNDUP((D17*E17)/(G17*8.8),0) -> 22 | I17: =ROUNDUP(H17/2,0) -> 11 | J17: =ROUNDUP(H17/4,0) -> 6 | K17: =J17+I17+H17 -> 39 | L17: =G17/22 -> 0.5
B18: Tipo | C18: 699.84 | D18: =C18*$C$32 -> 1749.6 | E18: 1.17 | F18: =8.8/E18 -> 7.5213675 | G18: 11 | H18: =ROUNDUP((D18*E18)/(G18*8.8),0) -> 22 | I18: =ROUNDUP(H18/2,0) -> 11 | J18: =ROUNDUP(H18/4,0) -> 6 | K18: =J18+I18+H18 -> 39 | L18: =G18/22 -> 0.5
B19: Tipo | C19: 699.84 | D19: =C19*$C$32 -> 1749.6 | E19: 1.17 | F19: =8.8/E19 -> 7.5213675 | G19: 11 | H19: =ROUNDUP((D19*E19)/(G19*8.8),0) -> 22 | I19: =ROUNDUP(H19/2,0) -> 11 | J19: =ROUNDUP(H19/4,0) -> 6 | K19: =J19+I19+H19 -> 39 | L19: =G19/22 -> 0.5
... B24: Tipo | C24: 699.84 | D24: =C24*$C$32 -> 1749.6 | E24: 1.17 | F24: =8.8/E24 -> 7.5213675 | G24: 11 | H24: =ROUNDUP((D24*E24)/(G24*8.8),0) -> 22 | I24: =ROUNDUP(H24/2,0) -> 11 | J24: =ROUNDUP(H24/4,0) -> 6 | K24: =J24+I24+H24 -> 39 | L24: =G24/22 -> 0.5
B25: Tipo | C25: =9097.92/13 -> 699.84 | D25: =C25*$C$32 -> 1749.6 | E25: 1.17 | F25: =8.8/E25 -> 7.5213675 | G25: 11 | H25: =ROUNDUP((D25*E25)/(G25*8.8),0) -> 22 | I25: =ROUNDUP(H25/2,0) -> 11 | J25: =ROUNDUP(H25/4,0) -> 6 | K25: =J25+I25+H25 -> 39 | L25: =G25/22 -> 0.5
B26: Tipo dif | C26: 699.84 | D26: =C26*$C$32 -> 1749.6 | E26: 1.21 | F26: =8.8/E26 -> 7.2727273 | G26: 11 | H26: =ROUNDUP((D26*E26)/(G26*8.8),0) -> 22 | I26: =ROUNDUP(H26/2,0) -> 11 | J26: =ROUNDUP(H26/4,0) -> 6 | K26: =J26+I26+H26 -> 39 | L26: =G26/22 -> 0.5
B27: Lazer | C27: 2513.4 | D27: =C27*$C$32 -> 6283.5 | E27: 2.01 | F27: =8.8/E27 -> 4.3781095 | G27: 48 | H27: =ROUNDUP((D27*E27)/(G27*8.8),0) -> 30 | I27: =ROUNDUP(H27/2,0) -> 15 | J27: =ROUNDUP(H27/4,0) -> 8 | K27: =J27+I27+H27 -> 53 | L27: =G27/22 -> 2.1818182
B28: Garagem 2 | C28: 2514.32 | D28: =C28*$C$32 -> 6285.8 | E28: 2.2 | F28: =8.8/E28 -> 4 | G28: 53 | H28: =ROUNDUP((D28*E28)/(G28*8.8),0) -> 30 | I28: =ROUNDUP(H28/2,0) -> 15 | J28: =ROUNDUP(H28/4,0) -> 8 | K28: =J28+I28+H28 -> 53 | L28: =G28/22 -> 2.4090909
B29: Garagem 1 | C29: 2339.03 | D29: =C29*$C$32 -> 5847.575 | E29: 2.2 | F29: =8.8/E29 -> 4 | G29: 49 | H29: =ROUNDUP((D29*E29)/(G29*8.8),0) -> 30 | I29: =ROUNDUP(H29/2,0) -> 15 | J29: =ROUNDUP(H29/4,0) -> 8 | K29: =J29+I29+H29 -> 53 | L29: =G29/22 -> 2.2272727
B30: Terreo | C30: 2365.57 | D30: =C30*$C$32 -> 5913.925 | E30: 2.01 | F30: =8.8/E30 -> 4.3781095 | G30: 46 | H30: =ROUNDUP((D30*E30)/(G30*8.8),0) -> 30 | I30: =ROUNDUP(H30/2,0) -> 15 | J30: =ROUNDUP(H30/4,0) -> 8 | K30: =J30+I30+H30 -> 53 | L30: =G30/22 -> 2.0909091
C31: =SUM(C8:C30) -> 21510.28
B32: FATOR MULT (X) | C32: 2.5 | F32: Total Dias | G32: =SUM(G8:G30) -> 398 | H32: Total Meses | I32: =G32/22 -> 18.090909
B33: RUP | I33: =(SUM(G27:G30))/22 -> 8.9090909
B34: Garagens | C34: 2.2 | I34: =(SUM(G8:G26))/22 -> 9.1818182
B35: Lazer | C35: 2.01
B36: Tipo Dif | C36: 1.21
B37: Tipo | C37: 1.17
B38: Técnicos | C38: 1.6

Sheet d. Fachada
B3: DIMENSIONAMENTO DE PRAZO - FACHADA
B6: HOTEL
B7: Serviço | C7: Quant (m²) | D7: RUP | E7: Dias | F7: Profissional | G7: Servente
B8: Chapisco | C8: 2678.8177 | D8: 0.1742 | E8: 15 | F8: =ROUNDUP(((($C8*D8)/(E8*8.8))),0) -> 4 | G8: =ROUNDUP(F8/2,0) -> 2
B9: Reboco | C9: 2678.8177 | D9: 0.6328 | E9: 49 | F9: =ROUNDUP(((($C9*D9)/(E9*8.8))),0) -> 4 | G9: =ROUNDUP(F9/2,0) -> 2
B10: Selador | C10: =C8 -> 2678.8177 | D10: 0.047 | E10: 8 | F10: =ROUNDUP(((($C10*D10)/(E10*8.8))),0) -> 2 | G10: =ROUNDUP(F10/2,0) -> 1
B11: Textura | C11: =C8 -> 2678.8177 | D11: 0.1855 | E11: 29 | F11: =ROUNDUP(((($C11*D11)/(E11*8.8))),0) -> 2 | G11: =ROUNDUP(F11/2,0) -> 1
B12: Moldura + reboco (1/2 duração de reboco) | D12: 0.945 | E12: =ROUNDUP(E9*0.75,0) -> 37 | F12: =ROUNDUP(((($C12*D12)/(E12*8.8))),0) -> 0 | G12: =ROUNDUP(F12/2,0) -> 0
B13: Preparação | C13: - | D13: - | E13: =5*4 -> 20 | F13: - | G13: -
B14: Balancim | C14: - | D14: - | E14: =4*4 -> 16 | F14: - | G14: -
D15: Total Dias | E15: =SUM(E8:E14) -> 174 | F15: Total Meses | G15: =E15/22 -> 7.9090909
B17: MOLDURAS EPS PINTADAS
B18: RESIDENCIAL
B19: Serviço | C19: Quant (m²) | D19: RUP | E19: Dias | F19: Profissional | G19: Servente
B20: Chapisco | C20: 13476.324 | D20: 0.1742 | E20: 27 | F20: =ROUNDUP(((($C20*D20)/(E20*8.8))),0) -> 10 | G20: =ROUNDUP(F20/2,0) -> 5 | I20: 4 EM CADA TORRE
B21: Reboco | C21: 13476.324 | D21: 0.6328 | E21: 97 | F21: =ROUNDUP(((($C21*D21)/(E21*8.8))),0) -> 10 | G21: =ROUNDUP(F21/2,0) -> 5
B22: Selador | C22: 13476.324 | D22: 0.047 | E22: 8 | F22: =ROUNDUP(((($C22*D22)/(E22*8.8))),0) -> 9 | G22: =ROUNDUP(F22/2,0) -> 5
B23: Textura | C23: 13476.324 | D23: 0.1855 | E23: 29 | F23: =ROUNDUP(((($C23*D23)/(E23*8.8))),0) -> 10 | G23: =ROUNDUP(F23/2,0) -> 5
B24: Moldura + reboco (1/2 duração de reboco) | D24: 0.945 | E24: =ROUNDUP(E21*0.5,0) -> 49 | F24: =ROUNDUP(((($C24*D24)/(E24*8.8))),0) -> 0 | G24: =ROUNDUP(F24/2,0) -> 0
B25: Preparação | C25: - | D25: - | E25: =5*4 -> 20 | F25: - | G25: -
B26: Balancim | C26: - | D26: - | E26: =4*4 -> 16 | F26: - | G26: -
D27: Total Dias | E27: =SUM(E20:E26) -> 246 | F27: Total Meses | G27: =E27/22 -> 11.181818
B29: MOLDURAS EPS PINTADAS

Sheet e. ESTIMATIVA PRAZO HOTEL
B3: ESTIMATIVA DE PRAZO
H5: ESTIMATIVA DE PRAZO | BK5: DIVISÃO DE CUSTOS PARA CURVAS
B6: Serviço | C6: Prazo | G6: SERVIÇOS | H6: M1 | I6: M2 | J6: M3 | K6: M4 | L6: M5 | M6: M6 | N6: M7 | O6: M8 | P6: M9 | Q6: M10 | R6: M11 | S6: M12 | T6: M13 | U6: M14 | V6: M15 | W6: M16 | X6: M17 | Y6: M18 | Z6: M19 | AA6: M20 | AB6: M21 | AC6: M22 | AD6: M23 | AE6: M24 | AF6: M25 | AG6: M26 | AH6: M27 | AI6: M28 | AJ6: M29 | AK6: M30 | AL6: M31 | AM6: M32 | AN6: M33 | AO6: M34 | AP6: M35 | AQ6: M36 | AR6: M37 | AS6: M38 | AT6: M39 | AU6: M40 | AV6: M41 | AW6: M42 | AX6: M43 | AY6: M44 | AZ6: M45 | BA6: M46 | BB6: M47 | BC6: M48 | BD6: M49 | BE6: M50 | BF6: M51 | BG6: M52 | BH6: M53 | BI6: M54 | BK6: SERVIÇOS ORÇAMENTO | BL6: SERVIÇO PLANEJAMENTO | BM6: M1 | BN6: M2 | BO6: M3 | BP6: M4 | BQ6: M5 | BR6: M6 | BS6: M7 | BT6: M8 | BU6: M9 | BV6: M10 | BW6: M11 | BX6: M12 | BY6: M13 | BZ6: M14 | CA6: M15 | CB6: M16 | CC6: M17 | CD6: M18 | CE6: M19 | CF6: M20 | CG6: M21 | CH6: M22 | CI6: M23 | CJ6: M24 | CK6: M25 | CL6: M26 | CM6: M27 | CN6: M28 | CO6: M29 | CP6: M30 | CQ6: M31 | CR6: M32 | CS6: M33 | CT6: M34 | CU6: M35 | CV6: M36 | CW6: M37 | CX6: M38 | CY6: M39 | CZ6: M40
B7: Iniciais | C7: 1 | D7: ="+/- 1 mês" -> +/- 1 mês | G7: Iniciais | H7: 1 | BK7: MOVIMENTAÇÃO DE TERRA | BL7: Iniciais | BM7: 1
B8: Infra | C8: ='b. Fundação'!H11+'b. Fundação'!L19 -> 5.5090909 | D8: Dimensionamento de Fundações | G8: Infra | I8: 1 | J8: 2 | K8: 3 | L8: 4 | M8: 5 | BK8: INFRAESTRUTURA | BL8: Infra | BN8: 1 | BO8: 2 | BP8: 3 | BQ8: 4 | BR8: 5
B9: Supra | C9: ='c. Supraestrutura HOTEL'!I15 -> 6.2727273 | D9: Dimensionamento de Supraestrutura | G9: Supra | N9: 1 | O9: 2 | P9: 3 | Q9: 4 | R9: 5 | S9: 6 | T9: 7 | U9: 8 | BK9: SUPRAESTRUTURA | BL9: Supra | BS9: 1 | BT9: 2 | BU9: 3 | BV9: 4 | BW9: 5 | BX9: 6 | BY9: 7 | BZ9: 8 | CA9: 9 | CB9: 10 | CC9: 11 | CD9: 12 | CE9: 13 | CF9: 14 | CG9: 15 | CH9: 16
B10: Alvenaria (3 meses após supra) | C10: 2 | D10: ="+/-3 meses após o término da Supraestrutura" -> +/-3 meses após o término da Supraestrutura | G10: Alvenaria | Q10: 1 | R10: 2 | S10: 3 | T10: 4 | U10: 5 | V10: 6 | W10: 7 | X10: 8 | BK10: ALVENARIA | BL10: Alvenaria | BW10: 1 | BX10: 2 | BY10: 3 | BZ10: 4 | CA10: 5 | CB10: 6 | CC10: 7 | CD10: 8 | CE10: 9 | CF10: 10 | CG10: 11 | CH10: 12 | CI10: 13 | CJ10: 14 | CK10: 15
B11: Fachada | C11: ='d. Fachada'!G15 -> 7.9090909 | D11: Dimensionamento de fachada | G11: Fachada | Y11: 1 | Z11: 2 | AA11: 3 | AB11: 4 | AC11: 5 | AD11: 6 | AE11: 7 | BK11: INSTALAÇÕES ELÉTRICAS, HIDRÁULICAS, GLP E PREVENTIVAS | BL11: INSTALAÇÕES ELÉTRICAS, HIDRÁULICAS, GLP E PREVENTIVAS | BX11: 1 | BY11: 2 | BZ11: 3 | CA11: 4 | CB11: 5 | CC11: 6 | CD11: 7 | CE11: 8 | CF11: 9 | CG11: 10 | CH11: 11 | CI11: 12 | CJ11: 13 | CK11: 14 | CL11: 15 | CM11: 16
B12: Acabamentos | C12: 12 | D12: ="+/-12 meses após o término da Alvenaria" -> +/-12 meses após o término da Alvenaria | G12: Acabamentos | Y12: 1 | Z12: 2 | AA12: 3 | AB12: 4 | AC12: 5 | AD12: 6 | AE12: 7 | AF12: 8 | AG12: 9 | AH12: 10 | AI12: 11 | AJ12: 12 | BK12: EQUIPAMENTOS E SISTEMAS ESPECIAIS | BL12: EQUIPAMENTOS E SISTEMAS ESPECIAIS | CL12: 1 | CM12: 2 | CN12: 3 | CO12: 4 | CP12: 5 | CQ12: 6
B13: Serviços Finais | C13: 5 | D13: ="+/-5 a 6 meses após o término da Fachada" -> +/-5 a 6 meses após o término da Fachada | G13: Serviços Finais | AK13: 1 | AL13: 2 | AM13: 3 | AN13: 4 | AO13: 5 | AP13: 6 | BK13: IMPERMEABILIZAÇÃO | BL13: IMPERMEABILIZAÇÃO | CA13: 1 | CB13: 2 | CC13: 3 | CD13: 4 | CE13: 5 | CF13: 6 | CG13: 7 | CH13: 8 | CI13: 9 | CJ13: 10 | CK13: 11 | CL13: 12 | CM13: 13 | CN13: 14 | CO13: 15 | CP13: 16
BK14: REVESTIMENTOS INTERNOS EM PISO E PAREDE | BL14: REVESTIMENTOS INTERNOS EM PISO E PAREDE | BY14: 1 | BZ14: 2 | CA14: 3 | CB14: 4 | CC14: 5 | CD14: 6 | CE14: 7 | CF14: 8 | CG14: 9 | CH14: 10 | CI14: 11 | CJ14: 12 | CK14: 13 | CL14: 14 | CM14: 15 | CN14: 16 | CO14: 17
B15: Grua | C15: =C9+1 -> 7.2727273 | D15: Prazo de supra + 1 mês | G15: SERVIÇOS | H15: M1 | I15: M2 | J15: M3 | K15: M4 | L15: M5 | M15: M6 | N15: M7 | O15: M8 | P15: M9 | Q15: M10 | R15: M11 | S15: M12 | T15: M13 | U15: M14 | V15: M15 | W15: M16 | X15: M17 | Y15: M18 | Z15: M19 | AA15: M20 | AB15: M21 | AC15: M22 | AD15: M23 | AE15: M24 | AF15: M25 | AG15: M26 | AH15: M27 | AI15: M28 | AJ15: M29 | AK15: M30 | AL15: M31 | AM15: M32 | AN15: M33 | AO15: M34 | AP15: M35 | AQ15: M36 | AR15: M37 | AS15: M38 | AT15: M39 | AU15: M40 | AV15: M41 | AW15: M42 | AX15: M43 | AY15: M44 | AZ15: M45 | BA15: M46 | BB15: M47 | BC15: M48 | BK15: REVESTIMENTOS E ACABAMENTOS INTERNOS EM TETO | BL15: REVESTIMENTOS E ACABAMENTOS INTERNOS EM TETO | CC15: 1 | CD15: 2 | CE15: 3 | CF15: 4 | CG15: 5 | CH15: 6 | CI15: 7 | CJ15: 8 | CK15: 9 | CL15: 10 | CM15: 11 | CN15: 12 | CO15: 13 | CP15: 14 | CQ15: 15 | CR15: 16
B16: Balancim | C16: =C11+1 -> 8.9090909 | D16: Prazo de Fachada + 1 mês | G16: MOVIMENTAÇÃO DE TERRA | H16: 1 | I16: 2 | J16: 3
B17: Cremalheira | C17: =C9-(('c. Supraestrutura HOTEL'!G13+'c. Supraestrutura HOTEL'!G12+'c. Supraestrutura HOTEL'!G11)/22)+C10+B21 -> 8.4090909 | D17: Montada no 3º pavimento de supraestrutura, desmontada após a instalação do elevador da obra | G17: INFRAESTRUTURA | H17: 1 | I17: 2 | J17: 3 | K17: 4 | L17: 5 | M17: 6 | N17: 7 | O17: 8 | BK17: ACABAMENTOS EM PISO E PAREDE | BL17: ACABAMENTOS EM PISO E PAREDE | CB17: 1 | CC17: 2 | CD17: 3 | CE17: 4 | CF17: 5 | CG17: 6 | CH17: 7 | CI17: 8 | CJ17: 9 | CK17: 10 | CL17: 11 | CM17: 12 | CN17: 13 | CO17: 14 | CP17: 15 | CQ17: 16 | CR17: 17 | CS17: 18
G18: SUPRAESTRUTURA | P18: 1 | Q18: 2 | R18: 3 | S18: 4 | T18: 5 | U18: 6 | V18: 7 | W18: 8 | X18: 9 | Y18: 10 | Z18: 11 | AA18: 12 | AB18: 13 | AC18: 14 | AD18: 15 | AE18: 16 | AF18: 17 | AG18: 18 | BK18: PINTURA INTERNA | BL18: PINTURA INTERNA | CD18: 1 | CE18: 2 | CF18: 3 | CG18: 4 | CH18: 5 | CI18: 6 | CJ18: 7 | CK18: 8 | CL18: 9 | CM18: 10 | CN18: 11 | CO18: 12 | CP18: 13 | CQ18: 14 | CR18: 15 | CS18: 16 | CT18: 17 | CU18: 18 | CV18: 19 | CW18: 20
B19: Preparação do Fosso do elevador | C19: =15+15+15 -> 45 | G19: ALVENARIA | S19: 1 | T19: 2 | U19: 3 | V19: 4 | W19: 5 | X19: 6 | Y19: 7 | Z19: 8 | AA19: 9 | AB19: 10 | AC19: 11 | AD19: 12 | AE19: 13 | AF19: 14 | AG19: 15 | AH19: 16 | AI19: 17 | AJ19: 18 | BK19: ESQUADRIAS, VIDROS E FERRAGENS | BL19: ESQUADRIAS, VIDROS E FERRAGENS | CN19: 1 | CO19: 2 | CP19: 3 | CQ19: 4 | CR19: 5 | CS19: 6 | CT19: 7 | CU19: 8 | CV19: 9 | CW19: 10 | CX19: 11
B20: Montagem Elevador | C20: 60 | G20: INSTALAÇÕES ELÉTRICAS, HIDRÁULICAS, GLP E PREVENTIVAS | U20: 1 | V20: 2 | W20: 3 | X20: 4 | Y20: 5 | Z20: 6 | AA20: 7 | AB20: 8 | AC20: 9 | AD20: 10 | AE20: 11 | AF20: 12 | AG20: 13 | AH20: 14 | AI20: 15 | AJ20: 16 | AK20: 17 | BK20: COBERTURA | BL20: COBERTURA | CU20: 1 | CV20: 2 | CW20: 3 | CX20: 4
B21: =C21/22 -> 4.7727273 | C21: =C19+C20 -> 105 | G21: EQUIPAMENTOS E SISTEMAS ESPECIAIS | AE21: 1 | AF21: 2 | AG21: 3 | AH21: 4 | AI21: 5 | AJ21: 6 | AK21: 7 | AL21: 8 | AM21: 9 | AN21: 10 | AO21: 11 | AP21: 12 | AQ21: 13 | AR21: 14 | BK21: REVESTIMENTOS E ACABAMENTOS DE FACHADA | BL21: REVESTIMENTOS E ACABAMENTOS DE FACHADA | CL21: 1 | CM21: 2 | CN21: 3 | CO21: 4 | CP21: 5 | CQ21: 6 | CR21: 7 | CS21: 8 | CT21: 9
G22: IMPERMEABILIZAÇÃO | W22: 1 | X22: 2 | Y22: 3 | Z22: 4 | AA22: 5 | AB22: 6 | AC22: 7 | AD22: 8 | AE22: 9 | AF22: 10 | AG22: 11 | AH22: 12 | AI22: 13 | AJ22: 14 | AK22: 15 | AL22: 16 | AM22: 17 | BK22: SERVIÇOS COMPLEMENTARES | BL22: Serviços Finais | CU22: 1 | CV22: 2 | CW22: 3 | CX22: 4 | CY22: 5 | CZ22: 6
G23: REVESTIMENTOS INTERNOS EM PISO E PAREDE | V23: 1 | W23: 2 | X23: 3 | Y23: 4 | Z23: 5 | AA23: 6 | AB23: 7 | AC23: 8 | AD23: 9 | AE23: 10 | AF23: 11 | AG23: 12 | AH23: 13 | AI23: 14 | AJ23: 15 | AK23: 16 | AL23: 17 | BL23: Acabamentos | CL23: 1 | CM23: 2 | CN23: 3 | CO23: 4 | CP23: 5 | CQ23: 6 | CR23: 7 | CS23: 8 | CT23: 9 | CU23: 10 | CV23: 11 | CW23: 12
G24: REVESTIMENTOS E ACABAMENTOS INTERNOS EM TETO | Y24: 1 | Z24: 2 | AA24: 3 | AB24: 4 | AC24: 5 | AD24: 6 | AE24: 7 | AF24: 8 | AG24: 9 | AH24: 10 | AI24: 11 | AJ24: 12 | AK24: 13 | AL24: 14 | AM24: 15 | AN24: 16 | AO24: 17
G25: ACABAMENTOS EM PISO E PAREDE | X25: 1 | Y25: 2 | Z25: 3 | AA25: 4 | AB25: 5 | AC25: 6 | AD25: 7 | AE25: 8 | AF25: 9 | AG25: 10 | AH25: 11 | AI25: 12 | AJ25: 13 | AK25: 14 | AL25: 15 | AM25: 16 | AN25: 17 | AO25: 18 | AP25: 19 | AQ25: 20 | AR25: 21 | AS25: 22 | AT25: 23 | AU25: 24 | AV25: 25
G26: PINTURA INTERNA | Z26: 1 | AA26: 2 | AB26: 3 | AC26: 4 | AD26: 5 | AE26: 6 | AF26: 7 | AG26: 8 | AH26: 9 | AI26: 10 | AJ26: 11 | AK26: 12 | AL26: 13 | AM26: 14 | AN26: 15 | AO26: 16 | AP26: 17 | AQ26: 18 | AR26: 19 | AS26: 20 | AT26: 21 | AU26: 22 | AV26: 23 | AW26: 24 | AX26: 25 | AY26: 26 | AZ26: 27
G27: ESQUADRIAS, VIDROS E FERRAGENS | AK27: 1 | AL27: 2 | AM27: 3 | AN27: 4 | AO27: 5 | AP27: 6 | AQ27: 7 | AR27: 8 | AS27: 9 | AT27: 10
G28: COBERTURA
G29: REVESTIMENTOS E ACABAMENTOS DE FACHADA | AK29: 1 | AL29: 2 | AM29: 3 | AN29: 4 | AO29: 5 | AP29: 6
G30: SERVIÇOS COMPLEMENTARES | AT30: 1 | AU30: 2 | AV30: 3 | AW30: 4 | AX30: 5 | AY30: 6 | AZ30: 7 | BA30: 8

Sheet e. ESTIMATIVA PRAZO RESID
B3: ESTIMATIVA DE PRAZO
H5: ESTIMATIVA DE PRAZO | BT5: DIVISÃO DE CUSTOS PARA CURVAS
B6: Serviço | C6: Prazo | G6: SERVIÇOS | H6: M1 | I6: M2 | J6: M3 | K6: M4 | L6: M5 | M6: M6 | N6: M7 | O6: M8 | P6: M9 | Q6: M10 | R6: M11 | S6: M12 | T6: M13 | U6: M14 | V6: M15 | W6: M16 | X6: M17 | Y6: M18 | Z6: M19 | AA6: M20 | AB6: M21 | AC6: M22 | AD6: M23 | AE6: M24 | AF6: M25 | AG6: M26 | AH6: M27 | AI6: M28 | AJ6: M29 | AK6: M30 | AL6: M31 | AM6: M32 | AN6: M33 | AO6: M34 | AP6: M35 | AQ6: M36 | AR6: M37 | AS6: M38 | AT6: M39 | AU6: M40 | AV6: M41 | AW6: M42 | AX6: M43 | AY6: M44 | AZ6: M45 | BA6: M46 | BB6: M47 | BC6: M48 | BD6: M49 | BE6: M50 | BF6: M51 | BG6: M52 | BH6: M53 | BI6: M54 | BJ6: M55 | BK6: M56 | BL6: M57 | BM6: M58 | BN6: M59 | BO6: M60 | BP6: M61 | BQ6: M62 | BR6: M63 | BT6: SERVIÇOS ORÇAMENTO | BU6: SERVIÇO PLANEJAMENTO | BV6: M1 | BW6: M2 | BX6: M3 | BY6: M4 | BZ6: M5 | CA6: M6 | CB6: M7 | CC6: M8 | CD6: M9 | CE6: M10 | CF6: M11 | CG6: M12 | CH6: M13 | CI6: M14 | CJ6: M15 | CK6: M16 | CL6: M17 | CM6: M18 | CN6: M19 | CO6: M20 | CP6: M21 | CQ6: M22 | CR6: M23 | CS6: M24 | CT6: M25 | CU6: M26 | CV6: M27 | CW6: M28 | CX6: M29 | CY6: M30 | CZ6: M31 | DA6: M32 | DB6: M33 | DC6: M34 | DD6: M35 | DE6: M36 | DF6: M37 | DG6: M38 | DH6: M39 | DI6: M40
B7: Iniciais | C7: 1 | D7: ="+/- 1 mês" -> +/- 1 mês | G7: Iniciais | H7: 1 | BT7: MOVIMENTAÇÃO DE TERRA | BU7: Iniciais | BV7: 1
B8: Infra | C8: ='b. Fundação'!H29+'b. Fundação'!L37 -> 7.8 | D8: Dimensionamento de Fundações | G8: Infra | I8: 1 | J8: 2 | K8: 3 | L8: 4 | M8: 5 | N8: 6 | O8: 7 | P8: 8 | BT8: INFRAESTRUTURA | BU8: Infra | BW8: 1 | BX8: 2 | BY8: 3 | BZ8: 4 | CA8: 5
B9: Supra | C9: ='c. Supraestrutura RESID'!I32 -> 18.090909 | D9: Dimensionamento de Supraestrutura | G9: Supra | Q9: 1 | R9: 2 | S9: 3 | T9: 4 | U9: 5 | V9: 6 | W9: 7 | X9: 8 | Y9: 9 | Z9: 10 | AA9: 11 | AB9: 12 | AC9: 13 | AD9: 14 | AE9: 15 | AF9: 16 | AG9: 17 | AH9: 18 | AI9: 19 | AJ9: 20 | AK9: 21 | AL9: 22 | BT9: SUPRAESTRUTURA | BU9: Supra | CB9: 1 | CC9: 2 | CD9: 3 | CE9: 4 | CF9: 5 | CG9: 6 | CH9: 7 | CI9: 8 | CJ9: 9 | CK9: 10 | CL9: 11 | CM9: 12 | CN9: 13 | CO9: 14 | CP9: 15 | CQ9: 16
B10: Alvenaria (3 meses após supra) | C10: 3 | D10: ="+/-3 meses após o término da Supraestrutura" -> +/-3 meses após o término da Supraestrutura | G10: Alvenaria | T10: 1 | U10: 2 | V10: 3 | W10: 4 | X10: 5 | Y10: 6 | Z10: 7 | AA10: 8 | AB10: 9 | AC10: 10 | AD10: 11 | AE10: 12 | AF10: 13 | AG10: 14 | AH10: 15 | AI10: 16 | AJ10: 17 | AK10: 18 | AL10: 19 | AM10: 20 | AN10: 21 | AO10: 22 | BT10: ALVENARIA | BU10: Alvenaria | CF10: 1 | CG10: 2 | CH10: 3 | CI10: 4 | CJ10: 5 | CK10: 6 | CL10: 7 | CM10: 8 | CN10: 9 | CO10: 10 | CP10: 11 | CQ10: 12 | CR10: 13 | CS10: 14 | CT10: 15
B11: Fachada | C11: ='d. Fachada'!G27 -> 11.181818 | D11: Dimensionamento de fachada | G11: Fachada | AP11: 1 | AQ11: 2 | AR11: 3 | AS11: 4 | AT11: 5 | AU11: 6 | AV11: 7 | AW11: 8 | AX11: 9 | AY11: 10 | AZ11: 11 | BT11: INSTALAÇÕES ELÉTRICAS, HIDRÁULICAS, GLP E PREVENTIVAS | BU11: INSTALAÇÕES ELÉTRICAS, HIDRÁULICAS, GLP E PREVENTIVAS | CG11: 1 | CH11: 2 | CI11: 3 | CJ11: 4 | CK11: 5 | CL11: 6 | CM11: 7 | CN11: 8 | CO11: 9 | CP11: 10 | CQ11: 11 | CR11: 12 | CS11: 13 | CT11: 14 | CU11: 15 | CV11: 16
B12: Acabamentos | C12: 12 | D12: ="+/-12 meses após o término da Alvenaria" -> +/-12 meses após o término da Alvenaria | G12: Acabamentos | BA12: 1 | BB12: 2 | BC12: 3 | BD12: 4 | BE12: 5 | BF12: 6 | BG12: 7 | BH12: 8 | BI12: 9 | BJ12: 10 | BK12: 11 | BL12: 12 | BT12: EQUIPAMENTOS E SISTEMAS ESPECIAIS | BU12: EQUIPAMENTOS E SISTEMAS ESPECIAIS | CU12: 1 | CV12: 2 | CW12: 3 | CX12: 4 | CY12: 5 | CZ12: 6
B13: Serviços Finais | C13: 5 | D13: ="+/-5 a 6 meses após o término da Fachada" -> +/-5 a 6 meses após o término da Fachada | G13: Serviços Finais | BM13: 1 | BN13: 2 | BO13: 3 | BP13: 4 | BQ13: 5 | BR13: 6 | BT13: IMPERMEABILIZAÇÃO | BU13: IMPERMEABILIZAÇÃO | CJ13: 1 | CK13: 2 | CL13: 3 | CM13: 4 | CN13: 5 | CO13: 6 | CP13: 7 | CQ13: 8 | CR13: 9 | CS13: 10 | CT13: 11 | CU13: 12 | CV13: 13 | CW13: 14 | CX13: 15 | CY13: 16
BT14: REVESTIMENTOS INTERNOS EM PISO E PAREDE | BU14: REVESTIMENTOS INTERNOS EM PISO E PAREDE | CH14: 1 | CI14: 2 | CJ14: 3 | CK14: 4 | CL14: 5 | CM14: 6 | CN14: 7 | CO14: 8 | CP14: 9 | CQ14: 10 | CR14: 11 | CS14: 12 | CT14: 13 | CU14: 14 | CV14: 15 | CW14: 16 | CX14: 17
B15: Grua | C15: =C9+1 -> 19.090909 | D15: Prazo de supra + 1 mês | G15: SERVIÇOS | H15: M1 | I15: M2 | J15: M3 | K15: M4 | L15: M5 | M15: M6 | N15: M7 | O15: M8 | P15: M9 | Q15: M10 | R15: M11 | S15: M12 | T15: M13 | U15: M14 | V15: M15 | W15: M16 | X15: M17 | Y15: M18 | Z15: M19 | AA15: M20 | AB15: M21 | AC15: M22 | AD15: M23 | AE15: M24 | AF15: M25 | AG15: M26 | AH15: M27 | AI15: M28 | AJ15: M29 | AK15: M30 | AL15: M31 | AM15: M32 | AN15: M33 | AO15: M34 | AP15: M35 | AQ15: M36 | AR15: M37 | AS15: M38 | AT15: M39 | AU15: M40 | AV15: M41 | AW15: M42 | AX15: M43 | AY15: M44 | AZ15: M45 | BA15: M46 | BB15: M47 | BC15: M48 | BT15: REVESTIMENTOS E ACABAMENTOS INTERNOS EM TETO | BU15: REVESTIMENTOS E ACABAMENTOS INTERNOS EM TETO | CL15: 1 | CM15: 2 | CN15: 3 | CO15: 4 | CP15: 5 | CQ15: 6 | CR15: 7 | CS15: 8 | CT15: 9 | CU15: 10 | CV15: 11 | CW15: 12 | CX15: 13 | CY15: 14 | CZ15: 15 | DA15: 16
B16: Balancim | C16: =C11+1 -> 12.181818 | D16: Prazo de Fachada + 1 mês | G16: MOVIMENTAÇÃO DE TERRA | H16: 1 | I16: 2 | J16: 3
B17: Cremalheira | C17: =C9-(('c. Supraestrutura RESID'!G13+'c. Supraestrutura RESID'!G12+'c. Supraestrutura RESID'!G11)/22)+C10+B21 -> 24.363636 | D17: Montada no 3º pavimento de supraestrutura, desmontada após a instalação do elevador da obra | G17: INFRAESTRUTURA | H17: 1 | I17: 2 | J17: 3 | K17: 4 | L17: 5 | M17: 6 | N17: 7 | O17: 8 | BT17: ACABAMENTOS EM PISO E PAREDE | BU17: ACABAMENTOS EM PISO E PAREDE | CK17: 1 | CL17: 2 | CM17: 3 | CN17: 4 | CO17: 5 | CP17: 6 | CQ17: 7 | CR17: 8 | CS17: 9 | CT17: 10 | CU17: 11 | CV17: 12 | CW17: 13 | CX17: 14 | CY17: 15 | CZ17: 16 | DA17: 17 | DB17: 18
G18: SUPRAESTRUTURA | P18: 1 | Q18: 2 | R18: 3 | S18: 4 | T18: 5 | U18: 6 | V18: 7 | W18: 8 | X18: 9 | Y18: 10 | Z18: 11 | AA18: 12 | AB18: 13 | AC18: 14 | AD18: 15 | AE18: 16 | AF18: 17 | AG18: 18 | BT18: PINTURA INTERNA | BU18: PINTURA INTERNA | CM18: 1 | CN18: 2 | CO18: 3 | CP18: 4 | CQ18: 5 | CR18: 6 | CS18: 7 | CT18: 8 | CU18: 9 | CV18: 10 | CW18: 11 | CX18: 12 | CY18: 13 | CZ18: 14 | DA18: 15 | DB18: 16 | DC18: 17 | DD18: 18 | DE18: 19 | DF18: 20
B19: Preparação do Fosso do elevador | C19: =15+15+15 -> 45 | G19: ALVENARIA | S19: 1 | T19: 2 | U19: 3 | V19: 4 | W19: 5 | X19: 6 | Y19: 7 | Z19: 8 | AA19: 9 | AB19: 10 | AC19: 11 | AD19: 12 | AE19: 13 | AF19: 14 | AG19: 15 | AH19: 16 | AI19: 17 | AJ19: 18 | BT19: ESQUADRIAS, VIDROS E FERRAGENS | BU19: ESQUADRIAS, VIDROS E FERRAGENS | CW19: 1 | CX19: 2 | CY19: 3 | CZ19: 4 | DA19: 5 | DB19: 6 | DC19: 7 | DD19: 8 | DE19: 9 | DF19: 10 | DG19: 11
B20: Montagem Elevador | C20: 60 | G20: INSTALAÇÕES ELÉTRICAS, HIDRÁULICAS, GLP E PREVENTIVAS | U20: 1 | V20: 2 | W20: 3 | X20: 4 | Y20: 5 | Z20: 6 | AA20: 7 | AB20: 8 | AC20: 9 | AD20: 10 | AE20: 11 | AF20: 12 | AG20: 13 | AH20: 14 | AI20: 15 | AJ20: 16 | AK20: 17 | BT20: COBERTURA | BU20: COBERTURA | DD20: 1 | DE20: 2 | DF20: 3 | DG20: 4
B21: =C21/22 -> 4.7727273 | C21: =C19+C20 -> 105 | G21: EQUIPAMENTOS E SISTEMAS ESPECIAIS | AE21: 1 | AF21: 2 | AG21: 3 | AH21: 4 | AI21: 5 | AJ21: 6 | AK21: 7 | AL21: 8 | AM21: 9 | AN21: 10 | AO21: 11 | AP21: 12 | AQ21: 13 | AR21: 14 | BT21: REVESTIMENTOS E ACABAMENTOS DE FACHADA | BU21: REVESTIMENTOS E ACABAMENTOS DE FACHADA | CU21: 1 | CV21: 2 | CW21: 3 | CX21: 4 | CY21: 5 | CZ21: 6 | DA21: 7 | DB21: 8 | DC21: 9
G22: IMPERMEABILIZAÇÃO | W22: 1 | X22: 2 | Y22: 3 | Z22: 4 | AA22: 5 | AB22: 6 | AC22: 7 | AD22: 8 | AE22: 9 | AF22: 10 | AG22: 11 | AH22: 12 | AI22: 13 | AJ22: 14 | AK22: 15 | AL22: 16 | AM22: 17 | BT22: SERVIÇOS COMPLEMENTARES | BU22: Serviços Finais | DD22: 1 | DE22: 2 | DF22: 3 | DG22: 4 | DH22: 5 | DI22: 6
G23: REVESTIMENTOS INTERNOS EM PISO E PAREDE | V23: 1 | W23: 2 | X23: 3 | Y23: 4 | Z23: 5 | AA23: 6 | AB23: 7 | AC23: 8 | AD23: 9 | AE23: 10 | AF23: 11 | AG23: 12 | AH23: 13 | AI23: 14 | AJ23: 15 | AK23: 16 | AL23: 17 | BU23: Acabamentos | CU23: 1 | CV23: 2 | CW23: 3 | CX23: 4 | CY23: 5 | CZ23: 6 | DA23: 7 | DB23: 8 | DC23: 9 | DD23: 10 | DE23: 11 | DF23: 12
G24: REVESTIMENTOS E ACABAMENTOS INTERNOS EM TETO | Y24: 1 | Z24: 2 | AA24: 3 | AB24: 4 | AC24: 5 | AD24: 6 | AE24: 7 | AF24: 8 | AG24: 9 | AH24: 10 | AI24: 11 | AJ24: 12 | AK24: 13 | AL24: 14 | AM24: 15 | AN24: 16 | AO24: 17
G25: ACABAMENTOS EM PISO E PAREDE | X25: 1 | Y25: 2 | Z25: 3 | AA25: 4 | AB25: 5 | AC25: 6 | AD25: 7 | AE25: 8 | AF25: 9 | AG25: 10 | AH25: 11 | AI25: 12 | AJ25: 13 | AK25: 14 | AL25: 15 | AM25: 16 | AN25: 17 | AO25: 18 | AP25: 19 | AQ25: 20 | AR25: 21 | AS25: 22 | AT25: 23 | AU25: 24 | AV25: 25
G26: PINTURA INTERNA | Z26: 1 | AA26: 2 | AB26: 3 | AC26: 4 | AD26: 5 | AE26: 6 | AF26: 7 | AG26: 8 | AH26: 9 | AI26: 10 | AJ26: 11 | AK26: 12 | AL26: 13 | AM26: 14 | AN26: 15 | AO26: 16 | AP26: 17 | AQ26: 18 | AR26: 19 | AS26: 20 | AT26: 21 | AU26: 22 | AV26: 23 | AW26: 24 | AX26: 25 | AY26: 26 | AZ26: 27
G27: ESQUADRIAS, VIDROS E FERRAGENS | AK27: 1 | AL27: 2 | AM27: 3 | AN27: 4 | AO27: 5 | AP27: 6 | AQ27: 7 | AR27: 8 | AS27: 9 | AT27: 10
G28: COBERTURA
G29: REVESTIMENTOS E ACABAMENTOS DE FACHADA | AK29: 1 | AL29: 2 | AM29: 3 | AN29: 4 | AO29: 5 | AP29: 6
G30: SERVIÇOS COMPLEMENTARES | AT30: 1 | AU30: 2 | AV30: 3 | AW30: 4 | AX30: 5 | AY30: 6 | AZ30: 7 | BA30: 8

Sheet Planilha3
B2: HOTEL
B3: SERVIÇOS | C3: M1 | D3: M2 | E3: M3 | F3: M4 | G3: M5 | H3: M6 | I3: M7 | J3: M8 | K3: M9 | L3: M10 | M3: M11 | N3: M12 | O3: M13 | P3: M14 | Q3: M15 | R3: M16 | S3: M17 | T3: M18 | U3: M19 | V3: M20 | W3: M21 | X3: M22 | Y3: M23 | Z3: M24 | AA3: M25 | AB3: M26 | AC3: M27 | AD3: M28 | AE3: M29 | AF3: M30 | AG3: M31 | AH3: M32 | AI3: M33 | AJ3: M34 | AK3: M35 | AL3: M36 | AM3: M37 | AN3: M38 | AO3: M39 | AP3: M40 | AQ3: M41 | AR3: M42 | AS3: M43 | AT3: M44 | AU3: M45 | AV3: M46 | AW3: M47 | AX3: M48 | AY3: M49 | AZ3: M50 | BA3: M51 | BB3: M52 | BC3: M53 | BD3: M54
B4: Iniciais | C4: 1
B5: Infra | D5: 1 | E5: 2 | F5: 3 | G5: 4 | H5: 5
B6: Supra | I6: 1 | J6: 2 | K6: 3 | L6: 4 | M6: 5 | N6: 6
B7: Alvenaria | K7: 1 | L7: 2 | M7: 3 | N7: 4 | O7: 5 | P7: 6
B8: Fachada | Q8: 1 | R8: 2 | S8: 3 | T8: 4 | U8: 5 | V8: 6 | W8: 7
B9: Acabamentos | Q9: 1 | R9: 2 | S9: 3 | T9: 4 | U9: 5 | V9: 6 | W9: 7 | X9: 8 | Y9: 9 | Z9: 10
B10: Serviços Finais | AA10: 1 | AB10: 2 | AC10: 3 | AD10: 4 | AE10: 5
B11: RESID
B12: SERVIÇOS | C12: M1 | D12: M2 | E12: M3 | F12: M4 | G12: M5 | H12: M6 | I12: M7 | J12: M8 | K12: M9 | L12: M10 | M12: M11 | N12: M12 | O12: M13 | P12: M14 | Q12: M15 | R12: M16 | S12: M17 | T12: M18 | U12: M19 | V12: M20 | W12: M21 | X12: M22 | Y12: M23 | Z12: M24 | AA12: M25 | AB12: M26 | AC12: M27 | AD12: M28 | AE12: M29 | AF12: M30 | AG12: M31 | AH12: M32 | AI12: M33 | AJ12: M34 | AK12: M35 | AL12: M36 | AM12: M37 | AN12: M38 | AO12: M39 | AP12: M40 | AQ12: M41 | AR12: M42 | AS12: M43 | AT12: M44 | AU12: M45 | AV12: M46 | AW12: M47 | AX12: M48 | AY12: M49 | AZ12: M50 | BA12: M51 | BB12: M52 | BC12: M53 | BD12: M54 | BE12: M55 | BF12: M56 | BG12: M57 | BH12: M58 | BI12: M59 | BJ12: M60 | BK12: M61 | BL12: M62 | BM12: M63
B13: Iniciais | C13: 1
B14: Infra | D14: 1 | E14: 2 | F14: 3 | G14: 4 | H14: 5
B15: Supra | I15: 1 | J15: 2 | K15: 3 | L15: 4 | M15: 5 | N15: 6 | O15: 7 | P15: 8 | Q15: 9 | R15: 10 | S15: 11 | T15: 12 | U15: 13 | V15: 14 | W15: 15 | X15: 16 | Y15: 17 | Z15: 18
B16: Alvenaria | K16: 1 | L16: 2 | M16: 3 | N16: 4 | O16: 5 | P16: 6 | Q16: 7 | R16: 8 | S16: 9 | T16: 10 | U16: 11 | V16: 12 | W16: 13 | X16: 14 | Y16: 15 | Z16: 16 | AA16: 17 | AB16: 18
B17: Fachada | AC17: 1 | AD17: 2 | AE17: 3 | AF17: 4 | AG17: 5 | AH17: 6 | AI17: 7 | AJ17: 8 | AK17: 9 | AL17: 10 | AM17: 11
B18: Acabamentos | AC18: 1 | AD18: 2 | AE18: 3 | AF18: 4 | AG18: 5 | AH18: 6 | AI18: 7 | AJ18: 8 | AK18: 9 | AL18: 10
B19: Serviços Finais | AM19: 1 | AN19: 2 | AO19: 3 | AP19: 4 | AQ19: 5
S22: 24
S23: 36

Sheet CUSTOS_INDIRETOS
A1: ORÇAMENTO PARAMÉTRICO - CUSTOS INDIRETOS | H1: =H6+$I$5 -> 0.084583749 | I1: =I6+$I$5 -> 0.077829426 | J1: =J6+$I$5 -> 0.077829426 | K1: =K6+$I$5 -> 0.068986871 | L1: =L6+$I$5 -> 0.068986871 | M1: =M6+$I$5 -> 0.068986871
A3: Cliente | B3: =[4]OBRA!B2 -> D'Lohn Empreendiementos | G3: =F66 -> 4230121.3
A4: Obra | B4: =[4]OBRA!B1 -> Estreito | G4: =SUM(H7:M7) -> 1540964.2
A5: Data | B5: 45741 | G5: =G3-G4 -> 2689157.1 | H5: =G5/46 -> 58459.936 | I5: =H5/G3 -> 0.01381992 | J5: =G5/G3 -> 0.6357163
A6: Versão | B6: =[4]OBRA!B3 -> R00 | H6: =H7/$G$3 -> 0.070763829 | I6: =I7/$G$3 -> 0.064009506 | J6: =J7/$G$3 -> 0.064009506 | K6: =K7/$G$3 -> 0.055166952 | L6: =L7/$G$3 -> 0.055166952 | M6: =M7/$G$3 -> 0.055166952
A7: GERENCIAMENTO TÉCNICO | H7: =SUM(H9:H66) -> 299339.58 | I7: =SUM(I9:I66) -> 270767.97 | J7: =SUM(J9:J66) -> 270767.97 | K7: =SUM(K9:K66) -> 233362.9 | L7: =SUM(L9:L66) -> 233362.9 | M7: =SUM(M9:M66) -> 233362.9
A8: Código | B8: Descrição | C8: Un. | D8: Quantidade orçada | E8: Preço unitário | F8: Preço total | H8: 1 | I8: 2 | J8: 3 | K8: 4 | L8: 5 | M8: 6
A9: 01 | B9: GERENCIAMENTO TÉCNICO | F9: =F10+F15 -> 1365027.4
A10: 01.001 | B10: ESTUDOS, PROJETOS E CONSULTORIAS | F10: =SUM(F11:F14) -> 1091483.6
A11: 01.001.001 | B11: Estudos | F11: =[4]BASES!H11*1.1 -> 23028.207 | H11: =$F11/6 -> 3838.0345 | I11: =$F11/6 -> 3838.0345 | J11: =$F11/6 -> 3838.0345 | K11: =$F11/6 -> 3838.0345 | L11: =$F11/6 -> 3838.0345 | M11: =$F11/6 -> 3838.0345
A12: 01.001.002 | B12: Projetos | F12: =[4]BASES!H12*1.1 -> 758963.06 | H12: =$F12/6 -> 126493.84 | I12: =$F12/6 -> 126493.84 | J12: =$F12/6 -> 126493.84 | K12: =$F12/6 -> 126493.84 | L12: =$F12/6 -> 126493.84 | M12: =$F12/6 -> 126493.84
A13: 01.001.003 | B13: Consultorias | F13: =[4]BASES!H13*1.1 -> 140400.91 | H13: =$F13/6 -> 23400.152 | I13: =$F13/6 -> 23400.152 | J13: =$F13/6 -> 23400.152 | K13: =$F13/6 -> 23400.152 | L13: =$F13/6 -> 23400.152 | M13: =$F13/6 -> 23400.152
A14: 01.001.004 | B14: Ensaios e Laudos | F14: =[4]BASES!H14*1.1 -> 169091.45 | H14: =$F14/6 -> 28181.908 | I14: =$F14/6 -> 28181.908 | J14: =$F14/6 -> 28181.908 | K14: =$F14/6 -> 28181.908 | L14: =$F14/6 -> 28181.908 | M14: =$F14/6 -> 28181.908
A15: 01.002 | B15: TAXAS E DOCUMENTOS | F15: =SUM(F16:F18) -> 273543.75
A16: 01.002.001 | B16: Seguros | F16: =[4]BASES!H16*1.1 -> 27131.405 | H16: =$F16/6 -> 4521.9008 | I16: =$F16/6 -> 4521.9008 | J16: =$F16/6 -> 4521.9008 | K16: =$F16/6 -> 4521.9008 | L16: =$F16/6 -> 4521.9008 | M16: =$F16/6 -> 4521.9008
A17: 01.002.002 | B17: Licenciamentos, Taxas, Impostos | F17: =[4]BASES!H17*1.1 -> 172391.98 | H17: =$F17/6 -> 28731.996 | I17: =$F17/6 -> 28731.996 | J17: =$F17/6 -> 28731.996 | K17: =$F17/6 -> 28731.996 | L17: =$F17/6 -> 28731.996 | M17: =$F17/6 -> 28731.996
A18: 01.002.003 | B18: Documentos | F18: =[4]BASES!H18*1.1 -> 74020.373 | H18: =$F18/6 -> 12336.729 | I18: =$F18/6 -> 12336.729 | J18: =$F18/6 -> 12336.729 | K18: =$F18/6 -> 12336.729 | L18: =$F18/6 -> 12336.729 | M18: =$F18/6 -> 12336.729
A19: 02 | B19: GERENCIAMENTO ADMINISTRATIVO | F19: =F20+F34+F53 -> 2865093.9
A20: 02.001 | B20: SEGURANÇA, MEIO AMBIENTE E SAÚDE | F20: =F21+F23+F33 -> 511881.42
A21: 02.001.001 | B21: Segurança do Trabalho | F21: =F22 -> 115000
A22: 02.001.001.001 | B22: Serviço de segurança do trabalho terceirizado | C22: mes | D22: =[4]OBRA!D12 -> 46 | E22: =[4]BASES!H20 -> 2500 | F22: =E22*D22 -> 115000
A23: 02.001.002 | B23: Equipamentos de proteção | F23: =SUM(F24:F32) -> 354289.87
A24: 02.001.002.001 | B24: Bandeja de proteção primária | C24: m | D24: =[4]EPCs!D13 -> 290.12 | E24: 294.33 | F24: =E24*D24 -> 85391.02
A25: 02.001.002.002 | B25: Bandeja de proteção secundária | C25: m | D25: =[4]EPCs!D14 -> 132.16 | E25: 210.06 | F25: =E25*D25 -> 27761.53
A26: 02.001.002.003 | B26: Guarda corpo em laje pós - desforma | C26: m | D26: =[4]EPCs!D21 -> 528.64 | E26: 17.89 | F26: =E26*D26 -> 9457.3696
A27: 02.001.002.004 | B27: Fechamento removível de vãos de porta de elevador em madeira | C27: m2 | D27: =[4]EPCs!D36 -> 56.16 | E27: 47.3 | F27: =E27*D27 -> 2656.368
A28: 02.001.002.005 | B28: Varal de segurança com cabo de aço | C28: m | D28: =D26 -> 528.64 | E28: 244 | F28: =E28*D28 -> 128988.16
A29: 02.001.002.006 | B29: Tela fachadeira reforçada com impressão digital | C29: m2 | D29: =[4]EPCs!D28 -> 5918.1248 | E29: 8.5 | F29: =E29*D29 -> 50304.061
A30: 02.001.002.007 | B30: Sinalização com placa indicativa fixada na estrutura | C30: vb | D30: 1 | E30: =[4]BASES!H21*1.1 -> 3615.5038 | F30: =E30*D30 -> 3615.5038
A31: 02.001.002.008 | B31: Equipamentos de proteção individual | C31: vb | D31: 1 | E31: =[4]CANTEIRO!D18 -> 40000 | F31: =E31*D31 -> 40000
A32: 02.001.002.009 | B32: Gurada-corpo de vãos com régua de pinus 2,5x15cm | C32: m | D32: 397.65 | E32: 15.38 | F32: =E32*D32 -> 6115.857
A33: 02.001.003 | B33: Meio Ambiente | F33: =[4]BASES!H22 -> 42591.549
A34: 02.002 | B34: ADMINISTRAÇÃO E CANTEIRO DE OBRA | F34: =F35+F41+F43+F52 -> 1834806.5
A35: 02.002.001 | B35: Equipe de Gestão e Apoio | F35: =SUM(F36:F40) -> 1244946.4
A36: 02.002.001.001 | B36: Engenheiro Civil | C36: mes | D36: =[4]OBRA!$D$12 -> 46 | E36: 8500 | F36: =E36*D36 -> 391000
A37: 02.002.001.002 | B37: Mestre Geral | C37: mes | D37: =[4]OBRA!$D$12 -> 46 | E37: 8000 | F37: =E37*D37 -> 368000
A38: 02.002.001.005 | B38: Estagiário de Engenharia | C38: mes | D38: =[4]OBRA!$D$12 -> 46 | E38: 2200 | F38: =E38*D38 -> 101200
A39: 02.002.001.006 | B39: Operador de Guincho | C39: mes | D39: =D56 -> 19 | E39: =[4]BASES!H29 -> 3500 | F39: =E39*D39 -> 66500
A40: 02.002.001.007 | B40: Equipe de apoio | C40: mes | D40: =[4]OBRA!$D$12 -> 46 | E40: =1880*1.84*2 -> 6918.4 | F40: =E40*D40 -> 318246.4 | G40: 2 seventes (84% de encargos)
A41: 02.002.002 | B41: Operação Inicial do Canteiro | F41: =SUM(F42) -> 19687.5
...
