Workbook
Name \0: #REF!
Name \0: #REF!
Name \0: #REF!
Name \0: #REF!
Name \0: #REF!
Name \0: #REF!
Name \0: #REF!
Name \a: #REF!
Name \a: #REF!
Name \m: #REF!
Name \m: #REF!
Name aa: #REF!
Name aa: #REF!
Name aaaa: '[1]M.O.'!#REF!
Name aaaa: '[1]M.O.'!#REF!
Name aaaa: '[1]M.O.'!#REF!
Name aaaa: '[1]M.O.'!#REF!
Name aaaa: '[1]M.O.'!#REF!
Name aaaa: '[1]M.O.'!#REF!
Name aaaa: '[1]M.O.'!#REF!
Name angelo: [2]Geral!#REF!
Name angelo: [2]Geral!#REF!
Name angelo: [2]Geral!#REF!
Name angelo: [2]Geral!#REF!
Name angelo: [2]Geral!#REF!
Name angelo: [2]Geral!#REF!
Name angelo: [2]Geral!#REF!
Name area: #REF!
Name aux: #REF!
Name aux: #REF!
Name aux: #REF!
Name aux: #REF!
Name aux: #REF!
Name aux: #REF!
Name aux: #REF!
Name BDA: #REF!
Name BDA: #REF!
Name BDI: #REF!
Name ca: #REF!
Name Capa: #REF!
Name cronograma: #REF!
Name D: #REF!
Name direto: #REF!
Name DRE: #REF!
Name ea: #REF!
Name FFFFFFF: #REF!
Name FFFFFFF: #REF!
Name FFFFFFF: #REF!
Name FFFFFFF: #REF!
Name FFFFFFF: #REF!
Name FFFFFFF: #REF!
Name FFFFFFF: #REF!
Name item_1: #REF!
Name item_1: #REF!
Name item_1: #REF!
Name item_1: #REF!
Name item_1: #REF!
Name item_1: #REF!
Name item_1: #REF!
Name LS: '[1]M.O.'!#REF!

Sheet DADOS_INICIAIS
A1: Obra | B1: Connect
A2: Empresa | B2: Passe
A3: Revisão | B3: R00
A4: Arquitetura base | B4: PAS_CNC_ARQ_EP_R08
A5: DADOS OBRA
B7: Descrição | C7: Identificador | D7: Unidade | E7: Quantidade
B8: ÁREA DO TERRENO | C8: AT | D8: M2 | E8: 1376.83
B9: ÁREA TOTAL CONSTRUÍDA | C9: AC | D9: M2 | E9: 13144.27
B10: UNIDADES RESIDENCIAIS | C10: UR | D10: UN | E10: 156 | F10: =E9-E22-E21 -> 6552.43
B11: Dormitórios | C11: dorm | D11: UN | E11: 156
B12: Banheiros | C12: ban | D12: UN
B13: UNIDADES COMERCIAIS | C13: UC | D13: UN | E13: 1
B14: Churrasqueiras | C14: CHU | D14: UN
B15: NÚMERO TOTAL DE PAVIMENTOS | C15: NP | D15: UN | E15: 20
B16: NÚMERO DE PAVIMENTOS TIPO | C16: NPT | D16: UN | E16: 14
B17: NÚMERO DE PAVIMENTOS TIPO DIFERENCIADOS | C17: NPD | D17: UN | E17: 1
B18: NÚMERO DE PAVIMENTOS DUPLEX | C18: ND | D18: UN | E18: 0
B19: ÁREA DE PROJEÇÃO DA TORRE | C19: APT | D19: M2 | E19: 614.944
B20: PERÍMETRO DE PROJEÇÃO DA TORRE | C20: PPT | D20: M | E20: 179.6335
B21: ÁREA DE LAZER | C21: AL | D21: M2 | E21: 1122.76
B22: ÁREA DO EMBASAMENTO | C22: AE | D22: M2 | E22: =1110.68+1089.6*4 -> 5469.08
B23: ÁREA DE SUBSOLOS | C23: S | D23: M2 | E23: 0
B24: NÚMERO DE SUBSOLOS | C24: NS | D24: UN | E24: 0
B25: ÁREA DE PROJEÇÃO DO EMBASAMENTO | C25: APE | D25: M2 | E25: 1156.02 | F25: =E25/E9 -> 0.087948589
B26: PERÍMETRO DE PROJEÇÃO DE EMBAMENTO | C26: PE | D26: M | E26: 179.11
B27: NÚMERO DE PAVIMENTOS DE EMBASAMENTO | C27: NE | D27: UN | E27: 5

Sheet MOVIMENTAÇÃO_DE_TERRA
A2: MOVIMENTAÇÃO DE TERRA
A3: Data | B3: 45456
A4: Arquivo base | B4: -
A6: ESCAVAÇÃO VERTICAL DE SUBSOLO
A8: Descrição | B8: Área de subsolo (m) | C8: Altura do subsolo (m) | D8: Volume total de escavação (m3) | E8: Preço unitário de escavação (R$ / m3) | F8: Valor total | G8: Observação
A9: Escavação | B9: =DADOS_INICIAIS!E23 -> 0 | D9: =C9*B9 -> 0 | E9: 0 | F9: =E9*D9*1.1 -> 0
A10: TOTAL | F10: =SUM(F9:F9) -> 0
A12: REBAIXAMENTO DE LENÇOL FREÁTICO
A14: Descrição | B14: Quantidade (dias) | E14: Preço unitário de rebaixamento (R$ / dias) | F14: Valor total | G14: Observação
A15: Rebaixamento de lençol | B15: 0 | E15: 200 | F15: =B15*E15*1.1 -> 0
A16: TOTAL | F16: =SUM(F15:F15) -> 0
A18: ESCAVAÇÃO E REATERRO DE VALAS
A20: Descrição | B20: Parâmetro | D20: Volume total de escavação (m3) | E20: Preço unitário (R$ / m3) | F20: Valor total | G20: Observação
A21: Escavação mecanizada para blocos e baldrames | B21: 1.3 | C21: m³ / Vol infra | D21: =B21*INFRAESTRUTURA!D29 -> 976.8369 | E21: 60 | F21: =E21*D21*1.1 -> 64471.235
A22: Reaterro para blocos e baldrames | B22: 0.6 | C22: m³ / Vol Escavação | D22: =D21-INFRAESTRUTURA!D29 -> 225.4239 | E22: 20 | F22: =E22*D22*1.1 -> 4959.3258
A23: Movimentação de bota-fora | B23: 1.3 | D23: =(D21-D22)*B23 -> 976.8369 | E23: 40 | F23: =E23*D23*1.1 -> 42980.824
A24: Movimentação de terra das estacas | B24: 1 | C24: m³ | D24: =INFRAESTRUTURA!D19 -> 1621.71 | E24: 40 | F24: =E24*D24*1.1 -> 71355.24
A25: TOTAL | F25: =SUM(F21:F24) -> 183766.62
A27: REGULARIZAÇÃO E APILOAMENTO DE FUNDO DE VALAS
A29: Descrição | B29: Parâmetro | D29: Área de lastro (m²) | E29: Preço unitário (R$ / m2) | F29: Valor total | G29: Observação
A30: Lastro de concreto magto e=5cm | B30: 0.8 | C30: m² / APE | D30: =B30*DADOS_INICIAIS!E25 -> 924.816 | E30: =370*0.05 -> 18.5 | F30: =E30*D30*1.1 -> 18820.006 | G30: Definição trazida do Celebration da Passe | H30: =F30/DADOS_INICIAIS!E25 -> 16.28
A31: TOTAL | F31: =SUM(F30:F30) -> 18820.006
A33: TOTAL MOVIMENTAÇÃO DE TERRA | F33: =F10+F16+F25+F31 -> 202586.63 | G33: =F33/DADOS_INICIAIS!E9 -> 15.412543

Sheet CONTENÇÕES
A3: CONTENÇÃO
A4: Data
A5: Arquivo base
A7: CORTINA DE ESTACAS
A9: Descrição | B9: Parâmetro | D9: Quantidade | F9: Preço unitário | G9: Valor total
A10: Número de Estacas | B10: 0.15 | C10: un / APE | D10: =B10*DADOS_INICIAIS!E25 -> 173.403 | E10: un
A11: Estaca Hélice Continua Diâmetro 40 | B11: 0.1 | D11: =B11*$D$10 -> 17.3403 | E11: un
B12: 20 | C12: m/un | D12: =B12*D11 -> 346.806 | E12: m | G12: =F12*D12 -> 0
A13: Estaca Hélice Continua Diâmetro 50 | B13: 0.5 | D13: =B13*$D$10 -> 86.7015 | E13: un
B14: 20 | C14: m/un | D14: =B14*D13 -> 1734.03 | E14: m | G14: =F14*D14 -> 0
A15: Estaca Hélice Continua Diâmetro 60 | B15: 0.4 | C15: un / APE | D15: =B15*$D$10 -> 69.3612 | E15: un
B16: 20 | C16: m/un | D16: =B16*D15 -> 1387.224 | E16: m | G16: =F16*D16 -> 0
A17: Concreto | B17: =(PI()*0.4^2)/4*D14+(PI()*0.5^2)/4*D16+(PI()*0.6^2)/4*D12 -> 588.34252 | C17: un / APE | D17: =(PI()*0.4^2)/4*D14+(PI()*0.5^2)/4*D16+(PI()*0.6^2)/4*D12 -> 588.34252 | E17: m³ | G17: =F17*D17 -> 0
A18: Armação 6,3mm | B18: 1.6575131 | C18: kg / m³ | D18: =B18*D17 -> 975.18544 | E18: kg | G18: =F18*D18 -> 0
A19: Armação 16mm | B19: 10.178338 | C19: kg / m³ | D19: =B19*D17 -> 5988.3487 | E19: kg | G19: =F19*D19 -> 0
A20: Mobilização | B20: 1 | C20: vb | D20: 1 | E20: vb | G20: =F20*D20 -> 0
A21: TOTAL | G21: =SUM(G10:G20) -> 0
A23: PAREDE DE CONCRETO
A25: Descrição | B25: Parâmetro | D25: Quantidade | F25: Preço unitário | G25: Valor total
A26: Fabricação, montagem e desmontagem de forma para blocos e baldrames resinado | B26: 2.1 | C26: m² / APE | D26: =B26*DADOS_INICIAIS!E25 -> 2427.642 | E26: m² | G26: =F26*D26 -> 0
A27: Concreto | B27: 0.65 | C27: m³ / APE | D27: =B27*DADOS_INICIAIS!E25 -> 751.413 | E27: m³ | G27: =F27*D27 -> 0
A28: Armação | B28: 110 | C28: kg / m³ | D28: =B28*D27 -> 82655.43 | E28: kg | G28: =F28*D28 -> 0
A29: Mão de obra | B29: =SUPRAESTRUTURA!B15*1.5 -> 360 | C29: R$ / APE | D29: =DADOS_INICIAIS!E25 -> 1156.02 | E29: m² | F29: =B29 -> 360 | G29: =F29*D29 -> 416167.2
A30: TOTAL | G30: =SUM(G26:G29) -> 416167.2
A33: PAREDE DIAFRAGMA
A35: Descrição | B35: Parâmetro | D35: Quantidade | F35: Preço unitário | G35: Valor total
A36: Fabricação, montagem e desmontagem de forma para blocos e baldrames resinado | B36: 2.1 | C36: m² / APE | D36: =B36*DADOS_INICIAIS!E35 -> 0 | E36: m² | G36: =F36*D36 -> 0
A37: Concreto | B37: 0.65 | C37: m³ / APE | D37: =B37*DADOS_INICIAIS!E35 -> 0 | E37: m³ | G37: =F37*D37 -> 0
A38: Armação | B38: 110 | C38: kg / m³ | D38: =B38*D37 -> 0 | E38: kg | G38: =F38*D38 -> 0
A39: Mão de obra | B39: =SUPRAESTRUTURA!B74*1.5 -> 0 | C39: R$ / APE | D39: =DADOS_INICIAIS!E35 -> 0 | E39: m² | F39: =B39 -> 0 | G39: =F39*D39 -> 0
A40: TOTAL | G40: =SUM(G36:G39) -> 0
A46: TOTAL INFRAESTRUTURA | G46: =G21+G30 -> 416167.2 | H46: =G46/DADOS_INICIAIS!E9 -> 31.661492

Sheet INFRAESTRUTURA
A3: INFRAESTRUTURA
A4: Data | B4: 45456
A5: Arquivo base | B5: -
A7: FUNDAÇÃO PROFUNDA
A9: Descrição | B9: Parâmetro | D9: Quantidade | F9: Preço unitário | G9: Valor total | H9: Observação
A10: Número de Estacas | B10: =D10/DADOS_INICIAIS!E25 -> 0.08477362 | C10: un / APE | D10: =D11+D13+D15+D17 -> 98 | E10: un | H10: Quantitativos trazidos de preliminar de fundação
A11: Estaca Hélice Continua Diâmetro 40 | B11: 0 | D11: 0 | E11: un
B12: 28 | C12: m/un | D12: =B12*D11 -> 0 | E12: m | F12: 70 | G12: =F12*D12*1.1 -> 0
A13: Estaca Hélice Continua Diâmetro 50 | B13: 0.45 | D13: 6 | E13: un
B14: 30 | C14: m/un | D14: =B14*D13 -> 180 | E14: m | F14: 90 | G14: =F14*D14*1.1 -> 17820
A15: Estaca Hélice Continua Diâmetro 60 | B15: =1-B13-B11 -> 0.55 | C15: un / APE | D15: 39 | E15: un
B16: 36 | C16: m/un | D16: =B16*D15 -> 1404 | E16: m | F16: 105 | G16: =F16*D16*1.1 -> 162162
A17: Estaca Hélice Continua Diâmetro 80 | B17: =1-B15-B13 -> 0 | C17: un / APE | D17: =33+20 -> 53 | E17: un
B18: 36 | C18: m/un | D18: =B18*D17 -> 1908 | E18: m | F18: 120 | G18: =F18*D18*1.1 -> 251856
A19: Concreto (40 Mpa) | B19: 1.1 | C19: perda | D19: 1621.71 | E19: m³ | F19: =535+45 -> 580 | G19: =F19*D19*B19*1.1 -> 1138116.1
A20: Armação | B20: =D20/D19 -> 9.2753945 | C20: kg / m³ | D20: 15042 | E20: kg | F20: 7.62 | G20: =F20*D20*1.1 -> 126082.04
A21: Mobilização | B21: 1 | C21: vb | D21: 1 | E21: vb | F21: 14500 | G21: =F21*D21*1.1 -> 15950
A22: Apoio e arrasamento de estacas | D22: =D10 -> 98 | E22: un | F22: 300 | G22: =F22*D22*1 -> 29400
A23: TOTAL | G23: =SUM(G10:G22) -> 1741386.1
A25: FUNDAÇÃO RASA
A27: Descrição | B27: Parâmetro | D27: Quantidade | F27: Preço unitário | G27: Valor total | H27: Observação
A28: Fabricação, montagem e desmontagem de forma para blocos e baldrames resinado | B28: 1.1 | C28: m² / APE | D28: =B28*DADOS_INICIAIS!E25 -> 1271.622 | E28: m² | F28: 68 | G28: =F28*D28*1.1 -> 95117.326 | H28: Definição de índice pelo Celebration
A29: Concreto (40 Mpa) | B29: 0.65 | C29: m³ / APE | D29: =B29*DADOS_INICIAIS!E25 -> 751.413 | E29: m³ | F29: =535+45 -> 580 | G29: =F29*D29*1.05*1.1 -> 503371.57 | H29: Definição de resitência trazida do Celebration da Passe
A30: Armação | B30: 60 | C30: kg / m³ | D30: =B30*D29 -> 45084.78 | E30: kg | F30: 7.62 | G30: =F30*D30*1.1 -> 377900.63
A31: Mão de obra | B31: =SUPRAESTRUTURA!B15*1.5 -> 360 | C31: R$ / APE | D31: =DADOS_INICIAIS!E25 -> 1156.02 | E31: m² | F31: =B31 -> 360 | G31: =F31*D31*1.1 -> 457783.92
A32: TOTAL | G32: =SUM(G28:G31) -> 1434173.4
A35: TOTAL INFRAESTRUTURA | G35: =G23+G32 -> 3175559.6 | H35: =G35/DADOS_INICIAIS!E9 -> 241.59269

Sheet SUPRAESTRUTURA
A3: SUPRAESTRUTURA
A4: Data | B4: 45456
A5: Arquivo base | B5: -
A7: SUPRAESTRUTURA - LAJE MACIÇA
A9: Descrição | B9: Parâmetro | D9: Quantidade | F9: Preço unitário | G9: Valor total | H9: Observação
A10: Fabricação forma | B10: 3 | C10: Jogos | D10: =(D11/DADOS_INICIAIS!$E$15)*B10 -> 4929.1012 | E10: m² | F10: 110 | G10: =F10*D10*1.1 -> 596421.25
A11: Montagem de forma | B11: 2.5 | C11: m² / AC | D11: =B11*DADOS_INICIAIS!$E$9 -> 32860.675 | E11: m² | F11: 2.5 | G11: =F11*D11*1.1 -> 90366.856
A12: Escoramento | B12: 4 | C12: un / AE | D12: =ROUNDUP(B12*DADOS_INICIAIS!$E$25*B10,0) -> 13873 | E12: un | F12: =17 -> 17 | G12: =F12*D12*1.1 -> 259425.1
A13: Concreto | B13: 0.22 | C13: m³ / AC | D13: =B13*DADOS_INICIAIS!$E$9 -> 2891.7394 | E13: m³ | F13: =535+45 -> 580 | G13: =F13*D13*1.05*1.1 -> 1937176.2
A14: Armadura Convencional para Estrutura | B14: 110 | C14: kg / m³ | D14: =D13*B14 -> 318091.33 | E14: kg | F14: 7.62 | G14: =F14*D14*1.1 -> 2666241.6
A15: Mão de obra - estrutura em concreto armado | B15: 240 | C15: R$ / AC | D15: =DADOS_INICIAIS!$E$9 -> 13144.27 | E15: m² | F15: =B15 -> 240 | G15: =F15*D15*1.1 -> 3470087.3
A16: Perfuração de vigas | B16: 5300 | C16: R$ / NP | D16: 1 | E16: vb | F16: =B16*DADOS_INICIAIS!$E$15 -> 106000 | G16: =F16*D16*1.1 -> 116600 | H16: Coeficiente originário do Gran Torino (R$ 160,00/un) | I16: Nova utiliza a verba de 1.500,00 por pav
A17: TOTAL | G17: =SUM(G10:G16) -> 9136318.3 | K17: =4160+1440+1120+2880+4800+91680+4000 -> 110080 | L17: =K17/21 -> 5241.9048
A19: SUPRAESTRUTURA - LAJE CUBETAS PROTENDIDAS
A21: Descrição | B21: Parâmetro | D21: Quantidade | F21: Preço unitário | G21: Valor total | H21: Observação
A22: Fabricação forma | B22: 2 | C22: Jogos | D22: =(D23/DADOS_INICIAIS!$E$15)*B22 -> 2760.2967 | E22: m² | F22: 110 | G22: =F22*D22*1.1 -> 333995.9
A23: Montagem de forma | B23: 2.1 | C23: m² / AC | D23: =B23*DADOS_INICIAIS!$E$9 -> 27602.967 | E23: m² | F23: 2.5 | G23: =F23*D23*1.1 -> 75908.159
A24: Escoramento | B24: 3 | C24: un / APT*NPT | D24: =ROUNDUP(B24*DADOS_INICIAIS!$E$25*B22,0) -> 6937 | E24: un | F24: =17 -> 17 | G24: =F24*D24*1.1 -> 129721.9
A25: Cubetas | B25: 25 | C25: R$ / AC | D25: 1 | E25: vb | F25: =B25*DADOS_INICIAIS!$E$9 -> 328606.75 | G25: =F25*D25*1.1 -> 361467.43
A26: Protensão - lajes - materiais | B26: =12.3*0.8 -> 9.84 | C26: RS / m² | D26: =(DADOS_INICIAIS!$E$16+DADOS_INICIAIS!$E$17)*DADOS_INICIAIS!$E$19+DADOS_INICIAIS!$E$22 -> 14693.24 | E26: m² | F26: =B26 -> 9.84 | G26: =F26*D26*1.1 -> 159039.63
A27: Protensão - lajes - cabos | B27: =2.83*0.8 -> 2.264 | C27: kg / m² | D27: =B27*D26 -> 33265.495 | E27: kg | F27: 12.3 | G27: =F27*D27*1.1 -> 450082.15
A28: Protensão - lajes - serviços | B28: 9000 | C28: und / pav | D28: =DADOS_INICIAIS!E15 -> 20 | E28: pav | F28: =B28 -> 9000 | G28: =F28*D28*1.1 -> 198000
A29: Concreto | B29: 0.18 | C29: m³ / AC | D29: =B29*DADOS_INICIAIS!$E$9 -> 2365.9686 | E29: m³ | F29: =535+45 -> 580 | G29: =F29*D29*1.05*1.1 -> 1584962.4
A30: Cristalizante (reservatorios) | B30: 0.2 | D30: =B30*D29 -> 473.19372 | E30: m³ | F30: =1.22*F29-F29 -> 127.6 | G30: =F30*D30*1.05*1.1 -> 69738.344
A31: Armadura Convencional para Estrutura | B31: 110 | C31: kg / m³ | D31: =D29*B31-D27 -> 226991.05 | E31: kg | F31: 7.62 | G31: =F31*D31*1.1 -> 1902639
A32: Mão de obra - estrutura em concreto armado | B32: 240 | C32: R$ / AC | D32: =DADOS_INICIAIS!$E$9 -> 13144.27 | E32: m² | F32: =B32 -> 240 | G32: =F32*D32*1.1 -> 3470087.3
A33: Perfuração de vigas | B33: 5300 | C33: R$ / NP | D33: 1 | E33: vb | F33: =B33*DADOS_INICIAIS!$E$15 -> 106000 | G33: =F33*D33*1.1 -> 116600 | H33: Coeficiente originário do Gran Torino (R$ 160,00/un)
A34: TOTAL | G34: =SUM(G22:G33) -> 8852242.1
A36: SUPRAESTRUTURA - LAJE TRELIÇADA
A38: Descrição | B38: Parâmetro | D38: Quantidade | F38: Preço unitário | G38: Valor total | H38: Observação
A39: Fabricação forma | B39: 2 | C39: Jogos | D39: =(D40/DADOS_INICIAIS!$E$15)*B39 -> 0 | E39: m² | F39: 85 | G39: =F39*D39*1.1 -> 0
A40: Montagem de forma | B40: 2.1 | C40: m² / AC | D40: =B40*DADOS_INICIAIS!E38 -> 0 | E40: m² | F40: 1.5 | G40: =F40*D40*1.1 -> 0
A41: Escoramento - Torre | B41: 2 | C41: un / APT*NPT | D41: =B41*DADOS_INICIAIS!E47*DADOS_INICIAIS!E44 -> 0 | E41: un | F41: 17 | G41: =F41*D41*1.1 -> 0
A42: Escoramento - Embasamento | B42: 2 | C42: un / AE | D42: =B42*DADOS_INICIAIS!E50 -> 0 | E42: un | F42: 17 | G42: =F42*D42*1.1 -> 0
A43: Cubetas | B43: 25 | C43: R$ / AC | D43: =B43*DADOS_INICIAIS!E38 -> 0 | E43: m³ | F43: =B43 -> 25 | G43: =F43*D43*1.1 -> 0
A44: Concreto | B44: 0.25 | C44: m³ / AC | D44: =B44*DADOS_INICIAIS!E38 -> 0 | E44: m³ | F44: =575 -> 575 | G44: =F44*D44*1.05*1.1 -> 0
A45: Armadura Convencional para Estrutura | B45: 110 | C45: kg / m³ | D45: =D44*B45 -> 0 | E45: kg | F45: 7.25 | G45: =F45*D45*1.1 -> 0
A46: Mão de obra - estrutura em concreto armado | B46: 240 | C46: R$ / AC | D46: =DADOS_INICIAIS!E38 -> 0 | E46: m² | F46: =B46 -> 240 | G46: =F46*D46*1.1 -> 0
A47: Perfuração de vigas | B47: 5300 | C47: R$ / NP | D47: 1 | E47: vb | F47: =B47*DADOS_INICIAIS!E43 -> 0 | G47: =F47*D47*1.1 -> 0 | H47: Coeficiente originário do Gran Torino (R$ 160,00/un)
A48: TOTAL | G48: =SUM(G39:G47) -> 0
...

Sheet ALVENARIA
A3: PAREDES E PAINÉIS
A4: Data | B4: 45457
A5: Arquivo base | B5: -
A7: ALVENARIA
A9: Descrição | B9: Parâmetro | D9: Quantidade | F9: Preço unitário | G9: Valor total | H9: Observação
A10: Alvenaria embasamento | B10: 1 | C10: m² / AE | D10: =B10*DADOS_INICIAIS!$E$22 -> 5469.08 | E10: m² | F10: 45 | G10: =F10*D10*1.1 -> 270719.46
A11: Alvenaria lazer | B11: 0.4 | C11: m² / AL | D11: =B11*DADOS_INICIAIS!$E$21 -> 449.104 | E11: m² | F11: 45 | G11: =F11*D11*1.1 -> 22230.648
A12: Alvenaria tipo | B12: 1.65 | C12: m² / APT*(NPT+2ND) | D12: =B12*(DADOS_INICIAIS!$E$19*(DADOS_INICIAIS!$E$16+DADOS_INICIAIS!$E$17)) -> 15219.864 | E12: m² | F12: 45 | G12: =F12*D12*1.1 -> 753383.27
A13: Alvenaria escadas | B13: 0.2 | C13: m² / AC | D13: =B13*DADOS_INICIAIS!$E$9 -> 2628.854 | E13: m² | F13: 70 | G13: =F13*D13*1.05*1.1 -> 212542.85
A14: Alvenaria cobertura / reservatório | B14: 0.8 | C14: m² / APT | D14: =B14*DADOS_INICIAIS!$E$19 -> 491.9552 | E14: m² | F14: 45 | G14: =F14*D14*1.1 -> 24351.782
A15: Alvenaria refratárias | B15: 1.75 | C15: m² * CHU | D15: =B15*DADOS_INICIAIS!$E$14 -> 0 | E15: un | F15: 210 | G15: =F15*D15*1.1 -> 0
A16: Serviços complementares | B16: 12.5 | C16: R$ / m² | D16: =D10+D11+D12+D13+D14 -> 24258.857 | E16: m² | F16: =B16 -> 12.5 | G16: =F16*D16*1.1 -> 333559.29
A17: Mão de obra | B17: 35 | C17: R$ / m² | D17: =D10+D11+D12+D13+D14 -> 24258.857 | E17: m² | F17: 35 | G17: =F17*D17*1.1 -> 933966
A18: TOTAL | G18: =SUM(G10:G17) -> 2550753.3 | K18: =4160+1440+1120+2880+4800+91680+4000 -> 110080 | L18: =K18/21 -> 5241.9048
A20: ALVENARIA - DRTWALL
A22: Descrição | B22: Parâmetro | D22: Quantidade | F22: Preço unitário | G22: Valor total | H22: Observação
A23: Alvenaria embasamento | B23: 1 | C23: m² / AE | D23: =B23*DADOS_INICIAIS!$E$22 -> 5469.08 | E23: m² | F23: 45 | G23: =F23*D23*1.1 -> 270719.46
A24: Alvenaria lazer | B24: 0.4 | C24: m² / AL | D24: =B24*DADOS_INICIAIS!$E$21 -> 449.104 | E24: m² | F24: 45 | G24: =F24*D24*1.1 -> 22230.648
A25: Alvenaria tipo | B25: 1.62 | C25: m² / APT*(NPT+2ND) | D25: =B25*(DADOS_INICIAIS!$E$19*(DADOS_INICIAIS!$E$16+DADOS_INICIAIS!$E$17))*0.3 -> 4482.9418 | E25: un | F25: 45 | G25: =F25*D25*1.1 -> 221905.62
A26: Drywall tipo | B26: 1.65 | C26: m² / APT*(NPT+2ND) | D26: =B26*(DADOS_INICIAIS!$E$19*(DADOS_INICIAIS!$E$16+DADOS_INICIAIS!$E$17))*0.7 -> 10653.905 | F26: 220 | G26: =F26*D26*1.1 -> 2578245 | J26: =D26/(D31+D26) -> 0.44068396
A27: Alvenaria escadas | B27: 0.2 | C27: m² / AC | D27: =B27*DADOS_INICIAIS!$E$9 -> 2628.854 | E27: un | F27: 70 | G27: =F27*D27*1.1 -> 202421.76 | J27: =1-J26 -> 0.55931604
A28: Alvenaria cobertura / reservatório | B28: 0.8 | C28: m² / APT | D28: =B28*DADOS_INICIAIS!$E$19 -> 491.9552 | E28: m³ | F28: 45 | G28: =F28*D28*1.1 -> 24351.782
A29: Alvenaria refratárias | B29: 1.75 | C29: m² * CHU | D29: ='SISTEMAS ESPECIAIS'!B10 -> 10 | E29: un | F29: 210
A30: Churrasqueiras pré-moldadas | D30: =D29 -> 10 | E30: un | F30: 1800 | G30: =F30*D30*1.1 -> 19800
A31: Serviços complementares | B31: 12.5 | C31: R$ / m² | D31: =D24+D25+D23+D27+D28 -> 13521.935 | E31: kg | F31: =B31 -> 12.5 | G31: =F31*D31*1.1 -> 185926.61
A32: Mão de obra | B32: 35 | C32: R$ / m² | D32: =D24+D25+D23+D27+D28 -> 13521.935 | E32: m² | F32: 35 | G32: =F32*D32*1.1 -> 520594.5
A33: TOTAL | G33: =SUM(G23:G32) -> 4046195.3
A36: TOTAL ALVENARIA | G36: =G33 -> 4046195.3 | H36: =G36/DADOS_INICIAIS!E9 -> 307.8296
G39: =G36/1.1 -> 3678359.4 | H39: =G39/DADOS_INICIAIS!E9 -> 279.84509

Sheet INSTALAÇÕES
A2: INSTALAÇÕES
A4: INSTALAÇÕES ELÉTRICAS
A6: Descrição | B6: Parâmetro | D6: Valor total
A7: Entrada de Energia | B7: 30 | C7: R$ / AC | D7: =B7*DADOS_INICIAIS!$E$9*1.1 -> 433760.91
A8: Eletrodutos e Eletrocalhas | B8: 15 | C8: R$ / AC | D8: =B8*DADOS_INICIAIS!$E$9*1.1 -> 216880.46
A9: Cabos e Fiações | B9: 35 | C9: R$ / AC | D9: =B9*DADOS_INICIAIS!$E$9*1.1 -> 506054.4
A10: Quadros e Disjuntores | B10: 6 | C10: R$ / AC | D10: =B10*DADOS_INICIAIS!$E$9*1.1 -> 86752.182
A11: Acabamentos Elétricos | B11: 8 | C11: R$ / AC | D11: =B11*DADOS_INICIAIS!$E$9*1.1 -> 115669.58
A12: Equipamentos e Iluminação | B12: 2 | C12: R$ / AC | D12: =B12*DADOS_INICIAIS!$E$9*1.1 -> 28917.394
A13: Mão de Obra para Instalações Elétricas | B13: 60 | C13: R$ / AC | D13: =B13*DADOS_INICIAIS!$E$9*1.1 -> 867521.82
A14: TOTAL | D14: =SUM(D7:D13) -> 2255556.7
A16: INSTALAÇÕES HIDROSSANITÁRIAS
A18: Descrição | B18: Parâmetro | D18: Valor total
A19: Instalações de Água Fria | B19: 20 | C19: R$ / AC | D19: =B19*DADOS_INICIAIS!$E$9*1.1 -> 289173.94
A20: Instalações de Água Quente | B20: 10 | C20: R$ / AC | D20: =B20*DADOS_INICIAIS!$E$9*1.1 -> 144586.97
A21: Instalações de Águas Pluviais | B21: 10 | C21: R$ / AC | D21: =B21*DADOS_INICIAIS!$E$9*1.1 -> 144586.97
A22: Instalações Sanitárias | B22: 15 | C22: R$ / AC | D22: =B22*DADOS_INICIAIS!$E$9*1.1 -> 216880.46
A23: Louças e Metais (bacias sanitárias) | B23: 5 | C23: R$ / AC | D23: =B23*DADOS_INICIAIS!$E$9*1.1 -> 72293.485
A24: Mão de Obra para Instalações Hidráulicas | B24: 55 | C24: R$ / AC | D24: =B24*DADOS_INICIAIS!$E$9*1.1 -> 795228.34
A25: TOTAL | D25: =SUM(D19:D24) -> 1662750.2
A27: INSTALAÇÕES PREVENTIVAS E GLP
A29: Descrição | B29: Parâmetro | D29: Valor total
A30: Instalações Preventivas | B30: 20 | C30: R$ / AC | D30: =B30*DADOS_INICIAIS!$E$9*1.1 -> 289173.94
A31: Instalações de GLP | B31: 15 | C31: R$ / AC | D31: =B31*DADOS_INICIAIS!$E$9*1.1 -> 216880.46
A32: Instalações de Proteção e Aterramento - SPDA | B32: 4 | C32: R$ / AC | D32: =B32*DADOS_INICIAIS!$E$9*1.1 -> 57834.788
A33: TOTAL | D33: =SUM(D30:D32) -> 563889.18
A35: TOTAL INSTALAÇÕES | D35: =D14+D25+D33 -> 4482196.1 | E35: =D35/DADOS_INICIAIS!E9 -> 341
E37: =E35/1.1 -> 310

Sheet SISTEMAS ESPECIAIS
A2: SISTEMAS ESPECIAIS
A4: CLIMATIZAÇÃO, EXAUSTÃO MECÂNICA E PRESSURIZAÇÃO
A6: Descrição | B6: Quantidade | C6: Preço Unitário | D6: Valor total | G6: TERREO | H6: TIPO 1 | I6: TIPO 2 | J6: TIPO 3 | K6: TIPO 4 | L6: TIPO 5 | M6: TIPO 6 | N6: TIPO 7 | O6: ATICO
A7: Infraestrutura para Instalação de Ar Condicionado | B7: =SUM(G7:O7) -> 292 | C7: 1500 | D7: =B7*C7*1.1 -> 481800 | G7: 12 | H7: =28*7 -> 196 | I7: =16+1 -> 17 | J7: =16+2 -> 18 | K7: 16 | L7: 16 | M7: 8 | N7: 8 | O7: 1
A8: Instalação de Ar Condicionado | B8: =SUM(G8:O8) -> 16 | C8: 5000 | D8: =B8*C8*1.1 -> 88000 | G8: 12 | I8: 1 | J8: 2 | O8: 1
A9: Ventokit | B9: =SUM(G9:O9) -> 36 | C9: 900 | D9: =B9*C9*1.1 -> 35640 | G9: 4 | I9: 6 | J9: 7 | M9: 8 | N9: 8 | O9: 3
A10: Churrasqueiras | B10: =SUM(G10:O10) -> 10 | C10: 2600 | D10: =B10*C10*1.1 -> 28600 | I10: 1 | M10: 4 | N10: 4 | O10: 1
A11: TOTAL | D11: =SUM(D7:D10) -> 634040
A13: COMUNICAÇÃO
A15: Descrição | B15: Parâmetro | D15: Valor total
A16: CFTV | B16: 2 | C16: R$ / AC | D16: =B16*DADOS_INICIAIS!$E$9*1.1 -> 28917.394
A17: Interfone | B17: 5 | C17: R$ / AC | D17: =B17*DADOS_INICIAIS!$E$9*1.1 -> 72293.485
A18: TV e internet | B18: 3 | C18: R$ / AC | D18: =B18*DADOS_INICIAIS!$E$9*1.1 -> 43376.091
A19: Automação, telecomunicação e sistemas de segurança | B19: 5 | C19: R$ / AC | D19: =B19*DADOS_INICIAIS!$E$9*1.1 -> 72293.485
A20: TOTAL | D20: =SUM(D16:D19) -> 216880.46
A22: EQUIPAMENTOS
A24: Descrição | B24: Quantidade | C24: Preço Unitário | D24: Valor total
A25: Elevadores | B25: 2 | C25: 486310 | D25: =B25*C25*1.1 -> 1069882
A26: Grupo de geradores | B26: 0 | C26: 80000 | D26: =B26*C26*1.1 -> 0
A27: Subestação | B27: 1 | C27: 350000 | D27: =B27*C27*1.1 -> 385000
A28: Escada pressurizada | B28: 0 | C28: =50*DADOS_INICIAIS!E9 -> 657213.5 | D28: =B28*C28*1.1 -> 0
A29: Bombas | B29: 1 | C29: 10000 | D29: =B29*C29*1.1 -> 11000
A30: Trataamento de esgoto | B30: 1 | C30: 110000 | D30: =B30*C30*1.1 -> 121000
A31: Infra de carro elétrico | B31: 4 | C31: 547 | D31: =B31*C31*1.1 -> 2406.8
A32: Equipamento d ecarro eletrico | B32: 4 | C32: 10500 | D32: =B32*C32*1.1 -> 46200
A33: Equipamentos para Sauna | B33: 1 | C33: 8500 | D33: =B33*C33*1.1 -> 9350
A34: Equipamentos para Piscina | B34: 1 | C34: 25000 | D34: =B34*C34*1.1 -> 27500
A35: TOTAL | D35: =SUM(D25:D34) -> 1672338.8
A37: OUTROS SISTEMAS ESPECIAIS
A39: Descrição | B39: Parâmetro | D39: Valor total
A40: Outros sistemas | B40: 20 | C40: R$ / AC | D40: =B40*DADOS_INICIAIS!E9*1.1 -> 289173.94
A41: TOTAL | D41: =SUM(D40:D40) -> 289173.94
A43: TOTAL SISTEMAS ESPECIAIS | D43: =D11+D20+D35+D41 -> 2812433.2 | E43: =D43/DADOS_INICIAIS!E9 -> 213.96648

Sheet IMPERMEABILIZAÇÃO
A3: IMPERMEABILIZAÇÃO
A4: Data | B4: 45457
A5: Arquivo base | B5: -
A7: ALVENARIA
A9: Descrição | B9: Parâmetro | D9: Quantidade | F9: Preço unitário | G9: Valor total | H9: Observação
A10: Regularização de Superfície | B10: 25 | C10: R$ / m² | D10: =D15+D16 -> 5257.708 | E10: m² | F10: 22 | G10: =F10*D10*1.1 -> 127236.53
A11: Poço do elevador | B11: 45 | C11: R$ / m² | D11: =(1.75*1.85)+(1.75+1.85)*2*1.8 -> 16.1975 | E11: m² | F11: 41 | G11: =F11*D11*1.1 -> 730.50725
A12: Baldrames | B12: 30 | C12: R$ / m² | D12: =INFRAESTRUTURA!D28 -> 1271.622 | E12: m² | F12: 35 | G12: =F12*D12*1.1 -> 48957.447
A13: Ralos | B13: 0.25 | C13: R$ / AC | D13: 1 | E13: vb | F13: =B13*DADOS_INICIAIS!$E$9 -> 3286.0675 | G13: =F13*D13*1.1 -> 3614.6743
A14: Tratamento de frisos | B14: 0.15 | C14: m²/m | D14: ='Rev. Fachada'!K19*5+'Rev. Fachada'!K20*9+'Rev. Fachada'!K21*5+'Rev. Fachada'!K22*2 -> 3381.6915 | E14: m | F14: 60 | G14: =D14*B14*F14*1.1 -> 33478.746
A15: Impermeabilizações cimenticias | B15: 0.3 | C15: m² / AC | D15: =B15*DADOS_INICIAIS!E9 -> 3943.281 | E15: m² | F15: 60 | G15: =F15*D15 -> 236596.86
A16: Impermeabilizações com manta asfaltica | B16: 0.1 | C16: m² / AC | D16: =B16*DADOS_INICIAIS!E9 -> 1314.427 | E16: m² | F16: 110 | G16: =F16*D16*1.1 -> 159045.67
A17: Impermeabilização de peitoril | B17: 0.6 | C17: R$ / AC | D17: 1 | E17: vb | F17: =B17*DADOS_INICIAIS!$E$9 -> 7886.562 | G17: =F17*D17*1.1 -> 8675.2182
A18: Proteção Mecânica | B18: 28 | C18: R$ / m² | D18: =D16 -> 1314.427 | E18: m² | F18: 28 | G18: =F18*D18*1.1 -> 40484.352
A19: TOTAL | G19: =SUM(G10:G18) -> 658820 | K19: =4160+1440+1120+2880+4800+91680+4000 -> 110080 | L19: =K19/21 -> 5241.9048
A21: TOTAL IMPERMEABILIZAÇÃO | G21: =G19 -> 658820 | H21: =G21/DADOS_INICIAIS!E9 -> 50.122221
H24: =H21/1.1 -> 45.565655

Sheet Rev. Internos Piso e Parede
A2: ORÇAMENTO PARAMÉTRICO GERENCIAMENTO EXECUTIVO
A7: Cliente | B7: Amalfi
A8: Obra | B8: San Felicce
A9: Data | B9: 45397
A10: Revisão | B10: R00
A12: REVESTIMENTOS INTERNOS EM PISO E PAREDE
J13: =SUM(G15:G18) -> 695869.97
A14: Descrição | B14: Quantidade | D14: Parâmetro | F14: Referência | G14: Valor total | J14: =G19+G20 -> 887474.82
A15: Polimento de concreto | B15: ='Acabamentos de Piso e Parede'!B36 -> 6243.04 | C15: m² | D15: 16.5 | E15: R$ / m² | F15: Média | G15: =D15*B15*1.1 -> 113311.18
A16: Piso alisado | B16: ='Acabamentos de Piso e Parede'!B42 -> 448.72 | C16: m² | D16: 25 | E16: R$ / m² | F16: Média | G16: =D16*B16*1.1 -> 12339.8
A17: Contrapiso | B17: 7543.26 | C17: m² | D17: =B17/DADOS_INICIAIS!E9 -> 0.573882 | E17: m² / AC | F17: Média | G17: =+B17*65*1.1 -> 539343.09
A18: Manta acústica | B18: =DADOS_INICIAIS!E21 -> 1122.76 | C18: m² | D18: =B18/DADOS_INICIAIS!E9 -> 0.085418209 | E18: m² / AC | F18: Média | G18: =+B18*25*1.1 -> 30875.9
A19: Chapisco | B19: =DADOS_INICIAIS!E9*'Rev. Internos Piso e Parede'!D19*0.62 -> 14669.005 | C19: m² | D19: 1.8 | E19: m² / AC | F19: Média | G19: =+B19*5*1.1 -> 80679.529
A20: Reboco | B20: =DADOS_INICIAIS!E9*'Rev. Internos Piso e Parede'!D20*0.62 -> 14669.005 | C20: m² | D20: 1.8 | E20: m² / AC | F20: Média | G20: =50*B20*1.1 -> 806795.29
A21: TOTAL | G21: =SUM(G15:G20) -> 1583344.8
A24: TOTAL REVESTIMENTOS | G24: =G21 -> 1583344.8 | H24: =G24/DADOS_INICIAIS!E9 -> 120.45894
H26: =H24/1.1 -> 109.50812

Sheet TETO
A3: REVESTIMENTOS E ACABAMENTOS DE TETO
A4: Data | B4: 45457
A5: Arquivo base | B5: -
A7: ALVENARIA
A9: Descrição | B9: Parâmetro | D9: Quantidade | F9: Preço unitário | G9: Valor total | H9: Observação
A10: Forro em placa mineral | B10: 0.6 | C10: m² / AC | D10: =B10*DADOS_INICIAIS!E9 -> 7886.562 | E10: m² | F10: 120 | G10: =F10*D10*1.1 -> 1041026.2
A11: Negativo | B11: 1.2 | C11: m / FORRO | D11: =D10*B11 -> 9463.8744 | E11: m² | F11: 22 | G11: =F11*D11*1.1 -> 229025.76
A12: Estucamento | B12: =D12/DADOS_INICIAIS!E9 -> 0.33158175 | C12: m² / AC | D12: =DADOS_INICIAIS!E22-1110.68 -> 4358.4 | E12: m² | F12: 24 | G12: =F12*D12*1.1 -> 115061.76
A13: Chapisco e reboco | B13: =1-B10-B12 -> 0.068418254 | C13: m² / AC | D13: =B13*DADOS_INICIAIS!E9 -> 899.308 | E13: m² | F13: 91 | G13: =F13*D13*1.05*1.1 -> 94521.767
A14: TOTAL | G14: =SUM(G10:G13) -> 1479635.5 | K14: =4160+1440+1120+2880+4800+91680+4000 -> 110080 | L14: =K14/21 -> 5241.9048
A16: TOTAL IMPERMEABILIZAÇÃO | G16: =G14 -> 1479635.5 | H16: =G16/DADOS_INICIAIS!E9 -> 112.56886
H19: =H16/1.1 -> 102.33533

Sheet Acabamentos de Piso e Parede
A2: ORÇAMENTO PARAMÉTRICO GERENCIAMENTO EXECUTIVO
A7: Cliente | B7: Amalfi
A8: Obra | B8: San Felicce
A9: Data | B9: 45397
A10: Revisão | B10: R00
A12: ACABAMENTOS EM PISO E PAREDE
A14: Descrição | B14: Quantidade | D14: Parâmetro | F14: Referência | G14: Valor total
A15: Porcelanato | B15: =B33 -> 2612.64 | C15: m² | D15: 125 | E15: R$ / m² | F15: Média | G15: =+D15*B15*1.1 -> 359238
A16: Cerâmico | B16: =B34 -> 29.99 | C16: m² | D16: 98 | E16: R$ / m² | F16: Média | G16: =+D16*B16*1.1 -> 3232.922
A17: Piso vinilico | B17: =B37+B35 -> 4707.69 | C17: m² | D17: 150 | E17: R$ / m² | F17: Média | G17: =+D17*B17*1.1 -> 776768.85
A18: Emborrachado | B18: =B43 -> 138.18 | C18: m² | D18: 350 | E18: R$ / m² | F18: Média | G18: =+D18*B18*1.1 -> 53199.3
A19: Carpete | B19: 0 | C19: m² | D19: 350 | E19: R$ / m² | F19: Média | G19: =+D19*B19*1.1 -> 0
A20: Piscina | B20: =B41 -> 54.76 | C20: m² | D20: 300 | E20: R$ / m² | F20: Média | G20: =+D20*B20*1.1 -> 18070.8
A21: Deck | B21: =B40 -> 58.41 | C21: m² | D21: 450 | E21: R$ / m² | F21: Média | G21: =+D21*B21*1.1 -> 28912.95
A22: Paver | B22: =B39 -> 134.39 | C22: m² | D22: 60 | E22: R$ / m² | F22: Média | G22: =+D22*B22*1.1 -> 8869.74
A23: Ladrilho hidaraulico | B23: =B38 -> 280.79 | C23: m² | D23: 180 | E23: R$ / m² | F23: Média | G23: =+D23*B23*1.1 -> 55596.42
A24: Rodapés | B24: 1 | C24: vb | D24: 30 | E24: R$ / AC | F24: Média | G24: =D24*DADOS_INICIAIS!$E$9*1.1 -> 433760.91
A25: Soleiras e peitoris | B25: 1 | C25: vb | D25: 20 | E25: R$ / AC | F25: Média | G25: =D25*DADOS_INICIAIS!$E$9*1.1 -> 289173.94
A26: Revestimentos de Parede | B26: 1 | C26: vb | D26: 30 | E26: R$ / AC | F26: Média | G26: =D26*DADOS_INICIAIS!$E$9*1.1 -> 433760.91
A27: =20*40 -> 800 | G27: =SUM(G15:G26) -> 2460584.7
A30: TOTAL ACABAMENTOS | G30: =G27 -> 2460584.7 | H30: =G30/DADOS_INICIAIS!E9 -> 187.19828
H32: =H30/1.1 -> 170.18025
A33: PORCELANATO | B33: 2612.64
A34: CERAMICA | B34: 29.99
A35: CARPETE | B35: 181.54
A36: PISO ALISADO | B36: 6243.04
A37: VINILICO | B37: 4526.15
A38: PISO RANHURADO | B38: 280.79
A39: PAVER | B39: 134.39
A40: DECK | B40: 58.41
A41: PASTILHA | B41: 54.76
A42: PISO ALISADO ESCADA | B42: 448.72
A43: EMBORRACHADO | B43: 138.18

Sheet PINTURA INTERNA
A3: PINTURA INTERNA
A4: Data | B4: 45457
A5: Arquivo base | B5: -
A7: ALVENARIA
A9: Descrição | B9: Parâmetro | D9: Quantidade | F9: Preço unitário | G9: Valor total | H9: Observação
A10: Pintura piso epoxi | B10: 25 | C10: R$ / m² | D10: ='Rev. Internos Piso e Parede'!B15 -> 6243.04 | E10: m² | F10: 110 | G10: =F10*D10*1.1 -> 755407.84
A11: Pintura acrílica antiderrapante | B11: 45 | C11: R$ / m² | D11: ='Rev. Internos Piso e Parede'!B16 -> 448.72 | E11: m² | F11: 65 | G11: =F11*D11*1.1 -> 32083.48
A12: Textura escadas | B12: 15 | C12: R$ / AC | D12: 1 | E12: vb | F12: =B12*DADOS_INICIAIS!$E$9 -> 197164.05 | G12: =F12*D12*1.1 -> 216880.46
A13: Pintura Interna | B13: 50 | C13: R$ / AC | D13: 1 | E13: vb | F13: =B13*DADOS_INICIAIS!$E$9 -> 657213.5 | G13: =F13*D13*1.05*1.1 -> 759081.59
A14: TOTAL | G14: =SUM(G10:G13) -> 1763453.4 | K14: =4160+1440+1120+2880+4800+91680+4000 -> 110080 | L14: =K14/21 -> 5241.9048
A16: TOTAL IMPERMEABILIZAÇÃO | G16: =G14 -> 1763453.4 | H16: =G16/DADOS_INICIAIS!E9 -> 134.16138
H18: =H16/1.1 -> 121.96489

Sheet ESQUADRIAS
A3: ESQUADRIAS
A4: Data | B4: 45460
A5: Arquivo base | B5: -
A7: ESQUADRIAS
A9: Descrição | B9: Parâmetro | D9: Quantidade | F9: Preço unitário | G9: Valor total | H9: Observação
A10: Esquadrias de Alumínio | B10: 0.15 | C10: m² / AC | D10: =B10*DADOS_INICIAIS!E9 -> 1971.6405 | E10: m² | F10: 1100 | G10: =F10*D10*1.1 -> 2385685 | H10: =G10/DADOS_INICIAIS!E9 -> 181.5
A11: Brise de aluminio | D11: =16.62*11.6 -> 192.792 | E11: m² | F11: 1500 | G11: =F11*D11*1.1 -> 318106.8
A12: Portão de alumínio | D12: 1 | E12: un | F12: 18000 | G12: =F12*D12*1.1 -> 19800
A13: Guarda-corpo - vidro | D13: =(0.5*2+30.55*2+8.5)+(1.5+7.5+7.45*2+7.5+1.15)+(1.1+3.5+3.25*3)+(15.1*2+7.11) -> 154.81 | E13: m | F13: =750*1.1 -> 825 | G13: =F13*D13*1.1 -> 140490.08
A14: Gradil | D14: =(1.9+0.5*2*8+1.8+2.89)*7+(1.8+2.89)*4 -> 120.89 | E14: m | F14: =680*1.1 -> 748 | G14: =F14*D14*1.1 -> 99468.292
A15: Corrimão inox | D15: =2.3*2 -> 4.6 | E15: m | F15: 150 | G15: =F15*D15*1.1 -> 759
A16: Serralherias | B16: 10 | C16: R$ / AC | D16: 1 | E16: vb | F16: =B16*DADOS_INICIAIS!$E$9 -> 131442.7 | G16: =F16*D16*1.1 -> 144586.97
A17: PCF | D17: =2*DADOS_INICIAIS!E15+1 -> 41 | E17: un | F17: 1750 | G17: =F17*D17*1.1 -> 78925
A18: Corrimão metálico | D18: =(2.6*2+2.96+1.4*2+0.56*2)*1.2*20 -> 289.92 | E18: m | F18: 120 | G18: =F18*D18*1.1 -> 38269.44
A19: Fechadura biométrica | D19: =DADOS_INICIAIS!E10 -> 156 | F19: 1400 | G19: =F19*D19*1.1 -> 240240
A20: Esquadrias de Madeira | D20: =13+44*7+31+34+24*3+16+1 -> 475 | E20: un | F20: 2100 | G20: =F20*D20*1.1 -> 1097250
A21: TOTAL | G21: =SUM(G10:G20) -> 4563580.6 | K21: =4160+1440+1120+2880+4800+91680+4000 -> 110080 | L21: =K21/21 -> 5241.9048
A23: TOTAL ESQUADRIAS | G23: =G21 -> 4563580.6 | H23: =G23/DADOS_INICIAIS!E9 -> 347.19163

Sheet COBERTURA
A2: COBERTURA
A3: Data | B3: 45460
A4: Arquivo base | B4: -
A6: TELHADO
A8: Descrição | B8: Parâmetro | D8: Quantidade | F8: Preço unitário | G8: Valor total | H8: Observação
A9: Estrutura e telhamento | D9: 105.86 | E9: m² | F9: 500 | G9: =F9*D9*1.1 -> 58223
A10: Serviços complementares | D10: 105.86 | E10: m² | F10: 45 | G10: =F10*D10*1.1 -> 5240.07
A11: Pergolados | G11: =F11*D11*1.1 -> 0
A12: Passarelas | G12: =F12*D12*1.1 -> 0
A13: Estrutura metálica cobertura atico | D13: 85.2 | F13: 700 | G13: =F13*D13*1.1 -> 65604
A14: TOTAL | G14: =SUM(G9:G13) -> 129067.07
A16: TOTAL COMPLEMENTARES | G16: =G14 -> 129067.07 | H16: =G16/DADOS_INICIAIS!$E$9 -> 9.819265

Sheet Rev. Fachada
A2: ORÇAMENTO PARAMÉTRICO GERENCIAMENTO EXECUTIVO
A7: Cliente | B7: Passe
A8: Obra | B8: Connect
A9: Data | B9: 45460
A10: Revisão | B10: R00
A12: REVESTIMENTOS ARGAMASSADOS
A14: Descrição | B14: Quantidade | D14: Parâmetro | F14: Referência | G14: Valor total
A15: Chapisco e reboco | B15: =K19*L19+K20*L20+K22*L22+K21*L21+K24*L24-(16.62*L19)-ESQUADRIAS!D10 -> 7899.8902 | C15: m² | D15: =25+70 -> 95 | E15: R$ / m² | F15: - | G15: =B15*D15*1.1 -> 825538.52
A16: Chapisco e reboco molduras | B16: =($K$20*9+$K$21*5+$K$22)*0.7 -> 1617.715 | C16: m² | D16: =25+70 -> 95 | E16: R$ / m² | G16: =B16*D16*1.1 -> 169051.22
A17: TOTAL | G17: =SUM(G15:G16) -> 994589.75
A19: PINTURA | J19: EMBASAMENTO | K19: =DADOS_INICIAIS!E26 -> 179.11 | L19: 11.34
J20: TORRE 1 | K20: =DADOS_INICIAIS!E20 -> 179.6335 | L20: 27.74
A21: Descrição | B21: Quantidade | D21: Parâmetro | F21: Referência | G21: Valor total | J21: TORRE 2 | K21: 103.84 | L21: 15.3
A22: Textura | B22: =B15 -> 7899.8902 | C22: m² | D22: =70+15 -> 85 | E22: R$ / m² | F22: - | G22: =B22*D22*1.1 -> 738639.73 | J22: ATICO | K22: 175.12 | L22: 7.24
A23: Textura molduras | B23: =($K$20*9+$K$21*5+$K$22)*0.7 -> 1617.715 | C23: m² | D23: =70+15 -> 85 | E23: R$ / m² | G23: =B23*D23*1.1 -> 151256.36
A24: TOTAL | G24: =SUM(G22:G23) -> 889896.09 | J24: RESERV | K24: 63.08 | L24: 3
L25: =K19*L19+K20*L20+K21*L21+K22*L22+K24*L24 -> 10060.001
A26: ACABAMENTOS ESPECIAIS
A28: Descrição | B28: Quantidade | D28: Parâmetro | F28: Referência | G28: Valor total
A29: Molduras ACM | B29: =(16.62*5)*0.7 -> 58.17 | C29: M² | D29: 850 | E29: R$ / m² | F29: - | G29: =B29*D29*1.1 -> 54388.95
A30: LED MOLDURAS | B30: =($K$20*9+$K$21*5+$K$22)+(16.62*5) -> 2394.1215 | C30: M | D30: 120 | E30: R$ / m | G30: =B30*D30*1.1 -> 316024.04
G31: =SUM(G29:G30) -> 370412.99
J32: =25.78*2 -> 51.56
A34: TOTAL FACHADA | G34: =G24+G17+G31 -> 2254898.8 | H34: =G34/DADOS_INICIAIS!E9 -> 171.54995
H35: =H34/1.1 -> 155.9545

Sheet COMPLEMENTARES
A2: COMPLEMENTARES
A3: Data | B3: 45460
A4: Arquivo base | B4: -
A6: SERVIÇOS COMPLEMENTARES
A8: Descrição | B8: Parâmetro | D8: Quantidade | F8: Valor total
A9: Móveis e decoração | B9: 1750 | C9: R$ / AL | D9: =DADOS_INICIAIS!E21 -> 1122.76 | E9: m² | F9: =D9*B9*1.1 -> 2161313
A10: Louças e metais | B10: 30 | C10: R$ / AC | D10: =B10*DADOS_INICIAIS!$E$9-INSTALAÇÕES!D23 -> 322034.61 | E10: R$ | F10: =D10*1.1 -> 354238.08
A11: Comunicação visual | B11: 10 | C11: R$ / AC | D11: =B11*DADOS_INICIAIS!$E$9 -> 131442.7 | E11: R$ | F11: =D11*1.1 -> 144586.97
A12: Paisagismo | B12: 12 | C12: R$ / AC | D12: =B12*DADOS_INICIAIS!$E$9 -> 157731.24 | E12: R$ | F12: =D12*1.1 -> 173504.36
A13: Quadra paddle | B13: 550 | C13: R$ / m² | D13: 194.89 | E13: R$ | F13: =D13*B13*1.1 -> 117908.45
A14: Ligações definitivas | B14: 4 | C14: R$ / AC | D14: =B14*DADOS_INICIAIS!$E$9 -> 52577.08 | E14: R$ | F14: =D14*1.1 -> 57834.788
A15: Desmobilização | B15: 5 | C15: R$ / AC | D15: =B15*DADOS_INICIAIS!$E$9 -> 65721.35 | E15: R$ | F15: =D15*1.1 -> 72293.485
A16: Limpeza | B16: 15 | C16: R$ / AC | D16: =B16*DADOS_INICIAIS!$E$9 -> 197164.05 | E16: R$ | F16: =D16*1.1 -> 216880.46
A17: TOTAL | F17: =SUM(F9:F16) -> 3298559.6
A19: TOTAL COMPLEMENTARES | F19: =F17 -> 3298559.6 | G19: =F19/DADOS_INICIAIS!$E$9 -> 250.95038

Sheet Auxiliar
A2: 2 Portões acesso garagem - Área: 9,2m² x 2 = 18,4m² | B2: 2 | C2: portão | D2: 18.4
A3: 2 portas corta-fogo 1 folha | B3: 2 | C3: pcf
A4: 1 porta de correr alumínio 2 folhas – Área: 3,465m² | B4: 1 | C4: porta alumínio | D4: 3.465
A5: 1 porta de correr alumínio 2 folhas – Área: 1,7325m² | B5: 1 | C5: porta alumínio | D5: 1.7325 | G5: Guarda alumínio | H5: =SUMIF(C:C,G5,D:D) -> 400.5221
A6: 2 portas de abrir alumínio 2 folhas – Área: 2,6376m² x 2 = 5,2752m² | B6: 2 | C6: porta alumínio | D6: 5.2752 | G6: janela | H6: =SUMIF(C:C,G6,D:D) -> 1895.06
A7: 1 porta de abrir alumínio 2 folhas – Área: 4,1916m² | B7: 1 | C7: porta alumínio | D7: 4.1916 | G7: madeira | H7: =SUMIF(C:C,G7,B:B) -> 218
A8: 1 porta pivotante | B8: 1 | C8: pivotante | G8: pcf | H8: =SUMIF(C:C,G8,B:B) -> 60
A9: 19 portas de abrir madeira 1 folha | B9: 19 | C9: madeira | G9: pivotante | H9: =SUMIF(C:C,G9,B:B) -> 1
A10: 3 portas de abrir vidro 1 folha – Área: 2,1m² x 3 = 6,3m² | B10: 3 | C10: porta alumínio | D10: 6.3 | G10: porta alumínio | H10: =SUMIF(C:C,G10,D:D) -> 46.62
A11: 2 portas de abrir vidro 1 folha – Área: 1,89m² x 2 = 3,78m² | B11: 2 | C11: porta alumínio | D11: 3.78 | G11: portão | H11: =SUMIF(C:C,G11,B:B) -> 2
A12: 1 porta de abrir alumínio 1 folha – Área: 2,0076m² | B12: 1 | C12: porta alumínio | D12: 2.0076 | G12: gradil | H12: =SUMIF(C:C,G12,D:D) -> 113.88
A13: Janelas – Área: 3,75 + 4,875 + 2,5 + 1,1 + 1,2 + 5,5402 + 4,4874 = 23,4526m² | C13: janela | D13: 23.4526 | G13: Brise | H13: 109.3146
A14: Muro de vidro – Área: 7,0774 + 5,485 + 3,43 + 4,8138 = 20,8062m² | C14: Guarda alumínio | D14: 20.8062
A15: 8 portas corta-fogo 1 folha | B15: 8 | C15: pcf
A16: Janelas – Area: (1,1 + 1,2 + 28,7391) x 4 = 124,1564m² | C16: janela | D16: 124.1564
A17: 2 portas corta-fogo 1 folha | B17: 2 | C17: pcf
A18: 2 portas de abrir alumínio 1 folha – Área: 1,47m² x 2 = 2,94m² | B18: 2 | C18: porta alumínio | D18: 2.94
A19: 2 portas de abrir vidro 1 folha – Área: 1,89m² x 2 = 3,78m² | B19: 2 | C19: porta alumínio | D19: 3.78
A20: 5 portas de abrir madeira 1 folha | B20: 5 | C20: madeira
A21: 1 janela-porta de correr vidro – Área: 14,7348m² | B21: 1 | C21: janela | D21: 14.7348
A22: Janelas – Área: 1,2894 + 1,2894 + 23,46 + 1,854 + 5,562 + 5,562 + 1,854 + 1,854 + 1,1 + 1,2 = 45,0248m² | C22: janela | D22: 45.0248
A23: Guarda corpo vidro – Área: 7,5299 + 5,7955 + 6,5555 = 19,8809m² | C23: Guarda alumínio | D23: 19.8809
A24: 38 portas corta-fogo 1 folha | B24: 38 | C24: pcf
A25: 171 portas de abrir madeira 1 folha | B25: 171 | C25: madeira
A26: 19 porta de abrir alumínio 1 folha – Área: 1,26m² x 19 = 23,94m² | B26: 19 | C26: porta alumínio | D26: 23.94
A27: 19 janela-porta de correr vidro 5 folhas - Área: 25,4205m² x 19 = 482,9895m² | B27: 19 | C27: janela | D27: 482.9895
A28: 19 janela-porta de correr vidro 5 folhas - Área: 17,8284m² x 19 = 338,7396m² | B28: 19 | C28: janela | D28: 338.7396
A29: Janelas – Área: 1,1 + 1,1 + 1,2 + 1,92 + 0,36 + 2,781 + 2,781 + 1,854 + 1,854 + 5,562 + 5,562 + 1,854 = 27,928m² x 19 = 530,632m² | C29: janela | D29: 530.632
A30: Guarda corpo metálico – Área: 4,745m² x 19 = 90,155m² - Perímetro: 3,65m x 19 = 69,35m | C30: gradil | D30: 90.155
A31: Guarda corpo vidro – Área: 15,645m² x 19 = 297,255m² - Perímetro: 14,9m x 19 = 283,1m | C31: Guarda alumínio | D31: 297.255
A32: 2 portas corta-fogo 1 folha | B32: 2 | C32: pcf
A33: 2 portas de abrir madeira 1 folha | B33: 2 | C33: madeira
A34: 1 porta de abrir alumínio 1 folha – Área: 1,26m² | B34: 1 | C34: porta alumínio | D34: 1.26
A35: 1 janela-porta de correr vidro 3 folhas - Área: 15,21m² | B35: 1 | C35: janela | D35: 15.21
A36: 1 janela-porta de correr vidro 5 folhas - Área: 25,4205m² | B36: 1 | C36: janela | D36: 25.4205
A37: 1 janela-porta de correr vidro 5 folhas - Área: 17,8284m² | B37: 1 | C37: janela | D37: 17.8284
A38: Janelas – Área: 1,1 + 1,2 + 1,1 + 1,92 + 0,36 + 2,781 + 2,781 + 1,854 + 1,854 + 5,562 + 5,562 + 1,854 = 27,928m² | C38: janela | D38: 27.928
A39: Guarda corpo metálico – Área: 4,745m² - Perímetro: 3,65m | C39: gradil | D39: 4.745
A40: Guarda corpo vidro – Área: 15,645m² - Perímetro: 14,9m | C40: Guarda alumínio | D40: 15.645
A41: 2 portas corta-fogo 1 folha | B41: 2 | C41: pcf
...
