Workbook

Sheet Fìsico
E2: 44378 | F2: 44409 | G2: 44440 | H2: 44470 | I2: 44501 | J2: 44531 | K2: 44562 | L2: 44593 | M2: 44621 | N2: 44652 | O2: 44682 | P2: 44713 | Q2: 44743 | R2: 44774 | S2: 44805 | T2: 44835 | U2: 44866 | V2: 44896 | W2: 44927 | X2: 44958 | Y2: 44986 | Z2: 45017 | AA2: 45047 | AB2: 45078 | AC2: 45108 | AD2: 45139 | AE2: 45170 | AF2: 45200 | AG2: 45231 | AH2: 45261 | AI2: 45292 | AJ2: 45323 | AK2: 45352 | AL2: 45383 | AM2: 45413 | AN2: 45444 | AO2: 45474 | AP2: 45505
A3: Nome da Tarefa | B3: Duração | C3: Início | D3: Término | E3: %Avanço Físico | F3: %Avanço Físico | G3: %Avanço Físico | H3: %Avanço Físico | I3: %Avanço Físico | J3: %Avanço Físico | K3: %Avanço Físico | L3: %Avanço Físico | M3: %Avanço Físico | N3: %Avanço Físico | O3: %Avanço Físico | P3: %Avanço Físico | Q3: %Avanço Físico | R3: %Avanço Físico | S3: %Avanço Físico | T3: %Avanço Físico | U3: %Avanço Físico | V3: %Avanço Físico | W3: %Avanço Físico | X3: %Avanço Físico | Y3: %Avanço Físico | Z3: %Avanço Físico | AA3: %Avanço Físico | AB3: %Avanço Físico | AC3: %Avanço Físico | AD3: %Avanço Físico | AE3: %Avanço Físico | AF3: %Avanço Físico | AG3: %Avanço Físico | AH3: %Avanço Físico | AI3: %Avanço Físico | AJ3: %Avanço Físico | AK3: %Avanço Físico | AL3: %Avanço Físico | AM3: %Avanço Físico | AN3: %Avanço Físico | AO3: %Avanço Físico | AP3: %Avanço Físico
A4: PLANEJAMENTO NAUTILUS | CHIQUETTI | B4: 823,63 dias | C4: 44377 | D4: 45509 | E4: 0.03 | F4: 1.3 | G4: 1.81 | H4: 2.36 | I4: 2.8 | J4: 3.57 | K4: 4.03 | L4: 4.49 | M4: 5.08 | N4: 5.8 | O4: 6.67 | P4: 7.42 | Q4: 10.65 | R4: 12.59 | S4: 19.28 | T4: 23.99 | U4: 25.83 | V4: 27.68 | W4: 34.82 | X4: 38.88 | Y4: 45.07 | Z4: 52.1 | AA4: 57.49 | AB4: 60.95 | AC4: 70.81 | AD4: 76.88 | AE4: 79.06 | AF4: 82.92 | AG4: 89.02 | AH4: 92.59 | AI4: 95.91 | AJ4: 98.58 | AK4: 98.58 | AL4: 98.61 | AM4: 99.19 | AN4: 99.74 | AO4: 100 | AP4: 100
A5: PLANEJAMENTO NAUTILUS | B5: 820,5 dias | C5: 44377 | D5: 45504 | E5: 0.03 | F5: 1.3 | G5: 1.81 | H5: 2.36 | I5: 2.8 | J5: 3.57 | K5: 4.03 | L5: 4.49 | M5: 5.08 | N5: 5.8 | O5: 6.67 | P5: 7.42 | Q5: 10.65 | R5: 12.59 | S5: 19.28 | T5: 23.99 | U5: 25.83 | V5: 27.68 | W5: 34.82 | X5: 38.88 | Y5: 45.07 | Z5: 52.1 | AA5: 57.49 | AB5: 60.95 | AC5: 70.81 | AD5: 76.88 | AE5: 79.06 | AF5: 82.92 | AG5: 89.02 | AH5: 92.59 | AI5: 95.91 | AJ5: 98.58 | AK5: 98.58 | AL5: 98.61 | AM5: 99.19 | AN5: 99.74 | AO5: 100 | AP5: 100
A6: INFRAESTRUTURA | B6: 130,5 dias | C6: 44377 | D6: 44552 | E6: 0.03 | F6: 1.3 | G6: 1.81 | H6: 2.36 | I6: 2.8 | J6: 3.39 | K6: 3.39 | L6: 3.39 | M6: 3.39 | N6: 3.39 | O6: 3.39 | P6: 3.39 | Q6: 3.39 | R6: 3.39 | S6: 3.39 | T6: 3.39 | U6: 3.39 | V6: 3.39 | W6: 3.39 | X6: 3.39 | Y6: 3.39 | Z6: 3.39 | AA6: 3.39 | AB6: 3.39 | AC6: 3.39 | AD6: 3.39 | AE6: 3.39 | AF6: 3.39 | AG6: 3.39 | AH6: 3.39 | AI6: 3.39 | AJ6: 3.39 | AK6: 3.39 | AL6: 3.39 | AM6: 3.39 | AN6: 3.39 | AO6: 3.39 | AP6: 3.39
A7: SERVIÇOS PRELIMINARES | B7: 126,38 dias | C7: 44377 | D7: 44544 | E7: 0.03 | F7: 1.16 | G7: 1.16 | H7: 1.29 | I7: 1.3 | J7: 1.49 | K7: 1.49 | L7: 1.49 | M7: 1.49 | N7: 1.49 | O7: 1.49 | P7: 1.49 | Q7: 1.49 | R7: 1.49 | S7: 1.49 | T7: 1.49 | U7: 1.49 | V7: 1.49 | W7: 1.49 | X7: 1.49 | Y7: 1.49 | Z7: 1.49 | AA7: 1.49 | AB7: 1.49 | AC7: 1.49 | AD7: 1.49 | AE7: 1.49 | AF7: 1.49 | AG7: 1.49 | AH7: 1.49 | AI7: 1.49 | AJ7: 1.49 | AK7: 1.49 | AL7: 1.49 | AM7: 1.49 | AN7: 1.49 | AO7: 1.49 | AP7: 1.49
A8: MOVIMENTAÇÃO DE TERRA | B8: 111 dias | C8: 44397 | D8: 44544 | E8: 0 | F8: 0.74 | G8: 0.74 | H8: 0.87 | I8: 0.88 | J8: 1.07 | K8: 1.07 | L8: 1.07 | M8: 1.07 | N8: 1.07 | O8: 1.07 | P8: 1.07 | Q8: 1.07 | R8: 1.07 | S8: 1.07 | T8: 1.07 | U8: 1.07 | V8: 1.07 | W8: 1.07 | X8: 1.07 | Y8: 1.07 | Z8: 1.07 | AA8: 1.07 | AB8: 1.07 | AC8: 1.07 | AD8: 1.07 | AE8: 1.07 | AF8: 1.07 | AG8: 1.07 | AH8: 1.07 | AI8: 1.07 | AJ8: 1.07 | AK8: 1.07 | AL8: 1.07 | AM8: 1.07 | AN8: 1.07 | AO8: 1.07 | AP8: 1.07
A9: Limpeza do Terreno | B9: 5 dias | C9: 44397 | D9: 44403 | E9: 0 | F9: 0 | G9: 0 | H9: 0 | I9: 0 | J9: 0 | K9: 0 | L9: 0 | M9: 0 | N9: 0 | O9: 0 | P9: 0 | Q9: 0 | R9: 0 | S9: 0 | T9: 0 | U9: 0 | V9: 0 | W9: 0 | X9: 0 | Y9: 0 | Z9: 0 | AA9: 0 | AB9: 0 | AC9: 0 | AD9: 0 | AE9: 0 | AF9: 0 | AG9: 0 | AH9: 0 | AI9: 0 | AJ9: 0 | AK9: 0 | AL9: 0 | AM9: 0 | AN9: 0 | AO9: 0 | AP9: 0
A10: Escavação Mecânica - Subsolo | B10: 12 dias | C10: 44414 | D10: 44431 | E10: 0 | F10: 0.74 | G10: 0.74 | H10: 0.74 | I10: 0.74 | J10: 0.74 | K10: 0.74 | L10: 0.74 | M10: 0.74 | N10: 0.74 | O10: 0.74 | P10: 0.74 | Q10: 0.74 | R10: 0.74 | S10: 0.74 | T10: 0.74 | U10: 0.74 | V10: 0.74 | W10: 0.74 | X10: 0.74 | Y10: 0.74 | Z10: 0.74 | AA10: 0.74 | AB10: 0.74 | AC10: 0.74 | AD10: 0.74 | AE10: 0.74 | AF10: 0.74 | AG10: 0.74 | AH10: 0.74 | AI10: 0.74 | AJ10: 0.74 | AK10: 0.74 | AL10: 0.74 | AM10: 0.74 | AN10: 0.74 | AO10: 0.74 | AP10: 0.74
A11: Escavação Mecânica - Blocos de Fundação | B11: 20 dias | C11: 44475 | D11: 44503 | E11: 0 | F11: 0 | G11: 0 | H11: 0.13 | I11: 0.14 | J11: 0.14 | K11: 0.14 | L11: 0.14 | M11: 0.14 | N11: 0.14 | O11: 0.14 | P11: 0.14 | Q11: 0.14 | R11: 0.14 | S11: 0.14 | T11: 0.14 | U11: 0.14 | V11: 0.14 | W11: 0.14 | X11: 0.14 | Y11: 0.14 | Z11: 0.14 | AA11: 0.14 | AB11: 0.14 | AC11: 0.14 | AD11: 0.14 | AE11: 0.14 | AF11: 0.14 | AG11: 0.14 | AH11: 0.14 | AI11: 0.14 | AJ11: 0.14 | AK11: 0.14 | AL11: 0.14 | AM11: 0.14 | AN11: 0.14 | AO11: 0.14 | AP11: 0.14
A12: Reaterro - Blocos e Baldrames | B12: 3 dias | C12: 44539 | D12: 44544 | E12: 0 | F12: 0 | G12: 0 | H12: 0 | I12: 0 | J12: 0.19 | K12: 0.19 | L12: 0.19 | M12: 0.19 | N12: 0.19 | O12: 0.19 | P12: 0.19 | Q12: 0.19 | R12: 0.19 | S12: 0.19 | T12: 0.19 | U12: 0.19 | V12: 0.19 | W12: 0.19 | X12: 0.19 | Y12: 0.19 | Z12: 0.19 | AA12: 0.19 | AB12: 0.19 | AC12: 0.19 | AD12: 0.19 | AE12: 0.19 | AF12: 0.19 | AG12: 0.19 | AH12: 0.19 | AI12: 0.19 | AJ12: 0.19 | AK12: 0.19 | AL12: 0.19 | AM12: 0.19 | AN12: 0.19 | AO12: 0.19 | AP12: 0.19
A13: SERVIÇOS COMPLEMENTARES E PROVISÓRIOS | B13: 30,38 dias | C13: 44377 | D13: 44414 | E13: 0.03 | F13: 0.42 | G13: 0.42 | H13: 0.42 | I13: 0.42 | J13: 0.42 | K13: 0.42 | L13: 0.42 | M13: 0.42 | N13: 0.42 | O13: 0.42 | P13: 0.42 | Q13: 0.42 | R13: 0.42 | S13: 0.42 | T13: 0.42 | U13: 0.42 | V13: 0.42 | W13: 0.42 | X13: 0.42 | Y13: 0.42 | Z13: 0.42 | AA13: 0.42 | AB13: 0.42 | AC13: 0.42 | AD13: 0.42 | AE13: 0.42 | AF13: 0.42 | AG13: 0.42 | AH13: 0.42 | AI13: 0.42 | AJ13: 0.42 | AK13: 0.42 | AL13: 0.42 | AM13: 0.42 | AN13: 0.42 | AO13: 0.42 | AP13: 0.42
A14: Rebaixamento de Lençol Freático | B14: 5 dias | C14: 44410 | D14: 44414 | E14: 0 | F14: 0.39 | G14: 0.39 | H14: 0.39 | I14: 0.39 | J14: 0.39 | K14: 0.39 | L14: 0.39 | M14: 0.39 | N14: 0.39 | O14: 0.39 | P14: 0.39 | Q14: 0.39 | R14: 0.39 | S14: 0.39 | T14: 0.39 | U14: 0.39 | V14: 0.39 | W14: 0.39 | X14: 0.39 | Y14: 0.39 | Z14: 0.39 | AA14: 0.39 | AB14: 0.39 | AC14: 0.39 | AD14: 0.39 | AE14: 0.39 | AF14: 0.39 | AG14: 0.39 | AH14: 0.39 | AI14: 0.39 | AJ14: 0.39 | AK14: 0.39 | AL14: 0.39 | AM14: 0.39 | AN14: 0.39 | AO14: 0.39 | AP14: 0.39
A15: Serviços de Sondagem | B15: 10 dias | C15: 44377 | D15: 44390 | E15: 0.03 | F15: 0.03 | G15: 0.03 | H15: 0.03 | I15: 0.03 | J15: 0.03 | K15: 0.03 | L15: 0.03 | M15: 0.03 | N15: 0.03 | O15: 0.03 | P15: 0.03 | Q15: 0.03 | R15: 0.03 | S15: 0.03 | T15: 0.03 | U15: 0.03 | V15: 0.03 | W15: 0.03 | X15: 0.03 | Y15: 0.03 | Z15: 0.03 | AA15: 0.03 | AB15: 0.03 | AC15: 0.03 | AD15: 0.03 | AE15: 0.03 | AF15: 0.03 | AG15: 0.03 | AH15: 0.03 | AI15: 0.03 | AJ15: 0.03 | AK15: 0.03 | AL15: 0.03 | AM15: 0.03 | AN15: 0.03 | AO15: 0.03 | AP15: 0.03
... A1116: Custo a ser aprovado: Ambientação e Taxa Adm | B1116: 1 dia | C1116: 45506 | D1116: 45509 | E1116: 0 | F1116: 0 | G1116: 0 | H1116: 0 | I1116: 0 | J1116: 0 | K1116: 0 | L1116: 0 | M1116: 0 | N1116: 0 | O1116: 0 | P1116: 0 | Q1116: 0 | R1116: 0 | S1116: 0 | T1116: 0 | U1116: 0 | V1116: 0 | W1116: 0 | X1116: 0 | Y1116: 0 | Z1116: 0 | AA1116: 0 | AB1116: 0 | AC1116: 0 | AD1116: 0 | AE1116: 0 | AF1116: 0 | AG1116: 0 | AH1116: 0 | AI1116: 0 | AJ1116: 0 | AK1116: 0 | AL1116: 0 | AM1116: 0 | AN1116: 0 | AO1116: 0 | AP1116: 0
E1126: =E5/100 -> 0.0003 | F1126: =F5/100 -> 0.013 | G1126: =G5/100 -> 0.0181 | H1126: =H5/100 -> 0.0236 | I1126: =I5/100 -> 0.028 | J1126: =J5/100 -> 0.0357 | K1126: =K5/100 -> 0.0403 | L1126: =L5/100 -> 0.0449 | ... AP1126: =AP5/100 -> 1
E1127: =E1126 -> 0.0003 | F1127: =F1126-E1126 -> 0.0127 | G1127: =G1126-F1126 -> 0.0051 | H1127: =H1126-G1126 -> 0.0055 | I1127: =I1126-H1126 -> 0.0044 | J1127: =J1126-I1126 -> 0.0077 | K1127: =K1126-J1126 -> 0.0046 | L1127: =L1126-K1126 -> 0.0046 | M1127: =M1126-L1126 -> 0.0059 | ... AP1127: =AP1126-AO1126 -> 0
E1132: 0.0003 | F1132: 0.0127 | G1132: 0.0051 | H1132: 0.0055 | I1132: 0.0044 | J1132: 0.0077 | K1132: 0.0046 | L1132: 0.0046 | M1132: 0.0059 | N1132: 0.0072 | O1132: 0.0087 | P1132: 0.0075 | Q1132: 0.0323 | R1132: 0.0194 | S1132: 0.0669 | T1132: 0.0471 | U1132: 0.0184 | V1132: 0.0185 | W1132: 0.0714 | X1132: 0.0406 | Y1132: 0.0619 | Z1132: 0.0703 | AA1132: 0.0539 | AB1132: 0.0346 | AC1132: 0.0986 | AD1132: 0.0607 | AE1132: 0.0218 | AF1132: 0.0386 | AG1132: 0.061 | AH1132: 0.0357 | AI1132: 0.0332 | AJ1132: 0.0267 | AK1132: 0 | AL1132: 0.0003 | AM1132: 0.0058 | AN1132: 0.0055 | AO1132: 0.0026 | AP1132: 0

Sheet FASE_A
E3: CURVA S | % BASELINE
E5: COSTÃO DO SANTINHO - SUÍTES DO MAR - FASE A
B8: FASE | C8: FASE 1 - A +A1
B9: ÁREA | C9: 11933.11
B10: PRAZO | C10: 36
B11: CUSTO | C11: =C9*[1]Gerenciamento_Exec!$D$20 -> 56933353
B13: Ano | C13: Mês/Ano | D13: % AVANÇO | E13: % AVANÇO Acumulado | F13: Valor Planejado | G13: Valor Planejado Acumulado
C14: 45597 | D14: 0.0034 | E14: =D14 -> 0.0034 | F14: =D14*$C$11 -> 193573.4 | G14: =F14 -> 193573.4
C15: 45627 | D15: 0.003 | E15: =D15+E14 -> 0.0064 | F15: =D15*$C$11 -> 170800.06 | G15: =F15+G14 -> 364373.46
C16: 45658 | D16: 0.0017 | E16: =D16+E15 -> 0.0081 | F16: =D16*$C$11 -> 96786.7 | G16: =F16+G15 -> 461160.16
C17: 45689 | D17: 0.0026 | E17: =D17+E16 -> 0.0107 | F17: =D17*$C$11 -> 148026.72 | G17: =F17+G16 -> 609186.88
C18: 45717 | D18: 0.0034 | E18: =D18+E17 -> 0.0141 | F18: =D18*$C$11 -> 193573.4 | G18: =F18+G17 -> 802760.28
C19: 45748 | D19: 0.0026 | E19: =D19+E18 -> 0.0167 | F19: =D19*$C$11 -> 148026.72 | G19: =F19+G18 -> 950787
C20: 45778 | D20: 0.0032 | E20: =D20+E19 -> 0.0199 | F20: =D20*$C$11 -> 182186.73 | G20: =F20+G19 -> 1132973.7
C21: 45809 | D21: 0.0057 | E21: =D21+E20 -> 0.0256 | F21: =D21*$C$11 -> 324520.11 | G21: =F21+G20 -> 1457493.8
C22: 45839 | D22: 0.0062 | E22: =D22+E21 -> 0.0318 | F22: =D22*$C$11 -> 352986.79 | G22: =F22+G21 -> 1810480.6
C23: 45870 | D23: 0.0108 | E23: =D23+E22 -> 0.0426 | F23: =D23*$C$11 -> 614880.21 | G23: =F23+G22 -> 2425360.8
C24: 45901 | D24: 0.0062 | E24: =D24+E23 -> 0.0488 | F24: =D24*$C$11 -> 352986.79 | G24: =F24+G23 -> 2778347.6
C25: 45931 | D25: 0.0085 | E25: =D25+E24 -> 0.0573 | F25: =D25*$C$11 -> 483933.5 | G25: =F25+G24 -> 3262281.1
C26: 45962 | D26: 0.011 | E26: =D26+E25 -> 0.0683 | F26: =D26*$C$11 -> 626266.88 | G26: =F26+G25 -> 3888548
... C41: 46419 | D41: 0.0522 | E41: =D41+E40 -> 0.6174 | F41: =D41*$C$11 -> 2971921 | G41: =F41+G40 -> 35150652
B42: 2024 | C42: 46447 | D42: 0.0486 | E42: =D42+E41 -> 0.666 | F42: =D42*$C$11 -> 2766961 | G42: =F42+G41 -> 37917613
C43: 46478 | D43: 0.0535 | E43: =D43+E42 -> 0.7195 | F43: =D43*$C$11 -> 3045934.4 | G43: =F43+G42 -> 40963548
C44: 46508 | D44: 0.0489 | E44: =D44+E43 -> 0.7684 | F44: =D44*$C$11 -> 2784041 | G44: =F44+G43 -> 43747589
C45: 46539 | D45: 0.0543 | E45: =D45+E44 -> 0.8227 | F45: =D45*$C$11 -> 3091481.1 | G45: =F45+G44 -> 46839070
C46: 46569 | D46: 0.0519 | E46: =D46+E45 -> 0.8746 | F46: =D46*$C$11 -> 2954841 | G46: =F46+G45 -> 49793911
C47: 46600 | D47: 0.0565 | E47: =D47+E46 -> 0.9311 | F47: =D47*$C$11 -> 3216734.5 | G47: =F47+G46 -> 53010645
C48: 46631 | D48: 0.0506 | E48: =D48+E47 -> 0.9817 | F48: =D48*$C$11 -> 2880827.7 | G48: =F48+G47 -> 55891473
C49: 46661 | D49: 0.0183 | E49: =D49+E48 -> 1 | F49: =D49*$C$11 -> 1041880.4 | G49: =F49+G48 -> 56933353
C51: =C14 -> 45597
C52: =C49 -> 46661

Sheet FASE_B
E3: CURVA S | % BASELINE
E5: COSTÃO DO SANTINHO - SUÍTES DO MAR - FASE A
B8: FASE | C8: FASE 2 - B + ÁREA SOCIAL
B9: ÁREA | C9: 12030.97
B10: PRAZO | C10: 28
B11: CUSTO | C11: =C9*[1]Gerenciamento_Exec!$D$20 -> 57400247
B13: Ano | C13: Mês/Ano | D13: % AVANÇO | E13: % AVANÇO Acumulado | F13: Valor Planejado | G13: Valor Planejado Acumulado
C14: 45992 | D14: 0.0037293571 | E14: =D14 -> 0.0037293571 | F14: =D14*$C$11 -> 214066.02 | G14: =F14 -> 214066.02
C15: 46023 | D15: 0.0043076429 | E15: =D15+E14 -> 0.008037 | F15: =D15*$C$11 -> 247259.76 | G15: =F15+G14 -> 461325.79
C16: 46054 | D16: 0.0057677143 | E16: =D16+E15 -> 0.013804714 | F16: =D16*$C$11 -> 331068.23 | G16: =F16+G15 -> 792394.01
C17: 46082 | D17: 0.0085482857 | E17: =D17+E16 -> 0.022353 | F17: =D17*$C$11 -> 490673.71 | G17: =F17+G16 -> 1283067.7
C18: 46113 | D18: 0.015177 | E18: =D18+E17 -> 0.03753 | F18: =D18*$C$11 -> 871163.55 | G18: =F18+G17 -> 2154231.3
C19: 46143 | D19: 0.017966 | E19: =D19+E18 -> 0.055496 | F19: =D19*$C$11 -> 1031252.8 | G19: =F19+G18 -> 3185484.1
C20: 46174 | D20: 0.01129 | E20: =D20+E19 -> 0.066786 | F20: =D20*$C$11 -> 648048.79 | G20: =F20+G19 -> 3833532.9
C21: 46204 | D21: 0.025354286 | E21: =D21+E20 -> 0.092140286 | F21: =D21*$C$11 -> 1455342.3 | G21: =F21+G20 -> 5288875.2
C22: 46235 | D22: 0.042069286 | E22: =D22+E21 -> 0.13420957 | F22: =D22*$C$11 -> 2414787.4 | G22: =F22+G21 -> 7703662.6
C23: 46266 | D23: 0.043560143 | E23: =D23+E22 -> 0.17776971 | F23: =D23*$C$11 -> 2500363 | G23: =F23+G22 -> 10204026
C24: 46296 | D24: 0.048741214 | E24: =D24+E23 -> 0.22651093 | F24: =D24*$C$11 -> 2797757.7 | G24: =F24+G23 -> 13001783
C25: 46327 | D25: 0.045529071 | E25: =D25+E24 -> 0.27204 | F25: =D25*$C$11 -> 2613380 | G25: =F25+G24 -> 15615163
C26: 46357 | D26: 0.038193571 | E26: =D26+E25 -> 0.31023357 | F26: =D26*$C$11 -> 2192320.4 | G26: =F26+G25 -> 17807484
... C41: 46813 | D41: 0.02682 | E41: =D41+E40 -> 1 | F41: =D41*$C$11 -> 1539474.6 | G41: =F41+G40 -> 57400247
C43: =C14 -> 45992
C44: =C41 -> 46813

Sheet FASE_C
E3: CURVA S | % BASELINE
E5: COSTÃO DO SANTINHO - SUÍTES DO MAR - FASE A
B8: FASE | C8: FASE 3 - C + D
B9: ÁREA | C9: 14465.41
B10: PRAZO | C10: 28
B11: CUSTO | C11: =C9*[1]Gerenciamento_Exec!$D$20 -> 69015059
B13: Ano | C13: Mês/Ano | D13: % AVANÇO | E13: % AVANÇO Acumulado | F13: Valor Planejado | G13: Valor Planejado Acumulado
C14: 46661 | D14: 0.0037293571 | E14: =D14 -> 0.0037293571 | F14: =D14*$C$11 -> 257381.8 | G14: =F14 -> 257381.8
C15: 46692 | D15: 0.0043076429 | E15: =D15+E14 -> 0.008037 | F15: =D15*$C$11 -> 297292.23 | G15: =F15+G14 -> 554674.03
C16: 46722 | D16: 0.0057677143 | E16: =D16+E15 -> 0.013804714 | F16: =D16*$C$11 -> 398059.14 | G16: =F16+G15 -> 952733.18
C17: 46753 | D17: 0.0085482857 | E17: =D17+E16 -> 0.022353 | F17: =D17*$C$11 -> 589960.45 | G17: =F17+G16 -> 1542693.6
C18: 46784 | D18: 0.015177 | E18: =D18+E17 -> 0.03753 | F18: =D18*$C$11 -> 1047441.6 | G18: =F18+G17 -> 2590135.2
C19: 46813 | D19: 0.017966 | E19: =D19+E18 -> 0.055496 | F19: =D19*$C$11 -> 1239924.6 | G19: =F19+G18 -> 3830059.7
C20: 46844 | D20: 0.01129 | E20: =D20+E19 -> 0.066786 | F20: =D20*$C$11 -> 779180.02 | G20: =F20+G19 -> 4609239.8
C21: 46874 | D21: 0.025354286 | E21: =D21+E20 -> 0.092140286 | F21: =D21*$C$11 -> 1749827.5 | G21: =F21+G20 -> 6359067.3
C22: 46905 | D22: 0.042069286 | E22: =D22+E21 -> 0.13420957 | F22: =D22*$C$11 -> 2903414.3 | G22: =F22+G21 -> 9262481.5
C23: 46935 | D23: 0.043560143 | E23: =D23+E22 -> 0.17776971 | F23: =D23*$C$11 -> 3006305.8 | G23: =F23+G22 -> 12268787
C24: 46966 | D24: 0.048741214 | E24: =D24+E23 -> 0.22651093 | F24: =D24*$C$11 -> 3363877.8 | G24: =F24+G23 -> 15632665
C25: 46997 | D25: 0.045529071 | E25: =D25+E24 -> 0.27204 | F25: =D25*$C$11 -> 3142191.6 | G25: =F25+G24 -> 18774857
C26: 47027 | D26: 0.038193571 | E26: =D26+E25 -> 0.31023357 | F26: =D26*$C$11 -> 2635931.6 | G26: =F26+G25 -> 21410788
... C41: 47484 | D41: 0.02682 | E41: =D41+E40 -> 1 | F41: =D41*$C$11 -> 1850983.9 | G41: =F41+G40 -> 69015059
C43: =C14 -> 46661
C44: =C41 -> 47484

Sheet TOTAL_OBRA
E3: CURVA S | % BASELINE
E5: COSTÃO DO SANTINHO - SUÍTES DO MAR
B8: FASE | C8: TOTAL
B9: ÁREA | C9: =[1]Gerenciamento_Exec!$G$12 -> 38429.49
B10: PRAZO | C10: 63
B11: CUSTO | C11: =C9*[1]Gerenciamento_Exec!$D$20 -> 1.8334866e+08
B13: Ano | C13: Mês/Ano | D13: % AVANÇO | E13: % AVANÇO Acumulado | F13: Valor Planejado | G13: Valor Planejado Acumulado
C14: 45597 | D14: =F14/$C$11 -> 0.0010557667 | E14: =D14 -> 0.0010557667 | F14: =SUMIF(FASE_A!$C$14:$C$49,TOTAL_OBRA!C14,FASE_A!$F$14:$F$49)+SUMIF(FASE_B!$C$14:$C$41,TOTAL_OBRA!C14,FASE_B!$F$14:$F$41)+SUMIF(FASE_C!$C$14:$C$41,TOTAL_OBRA!C14,FASE_C!$F$14:$F$41) -> 193573.4 | G14: =F14 -> 193573.4
C15: 45627 | D15: =F15/$C$11 -> 0.00093155881 | E15: =D15+E14 -> 0.0019873255 | F15: =SUMIF(FASE_A!$C$14:$C$49,TOTAL_OBRA!C15,FASE_A!$F$14:$F$49)+SUMIF(FASE_B!$C$14:$C$41,TOTAL_OBRA!C15,FASE_B!$F$14:$F$41)+SUMIF(FASE_C!$C$14:$C$41,TOTAL_OBRA!C15,FASE_C!$F$14:$F$41) -> 170800.06 | G15: =F15+G14 -> 364373.46
C16: 45658 | D16: =F16/$C$11 -> 0.00052788333 | E16: =D16+E15 -> 0.0025152088 | F16: =SUMIF(FASE_A!$C$14:$C$49,TOTAL_OBRA!C16,FASE_A!$F$14:$F$49)+SUMIF(FASE_B!$C$14:$C$41,TOTAL_OBRA!C16,FASE_B!$F$14:$F$41)+SUMIF(FASE_C!$C$14:$C$41,TOTAL_OBRA!C16,FASE_C!$F$14:$F$41) -> 96786.7 | G16: =F16+G15 -> 461160.16
C17: 45689 | D17: =F17/$C$11 -> 0.00080735097 | E17: =D17+E16 -> 0.0033225598 | F17: =SUMIF(FASE_A!$C$14:$C$49,TOTAL_OBRA!C17,FASE_A!$F$14:$F$49)+SUMIF(FASE_B!$C$14:$C$41,TOTAL_OBRA!C17,FASE_B!$F$14:$F$41)+SUMIF(FASE_C!$C$14:$C$41,TOTAL_OBRA!C17,FASE_C!$F$14:$F$41) -> 148026.72 | G17: =F17+G16 -> 609186.88
C18: 45717 | D18: =F18/$C$11 -> 0.0010557667 | E18: =D18+E17 -> 0.0043783264 | F18: =SUMIF(FASE_A!$C$14:$C$49,TOTAL_OBRA!C18,FASE_A!$F$14:$F$49)+SUMIF(FASE_B!$C$14:$C$41,TOTAL_OBRA!C18,FASE_B!$F$14:$F$41)+SUMIF(FASE_C!$C$14:$C$41,TOTAL_OBRA!C18,FASE_C!$F$14:$F$41) -> 193573.4 | G18: =F18+G17 -> 802760.28
C19: 45748 | D19: =F19/$C$11 -> 0.00080735097 | E19: =D19+E18 -> 0.0051856774 | F19: =SUMIF(FASE_A!$C$14:$C$49,TOTAL_OBRA!C19,FASE_A!$F$14:$F$49)+SUMIF(FASE_B!$C$14:$C$41,TOTAL_OBRA!C19,FASE_B!$F$14:$F$41)+SUMIF(FASE_C!$C$14:$C$41,TOTAL_OBRA!C19,FASE_C!$F$14:$F$41) -> 148026.72 | G19: =F19+G18 -> 950787
C20: 45778 | D20: =F20/$C$11 -> 0.00099366273 | E20: =D20+E19 -> 0.0061793401 | F20: =SUMIF(FASE_A!$C$14:$C$49,TOTAL_OBRA!C20,FASE_A!$F$14:$F$49)+SUMIF(FASE_B!$C$14:$C$41,TOTAL_OBRA!C20,FASE_B!$F$14:$F$41)+SUMIF(FASE_C!$C$14:$C$41,TOTAL_OBRA!C20,FASE_C!$F$14:$F$41) -> 182186.73 | G20: =F20+G19 -> 1132973.7
C21: 45809 | D21: =F21/$C$11 -> 0.0017699617 | E21: =D21+E20 -> 0.0079493019 | F21: =SUMIF(FASE_A!$C$14:$C$49,TOTAL_OBRA!C21,FASE_A!$F$14:$F$49)+SUMIF(FASE_B!$C$14:$C$41,TOTAL_OBRA!C21,FASE_B!$F$14:$F$41)+SUMIF(FASE_C!$C$14:$C$41,TOTAL_OBRA!C21,FASE_C!$F$14:$F$41) -> 324520.11 | G21: =F21+G20 -> 1457493.8
C22: 45839 | D22: =F22/$C$11 -> 0.0019252215 | E22: =D22+E21 -> 0.0098745234 | F22: =SUMIF(FASE_A!$C$14:$C$49,TOTAL_OBRA!C22,FASE_A!$F$14:$F$49)+SUMIF(FASE_B!$C$14:$C$41,TOTAL_OBRA!C22,FASE_B!$F$14:$F$41)+SUMIF(FASE_C!$C$14:$C$41,TOTAL_OBRA!C22,FASE_C!$F$14:$F$41) -> 352986.79 | G22: =F22+G21 -> 1810480.6
C23: 45870 | D23: =F23/$C$11 -> 0.0033536117 | E23: =D23+E22 -> 0.013228135 | F23: =SUMIF(FASE_A!$C$14:$C$49,TOTAL_OBRA!C23,FASE_A!$F$14:$F$49)+SUMIF(FASE_B!$C$14:$C$41,TOTAL_OBRA!C23,FASE_B!$F$14:$F$41)+SUMIF(FASE_C!$C$14:$C$41,TOTAL_OBRA!C23,FASE_C!$F$14:$F$41) -> 614880.21 | G23: =F23+G22 -> 2425360.8
C24: 45901 | D24: =F24/$C$11 -> 0.0019252215 | E24: =D24+E23 -> 0.015153357 | F24: =SUMIF(FASE_A!$C$14:$C$49,TOTAL_OBRA!C24,FASE_A!$F$14:$F$49)+SUMIF(FASE_B!$C$14:$C$41,TOTAL_OBRA!C24,FASE_B!$F$14:$F$41)+SUMIF(FASE_C!$C$14:$C$41,TOTAL_OBRA!C24,FASE_C!$F$14:$F$41) -> 352986.79 | G24: =F24+G23 -> 2778347.6
C25: 45931 | D25: =F25/$C$11 -> 0.0026394166 | E25: =D25+E24 -> 0.017792773 | F25: =SUMIF(FASE_A!$C$14:$C$49,TOTAL_OBRA!C25,FASE_A!$F$14:$F$49)+SUMIF(FASE_B!$C$14:$C$41,TOTAL_OBRA!C25,FASE_B!$F$14:$F$41)+SUMIF(FASE_C!$C$14:$C$41,TOTAL_OBRA!C25,FASE_C!$F$14:$F$41) -> 483933.5 | G25: =F25+G24 -> 3262281.1
C26: 45962 | D26: =F26/$C$11 -> 0.0034157156 | E26: =D26+E25 -> 0.021208489 | F26: =SUMIF(FASE_A!$C$14:$C$49,TOTAL_OBRA!C26,FASE_A!$F$14:$F$49)+SUMIF(FASE_B!$C$14:$C$41,TOTAL_OBRA!C26,FASE_B!$F$14:$F$41)+SUMIF(FASE_C!$C$14:$C$41,TOTAL_OBRA!C26,FASE_C!$F$14:$F$41) -> 626266.88 | G26: =F26+G25 -> 3888548
... C76: 47484 | D76: =F76/$C$11 -> 0.010095432 | E76: =D76+E75 -> 1 | F76: =SUMIF(FASE_A!$C$14:$C$49,TOTAL_OBRA!C76,FASE_A!$F$14:$F$49)+SUMIF(FASE_B!$C$14:$C$41,TOTAL_OBRA!C76,FASE_B!$F$14:$F$41)+SUMIF(FASE_C!$C$14:$C$41,TOTAL_OBRA!C76,FASE_C!$F$14:$F$41) -> 1850983.9 | G76: =F76+G75 -> 1.8334866e+08

Sheet FASE A,B,C
D8: FASE A | F8: FASE B | H8: FASE C
B9: Ano | C9: Mês/Ano | D9: % AVANÇO | E9: Valor Planejado | F9: % AVANÇO | G9: Valor Planejado | H9: % AVANÇO | I9: Valor Planejado | J9: Valor Planejado TOTAL
C10: 45597 | D10: 0.0034 | E10: 193573.4 | J10: =E10+G10+I10 -> 193573.4
C11: 45627 | D11: 0.003 | E11: 170800.06 | J11: =E11+G11+I11 -> 170800.06
C12: 45658 | D12: 0.0017 | E12: 96786.7 | J12: =E12+G12+I12 -> 96786.7
C13: 45689 | D13: 0.0026 | E13: 148026.72 | J13: =E13+G13+I13 -> 148026.72
C14: 45717 | D14: 0.0034 | E14: 193573.4 | J14: =E14+G14+I14 -> 193573.4
C15: 45748 | D15: 0.0026 | E15: 148026.72 | J15: =E15+G15+I15 -> 148026.72
C16: 45778 | D16: 0.0032 | E16: 182186.73 | J16: =E16+G16+I16 -> 182186.73
C17: 45809 | D17: 0.0057 | E17: 324520.11 | J17: =E17+G17+I17 -> 324520.11
C18: 45839 | D18: 0.0062 | E18: 352986.79 | J18: =E18+G18+I18 -> 352986.79
C19: 45870 | D19: 0.0108 | E19: 614880.21 | J19: =E19+G19+I19 -> 614880.21
C20: 45901 | D20: 0.0062 | E20: 352986.79 | J20: =E20+G20+I20 -> 352986.79
C21: 45931 | D21: 0.0085 | E21: 483933.5 | J21: =E21+G21+I21 -> 483933.5
C22: 45962 | D22: 0.011 | E22: 626266.88 | J22: =E22+G22+I22 -> 626266.88
C23: 45992 | D23: 0.0079 | E23: 449773.49 | F23: 0.0037293571 | G23: 214066.02 | J23: =E23+G23+I23 -> 663839.51
C24: 46023 | D24: 0.0131 | E24: 745826.93 | F24: 0.0043076429 | G24: 247259.76 | J24: =E24+G24+I24 -> 993086.69
C25: 46054 | D25: 0.0112 | E25: 637653.56 | F25: 0.0057677143 | G25: 331068.23 | J25: =E25+G25+I25 -> 968721.78
C26: 46082 | D26: 0.0101 | E26: 575026.87 | F26: 0.0085482857 | G26: 490673.71 | J26: =E26+G26+I26 -> 1065700.6
C27: 46113 | D27: 0.0368 | E27: 2095147.4 | F27: 0.015177 | G27: 871163.55 | J27: =E27+G27+I27 -> 2966310.9
C28: 46143 | D28: 0.0425 | E28: 2419667.5 | F28: 0.017966 | G28: 1031252.8 | J28: =E28+G28+I28 -> 3450920.3
C29: 46174 | D29: 0.0378 | E29: 2152080.7 | F29: 0.01129 | G29: 648048.79 | J29: =E29+G29+I29 -> 2800129.5
C30: 46204 | D30: 0.0614 | E30: 3495707.9 | F30: 0.025354286 | G30: 1455342.3 | J30: =E30+G30+I30 -> 4951050.1
C31: 46235 | D31: 0.0565 | E31: 3216734.5 | F31: 0.042069286 | G31: 2414787.4 | J31: =E31+G31+I31 -> 5631521.8
C32: 46266 | D32: 0.0395 | E32: 2248867.4 | F32: 0.043560143 | G32: 2500363 | J32: =E32+G32+I32 -> 4749230.4
C33: 46296 | D33: 0.0555 | E33: 3159801.1 | F33: 0.048741214 | G33: 2797757.7 | J33: =E33+G33+I33 -> 5957558.8
C34: 46327 | D34: 0.0424 | E34: 2413974.2 | F34: 0.045529071 | G34: 2613380 | J34: =E34+G34+I34 -> 5027354.1
... C44: 46631 | D44: 0.0506 | E44: 2880827.7 | F44: 0.059357357 | G44: 3407127 | J44: =E44+G44+I44 -> 6287954.6
C45: 46661 | D45: 0.0183 | E45: 1041880.4 | F45: 0.045087857 | G45: 2588054.1 | H45: 0.0037293571 | I45: 257381.8 | J45: =E45+G45+I45 -> 3887316.3
C46: 46692 | F46: 0.030854286 | G46: 1771043.6 | H46: 0.0043076429 | I46: 297292.23 | J46: =E46+G46+I46 -> 2068335.9
C47: 46722 | F47: 0.027289214 | G47: 1566407.6 | H47: 0.0057677143 | I47: 398059.14 | J47: =E47+G47+I47 -> 1964466.8
C48: 46753 | F48: 0.016252071 | G48: 932872.92 | H48: 0.0085482857 | I48: 589960.45 | J48: =E48+G48+I48 -> 1522833.4
C49: 46784 | F49: 0.019102714 | G49: 1096500.5 | H49: 0.015177 | I49: 1047441.6 | J49: =E49+G49+I49 -> 2143942.1
C50: 46813 | F50: 0.02682 | G50: 1539474.6 | H50: 0.017966 | I50: 1239924.6 | J50: =E50+G50+I50 -> 2779399.2
C51: 46844 | H51: 0.01129 | I51: 779180.02 | J51: =E51+G51+I51 -> 779180.02
C52: 46874 | H52: 0.025354286 | I52: 1749827.5 | J52: =E52+G52+I52 -> 1749827.5
C53: 46905 | H53: 0.042069286 | I53: 2903414.3 | J53: =E53+G53+I53 -> 2903414.3
C54: 46935 | H54: 0.043560143 | I54: 3006305.8 | J54: =E54+G54+I54 -> 3006305.8
C55: 46966 | H55: 0.048741214 | I55: 3363877.8 | J55: =E55+G55+I55 -> 3363877.8
C56: 46997 | H56: 0.045529071 | I56: 3142191.6 | J56: =E56+G56+I56 -> 3142191.6
...
