Workbook

Sheet Dados Gerais
A2: ORÇAMENTO PARAMÉTRICO GERENCIAMENTO EXECUTIVO
A7: Documento
A8: Cliente
A9: Obra
A10: Data | B10: 44874 | E10: Revisão | F10: R00 | G10: Status | H10: Em andamento | I10: Responsável | J10: Kelen
A12: Descrição | D12: Identificador | E12: Informação
A13: Área do terreno | D13: AT | E13: 26752.72 | H13: m²
A14: Testada do terreno | D14: TT | H14: m
A15: Área total construída | D15: AC | E15: 38429.49 | H15: m²
A16: N° total de pavimentos | D16: NP | E16: 7 | H16: un
A17: N° de pavimentos tipo | D17: NPT | H17: un
A18: N° de pavimentos tipo diferenciado | D18: NPD | E18: 5 | H18: un
A19: N° de pavimentos duplex | D19: ND | E19: 0 | H19: un
A20: Área de projeção da torre | D20: APT | E20: 5889.2 | H20: m²
A21: Perímetro de projeção da torre | D21: PPT | E21: 799 | H21: m
A22: Área Lazer | D22: AL | E22: 9154.8 | H22: m²
A23: Locação da obra | D23: LC | E23: =E21 -> 799 | H23: m
A24: Área do embasamento | D24: AE | E24: =6403.42+9154.8+3882.96 -> 19441.18 | H24: m²
A25: Área de subsolos | D25: AS | E25: 6403.42 | H25: m²
A26: N° de subsolos | D26: NS | E26: 1 | H26: un
A27: Área de projeção do embasamento | D27: APE | E27: =E20 -> 5889.2 | H27: m²
A28: Perímetro de projeção embasamento | D28: PPE | E28: =E21 -> 799 | H28: m
A29: N° de pavimentos de embasamento | D29: NPE | E29: 3 | H29: un

Sheet Resumo
A2: ORÇAMENTO PARAMÉTRICO GERENCIAMENTO EXECUTIVO
A7: Documento | B7: MTH_INC-RES Orçamento Paramétrico
A8: Cliente | B8: PASS-E
A9: Obra | B9: Reserva | E9: UC | F9: 01 | G9: Status | H9: Concluído
A10: Data | B10: 44294 | E10: Revisão | F10: R00 | G10: Resp. | H10: Kelen
A12: MOVIMENTAÇÃO DE TERRA
A14: Descrição | D14: Valor total
A15: =+'Movimentação de Terra'!A19 -> REBAIXAMENTO DE LENÇOL | D15: =+'Movimentação de Terra'!I23 -> 288000
A16: =+'Movimentação de Terra'!A34 -> ESCAVAÇÃO E REATERRO DE VALAS | D16: =+'Movimentação de Terra'!I40 -> 431466.41
A17: =+'Movimentação de Terra'!A43 -> REGULARIZAÇÃO E APILOAmENTO DE FUNDO DE VALAS | D17: =+'Movimentação de Terra'!I47 -> 84805
A18: TOTAL | D18: =SUM(D15:H17) -> 804271.41
A22: INFRAESTRUTURA
A24: Descrição | D24: Valor total
A25: =+Infraestrutura!A12 -> FUNDAÇÃO PROFUNDA | D25: =+Infraestrutura!I24 -> 5471870
A26: =+Infraestrutura!A27 -> FUNDAÇÃO RASA | D26: =+Infraestrutura!I34 -> 3875093.6
A27: CONTENÇÃO | D27: =Infraestrutura!#REF! -> #REF!
A28: TOTAL | D28: =SUM(D25:H27) -> #REF!
A31: SUPRAESTRUTURA
A33: Descrição | D33: Valor total
A34: =+Supraestrutura!A12 -> SUPRAESTRUTURA | D34: =+Supraestrutura!I21 -> 19474234
A35: TOTAL | D35: =SUM(D34:H34) -> 19474234
A38: ALVENARIA
A40: Descrição | D40: Valor total
A41: =+Alvenaria!A12 -> ALVENARIA | D41: =+Alvenaria!I24 -> 3251138.7
A42: TOTAL | D42: =SUM(D41) -> 3251138.7
A45: INSTALAÇÕES
A47: Descrição | D47: Valor total
A48: =+Instalações!A12 -> INSTALAÇÕES ELÉTRICAS | D48: =+Instalações!I22 -> 4573109.3
A49: =+Instalações!A24 -> INSTALAÇÕES HIDRÁULICAS | D49: =+Instalações!I34 -> 5209551.7
A50: =+Instalações!A37 -> INSTALAÇÕES PREVENTIVAS E GLP | D50: =+Instalações!I44 -> 1537179.6
A51: =+Instalações!#REF! -> #REF! | D51: =+Instalações!#REF! -> #REF!
A52: TOTAL | D52: =SUM(D48:H51) -> #REF!
A55: IMPERMEABILIZAÇÃO
A57: Descrição | D57: Valor total
A58: =+Impermeabilização!A12 -> IMPERMEABILIZAÇÃO | D58: =+Impermeabilização!I24 -> 2473644
A59: TOTAL | D59: =SUM(D58) -> 2473644
A62: REVESTIMENTOS INTERNOS EM PISO E PAREDE
A64: Descrição | D64: Valor total
A65: =+'Rev. Internos Piso e Parede'!A12 -> REVESTIMENTOS INTERNOS EM PISO E PAREDE | D65: =+'Rev. Internos Piso e Parede'!I21 -> 2943695.3
A66: TOTAL | D66: =SUM(D65) -> 2943695.3
...

Sheet Movimentação de Terra
A2: ORÇAMENTO PARAMÉTRICO MOVIMENTAÇÃO DE TERRA
A7: Documento | B7: MTH_INC-RES Orçamento Paramétrico
A8: Cliente
A9: Obra | B9: Reserva | I9: Status | J9: Concluído
A10: Data | B10: 44294 | G10: Revisão | H10: R00 | I10: Resp. | J10: Kelen
A12: ESCAVAÇÃO
A14: Descrição | D14: Quantidade | F14: Parâmetro | H14: Referência | I14: Valor total
A15: Escavação | D15: =+'Dados Gerais'!E25*3.06 -> 19594.465 | E15: m³ | F15: 28.5 | G15: R$ / m³ | H15: Pedro Chaves | I15: =+D15*F15 -> 558442.26
A16: TOTAL | I16: =SUM(I15:J15) -> 558442.26
A19: REBAIXAMENTO DE LENÇOL
A21: Descrição | D21: Quantidade | F21: Parâmetro | H21: Referência | I21: Valor total
A22: Rebaixamento de Lençol | D22: 5 | E22: - | F22: =9600*6 -> 57600 | G22: R$ / mês | H22: Média | I22: =F22*D22 -> 288000 | L22: *6 equipamentos de rebaixamento de lençol
A23: TOTAL | I23: =SUM(I22:J22) -> 288000
A26: ESCAVAÇÃO VERTICAL
A28: Descrição | D28: Quantidade | F28: Parâmetro | H28: Referência | I28: Valor total
A29: Escavação vertical | D29: =[1]MOV._TERRA!$E$15 -> 39229.65 | E29: m³ | F29: 45 | G29: R$ / m³ | H29: Média | I29: =F29*D29 -> 1765334.2
A30: Bota fora | D30: =D29 -> 39229.65 | E30: m³ | F30: 30 | G30: R$ / m³ | H30: Média | I30: =F30*D30 -> 1176889.5
A31: TOTAL | I31: =SUM(I29:J30) -> 2942223.7
A34: ESCAVAÇÃO E REATERRO DE VALAS
A36: Descrição | D36: Quantidade | F36: Parâmetro | H36: Referência | I36: Valor total
A37: Escavação mecanizada para blocos e baldrames | D37: ='Dados Gerais'!E27*F37 -> 3827.98 | E37: - | F37: 0.65 | G37: m³ / APE | H37: Média | I37: =+ROUNDUP((D37*35),0) -> 133980
A38: Reaterro para blocos e baldrames | D38: =F38*D37 -> 765.596 | E38: - | F38: 0.2 | G38: m³ / APE | H38: Média | I38: =+ROUNDUP((D38*25),0) -> 19140
A39: Movimentação de terra de bota - fora | D39: =+Infraestrutura!D23*F39+D37-D38 -> 9278.2136 | E39: m³ | F39: 1 | G39: m³ / m³ | H39: Média | I39: =+D39*30 -> 278346.41
A40: TOTAL | I40: =SUM(I37:J39) -> 431466.41
A43: REGULARIZAÇÃO E APILOAmENTO DE FUNDO DE VALAS
A45: Descrição | D45: Quantidade | F45: Parâmetro | H45: Referência | I45: Valor total
A46: Lastro de concreto magro e= 10cm - Blocos | D46: =F46*'Dados Gerais'!E27 -> 4711.36 | E46: m² | F46: 0.8 | G46: m² / AT | H46: Média | I46: =ROUNDUP((D46*18),0) -> 84805
A47: TOTAL | I47: =SUM(I46:J46) -> 84805
I50: =I47+I40+I23+I31 -> 3746495.2 | J50: =I50/'Dados Gerais'!E15 -> 97.490109

Sheet Conteções
A2: ORÇAMENTO PARAMÉTRICO CONTENÇÕES
A7: Documento | B7: MTH_MEN BRM Dados Gerais
A8: Cliente | B8: MENDES
A9: Obra | B9: Brava Mundo | G9: UC | H9: 02 | I9: Status | J9: Concluído
A10: Data | B10: 44160 | G10: Revisão | H10: R01 | I10: Resp. | J10: Kelen
A12: MURETA GUIA
A14: Descrição | D14: Quantidade | F14: Parâmetro | H14: Referência | I14: Valor total
A15: Armação | D15: =+F15*D16 -> 10239.02 | E15: kg | F15: 110 | G15: kg / m³ | H15: - | I15: =+D15*8 -> 81912.16
A16: Concreto | D16: =(B37*1*0.2) -> 93.082 | E16: m³ | F16: 490 | G16: R$ / m³ | H16: - | I16: =F16*D16 -> 45610.18 | L16: *fck 25MPa
A17: Forma | D17: =B37*1*2 -> 930.82 | E17: m² | F17: 160 | G17: R$ / m² | H17: - | I17: =+D17*F17 -> 148931.2
A18: TOTAL | I18: =SUM(I15:J17) -> 276453.54
A20: PAREDE DIAFRAGMA
A22: Descrição | D22: Quantidade | F22: Parâmetro | H22: Referência | I22: Valor total
A23: Armação | D23: =+F23*D24 -> 133960.51 | E23: kg | F23: 200 | G23: kg / m³ | H23: - | I23: =+D23*8 -> 1071684.1
A24: Concreto | D24: =(B32*C32*0.4+B33*C33*0.4+B34*C34*0.4)*1.05 -> 669.80256 | E24: m³ | F24: 0.4 | G24: m³ / m² | H24: - | I24: =+D24*530 -> 354995.36 | L24: *fck 40MPa
A25: Tirantes | D25: =B37 -> 465.41 | E25: m | F25: 350 | G25: R$ / m | H25: - | I25: =F25*D25 -> 162893.5
A26: Mão de obra | D26: =(B32*C32+B33*C33+B34*C34)*2 -> 3189.536 | E26: m² | F26: 600 | G26: R$ / m² | H26: - | I26: =+D26*F26 -> 1913721.6
A27: TOTAL | I27: =SUM(I23:J26) -> 3503294.6
J30: =I27+I18 -> 3779748.1 | L30: =J30/'Dados Gerais'!E15 -> 98.355406
B31: Perímetro de contenção | C31: Altura | D31: Extensão x profundidade
A32: SUBSOLO | B32: =45.4+121.85+25.55+15.4+62.61+6.01 -> 276.82 | C32: 3.5 | D32: =C32*B32 -> 968.87
A33: TÉRREO | B33: =45.2+45.77 -> 90.97 | C33: 3.5 | D33: =C33*B33 -> 318.395
A34: MEZANINO | B34: =6.7+6.3+11.3+6.3+36.92+6.3+10.8+6.3+6.7 -> 97.62 | C34: 3.15 | D34: =C34*B34 -> 307.503
A37: TOTAL | B37: =SUM(B32:B36) -> 465.41 | D37: =SUM(D32:D36) -> 1594.768
A38: EXECUÇÃO DIAFRAGMA
A39: Custo - referência | C39: Extensão x profundidade | D39: Valor por m2
A40: 44743 | B40: 44593
A41: 572680 | B41: =B42/A42*A41 -> 592697.25 | C41: 2696 | D41: =B41/C41 -> 219.84319
A42: 2572.55 | B42: 2662.47
A44: EXECUÇÃO TIRANTES
A45: Custo - referência | C45: Extensão | D45: Valor por m
A46: 44743 | B46: 44593
A47: 589427.37 | B47: =B48/A48*A47 -> 610030.01 | C47: 2940 | D47: =B47/C47 -> 207.4932
A48: 2572.55 | B48: 2662.47

Sheet Infraestrutura
A2: ORÇAMENTO PARAMÉTRICO INFRAESTRUTURA
A7: Documento
A8: Cliente
A9: Obra | I9: Status | J9: Concluído
A10: Data | G10: Revisão | H10: R00 | I10: Resp.
A12: FUNDAÇÃO PROFUNDA
A14: Descrição | D14: Quantidade | F14: Parâmetro | H14: Referência | I14: Valor total
A15: Número de Estacas | D15: =F15*9154.8 -> 915.48 | E15: un | F15: 0.1 | G15: un / m² | H15: Média | I15: 0 | M15: =D15/'Dados Gerais'!E13 -> 0.034220072
A16: Estaca Hélice Continua Diâmetro 50 | D16: =ROUNDUP(($D$15*(F16/100)),0) -> 0 | E16: un | F16: 0 | G16: % | H16: Média | I16: 0
A17: Estaca Hélice Continua Diâmetro 50 | D17: =ROUNDUP((F17*D16),0) -> 0 | E17: m | F17: 22 | G17: m / un | H17: Média | I17: =+ROUNDUP((D17*60),0) -> 0
A18: Estaca Hélice Continua Diâmetro 60 | D18: =ROUNDUP(($D$15*(F18/100)),0) -> 916 | E18: un | F18: 100 | G18: % | H18: Média | I18: 0
A19: Estaca Hélice Continua Diâmetro 60 | D19: =ROUNDUP((F19*D18),0) -> 18320 | E19: m | F19: 20 | G19: m / un | H19: Média | I19: =+ROUNDUP((D19*70),0) -> 1282400
A20: Estaca Hélice Continua Diâmetro 70 | D20: =ROUNDUP(($D$15*(F20/100)),0) -> 0 | E20: un | F20: 0 | G20: % | H20: Média | I20: 0
A21: Estaca Hélice Continua Diâmetro 70 | D21: =ROUNDUP((F21*D20),0) -> 0 | E21: m | F21: 22 | G21: m / un | H21: Média | I21: =+ROUNDUP((D21*80),0) -> 0
A22: Armação | D22: =ROUNDUP((D23*F22),0) -> 111885 | E22: kg | F22: 18 | G22: kg / m³ | H22: Média | I22: =D22*8 -> 895080
A23: Concreto | D23: =(PI()*(0.5^2)/4*D17+PI()*(0.6^2)/4*D19+PI()*(0.7^2)/4*D21)*1.2 -> 6215.8296 | E23: m³ | F23: 530 | G23: R$ / m³ | H23: Média | I23: =+ROUNDUP((D23*F23),0) -> 3294390
A24: TOTAL | I24: =SUM(I15:J23) -> 5471870 | N24: =I24/'Dados Gerais'!E15 -> 142.38727
A27: FUNDAÇÃO RASA
A29: Descrição | D29: Quantidade | F29: Parâmetro | H29: Referência | I29: Valor total
A30: Fabricação, montagem e desmontagem de forma para blocos e baldrames | D30: =F30*'Dados Gerais'!E27 -> 4711.36 | E30: m² | F30: 0.8 | G30: m² / AT | H30: Média | I30: =+D30*62 -> 292104.32
A31: Armação | D31: =D32*F31 -> 244990.72 | E31: kg | F31: 80 | G31: kg / m³ | H31: Média | I31: =+D31*8 -> 1959925.8
A32: Concreto | D32: ='Movimentação de Terra'!D37-'Movimentação de Terra'!D38 -> 3062.384 | E32: m³ | F32: 0.5 | G32: m³ / AT | H32: Média | I32: =+D32*530 -> 1623063.5
A33: Mão de obra | D33: 0 | E33: m² | F33: 220 | G33: R$ / AT | H33: Média | I33: =+D33*F33 -> 0
A34: TOTAL | I34: =SUM(I30:J33) -> 3875093.6
I37: =I34+I24 -> 9346963.6 | J37: =I37/'Dados Gerais'!E15 -> 243.22372
A40: MENDES
B41: m | C41: m³
A42: Perfuração 60 | B42: 1163
A43: Concreto | C43: 328.83
A45: Área | B45: =PI()*0.6^2/4 -> 0.28274334
A46: Unidades | B46: 81
A47: Perfuração unitária | B47: =B42/B46 -> 14.358025
A49: Aço | B49: =1134+5103 -> 6237
A50: kg/m3 | B50: =B49/C43 -> 18.967248
A53: Fundação rasa
A54: Aço | B54: =257+89+1786+2047+679+8998+2778 -> 16634
A55: Concreto | B55: =200.44 -> 200.44
A56: kg/m3 | B56: =B54/B55 -> 82.987428

Sheet Supraestrutura
A2: ORÇAMENTO PARAMÉTRICO SUPRAESTRUTURA
A7: Documento | B7: MTH_INC-RES Orçamento Paramétrico
A8: Cliente
A9: Obra | B9: Reserva | I9: Status | J9: Concluído
A10: Data | B10: 44294 | G10: Revisão | H10: R00 | I10: Resp. | J10: Kelen
A12: SUPRAESTRUTURA
A14: Descrição | D14: Quantidade | F14: Parâmetro | H14: Referência | I14: Valor total
A15: Fabricação forma | D15: =D16/2 -> 33625.804 | E15: m² | F15: 30 | G15: % | H15: Média | I15: =+D15*130 -> 4371354.5
A16: Montagem de forma | D16: =+'Dados Gerais'!$E$15*F16 -> 67251.607 | E16: m² | F16: 1.75 | G16: m² / AC | H16: Média | I16: =+D16*6 -> 403509.65
A17: Escoramento - Torre | D17: ='Dados Gerais'!E15-'Dados Gerais'!E25 -> 32026.07 | E17: m² | F17: 60 | G17: R$ / m² | H17: Média | I17: =+D17*F17 -> 1921564.2
A18: Armadura Convencional para Estrutura | D18: =(D19)*F18 -> 960737.25 | E18: kg | F18: 100 | G18: kg / m³ | H18: Média | I18: =+D18*8 -> 7685898
A19: Concreto | D19: =(+'Dados Gerais'!E15)*Supraestrutura!$F$19 -> 9607.3725 | E19: m³ | F19: 0.25 | G19: m³ / AC | H19: Média | I19: =+D19*530 -> 5091907.4
A20: Mão de obra - estrutura em concreto armado | D20: 0 | E20: m² | F20: 0 | G20: R$ / m² | H20: Média | I20: 0
A21: TOTAL | I21: =SUM(I15:J20) -> 19474234
A25: LIVE | K25: =I21 -> 19474234 | L25: =K25/'Dados Gerais'!E15 -> 506.75233
A26: FORMA | B26: 22547.1 | C26: =B26/B30 -> 1.5144011
A27: AÇO | B27: 215880.65 | C27: =B27/B28 -> 58.195443
A28: CONCRETO | B28: 3709.58 | C28: =B28/B30 -> 0.24915807
A30: ÁREA CONSTRUÍDA | B30: 14888.46

Sheet Alvenaria
A2: ORÇAMENTO PARAMÉTRICO ALVENARIA
A7: Documento | B7: MTH_INC-RES Orçamento Paramétrico
A8: Cliente
A9: Obra | B9: Reserva | I9: Status | J9: Concluído
A10: Data | B10: 44294 | G10: Revisão | H10: R00 | I10: Resp. | J10: Kelen
A12: ALVENARIA
A14: Descrição | D14: Quantidade | F14: Parâmetro | H14: Referência | I14: Valor total
A15: Alvenaria embasamento | D15: =+F15*'Dados Gerais'!E24 -> 14580.885 | E15: m² | F15: 0.75 | G15: m² / AE | H15: Média | I15: =+D15*50 -> 729044.25
A16: Alvenaria lazer | D16: =F16*'Dados Gerais'!E22 -> 7781.58 | E16: m² | F16: 0.85 | G16: m² / AL | H16: Média | I16: =+D16*50 -> 389079
A17: Alvenaria tipo | D17: 12830.7 | E17: m² | F17: 1 | G17: m² / APT*NPT | H17: Média | I17: =+D17*40 -> 513228.02
A18: Alvenaria cobertura / reservatório | D18: =F18*'Dados Gerais'!E20 -> 4711.36 | E18: m² | F18: 0.8 | G18: m² / APT | H18: Média | I18: =+D18*40 -> 188454.4
A19: Alvenaria divisórias | D19: =6630.72*1.5 -> 9946.08 | E19: m² | F19: 60 | G19: R$ / m² | H19: Média | I19: =F19*D19 -> 596764.8
A20: Drywall ST/ST sem isolamento | D20: =993.088*2 -> 1986.176 | E20: m² | F20: =73.75+15.62 -> 89.37 | G20: R$ / m² | H20: Média | I20: =F20*D20 -> 177504.55
A21: Drywall ST/RU sem isolamento | D21: =993.088*2 -> 1986.176 | E21: m² | F21: 92.38 | G21: R$ / m² | H21: Média | I21: =F21*D21 -> 183482.94
A22: Mão de obra | D22: =SUM(D15:D19) -> 49850.606 | E22: m² | F22: 9.5 | G22: R$ / m² | H22: Média | I22: 0
A23: Complementares | D23: =D22 -> 49850.606 | E23: m² | F23: 9.5 | G23: R$ / m² | H23: Média | I23: =F23*D23 -> 473580.75
A24: TOTAL | I24: =SUM(I15:J23) -> 3251138.7
J28: =I24 -> 3251138.7 | K28: =J28/'Dados Gerais'!E15 -> 84.6001

Sheet Instalações
A2: ORÇAMENTO PARAMÉTRICO INSTALAÇÕES
A7: Documento | B7: MTH_INC-RES Orçamento Paramétrico
A8: Cliente
A9: Obra | B9: Reserva | I9: Status | J9: Concluído
A10: Data | B10: 44294 | G10: Revisão | H10: R00 | I10: Resp. | J10: Kelen
A12: INSTALAÇÕES ELÉTRICAS
A14: Descrição | D14: Quantidade | F14: Parâmetro | H14: Referência | I14: Valor total
A15: Entrada de Energia | D15: 1 | E15: vb | F15: 10 | G15: R$ / AC | H15: Média | I15: =+F15*'Dados Gerais'!$E$15 -> 384294.9
A16: Eletrodutos e Eletrocalhas | D16: 1 | E16: vb | F16: 12 | G16: R$ / AC | H16: Média | I16: =+F16*'Dados Gerais'!$E$15 -> 461153.88
A17: Cabos e Fiações | D17: 1 | E17: vb | F17: 36 | G17: R$ / AC | H17: Média | I17: =+F17*'Dados Gerais'!$E$15 -> 1383461.6
A18: Quadros e Disjuntores | D18: 1 | E18: vb | F18: 20 | G18: R$ / AC | H18: Média | I18: =+F18*'Dados Gerais'!$E$15 -> 768589.8
A19: Acabamentos Elétricos | D19: 1 | E19: vb | F19: 20 | G19: R$ / AC | H19: Média | I19: =+F19*'Dados Gerais'!$E$15 -> 768589.8
A20: Equipamentos e Iluminação | D20: 1 | E20: vb | F20: 21 | G20: R$ / AC | H20: Média | I20: =+F20*'Dados Gerais'!$E$15 -> 807019.29
A21: Mão de Obra para Instalações Elétricas | D21: 0 | E21: vb | F21: 0 | G21: R$ / AC | H21: Média | I21: =+F21*'Dados Gerais'!$E$15 -> 0
A22: TOTAL | I22: =SUM(I15:J21) -> 4573109.3
A24: INSTALAÇÕES HIDRÁULICAS
A26: Descrição | D26: Quantidade | F26: Parâmetro | H26: Referência | I26: Valor total
A27: Instalações de Água Fria | D27: 1 | E27: vb | F27: 32 | G27: R$ / AC | H27: Média | I27: =+F27*'Dados Gerais'!$E$15 -> 1229743.7
A28: Instalações de Água Quente | D28: 1 | E28: vb | F28: 32 | G28: R$ / AC | H28: Média | I28: =+F28*'Dados Gerais'!$E$15 -> 1229743.7
A29: Instalações de Águas Pluviais | D29: 1 | E29: vb | F29: 10 | G29: R$ / AC | H29: Média | I29: =+F29*'Dados Gerais'!$E$15 -> 384294.9
A30: Instalações Sanitárias | D30: 1 | E30: vb | F30: 15 | G30: R$ / AC | H30: Média | I30: =+F30*'Dados Gerais'!$E$15 -> 576442.35
A31: Suportes | D31: 1 | E31: vb | F31: 0 | G31: R$ / AC | H31: Média | I31: =+F31*'Dados Gerais'!$E$15 -> 0
A32: Louças e Metais | D32: 1 | E32: vb | F32: 45 | G32: R$ / AC | H32: Média | I32: =+F32*'Dados Gerais'!$E$15+7500*4*2 -> 1789327
A33: Mão de Obra para Instalações Hidráulicas | D33: 0 | E33: vb | F33: 0 | G33: R$ / AC | H33: Média | I33: =+F33*'Dados Gerais'!$E$15 -> 0
A34: TOTAL | I34: =SUM(I27:J33) -> 5209551.7
A37: INSTALAÇÕES PREVENTIVAS E GLP
A39: Descrição | D39: Quantidade | F39: Parâmetro | H39: Referência | I39: Valor total
A40: Instalações Preventivas | D40: 1 | E40: vb | F40: 25 | G40: R$ / AC | H40: Média | I40: =+F40*'Dados Gerais'!$E$15 -> 960737.25
A41: Instalações de GLP | D41: 1 | E41: vb | F41: 5 | G41: R$ / AC | H41: Média | I41: =+F41*'Dados Gerais'!$E$15 -> 192147.45
A42: Instalações de Proteção e Aterramento - SPDA | D42: 1 | E42: vb | F42: 10 | G42: R$ / AC | H42: Média | I42: =+F42*'Dados Gerais'!$E$15 -> 384294.9
A43: Mão de Obra | D43: 0 | E43: vb | F43: 0 | G43: R$ / AC | H43: Média | I43: =+F43*'Dados Gerais'!$E$15 -> 0
A44: TOTAL | I44: =SUM(I40:J43) -> 1537179.6 | M44: =I44+I34+I22 -> 11319841 | N44: =M44/'Dados Gerais'!E15 -> 294.5613
A48: MENDES | B48: 4811.62
C49: VALOR/M2
A50: Eletrodutos e eletrocalhas | B50: 50310.24 | C50: =B50/$B$48 -> 10.455988
A51: Entrada de Energia | B51: 47231.41 | C51: =B51/$B$48 -> 9.8161139
A52: Fios e cabos | B52: 171028.56 | C52: =B52/$B$48 -> 35.544902
A53: Itens não orçados | B53: =165337.19+233.6 -> 165570.79 | C53: =B53/$B$48 -> 34.410612 | D53: =C53/2 -> 17.205306
A54: Luminárias | B54: 15196.95 | C54: =B54/$B$48 -> 3.1583853
A55: Mão de Obra | B55: 224684.52 | C55: =B55/$B$48 -> 46.696231
...

Sheet Sistemas especiais
A2: ORÇAMENTO PARAMÉTRICO INSTALAÇÕES
A7: Documento | B7: MTH_COTA-AFP Orçamento Paramétrico
A8: Cliente | B8: COTA
A9: Obra | B9: AFONSO PENA | I9: Status | J9: Concluído
A10: Data | B10: 44454 | G10: Revisão | H10: R00 | I10: Resp. | J10: Kelen
A12: CLIMATIZAÇÃO, EXAUSTÃO MECÂNICA E PRESSURIZAÇÃO
A14: Descrição | D14: Quantidade | F14: Parâmetro | H14: Referência | I14: Valor total
A15: Instalação de Ar Condicionado | D15: 702 | E15: un | F15: 6500 | G15: R$ / un | H15: Média | I15: =F15*D15 -> 4563000
A16: Ar condicionado central | D16: 4062.32 | E16: m2 | F16: 200 | G16: R$ / m² | H16: Média | I16: =+D16*F16 -> 812464
A17: Ventokit | D17: 370 | E17: un | F17: 1200 | G17: R$ / un | H17: Média | I17: =+D17*F17 -> 444000
A18: TOTAL | I18: =SUM(I15:J17) -> 5819464
A22: OUTROS SISTEMAS ESPECIAIS
A24: Descrição | D24: Quantidade | F24: Parâmetro | H24: Referência | I24: Valor total
A25: Outros sistemas | D25: 1 | E25: vb | F25: 15 | G25: R$ / AC | H25: Média | I25: =+F25*'Dados Gerais'!E15 -> 576442.35
I26: =SUM(I25:J25) -> 576442.35
A29: EQUIPAMENTOS
A31: Descrição | D31: Quantidade | F31: Parâmetro | H31: Referência | I31: Valor total
A32: Elevadores - Subsolo - Sociais | D32: 5 | E32: un | F32: 16500 | G32: R$ / NP | H32: Média | I32: =F32*D32*7 -> 577500
A33: Elevadores - Subsolo - Serviço | D33: 2 | E33: un | F33: 13500 | G33: R$ | H33: Média | I33: =F33*D33*7 -> 189000
A34: Elevadores - Térreo - Sociais | D34: 2 | E34: un | F34: 16500 | G34: R$ | H34: Média | I34: =D34*F34*6 -> 198000
A35: Elevadores - mezanino - Sociais | D35: 4 | E35: un | F35: 16500 | G35: R$ | H35: Média | I35: =D35*F35*5 -> 330000
A36: Subestação | D36: 1 | E36: vb | F36: 250000 | G36: R$ | H36: Média | I36: =F36*D36 -> 250000
A37: Gerador | D37: 1 | E37: vb | F37: 200000 | G37: R$ | H37: Média | I37: =+D37*F37 -> 200000
A38: Equipamentos para Piscina | D38: 1 | E38: vb | F38: 350000 | G38: R$ | H38: Média | I38: =+D38*F38 -> 350000
A39: Escada pré moldada | D39: 2 | E39: un | F39: 25000 | G39: R$ | H39: Média | I39: =+D39*F39 -> 50000
A40: Equipamentos para Sauna | D40: 1 | E40: vb | F40: 100000 | G40: R$ | H40: Média | I40: =+D40*F40 -> 100000
A41: TOTAL | I41: =SUM(I32:J40) -> 2244500
J45: =I41+I26+I18 -> 8640406.3 | K45: =J45/'Dados Gerais'!E15 -> 224.83791

Sheet Impermeabilização
A2: ORÇAMENTO PARAMÉTRICO IMPERMEABILIZAÇÃO
A7: Documento | B7: MTH_INC-RES Orçamento Paramétrico
A8: Cliente
A9: Obra | B9: Reserva | I9: Status | J9: Concluído
A10: Data | B10: 44294 | G10: Revisão | H10: R00 | I10: Resp. | J10: Kelen
A12: IMPERMEABILIZAÇÃO
A14: Descrição | D14: Quantidade | F14: Parâmetro | H14: Referência | I14: Valor total
A15: Regularização de Superfície | D15: =+D20+D21 -> 13329.898 | E15: m² | F15: 6 | G15: R$ / m² | H15: Média | I15: =+D15*10 -> 133298.98
A16: Poço do elevador | D16: =(6.87*1.5+2.97)*('Sistemas especiais'!D32+'Sistemas especiais'!D33+'Sistemas especiais'!D34+'Sistemas especiais'!D35) -> 172.575 | E16: m² | F16: 40 | G16: R$ / m² | H16: Média | I16: =+D16*F16 -> 6903
A17: Junta de dilatação | D17: =D46 -> 1429.16 | E17: m | F17: 115 | G17: R$ / m | H17: Média | I17: =+D17*F17 -> 164353.4
A18: Baldrames | D18: =0.7*Infraestrutura!D30 -> 3297.952 | E18: m² | F18: 40 | G18: R$ / m² | H18: Média | I18: =+D18*F18 -> 131918.08
A19: Ralos | D19: 1 | E19: vb | F19: 1 | G19: R$ / AC | H19: Média | I19: =+F19*'Dados Gerais'!$E$15 -> 38429.49
A20: Impermeabilizações cimenticias | D20: =+F20*'Dados Gerais'!$E$15 -> 5764.4235 | E20: m² | F20: 0.15 | G20: m² / AC | H20: Média | I20: =+D20*50 -> 288221.17
A21: Impermeabilizações com manta asfaltica | D21: =A35*1.5 -> 7565.475 | E21: m² | F21: 0 | G21: m² / AC | H21: Média | I21: =+D21*140 -> 1059166.5
A22: Impermeabilização de peitoril | D22: 1 | E22: vb | F22: 1.2 | G22: R$ / AC | H22: Média | I22: =+F22*'Dados Gerais'!$E$15 -> 46115.388
A23: Proteção Mecânica | D23: =+D21 -> 7565.475 | E23: m² | F23: 80 | G23: R$ / m² | H23: Média | I23: =F23*D23 -> 605238
A24: TOTAL | I24: =SUM(I15:J23) -> 2473644
A27: Laje impermeabilizada | J27: =I24 -> 2473644 | K27: =J27/'Dados Gerais'!E15 -> 64.36838
A28: 124.65
A29: 159.2
A30: 652.36
A31: 239.76
A32: 2496.09
A33: 1309.09
A34: 62.5
A35: =SUM(A28:A34) -> 5043.65
A37: Junta dilatação | B37: Comprimento | C37: Repetição | D37: Total
A38: Subsolo | B38: 45.2 | C38: 3 | D38: =C38*B38 -> 135.6
A39: Térreo | B39: =50.52+30.1+45.09+45.1+30.09+18.4 -> 219.3 | C39: 1 | D39: =C39*B39 -> 219.3
A40: Mezanino | B40: =28.42+22.27+22.92+30.1+45.1+45.1+30.1+18.4 -> 242.41 | C40: 1 | D40: =C40*B40 -> 242.41
A41: 2º Pavimento | B41: =21.4+22.92*6+21.42+22.27 -> 202.61 | C41: 1 | D41: =C41*B41 -> 202.61
A42: 3º Pavimento | B42: =B41 -> 202.61 | C42: 1 | D42: =C42*B42 -> 202.61
A43: 4º Pavimento | B43: =B42 -> 202.61 | C43: 1 | D43: =C43*B43 -> 202.61
A44: 5º Pavimento | B44: =B43 -> 202.61 | C44: 1 | D44: =C44*B44 -> 202.61
A45: Técnico | B45: 21.41 | C45: 1 | D45: =C45*B45 -> 21.41
D46: =SUM(D38:D45) -> 1429.16

Sheet Rev. Internos Piso e Parede
A2: ORÇAMENTO PARAMÉTRICO REVESTIMENTOS INTERNOS EM PISO E PAREDE
A7: Documento
A8: Cliente
A9: Obra | I9: Status | J9: Concluído
A10: Data | B10: 44294 | G10: Revisão | H10: R00 | I10: Resp. | J10: Kelen
A12: REVESTIMENTOS INTERNOS EM PISO E PAREDE
A14: Descrição | D14: Quantidade | F14: Parâmetro | H14: Referência | I14: Valor total
A15: Piso de concreto polido | D15: 8034.66 | E15: m² | G15: m² / AC | H15: Média | I15: =D15*20 -> 160693.2
A16: Contrapiso | D16: 34292.86 | E16: m² | F16: 0 | G16: m² / AC | H16: Média | I16: =D16*40 -> 1371714.4
A17: Manta acústica | D17: 14577 | E17: m² | F17: 0 | G17: m² / AC | H17: Média | I17: =+D17*25 -> 364425
A18: Chapisco | D18: =SUM(Alvenaria!D15:D19) -> 49850.606 | E18: m² | F18: 0 | G18: m² / AC | H18: Média | I18: =+D18*3 -> 149551.82
A19: Reboco | D19: =D18 -> 49850.606 | E19: m² | F19: 0 | G19: m² / AC | H19: Média | I19: =18*D19 -> 897310.9
A20: Estucamento | D20: 0 | E20: vb | F20: 0 | G20: R$ / AC | H20: Média | I20: =+F20*'Dados Gerais'!$E$15 -> 0
A21: TOTAL | I21: =SUM(I15:J20) -> 2943695.3
A24: =847.39+5.81+697.91+85.08+776.08+315.8+281.01+263.32*24+18.62+38.07+61.94 -> 9447.39 | C24: =759.99+764.4+1846.32+1159.98+936.44+942.49+1408.99+2025.1+972.59+902.67+904.15*24+517.98+42.85+84.85 -> 34064.25 | K24: =I21 -> 2943695.3 | L24: =K24/'Dados Gerais'!E15 -> 76.599906

Sheet Acabamentos de Teto
A2: ORÇAMENTO PARAMÉTRICO REVESTIMENTOS E ACABAMENTOS INTERNOS EM TETO
A7: Documento | B7: MTH_INC-RES Orçamento Paramétrico
A8: Cliente
A9: Obra | B9: Reserva | G9: UC | H9: 02 | I9: Status | J9: Concluído
A10: Data | B10: 44294 | G10: Revisão | H10: R00 | I10: Resp. | J10: Kelen
A12: ACABAMENTOS DE TETO
A14: Descrição | D14: Quantidade | F14: Parâmetro | H14: Referência | I14: Valor total
A15: Forro de Gesso mineral | D15: 13957.564 | E15: m² | F15: 0 | G15: m² / AC | H15: Média | I15: =+D15*102 -> 1423671.5
A16: Negativo | D16: =B24*D15 -> 19451.605 | E16: m | F16: 0 | G16: m / AC | H16: Média | I16: =+D16*26 -> 505741.72
A17: Estucamento | D17: 19076.716 | E17: m² | F17: 0 | G17: R$ / AC | H17: Média | I17: =D17*2 -> 38153.432
A18: TOTAL | I18: =SUM(I15:J17) -> 1967566.7
A21: Relação forro e negativo
A22: Forro | B22: 280.14
A23: Negativo | B23: 390.41 | J23: =I18 -> 1967566.7 | L23: =J23/'Dados Gerais'!E15 -> 51.199396
A24: Relação | B24: =B23/B22 -> 1.3936246

Sheet Acabamentos de Piso e Parede
A2: ORÇAMENTO PARAMÉTRICO ACABAMENTOS EM PISO E PAREDE
A7: Documento | B7: MTH_INC-RES Orçamento Paramétrico
A8: Cliente
A9: Obra | B9: Reserva | G9: UC | H9: 02 | I9: Status | J9: Concluído
A10: Data | B10: 44294 | G10: Revisão | H10: R00 | I10: Resp. | J10: Kelen
A12: ACABAMENTOS EM PISO E PAREDE
A14: Descrição | D14: Quantidade | F14: Parâmetro | H14: Referência | I14: Valor total
A15: Cerâmica | D15: 1577.73 | E15: m² | F15: 95 | G15: R$ / AC | H15: Média | I15: =+F15*D15 -> 149884.35
A16: Porcelanato 80x80 | D16: 8097.92 | E16: m² | F16: 100 | G16: R$ / m² | H16: Média | I16: =+F16*D16 -> 809792
A17: Varanda e deck molhado | D17: =515.92*1.2 -> 619.104 | E17: m² | F17: 110 | G17: R$ / m² | H17: Média | I17: =+F17*D17 -> 68101.44
A18: Pastilha | D18: =691.99+691.99*1.2*1.5 -> 1937.572 | E18: m² | F18: 150 | G18: R$ / m² | H18: Média | I18: =+F18*D18 -> 290635.8
A19: Piso emborrachado | D19: 197.06 | E19: m² | F19: 150 | G19: R$ / m² | H19: Média | I19: =+F19*D19 -> 29559
A20: Piso vinílico | D20: 27.3 | E20: m² | F20: 200 | G20: R$ / m² | H20: Média | I20: =+F20*D20 -> 5460
A21: Pisoporcelanato 90x90 | D21: 14577.08 | E21: m² | F21: 110 | G21: R$ / m² | H21: Média | I21: =+F21*D21 -> 1603478.8
A22: Piso antiderrapante de pedra | D22: 432.2 | E22: m² | F22: 160 | G22: R$ / m² | H22: Média | I22: =+F22*D22 -> 69152
A23: Paver | D23: 5371.08 | E23: m² | F23: 80 | G23: R$ / m² | H23: Média | I23: =+F23*D23 -> 429686.4
A24: Cimentício | D24: 573.2 | E24: m² | F24: 40 | G24: R$ / m² | H24: Média | I24: =+F24*D24 -> 22928
A25: Rodapés | D25: 1 | E25: vb | F25: 19 | G25: R$ / AC | H25: Média | I25: =+F25*D25*'Dados Gerais'!E15 -> 730160.31
A26: Revestimentos de Parede | D26: =B33*1.5 -> 1879.605 | E26: m² | F26: 80 | G26: R$ / m² | H26: Média | I26: =+F26*D26 -> 150368.4
A27: TOTAL | I27: =SUM(I15:J26) -> 4359206.5
B30: ÁREA | J30: =I27 -> 4359206.5 | K30: =J30/'Dados Gerais'!E15 -> 113.43389
A31: BOX | B31: =2.38*1.5 -> 3.57
A32: Quantidade | B32: =306+26+7+12 -> 351
A33: Total | B33: =B32*B31 -> 1253.07
A36: RODAPÉ MENDES
A37: Total custo | B37: =10215.71+2691.74+10654.86+10707.29+53650.49+4322.65 -> 92242.74
A38: Área | B38: 4811.62
A39: Valor/m2 | B39: =B37/B38 -> 19.170828

Sheet Pintura Interna
A2: ORÇAMENTO PARAMÉTRICO PINTURA INTERNA
A7: Documento | B7: MTH_INC-RES Orçamento Paramétrico
A8: Cliente
A9: Obra | B9: Reserva | G9: UC | H9: 02 | I9: Status | J9: Concluído
A10: Data | B10: 44294 | G10: Revisão | H10: R00 | I10: Resp. | J10: Kelen
N11: 664942.13
A12: PINTURA INTERNA | M12: 5730 | N12: =P21 -> 191930.44 | O12: =N13/M12 -> 82.550033
N13: =N11-N12 -> 473011.69
A14: Descrição | D14: Quantidade | F14: Parâmetro | H14: Referência | I14: Valor total | N14: 32483.89 | O14: 14107.95
A15: Demarcação de faixas | D15: =A26 -> 195 | E15: m2 | F15: 30 | G15: R$ / AC | H15: Média | I15: =D15*F15 -> 5850 | N15: 36129.33 | O15: 139.9
A16: Pintura piso escadaria | D16: 573.2 | E16: m2 | F16: 6 | G16: R$ / AC | H16: Média | I16: =D16*F16 -> 3439.2 | N16: 36129.33 | O16: 139.9
A17: Pintura Interna | D17: =Alvenaria!D22*2+'Pintura Interna'!B29*2+'Pintura Interna'!B30*2 -> 113558.49 | E17: m2 | F17: 12 | G17: R$ / AC | H17: Média | I17: =+F17*D17 -> 1362701.9 | N17: 17731.94 | O17: 28720.35
A18: TOTAL | I18: =SUM(I15:J17) -> 1371991.1 | N18: =SUM(N14:N17) -> 122474.49 | O18: 289.5
O19: 25792.65
O20: 265.7
A21: Número de vagas | J21: =I18 -> 1371991.1 | K21: =J21/'Dados Gerais'!E15 -> 35.701518 | O21: =SUM(O14:O20) -> 69455.95 | P21: =O21+N18 -> 191930.44
A22: =341+12+30+4+1+2 -> 390
A23: Área de pintura
A24: =5*0.1 -> 0.5
A25: Total
A26: =A24*A22 -> 195
A29: DRYWALL DUPLO | B29: 6630.715
A30: DRYWALL SIMPLES | B30: 297.9264

Sheet Esquadrias
A2: ORÇAMENTO PARAMÉTRICO ESQUADRIAS
A7: Documento | B7: MTH_INC-RES Orçamento Paramétrico
A8: Cliente
A9: Obra | B9: Reserva | G9: UC | H9: 02 | I9: Status | J9: Concluído
A10: Data | B10: 44294 | G10: Revisão | H10: R00 | I10: Resp. | J10: Kelen
A12: ESQUADRIAS
A14: Descrição | D14: Quantidade | F14: Parâmetro | H14: Referência | I14: Valor total
A15: Esquadrias de Alumínio | D15: 6234.88 | E15: m² | F15: 1500 | G15: R$ / m² | H15: Média | I15: =F15*D15 -> 9352320
A16: Pele de vidro | D16: =D69+D70+D71+226.96+4.2+4.67+8.29+94.95+25.25+22.74+17.72*24+70.32 -> 936.25187 | E16: m² | F16: 662 | G16: R$ / m² | H16: Média | I16: =F16*D16 -> 619798.74
A17: PCF | D17: 49 | E17: un | F17: 1500 | G17: R$ / un | H17: Média | I17: =F17*D17 -> 73500
A18: Serralherias | D18: 1 | E18: vb | F18: 350000 | G18: R$ | H18: Média | I18: =+D18*F18 -> 350000
A19: Brise | D19: =A40 -> 77.44 | E19: m² | F19: 1600 | G19: R$ / m² | H19: Média | I19: =+F19*D19 -> 123904
A20: Guarda corpo - alumínio e vidro | D20: =A34 -> 373.659 | E20: m² | F20: 1800 | G20: R$ / m² | I20: =+F20*D20 -> 672586.2
A21: Portão de alumínio | D21: 2 | E21: un | F21: 20000 | G21: R$ / un | H21: Média | I21: =+F21*D21 -> 40000
A22: Fechadura eletrônica | D22: ='Acabamentos de Piso e Parede'!B32 -> 351 | E22: un | F22: 250 | G22: R$ / un | H22: Média | I22: =F22*D22 -> 87750
A23: Esquadrias de Madeira | D23: 814 | E23: un | F23: 1800 | G23: R$ / un | H23: Média | I23: =F23*D23 -> 1465200
A24: TOTAL | I24: =SUM(I15:J23) -> 12785059
A27: GUARDA CORPO | D27: =D20/1.1 -> 339.69 | K27: =I24 -> 12785059 | L27: =K27/'Dados Gerais'!E15 -> 332.68875
A29: Gardens
A30: 26.13 | B30: metros | C30: perímetro
A31: 1.1 | B31: metros | C31: altura
A32: =A31*A30 -> 28.743 | B32: m2 | C32: por dupla de ap.
A33: 13 | B33: unidades | C33: par de apartamento
A34: =A33*A32 -> 373.659 | B34: m2 | C34: guarda corpo
A37: Brise
A38: 3.52 | B38: m2 | C38: uma unidade
A39: 22 | B39: unidades
A40: =A39*A38 -> 77.44 | B40: total | C40: brise
A58: LAZER
A59: 0.8 | B59: 0.6 | C59: 3 | D59: =C59*B59*A59 -> 1.44
A60: 2 | B60: 1.5 | C60: 1 | D60: =C60*B60*A60 -> 3 | E60: persiana
A61: 2 | B61: 2 | C61: 3 | D61: =C61*B61*A61 -> 12 | E61: persiana
A62: 1.2 | B62: 1 | C62: 2 | D62: =C62*B62*A62 -> 2.4
D63: =C63*B63*A63 -> 0
D64: =SUM(D31:D63) -> 18.84
D65: =C65*B65*A65 -> 0
A66: PORTA
D67: =C67*B67*A67 -> 0
A69: PELE DE VIDRO | B69: 2.1 | C69: 4.4 | D69: =C69*B69 -> 9.24
B70: 2.098 | C70: 3.8966 | D70: =C70*B70 -> 8.1750668
...

Sheet Auxiliar
A2: 2 Portões acesso garagem - Área: 9,2m² x 2 = 18,4m² | B2: 2 | C2: portão | D2: 18.4
A3: 2 portas corta-fogo 1 folha | B3: 2 | C3: pcf
A4: 1 porta de correr alumínio 2 folhas – Área: 3,465m² | B4: 1 | C4: porta alumínio | D4: 3.465
A5: 1 porta de correr alumínio 2 folhas – Área: 1,7325m² | B5: 1 | C5: porta alumínio | D5: 1.7325 | G5: Guarda alumínio | H5: =SUMIF(C:C,G5,D:D) -> 400.5221
A6: 2 portas de abrir alumínio 2 folhas – Área: 2,6376m² x 2 = 5,2752m² | B6: 2 | C6: porta alumínio | D6: 5.2752 | G6: janela | H6: =SUMIF(C:C,G6,D:D) -> 1895.06
A7: 1 porta de abrir alumínio 2 folhas – Área: 4,1916m² | B7: 1 | C7: porta alumínio | D7: 4.1916 | G7: madeira | H7: =SUMIF(C:C,G7,B:B) -> 218
A8: 1 porta pivotante | B8: 1 | C8: pivotante | G8: pcf | H8: =SUMIF(C:C,G8,B:B) -> 60
A9: 19 portas de abrir madeira 1 folha | B9: 19 | C9: madeira | G9: pivotante | H9: =SUMIF(C:C,G9,B:B) -> 1
A10: 3 portas de abrir vidro 1 folha – Área: 2,1m² x 3 = 6,3m² | B10: 3 | C10: porta alumínio | D10: 6.3 | G10: porta alumínio | H10: =SUMIF(C:C,G10,D:D) -> 46.62
A11: 2 portas de abrir vidro 1 folha – Área: 1,89m² x 2 = 3,78m² | B11: 2 | C11: porta alumínio | D11: 3.78 | G11: portão | H11: =SUMIF(C:C,G11,B:B) -> 2
A12: 1 porta de abrir alumínio 1 folha – Área: 2,0076m² | B12: 1 | C12: porta alumínio | D12: 2.0076 | G12: gradil | H12: =SUMIF(C:C,G12,D:D) -> 113.88
A13: Janelas – Área: 3,75 + 4,875 + 2,5 + 1,1 + 1,2 + 5,5402 + 4,4874 = 23,4526m² | C13: janela | D13: 23.4526 | G13: Brise | H13: 109.3146
A14: Muro de vidro – Área: 7,0774 + 5,485 + 3,43 + 4,8138 = 20,8062m² | C14: Guarda alumínio | D14: 20.8062
A15: 8 portas corta-fogo 1 folha | B15: 8 | C15: pcf
A16: Janelas – Area: (1,1 + 1,2 + 28,7391) x 4 = 124,1564m² | C16: janela | D16: 124.1564
A17: 2 portas corta-fogo 1 folha | B17: 2 | C17: pcf
A18: 2 portas de abrir alumínio 1 folha – Área: 1,47m² x 2 = 2,94m² | B18: 2 | C18: porta alumínio | D18: 2.94
A19: 2 portas de abrir vidro 1 folha – Área: 1,89m² x 2 = 3,78m² | B19: 2 | C19: porta alumínio | D19: 3.78
A20: 5 portas de abrir madeira 1 folha | B20: 5 | C20: madeira
A21: 1 janela-porta de correr vidro – Área: 14,7348m² | B21: 1 | C21: janela | D21: 14.7348
A22: Janelas – Área: 1,2894 + 1,2894 + 23,46 + 1,854 + 5,562 + 5,562 + 1,854 + 1,854 + 1,1 + 1,2 = 45,0248m² | C22: janela | D22: 45.0248
A23: Guarda corpo vidro – Área: 7,5299 + 5,7955 + 6,5555 = 19,8809m² | C23: Guarda alumínio | D23: 19.8809
A24: 38 portas corta-fogo 1 folha | B24: 38 | C24: pcf
A25: 171 portas de abrir madeira 1 folha | B25: 171 | C25: madeira
A26: 19 porta de abrir alumínio 1 folha – Área: 1,26m² x 19 = 23,94m² | B26: 19 | C26: porta alumínio | D26: 23.94
A27: 19 janela-porta de correr vidro 5 folhas - Área: 25,4205m² x 19 = 482,9895m² | B27: 19 | C27: janela | D27: 482.9895
A28: 19 janela-porta de correr vidro 5 folhas - Área: 17,8284m² x 19 = 338,7396m² | B28: 19 | C28: janela | D28: 338.7396
A29: Janelas – Área: 1,1 + 1,1 + 1,2 + 1,92 + 0,36 + 2,781 + 2,781 + 1,854 + 1,854 + 5,562 + 5,562 + 1,854 = 27,928m² x 19 = 530,632m² | C29: janela | D29: 530.632
A30: Guarda corpo metálico – Área: 4,745m² x 19 = 90,155m² - Perímetro: 3,65m x 19 = 69,35m | C30: gradil | D30: 90.155
A31: Guarda corpo vidro – Área: 15,645m² x 19 = 297,255m² - Perímetro: 14,9m x 19 = 283,1m | C31: Guarda alumínio | D31: 297.255
A32: 2 portas corta-fogo 1 folha | B32: 2 | C32: pcf
A33: 2 portas de abrir madeira 1 folha | B33: 2 | C33: madeira
A34: 1 porta de abrir alumínio 1 folha – Área: 1,26m² | B34: 1 | C34: porta alumínio | D34: 1.26
A35: 1 janela-porta de correr vidro 3 folhas - Área: 15,21m² | B35: 1 | C35: janela | D35: 15.21
A36: 1 janela-porta de correr vidro 5 folhas - Área: 25,4205m² | B36: 1 | C36: janela | D36: 25.4205
A37: 1 janela-porta de correr vidro 5 folhas - Área: 17,8284m² | B37: 1 | C37: janela | D37: 17.8284
A38: Janelas – Área: 1,1 + 1,2 + 1,1 + 1,92 + 0,36 + 2,781 + 2,781 + 1,854 + 1,854 + 5,562 + 5,562 + 1,854 = 27,928m² | C38: janela | D38: 27.928
A39: Guarda corpo metálico – Área: 4,745m² - Perímetro: 3,65m | C39: gradil | D39: 4.745
A40: Guarda corpo vidro – Área: 15,645m² - Perímetro: 14,9m | C40: Guarda alumínio | D40: 15.645
A41: 2 portas corta-fogo 1 folha | B41: 2 | C41: pcf
...

Sheet Rev. Fachada
A2: ORÇAMENTO PARAMÉTRICO REVESTIMENTOS E ACABAMENTOS DE FACHADA
A7: Documento | B7: MTH_INC-RES Orçamento Paramétrico
A8: Cliente
A9: Obra | B9: Reserva | G9: UC | H9: 02 | I9: Status | J9: Concluído
A10: Data | B10: 44294 | G10: Revisão | H10: R00 | I10: Resp. | J10: Kelen
A12: REVESTIMENTOS ARGAMASSADOS
A14: Descrição | D14: Quantidade | F14: Parâmetro | H14: Referência | I14: Valor total
A15: Chapisco e reboco | D15: =F15*('Dados Gerais'!E21*'Dados Gerais'!E16) -> 16779 | E15: m² | F15: 3 | G15: m² / PT * (NPT+NPD+ND) | H15: - | I15: =D15*F15*31 -> 1560447
A16: TOTAL | I16: =SUM(I15:J15) -> 1560447
A19: PINTURA
A21: Descrição | D21: Quantidade | F21: Parâmetro | H21: Referência | I21: Valor total
A22: Textura | D22: =D15 -> 16779 | E22: m² | F22: 30 | G22: R$ / m² | H22: - | I22: =+D22*F22 -> 503370
A23: TOTAL | I23: =SUM(I22) -> 503370
A25: REVESTIMENTOS ESPECIAIS
A27: Descrição | D27: Quantidade | F27: Parâmetro | H27: Referência | I27: Valor total
A28: Detalhes especiais | D28: 1 | E28: vb | F28: =D22*0.2*150 -> 503370 | H28: - | I28: =F28*D28 -> 503370
A29: Alumínio | D29: 1 | E29: vb | F29: 450000 | H29: - | I29: =F29*D29 -> 450000
I30: =SUM(I28:J29) -> 953370
I32: =I30+I23+I16 -> 3017187 | J32: =I32/'Dados Gerais'!E15 -> 78.512283

Sheet Cobertura
A2: ORÇAMENTO PARAMÉTRICO COBERTURA
A7: Documento | B7: MTH_INC-RES Orçamento Paramétrico
A8: Cliente
A9: Obra | B9: Reserva | G9: UC | H9: 02 | I9: Status | J9: Concluído
A10: Data | B10: 44294 | G10: Revisão | H10: R00 | I10: Resp. | J10: Kelen
A12: COBERTURA
A14: Descrição | D14: Quantidade | F14: Parâmetro | H14: Referência | I14: Valor total
A15: Estrutura telha | D15: =449.53*2 -> 899.06 | E15: m² | F15: 70 | G15: R$ / m² | H15: - | I15: =+F15*D15 -> 62934.2
A16: Telha sanduíche | D16: =D15 -> 899.06 | E16: m² | F16: =235 -> 235 | G16: R$ / m² | H16: - | I16: =+F16*D16 -> 211279.1
A17: Calha | D17: =35.22*2+25.26*2 -> 120.96 | E17: m | F17: 150 | G17: R$ / m | H17: - | I17: =+F17*D17 -> 18144
A18: Rufo | D18: =45.55+65.08+60.81 -> 171.44 | E18: m | F18: 50 | G18: R$ / m | H18: - | I18: =+F18*D18 -> 8572
A19: Contra rufo | D19: =508.91 -> 508.91 | E19: m | F19: 50 | G19: R$ / m | H19: - | I19: =+F19*D19 -> 25445.5
A20: Cobertura de vidro | D20: =264.13077*2 -> 528.26154 | E20: m² | F20: 600 | G20: R$ / m² | H20: - | I20: =+F20*D20 -> 316956.92
A21: TOTAL | I21: =SUM(I15:J20) -> 643331.72
B23: Área
A24: Ático | B24: 15 | J24: =I21 -> 643331.72 | K24: =J24/'Dados Gerais'!E15 -> 16.740574

Sheet Complementares
A2: ORÇAMENTO PARAMÉTRICO EQUIPAMENTOS
A7: Documento | B7: MTH_INC-RES Orçamento Paramétrico
A8: Cliente
A9: Obra | B9: Reserva | G9: UC | H9: 02 | I9: Status | J9: Concluído
A10: Data | B10: 44294 | G10: Revisão | H10: R00 | I10: Resp. | J10: Kelen
A12: SERVIÇOS COMPLEMENTARES
A14: Descrição | D14: Quantidade | F14: Parâmetro | H14: Referência | I14: Valor total
A15: Móveis e decoração | D15: 1 | E15: vb | F15: 2500 | G15: R$ / AL | H15: Média | I15: ='Dados Gerais'!E22*F15+[2]MOBILIÁRIO!$E$94 -> 32804877
A16: Comunicação visual | D16: 1 | E16: vb | F16: 25 | G16: R$ / AC | H16: Média | I16: =D16*F16*'Dados Gerais'!$E$15 -> 960737.25
A17: Paisagismo | D17: 1 | E17: vb | F17: 30 | G17: R$ / AC | H17: Média | I17: =D17*F17*'Dados Gerais'!$E$15 -> 1152884.7
A18: Parede verde | D18: 103.5 | E18: m2 | F18: 300 | G18: R$ / m2 | H18: Média | I18: =F18*D18 -> 31050
A19: Limpeza | D19: 1 | E19: vb | F19: 15 | G19: R$ / AC | H19: Média | I19: =D19*F19*'Dados Gerais'!$E$15 -> 576442.35
A20: TOTAL | I20: =SUM(I15:J19) -> 35525991
A23: MENDES | J23: =I20 -> 35525991 | L23: =J23/'Dados Gerais'!E15 -> 924.44607
A25: 5700000 | B25: TOTAL
A26: 4811.62 | B26: ÁREA
A27: =A25/A26 -> 1184.6322 | B27: R$/m2
