Workbook
Name \0: #REF!
Name \0: #REF!
Name \0: #REF!
Name \0: #REF!
Name \0: #REF!
Name \0: #REF!
Name \0: #REF!
Name \a: #REF!
Name \a: #REF!
Name \m: #REF!
Name \m: #REF!
Name aa: #REF!
Name aa: #REF!
Name aaaa: '[1]M.O.'!#REF!
Name aaaa: '[1]M.O.'!#REF!
Name aaaa: '[1]M.O.'!#REF!
Name aaaa: '[1]M.O.'!#REF!
Name aaaa: '[1]M.O.'!#REF!
Name aaaa: '[1]M.O.'!#REF!
Name aaaa: '[1]M.O.'!#REF!
Name angelo: [2]Geral!#REF!
Name angelo: [2]Geral!#REF!
Name angelo: [2]Geral!#REF!
Name angelo: [2]Geral!#REF!
Name angelo: [2]Geral!#REF!
Name angelo: [2]Geral!#REF!
Name angelo: [2]Geral!#REF!
Name area: #REF!
Name aux: #REF!
Name aux: #REF!
Name aux: #REF!
Name aux: #REF!
Name aux: #REF!
Name aux: #REF!
Name aux: #REF!
Name BDA: #REF!
Name BDA: #REF!
Name BDI: #REF!
Name ca: #REF!
Name Capa: #REF!
Name cronograma: #REF!
Name D: #REF!
Name direto: #REF!
Name DRE: #REF!
Name ea: #REF!
Name FFFFFFF: #REF!
Name FFFFFFF: #REF!
Name FFFFFFF: #REF!
Name FFFFFFF: #REF!
Name FFFFFFF: #REF!
Name FFFFFFF: #REF!
Name FFFFFFF: #REF!
Name item_1: #REF!
Name item_1: #REF!
Name item_1: #REF!
Name item_1: #REF!
Name item_1: #REF!
Name item_1: #REF!
Name item_1: #REF!
Name LS: '[1]M.O.'!#REF!

Sheet DADOS_INICIAIS
A1: Obra | B1: 365 (Afonso Pena)
A2: Empresa | B2: COTA
A3: Revisão | B3: R00
A4: Arquitetura base | B4: 0895-PL-ARQ-TDOS-001-R10
A5: DADOS OBRA
B7: Descrição | C7: Identificador | D7: Unidade | E7: Quantidade
B8: ÁREA DO TERRENO | C8: AT | D8: M2 | E8: 2133.78
B9: ÁREA TOTAL CONSTRUÍDA | C9: AC | D9: M2 | E9: 17473.08
B10: ÁREA PRIVATIVA RESIDENCIAL | C10: AP | D10: M2 | E10: 8783.16
B11: UNIDADES RESIDENCIAIS | C11: UR | D11: UN | E11: 176
B12: Dormitórios | C12: dorm | D12: UN | E12: =(22+44+21)*2+(64+22+2+1) -> 263
B13: Banheiros | C13: ban | D13: UN
A14: =E27/E8 -> 0.764793 | B14: ÁREA PRIVATIVA COMERCIAL | C14: AP | D14: M2 | E14: 484.62
B15: UNIDADES COMERCIAIS | C15: UC | D15: UN
B16: Churrasqueiras | C16: CHU | D16: UN | E16: 88
B17: NÚMERO TOTAL DE PAVIMENTOS | C17: NP | D17: UN | E17: 16
B18: NÚMERO DE PAVIMENTOS TIPO | C18: NPT | D18: UN | E18: 10
B19: NÚMERO DE PAVIMENTOS TIPO DIFERENCIADOS | C19: NPD | D19: UN | E19: 1
B20: NÚMERO DE PAVIMENTOS DUPLEX | C20: ND | D20: UN | E20: 0
B21: ÁREA DE PROJEÇÃO DA TORRE | C21: APT | D21: M2 | E21: 889.05
B22: PERÍMETRO DE PROJEÇÃO DA TORRE | C22: PPT | D22: M | E22: 161.37
B23: ÁREA DE LAZER | C23: AL | D23: M2
B24: ÁREA DO EMBASAMENTO | C24: AE | D24: M2 | E24: =E25+1570.87+1588.77 -> 6375.09
B25: ÁREA DE SUBSOLOS | C25: S | D25: M2 | E25: =1631.9+1583.55 -> 3215.45
B26: NÚMERO DE SUBSOLOS | C26: NS | D26: UN | E26: 2
B27: ÁREA DE PROJEÇÃO DO EMBASAMENTO | C27: APE | D27: M2 | E27: 1631.9 | F27: =E27/E9 -> 0.093395097
B28: PERÍMETRO DE PROJEÇÃO DE EMBAMENTO | C28: PE | D28: M | E28: 156.03
B29: NÚMERO DE PAVIMENTOS DE EMBASAMENTO | C29: NE | D29: UN | E29: 4

Sheet MÃO DE OBRA
A2: Planilha de levantamento de custo de mão de obra
A4: Obra | B4: AFONSO PENA
A5: Indiçe do Cub | B5: 0.41
A6: Cub ref | B6: 45566
A7: Valor cub ref | B7: 2846.12
A8: Área (m2) | B8: 17473.08
A11: Item | B11: Serviço | C11: Peso (%) | D11: Custo MO (R$)
A12: 1 | B12: Instalação canteiro de obra | C12: 0.01 | D12: =$B$5*$B$7*$B$8*C12 -> 203894.98
A13: 2 | B13: Contenções | C13: 0.01 | D13: =$B$5*$B$7*$B$8*C13 -> 203894.98
A14: 3 | B14: Infraestrutura | C14: 0.04 | D14: =$B$5*$B$7*$B$8*C14 -> 815579.91
A15: 4 | B15: Supraestrutura | C15: 0.23 | D15: =$B$5*$B$7*$B$8*C15 -> 4689584.5
A16: 5 | B16: Parede e paineis | C16: 0.07 | D16: =$B$5*$B$7*$B$8*C16 -> 1427264.8
A17: 6 | B17: Esquadrias de madeiras | C17: 0.03 | D17: =$B$5*$B$7*$B$8*C17 -> 611684.93
A18: 7 | B18: Esquadrias metálicas | C18: 0.01 | D18: =$B$5*$B$7*$B$8*C18 -> 203894.98
A19: 8 | B19: Cobertura | C19: 0.015 | D19: =$B$5*$B$7*$B$8*C19 -> 305842.47
A20: 9 | B20: Impermeabilização e tratamento | C20: 0.005 | D20: =$B$5*$B$7*$B$8*C20 -> 101947.49
A21: 10 | B21: Revestimento de teto | C21: 0.035 | D21: =$B$5*$B$7*$B$8*C21 -> 713632.42
A22: 11 | B22: Revestimento interno | C22: 0.12 | D22: =$B$5*$B$7*$B$8*C22 -> 2446739.7
A23: 12 | B23: Revestimento externo | C23: 0.07 | D23: =$B$5*$B$7*$B$8*C23 -> 1427264.8
... A29: 18 | B29: Retenção de mão de obra | C29: 0.05 | D29: =$B$5*$B$7*$B$8*C29 -> 1019474.9
A30: TOTAL | C30: =SUM(C12:C29) -> 1 | D30: =SUM(D12:D29) -> 20389498

Sheet MOVIMENTAÇÃO_DE_TERRA
A2: MOVIMENTAÇÃO DE TERRA
A3: Data | B3: 45573
A4: Arquivo base | B4: -
A6: ESCAVAÇÃO VERTICAL DE SUBSOLO
A8: Descrição | B8: Área de subsolo (m²) | C8: Altura do subsolo (m) | D8: Volume total de escavação (m3) | E8: Preço unitário de escavação (R$ / m3) | F8: Valor total | G8: Observação
A9: Escavação subsolos | B9: =DADOS_INICIAIS!E27 -> 1631.9 | C9: =32.68-26.74 -> 5.94 | D9: =C9*B9 -> 9693.486 | E9: 30 | F9: =E9*D9*1.1 -> 319885.04 | G9: Escavação total do pavmento
A10: Escavação terreo e mezanino | B10: =B9 -> 1631.9 | C10: =39.44-32.68 -> 6.76 | D10: =(C10*B10)/2 -> 5515.822 | E10: 30 | F10: =E10*D10*1.1 -> 182022.13 | G10: Escavação triangular
A11: Bota-fora | D11: =(D9+D10)*1.3 -> 19772.1 | E11: 32 | F11: =E11*D11*1.1 -> 695977.93 | G11: 30% de empolamento
A12: TOTAL | F12: =SUM(F9:F11) -> 1197885.1
A14: REBAIXAMENTO DE LENÇOL FREÁTICO
A16: Descrição | B16: Quantidade (dias) | E16: Preço unitário de rebaixamento (R$ / dias) | F16: Valor total | G16: Observação
A17: Rebaixamento de lençol | B17: 160 | E17: 200 | F17: =B17*E17*1.1 -> 35200 | G17: Quantidade do orçamento executivo
A18: TOTAL | F18: =SUM(F17:F17) -> 35200
A20: ESCAVAÇÃO E REATERRO DE VALAS
A22: Descrição | B22: Parâmetro | D22: Volume total de escavação (m3) | E22: Preço unitário (R$ / m3) | F22: Valor total | G22: Observação
A23: Escavação mecanizada para blocos e baldrames | B23: 1.2 | C23: m³ / Vol infra | D23: =B23*INFRAESTRUTURA!D29 -> 587.484 | E23: 45 | F23: =E23*D23*1.1 -> 29080.458 | G23: Custo do orçamento executivo
A24: Reaterro para blocos e baldrames | B24: 0.6 | C24: m³ / Vol Escavação | D24: =D23-INFRAESTRUTURA!D29 -> 97.914 | E24: 12 | F24: =E24*D24*1.1 -> 1292.4648 | G24: Custo do orçamento executivo
A25: Movimentação de bota-fora | B25: 1.3 | D25: =(D23-D24)*B25 -> 636.441 | E25: 35 | F25: =E25*D25*1.1 -> 24502.979 | G25: Custo do orçamento executivo
A26: Movimentação de terra das estacas | B26: 1.3 | C26: m³ | D26: =INFRAESTRUTURA!D19 -> 1230.0403 | E26: 35 | F26: =E26*D26*B26*1.1 -> 61563.519 | G26: Custo do orçamento executivo
A27: TOTAL | F27: =SUM(F23:F26) -> 116439.42
A29: REGULARIZAÇÃO E APILOAMENTO DE FUNDO DE VALAS
A31: Descrição | B31: Parâmetro | D31: Área de lastro (m²) | E31: Preço unitário (R$ / m2) | F31: Valor total | G31: Observação
A32: Lastro de concreto magro e=5cm | B32: 0.35 | C32: m² / APE | D32: =B32*DADOS_INICIAIS!E27 -> 571.165 | E32: 22 | F32: =E32*D32*1.1 -> 13822.193 | G32: Indice do orçamento executivo | H32: =F32/DADOS_INICIAIS!E27 -> 8.47
A33: Lastro de brita (piso) e=5cm | B33: 0.95 | C33: m² / APE | D33: =B33*DADOS_INICIAIS!E28 -> 148.2285 | E33: 8 | F33: =E33*D33*1.1 -> 1304.4108 | G33: Indice do orçamento executivo | H33: =F33/DADOS_INICIAIS!E28 -> 8.36
A34: TOTAL | F34: =SUM(F32:F33) -> 15126.604
A36: TOTAL MOVIMENTAÇÃO DE TERRA | F36: =F12+F18+F27+F34 -> 1364651.1 | G36: =F36/DADOS_INICIAIS!E9 -> 78.100205

Sheet CONTENÇÕES
A3: CONTENÇÃO
A4: Data
A5: Arquivo base
A7: CORTINA DE ESTACAS
A9: Descrição | B9: Parâmetro | D9: Quantidade | F9: Preço unitário | G9: Valor total
A10: Número de Estacas | B10: 0.15 | C10: un / APE | D10: =B10*DADOS_INICIAIS!E27 -> 244.785 | E10: un
A11: Estaca Hélice Continua Diâmetro 40 | B11: 0.1 | D11: =B11*$D$10 -> 24.4785 | E11: un
B12: 20 | C12: m/un | D12: =B12*D11 -> 489.57 | E12: m | G12: =F12*D12 -> 0
A13: Estaca Hélice Continua Diâmetro 50 | B13: 0.5 | D13: =B13*$D$10 -> 122.3925 | E13: un
B14: 20 | C14: m/un | D14: =B14*D13 -> 2447.85 | E14: m | G14: =F14*D14 -> 0
A15: Estaca Hélice Continua Diâmetro 60 | B15: 0.4 | C15: un / APE | D15: =B15*$D$10 -> 97.914 | E15: un
B16: 20 | C16: m/un | D16: =B16*D15 -> 1958.28 | E16: m | G16: =F16*D16 -> 0
A17: Concreto | B17: =(PI()*0.4^2)/4*D14+(PI()*0.5^2)/4*D16+(PI()*0.6^2)/4*D12 -> 830.53594 | C17: un / APE | D17: =(PI()*0.4^2)/4*D14+(PI()*0.5^2)/4*D16+(PI()*0.6^2)/4*D12 -> 830.53594 | E17: m³ | G17: =F17*D17 -> 0
A18: Armação 6,3mm | B18: 1.6575131 | C18: kg / m³ | D18: =B18*D17 -> 1376.6242 | E18: kg | G18: =F18*D18 -> 0
A19: Armação 16mm | B19: 10.178338 | C19: kg / m³ | D19: =B19*D17 -> 8453.4751 | E19: kg | G19: =F19*D19 -> 0
A20: Mobilização | B20: 1 | C20: vb | D20: 1 | E20: vb | G20: =F20*D20 -> 0
A21: TOTAL | G21: =SUM(G10:G20) -> 0
A23: PAREDE DE CONCRETO
A25: Descrição | B25: Parâmetro | D25: Quantidade | F25: Preço unitário | G25: Valor total
A26: Fabricação, montagem e desmontagem de forma para blocos e baldrames resinado | B26: 2.1 | C26: m² / APE | D26: =B26*DADOS_INICIAIS!E27 -> 3426.99 | E26: m² | G26: =F26*D26 -> 0
A27: Concreto | B27: 0.65 | C27: m³ / APE | D27: =B27*DADOS_INICIAIS!E27 -> 1060.735 | E27: m³ | G27: =F27*D27 -> 0
A28: Armação | B28: 110 | C28: kg / m³ | D28: =B28*D27 -> 116680.85 | E28: kg | G28: =F28*D28 -> 0
A29: Mão de obra | B29: =SUPRAESTRUTURA!B15*1.5 -> 360 | C29: R$ / APE | D29: =DADOS_INICIAIS!E27 -> 1631.9 | E29: m² | F29: =B29 -> 360 | G29: =F29*D29 -> 587484
A30: TOTAL | G30: =SUM(G26:G29) -> 587484
A33: PAREDE DIAFRAGMA
A35: Descrição | B35: Parâmetro | D35: Quantidade | F35: Preço unitário | G35: Valor total
A36: Fabricação, montagem e desmontagem de forma para blocos e baldrames resinado | B36: 2.1 | C36: m² / APE | D36: =B36*DADOS_INICIAIS!E37 -> 0 | E36: m² | G36: =F36*D36 -> 0
A37: Concreto | B37: 0.65 | C37: m³ / APE | D37: =B37*DADOS_INICIAIS!E37 -> 0 | E37: m³ | G37: =F37*D37 -> 0
A38: Armação | B38: 110 | C38: kg / m³ | D38: =B38*D37 -> 0 | E38: kg | G38: =F38*D38 -> 0
A39: Mão de obra | B39: =SUPRAESTRUTURA!B72*1.5 -> 0 | C39: R$ / APE | D39: =DADOS_INICIAIS!E37 -> 0 | E39: m² | F39: =B39 -> 0 | G39: =F39*D39 -> 0
A40: TOTAL | G40: =SUM(G36:G39) -> 0
A46: TOTAL INFRAESTRUTURA | G46: =G21+G30 -> 587484 | H46: =G46/DADOS_INICIAIS!E9 -> 33.622235

Sheet INFRAESTRUTURA
A3: INFRAESTRUTURA
A4: Data | B4: 45573
A5: Arquivo base | B5: -
A7: FUNDAÇÃO PROFUNDA
A9: Descrição | B9: Parâmetro | D9: Quantidade | F9: Preço unitário | G9: Valor total | H9: Observação
A10: Número de Estacas | B10: 0.1 | C10: un / APE | D10: =ROUNDUP(B10*DADOS_INICIAIS!E27,0) -> 164 | E10: un
A11: Estaca Hélice Continua Diâmetro 40 | B11: 0 | D11: =ROUND(B11*D10,0) -> 0 | E11: un
B12: 20 | C12: m/un | D12: =B12*D11 -> 0 | E12: m | F12: 70 | G12: =F12*D12*1.1 -> 0
A13: Estaca Hélice Continua Diâmetro 50 | B13: 0.4 | D13: =ROUND(B13*D10,0) -> 66 | E13: un
B14: 20 | C14: m/un | D14: =B14*D13 -> 1320 | E14: m | F14: 90 | G14: =F14*D14 -> 118800
A15: Estaca Hélice Continua Diâmetro 60 | B15: 0.5 | C15: un / APE | D15: =ROUND(B15*D10,0) -> 82 | E15: un
B16: 22 | C16: m/un | D16: =B16*D15 -> 1804 | E16: m | F16: 105 | G16: =F16*D16 -> 189420
A17: Estaca Hélice Continua Diâmetro 80 | B17: 0.1 | C17: un / APE | D17: =ROUND(B17*D10,0) -> 16 | E17: un
B18: 22 | C18: m/un | D18: =B18*D17 -> 352 | E18: m | F18: 120 | G18: =F18*D18 -> 42240
A19: Concreto (40 Mpa) | B19: 1.3 | C19: perda | D19: =(((PI()*(0.4^2)/4)*D12)+((PI()*(0.5^2)/4)*D14)+((PI()*(0.6^2)/4)*D16)+((PI()*(0.8^2)/4)*D18))*B19 -> 1230.0403 | E19: m³ | F19: =535+45 -> 580 | G19: =F19*D19*B19 -> 927450.41
A20: Armação | B20: 17.4 | C20: kg / m³ | D20: =B20*D19 -> 21402.702 | E20: kg | F20: 7.62 | G20: =F20*D20 -> 163088.59
A21: Mobilização | B21: 1 | C21: vb | D21: 1 | E21: vb | F21: 10000 | G21: =F21*D21 -> 10000
A22: Apoio e arrasamento de estacas | D22: =D10 -> 164 | E22: un | F22: 300 | H22: Empreitada Global
A23: TOTAL | G23: =SUM(G10:G22) -> 1450999
A25: FUNDAÇÃO RASA
A27: Descrição | B27: Parâmetro | D27: Quantidade | F27: Preço unitário | G27: Valor total | H27: Observação
A28: Fabricação, montagem e desmontagem de forma para blocos e baldrames resinado | B28: 0.8 | C28: m² / APE | D28: =B28*DADOS_INICIAIS!E27 -> 1305.52 | E28: m² | F28: 68 | G28: =F28*D28 -> 88775.36
A29: Concreto (40 Mpa) | B29: 0.3 | C29: m³ / APE | D29: =B29*DADOS_INICIAIS!E27 -> 489.57 | E29: m³ | F29: =535+45 -> 580 | G29: =F29*D29*1.05 -> 298148.13
A30: Armação | B30: 130 | C30: kg / m³ | D30: =B30*D29 -> 63644.1 | E30: kg | F30: 7.62 | G30: =F30*D30 -> 484968.04
A31: Mão de obra | B31: =SUPRAESTRUTURA!B15*1.5 -> 360 | C31: R$ / APE | D31: =DADOS_INICIAIS!E27 -> 1631.9 | E31: m² | F31: =B31 -> 360 | H31: Empreitada Global
A32: TOTAL | G32: =SUM(G28:G31) -> 871891.53
A35: TOTAL INFRAESTRUTURA | G35: =G23+G32 -> 2322890.5 | H35: =G35/DADOS_INICIAIS!E9 -> 132.9411

Sheet CONTENÇÃO
A3: INFRAESTRUTURA
A4: Data | B4: 45573
A5: Arquivo base | B5: -
A7: PAREDE DIAFRAGMA
A9: Descrição | B9: Parâmetro | D9: Quantidade | F9: Preço unitário | G9: Valor total | H9: Observação
A10: Perímetro de contenção | D10: 168.348 | E10: m | G10: =F10*D10*1.05 -> 0
A11: Area de contenção (acima da terra) | D11: =D10*14 -> 2356.872 | E11: m² | G11: =F11*D11*1.05 -> 0
A12: Execução de mureta guia | D12: =D10 -> 168.348 | E12: m | F12: 710 | G12: =F12*D12*1.1 -> 131479.79
A13: Serviço especializado parede diafragma | D13: =D11 -> 2356.872 | E13: m² | F13: 270 | G13: =F13*D13 -> 636355.44
A14: Mobilização para parede diagragma | D14: 1 | E14: vb | F14: 18000 | G14: =F14 -> 18000
A15: Armação | B15: 112 | C15: kg / m³ | D15: =B15*D16 -> 113506.96 | E15: kg | F15: =7.62*1.1 -> 8.382 | G15: =F15*D15 -> 951415.3
A16: Concreto (30 Mpa) COM CRISTALIZANTE | B16: 0.43 | C16: espessura | D16: =B16*D11 -> 1013.455 | E16: m³ | F16: 610 | G16: =F16*D16*1.05 -> 649117.9 | H16: 5% de perda
A17: Tratamento em juntas de concretagem com fita hidroexpansiva | D17: 969.34 | E17: m | F17: 41.5 | G17: =F17*D17*1.1 -> 44250.371
A18: Atirantamentos | D18: 1 | E18: vb | F18: 210 | G18: =F18*D18*D11*1.1 -> 544437.43
A19: TOTAL | G19: =SUM(G10:G18) -> 2975056.2
A21: PAREDE DE CONCRETO
A23: Descrição | B23: Parâmetro | D23: Quantidade | F23: Preço unitário | G23: Valor total | H23: Observação
A24: Perímetro de contenção | D24: 33.25 | E24: m | G24: =F24*D24*1.05 -> 0
A25: Fabricação, montagem e desmontagem de forma para parede de concreto | B25: 3 | C25: altura | D25: =[4]QUANTITATIVO_ESTRUTURA!$D$24 -> 281.02294 | E25: m² | F25: 68 | G25: =F25*D25*1.05 -> 20065.038
A26: Concreto (40 Mpa) | B26: 0.2 | C26: espessura | D26: =[4]QUANTITATIVO_ESTRUTURA!$E$24 -> 42.15237 | E26: m³ | F26: =477+40 -> 517 | G26: =F26*D26*1.05*1.05 -> 24026.535
A27: Armação | B27: =D27/D26 -> 65.696239 | C27: kg / m³ | D27: =[4]QUANTITATIVO_ESTRUTURA!$F$24 -> 2769.2522 | E27: kg | F27: 7.62 | G27: =F27*D27*1.05 -> 22156.787
A28: TOTAL | G28: =SUM(G25:G27) -> 66248.359
A31: TOTAL CONTENÇÃO | G31: =G19 -> 2975056.2 | H31: =G31/DADOS_INICIAIS!E9 -> 170.26513
H33: =H31/1.1 -> 154.78648

Sheet SUPRAESTRUTURA
A3: SUPRAESTRUTURA
A4: Data | B4: 45573
A5: Arquivo base | B5: -
A7: SUPRAESTRUTURA - LAJE MACIÇA
A9: Descrição | B9: Parâmetro | D9: Quantidade | F9: Preço unitário | G9: Valor total | H9: Observação
A10: Fabricação forma | B10: 3 | C10: Jogos | D10: =(D11/DADOS_INICIAIS!$E$17)*B10 -> 8190.5063 | E10: m² | F10: 110 | G10: =F10*D10*1.1 -> 991051.26
A11: Montagem de forma | B11: 2.5 | C11: m² / AC | D11: =B11*DADOS_INICIAIS!$E$9 -> 43682.7 | E11: m² | F11: 2.5 | G11: =F11*D11*1.1 -> 120127.43
A12: Escoramento | B12: 4 | C12: un / AE | D12: =ROUNDUP(B12*DADOS_INICIAIS!$E$27*B10,0) -> 19583 | E12: un | F12: =17 -> 17 | G12: =F12*D12*1.1 -> 366202.1
A13: Concreto | B13: 0.22 | C13: m³ / AC | D13: =B13*DADOS_INICIAIS!$E$9 -> 3844.0776 | E13: m³ | F13: =535+45 -> 580 | G13: =F13*D13*1.05*1.1 -> 2575147.6
A14: Armadura Convencional para Estrutura | B14: 110 | C14: kg / m³ | D14: =D13*B14 -> 422848.54 | E14: kg | F14: 7.62 | G14: =F14*D14*1.1 -> 3544316.4
A15: Mão de obra - estrutura em concreto armado | B15: 240 | C15: R$ / AC | D15: =DADOS_INICIAIS!$E$9 -> 17473.08 | E15: m² | F15: =B15 -> 240 | G15: =F15*D15*1.1 -> 4612893.1
A16: Perfuração de vigas | B16: 5300 | C16: R$ / NP | D16: 1 | E16: vb | F16: =B16*DADOS_INICIAIS!$E$17 -> 84800 | G16: =F16*D16*1.1 -> 93280 | H16: Coeficiente originário do Gran Torino (R$ 160,00/un) | I16: Nova utiliza a verba de 1.500,00 por pav
A17: TOTAL | G17: =SUM(G10:G16) -> 12303018 | K17: =4160+1440+1120+2880+4800+91680+4000 -> 110080 | L17: =K17/21 -> 5241.9048
A19: SUPRAESTRUTURA - LAJE CUBETAS
A21: Descrição | B21: Parâmetro | D21: Quantidade | F21: Preço unitário | G21: Valor total | H21: Observação
A22: Fabricação forma | B22: 2 | C22: Jogos | D22: =(D23/DADOS_INICIAIS!$E$17)*B22 -> 4368.27 | E22: m² | F22: 110 | G22: =F22*D22*1.1 -> 528560.67
A23: Montagem de forma | B23: 2 | C23: m² / AC | D23: =B23*DADOS_INICIAIS!$E$9 -> 34946.16 | E23: m² | F23: 2.5 | G23: =F23*D23*1.1 -> 96101.94
A24: Escoramento proprio | B24: 3 | C24: un / APT*NPT | D24: =ROUNDUP(B24*DADOS_INICIAIS!$E$27*B22,0) -> 9792 | E24: un | F24: 3.5 | G24: =F24*D24*1.1 -> 37699.2
A25: Cubetas proprias | B25: 1.5 | C25: R$ / AC | D25: 1 | E25: vb | F25: =B25*DADOS_INICIAIS!$E$9 -> 26209.62 | G25: =F25*D25*1.1 -> 28830.582
A26: Concreto | B26: 0.18 | C26: m³ / AC | D26: =B26*DADOS_INICIAIS!$E$9 -> 3145.1544 | E26: m³ | F26: =535+45 -> 580 | G26: =F26*D26*1.05 -> 1915399
A27: Cristalizante (reservatorios) | B27: 0.2 | D27: =B27*D26 -> 629.03088 | E27: m³ | F27: =1.22*F26-F26 -> 127.6 | G27: =F27*D27*1.05*1.1 -> 92705.313
A28: Armadura Convencional para Estrutura | B28: 100 | C28: kg / m³ | D28: =B28*(D27+D26) -> 377418.53 | E28: kg | F28: 7.62 | G28: =F28*D28 -> 2875929.2
A29: Mão de obra - estrutura em concreto armado | B29: 280 | C29: R$ / AC | D29: =DADOS_INICIAIS!$E$9 -> 17473.08 | E29: m² | F29: =B29 -> 280
A30: Piso sobre solo | D30: =DADOS_INICIAIS!E27 -> 1631.9 | E30: m² | F30: 25 | G30: =F30*D30*1.1 -> 44877.25
A31: Perfuração de vigas | B31: 5300 | C31: R$ / NP | D31: 1 | E31: vb | F31: =B31*DADOS_INICIAIS!$E$17 -> 84800 | G31: =F31*D31*1.1 -> 93280 | H31: Coeficiente originário do Gran Torino (R$ 160,00/un)
A32: TOTAL | G32: =SUM(G22:G31) -> 5713383.2
A34: SUPRAESTRUTURA - LAJE TRELIÇADA
A36: Descrição | B36: Parâmetro | D36: Quantidade | F36: Preço unitário | G36: Valor total | H36: Observação
A37: Fabricação forma | B37: 2 | C37: Jogos | D37: =(D38/DADOS_INICIAIS!$E$17)*B37 -> 0 | E37: m² | F37: 85 | G37: =F37*D37*1.1 -> 0
A38: Montagem de forma | B38: 2.1 | C38: m² / AC | D38: =B38*DADOS_INICIAIS!E40 -> 0 | E38: m² | F38: 1.5 | G38: =F38*D38*1.1 -> 0
A39: Escoramento - Torre | B39: 2 | C39: un / APT*NPT | D39: =B39*DADOS_INICIAIS!E49*DADOS_INICIAIS!E46 -> 0 | E39: un | F39: 17 | G39: =F39*D39*1.1 -> 0
A40: Escoramento - Embasamento | B40: 2 | C40: un / AE | D40: =B40*DADOS_INICIAIS!E52 -> 0 | E40: un | F40: 17 | G40: =F40*D40*1.1 -> 0
A41: Cubetas | B41: 25 | C41: R$ / AC | D41: =B41*DADOS_INICIAIS!E40 -> 0 | E41: m³ | F41: =B41 -> 25 | G41: =F41*D41*1.1 -> 0
A42: Concreto | B42: 0.25 | C42: m³ / AC | D42: =B42*DADOS_INICIAIS!E40 -> 0 | E42: m³ | F42: =575 -> 575 | G42: =F42*D42*1.05*1.1 -> 0
A43: Armadura Convencional para Estrutura | B43: 110 | C43: kg / m³ | D43: =D42*B43 -> 0 | E43: kg | F43: 7.25 | G43: =F43*D43*1.1 -> 0
A44: Mão de obra - estrutura em concreto armado | B44: 240 | C44: R$ / AC | D44: =DADOS_INICIAIS!E40 -> 0 | E44: m² | F44: =B44 -> 240 | G44: =F44*D44*1.1 -> 0
A45: Perfuração de vigas | B45: 5300 | C45: R$ / NP | D45: 1 | E45: vb | F45: =B45*DADOS_INICIAIS!E45 -> 0 | G45: =F45*D45*1.1 -> 0 | H45: Coeficiente originário do Gran Torino (R$ 160,00/un)
A46: TOTAL | G46: =SUM(G37:G45) -> 0
A48: SUPRAESTRUTURA - LAJE PROTENDIDA
A50: Descrição | B50: Parâmetro | D50: Quantidade | F50: Preço unitário | G50: Valor total | H50: Observação
...

Sheet ALVENARIA
A3: PAREDES E PAINÉIS
A4: Data | B4: 45569
A5: Arquivo base | B5: -
A7: ALVENARIA
A9: Descrição | B9: Parâmetro | D9: Quantidade | F9: Preço unitário | G9: Valor total | H9: Observação
A10: Alvenaria 9cm | B10: 1 | C10: m² / AE | D10: =[5]Planilha1!$O$545 -> 8231.37 | E10: m² | F10: 17.8 | G10: =F10*D10*1.1 -> 161170.22
A11: Alvenaria 11,5cm | B11: 0.4 | C11: m² / AL | D11: =[5]Planilha1!$O$546 -> 8028.73 | E11: m² | F11: 28.9 | G11: =F11*D11*1.1 -> 255233.33
A12: Alvenaria 14cm | B12: 1.65 | C12: m² / APT*(NPT+2ND) | D12: =[5]Planilha1!$O$547 -> 9287.53 | E12: m² | F12: 30.2 | G12: =F12*D12*1.1 -> 308531.75
A13: Alvenaria bloco concreto celular | B13: 0.2 | C13: m² / AC | D13: =[5]Planilha1!$O$544 -> 1340.85 | E13: m² | F13: =60 -> 60 | G13: =F13*D13*1.1 -> 88496.1
A14: Cobogó | B14: =0.4*0.4 -> 0.16 | C14: m² / UN | D14: =723*B14 -> 115.68 | E14: m² | F14: =22+2.5 -> 24.5 | G14: =F14*D14*1.1 -> 3117.576
A15: Alvenaria refratárias | B15: 1.75 | C15: m² * CHU | D15: =B15*DADOS_INICIAIS!$E$16 -> 154 | E15: un | F15: 210 | G15: =F15*D15*1.1 -> 35574
A16: Serviços complementares | B16: 12.5 | C16: R$ / m² | D16: =D10+D11+D12+D13 -> 26888.48 | E16: m² | F16: =B16 -> 12.5 | G16: =F16*D16*1.1 -> 369716.6
A17: Mão de obra | B17: 35 | C17: R$ / m² | D17: =D10+D11+D12+D13 -> 26888.48 | E17: m² | F17: 35
A18: TOTAL | G18: =SUM(G10:G17) -> 1221839.6 | K18: =4160+1440+1120+2880+4800+91680+4000 -> 110080 | L18: =K18/21 -> 5241.9048
A20: ALVENARIA - DRTWALL
A22: Descrição | B22: Parâmetro | D22: Quantidade | F22: Preço unitário | G22: Valor total | H22: Observação
A23: Alvenaria embasamento | B23: 1 | C23: m² / AE | D23: =B23*DADOS_INICIAIS!$E$24 -> 6375.09 | E23: m² | F23: 45 | G23: =F23*D23*1.1 -> 315566.96
A24: Alvenaria lazer | B24: 0.4 | C24: m² / AL | D24: =B24*DADOS_INICIAIS!$E$23 -> 0 | E24: m² | F24: 45 | G24: =F24*D24*1.1 -> 0
A25: Alvenaria tipo | B25: 1.62 | C25: m² / APT*(NPT+2ND) | D25: =B25*(DADOS_INICIAIS!$E$21*(DADOS_INICIAIS!$E$18+DADOS_INICIAIS!$E$19))*0.3 -> 4752.8613 | E25: un | F25: 45 | G25: =F25*D25*1.1 -> 235266.63
A26: Drywall tipo | B26: 1.65 | C26: m² / APT*(NPT+2ND) | D26: =B26*(DADOS_INICIAIS!$E$21*(DADOS_INICIAIS!$E$18+DADOS_INICIAIS!$E$19))*0.7 -> 11295.38 | F26: 220 | G26: =F26*D26*1.1 -> 2733482 | J26: =D26/(D31+D26) -> 0.42417292
A27: Alvenaria escadas | B27: 0.2 | C27: m² / AC | D27: =B27*DADOS_INICIAIS!$E$9 -> 3494.616 | E27: un | F27: 70 | G27: =F27*D27*1.1 -> 269085.43 | J27: =1-J26 -> 0.57582708
A28: Alvenaria cobertura / reservatório | B28: 0.8 | C28: m² / APT | D28: =B28*DADOS_INICIAIS!$E$21 -> 711.24 | E28: m³ | F28: 45 | G28: =F28*D28*1.1 -> 35206.38
A29: Alvenaria refratárias | B29: 1.75 | C29: m² * CHU | D29: ='SISTEMAS ESPECIAIS'!B11 -> 88 | E29: un | F29: 210
A30: Churrasqueiras pré-moldadas | D30: =D29 -> 88 | E30: un | F30: 1800 | G30: =F30*D30*1.1 -> 174240
A31: Serviços complementares | B31: 12.5 | C31: R$ / m² | D31: =D24+D25+D23+D27+D28 -> 15333.807 | E31: kg | F31: =B31 -> 12.5 | G31: =F31*D31*1.1 -> 210839.85
A32: Mão de obra | B32: 35 | C32: R$ / m² | D32: =D24+D25+D23+D27+D28 -> 15333.807 | E32: m² | F32: 35 | G32: =F32*D32*1.1 -> 590351.58
A33: TOTAL | G33: =SUM(G23:G32) -> 4564038.9
A36: TOTAL ALVENARIA | G36: =G18 -> 1221839.6 | H36: =G36/DADOS_INICIAIS!E9 -> 69.926972
G39: =G36/1.1 -> 1110763.2 | H39: =G39/DADOS_INICIAIS!E9 -> 63.569974

Sheet INSTALAÇÕES
A2: INSTALAÇÕES
A4: INSTALAÇÕES ELÉTRICAS
A6: Descrição | B6: Parâmetro | D6: Valor total
A7: Entrada de Energia | B7: 5 | C7: R$ / AC | D7: =B7*DADOS_INICIAIS!$E$9*1.1 -> 96101.94
A8: Eletrodutos e Eletrocalhas | B8: 17 | C8: R$ / AC | D8: =B8*DADOS_INICIAIS!$E$9*1.1 -> 326746.6
A9: Cabos e Fiações | B9: 30 | C9: R$ / AC | D9: =B9*DADOS_INICIAIS!$E$9*1.1 -> 576611.64
A10: Quadros e Disjuntores | B10: 22 | C10: R$ / AC | D10: =B10*DADOS_INICIAIS!$E$9*1.1 -> 422848.54
A11: Acabamentos Elétricos | B11: 12 | C11: R$ / AC | D11: =B11*DADOS_INICIAIS!$E$9*1.1 -> 230644.66
A12: Equipamentos e Iluminação | B12: 3 | C12: R$ / AC | D12: =B12*DADOS_INICIAIS!$E$9*1.1 -> 57661.164
A13: Mão de Obra para Instalações Elétricas | B13: 60 | C13: R$ / AC
A14: TOTAL | D14: =SUM(D7:D13) -> 1710614.5
A16: INSTALAÇÕES HIDROSSANITÁRIAS
A18: Descrição | B18: Parâmetro | D18: Valor total
A19: Instalações de Água Fria | B19: 25 | C19: R$ / AC | D19: =B19*DADOS_INICIAIS!$E$9*1.1 -> 480509.7
A20: Instalações de Água Quente | B20: 24 | C20: R$ / AC | D20: =B20*DADOS_INICIAIS!$E$9*1.1 -> 461289.31
A21: Instalações de Águas Pluviais | B21: 4 | C21: R$ / AC | D21: =B21*DADOS_INICIAIS!$E$9*1.1 -> 76881.552
A22: Instalações Sanitárias | B22: 15 | C22: R$ / AC | D22: =B22*DADOS_INICIAIS!$E$9*1.1 -> 288305.82
A23: Louças e Metais | B23: 20 | C23: R$ / AC | D23: =B23*DADOS_INICIAIS!$E$9*1.1 -> 384407.76
A24: Mão de Obra para Instalações Hidráulicas | B24: 55 | C24: R$ / AC
A25: TOTAL | D25: =SUM(D19:D24) -> 1691394.1
A27: INSTALAÇÕES PREVENTIVAS E GLP
A29: Descrição | B29: Parâmetro | D29: Valor total
A30: Instalações Preventivas | B30: 12 | C30: R$ / AC | D30: =B30*DADOS_INICIAIS!$E$9*1.1 -> 230644.66
A31: Instalações de GLP | B31: 15 | C31: R$ / AC | D31: =B31*DADOS_INICIAIS!$E$9*1.1 -> 288305.82
A32: Instalações de Proteção e Aterramento - SPDA | B32: 4 | C32: R$ / AC | D32: =B32*DADOS_INICIAIS!$E$9*1.1 -> 76881.552
A33: TOTAL | D33: =SUM(D30:D32) -> 595832.03
A35: TOTAL INSTALAÇÕES | D35: =D14+D25+D33 -> 3997840.7 | E35: =D35/DADOS_INICIAIS!E9 -> 228.8
E37: =E35/1.1 -> 208

Sheet SISTEMAS ESPECIAIS
A2: SISTEMAS ESPECIAIS
A4: CLIMATIZAÇÃO, EXAUSTÃO MECÂNICA E PRESSURIZAÇÃO
A6: Descrição | B6: Quantidade | C6: Preço Unitário | D6: Valor total | G6: TERREO | H6: MEZANINO | I6: 2 PAV | J6: TIPO | M6: TIPO 6 | N6: TIPO 7 | O6: ATICO
A7: Infraestrutura para Instalação de Ar Condicionado | B7: =G7+H7+I7+J7*10+K7 -> 303 | C7: 1500 | D7: =B7*C7*1.1 -> 499950 | G7: 2 | H7: =4+3+1 -> 8 | I7: 26 | J7: 26 | K7: 7 | M7: 8 | N7: 8 | O7: 1
A8: Instalação de Ar Condicionado | B8: =G8+H8+I8+J8*10+K8 -> 12 | C8: 5000 | D8: =B8*C8*1.1 -> 66000 | G8: 0 | H8: 5 | I8: 0 | J8: 0 | K8: 7 | O8: 1
A9: Aquecedores de passagem | B9: =DADOS_INICIAIS!E11 -> 176 | C9: 1400
A10: Ventokit | B10: =G10+H10+I10+J10*10+K10 -> 121 | C10: 900 | D10: =B10*C10*1.1 -> 119790 | G10: 2 | H10: 8 | I10: 10 | J10: 10 | K10: 1 | M10: 8 | N10: 8 | O10: 3
A11: Churrasqueiras | B11: =G11+H11+I11+J11*10+K11 -> 88 | C11: 2100 | D11: =B11*C11*1.1 -> 203280 | G11: 0 | H11: 0 | I11: 7 | J11: 8 | K11: 1 | M11: 4 | N11: 4 | O11: 1
A12: TOTAL | D12: =SUM(D7:D11) -> 889020
A14: COMUNICAÇÃO
A16: Descrição | B16: Parâmetro | D16: Valor total
A17: CFTV | B17: 5 | C17: R$ / AC | D17: =B17*DADOS_INICIAIS!$E$9*1.1 -> 96101.94
A18: Interfone | B18: 6 | C18: R$ / AC | D18: =B18*DADOS_INICIAIS!$E$9*1.1 -> 115322.33
A19: TV e internet | B19: 12 | C19: R$ / AC | D19: =B19*DADOS_INICIAIS!$E$9*1.1 -> 230644.66
A20: Automação, telecomunicação, som e sistemas de segurança | B20: 6 | C20: R$ / AC | D20: =B20*DADOS_INICIAIS!$E$9*1.1 -> 115322.33
A21: TOTAL | D21: =SUM(D17:D20) -> 557391.25
A23: EQUIPAMENTOS
A25: Descrição | B25: Quantidade | C25: Preço Unitário | D25: Valor total
A26: Elevadores | B26: 3 | C26: 280000 | D26: =B26*C26*1.1 -> 924000
A27: Plataforma vertical | B27: 1 | C27: 55000 | D27: =B27*C27*1.1 -> 60500
A28: Grupo de geradores | B28: 1 | C28: 110000 | D28: =B28*C28*1.1 -> 121000
A29: Subestação | B29: 1 | C29: 250000 | D29: =B29*C29*1.1 -> 275000
A30: Escada pressurizada | B30: 0 | C30: =50*DADOS_INICIAIS!E9 -> 873654 | D30: =B30*C30*1.1 -> 0
A31: Bombas | B31: 0 | C31: 10000 | D31: =B31*C31*1.1 -> 0
A32: Trataamento de esgoto | B32: 0 | C32: 110000 | D32: =B32*C32*1.1 -> 0
A33: Infra de carro elétrico | B33: =DADOS_INICIAIS!E11 -> 176 | C33: 550 | D33: =B33*C33*1.1 -> 106480
A34: Equipamento d ecarro eletrico | B34: 0 | C34: 10500 | D34: =B34*C34*1.1 -> 0
A35: Equipamentos para Sauna | B35: 0 | C35: 8500 | D35: =B35*C35*1.1 -> 0
A36: Equipamentos para Piscina | B36: 2 | C36: 25000 | D36: =B36*C36*1.1 -> 55000
A37: TOTAL | D37: =SUM(D26:D36) -> 1541980
A39: OUTROS SISTEMAS ESPECIAIS
A41: Descrição | B41: Parâmetro | D41: Valor total
A42: Outros sistemas | B42: 20 | C42: R$ / AC | D42: =B42*DADOS_INICIAIS!E9*1.1 -> 384407.76
A43: TOTAL | D43: =SUM(D42:D42) -> 384407.76
A45: TOTAL SISTEMAS ESPECIAIS | D45: =D12+D21+D37+D43 -> 3372799 | E45: =D45/DADOS_INICIAIS!E9 -> 193.0283

Sheet IMPERMEABILIZAÇÃO
A3: IMPERMEABILIZAÇÃO
A4: Data | B4: 45573
A5: Arquivo base | B5: -
A7: ALVENARIA
A9: Descrição | B9: Parâmetro | D9: Quantidade | F9: Preço unitário | G9: Valor total | H9: Observação
A10: Regularização de Superfície | B10: 25 | C10: R$ / m² | D10: =D14+D15 -> 4368.27 | E10: m² | F10: 7 | G10: =F10*D10*1.1 -> 33635.679
A11: Poço do elevador | B11: 45 | C11: R$ / m² | D11: =((3.8)+(1.9+1.85)*2*1.8)*3 -> 51.9 | E11: m² | F11: 41 | G11: =F11*D11*1.1 -> 2340.69
A12: Baldrames | B12: 30 | C12: R$ / m² | D12: =INFRAESTRUTURA!D28 -> 1305.52 | E12: m² | F12: 35 | G12: =F12*D12*1.1 -> 50262.52
A13: Ralos | B13: 0.8 | C13: R$ / AC | D13: 1 | E13: vb | F13: =B13*DADOS_INICIAIS!$E$9 -> 13978.464 | G13: =F13*D13*1.1 -> 15376.31
A14: Impermeabilizações cimenticias | B14: 0.15 | C14: m² / AC | D14: =B14*DADOS_INICIAIS!E9 -> 2620.962 | E14: m² | F14: 40 | G14: =F14*D14 -> 104838.48
A15: Impermeabilizações com manta asfaltica | B15: 0.1 | C15: m² / AC | D15: =B15*DADOS_INICIAIS!E9 -> 1747.308 | E15: m² | F15: 120 | G15: =F15*D15*1.1 -> 230644.66
A16: Impermeabilização de peitoril | B16: 0.08 | C16: m² / AC | D16: =B16*DADOS_INICIAIS!E9 -> 1397.8464 | E16: m² | F16: 50 | G16: =F16*D16*1.1 -> 76881.552
A17: Proteção Mecânica | B17: 28 | C17: R$ / m² | D17: =D15 -> 1747.308 | E17: m² | F17: 16 | G17: =F17*D17*1.1 -> 30752.621
A18: TOTAL | G18: =SUM(G10:G17) -> 544732.51 | K18: =4160+1440+1120+2880+4800+91680+4000 -> 110080 | L18: =K18/21 -> 5241.9048
A20: TOTAL IMPERMEABILIZAÇÃO | G20: =G18 -> 544732.51 | H20: =G20/DADOS_INICIAIS!E9 -> 31.175529
H23: =H20/1.1 -> 28.34139

Sheet Rev. Internos Piso e Parede
A2: ORÇAMENTO PARAMÉTRICO GERENCIAMENTO EXECUTIVO
A7: Cliente | B7: Amalfi
A8: Obra | B8: San Felicce
A9: Data | B9: 45397
A10: Revisão | B10: R00
A12: REVESTIMENTOS INTERNOS EM PISO E PAREDE
J13: =SUM(G15:G17) -> 881940.54
A14: Descrição | B14: Quantidade | D14: Parâmetro | F14: Referência | G14: Valor total | J14: =G18+G19 -> 564602.74
A15: Polimento de piso | B15: ='Acabamentos de Piso e Parede'!B39 -> 4841.26 | C15: m² | D15: 14 | E15: R$ / m² | F15: Média | G15: =D15*B15*1.1 -> 74555.404
A16: Contrapiso | B16: =[6]Planilha1!$J$701+[6]Planilha1!$J$702 -> 11988.48 | C16: m² | D16: =B16/DADOS_INICIAIS!E9 -> 0.68611144 | E16: m² / AC | F16: Média | G16: =+B16*38*1.1 -> 501118.46
A17: Manta acústica | B17: =[6]Planilha1!$J$704 -> 11136.97 | C17: m² | D17: =B17/DADOS_INICIAIS!E9 -> 0.63737876 | E17: m² / AC | F17: Média | G17: =+B17*25*1.1 -> 306266.68
A18: Chapisco | B18: =B19 -> 26321.806 | C18: m² | D18: 1.7 | E18: m² / AC | F18: Média | G18: =+B18*2.5*1.1 -> 72384.967
A19: Reboco | B19: =DADOS_INICIAIS!E9*'Rev. Internos Piso e Parede'!D19-B20 -> 26321.806 | C19: m² | D19: 1.7 | E19: m² / AC | F19: Média | G19: =17*B19*1.1 -> 492217.77
A20: Estucamento | B20: =[7]Planilha1!$J$742+[7]Planilha1!$J$745+[7]Planilha1!$J$746+[7]Planilha1!$J$747 -> 3382.43 | C20: m² | E20: m² / AC | F20: Média | G20: =5*B20*1.1 -> 18603.365
A21: TOTAL | G21: =SUM(G15:G20) -> 1465146.6
A24: TOTAL REVESTIMENTOS | G24: =G21 -> 1465146.6 | H24: =G24/DADOS_INICIAIS!E9 -> 83.851653
H26: =H24/1.1 -> 76.228776

Sheet TETO
A3: REVESTIMENTOS E ACABAMENTOS DE TETO
A4: Data | B4: 45457
A5: Arquivo base | B5: -
A7: ALVENARIA
A9: Descrição | B9: Parâmetro | D9: Quantidade | F9: Preço unitário | G9: Valor total | H9: Observação
A10: Forro acartonado | B10: 0.4 | C10: m² / AC | D10: =B10*DADOS_INICIAIS!E9 -> 6989.232 | E10: m² | F10: 120 | G10: =F10*D10*1.1 -> 922578.62
A11: Negativo | B11: 1.2 | C11: m / FORRO | D11: =D10*B11 -> 8387.0784 | E11: m² | F11: 22 | G11: =F11*D11*1.1 -> 202967.3
A12: Estucamento | B12: 0.1 | C12: m² / AC | D12: =DADOS_INICIAIS!E9*B12 -> 1747.308 | E12: m² | F12: 5 | G12: =F12*D12*1.1 -> 9610.194
A13: Chapisco e reboco | B13: 0.3 | C13: m² / AC | D13: =B13*DADOS_INICIAIS!E9 -> 5241.924 | E13: m² | F13: 17.5 | G13: =F13*D13*1.05*1.1 -> 105952.39
A14: TOTAL | G14: =SUM(G10:G13) -> 1241108.5 | K14: =4160+1440+1120+2880+4800+91680+4000 -> 110080 | L14: =K14/21 -> 5241.9048
A16: TOTAL IMPERMEABILIZAÇÃO | G16: =G14 -> 1241108.5 | H16: =G16/DADOS_INICIAIS!E9 -> 71.02975
H19: =H16/1.1 -> 64.5725

Sheet Acabamentos de Piso e Parede
A2: ORÇAMENTO PARAMÉTRICO GERENCIAMENTO EXECUTIVO
A7: Cliente | B7: Amalfi
A8: Obra | B8: San Felicce
A9: Data | B9: 45397
A10: Revisão | B10: R00
A12: ACABAMENTOS EM PISO E PAREDE
A14: Descrição | B14: Quantidade | D14: Parâmetro | F14: Referência | G14: Valor total | I14: =B15+B16+B17+B18+B21+B22+B23+B24 -> 11840.77
A15: Porcelanato | B15: =B36-330.2*0.6-B22 -> 2195.33 | C15: m² | D15: 80 | E15: R$ / m² | F15: Média | G15: =+D15*B15*1.1 -> 193189.04
A16: Cerâmico | B16: =B37 -> 8758.87 | C16: m² | D16: 65 | E16: R$ / m² | F16: Média | G16: =+D16*B16*1.1 -> 626259.21
A17: Piso vinilico - MAT+MO | B17: =B40 -> 89.92 | C17: m² | D17: 180 | E17: R$ / m² | F17: Média | G17: =+D17*B17*1.1 -> 17804.16
A18: Grama sintética | B18: 49.1 | C18: m² | D18: 130 | E18: R$ / m² | F18: Média | G18: =+D18*B18*1.1 -> 7021.3
A19: Argila expandida | B19: =B42 -> 20.17 | C19: m² | D19: =0.1*(20*43.9) -> 87.8 | E19: R$ / m² | F19: Média | G19: =+D19*B19*1.1 -> 1948.0186
A20: Piso elevador granito | B20: =3.8*3 -> 11.4 | C20: m² | D20: 550 | E20: R$ / m² | F20: Média | G20: =+D20*B20*1.1 -> 6897
A21: Piscina | B21: =B43+B50+20 -> 155.29 | C21: m² | D21: 80 | E21: R$ / m² | F21: Média | G21: =+D21*B21*1.1 -> 13665.52
A22: Deck piscina - MAT + MO | B22: 154.7 | C22: m² | D22: 450 | E22: R$ / m² | F22: Média | G22: =+D22*B22*1.1 -> 76576.5
A23: Piso drenante | B23: 182.97 | C23: m² | D23: 80 | E23: R$ / m² | F23: Média | G23: =+D23*B23*1.1 -> 16101.36
A24: Ladrilho hidaraulico | B24: =B44 -> 254.59 | C24: m² | D24: 68 | E24: R$ / m² | F24: Média | G24: =+D24*B24*1.1 -> 19043.332
A25: Rodapés | B25: 1 | C25: vb | D25: 15 | E25: R$ / AC | F25: Média | G25: =D25*DADOS_INICIAIS!$E$9*1.1 -> 288305.82
A26: Soleiras | B26: =(497.91)*0.15 -> 74.6865 | C26: m² | D26: 350 | E26: R$ / m² | F26: Média | G26: =D26*B26*1.1 -> 28754.303
A27: Peitoris | B27: =(106.46+154.47)*0.2 -> 52.186 | C27: m² | D27: 350 | E27: R$ / m² | F27: Média | G27: =D27*B27*1.1 -> 20091.61
A28: Revestimentos de Parede granito | B28: =B48 -> 7.35 | C28: m² | D28: 550 | E28: R$ / m² | F28: Média
A29: Revestimentos de Parede ceramica | B29: =B49 -> 5085.54 | C29: m² | D29: 60 | E29: R$ / m² | F29: Média | G29: =D29*B29*1.1 -> 335645.64
G30: =SUM(G15:G29) -> 1651302.8
A33: TOTAL ACABAMENTOS | G33: =G30 -> 1651302.8 | H33: =G33/DADOS_INICIAIS!E9 -> 94.505537
A35: PISO | H35: =H33/1.1 -> 85.914125
A36: PORCELANATO | B36: =[6]Planilha1!$J$762+[6]Planilha1!$J$774+[6]Planilha1!$J$775+[6]Planilha1!$J$781+[6]Planilha1!$J$782 -> 2548.15
A37: CERAMICA | B37: =[6]Planilha1!$J$764+[6]Planilha1!$J$765+[6]Planilha1!$J$780 -> 8758.87
A38: GRANITO (PINGADEIRAS) | B38: =[6]Planilha1!$J$766 -> 83
A39: PISO ALISADO (GARAGEM E ESCADAS) | B39: =[6]Planilha1!$J$759+[6]Planilha1!$J$760 -> 4841.26
A40: VINILICO | B40: =[6]Planilha1!$J$778 -> 89.92
A41: PAVER
A42: ARGILA EXPANDIDA | B42: =[6]Planilha1!$J$768 -> 20.17
A43: PASTILHA | B43: =[6]Planilha1!$J$773 -> 54.03
A44: LAJOTAS (RAMPA) | B44: =[6]Planilha1!$J$761 -> 254.59
B46: =B36+B37+B40+B43+B44 -> 11705.56
A47: PAREDE
A48: GRANITO PAREDE | B48: =[7]Planilha1!$J$750 -> 7.35
A49: CERAMICA | B49: =[7]Planilha1!$J$739 -> 5085.54
A50: PASTILHA | B50: =[7]Planilha1!$J$749 -> 81.26

Sheet PINTURA INTERNA
A3: PINTURA INTERNA
A4: Data | B4: 45457
A5: Arquivo base | B5: -
A7: ALVENARIA
A9: Descrição | B9: Parâmetro | D9: Quantidade | F9: Preço unitário | G9: Valor total | H9: Observação
A10: Pintura piso acrilica | C10: R$ / m² | D10: ='Rev. Internos Piso e Parede'!B15 -> 4841.26 | E10: m² | F10: 8 | G10: =F10*D10*1.1 -> 42603.088
A11: Textura parede | B11: 15 | C11: R$ / AC | D11: ='Rev. Internos Piso e Parede'!B20 -> 3382.43 | E11: m² | F11: =0.9+6.8 -> 7.7 | G11: =F11*D11*1.1 -> 28649.182
A12: Textura teto | B12: 15 | C12: R$ / AC | D12: =TETO!D13+TETO!D12 -> 6989.232 | E12: m² | F12: =1.25+6.8 -> 8.05 | G12: =F12*D12*1.1 -> 61889.649
A13: Pintura Interna parede | B13: 50 | C13: R$ / AC | D13: ='Rev. Internos Piso e Parede'!B19-'Acabamentos de Piso e Parede'!B29-'Acabamentos de Piso e Parede'!B28 -> 21228.916 | E13: m² | F13: =0.9+2.5+12 -> 15.4 | G13: =F13*D13*1.05*1.1 -> 377598.73
A14: Pintura Interna teto | B14: 50 | C14: R$ / AC | D14: =TETO!D10 -> 6989.232 | E14: m² | F14: =1.25+2.5+6.5 -> 10.25 | G14: =F14*D14*1.05*1.1 -> 82743.77
A15: TOTAL | G15: =SUM(G10:G14) -> 593484.42 | K15: =4160+1440+1120+2880+4800+91680+4000 -> 110080 | L15: =K15/21 -> 5241.9048
A17: TOTAL IMPERMEABILIZAÇÃO | G17: =G15 -> 593484.42 | H17: =G17/DADOS_INICIAIS!E9 -> 33.965644
H19: =H17/1.1 -> 30.877858

Sheet ESQUADRIAS
A3: ESQUADRIAS
A4: Data | B4: 45460
A5: Arquivo base | B5: -
A7: ESQUADRIAS
A9: Descrição | B9: Parâmetro | D9: Quantidade | F9: Preço unitário | G9: Valor total | H9: Observação
A10: Esquadrias de Alumínio com motorização | B10: =D10/DADOS_INICIAIS!E9 -> 0.10505646 | C10: m² / AC | D10: =[8]Planilha1!$J$574 -> 1835.66 | E10: m² | F10: 1500 | G10: =F10*D10*1.1 -> 3028839 | H10: =G10/DADOS_INICIAIS!E9 -> 173.34317
A11: Pele de vidro | D11: =[8]Planilha1!$J$575 -> 135.94 | E11: m² | F11: 950 | G11: =F11*D11*1.1 -> 142057.3
A12: Portão de alumínio | D12: 1 | E12: un | F12: 12000 | G12: =F12*D12*1.1 -> 13200
A13: Guarda-corpo - vidro 100cm | D13: =[8]Planilha1!$J$577+[8]Planilha1!$J$578*1 -> 280.44 | E13: m2 | F13: 1700 | G13: =F13*D13*1.1 -> 524422.8
A14: Guarda-corpo - vidro 400cm | D14: =[8]Planilha1!$J$579*0.4 -> 60.54 | E14: m2 | F14: 1700 | G14: =F14*D14*1.1 -> 113209.8
A15: Serralherias | B15: 10 | C15: R$ / AC | D15: 1 | E15: vb | F15: =B15*DADOS_INICIAIS!$E$9 -> 174730.8 | G15: =F15*D15*1.1 -> 192203.88
A16: PCF | D16: =[8]Planilha1!$J$623 -> 34 | E16: un | F16: 1750 | G16: =F16*D16*1.1 -> 65450
A17: Corrimão madeira | D17: =[8]Planilha1!$K$580 -> 123.684 | E17: m | F17: 85.5 | G17: =F17*D17*1.1 -> 11632.48
A18: Fechadura biométrica | D18: =DADOS_INICIAIS!E11 -> 176 | E18: un | F18: 1200 | G18: =F18*D18*1.1 -> 232320
A19: Esquadrias de Madeira | D19: =[8]Planilha1!$J$624 -> 692 | E19: un | F19: =810+280 -> 1090 | G19: =F19*D19*1.1 -> 829708
A20: TOTAL | G20: =SUM(G10:G19) -> 5153043.3 | K20: =4160+1440+1120+2880+4800+91680+4000 -> 110080 | L20: =K20/21 -> 5241.9048
A22: TOTAL ESQUADRIAS | G22: =G20 -> 5153043.3 | H22: =G22/DADOS_INICIAIS!E9 -> 294.91328

Sheet COBERTURA
A2: COBERTURA
A3: Data | B3: 45460
A4: Arquivo base | B4: -
A6: TELHADO
A8: Descrição | B8: Parâmetro | D8: Quantidade | F8: Preço unitário | G8: Valor total | H8: Observação
A9: Estrutura e telhamento | D9: =327.4-30 -> 297.4 | E9: m² | F9: 79 | G9: =F9*D9*1.1 -> 25844.06
A10: Serviços complementares | D10: =D9 -> 297.4 | E10: m² | F10: 80 | G10: =F10*D10*1.1 -> 26171.2
A11: Pergolados | D11: 26.39 | E11: m² | F11: 1100 | G11: =F11*D11*1.1 -> 31931.9
A12: TOTAL | G12: =SUM(G9:G11) -> 83947.16
A14: TOTAL COMPLEMENTARES | G14: =G12 -> 83947.16 | H14: =G14/DADOS_INICIAIS!$E$9 -> 4.8043711

Sheet Rev. Fachada
A2: ORÇAMENTO PARAMÉTRICO GERENCIAMENTO EXECUTIVO
A7: Cliente
A8: Obra
A9: Data | B9: 45460
A10: Revisão | B10: R00
A12: REVESTIMENTOS ARGAMASSADOS
A14: Descrição | B14: Quantidade | D14: Parâmetro | F14: Referência | G14: Valor total
A15: Chapisco e reboco | B15: =[9]Planilha1!$J$11 -> 7981.26 | C15: m² | D15: 30 | E15: R$ / m² | F15: - | G15: =B15*D15*1.1 -> 263381.58
A16: TOTAL | G16: =SUM(G15:G15) -> 263381.58
A18: PINTURA | J18: EMBASAMENTO | K18: =DADOS_INICIAIS!E28 -> 156.03
J19: TORRE | K19: =DADOS_INICIAIS!E22 -> 161.37
A20: Descrição | B20: Quantidade | D20: Parâmetro | F20: Referência | G20: Valor total | J20: ATICO
A21: Textura | B21: =B15 -> 7981.26 | C21: m² | D21: 25 | E21: R$ / m² | F21: - | G21: =B21*D21*1.1 -> 219484.65 | J21: RESERV
A22: TOTAL | G22: =SUM(G21:G21) -> 219484.65 | L22: =K18*L18+K19*L19+K20*L20+K21*L21 -> 0
A24: ACABAMENTOS ESPECIAIS
A26: Descrição | B26: Quantidade | D26: Parâmetro | F26: Referência | G26: Valor total
A27: Molduras ACM | C27: M² | D27: 850 | E27: R$ / m² | F27: - | G27: =B27*D27*1.1 -> 0
A28: LED MOLDURAS | C28: M | D28: 120 | E28: R$ / m | G28: =B28*D28*1.1 -> 0
G29: =SUM(G27:G28) -> 0
J30: =25.78*2 -> 51.56
A32: TOTAL FACHADA | G32: =G22+G16+G29 -> 482866.23 | H32: =G32/DADOS_INICIAIS!E9 -> 27.634866
H33: =H32/1.1 -> 25.122606

Sheet COMPLEMENTARES
A2: COMPLEMENTARES
A3: Data | B3: 45460
A4: Arquivo base | B4: -
A6: SERVIÇOS COMPLEMENTARES
A8: Descrição | B8: Parâmetro | D8: Quantidade | F8: Valor total
A9: Móveis e decoração | B9: 50 | C9: R$ / AC | D9: =B9*DADOS_INICIAIS!$E$9 -> 873654 | E9: R$ | F9: =D9*1.1 -> 961019.4
A10: Comunicação visual | B10: 10 | C10: R$ / AC | D10: =B10*DADOS_INICIAIS!$E$9 -> 174730.8 | E10: R$ | F10: =D10*1.1 -> 192203.88
A11: Paisagismo | B11: 15 | C11: R$ / AC | D11: =B11*DADOS_INICIAIS!$E$9 -> 262096.2 | E11: R$ | F11: =D11*1.1 -> 288305.82
A12: Mini-quadra | B12: 650 | C12: R$ / m2 | D12: 67.35 | E12: m² | F12: =D12*B12*1.1 -> 48155.25
A13: Ligações definitivas | B13: 4 | C13: R$ / AC | D13: =B13*DADOS_INICIAIS!$E$9 -> 69892.32 | E13: R$ | F13: =D13*1.1 -> 76881.552
A14: Desmobilização | B14: 2 | C14: R$ / AC | D14: =B14*DADOS_INICIAIS!$E$9 -> 34946.16 | E14: R$ | F14: =D14*1.1 -> 38440.776
A15: Limpeza | B15: 12 | C15: R$ / AC | D15: =B15*DADOS_INICIAIS!$E$9 -> 209676.96 | E15: R$ | F15: =D15*1.1 -> 230644.66
A16: TOTAL | F16: =SUM(F9:F15) -> 1835651.3
A18: TOTAL COMPLEMENTARES | F18: =F16 -> 1835651.3 | G18: =F18/DADOS_INICIAIS!$E$9 -> 105.05597

Sheet Auxiliar
A2: 2 Portões acesso garagem - Área: 9,2m² x 2 = 18,4m² | B2: 2 | C2: portão | D2: 18.4
A3: 2 portas corta-fogo 1 folha | B3: 2 | C3: pcf
A4: 1 porta de correr alumínio 2 folhas – Área: 3,465m² | B4: 1 | C4: porta alumínio | D4: 3.465
A5: 1 porta de correr alumínio 2 folhas – Área: 1,7325m² | B5: 1 | C5: porta alumínio | D5: 1.7325 | G5: Guarda alumínio | H5: =SUMIF(C:C,G5,D:D) -> 400.5221
A6: 2 portas de abrir alumínio 2 folhas – Área: 2,6376m² x 2 = 5,2752m² | B6: 2 | C6: porta alumínio | D6: 5.2752 | G6: janela | H6: =SUMIF(C:C,G6,D:D) -> 1895.06
A7: 1 porta de abrir alumínio 2 folhas – Área: 4,1916m² | B7: 1 | C7: porta alumínio | D7: 4.1916 | G7: madeira | H7: =SUMIF(C:C,G7,B:B) -> 218
A8: 1 porta pivotante | B8: 1 | C8: pivotante | G8: pcf | H8: =SUMIF(C:C,G8,B:B) -> 60
A9: 19 portas de abrir madeira 1 folha | B9: 19 | C9: madeira | G9: pivotante | H9: =SUMIF(C:C,G9,B:B) -> 1
A10: 3 portas de abrir vidro 1 folha – Área: 2,1m² x 3 = 6,3m² | B10: 3 | C10: porta alumínio | D10: 6.3 | G10: porta alumínio | H10: =SUMIF(C:C,G10,D:D) -> 46.62
A11: 2 portas de abrir vidro 1 folha – Área: 1,89m² x 2 = 3,78m² | B11: 2 | C11: porta alumínio | D11: 3.78 | G11: portão | H11: =SUMIF(C:C,G11,B:B) -> 2
A12: 1 porta de abrir alumínio 1 folha – Área: 2,0076m² | B12: 1 | C12: porta alumínio | D12: 2.0076 | G12: gradil | H12: =SUMIF(C:C,G12,D:D) -> 113.88
A13: Janelas – Área: 3,75 + 4,875 + 2,5 + 1,1 + 1,2 + 5,5402 + 4,4874 = 23,4526m² | C13: janela | D13: 23.4526 | G13: Brise | H13: 109.3146
A14: Muro de vidro – Área: 7,0774 + 5,485 + 3,43 + 4,8138 = 20,8062m² | C14: Guarda alumínio | D14: 20.8062
A15: 8 portas corta-fogo 1 folha | B15: 8 | C15: pcf
A16: Janelas – Area: (1,1 + 1,2 + 28,7391) x 4 = 124,1564m² | C16: janela | D16: 124.1564
A17: 2 portas corta-fogo 1 folha | B17: 2 | C17: pcf
A18: 2 portas de abrir alumínio 1 folha – Área: 1,47m² x 2 = 2,94m² | B18: 2 | C18: porta alumínio | D18: 2.94
A19: 2 portas de abrir vidro 1 folha – Área: 1,89m² x 2 = 3,78m² | B19: 2 | C19: porta alumínio | D19: 3.78
A20: 5 portas de abrir madeira 1 folha | B20: 5 | C20: madeira
A21: 1 janela-porta de correr vidro – Área: 14,7348m² | B21: 1 | C21: janela | D21: 14.7348
A22: Janelas – Área: 1,2894 + 1,2894 + 23,46 + 1,854 + 5,562 + 5,562 + 1,854 + 1,854 + 1,1 + 1,2 = 45,0248m² | C22: janela | D22: 45.0248
A23: Guarda corpo vidro – Área: 7,5299 + 5,7955 + 6,5555 = 19,8809m² | C23: Guarda alumínio | D23: 19.8809
A24: 38 portas corta-fogo 1 folha | B24: 38 | C24: pcf
A25: 171 portas de abrir madeira 1 folha | B25: 171 | C25: madeira
A26: 19 porta de abrir alumínio 1 folha – Área: 1,26m² x 19 = 23,94m² | B26: 19 | C26: porta alumínio | D26: 23.94
A27: 19 janela-porta de correr vidro 5 folhas - Área: 25,4205m² x 19 = 482,9895m² | B27: 19 | C27: janela | D27: 482.9895
A28: 19 janela-porta de correr vidro 5 folhas - Área: 17,8284m² x 19 = 338,7396m² | B28: 19 | C28: janela | D28: 338.7396
A29: Janelas – Área: 1,1 + 1,1 + 1,2 + 1,92 + 0,36 + 2,781 + 2,781 + 1,854 + 1,854 + 5,562 + 5,562 + 1,854 = 27,928m² x 19 = 530,632m² | C29: janela | D29: 530.632
A30: Guarda corpo metálico – Área: 4,745m² x 19 = 90,155m² - Perímetro: 3,65m x 19 = 69,35m | C30: gradil | D30: 90.155
A31: Guarda corpo vidro – Área: 15,645m² x 19 = 297,255m² - Perímetro: 14,9m x 19 = 283,1m | C31: Guarda alumínio | D31: 297.255
A32: 2 portas corta-fogo 1 folha | B32: 2 | C32: pcf
A33: 2 portas de abrir madeira 1 folha | B33: 2 | C33: madeira
A34: 1 porta de abrir alumínio 1 folha – Área: 1,26m² | B34: 1 | C34: porta alumínio | D34: 1.26
A35: 1 janela-porta de correr vidro 3 folhas - Área: 15,21m² | B35: 1 | C35: janela | D35: 15.21
A36: 1 janela-porta de correr vidro 5 folhas - Área: 25,4205m² | B36: 1 | C36: janela | D36: 25.4205
A37: 1 janela-porta de correr vidro 5 folhas - Área: 17,8284m² | B37: 1 | C37: janela | D37: 17.8284
A38: Janelas – Área: 1,1 + 1,2 + 1,1 + 1,92 + 0,36 + 2,781 + 2,781 + 1,854 + 1,854 + 5,562 + 5,562 + 1,854 = 27,928m² | C38: janela | D38: 27.928
A39: Guarda corpo metálico – Área: 4,745m² - Perímetro: 3,65m | C39: gradil | D39: 4.745
A40: Guarda corpo vidro – Área: 15,645m² - Perímetro: 14,9m | C40: Guarda alumínio | D40: 15.645
A41: 2 portas corta-fogo 1 folha | B41: 2 | C41: pcf
...
