Workbook

Sheet PRAZO
B2: ORÇAMENTO PARAMÉTRICO | ESTIMATIVA DE PRAZO
B4: COTA - 365 (Afonso Pena)
B7: SERVIÇOS | C7: M1 | D7: M2 | E7: M3 | F7: M4 | G7: M5 | H7: M6 | I7: M7 | J7: M8 | K7: M9 | L7: M10 | M7: M11 | N7: M12 | O7: M13 | P7: M14 | Q7: M15 | R7: M16 | S7: M17 | T7: M18 | U7: M19 | V7: M20 | W7: M21 | X7: M22 | Y7: M23 | Z7: M24 | AA7: M25 | AB7: M26 | AC7: M27 | AD7: M28 | AE7: M29 | AF7: M30 | AG7: M31 | AH7: M32 | AI7: M33 | AJ7: M34 | AK7: M35 | AL7: M36 | AM7: M37 | AN7: M38 | AO7: M39 | AP7: M40 | AQ7: M41 | AR7: M42 | AS7: M43
B8: MOVIMENTAÇÃO DE TERRA | C8: 1 | D8: 2 | E8: 3 | F8: 4 | G8: 5 | H8: 6 | I8: 7 | J8: 8 | K8: 9 | L8: 10 | M8: 11
B9: INFRAESTRUTURA | I9: 1 | J9: 2 | K9: 3 | L9: 4 | M9: 5
B10: CONTENÇÃO | C10: 1 | D10: 2 | E10: 3 | F10: 4 | G10: 5 | H10: 6
B11: SUPRAESTRUTURA | N11: 1 | O11: 2 | P11: 3 | Q11: 4 | R11: 5 | S11: 6 | T11: 7 | U11: 8 | V11: 9 | W11: 10 | X11: 11 | Y11: 12 | Z11: 13 | AA11: 14 | AB11: 15 | AC11: 16
B12: ALVENARIA | Q12: 1 | R12: 2 | S12: 3 | T12: 4 | U12: 5 | V12: 6 | W12: 7 | X12: 8 | Y12: 9 | Z12: 10 | AA12: 11 | AB12: 12 | AC12: 13 | AD12: 14 | AE12: 15 | AF12: 16
B13: INSTALAÇÕES ELÉTRICAS, HIDRÁULICAS, GLP E PREVENTIVAS | R13: 1 | S13: 2 | T13: 3 | U13: 4 | V13: 5 | W13: 6 | X13: 7 | Y13: 8 | Z13: 9 | AA13: 10 | AB13: 11 | AC13: 12 | AD13: 13 | AE13: 14 | AF13: 15 | AG13: 16
B14: EQUIPAMENTOS E SISTEMAS ESPECIAIS | AD14: 1 | AE14: 2 | AF14: 3 | AG14: 4 | AH14: 5 | AI14: 6
B15: IMPERMEABILIZAÇÃO | T15: 1 | U15: 2 | V15: 3 | W15: 4 | X15: 5 | Y15: 6 | Z15: 7 | AA15: 8 | AB15: 9 | AC15: 10 | AD15: 11 | AE15: 12 | AF15: 13 | AG15: 14 | AH15: 15 | AI15: 16
B16: REVESTIMENTOS INTERNOS EM PISO E PAREDE | S16: 1 | T16: 2 | U16: 3 | V16: 4 | W16: 5 | X16: 6 | Y16: 7 | Z16: 8 | AA16: 9 | AB16: 10 | AC16: 11 | AD16: 12 | AE16: 13 | AF16: 14 | AG16: 15 | AH16: 16
B17: REVESTIMENTOS E ACABAMENTOS INTERNOS EM TETO | V17: 1 | W17: 2 | X17: 3 | Y17: 4 | Z17: 5 | AA17: 6 | AB17: 7 | AC17: 8 | AD17: 9 | AE17: 10 | AF17: 11 | AG17: 12 | AH17: 13 | AI17: 14 | AJ17: 15 | AK17: 16 | AL17: 17
B18: ACABAMENTOS EM PISO E PAREDE | U18: 1 | V18: 2 | W18: 3 | X18: 4 | Y18: 5 | Z18: 6 | AA18: 7 | AB18: 8 | AC18: 9 | AD18: 10 | AE18: 11 | AF18: 12 | AG18: 13 | AH18: 14 | AI18: 15 | AJ18: 16 | AK18: 17
B19: PINTURA INTERNA | W19: 1 | X19: 2 | Y19: 3 | Z19: 4 | AA19: 5 | AB19: 6 | AC19: 7 | AD19: 8 | AE19: 9 | AF19: 10 | AG19: 11 | AH19: 12 | AI19: 13 | AJ19: 14 | AK19: 15 | AL19: 16 | AM19: 17 | AN19: 18 | AO19: 19 | AP19: 20
B20: ESQUADRIAS, VIDROS E FERRAGENS | AJ20: 1 | AK20: 2 | AL20: 3 | AM20: 4 | AN20: 5 | AO20: 6
B21: COBERTURA | AH21: 1 | AI21: 2 | AJ21: 3 | AK21: 4
B22: REVESTIMENTOS E ACABAMENTOS DE FACHADA | AG22: 1 | AH22: 2 | AI22: 3 | AJ22: 4 | AK22: 5 | AL22: 6 | AM22: 7 | AN22: 8
B23: SERVIÇOS COMPLEMENTARES | AL23: 1 | AM23: 2 | AN23: 3 | AO23: 4 | AP23: 5 | AQ23: 6 | AR23: 7 | AS23: 8

Sheet DISTRIBUIÇÃO CUSTO
B2: ORÇAMENTO PARAMÉTRICO | DISTRIBUIÇÃO MENSAL DE CUSTOS
B4: COTA - 365 (Afonso Pena)
B7: ETAPA | C7: VALOR ORÇADO | D7: % | E7: VALOR / m² | F7: % Distribuído | H7: M1 | J7: M2 | L7: M3 | N7: M4 | P7: M5 | R7: M6 | T7: M7 | V7: M8 | X7: M9 | Z7: M10 | AB7: M11 | AD7: M12 | AF7: M13 | AH7: M14 | AJ7: M15 | AL7: M16 | AN7: M17 | AP7: M18 | AR7: M19 | AT7: M20 | AV7: M21 | AX7: M22 | AZ7: M23 | BB7: M24 | BD7: M25 | BF7: M26 | BH7: M27 | BJ7: M28 | BL7: M29 | BN7: M30 | BP7: M31 | BR7: M32 | BT7: M33 | BV7: M34 | BX7: M35 | BZ7: M36 | CB7: M37 | CD7: M38 | CF7: M39 | CH7: M40 | CJ7: M41 | CL7: M42 | CN7: M43
H8: % | I8: R$ | J8: % | K8: R$ | L8: % | M8: R$ | N8: % | O8: R$ | P8: % | Q8: R$ | R8: % | S8: R$ | T8: % | U8: R$ | V8: % | W8: R$ | X8: % | Y8: R$ | Z8: % | AA8: R$ | AB8: % | AC8: R$ | AD8: % | AE8: R$ | AF8: % | AG8: R$ | AH8: % | AI8: R$ | AJ8: % | AK8: R$ | AL8: % | AM8: R$ | AN8: % | AO8: R$ | AP8: % | AQ8: R$ | AR8: % | AS8: R$ | AT8: % | AU8: R$ | AV8: % | AW8: R$ | AX8: % | AY8: R$ | AZ8: % | BA8: R$ | BB8: % | BC8: R$ | BD8: % | BE8: R$ | BF8: % | BG8: R$ | BH8: % | BI8: R$ | BJ8: % | BK8: R$ | BL8: % | BM8: R$ | BN8: % | BO8: R$ | BP8: % | BQ8: R$ | BR8: % | BS8: R$ | BT8: % | BU8: R$ | BV8: % | BW8: R$ | BX8: % | BY8: R$ | BZ8: % | CA8: R$ | CB8: % | CC8: R$ | CD8: % | CE8: R$ | CF8: % | CG8: R$ | CH8: % | CI8: R$ | CJ8: % | CK8: R$ | CL8: % | CM8: R$ | CN8: % | CO8: R$
B9: GERENCIAMENTO TÉCNICO E ADMINISTRATIVO | C9: 3504714.1 | D9: =C9/$C$27 -> 0.059573914 | E9: =C9/'DISTRIBUIÇÃO CUSTO'!C$31 -> 200.57793 | F9: =SUM(H9,J9,L9,N9,P9,R9,T9,V9,X9,Z9,AB9,AD9,AF9,AH9,AJ9,AL9,,AN9,AP9,AR9,AT9,AV9,AX9,AZ9,BB9,BD9,BF9,BH9,BJ9,BL9,BN9,BP9,BR9,BT9,BV9,BX9,BZ9,CB9,CD9,CF9,CH9,CJ9,CL9,CN9) -> 1 | H9: 0.07 | I9: =$C9*H9 -> 245329.99 | J9: 0.06 | K9: =$C9*J9 -> 210282.85 | L9: 0.06 | M9: =$C9*L9 -> 210282.85 | N9: 0.04 | O9: =$C9*N9 -> 140188.57 | P9: 0.04 | Q9: =$C9*P9 -> 140188.57 | R9: 0.04 | S9: =$C9*R9 -> 140188.57 | T9: =(100%-$R$9-$P$9-$N$9-$L$9-$J$9-$H$9)/($E$31-6) -> 0.018648649 | U9: =$C9*T9 -> 65358.182 | V9: =(100%-$R$9-$P$9-$N$9-$L$9-$J$9-$H$9)/($E$31-6) -> 0.018648649 | W9: =$C9*V9 -> 65358.182 | X9: =(100%-$R$9-$P$9-$N$9-$L$9-$J$9-$H$9)/($E$31-6) -> 0.018648649 | Y9: =$C9*X9 -> 65358.182 | Z9: =(100%-$R$9-$P$9-$N$9-$L$9-$J$9-$H$9)/($E$31-6) -> 0.018648649 | AA9: =$C9*Z9 -> 65358.182 | AB9: =(100%-$R$9-$P$9-$N$9-$L$9-$J$9-$H$9)/($E$31-6) -> 0.018648649 | AC9: =$C9*AB9 -> 65358.182 | AD9: =(100%-$R$9-$P$9-$N$9-$L$9-$J$9-$H$9)/($E$31-6) -> 0.018648649 | AE9: =$C9*AD9 -> 65358.182 | AF9: =(100%-$R$9-$P$9-$N$9-$L$9-$J$9-$H$9)/($E$31-6) -> 0.018648649 | AG9: =$C9*AF9 -> 65358.182 | AH9: =(100%-$R$9-$P$9-$N$9-$L$9-$J$9-$H$9)/($E$31-6) -> 0.018648649 | AI9: =$C9*AH9 -> 65358.182 | AJ9: =(100%-$R$9-$P$9-$N$9-$L$9-$J$9-$H$9)/($E$31-6) -> 0.018648649 | AK9: =$C9*AJ9 -> 65358.182 | AL9: =(100%-$R$9-$P$9-$N$9-$L$9-$J$9-$H$9)/($E$31-6) -> 0.018648649 | AM9: =$C9*AL9 -> 65358.182 | AN9: =(100%-$R$9-$P$9-$N$9-$L$9-$J$9-$H$9)/($E$31-6) -> 0.018648649 | AO9: =$C9*AN9 -> 65358.182 | AP9: =(100%-$R$9-$P$9-$N$9-$L$9-$J$9-$H$9)/($E$31-6) -> 0.018648649 | AQ9: =$C9*AP9 -> 65358.182 | AR9: =(100%-$R$9-$P$9-$N$9-$L$9-$J$9-$H$9)/($E$31-6) -> 0.018648649 | AS9: =$C9*AR9 -> 65358.182 | AT9: =(100%-$R$9-$P$9-$N$9-$L$9-$J$9-$H$9)/($E$31-6) -> 0.018648649 | AU9: =$C9*AT9 -> 65358.182 | AV9: =(100%-$R$9-$P$9-$N$9-$L$9-$J$9-$H$9)/($E$31-6) -> 0.018648649 | AW9: =$C9*AV9 -> 65358.182 | AX9: =(100%-$R$9-$P$9-$N$9-$L$9-$J$9-$H$9)/($E$31-6) -> 0.018648649 | AY9: =$C9*AX9 -> 65358.182 | AZ9: =(100%-$R$9-$P$9-$N$9-$L$9-$J$9-$H$9)/($E$31-6) -> 0.018648649 | BA9: =$C9*AZ9 -> 65358.182 | BB9: =(100%-$R$9-$P$9-$N$9-$L$9-$J$9-$H$9)/($E$31-6) -> 0.018648649 | BC9: =$C9*BB9 -> 65358.182 | BD9: =(100%-$R$9-$P$9-$N$9-$L$9-$J$9-$H$9)/($E$31-6) -> 0.018648649 | BE9: =$C9*BD9 -> 65358.182 | BF9: =(100%-$R$9-$P$9-$N$9-$L$9-$J$9-$H$9)/($E$31-6) -> 0.018648649 | BG9: =$C9*BF9 -> 65358.182 | BH9: =(100%-$R$9-$P$9-$N$9-$L$9-$J$9-$H$9)/($E$31-6) -> 0.018648649 | BI9: =$C9*BH9 -> 65358.182 | BJ9: =(100%-$R$9-$P$9-$N$9-$L$9-$J$9-$H$9)/($E$31-6) -> 0.018648649 | BK9: =$C9*BJ9 -> 65358.182 | BL9: =(100%-$R$9-$P$9-$N$9-$L$9-$J$9-$H$9)/($E$31-6) -> 0.018648649 | BM9: =$C9*BL9 -> 65358.182 | BN9: =(100%-$R$9-$P$9-$N$9-$L$9-$J$9-$H$9)/($E$31-6) -> 0.018648649 | BO9: =$C9*BN9 -> 65358.182 | BP9: =(100%-$R$9-$P$9-$N$9-$L$9-$J$9-$H$9)/($E$31-6) -> 0.018648649 | BQ9: =$C9*BP9 -> 65358.182 | BR9: =(100%-$R$9-$P$9-$N$9-$L$9-$J$9-$H$9)/($E$31-6) -> 0.018648649 | BS9: =$C9*BR9 -> 65358.182 | BT9: =(100%-$R$9-$P$9-$N$9-$L$9-$J$9-$H$9)/($E$31-6) -> 0.018648649 | BU9: =$C9*BT9 -> 65358.182 | BV9: =(100%-$R$9-$P$9-$N$9-$L$9-$J$9-$H$9)/($E$31-6) -> 0.018648649 | BW9: =$C9*BV9 -> 65358.182 | BX9: =(100%-$R$9-$P$9-$N$9-$L$9-$J$9-$H$9)/($E$31-6) -> 0.018648649 | BY9: =$C9*BX9 -> 65358.182 | BZ9: =(100%-$R$9-$P$9-$N$9-$L$9-$J$9-$H$9)/($E$31-6) -> 0.018648649 | CA9: =$C9*BZ9 -> 65358.182 | CB9: =(100%-$R$9-$P$9-$N$9-$L$9-$J$9-$H$9)/($E$31-6) -> 0.018648649 | CC9: =$C9*CB9 -> 65358.182 | CD9: =(100%-$R$9-$P$9-$N$9-$L$9-$J$9-$H$9)/($E$31-6) -> 0.018648649 | CE9: =$C9*CD9 -> 65358.182 | CF9: =(100%-$R$9-$P$9-$N$9-$L$9-$J$9-$H$9)/($E$31-6) -> 0.018648649 | CG9: =$C9*CF9 -> 65358.182 | CH9: =(100%-$R$9-$P$9-$N$9-$L$9-$J$9-$H$9)/($E$31-6) -> 0.018648649 | CI9: =$C9*CH9 -> 65358.182 | CJ9: =(100%-$R$9-$P$9-$N$9-$L$9-$J$9-$H$9)/($E$31-6) -> 0.018648649 | CK9: =$C9*CJ9 -> 65358.182 | CL9: =(100%-$R$9-$P$9-$N$9-$L$9-$J$9-$H$9)/($E$31-6) -> 0.018648649 | CM9: =$C9*CL9 -> 65358.182 | CN9: =(100%-$R$9-$P$9-$N$9-$L$9-$J$9-$H$9)/($E$31-6) -> 0.018648649 | CO9: =$C9*CN9 -> 65358.182
B10: MOVIMENTAÇÃO DE TERRA | C10: 1364651.1 | D10: =C10/$C$27 -> 0.023196645 | E10: =C10/'DISTRIBUIÇÃO CUSTO'!C$31 -> 78.100205 | F10: =SUM(H10,J10,L10,N10,P10,R10,T10,V10,X10,Z10,AB10,AD10,AF10,AH10,AJ10,AL10,,AN10,AP10,AR10,AT10,AV10,AX10,AZ10,BB10,BD10,BF10,BH10,BJ10,BL10,BN10,BP10,BR10,BT10,BV10,BX10,BZ10,CB10,CD10,CF10,CH10,CJ10,CL10,CN10) -> 1 | H10: =100%/11 -> 0.090909091 | I10: =$C10*H10 -> 124059.19 | J10: =100%/11 -> 0.090909091 | K10: =$C10*J10 -> 124059.19 | L10: =100%/11 -> 0.090909091 | M10: =$C10*L10 -> 124059.19 | N10: =100%/11 -> 0.090909091 | O10: =$C10*N10 -> 124059.19 | P10: =100%/11 -> 0.090909091 | Q10: =$C10*P10 -> 124059.19 | R10: =100%/11 -> 0.090909091 | S10: =$C10*R10 -> 124059.19 | T10: =100%/11 -> 0.090909091 | U10: =$C10*T10 -> 124059.19 | V10: =100%/11 -> 0.090909091 | W10: =$C10*V10 -> 124059.19 | X10: =100%/11 -> 0.090909091 | Y10: =$C10*X10 -> 124059.19 | Z10: =100%/11 -> 0.090909091 | AA10: =$C10*Z10 -> 124059.19 | AB10: =100%/11 -> 0.090909091 | AC10: =$C10*AB10 -> 124059.19 | AE10: =$C10*AD10 -> 0 | AG10: =$C10*AF10 -> 0 | AI10: =$C10*AH10 -> 0 | AK10: =$C10*AJ10 -> 0 | AM10: =$C10*AL10 -> 0 | AO10: =$C10*AN10 -> 0 | AQ10: =$C10*AP10 -> 0 | AS10: =$C10*AR10 -> 0 | AU10: =$C10*AT10 -> 0 | AW10: =$C10*AV10 -> 0 | AY10: =$C10*AX10 -> 0 | BA10: =$C10*AZ10 -> 0 | BC10: =$C10*BB10 -> 0 | BE10: =$C10*BD10 -> 0 | BG10: =$C10*BF10 -> 0 | BI10: =$C10*BH10 -> 0 | BK10: =$C10*BJ10 -> 0 | BM10: =$C10*BL10 -> 0 | BO10: =$C10*BN10 -> 0 | BQ10: =$C10*BP10 -> 0 | BS10: =$C10*BR10 -> 0 | BU10: =$C10*BT10 -> 0 | BW10: =$C10*BV10 -> 0 | BY10: =$C10*BX10 -> 0 | CA10: =$C10*BZ10 -> 0 | CC10: =$C10*CB10 -> 0 | CE10: =$C10*CD10 -> 0 | CG10: =$C10*CF10 -> 0 | CI10: =$C10*CH10 -> 0 | CK10: =$C10*CJ10 -> 0 | CM10: =$C10*CL10 -> 0 | CO10: =$C10*CN10 -> 0
B11: INFRAESTRUTURA | C11: 3138470.4 | D11: =C11/$C$27 -> 0.053348422 | E11: =C11/'DISTRIBUIÇÃO CUSTO'!C$31 -> 179.61747 | F11: =SUM(H11,J11,L11,N11,P11,R11,T11,V11,X11,Z11,AB11,AD11,AF11,AH11,AJ11,AL11,,AN11,AP11,AR11,AT11,AV11,AX11,AZ11,BB11,BD11,BF11,BH11,BJ11,BL11,BN11,BP11,BR11,BT11,BV11,BX11,BZ11,CB11,CD11,CF11,CH11,CJ11,CL11,CN11) -> 1 | I11: =$C11*H11 -> 0 | K11: =$C11*J11 -> 0 | M11: =$C11*L11 -> 0 | O11: =$C11*N11 -> 0 | Q11: =$C11*P11 -> 0 | S11: =$C11*R11 -> 0 | T11: =100%/5 -> 0.2 | U11: =$C11*T11 -> 627694.09 | V11: =100%/5 -> 0.2 | W11: =$C11*V11 -> 627694.09 | X11: =100%/5 -> 0.2 | Y11: =$C11*X11 -> 627694.09 | Z11: =100%/5 -> 0.2 | AA11: =$C11*Z11 -> 627694.09 | AB11: =100%/5 -> 0.2 | AC11: =$C11*AB11 -> 627694.09 | AE11: =$C11*AD11 -> 0 | AG11: =$C11*AF11 -> 0 | AI11: =$C11*AH11 -> 0 | AK11: =$C11*AJ11 -> 0 | AM11: =$C11*AL11 -> 0 | AO11: =$C11*AN11 -> 0 | AQ11: =$C11*AP11 -> 0 | AS11: =$C11*AR11 -> 0 | AU11: =$C11*AT11 -> 0 | AW11: =$C11*AV11 -> 0 | AY11: =$C11*AX11 -> 0 | BA11: =$C11*AZ11 -> 0 | BC11: =$C11*BB11 -> 0 | BE11: =$C11*BD11 -> 0 | BG11: =$C11*BF11 -> 0 | BI11: =$C11*BH11 -> 0 | BK11: =$C11*BJ11 -> 0 | BM11: =$C11*BL11 -> 0 | BO11: =$C11*BN11 -> 0 | BQ11: =$C11*BP11 -> 0 | BS11: =$C11*BR11 -> 0 | BU11: =$C11*BT11 -> 0 | BW11: =$C11*BV11 -> 0 | BY11: =$C11*BX11 -> 0 | CA11: =$C11*BZ11 -> 0 | CC11: =$C11*CB11 -> 0 | CE11: =$C11*CD11 -> 0 | CG11: =$C11*CF11 -> 0 | CI11: =$C11*CH11 -> 0 | CK11: =$C11*CJ11 -> 0 | CM11: =$C11*CL11 -> 0 | CO11: =$C11*CN11 -> 0
B12: CONTENÇÃO | C12: 3178951.2 | D12: =C12/$C$27 -> 0.054036523 | E12: =C12/'DISTRIBUIÇÃO CUSTO'!C$31 -> 181.93422 | F12: =SUM(H12,J12,L12,N12,P12,R12,T12,V12,X12,Z12,AB12,AD12,AF12,AH12,AJ12,AL12,,AN12,AP12,AR12,AT12,AV12,AX12,AZ12,BB12,BD12,BF12,BH12,BJ12,BL12,BN12,BP12,BR12,BT12,BV12,BX12,BZ12,CB12,CD12,CF12,CH12,CJ12,CL12,CN12) -> 1 | H12: =100%/6 -> 0.16666667 | I12: =$C12*H12 -> 529825.2 | J12: =100%/6 -> 0.16666667 | K12: =$C12*J12 -> 529825.2 | L12: =100%/6 -> 0.16666667 | M12: =$C12*L12 -> 529825.2 | N12: =100%/6 -> 0.16666667 | O12: =$C12*N12 -> 529825.2 | P12: =100%/6 -> 0.16666667 | Q12: =$C12*P12 -> 529825.2 | R12: =100%/6 -> 0.16666667 | S12: =$C12*R12 -> 529825.2 | U12: =$C12*T12 -> 0 | W12: =$C12*V12 -> 0 | Y12: =$C12*X12 -> 0 | AA12: =$C12*Z12 -> 0 | AC12: =$C12*AB12 -> 0 | AE12: =$C12*AD12 -> 0 | AG12: =$C12*AF12 -> 0 | AI12: =$C12*AH12 -> 0 | AK12: =$C12*AJ12 -> 0 | AM12: =$C12*AL12 -> 0 | AO12: =$C12*AN12 -> 0 | AQ12: =$C12*AP12 -> 0 | AS12: =$C12*AR12 -> 0 | AU12: =$C12*AT12 -> 0 | AW12: =$C12*AV12 -> 0 | AY12: =$C12*AX12 -> 0 | BA12: =$C12*AZ12 -> 0 | BC12: =$C12*BB12 -> 0 | BE12: =$C12*BD12 -> 0 | BG12: =$C12*BF12 -> 0 | BI12: =$C12*BH12 -> 0 | BK12: =$C12*BJ12 -> 0 | BM12: =$C12*BL12 -> 0 | BO12: =$C12*BN12 -> 0 | BQ12: =$C12*BP12 -> 0 | BS12: =$C12*BR12 -> 0 | BU12: =$C12*BT12 -> 0 | BW12: =$C12*BV12 -> 0 | BY12: =$C12*BX12 -> 0 | CA12: =$C12*BZ12 -> 0 | CC12: =$C12*CB12 -> 0 | CE12: =$C12*CD12 -> 0 | CG12: =$C12*CF12 -> 0 | CI12: =$C12*CH12 -> 0 | CK12: =$C12*CJ12 -> 0 | CM12: =$C12*CL12 -> 0 | CO12: =$C12*CN12 -> 0
B13: SUPRAESTRUTURA | C13: 10402968 | D13: =C13/$C$27 -> 0.17683197 | E13: =C13/'DISTRIBUIÇÃO CUSTO'!C$31 -> 595.37115 | F13: =SUM(H13,J13,L13,N13,P13,R13,T13,V13,X13,Z13,AB13,AD13,AF13,AH13,AJ13,AL13,,AN13,AP13,AR13,AT13,AV13,AX13,AZ13,BB13,BD13,BF13,BH13,BJ13,BL13,BN13,BP13,BR13,BT13,BV13,BX13,BZ13,CB13,CD13,CF13,CH13,CJ13,CL13,CN13) -> 1 | I13: =$C13*H13 -> 0 | K13: =$C13*J13 -> 0 | M13: =$C13*L13 -> 0 | O13: =$C13*N13 -> 0 | Q13: =$C13*P13 -> 0 | S13: =$C13*R13 -> 0 | U13: =$C13*T13 -> 0 | W13: =$C13*V13 -> 0 | Y13: =$C13*X13 -> 0 | AA13: =$C13*Z13 -> 0 | AC13: =$C13*AB13 -> 0 | AD13: =100%/16 -> 0.0625 | AE13: =$C13*AD13 -> 650185.48 | AF13: =100%/16 -> 0.0625 | AG13: =$C13*AF13 -> 650185.48 | AH13: =100%/16 -> 0.0625 | AI13: =$C13*AH13 -> 650185.48 | AJ13: =100%/16 -> 0.0625 | AK13: =$C13*AJ13 -> 650185.48 | AL13: =100%/16 -> 0.0625 | AM13: =$C13*AL13 -> 650185.48 | AN13: =100%/16 -> 0.0625 | AO13: =$C13*AN13 -> 650185.48 | AP13: =100%/16 -> 0.0625 | AQ13: =$C13*AP13 -> 650185.48 | AR13: =100%/16 -> 0.0625 | AS13: =$C13*AR13 -> 650185.48 | AT13: =100%/16 -> 0.0625 | AU13: =$C13*AT13 -> 650185.48 | AV13: =100%/16 -> 0.0625 | AW13: =$C13*AV13 -> 650185.48 | AX13: =100%/16 -> 0.0625 | AY13: =$C13*AX13 -> 650185.48 | AZ13: =100%/16 -> 0.0625 | BA13: =$C13*AZ13 -> 650185.48 | BB13: =100%/16 -> 0.0625 | BC13: =$C13*BB13 -> 650185.48 | BD13: =100%/16 -> 0.0625 | BE13: =$C13*BD13 -> 650185.48 | BF13: =100%/16 -> 0.0625 | BG13: =$C13*BF13 -> 650185.48 | BH13: =100%/16 -> 0.0625 | BI13: =$C13*BH13 -> 650185.48 | BK13: =$C13*BJ13 -> 0 | BM13: =$C13*BL13 -> 0 | BO13: =$C13*BN13 -> 0 | BQ13: =$C13*BP13 -> 0 | BS13: =$C13*BR13 -> 0 | BU13: =$C13*BT13 -> 0 | BW13: =$C13*BV13 -> 0 | BY13: =$C13*BX13 -> 0 | CA13: =$C13*BZ13 -> 0 | CC13: =$C13*CB13 -> 0 | CE13: =$C13*CD13 -> 0 | CG13: =$C13*CF13 -> 0 | CI13: =$C13*CH13 -> 0 | CK13: =$C13*CJ13 -> 0 | CM13: =$C13*CL13 -> 0 | CO13: =$C13*CN13 -> 0
B14: ALVENARIA | C14: 2649104.4 | D14: =C14/$C$27 -> 0.045030069 | E14: =C14/'DISTRIBUIÇÃO CUSTO'!C$31 -> 151.61062 | F14: =SUM(H14,J14,L14,N14,P14,R14,T14,V14,X14,Z14,AB14,AD14,AF14,AH14,AJ14,AL14,,AN14,AP14,AR14,AT14,AV14,AX14,AZ14,BB14,BD14,BF14,BH14,BJ14,BL14,BN14,BP14,BR14,BT14,BV14,BX14,BZ14,CB14,CD14,CF14,CH14,CJ14,CL14,CN14) -> 1 | I14: =$C14*H14 -> 0 | K14: =$C14*J14 -> 0 | M14: =$C14*L14 -> 0 | O14: =$C14*N14 -> 0 | Q14: =$C14*P14 -> 0 | S14: =$C14*R14 -> 0 | U14: =$C14*T14 -> 0 | W14: =$C14*V14 -> 0 | Y14: =$C14*X14 -> 0 | AA14: =$C14*Z14 -> 0 | AC14: =$C14*AB14 -> 0 | AE14: =$C14*AD14 -> 0 | AG14: =$C14*AF14 -> 0 | AI14: =$C14*AH14 -> 0 | AJ14: =100%/16 -> 0.0625 | AK14: =$C14*AJ14 -> 165569.03 | AL14: =100%/16 -> 0.0625 | AM14: =$C14*AL14 -> 165569.03 | AN14: =100%/16 -> 0.0625 | AO14: =$C14*AN14 -> 165569.03 | AP14: =100%/16 -> 0.0625 | AQ14: =$C14*AP14 -> 165569.03 | AR14: =100%/16 -> 0.0625 | AS14: =$C14*AR14 -> 165569.03 | AT14: =100%/16 -> 0.0625 | AU14: =$C14*AT14 -> 165569.03 | AV14: =100%/16 -> 0.0625 | AW14: =$C14*AV14 -> 165569.03 | AX14: =100%/16 -> 0.0625 | AY14: =$C14*AX14 -> 165569.03 | AZ14: =100%/16 -> 0.0625 | BA14: =$C14*AZ14 -> 165569.03 | BB14: =100%/16 -> 0.0625 | BC14: =$C14*BB14 -> 165569.03 | BD14: =100%/16 -> 0.0625 | BE14: =$C14*BD14 -> 165569.03 | BF14: =100%/16 -> 0.0625 | BG14: =$C14*BF14 -> 165569.03 | BH14: =100%/16 -> 0.0625 | BI14: =$C14*BH14 -> 165569.03 | BJ14: =100%/16 -> 0.0625 | BK14: =$C14*BJ14 -> 165569.03 | BL14: =100%/16 -> 0.0625 | BM14: =$C14*BL14 -> 165569.03 | BN14: =100%/16 -> 0.0625 | BO14: =$C14*BN14 -> 165569.03 | BQ14: =$C14*BP14 -> 0 | BS14: =$C14*BR14 -> 0 | BU14: =$C14*BT14 -> 0 | BW14: =$C14*BV14 -> 0 | BY14: =$C14*BX14 -> 0 | CA14: =$C14*BZ14 -> 0 | CC14: =$C14*CB14 -> 0 | CE14: =$C14*CD14 -> 0 | CG14: =$C14*CF14 -> 0 | CI14: =$C14*CH14 -> 0 | CK14: =$C14*CJ14 -> 0 | CM14: =$C14*CL14 -> 0 | CO14: =$C14*CN14 -> 0
B15: INSTALAÇÕES ELÉTRICAS, HIDRÁULICAS, GLP E PREVENTIVAS | C15: 6444580.4 | D15: =C15/$C$27 -> 0.10954642 | E15: =C15/'DISTRIBUIÇÃO CUSTO'!C$31 -> 368.8291 | F15: =SUM(H15,J15,L15,N15,P15,R15,T15,V15,X15,Z15,AB15,AD15,AF15,AH15,AJ15,AL15,,AN15,AP15,AR15,AT15,AV15,AX15,AZ15,BB15,BD15,BF15,BH15,BJ15,BL15,BN15,BP15,BR15,BT15,BV15,BX15,BZ15,CB15,CD15,CF15,CH15,CJ15,CL15,CN15) -> 1 | I15: =$C15*H15 -> 0 | K15: =$C15*J15 -> 0 | M15: =$C15*L15 -> 0 | O15: =$C15*N15 -> 0 | Q15: =$C15*P15 -> 0 | S15: =$C15*R15 -> 0 | U15: =$C15*T15 -> 0 | W15: =$C15*V15 -> 0 | Y15: =$C15*X15 -> 0 | AA15: =$C15*Z15 -> 0 | AC15: =$C15*AB15 -> 0 | AE15: =$C15*AD15 -> 0 | AG15: =$C15*AF15 -> 0 | AI15: =$C15*AH15 -> 0 | AK15: =$C15*AJ15 -> 0 | AL15: =100%/16 -> 0.0625 | AM15: =$C15*AL15 -> 402786.28 | AN15: =100%/16 -> 0.0625 | AO15: =$C15*AN15 -> 402786.28 | AP15: =100%/16 -> 0.0625 | AQ15: =$C15*AP15 -> 402786.28 | AR15: =100%/16 -> 0.0625 | AS15: =$C15*AR15 -> 402786.28 | AT15: =100%/16 -> 0.0625 | AU15: =$C15*AT15 -> 402786.28 | AV15: =100%/16 -> 0.0625 | AW15: =$C15*AV15 -> 402786.28 | AX15: =100%/16 -> 0.0625 | AY15: =$C15*AX15 -> 402786.28 | AZ15: =100%/16 -> 0.0625 | BA15: =$C15*AZ15 -> 402786.28 | BB15: =100%/16 -> 0.0625 | BC15: =$C15*BB15 -> 402786.28 | BD15: =100%/16 -> 0.0625 | BE15: =$C15*BD15 -> 402786.28 | BF15: =100%/16 -> 0.0625 | BG15: =$C15*BF15 -> 402786.28 | BH15: =100%/16 -> 0.0625 | BI15: =$C15*BH15 -> 402786.28 | BJ15: =100%/16 -> 0.0625 | BK15: =$C15*BJ15 -> 402786.28 | BL15: =100%/16 -> 0.0625 | BM15: =$C15*BL15 -> 402786.28 | BN15: =100%/16 -> 0.0625 | BO15: =$C15*BN15 -> 402786.28 | BP15: =100%/16 -> 0.0625 | BQ15: =$C15*BP15 -> 402786.28 | BS15: =$C15*BR15 -> 0 | BU15: =$C15*BT15 -> 0 | BW15: =$C15*BV15 -> 0 | BY15: =$C15*BX15 -> 0 | CA15: =$C15*BZ15 -> 0 | CC15: =$C15*CB15 -> 0 | CE15: =$C15*CD15 -> 0 | CG15: =$C15*CF15 -> 0 | CI15: =$C15*CH15 -> 0 | CK15: =$C15*CJ15 -> 0 | CM15: =$C15*CL15 -> 0 | CO15: =$C15*CN15 -> 0
B16: EQUIPAMENTOS E SISTEMAS ESPECIAIS | C16: 3372799 | D16: =C16/$C$27 -> 0.057331591 | E16: =C16/'DISTRIBUIÇÃO CUSTO'!C$31 -> 193.0283 | F16: =SUM(H16,J16,L16,N16,P16,R16,T16,V16,X16,Z16,AB16,AD16,AF16,AH16,AJ16,AL16,,AN16,AP16,AR16,AT16,AV16,AX16,AZ16,BB16,BD16,BF16,BH16,BJ16,BL16,BN16,BP16,BR16,BT16,BV16,BX16,BZ16,CB16,CD16,CF16,CH16,CJ16,CL16,CN16) -> 1 | I16: =$C16*H16 -> 0 | K16: =$C16*J16 -> 0 | M16: =$C16*L16 -> 0 | O16: =$C16*N16 -> 0 | Q16: =$C16*P16 -> 0 | S16: =$C16*R16 -> 0 | U16: =$C16*T16 -> 0 | W16: =$C16*V16 -> 0 | Y16: =$C16*X16 -> 0 | AA16: =$C16*Z16 -> 0 | AC16: =$C16*AB16 -> 0 | AE16: =$C16*AD16 -> 0 | AG16: =$C16*AF16 -> 0 | AI16: =$C16*AH16 -> 0 | AK16: =$C16*AJ16 -> 0 | AM16: =$C16*AL16 -> 0 | AO16: =$C16*AN16 -> 0 | AQ16: =$C16*AP16 -> 0 | AS16: =$C16*AR16 -> 0 | AU16: =$C16*AT16 -> 0 | AW16: =$C16*AV16 -> 0 | AY16: =$C16*AX16 -> 0 | BA16: =$C16*AZ16 -> 0 | BC16: =$C16*BB16 -> 0 | BE16: =$C16*BD16 -> 0 | BG16: =$C16*BF16 -> 0 | BI16: =$C16*BH16 -> 0 | BJ16: =100%/6 -> 0.16666667 | BK16: =$C16*BJ16 -> 562133.17 | BL16: =100%/6 -> 0.16666667 | BM16: =$C16*BL16 -> 562133.17 | BN16: =100%/6 -> 0.16666667 | BO16: =$C16*BN16 -> 562133.17 | BP16: =100%/6 -> 0.16666667 | BQ16: =$C16*BP16 -> 562133.17 | BR16: =100%/6 -> 0.16666667 | BS16: =$C16*BR16 -> 562133.17 | BT16: =100%/6 -> 0.16666667 | BU16: =$C16*BT16 -> 562133.17 | BW16: =$C16*BV16 -> 0 | BY16: =$C16*BX16 -> 0 | CA16: =$C16*BZ16 -> 0 | CC16: =$C16*CB16 -> 0 | CE16: =$C16*CD16 -> 0 | CG16: =$C16*CF16 -> 0 | CI16: =$C16*CH16 -> 0 | CK16: =$C16*CJ16 -> 0 | CM16: =$C16*CL16 -> 0 | CO16: =$C16*CN16 -> 0
B17: IMPERMEABILIZAÇÃO | C17: 646680 | D17: =C17/$C$27 -> 0.010992411 | E17: =C17/'DISTRIBUIÇÃO CUSTO'!C$31 -> 37.010075 | F17: =SUM(H17,J17,L17,N17,P17,R17,T17,V17,X17,Z17,AB17,AD17,AF17,AH17,AJ17,AL17,,AN17,AP17,AR17,AT17,AV17,AX17,AZ17,BB17,BD17,BF17,BH17,BJ17,BL17,BN17,BP17,BR17,BT17,BV17,BX17,BZ17,CB17,CD17,CF17,CH17,CJ17,CL17,CN17) -> 1 | I17: =$C17*H17 -> 0 | K17: =$C17*J17 -> 0 | M17: =$C17*L17 -> 0 | O17: =$C17*N17 -> 0 | Q17: =$C17*P17 -> 0 | S17: =$C17*R17 -> 0 | U17: =$C17*T17 -> 0 | W17: =$C17*V17 -> 0 | Y17: =$C17*X17 -> 0 | AA17: =$C17*Z17 -> 0 | AC17: =$C17*AB17 -> 0 | AE17: =$C17*AD17 -> 0 | AG17: =$C17*AF17 -> 0 | AI17: =$C17*AH17 -> 0 | AK17: =$C17*AJ17 -> 0 | AM17: =$C17*AL17 -> 0 | AO17: =$C17*AN17 -> 0 | AP17: =100%/16 -> 0.0625 | AQ17: =$C17*AP17 -> 40417.5 | AR17: =100%/16 -> 0.0625 | AS17: =$C17*AR17 -> 40417.5 | AT17: =100%/16 -> 0.0625 | AU17: =$C17*AT17 -> 40417.5 | AV17: =100%/16 -> 0.0625 | AW17: =$C17*AV17 -> 40417.5 | AX17: =100%/16 -> 0.0625 | AY17: =$C17*AX17 -> 40417.5 | AZ17: =100%/16 -> 0.0625 | BA17: =$C17*AZ17 -> 40417.5 | BB17: =100%/16 -> 0.0625 | BC17: =$C17*BB17 -> 40417.5 | BD17: =100%/16 -> 0.0625 | BE17: =$C17*BD17 -> 40417.5 | BF17: =100%/16 -> 0.0625 | BG17: =$C17*BF17 -> 40417.5 | BH17: =100%/16 -> 0.0625 | BI17: =$C17*BH17 -> 40417.5 | BJ17: =100%/16 -> 0.0625 | BK17: =$C17*BJ17 -> 40417.5 | BL17: =100%/16 -> 0.0625 | BM17: =$C17*BL17 -> 40417.5 | BN17: =100%/16 -> 0.0625 | BO17: =$C17*BN17 -> 40417.5 | BP17: =100%/16 -> 0.0625 | BQ17: =$C17*BP17 -> 40417.5 | BR17: =100%/16 -> 0.0625 | BS17: =$C17*BR17 -> 40417.5 | BT17: =100%/16 -> 0.0625 | BU17: =$C17*BT17 -> 40417.5 | BW17: =$C17*BV17 -> 0 | BY17: =$C17*BX17 -> 0 | CA17: =$C17*BZ17 -> 0 | CC17: =$C17*CB17 -> 0 | CE17: =$C17*CD17 -> 0 | CG17: =$C17*CF17 -> 0 | CI17: =$C17*CH17 -> 0 | CK17: =$C17*CJ17 -> 0 | CM17: =$C17*CL17 -> 0 | CO17: =$C17*CN17 -> 0
B18: REVESTIMENTOS INTERNOS EM PISO E PAREDE | C18: 3911886.4 | D18: =C18/$C$27 -> 0.066495119 | E18: =C18/'DISTRIBUIÇÃO CUSTO'!C$31 -> 223.88076 | F18: =SUM(H18,J18,L18,N18,P18,R18,T18,V18,X18,Z18,AB18,AD18,AF18,AH18,AJ18,AL18,,AN18,AP18,AR18,AT18,AV18,AX18,AZ18,BB18,BD18,BF18,BH18,BJ18,BL18,BN18,BP18,BR18,BT18,BV18,BX18,BZ18,CB18,CD18,CF18,CH18,CJ18,CL18,CN18) -> 1 | I18: =$C18*H18 -> 0 | K18: =$C18*J18 -> 0 | M18: =$C18*L18 -> 0 | O18: =$C18*N18 -> 0 | Q18: =$C18*P18 -> 0 | S18: =$C18*R18 -> 0 | U18: =$C18*T18 -> 0 | W18: =$C18*V18 -> 0 | Y18: =$C18*X18 -> 0 | AA18: =$C18*Z18 -> 0 | AC18: =$C18*AB18 -> 0 | AE18: =$C18*AD18 -> 0 | AG18: =$C18*AF18 -> 0 | AI18: =$C18*AH18 -> 0 | AK18: =$C18*AJ18 -> 0 | AM18: =$C18*AL18 -> 0 | AN18: =100%/16 -> 0.0625 | AO18: =$C18*AN18 -> 244492.9 | AP18: =100%/16 -> 0.0625 | AQ18: =$C18*AP18 -> 244492.9 | AR18: =100%/16 -> 0.0625 | AS18: =$C18*AR18 -> 244492.9 | AT18: =100%/16 -> 0.0625 | AU18: =$C18*AT18 -> 244492.9 | AV18: =100%/16 -> 0.0625 | AW18: =$C18*AV18 -> 244492.9 | AX18: =100%/16 -> 0.0625 | AY18: =$C18*AX18 -> 244492.9 | AZ18: =100%/16 -> 0.0625 | BA18: =$C18*AZ18 -> 244492.9 | BB18: =100%/16 -> 0.0625 | BC18: =$C18*BB18 -> 244492.9 | BD18: =100%/16 -> 0.0625 | BE18: =$C18*BD18 -> 244492.9 | BF18: =100%/16 -> 0.0625 | BG18: =$C18*BF18 -> 244492.9 | BH18: =100%/16 -> 0.0625 | BI18: =$C18*BH18 -> 244492.9 | BJ18: =100%/16 -> 0.0625 | BK18: =$C18*BJ18 -> 244492.9 | BL18: =100%/16 -> 0.0625 | BM18: =$C18*BL18 -> 244492.9 | BN18: =100%/16 -> 0.0625 | BO18: =$C18*BN18 -> 244492.9 | BP18: =100%/16 -> 0.0625 | BQ18: =$C18*BP18 -> 244492.9 | BR18: =100%/16 -> 0.0625 | BS18: =$C18*BR18 -> 244492.9 | BU18: =$C18*BT18 -> 0 | BW18: =$C18*BV18 -> 0 | BY18: =$C18*BX18 -> 0 | CA18: =$C18*BZ18 -> 0 | CC18: =$C18*CB18 -> 0 | CE18: =$C18*CD18 -> 0 | CG18: =$C18*CF18 -> 0 | CI18: =$C18*CH18 -> 0 | CK18: =$C18*CJ18 -> 0 | CM18: =$C18*CL18 -> 0 | CO18: =$C18*CN18 -> 0
B19: REVESTIMENTOS E ACABAMENTOS INTERNOS EM TETO | C19: 1954740.9 | D19: =C19/$C$27 -> 0.033227123 | E19: =C19/'DISTRIBUIÇÃO CUSTO'!C$31 -> 111.87157 | F19: =SUM(H19,J19,L19,N19,P19,R19,T19,V19,X19,Z19,AB19,AD19,AF19,AH19,AJ19,AL19,,AN19,AP19,AR19,AT19,AV19,AX19,AZ19,BB19,BD19,BF19,BH19,BJ19,BL19,BN19,BP19,BR19,BT19,BV19,BX19,BZ19,CB19,CD19,CF19,CH19,CJ19,CL19,CN19) -> 1 | I19: =$C19*H19 -> 0 | K19: =$C19*J19 -> 0 | M19: =$C19*L19 -> 0 | O19: =$C19*N19 -> 0 | Q19: =$C19*P19 -> 0 | S19: =$C19*R19 -> 0 | U19: =$C19*T19 -> 0 | W19: =$C19*V19 -> 0 | Y19: =$C19*X19 -> 0 | AA19: =$C19*Z19 -> 0 | AC19: =$C19*AB19 -> 0 | AE19: =$C19*AD19 -> 0 | AG19: =$C19*AF19 -> 0 | AI19: =$C19*AH19 -> 0 | AK19: =$C19*AJ19 -> 0 | AM19: =$C19*AL19 -> 0 | AO19: =$C19*AN19 -> 0 | AQ19: =$C19*AP19 -> 0 | AS19: =$C19*AR19 -> 0 | AT19: =100%/16 -> 0.0625 | AU19: =$C19*AT19 -> 122171.31 | AV19: =100%/16 -> 0.0625 | AW19: =$C19*AV19 -> 122171.31 | AX19: =100%/16 -> 0.0625 | AY19: =$C19*AX19 -> 122171.31 | AZ19: =100%/16 -> 0.0625 | BA19: =$C19*AZ19 -> 122171.31 | BB19: =100%/16 -> 0.0625 | BC19: =$C19*BB19 -> 122171.31 | BD19: =100%/16 -> 0.0625 | BE19: =$C19*BD19 -> 122171.31 | BF19: =100%/16 -> 0.0625 | BG19: =$C19*BF19 -> 122171.31 | BH19: =100%/16 -> 0.0625 | BI19: =$C19*BH19 -> 122171.31 | BJ19: =100%/16 -> 0.0625 | BK19: =$C19*BJ19 -> 122171.31 | BL19: =100%/16 -> 0.0625 | BM19: =$C19*BL19 -> 122171.31 | BN19: =100%/16 -> 0.0625 | BO19: =$C19*BN19 -> 122171.31 | BP19: =100%/16 -> 0.0625 | BQ19: =$C19*BP19 -> 122171.31 | BR19: =100%/16 -> 0.0625 | BS19: =$C19*BR19 -> 122171.31 | BT19: =100%/16 -> 0.0625 | BU19: =$C19*BT19 -> 122171.31 | BV19: =100%/16 -> 0.0625 | BW19: =$C19*BV19 -> 122171.31 | BX19: =100%/16 -> 0.0625 | BY19: =$C19*BX19 -> 122171.31 | CA19: =$C19*BZ19 -> 0 | CC19: =$C19*CB19 -> 0 | CE19: =$C19*CD19 -> 0 | CG19: =$C19*CF19 -> 0 | CI19: =$C19*CH19 -> 0 | CK19: =$C19*CJ19 -> 0 | CM19: =$C19*CL19 -> 0 | CO19: =$C19*CN19 -> 0
B20: ACABAMENTOS EM PISO E PAREDE | C20: 3486357.6 | D20: =C20/$C$27 -> 0.059261886 | E20: =C20/'DISTRIBUIÇÃO CUSTO'!C$31 -> 199.52736 | F20: =SUM(H20,J20,L20,N20,P20,R20,T20,V20,X20,Z20,AB20,AD20,AF20,AH20,AJ20,AL20,,AN20,AP20,AR20,AT20,AV20,AX20,AZ20,BB20,BD20,BF20,BH20,BJ20,BL20,BN20,BP20,BR20,BT20,BV20,BX20,BZ20,CB20,CD20,CF20,CH20,CJ20,CL20,CN20) -> 1 | I20: =$C20*H20 -> 0 | K20: =$C20*J20 -> 0 | M20: =$C20*L20 -> 0 | O20: =$C20*N20 -> 0 | Q20: =$C20*P20 -> 0 | S20: =$C20*R20 -> 0 | U20: =$C20*T20 -> 0 | W20: =$C20*V20 -> 0 | Y20: =$C20*X20 -> 0 | AA20: =$C20*Z20 -> 0 | AC20: =$C20*AB20 -> 0 | AE20: =$C20*AD20 -> 0 | AG20: =$C20*AF20 -> 0 | AI20: =$C20*AH20 -> 0 | AK20: =$C20*AJ20 -> 0 | AM20: =$C20*AL20 -> 0 | AO20: =$C20*AN20 -> 0 | AQ20: =$C20*AP20 -> 0 | AR20: =100%/18 -> 0.055555556 | AS20: =$C20*AR20 -> 193686.53 | AT20: =100%/18 -> 0.055555556 | AU20: =$C20*AT20 -> 193686.53 | AV20: =100%/18 -> 0.055555556 | AW20: =$C20*AV20 -> 193686.53 | AX20: =100%/18 -> 0.055555556 | AY20: =$C20*AX20 -> 193686.53 | AZ20: =100%/18 -> 0.055555556 | BA20: =$C20*AZ20 -> 193686.53 | BB20: =100%/18 -> 0.055555556 | BC20: =$C20*BB20 -> 193686.53 | BD20: =100%/18 -> 0.055555556 | BE20: =$C20*BD20 -> 193686.53 | BF20: =100%/18 -> 0.055555556 | BG20: =$C20*BF20 -> 193686.53 | BH20: =100%/18 -> 0.055555556 | BI20: =$C20*BH20 -> 193686.53 | BJ20: =100%/18 -> 0.055555556 | BK20: =$C20*BJ20 -> 193686.53 | BL20: =100%/18 -> 0.055555556 | BM20: =$C20*BL20 -> 193686.53 | BN20: =100%/18 -> 0.055555556 | BO20: =$C20*BN20 -> 193686.53 | BP20: =100%/18 -> 0.055555556 | BQ20: =$C20*BP20 -> 193686.53 | BR20: =100%/18 -> 0.055555556 | BS20: =$C20*BR20 -> 193686.53 | BT20: =100%/18 -> 0.055555556 | BU20: =$C20*BT20 -> 193686.53 | BV20: =100%/18 -> 0.055555556 | BW20: =$C20*BV20 -> 193686.53 | BX20: =100%/18 -> 0.055555556 | BY20: =$C20*BX20 -> 193686.53 | BZ20: =100%/18 -> 0.055555556 | CA20: =$C20*BZ20 -> 193686.53 | CC20: =$C20*CB20 -> 0 | CE20: =$C20*CD20 -> 0 | CG20: =$C20*CF20 -> 0 | CI20: =$C20*CH20 -> 0 | CK20: =$C20*CJ20 -> 0 | CM20: =$C20*CL20 -> 0 | CO20: =$C20*CN20 -> 0
B21: PINTURA INTERNA | C21: 2122696.8 | D21: =C21/$C$27 -> 0.036082074 | E21: =C21/'DISTRIBUIÇÃO CUSTO'!C$31 -> 121.48383 | F21: =SUM(H21,J21,L21,N21,P21,R21,T21,V21,X21,Z21,AB21,AD21,AF21,AH21,AJ21,AL21,,AN21,AP21,AR21,AT21,AV21,AX21,AZ21,BB21,BD21,BF21,BH21,BJ21,BL21,BN21,BP21,BR21,BT21,BV21,BX21,BZ21,CB21,CD21,CF21,CH21,CJ21,CL21,CN21) -> 1 | I21: =$C21*H21 -> 0 | K21: =$C21*J21 -> 0 | M21: =$C21*L21 -> 0 | O21: =$C21*N21 -> 0 | Q21: =$C21*P21 -> 0 | S21: =$C21*R21 -> 0 | U21: =$C21*T21 -> 0 | W21: =$C21*V21 -> 0 | Y21: =$C21*X21 -> 0 | AA21: =$C21*Z21 -> 0 | AC21: =$C21*AB21 -> 0 | AE21: =$C21*AD21 -> 0 | AG21: =$C21*AF21 -> 0 | AI21: =$C21*AH21 -> 0 | AK21: =$C21*AJ21 -> 0 | AM21: =$C21*AL21 -> 0 | AO21: =$C21*AN21 -> 0 | AQ21: =$C21*AP21 -> 0 | AS21: =$C21*AR21 -> 0 | AU21: =$C21*AT21 -> 0 | AV21: =100%/20 -> 0.05 | AW21: =$C21*AV21 -> 106134.84 | AX21: =100%/20 -> 0.05 | AY21: =$C21*AX21 -> 106134.84 | AZ21: =100%/20 -> 0.05 | BA21: =$C21*AZ21 -> 106134.84 | BB21: =100%/20 -> 0.05 | BC21: =$C21*BB21 -> 106134.84 | BD21: =100%/20 -> 0.05 | BE21: =$C21*BD21 -> 106134.84 | BF21: =100%/20 -> 0.05 | BG21: =$C21*BF21 -> 106134.84 | BH21: =100%/20 -> 0.05 | BI21: =$C21*BH21 -> 106134.84 | BJ21: =100%/20 -> 0.05 | BK21: =$C21*BJ21 -> 106134.84 | BL21: =100%/20 -> 0.05 | BM21: =$C21*BL21 -> 106134.84 | BN21: =100%/20 -> 0.05 | BO21: =$C21*BN21 -> 106134.84 | BP21: =100%/20 -> 0.05 | BQ21: =$C21*BP21 -> 106134.84 | BR21: =100%/20 -> 0.05 | BS21: =$C21*BR21 -> 106134.84 | BT21: =100%/20 -> 0.05 | BU21: =$C21*BT21 -> 106134.84 | BV21: =100%/20 -> 0.05 | BW21: =$C21*BV21 -> 106134.84 | BX21: =100%/20 -> 0.05 | BY21: =$C21*BX21 -> 106134.84 | BZ21: =100%/20 -> 0.05 | CA21: =$C21*BZ21 -> 106134.84 | CB21: =100%/20 -> 0.05 | CC21: =$C21*CB21 -> 106134.84 | CD21: =100%/20 -> 0.05 | CE21: =$C21*CD21 -> 106134.84 | CF21: =100%/20 -> 0.05 | CG21: =$C21*CF21 -> 106134.84 | CH21: =100%/20 -> 0.05 | CI21: =$C21*CH21 -> 106134.84 | CK21: =$C21*CJ21 -> 0 | CM21: =$C21*CL21 -> 0 | CO21: =$C21*CN21 -> 0
B22: ESQUADRIAS, VIDROS E FERRAGENS | C22: 5968623.2 | D22: =C22/$C$27 -> 0.10145599 | E22: =C22/'DISTRIBUIÇÃO CUSTO'!C$31 -> 341.58964 | F22: =SUM(H22,J22,L22,N22,P22,R22,T22,V22,X22,Z22,AB22,AD22,AF22,AH22,AJ22,AL22,,AN22,AP22,AR22,AT22,AV22,AX22,AZ22,BB22,BD22,BF22,BH22,BJ22,BL22,BN22,BP22,BR22,BT22,BV22,BX22,BZ22,CB22,CD22,CF22,CH22,CJ22,CL22,CN22) -> 1 | I22: =$C22*H22 -> 0 | K22: =$C22*J22 -> 0 | M22: =$C22*L22 -> 0 | O22: =$C22*N22 -> 0 | Q22: =$C22*P22 -> 0 | S22: =$C22*R22 -> 0 | U22: =$C22*T22 -> 0 | W22: =$C22*V22 -> 0 | Y22: =$C22*X22 -> 0 | AA22: =$C22*Z22 -> 0 | AC22: =$C22*AB22 -> 0 | AE22: =$C22*AD22 -> 0 | AG22: =$C22*AF22 -> 0 | AI22: =$C22*AH22 -> 0 | AK22: =$C22*AJ22 -> 0 | AM22: =$C22*AL22 -> 0 | AO22: =$C22*AN22 -> 0 | AQ22: =$C22*AP22 -> 0 | AS22: =$C22*AR22 -> 0 | AU22: =$C22*AT22 -> 0 | AW22: =$C22*AV22 -> 0 | AY22: =$C22*AX22 -> 0 | BA22: =$C22*AZ22 -> 0 | BC22: =$C22*BB22 -> 0 | BE22: =$C22*BD22 -> 0 | BG22: =$C22*BF22 -> 0 | BI22: =$C22*BH22 -> 0 | BK22: =$C22*BJ22 -> 0 | BM22: =$C22*BL22 -> 0 | BO22: =$C22*BN22 -> 0 | BQ22: =$C22*BP22 -> 0 | BS22: =$C22*BR22 -> 0 | BU22: =$C22*BT22 -> 0 | BV22: =100%/6 -> 0.16666667 | BW22: =$C22*BV22 -> 994770.53 | BX22: =100%/6 -> 0.16666667 | BY22: =$C22*BX22 -> 994770.53 | BZ22: =100%/6 -> 0.16666667 | CA22: =$C22*BZ22 -> 994770.53 | CB22: =100%/6 -> 0.16666667 | CC22: =$C22*CB22 -> 994770.53 | CD22: =100%/6 -> 0.16666667 | CE22: =$C22*CD22 -> 994770.53 | CF22: =100%/6 -> 0.16666667 | CG22: =$C22*CF22 -> 994770.53 | CI22: =$C22*CH22 -> 0 | CK22: =$C22*CJ22 -> 0 | CM22: =$C22*CL22 -> 0 | CO22: =$C22*CN22 -> 0
B23: COBERTURA | C23: 389789.63 | D23: =C23/$C$27 -> 0.0066257312 | E23: =C23/'DISTRIBUIÇÃO CUSTO'!C$31 -> 22.308009 | F23: =SUM(H23,J23,L23,N23,P23,R23,T23,V23,X23,Z23,AB23,AD23,AF23,AH23,AJ23,AL23,,AN23,AP23,AR23,AT23,AV23,AX23,AZ23,BB23,BD23,BF23,BH23,BJ23,BL23,BN23,BP23,BR23,BT23,BV23,BX23,BZ23,CB23,CD23,CF23,CH23,CJ23,CL23,CN23) -> 1 | I23: =$C23*H23 -> 0 | K23: =$C23*J23 -> 0 | M23: =$C23*L23 -> 0 | O23: =$C23*N23 -> 0 | Q23: =$C23*P23 -> 0 | S23: =$C23*R23 -> 0 | U23: =$C23*T23 -> 0 | W23: =$C23*V23 -> 0 | Y23: =$C23*X23 -> 0 | AA23: =$C23*Z23 -> 0 | AC23: =$C23*AB23 -> 0 | AE23: =$C23*AD23 -> 0 | AG23: =$C23*AF23 -> 0 | AI23: =$C23*AH23 -> 0 | AK23: =$C23*AJ23 -> 0 | AM23: =$C23*AL23 -> 0 | AO23: =$C23*AN23 -> 0 | AQ23: =$C23*AP23 -> 0 | AS23: =$C23*AR23 -> 0 | AU23: =$C23*AT23 -> 0 | AW23: =$C23*AV23 -> 0 | AY23: =$C23*AX23 -> 0 | BA23: =$C23*AZ23 -> 0 | BC23: =$C23*BB23 -> 0 | BE23: =$C23*BD23 -> 0 | BG23: =$C23*BF23 -> 0 | BI23: =$C23*BH23 -> 0 | BK23: =$C23*BJ23 -> 0 | BM23: =$C23*BL23 -> 0 | BO23: =$C23*BN23 -> 0 | BQ23: =$C23*BP23 -> 0 | BR23: =100%/4 -> 0.25 | BS23: =$C23*BR23 -> 97447.407 | BT23: =100%/4 -> 0.25 | BU23: =$C23*BT23 -> 97447.407 | BV23: =100%/4 -> 0.25 | BW23: =$C23*BV23 -> 97447.407 | BX23: =100%/4 -> 0.25 | BY23: =$C23*BX23 -> 97447.407 | CA23: =$C23*BZ23 -> 0 | CC23: =$C23*CB23 -> 0 | CE23: =$C23*CD23 -> 0 | CG23: =$C23*CF23 -> 0 | CI23: =$C23*CH23 -> 0 | CK23: =$C23*CJ23 -> 0 | CM23: =$C23*CL23 -> 0 | CO23: =$C23*CN23 -> 0
B24: REVESTIMENTOS E ACABAMENTOS DE FACHADA | C24: 1910131.1 | D24: =C24/$C$27 -> 0.032468835 | E24: =C24/'DISTRIBUIÇÃO CUSTO'!C$31 -> 109.31851 | F24: =SUM(H24,J24,L24,N24,P24,R24,T24,V24,X24,Z24,AB24,AD24,AF24,AH24,AJ24,AL24,,AN24,AP24,AR24,AT24,AV24,AX24,AZ24,BB24,BD24,BF24,BH24,BJ24,BL24,BN24,BP24,BR24,BT24,BV24,BX24,BZ24,CB24,CD24,CF24,CH24,CJ24,CL24,CN24) -> 1 | I24: =$C24*H24 -> 0 | K24: =$C24*J24 -> 0 | M24: =$C24*L24 -> 0 | O24: =$C24*N24 -> 0 | Q24: =$C24*P24 -> 0 | S24: =$C24*R24 -> 0 | U24: =$C24*T24 -> 0 | W24: =$C24*V24 -> 0 | Y24: =$C24*X24 -> 0 | AA24: =$C24*Z24 -> 0 | AC24: =$C24*AB24 -> 0 | AE24: =$C24*AD24 -> 0 | AG24: =$C24*AF24 -> 0 | AI24: =$C24*AH24 -> 0 | AK24: =$C24*AJ24 -> 0 | AM24: =$C24*AL24 -> 0 | AO24: =$C24*AN24 -> 0 | AQ24: =$C24*AP24 -> 0 | AS24: =$C24*AR24 -> 0 | AU24: =$C24*AT24 -> 0 | AW24: =$C24*AV24 -> 0 | AY24: =$C24*AX24 -> 0 | BA24: =$C24*AZ24 -> 0 | BC24: =$C24*BB24 -> 0 | BE24: =$C24*BD24 -> 0 | BG24: =$C24*BF24 -> 0 | BI24: =$C24*BH24 -> 0 | BK24: =$C24*BJ24 -> 0 | BM24: =$C24*BL24 -> 0 | BO24: =$C24*BN24 -> 0 | BP24: =100%/8 -> 0.125 | BQ24: =$C24*BP24 -> 238766.38 | BR24: =100%/8 -> 0.125 | BS24: =$C24*BR24 -> 238766.38 | BT24: =100%/8 -> 0.125 | BU24: =$C24*BT24 -> 238766.38 | BV24: =100%/8 -> 0.125 | BW24: =$C24*BV24 -> 238766.38 | BX24: =100%/8 -> 0.125 | BY24: =$C24*BX24 -> 238766.38 | BZ24: =100%/8 -> 0.125 | CA24: =$C24*BZ24 -> 238766.38 | CB24: =100%/8 -> 0.125 | CC24: =$C24*CB24 -> 238766.38 | CD24: =100%/8 -> 0.125 | CE24: =$C24*CD24 -> 238766.38 | CG24: =$C24*CF24 -> 0 | CI24: =$C24*CH24 -> 0 | CK24: =$C24*CJ24 -> 0 | CM24: =$C24*CL24 -> 0 | CO24: =$C24*CN24 -> 0
B25: SERVIÇOS COMPLEMENTARES | C25: 2243441.3 | D25: =C25/$C$27 -> 0.038134517 | E25: =C25/'DISTRIBUIÇÃO CUSTO'!C$31 -> 128.39415 | F25: =SUM(H25,J25,L25,N25,P25,R25,T25,V25,X25,Z25,AB25,AD25,AF25,AH25,AJ25,AL25,,AN25,AP25,AR25,AT25,AV25,AX25,AZ25,BB25,BD25,BF25,BH25,BJ25,BL25,BN25,BP25,BR25,BT25,BV25,BX25,BZ25,CB25,CD25,CF25,CH25,CJ25,CL25,CN25) -> 1 | I25: =$C25*H25 -> 0 | K25: =$C25*J25 -> 0 | M25: =$C25*L25 -> 0 | O25: =$C25*N25 -> 0 | Q25: =$C25*P25 -> 0 | S25: =$C25*R25 -> 0 | U25: =$C25*T25 -> 0 | W25: =$C25*V25 -> 0 | Y25: =$C25*X25 -> 0 | AA25: =$C25*Z25 -> 0 | AC25: =$C25*AB25 -> 0 | AE25: =$C25*AD25 -> 0 | AG25: =$C25*AF25 -> 0 | AI25: =$C25*AH25 -> 0 | AK25: =$C25*AJ25 -> 0 | AM25: =$C25*AL25 -> 0 | AO25: =$C25*AN25 -> 0 | AQ25: =$C25*AP25 -> 0 | AS25: =$C25*AR25 -> 0 | AU25: =$C25*AT25 -> 0 | AW25: =$C25*AV25 -> 0 | AY25: =$C25*AX25 -> 0 | BA25: =$C25*AZ25 -> 0 | BC25: =$C25*BB25 -> 0 | BE25: =$C25*BD25 -> 0 | BG25: =$C25*BF25 -> 0 | BI25: =$C25*BH25 -> 0 | BK25: =$C25*BJ25 -> 0 | BM25: =$C25*BL25 -> 0 | BO25: =$C25*BN25 -> 0 | BQ25: =$C25*BP25 -> 0 | BS25: =$C25*BR25 -> 0 | BU25: =$C25*BT25 -> 0 | BW25: =$C25*BV25 -> 0 | BY25: =$C25*BX25 -> 0 | BZ25: =100%/8 -> 0.125 | CA25: =$C25*BZ25 -> 280430.16 | CB25: =100%/8 -> 0.125 | CC25: =$C25*CB25 -> 280430.16 | CD25: =100%/8 -> 0.125 | CE25: =$C25*CD25 -> 280430.16 | CF25: =100%/8 -> 0.125 | CG25: =$C25*CF25 -> 280430.16 | CH25: =100%/8 -> 0.125 | CI25: =$C25*CH25 -> 280430.16 | CJ25: =100%/8 -> 0.125 | CK25: =$C25*CJ25 -> 280430.16 | CL25: =100%/8 -> 0.125 | CM25: =$C25*CL25 -> 280430.16 | CN25: =100%/8 -> 0.125 | CO25: =$C25*CN25 -> 280430.16
B26: IMPREVISTOS E CONTINGENCIAS | C26: 2139091.8 | D26: =C26/$C$27 -> 0.03636076 | E26: =C26/'DISTRIBUIÇÃO CUSTO'!C$31 -> 122.42214 | F26: =SUM(H26,J26,L26,N26,P26,R26,T26,V26,X26,Z26,AB26,AD26,AF26,AH26,AJ26,AL26,,AN26,AP26,AR26,AT26,AV26,AX26,AZ26,BB26,BD26,BF26,BH26,BJ26,BL26,BN26,BP26,BR26,BT26,BV26,BX26,BZ26,CB26,CD26,CF26,CH26,CJ26,CL26,CN26) -> 1 | H26: =100%/$E$31 -> 0.023255814 | I26: =$C26*H26 -> 49746.32 | J26: =100%/$E$31 -> 0.023255814 | K26: =$C26*J26 -> 49746.32 | L26: =100%/$E$31 -> 0.023255814 | M26: =$C26*L26 -> 49746.32 | N26: =100%/$E$31 -> 0.023255814 | O26: =$C26*N26 -> 49746.32 | P26: =100%/$E$31 -> 0.023255814 | Q26: =$C26*P26 -> 49746.32 | R26: =100%/$E$31 -> 0.023255814 | S26: =$C26*R26 -> 49746.32 | T26: =100%/$E$31 -> 0.023255814 | U26: =$C26*T26 -> 49746.32 | V26: =100%/$E$31 -> 0.023255814 | W26: =$C26*V26 -> 49746.32 | X26: =100%/$E$31 -> 0.023255814 | Y26: =$C26*X26 -> 49746.32 | Z26: =100%/$E$31 -> 0.023255814 | AA26: =$C26*Z26 -> 49746.32 | AB26: =100%/$E$31 -> 0.023255814 | AC26: =$C26*AB26 -> 49746.32 | AD26: =100%/$E$31 -> 0.023255814 | AE26: =$C26*AD26 -> 49746.32 | AF26: =100%/$E$31 -> 0.023255814 | AG26: =$C26*AF26 -> 49746.32 | AH26: =100%/$E$31 -> 0.023255814 | AI26: =$C26*AH26 -> 49746.32 | AJ26: =100%/$E$31 -> 0.023255814 | AK26: =$C26*AJ26 -> 49746.32 | AL26: =100%/$E$31 -> 0.023255814 | AM26: =$C26*AL26 -> 49746.32 | AN26: =100%/$E$31 -> 0.023255814 | AO26: =$C26*AN26 -> 49746.32 | AP26: =100%/$E$31 -> 0.023255814 | AQ26: =$C26*AP26 -> 49746.32 | AR26: =100%/$E$31 -> 0.023255814 | AS26: =$C26*AR26 -> 49746.32 | AT26: =100%/$E$31 -> 0.023255814 | AU26: =$C26*AT26 -> 49746.32 | AV26: =100%/$E$31 -> 0.023255814 | AW26: =$C26*AV26 -> 49746.32 | AX26: =100%/$E$31 -> 0.023255814 | AY26: =$C26*AX26 -> 49746.32 | AZ26: =100%/$E$31 -> 0.023255814 | BA26: =$C26*AZ26 -> 49746.32 | BB26: =100%/$E$31 -> 0.023255814 | BC26: =$C26*BB26 -> 49746.32 | BD26: =100%/$E$31 -> 0.023255814 | BE26: =$C26*BD26 -> 49746.32 | BF26: =100%/$E$31 -> 0.023255814 | BG26: =$C26*BF26 -> 49746.32 | BH26: =100%/$E$31 -> 0.023255814 | BI26: =$C26*BH26 -> 49746.32 | BJ26: =100%/$E$31 -> 0.023255814 | BK26: =$C26*BJ26 -> 49746.32 | BL26: =100%/$E$31 -> 0.023255814 | BM26: =$C26*BL26 -> 49746.32 | BN26: =100%/$E$31 -> 0.023255814 | BO26: =$C26*BN26 -> 49746.32 | BP26: =100%/$E$31 -> 0.023255814 | BQ26: =$C26*BP26 -> 49746.32 | BR26: =100%/$E$31 -> 0.023255814 | BS26: =$C26*BR26 -> 49746.32 | BT26: =100%/$E$31 -> 0.023255814 | BU26: =$C26*BT26 -> 49746.32 | BV26: =100%/$E$31 -> 0.023255814 | BW26: =$C26*BV26 -> 49746.32 | BX26: =100%/$E$31 -> 0.023255814 | BY26: =$C26*BX26 -> 49746.32 | BZ26: =100%/$E$31 -> 0.023255814 | CA26: =$C26*BZ26 -> 49746.32 | CB26: =100%/$E$31 -> 0.023255814 | CC26: =$C26*CB26 -> 49746.32 | CD26: =100%/$E$31 -> 0.023255814 | CE26: =$C26*CD26 -> 49746.32 | CF26: =100%/$E$31 -> 0.023255814 | CG26: =$C26*CF26 -> 49746.32 | CH26: =100%/$E$31 -> 0.023255814 | CI26: =$C26*CH26 -> 49746.32 | CJ26: =100%/$E$31 -> 0.023255814 | CK26: =$C26*CJ26 -> 49746.32 | CL26: =100%/$E$31 -> 0.023255814 | CM26: =$C26*CL26 -> 49746.32 | CN26: =100%/$E$31 -> 0.023255814 | CO26: =$C26*CN26 -> 49746.32
B27: TOTAL | C27: =SUM(C9:C26) -> 58829677 | D27: =SUM(D9:D26) -> 1 | E27: =SUM(E9:E26) -> 3366.875 | I27: =SUM(I9:I26) -> 948960.7 | K27: =SUM(K9:K26) -> 913913.56 | M27: =SUM(M9:M26) -> 913913.56 | O27: =SUM(O9:O26) -> 843819.28 | Q27: =SUM(Q9:Q26) -> 843819.28 | S27: =SUM(S9:S26) -> 843819.28 | U27: =SUM(U9:U26) -> 866857.78 | W27: =SUM(W9:W26) -> 866857.78 | Y27: =SUM(Y9:Y26) -> 866857.78 | AA27: =SUM(AA9:AA26) -> 866857.78 | AC27: =SUM(AC9:AC26) -> 866857.78 | AE27: =SUM(AE9:AE26) -> 765289.98 | AG27: =SUM(AG9:AG26) -> 765289.98 | AI27: =SUM(AI9:AI26) -> 765289.98 | AK27: =SUM(AK9:AK26) -> 930859.01 | AM27: =SUM(AM9:AM26) -> 1333645.3 | AO27: =SUM(AO9:AO26) -> 1578138.2 | AQ27: =SUM(AQ9:AQ26) -> 1618555.7 | AS27: =SUM(AS9:AS26) -> 1812242.2 | AU27: =SUM(AU9:AU26) -> 1934413.5 | AW27: =SUM(AW9:AW26) -> 2040548.4 | AY27: =SUM(AY9:AY26) -> 2040548.4 | BA27: =SUM(BA9:BA26) -> 2040548.4 | BC27: =SUM(BC9:BC26) -> 2040548.4 | BE27: =SUM(BE9:BE26) -> 2040548.4 | BG27: =SUM(BG9:BG26) -> 2040548.4 | BI27: =SUM(BI9:BI26) -> 2040548.4 | BK27: =SUM(BK9:BK26) -> 1952496.1 | BM27: =SUM(BM9:BM26) -> 1952496.1 | BO27: =SUM(BO9:BO26) -> 1952496.1 | BQ27: =SUM(BQ9:BQ26) -> 2025693.4 | BS27: =SUM(BS9:BS26) -> 1720354.5 | BU27: =SUM(BU9:BU26) -> 1475861.6 | BW27: =SUM(BW9:BW26) -> 1868081.5 | BY27: =SUM(BY9:BY26) -> 1868081.5 | CA27: =SUM(CA9:CA26) -> 1928892.9 | CC27: =SUM(CC9:CC26) -> 1735206.4 | CE27: =SUM(CE9:CE26) -> 1735206.4 | CG27: =SUM(CG9:CG26) -> 1496440 | CI27: =SUM(CI9:CI26) -> 501669.5 | CK27: =SUM(CK9:CK26) -> 395534.66 | CM27: =SUM(CM9:CM26) -> 395534.66 | CO27: =SUM(CO9:CO26) -> 395534.66 | CP27: SOMA TOTAL
B28: CUB/SC | C28: 2846.12 | D28: 45566 | E28: =+E27/C28 -> 1.1829702 | I28: =I27/$C$27 -> 0.016130646 | K28: =K27/$C$27 -> 0.015534907 | M28: =M27/$C$27 -> 0.015534907 | O28: =O27/$C$27 -> 0.014343429 | Q28: =Q27/$C$27 -> 0.014343429 | S28: =S27/$C$27 -> 0.014343429 | U28: =U27/$C$27 -> 0.014735042 | W28: =W27/$C$27 -> 0.014735042 | Y28: =Y27/$C$27 -> 0.014735042 | AA28: =AA27/$C$27 -> 0.014735042 | AC28: =AC27/$C$27 -> 0.014735042 | AE28: =AE27/$C$27 -> 0.01300857 | AG28: =AG27/$C$27 -> 0.01300857 | AI28: =AI27/$C$27 -> 0.01300857 | AK28: =AK27/$C$27 -> 0.015822949 | AM28: =AM27/$C$27 -> 0.022669601 | AO28: =AO27/$C$27 -> 0.026825546 | AQ28: =AQ27/$C$27 -> 0.027512571 | AS28: =AS27/$C$27 -> 0.030804898 | AU28: =AU27/$C$27 -> 0.032881593 | AW28: =AW27/$C$27 -> 0.034685697 | AY28: =AY27/$C$27 -> 0.034685697 | BA28: =BA27/$C$27 -> 0.034685697 | BC28: =BC27/$C$27 -> 0.034685697 | BE28: =BE27/$C$27 -> 0.034685697 | BG28: =BG27/$C$27 -> 0.034685697 | BI28: =BI27/$C$27 -> 0.034685697 | BK28: =BK27/$C$27 -> 0.033188964 | BM28: =BM27/$C$27 -> 0.033188964 | BO28: =BO27/$C$27 -> 0.033188964 | BQ28: =BQ27/$C$27 -> 0.034433189 | BS28: =BS27/$C$27 -> 0.029242971 | BU28: =BU27/$C$27 -> 0.025087026 | BW28: =BW27/$C$27 -> 0.031754067 | BY28: =BY27/$C$27 -> 0.031754067 | CA28: =CA27/$C$27 -> 0.032787753 | CC28: =CC27/$C$27 -> 0.029495426 | CE28: =CE27/$C$27 -> 0.029495426 | CG28: =CG27/$C$27 -> 0.025436822 | CI28: =CI27/$C$27 -> 0.0085274903 | CK28: =CK27/$C$27 -> 0.0067233866 | CM28: =CM27/$C$27 -> 0.0067233866 | CO28: =CO27/$C$27 -> 0.0067233866 | CP28: =SUM(I27:CO27) -> 58829677
C30: ÁREA CONSTRUÍDA | E30: Prazo de obra
C31: 17473.08 | D31: m² | E31: 43
C32: Mês | D32: %
C33: M1 | D33: =I28 -> 0.016130646
C34: M2 | D34: =K28 -> 0.015534907
C35: M3 | D35: =M28 -> 0.015534907
C36: M4 | D36: =O28 -> 0.014343429
C37: M5 | D37: =Q28 -> 0.014343429
C38: M6 | D38: =S28 -> 0.014343429
C39: M7 | D39: =U28 -> 0.014735042
C40: M8 | D40: =W28 -> 0.014735042
C41: M9 | D41: =Y28 -> 0.014735042
C42: M10 | D42: =AA28 -> 0.014735042
C43: M11 | D43: =AC28 -> 0.014735042
C44: M12 | D44: =AE28 -> 0.01300857
C45: M13 | D45: =AG28 -> 0.01300857
...

Sheet CURVA PARAMÉTRICA
B2: CURVA S | % PARAMÉTRICO
B5: COTA - 365 (Afonso Pena)
B8: Mês | C8: % AVANÇO | D8: % AVANÇO Acumulado | E8: Valor Planejado | F8: Valor Planejado Acumulado
B9: 1 | C9: ='DISTRIBUIÇÃO CUSTO'!D33 -> 0.016130646 | D9: =C9 -> 0.016130646 | E9: =C9*$F$52 -> 948960.7 | F9: =E9 -> 948960.7
B10: 2 | C10: ='DISTRIBUIÇÃO CUSTO'!D34 -> 0.015534907 | D10: =C10+D9 -> 0.031665553 | E10: =C10*$F$52 -> 913913.56 | F10: =F9+E10 -> 1862874.3
B11: 3 | C11: ='DISTRIBUIÇÃO CUSTO'!D35 -> 0.015534907 | D11: =C11+D10 -> 0.04720046 | E11: =C11*$F$52 -> 913913.56 | F11: =F10+E11 -> 2776787.8
B12: 4 | C12: ='DISTRIBUIÇÃO CUSTO'!D36 -> 0.014343429 | D12: =C12+D11 -> 0.061543889 | E12: =C12*$F$52 -> 843819.28 | F12: =F11+E12 -> 3620607.1
B13: 5 | C13: ='DISTRIBUIÇÃO CUSTO'!D37 -> 0.014343429 | D13: =C13+D12 -> 0.075887318 | E13: =C13*$F$52 -> 843819.28 | F13: =F12+E13 -> 4464426.4
B14: 6 | C14: ='DISTRIBUIÇÃO CUSTO'!D38 -> 0.014343429 | D14: =C14+D13 -> 0.090230746 | E14: =C14*$F$52 -> 843819.28 | F14: =F13+E14 -> 5308245.7
B15: 7 | C15: ='DISTRIBUIÇÃO CUSTO'!D39 -> 0.014735042 | D15: =C15+D14 -> 0.10496579 | E15: =C15*$F$52 -> 866857.78 | F15: =F14+E15 -> 6175103.5
B16: 8 | C16: ='DISTRIBUIÇÃO CUSTO'!D40 -> 0.014735042 | D16: =C16+D15 -> 0.11970083 | E16: =C16*$F$52 -> 866857.78 | F16: =F15+E16 -> 7041961.2
B17: 9 | C17: ='DISTRIBUIÇÃO CUSTO'!D41 -> 0.014735042 | D17: =C17+D16 -> 0.13443587 | E17: =C17*$F$52 -> 866857.78 | F17: =F16+E17 -> 7908819
B18: 10 | C18: ='DISTRIBUIÇÃO CUSTO'!D42 -> 0.014735042 | D18: =C18+D17 -> 0.14917092 | E18: =C18*$F$52 -> 866857.78 | F18: =F17+E18 -> 8775676.8
B19: 11 | C19: ='DISTRIBUIÇÃO CUSTO'!D43 -> 0.014735042 | D19: =C19+D18 -> 0.16390596 | E19: =C19*$F$52 -> 866857.78 | F19: =F18+E19 -> 9642534.6
B20: 12 | C20: ='DISTRIBUIÇÃO CUSTO'!D44 -> 0.01300857 | D20: =C20+D19 -> 0.17691453 | E20: =C20*$F$52 -> 765289.98 | F20: =F19+E20 -> 10407825
B21: 13 | C21: ='DISTRIBUIÇÃO CUSTO'!D45 -> 0.01300857 | D21: =C21+D20 -> 0.1899231 | E21: =C21*$F$52 -> 765289.98 | F21: =F20+E21 -> 11173115
... B51: 43 | C51: ='DISTRIBUIÇÃO CUSTO'!D75 -> 0.0067233866 | D51: =C51+D50 -> 1 | E51: =C51*$F$52 -> 395534.66 | F51: =F50+E51 -> 58829677
E52: Total | F52: ='DISTRIBUIÇÃO CUSTO'!C27 -> 58829677
