Workbook
Name \0: #REF!
Name \0: #REF!
Name \0: #REF!
Name \0: #REF!
Name \0: #REF!
Name \0: #REF!
Name \0: #REF!
Name \a: #REF!
Name \a: #REF!
Name \m: #REF!
Name \m: #REF!
Name aa: #REF!
Name aa: #REF!
Name aaaa: '[1]M.O.'!#REF!
Name aaaa: '[1]M.O.'!#REF!
Name aaaa: '[1]M.O.'!#REF!
Name aaaa: '[1]M.O.'!#REF!
Name aaaa: '[1]M.O.'!#REF!
Name aaaa: '[1]M.O.'!#REF!
Name aaaa: '[1]M.O.'!#REF!
Name angelo: [2]Geral!#REF!
Name angelo: [2]Geral!#REF!
Name angelo: [2]Geral!#REF!
Name angelo: [2]Geral!#REF!
Name angelo: [2]Geral!#REF!
Name angelo: [2]Geral!#REF!
Name angelo: [2]Geral!#REF!
Name area: #REF!
Name aux: #REF!
Name aux: #REF!
Name aux: #REF!
Name aux: #REF!
Name aux: #REF!
Name aux: #REF!
Name aux: #REF!
Name BDA: #REF!
Name BDA: #REF!
Name BDI: #REF!
Name ca: #REF!
Name Capa: #REF!
Name cronograma: #REF!
Name D: #REF!
Name direto: #REF!
Name DRE: #REF!
Name ea: #REF!
Name FFFFFFF: #REF!
Name FFFFFFF: #REF!
Name FFFFFFF: #REF!
Name FFFFFFF: #REF!
Name FFFFFFF: #REF!
Name FFFFFFF: #REF!
Name FFFFFFF: #REF!
Name item_1: #REF!
Name item_1: #REF!
Name item_1: #REF!
Name item_1: #REF!
Name item_1: #REF!
Name item_1: #REF!
Name item_1: #REF!
Name LS: '[1]M.O.'!#REF!

Sheet DADOS_INICIAIS
A1: Obra | B1: Estreito
A2: Empresa | B2: D'Lohn Empreendimentos
A3: Revisão | B3: R00
A4: Arquitetura base | B4: GEM-ETO-ARQ-EP-101/2/3/4/5/6/-R03
A5: DADOS OBRA
B7: Descrição | C7: Identificador | D7: Unidade | E7: Quantidade
B8: ÁREA DO TERRENO | C8: AT | D8: M2 | E8: 1575
B9: ÁREA TOTAL CONSTRUÍDA | C9: AC | D9: M2 | E9: 13147.78
B10: UNIDADES RESIDENCIAIS | C10: UR | D10: UN | E10: 84
B11: Dormitórios | C11: dorm | D11: UN
B12: Banheiros | C12: ban | D12: UN
B13: UNIDADES COMERCIAIS | C13: UC | D13: UN | E13: 5
B14: Churrasqueiras | C14: CHU | D14: UN | E14: ='SISTEMAS ESPECIAIS'!B10 -> 86
B15: NÚMERO TOTAL DE PAVIMENTOS | C15: NP | D15: UN | E15: 13
B16: NÚMERO DE PAVIMENTOS TIPO | C16: NPT | D16: UN | E16: 8
B17: NÚMERO DE PAVIMENTOS TIPO DIFERENCIADOS | C17: NPD | D17: UN | E17: 0
B18: NÚMERO DE PAVIMENTOS DUPLEX | C18: ND | D18: UN | E18: 0
B19: ÁREA DE PROJEÇÃO DA TORRE | C19: APT | D19: M2 | E19: 948.31
B20: PERÍMETRO DE PROJEÇÃO DA TORRE | C20: PPT | D20: M | E20: 132.16
B21: ÁREA DE LAZER | C21: AL | D21: M2 | E21: =92.36+11.33+7.41+7.83+7.83+2.65+3.09+50.23+64.15+90.44+9.73+39.9+34.62+21.23+19.14+112.8+134.69 -> 709.43
B22: ÁREA DO EMBASAMENTO | C22: AE | D22: M2 | E22: =1250.39+921.05 -> 2171.44
B23: ÁREA DE SUBSOLOS | C23: S | D23: M2 | E23: =1488.24+1488.24 -> 2976.48
B24: NÚMERO DE SUBSOLOS | C24: NS | D24: UN | E24: 2
B25: ÁREA DE PROJEÇÃO DO EMBASAMENTO | C25: APE | D25: M2 | E25: 1488.24
B26: PERÍMETRO DE PROJEÇÃO DE EMBAMENTO | C26: PE | D26: M | E26: 157.96
B27: NÚMERO DE PAVIMENTOS DE EMBASAMENTO | C27: NE | D27: UN | E27: 2

Sheet MOVIMENTAÇÃO_DE_TERRA
A2: MOVIMENTAÇÃO DE TERRA
A3: Data | B3: 45727
A4: Arquivo base | B4: -
A6: ESCAVAÇÃO VERTICAL DE SUBSOLO
A8: Descrição | B8: Área de subsolo (m2) | C8: Altura do subsolo (m) | D8: Volume total de escavação (m3) | E8: Preço unitário de escavação (R$ / m3) | F8: Valor total | G8: Observação
A9: Escavação | B9: =DADOS_INICIAIS!E25 -> 1488.24 | C9: 6 | D9: =(C9*B9) -> 8929.44 | E9: 2.66 | F9: =E9*D9*1.1 -> 26127.541
A10: Movimentação de bota-fora | D10: =D9*1.3 -> 11608.272 | E10: 45.45 | F10: =E10*D10*1.1 -> 580355.56 | G10: 30% de empolamento
A11: TOTAL | F11: =SUM(F9:F10) -> 606483.1
A13: REBAIXAMENTO DE LENÇOL FREÁTICO
A15: Descrição | B15: Quantidade (dias) | E15: Preço unitário de rebaixamento (R$ / dias) | F15: Valor total | G15: Observação
A16: Rebaixamento de lençol | B16: 0 | E16: 200 | F16: =B16*E16*1.1 -> 0 | G16: Sem rebaixamento
A17: TOTAL | F17: =SUM(F16:F16) -> 0
A19: ESCAVAÇÃO E REATERRO DE VALAS
A21: Descrição | B21: Parâmetro | D21: Volume total de escavação (m3) | E21: Preço unitário (R$ / m3) | F21: Valor total | G21: Observação
A22: Escavação mecanizada para blocos e baldrames | B22: 1.3 | C22: m³ / Vol infra | D22: =B22*INFRAESTRUTURA!D29 -> 444.98376 | E22: 36.36 | F22: =E22*D22*1.1 -> 17797.57
A23: Reaterro para blocos e baldrames | B23: 0.6 | C23: m³ / Vol Escavação | D23: =D22-INFRAESTRUTURA!D29 -> 102.68856 | E23: 14.55 | F23: =E23*D23*1.1 -> 1643.5304
A24: Movimentação de bota-fora | B24: 1.3 | D24: =(D22-D23)*B24 -> 444.98376 | E24: 45.45 | F24: =E24*D24*1.1 -> 22246.963
A25: Movimentação de terra das estacas | B25: 1 | C25: m³ | D25: =INFRAESTRUTURA!D19 -> 1454.7145 | E25: 68.18 | F25: =E25*D25*1.1 -> 109100.68
A26: TOTAL | F26: =SUM(F22:F25) -> 150788.74
A28: REGULARIZAÇÃO E APILOAMENTO DE FUNDO DE VALAS
A30: Descrição | B30: Parâmetro | D30: Área de lastro (m²) | E30: Preço unitário (R$ / m2) | F30: Valor total | G30: Observação
A31: Lastro de concreto magto e=10cm | B31: 0.8 | C31: m² / APE | D31: =B31*DADOS_INICIAIS!E25 -> 1190.592 | E31: =370*0.1 -> 37 | F31: =E31*D31*1.1 -> 48457.094 | H31: =F31/DADOS_INICIAIS!E25 -> 32.56
A32: TOTAL | F32: =SUM(F31:F31) -> 48457.094
A34: TOTAL MOVIMENTAÇÃO DE TERRA | F34: =F11+F17+F26+F32 -> 805728.93 | G34: =F34/DADOS_INICIAIS!E9 -> 61.282508

Sheet CONTENÇÕES
A3: CONTENÇÃO
A4: Data
A5: Arquivo base
A7: CORTINA DE ESTACAS
A9: Descrição | B9: Parâmetro | D9: Quantidade | F9: Preço unitário | G9: Valor total
A10: Número de Estacas | B10: 0.15 | C10: un / APE | D10: =B10*DADOS_INICIAIS!E25 -> 223.236 | E10: un
A11: Estaca Hélice Continua Diâmetro 40 | B11: 0.1 | D11: =B11*$D$10 -> 22.3236 | E11: un
B12: 20 | C12: m/un | D12: =B12*D11 -> 446.472 | E12: m | G12: =F12*D12 -> 0
A13: Estaca Hélice Continua Diâmetro 50 | B13: 0.5 | D13: =B13*$D$10 -> 111.618 | E13: un
B14: 20 | C14: m/un | D14: =B14*D13 -> 2232.36 | E14: m | G14: =F14*D14 -> 0
A15: Estaca Hélice Continua Diâmetro 60 | B15: 0.4 | C15: un / APE | D15: =B15*$D$10 -> 89.2944 | E15: un
B16: 20 | C16: m/un | D16: =B16*D15 -> 1785.888 | E16: m | G16: =F16*D16 -> 0
A17: Concreto | B17: =(PI()*0.4^2)/4*D14+(PI()*0.5^2)/4*D16+(PI()*0.6^2)/4*D12 -> 757.4219 | C17: un / APE | D17: =(PI()*0.4^2)/4*D14+(PI()*0.5^2)/4*D16+(PI()*0.6^2)/4*D12 -> 757.4219 | E17: m³ | G17: =F17*D17 -> 0
A18: Armação 6,3mm | B18: 1.6575131 | C18: kg / m³ | D18: =B18*D17 -> 1255.4367 | E18: kg | G18: =F18*D18 -> 0
A19: Armação 16mm | B19: 10.178338 | C19: kg / m³ | D19: =B19*D17 -> 7709.2958 | E19: kg | G19: =F19*D19 -> 0
A20: Mobilização | B20: 1 | C20: vb | D20: 1 | E20: vb | G20: =F20*D20 -> 0
A21: TOTAL | G21: =SUM(G10:G20) -> 0
A23: PAREDE DE CONCRETO
A25: Descrição | B25: Parâmetro | D25: Quantidade | F25: Preço unitário | G25: Valor total
A26: Fabricação, montagem e desmontagem de forma para blocos e baldrames resinado | B26: 2.1 | C26: m² / APE | D26: =B26*DADOS_INICIAIS!E25 -> 3125.304 | E26: m² | G26: =F26*D26 -> 0
A27: Concreto | B27: 0.65 | C27: m³ / APE | D27: =B27*DADOS_INICIAIS!E25 -> 967.356 | E27: m³ | G27: =F27*D27 -> 0
A28: Armação | B28: 110 | C28: kg / m³ | D28: =B28*D27 -> 106409.16 | E28: kg | G28: =F28*D28 -> 0
A29: Mão de obra | B29: =SUPRAESTRUTURA!B15*1.5 -> 360 | C29: R$ / APE | D29: =DADOS_INICIAIS!E25 -> 1488.24 | E29: m² | F29: =B29 -> 360 | G29: =F29*D29 -> 535766.4
A30: TOTAL | G30: =SUM(G26:G29) -> 535766.4
A33: PAREDE DIAFRAGMA
A35: Descrição | B35: Parâmetro | D35: Quantidade | F35: Preço unitário | G35: Valor total
A36: Fabricação, montagem e desmontagem de forma para blocos e baldrames resinado | B36: 2.1 | C36: m² / APE | D36: =B36*DADOS_INICIAIS!E35 -> 0 | E36: m² | G36: =F36*D36 -> 0
A37: Concreto | B37: 0.65 | C37: m³ / APE | D37: =B37*DADOS_INICIAIS!E35 -> 0 | E37: m³ | G37: =F37*D37 -> 0
A38: Armação | B38: 110 | C38: kg / m³ | D38: =B38*D37 -> 0 | E38: kg | G38: =F38*D38 -> 0
A39: Mão de obra | B39: =SUPRAESTRUTURA!B69*1.5 -> 0 | C39: R$ / APE | D39: =DADOS_INICIAIS!E35 -> 0 | E39: m² | F39: =B39 -> 0 | G39: =F39*D39 -> 0
A40: TOTAL | G40: =SUM(G36:G39) -> 0
A46: TOTAL INFRAESTRUTURA | G46: =G21+G30 -> 535766.4 | H46: =G46/DADOS_INICIAIS!E9 -> 40.749571

Sheet INFRAESTRUTURA
A3: INFRAESTRUTURA
A4: Data | B4: 45727
A5: Arquivo base | B5: -
A7: FUNDAÇÃO PROFUNDA
A9: Descrição | B9: Parâmetro | D9: Quantidade | F9: Preço unitário | G9: Valor total | H9: Observação
A10: Número de Estacas | B10: 0.15 | C10: un / APE | D10: =ROUNDUP(B10*DADOS_INICIAIS!$E$25,0) -> 224 | E10: un
A11: Estaca Hélice Continua Diâmetro 40 | B11: 0 | D11: =ROUNDUP(B11*$D$10,0) -> 0 | E11: un
B12: 28 | C12: m/un | D12: =B12*D11 -> 0 | E12: m | F12: 70 | G12: =F12*D12*1.1 -> 0 | H12: Profundidade de SPT
A13: Estaca Hélice Continua Diâmetro 50 | B13: 0.6 | D13: =ROUNDUP(B13*D10,0) -> 135 | E13: un
B14: 28 | C14: m/un | D14: =B14*D13 -> 3780 | E14: m | F14: 90 | G14: =F14*D14*1.1 -> 374220 | H14: Profundidade de SPT
A15: Estaca Hélice Continua Diâmetro 60 | B15: 0.4 | C15: un / APE | D15: =ROUNDUP(B15*$D$10,0) -> 90 | E15: un
B16: 28 | C16: m/un | D16: =B16*D15 -> 2520 | E16: m | F16: 105 | G16: =F16*D16*1.1 -> 291060 | H16: Profundidade de SPT
A17: Estaca Hélice Continua Diâmetro 80 | B17: 0 | C17: un / APE | D17: =ROUNDUP(B17*$D$10,0) -> 0 | E17: un
B18: 30 | C18: m/un | D18: =B18*D17 -> 0 | E18: m | F18: 120 | G18: =F18*D18*1.1 -> 0
A19: Concreto (40 Mpa) | B19: 1.3 | C19: perda | D19: =(PI()*((0.4^2)/4)*D12+PI()*((0.5^2)/4)*D14+PI()*((0.6^2)/4)*D16) -> 1454.7145 | E19: m³ | F19: =(535+45+(1.67*0.6))*B19 -> 755.3026 | G19: =F19*D19*1.1 -> 1208624.6
A20: Armação | B20: 12 | C20: kg / m³ | D20: =B20*D19 -> 17456.574 | E20: kg | F20: 7.62 | G20: =F20*D20*1.1 -> 146321
A21: Mobilização | B21: 1 | C21: vb | D21: 1 | E21: vb | F21: 12500 | G21: =F21*D21*1.1 -> 13750
A22: Apoio e arrasamento de estacas | D22: =D10 -> 224 | E22: un | F22: 300 | G22: =F22*D22*1 -> 67200
A23: TOTAL | G23: =SUM(G10:G22) -> 2101175.6
A25: FUNDAÇÃO RASA
A27: Descrição | B27: Parâmetro | D27: Quantidade | F27: Preço unitário | G27: Valor total | H27: Observação
A28: Fabricação, montagem e desmontagem de forma para blocos e baldrames resinado | B28: 0.76 | C28: m² / APE | D28: =B28*DADOS_INICIAIS!E25 -> 1131.0624 | E28: m² | F28: 68 | G28: =F28*D28*1.1 -> 84603.468
A29: Concreto (40 Mpa) | B29: 0.23 | C29: m³ / APE | D29: =B29*DADOS_INICIAIS!E25 -> 342.2952 | E29: m³ | F29: =(535+45+(1.67*0.6))*1.05 -> 610.0521 | G29: =F29*D29*1.1 -> 229699.7
A30: Armação | B30: 90 | C30: kg / m³ | D30: =B30*D29 -> 30806.568 | E30: kg | F30: 7.62 | G30: =F30*D30*1.1 -> 258220.65
A31: Laje de subpressão | B31: 1 | C31: m² / APE | D31: =B31*DADOS_INICIAIS!E25 -> 1488.24 | E31: m² | F31: =D39+D40+D41 -> 172.44521 | G31: =F31*D31*1.1 -> 282303.85
A32: Mão de obra | B32: =SUPRAESTRUTURA!B15*1.5 -> 360 | C32: R$ / APE | D32: =DADOS_INICIAIS!E25 -> 1488.24 | E32: m² | F32: =B32 -> 360 | G32: =F32*D32*1.1 -> 589343.04
A33: TOTAL | G33: =SUM(G28:G32) -> 1444170.7
A36: TOTAL INFRAESTRUTURA | G36: =G23+G33 -> 3545346.3 | H36: =G36/DADOS_INICIAIS!E9 -> 269.65361
H38: =H36/1.1 -> 245.13964
B39: concreto | C39: =0.1 -> 0.1 | D39: =C39*F29 -> 61.00521
B40: aço | C40: =C39*120 -> 12 | D40: =C40*F30 -> 91.44
B41: mo | C41: 1 | D41: =C41*20 -> 20

Sheet CONTENÇÃO
A3: INFRAESTRUTURA
A4: Data | B4: 45719
A5: Arquivo base | B5: -
A7: CORTINA DE ESTACAS
A9: Descrição | B9: Parâmetro | D9: Quantidade | F9: Preço unitário | G9: Valor total | H9: Observação
A10: Número de Estacas | B10: 2 | C10: un / Compr muro | D10: =ROUND(B10*D31,0) -> 316 | E10: un | H10: Base obra Trindade Parkside
A11: Estaca Hélice Continua Diâmetro 40 | B11: 0 | D11: =ROUNDUP(B11*$D$10,0) -> 0 | E11: un
B12: 28 | C12: m/un | D12: =B12*D11 -> 0 | E12: m | F12: 70 | G12: =F12*D12*1.1 -> 0
A13: Estaca Hélice Continua Diâmetro 50 | B13: 1 | D13: =ROUNDUP(B13*D10,0) -> 316 | E13: un
B14: =D32 -> 9 | C14: m/un | D14: =B14*D13 -> 2844 | E14: m | F14: 90 | G14: =F14*D14*1.1 -> 281556
A15: Estaca Hélice Continua Diâmetro 60 | B15: 0 | C15: un / APE | D15: =ROUNDUP(B15*$D$10,0) -> 0 | E15: un
B16: 28 | C16: m/un | D16: =B16*D15 -> 0 | E16: m | F16: 105 | G16: =F16*D16*1.1 -> 0
A17: Estaca Hélice Continua Diâmetro 80 | B17: 0 | C17: un / APE | D17: =ROUNDUP(B17*$D$10,0) -> 0 | E17: un
B18: 30 | C18: m/un | D18: =B18*D17 -> 0 | E18: m | F18: 120 | G18: =F18*D18*1.1 -> 0
A19: Concreto (30 Mpa) COM CRISTALIZANTE | B19: 1.3 | C19: perda | D19: =(PI()*((0.4^2)/4)*D12+PI()*((0.5^2)/4)*D14+PI()*((0.6^2)/4)*D16) -> 558.41809 | E19: m³ | F19: =(535*1.22+45+(1.67*0.6))*1.05 -> 733.6371 | G19: =F19*D19*B19*1.1 -> 585837.01
A20: Armação | B20: 12 | C20: kg / m³ | D20: =B20*D19 -> 6701.0171 | E20: kg | F20: 7.62 | G20: =F20*D20*1.1 -> 56167.926
A21: Mobilização | B21: 1 | C21: vb | D21: 1 | E21: vb | F21: 12500 | G21: =F21*D21*1.1 -> 13750
A22: Tirantes | B22: 3081.63 | C22: R$ / m | D22: =D31 -> 157.96 | E22: m | F22: =B22 -> 3081.63
A23: Apoio e arrasamento de estacas | D23: =D10 -> 316 | E23: un | F23: 300 | G23: =F23*D23*1 -> 94800
A24: Viga de coroamento | D24: =D31 -> 157.96 | E24: m² | F24: 384.56 | G24: =F24*D24*1 -> 60745.098
A25: Parede de fechamento | D25: =D31*D32 -> 1421.64 | E25: m² | F25: =J29/D25 -> 264.96 | G25: =F25*D25*1 -> 376677.73 | I25: =D25 -> 1421.64 | J25: =I25*[4]Infraestrutura!$F$49 -> 71082
A26: TOTAL | G26: =SUM(G10:G25) -> 1469533.8 | I26: =D25*0.1 -> 142.164 | J26: =[4]Infraestrutura!$F$50*I26 -> 83876.76
I27: =[4]Infraestrutura!$F$51*I26 -> 11373.12 | J27: =I27*F20 -> 86663.174
A28: PAREDE DE CONCRETO | I28: =I26 -> 142.164 | J28: =[4]Infraestrutura!$F$52*I28 -> 135055.8
J29: =J25+J26+J27+J28 -> 376677.73
A30: Descrição | B30: Parâmetro | D30: Quantidade | F30: Preço unitário | G30: Valor total | H30: Observação
A31: Comprimento do muro | D31: =DADOS_INICIAIS!E26 -> 157.96 | E31: m | H31: =D31*D32 -> 1421.64
A32: Altura do muro | D32: =6+3 -> 9 | E32: m
A33: Execução de mureta guia | D33: =D31 -> 157.96 | E33: m | F33: 710 | G33: =F33*D33*1.1 -> 123366.76
A34: Serviço especializado parede diafragma | D34: =D31*D32 -> 1421.64 | E34: m² | F34: 270 | G34: =F34*D34 -> 383842.8
A35: Mobilização para parede diagragma | D35: 1 | E35: vb | F35: 18000 | G35: =F35 -> 18000
A36: Armação | B36: 112 | C36: kg / m³ | D36: =B36*D37 -> 47767.104 | E36: kg | F36: 7.62 | G36: =F36*D36 -> 363985.33
A37: Concreto (30 Mpa) COM CRISTALIZANTE | B37: 0.3 | C37: espessura | D37: =B37*D32*D31 -> 426.492 | E37: m³ | F37: =(535*1.22+45+(1.67*0.6))*1.05 -> 733.6371 | G37: =F37*D37*1.05 -> 328534.87
A38: Tratamento em juntas de concretagem com fita hidroexpansiva | D38: =ROUNDUP(D31/1.25,0)*6 -> 762 | E38: m | F38: 41.5 | G38: =F38*D38*1.1 -> 34785.3
A39: TOTAL | G39: =SUM(G31:G38) -> 1252515.1
A42: TOTAL CONTENÇÃO | G42: =G39 -> 1252515.1 | H42: =G42/DADOS_INICIAIS!E9 -> 95.264377
H44: =H42/1.1 -> 86.603979

Sheet SUPRAESTRUTURA
A3: SUPRAESTRUTURA
A4: Data | B4: 45472
A5: Arquivo base | B5: -
A7: SUPRAESTRUTURA - LAJE MACIÇA
A9: Descrição | B9: Parâmetro | D9: Quantidade | F9: Preço unitário | G9: Valor total | H9: Observação
A10: Fabricação forma | B10: 3 | C10: Jogos | D10: =(D11/DADOS_INICIAIS!$E$15)*B10 -> 7585.2577 | E10: m² | F10: 110 | G10: =F10*D10*1.1 -> 917816.18
A11: Montagem de forma | B11: 2.5 | C11: m² / AC | D11: =B11*DADOS_INICIAIS!$E$9 -> 32869.45 | E11: m² | F11: 2.5 | G11: =F11*D11*1.1 -> 90390.988
A12: Escoramento | B12: 4 | C12: un / AE | D12: =ROUNDUP(B12*DADOS_INICIAIS!$E$25*B10,0) -> 17859 | E12: un | F12: =17 -> 17 | G12: =F12*D12*1.1 -> 333963.3
A13: Concreto | B13: 0.22 | C13: m³ / AC | D13: =B13*DADOS_INICIAIS!$E$9 -> 2892.5116 | E13: m³ | F13: =(535+45+(1.67*0.6))*1.05 -> 610.0521 | G13: =F13*D13*1.05*1.1 -> 2038093.1
A14: Armadura Convencional para Estrutura | B14: 110 | C14: kg / m³ | D14: =D13*B14 -> 318176.28 | E14: kg | F14: 7.62 | G14: =F14*D14*1.1 -> 2666953.5
A15: Mão de obra - estrutura em concreto armado | B15: 240 | C15: R$ / AC | D15: =DADOS_INICIAIS!$E$9 -> 13147.78 | E15: m² | F15: =B15 -> 240 | G15: =F15*D15*1.1 -> 3471013.9
A16: Perfuração de vigas | B16: 5300 | C16: R$ / NP | D16: 1 | E16: vb | F16: =B16*DADOS_INICIAIS!$E$15 -> 68900 | G16: =F16*D16*1.1 -> 75790 | H16: Coeficiente originário do Gran Torino (R$ 160,00/un) | I16: Nova utiliza a verba de 1.500,00 por pav
A17: TOTAL | G17: =SUM(G10:G16) -> 9594021 | K17: =4160+1440+1120+2880+4800+91680+4000 -> 110080 | L17: =K17/21 -> 5241.9048
A19: SUPRAESTRUTURA - LAJE CUBETAS
A21: Descrição | B21: Parâmetro | D21: Quantidade | F21: Preço unitário | G21: Valor total | H21: Observação
A22: Fabricação forma | B22: 2 | C22: Jogos | D22: =(D23/DADOS_INICIAIS!$E$15)*B22 -> 5056.8385 | E22: m² | F22: 110 | G22: =F22*D22*1.1 -> 611877.45
A23: Montagem de forma | B23: 2.5 | C23: m² / AC | D23: =B23*DADOS_INICIAIS!$E$9 -> 32869.45 | E23: m² | F23: 2.5 | G23: =F23*D23*1.1 -> 90390.988
A24: Escoramento | B24: =2.5 -> 2.5 | C24: um/m² | D24: =ROUNDUP(B24*888.65*B22,0) -> 4444 | E24: un | F24: =4*5 -> 20 | G24: =F24*D24*1.1 -> 97768
A25: Cubetas | D25: =14-2 -> 12 | E25: mês | F25: =H25*0.45*30 -> 25609.5 | G25: =F25*D25*1.1 -> 338045.4 | H25: =ROUNDUP(DADOS_INICIAIS!E19*B22,0) -> 1897
A26: Concreto | B26: 0.25 | C26: m³ / AC | D26: =B26*DADOS_INICIAIS!$E$9 -> 3286.945 | E26: m³ | F26: =(535+45+(1.67*0.6))*1.05 -> 610.0521 | G26: =F26*D26*1.1 -> 2205728.5
A27: Armadura Convencional para Estrutura | B27: 90 | C27: kg / m³ | D27: =D26*B27 -> 295825.05 | E27: kg | F27: 7.62 | G27: =F27*D27*1.1 -> 2479605.6
A28: Mão de obra - estrutura em concreto armado | B28: 240 | C28: R$ / AC | D28: =DADOS_INICIAIS!$E$9 -> 13147.78 | E28: m² | F28: =B28 -> 240 | G28: =F28*D28*1.1 -> 3471013.9
A29: Perfuração de vigas | B29: =5300*0.8 -> 4240 | C29: R$ / NP | D29: 1 | E29: vb | F29: =B29*DADOS_INICIAIS!$E$15 -> 55120 | G29: =F29*D29*1.1 -> 60632 | H29: Coeficiente originário do Gran Torino (R$ 160,00/un)
A30: TOTAL | G30: =SUM(G22:G29) -> 9355061.8
A32: SUPRAESTRUTURA - LAJE TRELIÇADA
A34: Descrição | B34: Parâmetro | D34: Quantidade | F34: Preço unitário | G34: Valor total | H34: Observação
A35: Fabricação forma | B35: 2 | C35: Jogos | D35: =(D36/DADOS_INICIAIS!$E$15)*B35 -> 0 | E35: m² | F35: 85 | G35: =F35*D35*1.1 -> 0
A36: Montagem de forma | B36: 2.1 | C36: m² / AC | D36: =B36*DADOS_INICIAIS!E38 -> 0 | E36: m² | F36: 1.5 | G36: =F36*D36*1.1 -> 0
A37: Escoramento - Torre | B37: 2 | C37: un / APT*NPT | D37: =B37*DADOS_INICIAIS!E47*DADOS_INICIAIS!E44 -> 0 | E37: un | F37: 17 | G37: =F37*D37*1.1 -> 0
A38: Escoramento - Embasamento | B38: 2 | C38: un / AE | D38: =B38*DADOS_INICIAIS!E50 -> 0 | E38: un | F38: 17 | G38: =F38*D38*1.1 -> 0
A39: Cubetas | B39: 25 | C39: R$ / AC | D39: =B39*DADOS_INICIAIS!E38 -> 0 | E39: m³ | F39: =B39 -> 25 | G39: =F39*D39*1.1 -> 0
A40: Concreto | B40: 0.25 | C40: m³ / AC | D40: =B40*DADOS_INICIAIS!E38 -> 0 | E40: m³ | F40: =575 -> 575 | G40: =F40*D40*1.05*1.1 -> 0
A41: Armadura Convencional para Estrutura | B41: 110 | C41: kg / m³ | D41: =D40*B41 -> 0 | E41: kg | F41: 7.25 | G41: =F41*D41*1.1 -> 0
A42: Mão de obra - estrutura em concreto armado | B42: 240 | C42: R$ / AC | D42: =DADOS_INICIAIS!E38 -> 0 | E42: m² | F42: =B42 -> 240 | G42: =F42*D42*1.1 -> 0
A43: Perfuração de vigas | B43: 5300 | C43: R$ / NP | D43: 1 | E43: vb | F43: =B43*DADOS_INICIAIS!E43 -> 0 | G43: =F43*D43*1.1 -> 0 | H43: Coeficiente originário do Gran Torino (R$ 160,00/un)
A44: TOTAL | G44: =SUM(G35:G43) -> 0
A46: SUPRAESTRUTURA - LAJE PROTENDIDA
A48: Descrição | B48: Parâmetro | D48: Quantidade | F48: Preço unitário | G48: Valor total | H48: Observação
A49: Fabricação forma | B49: 3 | C49: Jogos | D49: =(D50/DADOS_INICIAIS!$E$15)*B49 -> 6371.6165 | E49: m² | F49: 110 | G49: =F49*D49*1.1 -> 770965.59
A50: Montagem de forma | B50: 2.1 | C50: m² / AC | D50: =B50*DADOS_INICIAIS!$E$9 -> 27610.338 | E50: m² | F50: 2.5 | G50: =F50*D50*1.1 -> 75928.43
...

Sheet ALVENARIA
A3: PAREDES E PAINÉIS
A4: Data | B4: 45469
A5: Arquivo base | B5: -
A7: ALVENARIA
A9: Descrição | B9: Parâmetro | D9: Quantidade | F9: Preço unitário | G9: Valor total | H9: Observação
A10: Alvenaria | B10: 0.5 | C10: m² / AE | D10: =SUM(Orçamento!D62:D70) -> 19140.3 | E10: m² | F10: 45 | G10: =F10*D10*1.1 -> 947444.85 | I10: =(D10+#REF!+#REF!+#REF!+#REF!)/DADOS_INICIAIS!E9 -> #REF!
A11: Placa EPS | D11: =Orçamento!D67 -> 4791.64 | E11: m² | F11: 26.46 | G11: =F11*D11*1.1 -> 139465.47 | I11: =(D11+#REF!+#REF!+#REF!+#REF!)/DADOS_INICIAIS!E10 -> #REF!
A12: Alvenaria refratárias | B12: 1.75 | C12: m² * CHU | D12: =B12*DADOS_INICIAIS!$E$14 -> 150.5 | E12: m² | F12: 310 | G12: =F12*D12*1.1 -> 51320.5
A13: Serviços complementares | B13: 12.5 | C13: R$ / m² | D13: =D10 -> 19140.3 | E13: m² | F13: 6.5 | G13: =F13*D13*1.1 -> 136853.15
A14: Mão de obra | B14: 35 | C14: R$ / m² | D14: =D10 -> 19140.3 | E14: m² | F14: 35 | G14: =F14*D14*1.1 -> 736901.55
A15: TOTAL | G15: =SUM(G10:G14) -> 2011985.5 | K15: =4160+1440+1120+2880+4800+91680+4000 -> 110080 | L15: =K15/21 -> 5241.9048
A17: ALVENARIA - DRYWALL | G17: =G14/D14 -> 38.5
A19: Descrição | B19: Parâmetro | D19: Quantidade | F19: Preço unitário | G19: Valor total | H19: Observação
A20: Alvenaria embasamento | B20: 1 | C20: m² / AE | D20: =B20*DADOS_INICIAIS!$E$22 -> 2171.44 | E20: m² | F20: 45 | G20: =F20*D20*1.1 -> 107486.28
A21: Alvenaria lazer | B21: 0.4 | C21: m² / AL | D21: =B21*DADOS_INICIAIS!$E$21 -> 283.772 | E21: m² | F21: 45 | G21: =F21*D21*1.1 -> 14046.714
A22: Alvenaria tipo | B22: 1.65 | C22: m² / APT*(NPT+2ND) | D22: =B22*(DADOS_INICIAIS!$E$19*(DADOS_INICIAIS!$E$16+DADOS_INICIAIS!$E$17))*0.4 -> 5007.0768 | E22: m² | F22: 45 | G22: =F22*D22*1.1 -> 247850.3
A23: Drywall tipo | B23: 1.65 | C23: m² / APT*(NPT+2ND) | D23: =B23*(DADOS_INICIAIS!$E$19*(DADOS_INICIAIS!$E$16+DADOS_INICIAIS!$E$17))*0.6 -> 7510.6152 | E23: m² | F23: 220 | G23: =F23*D23*1.1 -> 1817568.9 | J23: =D23/(D27+D23) -> 0.40905022
A24: Alvenaria escadas | B24: 0.2 | C24: m² / AC | D24: =B24*DADOS_INICIAIS!$E$9 -> 2629.556 | E24: m² | F24: 70 | G24: =F24*D24*1.1 -> 202475.81 | J24: =1-J23 -> 0.59094978
A25: Alvenaria cobertura / reservatório | B25: 0.8 | C25: m² / APT | D25: =B25*DADOS_INICIAIS!$E$19 -> 758.648 | E25: m³ | F25: 45 | G25: =F25*D25*1.1 -> 37553.076
A26: Alvenaria refratárias | B26: 1.75 | C26: m² * CHU | D26: ='SISTEMAS ESPECIAIS'!B10 -> 86 | E26: un | F26: 210 | G26: =F26*D26*1.1 -> 19866
A27: Serviços complementares | B27: 12.5 | C27: R$ / m² | D27: =D21+D22+D20+D24+D25 -> 10850.493 | E27: m² | F27: =B27 -> 12.5 | G27: =F27*D27*1.1 -> 149194.28
A28: Mão de obra | B28: 35 | C28: R$ / m² | D28: =D21+D22+D20+D24+D25 -> 10850.493 | E28: m² | F28: 35 | G28: =F28*D28*1.1 -> 417743.97
A29: TOTAL | G29: =SUM(G20:G28) -> 3013785.3
A32: TOTAL ALVENARIA | G32: =G15 -> 2011985.5 | H32: =G32/DADOS_INICIAIS!E9 -> 153.02854
C35: =24000/(568+874+1996+1144) -> 5.2378874 | G35: =G32/1.1 -> 1829077.7 | H35: =G35/DADOS_INICIAIS!E9 -> 139.11685

Sheet Orçamento
A1: DADOS
A2: Titulo | B2: QUANTITATIVO
A3: Obra
A4: Cliente
A5: Cidade
A6: Endereço
A7: Descrição
A9: QUANTITATIVOS
A10: Item | B10: Descrição | C10: Unid. | D10: Quantidade
A12: 1. | B12: GERAL CORRIMAO
A13: 1.1. | B13: Corrimão
A14: 1.1.1 | B14: Railing:Guarda-corpo cobertura | C14: m | D14: 128.68
A15: 1.1.2 | B15: Railing:Guarda-corpo Sacadas | C15: m | D15: 246.61
A16: 2. | B16: GERAL ESCADAS
A17: 2.1. | B17: Escada
A18: 2.1.1 | B18: Assembled Stair:Cascata | C18: m²
A19: 2.1.2 | B19: Cast-In-Place Stair:Escada Concreto | C19: m²
A20: 3. | B20: GERAL FORRO
A21: 3.1. | B21: Revestimento
A22: 3.1.1 | B22: Compound Ceiling:FO_Madeira | C22: m² | D22: 369.9
A23: 4. | B23: GERAL JANELAS
A24: 4.1. | B24: Janela | C24: m2 | D24: 1125.2525
A25: 4.1.1 | B25: JFSZ-Windos-M3-Domus-BR-G3:JFSZ-Windos-M3-Domus-BR-G3 | C25: un | D25: 5
A26: 4.1.2 | B26: JFSZ-Windows-M3-AberturaChurrasqueira:Acabamento em granito para churrasqueira (60x50) | C26: un | D26: 16
A27: 4.1.3 | B27: JFSZ-Windows-M3-AberturaChurrasqueira:Acabamento em granito para churrasqueira (60x60) | C27: un | D27: 64
A28: 4.1.4 | B28: JFSZ-Windows-M3-AberturaChurrasqueira:Acabamento em granito para churrasqueira (80x60) | C28: un | D28: 4
A29: 4.1.5 | B29: JFSZ-Windows-M3-JanelaCorrerR04-BR-G3:180 | C29: un | D29: 16
A30: 4.1.6 | B30: JFSZ-Windows-M3-JanelaCorrerR04-BR-G3:200x200 | C30: un | D30: 24
A31: 4.1.7 | B31: JFSZ-Windows-M3-JanelaCorrerR04-BR-G3:240x200 | C31: un | D31: 104
A32: 4.1.8 | B32: JFSZ-Windows-M3-JanelaCorrerR04-BR-G3:240xx 2 | C32: un | D32: 32
A33: 4.1.9 | B33: JFSZ-Windows-M3-JanelaCorrerR04-BR-G3:280 | C33: un | D33: 16
A34: 4.1.10 | B34: JFSZ-Windows-M3-JanelaCorrerR04-BR-G3:Janela de correr 2 folhas (120x120) | C34: un | D34: 48
A35: 4.1.11 | B35: JFSZ-Windows-M3-VisitaTecnica-BR-G3:Visita Técnica (60x60) | C35: un | D35: 2
... A47: 4.1.23 | B47: Vertical_Brise_de_Soleil_Sun_Screen_4523:M_Brise_Soleil | C47: un | D47: 2
A48: 5. | B48: GERAL LANCE ESCADAS
A49: 5.1. | B49: Lance de escada
A50: 5.1.1 | B50: Monolithic Run:Moldado in loco - 150mm | C50: m² | D50: 81.69
A51: 5.1.2 | B51: Non-Monolithic Run:Piso de 50 mm com espelho degrau de 13 mm | C51: m² | D51: 27.17
A52: 6. | B52: GERAL MEMBRO
A53: 6.1. | B53: Membro
...

Sheet INSTALAÇÕES
A2: INSTALAÇÕES
A4: INSTALAÇÕES ELÉTRICAS
A6: Descrição | B6: Parâmetro | D6: Valor total
A7: Entrada de Energia | B7: 5.5 | C7: R$ / AC | D7: =B7*DADOS_INICIAIS!$E$9*1.1 -> 79544.069
A8: Eletrodutos e Eletrocalhas | B8: 10 | C8: R$ / AC | D8: =B8*DADOS_INICIAIS!$E$9*1.1 -> 144625.58
A9: Cabos e Fiações | B9: 30 | C9: R$ / AC | D9: =B9*DADOS_INICIAIS!$E$9*1.1 -> 433876.74
A10: Quadros e Disjuntores | B10: 18 | C10: R$ / AC | D10: =B10*DADOS_INICIAIS!$E$9*1.1 -> 260326.04
A11: Acabamentos Elétricos | B11: 15 | C11: R$ / AC | D11: =B11*DADOS_INICIAIS!$E$9*1.1 -> 216938.37
A12: Equipamentos e Iluminação | B12: 15 | C12: R$ / AC | D12: =B12*DADOS_INICIAIS!$E$9*1.1 -> 216938.37
A13: Mão de Obra para Instalações Elétricas | B13: 60 | C13: R$ / AC | D13: =B13*DADOS_INICIAIS!$E$9*1.1 -> 867753.48 | E13: =D13/DADOS_INICIAIS!$E$9 -> 66
A14: TOTAL | D14: =SUM(D7:D13) -> 2220002.7
A16: INSTALAÇÕES HIDROSSANITÁRIAS
A18: Descrição | B18: Parâmetro | D18: Valor total
A19: Instalações de Água Fria | B19: 25 | C19: R$ / AC | D19: =B19*DADOS_INICIAIS!$E$9*1.1 -> 361563.95
A20: Instalações de Água Quente | B20: 20 | C20: R$ / AC | D20: =B20*DADOS_INICIAIS!$E$9*1.1 -> 289251.16
A21: Instalações de Águas Pluviais | B21: 10 | C21: R$ / AC | D21: =B21*DADOS_INICIAIS!$E$9*1.1 -> 144625.58
A22: Instalações Sanitárias | B22: 15 | C22: R$ / AC | D22: =B22*DADOS_INICIAIS!$E$9*1.1 -> 216938.37
A23: Louças e Metais | B23: 50 | C23: R$ / AC | D23: =B23*DADOS_INICIAIS!$E$9*1.1 -> 723127.9
A24: Mão de Obra para Instalações Hidráulicas | B24: 55 | C24: R$ / AC | D24: =B24*DADOS_INICIAIS!$E$9*1.1 -> 795440.69 | E24: =D24/DADOS_INICIAIS!$E$9 -> 60.5
A25: TOTAL | D25: =SUM(D19:D24) -> 2530947.7
A27: INSTALAÇÕES PREVENTIVAS E GLP
A29: Descrição | B29: Parâmetro | D29: Valor total
A30: Instalações Preventivas | B30: 20 | C30: R$ / AC | D30: =B30*DADOS_INICIAIS!$E$9*1.1 -> 289251.16
A31: Instalações de GLP | B31: 15 | C31: R$ / AC | D31: =B31*DADOS_INICIAIS!$E$9*1.1 -> 216938.37
A32: Instalações de Proteção e Aterramento - SPDA | B32: 8 | C32: R$ / AC | D32: =B32*DADOS_INICIAIS!$E$9*1.1 -> 115700.46
A33: TOTAL | D33: =SUM(D30:D32) -> 621889.99
A35: TOTAL INSTALAÇÕES | D35: =D14+D25+D33 -> 5372840.3 | E35: =D35/DADOS_INICIAIS!E9 -> 408.65
E37: =E35/1.1 -> 371.5

Sheet SISTEMAS ESPECIAIS
A2: SISTEMAS ESPECIAIS
A4: CLIMATIZAÇÃO, EXAUSTÃO MECÂNICA E PRESSURIZAÇÃO
A6: Descrição | B6: Quantidade | C6: Preço Unitário | D6: Valor total | G6: TERREO | H6: INTERMED | I6: TIPO | J6: COBERTURA
A7: Infraestrutura para Instalação de Ar Condicionado | B7: =G7+H7+I7*8+J7 -> 291 | C7: 1200 | D7: =B7*C7*1.1 -> 384120 | G7: =4+1 -> 5 | H7: =4+8 -> 12 | I7: =3+3+3+3+4+3*3+3+4 -> 32 | J7: =(4+5)*2 -> 18
A8: Instalação de Ar Condicionado | B8: =G8+H8+I8*8+J8 -> 8 | C8: 5000 | D8: =B8*C8*1.1 -> 44000 | G8: 0 | H8: =8 -> 8 | I8: 0
A9: Ventokit | B9: =G9+H9+I9*8+J9 -> 217 | C9: 900 | D9: =B9*C9*1.1 -> 214830 | G9: =5 -> 5 | H9: =4 -> 4 | I9: =13+13 -> 26
A10: Churrasqueiras | B10: =G10+H10+I10*8+J10 -> 86 | C10: 280 | D10: =B10*C10*1.1+10*300 -> 29488 | G10: 0 | H10: =2 -> 2 | I10: =10 -> 10 | J10: 4
A11: TOTAL | D11: =SUM(D7:D10) -> 672438
A13: COMUNICAÇÃO
A15: Descrição | B15: Parâmetro | D15: Valor total
A16: CFTV | B16: 2 | C16: R$ / AC | D16: =B16*DADOS_INICIAIS!$E$9*1.1+2500 -> 31425.116
A17: Interfone | B17: 5 | C17: R$ / AC | D17: =B17*DADOS_INICIAIS!$E$9*1.1 -> 72312.79
A18: TV e internet | B18: 3 | C18: R$ / AC | D18: =B18*DADOS_INICIAIS!$E$9*1.1 -> 43387.674
A19: Automação, telecomunicação e sistemas de segurança | B19: 5 | C19: R$ / AC | D19: =B19*DADOS_INICIAIS!$E$9*1.1 -> 72312.79
A20: TOTAL | D20: =SUM(D16:D19) -> 219438.37
A22: EQUIPAMENTOS
A24: Descrição | B24: Quantidade | C24: Preço Unitário | D24: Valor total
A25: Elevadores | B25: 2 | C25: =399080.16 -> 399080.16 | D25: =B25*C25*1.1 -> 877976.35
A26: Plataforma elevatória | C26: 42750 | D26: =B26*C26*1.1 -> 0 | E26: inox
A27: Grupo de geradores | B27: 1 | C27: 50000 | D27: =B27*C27*1.1 -> 55000
A28: Bombas | B28: 1 | C28: 12000 | D28: =B28*C28*1.1 -> 13200
A29: Infra de carro elétrico | B29: =DADOS_INICIAIS!E10 -> 84 | C29: 560 | D29: =B29*C29*1.1 -> 51744
A30: Equipamento de piscina | B30: 1 | C30: 25000 | D30: =B30*C30*1.1 -> 27500
A31: Sistema de placas solares | C31: 1150 | D31: =B31*C31*1.1 -> 0
A32: TOTAL | D32: =SUM(D25:D31) -> 1025420.4
A34: OUTROS SISTEMAS ESPECIAIS
A36: Descrição | B36: Parâmetro | D36: Valor total
A37: Outros sistemas | B37: 20 | C37: R$ / AC | D37: =B37*DADOS_INICIAIS!E9*1.1 -> 289251.16
A38: TOTAL | D38: =SUM(D37:D37) -> 289251.16
A40: TOTAL SISTEMAS ESPECIAIS | D40: =D11+D20+D32+D38 -> 2206547.9 | E40: =D40/DADOS_INICIAIS!E9 -> 167.82665

Sheet IMPERMEABILIZAÇÃO
A3: IMPERMEABILIZAÇÃO
A4: Data | B4: 45471
A5: Arquivo base | B5: -
A7: IMPERMEABILIZAÇÃO
A9: Descrição | B9: Parâmetro | D9: Quantidade | F9: Preço unitário | G9: Valor total | H9: Observação
A10: Regularização de Superfície | B10: 25 | C10: R$ / m² | D10: =D14+D15 -> 6059.733 | E10: m² | F10: =5 -> 5 | G10: =F10*D10*1.1 -> 33328.532
A11: Poço do elevador | B11: 45 | C11: R$ / m² | D11: =((1.99*2.1)+(1.99*2+2.1*2)*1.8)*2 -> 37.806 | E11: m² | F11: =41-30 -> 11 | G11: =F11*D11*1.1 -> 457.4526
A12: Baldrames | B12: 30 | C12: R$ / m² | D12: =INFRAESTRUTURA!D28 -> 1131.0624 | E12: m² | F12: =15 -> 15 | G12: =F12*D12*1.1 -> 18662.53
A13: Ralos | B13: 1 | C13: R$ / AC | D13: 1 | E13: vb | F13: =B13*DADOS_INICIAIS!$E$9 -> 13147.78 | G13: =F13*D13*1.1 -> 14462.558 | H13: =G13/I13 -> #DIV/0!
A14: Impermeabilizações cimenticias | B14: 0.3 | C14: m² / AC | D14: =B14*DADOS_INICIAIS!E9 -> 3944.334 | E14: m² | F14: =40 -> 40 | G14: =F14*D14*1.1 -> 173550.7
A15: Impermeabilizações com manta asfaltica | B15: =D15/DADOS_INICIAIS!E9 -> 0.16089401 | C15: m² / AC | D15: =(96.22+112.8+19.14+29.23+'PISO E TETO'!M34-'PISO E TETO'!D81-'PISO E TETO'!D123-'PISO E TETO'!D124-'PISO E TETO'!D149-'PISO E TETO'!D191-'PISO E TETO'!D192-'PISO E TETO'!D197-'PISO E TETO'!D208-'PISO E TETO'!D231-'PISO E TETO'!D241)*1.3 -> 2115.399 | E15: m² | F15: =50 -> 50 | G15: =F15*D15*1.1 -> 116346.95
A16: Impermeabilizações com manta asfalticafloreiras | C16: m² / AC | D16: =(12.057+24.39)*1.2 -> 43.7364 | E16: m² | F16: =50 -> 50 | G16: =F16*D16*1.1 -> 2405.502
A17: Impermeabilização de peitoril | B17: 1.2 | C17: R$ / AC | D17: 1 | E17: vb | F17: =B17*DADOS_INICIAIS!$E$9 -> 15777.336 | G17: =F17*D17*1.1 -> 17355.07 | H17: =G17/I17 -> #DIV/0!
A18: Proteção Mecânica | B18: 28 | C18: R$ / m² | D18: =D15 -> 2115.399 | E18: m² | F18: =35 -> 35 | G18: =F18*D18*1.1 -> 81442.862
A19: MO REGULARIZAÇÃO | D19: =D10 -> 6059.733 | F19: 20 | G19: =F19*D19*1.1 -> 133314.13
A20: MO PROT MECANICA | D20: =D18 -> 2115.399 | F20: 22 | G20: =F20*D20*1.1 -> 51192.656
A21: MO IMPERM POÇO | D21: =D11 -> 37.806 | F21: 30 | G21: =F21*D21*1.1 -> 1247.598
A22: MO BALDRAMES | D22: =D12 -> 1131.0624 | F22: 38 | G22: =F22*D22*1.1 -> 47278.408
A23: MO CIMENTICIA | D23: =D14 -> 3944.334 | F23: 30 | G23: =F23*D23*1.1 -> 130163.02
A24: MO MANTA | D24: =D15+D16 -> 2159.1354 | F24: 48 | G24: =F24*D24*1.1 -> 114002.35
A25: TOTAL | G25: =SUM(G10:G24) -> 935210.31 | K25: =4160+1440+1120+2880+4800+91680+4000 -> 110080 | L25: =K25/21 -> 5241.9048
A27: TOTAL IMPERMEABILIZAÇÃO | G27: =G25 -> 935210.31 | H27: =G27/DADOS_INICIAIS!E9 -> 71.130663
H30: =H27/1.1 -> 64.664239
C31: =3.36*(141*2+10) -> 981.12
C32: =1.5*2.1*(141*2+10) -> 919.8
C33: =C31+C32 -> 1900.92 | D33: só banheiro
C34: =4*1.5*56 -> 336 | D34: cozinha
A37: IMPERMEABILIZAÇÃO
A39: Descrição | B39: Parâmetro | D39: Quantidade | F39: Preço unitário | G39: Valor total | H39: Observação
A40: Regularização de Superfície | B40: 25 | C40: R$ / m² | D40: 6235.376 | E40: m² | F40: =5+20 -> 25 | G40: =F40*D40*1.1 -> 171472.84
A41: Poço do elevador | B41: 45 | C41: R$ / m² | D41: 37.806 | E41: m² | F41: =41 -> 41 | G41: =F41*D41*1.1 -> 1705.0506
A42: Baldrames | B42: 30 | C42: R$ / m² | D42: 1131.0624 | E42: m² | F42: =15+38 -> 53 | G42: =F42*D42*1.1 -> 65940.938
A43: Ralos | B43: 1 | C43: R$ / AC | D43: 1 | E43: vb | F43: =B43*DADOS_INICIAIS!$E$9 -> 13147.78 | G43: =F43*D43*1.1 -> 14462.558 | H43: =G43/I43 -> #DIV/0!
A44: Impermeabilizações cimenticias | B44: 0.3 | C44: m² / AC | D44: 3944.334 | E44: m² | F44: =40+30 -> 70 | G44: =F44*D44*1.1 -> 303713.72
A45: Impermeabilizações com manta asfaltica | B45: =D45/DADOS_INICIAIS!E33 -> #DIV/0! | C45: m² / AC | D45: 2291.042 | E45: m² | F45: =50+48 -> 98 | G45: =F45*D45*1.1 -> 246974.33
A46: Impermeabilizações com manta asfalticafloreiras | C46: m² / AC | E46: m² | F46: =50+48 -> 98 | G46: =F46*D46*1.1 -> 0
A47: Impermeabilização de peitoril | B47: 1.2 | C47: R$ / AC | D47: 1 | E47: vb | F47: =B47*DADOS_INICIAIS!$E$9 -> 15777.336 | G47: =F47*D47*1.1 -> 17355.07 | H47: =G47/I47 -> #DIV/0!
A48: Proteção Mecânica | B48: 28 | C48: R$ / m² | D48: 2291.042 | E48: m² | F48: =35+22 -> 57 | G48: =F48*D48*1.1 -> 143648.33
A49: TOTAL | G49: =SUM(G40:G48) -> 965272.84 | K49: =4160+1440+1120+2880+4800+91680+4000 -> 110080 | L49: =K49/21 -> 5241.9048

Sheet PISO E TETO
A1: Obra | B1: =DADOS_INICIAIS!B1 -> Estreito
A2: Empresa | B2: =DADOS_INICIAIS!B2 -> D'Lohn Empreendimentos
A3: Revisão | B3: R00
A4: Data | B4: 45726
A5: LEVANTAMENTO QUANTITATIVO
A7: REVESTIMENTOS E ACABAMENTOS DE PISO E TETO
B9: LEVANTAMENTO DE PROJETO | L9: CONTRAPISO
B10: Pavimento | C10: Ambiente | D10: Área (m²) | E10: Material | F10: Contrapiso (Sim/Não) | G10: Forro | H10: Repetição | I10: Total | L10: Revestimento | M10: Área total
B11: SUBSOLO 2 | C11: GARAGEM | D11: 778.19 | E11: POLIDO | F11: Não | G11: Estucamento | H11: 1 | I11: =H11*Table_2[[#This Row],[Área (m²)]] -> 778.19 | L11: Contrapiso | M11: =SUMIF(F:F,"Sim",I:I) -> 9257.564
B12: SUBSOLO 2 | C12: RAMPA | D12: =80.83*1.2 -> 96.996 | E12: CONCRETO ESCVADO | F12: Não | G12: Estucamento | H12: 1 | I12: =H12*Table_2[[#This Row],[Área (m²)]] -> 96.996 | L12: Manta acústica | M12: =SUM(I58:I239) -> 7235.914
B13: SUBSOLO 2 | C13: ESCADA | D13: =15.66+18*1.2*0.18 -> 19.548 | E13: CIMENTADO | F13: Sim | G13: Estucamento | H13: 1 | I13: =H13*Table_2[[#This Row],[Área (m²)]] -> 19.548 | L13: FORRO
B14: SUBSOLO 1 | C14: GARAGEM | D14: 778.19 | E14: POLIDO | F14: Não | G14: Estucamento | H14: 1 | I14: =H14*Table_2[[#This Row],[Área (m²)]] -> 778.19 | L14: Revestimento | M14: Área total
B15: SUBSOLO 1 | C15: RAMPA | D15: =80.83*1.2 -> 96.996 | E15: CONCRETO ESCVADO | F15: Não | G15: Estucamento | H15: 1 | I15: =H15*Table_2[[#This Row],[Área (m²)]] -> 96.996 | L15: Estucamento | M15: =SUMIF(G:G,L15,I:I) -> 3110.626
B16: SUBSOLO 1 | C16: ESCADA | D16: =15.66+18*1.2*0.18 -> 19.548 | E16: CIMENTADO | F16: Sim | G16: Estucamento | H16: 1 | I16: =H16*Table_2[[#This Row],[Área (m²)]] -> 19.548 | L16: Gesso | M16: =SUMIF(G:G,L16,I:I) -> 6751.37
B17: TERREO / 1 PAV | C17: PASSEIO | D17: 134.11 | E17: CONCRETO CALÇADA | F17: Não | G17: - | H17: 1 | I17: =H17*Table_2[[#This Row],[Área (m²)]] -> 134.11 | L17: Madeira | M17: =SUMIF(G:G,L17,I:I) -> 1219.45
B18: TERREO / 1 PAV | C18: ACESSO GARAGEM | D18: 114.55 | E18: POLIDO | F18: Não | G18: - | H18: 1 | I18: =H18*Table_2[[#This Row],[Área (m²)]] -> 114.55
B19: TERREO / 1 PAV | C19: GARAGEM | D19: 746.82 | E19: POLIDO | F19: Não | G19: Estucamento | H19: 1 | I19: =H19*Table_2[[#This Row],[Área (m²)]] -> 746.82 | J19: parte descoberta
B20: TERREO / 1 PAV | C20: CISTERNAS | D20: 67.69 | E20: POLIDO | F20: Não | G20: Estucamento | H20: 1 | I20: =H20*Table_2[[#This Row],[Área (m²)]] -> 67.69 | J20: parte descoberta
B21: TERREO / 1 PAV | C21: LOJA01 | D21: 29.99 | E21: PORCELANATO | F21: Sim | G21: Gesso | H21: 1 | I21: =H21*Table_2[[#This Row],[Área (m²)]] -> 29.99 | L21: ACABAMENTOS
B22: TERREO / 1 PAV | C22: LOJA02 | D22: 29.92 | E22: PORCELANATO | F22: Sim | G22: Gesso | H22: 1 | I22: =H22*Table_2[[#This Row],[Área (m²)]] -> 29.92 | L22: Material | M22: Área total
B23: TERREO / 1 PAV | C23: LOJA03 | D23: 33.19 | E23: PORCELANATO | F23: Sim | G23: Gesso | H23: 1 | I23: =H23*Table_2[[#This Row],[Área (m²)]] -> 33.19 | L23: POLIDO | M23: =SUMIF(E:E,L23,I:I) -> 2485.44
B24: TERREO / 1 PAV | C24: LOJA04 | D24: 71.66 | E24: PORCELANATO | F24: Sim | G24: Gesso | H24: 1 | I24: =H24*Table_2[[#This Row],[Área (m²)]] -> 71.66 | L24: CONCRETO ESCVADO | M24: =SUMIF(E:E,L24,I:I) -> 193.992
B25: TERREO / 1 PAV | C25: WC PCD LOJAS | D25: =2.95*2+3.29*2 -> 12.48 | E25: PORCELANATO | F25: Sim | G25: Gesso | H25: 1 | I25: =H25*Table_2[[#This Row],[Área (m²)]] -> 12.48 | L25: CIMENTADO | M25: =SUMIF(E:E,L25,I:I) -> 500.984
B26: TERREO / 1 PAV | C26: DEPÓSITO DE LIXO | D26: 15.38 | E26: CERAMICA | F26: Sim | G26: Gesso | H26: 1 | I26: =H26*Table_2[[#This Row],[Área (m²)]] -> 15.38 | L26: CONCRETO CALÇADA | M26: =SUMIF(E:E,L26,I:I) -> 134.11
B27: TERREO / 1 PAV | C27: HALL | D27: 23.11 | E27: PORCELANATO | F27: Sim | G27: Gesso | H27: 1 | I27: =H27*Table_2[[#This Row],[Área (m²)]] -> 23.11 | L27: PORCELANATO | M27: =SUMIF(E:E,L27,I:I) -> 4938.99
B28: TERREO / 1 PAV | C28: CIRCULAÇÃO | D28: 24.31 | E28: PORCELANATO | F28: Sim | G28: Gesso | H28: 1 | I28: =H28*Table_2[[#This Row],[Área (m²)]] -> 24.31 | L28: CERAMICA | M28: =SUMIF(E:E,L28,I:I) -> 27.2
B29: TERREO / 1 PAV | C29: ENTREGAS | D29: 3.03 | E29: PORCELANATO | F29: Sim | G29: Gesso | H29: 1 | I29: =H29*Table_2[[#This Row],[Área (m²)]] -> 3.03 | L29: EMBORRACHADO | M29: =SUMIF(E:E,L29,I:I) -> 126.98
B30: TERREO / 1 PAV | C30: ZELADORIA | D30: 8.35 | E30: CERAMICA | F30: Sim | G30: Gesso | H30: 1 | I30: =H30*Table_2[[#This Row],[Área (m²)]] -> 8.35 | L30: VINILICO | M30: =SUMIF(E:E,L30,I:I) -> 2328.21
B31: TERREO / 1 PAV | C31: BWC | D31: 3.47 | E31: CERAMICA | F31: Sim | G31: Gesso | H31: 1 | I31: =H31*Table_2[[#This Row],[Área (m²)]] -> 3.47 | L31: MADEIRA | M31: =SUMIF(E:E,L31,I:I) -> 7.41
B32: TERREO / 1 PAV | C32: QGM | D32: 11.42 | E32: CIMENTADO | F32: Sim | G32: - | H32: 1 | I32: =H32*Table_2[[#This Row],[Área (m²)]] -> 11.42 | L32: DECK | M32: =SUMIF(E:E,L32,I:I) -> 96.22
B33: TERREO / 1 PAV | C33: ESCADA | D33: =19.27+20*1.2*0.18 -> 23.59 | E33: CIMENTADO | F33: Sim | G33: Estucamento | H33: 1 | I33: =H33*Table_2[[#This Row],[Área (m²)]] -> 23.59 | L33: PASTILHA | M33: =SUMIF(E:E,L33,I:I) -> 54.96
B34: PAV INTERMEDIARIO | C34: LOJA01 | D34: 13.15 | E34: PORCELANATO | F34: Sim | G34: Gesso | H34: 1 | I34: =H34*Table_2[[#This Row],[Área (m²)]] -> 13.15 | L34: - | M34: =SUMIF(E:E,L34,I:I) -> 1504.95
B35: PAV INTERMEDIARIO | C35: LOJA02 | D35: 14.68 | E35: PORCELANATO | F35: Sim | G35: Gesso | H35: 1 | I35: =H35*Table_2[[#This Row],[Área (m²)]] -> 14.68
B36: PAV INTERMEDIARIO | C36: LOJA03 | D36: 15.63 | E36: PORCELANATO | F36: Sim | G36: Gesso | H36: 1 | I36: =H36*Table_2[[#This Row],[Área (m²)]] -> 15.63
B37: PAV INTERMEDIARIO | C37: LOJA04 | D37: 34.46 | E37: PORCELANATO | F37: Sim | G37: Gesso | H37: 1 | I37: =H37*Table_2[[#This Row],[Área (m²)]] -> 34.46
B38: PAV INTERMEDIARIO | C38: ESCADA LOJAS | D38: =1*20*0.18+1*19*0.3 -> 9.3 | E38: PORCELANATO | F38: Sim | G38: Estucamento | H38: 4 | I38: =H38*Table_2[[#This Row],[Área (m²)]] -> 37.2
B39: PAV INTERMEDIARIO | C39: ACADEMIA | D39: 92.36 | E39: EMBORRACHADO | F39: Sim | G39: Gesso | H39: 1 | I39: =H39*Table_2[[#This Row],[Área (m²)]] -> 92.36
B40: PAV INTERMEDIARIO | C40: MARKET | D40: 11.33 | E40: PORCELANATO | F40: Sim | G40: Gesso | H40: 1 | I40: =H40*Table_2[[#This Row],[Área (m²)]] -> 11.33
B41: PAV INTERMEDIARIO | C41: CIRCULAÇÃO | D41: 50.28 | E41: PORCELANATO | F41: Sim | G41: Gesso | H41: 1 | I41: =H41*Table_2[[#This Row],[Área (m²)]] -> 50.28
B42: PAV INTERMEDIARIO | C42: VENDING MACHINES | D42: 2.6 | E42: PORCELANATO | F42: Sim | G42: Gesso | H42: 1 | I42: =H42*Table_2[[#This Row],[Área (m²)]] -> 2.6
...

Sheet Rev. Internos Piso e Parede
A2: ORÇAMENTO PARAMÉTRICO GERENCIAMENTO EXECUTIVO
A7: Cliente
A8: Obra
A9: Data | B9: 45471
A10: Revisão | B10: R00
A12: REVESTIMENTOS INTERNOS EM PISO E PAREDE
A14: Descrição | B14: Quantidade | D14: Parâmetro | F14: Referência | G14: Valor total
A15: Polimento de concreto | B15: ='PISO E TETO'!M23 -> 2485.44 | C15: m² | D15: 50 | E15: R$ / m² | F15: Média | G15: =D15*B15*1.1 -> 136699.2 | H15: =G15/B15 -> 55 | I15: =172.7*B15 -> 429235.49
A16: Piso alisado | B16: ='PISO E TETO'!M25 -> 500.984 | C16: m² | D16: =25-D20 -> 5 | E16: R$ / m² | F16: Média | G16: =D16*B16*1.1 -> 2755.412
A17: Piso ranhurado | B17: ='PISO E TETO'!M24 -> 193.992 | C17: m² | D17: =28-D20 -> 8 | E17: R$ / m² | F17: Média | G17: =D17*B17*1.1 -> 1707.1296
A18: Contrapiso | B18: ='PISO E TETO'!M11 -> 9257.564 | C18: m² | D18: =B18/DADOS_INICIAIS!E9 -> 0.70411613 | E18: m² / AC | F18: Média | G18: =+B18*65*1.1-G21 -> 254583.01
A19: Manta acústica | B19: ='PISO E TETO'!M12 -> 7235.914 | C19: m² | D19: =B19/DADOS_INICIAIS!E9 -> 0.55035253 | E19: m² / AC | F19: Média | G19: =+B19*25*1.1 -> 198987.63 | J19: =G19/B19 -> 27.5 | K19: =G19/DADOS_INICIAIS!E9 -> 15.134695
A20: MO ALISADO | B20: =B16+B17 -> 694.976 | D20: 20 | G20: =D20*B20*1.1 -> 15289.472
A21: MO CONTRAPISO | B21: =B18 -> 9257.564 | D21: 40 | G21: =D21*B21*1.1 -> 407332.82
A22: Chapisco | B22: =ALVENARIA!D14*2-'Rev. Fachada'!B15 -> 35425.93 | C22: m² | D22: 2.2 | E22: m² / AC | F22: Média | G22: =+B22*5*1.1 -> 194842.62
A23: Reboco | B23: =B22 -> 35425.93 | C23: m² | D23: 2.2 | E23: m² / AC | F23: Média | G23: =17*B23*1.1 -> 662464.89
A24: mo Reboco | B24: =B23 -> 35425.93 | C24: m² | D24: 2.2 | E24: m² / AC | F24: Média | G24: =33*B24*1.1 -> 1285961.3
A25: TOTAL | G25: =SUM(G15:G24) -> 3160623.4
A28: TOTAL REVESTIMENTOS | G28: =G25 -> 3160623.4 | H28: =G28/DADOS_INICIAIS!E9 -> 240.39218
B30: =2*ALVENARIA!D14-'Rev. Fachada'!B15 -> 35425.93 | H30: =H28/1.1 -> 218.53834
A32: REVESTIMENTOS INTERNOS EM PISO E PAREDE | K32: =17+33 -> 50
A34: Descrição | B34: Quantidade | D34: Parâmetro | F34: Referência | G34: Valor total
A35: Polimento de concreto | B35: 2485.44 | C35: m² | D35: =0.1*610+16+80 -> 157 | E35: R$ / m² | F35: Média | G35: =D35*B35*1.1 -> 429235.49 | H35: =G35/B35 -> 172.7
A36: Piso alisado | B36: 500.984 | C36: m² | D36: =25 -> 25 | E36: R$ / m² | F36: Média | G36: =D36*B36*1.1 -> 13777.06
A37: Piso ranhurado | B37: 193.992 | C37: m² | D37: =28 -> 28 | E37: R$ / m² | F37: Média | G37: =D37*B37*1.1 -> 5974.9536
A38: Contrapiso | B38: 9257.564 | C38: m² | D38: =B38/DADOS_INICIAIS!E26 -> 58.607014 | E38: m² / AC | F38: Média | G38: =+B38*65*1.1 -> 661915.83
A39: Manta acústica | B39: 7235.914 | C39: m² | D39: =B39/DADOS_INICIAIS!E26 -> 45.808521 | E39: m² / AC | F39: Média | G39: =+B39*25*1.1 -> 198987.63
A40: Chapisco | B40: 35425.93 | C40: m² | D40: 2.2 | E40: m² / AC | F40: Média
A41: Reboco | B41: 35425.93 | C41: m² | D41: 2.2 | E41: m² / AC | F41: Média | G41: =(12.5)*B41*1.1 -> 487106.54
A42: mo REBOCO | B42: 35425.93 | C42: m² | D42: 2.2 | E42: m² / AC | F42: Média | G42: =20*B42*1.1 -> 779370.46 | L42: =52.21-33 -> 19.21
A43: TOTAL | G43: =SUM(G35:G41) -> 1796997.5

Sheet TETO
A3: REVESTIMENTOS E ACABAMENTOS DE TETO
A4: Data | B4: 45471
A5: Arquivo base | B5: -
A7: GESSO
A9: Descrição | B9: Parâmetro | D9: Quantidade | F9: Preço unitário | G9: Valor total | H9: Observação
A10: Forro gesso mineral | B10: =D10/DADOS_INICIAIS!$E$9 -> 0.60624836 | C10: m² / AC | D10: ='PISO E TETO'!M16+'PISO E TETO'!M17 -> 7970.82 | E10: m² | F10: 60 | G10: =F10*D10*1.1 -> 526074.12
A11: Negativo | B11: 1.2 | C11: m / FORRO | D11: =(D10)*B11 -> 9564.984 | E11: m² | F11: 22 | G11: =F11*D11*1.1 -> 231472.61
A12: Estucamento | B12: =D12/DADOS_INICIAIS!$E$9 -> 0.23658945 | C12: m² / AC | D12: ='PISO E TETO'!M15 -> 3110.626 | E12: m² | F12: =7.5 -> 7.5 | G12: =F12*D12*1.1 -> 25662.664
A13: mo Estucamento | B13: =D13/DADOS_INICIAIS!$E$9 -> 0.23658945 | C13: m² / AC | D13: =D12 -> 3110.626 | E13: m² | F13: 22 | G13: =F13*D13*1.1 -> 75277.149
A14: TOTAL | G14: =SUM(G10:G12) -> 783209.4 | H14: =G14/DADOS_INICIAIS!$E$9 -> 59.569707 | K14: =4160+1440+1120+2880+4800+91680+4000 -> 110080 | L14: =K14/21 -> 5241.9048
A15: GESSO + MADEIRA
A17: Descrição | B17: Parâmetro | D17: Quantidade | F17: Preço unitário | G17: Valor total | H17: Observação
A18: Forro gesso mineral | B18: =D18/DADOS_INICIAIS!$E$9 -> 0.57811433 | C18: m² / AC | D18: ='PISO E TETO'!$M$16+'PISO E TETO'!M17-TETO!D20 -> 7600.92 | E18: m² | F18: 60 | G18: =F18*D18*1.1 -> 501660.72
A19: Negativo | B19: 1.2 | C19: m / FORRO | D19: =(D18)*B19 -> 9121.104 | E19: m² | F19: 22 | G19: =F19*D19*1.1 -> 220730.72
A20: Forro de madeira | B20: =D20/DADOS_INICIAIS!$E$9 -> 0.028134027 | C20: m² / AC | D20: 369.9 | E20: m² | F20: 579 | G20: =F20*D20*1.1 -> 235589.31 | H20: =G20/D20 -> 636.9
A21: Estucamento | B21: =D21/DADOS_INICIAIS!$E$9 -> 0.23658945 | C21: m² / AC | D21: ='PISO E TETO'!$M$15 -> 3110.626 | E21: m² | F21: =7.5+22 -> 29.5 | G21: =F21*D21*1.1 -> 100939.81
A22: TOTAL | G22: =SUM(G18:G21) -> 1058920.6 | H22: =G22/DADOS_INICIAIS!$E$9 -> 80.539875 | K22: =4160+1440+1120+2880+4800+91680+4000 -> 110080 | L22: =K22/21 -> 5241.9048
A23: GESSO + PVC
A25: Descrição | B25: Parâmetro | D25: Quantidade | F25: Preço unitário | G25: Valor total | H25: Observação
A26: Forro gesso mineral | B26: =D26/DADOS_INICIAIS!$E$9 -> 0.57811433 | C26: m² / AC | D26: ='PISO E TETO'!$M$16+'PISO E TETO'!M17-TETO!D28 -> 7600.92 | E26: m² | F26: 60 | G26: =F26*D26*1.1 -> 501660.72
A27: Negativo | B27: 1.2 | C27: m / FORRO | D27: =(D26)*B27 -> 9121.104 | E27: m² | F27: 22 | G27: =F27*D27*1.1 -> 220730.72
A28: Forro PVC imita madeira | B28: =D28/DADOS_INICIAIS!$E$9 -> 0.028134027 | C28: m² / AC | D28: 369.9 | E28: m² | F28: 74.16 | G28: =F28*D28*1.1 -> 30174.962 | H28: =G28/D28 -> 81.576
A29: Estucamento | B29: =D29/DADOS_INICIAIS!$E$9 -> 0.23658945 | C29: m² / AC | D29: ='PISO E TETO'!$M$15 -> 3110.626 | E29: m² | F29: =7.5+22 -> 29.5 | G29: =F29*D29*1.1 -> 100939.81
A30: TOTAL | G30: =SUM(G26:G29) -> 853506.21 | H30: =G30/DADOS_INICIAIS!$E$9 -> 64.916375 | K30: =4160+1440+1120+2880+4800+91680+4000 -> 110080 | L30: =K30/21 -> 5241.9048
A31: GESSO + VINILICO
A33: Descrição | B33: Parâmetro | D33: Quantidade | F33: Preço unitário | G33: Valor total | H33: Observação
A34: Forro gesso mineral | B34: =D34/DADOS_INICIAIS!$E$9 -> 0.57811433 | C34: m² / AC | D34: ='PISO E TETO'!$M$16+'PISO E TETO'!M17-TETO!D36 -> 7600.92 | E34: m² | F34: 60 | G34: =F34*D34*1.1 -> 501660.72
A35: Negativo | B35: 1.2 | C35: m / FORRO | D35: =(D34)*B35 -> 9121.104 | E35: m² | F35: 22 | G35: =F35*D35*1.1 -> 220730.72
A36: Forro PVC imita madeira | B36: =D36/DADOS_INICIAIS!$E$9 -> 0.028134027 | C36: m² / AC | D36: 369.9 | E36: m² | F36: =F18+'Acabamentos de Piso e Parede'!D19+20 -> 230 | G36: =F36*D36*1.1 -> 93584.7 | H36: =G36/D36 -> 253
A37: Estucamento | B37: =D37/DADOS_INICIAIS!$E$9 -> 0.23658945 | C37: m² / AC | D37: ='PISO E TETO'!$M$15 -> 3110.626 | E37: m² | F37: =7.5+22 -> 29.5 | G37: =F37*D37*1.1 -> 100939.81
A38: TOTAL | G38: =SUM(G34:G37) -> 916915.95 | H38: =G38/DADOS_INICIAIS!$E$9 -> 69.739222 | K38: =4160+1440+1120+2880+4800+91680+4000 -> 110080 | L38: =K38/21 -> 5241.9048
A40: TOTAL FORRO | G40: =G14 -> 783209.4 | H40: =G40/DADOS_INICIAIS!E9 -> 59.569707
G42: =G22/DADOS_INICIAIS!E9 -> 80.539875
H43: =H40/1.1 -> 54.154279

Sheet Acabamentos de Piso e Parede
A2: ORÇAMENTO PARAMÉTRICO GERENCIAMENTO EXECUTIVO
A7: Cliente
A8: Obra
A9: Data | B9: 45471
A10: Revisão | B10: R00
A12: ACABAMENTOS EM PISO E PAREDE - DECK
A14: Descrição | B14: Quantidade | D14: Parâmetro | F14: Referência | G14: Valor total
A15: Porcelanato | B15: ='PISO E TETO'!$M$27 -> 4938.99 | C15: m² | D15: =125+45 -> 170 | E15: R$ / m² | F15: Média | G15: =+D15*B15*1.1 -> 923591.13
A16: Ceramica | B16: ='PISO E TETO'!$M$28 -> 27.2 | C16: m² | D16: =85.1+45 -> 130.1 | E16: R$ / m² | F16: Média | G16: =+D16*B16*1.1 -> 3892.592
A17: Piscina | B17: ='PISO E TETO'!$M$33 -> 54.96 | C17: m² | D17: =290+50 -> 340 | E17: R$ / m² | F17: Média | G17: =+D17*B17*1.1 -> 20555.04
A18: Concreto calçada | B18: ='PISO E TETO'!$M$26 -> 134.11 | C18: m² | D18: =60+21 -> 81 | E18: R$ / m² | F18: Média | G18: =+D18*B18*1.1 -> 11949.201
A19: Vinilico | B19: ='PISO E TETO'!$M$30 -> 2328.21 | C19: m² | D19: 150 | E19: R$ / m² | F19: Média | G19: =+D19*B19*1.1 -> 384154.65
A20: Emborrachado | B20: ='PISO E TETO'!$M$29 -> 126.98 | C20: m² | D20: 350 | E20: R$ / m² | F20: Média | G20: =+D20*B20*1.1 -> 48887.3 | H20: =G20/B20 -> 385
A21: Deck | B21: ='PISO E TETO'!$M$32 -> 96.22 | C21: m² | D21: =768+40 -> 808 | E21: R$ / m² | F21: Média | G21: =+D21*B21*1.1 -> 85520.336 | H21: =G21/B21 -> 888.8 | I21: =B21*(245+45)*1.1 -> 30694.18 | J21: =I21/B21 -> 319
A22: Madeira sauna | B22: ='PISO E TETO'!$M$31 -> 7.41 | C22: m² | D22: =985.2 -> 985.2 | E22: R$ / m² | F22: Média | G22: =+D22*B22*1.1 -> 8030.3652
A23: Rodapés | B23: 1 | C23: vb | D23: 20 | E23: R$ / AC | F23: Média | G23: =D23*DADOS_INICIAIS!$E$9*1.1 -> 289251.16
A24: Soleiras e peitoris | B24: 1 | C24: vb | D24: 15 | E24: R$ / AC | F24: Média | G24: =D24*DADOS_INICIAIS!$E$9*1.1 -> 216938.37
A25: Revestimentos de Parede | B25: =Orçamento!D78+Orçamento!D79 -> 3691.46 | C25: m² | D25: =75+45 -> 120 | E25: R$ / AC | F25: Média | G25: =D25*B25*1.1 -> 487272.72 | I25: =G25/D16 -> 3745.3706
G26: =SUM(G15:G25) -> 2480042.9 | H26: =G26/DADOS_INICIAIS!$E$9 -> 188.62826
A28: ACABAMENTOS EM PISO E PAREDE - PISO IMITA MADEIRA
A30: Descrição | B30: Quantidade | D30: Parâmetro | F30: Referência | G30: Valor total
A31: Porcelanato | B31: ='PISO E TETO'!$M$27 -> 4938.99 | C31: m² | D31: =125+45 -> 170 | E31: R$ / m² | F31: Média | G31: =+D31*B31*1.1 -> 923591.13
A32: Ceramica | B32: ='PISO E TETO'!$M$28 -> 27.2 | C32: m² | D32: =85.1+45 -> 130.1 | E32: R$ / m² | F32: Média | G32: =+D32*B32*1.1 -> 3892.592
A33: Piscina | B33: ='PISO E TETO'!$M$33 -> 54.96 | C33: m² | D33: =290+50 -> 340 | E33: R$ / m² | F33: Média | G33: =+D33*B33*1.1 -> 20555.04
A34: Concreto calçada | B34: ='PISO E TETO'!$M$26 -> 134.11 | C34: m² | D34: =60+21 -> 81 | E34: R$ / m² | F34: Média | G34: =+D34*B34*1.1 -> 11949.201
A35: Vinilico | B35: ='PISO E TETO'!$M$30 -> 2328.21 | C35: m² | D35: 150 | E35: R$ / m² | F35: Média | G35: =+D35*B35*1.1 -> 384154.65
A36: Emborrachado | B36: ='PISO E TETO'!$M$29 -> 126.98 | C36: m² | D36: 150 | E36: R$ / m² | F36: Média | G36: =+D36*B36*1.1 -> 20951.7
A37: Piso imita madeira | B37: ='PISO E TETO'!$M$32 -> 96.22 | C37: m² | D37: =250+45 -> 295 | E37: R$ / m² | F37: Média | G37: =+D37*B37*1.1 -> 31223.39 | H37: =G37/B37 -> 324.5 | I37: =B37*(245+45)*1.1 -> 30694.18 | J37: =I37/B37 -> 319
A38: Madeira sauna | B38: ='PISO E TETO'!$M$31 -> 7.41 | C38: m² | D38: =985.2 -> 985.2 | E38: R$ / m² | F38: Média | G38: =+D38*B38*1.1 -> 8030.3652
A39: Rodapés | B39: 1 | C39: vb | D39: 20 | E39: R$ / AC | F39: Média | G39: =D39*DADOS_INICIAIS!$E$9*1.1 -> 289251.16
A40: Soleiras e peitoris | B40: 1 | C40: vb | D40: 15 | E40: R$ / AC | F40: Média | G40: =D40*DADOS_INICIAIS!$E$9*1.1 -> 216938.37
A41: Revestimentos de Parede | B41: =Orçamento!D78+Orçamento!D79 -> 3691.46 | C41: m² | D41: =75+45 -> 120 | E41: R$ / AC | F41: Média | G41: =D41*B41*1.1 -> 487272.72 | I41: =G41/D32 -> 3745.3706
G42: =SUM(G31:G41) -> 2397810.3 | H42: =G42/DADOS_INICIAIS!$E$9 -> 182.37378
A44: ACABAMENTOS EM PISO E PAREDE - VINILICO
A46: Descrição | B46: Quantidade | D46: Parâmetro | F46: Referência | G46: Valor total
A47: Porcelanato | B47: ='PISO E TETO'!$M$27 -> 4938.99 | C47: m² | D47: =125+45 -> 170 | E47: R$ / m² | F47: Média | G47: =+D47*B47*1.1 -> 923591.13
A48: Ceramica | B48: ='PISO E TETO'!$M$28 -> 27.2 | C48: m² | D48: =85.1+45 -> 130.1 | E48: R$ / m² | F48: Média | G48: =+D48*B48*1.1 -> 3892.592
A49: Piscina | B49: ='PISO E TETO'!$M$33 -> 54.96 | C49: m² | D49: =290+50 -> 340 | E49: R$ / m² | F49: Média | G49: =+D49*B49*1.1 -> 20555.04
A50: Concreto calçada | B50: ='PISO E TETO'!$M$26 -> 134.11 | C50: m² | D50: =60+21 -> 81 | E50: R$ / m² | F50: Média | G50: =+D50*B50*1.1 -> 11949.201
A51: Vinilico | B51: ='PISO E TETO'!$M$30 -> 2328.21 | C51: m² | D51: 150 | E51: R$ / m² | F51: Média | G51: =+D51*B51*1.1 -> 384154.65
...

Sheet PINTURA INTERNA
A3: PINTURA INTERNA
A4: Data | B4: 45457
A5: Arquivo base | B5: -
A7: ALVENARIA
A9: Descrição | B9: Parâmetro | D9: Quantidade | F9: Preço unitário | G9: Valor total | H9: Observação
A10: Pintura piso epoxi | B10: 110 | C10: R$ / m² | D10: ='PISO E TETO'!M23*0.1 -> 248.544 | E10: m² | F10: =80+40 -> 120 | G10: =F10*D10*1.1 -> 32807.808 | H10: =ALVENARIA!D13*2-'Rev. Fachada'!B15 -> 35425.93 | I10: =G10/D10 -> 132
A11: Pintura acrílica antiderrapante | B11: 65 | C11: R$ / m² | D11: ='PISO E TETO'!M25 -> 500.984 | E11: m² | F11: =65 -> 65 | G11: =F11*D11*1.1 -> 35820.356 | H11: =H10*0.8+TETO!D10 -> 36311.564 | I11: =1+1.5+15+35 -> 52.5
A12: Textura escadas | B12: 25 | C12: R$ / AC | D12: =('Rev. Internos Piso e Parede'!B22-'Acabamentos de Piso e Parede'!B78)*0.3 -> 9520.341 | E12: m² | F12: =1.5727+6.3758+27 -> 34.9485 | G12: =F12*D12*1.1 -> 365993.8 | H12: =H10*0.2+TETO!D12 -> 10195.812 | I12: =1-I15 -> 0.33333333 | J12: =I12*G15 -> 406439.63
A13: Textura Teto | B13: 25 | C13: R$ / AC | D13: =TETO!D21 -> 3110.626 | E13: m² | F13: =F12 -> 34.9485 | G13: =F13*D13*1.1 -> 119582.88 | H13: =H11*0.2+TETO!D14 -> 7262.3128 | I13: =1-I16 -> #REF! | J13: =I13*G16 -> #REF!
A14: Pintura Interna Tetos | B14: =90*0.9 -> 81 | C14: R$ / AC | D14: =TETO!D18 -> 7600.92 | E14: m² | F14: =1.5727+4.8875+11.4392+32 -> 49.8994 | G14: =F14*D14*1.1 -> 417209.48 | I14: =35/I10 -> 0.26515152 | J14: =I14*G14 -> 110623.73
A15: Pintura Interna | B15: =90*0.9 -> 81 | C15: R$ / AC | D15: =('Rev. Internos Piso e Parede'!B22-'Acabamentos de Piso e Parede'!B78)*0.7 -> 22214.129 | E15: m² | F15: =F14 -> 49.8994 | G15: =F15*D15*1.1 -> 1219318.9 | I15: =35/I11 -> 0.66666667 | J15: =I15*G15 -> 812879.25
A16: TOTAL | G16: =SUM(G10:G15) -> 2190733.2 | I16: =31/#REF! -> #REF! | J16: =I16*G12 -> #REF! | K16: =4160+1440+1120+2880+4800+91680+4000 -> 110080 | L16: =K16/21 -> 5241.9048
A18: TOTAL IMPERMEABILIZAÇÃO | G18: =G16 -> 2190733.2 | H18: =G18/DADOS_INICIAIS!E9 -> 166.62381
H20: =H18/1.1 -> 151.47619
A22: ALVENARIA
A24: Descrição | B24: Parâmetro | D24: Quantidade | F24: Preço unitário | G24: Valor total | H24: Observação
A25: Pintura piso epoxi | B25: 110 | C25: R$ / m² | E25: m² | F25: =80+40 -> 120 | G25: =F25*D25*1.1 -> 0 | H25: =ALVENARIA!D28*2-'Rev. Fachada'!B30 -> 21700.986
A26: Pintura acrílica antiderrapante | B26: 65 | C26: R$ / m² | D26: 500.984 | E26: m² | F26: =65 -> 65 | G26: =F26*D26*1.1 -> 35820.356 | H26: =H25*0.8+TETO!D26 -> 24961.708
A27: Textura escadas | B27: 25 | C27: R$ / AC | D27: 6346.894 | E27: vb | F27: =1.5727+7.3758+31 -> 39.9485 | G27: =F27*D27*1.1 -> 278903.78 | H27: =H25*0.2+TETO!D28 -> 4710.0971
A28: Textura Teto | B28: 25 | C28: R$ / AC | D28: 3110.626 | E28: m² | F28: =0.96+7.3758+31 -> 39.3358 | G28: =F28*D28*1.1 -> 134594.86 | H28: =H26*0.2+TETO!D29 -> 8102.9677
A29: Pintura Interna Tetos | B29: =90*0.9 -> 81 | C29: R$ / AC | D29: 7600.92 | E29: m² | F29: =1.5727+5.8875+14.4392+32 -> 53.8994 | G29: =F29*D29*1.1 -> 450653.53
A30: Pintura Interna | B30: =90*0.9 -> 81 | C30: R$ / AC | D30: 25387.576 | E30: m² | F30: =1.5727+5.8875+14.4392+34 -> 55.8994 | G30: =F30*D30*1.1 -> 1561065.3
A31: TOTAL | G31: =SUM(G25:G30) -> 2461037.8

Sheet COBERTURA
A2: COBERTURA
A3: Data | B3: 45543
A4: Arquivo base | B4: -
A6: TELHADO
A8: Descrição | B8: Parâmetro | D8: Quantidade | F8: Preço unitário | G8: Valor total | H8: Observação
A9: Estrutura e telhamento | D9: =5041.4/14-39.9 -> 320.2 | E9: m² | F9: 500 | G9: =F9*D9*1.1 -> 176110
A10: Serviços complementares | D10: =D9 -> 320.2 | E10: m² | F10: 45 | G10: =F10*D10*1.1 -> 15849.9
A11: Pergolados | D11: 15 | E11: m² | F11: 450 | G11: =F11*D11*1.1 -> 7425
A12: Passarelas | G12: =F12*D12*1.1 -> 0
A13: TOTAL | G13: =SUM(G9:G12) -> 199384.9
A15: TOTAL COMPLEMENTARES | G15: =G13 -> 199384.9 | H15: =G15/DADOS_INICIAIS!$E$9 -> 15.16491

Sheet ESQUADRIAS
A3: ESQUADRIAS
A4: Data | B4: 45460
A5: Arquivo base | B5: -
A7: ESQUADRIAS
A9: Descrição | B9: Parâmetro | D9: Quantidade | G9: Valor total | H9: Observação
A10: Esquadrias de Alumínio | B10: =D10/DADOS_INICIAIS!E9 -> 0.16054232 | C10: m² / AC | D10: =Orçamento!D120+Orçamento!D24 -> 2110.7751 | E10: m² | F10: 1250 | G10: =F10*D10*1.1 -> 2902315.8 | H10: praticamente toda aa rea da torre | I10: =G10/D10 -> 1375
A11: Pele de vidro | D11: =18.15+236.54 -> 254.69 | E11: m² | F11: 950 | G11: =F11*D11*1.1 -> 266151.05
A12: Brise de fachada | D12: =F30 -> 345.254 | E12: m² | F12: 2100 | G12: =F12*D12*1.1 -> 797536.74 | H12: =G12/D12 -> 2310
A13: Portão de alumínio | D13: 2 | E13: un | F13: 18000 | G13: =F13*D13*1.1 -> 39600
A14: Guarda-corpo - vidro | D14: =E30 -> 454.5664 | E14: m² | F14: 2100 | G14: =F14*D14*1.1 -> 1050048.4
A15: Gradil area tecnica | D15: =E29 -> 497.4144 | E15: m² | F15: 610 | G15: =F15*D15*1.1 -> 333765.06
A16: Serralherias | B16: 6 | C16: R$ / AC | D16: 1 | E16: vb | F16: =B16*DADOS_INICIAIS!$E$9 -> 78886.68 | G16: =F16*D16*1.1 -> 86775.348
A17: PCF | D17: =2*DADOS_INICIAIS!E15 -> 26 | E17: un | F17: 1750 | G17: =F17*D17*1.1 -> 50050
A18: Corrimão madeira | D18: =16.4*1.2*DADOS_INICIAIS!E15 -> 255.84 | E18: m | F18: 65 | G18: =F18*D18*1.1 -> 18292.56
A19: Corrimão comercial | D19: =7.228*4 -> 28.912 | E19: m | F19: 650 | G19: =F19*D19*1.1 -> 20672.08
A20: Fechadura Biometrica | D20: =DADOS_INICIAIS!E10 -> 84 | E20: un | F20: 1500 | G20: =F20*D20*1.1 -> 138600
A21: Esquadrias de Madeira | D21: =16+187+201+69+3 -> 476 | E21: un | F21: =1800+130 -> 1930 | G21: =F21*D21*1.1 -> 1010548
A22: TOTAL | G22: =SUM(G10:G21) -> 6714355 | K22: =4160+1440+1120+2880+4800+91680+4000 -> 110080 | L22: =K22/21 -> 5241.9048
A24: TOTAL ESQUADRIAS | G24: =G22 -> 6714355 | H24: =G24/DADOS_INICIAIS!E9 -> 510.68355
B28: LAZER | C28: TIPO | D28: COBERTURA | E28: GUARDA | F28: brise movel
A29: BRISE AREA TECNICA | C29: =22.206 -> 22.206 | D29: 0 | E29: =C29*2.8*8 -> 497.4144
A30: GC SACADA | B30: =27.767*1.2+23.699*2 -> 80.7184 | C30: 246.61 | D30: =43.092*2+20.527*2 -> 127.238 | E30: =B30+C30+D30 -> 454.5664 | F30: =C30*2.8/2 -> 345.254
C34: =43.092*2+20.527*2 -> 127.238

Sheet ESQUADRIAS (2)
A3: ESQUADRIAS
A4: Data | B4: 45460
A5: Arquivo base | B5: -
A7: ESQUADRIAS
D8: =ESQUADRIAS!D10-'ESQUADRIAS (2)'!D10 -> 460.8
A9: Descrição | B9: Parâmetro | D9: Quantidade | G9: Valor total | H9: Observação
A10: Esquadrias de Alumínio | B10: =D10/DADOS_INICIAIS!E9 -> 0.12549458 | C10: m² / AC | D10: =Orçamento!D120+Orçamento!D24-748.8+288 -> 1649.9751 | E10: m² | F10: 1150 | G10: =F10*D10*1.1 -> 2087218.5 | H10: praticamente toda aa rea da torre | I10: =G10/D10 -> 1265
A11: Pele de vidro | D11: =18.15+236.54 -> 254.69 | E11: m² | F11: 950 | G11: =F11*D11*1.1 -> 266151.05
A12: Brise de fachada | D12: =F30 -> 345.254 | E12: m² | F12: 2100 | G12: =F12*D12*1.1 -> 797536.74
A13: Portão de alumínio | D13: 2 | E13: un | F13: 18000 | G13: =F13*D13*1.1 -> 39600
A14: Guarda-corpo - vidro | D14: =E30 -> 454.5664 | E14: m² | F14: 2100 | G14: =F14*D14*1.1 -> 1050048.4
A15: Gradil area tecnica | D15: =E29 -> 497.4144 | E15: m² | F15: 610 | G15: =F15*D15*1.1 -> 333765.06
A16: Serralherias | B16: 6 | C16: R$ / AC | D16: 1 | E16: vb | F16: =B16*DADOS_INICIAIS!$E$9 -> 78886.68 | G16: =F16*D16*1.1 -> 86775.348
