Workbook
Name aa: #REF!
Name aa: #REF!
Name aa: #REF!
Name aa: #REF!
Name aaaa: '[1]M.O.'!#REF!
Name aaaa: '[1]M.O.'!#REF!
Name aaaa: '[1]M.O.'!#REF!
Name aaaa: '[1]M.O.'!#REF!
Name angelo: [2]Geral!#REF!
Name angelo: [2]Geral!#REF!
Name angelo: [2]Geral!#REF!
Name area: #REF!
Name aux: #REF!
Name aux: #REF!
Name aux: #REF!
Name BDA: #REF!
Name BDA: #REF!
Name BDA: #REF!
Name BDI: #REF!
Name BDI: #REF!
Name ca: #REF!
Name ca: #REF!
Name Capa: #REF!
Name Capa: #REF!
Name cronograma: #REF!
Name cronograma: #REF!
Name D: #REF!
Name D: #REF!
Name direto: #REF!
Name direto: #REF!
Name DRE: #REF!
Name DRE: #REF!
Name ea: #REF!
Name ea: #REF!
Name eee: {#N/A,#N/A,FALSE,"ET-CAPA";#N/A,#N/A,FALSE,"ET-PAG1";#N/A,#N/A,FALSE,"ET-PAG2";#N/A,#N/A,FALSE,"ET-PAG3";#N/A,#N/A,FALSE,"ET-PAG4";#N/A,#N/A,FALSE,"ET-PAG5"}
Name eee: {#N/A,#N/A,FALSE,"ET-CAPA";#N/A,#N/A,FALSE,"ET-PAG1";#N/A,#N/A,FALSE,"ET-PAG2";#N/A,#N/A,FALSE,"ET-PAG3";#N/A,#N/A,FALSE,"ET-PAG4";#N/A,#N/A,FALSE,"ET-PAG5"}
Name eee: {#N/A,#N/A,FALSE,"ET-CAPA";#N/A,#N/A,FALSE,"ET-PAG1";#N/A,#N/A,FALSE,"ET-PAG2";#N/A,#N/A,FALSE,"ET-PAG3";#N/A,#N/A,FALSE,"ET-PAG4";#N/A,#N/A,FALSE,"ET-PAG5"}
Name eee: {#N/A,#N/A,FALSE,"ET-CAPA";#N/A,#N/A,FALSE,"ET-PAG1";#N/A,#N/A,FALSE,"ET-PAG2";#N/A,#N/A,FALSE,"ET-PAG3";#N/A,#N/A,FALSE,"ET-PAG4";#N/A,#N/A,FALSE,"ET-PAG5"}
Name FFFFFFF: #REF!
Name FFFFFFF: #REF!
Name item_1: #REF!
Name item_1: #REF!
Name LS: '[1]M.O.'!#REF!
Name LS: '[1]M.O.'!#REF!
Name MENU: #REF!
Name MENU: #REF!
Name MENU: #REF!
Name MENU: #REF!
Name MENU1: #REF!
Name MENU1: #REF!
Name MENU1: #REF!
Name MENU2: #REF!
Name MENU2: #REF!
Name MENU2: #REF!
Name MENU3: #REF!
Name MENU3: #REF!
Name MENU4: #REF!
Name MENU4: #REF!
Name MENU5: #REF!
Name MENU5: #REF!

Sheet OBRA
A1: Obra | B1: Jurerê Blue
A2: Empresa | B2: GRUPO EIS
A3: Revisão | B3: R00
A4: DADOS OBRA
A6: ARQUITETURA
B8: Descrição | C8: Unidade | D8: Quantidade
B9: ÁREA DO TERRENO | C9: M2 | D9: 720
B10: ÁREA CONSTRUÍDA | C10: M2 | D10: ='[4]Obra '!$C$10 -> 5347.86
B11: NÚMERO DE UNIDADES HABITACIONAIS | C11: UN | D11: 77
B12: MESES DE OBRA | C12: MÊS | D12: 48
B13: NÚMERO DE PAVIMENTOS | C13: UN | D13: 13

Sheet CANTEIRO
A1: Obra | B1: =OBRA!B1 -> Jurerê Blue
A2: Empresa | B2: =OBRA!B2 -> GRUPO EIS
A3: Revisão | B3: =OBRA!B3 -> R00
A4: LEVANTAMENTO QUANTITATIVO
A6: Instalações de canteiro
A8: Instalações de canteiro
B10: Descrição | C10: Unidade | D10: Quantidade
B11: Produtividade média | C11: m2 / mês | D11: =OBRA!D10/OBRA!D12 -> 111.41375
B12: Pm | C12: h/m2 | D12: 49
B13: Numero de funcionários | C13: un | D13: =ROUNDUP((D12*OBRA!D10)/OBRA!D12/180,) -> 31
B14: Equipe administrativa | C14: un | D14: 4
B15: Pontos de água e esgoto | C15: un | D15: =ROUNDUP($D$13/20,0) -> 2 | E15: 20 funcionários/ponto
B16: Bebedouro | C16: un | D16: =ROUNDUP(OBRA!$D$13/5,0) -> 3 | E16: 1 / 5 pav.
B17: Ferramentas | C17: R$ | D17: =800*D13 -> 24800 | E17: 800,00/func.
B18: EPI | C18: R$ | D18: =500*(D13+D14) -> 17500 | E18: 500,00/func.
B19: Banheiro | C19: un | D19: =ROUNDUP($D$13/20,0) -> 2 | E19: 1/20 func
A21: Mobiliário de canteiro
B23: Descrição | C23: Unidade | D23: Quantidade | E23: Custo unitário | F23: Custo total
B24: Cadeira | C24: un | D24: =D14*1.5 -> 6 | E24: 200 | F24: =D24*E24 -> 1200
B25: Mesa | C25: un | D25: 1 | E25: 1000 | F25: =E25*D25 -> 1000
B26: Ar condicionado | C26: un | D26: 1 | E26: 5000 | F26: =E26*D26 -> 5000
B27: Armário | C27: m | D27: =2 -> 2 | E27: 900 | F27: =E27*D27 -> 1800
B28: Escrivaninha | C28: un | D28: =D14 -> 4 | E28: 800 | F28: =E28*D28 -> 3200
B29: TOTAL | F29: =F26+F27+F28+F25+F24 -> 12200
B30: Descrição | C30: Unidade | D30: Quantidade | E30: Custo unitário | F30: Custo total
B31: Computador pessoal | C31: un | D31: =D14/2 -> 2 | E31: 6000 | F31: =D31*E31 -> 12000
B32: Impressora | C32: un | D32: 1 | E32: 2000 | F32: =E32*D32 -> 2000
B33: Roteador | C33: un | D33: 1 | E33: 500 | F33: =E33*D33 -> 500
B34: TOTAL | F34: =+F31+F32+F33 -> 14500

Sheet BASES
A1: Estimativas
B3: Área de Terreno | C3: Área Construída | D3: N° pavimentos | G3: Parâmetros | H3: Área de Terreno | I3: Área Construída | J3: index
A4: =OBRA!B1 -> Jurerê Blue | B4: =OBRA!D9 -> 720 | C4: =OBRA!D10 -> 5347.86 | D4: =OBRA!D13 -> 13 | G4: Bela Vida | H4: 0 | I4: 5039.98 | J4: 0
G5: Esmeralda | H5: 0 | I5: 5579.63 | J5: 0
G6: MARINE | H6: 0 | I6: 4498.66 | J6: 0
I8: =G4 -> Bela Vida | J8: =G4 -> Bela Vida | K8: =$G$5 -> Esmeralda | L8: =$G$5 -> Esmeralda | M8: =G6 -> MARINE | N8: =G6 -> MARINE
A9: Descrição | F9: Unidade | G9: Quantidade | H9: Valor (R$) | I9: Valor | J9: Referencia | K9: Valor | L9: Referencia | M9: Valor | N9: Referencia
A10: ESTUDOS | H10: =$C$4*J10 -> 27217.957 | I10: 25651 | J10: =I10/$I$4 -> 5.0895043 | K10: 30482.799 | L10: =K10/$I$5 -> 5.4632295 | M10: 40433.9 | N10: =M10/$I$6 -> 8.9879875
A11: PROJETOS | H11: =$C$4*L11 -> 306985.78 | I11: 631568.72 | J11: =I11/$I$4 -> 125.31175 | K11: 320290.19 | L11: =K11/$I$5 -> 57.403481 | M11: =[5]ORÇAMENTO_EXECUTIVO_COMENTADO!$F$17 -> 166779.75 | N11: =M11/$I$6 -> 37.073206
A12: CONSULTORIAS | H12: =$C$4*N12 -> 87643.119 | I12: 117787.8 | J12: =I12/$I$4 -> 23.370687 | K12: 51771.996 | L12: =K12/$I$5 -> 9.2787507 | M12: =[5]ORÇAMENTO_EXECUTIVO_COMENTADO!$F$42 -> 73726.05 | N12: =M12/$I$6 -> 16.388447
A13: ENSAIOS E LAUDOS | H13: =$C$4*L13 -> 35578.087 | I13: 200352.18 | J13: =I13/$I$4 -> 39.752574 | K13: 37120 | L13: =K13/$I$5 -> 6.6527709 | M13: =[5]ORÇAMENTO_EXECUTIVO_COMENTADO!$F$51 -> 23350 | N13: =M13/$I$6 -> 5.1904345
A14: TAXAS
A15: Despesas de Seguros | F15: vb | H15: =J15*$C$4 -> 47632.156 | I15: 44889.94 | J15: =I15/$I$4 -> 8.9067695 | K15: 31285.257 | L15: =K15/$I$5 -> 5.6070486 | M15: 13004.64 | N15: =M15/$I$6 -> 2.8907808
A16: Licenciamentos, Taxas, Impostos | F16: vb | H16: =N16*$C$4 -> 73737.703 | I16: 174592.56 | J16: =I16/$I$4 -> 34.641518 | K16: 67490.003 | L16: =K16/$I$5 -> 12.095785 | M16: =[5]ORÇAMENTO_EXECUTIVO_COMENTADO!$F$56-M15 -> 62028.71 | N16: =M16/$I$6 -> 13.788264
A17: DOCUMENTOS | H17: =L17*C4 -> 22621.734 | I17: 26937.34 | J17: =I17/$I$4 -> 5.3447315 | K17: 23602.134 | L17: =K17/$I$5 -> 4.2300536 | M17: =[5]ORÇAMENTO_EXECUTIVO_COMENTADO!$F$70 -> 8250 | N17: =M17/$I$6 -> 1.8338794
A18: SEGURANÇA DO TRABALHO
A19: Serviço segurança do trabalho terceirizado | F19: mês | H19: 2000 | I19: 2000 | J19: =I19/$I$4 -> 0.39682697 | K19: 875.49 | L19: =K19/$I$5 -> 0.15690825 | M19: 60000 | N19: =M19/$I$6 -> 13.337305
A20: Placas de Sinalização de Obra | F20: vb | H20: 2850 | J20: =I20/$I$4 -> 0 | L20: =K20/$I$5 -> 0 | M20: 1500 | N20: =M20/$I$6 -> 0.33343262
A21: MEIO AMBIENTE | SAÚDE OCUPACIONAL | H21: =J21*C4 -> 40056.055 | I21: 37750 | J21: =I21/$I$4 -> 7.4901091 | K21: 0 | L21: =K21/$I$5 -> 0 | M21: =[5]ORÇAMENTO_EXECUTIVO_COMENTADO!$F$92+[5]ORÇAMENTO_EXECUTIVO_COMENTADO!$F$89 -> 52200 | N21: =M21/$I$6 -> 11.603455
A22: EQUIPE | M22: 1107599 | N22: =M22/$I$6 -> 246.20643
A23: Engenheiro Civil | F23: mês | H23: 8000 | I23: 5000 | K23: 13580.814 | M23: 5000
A24: Mestre Geral | F24: mês | H24: 6000 | M24: 5000
A25: Almoxarife | F25: mês | H25: 5000 | I25: 3000 | K25: 1833.2167 | M25: 2500
A26: Auxiliar de Engenharia | F26: mês | H26: 3000 | I26: 3000 | K26: 1833.2167
A27: Estagiário de Engenharia | F27: mês | H27: 1400 | I27: 700 | K27: 1833.2167 | M27: 2400
A28: Operador de Guincho | F28: mês | H28: 3500 | M28: 2500
A29: Equipe de apoio | F29: mês | H29: 10500 | M29: 380448
A30: Serviço de vigilância | F30: vb | H30: 2500 | I30: 1700 | J30: =I30/$I$4 -> 0.33730293 | L30: =K30/$I$5 -> 0 | M30: 26358.92 | N30: =M30/$I$6 -> 5.8592825
A31: CANTEIRO DE OBRA
A32: Limpeza da camada vegetal | F32: m2 | H32: =3.5*B4 -> 2520 | I32: 36000 | J32: =I32/$I$4 -> 7.1428855 | K32: 33733.3 | L32: =K32/$I$5 -> 6.0457952 | M32: 37440 | N32: =M32/$I$6 -> 8.3224782
A33: Demolições | H33: =N33*C4 -> 41606.856 | I33: 80000 | J33: =I33/$I$4 -> 15.873079 | K33: 24271.74 | L33: =K33/$I$5 -> 4.3500626 | M33: 35000 | N33: =M33/$I$6 -> 7.7800945
A34: Locação da obra | F34: m | J34: =I34/$I$4 -> 0 | L34: =K34/$I$5 -> 0 | N34: =M34/$I$6 -> 0
A35: Instalações Provisórias: Redes de Água Fria, Esgoto e Drenagem | F35: vb | H35: =N35*$C$4 -> 6419.3435 | I35: ='[6]Ger_Tec e Adm'!$M$90 -> 6007.98 | J35: =I35/$I$4 -> 1.1920643 | K35: 9417.8359 | L35: =K35/$I$5 -> 1.6878961 | M35: 5400 | N35: =M35/$I$6 -> 1.2003574
A36: Instalações Provisórias: Redes Elétrica, Comunicação e Dados | F36: vb | H36: =N36*$C$4 -> 5622.8694 | I36: ='[6]Ger_Tec e Adm'!$M$89 -> 7560.02 | J36: =I36/$I$4 -> 1.5000099 | K36: 10635.501 | L36: =K36/$I$5 -> 1.9061302 | M36: 4730 | N36: =M36/$I$6 -> 1.0514242
A37: Locação de banheiro químico | F37: mês | H37: =L37*$C$4 -> 0 | J37: =I37/$I$4 -> 0 | L37: =K37/$I$5 -> 0 | N37: =M37/$I$6 -> 0
A38: Galpão provisório | F38: vb | H38: =N38*$C$4 -> 169041.16 | J38: =I38/$I$4 -> 0 | L38: =K38/$I$5 -> 0 | M38: 142198.69 | N38: =M38/$I$6 -> 31.609121
A39: Despesas de Consumo e manutenção | F39: vb | H39: =N39*$C$4 -> 297219.01 | I39: ='[6]Ger_Tec e Adm'!$N$104 -> 462826.16 | J39: =I39/$I$4 -> 91.830952 | K39: 1156289.7 | L39: =K39/$I$5 -> 207.23411 | M39: 250022.86 | N39: =M39/$I$6 -> 55.577185

Sheet EPCs
A1: Obra | B1: =OBRA!B1 -> Jurerê Blue
A2: Empresa | B2: =OBRA!B2 -> GRUPO EIS
A3: Revisão | B3: =OBRA!B3 -> R00
A4: LEVANTAMENTO QUANTITATIVO
A6: Equipamentos de proteção coletiva
A8: Bandejas de proteção
B10: Descrição | C10: Unidade | D10: Quantidade
B11: Perímetro de projeção embasamneto | C11: m | D11: ='[7]Obra '!$F$23 -> 87.82
B12: Perímetro de projeção torre | C12: m | D12: ='[7]Obra '!$F$24 -> 93.9
B13: Bandeja de proteção primária | C13: m | D13: =D11 -> 87.82
B14: Bandeja de proteção secundária | C14: m | D14: =D12 -> 93.9
A16: Guarda - corpo de desforma
B18: Descrição | C18: Unidade | D18: Quantidade
B19: Perímetro de projeção da torre | C19: m | D19: =D12 -> 93.9
B20: Repetições de pavimentos** | C20: un | D20: 4
B21: Proteção de periferia pós desforma torre | C21: m | D21: =(D19*D20) -> 375.6
A23: Tela fachadeira
B25: Descrição | C25: Unidade | D25: Quantidade
B26: Perimetro da torre | C26: m | D26: =D12 -> 93.9
B27: Altura da torre | C27: m | D27: =SUM('[7]Obra '!$G$23:$G$32) -> 30.76
B28: Tela fachadeira | C28: m2 | D28: =D26*D27 -> 2888.364
A30: Fechamento removível de vãos em madeira
B32: Descrição | C32: Unidade | D32: Quantidade
B33: Área das portas de elevadores | C33: m2 | D33: =0.9*2.4 -> 2.16
B34: Quantidade de elevadores | C34: un | D34: 2
B35: Quantidade de portas de elevadores | C35: un | D35: =D34*11 -> 22
B36: Fechamento removível de vãos em madeira | C36: m2 | D36: =D33*D35 -> 47.52
A38: Tapume
B40: Descrição | C40: Unidade | D40: Quantidade
B41: Perímetro de encontro com pavimentação | C41: m | D41: =24*2+30/2 -> 63
B42: Altura do tapume | C42: m | D42: 2.4
B43: Cobertura para proteção de pedestres | C43: m2 | D43: =D42*D41 -> 151.2

Sheet CUSTOS_INDIRETOS
A1: ORÇAMENTO PARAMÉTRICO - CUSTOS INDIRETOS
A7: Cliente | B7: =OBRA!B2 -> GRUPO EIS
A8: Obra | B8: =OBRA!B1 -> Jurerê Blue
A9: Data | B9: 45931
A10: Versão | B10: =OBRA!B3 -> R00
A12: GERENCIAMENTO TÉCNICO
A13: Código | B13: Descrição | C13: Un. | D13: Quantidade orçada | E13: Preço unitário | F13: Preço total
A14: 01 | B14: GERENCIAMENTO TÉCNICO | F14: =F15+F20 -> 1542090.5
A15: 01.001 | B15: ESTUDOS, PROJETOS E CONSULTORIAS | F15: =SUM(F16:F19) -> 461924.94 | G15: =F15/$F$67 -> 0.15217592
A16: 01.001.001 | B16: Estudos | F16: =BASES!H10 -> 27217.957 | G16: =F16/$F$67 -> 0.0089666461
A17: 01.001.002 | B17: Projetos | F17: =BASES!H11+4500 -> 311485.78 | G17: =F17/$F$67 -> 0.10261545
A18: 01.001.003 | B18: Consultorias | F18: =BASES!H12 -> 87643.119 | G18: =F18/$F$67 -> 0.028873028
A19: 01.001.004 | B19: Ensaios e Laudos | F19: =BASES!H13 -> 35578.087 | G19: =F19/$F$67 -> 0.011720796
A20: 01.002 | B20: TAXAS E DOCUMENTOS | F20: =SUM(F21:F23) -> 1080165.6 | G20: =F20/$F$67 -> 0.35584826
A21: 01.002.001 | B21: Seguros | F21: =BASES!H15 -> 47632.156 | G21: =F21/$F$67 -> 0.015691872
A22: 01.002.002 | B22: Licenciamentos, Taxas, Impostos e Outorga | F22: =BASES!H16+H22 -> 1009911.7 | G22: =F22/$F$67 -> 0.33270392 | H22: 936174 | I22: *Outorga | J22: ARV VERIFICAR OUTORGA
A23: 01.002.003 | B23: Documentos | F23: =BASES!H17 -> 22621.734 | G23: =F23/$F$67 -> 0.0074524729
A24: 02 | B24: GERENCIAMENTO ADMINISTRATIVO | F24: =F25+F39+F53 -> 1493376.3 | G24: =F24/$F$67 -> 0.49197582
A25: 02.001 | B25: SEGURANÇA, MEIO AMBIENTE E SAÚDE | F25: =F26+F28+F38 -> 351212.51 | G25: =F25/$F$67 -> 0.11570296
A26: 02.001.001 | B26: Segurança do Trabalho | F26: =F27 -> 105600 | G26: =F26/$F$67 -> 0.034788718
A27: 02.001.001.001 | B27: Serviço de segurança do trabalho terceirizado | C27: mes | D27: =OBRA!D12 -> 48 | E27: 2200 | F27: =E27*D27 -> 105600 | G27: =F27/$F$67 -> 0.034788718
A28: 02.001.002 | B28: Equipamentos de proteção | F28: =SUM(F29:F37) -> 205556.45 | G28: =F28/$F$67 -> 0.067718235
A29: 02.001.002.001 | B29: Bandeja de proteção primária | C29: m | D29: =EPCs!D13 -> 87.82 | E29: 294.33 | F29: =E29*D29 -> 25848.061 | G29: =F29/$F$67 -> 0.0085153494
A30: 02.001.002.002 | B30: Bandeja de proteção secundária | C30: m | D30: =EPCs!D14 -> 93.9 | E30: 210.06 | F30: =E30*D30 -> 19724.634 | G30: =F30/$F$67 -> 0.0064980562
A31: 02.001.002.003 | B31: Guarda corpo em laje pós - desforma | C31: m | D31: =EPCs!D21 -> 375.6 | E31: =39.19+7.55+0.63+1.63 -> 49 | F31: =E31*D31 -> 18404.4 | G31: =F31/$F$67 -> 0.0060631201
A32: 02.001.002.003 | B32: Gurada-corpo de vãos com régua de pinus 2,5x15cm | C32: m | D32: =[8]ESQUADRIAS!$D$13 -> 109.345 | E32: 15.38 | F32: =E32*D32 -> 1681.7261 | G32: =F32/$F$67 -> 0.00055402553
A33: 02.001.002.004 | B33: Fechamento removível de vãos de porta de elevador em madeira | C33: m2 | D33: =EPCs!D36 -> 47.52 | E33: 19.89 | F33: =E33*D33 -> 945.1728 | G33: =F33/$F$67 -> 0.00031137642
A34: 02.001.002.005 | B34: Varal de segurança com cabo de aço | C34: m | D34: =D31 -> 375.6 | E34: 195 | F34: =E34*D34 -> 73242 | G34: =F34/$F$67 -> 0.024128743
A35: 02.001.002.006 | B35: Tela fachadeira reforçada com impressão digital | C35: m2 | D35: =EPCs!D28 -> 2888.364 | E35: 15 | F35: =E35*D35 -> 43325.46 | G35: =F35/$F$67 -> 0.01427308
A36: 02.001.002.007 | B36: Sinalização com placa indicativa fixada na estrutura | C36: vb | D36: 1 | E36: =BASES!H20*1.1 -> 3135 | F36: =E36*D36 -> 3135 | G36: =F36/$F$67 -> 0.0010327901
A37: 02.001.002.008 | B37: Equipamentos de proteção individual | C37: vb | D37: 1 | E37: =CANTEIRO!D18*1.1 -> 19250 | F37: =E37*D37 -> 19250 | G37: =F37/$F$67 -> 0.0063416934
A38: 02.001.003 | B38: Meio Ambiente | F38: =BASES!H21 -> 40056.055 | G38: =F38/$F$67 -> 0.013196011
A39: 02.002 | B39: ADMINISTRAÇÃO E CANTEIRO DE OBRA | F39: =F40+F42+F44+F52 -> 669157.17 | G39: =F39/$F$67 -> 0.22044621
A40: 02.002.001 | B40: Equipe de Gestão e Apoio | F40: =SUM(F41:F41) -> 120000 | G40: =F40/$F$67 -> 0.039532634 | H40: =F40/OBRA!$D$10 -> 22.438882
A41: 02.002.001.008 | B41: Serviço de vigilância | C41: mes | D41: =OBRA!$D$12 -> 48 | E41: =BASES!H30 -> 2500 | F41: =E41*D41 -> 120000 | G41: =F41/$F$67 -> 0.039532634
A42: 02.002.002 | B42: Operação Inicial do Canteiro | F42: =SUM(F43) -> 9000 | G42: =F42/$F$67 -> 0.0029649476
A43: 02.002.002.001 | B43: Limpeza mecanizada de camada vegetal | C43: m2 | D43: =OBRA!D9 -> 720 | E43: 12.5 | F43: =E43*D43 -> 9000 | G43: =F43/$F$67 -> 0.0029649476
A44: 02.002.003 | B44: Instalações Provisórias | F44: =SUM(F45:F51) -> 242938.16 | G44: =F44/$F$67 -> 0.080033213
A45: 02.002.003.001 | B45: Locação de banheiro químico | C45: mes | D45: 6 | E45: 2850 | F45: =E45*D45 -> 17100 | G45: =F45/$F$67 -> 0.0056334004
A46: 02.002.003.002 | B46: Instalações de canteiro | C46: vb | D46: 1 | E46: =BASES!H38 -> 169041.16 | F46: =E46*D46 -> 169041.16 | G46: =F46/$F$67 -> 0.055688685
...
