Workbook

Sheet PRAZO
B2: ORÇAMENTO PARAMÉTRICO | ESTIMATIVA DE PRAZO
B4: GRUPO EIS - JURERE BLUE
B7: SERVIÇOS | C7: M1 | D7: M2 | E7: M3 | F7: M4 | G7: M5 | H7: M6 | I7: M7 | J7: M8 | K7: M9 | L7: M10 | M7: M11 | N7: M12 | O7: M13 | P7: M14 | Q7: M15 | R7: M16 | S7: M17 | T7: M18 | U7: M19 | V7: M20 | W7: M21 | X7: M22 | Y7: M23 | Z7: M24 | AA7: M25 | AB7: M26 | AC7: M27 | AD7: M28 | AE7: M29 | AF7: M30 | AG7: M31 | AH7: M32 | AI7: M33 | AJ7: M34 | AK7: M35 | AL7: M36 | AM7: M37 | AN7: M38 | AO7: M39 | AP7: M40 | AQ7: M41 | AR7: M42 | AS7: M43 | AT7: M44 | AU7: M45 | AV7: M46 | AW7: M47 | AX7: M48
B8: MOVIMENTAÇÃO DE TERRA | C8: 1 | AY8: =COUNTA(C8:AX8) -> 1
B9: INFRAESTRUTURA | D9: 1 | E9: 2 | F9: 3 | G9: 4 | H9: 5 | I9: 6 | J9: 7 | K9: 8 | AY9: =COUNTA(C9:AX9) -> 8
B10: SUPRAESTRUTURA | L10: 1 | M10: 2 | N10: 3 | O10: 4 | P10: 5 | Q10: 6 | R10: 7 | S10: 8 | T10: 9 | U10: 10 | V10: 11 | W10: 12 | X10: 13 | Y10: 14 | Z10: 15 | AA10: 16 | AY10: =COUNTA(C10:AX10) -> 16
B11: ALVENARIA | O11: 1 | P11: 2 | Q11: 3 | R11: 4 | S11: 5 | T11: 6 | U11: 7 | V11: 8 | W11: 9 | X11: 10 | Y11: 11 | Z11: 12 | AA11: 13 | AB11: 14 | AC11: 15 | AD11: 16 | AY11: =COUNTA(C11:AX11) -> 16
B12: INSTALAÇÕES ELÉTRICAS, HIDRÁULICAS, GLP E PREVENTIVAS | O12: 1 | P12: 2 | Q12: 3 | R12: 4 | S12: 5 | T12: 6 | U12: 7 | V12: 8 | W12: 9 | X12: 10 | Y12: 11 | Z12: 12 | AA12: 13 | AB12: 14 | AC12: 15 | AD12: 16 | AE12: 17 | AF12: 18 | AG12: 19 | AH12: 20 | AI12: 21 | AJ12: 22 | AK12: 23 | AL12: 24 | AY12: =COUNTA(C12:AX12) -> 24
B13: EQUIPAMENTOS E SISTEMAS ESPECIAIS | W13: 1 | X13: 2 | Y13: 3 | Z13: 4 | AA13: 5 | AB13: 6 | AC13: 7 | AD13: 8 | AE13: 9 | AF13: 10 | AG13: 11 | AH13: 12 | AI13: 13 | AJ13: 14 | AK13: 15 | AL13: 16 | AM13: 17 | AN13: 18 | AO13: 19 | AP13: 20 | AQ13: 21 | AR13: 22 | AY13: =COUNTA(C13:AX13) -> 22
B14: IMPERMEABILIZAÇÃO | Y14: 1 | Z14: 2 | AA14: 3 | AB14: 4 | AC14: 5 | AD14: 6 | AE14: 7 | AF14: 8 | AG14: 9 | AH14: 10 | AI14: 11 | AJ14: 12 | AY14: =COUNTA(C14:AX14) -> 12
B15: REVESTIMENTOS INTERNOS EM PISO E PAREDE | S15: 1 | T15: 2 | U15: 3 | V15: 4 | W15: 5 | X15: 6 | Y15: 7 | Z15: 8 | AA15: 9 | AB15: 10 | AC15: 11 | AD15: 12 | AE15: 13 | AF15: 14 | AG15: 15 | AY15: =COUNTA(C15:AX15) -> 15
B16: REVESTIMENTOS E ACABAMENTOS INTERNOS EM TETO | AC16: 1 | AD16: 2 | AE16: 3 | AF16: 4 | AG16: 5 | AH16: 6 | AI16: 7 | AJ16: 8 | AK16: 9 | AL16: 10 | AM16: 11 | AN16: 12 | AY16: =COUNTA(C16:AX16) -> 12
B17: ACABAMENTOS EM PISO E PAREDE | AE17: 1 | AF17: 2 | AG17: 3 | AH17: 4 | AI17: 5 | AJ17: 6 | AK17: 7 | AL17: 8 | AM17: 9 | AN17: 10 | AO17: 11 | AP17: 12 | AQ17: 13 | AR17: 14 | AS17: 15 | AY17: =COUNTA(C17:AX17) -> 15
B18: PINTURA INTERNA | AI18: 1 | AJ18: 2 | AK18: 3 | AL18: 4 | AM18: 5 | AN18: 6 | AO18: 7 | AP18: 8 | AQ18: 9 | AR18: 10 | AS18: 11 | AT18: 12 | AU18: 13 | AV18: 14 | AY18: =COUNTA(C18:AX18) -> 14
B19: ESQUADRIAS, VIDROS E FERRAGENS | Z19: 1 | AA19: 2 | AB19: 3 | AC19: 4 | AD19: 5 | AE19: 6 | AF19: 7 | AG19: 8 | AH19: 9 | AI19: 10 | AJ19: 11 | AK19: 12 | AL19: 13 | AM19: 14 | AY19: =COUNTA(C19:AX19) -> 14
B20: REVESTIMENTOS E ACABAMENTOS DE FACHADA | AE20: 1 | AF20: 2 | AG20: 3 | AH20: 4 | AI20: 5 | AJ20: 6 | AK20: 7 | AL20: 8 | AM20: 9 | AN20: 10 | AO20: 11 | AP20: 12 | AY20: =COUNTA(C20:AX20) -> 12
B21: SERVIÇOS COMPLEMENTARES | AS21: 1 | AT21: 2 | AU21: 3 | AV21: 4 | AW21: 5 | AX21: 6 | AY21: =COUNTA(C21:AX21) -> 6

Sheet DISTRIBUIÇÃO CUSTO
B2: ORÇAMENTO PARAMÉTRICO | DISTRIBUIÇÃO MENSAL DE CUSTOS
B4: GRUPO EIS - JURERE BLUE
B7: ETAPA | C7: VALOR ORÇADO | D7: % | E7: VALOR / m² | F7: % Distribuído | H7: M1 | J7: M2 | L7: M3 | N7: M4 | P7: M5 | R7: M6 | T7: M7 | V7: M8 | X7: M9 | Z7: M10 | AB7: M11 | AD7: M12 | AF7: M13 | AH7: M14 | AJ7: M15 | AL7: M16 | AN7: M17 | AP7: M18 | AR7: M19 | AT7: M20 | AV7: M21 | AX7: M22 | AZ7: M23 | BB7: M24 | BD7: M25 | BF7: M26 | BH7: M27 | BJ7: M28 | BL7: M29 | BN7: M30 | BP7: M31 | BR7: M32 | BT7: M33 | BV7: M34 | BX7: M35 | BZ7: M36 | CB7: M37 | CD7: M38 | CF7: M39 | CH7: M40 | CJ7: M41 | CL7: M42 | CN7: M43 | CP7: M44 | CR7: M45 | CT7: M46 | CV7: M47 | CX7: M48
H8: % | I8: R$ | J8: % | K8: R$ | L8: % | M8: R$ | N8: % | O8: R$ | P8: % | Q8: R$ | R8: % | S8: R$ | T8: % | U8: R$ | V8: % | W8: R$ | X8: % | Y8: R$ | Z8: % | AA8: R$ | AB8: % | AC8: R$ | AD8: % | AE8: R$ | AF8: % | AG8: R$ | AH8: % | AI8: R$ | AJ8: % | AK8: R$ | AL8: % | AM8: R$ | AN8: % | AO8: R$ | AP8: % | AQ8: R$ | AR8: % | AS8: R$ | AT8: % | AU8: R$ | AV8: % | AW8: R$ | AX8: % | AY8: R$ | AZ8: % | BA8: R$ | BB8: % | BC8: R$ | BD8: % | BE8: R$ | BF8: % | BG8: R$ | BH8: % | BI8: R$ | BJ8: % | BK8: R$ | BL8: % | BM8: R$ | BN8: % | BO8: R$ | BP8: % | BQ8: R$ | BR8: % | BS8: R$ | BT8: % | BU8: R$ | BV8: % | BW8: R$ | BX8: % | BY8: R$ | BZ8: % | CA8: R$ | CB8: % | CC8: R$ | CD8: % | CE8: R$ | CF8: % | CG8: R$ | CH8: % | CI8: R$ | CJ8: % | CK8: R$ | CL8: % | CM8: R$ | CN8: % | CO8: R$ | CP8: % | CQ8: R$ | CR8: % | CS8: R$ | CT8: % | CU8: R$ | CV8: % | CW8: R$ | CX8: % | CY8: R$
B9: GERENCIAMENTO TÉCNICO E ADMINISTRATIVO | C9: =SUM([1]RESUMO!$B$2:$C$2) -> 3035466.8 | D9: =C9/$C$28 -> 0.08513898 | E9: =C9/'DISTRIBUIÇÃO CUSTO'!C$32 -> 138.35744 | F9: =SUM(H9,J9,L9,N9,P9,R9,T9,V9,X9,Z9,AB9,AD9,AF9,AH9,AJ9,AL9,,AN9,AP9,AR9,AT9,AV9,AX9,AZ9,BB9,BD9,BF9,BH9,BJ9,BL9,BN9,BP9,BR9,BT9,BV9,BX9,BZ9,CB9,CD9,CF9,CH9,CJ9,CL9,CN9,CP9,CR9,CT9,CV9,CX9,) -> 1 | H9: 0.12424465 | I9: =$C9*H9 -> 377140.52 | J9: 0.11533176 | K9: =$C9*J9 -> 350085.73 | L9: 0.11533176 | M9: =$C9*L9 -> 350085.73 | N9: 0.089525588 | O9: =$C9*N9 -> 271751.95 | P9: 0.089525588 | Q9: =$C9*P9 -> 271751.95 | R9: 0.089525588 | S9: =$C9*R9 -> 271751.95 | T9: 0.0089646444 | U9: =$C9*T9 -> 27211.881 | V9: 0.0089646444 | W9: =$C9*V9 -> 27211.881 | X9: 0.0089646444 | Y9: =$C9*X9 -> 27211.881 | Z9: 0.0089646444 | AA9: =$C9*Z9 -> 27211.881 | AB9: 0.0089646444 | AC9: =$C9*AB9 -> 27211.881 | AD9: 0.0089646444 | AE9: =$C9*AD9 -> 27211.881 | AF9: 0.0089646444 | AG9: =$C9*AF9 -> 27211.881 | AH9: 0.0089646444 | AI9: =$C9*AH9 -> 27211.881 | AJ9: 0.0089646444 | AK9: =$C9*AJ9 -> 27211.881 | AL9: 0.0089646444 | AM9: =$C9*AL9 -> 27211.881 | AN9: 0.0089646444 | AO9: =$C9*AN9 -> 27211.881 | AP9: 0.0089646444 | AQ9: =$C9*AP9 -> 27211.881 | AR9: 0.0089646444 | AS9: =$C9*AR9 -> 27211.881 | AT9: 0.0089646444 | AU9: =$C9*AT9 -> 27211.881 | AV9: 0.0089646444 | AW9: =$C9*AV9 -> 27211.881 | AX9: 0.0089646444 | AY9: =$C9*AX9 -> 27211.881 | AZ9: 0.0089646444 | BA9: =$C9*AZ9 -> 27211.881 | BB9: 0.0089646444 | BC9: =$C9*BB9 -> 27211.881 | BD9: 0.0089646444 | BE9: =$C9*BD9 -> 27211.881 | BF9: 0.0089646444 | BG9: =$C9*BF9 -> 27211.881 | BH9: 0.0089646444 | BI9: =$C9*BH9 -> 27211.881 | BJ9: 0.0089646444 | BK9: =$C9*BJ9 -> 27211.881 | BL9: 0.0089646444 | BM9: =$C9*BL9 -> 27211.881 | BN9: 0.0089646444 | BO9: =$C9*BN9 -> 27211.881 | BP9: 0.0089646444 | BQ9: =$C9*BP9 -> 27211.881 | BR9: 0.0089646444 | BS9: =$C9*BR9 -> 27211.881 | BT9: 0.0089646444 | BU9: =$C9*BT9 -> 27211.881 | BV9: 0.0089646444 | BW9: =$C9*BV9 -> 27211.881 | BX9: 0.0089646444 | BY9: =$C9*BX9 -> 27211.881 | BZ9: 0.0089646444 | CA9: =$C9*BZ9 -> 27211.881 | CB9: 0.0089646444 | CC9: =$C9*CB9 -> 27211.881 | CD9: 0.0089646444 | CE9: =$C9*CD9 -> 27211.881 | CF9: 0.0089646444 | CG9: =$C9*CF9 -> 27211.881 | CH9: 0.0089646444 | CI9: =$C9*CH9 -> 27211.881 | CJ9: 0.0089646444 | CK9: =$C9*CJ9 -> 27211.881 | CL9: 0.0089646444 | CM9: =$C9*CL9 -> 27211.881 | CN9: 0.0089646444 | CO9: =$C9*CN9 -> 27211.881 | CP9: 0.0089646444 | CQ9: =$C9*CP9 -> 27211.881 | CR9: 0.0089646444 | CS9: =$C9*CR9 -> 27211.881 | CT9: 0.0089646444 | CU9: =$C9*CT9 -> 27211.881 | CV9: 0.0089646444 | CW9: =$C9*CV9 -> 27211.881 | CX9: 0.0089646444 | CY9: =$C9*CX9 -> 27211.881
B10: MOVIMENTAÇÃO DE TERRA | C10: =SUM([1]RESUMO!$B$3:$C$3) -> 245046.93 | D10: =C10/$C$28 -> 0.0068730929 | E10: =C10/'DISTRIBUIÇÃO CUSTO'!C$32 -> 11.169309 | F10: =SUM(H10,J10,L10,N10,P10,R10,T10,V10,X10,Z10,AB10,AD10,AF10,AH10,AJ10,AL10,,AN10,AP10,AR10,AT10,AV10,AX10,AZ10,BB10,BD10,BF10,BH10,BJ10,BL10,BN10,BP10,BR10,BT10,BV10,BX10,BZ10,CB10,CD10,CF10,CH10,CJ10,CL10,CN10,CP10,CR10,CT10,CV10,CX10,) -> 1 | H10: =IF(PRAZO!C8>0,1/PRAZO!$AY8,0) -> 1 | I10: =$C10*H10 -> 245046.93 | J10: =IF(PRAZO!D8>0,1/PRAZO!$AY8,0) -> 0 | K10: =$C10*J10 -> 0 | L10: =IF(PRAZO!E8>0,1/PRAZO!$AY8,0) -> 0 | M10: =$C10*L10 -> 0 | N10: =IF(PRAZO!F8>0,1/PRAZO!$AY8,0) -> 0 | O10: =$C10*N10 -> 0 | P10: =IF(PRAZO!G8>0,1/PRAZO!$AY8,0) -> 0 | Q10: =$C10*P10 -> 0 | R10: =IF(PRAZO!H8>0,1/PRAZO!$AY8,0) -> 0 | S10: =$C10*R10 -> 0 | T10: =IF(PRAZO!I8>0,1/PRAZO!$AY8,0) -> 0 | U10: =$C10*T10 -> 0 | V10: =IF(PRAZO!J8>0,1/PRAZO!$AY8,0) -> 0 | W10: =$C10*V10 -> 0 | X10: =IF(PRAZO!K8>0,1/PRAZO!$AY8,0) -> 0 | Y10: =$C10*X10 -> 0 | Z10: =IF(PRAZO!L8>0,1/PRAZO!$AY8,0) -> 0 | AA10: =$C10*Z10 -> 0 | AB10: =IF(PRAZO!M8>0,1/PRAZO!$AY8,0) -> 0 | AC10: =$C10*AB10 -> 0 | AD10: =IF(PRAZO!N8>0,1/PRAZO!$AY8,0) -> 0 | AE10: =$C10*AD10 -> 0 | AF10: =IF(PRAZO!O8>0,1/PRAZO!$AY8,0) -> 0 | AG10: =$C10*AF10 -> 0 | AH10: =IF(PRAZO!P8>0,1/PRAZO!$AY8,0) -> 0 | AI10: =$C10*AH10 -> 0 | AJ10: =IF(PRAZO!Q8>0,1/PRAZO!$AY8,0) -> 0 | AK10: =$C10*AJ10 -> 0 | AL10: =IF(PRAZO!R8>0,1/PRAZO!$AY8,0) -> 0 | AM10: =$C10*AL10 -> 0 | AN10: =IF(PRAZO!S8>0,1/PRAZO!$AY8,0) -> 0 | AO10: =$C10*AN10 -> 0 | AP10: =IF(PRAZO!T8>0,1/PRAZO!$AY8,0) -> 0 | AQ10: =$C10*AP10 -> 0 | AR10: =IF(PRAZO!U8>0,1/PRAZO!$AY8,0) -> 0 | AS10: =$C10*AR10 -> 0 | AT10: =IF(PRAZO!V8>0,1/PRAZO!$AY8,0) -> 0 | AU10: =$C10*AT10 -> 0 | AV10: =IF(PRAZO!W8>0,1/PRAZO!$AY8,0) -> 0 | AW10: =$C10*AV10 -> 0 | AX10: =IF(PRAZO!X8>0,1/PRAZO!$AY8,0) -> 0 | AY10: =$C10*AX10 -> 0 | AZ10: =IF(PRAZO!Y8>0,1/PRAZO!$AY8,0) -> 0 | BA10: =$C10*AZ10 -> 0 | BB10: =IF(PRAZO!Z8>0,1/PRAZO!$AY8,0) -> 0 | BC10: =$C10*BB10 -> 0 | BD10: =IF(PRAZO!AA8>0,1/PRAZO!$AY8,0) -> 0 | BE10: =$C10*BD10 -> 0 | BF10: =IF(PRAZO!AB8>0,1/PRAZO!$AY8,0) -> 0 | BG10: =$C10*BF10 -> 0 | BH10: =IF(PRAZO!AC8>0,1/PRAZO!$AY8,0) -> 0 | BI10: =$C10*BH10 -> 0 | BJ10: =IF(PRAZO!AD8>0,1/PRAZO!$AY8,0) -> 0 | BK10: =$C10*BJ10 -> 0 | BL10: =IF(PRAZO!AE8>0,1/PRAZO!$AY8,0) -> 0 | BM10: =$C10*BL10 -> 0 | BN10: =IF(PRAZO!AF8>0,1/PRAZO!$AY8,0) -> 0 | BO10: =$C10*BN10 -> 0 | BP10: =IF(PRAZO!AG8>0,1/PRAZO!$AY8,0) -> 0 | BQ10: =$C10*BP10 -> 0 | BR10: =IF(PRAZO!AH8>0,1/PRAZO!$AY8,0) -> 0 | BS10: =$C10*BR10 -> 0 | BT10: =IF(PRAZO!AI8>0,1/PRAZO!$AY8,0) -> 0 | BU10: =$C10*BT10 -> 0 | BV10: =IF(PRAZO!AJ8>0,1/PRAZO!$AY8,0) -> 0 | BW10: =$C10*BV10 -> 0 | BX10: =IF(PRAZO!AK8>0,1/PRAZO!$AY8,0) -> 0 | BY10: =$C10*BX10 -> 0 | BZ10: =IF(PRAZO!AL8>0,1/PRAZO!$AY8,0) -> 0 | CA10: =$C10*BZ10 -> 0 | CB10: =IF(PRAZO!AM8>0,1/PRAZO!$AY8,0) -> 0 | CC10: =$C10*CB10 -> 0 | CD10: =IF(PRAZO!AN8>0,1/PRAZO!$AY8,0) -> 0 | CE10: =$C10*CD10 -> 0 | CF10: =IF(PRAZO!AO8>0,1/PRAZO!$AY8,0) -> 0 | CG10: =$C10*CF10 -> 0 | CH10: =IF(PRAZO!AP8>0,1/PRAZO!$AY8,0) -> 0 | CI10: =$C10*CH10 -> 0 | CJ10: =IF(PRAZO!AQ8>0,1/PRAZO!$AY8,0) -> 0 | CK10: =$C10*CJ10 -> 0 | CL10: =IF(PRAZO!AR8>0,1/PRAZO!$AY8,0) -> 0 | CM10: =$C10*CL10 -> 0 | CN10: =IF(PRAZO!AS8>0,1/PRAZO!$AY8,0) -> 0 | CO10: =$C10*CN10 -> 0 | CP10: =IF(PRAZO!AT8>0,1/PRAZO!$AY8,0) -> 0 | CQ10: =$C10*CP10 -> 0 | CR10: =IF(PRAZO!AU8>0,1/PRAZO!$AY8,0) -> 0 | CS10: =$C10*CR10 -> 0 | CT10: =IF(PRAZO!AV8>0,1/PRAZO!$AY8,0) -> 0 | CU10: =$C10*CT10 -> 0 | CV10: =IF(PRAZO!AW8>0,1/PRAZO!$AY8,0) -> 0 | CW10: =$C10*CV10 -> 0 | CX10: =IF(PRAZO!AX8>0,1/PRAZO!$AY8,0) -> 0 | CY10: =$C10*CX10 -> 0
B11: INFRAESTRUTURA | C11: =SUM([1]RESUMO!$B$4:$C$5) -> 3074660.6 | D11: =C11/$C$28 -> 0.08623829 | E11: =C11/'DISTRIBUIÇÃO CUSTO'!C$32 -> 140.14391 | F11: =SUM(H11,J11,L11,N11,P11,R11,T11,V11,X11,Z11,AB11,AD11,AF11,AH11,AJ11,AL11,,AN11,AP11,AR11,AT11,AV11,AX11,AZ11,BB11,BD11,BF11,BH11,BJ11,BL11,BN11,BP11,BR11,BT11,BV11,BX11,BZ11,CB11,CD11,CF11,CH11,CJ11,CL11,CN11,CP11,CR11,CT11,CV11,CX11,) -> 1 | H11: =IF(PRAZO!C9>0,1/PRAZO!$AY9,0) -> 0 | I11: =$C11*H11 -> 0 | J11: =IF(PRAZO!D9>0,1/PRAZO!$AY9,0) -> 0.125 | K11: =$C11*J11 -> 384332.57 | L11: =IF(PRAZO!E9>0,1/PRAZO!$AY9,0) -> 0.125 | M11: =$C11*L11 -> 384332.57 | N11: =IF(PRAZO!F9>0,1/PRAZO!$AY9,0) -> 0.125 | O11: =$C11*N11 -> 384332.57 | P11: =IF(PRAZO!G9>0,1/PRAZO!$AY9,0) -> 0.125 | Q11: =$C11*P11 -> 384332.57 | R11: =IF(PRAZO!H9>0,1/PRAZO!$AY9,0) -> 0.125 | S11: =$C11*R11 -> 384332.57 | T11: =IF(PRAZO!I9>0,1/PRAZO!$AY9,0) -> 0.125 | U11: =$C11*T11 -> 384332.57 | V11: =IF(PRAZO!J9>0,1/PRAZO!$AY9,0) -> 0.125 | W11: =$C11*V11 -> 384332.57 | X11: =IF(PRAZO!K9>0,1/PRAZO!$AY9,0) -> 0.125 | Y11: =$C11*X11 -> 384332.57 | Z11: =IF(PRAZO!L9>0,1/PRAZO!$AY9,0) -> 0 | AA11: =$C11*Z11 -> 0 | AB11: =IF(PRAZO!M9>0,1/PRAZO!$AY9,0) -> 0 | AC11: =$C11*AB11 -> 0 | AD11: =IF(PRAZO!N9>0,1/PRAZO!$AY9,0) -> 0 | AE11: =$C11*AD11 -> 0 | AF11: =IF(PRAZO!O9>0,1/PRAZO!$AY9,0) -> 0 | AG11: =$C11*AF11 -> 0 | AH11: =IF(PRAZO!P9>0,1/PRAZO!$AY9,0) -> 0 | AI11: =$C11*AH11 -> 0 | AJ11: =IF(PRAZO!Q9>0,1/PRAZO!$AY9,0) -> 0 | AK11: =$C11*AJ11 -> 0 | AL11: =IF(PRAZO!R9>0,1/PRAZO!$AY9,0) -> 0 | AM11: =$C11*AL11 -> 0 | AN11: =IF(PRAZO!S9>0,1/PRAZO!$AY9,0) -> 0 | AO11: =$C11*AN11 -> 0 | AP11: =IF(PRAZO!T9>0,1/PRAZO!$AY9,0) -> 0 | AQ11: =$C11*AP11 -> 0 | AR11: =IF(PRAZO!U9>0,1/PRAZO!$AY9,0) -> 0 | AS11: =$C11*AR11 -> 0 | AT11: =IF(PRAZO!V9>0,1/PRAZO!$AY9,0) -> 0 | AU11: =$C11*AT11 -> 0 | AV11: =IF(PRAZO!W9>0,1/PRAZO!$AY9,0) -> 0 | AW11: =$C11*AV11 -> 0 | AX11: =IF(PRAZO!X9>0,1/PRAZO!$AY9,0) -> 0 | AY11: =$C11*AX11 -> 0 | AZ11: =IF(PRAZO!Y9>0,1/PRAZO!$AY9,0) -> 0 | BA11: =$C11*AZ11 -> 0 | BB11: =IF(PRAZO!Z9>0,1/PRAZO!$AY9,0) -> 0 | BC11: =$C11*BB11 -> 0 | BD11: =IF(PRAZO!AA9>0,1/PRAZO!$AY9,0) -> 0 | BE11: =$C11*BD11 -> 0 | BF11: =IF(PRAZO!AB9>0,1/PRAZO!$AY9,0) -> 0 | BG11: =$C11*BF11 -> 0 | BH11: =IF(PRAZO!AC9>0,1/PRAZO!$AY9,0) -> 0 | BI11: =$C11*BH11 -> 0 | BJ11: =IF(PRAZO!AD9>0,1/PRAZO!$AY9,0) -> 0 | BK11: =$C11*BJ11 -> 0 | BL11: =IF(PRAZO!AE9>0,1/PRAZO!$AY9,0) -> 0 | BM11: =$C11*BL11 -> 0 | BN11: =IF(PRAZO!AF9>0,1/PRAZO!$AY9,0) -> 0 | BO11: =$C11*BN11 -> 0 | BP11: =IF(PRAZO!AG9>0,1/PRAZO!$AY9,0) -> 0 | BQ11: =$C11*BP11 -> 0 | BR11: =IF(PRAZO!AH9>0,1/PRAZO!$AY9,0) -> 0 | BS11: =$C11*BR11 -> 0 | BT11: =IF(PRAZO!AI9>0,1/PRAZO!$AY9,0) -> 0 | BU11: =$C11*BT11 -> 0 | BV11: =IF(PRAZO!AJ9>0,1/PRAZO!$AY9,0) -> 0 | BW11: =$C11*BV11 -> 0 | BX11: =IF(PRAZO!AK9>0,1/PRAZO!$AY9,0) -> 0 | BY11: =$C11*BX11 -> 0 | BZ11: =IF(PRAZO!AL9>0,1/PRAZO!$AY9,0) -> 0 | CA11: =$C11*BZ11 -> 0 | CB11: =IF(PRAZO!AM9>0,1/PRAZO!$AY9,0) -> 0 | CC11: =$C11*CB11 -> 0 | CD11: =IF(PRAZO!AN9>0,1/PRAZO!$AY9,0) -> 0 | CE11: =$C11*CD11 -> 0 | CF11: =IF(PRAZO!AO9>0,1/PRAZO!$AY9,0) -> 0 | CG11: =$C11*CF11 -> 0 | CH11: =IF(PRAZO!AP9>0,1/PRAZO!$AY9,0) -> 0 | CI11: =$C11*CH11 -> 0 | CJ11: =IF(PRAZO!AQ9>0,1/PRAZO!$AY9,0) -> 0 | CK11: =$C11*CJ11 -> 0 | CL11: =IF(PRAZO!AR9>0,1/PRAZO!$AY9,0) -> 0 | CM11: =$C11*CL11 -> 0 | CN11: =IF(PRAZO!AS9>0,1/PRAZO!$AY9,0) -> 0 | CO11: =$C11*CN11 -> 0 | CP11: =IF(PRAZO!AT9>0,1/PRAZO!$AY9,0) -> 0 | CQ11: =$C11*CP11 -> 0 | CR11: =IF(PRAZO!AU9>0,1/PRAZO!$AY9,0) -> 0 | CS11: =$C11*CR11 -> 0 | CT11: =IF(PRAZO!AV9>0,1/PRAZO!$AY9,0) -> 0 | CU11: =$C11*CT11 -> 0 | CV11: =IF(PRAZO!AW9>0,1/PRAZO!$AY9,0) -> 0 | CW11: =$C11*CV11 -> 0 | CX11: =IF(PRAZO!AX9>0,1/PRAZO!$AY9,0) -> 0 | CY11: =$C11*CX11 -> 0
B12: SUPRAESTRUTURA | C12: =SUM([1]RESUMO!$B$6:$C$6) -> 4269342.1 | D12: =C12/$C$28 -> 0.1197468 | E12: =C12/'DISTRIBUIÇÃO CUSTO'!C$32 -> 194.59783 | F12: =SUM(H12,J12,L12,N12,P12,R12,T12,V12,X12,Z12,AB12,AD12,AF12,AH12,AJ12,AL12,,AN12,AP12,AR12,AT12,AV12,AX12,AZ12,BB12,BD12,BF12,BH12,BJ12,BL12,BN12,BP12,BR12,BT12,BV12,BX12,BZ12,CB12,CD12,CF12,CH12,CJ12,CL12,CN12,CP12,CR12,CT12,CV12,CX12,) -> 1 | H12: =IF(PRAZO!C10>0,1/PRAZO!$AY10,0) -> 0 | I12: =$C12*H12 -> 0 | J12: =IF(PRAZO!D10>0,1/PRAZO!$AY10,0) -> 0 | K12: =$C12*J12 -> 0 | L12: =IF(PRAZO!E10>0,1/PRAZO!$AY10,0) -> 0 | M12: =$C12*L12 -> 0 | N12: =IF(PRAZO!F10>0,1/PRAZO!$AY10,0) -> 0 | O12: =$C12*N12 -> 0 | P12: =IF(PRAZO!G10>0,1/PRAZO!$AY10,0) -> 0 | Q12: =$C12*P12 -> 0 | R12: =IF(PRAZO!H10>0,1/PRAZO!$AY10,0) -> 0 | S12: =$C12*R12 -> 0 | T12: =IF(PRAZO!I10>0,1/PRAZO!$AY10,0) -> 0 | U12: =$C12*T12 -> 0 | V12: =IF(PRAZO!J10>0,1/PRAZO!$AY10,0) -> 0 | W12: =$C12*V12 -> 0 | X12: =IF(PRAZO!K10>0,1/PRAZO!$AY10,0) -> 0 | Y12: =$C12*X12 -> 0 | Z12: =IF(PRAZO!L10>0,1/PRAZO!$AY10,0) -> 0.0625 | AA12: =$C12*Z12 -> 266833.88 | AB12: =IF(PRAZO!M10>0,1/PRAZO!$AY10,0) -> 0.0625 | AC12: =$C12*AB12 -> 266833.88 | AD12: =IF(PRAZO!N10>0,1/PRAZO!$AY10,0) -> 0.0625 | AE12: =$C12*AD12 -> 266833.88 | AF12: =IF(PRAZO!O10>0,1/PRAZO!$AY10,0) -> 0.0625 | AG12: =$C12*AF12 -> 266833.88 | AH12: =IF(PRAZO!P10>0,1/PRAZO!$AY10,0) -> 0.0625 | AI12: =$C12*AH12 -> 266833.88 | AJ12: =IF(PRAZO!Q10>0,1/PRAZO!$AY10,0) -> 0.0625 | AK12: =$C12*AJ12 -> 266833.88 | AL12: =IF(PRAZO!R10>0,1/PRAZO!$AY10,0) -> 0.0625 | AM12: =$C12*AL12 -> 266833.88 | AN12: =IF(PRAZO!S10>0,1/PRAZO!$AY10,0) -> 0.0625 | AO12: =$C12*AN12 -> 266833.88 | AP12: =IF(PRAZO!T10>0,1/PRAZO!$AY10,0) -> 0.0625 | AQ12: =$C12*AP12 -> 266833.88 | AR12: =IF(PRAZO!U10>0,1/PRAZO!$AY10,0) -> 0.0625 | AS12: =$C12*AR12 -> 266833.88 | AT12: =IF(PRAZO!V10>0,1/PRAZO!$AY10,0) -> 0.0625 | AU12: =$C12*AT12 -> 266833.88 | AV12: =IF(PRAZO!W10>0,1/PRAZO!$AY10,0) -> 0.0625 | AW12: =$C12*AV12 -> 266833.88 | AX12: =IF(PRAZO!X10>0,1/PRAZO!$AY10,0) -> 0.0625 | AY12: =$C12*AX12 -> 266833.88 | AZ12: =IF(PRAZO!Y10>0,1/PRAZO!$AY10,0) -> 0.0625 | BA12: =$C12*AZ12 -> 266833.88 | BB12: =IF(PRAZO!Z10>0,1/PRAZO!$AY10,0) -> 0.0625 | BC12: =$C12*BB12 -> 266833.88 | BD12: =IF(PRAZO!AA10>0,1/PRAZO!$AY10,0) -> 0.0625 | BE12: =$C12*BD12 -> 266833.88 | BF12: =IF(PRAZO!AB10>0,1/PRAZO!$AY10,0) -> 0 | BG12: =$C12*BF12 -> 0 | BH12: =IF(PRAZO!AC10>0,1/PRAZO!$AY10,0) -> 0 | BI12: =$C12*BH12 -> 0 | BJ12: =IF(PRAZO!AD10>0,1/PRAZO!$AY10,0) -> 0 | BK12: =$C12*BJ12 -> 0 | BL12: =IF(PRAZO!AE10>0,1/PRAZO!$AY10,0) -> 0 | BM12: =$C12*BL12 -> 0 | BN12: =IF(PRAZO!AF10>0,1/PRAZO!$AY10,0) -> 0 | BO12: =$C12*BN12 -> 0 | BP12: =IF(PRAZO!AG10>0,1/PRAZO!$AY10,0) -> 0 | BQ12: =$C12*BP12 -> 0 | BR12: =IF(PRAZO!AH10>0,1/PRAZO!$AY10,0) -> 0 | BS12: =$C12*BR12 -> 0 | BT12: =IF(PRAZO!AI10>0,1/PRAZO!$AY10,0) -> 0 | BU12: =$C12*BT12 -> 0 | BV12: =IF(PRAZO!AJ10>0,1/PRAZO!$AY10,0) -> 0 | BW12: =$C12*BV12 -> 0 | BX12: =IF(PRAZO!AK10>0,1/PRAZO!$AY10,0) -> 0 | BY12: =$C12*BX12 -> 0 | BZ12: =IF(PRAZO!AL10>0,1/PRAZO!$AY10,0) -> 0 | CA12: =$C12*BZ12 -> 0 | CB12: =IF(PRAZO!AM10>0,1/PRAZO!$AY10,0) -> 0 | CC12: =$C12*CB12 -> 0 | CD12: =IF(PRAZO!AN10>0,1/PRAZO!$AY10,0) -> 0 | CE12: =$C12*CD12 -> 0 | CF12: =IF(PRAZO!AO10>0,1/PRAZO!$AY10,0) -> 0 | CG12: =$C12*CF12 -> 0 | CH12: =IF(PRAZO!AP10>0,1/PRAZO!$AY10,0) -> 0 | CI12: =$C12*CH12 -> 0 | CJ12: =IF(PRAZO!AQ10>0,1/PRAZO!$AY10,0) -> 0 | CK12: =$C12*CJ12 -> 0 | CL12: =IF(PRAZO!AR10>0,1/PRAZO!$AY10,0) -> 0 | CM12: =$C12*CL12 -> 0 | CN12: =IF(PRAZO!AS10>0,1/PRAZO!$AY10,0) -> 0 | CO12: =$C12*CN12 -> 0 | CP12: =IF(PRAZO!AT10>0,1/PRAZO!$AY10,0) -> 0 | CQ12: =$C12*CP12 -> 0 | CR12: =IF(PRAZO!AU10>0,1/PRAZO!$AY10,0) -> 0 | CS12: =$C12*CR12 -> 0 | CT12: =IF(PRAZO!AV10>0,1/PRAZO!$AY10,0) -> 0 | CU12: =$C12*CT12 -> 0 | CV12: =IF(PRAZO!AW10>0,1/PRAZO!$AY10,0) -> 0 | CW12: =$C12*CV12 -> 0 | CX12: =IF(PRAZO!AX10>0,1/PRAZO!$AY10,0) -> 0 | CY12: =$C12*CX12 -> 0
B13: ALVENARIA | C13: =SUM([1]RESUMO!$B$7:$C$7) -> 1564822.9 | D13: =C13/$C$28 -> 0.04389026 | E13: =C13/'DISTRIBUIÇÃO CUSTO'!C$32 -> 71.325075 | F13: =SUM(H13,J13,L13,N13,P13,R13,T13,V13,X13,Z13,AB13,AD13,AF13,AH13,AJ13,AL13,,AN13,AP13,AR13,AT13,AV13,AX13,AZ13,BB13,BD13,BF13,BH13,BJ13,BL13,BN13,BP13,BR13,BT13,BV13,BX13,BZ13,CB13,CD13,CF13,CH13,CJ13,CL13,CN13,CP13,CR13,CT13,CV13,CX13,) -> 1 | H13: =IF(PRAZO!C11>0,1/PRAZO!$AY11,0) -> 0 | I13: =$C13*H13 -> 0 | J13: =IF(PRAZO!D11>0,1/PRAZO!$AY11,0) -> 0 | K13: =$C13*J13 -> 0 | L13: =IF(PRAZO!E11>0,1/PRAZO!$AY11,0) -> 0 | M13: =$C13*L13 -> 0 | N13: =IF(PRAZO!F11>0,1/PRAZO!$AY11,0) -> 0 | O13: =$C13*N13 -> 0 | P13: =IF(PRAZO!G11>0,1/PRAZO!$AY11,0) -> 0 | Q13: =$C13*P13 -> 0 | R13: =IF(PRAZO!H11>0,1/PRAZO!$AY11,0) -> 0 | S13: =$C13*R13 -> 0 | T13: =IF(PRAZO!I11>0,1/PRAZO!$AY11,0) -> 0 | U13: =$C13*T13 -> 0 | V13: =IF(PRAZO!J11>0,1/PRAZO!$AY11,0) -> 0 | W13: =$C13*V13 -> 0 | X13: =IF(PRAZO!K11>0,1/PRAZO!$AY11,0) -> 0 | Y13: =$C13*X13 -> 0 | Z13: =IF(PRAZO!L11>0,1/PRAZO!$AY11,0) -> 0 | AA13: =$C13*Z13 -> 0 | AB13: =IF(PRAZO!M11>0,1/PRAZO!$AY11,0) -> 0 | AC13: =$C13*AB13 -> 0 | AD13: =IF(PRAZO!N11>0,1/PRAZO!$AY11,0) -> 0 | AE13: =$C13*AD13 -> 0 | AF13: =IF(PRAZO!O11>0,1/PRAZO!$AY11,0) -> 0.0625 | AG13: =$C13*AF13 -> 97801.433 | AH13: =IF(PRAZO!P11>0,1/PRAZO!$AY11,0) -> 0.0625 | AI13: =$C13*AH13 -> 97801.433 | AJ13: =IF(PRAZO!Q11>0,1/PRAZO!$AY11,0) -> 0.0625 | AK13: =$C13*AJ13 -> 97801.433 | AL13: =IF(PRAZO!R11>0,1/PRAZO!$AY11,0) -> 0.0625 | AM13: =$C13*AL13 -> 97801.433 | AN13: =IF(PRAZO!S11>0,1/PRAZO!$AY11,0) -> 0.0625 | AO13: =$C13*AN13 -> 97801.433 | AP13: =IF(PRAZO!T11>0,1/PRAZO!$AY11,0) -> 0.0625 | AQ13: =$C13*AP13 -> 97801.433 | AR13: =IF(PRAZO!U11>0,1/PRAZO!$AY11,0) -> 0.0625 | AS13: =$C13*AR13 -> 97801.433 | AT13: =IF(PRAZO!V11>0,1/PRAZO!$AY11,0) -> 0.0625 | AU13: =$C13*AT13 -> 97801.433 | AV13: =IF(PRAZO!W11>0,1/PRAZO!$AY11,0) -> 0.0625 | AW13: =$C13*AV13 -> 97801.433 | AX13: =IF(PRAZO!X11>0,1/PRAZO!$AY11,0) -> 0.0625 | AY13: =$C13*AX13 -> 97801.433 | AZ13: =IF(PRAZO!Y11>0,1/PRAZO!$AY11,0) -> 0.0625 | BA13: =$C13*AZ13 -> 97801.433 | BB13: =IF(PRAZO!Z11>0,1/PRAZO!$AY11,0) -> 0.0625 | BC13: =$C13*BB13 -> 97801.433 | BD13: =IF(PRAZO!AA11>0,1/PRAZO!$AY11,0) -> 0.0625 | BE13: =$C13*BD13 -> 97801.433 | BF13: =IF(PRAZO!AB11>0,1/PRAZO!$AY11,0) -> 0.0625 | BG13: =$C13*BF13 -> 97801.433 | BH13: =IF(PRAZO!AC11>0,1/PRAZO!$AY11,0) -> 0.0625 | BI13: =$C13*BH13 -> 97801.433 | BJ13: =IF(PRAZO!AD11>0,1/PRAZO!$AY11,0) -> 0.0625 | BK13: =$C13*BJ13 -> 97801.433 | BL13: =IF(PRAZO!AE11>0,1/PRAZO!$AY11,0) -> 0 | BM13: =$C13*BL13 -> 0 | BN13: =IF(PRAZO!AF11>0,1/PRAZO!$AY11,0) -> 0 | BO13: =$C13*BN13 -> 0 | BP13: =IF(PRAZO!AG11>0,1/PRAZO!$AY11,0) -> 0 | BQ13: =$C13*BP13 -> 0 | BR13: =IF(PRAZO!AH11>0,1/PRAZO!$AY11,0) -> 0 | BS13: =$C13*BR13 -> 0 | BT13: =IF(PRAZO!AI11>0,1/PRAZO!$AY11,0) -> 0 | BU13: =$C13*BT13 -> 0 | BV13: =IF(PRAZO!AJ11>0,1/PRAZO!$AY11,0) -> 0 | BW13: =$C13*BV13 -> 0 | BX13: =IF(PRAZO!AK11>0,1/PRAZO!$AY11,0) -> 0 | BY13: =$C13*BX13 -> 0 | BZ13: =IF(PRAZO!AL11>0,1/PRAZO!$AY11,0) -> 0 | CA13: =$C13*BZ13 -> 0 | CB13: =IF(PRAZO!AM11>0,1/PRAZO!$AY11,0) -> 0 | CC13: =$C13*CB13 -> 0 | CD13: =IF(PRAZO!AN11>0,1/PRAZO!$AY11,0) -> 0 | CE13: =$C13*CD13 -> 0 | CF13: =IF(PRAZO!AO11>0,1/PRAZO!$AY11,0) -> 0 | CG13: =$C13*CF13 -> 0 | CH13: =IF(PRAZO!AP11>0,1/PRAZO!$AY11,0) -> 0 | CI13: =$C13*CH13 -> 0 | CJ13: =IF(PRAZO!AQ11>0,1/PRAZO!$AY11,0) -> 0 | CK13: =$C13*CJ13 -> 0 | CL13: =IF(PRAZO!AR11>0,1/PRAZO!$AY11,0) -> 0 | CM13: =$C13*CL13 -> 0 | CN13: =IF(PRAZO!AS11>0,1/PRAZO!$AY11,0) -> 0 | CO13: =$C13*CN13 -> 0 | CP13: =IF(PRAZO!AT11>0,1/PRAZO!$AY11,0) -> 0 | CQ13: =$C13*CP13 -> 0 | CR13: =IF(PRAZO!AU11>0,1/PRAZO!$AY11,0) -> 0 | CS13: =$C13*CR13 -> 0 | CT13: =IF(PRAZO!AV11>0,1/PRAZO!$AY11,0) -> 0 | CU13: =$C13*CT13 -> 0 | CV13: =IF(PRAZO!AW11>0,1/PRAZO!$AY11,0) -> 0 | CW13: =$C13*CV13 -> 0 | CX13: =IF(PRAZO!AX11>0,1/PRAZO!$AY11,0) -> 0 | CY13: =$C13*CX13 -> 0
B14: INSTALAÇÕES ELÉTRICAS, HIDRÁULICAS, GLP E PREVENTIVAS | C14: =SUM([1]RESUMO!$B$8:$C$8) -> 2773667.6 | D14: =C14/$C$28 -> 0.077796017 | E14: =C14/'DISTRIBUIÇÃO CUSTO'!C$32 -> 126.42456 | F14: =SUM(H14,J14,L14,N14,P14,R14,T14,V14,X14,Z14,AB14,AD14,AF14,AH14,AJ14,AL14,,AN14,AP14,AR14,AT14,AV14,AX14,AZ14,BB14,BD14,BF14,BH14,BJ14,BL14,BN14,BP14,BR14,BT14,BV14,BX14,BZ14,CB14,CD14,CF14,CH14,CJ14,CL14,CN14,CP14,CR14,CT14,CV14,CX14,) -> 1 | H14: =IF(PRAZO!C12>0,1/PRAZO!$AY12,0) -> 0 | I14: =$C14*H14 -> 0 | J14: =IF(PRAZO!D12>0,1/PRAZO!$AY12,0) -> 0 | K14: =$C14*J14 -> 0 | L14: =IF(PRAZO!E12>0,1/PRAZO!$AY12,0) -> 0 | M14: =$C14*L14 -> 0 | N14: =IF(PRAZO!F12>0,1/PRAZO!$AY12,0) -> 0 | O14: =$C14*N14 -> 0 | P14: =IF(PRAZO!G12>0,1/PRAZO!$AY12,0) -> 0 | Q14: =$C14*P14 -> 0 | R14: =IF(PRAZO!H12>0,1/PRAZO!$AY12,0) -> 0 | S14: =$C14*R14 -> 0 | T14: =IF(PRAZO!I12>0,1/PRAZO!$AY12,0) -> 0 | U14: =$C14*T14 -> 0 | V14: =IF(PRAZO!J12>0,1/PRAZO!$AY12,0) -> 0 | W14: =$C14*V14 -> 0 | X14: =IF(PRAZO!K12>0,1/PRAZO!$AY12,0) -> 0 | Y14: =$C14*X14 -> 0 | Z14: =IF(PRAZO!L12>0,1/PRAZO!$AY12,0) -> 0 | AA14: =$C14*Z14 -> 0 | AB14: =IF(PRAZO!M12>0,1/PRAZO!$AY12,0) -> 0 | AC14: =$C14*AB14 -> 0 | AD14: =IF(PRAZO!N12>0,1/PRAZO!$AY12,0) -> 0 | AE14: =$C14*AD14 -> 0 | AF14: =IF(PRAZO!O12>0,1/PRAZO!$AY12,0) -> 0.041666667 | AG14: =$C14*AF14 -> 115569.48 | AH14: =IF(PRAZO!P12>0,1/PRAZO!$AY12,0) -> 0.041666667 | AI14: =$C14*AH14 -> 115569.48 | AJ14: =IF(PRAZO!Q12>0,1/PRAZO!$AY12,0) -> 0.041666667 | AK14: =$C14*AJ14 -> 115569.48 | AL14: =IF(PRAZO!R12>0,1/PRAZO!$AY12,0) -> 0.041666667 | AM14: =$C14*AL14 -> 115569.48 | AN14: =IF(PRAZO!S12>0,1/PRAZO!$AY12,0) -> 0.041666667 | AO14: =$C14*AN14 -> 115569.48 | AP14: =IF(PRAZO!T12>0,1/PRAZO!$AY12,0) -> 0.041666667 | AQ14: =$C14*AP14 -> 115569.48 | AR14: =IF(PRAZO!U12>0,1/PRAZO!$AY12,0) -> 0.041666667 | AS14: =$C14*AR14 -> 115569.48 | AT14: =IF(PRAZO!V12>0,1/PRAZO!$AY12,0) -> 0.041666667 | AU14: =$C14*AT14 -> 115569.48 | AV14: =IF(PRAZO!W12>0,1/PRAZO!$AY12,0) -> 0.041666667 | AW14: =$C14*AV14 -> 115569.48 | AX14: =IF(PRAZO!X12>0,1/PRAZO!$AY12,0) -> 0.041666667 | AY14: =$C14*AX14 -> 115569.48 | AZ14: =IF(PRAZO!Y12>0,1/PRAZO!$AY12,0) -> 0.041666667 | BA14: =$C14*AZ14 -> 115569.48 | BB14: =IF(PRAZO!Z12>0,1/PRAZO!$AY12,0) -> 0.041666667 | BC14: =$C14*BB14 -> 115569.48 | BD14: =IF(PRAZO!AA12>0,1/PRAZO!$AY12,0) -> 0.041666667 | BE14: =$C14*BD14 -> 115569.48 | BF14: =IF(PRAZO!AB12>0,1/PRAZO!$AY12,0) -> 0.041666667 | BG14: =$C14*BF14 -> 115569.48 | BH14: =IF(PRAZO!AC12>0,1/PRAZO!$AY12,0) -> 0.041666667 | BI14: =$C14*BH14 -> 115569.48 | BJ14: =IF(PRAZO!AD12>0,1/PRAZO!$AY12,0) -> 0.041666667 | BK14: =$C14*BJ14 -> 115569.48 | BL14: =IF(PRAZO!AE12>0,1/PRAZO!$AY12,0) -> 0.041666667 | BM14: =$C14*BL14 -> 115569.48 | BN14: =IF(PRAZO!AF12>0,1/PRAZO!$AY12,0) -> 0.041666667 | BO14: =$C14*BN14 -> 115569.48 | BP14: =IF(PRAZO!AG12>0,1/PRAZO!$AY12,0) -> 0.041666667 | BQ14: =$C14*BP14 -> 115569.48 | BR14: =IF(PRAZO!AH12>0,1/PRAZO!$AY12,0) -> 0.041666667 | BS14: =$C14*BR14 -> 115569.48 | BT14: =IF(PRAZO!AI12>0,1/PRAZO!$AY12,0) -> 0.041666667 | BU14: =$C14*BT14 -> 115569.48 | BV14: =IF(PRAZO!AJ12>0,1/PRAZO!$AY12,0) -> 0.041666667 | BW14: =$C14*BV14 -> 115569.48 | BX14: =IF(PRAZO!AK12>0,1/PRAZO!$AY12,0) -> 0.041666667 | BY14: =$C14*BX14 -> 115569.48 | BZ14: =IF(PRAZO!AL12>0,1/PRAZO!$AY12,0) -> 0.041666667 | CA14: =$C14*BZ14 -> 115569.48 | CB14: =IF(PRAZO!AM12>0,1/PRAZO!$AY12,0) -> 0 | CC14: =$C14*CB14 -> 0 | CD14: =IF(PRAZO!AN12>0,1/PRAZO!$AY12,0) -> 0 | CE14: =$C14*CD14 -> 0 | CF14: =IF(PRAZO!AO12>0,1/PRAZO!$AY12,0) -> 0 | CG14: =$C14*CF14 -> 0 | CH14: =IF(PRAZO!AP12>0,1/PRAZO!$AY12,0) -> 0 | CI14: =$C14*CH14 -> 0 | CJ14: =IF(PRAZO!AQ12>0,1/PRAZO!$AY12,0) -> 0 | CK14: =$C14*CJ14 -> 0 | CL14: =IF(PRAZO!AR12>0,1/PRAZO!$AY12,0) -> 0 | CM14: =$C14*CL14 -> 0 | CN14: =IF(PRAZO!AS12>0,1/PRAZO!$AY12,0) -> 0 | CO14: =$C14*CN14 -> 0 | CP14: =IF(PRAZO!AT12>0,1/PRAZO!$AY12,0) -> 0 | CQ14: =$C14*CP14 -> 0 | CR14: =IF(PRAZO!AU12>0,1/PRAZO!$AY12,0) -> 0 | CS14: =$C14*CR14 -> 0 | CT14: =IF(PRAZO!AV12>0,1/PRAZO!$AY12,0) -> 0 | CU14: =$C14*CT14 -> 0 | CV14: =IF(PRAZO!AW12>0,1/PRAZO!$AY12,0) -> 0 | CW14: =$C14*CV14 -> 0 | CX14: =IF(PRAZO!AX12>0,1/PRAZO!$AY12,0) -> 0 | CY14: =$C14*CX14 -> 0
B15: EQUIPAMENTOS E SISTEMAS ESPECIAIS | C15: =SUM([1]RESUMO!$B$9:$C$9) -> 1577982.4 | D15: =C15/$C$28 -> 0.044259358 | E15: =C15/'DISTRIBUIÇÃO CUSTO'!C$32 -> 71.924887 | F15: =SUM(H15,J15,L15,N15,P15,R15,T15,V15,X15,Z15,AB15,AD15,AF15,AH15,AJ15,AL15,,AN15,AP15,AR15,AT15,AV15,AX15,AZ15,BB15,BD15,BF15,BH15,BJ15,BL15,BN15,BP15,BR15,BT15,BV15,BX15,BZ15,CB15,CD15,CF15,CH15,CJ15,CL15,CN15,CP15,CR15,CT15,CV15,CX15,) -> 1 | H15: =IF(PRAZO!C13>0,1/PRAZO!$AY13,0) -> 0 | I15: =$C15*H15 -> 0 | J15: =IF(PRAZO!D13>0,1/PRAZO!$AY13,0) -> 0 | K15: =$C15*J15 -> 0 | L15: =IF(PRAZO!E13>0,1/PRAZO!$AY13,0) -> 0 | M15: =$C15*L15 -> 0 | N15: =IF(PRAZO!F13>0,1/PRAZO!$AY13,0) -> 0 | O15: =$C15*N15 -> 0 | P15: =IF(PRAZO!G13>0,1/PRAZO!$AY13,0) -> 0 | Q15: =$C15*P15 -> 0 | R15: =IF(PRAZO!H13>0,1/PRAZO!$AY13,0) -> 0 | S15: =$C15*R15 -> 0 | T15: =IF(PRAZO!I13>0,1/PRAZO!$AY13,0) -> 0 | U15: =$C15*T15 -> 0 | V15: =IF(PRAZO!J13>0,1/PRAZO!$AY13,0) -> 0 | W15: =$C15*V15 -> 0 | X15: =IF(PRAZO!K13>0,1/PRAZO!$AY13,0) -> 0 | Y15: =$C15*X15 -> 0 | Z15: =IF(PRAZO!L13>0,1/PRAZO!$AY13,0) -> 0 | AA15: =$C15*Z15 -> 0 | AB15: =IF(PRAZO!M13>0,1/PRAZO!$AY13,0) -> 0 | AC15: =$C15*AB15 -> 0 | AD15: =IF(PRAZO!N13>0,1/PRAZO!$AY13,0) -> 0 | AE15: =$C15*AD15 -> 0 | AF15: =IF(PRAZO!O13>0,1/PRAZO!$AY13,0) -> 0 | AG15: =$C15*AF15 -> 0 | AH15: =IF(PRAZO!P13>0,1/PRAZO!$AY13,0) -> 0 | AI15: =$C15*AH15 -> 0 | AJ15: =IF(PRAZO!Q13>0,1/PRAZO!$AY13,0) -> 0 | AK15: =$C15*AJ15 -> 0 | AL15: =IF(PRAZO!R13>0,1/PRAZO!$AY13,0) -> 0 | AM15: =$C15*AL15 -> 0 | AN15: =IF(PRAZO!S13>0,1/PRAZO!$AY13,0) -> 0 | AO15: =$C15*AN15 -> 0 | AP15: =IF(PRAZO!T13>0,1/PRAZO!$AY13,0) -> 0 | AQ15: =$C15*AP15 -> 0 | AR15: =IF(PRAZO!U13>0,1/PRAZO!$AY13,0) -> 0 | AS15: =$C15*AR15 -> 0 | AT15: =IF(PRAZO!V13>0,1/PRAZO!$AY13,0) -> 0 | AU15: =$C15*AT15 -> 0 | AV15: =IF(PRAZO!W13>0,1/PRAZO!$AY13,0) -> 0.045454545 | AW15: =$C15*AV15 -> 71726.473 | AX15: =IF(PRAZO!X13>0,1/PRAZO!$AY13,0) -> 0.045454545 | AY15: =$C15*AX15 -> 71726.473 | AZ15: =IF(PRAZO!Y13>0,1/PRAZO!$AY13,0) -> 0.045454545 | BA15: =$C15*AZ15 -> 71726.473 | BB15: =IF(PRAZO!Z13>0,1/PRAZO!$AY13,0) -> 0.045454545 | BC15: =$C15*BB15 -> 71726.473 | BD15: =IF(PRAZO!AA13>0,1/PRAZO!$AY13,0) -> 0.045454545 | BE15: =$C15*BD15 -> 71726.473 | BF15: =IF(PRAZO!AB13>0,1/PRAZO!$AY13,0) -> 0.045454545 | BG15: =$C15*BF15 -> 71726.473 | BH15: =IF(PRAZO!AC13>0,1/PRAZO!$AY13,0) -> 0.045454545 | BI15: =$C15*BH15 -> 71726.473 | BJ15: =IF(PRAZO!AD13>0,1/PRAZO!$AY13,0) -> 0.045454545 | BK15: =$C15*BJ15 -> 71726.473 | BL15: =IF(PRAZO!AE13>0,1/PRAZO!$AY13,0) -> 0.045454545 | BM15: =$C15*BL15 -> 71726.473 | BN15: =IF(PRAZO!AF13>0,1/PRAZO!$AY13,0) -> 0.045454545 | BO15: =$C15*BN15 -> 71726.473 | BP15: =IF(PRAZO!AG13>0,1/PRAZO!$AY13,0) -> 0.045454545 | BQ15: =$C15*BP15 -> 71726.473 | BR15: =IF(PRAZO!AH13>0,1/PRAZO!$AY13,0) -> 0.045454545 | BS15: =$C15*BR15 -> 71726.473 | BT15: =IF(PRAZO!AI13>0,1/PRAZO!$AY13,0) -> 0.045454545 | BU15: =$C15*BT15 -> 71726.473 | BV15: =IF(PRAZO!AJ13>0,1/PRAZO!$AY13,0) -> 0.045454545 | BW15: =$C15*BV15 -> 71726.473 | BX15: =IF(PRAZO!AK13>0,1/PRAZO!$AY13,0) -> 0.045454545 | BY15: =$C15*BX15 -> 71726.473 | BZ15: =IF(PRAZO!AL13>0,1/PRAZO!$AY13,0) -> 0.045454545 | CA15: =$C15*BZ15 -> 71726.473 | CB15: =IF(PRAZO!AM13>0,1/PRAZO!$AY13,0) -> 0.045454545 | CC15: =$C15*CB15 -> 71726.473 | CD15: =IF(PRAZO!AN13>0,1/PRAZO!$AY13,0) -> 0.045454545 | CE15: =$C15*CD15 -> 71726.473 | CF15: =IF(PRAZO!AO13>0,1/PRAZO!$AY13,0) -> 0.045454545 | CG15: =$C15*CF15 -> 71726.473 | CH15: =IF(PRAZO!AP13>0,1/PRAZO!$AY13,0) -> 0.045454545 | CI15: =$C15*CH15 -> 71726.473 | CJ15: =IF(PRAZO!AQ13>0,1/PRAZO!$AY13,0) -> 0.045454545 | CK15: =$C15*CJ15 -> 71726.473 | CL15: =IF(PRAZO!AR13>0,1/PRAZO!$AY13,0) -> 0.045454545 | CM15: =$C15*CL15 -> 71726.473 | CN15: =IF(PRAZO!AS13>0,1/PRAZO!$AY13,0) -> 0 | CO15: =$C15*CN15 -> 0 | CP15: =IF(PRAZO!AT13>0,1/PRAZO!$AY13,0) -> 0 | CQ15: =$C15*CP15 -> 0 | CR15: =IF(PRAZO!AU13>0,1/PRAZO!$AY13,0) -> 0 | CS15: =$C15*CR15 -> 0 | CT15: =IF(PRAZO!AV13>0,1/PRAZO!$AY13,0) -> 0 | CU15: =$C15*CT15 -> 0 | CV15: =IF(PRAZO!AW13>0,1/PRAZO!$AY13,0) -> 0 | CW15: =$C15*CV15 -> 0 | CX15: =IF(PRAZO!AX13>0,1/PRAZO!$AY13,0) -> 0 | CY15: =$C15*CX15 -> 0
B16: IMPERMEABILIZAÇÃO | C16: =SUM([1]RESUMO!$B$10:$C$10) -> 357850.36 | D16: =C16/$C$28 -> 0.010037011 | E16: =C16/'DISTRIBUIÇÃO CUSTO'!C$32 -> 16.310921 | F16: =SUM(H16,J16,L16,N16,P16,R16,T16,V16,X16,Z16,AB16,AD16,AF16,AH16,AJ16,AL16,,AN16,AP16,AR16,AT16,AV16,AX16,AZ16,BB16,BD16,BF16,BH16,BJ16,BL16,BN16,BP16,BR16,BT16,BV16,BX16,BZ16,CB16,CD16,CF16,CH16,CJ16,CL16,CN16,CP16,CR16,CT16,CV16,CX16,) -> 1 | H16: =IF(PRAZO!C14>0,1/PRAZO!$AY14,0) -> 0 | I16: =$C16*H16 -> 0 | J16: =IF(PRAZO!D14>0,1/PRAZO!$AY14,0) -> 0 | K16: =$C16*J16 -> 0 | L16: =IF(PRAZO!E14>0,1/PRAZO!$AY14,0) -> 0 | M16: =$C16*L16 -> 0 | N16: =IF(PRAZO!F14>0,1/PRAZO!$AY14,0) -> 0 | O16: =$C16*N16 -> 0 | P16: =IF(PRAZO!G14>0,1/PRAZO!$AY14,0) -> 0 | Q16: =$C16*P16 -> 0 | R16: =IF(PRAZO!H14>0,1/PRAZO!$AY14,0) -> 0 | S16: =$C16*R16 -> 0 | T16: =IF(PRAZO!I14>0,1/PRAZO!$AY14,0) -> 0 | U16: =$C16*T16 -> 0 | V16: =IF(PRAZO!J14>0,1/PRAZO!$AY14,0) -> 0 | W16: =$C16*V16 -> 0 | X16: =IF(PRAZO!K14>0,1/PRAZO!$AY14,0) -> 0 | Y16: =$C16*X16 -> 0 | Z16: =IF(PRAZO!L14>0,1/PRAZO!$AY14,0) -> 0 | AA16: =$C16*Z16 -> 0 | AB16: =IF(PRAZO!M14>0,1/PRAZO!$AY14,0) -> 0 | AC16: =$C16*AB16 -> 0 | AD16: =IF(PRAZO!N14>0,1/PRAZO!$AY14,0) -> 0 | AE16: =$C16*AD16 -> 0 | AF16: =IF(PRAZO!O14>0,1/PRAZO!$AY14,0) -> 0 | AG16: =$C16*AF16 -> 0 | AH16: =IF(PRAZO!P14>0,1/PRAZO!$AY14,0) -> 0 | AI16: =$C16*AH16 -> 0 | AJ16: =IF(PRAZO!Q14>0,1/PRAZO!$AY14,0) -> 0 | AK16: =$C16*AJ16 -> 0 | AL16: =IF(PRAZO!R14>0,1/PRAZO!$AY14,0) -> 0 | AM16: =$C16*AL16 -> 0 | AN16: =IF(PRAZO!S14>0,1/PRAZO!$AY14,0) -> 0 | AO16: =$C16*AN16 -> 0 | AP16: =IF(PRAZO!T14>0,1/PRAZO!$AY14,0) -> 0 | AQ16: =$C16*AP16 -> 0 | AR16: =IF(PRAZO!U14>0,1/PRAZO!$AY14,0) -> 0 | AS16: =$C16*AR16 -> 0 | AT16: =IF(PRAZO!V14>0,1/PRAZO!$AY14,0) -> 0 | AU16: =$C16*AT16 -> 0 | AV16: =IF(PRAZO!W14>0,1/PRAZO!$AY14,0) -> 0 | AW16: =$C16*AV16 -> 0 | AX16: =IF(PRAZO!X14>0,1/PRAZO!$AY14,0) -> 0 | AY16: =$C16*AX16 -> 0 | AZ16: =IF(PRAZO!Y14>0,1/PRAZO!$AY14,0) -> 0.083333333 | BA16: =$C16*AZ16 -> 29820.863 | BB16: =IF(PRAZO!Z14>0,1/PRAZO!$AY14,0) -> 0.083333333 | BC16: =$C16*BB16 -> 29820.863 | BD16: =IF(PRAZO!AA14>0,1/PRAZO!$AY14,0) -> 0.083333333 | BE16: =$C16*BD16 -> 29820.863 | BF16: =IF(PRAZO!AB14>0,1/PRAZO!$AY14,0) -> 0.083333333 | BG16: =$C16*BF16 -> 29820.863 | BH16: =IF(PRAZO!AC14>0,1/PRAZO!$AY14,0) -> 0.083333333 | BI16: =$C16*BH16 -> 29820.863 | BJ16: =IF(PRAZO!AD14>0,1/PRAZO!$AY14,0) -> 0.083333333 | BK16: =$C16*BJ16 -> 29820.863 | BL16: =IF(PRAZO!AE14>0,1/PRAZO!$AY14,0) -> 0.083333333 | BM16: =$C16*BL16 -> 29820.863 | BN16: =IF(PRAZO!AF14>0,1/PRAZO!$AY14,0) -> 0.083333333 | BO16: =$C16*BN16 -> 29820.863 | BP16: =IF(PRAZO!AG14>0,1/PRAZO!$AY14,0) -> 0.083333333 | BQ16: =$C16*BP16 -> 29820.863 | BR16: =IF(PRAZO!AH14>0,1/PRAZO!$AY14,0) -> 0.083333333 | BS16: =$C16*BR16 -> 29820.863 | BT16: =IF(PRAZO!AI14>0,1/PRAZO!$AY14,0) -> 0.083333333 | BU16: =$C16*BT16 -> 29820.863 | BV16: =IF(PRAZO!AJ14>0,1/PRAZO!$AY14,0) -> 0.083333333 | BW16: =$C16*BV16 -> 29820.863 | BX16: =IF(PRAZO!AK14>0,1/PRAZO!$AY14,0) -> 0 | BY16: =$C16*BX16 -> 0 | BZ16: =IF(PRAZO!AL14>0,1/PRAZO!$AY14,0) -> 0 | CA16: =$C16*BZ16 -> 0 | CB16: =IF(PRAZO!AM14>0,1/PRAZO!$AY14,0) -> 0 | CC16: =$C16*CB16 -> 0 | CD16: =IF(PRAZO!AN14>0,1/PRAZO!$AY14,0) -> 0 | CE16: =$C16*CD16 -> 0 | CF16: =IF(PRAZO!AO14>0,1/PRAZO!$AY14,0) -> 0 | CG16: =$C16*CF16 -> 0 | CH16: =IF(PRAZO!AP14>0,1/PRAZO!$AY14,0) -> 0 | CI16: =$C16*CH16 -> 0 | CJ16: =IF(PRAZO!AQ14>0,1/PRAZO!$AY14,0) -> 0 | CK16: =$C16*CJ16 -> 0 | CL16: =IF(PRAZO!AR14>0,1/PRAZO!$AY14,0) -> 0 | CM16: =$C16*CL16 -> 0 | CN16: =IF(PRAZO!AS14>0,1/PRAZO!$AY14,0) -> 0 | CO16: =$C16*CN16 -> 0 | CP16: =IF(PRAZO!AT14>0,1/PRAZO!$AY14,0) -> 0 | CQ16: =$C16*CP16 -> 0 | CR16: =IF(PRAZO!AU14>0,1/PRAZO!$AY14,0) -> 0 | CS16: =$C16*CR16 -> 0 | CT16: =IF(PRAZO!AV14>0,1/PRAZO!$AY14,0) -> 0 | CU16: =$C16*CT16 -> 0 | CV16: =IF(PRAZO!AW14>0,1/PRAZO!$AY14,0) -> 0 | CW16: =$C16*CV16 -> 0 | CX16: =IF(PRAZO!AX14>0,1/PRAZO!$AY14,0) -> 0 | CY16: =$C16*CX16 -> 0
B17: REVESTIMENTOS INTERNOS EM PISO E PAREDE | C17: =SUM([1]RESUMO!$B$11:$C$11) -> 631938.58 | D17: =C17/$C$28 -> 0.017724656 | E17: =C17/'DISTRIBUIÇÃO CUSTO'!C$32 -> 28.80394 | F17: =SUM(H17,J17,L17,N17,P17,R17,T17,V17,X17,Z17,AB17,AD17,AF17,AH17,AJ17,AL17,,AN17,AP17,AR17,AT17,AV17,AX17,AZ17,BB17,BD17,BF17,BH17,BJ17,BL17,BN17,BP17,BR17,BT17,BV17,BX17,BZ17,CB17,CD17,CF17,CH17,CJ17,CL17,CN17,CP17,CR17,CT17,CV17,CX17,) -> 1 | H17: =IF(PRAZO!C15>0,1/PRAZO!$AY15,0) -> 0 | I17: =$C17*H17 -> 0 | J17: =IF(PRAZO!D15>0,1/PRAZO!$AY15,0) -> 0 | K17: =$C17*J17 -> 0 | L17: =IF(PRAZO!E15>0,1/PRAZO!$AY15,0) -> 0 | M17: =$C17*L17 -> 0 | N17: =IF(PRAZO!F15>0,1/PRAZO!$AY15,0) -> 0 | O17: =$C17*N17 -> 0 | P17: =IF(PRAZO!G15>0,1/PRAZO!$AY15,0) -> 0 | Q17: =$C17*P17 -> 0 | R17: =IF(PRAZO!H15>0,1/PRAZO!$AY15,0) -> 0 | S17: =$C17*R17 -> 0 | T17: =IF(PRAZO!I15>0,1/PRAZO!$AY15,0) -> 0 | U17: =$C17*T17 -> 0 | V17: =IF(PRAZO!J15>0,1/PRAZO!$AY15,0) -> 0 | W17: =$C17*V17 -> 0 | X17: =IF(PRAZO!K15>0,1/PRAZO!$AY15,0) -> 0 | Y17: =$C17*X17 -> 0 | Z17: =IF(PRAZO!L15>0,1/PRAZO!$AY15,0) -> 0 | AA17: =$C17*Z17 -> 0 | AB17: =IF(PRAZO!M15>0,1/PRAZO!$AY15,0) -> 0 | AC17: =$C17*AB17 -> 0 | AD17: =IF(PRAZO!N15>0,1/PRAZO!$AY15,0) -> 0 | AE17: =$C17*AD17 -> 0 | AF17: =IF(PRAZO!O15>0,1/PRAZO!$AY15,0) -> 0 | AG17: =$C17*AF17 -> 0 | AH17: =IF(PRAZO!P15>0,1/PRAZO!$AY15,0) -> 0 | AI17: =$C17*AH17 -> 0 | AJ17: =IF(PRAZO!Q15>0,1/PRAZO!$AY15,0) -> 0 | AK17: =$C17*AJ17 -> 0 | AL17: =IF(PRAZO!R15>0,1/PRAZO!$AY15,0) -> 0 | AM17: =$C17*AL17 -> 0 | AN17: =IF(PRAZO!S15>0,1/PRAZO!$AY15,0) -> 0.066666667 | AO17: =$C17*AN17 -> 42129.238 | AP17: =IF(PRAZO!T15>0,1/PRAZO!$AY15,0) -> 0.066666667 | AQ17: =$C17*AP17 -> 42129.238 | AR17: =IF(PRAZO!U15>0,1/PRAZO!$AY15,0) -> 0.066666667 | AS17: =$C17*AR17 -> 42129.238 | AT17: =IF(PRAZO!V15>0,1/PRAZO!$AY15,0) -> 0.066666667 | AU17: =$C17*AT17 -> 42129.238 | AV17: =IF(PRAZO!W15>0,1/PRAZO!$AY15,0) -> 0.066666667 | AW17: =$C17*AV17 -> 42129.238 | AX17: =IF(PRAZO!X15>0,1/PRAZO!$AY15,0) -> 0.066666667 | AY17: =$C17*AX17 -> 42129.238 | AZ17: =IF(PRAZO!Y15>0,1/PRAZO!$AY15,0) -> 0.066666667 | BA17: =$C17*AZ17 -> 42129.238 | BB17: =IF(PRAZO!Z15>0,1/PRAZO!$AY15,0) -> 0.066666667 | BC17: =$C17*BB17 -> 42129.238 | BD17: =IF(PRAZO!AA15>0,1/PRAZO!$AY15,0) -> 0.066666667 | BE17: =$C17*BD17 -> 42129.238 | BF17: =IF(PRAZO!AB15>0,1/PRAZO!$AY15,0) -> 0.066666667 | BG17: =$C17*BF17 -> 42129.238 | BH17: =IF(PRAZO!AC15>0,1/PRAZO!$AY15,0) -> 0.066666667 | BI17: =$C17*BH17 -> 42129.238 | BJ17: =IF(PRAZO!AD15>0,1/PRAZO!$AY15,0) -> 0.066666667 | BK17: =$C17*BJ17 -> 42129.238 | BL17: =IF(PRAZO!AE15>0,1/PRAZO!$AY15,0) -> 0.066666667 | BM17: =$C17*BL17 -> 42129.238 | BN17: =IF(PRAZO!AF15>0,1/PRAZO!$AY15,0) -> 0.066666667 | BO17: =$C17*BN17 -> 42129.238 | BP17: =IF(PRAZO!AG15>0,1/PRAZO!$AY15,0) -> 0.066666667 | BQ17: =$C17*BP17 -> 42129.238 | BR17: =IF(PRAZO!AH15>0,1/PRAZO!$AY15,0) -> 0 | BS17: =$C17*BR17 -> 0 | BT17: =IF(PRAZO!AI15>0,1/PRAZO!$AY15,0) -> 0 | BU17: =$C17*BT17 -> 0 | BV17: =IF(PRAZO!AJ15>0,1/PRAZO!$AY15,0) -> 0 | BW17: =$C17*BV17 -> 0 | BX17: =IF(PRAZO!AK15>0,1/PRAZO!$AY15,0) -> 0 | BY17: =$C17*BX17 -> 0 | BZ17: =IF(PRAZO!AL15>0,1/PRAZO!$AY15,0) -> 0 | CA17: =$C17*BZ17 -> 0 | CB17: =IF(PRAZO!AM15>0,1/PRAZO!$AY15,0) -> 0 | CC17: =$C17*CB17 -> 0 | CD17: =IF(PRAZO!AN15>0,1/PRAZO!$AY15,0) -> 0 | CE17: =$C17*CD17 -> 0 | CF17: =IF(PRAZO!AO15>0,1/PRAZO!$AY15,0) -> 0 | CG17: =$C17*CF17 -> 0 | CH17: =IF(PRAZO!AP15>0,1/PRAZO!$AY15,0) -> 0 | CI17: =$C17*CH17 -> 0 | CJ17: =IF(PRAZO!AQ15>0,1/PRAZO!$AY15,0) -> 0 | CK17: =$C17*CJ17 -> 0 | CL17: =IF(PRAZO!AR15>0,1/PRAZO!$AY15,0) -> 0 | CM17: =$C17*CL17 -> 0 | CN17: =IF(PRAZO!AS15>0,1/PRAZO!$AY15,0) -> 0 | CO17: =$C17*CN17 -> 0 | CP17: =IF(PRAZO!AT15>0,1/PRAZO!$AY15,0) -> 0 | CQ17: =$C17*CP17 -> 0 | CR17: =IF(PRAZO!AU15>0,1/PRAZO!$AY15,0) -> 0 | CS17: =$C17*CR17 -> 0 | CT17: =IF(PRAZO!AV15>0,1/PRAZO!$AY15,0) -> 0 | CU17: =$C17*CT17 -> 0 | CV17: =IF(PRAZO!AW15>0,1/PRAZO!$AY15,0) -> 0 | CW17: =$C17*CV17 -> 0 | CX17: =IF(PRAZO!AX15>0,1/PRAZO!$AY15,0) -> 0 | CY17: =$C17*CX17 -> 0
B18: REVESTIMENTOS E ACABAMENTOS INTERNOS EM TETO | C18: =SUM([1]RESUMO!$B$12:$C$12) -> 365758.96 | D18: =C18/$C$28 -> 0.010258832 | E18: =C18/'DISTRIBUIÇÃO CUSTO'!C$32 -> 16.671398 | F18: =SUM(H18,J18,L18,N18,P18,R18,T18,V18,X18,Z18,AB18,AD18,AF18,AH18,AJ18,AL18,,AN18,AP18,AR18,AT18,AV18,AX18,AZ18,BB18,BD18,BF18,BH18,BJ18,BL18,BN18,BP18,BR18,BT18,BV18,BX18,BZ18,CB18,CD18,CF18,CH18,CJ18,CL18,CN18,CP18,CR18,CT18,CV18,CX18,) -> 1 | H18: =IF(PRAZO!C16>0,1/PRAZO!$AY16,0) -> 0 | I18: =$C18*H18 -> 0 | J18: =IF(PRAZO!D16>0,1/PRAZO!$AY16,0) -> 0 | K18: =$C18*J18 -> 0 | L18: =IF(PRAZO!E16>0,1/PRAZO!$AY16,0) -> 0 | M18: =$C18*L18 -> 0 | N18: =IF(PRAZO!F16>0,1/PRAZO!$AY16,0) -> 0 | O18: =$C18*N18 -> 0 | P18: =IF(PRAZO!G16>0,1/PRAZO!$AY16,0) -> 0 | Q18: =$C18*P18 -> 0 | R18: =IF(PRAZO!H16>0,1/PRAZO!$AY16,0) -> 0 | S18: =$C18*R18 -> 0 | T18: =IF(PRAZO!I16>0,1/PRAZO!$AY16,0) -> 0 | U18: =$C18*T18 -> 0 | V18: =IF(PRAZO!J16>0,1/PRAZO!$AY16,0) -> 0 | W18: =$C18*V18 -> 0 | X18: =IF(PRAZO!K16>0,1/PRAZO!$AY16,0) -> 0 | Y18: =$C18*X18 -> 0 | Z18: =IF(PRAZO!L16>0,1/PRAZO!$AY16,0) -> 0 | AA18: =$C18*Z18 -> 0 | AB18: =IF(PRAZO!M16>0,1/PRAZO!$AY16,0) -> 0 | AC18: =$C18*AB18 -> 0 | AD18: =IF(PRAZO!N16>0,1/PRAZO!$AY16,0) -> 0 | AE18: =$C18*AD18 -> 0 | AF18: =IF(PRAZO!O16>0,1/PRAZO!$AY16,0) -> 0 | AG18: =$C18*AF18 -> 0 | AH18: =IF(PRAZO!P16>0,1/PRAZO!$AY16,0) -> 0 | AI18: =$C18*AH18 -> 0 | AJ18: =IF(PRAZO!Q16>0,1/PRAZO!$AY16,0) -> 0 | AK18: =$C18*AJ18 -> 0 | AL18: =IF(PRAZO!R16>0,1/PRAZO!$AY16,0) -> 0 | AM18: =$C18*AL18 -> 0 | AN18: =IF(PRAZO!S16>0,1/PRAZO!$AY16,0) -> 0 | AO18: =$C18*AN18 -> 0 | AP18: =IF(PRAZO!T16>0,1/PRAZO!$AY16,0) -> 0 | AQ18: =$C18*AP18 -> 0 | AR18: =IF(PRAZO!U16>0,1/PRAZO!$AY16,0) -> 0 | AS18: =$C18*AR18 -> 0 | AT18: =IF(PRAZO!V16>0,1/PRAZO!$AY16,0) -> 0 | AU18: =$C18*AT18 -> 0 | AV18: =IF(PRAZO!W16>0,1/PRAZO!$AY16,0) -> 0 | AW18: =$C18*AV18 -> 0 | AX18: =IF(PRAZO!X16>0,1/PRAZO!$AY16,0) -> 0 | AY18: =$C18*AX18 -> 0 | AZ18: =IF(PRAZO!Y16>0,1/PRAZO!$AY16,0) -> 0 | BA18: =$C18*AZ18 -> 0 | BB18: =IF(PRAZO!Z16>0,1/PRAZO!$AY16,0) -> 0 | BC18: =$C18*BB18 -> 0 | BD18: =IF(PRAZO!AA16>0,1/PRAZO!$AY16,0) -> 0 | BE18: =$C18*BD18 -> 0 | BF18: =IF(PRAZO!AB16>0,1/PRAZO!$AY16,0) -> 0 | BG18: =$C18*BF18 -> 0 | BH18: =IF(PRAZO!AC16>0,1/PRAZO!$AY16,0) -> 0.083333333 | BI18: =$C18*BH18 -> 30479.914 | BJ18: =IF(PRAZO!AD16>0,1/PRAZO!$AY16,0) -> 0.083333333 | BK18: =$C18*BJ18 -> 30479.914 | BL18: =IF(PRAZO!AE16>0,1/PRAZO!$AY16,0) -> 0.083333333 | BM18: =$C18*BL18 -> 30479.914 | BN18: =IF(PRAZO!AF16>0,1/PRAZO!$AY16,0) -> 0.083333333 | BO18: =$C18*BN18 -> 30479.914 | BP18: =IF(PRAZO!AG16>0,1/PRAZO!$AY16,0) -> 0.083333333 | BQ18: =$C18*BP18 -> 30479.914 | BR18: =IF(PRAZO!AH16>0,1/PRAZO!$AY16,0) -> 0.083333333 | BS18: =$C18*BR18 -> 30479.914 | BT18: =IF(PRAZO!AI16>0,1/PRAZO!$AY16,0) -> 0.083333333 | BU18: =$C18*BT18 -> 30479.914 | BV18: =IF(PRAZO!AJ16>0,1/PRAZO!$AY16,0) -> 0.083333333 | BW18: =$C18*BV18 -> 30479.914 | BX18: =IF(PRAZO!AK16>0,1/PRAZO!$AY16,0) -> 0.083333333 | BY18: =$C18*BX18 -> 30479.914 | BZ18: =IF(PRAZO!AL16>0,1/PRAZO!$AY16,0) -> 0.083333333 | CA18: =$C18*BZ18 -> 30479.914 | CB18: =IF(PRAZO!AM16>0,1/PRAZO!$AY16,0) -> 0.083333333 | CC18: =$C18*CB18 -> 30479.914 | CD18: =IF(PRAZO!AN16>0,1/PRAZO!$AY16,0) -> 0.083333333 | CE18: =$C18*CD18 -> 30479.914 | CF18: =IF(PRAZO!AO16>0,1/PRAZO!$AY16,0) -> 0 | CG18: =$C18*CF18 -> 0 | CH18: =IF(PRAZO!AP16>0,1/PRAZO!$AY16,0) -> 0 | CI18: =$C18*CH18 -> 0 | CJ18: =IF(PRAZO!AQ16>0,1/PRAZO!$AY16,0) -> 0 | CK18: =$C18*CJ18 -> 0 | CL18: =IF(PRAZO!AR16>0,1/PRAZO!$AY16,0) -> 0 | CM18: =$C18*CL18 -> 0 | CN18: =IF(PRAZO!AS16>0,1/PRAZO!$AY16,0) -> 0 | CO18: =$C18*CN18 -> 0 | CP18: =IF(PRAZO!AT16>0,1/PRAZO!$AY16,0) -> 0 | CQ18: =$C18*CP18 -> 0 | CR18: =IF(PRAZO!AU16>0,1/PRAZO!$AY16,0) -> 0 | CS18: =$C18*CR18 -> 0 | CT18: =IF(PRAZO!AV16>0,1/PRAZO!$AY16,0) -> 0 | CU18: =$C18*CT18 -> 0 | CV18: =IF(PRAZO!AW16>0,1/PRAZO!$AY16,0) -> 0 | CW18: =$C18*CV18 -> 0 | CX18: =IF(PRAZO!AX16>0,1/PRAZO!$AY16,0) -> 0 | CY18: =$C18*CX18 -> 0
B19: ACABAMENTOS EM PISO E PAREDE | C19: =SUM([1]RESUMO!$B$13:$C$13) -> 1225174.5 | D19: =C19/$C$28 -> 0.034363777 | E19: =C19/'DISTRIBUIÇÃO CUSTO'!C$32 -> 55.843801 | F19: =SUM(H19,J19,L19,N19,P19,R19,T19,V19,X19,Z19,AB19,AD19,AF19,AH19,AJ19,AL19,,AN19,AP19,AR19,AT19,AV19,AX19,AZ19,BB19,BD19,BF19,BH19,BJ19,BL19,BN19,BP19,BR19,BT19,BV19,BX19,BZ19,CB19,CD19,CF19,CH19,CJ19,CL19,CN19,CP19,CR19,CT19,CV19,CX19,) -> 1 | H19: =IF(PRAZO!C17>0,1/PRAZO!$AY17,0) -> 0 | I19: =$C19*H19 -> 0 | J19: =IF(PRAZO!D17>0,1/PRAZO!$AY17,0) -> 0 | K19: =$C19*J19 -> 0 | L19: =IF(PRAZO!E17>0,1/PRAZO!$AY17,0) -> 0 | M19: =$C19*L19 -> 0 | N19: =IF(PRAZO!F17>0,1/PRAZO!$AY17,0) -> 0 | O19: =$C19*N19 -> 0 | P19: =IF(PRAZO!G17>0,1/PRAZO!$AY17,0) -> 0 | Q19: =$C19*P19 -> 0 | R19: =IF(PRAZO!H17>0,1/PRAZO!$AY17,0) -> 0 | S19: =$C19*R19 -> 0 | T19: =IF(PRAZO!I17>0,1/PRAZO!$AY17,0) -> 0 | U19: =$C19*T19 -> 0 | V19: =IF(PRAZO!J17>0,1/PRAZO!$AY17,0) -> 0 | W19: =$C19*V19 -> 0 | X19: =IF(PRAZO!K17>0,1/PRAZO!$AY17,0) -> 0 | Y19: =$C19*X19 -> 0 | Z19: =IF(PRAZO!L17>0,1/PRAZO!$AY17,0) -> 0 | AA19: =$C19*Z19 -> 0 | AB19: =IF(PRAZO!M17>0,1/PRAZO!$AY17,0) -> 0 | AC19: =$C19*AB19 -> 0 | AD19: =IF(PRAZO!N17>0,1/PRAZO!$AY17,0) -> 0 | AE19: =$C19*AD19 -> 0 | AF19: =IF(PRAZO!O17>0,1/PRAZO!$AY17,0) -> 0 | AG19: =$C19*AF19 -> 0 | AH19: =IF(PRAZO!P17>0,1/PRAZO!$AY17,0) -> 0 | AI19: =$C19*AH19 -> 0 | AJ19: =IF(PRAZO!Q17>0,1/PRAZO!$AY17,0) -> 0 | AK19: =$C19*AJ19 -> 0 | AL19: =IF(PRAZO!R17>0,1/PRAZO!$AY17,0) -> 0 | AM19: =$C19*AL19 -> 0 | AN19: =IF(PRAZO!S17>0,1/PRAZO!$AY17,0) -> 0 | AO19: =$C19*AN19 -> 0 | AP19: =IF(PRAZO!T17>0,1/PRAZO!$AY17,0) -> 0 | AQ19: =$C19*AP19 -> 0 | AR19: =IF(PRAZO!U17>0,1/PRAZO!$AY17,0) -> 0 | AS19: =$C19*AR19 -> 0 | AT19: =IF(PRAZO!V17>0,1/PRAZO!$AY17,0) -> 0 | AU19: =$C19*AT19 -> 0 | AV19: =IF(PRAZO!W17>0,1/PRAZO!$AY17,0) -> 0 | AW19: =$C19*AV19 -> 0 | AX19: =IF(PRAZO!X17>0,1/PRAZO!$AY17,0) -> 0 | AY19: =$C19*AX19 -> 0 | AZ19: =IF(PRAZO!Y17>0,1/PRAZO!$AY17,0) -> 0 | BA19: =$C19*AZ19 -> 0 | BB19: =IF(PRAZO!Z17>0,1/PRAZO!$AY17,0) -> 0 | BC19: =$C19*BB19 -> 0 | BD19: =IF(PRAZO!AA17>0,1/PRAZO!$AY17,0) -> 0 | BE19: =$C19*BD19 -> 0 | BF19: =IF(PRAZO!AB17>0,1/PRAZO!$AY17,0) -> 0 | BG19: =$C19*BF19 -> 0 | BH19: =IF(PRAZO!AC17>0,1/PRAZO!$AY17,0) -> 0 | BI19: =$C19*BH19 -> 0 | BJ19: =IF(PRAZO!AD17>0,1/PRAZO!$AY17,0) -> 0 | BK19: =$C19*BJ19 -> 0 | BL19: =IF(PRAZO!AE17>0,1/PRAZO!$AY17,0) -> 0.066666667 | BM19: =$C19*BL19 -> 81678.297 | BN19: =IF(PRAZO!AF17>0,1/PRAZO!$AY17,0) -> 0.066666667 | BO19: =$C19*BN19 -> 81678.297 | BP19: =IF(PRAZO!AG17>0,1/PRAZO!$AY17,0) -> 0.066666667 | BQ19: =$C19*BP19 -> 81678.297 | BR19: =IF(PRAZO!AH17>0,1/PRAZO!$AY17,0) -> 0.066666667 | BS19: =$C19*BR19 -> 81678.297 | BT19: =IF(PRAZO!AI17>0,1/PRAZO!$AY17,0) -> 0.066666667 | BU19: =$C19*BT19 -> 81678.297 | BV19: =IF(PRAZO!AJ17>0,1/PRAZO!$AY17,0) -> 0.066666667 | BW19: =$C19*BV19 -> 81678.297 | BX19: =IF(PRAZO!AK17>0,1/PRAZO!$AY17,0) -> 0.066666667 | BY19: =$C19*BX19 -> 81678.297 | BZ19: =IF(PRAZO!AL17>0,1/PRAZO!$AY17,0) -> 0.066666667 | CA19: =$C19*BZ19 -> 81678.297 | CB19: =IF(PRAZO!AM17>0,1/PRAZO!$AY17,0) -> 0.066666667 | CC19: =$C19*CB19 -> 81678.297 | CD19: =IF(PRAZO!AN17>0,1/PRAZO!$AY17,0) -> 0.066666667 | CE19: =$C19*CD19 -> 81678.297 | CF19: =IF(PRAZO!AO17>0,1/PRAZO!$AY17,0) -> 0.066666667 | CG19: =$C19*CF19 -> 81678.297 | CH19: =IF(PRAZO!AP17>0,1/PRAZO!$AY17,0) -> 0.066666667 | CI19: =$C19*CH19 -> 81678.297 | CJ19: =IF(PRAZO!AQ17>0,1/PRAZO!$AY17,0) -> 0.066666667 | CK19: =$C19*CJ19 -> 81678.297 | CL19: =IF(PRAZO!AR17>0,1/PRAZO!$AY17,0) -> 0.066666667 | CM19: =$C19*CL19 -> 81678.297 | CN19: =IF(PRAZO!AS17>0,1/PRAZO!$AY17,0) -> 0.066666667 | CO19: =$C19*CN19 -> 81678.297 | CP19: =IF(PRAZO!AT17>0,1/PRAZO!$AY17,0) -> 0 | CQ19: =$C19*CP19 -> 0 | CR19: =IF(PRAZO!AU17>0,1/PRAZO!$AY17,0) -> 0 | CS19: =$C19*CR19 -> 0 | CT19: =IF(PRAZO!AV17>0,1/PRAZO!$AY17,0) -> 0 | CU19: =$C19*CT19 -> 0 | CV19: =IF(PRAZO!AW17>0,1/PRAZO!$AY17,0) -> 0 | CW19: =$C19*CV19 -> 0 | CX19: =IF(PRAZO!AX17>0,1/PRAZO!$AY17,0) -> 0 | CY19: =$C19*CX19 -> 0
B20: PINTURA INTERNA | C20: =SUM([1]RESUMO!$B$14:$C$14) -> 760611.38 | D20: =C20/$C$28 -> 0.02133368 | E20: =C20/'DISTRIBUIÇÃO CUSTO'!C$32 -> 34.668884 | F20: =SUM(H20,J20,L20,N20,P20,R20,T20,V20,X20,Z20,AB20,AD20,AF20,AH20,AJ20,AL20,,AN20,AP20,AR20,AT20,AV20,AX20,AZ20,BB20,BD20,BF20,BH20,BJ20,BL20,BN20,BP20,BR20,BT20,BV20,BX20,BZ20,CB20,CD20,CF20,CH20,CJ20,CL20,CN20,CP20,CR20,CT20,CV20,CX20,) -> 1 | H20: =IF(PRAZO!C18>0,1/PRAZO!$AY18,0) -> 0 | I20: =$C20*H20 -> 0 | J20: =IF(PRAZO!D18>0,1/PRAZO!$AY18,0) -> 0 | K20: =$C20*J20 -> 0 | L20: =IF(PRAZO!E18>0,1/PRAZO!$AY18,0) -> 0 | M20: =$C20*L20 -> 0 | N20: =IF(PRAZO!F18>0,1/PRAZO!$AY18,0) -> 0 | O20: =$C20*N20 -> 0 | P20: =IF(PRAZO!G18>0,1/PRAZO!$AY18,0) -> 0 | Q20: =$C20*P20 -> 0 | R20: =IF(PRAZO!H18>0,1/PRAZO!$AY18,0) -> 0 | S20: =$C20*R20 -> 0 | T20: =IF(PRAZO!I18>0,1/PRAZO!$AY18,0) -> 0 | U20: =$C20*T20 -> 0 | V20: =IF(PRAZO!J18>0,1/PRAZO!$AY18,0) -> 0 | W20: =$C20*V20 -> 0 | X20: =IF(PRAZO!K18>0,1/PRAZO!$AY18,0) -> 0 | Y20: =$C20*X20 -> 0 | Z20: =IF(PRAZO!L18>0,1/PRAZO!$AY18,0) -> 0 | AA20: =$C20*Z20 -> 0 | AB20: =IF(PRAZO!M18>0,1/PRAZO!$AY18,0) -> 0 | AC20: =$C20*AB20 -> 0 | AD20: =IF(PRAZO!N18>0,1/PRAZO!$AY18,0) -> 0 | AE20: =$C20*AD20 -> 0 | AF20: =IF(PRAZO!O18>0,1/PRAZO!$AY18,0) -> 0 | AG20: =$C20*AF20 -> 0 | AH20: =IF(PRAZO!P18>0,1/PRAZO!$AY18,0) -> 0 | AI20: =$C20*AH20 -> 0 | AJ20: =IF(PRAZO!Q18>0,1/PRAZO!$AY18,0) -> 0 | AK20: =$C20*AJ20 -> 0 | AL20: =IF(PRAZO!R18>0,1/PRAZO!$AY18,0) -> 0 | AM20: =$C20*AL20 -> 0 | AN20: =IF(PRAZO!S18>0,1/PRAZO!$AY18,0) -> 0 | AO20: =$C20*AN20 -> 0 | AP20: =IF(PRAZO!T18>0,1/PRAZO!$AY18,0) -> 0 | AQ20: =$C20*AP20 -> 0 | AR20: =IF(PRAZO!U18>0,1/PRAZO!$AY18,0) -> 0 | AS20: =$C20*AR20 -> 0 | AT20: =IF(PRAZO!V18>0,1/PRAZO!$AY18,0) -> 0 | AU20: =$C20*AT20 -> 0 | AV20: =IF(PRAZO!W18>0,1/PRAZO!$AY18,0) -> 0 | AW20: =$C20*AV20 -> 0 | AX20: =IF(PRAZO!X18>0,1/PRAZO!$AY18,0) -> 0 | AY20: =$C20*AX20 -> 0 | AZ20: =IF(PRAZO!Y18>0,1/PRAZO!$AY18,0) -> 0 | BA20: =$C20*AZ20 -> 0 | BB20: =IF(PRAZO!Z18>0,1/PRAZO!$AY18,0) -> 0 | BC20: =$C20*BB20 -> 0 | BD20: =IF(PRAZO!AA18>0,1/PRAZO!$AY18,0) -> 0 | BE20: =$C20*BD20 -> 0 | BF20: =IF(PRAZO!AB18>0,1/PRAZO!$AY18,0) -> 0 | BG20: =$C20*BF20 -> 0 | BH20: =IF(PRAZO!AC18>0,1/PRAZO!$AY18,0) -> 0 | BI20: =$C20*BH20 -> 0 | BJ20: =IF(PRAZO!AD18>0,1/PRAZO!$AY18,0) -> 0 | BK20: =$C20*BJ20 -> 0 | BL20: =IF(PRAZO!AE18>0,1/PRAZO!$AY18,0) -> 0 | BM20: =$C20*BL20 -> 0 | BN20: =IF(PRAZO!AF18>0,1/PRAZO!$AY18,0) -> 0 | BO20: =$C20*BN20 -> 0 | BP20: =IF(PRAZO!AG18>0,1/PRAZO!$AY18,0) -> 0 | BQ20: =$C20*BP20 -> 0 | BR20: =IF(PRAZO!AH18>0,1/PRAZO!$AY18,0) -> 0 | BS20: =$C20*BR20 -> 0 | BT20: =IF(PRAZO!AI18>0,1/PRAZO!$AY18,0) -> 0.071428571 | BU20: =$C20*BT20 -> 54329.385 | BV20: =IF(PRAZO!AJ18>0,1/PRAZO!$AY18,0) -> 0.071428571 | BW20: =$C20*BV20 -> 54329.385 | BX20: =IF(PRAZO!AK18>0,1/PRAZO!$AY18,0) -> 0.071428571 | BY20: =$C20*BX20 -> 54329.385 | BZ20: =IF(PRAZO!AL18>0,1/PRAZO!$AY18,0) -> 0.071428571 | CA20: =$C20*BZ20 -> 54329.385 | CB20: =IF(PRAZO!AM18>0,1/PRAZO!$AY18,0) -> 0.071428571 | CC20: =$C20*CB20 -> 54329.385 | CD20: =IF(PRAZO!AN18>0,1/PRAZO!$AY18,0) -> 0.071428571 | CE20: =$C20*CD20 -> 54329.385 | CF20: =IF(PRAZO!AO18>0,1/PRAZO!$AY18,0) -> 0.071428571 | CG20: =$C20*CF20 -> 54329.385 | CH20: =IF(PRAZO!AP18>0,1/PRAZO!$AY18,0) -> 0.071428571 | CI20: =$C20*CH20 -> 54329.385 | CJ20: =IF(PRAZO!AQ18>0,1/PRAZO!$AY18,0) -> 0.071428571 | CK20: =$C20*CJ20 -> 54329.385 | CL20: =IF(PRAZO!AR18>0,1/PRAZO!$AY18,0) -> 0.071428571 | CM20: =$C20*CL20 -> 54329.385 | CN20: =IF(PRAZO!AS18>0,1/PRAZO!$AY18,0) -> 0.071428571 | CO20: =$C20*CN20 -> 54329.385 | CP20: =IF(PRAZO!AT18>0,1/PRAZO!$AY18,0) -> 0.071428571 | CQ20: =$C20*CP20 -> 54329.385 | CR20: =IF(PRAZO!AU18>0,1/PRAZO!$AY18,0) -> 0.071428571 | CS20: =$C20*CR20 -> 54329.385 | CT20: =IF(PRAZO!AV18>0,1/PRAZO!$AY18,0) -> 0.071428571 | CU20: =$C20*CT20 -> 54329.385 | CV20: =IF(PRAZO!AW18>0,1/PRAZO!$AY18,0) -> 0 | CW20: =$C20*CV20 -> 0 | CX20: =IF(PRAZO!AX18>0,1/PRAZO!$AY18,0) -> 0 | CY20: =$C20*CX20 -> 0
B21: ESQUADRIAS, VIDROS E FERRAGENS | C21: =SUM([1]RESUMO!$B$15:$C$15) -> 2428604.4 | D21: =C21/$C$28 -> 0.068117663 | E21: =C21/'DISTRIBUIÇÃO CUSTO'!C$32 -> 110.69648 | F21: =SUM(H21,J21,L21,N21,P21,R21,T21,V21,X21,Z21,AB21,AD21,AF21,AH21,AJ21,AL21,,AN21,AP21,AR21,AT21,AV21,AX21,AZ21,BB21,BD21,BF21,BH21,BJ21,BL21,BN21,BP21,BR21,BT21,BV21,BX21,BZ21,CB21,CD21,CF21,CH21,CJ21,CL21,CN21,CP21,CR21,CT21,CV21,CX21,) -> 1 | H21: =IF(PRAZO!C19>0,1/PRAZO!$AY19,0) -> 0 | I21: =$C21*H21 -> 0 | J21: =IF(PRAZO!D19>0,1/PRAZO!$AY19,0) -> 0 | K21: =$C21*J21 -> 0 | L21: =IF(PRAZO!E19>0,1/PRAZO!$AY19,0) -> 0 | M21: =$C21*L21 -> 0 | N21: =IF(PRAZO!F19>0,1/PRAZO!$AY19,0) -> 0 | O21: =$C21*N21 -> 0 | P21: =IF(PRAZO!G19>0,1/PRAZO!$AY19,0) -> 0 | Q21: =$C21*P21 -> 0 | R21: =IF(PRAZO!H19>0,1/PRAZO!$AY19,0) -> 0 | S21: =$C21*R21 -> 0 | T21: =IF(PRAZO!I19>0,1/PRAZO!$AY19,0) -> 0 | U21: =$C21*T21 -> 0 | V21: =IF(PRAZO!J19>0,1/PRAZO!$AY19,0) -> 0 | W21: =$C21*V21 -> 0 | X21: =IF(PRAZO!K19>0,1/PRAZO!$AY19,0) -> 0 | Y21: =$C21*X21 -> 0 | Z21: =IF(PRAZO!L19>0,1/PRAZO!$AY19,0) -> 0 | AA21: =$C21*Z21 -> 0 | AB21: =IF(PRAZO!M19>0,1/PRAZO!$AY19,0) -> 0 | AC21: =$C21*AB21 -> 0 | AD21: =IF(PRAZO!N19>0,1/PRAZO!$AY19,0) -> 0 | AE21: =$C21*AD21 -> 0 | AF21: =IF(PRAZO!O19>0,1/PRAZO!$AY19,0) -> 0 | AG21: =$C21*AF21 -> 0 | AH21: =IF(PRAZO!P19>0,1/PRAZO!$AY19,0) -> 0 | AI21: =$C21*AH21 -> 0 | AJ21: =IF(PRAZO!Q19>0,1/PRAZO!$AY19,0) -> 0 | AK21: =$C21*AJ21 -> 0 | AL21: =IF(PRAZO!R19>0,1/PRAZO!$AY19,0) -> 0 | AM21: =$C21*AL21 -> 0 | AN21: =IF(PRAZO!S19>0,1/PRAZO!$AY19,0) -> 0 | AO21: =$C21*AN21 -> 0 | AP21: =IF(PRAZO!T19>0,1/PRAZO!$AY19,0) -> 0 | AQ21: =$C21*AP21 -> 0 | AR21: =IF(PRAZO!U19>0,1/PRAZO!$AY19,0) -> 0 | AS21: =$C21*AR21 -> 0 | AT21: =IF(PRAZO!V19>0,1/PRAZO!$AY19,0) -> 0 | AU21: =$C21*AT21 -> 0 | AV21: =IF(PRAZO!W19>0,1/PRAZO!$AY19,0) -> 0 | AW21: =$C21*AV21 -> 0 | AX21: =IF(PRAZO!X19>0,1/PRAZO!$AY19,0) -> 0 | AY21: =$C21*AX21 -> 0 | AZ21: =IF(PRAZO!Y19>0,1/PRAZO!$AY19,0) -> 0 | BA21: =$C21*AZ21 -> 0 | BB21: =IF(PRAZO!Z19>0,1/PRAZO!$AY19,0) -> 0.071428571 | BC21: =$C21*BB21 -> 173471.75 | BD21: =IF(PRAZO!AA19>0,1/PRAZO!$AY19,0) -> 0.071428571 | BE21: =$C21*BD21 -> 173471.75 | BF21: =IF(PRAZO!AB19>0,1/PRAZO!$AY19,0) -> 0.071428571 | BG21: =$C21*BF21 -> 173471.75 | BH21: =IF(PRAZO!AC19>0,1/PRAZO!$AY19,0) -> 0.071428571 | BI21: =$C21*BH21 -> 173471.75 | BJ21: =IF(PRAZO!AD19>0,1/PRAZO!$AY19,0) -> 0.071428571 | BK21: =$C21*BJ21 -> 173471.75 | BL21: =IF(PRAZO!AE19>0,1/PRAZO!$AY19,0) -> 0.071428571 | BM21: =$C21*BL21 -> 173471.75 | BN21: =IF(PRAZO!AF19>0,1/PRAZO!$AY19,0) -> 0.071428571 | BO21: =$C21*BN21 -> 173471.75 | BP21: =IF(PRAZO!AG19>0,1/PRAZO!$AY19,0) -> 0.071428571 | BQ21: =$C21*BP21 -> 173471.75 | BR21: =IF(PRAZO!AH19>0,1/PRAZO!$AY19,0) -> 0.071428571 | BS21: =$C21*BR21 -> 173471.75 | BT21: =IF(PRAZO!AI19>0,1/PRAZO!$AY19,0) -> 0.071428571 | BU21: =$C21*BT21 -> 173471.75 | BV21: =IF(PRAZO!AJ19>0,1/PRAZO!$AY19,0) -> 0.071428571 | BW21: =$C21*BV21 -> 173471.75 | BX21: =IF(PRAZO!AK19>0,1/PRAZO!$AY19,0) -> 0.071428571 | BY21: =$C21*BX21 -> 173471.75 | BZ21: =IF(PRAZO!AL19>0,1/PRAZO!$AY19,0) -> 0.071428571 | CA21: =$C21*BZ21 -> 173471.75 | CB21: =IF(PRAZO!AM19>0,1/PRAZO!$AY19,0) -> 0.071428571 | CC21: =$C21*CB21 -> 173471.75 | CD21: =IF(PRAZO!AN19>0,1/PRAZO!$AY19,0) -> 0 | CE21: =$C21*CD21 -> 0 | CF21: =IF(PRAZO!AO19>0,1/PRAZO!$AY19,0) -> 0 | CG21: =$C21*CF21 -> 0 | CH21: =IF(PRAZO!AP19>0,1/PRAZO!$AY19,0) -> 0 | CI21: =$C21*CH21 -> 0 | CJ21: =IF(PRAZO!AQ19>0,1/PRAZO!$AY19,0) -> 0 | CK21: =$C21*CJ21 -> 0 | CL21: =IF(PRAZO!AR19>0,1/PRAZO!$AY19,0) -> 0 | CM21: =$C21*CL21 -> 0 | CN21: =IF(PRAZO!AS19>0,1/PRAZO!$AY19,0) -> 0 | CO21: =$C21*CN21 -> 0 | CP21: =IF(PRAZO!AT19>0,1/PRAZO!$AY19,0) -> 0 | CQ21: =$C21*CP21 -> 0 | CR21: =IF(PRAZO!AU19>0,1/PRAZO!$AY19,0) -> 0 | CS21: =$C21*CR21 -> 0 | CT21: =IF(PRAZO!AV19>0,1/PRAZO!$AY19,0) -> 0 | CU21: =$C21*CT21 -> 0 | CV21: =IF(PRAZO!AW19>0,1/PRAZO!$AY19,0) -> 0 | CW21: =$C21*CV21 -> 0 | CX21: =IF(PRAZO!AX19>0,1/PRAZO!$AY19,0) -> 0 | CY21: =$C21*CX21 -> 0
B22: REVESTIMENTOS E ACABAMENTOS DE FACHADA | C22: =SUM([1]RESUMO!$B$16:$C$16) -> 1817850.7 | D22: =C22/$C$28 -> 0.0509872 | E22: =C22/'DISTRIBUIÇÃO CUSTO'!C$32 -> 82.858152 | F22: =SUM(H22,J22,L22,N22,P22,R22,T22,V22,X22,Z22,AB22,AD22,AF22,AH22,AJ22,AL22,,AN22,AP22,AR22,AT22,AV22,AX22,AZ22,BB22,BD22,BF22,BH22,BJ22,BL22,BN22,BP22,BR22,BT22,BV22,BX22,BZ22,CB22,CD22,CF22,CH22,CJ22,CL22,CN22,CP22,CR22,CT22,CV22,CX22,) -> 1 | H22: =IF(PRAZO!C20>0,1/PRAZO!$AY20,0) -> 0 | I22: =$C22*H22 -> 0 | J22: =IF(PRAZO!D20>0,1/PRAZO!$AY20,0) -> 0 | K22: =$C22*J22 -> 0 | L22: =IF(PRAZO!E20>0,1/PRAZO!$AY20,0) -> 0 | M22: =$C22*L22 -> 0 | N22: =IF(PRAZO!F20>0,1/PRAZO!$AY20,0) -> 0 | O22: =$C22*N22 -> 0 | P22: =IF(PRAZO!G20>0,1/PRAZO!$AY20,0) -> 0 | Q22: =$C22*P22 -> 0 | R22: =IF(PRAZO!H20>0,1/PRAZO!$AY20,0) -> 0 | S22: =$C22*R22 -> 0 | T22: =IF(PRAZO!I20>0,1/PRAZO!$AY20,0) -> 0 | U22: =$C22*T22 -> 0 | V22: =IF(PRAZO!J20>0,1/PRAZO!$AY20,0) -> 0 | W22: =$C22*V22 -> 0 | X22: =IF(PRAZO!K20>0,1/PRAZO!$AY20,0) -> 0 | Y22: =$C22*X22 -> 0 | Z22: =IF(PRAZO!L20>0,1/PRAZO!$AY20,0) -> 0 | AA22: =$C22*Z22 -> 0 | AB22: =IF(PRAZO!M20>0,1/PRAZO!$AY20,0) -> 0 | AC22: =$C22*AB22 -> 0 | AD22: =IF(PRAZO!N20>0,1/PRAZO!$AY20,0) -> 0 | AE22: =$C22*AD22 -> 0 | AF22: =IF(PRAZO!O20>0,1/PRAZO!$AY20,0) -> 0 | AG22: =$C22*AF22 -> 0 | AH22: =IF(PRAZO!P20>0,1/PRAZO!$AY20,0) -> 0 | AI22: =$C22*AH22 -> 0 | AJ22: =IF(PRAZO!Q20>0,1/PRAZO!$AY20,0) -> 0 | AK22: =$C22*AJ22 -> 0 | AL22: =IF(PRAZO!R20>0,1/PRAZO!$AY20,0) -> 0 | AM22: =$C22*AL22 -> 0 | AN22: =IF(PRAZO!S20>0,1/PRAZO!$AY20,0) -> 0 | AO22: =$C22*AN22 -> 0 | AP22: =IF(PRAZO!T20>0,1/PRAZO!$AY20,0) -> 0 | AQ22: =$C22*AP22 -> 0 | AR22: =IF(PRAZO!U20>0,1/PRAZO!$AY20,0) -> 0 | AS22: =$C22*AR22 -> 0 | AT22: =IF(PRAZO!V20>0,1/PRAZO!$AY20,0) -> 0 | AU22: =$C22*AT22 -> 0 | AV22: =IF(PRAZO!W20>0,1/PRAZO!$AY20,0) -> 0 | AW22: =$C22*AV22 -> 0 | AX22: =IF(PRAZO!X20>0,1/PRAZO!$AY20,0) -> 0 | AY22: =$C22*AX22 -> 0 | AZ22: =IF(PRAZO!Y20>0,1/PRAZO!$AY20,0) -> 0 | BA22: =$C22*AZ22 -> 0 | BB22: =IF(PRAZO!Z20>0,1/PRAZO!$AY20,0) -> 0 | BC22: =$C22*BB22 -> 0 | BD22: =IF(PRAZO!AA20>0,1/PRAZO!$AY20,0) -> 0 | BE22: =$C22*BD22 -> 0 | BF22: =IF(PRAZO!AB20>0,1/PRAZO!$AY20,0) -> 0 | BG22: =$C22*BF22 -> 0 | BH22: =IF(PRAZO!AC20>0,1/PRAZO!$AY20,0) -> 0 | BI22: =$C22*BH22 -> 0 | BJ22: =IF(PRAZO!AD20>0,1/PRAZO!$AY20,0) -> 0 | BK22: =$C22*BJ22 -> 0 | BL22: =IF(PRAZO!AE20>0,1/PRAZO!$AY20,0) -> 0.083333333 | BM22: =$C22*BL22 -> 151487.56 | BN22: =IF(PRAZO!AF20>0,1/PRAZO!$AY20,0) -> 0.083333333 | BO22: =$C22*BN22 -> 151487.56 | BP22: =IF(PRAZO!AG20>0,1/PRAZO!$AY20,0) -> 0.083333333 | BQ22: =$C22*BP22 -> 151487.56 | BR22: =IF(PRAZO!AH20>0,1/PRAZO!$AY20,0) -> 0.083333333 | BS22: =$C22*BR22 -> 151487.56 | BT22: =IF(PRAZO!AI20>0,1/PRAZO!$AY20,0) -> 0.083333333 | BU22: =$C22*BT22 -> 151487.56 | BV22: =IF(PRAZO!AJ20>0,1/PRAZO!$AY20,0) -> 0.083333333 | BW22: =$C22*BV22 -> 151487.56 | BX22: =IF(PRAZO!AK20>0,1/PRAZO!$AY20,0) -> 0.083333333 | BY22: =$C22*BX22 -> 151487.56 | BZ22: =IF(PRAZO!AL20>0,1/PRAZO!$AY20,0) -> 0.083333333 | CA22: =$C22*BZ22 -> 151487.56 | CB22: =IF(PRAZO!AM20>0,1/PRAZO!$AY20,0) -> 0.083333333 | CC22: =$C22*CB22 -> 151487.56 | CD22: =IF(PRAZO!AN20>0,1/PRAZO!$AY20,0) -> 0.083333333 | CE22: =$C22*CD22 -> 151487.56 | CF22: =IF(PRAZO!AO20>0,1/PRAZO!$AY20,0) -> 0.083333333 | CG22: =$C22*CF22 -> 151487.56 | CH22: =IF(PRAZO!AP20>0,1/PRAZO!$AY20,0) -> 0.083333333 | CI22: =$C22*CH22 -> 151487.56 | CJ22: =IF(PRAZO!AQ20>0,1/PRAZO!$AY20,0) -> 0 | CK22: =$C22*CJ22 -> 0 | CL22: =IF(PRAZO!AR20>0,1/PRAZO!$AY20,0) -> 0 | CM22: =$C22*CL22 -> 0 | CN22: =IF(PRAZO!AS20>0,1/PRAZO!$AY20,0) -> 0 | CO22: =$C22*CN22 -> 0 | CP22: =IF(PRAZO!AT20>0,1/PRAZO!$AY20,0) -> 0 | CQ22: =$C22*CP22 -> 0 | CR22: =IF(PRAZO!AU20>0,1/PRAZO!$AY20,0) -> 0 | CS22: =$C22*CR22 -> 0 | CT22: =IF(PRAZO!AV20>0,1/PRAZO!$AY20,0) -> 0 | CU22: =$C22*CT22 -> 0 | CV22: =IF(PRAZO!AW20>0,1/PRAZO!$AY20,0) -> 0 | CW22: =$C22*CV22 -> 0 | CX22: =IF(PRAZO!AX20>0,1/PRAZO!$AY20,0) -> 0 | CY22: =$C22*CX22 -> 0
