Workbook
Name \0: #REF!
Name \0: #REF!
Name \0: #REF!
Name \0: #REF!
Name \0: #REF!
Name \0: #REF!
Name \0: #REF!
Name \0: #REF!
Name \1: #REF!
Name \a: #REF!
Name \a: #REF!
Name \a: #REF!
Name \b: #REF!
Name \c: #REF!
Name \d: #REF!
Name \e: #REF!
Name \i: #REF!
Name \J: #REF!
Name \k: #REF!
Name \l: #N/A
Name \m: #REF!
Name \m: #REF!
Name \m: #REF!
Name \o: #REF!
Name \o: #REF!
Name \p: #REF!
Name \r: #REF!
Name \T: #REF!
Name \z: #REF!
Name \z: #REF!
Name _\0: #REF!
Name _\1: #REF!
Name _\a: #REF!
Name _\b: #REF!
Name _\c: #REF!
Name _\d: #REF!
Name _\e: #REF!
Name _\i: #REF!
Name _\J: #REF!
Name _\k: #REF!
Name _\l: #N/A
Name _\m: #REF!
Name _\o: #REF!
Name _\p: #REF!
Name _\r: #REF!
Name _\T: #REF!
Name _\z: #REF!
Name ______ACR10: #REF!
Name ______ACR10: #REF!
Name ______ACR15: #REF!
Name ______ACR15: #REF!
Name ______acr20: #REF!
Name ______acr20: #REF!
Name ______acr5: #REF!
Name ______ARQ1: #REF!
Name ______QT100: #REF!
Name ______QT2: #REF!
Name ______QT3: #REF!
Name ______QT4: #REF!
Name ______QT50: #REF!

Sheet Obra 
C1: DADOS DO EMPREENDIMENTO
B2: Projeto: | C2: Jurerê Blue | E2: ENDEREÇO DA OBRA: | F2: RUA PROFESSOR RENATO BARBOSA | JURERÊ | FLORIANÓPOLIS
B3: Empresa: | C3: GRUPO EIS | E3: Cidade/ES: | F3: Florianópolis /SC
B4: Revisão: | C4: R00 -Valquiria | E4: CNPJ: | F4: 51.382.701/0001-73
B6: Pazo de Obra: | C6: 36 | E6: Nº Unid. Residenciais: | F6: 66 | H6: Nº Elevadores: | I6: 2 | K6: Imagens
B8: Área do Terreno: | C8: 720 | E8: Nº Unid. Comerciais: | F8: 3
B10: Área Construída: | C10: =SUM($D$21:$D$36) -> 5347.86 | E10: Nº Pavimentos: | F10: =COUNTA(C21:C35) -> 14
B12: Área Privativa: | C12: =SUM($E$21:$E$35) -> 2972.4 | E12: Total de Dormitórios: | F12: =SUM(J20:J36) -> 77
B14: Área de Lazer: | C14: =SUM(E39:E46,E51:E56,E63:E68) -> 813.67 | E14: Nº Subsolos: | F14: 1
B16: Área Comercial: | C16: 311.82 | E16: Nº Vagas: | F16: 14
B18: Nº Banheiros: | C18: =SUM(H20:H36) -> 81 | E18: Nº Churrasqueiras: | F18: =SUM(I20:I36) -> 0
B20: Torre | C20: Pavimento | D20: Área | E20: Área Privativa | F20: Perímetro | G20: Pé direito | H20: Banheiros | I20: Churrasqueira | J20: Quartos | K20: Ventokit | L20: Ar - Condicionado Ponto | M20: Ar - Condicionado Equipamento | N20: Ralos | O20: Nº Unidades
B21: Torre A | C21: SUBSOLO 01 | D21: 624 | E21: 150 | F21: 99.93 | G21: 3.06 | N21: 13
B22: Torre A | C22: 1º PAV-TÉRREO | D22: 593.67 | F22: 87.82 | G22: 3.24 | H22: 4 | K22: =H22 -> 4 | L22: 4 | M22: 4 | N22: 7 | O22: 3
B23: Torre A | C23: 1º PAV-MEZANINO | D23: 301.01 | F23: 87.82 | G23: 3.24 | N23: 3
B24: Torre A | C24: 2º PAVIMENTO | D24: 464.43 | E24: 403.2 | F24: 93.9 | G24: 3.24 | H24: =O24 -> 11 | J24: =O24 -> 11 | K24: =O24 -> 11 | L24: =O24 -> 11 | N24: =4*O24 -> 44 | O24: 11
B25: Torre A | C25: 3º PAVIMENTO | D25: 464.43 | E25: 403.2 | F25: 93.9 | G25: 3.24 | H25: =O25 -> 11 | J25: =O25 -> 11 | K25: =O25 -> 11 | L25: =O25 -> 11 | N25: =4*O25 -> 44 | O25: 11
B26: Torre A | C26: 4º PAVIMENTO | D26: 464.43 | E26: 403.2 | F26: 93.9 | G26: 3.24 | H26: =O26 -> 11 | J26: =O26 -> 11 | K26: =O26 -> 11 | L26: =O26 -> 11 | N26: =4*O26 -> 44 | O26: 11
B27: Torre A | C27: 5º PAVIMENTO | D27: 464.43 | E27: 403.2 | F27: 93.9 | G27: 3.24 | H27: =O27 -> 11 | J27: =O27 -> 11 | K27: =O27 -> 11 | L27: =O27 -> 11 | N27: =4*O27 -> 44 | O27: 11
B28: Torre A | C28: 6º PAVIMENTO | D28: 464.43 | E28: 403.2 | F28: 93.9 | G28: 3.24 | H28: =O28 -> 11 | J28: =O28 -> 11 | K28: =O28 -> 11 | L28: =O28 -> 11 | N28: =4*O28 -> 44 | O28: 11
B29: Torre A | C29: 7º PAVIMENTO | D29: 464.43 | E29: 403.2 | F29: 93.9 | G29: 3.24 | H29: =O29 -> 11 | J29: =O29 -> 11 | K29: =O29 -> 11 | L29: =O29 -> 11 | N29: =4*O29 -> 44 | O29: 11
B30: Torre A | C30: 8º PAVIMENTO | D30: 464.43 | E30: 403.2 | F30: 93.9 | G30: 3.24 | H30: =O30 -> 11 | J30: =O30 -> 11 | K30: =O30 -> 11 | L30: =O30 -> 11 | N30: =4*O30 -> 44 | O30: 11
B31: Torre A | C31: PLANO COBERTURA | D31: 425.51 | F31: 93.9 | G31: 3.24 | L31: 3 | M31: 3 | N31: 5
B32: Torre A | C32: BARRILETE | D32: 61.02 | F32: 37.6 | G32: 3.24
B33: Torre A | C33: CASA DE MÁQUINAS | D33: 30.62 | F33: 37.6 | G33: 1.6
B34: Torre A | C34: RESERVATÓRIO | D34: 61.02 | F34: 37.6 | G34: 2
B35: Torre A
B38: Torre | C38: Pavimento | D38: Descrição | E38: Área | G38: QUADRO DE ÁREAS
B39: Torre A | C39: SUBSOLO 01 | D39: DESCOMPRESSÃO FUNCIONÁRIO | E39: 11.27
B40: Torre A | C40: SUBSOLO 01 | D40: REFEITÓRIO E ÁREA DE DESCANSO | E40: 24.16
B41: Torre A | C41: SUBSOLO 01 | D41: BANHEIRO E VESTIÁRIO | E41: 5.57
B42: Torre A | C42: SUBSOLO 01 | D42: BANHEIRO E VESTIÁRIO | E42: 5.4
B43: Torre A | C43: SUBSOLO 01 | D43: DEPÓSITO BANCADA | E43: 12.53
B44: Torre A | C44: SUBSOLO 01 | D44: ROUPA LIMPA | E44: 13.65
B45: Torre A | C45: SUBSOLO 01 | D45: ROUPA SUJA | E45: 14.74
B46: Torre A | C46: SUBSOLO 01 | D46: DEPÓSITO DE LIXO | E46: 15.04
B47: Torre A | C47: SUBSOLO 01 | D47: CISTERNA ENTERRADA | E47: 69
B48: Torre A | C48: 1º PAV-TÉRREO | D48: SUBESTAÇÃO | E48: 2.6
B49: Torre A | C49: 1º PAV-TÉRREO | D49: GLP | E49: 2.52
B50: Torre A | C50: 1º PAV-TÉRREO | D50: GLP | E50: 3.33
...

Sheet DADOS_INICIAIS
A1: Obra | B1: Zapata
A2: Empresa | B2: Ckock
A3: Revisão | B3: R00
A4: Arquitetura base | B4: HPSC0457
A5: DADOS OBRA
B7: Descrição | C7: Identificador | D7: Unidade | E7: Quantidade
B8: ÁREA DO TERRENO | C8: AT | D8: M2 | E8: ='Obra '!C8 -> 720
B9: ÁREA TOTAL CONSTRUÍDA | C9: AC | D9: M2 | E9: ='Obra '!C10 -> 5347.86
B10: UNIDADES RESIDENCIAIS | C10: UR | D10: UN | E10: ='Obra '!F6 -> 66
B11: Dormitórios | C11: dorm | D11: UN | E11: ='Obra '!F12 -> 77
B12: Banheiros | C12: ban | D12: UN | E12: ='Obra '!$C$18 -> 81
B13: UNIDADES COMERCIAIS | C13: UC | D13: UN | E13: ='Obra '!$F$8 -> 3
B14: Churrasqueiras | C14: CHU | D14: UN | E14: ='Obra '!$F$18 -> 0
B15: NÚMERO TOTAL DE PAVIMENTOS | C15: NP | D15: UN | E15: ='Obra '!$F$10 -> 14
B16: NÚMERO DE PAVIMENTOS TIPO | C16: NPT | D16: UN | E16: =COUNTA('Obra '!C24:C31) -> 8
B17: NÚMERO DE PAVIMENTOS TIPO DIFERENCIADOS | C17: NPD | D17: UN | E17: 1
B18: NÚMERO DE PAVIMENTOS DUPLEX | C18: ND | D18: UN | E18: 0
B19: ÁREA DE PROJEÇÃO DA TORRE | C19: APT | D19: M2 | E19: ='Obra '!D24 -> 464.43
B20: PERÍMETRO DE PROJEÇÃO DA TORRE | C20: PPT | D20: M | E20: ='Obra '!F24 -> 93.9
B21: ÁREA DE LAZER | C21: AL | D21: M2 | E21: ='Obra '!$C$14 -> 813.67
B22: ÁREA DO EMBASAMENTO | C22: AE | D22: M2 | E22: ='Obra '!D22 -> 593.67
B23: ÁREA DE SUBSOLOS | C23: S | D23: M2 | E23: ='Obra '!D21 -> 624
B24: NÚMERO DE SUBSOLOS | C24: NS | D24: UN | E24: 1
B25: ÁREA DE PROJEÇÃO DO EMBASAMENTO | C25: APE | D25: M2 | E25: =E22 -> 593.67
B26: PERÍMETRO DE PROJEÇÃO DE EMBAMENTO | C26: PE | D26: M | E26: ='Obra '!F22 -> 87.82
B27: NÚMERO DE PAVIMENTOS DE EMBASAMENTO | C27: NE | D27: UN | E27: 3

Sheet MOVIMENTAÇÃO_DE_TERRA
A2: MOVIMENTAÇÃO DE TERRA
A3: Data | B3: 45472
A4: Arquivo base | B4: -
A6: ESCAVAÇÃO VERTICAL DE SUBSOLO
A8: Descrição | B8: Área de subsolo (m) | C8: Altura do subsolo (m) | D8: Volume total de escavação (m3) | E8: Preço unitário de escavação (R$ / m3) | F8: Valor total | G8: Observação
A9: Escavação | B9: 623.18 | C9: 3.06 | D9: =C9*B9 -> 1906.9308 | E9: 36.36 | F9: =E9*D9*1.1 -> 76269.604
A10: TOTAL | F10: =SUM(F9:F9) -> 76269.604
A12: REBAIXAMENTO DE LENÇOL FREÁTICO
A14: Descrição | B14: Quantidade (dias) | E14: Preço unitário de rebaixamento (R$ / dias) | F14: Valor total | G14: Observação
A15: Rebaixamento de lençol | B15: =4*30 -> 120 | E15: 200 | F15: =B15*E15*1.1 -> 26400 | G15: 4 meses
A16: TOTAL | F16: =SUM(F15:F15) -> 26400
A18: ESCAVAÇÃO E REATERRO DE VALAS
A20: Descrição | B20: Parâmetro | D20: Volume total de escavação (m3) | E20: Preço unitário (R$ / m3) | F20: Valor total | G20: Observação
A21: Escavação mecanizada para blocos e baldrames | B21: 1.3 | C21: m³ / Vol infra | D21: =B21*INFRAESTRUTURA!D29 -> 501.65115 | E21: 36.36 | F21: =E21*D21*1.1 -> 20064.039
A22: Reaterro para blocos e baldrames | B22: 0.6 | C22: m³ / Vol Escavação | D22: =D21-INFRAESTRUTURA!D29 -> 115.76565 | E22: 14.55 | F22: =E22*D22*1.1 -> 1852.8292
A23: Movimentação de bota-fora | B23: 1.3 | D23: =(D21-D22)*B23 -> 501.65115 | E23: 45.45 | F23: =E23*D23*1.1 -> 25080.049
A24: Movimentação de terra das estacas | B24: 1 | C24: m³ | D24: =INFRAESTRUTURA!D19 -> 623.44906 | E24: 68.18 | F24: =E24*D24*1.1 -> 46757.433
A25: TOTAL | F25: =SUM(F21:F24) -> 93754.351
A27: REGULARIZAÇÃO E APILOAMENTO DE FUNDO DE VALAS
A29: Descrição | B29: Parâmetro | D29: Área de lastro (m²) | E29: Preço unitário (R$ / m2) | F29: Valor total | G29: Observação
A30: Lastro de concreto magto e=5cm | B30: 0.8 | C30: m² / APE | D30: =B30*DADOS_INICIAIS!E25 -> 474.936 | E30: =370*0.1 -> 37 | F30: =E30*D30*1.1 -> 19329.895 | G30: Definição trazida do Celebration da Passe | H30: =F30/DADOS_INICIAIS!E25 -> 32.56
A31: TOTAL | F31: =SUM(F30:F30) -> 19329.895
A33: TOTAL MOVIMENTAÇÃO DE TERRA | F33: =F10+F16+F25+F31 -> 215753.85 | G33: =F33/DADOS_INICIAIS!E9 -> 40.34396

Sheet CONTENÇÕES
J2: Perímetro | K2: Altura | L2: Espessura | M2: Repetição
A3: CONTENÇÃO | I3: Contenção | J3: ='Obra '!F21 -> 99.93 | K3: 7.6 | L3: 0.2 | M3: 1
A4: Data | I4: Viga Coroamento | J4: =J3 -> 99.93 | K4: 0.6 | L4: 0.2 | M4: 1
A5: Arquivo base | I5: Mureta Guia | J5: =J4 -> 99.93 | K5: 1.1 | L5: 0.1 | M5: 2
A7: CORTINA DE ESTACAS
A9: Descrição | B9: Parâmetro | D9: Quantidade | F9: Preço unitário | G9: Valor total
A10: Número de Estacas | B10: 0.15 | C10: un / APE | D10: =B10*DADOS_INICIAIS!E25 -> 89.0505 | E10: un
A11: Estaca Hélice Continua Diâmetro 40 | B11: 0.1 | D11: =B11*$D$10 -> 8.90505 | E11: un
B12: 20 | C12: m/un | D12: =B12*D11 -> 178.101 | E12: m | G12: =F12*D12 -> 0
A13: Estaca Hélice Continua Diâmetro 50 | B13: 0.5 | D13: =B13*$D$10 -> 44.52525 | E13: un
B14: 20 | C14: m/un | D14: =B14*D13 -> 890.505 | E14: m | G14: =F14*D14 -> 0
A15: Estaca Hélice Continua Diâmetro 60 | B15: 0.4 | C15: un / APE | D15: =B15*$D$10 -> 35.6202 | E15: un
B16: 20 | C16: m/un | D16: =B16*D15 -> 712.404 | E16: m | G16: =F16*D16 -> 0
A17: Concreto | B17: =(PI()*0.4^2)/4*D14+(PI()*0.5^2)/4*D16+(PI()*0.6^2)/4*D12 -> 302.14123 | C17: un / APE | D17: =(PI()*0.4^2)/4*D14+(PI()*0.5^2)/4*D16+(PI()*0.6^2)/4*D12 -> 302.14123 | E17: m³ | G17: =F17*D17 -> 0
A18: Armação 6,3mm | B18: 1.6575131 | C18: kg / m³ | D18: =B18*D17 -> 500.80305 | E18: kg | G18: =F18*D18 -> 0
A19: Armação 16mm | B19: 10.178338 | C19: kg / m³ | D19: =B19*D17 -> 3075.2954 | E19: kg | G19: =F19*D19 -> 0
A20: Mobilização | B20: 1 | C20: vb | D20: 1 | E20: vb | G20: =F20*D20 -> 0
A21: TOTAL | G21: =SUM(G10:G20) -> 0
A23: PAREDE DE CONCRETO
A25: Descrição | B25: Parâmetro | D25: Quantidade | F25: Preço unitário | G25: Valor total
A26: Fabricação, montagem e desmontagem de forma para blocos e baldrames resinado | B26: 2.1 | C26: m² / APE | D26: =B26*DADOS_INICIAIS!E25 -> 1246.707 | E26: m² | G26: =F26*D26 -> 0
A27: Concreto | B27: 0.65 | C27: m³ / APE | D27: =B27*DADOS_INICIAIS!E25 -> 385.8855 | E27: m³ | G27: =F27*D27 -> 0
A28: Armação | B28: 110 | C28: kg / m³ | D28: =B28*D27 -> 42447.405 | E28: kg | G28: =F28*D28 -> 0
A29: Mão de obra | B29: =SUPRAESTRUTURA!B15*1.5 -> 360 | C29: R$ / APE | D29: =DADOS_INICIAIS!E25 -> 593.67 | E29: m² | F29: =B29 -> 360 | G29: =F29*D29 -> 213721.2
A30: TOTAL | G30: =SUM(G26:G29) -> 213721.2
A33: PAREDE DIAFRAGMA
A35: Descrição | B35: Parâmetro | D35: Quantidade | F35: Preço unitário | G35: Valor total | H35: MT | I35: MT Total | J35: MO | K35: MO Total
A36: Fabricação, montagem e desmontagem de forma para blocos e baldrames resinado | B36: 2.1 | C36: m² / APE | D36: =SUMPRODUCT(J4:J5,K4:K5,M4:M5) -> 279.804 | E36: m² | F36: 68 | G36: =F36*D36*1.1 -> 20929.339 | H36: =F36*1.1 -> 74.8 | I36: =H36*$D36 -> 20929.339
A37: Concreto | B37: 0.65 | C37: m³ / APE | D37: =SUMPRODUCT(J3:J5,K3:K5,L3:L5,M3:M5) -> 185.8698 | E37: m³ | F37: =(535+45+(1.67*0.6))*1.3 -> 755.3026 | G37: =F37*D37*1.1 -> 154426.74 | H37: =F37*1.1 -> 830.83286 | I37: =H37*$D37 -> 154426.74
A38: Armação | B38: 110 | C38: kg / m³ | D38: =B38*D37 -> 20445.678 | E38: kg | F38: 7.62 | G38: =F38*D38*1.1 -> 171375.67 | H38: =F38*1.1 -> 8.382 | I38: =H38*$D38 -> 171375.67
A39: Mão de obra - SERVIÇO ESPECIALIZADO PAREDE DIAFRAGMA | B39: =SUPRAESTRUTURA!B71*1.5 -> 0 | C39: R$ / APE | D39: =J3*K3 -> 759.468 | E39: m² | F39: 835 | G39: =F39*D39*1.1 -> 697571.36 | J39: =F39*1.1 -> 918.5 | K39: =J39*$D39 -> 697571.36
A40: TOTAL | G40: =SUM(G36:G39) -> 1044303.1
A46: TOTAL INFRAESTRUTURA | G46: =G40 -> 1044303.1 | H46: =G46/DADOS_INICIAIS!E9 -> 195.27495

Sheet INFRAESTRUTURA
A3: INFRAESTRUTURA
A4: Data | B4: 45472
A5: Arquivo base | B5: -
A7: FUNDAÇÃO PROFUNDA
A9: Descrição | B9: Parâmetro | D9: Quantidade | F9: Preço unitário | G9: Valor total | H9: Observação | I9: MT | J9: MT Total | K9: MO | L9: MO Total
A10: Número de Estacas | B10: 0.15 | C10: un / APE | D10: =ROUNDUP(B10*DADOS_INICIAIS!$E$25,0) -> 90 | E10: un | H10: Base obra Trindade Parkside | J10: =I10*$D10 -> 0 | L10: =K10*$D10 -> 0
A11: Estaca Hélice Continua Diâmetro 40 | B11: 0 | D11: =ROUNDUP(B11*$D$10,0) -> 0 | E11: un | J11: =I11*$D11 -> 0 | L11: =K11*$D11 -> 0
B12: 30 | C12: m/un | D12: =B12*D11 -> 0 | E12: m | F12: 70 | G12: =F12*D12*1.1 -> 0 | J12: =I12*$D12 -> 0 | L12: =K12*$D12 -> 0
A13: Estaca Hélice Continua Diâmetro 50 | B13: 0.6 | D13: =ROUNDUP(B13*D10,0) -> 54 | E13: un | J13: =I13*$D13 -> 0 | L13: =K13*$D13 -> 0
B14: 30 | C14: m/un | D14: =B14*D13 -> 1620 | E14: m | F14: 90 | G14: =F14*D14*1.1 -> 160380 | I14: =F14*1.1 -> 99 | J14: =I14*$D14 -> 160380 | L14: =K14*$D14 -> 0
A15: Estaca Hélice Continua Diâmetro 60 | B15: 0.4 | C15: un / APE | D15: =ROUNDUP(B15*$D$10,0) -> 36 | E15: un | J15: =I15*$D15 -> 0 | L15: =K15*$D15 -> 0
B16: 30 | C16: m/un | D16: =B16*D15 -> 1080 | E16: m | F16: 105 | G16: =F16*D16*1.1 -> 124740 | I16: =F16*1.1 -> 115.5 | J16: =I16*$D16 -> 124740 | L16: =K16*$D16 -> 0
A17: Estaca Hélice Continua Diâmetro 80 | B17: 0 | C17: un / APE | D17: =ROUNDUP(B17*$D$10,0) -> 0 | E17: un | J17: =I17*$D17 -> 0 | L17: =K17*$D17 -> 0
B18: 30 | C18: m/un | D18: =B18*D17 -> 0 | E18: m | F18: 120 | G18: =F18*D18*1.1 -> 0 | J18: =I18*$D18 -> 0 | L18: =K18*$D18 -> 0
A19: Concreto (40 Mpa) | B19: 1.3 | C19: perda | D19: =(PI()*((0.4^2)/4)*D12+PI()*((0.5^2)/4)*D14+PI()*((0.6^2)/4)*D16) -> 623.44906 | E19: m³ | F19: =(535+45+(1.67*0.6))*B19 -> 755.3026 | G19: =F19*D19*1.1 -> 517981.97 | I19: =F19*1.1 -> 830.83286 | J19: =I19*$D19 -> 517981.97 | L19: =K19*$D19 -> 0
A20: Armação | B20: 12 | C20: kg / m³ | D20: =B20*D19 -> 7481.3887 | E20: kg | F20: 7.62 | G20: =F20*D20*1.1 -> 62709 | I20: =F20*1.1 -> 8.382 | J20: =I20*$D20 -> 62709 | L20: =K20*$D20 -> 0
A21: Mobilização | B21: 1 | C21: vb | D21: 1 | E21: vb | F21: 12500 | G21: =F21*D21*1.1 -> 13750 | I21: =F21*1.1 -> 13750 | J21: =I21*$D21 -> 13750 | L21: =K21*$D21 -> 0
A22: Apoio e arrasamento de estacas | D22: =D10 -> 90 | E22: un | F22: 300 | G22: =F22*D22*1 -> 27000 | J22: =I22*$D22 -> 0 | K22: =F22 -> 300 | L22: =K22*$D22 -> 27000
A23: TOTAL | G23: =SUM(G10:G22) -> 906560.97
A25: FUNDAÇÃO RASA
A27: Descrição | B27: Parâmetro | D27: Quantidade | F27: Preço unitário | G27: Valor total | H27: Observação | I27: MT | J27: MT Total | K27: MO | L27: MO Total
A28: Fabricação, montagem e desmontagem de forma para blocos e baldrames resinado | B28: 1.1 | C28: m² / APE | D28: =B28*DADOS_INICIAIS!E25 -> 653.037 | E28: m² | F28: 68 | G28: =F28*D28*1.1 -> 48847.168 | I28: =F28*1.1 -> 74.8 | J28: =I28*$D28 -> 48847.168
A29: Concreto (40 Mpa) | B29: 0.65 | C29: m³ / APE | D29: =B29*DADOS_INICIAIS!E25 -> 385.8855 | E29: m³ | F29: =(535+45+(1.67*0.6))*1.05 -> 610.0521 | G29: =F29*D29*1.1 -> 258951.29 | I29: =F29*1.1 -> 671.05731 | J29: =I29*$D29 -> 258951.29
A30: Armação | B30: 110 | C30: kg / m³ | D30: =B30*D29 -> 42447.405 | E30: kg | F30: 7.62 | G30: =F30*D30*1.1 -> 355794.15 | I30: =F30*1.1 -> 8.382 | J30: =I30*$D30 -> 355794.15
A31: Piso de concreto armado | B31: 1 | C31: m² / APE | D31: =B31*DADOS_INICIAIS!E25 -> 593.67 | E31: m² | F31: 180 | G31: =F31*D31*1.1 -> 117546.66 | I31: =F31*1.1 -> 198 | J31: =I31*$D31 -> 117546.66
A32: Mão de obra | B32: =SUPRAESTRUTURA!B30*1.5 -> 435 | C32: R$ / APE | D32: =DADOS_INICIAIS!E25 -> 593.67 | E32: m² | F32: =B32 -> 435 | G32: =F32*D32*1.1 -> 284071.1 | K32: =F32*1.1 -> 478.5 | L32: =K32*$D32 -> 284071.1
A33: TOTAL | G33: =SUM(G28:G32) -> 1065210.4
A36: TOTAL INFRAESTRUTURA | G36: =G23+G33 -> 1971771.3 | H36: =G36/DADOS_INICIAIS!E9 -> 368.70287
H38: =H36/1.1 -> 335.18443

Sheet SUPRAESTRUTURA
A3: SUPRAESTRUTURA
A4: Data | B4: 45472
A5: Arquivo base | B5: -
G6: =8-2+1 -> 7
A7: SUPRAESTRUTURA - LAJE MACIÇA
A9: Descrição | B9: Parâmetro | D9: Quantidade | F9: Preço unitário | G9: Valor total | H9: Observação
A10: Fabricação forma | B10: 3 | C10: Jogos | D10: =(D11/DADOS_INICIAIS!$E$15)*B10 -> 2864.925 | E10: m² | F10: 110 | G10: =F10*D10*1.1 -> 346655.93
A11: Montagem de forma | B11: 2.5 | C11: m² / AC | D11: =B11*DADOS_INICIAIS!$E$9 -> 13369.65 | E11: m² | F11: 2.5 | G11: =F11*D11*1.1 -> 36766.538
A12: Escoramento | B12: 4 | C12: un / AE | D12: =ROUNDUP(B12*DADOS_INICIAIS!$E$25*B10,0) -> 7125 | E12: un | F12: =17 -> 17 | G12: =F12*D12*1.1 -> 133237.5
A13: Concreto | B13: 0.22 | C13: m³ / AC | D13: =B13*DADOS_INICIAIS!$E$9 -> 1176.5292 | E13: m³ | F13: =535+45 -> 580 | G13: =F13*D13*1.05*1.1 -> 788156.91
A14: Armadura Convencional para Estrutura | B14: 110 | C14: kg / m³ | D14: =D13*B14 -> 129418.21 | E14: kg | F14: 7.62 | G14: =F14*D14*1.1 -> 1084783.5
A15: Mão de obra - estrutura em concreto armado | B15: 240 | C15: R$ / AC | D15: =DADOS_INICIAIS!$E$9 -> 5347.86 | E15: m² | F15: =B15 -> 240 | G15: =F15*D15*1.1 -> 1411835
A16: Perfuração de vigas | B16: 5300 | C16: R$ / NP | D16: 1 | E16: vb | F16: =B16*DADOS_INICIAIS!$E$15 -> 74200 | G16: =F16*D16*1.1 -> 81620 | H16: Coeficiente originário do Gran Torino (R$ 160,00/un) | I16: Nova utiliza a verba de 1.500,00 por pav
A17: TOTAL | G17: =SUM(G10:G16) -> 3883055.4 | K17: =4160+1440+1120+2880+4800+91680+4000 -> 110080 | L17: =K17/21 -> 5241.9048
A19: SUPRAESTRUTURA - LAJE CUBETAS PROTENDIDAS
A21: Descrição | B21: Parâmetro | D21: Quantidade | F21: Preço unitário | G21: Valor total | H21: Observação
A22: Fabricação forma | B22: 3 | C22: Jogos | D22: =(D23/DADOS_INICIAIS!$E$15)*B22 -> 1260.567 | E22: m² | F22: 110 | G22: =F22*D22*1.1 -> 152528.61
A23: Montagem de forma | B23: 1.1 | C23: m² / AC | D23: =B23*DADOS_INICIAIS!$E$9 -> 5882.646 | E23: m² | F23: 2.5 | G23: =F23*D23*1.1 -> 16177.277
A24: Escoramento | C24: un / APT*NPT | D24: =DADOS_INICIAIS!$E$9-DADOS_INICIAIS!$E$25 -> 4754.19 | E24: m² | F24: 22 | G24: =F24*D24*1.1 -> 115051.4 | I24: Custos connect executivo
A25: Cubetas | B25: 25 | C25: R$ / AC | D25: =DADOS_INICIAIS!$E$9-DADOS_INICIAIS!$E$25 -> 4754.19 | E25: m² | F25: 15 | G25: =F25*D25*1.1 -> 78444.135 | H25: =ROUNDUP(DADOS_INICIAIS!E19*B22,0) -> 1394 | I25: Custos connect executivo
A26: Protensão - lajes - materiais | D26: =DADOS_INICIAIS!$E$9-DADOS_INICIAIS!$E$25-48.02-23.98 -> 4682.19 | E26: m² | F26: 11.5 | G26: =F26*D26*1.1 -> 59229.704 | I26: Custos connect executivo
A27: Protensão - lajes - serviços | D27: =D26 -> 4682.19 | E27: m² | F27: 11.5 | G27: =F27*D27*1.1 -> 59229.704 | I27: Custos connect executivo
A28: Concreto | B28: 0.25 | C28: m³ / AC | D28: =B28*DADOS_INICIAIS!$E$9 -> 1336.965 | E28: m³ | F28: =(535+45+(1.67*0.6))*1.05 -> 610.0521 | G28: =F28*D28*1.1 -> 897180.14
A29: Armadura Convencional para Estrutura | B29: 100 | C29: kg / m³ | D29: =D28*B29 -> 133696.5 | E29: kg | F29: 7.62 | G29: =F29*D29*1.1 -> 1120644.1
A30: Mão de obra - estrutura em concreto armado | B30: 290 | C30: R$ / AC | D30: =DADOS_INICIAIS!$E$9 -> 5347.86 | E30: m² | F30: =B30 -> 290 | G30: =F30*D30*1.1 -> 1705967.3
A31: Perfuração de vigas | B31: 2300 | C31: R$ / NP | D31: 1 | E31: vb | F31: =B31*DADOS_INICIAIS!$E$15 -> 32200 | G31: =F31*D31*1.1 -> 35420 | H31: Coeficiente originário do Gran Torino (R$ 160,00/un)
A32: TOTAL | G32: =SUM(G22:G31) -> 4239872.4
A34: SUPRAESTRUTURA - LAJE TRELIÇADA
A36: Descrição | B36: Parâmetro | D36: Quantidade | F36: Preço unitário | G36: Valor total | H36: Observação
A37: Fabricação forma | B37: 2 | C37: Jogos | D37: =(D38/DADOS_INICIAIS!$E$15)*B37 -> 0 | E37: m² | F37: 85 | G37: =F37*D37*1.1 -> 0
A38: Montagem de forma | B38: 2.1 | C38: m² / AC | D38: =B38*DADOS_INICIAIS!E38 -> 0 | E38: m² | F38: 1.5 | G38: =F38*D38*1.1 -> 0
A39: Escoramento - Torre | B39: 2 | C39: un / APT*NPT | D39: =B39*DADOS_INICIAIS!E47*DADOS_INICIAIS!E44 -> 0 | E39: un | F39: 17 | G39: =F39*D39*1.1 -> 0
A40: Escoramento - Embasamento | B40: 2 | C40: un / AE | D40: =B40*DADOS_INICIAIS!E50 -> 0 | E40: un | F40: 17 | G40: =F40*D40*1.1 -> 0
A41: Cubetas | B41: 25 | C41: R$ / AC | D41: =B41*DADOS_INICIAIS!E38 -> 0 | E41: m³ | F41: =B41 -> 25 | G41: =F41*D41*1.1 -> 0
A42: Concreto | B42: 0.25 | C42: m³ / AC | D42: =B42*DADOS_INICIAIS!E38 -> 0 | E42: m³ | F42: =575 -> 575 | G42: =F42*D42*1.05*1.1 -> 0
A43: Armadura Convencional para Estrutura | B43: 110 | C43: kg / m³ | D43: =D42*B43 -> 0 | E43: kg | F43: 7.25 | G43: =F43*D43*1.1 -> 0
A44: Mão de obra - estrutura em concreto armado | B44: 240 | C44: R$ / AC | D44: =DADOS_INICIAIS!E38 -> 0 | E44: m² | F44: =B44 -> 240 | G44: =F44*D44*1.1 -> 0
A45: Perfuração de vigas | B45: 5300 | C45: R$ / NP | D45: 1 | E45: vb | F45: =B45*DADOS_INICIAIS!E43 -> 0 | G45: =F45*D45*1.1 -> 0 | H45: Coeficiente originário do Gran Torino (R$ 160,00/un)
A46: TOTAL | G46: =SUM(G37:G45) -> 0
A48: SUPRAESTRUTURA - LAJE PROTENDIDA
...

Sheet ALVENARIA
A3: PAREDES E PAINÉIS
A4: Data | B4: 45469
A5: Arquivo base | B5: -
A7: ALVENARIA
A9: Descrição | B9: Parâmetro | D9: Quantidade | F9: Preço unitário | G9: Valor total | H9: Observação | I9: MT | J9: MT Total | K9: MO | L9: MO Total
A10: Bloco de 09 | B10: 0.6 | C10: m² / AE | E10: m² | F10: 30.92 | G10: =F10*D10*1 -> 0 | H10: CPU Blue Cost | I10: =F10 -> 30.92 | J10: =I10*$D10 -> 0 | L10: =K10*$D10 -> 0
A11: Bloco de 11,5 | B11: 0.6 | C11: m² / AE | D11: =SUM(ARQUITETURA!D15:D18,ARQUITETURA!D31:D33) -> 724.48 | E11: m² | F11: 35.67 | G11: =F11*D11*1 -> 25842.202 | H11: CPU Blue Cost | I11: =F11 -> 35.67 | J11: =I11*$D11 -> 25842.202 | L11: =K11*$D11 -> 0
A12: Bloco de 14 | B12: 0.8 | C12: m² / AL | D12: =SUM(ARQUITETURA!D19:D28,ARQUITETURA!D34:D35)-D14 -> 2260.78 | E12: m² | F12: 41.18 | G12: =F12*D12*1 -> 93098.92 | H12: CPU Blue Cost | I12: =F12 -> 41.18 | J12: =I12*$D12 -> 93098.92 | L12: =K12*$D12 -> 0
A13: Bloco de 19 | B13: 0.8 | C13: m² / AL | D13: =SUM(ARQUITETURA!D29:D30,ARQUITETURA!D36) -> 992.74 | E13: m² | F13: 53.02 | G13: =F13*D13*1 -> 52635.075 | H13: CPU Blue Cost | I13: =F13 -> 53.02 | J13: =I13*$D13 -> 52635.075 | L13: =K13*$D13 -> 0
A14: Alvenaria escadas | B14: 0.18 | C14: m² / AC | D14: =COUNTA('Obra '!C21:C32)*18.16 -> 217.92 | E14: m² | F14: 82.96 | G14: =F14*D14*1 -> 18078.643 | H14: CPU Blue Cost | I14: =F14 -> 82.96 | J14: =I14*$D14 -> 18078.643 | L14: =K14*$D14 -> 0
A15: Alvenaria refratárias | B15: 1.75 | C15: m² * CHU | D15: =1*B15 -> 1.75 | E15: m² | F15: 310 | G15: =F15*D15*1.1 -> 596.75 | I15: =F15 -> 310 | J15: =I15*$D15 -> 542.5 | L15: =K15*$D15 -> 0
A16: Drywall tipo RU | B16: 1.65 | C16: m² / APT*(NPT+2ND) | D16: =ARQUITETURA!D37 -> 972.78 | E16: m² | F16: 270 | G16: =F16*D16*1 -> 262650.6 | I16: =F16 -> 270 | J16: =I16*$D16 -> 262650.6 | L16: =K16*$D16 -> 0 | M16: Terceiro
A17: Drywall tipo ST | B17: 1.65 | C17: m² / APT*(NPT+2ND) | D17: =SUM(ARQUITETURA!D38:D41) -> 2935.41 | E17: m² | F17: 250 | G17: =F17*D17*1 -> 733852.5 | I17: =F17 -> 250 | J17: =I17*$D17 -> 733852.5 | L17: =K17*$D17 -> 0 | M17: Terceiro
A18: Serviços complementares | B18: 12.5 | C18: R$ / m² | D18: =SUM(D11:D14) -> 4195.92 | E18: m² | F18: 6.5 | G18: =F18*D18*1.1*0 -> 0 | I18: =F18 -> 6.5 | J18: =I18*$D18 -> 27273.48 | L18: =K18*$D18 -> 0
A19: Encunhamento | D19: =ARQUITETURA!D44 -> 1609.5 | E19: m | F19: 14.79 | G19: =F19*D19*1 -> 23804.505 | I19: =F19 -> 14.79 | J19: =I19*$D19 -> 23804.505 | L19: =K19*$D19 -> 0
A20: Tela amarração alvenaria | D20: =SUM(D10:D14) -> 4195.92 | E20: m² | F20: =4.11*0.5 -> 2.055 | G20: =F20*D20*1 -> 8622.6156 | I20: =F20 -> 2.055 | J20: =I20*$D20 -> 8622.6156 | L20: =K20*$D20 -> 0
A21: Verga e contraverga | D21: =SUM(ARQUITETURA!D111:D112) -> 1793.1 | E21: m | F21: 80.44 | G21: =F21*D21*1 -> 144236.96 | H21: CPU Blue Cost | I21: =F21 -> 80.44 | J21: =I21*$D21 -> 144236.96 | L21: =K21*$D21 -> 0
A22: Mão de obra | B22: 35 | C22: R$ / m² | D22: =SUM(D10:D14) -> 4195.92 | E22: m² | F22: 48 | G22: =F22*D22*1 -> 201404.16 | J22: =I22*$D22 -> 0 | K22: =F22 -> 48 | L22: =K22*$D22 -> 201404.16 | M22: Emp
A23: TOTAL | G23: =SUM(G10:G22) -> 1564822.9
A25: ALVENARIA - DRYWALL
A27: Descrição | B27: Parâmetro | D27: Quantidade | F27: Preço unitário | G27: Valor total | H27: Observação
A28: Alvenaria embasamento | B28: 1 | C28: m² / AE | D28: =B28*DADOS_INICIAIS!$E$22 -> 593.67 | E28: m² | F28: 45 | G28: =F28*D28*1.1 -> 29386.665
A29: Alvenaria lazer | B29: 0.4 | C29: m² / AL | D29: =B29*DADOS_INICIAIS!$E$21 -> 325.468 | E29: m² | F29: 45 | G29: =F29*D29*1.1 -> 16110.666
A30: Alvenaria tipo | B30: 1.65 | C30: m² / APT*(NPT+2ND) | D30: =B30*(DADOS_INICIAIS!$E$19*(DADOS_INICIAIS!$E$16+DADOS_INICIAIS!$E$17))*0.4 -> 2758.7142 | E30: m² | F30: 45 | G30: =F30*D30*1.1 -> 136556.35
A31: Drywall tipo | B31: 1.65 | C31: m² / APT*(NPT+2ND) | D31: =B31*(DADOS_INICIAIS!$E$19*(DADOS_INICIAIS!$E$16+DADOS_INICIAIS!$E$17))*0.6 -> 4138.0713 | E31: m² | F31: 220 | G31: =F31*D31*1.1 -> 1001413.3 | J31: =D31/(D35+D31) -> 0.44701887
A32: Alvenaria escadas | B32: 0.2 | C32: m² / AC | D32: =B32*DADOS_INICIAIS!$E$9 -> 1069.572 | E32: m² | F32: 70 | G32: =F32*D32*1.1 -> 82357.044 | J32: =1-J31 -> 0.55298113
A33: Alvenaria cobertura / reservatório | B33: 0.8 | C33: m² / APT | D33: =B33*DADOS_INICIAIS!$E$19 -> 371.544 | E33: m³ | F33: 45 | G33: =F33*D33*1.1 -> 18391.428
A34: Alvenaria refratárias | B34: 1.75 | C34: m² * CHU | D34: ='SISTEMAS ESPECIAIS'!B10 -> 1 | E34: un | F34: 210 | G34: =F34*D34*1.1 -> 231
A35: Serviços complementares | B35: 12.5 | C35: R$ / m² | D35: =D29+D30+D28+D32+D33 -> 5118.9682 | E35: m² | F35: =B35 -> 12.5 | G35: =F35*D35*1.1 -> 70385.813
A36: Mão de obra | B36: 35 | C36: R$ / m² | D36: =D29+D30+D28+D32+D33 -> 5118.9682 | E36: m² | F36: 35 | G36: =F36*D36*1.1 -> 197080.28
A37: TOTAL | G37: =SUM(G28:G36) -> 1551912.5
A40: TOTAL ALVENARIA | G40: =G23 -> 1564822.9 | H40: =G40/DADOS_INICIAIS!E9 -> 292.60731
G43: =G40/1.1 -> 1422566.3 | H43: =G43/DADOS_INICIAIS!E9 -> 266.00665

Sheet IMPERMEABILIZAÇÃO
A3: IMPERMEABILIZAÇÃO
A4: Data | B4: 45471
A5: Arquivo base | B5: -
A7: ALVENARIA
A9: Descrição | B9: Parâmetro | D9: Quantidade | F9: Preço unitário | G9: Valor total | H9: Observação
A10: Regularização de Superfície | B10: 25 | C10: R$ / m² | D10: =D14+D15 -> 2005.7309 | E10: m² | F10: =7.69+25 -> 32.69 | G10: =F10*D10*1.1 -> 72124.077 | I10: Terceiro
A11: Poço do elevador | B11: 45 | C11: R$ / m² | D11: =(3.24+(7.2)*1.8)*2 -> 32.4 | E11: m² | F11: 41 | G11: =F11*D11*1.1 -> 1461.24 | I11: Terceiro
A12: Baldrames | B12: 30 | C12: R$ / m² | D12: =INFRAESTRUTURA!D28 -> 653.037 | E12: m² | F12: 35 | G12: =F12*D12*1.1 -> 25141.925 | I12: Terceiro
A13: Ralos | D13: =SUM('Obra '!N21:N36) -> 336 | E13: un | F13: 80 | G13: =F13*D13*1.1 -> 29568 | I13: Terceiro
A14: Impermeabilizações cimenticias | B14: 0.25 | C14: m² / AC | D14: =B14*DADOS_INICIAIS!E9 -> 1336.965 | E14: m² | F14: 60 | G14: =F14*D14*1.1 -> 88239.69 | I14: Terceiro
A15: Impermeabilizações com manta asfaltica | B15: 0.11 | C15: m² / AC | D15: =B15*DADOS_INICIAIS!E9+'Acabamentos de Piso e Parede'!B18 -> 668.7659 | E15: m² | F15: 110 | G15: =F15*D15*1.1 -> 80920.674 | I15: Terceiro
A16: Impermeabilização de peitoril | B16: 0.6 | C16: R$ / AC | D16: 1 | E16: vb | F16: =B16*DADOS_INICIAIS!$E$9 -> 3208.716 | G16: =F16*D16*1.1 -> 3529.5876 | I16: Terceiro
A17: Proteção Mecânica | B17: 28 | C17: R$ / m² | D17: =D15 -> 668.7659 | E17: m² | F17: =42.3+35 -> 77.3 | G17: =F17*D17*1.1 -> 56865.164 | I17: Terceiro
A18: TOTAL | G18: =SUM(G10:G17) -> 357850.36
A20: TOTAL IMPERMEABILIZAÇÃO | G20: =G18 -> 357850.36 | H20: =G20/DADOS_INICIAIS!E9 -> 66.914683
H23: =H20/1.1 -> 60.83153
F24: =SUM('Obra '!N21:N36) -> 336

Sheet INSTALAÇÕES
A2: INSTALAÇÕES
A4: INSTALAÇÕES ELÉTRICAS
A6: Descrição | B6: Parâmetro | D6: Valor total
A7: Entrada de Energia | B7: 5.5 | C7: R$ / AC | D7: =B7*DADOS_INICIAIS!$E$9*1.1 -> 32354.553
A8: Eletrodutos e Eletrocalhas | B8: 10 | C8: R$ / AC | D8: =B8*DADOS_INICIAIS!$E$9*1.1 -> 58826.46
A9: Cabos e Fiações | B9: 30 | C9: R$ / AC | D9: =B9*DADOS_INICIAIS!$E$9*1.1 -> 176479.38
A10: Quadros e Disjuntores | B10: 18 | C10: R$ / AC | D10: =B10*DADOS_INICIAIS!$E$9*1.1 -> 105887.63
A11: Acabamentos Elétricos | B11: 15 | C11: R$ / AC | D11: =B11*DADOS_INICIAIS!$E$9*1.1 -> 88239.69
A12: Equipamentos e Iluminação | B12: 15 | C12: R$ / AC | D12: =B12*DADOS_INICIAIS!$E$9*1.1 -> 88239.69
A13: Mão de Obra para Instalações Elétricas | B13: 60 | C13: R$ / AC | D13: =B13*DADOS_INICIAIS!$E$9*1.1 -> 352958.76
A14: TOTAL | D14: =SUM(D7:D13) -> 902986.16 | E14: =D14/'Obra '!$C$10 -> 168.85
A16: INSTALAÇÕES HIDROSSANITÁRIAS
A18: Descrição | B18: Parâmetro | D18: Valor total
A19: Instalações de Água Fria | B19: 25 | C19: R$ / AC | D19: =B19*DADOS_INICIAIS!$E$9*1.1 -> 147066.15
A20: Instalações de Água Quente | B20: 20 | C20: R$ / AC | D20: =B20*DADOS_INICIAIS!$E$9*1.1 -> 117652.92
A21: Instalações de Águas Pluviais | B21: 10 | C21: R$ / AC | D21: =B21*DADOS_INICIAIS!$E$9*1.1 -> 58826.46
A22: Instalações Sanitárias | B22: 15 | C22: R$ / AC | D22: =B22*DADOS_INICIAIS!$E$9*1.1 -> 88239.69
A23: Louças e Metais | B23: 20 | C23: R$ / AC | D23: =B23*DADOS_INICIAIS!$E$9*1.1 -> 117652.92
A24: Mão de Obra para Instalações Hidráulicas | B24: 55 | C24: R$ / AC | D24: =B24*DADOS_INICIAIS!$E$9*1.1 -> 323545.53
A25: TOTAL | D25: =SUM(D19:D24) -> 852983.67 | E25: =D25/'Obra '!$C$10 -> 159.5
A27: INSTALAÇÕES PREVENTIVAS E GLP
A29: Descrição | B29: Parâmetro | D29: Valor total
A30: Instalações Preventivas | B30: 20 | C30: R$ / AC | D30: =B30*DADOS_INICIAIS!$E$9*1.1 -> 117652.92 | E30: =D30/'Obra '!$C$10 -> 22
A31: Instalações Sprinklers | B31: =95+35 -> 130 | C31: R$ / AC | D31: =B31*DADOS_INICIAIS!$E$9*1.1 -> 764743.98 | E31: =D31/'Obra '!$C$10 -> 143 | F31: Estimado com Base no Redentor
A32: Instalações de GLP | B32: 15 | C32: R$ / AC | D32: =B32*DADOS_INICIAIS!$E$9*1.1 -> 88239.69 | E32: =D32/'Obra '!$C$10 -> 16.5
A33: Instalações de Proteção e Aterramento - SPDA | B33: 8 | C33: R$ / AC | D33: =B33*DADOS_INICIAIS!$E$9*1.1 -> 47061.168 | E33: =D33/'Obra '!$C$10 -> 8.8
A34: TOTAL | D34: =SUM(D30:D33) -> 1017697.8
A36: TOTAL INSTALAÇÕES | D36: =D14+D25+D34 -> 2773667.6 | E36: =D36/DADOS_INICIAIS!E9 -> 518.65
E38: =E36/1.1 -> 471.5

Sheet SISTEMAS ESPECIAIS
A2: SISTEMAS ESPECIAIS
A4: CLIMATIZAÇÃO, EXAUSTÃO MECÂNICA E PRESSURIZAÇÃO
A6: Descrição | B6: Quantidade | C6: Preço Unitário | D6: Valor total
A7: Infraestrutura para Instalação de Ar Condicionado | B7: =SUM('Obra '!L21:L36) -> 84 | C7: 1200 | D7: =B7*C7*1.1 -> 110880
A8: Instalação de Ar Condicionado | B8: =SUM('Obra '!M21:M36) -> 7 | C8: 5000 | D8: =B8*C8*1.1 -> 38500
A9: Ventokit | B9: =SUM('Obra '!K21:K36) -> 81 | C9: 900 | D9: =B9*C9*1.1 -> 80190
A10: Churrasqueiras | B10: 1 | C10: 2600 | D10: =B10*C10*1.1 -> 2860 | E10: 1 por unidade no lazer
A11: TOTAL | D11: =SUM(D7:D10) -> 232430
A13: COMUNICAÇÃO
A15: Descrição | B15: Parâmetro | D15: Valor total
A16: CFTV | B16: 1.5 | C16: R$ / AC | D16: =B16*DADOS_INICIAIS!$E$9*1.1 -> 8823.969
A17: Interfone | B17: 2 | C17: R$ / AC | D17: =B17*DADOS_INICIAIS!$E$9*1.1 -> 11765.292
A18: TV e internet | B18: 4 | C18: R$ / AC | D18: =B18*DADOS_INICIAIS!$E$9*1.1 -> 23530.584
A19: Automação, telecomunicação e sistemas de segurança | B19: 5 | C19: R$ / AC | D19: =B19*DADOS_INICIAIS!$E$9*1.1*0+45000 -> 45000 | E19: *Valor recebido do cliente
A20: TOTAL | D20: =SUM(D16:D19) -> 89119.845
A22: EQUIPAMENTOS
A24: Descrição | B24: Quantidade | C24: Preço Unitário | D24: Valor total
A25: Elevadores | B25: 2 | C25: =266000/12*11 -> 243833.33 | D25: =B25*C25*1.1 -> 536433.33
A26: Grupo de geradores | B26: 1 | C26: 209103.55 | D26: =B26*C26*1.1 -> 230013.9 | E26: *Cotação mercado
A27: Pressurização de escada | B27: 0 | C27: =26.4*DADOS_INICIAIS!E9 -> 141183.5 | D27: =B27*C27*1.1 -> 0
A28: Bombas | B28: 1 | C28: 15000 | D28: =B28*C28*1.1 -> 16500
A29: Infra de carro elétrico | B29: 5 | C29: 560 | D29: =B29*C29*1.1 -> 3080
A30: Equipamento Carro Elétrico | B30: 1 | C30: 43000 | D30: =B30*C30*1.1 -> 47300
A31: Equipamento de piscina | B31: 1 | C31: =39684 -> 39684 | D31: =B31*C31*1.1 -> 43652.4 | E31: *Cotação cliente
A32: Subestação de Energia | B32: 1 | C32: 238000 | D32: =B32*C32*1.1 -> 261800 | E32: *Estimado
A33: Spa | C33: 15000 | D33: =B33*C33*1.1 -> 0
A34: Sistema de aquecimento | B34: 0 | C34: =55*DADOS_INICIAIS!E9 -> 294132.3 | D34: =B34*C34 -> 0
A35: TOTAL | D35: =SUM(D25:D34) -> 1138779.6
A37: OUTROS SISTEMAS ESPECIAIS
A39: Descrição | B39: Parâmetro | D39: Valor total
A40: Outros sistemas | B40: 20 | C40: R$ / AC | D40: =B40*DADOS_INICIAIS!E9*1.1 -> 117652.92
A41: TOTAL | D41: =SUM(D40:D40) -> 117652.92
A43: TOTAL SISTEMAS ESPECIAIS | D43: =D11+D20+D35+D41 -> 1577982.4 | E43: =D43/DADOS_INICIAIS!E9 -> 295.06801

Sheet Rev. Internos Piso e Parede
A2: ORÇAMENTO PARAMÉTRICO GERENCIAMENTO EXECUTIVO
A7: Cliente
A8: Obra
A9: Data | B9: 45471
A10: Revisão | B10: R00
A12: REVESTIMENTOS INTERNOS EM PISO E PAREDE
A14: Descrição | B14: Quantidade | D14: Parâmetro | F14: Referência | G14: Valor total | I14: MT | J14: MT Total | K14: MO | L14: MO Total
A15: Polimento de concreto | B15: 0 | C15: m² | D15: 16.5 | E15: R$ / m² | F15: Média | G15: =D15*B15*1.1 -> 0 | J15: =I15*$B15 -> 0 | L15: =K15*$B15 -> 0
A16: Piso alisado | B16: 0 | C16: m² | D16: 25 | E16: R$ / m² | F16: Média | G16: =D16*B16*1.1 -> 0 | J16: =I16*$B16 -> 0 | L16: =K16*$B16 -> 0
A17: Contrapiso | B17: =SUM(ARQUITETURA!D91:D97) -> 4197.54 | C17: m² | D17: =B17/DADOS_INICIAIS!E9 -> 0.78490088 | E17: m² / AC | F17: Média | G17: =+B17*65*1.05 -> 286482.1 | I17: =65*1.05-K17 -> 28.25 | J17: =I17*$B17 -> 118580.51 | K17: 40 | L17: =K17*$B17 -> 167901.6
A18: Manta acústica | B18: ='Acabamentos de Piso e Parede'!B17 -> 1959.559 | C18: m² | D18: =B18/DADOS_INICIAIS!E9 -> 0.36641928 | E18: m² / AC | F18: Média | G18: =+B18*26*1.05 -> 53495.961 | I18: =26*1.05 -> 27.3 | J18: =I18*$B18 -> 53495.961 | L18: =K18*$B18 -> 0
A19: Chapisco | B19: =ALVENARIA!D22*2-('Rev. Fachada'!B15) -> 5782.44 | C19: m² | D19: =B19/DADOS_INICIAIS!E9 -> 1.0812624 | E19: m² / AC | F19: Média | G19: =+B19*5*1.05 -> 30357.81 | I19: =5*1.05 -> 5.25 | J19: =I19*$B19 -> 30357.81 | L19: =K19*$B19 -> 0
A20: Reboco | B20: =B19 -> 5782.44 | C20: m² | D20: =B20/DADOS_INICIAIS!E9 -> 1.0812624 | E20: m² / AC | F20: Média | G20: =50*B20*1.05 -> 303578.1 | I20: =50*1.05-K20 -> 17.5 | J20: =I20*$B20 -> 101192.7 | K20: 35 | L20: =K20*$B20 -> 202385.4
A21: TOTAL | G21: =SUM(G15:G20) -> 673913.98
A24: TOTAL REVESTIMENTOS | G24: =G21 -> 673913.98 | H24: =G24/DADOS_INICIAIS!E9 -> 126.01564
H26: =H24/1.1 -> 114.55967

Sheet TETO
A3: REVESTIMENTOS E ACABAMENTOS DE TETO
A4: Data | B4: 45471
A5: Arquivo base | B5: -
A7: ALVENARIA
A9: Descrição | B9: Parâmetro | D9: Quantidade | F9: Preço unitário | G9: Valor total | H9: Observação | J9: MT | K9: MT Total | L9: MO | M9: MO Total
A10: Forro gesso Acartonado ST | B10: 0.6 | C10: m² / AC | D10: =SUM(D19:D34) -> 364.99 | E10: m² | F10: 110 | G10: =F10*D10*1 -> 40148.9 | J10: =F10*1 -> 110 | K10: =J10*$D10 -> 40148.9 | M10: =L10*$D10 -> 0
A11: Forro gesso Acartonado RU | B11: 0.6 | C11: m² / AC | D11: =SUM(E19:E34) -> 595.98 | E11: m² | F11: 120 | G11: =F11*D11*1 -> 71517.6 | J11: =F11*1 -> 120 | K11: =J11*$D11 -> 71517.6 | M11: =L11*$D11 -> 0
A12: Estucamento | B12: 0.2 | C12: m² / AC | D12: =SUM(B19:B35) -> 3948.201 | E12: m² | F12: 24 | G12: =F12*D12*1 -> 94756.824 | J12: =F12*1-L12 -> 4 | K12: =J12*$D12 -> 15792.804 | L12: 20 | M12: =L12*$D12 -> 78964.02
A13: Tratamento de concreto Aparente | B13: 1.2 | C13: m / FORRO | D13: =SUM(C19:C34) -> 3390.12 | E13: m² | F13: 47 | G13: =F13*D13*1 -> 159335.64 | H13: Resina e Mão de obra | J13: =F13*1-L13 -> 17 | K13: =J13*$D13 -> 57632.04 | L13: 30 | M13: =L13*$D13 -> 101703.6
A14: TOTAL | G14: =SUM(G10:G13) -> 365758.96
A16: TOTAL FORRO | G16: =G14 -> 365758.96 | H16: =G16/DADOS_INICIAIS!E9 -> 68.393519
A18: PAVIMENTOS | B18: Estucamento | C18: Tratamento de concreto Aparente | D18: Acartonado | E18: RU
A19: SUBSOLO 01 | B19: =('Obra '!D21-SUM(D19:E19))*0.9 -> 558.081 | D19: 3.91 | H19: =H16/1.1 -> 62.175926
A20: 1º PAV-TÉRREO | B20: =C20 -> 526.464 | C20: =('Obra '!D22-SUM(D20:E20))*0.9 -> 526.464 | D20: 8.71
A21: 1º PAV-MEZANINO | B21: =C21 -> 270.909 | C21: =('Obra '!D23-SUM(D21:E21))*0.9 -> 270.909
A22: 2º PAVIMENTO | B22: =C22 -> 314.325 | C22: =('Obra '!D24-SUM(D22:E22))*0.9 -> 314.325 | D22: 30.04 | E22: 85.14
A23: 3º PAVIMENTO | B23: =C23 -> 314.325 | C23: =('Obra '!D25-SUM(D23:E23))*0.9 -> 314.325 | D23: 30.04 | E23: 85.14
A24: 4º PAVIMENTO | B24: =C24 -> 314.325 | C24: =('Obra '!D26-SUM(D24:E24))*0.9 -> 314.325 | D24: 30.04 | E24: 85.14
A25: 5º PAVIMENTO | B25: =C25 -> 314.325 | C25: =('Obra '!D27-SUM(D25:E25))*0.9 -> 314.325 | D25: 30.04 | E25: 85.14
A26: 6º PAVIMENTO | B26: =C26 -> 314.325 | C26: =('Obra '!D28-SUM(D26:E26))*0.9 -> 314.325 | D26: 30.04 | E26: 85.14
A27: 7º PAVIMENTO | B27: =C27 -> 314.325 | C27: =('Obra '!D29-SUM(D27:E27))*0.9 -> 314.325 | D27: 30.04 | E27: 85.14
A28: 8º PAVIMENTO | B28: =C28 -> 314.325 | C28: =('Obra '!D30-SUM(D28:E28))*0.9 -> 314.325 | D28: 30.04 | E28: 85.14
A29: PLANO COBERTURA | B29: =C29 -> 255.078 | C29: =('Obra '!D31-SUM(D29:E29))*0.9 -> 255.078 | D29: 142.09
A30: BARRILETE | B30: =C30 -> 54.918 | C30: =('Obra '!D32-SUM(D30:E30))*0.9 -> 54.918
A31: CASA DE MÁQUINAS | B31: =C31 -> 27.558 | C31: =('Obra '!D33-SUM(D31:E31))*0.9 -> 27.558
A32: RESERVATÓRIO | B32: =C32 -> 54.918 | C32: =('Obra '!D34-SUM(D32:E32))*0.9 -> 54.918

Sheet Acabamentos de Piso e Parede
A2: ORÇAMENTO PARAMÉTRICO GERENCIAMENTO EXECUTIVO
A7: Cliente
A8: Obra
A9: Data | B9: 45471
A10: Revisão | B10: R00
A12: ACABAMENTOS EM PISO E PAREDE
A14: Descrição | B14: Quantidade | D14: Parâmetro | F14: Referência | G14: Valor total | I14: MT | J14: MT Total | K14: MO | L14: MO Total
A15: Piso Cerâmico Garagens | B15: 613.65 | C15: m² | D15: =40*1.1+1.75*8.5+8*0.5+60 -> 122.875 | E15: R$ / m² | F15: Média | G15: =+D15*B15*1 -> 75402.244 | I15: =40*1.1+1.75*8.5+8*0.5 -> 62.875 | J15: =I15*$B15 -> 38583.244 | K15: =60 -> 60 | L15: =K15*$B15 -> 36819 | M15: Emp
A16: Piso Cerâmico halls, Circulaçõa, áreas Comuns e banheiros unidades | B16: =SUM(ARQUITETURA!D91:D93,ARQUITETURA!D95)-B15-B17 -> 1433.051 | C16: m² | D16: =55*1.1+1.75*8.5+8*0.5+60 -> 139.375 | E16: R$ / m² | F16: Média | G16: =+D16*B16*1 -> 199731.48 | I16: =55*1.1+1.75*8.5+8*0.5 -> 79.375 | J16: =I16*$B16 -> 113748.42 | K16: =60 -> 60 | L16: =K16*$B16 -> 85983.06 | M16: Emp
A17: Vinilico | B17: =SUM(C35:C51) -> 1959.559 | C17: m² | D17: 160 | E17: R$ / m² | F17: Média | G17: =+D17*B17*1 -> 313529.44 | I17: 160 | J17: =I17*$B17 -> 313529.44 | L17: =K17*$B17 -> 0 | M17: Terceirizado
A18: Piscina | B18: =1.47*11.65*2+1.47*3.17*2+11.65*3.17 -> 80.5013 | C18: m² | D18: =110*1.1+1.8*8.5+9*0.5+60 -> 200.8 | E18: R$ / m² | F18: Média | G18: =+D18*B18*1 -> 16164.661 | I18: =110*1.1+1.8*8.5+9*0.5 -> 140.8 | J18: =I18*$B18 -> 11334.583 | K18: =60 -> 60 | L18: =K18*$B18 -> 4830.078 | M18: Emp
A19: Grama sintetica | B19: 0 | C19: m² | D19: 210 | E19: R$ / m² | F19: Média | G19: =+D19*B19*1 -> 0 | J19: =I19*$B19 -> 0 | L19: =K19*$B19 -> 0
A20: Ladrilho Hidraulico Rampa | B20: =ARQUITETURA!D97 -> 53.37 | C20: m² | D20: 60 | E20: R$ / m² | F20: Média | G20: =+D20*B20*1 -> 3202.2 | I20: 30 | J20: =I20*$B20 -> 1601.1 | K20: 30 | L20: =K20*$B20 -> 1601.1 | M20: Emp
A21: Paver | B21: =ARQUITETURA!D96 -> 95.8 | C21: m² | D21: 60 | E21: R$ / m² | F21: Média | G21: =+D21*B21*1 -> 5748 | I21: 30 | J21: =I21*$B21 -> 2874 | K21: 30 | L21: =K21*$B21 -> 2874 | M21: Emp
A22: Rodapés | B22: =SUM(B15:B17)*1.2 -> 4807.512 | C22: m | D22: =35+20 -> 55 | E22: R$ / AC | F22: Média | G22: =D22*B22*1 -> 264413.16 | I22: 35 | J22: =I22*$B22 -> 168262.92 | K22: 20 | L22: =K22*$B22 -> 96150.24 | M22: Emp
A23: Soleiras | B23: =SUM(ARQUITETURA!D109) -> 106.75 | C23: m² | D23: =1.05*650+8.5*1.8+10*0.5+60 -> 762.8 | E23: R$ / AC | F23: Média | G23: =D23*B23*1 -> 81428.9 | I23: =1.05*650+8.5*1.8+10*0.5 -> 702.8 | J23: =I23*$B23 -> 75023.9 | K23: 60 | L23: =K23*$B23 -> 6405 | M23: Emp
A24: Peitoris | B24: =ARQUITETURA!D107 -> 36.77 | C24: m² | D24: =1.05*650+8.5*1.8+10*0.5+60 -> 762.8 | E24: R$ / AC | F24: Média | G24: =D24*B24*1 -> 28048.156 | I24: =1.05*650+8.5*1.8+10*0.5 -> 702.8 | J24: =I24*$B24 -> 25841.956 | K24: 60 | L24: =K24*$B24 -> 2206.2 | M24: Emp
A25: Rodapés | B25: 1 | C25: vb | D25: 30 | E25: R$ / AC | F25: Média | G25: =D25*DADOS_INICIAIS!$E$9*1.1*0 -> 0 | J25: =I25*$B25 -> 0 | L25: =K25*$B25 -> 0
A26: Soleiras e peitoris | B26: 1 | C26: vb | D26: 20 | E26: R$ / AC | F26: Média | G26: =D26*DADOS_INICIAIS!$E$9*1.1*0 -> 0 | J26: =I26*$B26 -> 0 | L26: =K26*$B26 -> 0
A27: Revestimentos de Parede | B27: =SUM(B35:B50) -> 1579.4262 | C27: m2 | D27: =65*1.1+1.75*8.5+8*0.5+60 -> 150.375 | E27: R$ / AC | F27: Média | G27: =D27*B27*1 -> 237506.21 | I27: =65*1.1+1.75*8.5+8*0.5 -> 90.375 | J27: =I27*$B27 -> 142740.64 | K27: 60 | L27: =K27*$B27 -> 94765.572 | M27: Emp
A28: =20*40 -> 800 | G28: =SUM(G15:G27) -> 1225174.5
A31: TOTAL ACABAMENTOS | G31: =G28 -> 1225174.5 | H31: =G31/DADOS_INICIAIS!E9 -> 229.09621
H33: =H31/1.1 -> 208.26928
A34: PAVIMENTOS | B34: Ceramica Paredes | C34: Piso Vinílico
A35: SUBSOLO 01 | B35: =(3.75*2+4.54*2+3*2+3.75*2)*3.09 -> 92.9472
A36: 1º PAV-TÉRREO | B36: =(9.85*3+1.6*6)*3.2+(2.2+1.75)*2*2.29 -> 143.371
A37: 1º PAV-MEZANINO | B37: =(6.3+1.45*4)*3.09 -> 37.389
A38: 2º PAVIMENTO | B38: =(1.45+0.9)*2*3.24*10+(2.04+2.69)*2*3.24 -> 182.9304 | C38: =336.397-((1.45+0.9)*2*10+(2.04+2.69)*2) -> 279.937
A39: 3º PAVIMENTO | B39: =(1.45+0.9)*2*3.24*10+(2.04+2.69)*2*3.24 -> 182.9304 | C39: =336.397-((1.45+0.9)*2*10+(2.04+2.69)*2) -> 279.937
A40: 4º PAVIMENTO | B40: =(1.45+0.9)*2*3.24*10+(2.04+2.69)*2*3.24 -> 182.9304 | C40: =336.397-((1.45+0.9)*2*10+(2.04+2.69)*2) -> 279.937
A41: 5º PAVIMENTO | B41: =(1.45+0.9)*2*3.24*10+(2.04+2.69)*2*3.24 -> 182.9304 | C41: =336.397-((1.45+0.9)*2*10+(2.04+2.69)*2) -> 279.937
A42: 6º PAVIMENTO | B42: =(1.45+0.9)*2*3.24*10+(2.04+2.69)*2*3.24 -> 182.9304 | C42: =336.397-((1.45+0.9)*2*10+(2.04+2.69)*2) -> 279.937
A43: 7º PAVIMENTO | B43: =(1.45+0.9)*2*3.24*10+(2.04+2.69)*2*3.24 -> 182.9304 | C43: =336.397-((1.45+0.9)*2*10+(2.04+2.69)*2) -> 279.937
A44: 8º PAVIMENTO | B44: =(1.45+0.9)*2*3.24*10+(2.04+2.69)*2*3.24 -> 182.9304 | C44: =336.397-((1.45+0.9)*2*10+(2.04+2.69)*2) -> 279.937
A45: PLANO COBERTURA | B45: =(3.03+1.4*2)*3.14+6.9 -> 25.2062
A46: BARRILETE
A47: CASA DE MÁQUINAS
A48: RESERVATÓRIO

Sheet PINTURA INTERNA
A3: PINTURA INTERNA
A4: Data | B4: 45457
A5: Arquivo base | B5: -
A7: ALVENARIA
A9: Descrição | B9: Parâmetro | D9: Quantidade | F9: Preço unitário | G9: Valor total | H9: Observação | I9: MT | J9: MT Total | K9: MO | L9: MO Total
A10: Pintura piso epoxi | B10: 110 | C10: R$ / m² | D10: ='Rev. Internos Piso e Parede'!B15 -> 0 | E10: m² | F10: 110 | G10: =F10*D10*1.1 -> 0
A11: Pintura acrílica antiderrapante | B11: 65 | C11: R$ / m² | D11: ='Rev. Internos Piso e Parede'!B16 -> 0 | E11: m² | F11: 65 | G11: =F11*D11*1.1 -> 0
A12: Textura escadas | B12: 26 | C12: R$ / AC | D12: =ALVENARIA!D14*2 -> 435.84 | E12: m² | F12: =12+35 -> 47 | G12: =F12*D12*1 -> 20484.48 | I12: 12 | J12: =I12*$D12 -> 5230.08 | K12: 35 | L12: =K12*$D12 -> 15254.4 | M12: Emp
A13: Pintura Interna Paredes | D13: =SUM(ALVENARIA!D16:D17)*2+ALVENARIA!D22*2-'Rev. Fachada'!B15-'Acabamentos de Piso e Parede'!B27-D12 -> 11583.554 | E13: m² | F13: =19+40 -> 59 | G13: =F13*D13 -> 683429.67 | I13: 19 | J13: =I13*$D13 -> 220087.52 | K13: 40 | L13: =K13*$D13 -> 463342.15 | M13: Emp
A14: Pintura Interna Teto | D14: =TETO!D10+TETO!D11 -> 960.97 | E14: m² | F14: =F13 -> 59 | G14: =F14*D14 -> 56697.23 | I14: 19 | J14: =I14*$D14 -> 18258.43 | K14: 40 | L14: =K14*$D14 -> 38438.8 | M14: Emp
A15: TOTAL | G15: =SUM(G10:G14) -> 760611.38
A17: TOTAL IMPERMEABILIZAÇÃO | G17: =G15 -> 760611.38 | H17: =G17/DADOS_INICIAIS!E9 -> 142.22724
H19: =H17/1.1 -> 129.29749
G22: =4160+1440+1120+2880+4800+91680+4000 -> 110080 | H22: =G22/21 -> 5241.9048

Sheet ARQUITETURA
A1: DADOS
A2: Titulo | B2: QUANTITATIVO
A3: Obra | B3: Obra Modelo
A4: Cliente | B4: Nome cliente
A5: Cidade | B5: São Paulo
A6: Endereço | B6: Avenida Paulista, S/N
A7: Descrição | B7: Obra BIM
A9: QUANTITATIVOS
A10: Item | B10: Descrição | C10: Unid. | D10: Quantidade
A12: 1. | B12: Geral parade
A13: 1.1 | B13: Basic Wall:SM-EST-CON-CN0 20cm | C13: m² | D13: 164.83
A14: 1.2 | B14: Basic Wall:SM-EST-CON-CN0 25cm | C14: m² | D14: 92.46
A15: 1.3 | B15: Basic Wall:SM-EXT-ALV-BE11.5 11.5cm | C15: m² | D15: 2.72
A16: 1.4 | B16: Basic Wall:SM-EXT-ALV-BE11.5 15cm-PT1/PT1 | C16: m² | D16: 23.74
A17: 1.5 | B17: Basic Wall:SM-EXT-ALV-BE11.5 16.5cm-PT1/PT1 | C17: m² | D17: 7.33
A18: 1.6 | B18: Basic Wall:SM-EXT-ALV-BE11.5 16.5cm-PT1/PT1 - Ventilada | C18: m² | D18: 15.94
A19: 1.7 | B19: Basic Wall:SM-EXT-ALV-BE14 17cm-PT1/PT1 - Ventilada | C19: m² | D19: 60.15
A20: 1.8 | B20: Basic Wall:SM-EXT-ALV-BE14 20cm-CE1/CE1 | C20: m² | D20: 27.35
A21: 1.9 | B21: Basic Wall:SM-EXT-ALV-BE14 20cm-CE1/CE1 - Ventilada | C21: m² | D21: 19.46
A22: 1.10 | B22: Basic Wall:SM-EXT-ALV-BE14 20cm-CON1/CON1 | C22: m² | D22: 56.92
A23: 1.11 | B23: Basic Wall:SM-EXT-ALV-BE14 20cm-PT1/CE1 - Ventilada | C23: m² | D23: 128.3
A24: 1.12 | B24: Basic Wall:SM-EXT-ALV-BE14 20cm-PT1/CON1 | C24: m² | D24: 15.92
... A42: 1.30 | B42: Basic Wall:SM-INT-REV 01.5cm-PT1 | C42: m² | D42: 74.13
A43: 2. | B43: Serviços complementares para alvenaria
A44: 2.1 | B44: ENCUNHAMENTO | C44: m | D44: 1609.5
A45: 3. | B45: Esquadrias de alumínio
A46: 3.1 | B46: 23.30.10.17.21 - P.ABRIR.2F.VENEZIANA:150X160cm | C46: m² | D46: 9.6
A47: 3.2 | B47: 23.30.10.17.21 - P.ABRIR.2F.VENEZIANA:180x210 | C47: m² | D47: 3.78
A48: 3.3 | B48: Railing:C04 - SM-GPO-h=110cm-Barras Circulares-Postes Retangulares-Painel Barras Circulares Horizontais | C48: m² | D48: 3.21 | E48: =(9.02+4.5+5.14*2)*1.1 -> 26.18
A49: 3.4 | B49: Railing:SM-COR-H=92/70cm-Fixado na Parede-Barras Circulares-Suportes S.Canopla | C49: m | D49: 124.45
A50: 3.5 | B50: Railing:SM-GPO-h=110cm-Corrimão 92cm-Barras Circulares-Postes Retangulares-Painel Barras Circulares Horizontais | C50: m² | D50: 6.88 | E50: =2.25*1.1*8*2 -> 39.6
A51: 3.6 | B51: Railing:SM-GPO-h=110cm-Corrimão 92cm-Painel Vidro VD1-Fixação Inferior-Embutido | C51: m² | D51: 17.24
A52: 3.7 | B52: Railing:SM-GPO-h=110cm-Corrimão 92cm-Painel Vidro VD1-Fixação Inferior-Sobreposto | C52: m² | D52: 15.49
A53: 3.8 | B53: Railing:SM-GPO-h=110cm-S.Corrimão-Painel Vidro VD1-Fixação Inferior-Embutido | C53: m² | D53: 244.49
A54: 3.9 | B54: Railing:SM-GPO-h=130cm-S.Corrimão-Painel Vidro VD1-Fixação Inferior-Embutido | C54: m² | D54: 35.84
A55: 3.10 | B55: SM-JAN-ALU-X Folhas Maximar:1 Folha-060x060cm-Vidro 8mm | C55: m² | D55: 0.72
A56: 3.11 | B56: SM-JAN-ALU-X Folhas Maximar:1 Folha-060x080cm-Vidro 8mm | C56: m² | D56: 20.16
A57: 3.12 | B57: SM-JAN-ALU-X Folhas Maximar - X Folhas Fixas Inf:2 Folhas(1-1)-100x200cm-Vidro 8mm | C57: m² | D57: 42
A58: 3.13 | B58: SM-JAN-ALU-X Folhas Maximar - X Folhas Fixas Inf:2 Folhas(1-1)-100x210cm-Vidro 8mm | C58: m² | D58: 1.8
A59: 3.14 | B59: SM-JAN-ALU-X Folhas Maximar - X Folhas Fixas Inf:3 Folhas(2-1)-133x200cm-Vidro 8mm | C59: m² | D59: 18.62
...

Sheet ESQUADRIAS
A3: ESQUADRIAS
A4: Data | B4: 45460
A5: Arquivo base | B5: -
A7: ESQUADRIAS
A9: Descrição | B9: Parâmetro | D9: Quantidade | G9: Valor total | H9: Observação | I9: MT | J9: MT Total | K9: MO | L9: MO Total
A10: Esquadrias de Alumínio | B10: 0.2 | C10: m² / AC | D10: =SUM(ARQUITETURA!D46:D47,ARQUITETURA!D55:D76) -> 1035.85 | E10: m² | F10: 1290 | G10: =F10*D10*1 -> 1336246.5 | I10: =F10 -> 1290 | J10: =I10*$D10 -> 1336246.5 | L10: =K10*$D10 -> 0 | M10: Terceiro
A11: Pele de vidro | D11: =SUM(ARQUITETURA!D78:D80) -> 343.78 | E11: m² | F11: 980 | G11: =F11*D11*1 -> 336904.4 | H11: lojas | I11: =F11 -> 980 | J11: =I11*$D11 -> 336904.4 | L11: =K11*$D11 -> 0 | M11: Terceiro
A12: Portão de alumínio | D12: 1 | E12: un | F12: 16000 | G12: =F12*D12*1 -> 16000 | I12: =F12 -> 16000 | J12: =I12*$D12 -> 16000 | L12: =K12*$D12 -> 0 | M12: Terceiro
A13: Guarda-corpo - vidro | D13: =SUM(ARQUITETURA!D51:D54) -> 313.06 | E13: m² | F13: =750*1.1 -> 825 | G13: =F13*D13*1 -> 258274.5 | I13: =F13 -> 825 | J13: =I13*$D13 -> 258274.5 | L13: =K13*$D13 -> 0 | M13: Terceiro
A14: Gradil | D14: =ARQUITETURA!$E$50+ARQUITETURA!E48 -> 65.78 | E14: m² | F14: 610 | G14: =F14*D14*1 -> 40125.8 | I14: =F14 -> 610 | J14: =I14*$D14 -> 40125.8 | L14: =K14*$D14 -> 0 | M14: Terceiro
A15: Serralherias | B15: 5 | C15: R$ / AC | D15: 1 | E15: vb | F15: =B15*DADOS_INICIAIS!$E$9 -> 26739.3 | G15: =F15*D15*1.1 -> 29413.23 | I15: =F15*1.1 -> 29413.23 | J15: =I15*$D15 -> 29413.23 | L15: =K15*$D15 -> 0 | M15: Emp
A16: PCF | D16: =2*(DADOS_INICIAIS!E15-2) -> 24 | E16: un | F16: 1750 | G16: =F16*D16*1 -> 42000 | I16: =F16-K16 -> 1450 | J16: =I16*$D16 -> 34800 | K16: 300 | L16: =K16*$D16 -> 7200 | M16: Emp
A17: Corrimão madeira | D17: =ARQUITETURA!D49 -> 124.45 | E17: m | F17: 85 | G17: =F17*D17*1 -> 10578.25 | I17: =F17 -> 85 | J17: =I17*$D17 -> 10578.25 | L17: =K17*$D17 -> 0 | M17: Terceiro
A18: Fechadura Biometrica | D18: =DADOS_INICIAIS!E10 -> 66 | E18: un | F18: 1500 | G18: =F18*D18*1 -> 99000 | H18: Fechadura consideraeda no Coline é de 1500,00 | I18: =F18 -> 1500 | J18: =I18*$D18 -> 99000 | L18: =K18*$D18 -> 0 | M18: Terceiro
A19: Esquadrias de Madeira | D19: =SUM(ARQUITETURA!D82:D85) -> 103 | E19: un | F19: =2200+350 -> 2550 | G19: =F19*D19*1 -> 262650 | I19: =F19-K19 -> 2250 | J19: =I19*$D19 -> 231750 | K19: 300 | L19: =K19*$D19 -> 30900 | M19: Emp
A20: TOTAL | G20: =SUM(G10:G19) -> 2431192.7
A22: TOTAL ESQUADRIAS | G22: =G20 -> 2431192.7 | H22: =G22/DADOS_INICIAIS!E9 -> 454.61038

Sheet COBERTURA
A2: COBERTURA
A3: Data | B3: 45460
A4: Arquivo base | B4: -
A6: TELHADO
A8: Descrição | B8: Parâmetro | D8: Quantidade | F8: Preço unitário | G8: Valor total | H8: Observação
A9: Estrutura e telhamento | D9: 266.19 | E9: m² | F9: 500 | G9: =F9*D9*1.1 -> 146404.5
A10: Serviços complementares | D10: =D9 -> 266.19 | E10: m² | F10: 45 | G10: =F10*D10*1.1 -> 13176.405
A11: Pergolados | G11: =F11*D11*1.1 -> 0
A12: Passarelas | G12: =F12*D12*1.1 -> 0
A13: TOTAL | G13: =SUM(G9:G12) -> 159580.9
A15: TOTAL COMPLEMENTARES | G15: =G13 -> 159580.9 | H15: =G15/DADOS_INICIAIS!$E$9 -> 29.840143

Sheet Rev. Fachada
A2: ORÇAMENTO PARAMÉTRICO GERENCIAMENTO EXECUTIVO
A7: Cliente | B7: Passe
A8: Obra | B8: Connect
A9: Data | B9: 45460
A10: Revisão | B10: R00
A12: REVESTIMENTOS ARGAMASSADOS
A14: Descrição | B14: Quantidade | D14: Parâmetro | F14: Referência | G14: Valor total | I14: MT | J14: MT Total | K14: MO | L14: MO Total | O14: Versão Sem Fachada Ventilada Com Textura Comum
A15: Chapisco e reboco | B15: =SUM(ARQUITETURA!$D$15:$D$30) -> 2609.4 | C15: m² | D15: =25+70 -> 95 | E15: R$ / m² | F15: - | G15: =B15*D15*1 -> 247893 | I15: 25 | J15: =I15*$B15 -> 65235 | K15: 70 | L15: =K15*$B15 -> 182658 | M15: Emp | O15: Descrição | P15: Qtdade | Q15: Custo Unit | R15: Custo Total
A16: Trtamento de friso | B16: =(K9*2+K10*7)*0 -> 0 | C16: m | D16: 5 | E16: R$ / m² | F16: - | G16: =B16*D16*1.1 -> 0 | O16: Chapisco e reboco | P16: =B15 -> 2609.4 | Q16: =D15*1.1 -> 104.5 | R16: =Q16*P16 -> 272682.3
A17: TOTAL | G17: =SUM(G15:G16) -> 247893 | O17: Textura | P17: =P16 -> 2609.4 | Q17: =D23*1.1 -> 99 | R17: =Q17*P17 -> 258330.6
R18: =SUM(R16:R17) -> 531012.9 | S18: =R18/DADOS_INICIAIS!$E$9 -> 99.294465
A19: PINTURA
A21: Descrição | B21: Quantidade | D21: Parâmetro | F21: Referência | G21: Valor total
A22: Selador | B22: =B30 -> 1614.96 | C22: m² | D22: =0.16*17+20 -> 22.72 | E22: R$ / m² | F22: - | G22: =B22*D22*1 -> 36691.891 | H22: *Fachada Ventilada | I22: =0.16*17 -> 2.72 | J22: =I22*$B22 -> 4392.6912 | K22: 20 | L22: =K22*$B22 -> 32299.2 | M22: Emp
A23: Textura | B23: =B15-B30 -> 994.44 | C23: m² | D23: =30+60 -> 90 | E23: R$ / m² | F23: - | G23: =B23*D23*1 -> 89499.6 | I23: 25 | J23: =I23*$B23 -> 24861 | K23: 52 | L23: =K23*$B23 -> 51710.88 | M23: Emp
A24: Patilha | B24: =B15*0.2*0 -> 0 | C24: m² | D24: =110+2.25+65 -> 177.25 | E24: R$ / m² | F24: - | G24: =B24*D24*1.1 -> 0
A25: TOTAL | G25: =SUM(G22:G24) -> 126191.49
A27: ACABAMENTOS ESPECIAIS
A29: Descrição | B29: Quantidade | D29: Parâmetro | F29: Referência | G29: Valor total
A30: FACHADA VENTILADA COM PORCELANATO | B30: =ARQUITETURA!D18+ARQUITETURA!D19+ARQUITETURA!D21+ARQUITETURA!D23+ARQUITETURA!D25+ARQUITETURA!D27+ARQUITETURA!D28+ARQUITETURA!D30 -> 1614.96 | C30: m² | D30: =702+200 -> 902 | E30: R$ / m² | F30: - | G30: =B30*D30*1 -> 1456693.9 | I30: =D30 -> 902 | J30: =I30*$B30 -> 1456693.9 | L30: =K30*$B30 -> 0 | M30: Terceiro
A31: ACM embasamento | C31: m² | D31: 850 | E31: R$ / m² | F31: - | G31: =B31*D31*1.1 -> 0
A32: Led vertical | C32: m | D32: 120 | E32: R$ / m | F32: - | G32: =B32*D32*1.1 -> 0
A33: Brise Amadeirado embasamento | C33: m² | D33: 1800 | E33: R$ / m² | F33: - | G33: =B33*D33*1.1 -> 0
G34: =SUM(G30:G33) -> 1456693.9
A37: TOTAL FACHADA | G37: =G25+G17+G34 -> 1830778.4 | H37: =G37/DADOS_INICIAIS!$E$9 -> 342.33851
H38: =H37/1.1 -> 311.21683

Sheet COMPLEMENTARES
A2: COMPLEMENTARES
A3: Data | B3: 45460
A4: Arquivo base | B4: -
A6: SERVIÇOS COMPLEMENTARES
A8: Descrição | B8: Parâmetro | D8: Quantidade | F8: Valor total
A9: Móveis e decoração - ENXOVAL ÁREAS PRIVATIVAS | B9: 1990 | C9: R$ / AP | D9: =SUM('Obra '!E24:E30) -> 2822.4 | E9: m² | F9: =D9*B9*1.1 -> 6178233.6 | G9: * Base Trindade
A10: Móveis e decoração | B10: 1700 | C10: R$ / AL | D10: =DADOS_INICIAIS!E21 -> 813.67 | E10: m² | F10: =D10*B10*1.1 -> 1521562.9
A11: Comunicação visual | B11: 10 | C11: R$ / AC | D11: =B11*DADOS_INICIAIS!$E$9 -> 53478.6 | E11: vb | F11: =D11*1.1 -> 58826.46
A12: Paisagismo | B12: 9 | C12: R$ / AC | D12: =B12*DADOS_INICIAIS!$E$9 -> 48130.74 | E12: vb | F12: =D12*1.1 -> 52943.814
A13: Ligações definitivas | B13: 4 | C13: R$ / AC | D13: =B13*DADOS_INICIAIS!$E$9 -> 21391.44 | E13: vb | F13: =D13*1.1 -> 23530.584
A14: Desmobilização | B14: 5 | C14: R$ / AC | D14: =B14*DADOS_INICIAIS!$E$9 -> 26739.3 | E14: vb | F14: =D14*1.1 -> 29413.23
A15: Limpeza | B15: 15 | C15: R$ / AC | D15: =B15*DADOS_INICIAIS!$E$9 -> 80217.9 | E15: vb | F15: =D15*1.1 -> 88239.69
A16: TOTAL | F16: =SUM(F10:F15) -> 1774516.7
A18: TOTAL COMPLEMENTARES | F18: =F16 -> 1774516.7 | G18: =F18/DADOS_INICIAIS!$E$9 -> 331.81809

Sheet Auxiliar
A2: 2 Portões acesso garagem - Área: 9,2m² x 2 = 18,4m² | B2: 2 | C2: portão | D2: 18.4
A3: 2 portas corta-fogo 1 folha | B3: 2 | C3: pcf
A4: 1 porta de correr alumínio 2 folhas – Área: 3,465m² | B4: 1 | C4: porta alumínio | D4: 3.465
A5: 1 porta de correr alumínio 2 folhas – Área: 1,7325m² | B5: 1 | C5: porta alumínio | D5: 1.7325 | G5: Guarda alumínio | H5: =SUMIF(C:C,G5,D:D) -> 400.5221
A6: 2 portas de abrir alumínio 2 folhas – Área: 2,6376m² x 2 = 5,2752m² | B6: 2 | C6: porta alumínio | D6: 5.2752 | G6: janela | H6: =SUMIF(C:C,G6,D:D) -> 1895.06
A7: 1 porta de abrir alumínio 2 folhas – Área: 4,1916m² | B7: 1 | C7: porta alumínio | D7: 4.1916 | G7: madeira | H7: =SUMIF(C:C,G7,B:B) -> 218
A8: 1 porta pivotante | B8: 1 | C8: pivotante | G8: pcf | H8: =SUMIF(C:C,G8,B:B) -> 60
A9: 19 portas de abrir madeira 1 folha | B9: 19 | C9: madeira | G9: pivotante | H9: =SUMIF(C:C,G9,B:B) -> 1
A10: 3 portas de abrir vidro 1 folha – Área: 2,1m² x 3 = 6,3m² | B10: 3 | C10: porta alumínio | D10: 6.3 | G10: porta alumínio | H10: =SUMIF(C:C,G10,D:D) -> 46.62
A11: 2 portas de abrir vidro 1 folha – Área: 1,89m² x 2 = 3,78m² | B11: 2 | C11: porta alumínio | D11: 3.78 | G11: portão | H11: =SUMIF(C:C,G11,B:B) -> 2
A12: 1 porta de abrir alumínio 1 folha – Área: 2,0076m² | B12: 1 | C12: porta alumínio | D12: 2.0076 | G12: gradil | H12: =SUMIF(C:C,G12,D:D) -> 113.88
A13: Janelas – Área: 3,75 + 4,875 + 2,5 + 1,1 + 1,2 + 5,5402 + 4,4874 = 23,4526m² | C13: janela | D13: 23.4526 | G13: Brise | H13: 109.3146
A14: Muro de vidro – Área: 7,0774 + 5,485 + 3,43 + 4,8138 = 20,8062m² | C14: Guarda alumínio | D14: 20.8062
A15: 8 portas corta-fogo 1 folha | B15: 8 | C15: pcf
A16: Janelas – Area: (1,1 + 1,2 + 28,7391) x 4 = 124,1564m² | C16: janela | D16: 124.1564
A17: 2 portas corta-fogo 1 folha | B17: 2 | C17: pcf
A18: 2 portas de abrir alumínio 1 folha – Área: 1,47m² x 2 = 2,94m² | B18: 2 | C18: porta alumínio | D18: 2.94
A19: 2 portas de abrir vidro 1 folha – Área: 1,89m² x 2 = 3,78m² | B19: 2 | C19: porta alumínio | D19: 3.78
A20: 5 portas de abrir madeira 1 folha | B20: 5 | C20: madeira
A21: 1 janela-porta de correr vidro – Área: 14,7348m² | B21: 1 | C21: janela | D21: 14.7348
A22: Janelas – Área: 1,2894 + 1,2894 + 23,46 + 1,854 + 5,562 + 5,562 + 1,854 + 1,854 + 1,1 + 1,2 = 45,0248m² | C22: janela | D22: 45.0248
A23: Guarda corpo vidro – Área: 7,5299 + 5,7955 + 6,5555 = 19,8809m² | C23: Guarda alumínio | D23: 19.8809
A24: 38 portas corta-fogo 1 folha | B24: 38 | C24: pcf
A25: 171 portas de abrir madeira 1 folha | B25: 171 | C25: madeira
A26: 19 porta de abrir alumínio 1 folha – Área: 1,26m² x 19 = 23,94m² | B26: 19 | C26: porta alumínio | D26: 23.94
A27: 19 janela-porta de correr vidro 5 folhas - Área: 25,4205m² x 19 = 482,9895m² | B27: 19 | C27: janela | D27: 482.9895
A28: 19 janela-porta de correr vidro 5 folhas - Área: 17,8284m² x 19 = 338,7396m² | B28: 19 | C28: janela | D28: 338.7396
A29: Janelas – Área: 1,1 + 1,1 + 1,2 + 1,92 + 0,36 + 2,781 + 2,781 + 1,854 + 1,854 + 5,562 + 5,562 + 1,854 = 27,928m² x 19 = 530,632m² | C29: janela | D29: 530.632
A30: Guarda corpo metálico – Área: 4,745m² x 19 = 90,155m² - Perímetro: 3,65m x 19 = 69,35m | C30: gradil | D30: 90.155
A31: Guarda corpo vidro – Área: 15,645m² x 19 = 297,255m² - Perímetro: 14,9m x 19 = 283,1m | C31: Guarda alumínio | D31: 297.255
A32: 2 portas corta-fogo 1 folha | B32: 2 | C32: pcf
A33: 2 portas de abrir madeira 1 folha | B33: 2 | C33: madeira
A34: 1 porta de abrir alumínio 1 folha – Área: 1,26m² | B34: 1 | C34: porta alumínio | D34: 1.26
A35: 1 janela-porta de correr vidro 3 folhas - Área: 15,21m² | B35: 1 | C35: janela | D35: 15.21
A36: 1 janela-porta de correr vidro 5 folhas - Área: 25,4205m² | B36: 1 | C36: janela | D36: 25.4205
A37: 1 janela-porta de correr vidro 5 folhas - Área: 17,8284m² | B37: 1 | C37: janela | D37: 17.8284
A38: Janelas – Área: 1,1 + 1,2 + 1,1 + 1,92 + 0,36 + 2,781 + 2,781 + 1,854 + 1,854 + 5,562 + 5,562 + 1,854 = 27,928m² | C38: janela | D38: 27.928
A39: Guarda corpo metálico – Área: 4,745m² - Perímetro: 3,65m | C39: gradil | D39: 4.745
A40: Guarda corpo vidro – Área: 15,645m² - Perímetro: 14,9m | C40: Guarda alumínio | D40: 15.645
A41: 2 portas corta-fogo 1 folha | B41: 2 | C41: pcf
...
