Workbook
Name \0: #REF!
Name \0: #REF!
Name \0: #REF!
Name \0: #REF!
Name \0: #REF!
Name \0: #REF!
Name \0: #REF!
Name \a: #REF!
Name \a: #REF!
Name \m: #REF!
Name \m: #REF!
Name aa: #REF!
Name aa: #REF!
Name aaaa: '[1]M.O.'!#REF!
Name aaaa: '[1]M.O.'!#REF!
Name aaaa: '[1]M.O.'!#REF!
Name aaaa: '[1]M.O.'!#REF!
Name aaaa: '[1]M.O.'!#REF!
Name aaaa: '[1]M.O.'!#REF!
Name aaaa: '[1]M.O.'!#REF!
Name angelo: [2]Geral!#REF!
Name angelo: [2]Geral!#REF!
Name angelo: [2]Geral!#REF!
Name angelo: [2]Geral!#REF!
Name angelo: [2]Geral!#REF!
Name angelo: [2]Geral!#REF!
Name angelo: [2]Geral!#REF!
Name area: #REF!
Name aux: #REF!
Name aux: #REF!
Name aux: #REF!
Name aux: #REF!
Name aux: #REF!
Name aux: #REF!
Name aux: #REF!
Name BDA: #REF!
Name BDA: #REF!
Name BDI: #REF!
Name ca: #REF!
Name Capa: #REF!
Name cronograma: #REF!
Name D: #REF!
Name direto: #REF!
Name DRE: #REF!
Name ea: #REF!
Name FFFFFFF: #REF!
Name FFFFFFF: #REF!
Name FFFFFFF: #REF!
Name FFFFFFF: #REF!
Name FFFFFFF: #REF!
Name FFFFFFF: #REF!
Name FFFFFFF: #REF!
Name item_1: #REF!
Name item_1: #REF!
Name item_1: #REF!
Name item_1: #REF!
Name item_1: #REF!
Name item_1: #REF!
Name item_1: #REF!
Name LS: '[1]M.O.'!#REF!

Sheet DADOS_INICIAIS
A1: Obra | B1: Eternity
A2: Empresa | B2: Meia Praia Empreendiementos
A3: Revisão | B3: R00
A4: Arquitetura base | B4: Eternity - Arquitetonico
A5: DADOS OBRA
B7: Descrição | C7: Identificador | D7: Unidade | E7: Quantidade
B8: ÁREA DO TERRENO | C8: AT | D8: M2 | E8: 304.5
B9: ÁREA TOTAL CONSTRUÍDA | C9: AC | D9: M2 | E9: 11892.95
B10: UNIDADES RESIDENCIAIS | C10: UR | D10: UN | E10: =2*E16 -> 46
B11: Dormitórios | C11: dorm | D11: UN | E11: =3*E10 -> 138
B12: Banheiros | C12: ban | D12: UN | E12: =4*E10 -> 184
B13: UNIDADES COMERCIAIS | C13: UC | D13: UN | E13: 5
B14: Churrasqueiras | C14: CHU | D14: UN | E14: ='SISTEMAS ESPECIAIS'!B10 -> 48
B15: NÚMERO TOTAL DE PAVIMENTOS | C15: NP | D15: UN | E15: 28
B16: NÚMERO DE PAVIMENTOS TIPO | C16: NPT | D16: UN | E16: 23
B17: NÚMERO DE PAVIMENTOS TIPO DIFERENCIADOS | C17: NPD | D17: UN | E17: 0
B18: NÚMERO DE PAVIMENTOS DUPLEX | C18: ND | D18: UN | E18: 0
B19: ÁREA DE PROJEÇÃO DA TORRE | C19: APT | D19: M2 | E19: 329.13
B20: PERÍMETRO DE PROJEÇÃO DA TORRE | C20: PPT | D20: M | E20: 76.48
B21: ÁREA DE LAZER | C21: AL | D21: M2 | E21: 895
B22: ÁREA DO EMBASAMENTO | C22: AE | D22: M2 | E22: =855.2+895*4 -> 4435.2
B23: ÁREA DE SUBSOLOS | C23: S | D23: M2 | E23: 0
B24: NÚMERO DE SUBSOLOS | C24: NS | D24: UN | E24: 0
B25: ÁREA DE PROJEÇÃO DO EMBASAMENTO | C25: APE | D25: M2 | E25: 898.56
B26: PERÍMETRO DE PROJEÇÃO DE EMBAMENTO | C26: PE | D26: M | E26: 119.84
B27: NÚMERO DE PAVIMENTOS DE EMBASAMENTO | C27: NE | D27: UN | E27: 5

Sheet MOVIMENTAÇÃO_DE_TERRA
A2: MOVIMENTAÇÃO DE TERRA
A3: Data | B3: 45472
A4: Arquivo base | B4: -
A6: ESCAVAÇÃO VERTICAL DE SUBSOLO
A8: Descrição | B8: Área de subsolo (m) | C8: Altura do subsolo (m) | D8: Volume total de escavação (m3) | E8: Preço unitário de escavação (R$ / m3) | F8: Valor total | G8: Observação
A9: Escavação | B9: =DADOS_INICIAIS!E23 -> 0 | D9: =C9*B9 -> 0 | E9: 0 | F9: =E9*D9*1.1 -> 0
A10: TOTAL | F10: =SUM(F9:F9) -> 0
A12: REBAIXAMENTO DE LENÇOL FREÁTICO
A14: Descrição | B14: Quantidade (dias) | E14: Preço unitário de rebaixamento (R$ / dias) | F14: Valor total | G14: Observação
A15: Rebaixamento de lençol | B15: 0 | E15: 200 | F15: =B15*E15*1.1 -> 0
A16: TOTAL | F16: =SUM(F15:F15) -> 0
A18: ESCAVAÇÃO E REATERRO DE VALAS
A20: Descrição | B20: Parâmetro | D20: Volume total de escavação (m3) | E20: Preço unitário (R$ / m3) | F20: Valor total | G20: Observação
A21: Escavação mecanizada para blocos e baldrames | B21: 1.3 | C21: m³ / Vol infra | D21: =B21*INFRAESTRUTURA!D29 -> 759.2832 | E21: 60 | F21: =E21*D21*1.1 -> 50112.691
A22: Reaterro para blocos e baldrames | B22: 0.6 | C22: m³ / Vol Escavação | D22: =D21-INFRAESTRUTURA!D29 -> 175.2192 | E22: 20 | F22: =E22*D22*1.1 -> 3854.8224
A23: Movimentação de bota-fora | B23: 1.3 | D23: =(D21-D22)*B23 -> 759.2832 | E23: 40 | F23: =E23*D23*1.1 -> 33408.461
A24: Movimentação de terra das estacas | B24: 1 | C24: m³ | D24: =INFRAESTRUTURA!D19 -> 872.82869 | E24: 40 | F24: =E24*D24*1.1 -> 38404.462
A25: TOTAL | F25: =SUM(F21:F24) -> 125780.44
A27: REGULARIZAÇÃO E APILOAMENTO DE FUNDO DE VALAS
A29: Descrição | B29: Parâmetro | D29: Área de lastro (m²) | E29: Preço unitário (R$ / m2) | F29: Valor total | G29: Observação
A30: Lastro de concreto magto e=5cm | B30: 0.8 | C30: m² / APE | D30: =B30*DADOS_INICIAIS!E25 -> 718.848 | E30: =370*0.05 -> 18.5 | F30: =E30*D30*1.1 -> 14628.557 | G30: Definição trazida do Celebration da Passe | H30: =F30/DADOS_INICIAIS!E25 -> 16.28
A31: TOTAL | F31: =SUM(F30:F30) -> 14628.557
A33: TOTAL MOVIMENTAÇÃO DE TERRA | F33: =F10+F16+F25+F31 -> 140408.99 | G33: =F33/DADOS_INICIAIS!E9 -> 11.806069

Sheet CONTENÇÕES
A3: CONTENÇÃO
A4: Data
A5: Arquivo base
A7: CORTINA DE ESTACAS
A9: Descrição | B9: Parâmetro | D9: Quantidade | F9: Preço unitário | G9: Valor total
A10: Número de Estacas | B10: 0.15 | C10: un / APE | D10: =B10*DADOS_INICIAIS!E25 -> 134.784 | E10: un
A11: Estaca Hélice Continua Diâmetro 40 | B11: 0.1 | D11: =B11*$D$10 -> 13.4784 | E11: un
B12: 20 | C12: m/un | D12: =B12*D11 -> 269.568 | E12: m | G12: =F12*D12 -> 0
A13: Estaca Hélice Continua Diâmetro 50 | B13: 0.5 | D13: =B13*$D$10 -> 67.392 | E13: un
B14: 20 | C14: m/un | D14: =B14*D13 -> 1347.84 | E14: m | G14: =F14*D14 -> 0
A15: Estaca Hélice Continua Diâmetro 60 | B15: 0.4 | C15: un / APE | D15: =B15*$D$10 -> 53.9136 | E15: un
B16: 20 | C16: m/un | D16: =B16*D15 -> 1078.272 | E16: m | G16: =F16*D16 -> 0
A17: Concreto | B17: =(PI()*0.4^2)/4*D14+(PI()*0.5^2)/4*D16+(PI()*0.6^2)/4*D12 -> 457.31134 | C17: un / APE | D17: =(PI()*0.4^2)/4*D14+(PI()*0.5^2)/4*D16+(PI()*0.6^2)/4*D12 -> 457.31134 | E17: m³ | G17: =F17*D17 -> 0
A18: Armação 6,3mm | B18: 1.6575131 | C18: kg / m³ | D18: =B18*D17 -> 757.99954 | E18: kg | G18: =F18*D18 -> 0
A19: Armação 16mm | B19: 10.178338 | C19: kg / m³ | D19: =B19*D17 -> 4654.6692 | E19: kg | G19: =F19*D19 -> 0
A20: Mobilização | B20: 1 | C20: vb | D20: 1 | E20: vb | G20: =F20*D20 -> 0
A21: TOTAL | G21: =SUM(G10:G20) -> 0
A23: PAREDE DE CONCRETO
A25: Descrição | B25: Parâmetro | D25: Quantidade | F25: Preço unitário | G25: Valor total
A26: Fabricação, montagem e desmontagem de forma para blocos e baldrames resinado | B26: 2.1 | C26: m² / APE | D26: =B26*DADOS_INICIAIS!E25 -> 1886.976 | E26: m² | G26: =F26*D26 -> 0
A27: Concreto | B27: 0.65 | C27: m³ / APE | D27: =B27*DADOS_INICIAIS!E25 -> 584.064 | E27: m³ | G27: =F27*D27 -> 0
A28: Armação | B28: 110 | C28: kg / m³ | D28: =B28*D27 -> 64247.04 | E28: kg | G28: =F28*D28 -> 0
A29: Mão de obra | B29: =SUPRAESTRUTURA!B15*1.5 -> 360 | C29: R$ / APE | D29: =DADOS_INICIAIS!E25 -> 898.56 | E29: m² | F29: =B29 -> 360 | G29: =F29*D29 -> 323481.6
A30: TOTAL | G30: =SUM(G26:G29) -> 323481.6
A33: PAREDE DIAFRAGMA
A35: Descrição | B35: Parâmetro | D35: Quantidade | F35: Preço unitário | G35: Valor total
A36: Fabricação, montagem e desmontagem de forma para blocos e baldrames resinado | B36: 2.1 | C36: m² / APE | D36: =B36*DADOS_INICIAIS!E35 -> 0 | E36: m² | G36: =F36*D36 -> 0
A37: Concreto | B37: 0.65 | C37: m³ / APE | D37: =B37*DADOS_INICIAIS!E35 -> 0 | E37: m³ | G37: =F37*D37 -> 0
A38: Armação | B38: 110 | C38: kg / m³ | D38: =B38*D37 -> 0 | E38: kg | G38: =F38*D38 -> 0
A39: Mão de obra | B39: =SUPRAESTRUTURA!B70*1.5 -> 0 | C39: R$ / APE | D39: =DADOS_INICIAIS!E35 -> 0 | E39: m² | F39: =B39 -> 0 | G39: =F39*D39 -> 0
A40: TOTAL | G40: =SUM(G36:G39) -> 0
A46: TOTAL INFRAESTRUTURA | G46: =G21+G30 -> 323481.6 | H46: =G46/DADOS_INICIAIS!E9 -> 27.199442

Sheet INFRAESTRUTURA
A3: INFRAESTRUTURA
A4: Data | B4: 45472
A5: Arquivo base | B5: -
A7: FUNDAÇÃO PROFUNDA
A9: Descrição | B9: Parâmetro | D9: Quantidade | F9: Preço unitário | G9: Valor total | H9: Observação
A10: Número de Estacas | B10: 0.15 | C10: un / APE | D10: =ROUNDUP(B10*DADOS_INICIAIS!$E$25,0) -> 135 | E10: un | H10: Base obra Trindade Parkside
A11: Estaca Hélice Continua Diâmetro 40 | B11: 0 | D11: =ROUNDUP(B11*$D$10,0) -> 0 | E11: un
B12: 28 | C12: m/un | D12: =B12*D11 -> 0 | E12: m | F12: 70 | G12: =F12*D12*1.1 -> 0
A13: Estaca Hélice Continua Diâmetro 50 | B13: 0.6 | D13: =ROUNDUP(B13*D10,0) -> 81 | E13: un
B14: 28 | C14: m/un | D14: =B14*D13 -> 2268 | E14: m | F14: 90 | G14: =F14*D14*1.1 -> 224532
A15: Estaca Hélice Continua Diâmetro 60 | B15: 0.4 | C15: un / APE | D15: =ROUNDUP(B15*$D$10,0) -> 54 | E15: un
B16: 28 | C16: m/un | D16: =B16*D15 -> 1512 | E16: m | F16: 105 | G16: =F16*D16*1.1 -> 174636
A17: Estaca Hélice Continua Diâmetro 80 | B17: 0 | C17: un / APE | D17: =ROUNDUP(B17*$D$10,0) -> 0 | E17: un
B18: 30 | C18: m/un | D18: =B18*D17 -> 0 | E18: m | F18: 120 | G18: =F18*D18*1.1 -> 0
A19: Concreto (40 Mpa) | B19: 1.3 | C19: perda | D19: =(PI()*((0.4^2)/4)*D12+PI()*((0.5^2)/4)*D14+PI()*((0.6^2)/4)*D16) -> 872.82869 | E19: m³ | F19: =535+45 -> 580 | G19: =F19*D19*B19*1.1 -> 723924.11
A20: Armação | B20: 12 | C20: kg / m³ | D20: =B20*D19 -> 10473.944 | E20: kg | F20: 7.62 | G20: =F20*D20*1.1 -> 87792.601
A21: Mobilização | B21: 1 | C21: vb | D21: 1 | E21: vb | F21: 12500 | G21: =F21*D21*1.1 -> 13750
A22: Apoio e arrasamento de estacas | D22: =D10 -> 135 | E22: un | F22: 300 | G22: =F22*D22*1 -> 40500
A23: TOTAL | G23: =SUM(G10:G22) -> 1265134.7
A25: FUNDAÇÃO RASA
A27: Descrição | B27: Parâmetro | D27: Quantidade | F27: Preço unitário | G27: Valor total | H27: Observação
A28: Fabricação, montagem e desmontagem de forma para blocos e baldrames resinado | B28: 1.1 | C28: m² / APE | D28: =B28*DADOS_INICIAIS!E25 -> 988.416 | E28: m² | F28: 68 | G28: =F28*D28*1.1 -> 73933.517
A29: Concreto (40 Mpa) | B29: 0.65 | C29: m³ / APE | D29: =B29*DADOS_INICIAIS!E25 -> 584.064 | E29: m³ | F29: =535+45 -> 580 | G29: =F29*D29*1.05*1.1 -> 391264.47
A30: Armação | B30: 80 | C30: kg / m³ | D30: =B30*D29 -> 46725.12 | E30: kg | F30: 7.62 | G30: =F30*D30*1.1 -> 391649.96 | H30: Base obra Trindade Parkside
A31: Piso de concreto armado | B31: 1 | C31: m² / APE | D31: =B31*DADOS_INICIAIS!E25 -> 898.56 | E31: m² | F31: 180 | G31: =F31*D31*1.1 -> 177914.88
A32: Mão de obra | B32: =SUPRAESTRUTURA!B15*1.5 -> 360 | C32: R$ / APE | D32: =DADOS_INICIAIS!E25 -> 898.56 | E32: m² | F32: =B32 -> 360 | G32: =F32*D32*1.1 -> 355829.76
A33: TOTAL | G33: =SUM(G28:G32) -> 1390592.6
A36: TOTAL INFRAESTRUTURA | G36: =G23+G33 -> 2655727.3 | H36: =G36/DADOS_INICIAIS!E9 -> 223.30265
H38: =H36/1.1 -> 203.00241

Sheet SUPRAESTRUTURA
A3: SUPRAESTRUTURA
A4: Data | B4: 45472
A5: Arquivo base | B5: -
A7: SUPRAESTRUTURA - LAJE MACIÇA
A9: Descrição | B9: Parâmetro | D9: Quantidade | F9: Preço unitário | G9: Valor total | H9: Observação
A10: Fabricação forma | B10: 3 | C10: Jogos | D10: =(D11/DADOS_INICIAIS!$E$15)*B10 -> 3185.6116 | E10: m² | F10: 110 | G10: =F10*D10*1.1 -> 385459
A11: Montagem de forma | B11: 2.5 | C11: m² / AC | D11: =B11*DADOS_INICIAIS!$E$9 -> 29732.375 | E11: m² | F11: 2.5 | G11: =F11*D11*1.1 -> 81764.031
A12: Escoramento | B12: 4 | C12: un / AE | D12: =ROUNDUP(B12*DADOS_INICIAIS!$E$25*B10,0) -> 10783 | E12: un | F12: =17 -> 17 | G12: =F12*D12*1.1 -> 201642.1
A13: Concreto | B13: 0.22 | C13: m³ / AC | D13: =B13*DADOS_INICIAIS!$E$9 -> 2616.449 | E13: m³ | F13: =535+45 -> 580 | G13: =F13*D13*1.05*1.1 -> 1752759.2
A14: Armadura Convencional para Estrutura | B14: 110 | C14: kg / m³ | D14: =D13*B14 -> 287809.39 | E14: kg | F14: 7.62 | G14: =F14*D14*1.1 -> 2412418.3
A15: Mão de obra - estrutura em concreto armado | B15: 240 | C15: R$ / AC | D15: =DADOS_INICIAIS!$E$9 -> 11892.95 | E15: m² | F15: =B15 -> 240 | G15: =F15*D15*1.1 -> 3139738.8
A16: Perfuração de vigas | B16: 5300 | C16: R$ / NP | D16: 1 | E16: vb | F16: =B16*DADOS_INICIAIS!$E$15 -> 148400 | G16: =F16*D16*1.1 -> 163240 | H16: Coeficiente originário do Gran Torino (R$ 160,00/un) | I16: Nova utiliza a verba de 1.500,00 por pav
A17: TOTAL | G17: =SUM(G10:G16) -> 8137021.4 | K17: =4160+1440+1120+2880+4800+91680+4000 -> 110080 | L17: =K17/21 -> 5241.9048
A19: SUPRAESTRUTURA - LAJE CUBETAS
A21: Descrição | B21: Parâmetro | D21: Quantidade | F21: Preço unitário | G21: Valor total | H21: Observação
A22: Fabricação forma | B22: 2 | C22: Jogos | D22: =(D23/DADOS_INICIAIS!$E$15)*B22 -> 2123.7411 | E22: m² | F22: 110 | G22: =F22*D22*1.1 -> 256972.67
A23: Montagem de forma | B23: 2.5 | C23: m² / AC | D23: =B23*DADOS_INICIAIS!$E$9 -> 29732.375 | E23: m² | F23: 2.5 | G23: =F23*D23*1.1 -> 81764.031
A24: Escoramento | B24: 3 | C24: un / APT*NPT | D24: =ROUNDUP(B24*DADOS_INICIAIS!$E$25*B22,0) -> 5392 | E24: un | F24: =17 -> 17 | G24: =F24*D24*1.1 -> 100830.4
A25: Manutenção de escoramento proprio | D25: =D24 -> 5392 | E25: =E24 -> un | F25: 5 | G25: =F25*D25*1.1 -> 29656
A26: Cubetas | B26: 25 | C26: R$ / AC | D26: 1 | E26: vb | F26: =B26*DADOS_INICIAIS!$E$9 -> 297323.75 | G26: =F26*D26*1.1 -> 327056.12 | H26: =DADOS_INICIAIS!E19*3 -> 987.39 | I26: =G26/H26 -> 331.23297
A27: Concreto | B27: 0.25 | C27: m³ / AC | D27: =B27*DADOS_INICIAIS!$E$9 -> 2973.2375 | E27: m³ | F27: =535+45 -> 580 | G27: =F27*D27*1.05*1.1 -> 1991771.8 | I27: =I26/(24*30) -> 0.4600458
A28: Armadura Convencional para Estrutura | B28: 110 | C28: kg / m³ | D28: =D27*B28 -> 327056.12 | E28: kg | F28: 7.62 | G28: =F28*D28*1.1 -> 2741384.4
A29: Mão de obra - estrutura em concreto armado | B29: 240 | C29: R$ / AC | D29: =DADOS_INICIAIS!$E$9 -> 11892.95 | E29: m² | F29: =B29 -> 240 | G29: =F29*D29*1.1 -> 3139738.8
A30: Perfuração de vigas | B30: 5300 | C30: R$ / NP | D30: 1 | E30: vb | F30: =B30*DADOS_INICIAIS!$E$15 -> 148400 | G30: =F30*D30*1.1 -> 163240 | H30: Coeficiente originário do Gran Torino (R$ 160,00/un)
A31: TOTAL | G31: =SUM(G22:G30) -> 8832414.3
A33: SUPRAESTRUTURA - LAJE TRELIÇADA
A35: Descrição | B35: Parâmetro | D35: Quantidade | F35: Preço unitário | G35: Valor total | H35: Observação
A36: Fabricação forma | B36: 2 | C36: Jogos | D36: =(D37/DADOS_INICIAIS!$E$15)*B36 -> 0 | E36: m² | F36: 85 | G36: =F36*D36*1.1 -> 0
A37: Montagem de forma | B37: 2.1 | C37: m² / AC | D37: =B37*DADOS_INICIAIS!E38 -> 0 | E37: m² | F37: 1.5 | G37: =F37*D37*1.1 -> 0
A38: Escoramento - Torre | B38: 2 | C38: un / APT*NPT | D38: =B38*DADOS_INICIAIS!E47*DADOS_INICIAIS!E44 -> 0 | E38: un | F38: 17 | G38: =F38*D38*1.1 -> 0
A39: Escoramento - Embasamento | B39: 2 | C39: un / AE | D39: =B39*DADOS_INICIAIS!E50 -> 0 | E39: un | F39: 17 | G39: =F39*D39*1.1 -> 0
A40: Cubetas | B40: 25 | C40: R$ / AC | D40: =B40*DADOS_INICIAIS!E38 -> 0 | E40: m³ | F40: =B40 -> 25 | G40: =F40*D40*1.1 -> 0
A41: Concreto | B41: 0.25 | C41: m³ / AC | D41: =B41*DADOS_INICIAIS!E38 -> 0 | E41: m³ | F41: =575 -> 575 | G41: =F41*D41*1.05*1.1 -> 0
A42: Armadura Convencional para Estrutura | B42: 110 | C42: kg / m³ | D42: =D41*B42 -> 0 | E42: kg | F42: 7.25 | G42: =F42*D42*1.1 -> 0
A43: Mão de obra - estrutura em concreto armado | B43: 240 | C43: R$ / AC | D43: =DADOS_INICIAIS!E38 -> 0 | E43: m² | F43: =B43 -> 240 | G43: =F43*D43*1.1 -> 0
A44: Perfuração de vigas | B44: 5300 | C44: R$ / NP | D44: 1 | E44: vb | F44: =B44*DADOS_INICIAIS!E43 -> 0 | G44: =F44*D44*1.1 -> 0 | H44: Coeficiente originário do Gran Torino (R$ 160,00/un)
A45: TOTAL | G45: =SUM(G36:G44) -> 0
A47: SUPRAESTRUTURA - LAJE PROTENDIDA
A49: Descrição | B49: Parâmetro | D49: Quantidade | F49: Preço unitário | G49: Valor total | H49: Observação
A50: Fabricação forma | B50: 3 | C50: Jogos | D50: =(D51/DADOS_INICIAIS!$E$15)*B50 -> 2675.9138 | E50: m² | F50: 110 | G50: =F50*D50*1.1 -> 323785.56
...

Sheet ALVENARIA
A3: PAREDES E PAINÉIS
A4: Data | B4: 45469
A5: Arquivo base | B5: -
A7: ALVENARIA
A9: Descrição | B9: Parâmetro | D9: Quantidade | F9: Preço unitário | G9: Valor total | H9: Observação
A10: Alvenaria embasamento | B10: 1 | C10: m² / AE | D10: =B10*DADOS_INICIAIS!$E$22 -> 4435.2 | E10: m² | F10: 45 | G10: =F10*D10*1.1 -> 219542.4
A11: Alvenaria lazer | B11: 0.4 | C11: m² / AL | D11: =B11*DADOS_INICIAIS!$E$21 -> 358 | E11: m² | F11: 45 | G11: =F11*D11*1.1 -> 17721
A12: Alvenaria tipo | B12: 1.2 | C12: m² / APT*(NPT+2ND) | D12: =B12*(DADOS_INICIAIS!$E$19*(DADOS_INICIAIS!$E$16+DADOS_INICIAIS!$E$17)) -> 9083.988 | E12: m² | F12: 45 | G12: =F12*D12*1.1 -> 449657.41
A13: Alvenaria escadas | B13: 0.2 | C13: m² / AC | D13: =B13*DADOS_INICIAIS!$E$9 -> 2378.59 | E13: m² | F13: 70 | G13: =F13*D13*1.05*1.1 -> 192309
A14: Alvenaria cobertura / reservatório | B14: 0.4 | C14: m² / APT | D14: =B14*DADOS_INICIAIS!$E$19 -> 131.652 | E14: m² | F14: 45 | G14: =F14*D14*1.1 -> 6516.774
A15: Alvenaria refratárias | B15: 1.75 | C15: m² * CHU | D15: =B15*DADOS_INICIAIS!$E$14 -> 84 | E15: un | F15: 210 | G15: =F15*D15*1.1 -> 19404
A16: Serviços complementares | B16: 12.5 | C16: R$ / m² | D16: =D10+D11+D12+D13+D14 -> 16387.43 | E16: m² | F16: =B16 -> 12.5 | G16: =F16*D16*1.1 -> 225327.16
A17: Mão de obra | B17: 35 | C17: R$ / m² | D17: =D10+D11+D12+D13+D14 -> 16387.43 | E17: m² | F17: 35 | G17: =F17*D17*1.1 -> 630916.05
A18: TOTAL | G18: =SUM(G10:G17) -> 1761393.8 | K18: =4160+1440+1120+2880+4800+91680+4000 -> 110080 | L18: =K18/21 -> 5241.9048
A20: ALVENARIA - DRYWALL | G20: =G17/D17 -> 38.5
A22: Descrição | B22: Parâmetro | D22: Quantidade | F22: Preço unitário | G22: Valor total | H22: Observação
A23: Alvenaria embasamento | B23: 1 | C23: m² / AE | D23: =B23*DADOS_INICIAIS!$E$22 -> 4435.2 | E23: m² | F23: 45 | G23: =F23*D23*1.1 -> 219542.4
A24: Alvenaria lazer | B24: 0.4 | C24: m² / AL | D24: =B24*DADOS_INICIAIS!$E$21 -> 358 | E24: m² | F24: 45 | G24: =F24*D24*1.1 -> 17721
A25: Alvenaria tipo | B25: 1.65 | C25: m² / APT*(NPT+2ND) | D25: =B25*(DADOS_INICIAIS!$E$19*(DADOS_INICIAIS!$E$16+DADOS_INICIAIS!$E$17))*0.4 -> 4996.1934 | E25: m² | F25: 45 | G25: =F25*D25*1.1 -> 247311.57
A26: Drywall tipo | B26: 1.65 | C26: m² / APT*(NPT+2ND) | D26: =B26*(DADOS_INICIAIS!$E$19*(DADOS_INICIAIS!$E$16+DADOS_INICIAIS!$E$17))*0.6 -> 7494.2901 | E26: m² | F26: 220 | G26: =F26*D26*1.1 -> 1813618.2 | J26: =D26/(D30+D26) -> 0.37611407
A27: Alvenaria escadas | B27: 0.2 | C27: m² / AC | D27: =B27*DADOS_INICIAIS!$E$9 -> 2378.59 | E27: m² | F27: 70 | G27: =F27*D27*1.1 -> 183151.43 | J27: =1-J26 -> 0.62388593
A28: Alvenaria cobertura / reservatório | B28: 0.8 | C28: m² / APT | D28: =B28*DADOS_INICIAIS!$E$19 -> 263.304 | E28: m³ | F28: 45 | G28: =F28*D28*1.1 -> 13033.548
A29: Alvenaria refratárias | B29: 1.75 | C29: m² * CHU | D29: ='SISTEMAS ESPECIAIS'!B10 -> 48 | E29: un | F29: 210 | G29: =F29*D29*1.1 -> 11088
A30: Serviços complementares | B30: 12.5 | C30: R$ / m² | D30: =D24+D25+D23+D27+D28 -> 12431.287 | E30: m² | F30: =B30 -> 12.5 | G30: =F30*D30*1.1 -> 170930.2
A31: Mão de obra | B31: 35 | C31: R$ / m² | D31: =D24+D25+D23+D27+D28 -> 12431.287 | E31: m² | F31: 35 | G31: =F31*D31*1.1 -> 478604.56
A32: TOTAL | G32: =SUM(G23:G31) -> 3155000.9
A35: TOTAL ALVENARIA | G35: =G18 -> 1761393.8 | H35: =G35/DADOS_INICIAIS!E9 -> 148.10403
G38: =G35/1.1 -> 1601267.1 | H38: =G38/DADOS_INICIAIS!E9 -> 134.64003

Sheet INSTALAÇÕES
A2: INSTALAÇÕES
A4: INSTALAÇÕES ELÉTRICAS
A6: Descrição | B6: Parâmetro | D6: Valor total
A7: Entrada de Energia | B7: 5.5 | C7: R$ / AC | D7: =B7*DADOS_INICIAIS!$E$9*1.1 -> 71952.348
A8: Eletrodutos e Eletrocalhas | B8: 10 | C8: R$ / AC | D8: =B8*DADOS_INICIAIS!$E$9*1.1 -> 130822.45
A9: Cabos e Fiações | B9: 30 | C9: R$ / AC | D9: =B9*DADOS_INICIAIS!$E$9*1.1 -> 392467.35
A10: Quadros e Disjuntores | B10: 15 | C10: R$ / AC | D10: =B10*DADOS_INICIAIS!$E$9*1.1 -> 196233.68
A11: Acabamentos Elétricos | B11: 15 | C11: R$ / AC | D11: =B11*DADOS_INICIAIS!$E$9*1.1 -> 196233.68
A12: Equipamentos e Iluminação | B12: 15 | C12: R$ / AC | D12: =B12*DADOS_INICIAIS!$E$9*1.1 -> 196233.68
A13: Mão de Obra para Instalações Elétricas | B13: 60 | C13: R$ / AC | D13: =B13*DADOS_INICIAIS!$E$9*1.1 -> 784934.7 | E13: =D13/DADOS_INICIAIS!$E$9 -> 66
A14: TOTAL | D14: =SUM(D7:D13) -> 1968877.9
A16: INSTALAÇÕES HIDROSSANITÁRIAS
A18: Descrição | B18: Parâmetro | D18: Valor total
A19: Instalações de Água Fria | B19: 22 | C19: R$ / AC | D19: =B19*DADOS_INICIAIS!$E$9*1.1 -> 287809.39
A20: Instalações de Água Quente | B20: 20 | C20: R$ / AC | D20: =B20*DADOS_INICIAIS!$E$9*1.1 -> 261644.9
A21: Instalações de Águas Pluviais | B21: 10 | C21: R$ / AC | D21: =B21*DADOS_INICIAIS!$E$9*1.1 -> 130822.45
A22: Instalações Sanitárias | B22: 15 | C22: R$ / AC | D22: =B22*DADOS_INICIAIS!$E$9*1.1 -> 196233.68
A23: Louças e Metais | B23: 35 | C23: R$ / AC | D23: =B23*DADOS_INICIAIS!$E$9*1.1 -> 457878.58
A24: Mão de Obra para Instalações Hidráulicas | B24: 55 | C24: R$ / AC | D24: =B24*DADOS_INICIAIS!$E$9*1.1 -> 719523.48 | E24: =D24/DADOS_INICIAIS!$E$9 -> 60.5
A25: TOTAL | D25: =SUM(D19:D24) -> 2053912.5
A27: INSTALAÇÕES PREVENTIVAS E GLP
A29: Descrição | B29: Parâmetro | D29: Valor total
A30: Instalações Preventivas | B30: 20 | C30: R$ / AC | D30: =B30*DADOS_INICIAIS!$E$9*1.1 -> 261644.9
A31: Instalações de GLP | B31: 13 | C31: R$ / AC | D31: =B31*DADOS_INICIAIS!$E$9*1.1 -> 170069.19
A32: Instalações de Proteção e Aterramento - SPDA | B32: 8 | C32: R$ / AC | D32: =B32*DADOS_INICIAIS!$E$9*1.1 -> 104657.96
A33: TOTAL | D33: =SUM(D30:D32) -> 536372.05
A35: TOTAL INSTALAÇÕES | D35: =D14+D25+D33 -> 4559162.4 | E35: =D35/DADOS_INICIAIS!E9 -> 383.35
E37: =E35/1.1 -> 348.5

Sheet SISTEMAS ESPECIAIS
A2: SISTEMAS ESPECIAIS
A4: CLIMATIZAÇÃO, EXAUSTÃO MECÂNICA E PRESSURIZAÇÃO
A6: Descrição | B6: Quantidade | C6: Preço Unitário | D6: Valor total | G6: TERREO | H6: LAZER | I6: TIPO
A7: Infraestrutura para Instalação de Ar Condicionado | B7: =G7+H7+I7*23 -> 195 | C7: 1200 | D7: =B7*C7*1.1 -> 257400 | G7: =1+5 -> 6 | H7: =3+2 -> 5 | I7: =(3+1)*2 -> 8
A8: Instalação de Ar Condicionado | B8: =G8+H8+I8*23 -> 6 | C8: 5000 | D8: =B8*C8*1.1 -> 33000 | G8: =1 -> 1 | H8: =H7 -> 5 | I8: 0
A9: Ventokit | B9: =G9+H9+I9*23 -> 50 | C9: 900 | D9: =B9*C9*1.1 -> 49500 | G9: 0 | H9: =2+2 -> 4 | I9: =1*2 -> 2
A10: Churrasqueiras | B10: =G10+H10+I10*23 -> 48 | C10: 2600 | D10: =B10*C10*1.1 -> 137280 | G10: 0 | H10: =1+1 -> 2 | I10: 2
A11: TOTAL | D11: =SUM(D7:D10) -> 477180
A13: COMUNICAÇÃO
A15: Descrição | B15: Parâmetro | D15: Valor total
A16: CFTV | B16: 2 | C16: R$ / AC | D16: =B16*DADOS_INICIAIS!$E$9*1.1 -> 26164.49
A17: Interfone | B17: 5 | C17: R$ / AC | D17: =B17*DADOS_INICIAIS!$E$9*1.1 -> 65411.225
A18: TV e internet | B18: 3 | C18: R$ / AC | D18: =B18*DADOS_INICIAIS!$E$9*1.1 -> 39246.735
A19: Automação, telecomunicação e sistemas de segurança | B19: 5 | C19: R$ / AC | D19: =B19*DADOS_INICIAIS!$E$9*1.1 -> 65411.225
A20: TOTAL | D20: =SUM(D16:D19) -> 196233.68
A22: EQUIPAMENTOS
A24: Descrição | B24: Quantidade | C24: Preço Unitário | D24: Valor total
A25: Elevadores | B25: 2 | C25: =(768900/2) -> 384450 | D25: =B25*C25*1.1 -> 845790
A26: Grupo de geradores | B26: 1 | C26: 42000 | D26: =B26*C26*1.1 -> 46200
A27: Bombas | B27: 1 | C27: 10000 | D27: =B27*C27*1.1 -> 11000
A28: Infra de carro elétrico | B28: =DADOS_INICIAIS!E10 -> 46 | C28: 560 | D28: =B28*C28*1.1 -> 28336
A29: Equipamento de piscina | B29: 1 | C29: 25000 | D29: =B29*C29*1.1 -> 27500
A30: Sauna | B30: 1 | C30: 8000 | D30: =B30*C30*1.1 -> 8800
A31: Spa | B31: 2 | C31: 15000 | D31: =B31*C31*1.1 -> 33000
A32: Sistema de aquecimento | B32: 0 | C32: =55*DADOS_INICIAIS!E9 -> 654112.25 | D32: =B32*C32 -> 0
A33: TOTAL | D33: =SUM(D25:D32) -> 1000626
A35: OUTROS SISTEMAS ESPECIAIS
A37: Descrição | B37: Parâmetro | D37: Valor total
A38: Outros sistemas | B38: 20 | C38: R$ / AC | D38: =B38*DADOS_INICIAIS!E9*1.1 -> 261644.9
A39: TOTAL | D39: =SUM(D38:D38) -> 261644.9
A41: TOTAL SISTEMAS ESPECIAIS | D41: =D11+D20+D33+D39 -> 1935684.6 | E41: =D41/DADOS_INICIAIS!E9 -> 162.75899

Sheet IMPERMEABILIZAÇÃO
A3: IMPERMEABILIZAÇÃO
A4: Data | B4: 45471
A5: Arquivo base | B5: -
A7: IMPERMEABILIZAÇÃO
A9: Descrição | B9: Parâmetro | D9: Quantidade | F9: Preço unitário | G9: Valor total | H9: Observação
A10: Regularização de Superfície | B10: 25 | C10: R$ / m² | D10: =D14+D15 -> 4882.056 | E10: m² | F10: 8 | G10: =F10*D10*1.1 -> 42962.093
A11: Poço do elevador | B11: 45 | C11: R$ / m² | D11: =(3.24+(7.2)*1.8)*2 -> 32.4 | E11: m² | F11: =41-F19 -> 13 | G11: =F11*D11*1.1 -> 463.32
A12: Baldrames | B12: 30 | C12: R$ / m² | D12: =INFRAESTRUTURA!D28 -> 988.416 | E12: m² | F12: =35-F19 -> 7 | G12: =F12*D12*1.1 -> 7610.8032
A13: Ralos | B13: 1 | C13: R$ / AC | D13: 1 | E13: vb | F13: =B13*DADOS_INICIAIS!$E$9 -> 11892.95 | G13: =F13*D13*1.1 -> 13082.245 | H13: =G13/I13 -> 225.55595 | I13: =8+50 -> 58
A14: Impermeabilizações cimenticias | B14: 0.25 | C14: m² / AC | D14: =B14*DADOS_INICIAIS!E9 -> 2973.2375 | E14: m² | F14: =60-F20 -> 32 | G14: =F14*D14*1.1 -> 104657.96 | I14: =8/I13 -> 0.13793103 | J14: =I14*G13 -> 1804.4476
A15: Impermeabilizações com manta asfaltica | B15: 0.1605 | C15: m² / AC | D15: =B15*DADOS_INICIAIS!E9 -> 1908.8185 | E15: m² | F15: =110-F21 -> 62 | G15: =F15*D15*1.1 -> 130181.42 | I15: =50/I13 -> 0.86206897 | J15: =I15*G13 -> 11277.797
A16: Impermeabilização de peitoril | B16: 0.6 | C16: R$ / AC | D16: 1 | E16: vb | F16: =B16*DADOS_INICIAIS!$E$9 -> 7135.77 | G16: =F16*D16*1.1 -> 7849.347 | H16: =G16/I16 -> 107.5253 | I16: =41+32 -> 73
A17: Proteção Mecânica | B17: 28 | C17: R$ / m² | D17: =D15 -> 1908.8185 | E17: m² | F17: =28-F22 -> 12 | G17: =F17*D17*1.1 -> 25196.404 | I17: =41/I16 -> 0.56164384 | J17: =I17*G16 -> 4408.5374
A18: Mão de obra para regularização | D18: =D10 -> 4882.056 | E18: m² | F18: =22-F10 -> 14 | G18: =F18*D18*1.1 -> 75183.662 | I18: =32/I16 -> 0.43835616 | J18: =I18*G16 -> 3440.8096
A19: Mão de obra para impermeabilização de poço e baldrames | D19: =D11+D12 -> 1020.816 | E19: m² | F19: 28 | G19: =F19*D19*1.1 -> 31441.133
A20: Mão de obra impermeabilizações cimenticias | D20: =D14 -> 2973.2375 | E20: m² | F20: 28 | G20: =F20*D20*1.1 -> 91575.715
A21: Mão de obra impermeabilizações com manta asfáltica | D21: =D15 -> 1908.8185 | E21: m² | F21: 48 | G21: =F21*D21*1.1 -> 100785.62
A22: Mão de obra para proteção mecânica | D22: =D17 -> 1908.8185 | E22: m² | F22: 16 | G22: =F22*D22*1.1 -> 33595.205
A23: TOTAL | G23: =SUM(G10:G22) -> 664584.92 | K23: =4160+1440+1120+2880+4800+91680+4000 -> 110080 | L23: =K23/21 -> 5241.9048
A25: TOTAL IMPERMEABILIZAÇÃO | G25: =G23 -> 664584.92 | H25: =G25/DADOS_INICIAIS!E9 -> 55.880578
H28: =H25/1.1 -> 50.800526

Sheet Rev. Internos Piso e Parede
A2: ORÇAMENTO PARAMÉTRICO GERENCIAMENTO EXECUTIVO
A7: Cliente
A8: Obra
A9: Data | B9: 45471
A10: Revisão | B10: R00
A12: REVESTIMENTOS INTERNOS EM PISO E PAREDE
A14: Descrição | B14: Quantidade | D14: Parâmetro | F14: Referência | G14: Valor total
A15: Polimento de concreto | B15: ='Acabamentos de Piso e Parede'!B32+'Acabamentos de Piso e Parede'!B36 -> 2515.69 | C15: m² | D15: 16.5 | E15: R$ / m² | F15: Média | G15: =D15*B15*1.1 -> 45659.774
A16: Piso alisado | B16: ='Acabamentos de Piso e Parede'!B34 -> 608.5244 | C16: m² | D16: =25-D20 -> 4 | E16: R$ / m² | F16: Média | G16: =D16*B16*1.1 -> 2677.5074
A17: Piso ranhurado | B17: ='Acabamentos de Piso e Parede'!B33 -> 359.812 | C17: m² | D17: =28-D21 -> 4 | E17: R$ / m² | F17: Média | G17: =D17*B17*1.1 -> 1583.1728
A18: Contrapiso | B18: 6693.67 | C18: m² | D18: =B18/DADOS_INICIAIS!E9 -> 0.56282672 | E18: m² / AC | F18: Média | G18: =+B18*(65-D22)*1.1 -> 294521.48
A19: Manta acústica | B19: =B18-269.79 -> 6423.88 | C19: m² | D19: =B19/DADOS_INICIAIS!E9 -> 0.54014185 | E19: m² / AC | F19: Média | G19: =+B19*25*1.1 -> 176656.7
A20: MO piso alisado | B20: =B16 -> 608.5244 | C20: m² | D20: 21 | G20: =D20*B20*1.1 -> 14056.914 | H20: =G20/B20 -> 23.1
A21: Mo piso ranhurado | B21: =B17 -> 359.812 | C21: m² | D21: 24 | G21: =D21*B21*1.1 -> 9499.0368 | H21: =G21/B21 -> 26.4
A22: MO contrapiso | B22: =B18 -> 6693.67 | C22: m² | D22: 25 | G22: =D22*B22*1.1 -> 184075.93 | H22: =G22/B22 -> 27.5
A23: Chapisco | B23: =DADOS_INICIAIS!E9*'Rev. Internos Piso e Parede'!D23 -> 21407.31 | C23: m² | D23: 1.8 | E23: m² / AC | F23: Média | G23: =+B23*5*1.1-G25*0.1 -> 35322.061
A24: Reboco | B24: =DADOS_INICIAIS!E9*'Rev. Internos Piso e Parede'!D24 -> 21407.31 | C24: m² | D24: 1.8 | E24: m² / AC | F24: Média | G24: =50*B24*1.1-G25*0.9 -> 435638.76
A25: Mo chapisco e reboco | B25: =B24 -> 21407.31 | C25: m² | D25: 35 | G25: =D25*B25*1.1 -> 824181.44 | H25: =G25/B25 -> 38.5
A26: TOTAL | G26: =SUM(G15:G25) -> 2023872.8
A29: TOTAL REVESTIMENTOS | G29: =G26 -> 2023872.8 | H29: =G29/DADOS_INICIAIS!E9 -> 170.17416
H31: =H29/1.1 -> 154.70378

Sheet TETO
A3: REVESTIMENTOS E ACABAMENTOS DE TETO
A4: Data | B4: 45471
A5: Arquivo base | B5: -
A7: ALVENARIA
A9: Descrição | B9: Parâmetro | D9: Quantidade | F9: Preço unitário | G9: Valor total | H9: Observação
A10: Forro gesso mineral | B10: =D10/DADOS_INICIAIS!$E$9 -> 0.56282672 | C10: m² / AC | D10: ='Rev. Internos Piso e Parede'!B18 -> 6693.67 | E10: m² | F10: 65 | G10: =F10*D10*1.1 -> 478597.41
A11: Negativo | B11: 1.2 | C11: m / FORRO | D11: =(D10)*B11 -> 8032.404 | E11: m² | F11: 22 | G11: =F11*D11*1.1 -> 194384.18
A12: Estucamento | B12: =D12/DADOS_INICIAIS!$E$9 -> 0.29294888 | C12: m² / AC | D12: ='Rev. Internos Piso e Parede'!B15+'Rev. Internos Piso e Parede'!B16+'Rev. Internos Piso e Parede'!B17 -> 3484.0264 | E12: m² | F12: =24-F13 -> 3 | G12: =F12*D12*1.1 -> 11497.287
A13: mo estucamento | D13: =D12 -> 3484.0264 | E13: m² | F13: =21 -> 21 | G13: =F13*D13*1.1 -> 80481.01
A14: TOTAL | G14: =SUM(G10:G13) -> 764959.88 | K14: =4160+1440+1120+2880+4800+91680+4000 -> 110080 | L14: =K14/21 -> 5241.9048
A16: TOTAL FORRO | G16: =G14 -> 764959.88 | H16: =G16/DADOS_INICIAIS!E9 -> 64.320449
H19: =H16/1.1 -> 58.473135

Sheet Acabamentos de Piso e Parede
A2: ORÇAMENTO PARAMÉTRICO GERENCIAMENTO EXECUTIVO
A7: Cliente
A8: Obra
A9: Data | B9: 45471
A10: Revisão | B10: R00
A12: ACABAMENTOS EM PISO E PAREDE
A14: Descrição | B14: Quantidade | D14: Parâmetro | F14: Referência | G14: Valor total | H14: =G19/I14 -> 6541.1225 | I14: =40+20 -> 60
A15: Porcelanato | B15: =B31 -> 6641.47 | C15: m² | D15: =125-D22 -> 77 | E15: R$ / m² | F15: Média | G15: =+D15*B15*1.1 -> 562532.51 | I15: =40/I14 -> 0.66666667 | J15: =I15*G19 -> 261644.9
A16: Piscina | B16: =B37 -> 144.899 | C16: m² | D16: =250-D23 -> 200 | E16: R$ / m² | F16: Média | G16: =+D16*B16*1.1 -> 31877.78 | I16: =20/I14 -> 0.33333333 | J16: =I16*G19 -> 130822.45
A17: Grama sintetica | B17: =B35 -> 52.2 | C17: m² | D17: 210 | E17: R$ / m² | F17: Média | G17: =+D17*B17*1.1 -> 12058.2
A18: Paver | B18: 117.4 | C18: m² | D18: =60-D24 -> 42 | E18: R$ / m² | F18: Média | G18: =+D18*B18*1.1 -> 5423.88
A19: Rodapés | B19: 1 | C19: vb | D19: 30 | E19: R$ / AC | F19: Média | G19: =D19*DADOS_INICIAIS!$E$9*1.1 -> 392467.35 | H19: =G20/I19 -> 2813.386 | I19: =81+12 -> 93
A20: Soleiras e peitoris | B20: 1 | C20: vb | D20: 20 | E20: R$ / AC | F20: Média | G20: =D20*DADOS_INICIAIS!$E$9*1.1 -> 261644.9 | I20: =81/I19 -> 0.87096774 | J20: =I20*G20 -> 227884.27
A21: Revestimentos de Parede | B21: 1 | C21: vb | D21: 50 | E21: R$ / AC | F21: Média | G21: =D21*DADOS_INICIAIS!$E$9*1.1 -> 654112.25 | I21: =12/I19 -> 0.12903226 | J21: =I21*G20 -> 33760.632
A22: MO PORCELANATO | B22: =B15 -> 6641.47 | C22: m² | D22: 48 | E22: R$ / m² | G22: =+D22*B22*1.1 -> 350669.62 | H22: =G21/I22 -> 3442.6961 | I22: =145+45 -> 190
A23: MO PASTILHA | B23: =B16 -> 144.899 | C23: m² | D23: 50 | E23: R$ / m² | G23: =+D23*B23*1.1 -> 7969.445 | I23: =145/I22 -> 0.76315789 | J23: =I23*G21 -> 499190.93
A24: MO PAVER | B24: =B18 -> 117.4 | C24: m² | D24: 18 | E24: R$ / m² | G24: =+D24*B24*1.1 -> 2324.52 | I24: =45/I22 -> 0.23684211 | J24: =I24*G21 -> 154921.32
A25: =20*40 -> 800 | G25: =SUM(G15:G24) -> 2281080.4
A28: TOTAL ACABAMENTOS | G28: =G25 -> 2281080.4 | H28: =G28/DADOS_INICIAIS!E9 -> 191.80106
H30: =H28/1.1 -> 174.3646
A31: PORCELANATO | B31: 6641.47
A32: CIMENTADO | B32: 2429.94
A33: CIMENTADO RANHURADO | B33: 359.812
A34: CIMENTADO ESCADA | B34: 608.5244
A35: GRAMA SINTETICA | B35: 52.2
A36: POLIDO | B36: 85.75
A37: PASTILHA | B37: 144.899

Sheet PINTURA INTERNA
A3: PINTURA INTERNA
A4: Data | B4: 45457
A5: Arquivo base | B5: -
A7: ALVENARIA
A9: Descrição | B9: Parâmetro | D9: Quantidade | F9: Preço unitário | G9: Valor total | H9: Observação
A10: Pintura piso epoxi | B10: 110 | C10: R$ / m² | D10: ='Rev. Internos Piso e Parede'!B15*0.05 -> 125.7845 | E10: m² | F10: =110-F14 -> 70 | G10: =F10*D10*1.1 -> 9685.4065 | H10: =ALVENARIA!D16*2-'Rev. Fachada'!B15 -> 26700.562
A11: Pintura acrílica antiderrapante | B11: 65 | C11: R$ / m² | D11: ='Rev. Internos Piso e Parede'!B16 -> 608.5244 | E11: m² | F11: =65-28 -> 37 | G11: =F11*D11*1.1 -> 24766.943 | H11: =H10*0.8+TETO!D10 -> 28054.12 | I11: =1+1.5+15+35 -> 52.5
A12: Textura escadas | B12: 22 | C12: R$ / AC | D12: 1 | E12: vb | F12: =B12*DADOS_INICIAIS!$E$9 -> 261644.9 | G12: =F12*D12*1.1 -> 287809.39 | H12: =H10*0.2+TETO!D12 -> 8824.1389 | I12: =1-I13 -> 0.33333333 | J12: =I12*G13 -> 479682.32
A13: Pintura Interna | B13: 110 | C13: R$ / AC | D13: 1 | E13: vb | F13: =B13*DADOS_INICIAIS!$E$9 -> 1308224.5 | G13: =F13*D13*1.1 -> 1439047 | I13: =35/I11 -> 0.66666667 | J13: =I13*G13 -> 959364.63
A14: MO pintura de piso epoxi | D14: =D10 -> 125.7845 | F14: 40 | G14: =F14*D14*1.1 -> 5534.518 | I14: =1+5+31 -> 37
A15: MO pintura de piso acrilica | D15: =D11 -> 608.5244 | F15: =28 -> 28 | G15: =F15*D15*1.1 -> 18742.552 | I15: =1-I16 -> 0.16216216 | J15: =I15*G12 -> 46671.793
A16: TOTAL | G16: =SUM(G10:G15) -> 1785585.8 | I16: =31/I14 -> 0.83783784 | J16: =I16*G12 -> 241137.6 | K16: =4160+1440+1120+2880+4800+91680+4000 -> 110080 | L16: =K16/21 -> 5241.9048
A18: TOTAL IMPERMEABILIZAÇÃO | G18: =G16 -> 1785585.8 | H18: =G18/DADOS_INICIAIS!E9 -> 150.13817
H20: =H18/1.1 -> 136.48925

Sheet ESQUADRIAS
A3: ESQUADRIAS
A4: Data | B4: 45460
A5: Arquivo base | B5: -
A7: ESQUADRIAS
A9: Descrição | B9: Parâmetro | D9: Quantidade | G9: Valor total | H9: Observação
A10: Esquadrias de Alumínio | B10: 0.15 | C10: m² / AC | D10: =B10*DADOS_INICIAIS!E9 -> 1783.9425 | E10: m² | F10: 1250 | G10: =F10*D10*1.1 -> 2452920.9 | H10: =G10/DADOS_INICIAIS!E9 -> 206.25
A11: Pele de vidro | D11: =25.44*3.2 -> 81.408 | E11: m² | F11: 950 | G11: =F11*D11*1.1 -> 85071.36
A12: Portão de alumínio | D12: 1 | E12: un | F12: 18000 | G12: =F12*D12*1.1 -> 19800
A13: Guarda-corpo - vidro | D13: =(1.45+4.47+0.6)*2*DADOS_INICIAIS!E16+6.48+7.76 -> 314.16 | E13: m | F13: =750*1.1 -> 825 | G13: =F13*D13*1.1 -> 285100.2
A14: Gradil | D14: =1.65*2*DADOS_INICIAIS!E16*1.1 -> 83.49 | E14: m² | F14: 610 | G14: =F14*D14*1.1 -> 56021.79
A15: Serralherias | B15: 10 | C15: R$ / AC | D15: 1 | E15: vb | F15: =B15*DADOS_INICIAIS!$E$9 -> 118929.5 | G15: =F15*D15*1.1 -> 130822.45
A16: PCF | D16: =2*DADOS_INICIAIS!E15 -> 56 | E16: un | F16: 1750 | G16: =F16*D16*1.1 -> 107800
A17: Corrimão madeira | D17: =((2.5+3.75+3.55+2.38+1.08*4)*1.2*DADOS_INICIAIS!E15) -> 554.4 | E17: m | F17: 65 | G17: =F17*D17*1.1 -> 39639.6
A18: Fechadura Biometrica | D18: =2*DADOS_INICIAIS!E10 -> 92 | E18: un | F18: 1500 | G18: =F18*D18*1.1 -> 151800
A19: Esquadrias de Madeira | D19: =2+(11*2*23) -> 508 | E19: un | F19: =1450-F20 -> 1300 | G19: =F19*D19*1.1 -> 726440
A20: MO PORTAS DE MADEIRA | D20: =D19 -> 508 | E20: =E19 -> un | F20: 150 | G20: =F20*D20*1.1 -> 83820
A21: TOTAL | G21: =SUM(G10:G20) -> 4139236.3 | K21: =4160+1440+1120+2880+4800+91680+4000 -> 110080 | L21: =K21/21 -> 5241.9048
A23: TOTAL ESQUADRIAS | G23: =G21 -> 4139236.3 | H23: =G23/DADOS_INICIAIS!E9 -> 348.04118

Sheet COBERTURA
A2: COBERTURA
A3: Data | B3: 45460
A4: Arquivo base | B4: -
A6: TELHADO
A8: Descrição | B8: Parâmetro | D8: Quantidade | F8: Preço unitário | G8: Valor total | H8: Observação
A9: Estrutura e telhamento | D9: 266.19 | E9: m² | F9: 500 | G9: =F9*D9*1.1 -> 146404.5
A10: Serviços complementares | D10: =D9 -> 266.19 | E10: m² | F10: 45 | G10: =F10*D10*1.1 -> 13176.405
A11: Pergolados | G11: =F11*D11*1.1 -> 0
A12: Passarelas | G12: =F12*D12*1.1 -> 0
A13: TOTAL | G13: =SUM(G9:G12) -> 159580.9
A15: TOTAL COMPLEMENTARES | G15: =G13 -> 159580.9 | H15: =G15/DADOS_INICIAIS!$E$9 -> 13.418109

Sheet Rev. Fachada
A2: ORÇAMENTO PARAMÉTRICO GERENCIAMENTO EXECUTIVO
A7: Cliente | B7: Passe
A8: Obra | B8: Connect
A9: Data | B9: 45460
A10: Revisão | B10: R00
A12: REVESTIMENTOS ARGAMASSADOS
A14: Descrição | B14: Quantidade | D14: Parâmetro | F14: Referência | G14: Valor total | J14: =G15-J15 -> 167043.18
A15: Chapisco e reboco | B15: =(K18*L18+K19*L19+K20*L20-ESQUADRIAS!D10) -> 6074.2975 | C15: m² | D15: =25+70 -> 95 | E15: R$ / m² | F15: - | G15: =B15*D15*1.1 -> 634764.09 | I15: =70/D15 -> 0.73684211 | J15: =I15*G15 -> 467720.91
A16: TOTAL | G16: =SUM(G15:G15) -> 634764.09
A18: PINTURA | J18: EMBASAMENTO | K18: =DADOS_INICIAIS!E26 -> 119.84 | L18: =3.2*4+1.2 -> 14
J19: TORRE 1 | K19: =DADOS_INICIAIS!E20 -> 76.48 | L19: =3.2*24+1.2 -> 78
A20: Descrição | B20: Quantidade | D20: Parâmetro | F20: Referência | G20: Valor total | J20: RESERV | K20: 33.6 | L20: =6.4 -> 6.4
A21: Textura | B21: =B15 -> 6074.2975 | C21: m² | D21: =70+15 -> 85 | E21: R$ / m² | F21: - | G21: =B21*D21*1.1 -> 567946.82 | I21: =45/D21 -> 0.52941176 | J21: =I21*G21 -> 300677.73 | L21: =K18*L18+K19*L19+K20*L20 -> 7858.24
A22: TOTAL | G22: =SUM(G21:G21) -> 567946.82 | J22: =G21-J21 -> 267269.09
A24: ACABAMENTOS ESPECIAIS
A26: Descrição | B26: Quantidade | D26: Parâmetro | F26: Referência | G26: Valor total
A27: ACM embasamento | B27: =31.31*3.2*3 -> 300.576 | C27: M² | D27: 600 | E27: R$ / m² | F27: - | G27: =B27*D27*1.1 -> 198380.16
A28: ACM torre | B28: =(L19*3*0.3+3.2*2+10*15)*2 -> 453.2 | C28: M² | D28: 600 | E28: R$ / m² | F28: - | G28: =B28*D28*1.1 -> 299112
G29: =SUM(G27:G28) -> 497492.16
J30: =25.78*2 -> 51.56
A32: TOTAL FACHADA | G32: =G22+G16+G29 -> 1700203.1 | H32: =G32/DADOS_INICIAIS!E9 -> 142.9589
H33: =H32/1.1 -> 129.96264

Sheet COMPLEMENTARES
A2: COMPLEMENTARES
A3: Data | B3: 45460
A4: Arquivo base | B4: -
A6: SERVIÇOS COMPLEMENTARES
A8: Descrição | B8: Parâmetro | D8: Quantidade | F8: Valor total
A9: Móveis e decoração | B9: 1500 | C9: R$ / AL | D9: =DADOS_INICIAIS!E21 -> 895 | E9: m² | F9: =D9*B9*1.1 -> 1476750
A10: Comunicação visual | B10: 10 | C10: R$ / AC | D10: =B10*DADOS_INICIAIS!$E$9 -> 118929.5 | E10: vb | F10: =D10*1.1 -> 130822.45
A11: Paisagismo | B11: 12 | C11: R$ / AC | D11: =B11*DADOS_INICIAIS!$E$9 -> 142715.4 | E11: vb | F11: =D11*1.1 -> 156986.94
A12: Quadra poliesportiva | B12: 320 | C12: R$ / m² | D12: 85.75 | E12: m² | F12: =D12*B12*1.1 -> 30184
A13: Ligações definitivas | B13: 4 | C13: R$ / AC | D13: =B13*DADOS_INICIAIS!$E$9 -> 47571.8 | E13: vb | F13: =D13*1.1 -> 52328.98
A14: Desmobilização | B14: 5 | C14: R$ / AC | D14: =B14*DADOS_INICIAIS!$E$9 -> 59464.75 | E14: vb | F14: =D14*1.1 -> 65411.225
A15: Limpeza | B15: 15 | C15: R$ / AC | D15: =B15*DADOS_INICIAIS!$E$9 -> 178394.25 | E15: vb | F15: =D15*1.1 -> 196233.68
A16: TOTAL | F16: =SUM(F9:F15) -> 2108717.3
A18: TOTAL COMPLEMENTARES | F18: =F16 -> 2108717.3 | G18: =F18/DADOS_INICIAIS!$E$9 -> 177.30818

Sheet Auxiliar
A2: 2 Portões acesso garagem - Área: 9,2m² x 2 = 18,4m² | B2: 2 | C2: portão | D2: 18.4
A3: 2 portas corta-fogo 1 folha | B3: 2 | C3: pcf
A4: 1 porta de correr alumínio 2 folhas – Área: 3,465m² | B4: 1 | C4: porta alumínio | D4: 3.465
A5: 1 porta de correr alumínio 2 folhas – Área: 1,7325m² | B5: 1 | C5: porta alumínio | D5: 1.7325 | G5: Guarda alumínio | H5: =SUMIF(C:C,G5,D:D) -> 400.5221
A6: 2 portas de abrir alumínio 2 folhas – Área: 2,6376m² x 2 = 5,2752m² | B6: 2 | C6: porta alumínio | D6: 5.2752 | G6: janela | H6: =SUMIF(C:C,G6,D:D) -> 1895.06
A7: 1 porta de abrir alumínio 2 folhas – Área: 4,1916m² | B7: 1 | C7: porta alumínio | D7: 4.1916 | G7: madeira | H7: =SUMIF(C:C,G7,B:B) -> 218
A8: 1 porta pivotante | B8: 1 | C8: pivotante | G8: pcf | H8: =SUMIF(C:C,G8,B:B) -> 60
A9: 19 portas de abrir madeira 1 folha | B9: 19 | C9: madeira | G9: pivotante | H9: =SUMIF(C:C,G9,B:B) -> 1
A10: 3 portas de abrir vidro 1 folha – Área: 2,1m² x 3 = 6,3m² | B10: 3 | C10: porta alumínio | D10: 6.3 | G10: porta alumínio | H10: =SUMIF(C:C,G10,D:D) -> 46.62
A11: 2 portas de abrir vidro 1 folha – Área: 1,89m² x 2 = 3,78m² | B11: 2 | C11: porta alumínio | D11: 3.78 | G11: portão | H11: =SUMIF(C:C,G11,B:B) -> 2
A12: 1 porta de abrir alumínio 1 folha – Área: 2,0076m² | B12: 1 | C12: porta alumínio | D12: 2.0076 | G12: gradil | H12: =SUMIF(C:C,G12,D:D) -> 113.88
A13: Janelas – Área: 3,75 + 4,875 + 2,5 + 1,1 + 1,2 + 5,5402 + 4,4874 = 23,4526m² | C13: janela | D13: 23.4526 | G13: Brise | H13: 109.3146
A14: Muro de vidro – Área: 7,0774 + 5,485 + 3,43 + 4,8138 = 20,8062m² | C14: Guarda alumínio | D14: 20.8062
A15: 8 portas corta-fogo 1 folha | B15: 8 | C15: pcf
A16: Janelas – Area: (1,1 + 1,2 + 28,7391) x 4 = 124,1564m² | C16: janela | D16: 124.1564
A17: 2 portas corta-fogo 1 folha | B17: 2 | C17: pcf
A18: 2 portas de abrir alumínio 1 folha – Área: 1,47m² x 2 = 2,94m² | B18: 2 | C18: porta alumínio | D18: 2.94
A19: 2 portas de abrir vidro 1 folha – Área: 1,89m² x 2 = 3,78m² | B19: 2 | C19: porta alumínio | D19: 3.78
A20: 5 portas de abrir madeira 1 folha | B20: 5 | C20: madeira
A21: 1 janela-porta de correr vidro – Área: 14,7348m² | B21: 1 | C21: janela | D21: 14.7348
A22: Janelas – Área: 1,2894 + 1,2894 + 23,46 + 1,854 + 5,562 + 5,562 + 1,854 + 1,854 + 1,1 + 1,2 = 45,0248m² | C22: janela | D22: 45.0248
A23: Guarda corpo vidro – Área: 7,5299 + 5,7955 + 6,5555 = 19,8809m² | C23: Guarda alumínio | D23: 19.8809
A24: 38 portas corta-fogo 1 folha | B24: 38 | C24: pcf
A25: 171 portas de abrir madeira 1 folha | B25: 171 | C25: madeira
A26: 19 porta de abrir alumínio 1 folha – Área: 1,26m² x 19 = 23,94m² | B26: 19 | C26: porta alumínio | D26: 23.94
A27: 19 janela-porta de correr vidro 5 folhas - Área: 25,4205m² x 19 = 482,9895m² | B27: 19 | C27: janela | D27: 482.9895
A28: 19 janela-porta de correr vidro 5 folhas - Área: 17,8284m² x 19 = 338,7396m² | B28: 19 | C28: janela | D28: 338.7396
A29: Janelas – Área: 1,1 + 1,1 + 1,2 + 1,92 + 0,36 + 2,781 + 2,781 + 1,854 + 1,854 + 5,562 + 5,562 + 1,854 = 27,928m² x 19 = 530,632m² | C29: janela | D29: 530.632
A30: Guarda corpo metálico – Área: 4,745m² x 19 = 90,155m² - Perímetro: 3,65m x 19 = 69,35m | C30: gradil | D30: 90.155
A31: Guarda corpo vidro – Área: 15,645m² x 19 = 297,255m² - Perímetro: 14,9m x 19 = 283,1m | C31: Guarda alumínio | D31: 297.255
A32: 2 portas corta-fogo 1 folha | B32: 2 | C32: pcf
A33: 2 portas de abrir madeira 1 folha | B33: 2 | C33: madeira
A34: 1 porta de abrir alumínio 1 folha – Área: 1,26m² | B34: 1 | C34: porta alumínio | D34: 1.26
A35: 1 janela-porta de correr vidro 3 folhas - Área: 15,21m² | B35: 1 | C35: janela | D35: 15.21
A36: 1 janela-porta de correr vidro 5 folhas - Área: 25,4205m² | B36: 1 | C36: janela | D36: 25.4205
A37: 1 janela-porta de correr vidro 5 folhas - Área: 17,8284m² | B37: 1 | C37: janela | D37: 17.8284
A38: Janelas – Área: 1,1 + 1,2 + 1,1 + 1,92 + 0,36 + 2,781 + 2,781 + 1,854 + 1,854 + 5,562 + 5,562 + 1,854 = 27,928m² | C38: janela | D38: 27.928
A39: Guarda corpo metálico – Área: 4,745m² - Perímetro: 3,65m | C39: gradil | D39: 4.745
A40: Guarda corpo vidro – Área: 15,645m² - Perímetro: 14,9m | C40: Guarda alumínio | D40: 15.645
A41: 2 portas corta-fogo 1 folha | B41: 2 | C41: pcf
...
