Workbook

Sheet Dados Gerais
A2: ORÇAMENTO PARAMÉTRICO GERENCIAMENTO EXECUTIVO
A7: Documento
A8: Cliente
A9: Obra
A10: Data | B10: 44294 | E10: Revisão | F10: R00 | G10: Status | H10: Em andamento | I10: Responsável | J10: Kelen
A12: Descrição | D12: Identificador | E12: Informação
A13: Área do terreno | D13: AT | E13: 891 | H13: m²
A14: Testada do terreno | D14: TT | E14: 33 | H14: m
A15: Área total construída | D15: AC | E15: 20550.4 | H15: m²
A16: N° total de pavimentos | D16: NP | E16: 27 | H16: un
A17: N° de pavimentos tipo | D17: NPT | E17: 17 | H17: un
A18: N° de pavimentos tipo diferenciado | D18: NPD | E18: 2 | H18: un
A19: N° de pavimentos duplex | D19: ND | E19: 2 | H19: un
A20: Área de projeção da torre | D20: APT | E20: 587.81 | H20: m²
A21: Perímetro de projeção da torre | D21: PPT | E21: 125.39 | H21: m
A22: Área Lazer | D22: AL | E22: 785 | H22: m²
A23: Locação da obra | D23: LC | E23: 163.31 | H23: m
A24: Área do embasamento | D24: AE | E24: =1253.2+1372.06*4+1231.69 -> 7973.13 | H24: m²
A25: Área de subsolos | D25: AS | E25: 0 | H25: m²
A26: N° de subsolos | D26: NS | E26: 0 | H26: un
A27: Área de projeção do embasamento | D27: APE | E27: =783.72+E20 -> 1371.53 | H27: m²
A28: Perímetro de projeção embasamento | D28: PPE | E28: 155.31 | H28: m
A29: N° de pavimentos de embasamento | D29: NPE | E29: 6 | H29: un
A30: Área de Marina Cond. | D30: AMC | E30: 411.79 | H30: m²

Sheet Resumo
A2: ORÇAMENTO PARAMÉTRICO GERENCIAMENTO EXECUTIVO
A7: Documento | B7: MTH_INC-RES Orçamento Paramétrico
A8: Cliente | B8: PASS-E
A9: Obra | B9: Reserva | E9: UC | F9: 01 | G9: Status | H9: Concluído
A10: Data | B10: 44294 | E10: Revisão | F10: R00 | G10: Resp. | H10: Kelen
A12: MOVIMENTAÇÃO DE TERRA
A14: Descrição | D14: Valor total
A15: =+'Movimentação de Terra'!A19 -> REBAIXAMENTO DE LENÇOL | D15: =+'Movimentação de Terra'!I23 -> 26284.5
A16: =+'Movimentação de Terra'!A26 -> ESCAVAÇÃO E REATERRO DE VALAS | D16: =+'Movimentação de Terra'!I32 -> 141304.98
A17: =+'Movimentação de Terra'!A35 -> REGULARIZAÇÃO E APILOAmENTO DE FUNDO DE VALAS | D17: =+'Movimentação de Terra'!I39 -> 5891
A18: TOTAL | D18: =SUM(D15:H17) -> 173480.48
A22: INFRAESTRUTURA
A24: Descrição | D24: Valor total
A25: =+Infraestrutura!A12 -> FUNDAÇÃO PROFUNDA | D25: =+Infraestrutura!I26 -> 2904912
A26: =+Infraestrutura!A29 -> FUNDAÇÃO RASA | D26: =+Infraestrutura!I36 -> 1205106.3
A27: CONTENÇÃO | D27: =Infraestrutura!I46 -> 257581.24
A28: TOTAL | D28: =SUM(D25:H27) -> 4367599.5
A31: SUPRAESTRUTURA
A33: Descrição | D33: Valor total
A34: =+Supraestrutura!A12 -> SUPRAESTRUTURA | D34: =+Supraestrutura!I24 -> 14390209
A35: TOTAL | D35: =SUM(D34:H34) -> 14390209
A38: ALVENARIA
A40: Descrição | D40: Valor total
A41: =+Alvenaria!A12 -> ALVENARIA | D41: =+Alvenaria!I22 -> 2280313.8
A42: TOTAL | D42: =SUM(D41) -> 2280313.8
A45: INSTALAÇÕES
A47: Descrição | D47: Valor total
A48: =+Instalações!A12 -> INSTALAÇÕES ELÉTRICAS | D48: =+Instalações!I23 -> 2660249.3
A49: =+Instalações!A25 -> INSTALAÇÕES HIDRÁULICAS | D49: =+Instalações!I35 -> 2187993.9
A50: =+Instalações!A38 -> INSTALAÇÕES PREVENTIVAS E GLP | D50: =+Instalações!I45 -> 986419.2
A51: =+Instalações!A48 -> CLIMATIZAÇÃO, EXAUSTÃO MECÂNICA E PRESSURIZAÇÃO | D51: =+Instalações!I54 -> 965760
A52: TOTAL | D52: =SUM(D48:H51) -> 6800422.4
A55: IMPERMEABILIZAÇÃO
A57: Descrição | D57: Valor total
A58: =+Impermeabilização!A12 -> IMPERMEABILIZAÇÃO | D58: =+Impermeabilização!I23 -> 885001.44
A59: TOTAL | D59: =SUM(D58) -> 885001.44
A62: REVESTIMENTOS INTERNOS EM PISO E PAREDE
A64: Descrição | D64: Valor total
A65: =+'Rev. Internos Piso e Parede'!A12 -> REVESTIMENTOS INTERNOS EM PISO E PAREDE | D65: =+'Rev. Internos Piso e Parede'!I19 -> 2776646.7
A66: TOTAL | D66: =SUM(D65) -> 2776646.7
...

Sheet Movimentação de Terra
A2: ORÇAMENTO PARAMÉTRICO MOVIMENTAÇÃO DE TERRA
A7: Documento | B7: MTH_INC-RES Orçamento Paramétrico
A8: Cliente
A9: Obra | B9: Reserva | I9: Status | J9: Concluído
A10: Data | B10: 44294 | G10: Revisão | H10: R00 | I10: Resp. | J10: Kelen
A12: ESCAVAÇÃO
A14: Descrição | D14: Quantidade | F14: Parâmetro | H14: Referência | I14: Valor total
A15: Escavação | D15: =+'Dados Gerais'!E25*3.06 -> 0 | E15: m³ | F15: 28.5 | G15: R$ / m³ | H15: Pedro Chaves | I15: =+D15*F15 -> 0
A16: TOTAL | I16: =SUM(I15:J15) -> 0
A19: REBAIXAMENTO DE LENÇOL
A21: Descrição | D21: Quantidade | F21: Parâmetro | H21: Referência | I21: Valor total
A22: Rebaixamento de Lençol | D22: 0 | E22: - | F22: 29.5 | G22: R$ / AT | H22: Média | I22: =F22*'Dados Gerais'!E13 -> 26284.5
A23: TOTAL | I23: =SUM(I22:J22) -> 26284.5
A26: ESCAVAÇÃO E REATERRO DE VALAS
A28: Descrição | D28: Quantidade | F28: Parâmetro | H28: Referência | I28: Valor total
A29: Escavação mecanizada para blocos e baldrames | D29: =M29*1.3 -> 952.042 | E29: - | G29: m³ / AT | H29: Locação Fundação | I29: =+ROUNDUP((D29*31),0) -> 29514 | M29: =(721.74+10.6) -> 732.34
A30: Reaterro para blocos e baldrames | D30: =D29-M29 -> 219.702 | E30: - | G30: m³ / AT | H30: Locação Fundação | I30: =+ROUNDUP((D30*8.5),0) -> 1868
A31: Movimentação de terra das estacas | D31: =+Infraestrutura!D25*F31 -> 3489.6183 | E31: m³ | F31: 1.2 | G31: m³ / m³ | H31: Locação Fundação | I31: =+D31*31.5 -> 109922.98
A32: TOTAL | I32: =SUM(I29:J31) -> 141304.98
A35: REGULARIZAÇÃO E APILOAmENTO DE FUNDO DE VALAS
A37: Descrição | D37: Quantidade | F37: Parâmetro | H37: Referência | I37: Valor total
A38: Lastro de concreto magro e= 10cm - Blocos | D38: 357.01 | E38: m² | H38: Locação Fundação | I38: =ROUNDUP((D38*16.5),0) -> 5891
A39: TOTAL | I39: =SUM(I38:J38) -> 5891
I42: =I39+I32+I23 -> 173480.48

Sheet Infraestrutura
A2: ORÇAMENTO PARAMÉTRICO INFRAESTRUTURA
A7: Documento | B7: MTH_INC-RES Orçamento Paramétrico
A8: Cliente
A9: Obra | B9: Reserva | I9: Status | J9: Concluído
A10: Data | B10: 44097 | G10: Revisão | H10: R00 | I10: Resp. | J10: Kelen
A12: FUNDAÇÃO PROFUNDA
A14: Descrição | D14: Quantidade | F14: Parâmetro | H14: Referência | I14: Valor total
A15: Número de Estacas | D15: =ROUNDUP((F15*'Dados Gerais'!$E$13),0) -> 223 | E15: un | F15: 0.25 | G15: un / m² | H15: Média | I15: 0
A16: Estaca Hélice Continua Diâmetro 40 | D16: =ROUNDUP(($D$15*(F16/100)),0) -> 56 | E16: un | F16: 25 | G16: % | H16: Média | I16: 0
A17: Estaca Hélice Continua Diâmetro 40 | D17: =ROUNDUP((F17*D16),0) -> 1904 | E17: m | F17: 34 | G17: m / un | H17: Média | I17: =+ROUNDUP((D17*110),0) -> 209440
A18: Estaca Hélice Continua Diâmetro 60 | D18: =ROUNDUP(($D$15*(F18/100)),0) -> 56 | E18: un | F18: 25 | G18: % | H18: Média | I18: 0
A19: Estaca Hélice Continua Diâmetro 60 | D19: =ROUNDUP((F19*D18),0) -> 1904 | E19: m | F19: 34 | G19: m / un | H19: Média | I19: =+ROUNDUP((D19*120),0) -> 228480
A20: Estaca Hélice Continua Diâmetro 70 | D20: =ROUNDUP(($D$15*(F20/100)),0) -> 67 | E20: un | F20: 30 | G20: % | H20: Média | I20: 0
A21: Estaca Hélice Continua Diâmetro 70 | D21: =ROUNDUP((F21*D20),0) -> 2278 | E21: m | F21: 34 | G21: m / un | H21: Média | I21: =+ROUNDUP((D21*140),0) -> 318920
A22: Estaca Hélice Continua Diâmetro 80 | D22: =ROUNDUP(($D$15*(F22/100)),0) -> 45 | E22: un | F22: 20 | G22: % | H22: Média | I22: 0
A23: Estaca Hélice Continua Diâmetro 80 | D23: =ROUNDUP((F23*D22),0) -> 1530 | E23: m | F23: 34 | G23: m / un | H23: Média | I23: =+ROUNDUP((D23*150),0) -> 229500
A24: Armação | D24: =ROUNDUP((D25*F24),0) -> 30535 | E24: kg | F24: 10.5 | G24: kg / m³ | H24: Média | I24: =+ROUNDUP((D24*9.5),0) -> 290083
A25: Concreto | D25: =(PI()*(0.4^2)/4*D17+PI()*(0.6^2)/4*D19+PI()*(0.7^2)/4*D21+PI()*(0.8^2)/4*D23)*1.2 -> 2908.0152 | E25: m³ | F25: 560 | G25: R$ / m³ | H25: Média | I25: =+ROUNDUP((D25*F25),0) -> 1628489
A26: TOTAL | I26: =SUM(I15:J25) -> 2904912
A29: FUNDAÇÃO RASA
A31: Descrição | D31: Quantidade | F31: Parâmetro | H31: Referência | I31: Valor total
A32: Fabricação, montagem e desmontagem de forma para blocos e baldrames | D32: =+P33*1.5 -> 1204.095 | E32: m² | G32: m² / AT | H32: Locação Fundação | I32: =+D32*33.7 -> 40578.002 | M32: Aço blocos e baldrames | P32: Forma blocos
A33: Armação | D33: =N37*1.1*1.5 -> 59652.45 | E33: kg | G33: kg / m³ | H33: Locação Fundação | I33: =+D33*9.5 -> 566698.28 | M33: 1265 | N33: 167 | P33: 802.73
A34: Concreto | D34: ='Movimentação de Terra'!M29 -> 732.34 | E34: m³ | G34: m³ / AT | H34: Locação Fundação | I34: =+D34*500 -> 366170 | M34: 1285 | N34: 251
A35: Mão de obra | D35: =+'Dados Gerais'!E13 -> 891 | E35: m² | F35: 260 | G35: R$ / AT | H35: Média | I35: =+D35*F35 -> 231660 | M35: 1879 | N35: 222
A36: TOTAL | I36: =SUM(I32:J35) -> 1205106.3 | M36: 1173 | N36: 110
M37: 2760 | N37: =SUM(N33:N36)+SUM(M33:M48) -> 36153
M38: 1140
A39: CONTENÇÃO - PAREDE DIAFRAGMA | M39: 1320
M40: 878
A41: Descrição | D41: Quantidade | F41: Parâmetro | H41: Referência | I41: Valor total | M41: 1698
A42: Armação | D42: =F42*D43 -> 9117.92 | E42: kg | F42: 80 | G42: kg/m³ | H42: Média | I42: =+D42*9.5 -> 86620.24 | M42: 1543
A43: Concreto | D43: 113.974 | E43: m³ | F43: 500 | G43: R$ / m³ | H43: Média | I43: =+D43*F43 -> 56987 | M43: 1682
A44: Mureta Guia | D44: 81.41 | E44: m | F44: 350 | G44: R$ / m | H44: Média | I44: =F44*D44 -> 28493.5 | M44: 1583
A45: Mão de obra | D45: 284.935 | E45: m² | F45: 300 | G45: R$ / AT | H45: Média | I45: =+D45*F45 -> 85480.5 | M45: 350
A46: TOTAL | I46: =SUM(I42:J45) -> 257581.24 | M46: 9425
M47: 5457
M48: 1965
I49: =I46+I36+I26 -> 4367599.5

Sheet Supraestrutura
A2: ORÇAMENTO PARAMÉTRICO SUPRAESTRUTURA
A7: Documento | B7: MTH_INC-RES Orçamento Paramétrico
A8: Cliente
A9: Obra | B9: Reserva | I9: Status | J9: Concluído
A10: Data | B10: 44294 | G10: Revisão | H10: R00 | I10: Resp. | J10: Kelen
A12: SUPRAESTRUTURA
A14: Descrição | D14: Quantidade | F14: Parâmetro | H14: Referência | I14: Valor total
A15: Fabricação forma | D15: =+D16*F15/100 -> 10850.611 | E15: m² | F15: 16.5 | G15: % | H15: Média | I15: =+D15*70 -> 759542.78
A16: Montagem de forma | D16: =+'Dados Gerais'!$E$15*F16 -> 65761.28 | E16: m² | F16: 3.2 | G16: m² / AC | H16: Média | I16: =+D16*9.5 -> 624732.16
A17: Escoramento - Torre | D17: =+'Dados Gerais'!E20*'Dados Gerais'!E17 -> 9992.77 | E17: m² | F17: 25 | G17: R$ / m² | H17: Média | I17: =+D17*F17 -> 249819.25
A18: Escoramento - Embasamento | D18: =+'Dados Gerais'!E24 -> 7973.13 | E18: m² | F18: 30 | G18: R$ / m² | H18: Média | I18: =+D18*F18 -> 239193.9
A19: Armadura Convencional para Estrutura | D19: =(D20+D21)*F19 -> 436696 | E19: kg | F19: 85 | G19: kg / m³ | H19: Média | I19: =+D19*9.5 -> 4148612
A20: Concreto - embasamento | D20: ='Dados Gerais'!E24*F20 -> 1993.2825 | E20: m³ | F20: 0.25 | G20: m³ / AC | H20: Média | I20: =+D20*630 -> 1255768
A21: Concreto - torre | D21: =(+'Dados Gerais'!E15-'Dados Gerais'!E24)*Supraestrutura!$F$21 -> 3144.3175 | E21: m³ | F21: 0.25 | G21: m³ / AC | H21: Média | I21: =+D21*450 -> 1414942.9
A22: Protensão - Material e mão de obra | D22: ='Dados Gerais'!E15 -> 20550.4 | E22: m² | F22: 90 | G22: R$ / AC | H22: Média | I22: =+D22*F22 -> 1849536
A23: Mão de obra - estrutura em concreto armado | D23: =+'Dados Gerais'!E15 -> 20550.4 | E23: m² | F23: 187.25 | G23: R$ / m² | H23: Média | I23: =+D23*F23 -> 3848062.4
A24: TOTAL | I24: =SUM(I15:J23) -> 14390209
K28: =I24 -> 14390209

Sheet Marina
A2: ORÇAMENTO PARAMÉTRICO SUPRAESTRUTURA
A7: Documento | B7: MTH_INC-RES Orçamento Paramétrico
A8: Cliente
A9: Obra | B9: Reserva | I9: Status | J9: Concluído
A10: Data | B10: 44294 | G10: Revisão | H10: R00 | I10: Resp. | J10: Kelen
A12: MARINA
A14: Descrição | D14: Quantidade | F14: Parâmetro | H14: Referência | I14: Valor total
A15: Estrutura metálica de sustentação | D15: ='Dados Gerais'!E30*Marina!F15 -> 16471.6 | E15: kg | F15: 40 | G15: kg/m² | H15: Média | I15: =ROUNDUP(+D15*25*1.2,) -> 494148
A16: Número de Estacas | D16: =ROUNDUP(F16*'Dados Gerais'!E30,) -> 54 | E16: m² | F16: =ROUNDUP(0.11*1.15,2) -> 0.13 | G16: un / AMC | H16: Média | I16: 0
A17: Estaca Hélice Continua Diâmetro 60 | D17: =ROUNDUP(F17/100*D16,) -> 19 | E17: un | F17: 35 | G17: % | H17: Média | I17: 0
A18: Estaca Hélice Continua Diâmetro 60 | D18: =F18*D17 -> 760 | E18: m | F18: 40 | G18: m / un | H18: Média | I18: =ROUNDUP(D18*120*1.7,) -> 155040
A19: Estaca Hélice Continua Diâmetro 70 | D19: =D16-D17 -> 35 | E19: un | F19: =100-F17 -> 65 | G19: % | H19: Média | I19: 0
A20: Estaca Hélice Continua Diâmetro 70 | D20: =F20*D19 -> 1400 | E20: m | F20: 40 | G20: m / un | H20: Média | I20: =ROUNDUP(D20*125*1.7,) -> 297500
A21: Armação | D21: =F21*D22 -> 6195.7972 | E21: kg | F21: 10.5 | G21: kg / m³ | H21: Média | I21: =D21*9.5 -> 58860.073
A22: Concreto | D22: =(PI()*(0.4^2)/4*D18+PI()*(0.6^2)/4*D20+PI()*(0.7^2)/4)*1.2 -> 590.07592 | E22: m³ | F22: 630 | G22: R$ / m³ | H22: Média | I22: =D22*F22 -> 371747.83
A23: TOTAL | I23: =SUM(I15:J22) -> 1377295.9
K27: =I23 -> 1377295.9

Sheet Alvenaria
A2: ORÇAMENTO PARAMÉTRICO ALVENARIA
A7: Documento | B7: MTH_INC-RES Orçamento Paramétrico
A8: Cliente
A9: Obra | B9: Reserva | I9: Status | J9: Concluído
A10: Data | B10: 44294 | G10: Revisão | H10: R00 | I10: Resp. | J10: Kelen
A12: ALVENARIA
A14: Descrição | D14: Quantidade | F14: Parâmetro | H14: Referência | I14: Valor total
A15: Alvenaria embasamento | D15: =+F15*'Dados Gerais'!E24 -> 5979.8475 | E15: m² | F15: 0.75 | G15: m² / AE | H15: Média | I15: =+D15*43.5 -> 260123.37
A16: Alvenaria lazer | D16: =+'Dados Gerais'!$E$22*Alvenaria!F16 -> 667.25 | E16: m² | F16: 0.85 | G16: m² / AL | H16: Média | I16: =+D16*43.5 -> 29025.375
A17: Alvenaria tipo | D17: =+'Dados Gerais'!$E$20*'Dados Gerais'!$E$17*Alvenaria!F17 -> 17986.986 | E17: m² | F17: 1.8 | G17: m² / APT*NPT | H17: Média | I17: =+D17*43.5 -> 782433.89
A18: Alvenaria tipo diferenciado | D18: =+'Dados Gerais'!$E$20*'Dados Gerais'!$E$18*Alvenaria!F18 -> 2116.116 | E18: m131 | F18: 1.8 | G18: m² / APT*NPD | H18: Média | I18: =+D18*43.5 -> 92051.046
A19: Alvenaria duplex | D19: =+'Dados Gerais'!$E$20*'Dados Gerais'!$E$19*Alvenaria!F19 -> 2116.116 | E19: m132 | F19: 1.8 | G19: m² / APT*ND | H19: Média | I19: =+D19*43.5 -> 92051.046
A20: Alvenaria cobertura / reservatório | D20: =+'Dados Gerais'!E20*F20 -> 470.248 | E20: m² | F20: 0.8 | G20: m² / APT | H20: Média | I20: =+D20*43.5 -> 20455.788
A21: Mão de obra | D21: =+D15+D17+D16+D20 -> 25104.331 | E21: m² | F21: 40 | G21: R$ / m² | H21: Média | I21: =+D21*F21 -> 1004173.3
A22: TOTAL | I22: =SUM(I15:J21) -> 2280313.8
J26: =I22 -> 2280313.8

Sheet Instalações
A2: ORÇAMENTO PARAMÉTRICO INSTALAÇÕES
A7: Documento | B7: MTH_INC-RES Orçamento Paramétrico
A8: Cliente
A9: Obra | B9: Reserva | I9: Status | J9: Concluído
A10: Data | B10: 44294 | G10: Revisão | H10: R00 | I10: Resp. | J10: Kelen
A12: INSTALAÇÕES ELÉTRICAS
A14: Descrição | D14: Quantidade | F14: Parâmetro | H14: Referência | I14: Valor total
A15: Entrada de Energia | D15: 1 | E15: vb | F15: 2.65 | G15: R$ / AC | H15: Média | I15: =+F15*'Dados Gerais'!$E$15 -> 54458.56
A16: Eletrodutos e Eletrocalhas | D16: 1 | E16: vb | F16: 8.2 | G16: R$ / AC | H16: Média | I16: =+F16*'Dados Gerais'!$E$15 -> 168513.28
A17: Instalações Embutidas e Aparentes | D17: 1 | E17: vb | F17: 5.6 | G17: R$ / AC | H17: Média | I17: =+F17*'Dados Gerais'!$E$15 -> 115082.24
A18: Cabos e Fiações | D18: 1 | E18: vb | F18: 35 | G18: R$ / AC | H18: Média | I18: =+F18*'Dados Gerais'!$E$15 -> 719264
A19: Quadros e Disjuntores | D19: 1 | E19: vb | F19: 15 | G19: R$ / AC | H19: Média | I19: =+F19*'Dados Gerais'!$E$15 -> 308256
A20: Acabamentos Elétricos | D20: 1 | E20: vb | F20: 10 | G20: R$ / AC | H20: Média | I20: =+F20*'Dados Gerais'!$E$15 -> 205504
A21: Equipamentos e Iluminação | D21: 1 | E21: vb | F21: 8 | G21: R$ / AC | H21: Média | I21: =+F21*'Dados Gerais'!$E$15 -> 164403.2
A22: Mão de Obra para Instalações Elétricas | D22: 1 | E22: vb | F22: 45 | G22: R$ / AC | H22: Média | I22: =+F22*'Dados Gerais'!$E$15 -> 924768
A23: TOTAL | I23: =SUM(I15:J22) -> 2660249.3
A25: INSTALAÇÕES HIDRÁULICAS
A27: Descrição | D27: Quantidade | F27: Parâmetro | H27: Referência | I27: Valor total
A28: Instalações de Água Fria | D28: 1 | E28: vb | F28: 15 | G28: R$ / AC | H28: Média | I28: =+F28*'Dados Gerais'!$E$15 -> 308256
A29: Instalações de Água Quente | D29: 1 | E29: vb | F29: 7.5 | G29: R$ / AC | H29: Média | I29: =+F29*'Dados Gerais'!$E$15 -> 154128
A30: Instalações de Águas Pluviais | D30: 1 | E30: vb | F30: 6.4 | G30: R$ / AC | H30: Média | I30: =+F30*'Dados Gerais'!$E$15 -> 131522.56
A31: Instalações Sanitárias | D31: 1 | E31: vb | F31: 8.15 | G31: R$ / AC | H31: Média | I31: =+F31*'Dados Gerais'!$E$15 -> 167485.76
A32: Suportes | D32: 1 | E32: vb | F32: 1.5 | G32: R$ / AC | H32: Média | I32: =+F32*'Dados Gerais'!$E$15 -> 30825.6
A33: Louças e Metais | D33: 1 | E33: vb | F33: 25 | G33: R$ / AC | H33: Média | I33: =+F33*'Dados Gerais'!$E$15+7500*4*2 -> 573760
A34: Mão de Obra para Instalações Hidráulicas | D34: 1 | E34: vb | F34: 40 | G34: R$ / AC | H34: Média | I34: =+F34*'Dados Gerais'!$E$15 -> 822016
A35: TOTAL | I35: =SUM(I28:J34) -> 2187993.9
A38: INSTALAÇÕES PREVENTIVAS E GLP
A40: Descrição | D40: Quantidade | F40: Parâmetro | H40: Referência | I40: Valor total
A41: Instalações Preventivas | D41: 1 | E41: vb | F41: 18 | G41: R$ / AC | H41: Média | I41: =+F41*'Dados Gerais'!$E$15 -> 369907.2
A42: Instalações de GLP | D42: 1 | E42: vb | F42: 9.5 | G42: R$ / AC | H42: Média | I42: =+F42*'Dados Gerais'!$E$15 -> 195228.8
A43: Instalações de Proteção e Aterramento - SPDA | D43: 1 | E43: vb | F43: 6 | G43: R$ / AC | H43: Média | I43: =+F43*'Dados Gerais'!$E$15 -> 123302.4
A44: Mão de Obra | D44: 1 | E44: vb | F44: 14.5 | G44: R$ / AC | H44: Média | I44: =+F44*'Dados Gerais'!$E$15 -> 297980.8
A45: TOTAL | I45: =SUM(I41:J44) -> 986419.2 | M45: =I45+I35+I23 -> 5834662.4
A48: CLIMATIZAÇÃO, EXAUSTÃO MECÂNICA E PRESSURIZAÇÃO
A50: Descrição | D50: Quantidade | F50: Parâmetro | H50: Referência | I50: Valor total
A51: Infraestrutura para Instalação de Ar Condicionado* | D51: 1 | E51: vb | F51: 25 | G51: R$ / AC | H51: Média | I51: =+F51*'Dados Gerais'!$E$15 -> 513760
A52: Pressurização da escada | D52: 1 | E52: vb | F52: 6500 | G52: R$ / NP | H52: Média | I52: =+F52*('Dados Gerais'!E29+'Dados Gerais'!E17+'Dados Gerais'!E18+'Dados Gerais'!E19) -> 175500
A53: Churrasqueiras | D53: 1 | E53: vb | F53: 3500 | G53: R$ / AC | H53: Média | I53: =+F53*79 -> 276500
A54: TOTAL | I54: =SUM(I51:J53) -> 965760

Sheet Impermeabilização
A2: ORÇAMENTO PARAMÉTRICO IMPERMEABILIZAÇÃO
A7: Documento | B7: MTH_INC-RES Orçamento Paramétrico
A8: Cliente
A9: Obra | B9: Reserva | I9: Status | J9: Concluído
A10: Data | B10: 44294 | G10: Revisão | H10: R00 | I10: Resp. | J10: Kelen
A12: IMPERMEABILIZAÇÃO
A14: Descrição | D14: Quantidade | F14: Parâmetro | H14: Referência | I14: Valor total
A15: Regularização de Superfície | D15: =+D19+D20 -> 7192.64 | E15: m² | F15: 15.5 | G15: R$ / m² | H15: Média | I15: =+D15*F15 -> 111485.92
A16: Poço do elevador | D16: 50 | E16: m² | F16: 45 | G16: R$ / m² | H16: Média | I16: =+D16*F16 -> 2250
A17: Baldrames | D17: =0.7*Infraestrutura!D32 -> 842.8665 | E17: m² | F17: 30 | G17: R$ / m² | H17: Média | I17: =+D17*F17 -> 25285.995
A18: Ralos | D18: 1 | E18: vb | F18: 2.8 | G18: R$ / AC | H18: Média | I18: =+F18*'Dados Gerais'!$E$15 -> 57541.12
A19: Impermeabilizações cimenticias | D19: =+F19*'Dados Gerais'!$E$15 -> 4110.08 | E19: m² | F19: 0.2 | G19: m² / AC | H19: Média | I19: =+D19*40 -> 164403.2
A20: Impermeabilizações com manta asfaltica | D20: =+F20*'Dados Gerais'!$E$15 -> 3082.56 | E20: m² | F20: 0.15 | G20: m² / AC | H20: Média | I20: =+D20*105 -> 323668.8
A21: Impermeabilização de peitoril | D21: 1 | E21: vb | F21: 0.75 | G21: R$ / AC | H21: Média | I21: =+F21*'Dados Gerais'!$E$15 -> 15412.8
A22: Proteção Mecânica | D22: =+D20 -> 3082.56 | E22: m² | F22: 60 | G22: R$ / m² | H22: Média | I22: =+D22*60 -> 184953.6
A23: TOTAL | I23: =SUM(I15:J22) -> 885001.44

Sheet Rev. Internos Piso e Parede
A2: ORÇAMENTO PARAMÉTRICO REVESTIMENTOS INTERNOS EM PISO E PAREDE
A7: Documento | B7: MTH_INC-RES Orçamento Paramétrico
A8: Cliente
A9: Obra | B9: Reserva | I9: Status | J9: Concluído
A10: Data | B10: 44294 | G10: Revisão | H10: R00 | I10: Resp. | J10: Kelen
A12: REVESTIMENTOS INTERNOS EM PISO E PAREDE
A14: Descrição | D14: Quantidade | F14: Parâmetro | H14: Referência | I14: Valor total
A15: Contrapiso | D15: =+'Dados Gerais'!$E$15*'Rev. Internos Piso e Parede'!F15 -> 16851.328 | E15: m² | F15: 0.82 | G15: m² / AC | H15: Média | I15: =+D15*48*1.15 -> 930193.31
A16: Chapisco | D16: =+'Dados Gerais'!$E$15*'Rev. Internos Piso e Parede'!F16 -> 45210.88 | E16: m² | F16: 2.2 | G16: m² / AC | H16: Média | I16: =+D16*5.5 -> 248659.84
A17: Reboco | D17: =+'Dados Gerais'!$E$15*'Rev. Internos Piso e Parede'!F17 -> 45210.88 | E17: m² | F17: 2.2 | G17: m² / AC | H17: Média | I17: =35*D17 -> 1582380.8
A18: Estucamento | D18: 1 | E18: vb | F18: 0.75 | G18: R$ / AC | H18: Média | I18: =+F18*'Dados Gerais'!$E$15 -> 15412.8
A19: TOTAL | I19: =SUM(I15:J18) -> 2776646.7
K22: =I19 -> 2776646.7

Sheet Acabamentos de Teto
A2: ORÇAMENTO PARAMÉTRICO REVESTIMENTOS E ACABAMENTOS INTERNOS EM TETO
A7: Documento | B7: MTH_INC-RES Orçamento Paramétrico
A8: Cliente
A9: Obra | B9: Reserva | G9: UC | H9: 02 | I9: Status | J9: Concluído
A10: Data | B10: 44294 | G10: Revisão | H10: R00 | I10: Resp. | J10: Kelen
A12: ACABAMENTOS DE TETO
A14: Descrição | D14: Quantidade | F14: Parâmetro | H14: Referência | I14: Valor total
A15: Forro de Gesso | D15: =+'Dados Gerais'!E15*F15 -> 16440.32 | E15: m² | F15: 0.8 | G15: m² / AC | H15: Média | I15: =+D15*75 -> 1233024
A16: Negativo | D16: =+F16*'Dados Gerais'!$E$15 -> 14796.288 | E16: m² | F16: 0.72 | G16: m / AC | H16: Média | I16: =+D16*23 -> 340314.62
A17: Cortineiro | D17: =+F17*'Dados Gerais'!$E$15 -> 1582.6484 | E17: m² | F17: =(384.435/5491)*1.1 -> 0.077013021 | G17: m / AC | H17: Média | I17: =D17*45 -> 71219.178
A18: Estucamento | D18: 1 | E18: vb | F18: 4.5 | G18: R$ / AC | H18: Média | I18: =+F18*'Dados Gerais'!$E$15 -> 92476.8
A19: TOTAL | I19: =SUM(I15:J18) -> 1737034.6
J24: =I19 -> 1737034.6

Sheet Acabamentos de Piso e Parede
A2: ORÇAMENTO PARAMÉTRICO ACABAMENTOS EM PISO E PAREDE
A7: Documento | B7: MTH_INC-RES Orçamento Paramétrico
A8: Cliente
A9: Obra | B9: Reserva | G9: UC | H9: 02 | I9: Status | J9: Concluído
A10: Data | B10: 44294 | G10: Revisão | H10: R00 | I10: Resp. | J10: Kelen
A12: ACABAMENTOS EM PISO E PAREDE
A14: Descrição | D14: Quantidade | F14: Parâmetro | H14: Referência | I14: Valor total
A15: Revestimentos de Piso | D15: 1 | E15: vb | F15: 110 | G15: R$ / AC | H15: Média | I15: =+F15*'Dados Gerais'!$E$15 -> 2260544
A16: Revestimentos de Piso - vinílico | D16: 3476.97 | E16: m² | F16: 140 | G16: R$ / m² | H16: Média | I16: =+F16*D16 -> 486775.8
A17: Rodapés | D17: 1 | E17: vb | F17: 30 | G17: R$ / AC | H17: Média | I17: =+F17*'Dados Gerais'!$E$15 -> 616512
A18: Revestimentos de Parede | D18: 1 | E18: vb | F18: 40 | G18: R$ / AC | H18: Média | I18: =+F18*'Dados Gerais'!$E$15 -> 822016
A19: TOTAL | I19: =SUM(I15:J18) -> 4185847.8
J22: =I19 -> 4185847.8

Sheet Pintura Interna
A2: ORÇAMENTO PARAMÉTRICO PINTURA INTERNA
A7: Documento | B7: MTH_INC-RES Orçamento Paramétrico
A8: Cliente
A9: Obra | B9: Reserva | G9: UC | H9: 02 | I9: Status | J9: Concluído
A10: Data | B10: 44294 | G10: Revisão | H10: R00 | I10: Resp. | J10: Kelen
A12: PINTURA INTERNA
A14: Descrição | D14: Quantidade | F14: Parâmetro | H14: Referência | I14: Valor total
A15: Pintura Interna | D15: 1 | E15: vb | F15: 95 | G15: R$ / AC | H15: Média | I15: =+F15*'Dados Gerais'!$E$15 -> 1952288
A16: TOTAL | I16: =SUM(I15:J15) -> 1952288
J19: =I16 -> 1952288

Sheet Esquadrias
A2: ORÇAMENTO PARAMÉTRICO ESQUADRIAS
A7: Documento | B7: MTH_INC-RES Orçamento Paramétrico
A8: Cliente
A9: Obra | B9: Reserva | G9: UC | H9: 02 | I9: Status | J9: Concluído
A10: Data | B10: 44294 | G10: Revisão | H10: R00 | I10: Resp. | J10: Kelen
A12: ESQUADRIAS
A14: Descrição | D14: Quantidade | F14: Parâmetro | H14: Referência | I14: Valor total
A15: Esquadrias de Alumínio | D15: 1 | E15: vb | F15: 200 | G15: R$ / AC | H15: Média | I15: =+F15*'Dados Gerais'!$E$15 -> 4110080
A16: Esquadrias Metálicas | D16: 1 | E16: vb | F16: 3000 | G16: R$ / NP | H16: Média | I16: =+F16*'Dados Gerais'!$E$16 -> 81000
A17: Serralherias | D17: 1 | E17: vb | F17: 80000 | G17: R$ | H17: Média | I17: =+D17*F17 -> 80000
A18: Guarda Corpo | D18: 475.02 | E18: m² | F18: 600 | G18: R$ / m² | H18: Média | I18: =+F18*D18 -> 285012
A19: Brise da Fachada Móvel | D19: 328.698 | E19: m² | F19: 1000 | G19: R$ / m² | H19: Média | I19: =+F19*D19 -> 328698
A20: Brise Fixo | D20: 495.688 | E20: m² | F20: 750 | G20: R$ / m² | H20: Média | I20: =+F20*D20 -> 371766
A21: Pele de Vidro | D21: 152.856 | E21: m² | F21: 1200 | G21: R$ / m² | H21: Média | I21: =+F21*D21 -> 183427.2
A22: Esquadrias de Madeira | D22: 1 | E22: vb | F22: 80 | G22: R$ / AC | H22: Média | I22: =+F22*'Dados Gerais'!$E$15 -> 1644032
A23: TOTAL | I23: =SUM(I15:J22) -> 7084015.2
K26: =I23 -> 7084015.2

Sheet Rev. Fachada
A2: ORÇAMENTO PARAMÉTRICO REVESTIMENTOS E ACABAMENTOS DE FACHADA
A7: Documento | B7: MTH_INC-RES Orçamento Paramétrico
A8: Cliente
A9: Obra | B9: Reserva | G9: UC | H9: 02 | I9: Status | J9: Concluído
A10: Data | B10: 44294 | G10: Revisão | H10: R00 | I10: Resp. | J10: Kelen
A12: REVESTIMENTOS ARGAMASSADOS
A14: Descrição | D14: Quantidade | F14: Parâmetro | H14: Referência | I14: Valor total
A15: Chapisco em Estrutura | D15: =F15*'Dados Gerais'!$E$15 -> 3842.9248 | E15: m² | F15: 0.187 | G15: m² / AC | H15: - | I15: =D15*5.04*1.5 -> 29052.511
A16: Chapisco em Alvenaria | D16: =F16*'Dados Gerais'!$E$15 -> 15351.149 | E16: m² | F16: 0.747 | G16: m² / AC | H16: - | I16: =D16*F16*1.5 -> 17200.962
A17: Reboco | D17: =F17*'Dados Gerais'!$E$15 -> 19194.074 | E17: m² | F17: 0.934 | G17: m² / AC | H17: - | I17: =D17*11.1565*1.1*1.45 -> 341551.2 | L17: =+D17*F17 -> 17927.265
A18: TOTAL | I18: =SUM(I15:J17) -> 387804.67
A21: PINTURA
A23: Descrição | D23: Quantidade | F23: Parâmetro | H23: Referência | I23: Valor total
A24: Textura / Pintura | D24: =633.12 -> 633.12 | E24: m² | F24: 25 | G24: R$ / m² | H24: - | I24: =+D24*F24*65 -> 1028820
A25: TOTAL | I25: =SUM(I24:J24) -> 1028820
A27: REVESTIMENTOS ESPECIAIS
A29: Descrição | D29: Quantidade | F29: Parâmetro | H29: Referência | I29: Valor total
A30: Detalhes | D30: 1 | E30: vb | F30: 60000 | H30: - | I30: =+F30 -> 60000
A31: Pastilhas | D31: =D17-D24 -> 18560.954 | E31: m² | F31: 180 | H31: - | I31: =+F31*D31 -> 3340971.6
I32: =SUM(I30:J31) -> 3400971.6
I34: =I32+I25+I18 -> 4817596.3

Sheet Cobertura
A2: ORÇAMENTO PARAMÉTRICO COBERTURA
A7: Documento | B7: MTH_INC-RES Orçamento Paramétrico
A8: Cliente
A9: Obra | B9: Reserva | G9: UC | H9: 02 | I9: Status | J9: Concluído
A10: Data | B10: 44294 | G10: Revisão | H10: R00 | I10: Resp. | J10: Kelen
A12: COBERTURA
A14: Descrição | D14: Quantidade | F14: Parâmetro | H14: Referência | I14: Valor total
A15: Cobertura | D15: =145.06*2+82.33+29.15 -> 401.6 | E15: m² | F15: 450 | G15: R$ / m² | H15: - | I15: =+F15*D15 -> 180720
A16: TOTAL | I16: =SUM(I15:J15) -> 180720
J19: =I16 -> 180720

Sheet Equipamentos
A2: ORÇAMENTO PARAMÉTRICO EQUIPAMENTOS
A7: Documento | B7: MTH_INC-RES Orçamento Paramétrico
A8: Cliente
A9: Obra | B9: Reserva | G9: UC | H9: 02 | I9: Status | J9: Concluído
A10: Data | B10: 44294 | G10: Revisão | H10: R00 | I10: Resp. | J10: Kelen
A12: EQUIPAMENTOS
A14: Descrição | D14: Quantidade | F14: Parâmetro | H14: Referência | I14: Valor total
A15: Elevadores | D15: 3 | E15: un | F15: 15000 | G15: R$ / NP | H15: Média | I15: =D15*F15*('Dados Gerais'!$E$16) -> 1215000
A16: Gerador | D16: 1 | E16: un | F16: 70000 | G16: R$ | H16: Média | I16: =+D16*F16 -> 70000
A17: Equipamentos para Piscina | D17: 1 | E17: vb | F17: =150000+60000*2 -> 270000 | G17: R$ | H17: Média | I17: =+D17*F17 -> 270000
A18: Equipamentos para Sauna | D18: 1 | E18: vb | F18: =75000 -> 75000 | G18: R$ | H18: Média | I18: =+D18*F18 -> 75000
A19: Equipamentos Marina | D19: 1 | E19: vb | F19: 100000 | G19: R$ | H19: Média | I19: =+D19*F19 -> 100000
A20: Equipamentos e Sistemas especiais | D20: 1 | E20: vb | F20: =Instalações!I54 -> 965760 | G20: R$ | H20: Média | I20: =+D20*F20 -> 965760
A21: TOTAL | I21: =SUM(I15:J20) -> 2695760
J24: =I21 -> 2695760

Sheet Complementares
A2: ORÇAMENTO PARAMÉTRICO EQUIPAMENTOS
A7: Documento | B7: MTH_INC-RES Orçamento Paramétrico
A8: Cliente
A9: Obra | B9: Reserva | G9: UC | H9: 02 | I9: Status | J9: Concluído
A10: Data | B10: 44294 | G10: Revisão | H10: R00 | I10: Resp. | J10: Kelen
A12: SERVIÇOS COMPLEMENTARES
A14: Descrição | D14: Quantidade | F14: Parâmetro | H14: Referência | I14: Valor total
A15: Móveis e decoração | D15: 1 | E15: vb | F15: 2500 | G15: R$ / AL | H15: Média | I15: =D15*F15*'Dados Gerais'!$E$22 -> 1962500
A16: Equipamentos de lazer | D16: 1 | E16: vb | F16: 500 | G16: R$ / AL | H16: Média | I16: =D16*F16*'Dados Gerais'!$E$22 -> 392500
A17: Comunicação visual | D17: 1 | E17: vb | F17: 7 | G17: R$ / AC | H17: Média | I17: =D17*F17*'Dados Gerais'!$E$15 -> 143852.8
A18: Paisagismo | D18: 1 | E18: vb | F18: 5 | G18: R$ / AC | H18: Média | I18: =D18*F18*'Dados Gerais'!$E$15 -> 102752
A19: Limpeza | D19: 1 | E19: vb | F19: 6.5 | G19: R$ / AC | H19: Média | I19: =D19*F19*'Dados Gerais'!$E$15 -> 133577.6
A20: TOTAL | I20: =SUM(I15:J19) -> 2735182.4
J23: =I20 -> 2735182.4
