Workbook

Sheet Dados Gerais
A2: ORÇAMENTO PARAMÉTRICO GERENCIAMENTO EXECUTIVO
A7: Documento
A8: Cliente
A9: Obra
A10: Data | B10: 44294 | E10: Revisão | F10: R00 | G10: Status | H10: Em andamento | I10: Responsável | J10: Kelen
A12: Descrição | D12: Identificador | E12: Informação
A13: Área do terreno | D13: AT | E13: 581.35 | H13: m²
A14: Testada do terreno | D14: TT | E14: 33.59 | H14: m
A15: Área total construída | D15: AC | E15: 6964.97 | H15: m²
A16: N° total de pavimentos | D16: NP | E16: 29 | H16: un
A17: N° de pavimentos tipo | D17: NPT | E17: 19 | H17: un
A18: N° de pavimentos tipo diferenciado | D18: NPD | E18: 0 | H18: un
A19: N° de pavimentos duplex | D19: ND | E19: 2 | H19: un
A20: Área de projeção da torre | D20: APT | E20: 188.51 | H20: m²
A21: Perímetro de projeção da torre | D21: PPT | E21: 64.23 | H21: m
A22: Área Lazer | D22: AL | E22: 146.89 | H22: m²
A23: Locação da obra | D23: LC | E23: 106.87 | H23: m
A24: Área do embasamento | D24: AE | E24: =432.16+485.68+485.68+485.68+310.37+485.94 -> 2685.51 | H24: m²
A25: Área de subsolos | D25: AS | E25: 0 | H25: m²
A26: N° de subsolos | D26: NS | E26: 0 | H26: un
A27: Área de projeção do embasamento | D27: APE | E27: 432.11 | H27: m²
A28: Perímetro de projeção embasamento | D28: PPE | E28: 100.35 | H28: m
A29: N° de pavimentos de embasamento | D29: NPE | E29: 6 | H29: un

Sheet Resumo
A2: ORÇAMENTO PARAMÉTRICO GERENCIAMENTO EXECUTIVO
A7: Documento | B7: MTH_INC-RES Orçamento Paramétrico
A8: Cliente | B8: PASS-E
A9: Obra | B9: Reserva | E9: UC | F9: 01 | G9: Status | H9: Concluído
A10: Data | B10: 44294 | E10: Revisão | F10: R00 | G10: Resp. | H10: Kelen
A12: MOVIMENTAÇÃO DE TERRA
A14: Descrição | D14: Valor total
A15: =+'Movimentação de Terra'!A19 -> REBAIXAMENTO DE LENÇOL | D15: =+'Movimentação de Terra'!I23 -> 23254
A16: =+'Movimentação de Terra'!A26 -> ESCAVAÇÃO E REATERRO DE VALAS | D16: =+'Movimentação de Terra'!I32 -> 64148.026
A17: =+'Movimentação de Terra'!A35 -> REGULARIZAÇÃO E APILOAmENTO DE FUNDO DE VALAS | D17: =+'Movimentação de Terra'!I39 -> 2093
A18: TOTAL | D18: =SUM(D15:H17) -> 89495.026
A22: INFRAESTRUTURA
A24: Descrição | D24: Valor total
A25: =+Infraestrutura!A12 -> FUNDAÇÃO PROFUNDA | D25: =+Infraestrutura!I24 -> 1059697
A26: =+Infraestrutura!A27 -> FUNDAÇÃO RASA | D26: =+Infraestrutura!I34 -> 603816.27
A27: CONTENÇÃO | D27: =Infraestrutura!#REF! -> #REF!
A28: TOTAL | D28: =SUM(D25:H27) -> #REF!
A31: SUPRAESTRUTURA
A33: Descrição | D33: Valor total
A34: =+Supraestrutura!A12 -> SUPRAESTRUTURA | D34: =+Supraestrutura!I23 -> 4497095.2
A35: TOTAL | D35: =SUM(D34:H34) -> 4497095.2
A38: ALVENARIA
A40: Descrição | D40: Valor total
A41: =+Alvenaria!A12 -> ALVENARIA | D41: =+Alvenaria!I23 -> 1217886.5
A42: TOTAL | D42: =SUM(D41) -> 1217886.5
A45: INSTALAÇÕES
A47: Descrição | D47: Valor total
A48: =+Instalações!A12 -> INSTALAÇÕES ELÉTRICAS | D48: =+Instalações!I23 -> 1187527.4
A49: =+Instalações!A25 -> INSTALAÇÕES HIDRÁULICAS | D49: =+Instalações!I35 -> 1000270.9
A50: =+Instalações!A38 -> INSTALAÇÕES PREVENTIVAS E GLP | D50: =+Instalações!I45 -> 219396.55
A51: =+Instalações!#REF! -> #REF! | D51: =+Instalações!#REF! -> #REF!
A52: TOTAL | D52: =SUM(D48:H51) -> #REF!
A55: IMPERMEABILIZAÇÃO
A57: Descrição | D57: Valor total
A58: =+Impermeabilização!A12 -> IMPERMEABILIZAÇÃO | D58: =+Impermeabilização!I23 -> 303240.47
A59: TOTAL | D59: =SUM(D58) -> 303240.47
A62: REVESTIMENTOS INTERNOS EM PISO E PAREDE
A64: Descrição | D64: Valor total
A65: =+'Rev. Internos Piso e Parede'!A12 -> REVESTIMENTOS INTERNOS EM PISO E PAREDE | D65: =+'Rev. Internos Piso e Parede'!I19 -> 1100465.3
A66: TOTAL | D66: =SUM(D65) -> 1100465.3
...

Sheet Movimentação de Terra
A2: ORÇAMENTO PARAMÉTRICO MOVIMENTAÇÃO DE TERRA
A7: Documento | B7: MTH_INC-RES Orçamento Paramétrico
A8: Cliente
A9: Obra | B9: Reserva | I9: Status | J9: Concluído
A10: Data | B10: 44294 | G10: Revisão | H10: R00 | I10: Resp. | J10: Kelen
A12: ESCAVAÇÃO
A14: Descrição | D14: Quantidade | F14: Parâmetro | H14: Referência | I14: Valor total
A15: Escavação | D15: =+'Dados Gerais'!E25*3.06 -> 0 | E15: m³ | F15: 28.5 | G15: R$ / m³ | H15: Pedro Chaves | I15: =+D15*F15 -> 0
A16: TOTAL | I16: =SUM(I15:J15) -> 0
A19: REBAIXAMENTO DE LENÇOL
A21: Descrição | D21: Quantidade | F21: Parâmetro | H21: Referência | I21: Valor total
A22: Rebaixamento de Lençol | D22: 0 | E22: - | F22: 40 | G22: R$ / AT | H22: Média | I22: =F22*'Dados Gerais'!E13 -> 23254
A23: TOTAL | I23: =SUM(I22:J22) -> 23254
A26: ESCAVAÇÃO E REATERRO DE VALAS
A28: Descrição | D28: Quantidade | F28: Parâmetro | H28: Referência | I28: Valor total
A29: Escavação mecanizada para blocos e baldrames | D29: =F29*'Dados Gerais'!E13 -> 232.54 | E29: - | F29: 0.4 | G29: m³ / AT | H29: Média | I29: =+ROUNDUP((D29*35),0) -> 8139
A30: Reaterro para blocos e baldrames | D30: =F30*'Dados Gerais'!E13 -> 116.27 | E30: - | F30: 0.2 | G30: m³ / AT | H30: Média | I30: =+ROUNDUP((D30*25),0) -> 2907
A31: Movimentação de terra das estacas | D31: =+Infraestrutura!D23*F31 -> 1517.2008 | E31: m³ | F31: 1.2 | G31: m³ / m³ | H31: Média | I31: =+D31*35 -> 53102.026
A32: TOTAL | I32: =SUM(I29:J31) -> 64148.026
A35: REGULARIZAÇÃO E APILOAmENTO DE FUNDO DE VALAS
A37: Descrição | D37: Quantidade | F37: Parâmetro | H37: Referência | I37: Valor total
A38: Lastro de concreto magro e= 10cm - Blocos | D38: =F38*'Dados Gerais'!E13 -> 116.27 | E38: m² | F38: 0.2 | G38: m² / AT | H38: Média | I38: =ROUNDUP((D38*18),0) -> 2093
A39: TOTAL | I39: =SUM(I38:J38) -> 2093
I42: =I39+I32+I23 -> 89495.026

Sheet Conteções
A2: ORÇAMENTO PARAMÉTRICO CONTENÇÕES
A7: Documento | B7: MTH_MEN BRM Dados Gerais
A8: Cliente | B8: MENDES
A9: Obra | B9: Brava Mundo | G9: UC | H9: 02 | I9: Status | J9: Concluído
A10: Data | B10: 44160 | G10: Revisão | H10: R01 | I10: Resp. | J10: Kelen
A12: MURETA GUIA
A14: Descrição | D14: Quantidade | F14: Parâmetro | H14: Referência | I14: Valor total
A15: Armação | D15: =+F15*D16 -> 1428.24 | E15: kg | F15: 110 | G15: kg / m³ | H15: - | I15: =+D15*8.5 -> 12140.04
A16: Concreto | D16: =(64.92*1*0.2) -> 12.984 | E16: m³ | F16: 350 | G16: R$ / m³ | H16: - | I16: =F16*D16 -> 4544.4
A17: Forma | D17: =64.92*1*2 -> 129.84 | E17: m² | F17: 110 | G17: R$ / m² | H17: - | I17: =+D17*F17 -> 14282.4
A18: TOTAL | I18: =SUM(I15:J17) -> 30966.84
A20: PAREDE DIAFRAGMA
A22: Descrição | D22: Quantidade | F22: Parâmetro | H22: Referência | I22: Valor total
A23: Armação | D23: =+F23*D24 -> 25708.32 | E23: kg | F23: 110 | G23: kg / m³ | H23: - | I23: =+D23*8.5 -> 218520.72
A24: Concreto | D24: =64.92*9*0.4 -> 233.712 | E24: m³ | F24: 0.4 | G24: m³ / m² | H24: - | I24: =+D24*560 -> 130878.72
A25: Tirantes | E25: vb | F25: 23 | G25: R$ / AC | H25: - | I25: =F25*'Dados Gerais'!E15 -> 160194.31
A26: Mão de obra | D26: =64.92*9*2 -> 1168.56 | E26: m² | F26: 300 | G26: R$ / m² | H26: - | I26: =+D26*F26 -> 350568
A27: TOTAL | I27: =SUM(I23:J26) -> 860161.75
J30: =I27+I18 -> 891128.59

Sheet Infraestrutura
A2: ORÇAMENTO PARAMÉTRICO INFRAESTRUTURA
A7: Documento
A8: Cliente
A9: Obra | I9: Status | J9: Concluído
A10: Data | G10: Revisão | H10: R00 | I10: Resp.
A12: FUNDAÇÃO PROFUNDA
A14: Descrição | D14: Quantidade | F14: Parâmetro | H14: Referência | I14: Valor total
A15: Número de Estacas | D15: =ROUNDUP((F15*'Dados Gerais'!$E$13),0) -> 146 | E15: un | F15: 0.25 | G15: un / m² | H15: Média | I15: 0
A16: Estaca Hélice Continua Diâmetro 50 | D16: =ROUNDUP(($D$15*(F16/100)),0) -> 37 | E16: un | F16: 25 | G16: % | H16: Média | I16: 0
A17: Estaca Hélice Continua Diâmetro 50 | D17: =ROUNDUP((F17*D16),0) -> 1110 | E17: m | F17: 30 | G17: m / un | H17: Média | I17: =+ROUNDUP((D17*54),0) -> 59940
A18: Estaca Hélice Continua Diâmetro 60 | D18: =ROUNDUP(($D$15*(F18/100)),0) -> 73 | E18: un | F18: 50 | G18: % | H18: Média | I18: 0
A19: Estaca Hélice Continua Diâmetro 60 | D19: =ROUNDUP((F19*D18),0) -> 2190 | E19: m | F19: 30 | G19: m / un | H19: Média | I19: =+ROUNDUP((D19*70),0) -> 153300
A20: Estaca Hélice Continua Diâmetro 70 | D20: =ROUNDUP(($D$15*(F20/100)),0) -> 37 | E20: un | F20: 25 | G20: % | H20: Média | I20: 0
A21: Estaca Hélice Continua Diâmetro 70 | D21: =ROUNDUP((F21*D20),0) -> 1110 | E21: m | F21: 30 | G21: m / un | H21: Média | I21: =+ROUNDUP((D21*80),0) -> 88800
A22: Armação | D22: =ROUNDUP((D23*F22),0) -> 13276 | E22: kg | F22: 10.5 | G22: kg / m³ | H22: Média | I22: =+ROUNDUP((D22*8.5),0) -> 112846
A23: Concreto | D23: =PI()*(0.5^2)/4*D17+PI()*(0.6^2)/4*D19+PI()*(0.7^2)/4*D21 -> 1264.334 | E23: m³ | F23: 510 | G23: R$ / m³ | H23: Média | I23: =+ROUNDUP((D23*F23),0) -> 644811
A24: TOTAL | I24: =SUM(I15:J23) -> 1059697 | N24: =I24/'Dados Gerais'!E15 -> 152.14667
A27: FUNDAÇÃO RASA
A29: Descrição | D29: Quantidade | F29: Parâmetro | H29: Referência | I29: Valor total
A30: Fabricação, montagem e desmontagem de forma para blocos e baldrames | D30: ='Dados Gerais'!E13*Infraestrutura!F30 -> 494.1475 | E30: m² | F30: 0.85 | G30: m² / AT | H30: Média | I30: =+D30*33.7 -> 16652.771
A31: Armação | D31: =D32*F31 -> 29067.5 | E31: kg | F31: 100 | G31: kg / m³ | H31: Média | I31: =+D31*9.5 -> 276141.25
A32: Concreto | D32: =F32*'Dados Gerais'!E13 -> 290.675 | E32: m³ | F32: 0.5 | G32: m³ / AT | H32: Média | I32: =+D32*510 -> 148244.25
A33: Mão de obra | D33: =+'Dados Gerais'!E13 -> 581.35 | E33: m² | F33: 280 | G33: R$ / AT | H33: Média | I33: =+D33*F33 -> 162778
A34: TOTAL | I34: =SUM(I30:J33) -> 603816.27
I37: =I34+I24 -> 1663513.3

Sheet Supraestrutura
A2: ORÇAMENTO PARAMÉTRICO SUPRAESTRUTURA
A7: Documento | B7: MTH_INC-RES Orçamento Paramétrico
A8: Cliente
A9: Obra | B9: Reserva | I9: Status | J9: Concluído
A10: Data | B10: 44294 | G10: Revisão | H10: R00 | I10: Resp. | J10: Kelen
A12: SUPRAESTRUTURA
A14: Descrição | D14: Quantidade | F14: Parâmetro | H14: Referência | I14: Valor total
A15: Fabricação forma | D15: =+D16*F15/100 -> 2611.8637 | E15: m² | F15: 15 | G15: % | H15: Média | I15: =+D15*90 -> 235067.74
A16: Montagem de forma | D16: =+'Dados Gerais'!$E$15*F16 -> 17412.425 | E16: m² | F16: 2.5 | G16: m² / AC | H16: Média | I16: =+D16*7 -> 121886.97
A17: Escoramento - Torre | D17: =+'Dados Gerais'!E20*'Dados Gerais'!E17 -> 3581.69 | E17: m² | F17: 25 | G17: R$ / m² | H17: Média | I17: =+D17*F17 -> 89542.25
A18: Escoramento - Embasamento | D18: =+'Dados Gerais'!E24 -> 2685.51 | E18: m² | F18: 30 | G18: R$ / m² | H18: Média | I18: =+D18*F18 -> 80565.3
A19: Armadura Convencional para Estrutura | D19: =(D20)*F19 -> 148005.61 | E19: kg | F19: 85 | G19: kg / m³ | H19: Média | I19: =+D19*8 -> 1184044.9
A20: Concreto | D20: =(+'Dados Gerais'!E15)*Supraestrutura!$F$20 -> 1741.2425 | E20: m³ | F20: 0.25 | G20: m³ / AC | H20: Média | I20: =+D20*500 -> 870621.25
A21: Protensão - Material e mão de obra | D21: ='Dados Gerais'!E15 -> 6964.97 | E21: m² | F21: 60 | G21: R$ / AC | H21: Média | I21: =+D21*F21 -> 417898.2
A22: Mão de obra - estrutura em concreto armado | D22: =+'Dados Gerais'!E15 -> 6964.97 | E22: m² | F22: 215 | G22: R$ / m² | H22: Média | I22: =+D22*F22 -> 1497468.6
A23: TOTAL | I23: =SUM(I15:J22) -> 4497095.2
K27: =I23 -> 4497095.2

Sheet Alvenaria
A2: ORÇAMENTO PARAMÉTRICO ALVENARIA
A7: Documento | B7: MTH_INC-RES Orçamento Paramétrico
A8: Cliente
A9: Obra | B9: Reserva | I9: Status | J9: Concluído
A10: Data | B10: 44294 | G10: Revisão | H10: R00 | I10: Resp. | J10: Kelen
A12: ALVENARIA
A14: Descrição | D14: Quantidade | F14: Parâmetro | H14: Referência | I14: Valor total
A15: Alvenaria embasamento | D15: =+F15*'Dados Gerais'!E24 -> 2416.959 | E15: m² | F15: 0.9 | G15: m² / AE | H15: Média | I15: =+D15*43.5 -> 105137.72
A16: Alvenaria lazer | D16: =+'Dados Gerais'!$E$22*Alvenaria!F16 -> 132.201 | E16: m² | F16: 0.9 | G16: m² / AL | H16: Média | I16: =+D16*43.5 -> 5750.7435
A17: Alvenaria tipo - externo | D17: =+'Dados Gerais'!$E$20*'Dados Gerais'!$E$17*Alvenaria!F17 -> 4298.028 | E17: m² | F17: 1.2 | G17: m² / APT*NPT | H17: Média | I17: =+D17*43.5 -> 186964.22
A18: Alvenaria tipo - interno | D18: =+'Dados Gerais'!$E$20*'Dados Gerais'!$E$17*Alvenaria!F18 -> 5372.535 | E18: m² | F18: 1.5 | G18: m² / APT*NPT | H18: Média | I18: =+D18*110 -> 590978.85
A19: Alvenaria tipo diferenciado | D19: =+'Dados Gerais'!$E$20*'Dados Gerais'!$E$18*Alvenaria!F19 -> 0 | E19: m131 | F19: 2.5 | G19: m² / APT*NPD | H19: Média | I19: =+D19*43.5 -> 0
A20: Alvenaria duplex | D20: =+'Dados Gerais'!$E$20*'Dados Gerais'!$E$19*Alvenaria!F20 -> 942.55 | E20: m132 | F20: 2.5 | G20: m² / APT*ND | H20: Média | I20: =+D20*43.5 -> 41000.925
A21: Alvenaria cobertura / reservatório | D21: =+'Dados Gerais'!E20*F21 -> 169.659 | E21: m² | F21: 0.9 | G21: m² / APT | H21: Média | I21: =+D21*43.5 -> 7380.1665
A22: Mão de obra | D22: =+D15+D17+D16+D21 -> 7016.847 | E22: m² | F22: 40 | G22: R$ / m² | H22: Média | I22: =+D22*F22 -> 280673.88
A23: TOTAL | I23: =SUM(I15:J22) -> 1217886.5
J27: =I23 -> 1217886.5

Sheet Instalações
A2: ORÇAMENTO PARAMÉTRICO INSTALAÇÕES
A7: Documento | B7: MTH_INC-RES Orçamento Paramétrico
A8: Cliente
A9: Obra | B9: Reserva | I9: Status | J9: Concluído
A10: Data | B10: 44294 | G10: Revisão | H10: R00 | I10: Resp. | J10: Kelen
A12: INSTALAÇÕES ELÉTRICAS
A14: Descrição | D14: Quantidade | F14: Parâmetro | H14: Referência | I14: Valor total
A15: Entrada de Energia | D15: 1 | E15: vb | F15: 5.5 | G15: R$ / AC | H15: Média | I15: =+F15*'Dados Gerais'!$E$15 -> 38307.335
A16: Eletrodutos e Eletrocalhas | D16: 1 | E16: vb | F16: 10 | G16: R$ / AC | H16: Média | I16: =+F16*'Dados Gerais'!$E$15 -> 69649.7
A17: Instalações Embutidas e Aparentes | D17: 1 | E17: vb | F17: 15 | G17: R$ / AC | H17: Média | I17: =+F17*'Dados Gerais'!$E$15 -> 104474.55
A18: Cabos e Fiações | D18: 1 | E18: vb | F18: 35 | G18: R$ / AC | H18: Média | I18: =+F18*'Dados Gerais'!$E$15 -> 243773.95
A19: Quadros e Disjuntores | D19: 1 | E19: vb | F19: 20 | G19: R$ / AC | H19: Média | I19: =+F19*'Dados Gerais'!$E$15 -> 139299.4
A20: Acabamentos Elétricos | D20: 1 | E20: vb | F20: 15 | G20: R$ / AC | H20: Média | I20: =+F20*'Dados Gerais'!$E$15 -> 104474.55
A21: Equipamentos e Iluminação | D21: 1 | E21: vb | F21: 15 | G21: R$ / AC | H21: Média | I21: =+F21*'Dados Gerais'!$E$15 -> 104474.55
A22: Mão de Obra para Instalações Elétricas | D22: 1 | E22: vb | F22: 55 | G22: R$ / AC | H22: Média | I22: =+F22*'Dados Gerais'!$E$15 -> 383073.35
A23: TOTAL | I23: =SUM(I15:J22) -> 1187527.4
A25: INSTALAÇÕES HIDRÁULICAS
A27: Descrição | D27: Quantidade | F27: Parâmetro | H27: Referência | I27: Valor total
A28: Instalações de Água Fria | D28: 1 | E28: vb | F28: 20 | G28: R$ / AC | H28: Média | I28: =+F28*'Dados Gerais'!$E$15 -> 139299.4
A29: Instalações de Água Quente | D29: 1 | E29: vb | F29: 15 | G29: R$ / AC | H29: Média | I29: =+F29*'Dados Gerais'!$E$15 -> 104474.55
A30: Instalações de Águas Pluviais | D30: 1 | E30: vb | F30: 10 | G30: R$ / AC | H30: Média | I30: =+F30*'Dados Gerais'!$E$15 -> 69649.7
A31: Instalações Sanitárias | D31: 1 | E31: vb | F31: 10 | G31: R$ / AC | H31: Média | I31: =+F31*'Dados Gerais'!$E$15 -> 69649.7
A32: Suportes | D32: 1 | E32: vb | F32: 0 | G32: R$ / AC | H32: Média | I32: =+F32*'Dados Gerais'!$E$15 -> 0
A33: Louças e Metais | D33: 1 | E33: vb | F33: 30 | G33: R$ / AC | H33: Média | I33: =+F33*'Dados Gerais'!$E$15+7500*4*2 -> 268949.1
A34: Mão de Obra para Instalações Hidráulicas | D34: 1 | E34: vb | F34: 50 | G34: R$ / AC | H34: Média | I34: =+F34*'Dados Gerais'!$E$15 -> 348248.5
A35: TOTAL | I35: =SUM(I28:J34) -> 1000270.9
A38: INSTALAÇÕES PREVENTIVAS E GLP
A40: Descrição | D40: Quantidade | F40: Parâmetro | H40: Referência | I40: Valor total
A41: Instalações Preventivas | D41: 1 | E41: vb | F41: 9.5 | G41: R$ / AC | H41: Média | I41: =+F41*'Dados Gerais'!$E$15 -> 66167.215
A42: Instalações de GLP | D42: 1 | E42: vb | F42: 5 | G42: R$ / AC | H42: Média | I42: =+F42*'Dados Gerais'!$E$15 -> 34824.85
A43: Instalações de Proteção e Aterramento - SPDA | D43: 1 | E43: vb | F43: 5 | G43: R$ / AC | H43: Média | I43: =+F43*'Dados Gerais'!$E$15 -> 34824.85
A44: Mão de Obra | D44: 1 | E44: vb | F44: 12 | G44: R$ / AC | H44: Média | I44: =+F44*'Dados Gerais'!$E$15 -> 83579.64
A45: TOTAL | I45: =SUM(I41:J44) -> 219396.55 | M45: =I45+I35+I23 -> 2407194.9

Sheet Sistemas especiais
A2: ORÇAMENTO PARAMÉTRICO INSTALAÇÕES
A7: Documento | B7: MTH_COTA-AFP Orçamento Paramétrico
A8: Cliente | B8: COTA
A9: Obra | B9: AFONSO PENA | I9: Status | J9: Concluído
A10: Data | B10: 44454 | G10: Revisão | H10: R00 | I10: Resp. | J10: Kelen
A12: CLIMATIZAÇÃO, EXAUSTÃO MECÂNICA E PRESSURIZAÇÃO
A14: Descrição | D14: Quantidade | F14: Parâmetro | H14: Referência | I14: Valor total
A15: Infraestrutura para Instalação de Ar Condicionado | D15: 1 | E15: vb | F15: 40 | G15: R$ / AC | H15: Média | I15: =F15*'Dados Gerais'!E15 -> 278598.8
A16: Churrasqueiras | D16: 22 | E16: un | F16: 1750 | G16: R$ / un | H16: Média | I16: =+D16*F16 -> 38500
A17: TOTAL | I17: =SUM(I15:J16) -> 317098.8
A20: AUTOMAÇÃO
A22: Descrição | D22: Quantidade | F22: Parâmetro | H22: Referência | I22: Valor total
A23: Automação, teleocomunicação e sistemas de segurança | D23: 1 | E23: vb | F23: 15 | G23: R$ / AC | H23: - | I23: =+F23*'[1]Dados Gerais'!$E$14 -> 211627.35
A24: TOTAL | I24: =SUM(I23:J23) -> 211627.35
A27: OUTROS SISTEMAS ESPECIAIS
A29: Descrição | D29: Quantidade | F29: Parâmetro | H29: Referência | I29: Valor total
A30: Outros sistemas | D30: 1 | E30: vb | F30: 5 | G30: R$ / AC | H30: Média | I30: =+F30*'[1]Dados Gerais'!$E$14 -> 70542.45
A31: TOTAL | I31: =SUM(I30:J30) -> 70542.45
A34: EQUIPAMENTOS
A36: Descrição | D36: Quantidade | F36: Parâmetro | H36: Referência | I36: Valor total
A37: Elevadores | D37: 2 | E37: un | F37: 13500 | G37: R$ / NP | H37: Média | I37: =D37*F37*('[1]Dados Gerais'!$E$15-1) -> 405000
A38: Gerador | D38: 1 | E38: vb | F38: 70000 | G38: R$ / NP | H38: Média | I38: =F38*D38 -> 70000
A39: Pressurização de escadas | D39: 1 | E39: vb | F39: 4500 | G39: R$ / NP | H39: Média | I39: =F39*'Dados Gerais'!E16 -> 130500
A40: Equipamentos para Piscina | D40: 1 | E40: vb | F40: 15000 | G40: R$ | H40: Média | I40: =+D40*F40 -> 15000
A41: TOTAL | I41: =SUM(I37:J40) -> 620500
J45: =I41+I31+I24+I17 -> 1219768.6

Sheet Impermeabilização
A2: ORÇAMENTO PARAMÉTRICO IMPERMEABILIZAÇÃO
A7: Documento | B7: MTH_INC-RES Orçamento Paramétrico
A8: Cliente
A9: Obra | B9: Reserva | I9: Status | J9: Concluído
A10: Data | B10: 44294 | G10: Revisão | H10: R00 | I10: Resp. | J10: Kelen
A12: IMPERMEABILIZAÇÃO
A14: Descrição | D14: Quantidade | F14: Parâmetro | H14: Referência | I14: Valor total
A15: Regularização de Superfície | D15: =+D19+D20 -> 2437.7395 | E15: m² | F15: 15.5 | G15: R$ / m² | H15: Média | I15: =+D15*F15 -> 37784.962
A16: Poço do elevador | D16: 50 | E16: m² | F16: 45 | G16: R$ / m² | H16: Média | I16: =+D16*F16 -> 2250
A17: Baldrames | D17: =0.7*Infraestrutura!D30 -> 345.90325 | E17: m² | F17: 30 | G17: R$ / m² | H17: Média | I17: =+D17*F17 -> 10377.097
A18: Ralos | D18: 1 | E18: vb | F18: 2.8 | G18: R$ / AC | H18: Média | I18: =+F18*'Dados Gerais'!$E$15 -> 19501.916
A19: Impermeabilizações cimenticias | D19: =+F19*'Dados Gerais'!$E$15 -> 1392.994 | E19: m² | F19: 0.2 | G19: m² / AC | H19: Média | I19: =+D19*40 -> 55719.76
A20: Impermeabilizações com manta asfaltica | D20: =+F20*'Dados Gerais'!$E$15 -> 1044.7455 | E20: m² | F20: 0.15 | G20: m² / AC | H20: Média | I20: =+D20*105 -> 109698.28
A21: Impermeabilização de peitoril | D21: 1 | E21: vb | F21: 0.75 | G21: R$ / AC | H21: Média | I21: =+F21*'Dados Gerais'!$E$15 -> 5223.7275
A22: Proteção Mecânica | D22: =+D20 -> 1044.7455 | E22: m² | F22: 60 | G22: R$ / m² | H22: Média | I22: =+D22*60 -> 62684.73
A23: TOTAL | I23: =SUM(I15:J22) -> 303240.47

Sheet Rev. Internos Piso e Parede
A2: ORÇAMENTO PARAMÉTRICO REVESTIMENTOS INTERNOS EM PISO E PAREDE
A7: Documento | B7: MTH_INC-RES Orçamento Paramétrico
A8: Cliente
A9: Obra | B9: Reserva | I9: Status | J9: Concluído
A10: Data | B10: 44294 | G10: Revisão | H10: R00 | I10: Resp. | J10: Kelen
A12: REVESTIMENTOS INTERNOS EM PISO E PAREDE
A14: Descrição | D14: Quantidade | F14: Parâmetro | H14: Referência | I14: Valor total
A15: Contrapiso | D15: =+'Dados Gerais'!$E$15*'Rev. Internos Piso e Parede'!F15 -> 6964.97 | E15: m² | F15: 1 | G15: m² / AC | H15: Média | I15: =+D15*58 -> 403968.26
A16: Chapisco | D16: =+'Dados Gerais'!$E$15*'Rev. Internos Piso e Parede'!F16 -> 15322.934 | E16: m² | F16: 2.2 | G16: m² / AC | H16: Média | I16: =+D16*5 -> 76614.67
A17: Reboco | D17: =+'Dados Gerais'!$E$15*'Rev. Internos Piso e Parede'!F17 -> 15322.934 | E17: m² | F17: 2.2 | G17: m² / AC | H17: Média | I17: =(25+15)*D17 -> 612917.36
A18: Estucamento | D18: 1 | E18: vb | F18: 1 | G18: R$ / AC | H18: Média | I18: =+F18*'Dados Gerais'!$E$15 -> 6964.97
A19: TOTAL | I19: =SUM(I15:J18) -> 1100465.3
K22: =I19 -> 1100465.3

Sheet Acabamentos de Teto
A2: ORÇAMENTO PARAMÉTRICO REVESTIMENTOS E ACABAMENTOS INTERNOS EM TETO
A7: Documento | B7: MTH_INC-RES Orçamento Paramétrico
A8: Cliente
A9: Obra | B9: Reserva | G9: UC | H9: 02 | I9: Status | J9: Concluído
A10: Data | B10: 44294 | G10: Revisão | H10: R00 | I10: Resp. | J10: Kelen
A12: ACABAMENTOS DE TETO
A14: Descrição | D14: Quantidade | F14: Parâmetro | H14: Referência | I14: Valor total
A15: Forro de Gesso | D15: =+'Dados Gerais'!E15*F15 -> 4875.479 | E15: m² | F15: 0.7 | G15: m² / AC | H15: Média | I15: =+D15*100 -> 487547.9
A16: Negativo | D16: =+F16*'Dados Gerais'!$E$15 -> 3482.485 | E16: m² | F16: 0.5 | G16: m / AC | H16: Média | I16: =+D16*20 -> 69649.7
A17: Estucamento | D17: 1 | E17: vb | F17: 1 | G17: R$ / AC | H17: Média | I17: =+F17*'Dados Gerais'!$E$15 -> 6964.97
A18: TOTAL | I18: =SUM(I15:J17) -> 564162.57
J23: =I18 -> 564162.57

Sheet Acabamentos de Piso e Parede
A2: ORÇAMENTO PARAMÉTRICO ACABAMENTOS EM PISO E PAREDE
A7: Documento | B7: MTH_INC-RES Orçamento Paramétrico
A8: Cliente
A9: Obra | B9: Reserva | G9: UC | H9: 02 | I9: Status | J9: Concluído
A10: Data | B10: 44294 | G10: Revisão | H10: R00 | I10: Resp. | J10: Kelen
A12: ACABAMENTOS EM PISO E PAREDE
A14: Descrição | D14: Quantidade | F14: Parâmetro | H14: Referência | I14: Valor total
A15: Revestimentos de Piso | E15: vb | F15: 100 | G15: R$ / AC | H15: Média | I15: =+F15*'Dados Gerais'!$E$15 -> 696497
A16: Revestimentos de Piso - laminado | D16: =(14.1+14.07+4.86+15.41)*21 -> 1017.24 | E16: m² | F16: 105 | G16: R$ / m² | H16: Média | I16: =+F16*D16 -> 106810.2
A17: Rodapés | D17: 1 | E17: vb | F17: 30 | G17: R$ / AC | H17: Média | I17: =+F17*'Dados Gerais'!$E$15 -> 208949.1
A18: Revestimentos de Parede | D18: 1 | E18: vb | F18: 40 | G18: R$ / AC | H18: Média | I18: =+F18*'Dados Gerais'!$E$15 -> 278598.8
A19: TOTAL | I19: =SUM(I15:J18) -> 1290855.1
J22: =I19 -> 1290855.1

Sheet Pintura Interna
A2: ORÇAMENTO PARAMÉTRICO PINTURA INTERNA
A7: Documento | B7: MTH_INC-RES Orçamento Paramétrico
A8: Cliente
A9: Obra | B9: Reserva | G9: UC | H9: 02 | I9: Status | J9: Concluído
A10: Data | B10: 44294 | G10: Revisão | H10: R00 | I10: Resp. | J10: Kelen
A12: PINTURA INTERNA
A14: Descrição | D14: Quantidade | F14: Parâmetro | H14: Referência | I14: Valor total
A15: Pintura Interna | D15: 1 | E15: vb | F15: 115 | G15: R$ / AC | H15: Média | I15: =+F15*'Dados Gerais'!$E$15 -> 800971.55
A16: TOTAL | I16: =SUM(I15:J15) -> 800971.55
J19: =I16 -> 800971.55

Sheet Esquadrias
A2: ORÇAMENTO PARAMÉTRICO ESQUADRIAS
A7: Documento | B7: MTH_INC-RES Orçamento Paramétrico
A8: Cliente
A9: Obra | B9: Reserva | G9: UC | H9: 02 | I9: Status | J9: Concluído
A10: Data | B10: 44294 | G10: Revisão | H10: R00 | I10: Resp. | J10: Kelen
A12: ESQUADRIAS
A14: Descrição | D14: Quantidade | F14: Parâmetro | H14: Referência | I14: Valor total
A15: Esquadrias de Alumínio | D15: =Auxiliar!H6+Auxiliar!H10 -> 1941.68 | E15: m² | F15: 900 | G15: R$ / m² | H15: Média | I15: =+F15*D15 -> 1747512
A16: Esquadrias Metálicas | D16: =Auxiliar!H8 -> 60 | E16: un | F16: 1200 | G16: R$ / un | H16: Média | I16: =F16*D16 -> 72000
A17: Serralherias | D17: 1 | E17: vb | F17: 80000 | G17: R$ | H17: Média | I17: =+D17*F17 -> 80000
A18: Gradil de alumínio | D18: =Auxiliar!H12 -> 113.88 | E18: m² | F18: 800 | G18: R$ / m² | H18: Média | I18: =+F18*D18 -> 91104
A19: Guarda Corpo de vidro | D19: =Auxiliar!H5 -> 400.5221 | E19: m² | F19: 950 | G19: R$ / m² | H19: Média | I19: =+F19*D19 -> 380495.99
A20: Brise de alumínio | D20: =Auxiliar!H13 -> 109.3146 | E20: m² | F20: 1000 | G20: R$ / m² | H20: Média | I20: =+F20*D20 -> 109314.6
A21: Porta pivotante | D21: =Auxiliar!H9 -> 1 | E21: un | F21: 2500 | G21: R$ / un | H21: Média | I21: =+F21*D21 -> 2500
A22: Portão de alumínio | D22: =Auxiliar!H11 -> 2 | E22: un | F22: 8000 | G22: R$ / un | H22: Média | I22: =+F22*D22 -> 16000
A23: Esquadrias de Madeira | D23: =Auxiliar!H7 -> 218 | E23: un | F23: 900 | G23: R$ / un | H23: Média | I23: =F23*D23 -> 196200
A24: TOTAL | I24: =SUM(I15:J23) -> 2695126.6
K27: =I24 -> 2695126.6

Sheet Auxiliar
A2: 2 Portões acesso garagem - Área: 9,2m² x 2 = 18,4m² | B2: 2 | C2: portão | D2: 18.4
A3: 2 portas corta-fogo 1 folha | B3: 2 | C3: pcf
A4: 1 porta de correr alumínio 2 folhas – Área: 3,465m² | B4: 1 | C4: porta alumínio | D4: 3.465
A5: 1 porta de correr alumínio 2 folhas – Área: 1,7325m² | B5: 1 | C5: porta alumínio | D5: 1.7325 | G5: Guarda alumínio | H5: =SUMIF(C:C,G5,D:D) -> 400.5221
A6: 2 portas de abrir alumínio 2 folhas – Área: 2,6376m² x 2 = 5,2752m² | B6: 2 | C6: porta alumínio | D6: 5.2752 | G6: janela | H6: =SUMIF(C:C,G6,D:D) -> 1895.06
A7: 1 porta de abrir alumínio 2 folhas – Área: 4,1916m² | B7: 1 | C7: porta alumínio | D7: 4.1916 | G7: madeira | H7: =SUMIF(C:C,G7,B:B) -> 218
A8: 1 porta pivotante | B8: 1 | C8: pivotante | G8: pcf | H8: =SUMIF(C:C,G8,B:B) -> 60
A9: 19 portas de abrir madeira 1 folha | B9: 19 | C9: madeira | G9: pivotante | H9: =SUMIF(C:C,G9,B:B) -> 1
A10: 3 portas de abrir vidro 1 folha – Área: 2,1m² x 3 = 6,3m² | B10: 3 | C10: porta alumínio | D10: 6.3 | G10: porta alumínio | H10: =SUMIF(C:C,G10,D:D) -> 46.62
A11: 2 portas de abrir vidro 1 folha – Área: 1,89m² x 2 = 3,78m² | B11: 2 | C11: porta alumínio | D11: 3.78 | G11: portão | H11: =SUMIF(C:C,G11,B:B) -> 2
A12: 1 porta de abrir alumínio 1 folha – Área: 2,0076m² | B12: 1 | C12: porta alumínio | D12: 2.0076 | G12: gradil | H12: =SUMIF(C:C,G12,D:D) -> 113.88
A13: Janelas – Área: 3,75 + 4,875 + 2,5 + 1,1 + 1,2 + 5,5402 + 4,4874 = 23,4526m² | C13: janela | D13: 23.4526 | G13: Brise | H13: 109.3146
A14: Muro de vidro – Área: 7,0774 + 5,485 + 3,43 + 4,8138 = 20,8062m² | C14: Guarda alumínio | D14: 20.8062
A15: 8 portas corta-fogo 1 folha | B15: 8 | C15: pcf
A16: Janelas – Area: (1,1 + 1,2 + 28,7391) x 4 = 124,1564m² | C16: janela | D16: 124.1564
A17: 2 portas corta-fogo 1 folha | B17: 2 | C17: pcf
A18: 2 portas de abrir alumínio 1 folha – Área: 1,47m² x 2 = 2,94m² | B18: 2 | C18: porta alumínio | D18: 2.94
A19: 2 portas de abrir vidro 1 folha – Área: 1,89m² x 2 = 3,78m² | B19: 2 | C19: porta alumínio | D19: 3.78
A20: 5 portas de abrir madeira 1 folha | B20: 5 | C20: madeira
A21: 1 janela-porta de correr vidro – Área: 14,7348m² | B21: 1 | C21: janela | D21: 14.7348
A22: Janelas – Área: 1,2894 + 1,2894 + 23,46 + 1,854 + 5,562 + 5,562 + 1,854 + 1,854 + 1,1 + 1,2 = 45,0248m² | C22: janela | D22: 45.0248
A23: Guarda corpo vidro – Área: 7,5299 + 5,7955 + 6,5555 = 19,8809m² | C23: Guarda alumínio | D23: 19.8809
A24: 38 portas corta-fogo 1 folha | B24: 38 | C24: pcf
A25: 171 portas de abrir madeira 1 folha | B25: 171 | C25: madeira
A26: 19 porta de abrir alumínio 1 folha – Área: 1,26m² x 19 = 23,94m² | B26: 19 | C26: porta alumínio | D26: 23.94
A27: 19 janela-porta de correr vidro 5 folhas - Área: 25,4205m² x 19 = 482,9895m² | B27: 19 | C27: janela | D27: 482.9895
A28: 19 janela-porta de correr vidro 5 folhas - Área: 17,8284m² x 19 = 338,7396m² | B28: 19 | C28: janela | D28: 338.7396
A29: Janelas – Área: 1,1 + 1,1 + 1,2 + 1,92 + 0,36 + 2,781 + 2,781 + 1,854 + 1,854 + 5,562 + 5,562 + 1,854 = 27,928m² x 19 = 530,632m² | C29: janela | D29: 530.632
A30: Guarda corpo metálico – Área: 4,745m² x 19 = 90,155m² - Perímetro: 3,65m x 19 = 69,35m | C30: gradil | D30: 90.155
A31: Guarda corpo vidro – Área: 15,645m² x 19 = 297,255m² - Perímetro: 14,9m x 19 = 283,1m | C31: Guarda alumínio | D31: 297.255
A32: 2 portas corta-fogo 1 folha | B32: 2 | C32: pcf
A33: 2 portas de abrir madeira 1 folha | B33: 2 | C33: madeira
A34: 1 porta de abrir alumínio 1 folha – Área: 1,26m² | B34: 1 | C34: porta alumínio | D34: 1.26
A35: 1 janela-porta de correr vidro 3 folhas - Área: 15,21m² | B35: 1 | C35: janela | D35: 15.21
A36: 1 janela-porta de correr vidro 5 folhas - Área: 25,4205m² | B36: 1 | C36: janela | D36: 25.4205
A37: 1 janela-porta de correr vidro 5 folhas - Área: 17,8284m² | B37: 1 | C37: janela | D37: 17.8284
A38: Janelas – Área: 1,1 + 1,2 + 1,1 + 1,92 + 0,36 + 2,781 + 2,781 + 1,854 + 1,854 + 5,562 + 5,562 + 1,854 = 27,928m² | C38: janela | D38: 27.928
A39: Guarda corpo metálico – Área: 4,745m² - Perímetro: 3,65m | C39: gradil | D39: 4.745
A40: Guarda corpo vidro – Área: 15,645m² - Perímetro: 14,9m | C40: Guarda alumínio | D40: 15.645
A41: 2 portas corta-fogo 1 folha | B41: 2 | C41: pcf
...

Sheet Rev. Fachada
A2: ORÇAMENTO PARAMÉTRICO REVESTIMENTOS E ACABAMENTOS DE FACHADA
A7: Documento | B7: MTH_INC-RES Orçamento Paramétrico
A8: Cliente
A9: Obra | B9: Reserva | G9: UC | H9: 02 | I9: Status | J9: Concluído
A10: Data | B10: 44294 | G10: Revisão | H10: R00 | I10: Resp. | J10: Kelen
A12: REVESTIMENTOS ARGAMASSADOS
A14: Descrição | D14: Quantidade | F14: Parâmetro | H14: Referência | I14: Valor total
A15: Chapisco em Estrutura | D15: =F15*'Dados Gerais'!$E$15 -> 1302.4494 | E15: m² | F15: 0.187 | G15: m² / AC | H15: - | I15: =D15*5.04*1.5 -> 9846.5174
A16: Chapisco em Alvenaria | D16: =F16*'Dados Gerais'!$E$15 -> 5202.8326 | E16: m² | F16: 0.747 | G16: m² / AC | H16: - | I16: =D16*F16*1.5 -> 5829.7739
A17: Reboco | D17: =F17*'Dados Gerais'!$E$15 -> 6616.7215 | E17: m² | F17: 0.95 | G17: m² / AC | H17: - | I17: =D17*11.1565*1.1*1.45 -> 117742.03 | L17: =+D17*F17 -> 6285.8854
A18: TOTAL | I18: =SUM(I15:J17) -> 133418.32
A21: PINTURA
A23: Descrição | D23: Quantidade | F23: Parâmetro | H23: Referência | I23: Valor total
A24: Pastilha | D24: =D17 -> 6616.7215 | E24: m² | F24: 25 | G24: R$ / m² | H24: - | I24: =+D24*180 -> 1191009.9
A25: TOTAL | I25: =SUM(I24:J24) -> 1191009.9
A27: REVESTIMENTOS ESPECIAIS
A29: Descrição | D29: Quantidade | F29: Parâmetro | H29: Referência | I29: Valor total
A30: Detalhes | D30: 1 | E30: vb | F30: 200000 | H30: - | I30: =+F30 -> 200000
A31: ACM | D31: 94.35 | E31: m² | F31: 550 | H31: - | I31: =F31*D31 -> 51892.5
I32: =SUM(I30:J31) -> 251892.5
I34: =I32+I25+I18 -> 1576320.7
A37: 2.08 | B37: 6.2057 | C37: 6.207 | D37: 2.08
A38: 2.08 | B38: 6.2057 | C38: 6.2057 | D38: 2.08
A39: 2.08 | B39: 6.2057 | C39: 6.2057 | D39: 2.08
A40: 2.08 | B40: 6.2057
A41: 10.89
A42: =SUM(A37:A41) -> 19.21 | B42: =SUM(B37:B41) -> 24.8228 | C42: =SUM(A42:B42) -> 44.0328 | D42: =SUM(D37:D41) -> 6.24 | E42: =SUM(A42:D42) -> 94.3056

Sheet Cobertura
A2: ORÇAMENTO PARAMÉTRICO COBERTURA
A7: Documento | B7: MTH_INC-RES Orçamento Paramétrico
A8: Cliente
A9: Obra | B9: Reserva | G9: UC | H9: 02 | I9: Status | J9: Concluído
A10: Data | B10: 44294 | G10: Revisão | H10: R00 | I10: Resp. | J10: Kelen
A12: COBERTURA
A14: Descrição | D14: Quantidade | F14: Parâmetro | H14: Referência | I14: Valor total
A15: Cobertura | D15: =62.16+53.44 -> 115.6 | E15: m² | F15: 500 | G15: R$ / m² | H15: - | I15: =+F15*D15 -> 57800
A16: TOTAL | I16: =SUM(I15:J15) -> 57800
J19: =I16 -> 57800

Sheet Complementares
A2: ORÇAMENTO PARAMÉTRICO EQUIPAMENTOS
A7: Documento | B7: MTH_INC-RES Orçamento Paramétrico
A8: Cliente
A9: Obra | B9: Reserva | G9: UC | H9: 02 | I9: Status | J9: Concluído
A10: Data | B10: 44294 | G10: Revisão | H10: R00 | I10: Resp. | J10: Kelen
A12: SERVIÇOS COMPLEMENTARES
A14: Descrição | D14: Quantidade | F14: Parâmetro | H14: Referência | I14: Valor total
A15: Móveis e decoração | D15: 1 | E15: vb | F15: 2500 | G15: R$ / AL | H15: Média | I15: =D15*F15*'Dados Gerais'!$E$22 -> 367225
A16: Comunicação visual | D16: 1 | E16: vb | F16: 12 | G16: R$ / AC | H16: Média | I16: =D16*F16*'Dados Gerais'!$E$15 -> 83579.64
A17: Paisagismo | D17: 1 | E17: vb | F17: 15 | G17: R$ / AC | H17: Média | I17: =D17*F17*'Dados Gerais'!$E$15 -> 104474.55
A18: Limpeza | D18: 1 | E18: vb | F18: 10 | G18: R$ / AC | H18: Média | I18: =D18*F18*'Dados Gerais'!$E$15 -> 69649.7
A19: TOTAL | I19: =SUM(I15:J18) -> 624928.89
J22: =I19 -> 624928.89
