Workbook
Name \0: #REF!
Name \0: #REF!
Name \0: #REF!
Name \0: #REF!
Name \0: #REF!
Name \0: #REF!
Name \0: #REF!
Name \0: #REF!
Name \0: #REF!
Name \1: #REF!
Name \a: #REF!
Name \a: #REF!
Name \a: #REF!
Name \a: #REF!
Name \a: #REF!
Name \b: #REF!
Name \c: #REF!
Name \d: #REF!
Name \e: #REF!
Name \i: #REF!
Name \J: #REF!
Name \k: #REF!
Name \l: #N/A
Name \m: #REF!
Name \m: #REF!
Name \m: #REF!
Name \m: #REF!
Name \m: #REF!
Name \o: #REF!
Name \p: #REF!
Name \r: #REF!
Name \T: #REF!
Name \z: #REF!
Name ______ACR10: #REF!
Name ______ACR15: #REF!
Name ______acr20: #REF!
Name ______acr5: #REF!
Name ______ARQ1: #REF!
Name ______QT100: #REF!
Name ______QT2: #REF!
Name ______QT3: #REF!
Name ______QT4: #REF!
Name ______QT50: #REF!
Name ______QT75: #REF!
Name _____ACR10: #REF!
Name _____ACR15: #REF!
Name _____acr20: #REF!
Name _____acr5: #REF!
Name _____ARQ1: #REF!
Name _____QT100: #REF!
Name _____QT2: #REF!
Name _____QT3: #REF!
Name _____QT4: #REF!
Name _____QT50: #REF!
Name _____QT75: #REF!
Name ___ACR10: #REF!
Name ___ACR15: #REF!
Name ___acr20: #REF!
Name ___acr5: #REF!
Name ___ARQ1: #REF!

Sheet DADOS_INICIAIS
A1: Obra | B1: MONOLYT
A2: Empresa | B2: BLUE HEAVEN
A3: Revisão | B3: R00
A4: DADOS OBRA
A6: ARQUITETURA
B8: Descrição | C8: Identificador | D8: Unidade | E8: Quantidade | G8: Separar por torre
E9: TORRE B | F9: TORRE A
B10: ÁREA DO TERRENO | C10: AT | D10: M2 | E10: 7541.68
B11: ÁREA TOTAL CONSTRUÍDA | C11: AC | D11: M2 | E11: 14693.42
B12: NÚMERO TOTAL DE PAVIMENTOS | C12: NP | D12: UN | E12: 4 | F12: 4 | G12: Níveis diferentes
B13: NÚMERO DE PAVIMENTOS TIPO | C13: NPT | D13: UN | E13: 3 | F13: 3
B14: NÚMERO DE PAVIMENTOS DIFERENCIADOS | C14: NPD | D14: UN | E14: 1 | F14: 0
B15: ÁREA DE PROJEÇÃO DO PAV DIFERENCIADO | C15: APD | D15: M2 | E15: 774.97 | F15: 0
B16: NÚMERO DE PAVIMENTOS DUPLEX | C16: ND | D16: UN | E16: 1 | F16: 1
B17: ÁREA DE PROJEÇÃO DA TORRE | C17: APT | D17: M2 | E17: =1469.1-174.91 -> 1294.19 | F17: =1502.76-126.91 -> 1375.85
B18: PERÍMETRO DE PROJEÇÃO DA TORRE | C18: PPT | D18: M | E18: 209.46 | F18: 239.41
B19: ÁREA DE LAZER INTERNA | C19: ALI | D19: M2 | E19: 343.39
B20: ÁREA DE LAZER EXTERNA | C20: ALE | D20: M2 | E20: 2661.29
B21: ÁREA DE SUBSOLOS | C21: S | D21: M2 | E21: 1879.83 | F21: 2024.31 | G21: ESTACIONAMENTO
B22: NÚMERO DE SUBSOLOS | C22: NS | D22: UN | E22: 1 | F22: 1
B23: ÁREA DE PROJEÇÃO DO EMBASAMENTO | C23: APE | D23: M2 | E23: 1879.83 | F23: 2024.31
B24: PERÍMETRO DE PROJEÇÃO DE EMBAMENTO | C24: PE | D24: M | E24: 176.28 | F24: 215.72
B25: NÚMERO DE PAVIMENTOS DE EMBASAMENTO | C25: NE | D25: UN | E25: 1 | F25: 1
B26: NÚMERO DE APARTAMENTOS | D26: UN | E26: 24
K44: =12224.04-301.82 -> 11922.22 | L44: =12469.72-K44 -> 547.5
K48: =3188.34+1879.83 -> 5068.17

Sheet MOVIMENTAÇÃO_DE_TERRA
A2: MOVIMENTAÇÃO DE TERRA
A4: ESCAVAÇÃO VERTICAL DE SUBSOLO
A6: Descrição | B6: Área de subsolo (m2) | C6: Altura do subsolo (m) | D6: Volume total de escavação (m3) | E6: Preço unitário de escavação (R$ / m3) | F6: Valor total
A7: Escavação Torre A | B7: =(DADOS_INICIAIS!F21)*1.1 -> 2226.741 | C7: 5.1 | D7: =C7*B7 -> 11356.379 | E7: 60 | F7: =E7*D7*1.1 -> 749521.02 | G7: VIVA4
A8: Escavação Torre B | B8: =(DADOS_INICIAIS!E21)*1.1 -> 2067.813 | C8: 1 | D8: =C8*B8 -> 2067.813 | E8: 60 | F8: =E8*D8*1.1 -> 136475.66 | G8: VIVA4
A9: Reaterro | B9: =B8*0.2 -> 413.5626 | C9: 0.6 | D9: =C9*B9 -> 248.13756 | E9: 25 | F9: =E9*D9*1.1 -> 6823.7829 | G9: VIVA4
A10: Movimentação de bota-fora Torre A | B10: =B7 -> 2226.741 | C10: =C7 -> 5.1 | D10: =C10*B10*1.3 -> 14763.293 | E10: 35 | F10: =E10*D10*1.1 -> 568386.77
A11: Movimentação de bota-fora Torre B | B11: - | C11: - | D11: =((B8*C8)-(B9*C9))*1.3 -> 2365.5781 | E11: 35 | F11: =E11*D11*1.1 -> 91074.756
A12: TOTAL | F12: =SUM(F7:F11) -> 1552282
A14: REBAIXAMENTO DE LENÇOL FREÁTICO
A16: Descrição | B16: Quantidade (dias) | E16: Preço unitário de rebaixamento (R$ / dias) | F16: Valor total
A17: Rebaixamento provisório de lençol | B17: =6*30 -> 180 | E17: 200 | F17: =B17*E17*1.1 -> 39600
A18: TOTAL | F18: =SUM(F17:F17) -> 39600
A20: ESCAVAÇÃO E REATERRO DE VALAS
A22: Descrição | B22: Parâmetro | D22: Volume total de escavação (m3) | E22: Preço unitário (R$ / m3) | F22: Valor total
A23: Escavação mecanizada para blocos e baldrames | B23: 1.2 | C23: m³ / APE | D23: =B23*(DADOS_INICIAIS!E21+DADOS_INICIAIS!F21) -> 4684.968 | E23: 50 | F23: =E23*D23*1.1 -> 257673.24 | G23: VIVA4
A24: Reaterro para blocos e baldrames | B24: 0.6 | C24: m³ / Vol Escavação | D24: =B24*D23 -> 2810.9808 | E24: 25 | F24: =E24*D24*1.1 -> 77301.972 | G24: VIVA4
A25: Movimentação de bota-fora | B25: 1.4 | C25: m³ | D25: =(D23-D24)*B25 -> 2623.5821 | E25: 40 | F25: =E25*D25*1.1 -> 115437.61 | G25: Conforme solicitado em 18/07 via whatsapp: considerar 40% | M25: Estava 30 reais
A26: Movimentação de terra das estacas | B26: 1.4 | C26: m³ | D26: ='INFRAESTRUTURA REV01'!D15 -> 1275.7945 | E26: 40 | F26: =E26*D26*1.1 -> 56134.958 | G26: Conforme solicitado em 18/07 via whatsapp: considerar 40% | M26: Estava 30 reais
A27: TOTAL | F27: =SUM(F23:F26) -> 506547.78
A29: REGULARIZAÇÃO E APILOAMENTO DE FUNDO DE VALAS
A31: Descrição | B31: Parâmetro | D31: Área de lastro (m²) | E31: Preço unitário (R$ / m2) | F31: Valor total
A32: Lastro de concreto magro | B32: 0.4 | C32: m² / APE | D32: =B32*(DADOS_INICIAIS!F23+DADOS_INICIAIS!E23) -> 1561.656 | E32: =230+30 -> 260 | F32: =E32*D32*1.1 -> 446633.62
A33: TOTAL | F33: =SUM(F32:F32) -> 446633.62
A35: TOTAL MOVIMENTAÇÃO DE TERRA | F35: =F12+F18+F27+F33 -> 2545063.4 | G35: =F35/DADOS_INICIAIS!E11 -> 173.2111

Sheet TERRAPLENAGEM

Sheet CONTENÇÕES
A3: CONTENÇÃO
A5: CORTINA DE ESTACAS
A7: Descrição | B7: Parâmetro | D7: Quantidade | F7: Preço unitário | G7: Valor total
A8: Número de Estacas | B8: 0.15 | C8: un / APE | D8: =B8*DADOS_INICIAIS!F23 -> 303.6465 | E8: un
A9: Estaca Hélice Continua Diâmetro 40 | B9: 0.1 | D9: =B9*$D$8 -> 30.36465 | E9: un
B10: 20 | C10: m/un | D10: =B10*D9 -> 607.293 | E10: m | G10: =F10*D10 -> 0
A11: Estaca Hélice Continua Diâmetro 50 | B11: 0.5 | D11: =B11*$D$8 -> 151.82325 | E11: un
B12: 20 | C12: m/un | D12: =B12*D11 -> 3036.465 | E12: m | G12: =F12*D12 -> 0
A13: Estaca Hélice Continua Diâmetro 60 | B13: 0.4 | C13: un / APE | D13: =B13*$D$8 -> 121.4586 | E13: un
B14: 20 | C14: m/un | D14: =B14*D13 -> 2429.172 | E14: m | G14: =F14*D14 -> 0
A15: Concreto | B15: =(PI()*0.4^2)/4*D12+(PI()*0.5^2)/4*D14+(PI()*0.6^2)/4*D10 -> 1030.2483 | C15: un / APE | D15: =(PI()*0.4^2)/4*D12+(PI()*0.5^2)/4*D14+(PI()*0.6^2)/4*D10 -> 1030.2483 | E15: m³ | G15: =F15*D15 -> 0
A16: Armação 6,3mm | B16: 1.6575131 | C16: kg / m³ | D16: =B16*D15 -> 1707.6501 | E16: kg | G16: =F16*D16 -> 0
A17: Armação 16mm | B17: 10.178338 | C17: kg / m³ | D17: =B17*D15 -> 10486.215 | E17: kg | G17: =F17*D17 -> 0
A18: Mobilização | B18: 1 | C18: vb | D18: 1 | E18: vb | G18: =F18*D18 -> 0
A19: TOTAL | G19: =SUM(G8:G18) -> 0
A21: PAREDE DE CONCRETO
A23: Descrição | B23: Parâmetro | D23: Quantidade | F23: Preço unitário | G23: Valor total
A24: Área de Contenção | D24: 1163.48 | H24: quantitativo de modelo (ambos subsolos)
A25: Fabricação, montagem e desmontagem de forma - resinado | B25: 2 | C25: m² | D25: =B25*D24 -> 2326.96 | E25: m² | F25: =206.56+0.130939 -> 206.69094 | G25: =F25*D25*1.1 -> 529057.7
A26: Concreto | B26: 0.4 | C26: m | D26: =D24*B26 -> 465.392 | E26: m³ | F26: =(650+45)*1.05 -> 729.75 | G26: =F26*D26*1.1 -> 373581.79 | H26: Custo Viva 4
A27: Armação | B27: 100 | C27: kg / m³ | D27: =B27*D26 -> 46539.2 | E27: kg | F27: 8 | G27: =F27*D27*1.1 -> 409544.96 | H27: Custo Viva 4
A28: Estrutura - drenagem | D28: 343.28 | E28: m | F28: 260 | G28: =F28*D28 -> 89252.8
A29: Mão de obra | B29: - | D29: =D24 -> 1163.48 | E29: m² | F29: 190 | G29: =F29*D29*1.1 -> 243167.32
A30: TOTAL | G30: =SUM(G25:G29) -> 1644604.6
A33: TOTAL INFRAESTRUTURA | G33: =G19+G30 -> 1644604.6 | H33: =G33/DADOS_INICIAIS!E11 -> 111.92796
B36: ATALAIA | C36: MONOLYT
A37: Projeção embasamento | B37: 659.3 | C37: =DADOS_INICIAIS!E23+DADOS_INICIAIS!F23 -> 3904.14
A38: Perímetro contenção | B38: 80 | C38: 343
A39: Área forma | B39: 610.01 | C39: 2326.96
A40: Altura média | B40: =(B39/2)/B38 -> 3.8125625 | C40: =(C39/2)/C38 -> 3.39207
A41: AC | B41: 7374 | C41: 12469.72
A42: Índice | B42: =B39/B41 -> 0.082724437 | C42: =C39/C41 -> 0.18660884 | E42: =B40*B38*2 -> 610.01
A43: Custo total | B43: 386506.36 | C43: =G30 -> 1644604.6
A44: Custo / m | B44: =B43/B38 -> 4831.3295 | C44: =C43/C38 -> 4794.7655
A45: Custo / m² | B45: =B43/B39 -> 633.6066 | C45: =C43/C39 -> 706.761
A46: Custo / AC | B46: =B43/B41 -> 52.414749 | C46: =C43/C41 -> 131.88785

Sheet INFRAESTRUTURA REV01
A3: INFRAESTRUTURA
A5: FUNDAÇÃO PROFUNDA
A7: Descrição | B7: Parâmetro | D7: Quantidade | F7: Preço unitário | G7: Valor total
A8: Número de Estacas | B8: 0.15 | C8: un / APE | D8: =ROUNDUP(B8*(DADOS_INICIAIS!F23+DADOS_INICIAIS!E23),0) -> 586 | E8: un
A9: Estaca Hélice Continua Diâmetro 40 | B9: 0.1 | D9: =B9*$D$8 -> 58.6 | E9: un
B10: 14 | C10: m/un | D10: =B10*D9 -> 820.4 | E10: m | F10: 70 | G10: =F10*D10*1.1 -> 63170.8 | H10: Gran Torino
A11: Estaca Hélice Continua Diâmetro 50 | B11: 0.7 | D11: =B11*$D$8 -> 410.2 | E11: un
B12: 14 | C12: m/un | D12: =B12*D11 -> 5742.8 | E12: m | F12: 100 | G12: =F12*D12*1.1 -> 631708 | H12: Gran Torino
A13: Estaca Hélice Continua Diâmetro 60 | B13: 0.2 | C13: un / APE | D13: =B13*$D$8 -> 117.2 | E13: un
B14: 14 | C14: m/un | D14: =B14*D13 -> 1640.8 | E14: m | F14: 120 | G14: =F14*D14*1.1 -> 216585.6 | H14: Gran Torino
A15: Concreto | B15: =(PI()*0.4^2)/4*D12+(PI()*0.5^2)/4*D14+(PI()*0.6^2)/4*D10 -> 1275.7945 | C15: un / APE | D15: =(PI()*0.4^2)/4*D12+(PI()*0.5^2)/4*D14+(PI()*0.6^2)/4*D10 -> 1275.7945 | E15: m³ | F15: =(650+45)*1.3 -> 903.5 | G15: =F15*D15*1.1 -> 1267948.4 | H15: Considerado 30% de perda
A16: Armação 6,3mm | B16: 1.6575131 | C16: kg / m³ | D16: =B16*D15 -> 2114.6461 | E16: kg | F16: 8 | G16: =F16*D16*1.1 -> 18608.886
A17: Armação 16mm | B17: 10.178338 | C17: kg / m³ | D17: =B17*D15 -> 12985.467 | E17: kg | F17: 8.5 | G17: =F17*D17*1.1 -> 121414.12
A18: Mobilização e arrasamento de estacas | B18: 1 | C18: vb | D18: 1 | E18: vb | F18: =15000+(586*300) -> 190800 | G18: =F18*D18*1.1 -> 209880 | H18: Não considerado anteriormente
A19: TOTAL | G19: =SUM(G8:G18) -> 2529315.8
A21: BALDRAMES
A23: Descrição | B23: Parâmetro | D23: Quantidade | F23: Preço unitário | G23: Valor total
A24: Fabricação, montagem e desmontagem de forma para blocos e baldrames madeira serrada | B24: 0.76 | C24: m² / APE | D24: =B24*(DADOS_INICIAIS!F23+DADOS_INICIAIS!E23) -> 2967.1464 | E24: m² | F24: 72 | G24: =F24*D24*1.1 -> 234997.99 | H24: Índice ABC- Estaleiro | I24: Custo Malaga
A25: Armação | B25: 90 | C25: kg / m³ | D25: =B25*D26 -> 80815.698 | E25: kg | F25: 8 | G25: =F25*D25*1.1 -> 711178.14 | H25: Índice VIVA4
A26: Concreto 45MPa | B26: 0.23 | C26: m³ / APE | D26: =B26*(DADOS_INICIAIS!F23+DADOS_INICIAIS!E23) -> 897.9522 | E26: m³ | F26: =(650+45)*1.05 -> 729.75 | G26: =F26*D26*1.1 -> 720808.68 | H26: Índice VIVA4
A27: Mão de obra | B27: =SUPRAESTRUTURA!B22*1.5 -> 360 | C27: R$ / APE | D27: =(DADOS_INICIAIS!F23+DADOS_INICIAIS!E23) -> 3904.14 | E27: m² | F27: =B27 -> 360 | G27: =F27*D27*1.1 -> 1546039.4 | H27: *****
A28: TOTAL | G28: =SUM(G24:G27) -> 3213024.3
A31: TOTAL INFRAESTRUTURA | G31: =G19+G28 -> 5742340 | H31: =G31/DADOS_INICIAIS!E11 -> 390.81031
C34: LIVE - LUMIS (Sapatas) - NÃO FOI UTILIZADA NESSA INFRA
C35: Projeção | D35: =10345.89/4 -> 2586.4725
C36: Peso do aço +10 % (kg) | D36: 12387.1
C37: Volume de concreto (m³) | D37: 204.9
C38: Área de forma (m²) | D38: 213.6
C39: Consumo de aço (kg/m³) | D39: =D36/D37 -> 60.454368

Sheet SUPRAESTRUTURA
A3: SUPRAESTRUTURA
A5: SUPRAESTRUTURA
A6: * PARÂMETROS BASEADOS EM BRASIN - REDENTOR
A7: Descrição | B7: Parâmetro | D7: Quantidade | F7: Preço unitário | G7: Valor total | K7: 15974922
A8: Piso Armado | B8: =SUPRAESTRUTURA!B4*1.5 -> 0 | C8: R$ / APE | D8: =DADOS_INICIAIS!$F$23+DADOS_INICIAIS!$E$23 -> 3904.14 | E8: m² | F8: 228.24 | G8: =F8*D8*1.1 -> 980189 | K8: =G25-K7 -> 980468.45
A9: Fabricação forma | B9: 4 | C9: Reutilizações | D9: =D11/B9 -> 7714.0455 | E9: m² | F9: 115 | G9: =F9*D9*1.1 -> 975826.76 | H9: CUSTO DO PISO ARMADO DILUÍDO NA SUPRA
A10: Fabricação forma - paredes de concreto | B10: 2.1 | C10: Lados | D10: =(499.15+1024.44)*B10 -> 3199.539 | E10: m² | F10: 115 | G10: =F10*D10*1.1 -> 404741.68
A11: Montagem de forma | B11: 2.1 | C11: m² / AC | D11: =B11*DADOS_INICIAIS!E11 -> 30856.182 | E11: m² | F11: 4.75 | G11: =F11*D11*1.1 -> 161223.55 | J11: =D11/4 -> 7714.0455
A12: Montagem de forma - paredes de concreto | D12: =D10 -> 3199.539 | E12: m² | F12: 4.75 | G12: =F12*D12*1.1 -> 16717.591
A13: Escoramento - Torre | B13: 3 | C13: un / APT*NPT | D13: =B13*(DADOS_INICIAIS!E17*DADOS_INICIAIS!E13+DADOS_INICIAIS!F17*DADOS_INICIAIS!F13+816.228) -> 26479.044 | E13: un | F13: 19 | G13: =F13*D13*1.1 -> 553412.02
A14: Escoramento - Embasamento | B14: 3 | C14: un / AE | D14: =DADOS_INICIAIS!F21*B14 -> 6072.93 | E14: un | F14: 19 | G14: =F14*D14*1.1 -> 126924.24
A15: Escoramento - Paredes de concreto | B15: 5 | C15: un / m2 | D15: =B15*(499.15+1024.44) -> 7617.95 | E15: un | F15: 19 | G15: =F15*D15*1.1 -> 159215.16
A16: Protensão | B16: 16.78 | C16: kg / m³ | D16: =B16*D17 -> 61638.897 | E16: kg | F16: 35 | G16: =F16*D16*1.1 -> 2373097.5 | J16: =70506.16/2618.24 -> 26.928838 | K16: reais/AC Ingleses Spot
A17: Concreto 45MPa | B17: 0.25 | C17: m³ / AC | D17: =B17*DADOS_INICIAIS!E11 -> 3673.355 | E17: m³ | F17: =(650+45)*1.05 -> 729.75 | G17: =F17*D17*1.1 -> 2948693.9
A18: Concreto - paredes de concreto45MPa | D18: =499.15*0.14+1024.44*0.2 -> 274.769 | E18: m³ | F18: =(650*1.25+45)*1.05 -> 900.375 | G18: =F18*D18*1.05*1.1 -> 285741.38
A19: Armadura Convencional para Estrutura | B19: 112 | C19: kg / m³ | D19: =D17*$B$19 -> 411415.76 | E19: kg | F19: 8 | G19: =F19*D19*1.1 -> 3620458.7
A20: Armadura Convencional para paredes de concreto | B20: 112 | C20: kg / m³ | D20: =D18*$B$20 -> 30774.128 | E20: kg | F20: 8 | G20: =F20*D20*1.1 -> 270812.33
A21: Mão de obra - laje inclinada | D21: =(499.15+1024.44) -> 1523.59 | E21: m² | F21: 318 | G21: =F21*D21*1.1 -> 532951.78
A22: Mão de obra - estrutura em concreto armado | B22: 240 | C22: R$ / AC | D22: =DADOS_INICIAIS!E11 -> 14693.42 | E22: m² | F22: 280 | G22: =F22*D22*1.1 -> 4525573.4
A23: TOTAL | G23: =SUM(G9:G22) -> 16955390
A25: TOTAL SUPRAESTRUTURA | G25: =G23 -> 16955390 | H25: =G25/DADOS_INICIAIS!E11 -> 1153.9444

Sheet SUPRAESTRUTURA (2)
A3: SUPRAESTRUTURA
A5: SUPRAESTRUTURA
A6: * PARÂMETROS BASEADOS EM BRASIN - REDENTOR | E6: ÍNDICES OK, MAS FALTANDO PISO ARMADO!!!!
A7: Descrição | B7: Parâmetro | D7: Quantidade | F7: Preço unitário | G7: Valor total | K7: 16068422
A8: Fabricação forma | B8: 4 | C8: Reutilizações | D8: =D10/B8 -> 7714.0455 | E8: m² | F8: 85 | G8: =F8*D8*1.1 -> 721263.25
A9: Fabricação forma - paredes de concreto | B9: 2.1 | C9: Lados | D9: =(499.15+1024.44)*B9 -> 3199.539 | E9: m² | F9: 85 | G9: =F9*D9*1.1 -> 299156.9
A10: Montagem de forma | B10: 2.1 | C10: m² / AC | D10: =B10*DADOS_INICIAIS!E11 -> 30856.182 | E10: m² | F10: 4.75 | G10: =F10*D10*1.1 -> 161223.55 | H10: Custo M | J10: =D10/4 -> 7714.0455
A11: Montagem de forma - paredes de concreto | D11: =D9 -> 3199.539 | E11: m² | F11: 4.75 | G11: =F11*D11*1.1 -> 16717.591
A12: Escoramento - Torre | B12: 3 | C12: un / APT*NPT | D12: =B12*(DADOS_INICIAIS!E17*DADOS_INICIAIS!E13+DADOS_INICIAIS!F17*DADOS_INICIAIS!F13+816.228) -> 26479.044 | E12: un | F12: 17 | G12: =F12*D12*1.1 -> 495158.12
A13: Escoramento - Embasamento | B13: 3 | C13: un / AE | D13: =DADOS_INICIAIS!F21*B13 -> 6072.93 | E13: un | F13: 17 | G13: =F13*D13*1.1 -> 113563.79
A14: Escoramento - Paredes de concreto | B14: 5 | C14: un / m2 | D14: =B14*(499.15+1024.44) -> 7617.95 | E14: un | F14: 17 | G14: =F14*D14*1.1 -> 142455.67
A15: Protensão | B15: 16.78 | C15: kg / m³ | D15: =B15*D16 -> 61638.897 | E15: kg | F15: =(11.95+11.4)*1.1*1.1 -> 28.2535 | G15: =F15*D15*1.1 -> 1915666 | J15: =70506.16/2618.24 -> 26.928838 | K15: reais/AC Ingleses Spot
A16: Concreto 45MPa | B16: 0.25 | C16: m³ / AC | D16: =B16*DADOS_INICIAIS!E11 -> 3673.355 | E16: m³ | F16: =(650+45)*1.05 -> 729.75 | G16: =F16*D16*1.1 -> 2948693.9
A17: Concreto - paredes de concreto45MPa | D17: =499.15*0.14+1024.44*0.2 -> 274.769 | E17: m³ | F17: =(650*1.25+45)*1.05 -> 900.375 | G17: =F17*D17*1.05*1.1 -> 285741.38
A18: Armadura Convencional para Estrutura | B18: 110 | C18: kg / m³ | D18: =D16*$B$18 -> 404069.05 | E18: kg | F18: 8 | G18: =F18*D18*1.1 -> 3555807.6
A19: Armadura Convencional para paredes de concreto | B19: 110 | C19: kg / m³ | D19: =D17*$B$19 -> 30224.59 | E19: kg | F19: 8 | G19: =F19*D19*1.1 -> 265976.39
A20: Mão de obra - laje inclinada | D20: =(499.15+1024.44) -> 1523.59 | E20: m² | F20: =250*1.26 -> 315 | G20: =F20*D20*1.1 -> 527923.94
A21: Mão de obra - estrutura em concreto armado | B21: 240 | C21: R$ / AC | D21: =DADOS_INICIAIS!E11 -> 14693.42 | E21: m² | F21: 280 | G21: =F21*D21*1.1 -> 4525573.4 | H21: Antes R$240,00
A22: TOTAL | G22: =SUM(G8:G21) -> 15974922
A24: TOTAL SUPRAESTRUTURA | G24: =G22 -> 15974922 | H24: =G24/DADOS_INICIAIS!E11 -> 1087.216

Sheet Alvenaria
A2: ORÇAMENTO PARAMÉTRICO GERENCIAMENTO EXECUTIVO
A7: Cliente | B7: =DADOS_INICIAIS!B2 -> BLUE HEAVEN
A8: Obra | B8: =DADOS_INICIAIS!B1 -> MONOLYT
A9: Data | B9: 45443
A10: Revisão | B10: R00
A12: ALVENARIA
A14: Descrição | B14: Quantidade | D14: Parâmetro | F14: Referência | G14: Valor total
A15: Alvenaria | B15: =4992.75 -> 4992.75 | C15: m² | D15: 48 | E15: R$ / m² | F15: Média | G15: =+B15*D15*1.1 -> 263617.2
A16: Drywall | B16: =7551.67*1.05 -> 7929.2535 | C16: m² | D16: 220 | E16: R$ / m² | F16: Média | G16: =+B16*D16*1.1 -> 1918879.3
A17: Isolamento lã pet | B17: =B16 -> 7929.2535 | C17: m² | D17: 35 | E17: R$ / m² | F17: Média | G17: =+B17*D17*1.1 -> 305276.26
A18: Alvenaria escadas | B18: =D18*B15 -> 998.55 | C18: m² | D18: 0.2 | E18: m² / AC | F18: Média | G18: =+B18*180*1.1 -> 197712.9 | I18: =(B15+B16)/DADOS_INICIAIS!E11 -> 0.87944151
A19: Alvenaria refratárias | B19: =DADOS_INICIAIS!E26 -> 24 | C19: un | D19: 1.75 | E19: m² / un | F19: Média | G19: =+B19*320*1.1 -> 8448
A20: Serviços complementares | B20: =B15+B18 -> 5991.3 | C20: m² | D20: 25 | E20: R$ / m² | F20: Média | G20: =+B20*D20*1.1 -> 164760.75
A21: Mão de obra | B21: =B20 -> 5991.3 | C21: m² | D21: 44 | E21: R$ / m² | F21: Média | G21: =+B21*D21*1.1 -> 289978.92
A22: TOTAL | G22: =SUM(G15:G21) -> 3148673.4
A25: TOTAL ALVENARIA | G25: =G22 -> 3148673.4 | H25: =G25/DADOS_INICIAIS!E11 -> 214.29139
A27: Gran Torino mat+o
A28: Somauma | B28: 72,00 alvenaria
H34: TORRE A E B + EMBASAMENTO
H35: Alvenaria | I35: 4992.75 | J35: =I35/I37 -> 0.39800565
H36: Drywall | I36: 7551.67 | J36: =I36/I37 -> 0.60199435
I37: =SUM(I35:I36) -> 12544.42

Sheet REVESTIMENTO PISO
A1: Obra
A2: Empresa
A3: Revisão
A4: Data
A5: LEVANTAMENTO QUANTITATIVO
A7: REVESTIMENTOS E ACABAMENTOS DE PISO
B9: LEVANTAMENTO DE PROJETO | K9: CONTRAPISO
B10: Pavimento | C10: APT0 / A.C. | D10: Ambiente | E10: Material | F10: Área (m²) | G10: Contrapiso (Sim/Não) | H10: Repetição | I10: Total | K10: Revestimento | L10: Área total
B11: 1SS | C11: A.C. | D11: ÁREA TÉCNICA | E11: Pintura acrílica antiderrapante | F11: 456.33 | G11: Sim | H11: 1 | I11: =F11*H11 -> 456.33 | K11: Contrapiso | L11: =SUMIF(G:G,"Sim",I:I) -> 9592.09
B12: 1SS | C12: A.C. | D12: ÁREA PERMEÁVEL | F12: 26.38 | G12: Não | H12: 1 | I12: =F12*H12 -> 26.38 | K12: Manta acústica | L12: =SUMIFS(I:I,G:G,"Sim",C:C,"*APT*") -> 5559.67
B13: 1SS | C13: A.C. | D13: HALL | E13: Piso especial | F13: 33.58 | G13: Sim | H13: 1 | I13: =F13*H13 -> 33.58
B14: 1SS | C14: A.C. | D14: ESTACIONAMENTO | E14: Pintura piso epoxi | F14: 1500.84 | G14: Não | H14: 1 | I14: =F14*H14 -> 1500.84 | K14: ACABAMENTOS
B15: 1SS | C15: A.C. | D15: SALA DE ESPERA | E15: Piso especial | F15: 41.28 | G15: Sim | H15: 1 | I15: =F15*H15 -> 41.28 | K15: Material | L15: Área total
A16: =C16<>C14 -> TRUE | B16: TÉRREO | C16: APT01 - TB | D16: ESTAR | E16: Piso especial | F16: 24.87 | G16: Sim | H16: 1 | I16: =F16*H16 -> 24.87 | K16: Pintura acrílica antiderrapante | L16: =SUMIF(E:E,K16,I:I) -> 626.89
A17: =IF(C16="*&APTO&*","OK","") | B17: TÉRREO | C17: APT01 - TB | D17: JANTAR | E17: Piso especial | F17: 28.27 | G17: Sim | H17: 1 | I17: =F17*H17 -> 28.27 | K17: Porcelanato | L17: =SUMIF(E:E,K17,I:I) -> 0
B18: TÉRREO | C18: APT01 - TB | D18: LAVABO | E18: Piso especial | F18: 3.4 | G18: Sim | H18: 1 | I18: =F18*H18 -> 3.4 | K18: Pintura piso epoxi | L18: =SUMIF(E:E,K18,I:I) -> 2584.45
B19: TÉRREO | C19: APT01 - TB | D19: DECK | E19: Deck | F19: 27.53 | H19: 1 | I19: =F19*H19 -> 27.53 | K19: Deck | L19: =SUMIF(E:E,K19,I:I) -> 1341.17
B20: TÉRREO | C20: APT01 - TB | D20: PISCINA (PROF. 1,2m) | E20: Piscina | F20: 21.52 | H20: 1 | I20: =F20*H20 -> 21.52 | K20: Piscina | L20: =SUMIF(E:E,K20,I:I) -> 830.41
B21: TÉRREO | C21: APT01 - TB | D21: COZINHA | E21: Piso especial | F21: 15.72 | G21: Sim | H21: 1 | I21: =F21*H21 -> 15.72 | K21: Piso madeira engenheirada | L21: =SUMIF(E:E,K21,I:I) -> 2122.95
A22: Piso especial | B22: TÉRREO | C22: APT01 - TB | D22: A.S. | E22: Piso especial | F22: 7.6 | G22: Sim | H22: 1 | I22: =F22*H22 -> 7.6 | K22: Piso especial A.C. | L22: =SUMIF(E:E,K22,I:I) -> 0
B23: TÉRREO | C23: APT01 - TB | D23: BANHO SERV. | E23: Piso especial | F23: 4.22 | G23: Sim | H23: 1 | I23: =F23*H23 -> 4.22 | K23: Emborrachado | L23: =SUMIF(E:E,K23,I:I) -> 35.17
B24: TÉRREO | C24: APT01 - TB | D24: CIRC. | E24: Piso madeira engenheirada | F24: 12.36 | G24: Sim | H24: 1 | I24: =F24*H24 -> 12.36 | K24: Piso vinilico | L24: =SUMIF(E:E,K24,I:I) -> 77.76
B25: TÉRREO | C25: APT01 - TB | D25: SUÍTE MASTER | E25: Piso madeira engenheirada | F25: 27.24 | G25: Sim | H25: 1 | I25: =F25*H25 -> 27.24 | L25: =SUMIF(E:E,K25,I:I) -> 0
B26: TÉRREO | C26: APT01 - TB | D26: BANHO MASTER | E26: Piso especial | F26: 7.54 | G26: Sim | H26: 1 | I26: =F26*H26 -> 7.54 | L26: =SUMIF(E:E,K26,I:I) -> 0
B27: TÉRREO | C27: APT01 - TB | D27: SUÍTE 2 | E27: Piso madeira engenheirada | F27: 18.87 | G27: Sim | H27: 1 | I27: =F27*H27 -> 18.87 | L27: =SUMIF(E:E,K27,I:I) -> 0
B28: TÉRREO | C28: APT01 - TB | D28: BANHO 2 | E28: Piso especial | F28: 4.85 | G28: Sim | H28: 1 | I28: =F28*H28 -> 4.85 | L28: =SUMIF(E:E,K28,I:I) -> 0
B29: TÉRREO | C29: APT01 - TB | D29: SUÍTE 1 | E29: Piso madeira engenheirada | F29: 18.87 | G29: Sim | H29: 1 | I29: =F29*H29 -> 18.87 | L29: =SUMIF(E:E,K29,I:I) -> 0
B30: TÉRREO | C30: APT01 - TB | D30: BANHO 1 | E30: Piso especial | F30: 4.85 | G30: Sim | H30: 1 | I30: =F30*H30 -> 4.85 | L30: =SUMIF(E:E,K30,I:I) -> 0
B31: TÉRREO | C31: A.C. | D31: (ÁREA TÉCNICA) ESCADA EMERG. | E31: Pintura acrílica antiderrapante | F31: =18.79+1.5*0.18*20 -> 24.19 | G31: Sim | H31: 1 | I31: =F31*H31 -> 24.19 | L31: =SUMIF(E:E,K31,I:I) -> 0
B32: TÉRREO | C32: A.C. | D32: YOGA | E32: Piso especial | F32: 41.02 | G32: Sim | H32: 1 | I32: =F32*H32 -> 41.02 | L32: =SUMIF(E:E,K32,I:I) -> 0
B33: TÉRREO | C33: A.C. | D33: SALA DE ESPERA | E33: Piso especial | F33: 25.18 | G33: Sim | H33: 1 | I33: =F33*H33 -> 25.18 | L33: =SUMIF(E:E,K33,I:I) -> 0
B34: TÉRREO | C34: A.C. | D34: GOUMERT | E34: Piso especial | F34: 18.45 | G34: Sim | H34: 1 | I34: =F34*H34 -> 18.45 | L34: =SUMIF(E:E,K34,I:I) -> 0
B35: TÉRREO | C35: APT02 - TB | D35: ESTAR | E35: Piso especial | F35: 26.95 | G35: Sim | H35: 1 | I35: =F35*H35 -> 26.95 | L35: =SUMIF(E:E,K35,I:I) -> 0
B36: TÉRREO | C36: APT02 - TB | D36: JANTAR | E36: Piso especial | F36: 41.59 | G36: Sim | H36: 1 | I36: =F36*H36 -> 41.59
B37: TÉRREO | C37: APT02 - TB | D37: LAVABO | E37: Piso especial | F37: 3.67 | G37: Sim | H37: 1 | I37: =F37*H37 -> 3.67
B38: TÉRREO | C38: APT02 - TB | D38: DECK | E38: Deck | F38: 32.26 | H38: 1 | I38: =F38*H38 -> 32.26
B39: TÉRREO | C39: APT02 - TB | D39: PISCINA (PROF. 1,2m) | E39: Piscina | F39: 21.56 | G39: Sim | H39: 1 | I39: =F39*H39 -> 21.56
B40: TÉRREO | C40: APT02 - TB | D40: COZINHA | E40: Piso especial | F40: 15.02 | G40: Sim | H40: 1 | I40: =F40*H40 -> 15.02
B41: TÉRREO | C41: APT02 - TB | D41: DESPENSA | E41: Piso especial | F41: 3.12 | G41: Sim | H41: 1 | I41: =F41*H41 -> 3.12
B42: TÉRREO | C42: APT02 - TB | D42: A.S. | E42: Piso especial | F42: 9.49 | G42: Sim | H42: 1 | I42: =F42*H42 -> 9.49
...

Sheet REVESTIMENTO PAREDE PISCINA
A1: Obra
A2: Empresa
A3: Revisão
A4: Data
A5: LEVANTAMENTO QUANTITATIVO
A7: REVESTIMENTOS E ACABAMENTOS DE PAREDE
B9: LEVANTAMENTO DE PROJETO | L9: REBOCO
B10: Pavimento | C10: Apto / A.C. | D10: Ambiente | E10: Material | F10: Perímetro (m) | G10: Altura (m) | H10: Reboco (Sim/Não) | I10: Repetição | J10: Total | L10: Revestimento | M10: Área total
B11: 1SS | C11: A.C. | D11: ÁREA TÉCNICA | E11: Pintura acrílica antiderrapante | I11: 1 | J11: =G11*I11 -> 0
B12: 1SS | C12: A.C. | D12: ÁREA PERMEÁVEL | I12: 1 | J12: =G12*I12 -> 0
B13: 1SS | C13: A.C. | D13: HALL | E13: Porcelanato | I13: 1 | J13: =G13*I13 -> 0
B14: 1SS | C14: A.C. | D14: ESTACIONAMENTO | E14: Pintura piso epoxi | I14: 1 | J14: =G14*I14 -> 0 | L14: ACABAMENTOS
B15: TÉRREO | C15: APTO1 | D15: ESTAR | E15: Porcelanato | I15: 1 | J15: =G15*I15 -> 0 | L15: Material | M15: Área total
B16: TÉRREO | C16: APTO1 | D16: JANTAR | E16: Porcelanato | I16: 1 | J16: =G16*I16 -> 0 | L16: Pintura acrílica antiderrapante | M16: =SUMIF(E:E,L16,J:J) -> 0
B17: TÉRREO | C17: APTO1 | D17: LAVABO | E17: Porcelanato | I17: 1 | J17: =G17*I17 -> 0 | L17: Porcelanato | M17: =SUMIF(E:E,L17,J:J) -> 0
B18: TÉRREO | C18: APTO1 | D18: DECK | E18: Deck | I18: 1 | J18: =G18*I18 -> 0 | L18: Pintura piso epoxi | M18: =SUMIF(E:E,L18,J:J) -> 0
B19: TÉRREO | C19: APTO1 | D19: PISCINA (PROF. 1,2m) | E19: Piscina | F19: 13.69 | G19: 1.2 | H19: Sim | I19: 1 | J19: =F19*G19 -> 16.428 | L19: Deck | M19: =SUMIF(E:E,L19,J:J) -> 0
B20: TÉRREO | C20: APTO1 | D20: COZINHA | E20: Porcelanato | I20: 1 | J20: =G20*I20 -> 0 | L20: Piscina | M20: =SUMIF(E:E,L20,J:J) -> 677.348
B21: TÉRREO | C21: APTO1 | D21: A.S. | E21: Porcelanato | I21: 1 | J21: =G21*I21 -> 0 | L21: Piso madeira engenheirada | M21: =SUMIF(E:E,L21,J:J) -> 0
B22: TÉRREO | C22: APTO1 | D22: BANHO SERV. | E22: Porcelanato | I22: 1 | J22: =G22*I22 -> 0 | L22: Piso especial A.C. | M22: =SUMIF(E:E,L22,J:J) -> 0
B23: TÉRREO | C23: APTO1 | D23: CIRC. | E23: Porcelanato | I23: 1 | J23: =G23*I23 -> 0 | L23: Emborrachado | M23: =SUMIF(E:E,L23,J:J) -> 0
B24: TÉRREO | C24: APTO1 | D24: SUÍTE MASTER | E24: Piso madeira engenheirada | I24: 1 | J24: =G24*I24 -> 0 | L24: Piso vinilico | M24: =SUMIF(E:E,L24,J:J) -> 0
B25: TÉRREO | C25: APTO1 | D25: BANHO MASTER | E25: Porcelanato | I25: 1 | J25: =G25*I25 -> 0 | M25: =SUMIF(E:E,L25,J:J) -> 0
B26: TÉRREO | C26: APTO1 | D26: SUÍTE 2 | E26: Piso madeira engenheirada | I26: 1 | J26: =G26*I26 -> 0 | M26: =SUMIF(E:E,L26,J:J) -> 0
B27: TÉRREO | C27: APTO1 | D27: BANHO 2 | E27: Porcelanato | I27: 1 | J27: =G27*I27 -> 0 | M27: =SUMIF(E:E,L27,J:J) -> 0
B28: TÉRREO | C28: APTO1 | D28: SUÍTE 1 | E28: Piso madeira engenheirada | I28: 1 | J28: =G28*I28 -> 0 | M28: =SUMIF(E:E,L28,J:J) -> 0
B29: TÉRREO | C29: APTO1 | D29: BANHO 1 | E29: Porcelanato | I29: 1 | J29: =G29*I29 -> 0 | M29: =SUMIF(E:E,L29,J:J) -> 0
B30: TÉRREO | C30: A.C. | D30: (ÁREA TÉCNICA) ESCADA EMERG. | E30: Pintura acrílica antiderrapante | I30: 1 | J30: =G30*I30 -> 0 | M30: =SUMIF(E:E,L30,J:J) -> 0
B31: TÉRREO | C31: A.C. | D31: CIRCULAÇÃO | E31: Porcelanato | I31: 1 | J31: =G31*I31 -> 0 | M31: =SUMIF(E:E,L31,J:J) -> 0
B32: TÉRREO | C32: A.C. | D32: ÁREA COMUM DESCOBERTA | E32: Piso especial A.C. | I32: 1 | J32: =G32*I32 -> 0 | M32: =SUMIF(E:E,L32,J:J) -> 0
B33: TÉRREO | C33: APTO2 | D33: ESTAR | E33: Porcelanato | I33: 1 | J33: =G33*I33 -> 0 | M33: =SUMIF(E:E,L33,J:J) -> 0
B34: TÉRREO | C34: APTO2 | D34: JANTAR | E34: Porcelanato | I34: 1 | J34: =G34*I34 -> 0 | M34: =SUMIF(E:E,L34,J:J) -> 0
B35: TÉRREO | C35: APTO2 | D35: LAVABO | E35: Porcelanato | I35: 1 | J35: =G35*I35 -> 0 | M35: =SUMIF(E:E,L35,J:J) -> 0
B36: TÉRREO | C36: APTO2 | D36: DECK | E36: Deck | I36: 1 | J36: =G36*I36 -> 0
B37: TÉRREO | C37: APTO2 | D37: PISCINA (PROF. 1,2m) | E37: Piscina | F37: 13.72 | G37: 1.2 | H37: Sim | I37: 1 | J37: =F37*G37 -> 16.464
B38: TÉRREO | C38: APTO2 | D38: COZINHA | E38: Porcelanato | I38: 1 | J38: =G38*I38 -> 0
B39: TÉRREO | C39: APTO2 | D39: DESPENSA | E39: Porcelanato | I39: 1 | J39: =G39*I39 -> 0
B40: TÉRREO | C40: APTO2 | D40: A.S. | E40: Porcelanato | I40: 1 | J40: =G40*I40 -> 0
B41: TÉRREO | C41: APTO2 | D41: DORM. SERV. | E41: Porcelanato | I41: 1 | J41: =G41*I41 -> 0
B42: TÉRREO | C42: APTO2 | D42: BANHO SERV. | E42: Porcelanato | I42: 1 | J42: =G42*I42 -> 0
...

Sheet REVESTIMENTO TETO
A1: Obra
A2: Empresa
A3: Revisão
A4: Data
A5: LEVANTAMENTO QUANTITATIVO
A7: REVESTIMENTOS E ACABAMENTOS DE PISO
B9: LEVANTAMENTO DE PROJETO
B10: Pavimento | C10: Apto / A.C. | D10: Ambiente | E10: Material | F10: Área (m²) | G10: Forro (Sim/Não) | H10: Repetição | I10: Total
B11: 1SS | C11: A.C. | D11: ÁREA TÉCNICA | F11: 456.33 | H11: 1 | I11: =F11*H11 -> 456.33
B12: 1SS | C12: A.C. | D12: ÁREA PERMEÁVEL | F12: 26.38 | H12: 1 | I12: =F12*H12 -> 26.38
B13: 1SS | C13: A.C. | D13: HALL | F13: 33.58 | G13: Sim | H13: 1 | I13: =F13*H13 -> 33.58
B14: 1SS | C14: A.C. | D14: ESTACIONAMENTO | F14: 1500.84 | H14: 1 | I14: =F14*H14 -> 1500.84
B15: TÉRREO | C15: APTO1 | D15: ESTAR | F15: 24.87 | G15: Sim | H15: 1 | I15: =F15*H15 -> 24.87
B16: TÉRREO | C16: APTO1 | D16: JANTAR | F16: 28.27 | G16: Sim | H16: 1 | I16: =F16*H16 -> 28.27
B17: TÉRREO | C17: APTO1 | D17: LAVABO | F17: 3.4 | G17: Sim | H17: 1 | I17: =F17*H17 -> 3.4
B18: TÉRREO | C18: APTO1 | D18: DECK | F18: 27.53 | H18: 1 | I18: =F18*H18 -> 27.53
B19: TÉRREO | C19: APTO1 | D19: PISCINA (PROF. 1,2m) | F19: 21.52 | G19: Sim | H19: 1 | I19: =F19*H19 -> 21.52
B20: TÉRREO | C20: APTO1 | D20: COZINHA | F20: 15.72 | G20: Sim | H20: 1 | I20: =F20*H20 -> 15.72
B21: TÉRREO | C21: APTO1 | D21: A.S. | F21: 7.6 | G21: Sim | H21: 1 | I21: =F21*H21 -> 7.6
B22: TÉRREO | C22: APTO1 | D22: BANHO SERV. | F22: 4.22 | G22: Sim | H22: 1 | I22: =F22*H22 -> 4.22
B23: TÉRREO | C23: APTO1 | D23: CIRC. | F23: 12.36 | G23: Sim | H23: 1 | I23: =F23*H23 -> 12.36
B24: TÉRREO | C24: APTO1 | D24: SUÍTE MASTER | F24: 27.24 | G24: Sim | H24: 1 | I24: =F24*H24 -> 27.24
B25: TÉRREO | C25: APTO1 | D25: BANHO MASTER | F25: 7.54 | G25: Sim | H25: 1 | I25: =F25*H25 -> 7.54
B26: TÉRREO | C26: APTO1 | D26: SUÍTE 2 | F26: 18.87 | G26: Sim | H26: 1 | I26: =F26*H26 -> 18.87
B27: TÉRREO | C27: APTO1 | D27: BANHO 2 | F27: 4.85 | G27: Sim | H27: 1 | I27: =F27*H27 -> 4.85
B28: TÉRREO | C28: APTO1 | D28: SUÍTE 1 | F28: 18.87 | G28: Sim | H28: 1 | I28: =F28*H28 -> 18.87
B29: TÉRREO | C29: APTO1 | D29: BANHO 1 | F29: 4.85 | G29: Sim | H29: 1 | I29: =F29*H29 -> 4.85
B30: TÉRREO | C30: A.C. | D30: (ÁREA TÉCNICA) ESCADA EMERG. | F30: 18.79 | H30: 1 | I30: =F30*H30 -> 18.79
B31: TÉRREO | C31: APTO2 | D31: ESTAR | F31: 26.95 | G31: Sim | H31: 1 | I31: =F31*H31 -> 26.95
B32: TÉRREO | C32: APTO2 | D32: JANTAR | F32: 41.59 | G32: Sim | H32: 1 | I32: =F32*H32 -> 41.59
B33: TÉRREO | C33: APTO2 | D33: LAVABO | F33: 3.67 | G33: Sim | H33: 1 | I33: =F33*H33 -> 3.67
B34: TÉRREO | C34: APTO2 | D34: DECK | F34: 32.26 | H34: 1 | I34: =F34*H34 -> 32.26
B35: TÉRREO | C35: APTO2 | D35: PISCINA (PROF. 1,2m) | F35: 21.56 | G35: Sim | H35: 1 | I35: =F35*H35 -> 21.56
B36: TÉRREO | C36: APTO2 | D36: COZINHA | F36: 15.02 | G36: Sim | H36: 1 | I36: =F36*H36 -> 15.02
B37: TÉRREO | C37: APTO2 | D37: DESPENSA | F37: 3.12 | G37: Sim | H37: 1 | I37: =F37*H37 -> 3.12
B38: TÉRREO | C38: APTO2 | D38: A.S. | F38: 9.49 | G38: Sim | H38: 1 | I38: =F38*H38 -> 9.49
B39: TÉRREO | C39: APTO2 | D39: DORM. SERV. | F39: 6.96 | G39: Sim | H39: 1 | I39: =F39*H39 -> 6.96
B40: TÉRREO | C40: APTO2 | D40: BANHO SERV. | F40: 4.09 | G40: Sim | H40: 1 | I40: =F40*H40 -> 4.09
B41: TÉRREO | C41: APTO2 | D41: CIRC. | F41: 14.97 | G41: Sim | H41: 1 | I41: =F41*H41 -> 14.97
B42: TÉRREO | C42: APTO2 | D42: SUÍTE MASTER | F42: 28.46 | G42: Sim | H42: 1 | I42: =F42*H42 -> 28.46
...

Sheet Acabamentos de Piso
A2: ORÇAMENTO PARAMÉTRICO GERENCIAMENTO EXECUTIVO
A7: Cliente | B7: =DADOS_INICIAIS!B2 -> BLUE HEAVEN
A8: Obra | B8: =DADOS_INICIAIS!B1 -> MONOLYT
A9: Data | B9: 45441
A10: Revisão | B10: R00
A12: REVESTIMENTOS INTERNOS EM PISO
A14: Descrição | B14: Quantidade | D14: Parâmetro | F14: Referência | G14: Valor total
A15: Piso de concreto alisado | B15: ='Pintura Interna'!$B$15 -> 2584.45 | C15: m² | D15: 28 | E15: R$ / m² | F15: Média | G15: =D15*B15*1.1 -> 79601.06
A16: Piso de concreto alisado ranhurado | B16: ='Pintura Interna'!$B$16 -> 626.89 | C16: m² | D16: 30 | E16: R$ / m² | F16: Média | G16: =D16*B16*1.1 -> 20687.37
A17: Contrapiso | B17: ='REVESTIMENTO PISO'!L11 -> 9592.09 | C17: m² | D17: =B17/DADOS_INICIAIS!$E$11 -> 0.65281534 | E17: m² / AC | F17: Média | G17: =+B17*65*1.1 -> 685834.44
A18: Manta acústica + tela | B18: ='REVESTIMENTO PISO'!L12 -> 5559.67 | C18: m² | D18: =B18/DADOS_INICIAIS!$E$11 -> 0.37837821 | E18: m² / AC | F18: Média | G18: =+B18*25*1.1 -> 152890.93
A19: Piso Elevador | B19: =6*1.83*1.95 -> 21.411 | C19: m² | D19: 562.9458 | E19: m² / AC | F19: Média | G19: =+B19*D19*1.1*0 -> 0 | H19: Considerar no preliminar
A20: Porcelanato | B20: =SUMIF('REVESTIMENTO PISO'!E:E,'Acabamentos de Piso'!A20,'REVESTIMENTO PISO'!I:I) -> 0 | C20: m² | D20: 130 | E20: R$ / m² | F20: Média | G20: =+D20*B20*1.1 -> 0
A21: Piso vinilico | B21: =SUMIF('REVESTIMENTO PISO'!E:E,'Acabamentos de Piso'!A21,'REVESTIMENTO PISO'!I:I) -> 77.76 | C21: m² | D21: 250 | E21: R$ / m² | F21: Média | G21: =+D21*B21*1.1 -> 21384
A22: Piso madeira engenheirada | B22: =SUMIF('REVESTIMENTO PISO'!E:E,'Acabamentos de Piso'!A22,'REVESTIMENTO PISO'!I:I) -> 2122.95 | C22: m² | D22: =392.8+45 -> 437.8 | E22: R$ / m² | F22: Média | G22: =+D22*B22*1.1 -> 1022370.3
A23: Piso especial | B23: =SUMIF('REVESTIMENTO PISO'!E:E,'Acabamentos de Piso'!A23,'REVESTIMENTO PISO'!I:I) -> 965.36 | C23: m² | D23: 210 | E23: R$ / m² | F23: Média | G23: =+D23*B23*1.1 -> 222998.16 | H23: Pedra rústica em cacos
A24: Deck | B24: =SUMIF('REVESTIMENTO PISO'!E:E,'Acabamentos de Piso'!A24,'REVESTIMENTO PISO'!I:I) -> 1341.17 | C24: m² | D24: 300 | E24: R$ / m² | F24: Média | G24: =+D24*B24*1.1 -> 442586.1
A25: Piscina | B25: =SUMIF('REVESTIMENTO PISO'!E:E,'Acabamentos de Piso'!A25,'REVESTIMENTO PISO'!I:I) -> 830.41 | C25: m² | D25: =D23 -> 210 | E25: R$ / m² | F25: Média | G25: =+D25*B25*1.1 -> 191824.71 | H25: =H23 -> Pedra rústica em cacos
A26: Emborrachado | B26: =SUMIF('REVESTIMENTO PISO'!E:E,'Acabamentos de Piso'!A26,'REVESTIMENTO PISO'!I:I) -> 35.17 | C26: m² | D26: 230 | E26: R$ / m² | F26: Média | G26: =+D26*B26*1.1 -> 8898.01
A27: Paver fulget | B27: =SUMIF('REVESTIMENTO PISO'!E:E,'Acabamentos de Piso'!A27,'REVESTIMENTO PISO'!I:I) -> 171.49 | C27: m² | D27: 135 | E27: R$ / m² | F27: Média | G27: =+D27*B27*1.1 -> 25466.265 | H27: CALÇADA
A28: Rodapés Invertidos | B28: 1 | C28: vb | D28: =ROUNDUP(D49,0) -> 38 | E28: R$ / AC | F28: Média | G28: =D28*DADOS_INICIAIS!$E$11*1.1 -> 614184.96
A29: Soleiras e peitoris | B29: 1 | C29: vb | D29: 20 | E29: R$ / AC | F29: Média | G29: =D29*DADOS_INICIAIS!$E$11*1.1 -> 323255.24
G30: =SUM(G15:G29) -> 3811981.5
A33: TOTAL REVESTIMENTOS | G33: =SUM(G15:G18) -> 939013.79 | H33: =G33/DADOS_INICIAIS!$E$11 -> 63.907095
A34: TOTAL ACABAMENTOS | G34: =SUM(G20:G29) -> 2872967.7 | H34: =G34/DADOS_INICIAIS!$E$11 -> 195.5275 | I34: =G34+'Rev. Internos de Parede'!G24 -> 4311125.5
A35: TOTAL | G35: =G30 -> 3811981.5 | H35: =G35/DADOS_INICIAIS!$E$11 -> 259.4346
A40: ÍNDICE RODAPÉ INVERTIDO - BRAVA (CN)
D47: =1560.11+160.54+518.7871 -> 2239.4371
D48: =(224.88+487.65+266.03+43.04)*82.84 -> 84629.344
D49: =D48/D47 -> 37.790454 | E49: =D49*DADOS_INICIAIS!E11 -> 555271.01

Sheet Rev. Internos de Parede
A2: ORÇAMENTO PARAMÉTRICO GERENCIAMENTO EXECUTIVO
O5: =(Alvenaria!B15+Alvenaria!B16)*2 -> 25844.007
O6: =B16+B17+FACHADA!I11+FACHADA!I12+FACHADA!I13 -> 31215.194
A7: Cliente | B7: =DADOS_INICIAIS!B2 -> BLUE HEAVEN
A8: Obra | B8: =DADOS_INICIAIS!B1 -> MONOLYT
A9: Data
A10: Revisão | B10: R00
A12: REVESTIMENTOS INTERNOS EM PAREDE
A14: Descrição | B14: Quantidade | D14: Parâmetro | F14: Referência | G14: Valor total
A15: Chapisco | B15: =DADOS_INICIAIS!E11*'Rev. Internos de Parede'!D15 -> 12280.935 | C15: m² | D15: =2.1*Alvenaria!$J$35 -> 0.83581186 | E15: m² / AC | F15: Média | G15: =+B15*5*1.1 -> 67545.141 | H15: Paredes internas drywall
A16: Reboco | B16: =DADOS_INICIAIS!E11*'Rev. Internos de Parede'!D16 -> 12280.935 | C16: m² | D16: =2.1*Alvenaria!$J$35 -> 0.83581186 | E16: m² / AC | F16: Média | G16: =50*B16*1.1 -> 675451.41 | H16: Paredes internas drywall
A17: Estucamento | B17: =DADOS_INICIAIS!E21+DADOS_INICIAIS!F21 -> 3904.14 | C17: APE | D17: =542.84/772 -> 0.70316062 | E17: m² / m² | F17: Média | G17: =B17*D17*24*1.1 -> 72474.27
A18: Piscina | B18: =SUMIF('REVESTIMENTO PAREDE PISCINA'!E:E,A18,'REVESTIMENTO PAREDE PISCINA'!J:J) -> 677.348 | C18: m² | D18: 210 | E18: R$ / m² | F18: Média | G18: =+D18*B18*1.1 -> 156467.39 | H18: Pedra rústica em cacos
A19: Revestimentos de Parede | B19: 1 | C19: vb | D19: =D43 -> 79.298972 | E19: R$ / AC | F19: Média | G19: =D19*DADOS_INICIAIS!$E$11*1.1 -> 1281690.4
A20: TOTAL | G20: =SUM(G15:G19) -> 2253628.6
A23: TOTAL REVESTIMENTOS | G23: =SUM(G15:G17) -> 815470.82 | H23: =G23/DADOS_INICIAIS!$E$11 -> 55.499048
A24: TOTAL ACABAMENTOS | G24: =SUM(G18:G19) -> 1438157.8 | H24: =G24/DADOS_INICIAIS!$E$11 -> 97.877676
A25: TOTAL | G25: =G20 -> 2253628.6 | H25: =G25/DADOS_INICIAIS!E11 -> 153.37672
B30: LIVE - LUMIS | J30: LIVE - LUMIS (MUDANDO CUSTO REVESTIMENTO P/ PORCELANATO)
B31: Quant. | C31: Valor total | J31: Quant. | L31: Valor total
A32: Revest | B32: =3856.77 -> 3856.77 | C32: 216873.88 | E32: MO CHAPISCO/REBOCO JUNTO | I32: Revest | J32: =3856.77 -> 3856.77 | K32: 175 | L32: =J32*K32 -> 674934.75
A33: Revest | B33: 28.9 | C33: 440.95 | E33: =280859.09+2140564.22-437026.95-(31147.02*40) -> 738515.56 | I33: Revest | J33: 28.9 | K33: 175 | L33: =J33*K33 -> 5057.5
A34: Revest | B34: 49 | C34: 32181 | E34: 14888.46 | F34: AC | I34: Revest | J34: 49 | K34: 559.25 | L34: =J34*K34 -> 27403.25
A35: Revest | B35: =SUM(B32:B34) -> 3934.67 | C35: 327403.25 | E35: =E33/E34 -> 49.60322 | G35: 228 | I35: Revest | J35: =SUM(J32:J34) -> 3934.67 | L35: 327403.25
A36: Revest | C36: =2410564.22-(31147.02*50) -> 853213.22 | I36: Revest | L36: =2410564.22-(31147.02*50) -> 853213.22
A37: MO Revest | B37: =SUM(B32:B36) -> 7869.34 | C37: =SUM(C32:C36) -> 1430112.3 | I37: MO Revest | J37: =SUM(J32:J36) -> 7869.34 | L37: =SUM(L32:L36) -> 1888012
A38: Banheiros | B38: 175 | C38: 175 | I38: Banheiros | J38: 175 | L38: 175
B39: =B37/B38 -> 44.967657 | C39: =C37/C38 -> 8172.0703 | J39: =J37/J38 -> 44.967657 | L39: =L37/L38 -> 10788.64
B42: 108 | C42: 108
B43: =B42*B39 -> 4856.507 | C43: =C42*L39 -> 1165173.1 | D43: =C43/DADOS_INICIAIS!E11 -> 79.298972

Sheet Acabamentos de Teto
A2: ORÇAMENTO PARAMÉTRICO GERENCIAMENTO EXECUTIVO
A7: Cliente | B7: =DADOS_INICIAIS!B2 -> BLUE HEAVEN
A8: Obra | B8: =DADOS_INICIAIS!B1 -> MONOLYT
A9: Data
A10: Revisão | B10: R00
A12: ACABAMENTOS DE TETO
A14: Descrição | B14: Quantidade | D14: Parâmetro | F14: Referência | G14: Valor total
A15: Forro de gesso acartonado | B15: =D15*DADOS_INICIAIS!$E$11 -> 8816.052 | C15: m² | D15: 0.6 | E15: m² / AC | F15: Média | G15: =+B15*140*1.1 -> 1357672 | H15: Alterado índice COTAÇÃO SOMAUMA CONSIDERANDO A MAIS... SANCA E CHAPA RU
A16: Negativo | B16: =B15*1.2 -> 10579.262 | C16: m | D16: =B16/DADOS_INICIAIS!E11 -> 0.72 | E16: m / AC | F16: Média | G16: =+B16*25*1.1 -> 290929.72
A17: Estucamento | B17: =D17*DADOS_INICIAIS!$E$11 -> 4408.026 | C17: m² | D17: 0.3 | E17: m² / AC | F17: Média | G17: =B17*24*1.1 -> 116371.89 | H17: Não estava considerando garagem - Confirmar se devemos considerar
A18: TOTAL | G18: =SUM(G15:G17) -> 1764973.6
A21: TOTAL TETO | G21: =G18 -> 1764973.6 | H21: =G21/DADOS_INICIAIS!E11 -> 120.12

Sheet Ambientes
A1: Obra
A2: Empresa
A3: Revisão
A4: Data
A5: LEVANTAMENTO QUANTITATIVO
A7: AMBIENTES
B9: LEVANTAMENTO DE PROJETO | I9: Ar cond.
B10: Pavimento | C10: Apto / A.C. | D10: Ambiente | E10: Infra Ar Cond. | F10: Aparelho Ar cond. | G10: Enclausurado | I10: Descrição | J10: Quant. total
B11: 1SS | C11: A.C. | D11: ÁREA TÉCNICA | I11: Infra | J11: =COUNTIF(E:E,"Sim") -> 132
B12: 1SS | C12: A.C. | D12: ÁREA PERMEÁVEL | I12: Aparelho | J12: =COUNTIF(F:F,"Sim") -> 12
B13: 1SS | C13: A.C. | D13: HALL
B14: 1SS | C14: A.C. | D14: ESTACIONAMENTO
B15: TÉRREO | C15: APTO1 | D15: ESTAR | E15: Sim | I15: Material | J15: Área total
A16: =IF(C15="*&APTO&*","OK","") | B16: TÉRREO | C16: APTO1 | D16: JANTAR | J16: =SUMIF(E:E,I16,G:G) -> 0
B17: TÉRREO | C17: APTO1 | D17: LAVABO | G17: Sim | J17: =SUMIF(E:E,I17,G:G) -> 0
B18: TÉRREO | C18: APTO1 | D18: DECK | J18: =SUMIF(E:E,I18,G:G) -> 0
B19: TÉRREO | C19: APTO1 | D19: PISCINA (PROF. 1,2m) | J19: =SUMIF(E:E,I19,G:G) -> 0
B20: TÉRREO | C20: APTO1 | D20: COZINHA | J20: =SUMIF(E:E,I20,G:G) -> 0
B21: TÉRREO | C21: APTO1 | D21: A.S. | J21: =SUMIF(E:E,I21,G:G) -> 0
B22: TÉRREO | C22: APTO1 | D22: BANHO SERV. | G22: Sim | J22: =SUMIF(E:E,I22,G:G) -> 0
B23: TÉRREO | C23: APTO1 | D23: CIRC. | J23: =SUMIF(E:E,I23,G:G) -> 0
B24: TÉRREO | C24: APTO1 | D24: SUÍTE MASTER | E24: Sim | J24: =SUMIF(E:E,I24,G:G) -> 0
B25: TÉRREO | C25: APTO1 | D25: BANHO MASTER | G25: Sim | J25: =SUMIF(E:E,I25,G:G) -> 0
B26: TÉRREO | C26: APTO1 | D26: SUÍTE 2 | E26: Sim | J26: =SUMIF(E:E,I26,G:G) -> 0
B27: TÉRREO | C27: APTO1 | D27: BANHO 2 | G27: Sim | J27: =SUMIF(E:E,I27,G:G) -> 0
B28: TÉRREO | C28: APTO1 | D28: SUÍTE 1 | E28: Sim | J28: =SUMIF(E:E,I28,G:G) -> 0
B29: TÉRREO | C29: APTO1 | D29: BANHO 1 | G29: Sim | J29: =SUMIF(E:E,I29,G:G) -> 0
B30: TÉRREO | C30: A.C. | D30: (ÁREA TÉCNICA) ESCADA EMERG. | J30: =SUMIF(E:E,I30,G:G) -> 0
B31: TÉRREO | C31: APTO2 | D31: ESTAR | E31: Sim | J31: =SUMIF(E:E,I31,G:G) -> 0
B32: TÉRREO | C32: APTO2 | D32: JANTAR | J32: =SUMIF(E:E,I32,G:G) -> 0
B33: TÉRREO | C33: APTO2 | D33: LAVABO | G33: Sim | J33: =SUMIF(E:E,I33,G:G) -> 0
B34: TÉRREO | C34: APTO2 | D34: DECK
B35: TÉRREO | C35: APTO2 | D35: PISCINA (PROF. 1,2m)
B36: TÉRREO | C36: APTO2 | D36: COZINHA
B37: TÉRREO | C37: APTO2 | D37: DESPENSA
B38: TÉRREO | C38: APTO2 | D38: A.S.
B39: TÉRREO | C39: APTO2 | D39: DORM. SERV. | E39: Sim
B40: TÉRREO | C40: APTO2 | D40: BANHO SERV. | G40: Sim
B41: TÉRREO | C41: APTO2 | D41: CIRC.
B42: TÉRREO | C42: APTO2 | D42: SUÍTE MASTER | E42: Sim
...

Sheet Pintura Interna
A2: ORÇAMENTO PARAMÉTRICO GERENCIAMENTO EXECUTIVO
A7: Cliente | B7: =DADOS_INICIAIS!B2 -> BLUE HEAVEN
A8: Obra | B8: =DADOS_INICIAIS!B1 -> MONOLYT
A9: Data | B9: 45441
A10: Revisão | B10: R00
A12: PINTURA INTERNA
A14: Descrição | B14: Quantidade | D14: Parâmetro | F14: Referência | G14: Valor total
A15: Pintura piso epoxi | B15: =SUMIF('REVESTIMENTO PISO'!E:E,'Pintura Interna'!A15,'REVESTIMENTO PISO'!I:I) -> 2584.45 | C15: m2 | D15: 110 | E15: R$ / m² | F15: Média | G15: =+D15*B15*1.1 -> 312718.45
A16: Pintura acrílica antiderrapante | B16: =SUMIF('REVESTIMENTO PISO'!E:E,'Pintura Interna'!A16,'REVESTIMENTO PISO'!I:I) -> 626.89 | C16: m2 | D16: 65 | E16: R$ / m² | F16: Média | G16: =+D16*B16*1.1 -> 44822.635
A17: Textura escadas | B17: 1 | C17: vb | D17: 30 | E17: R$ / AC | F17: Média | G17: =+D17*DADOS_INICIAIS!$E$11*1.1 -> 484882.86
A18: Pintura Interna | B18: 1 | C18: vb | D18: 90 | E18: R$ / AC | F18: Média | G18: =+D18*DADOS_INICIAIS!$E$11*1.1 -> 1454648.6
A19: TOTAL | G19: =SUM(G15:G18) -> 2297072.5
A21: TOTAL PINTURA | G21: =G19 -> 2297072.5 | H21: =G21/DADOS_INICIAIS!E11 -> 156.33341

Sheet Impermeabilização
A2: ORÇAMENTO PARAMÉTRICO GERENCIAMENTO EXECUTIVO
A7: Cliente | B7: =DADOS_INICIAIS!B2 -> BLUE HEAVEN
A8: Obra | B8: =DADOS_INICIAIS!B1 -> MONOLYT
A9: Data
A10: Revisão | B10: R00
A12: IMPERMEABILIZAÇÃO
A14: Descrição | B14: Quantidade | D14: Parâmetro | F14: Referência | G14: Valor total
A15: Regularização de Superfície | B15: =B19+B20 -> 11020.065 | C15: m² | D15: 25 | E15: R$ / m² | F15: Média | G15: =+B15*D15*1.1 -> 303051.79
A16: Poço do elevador | B16: =((1.83*1.95)+((1.83+1.95)*2*1.8))*6 -> 103.059 | C16: m² | D16: 45 | E16: R$ / m² | F16: Média | G16: =+B16*D16*1.1 -> 5101.4205 | H16: Estava 32,94m²
A17: Baldrames | B17: ='INFRAESTRUTURA REV01'!D24 -> 2967.1464 | C17: m² | D17: 30 | E17: R$ / m² | F17: Média | G17: =+B17*D17*1.1 -> 97915.831
A18: Ralos | B18: 1 | C18: vb | D18: 0.4 | E18: R$ / AC | F18: Média | G18: =D18*DADOS_INICIAIS!E11*1.1 -> 6465.1048
A19: Impermeabilizações cimenticias | B19: =D19*DADOS_INICIAIS!$E$11 -> 5877.368 | C19: m² | D19: 0.4 | E19: m² / AC | F19: Média | G19: =+B19*60*1.1 -> 387906.29
A20: Impermeabilizações com aditivo cristalizante | B20: =D20*DADOS_INICIAIS!$E$11 -> 5142.697 | C20: m² | D20: 0.35 | E20: m² / AC | F20: Média | G20: =+B20*28*1.1 -> 158395.07
A21: Impermeabilizações com aditivo cristalizante (telhado verde) | B21: =DADOS_INICIAIS!E20 -> 2661.29 | C21: m² | D21: 28 | E21: R$ / m² | F21: Média | G21: =+B21*D21*1.1 -> 81967.732 | H21: áreas laje descobertas - verdes
A22: Impermeabilizações com aditivo cristalizante (piscinas) | B22: ='Acabamentos de Piso'!B25+'Rev. Internos de Parede'!B18+Complementares!D11 -> 1559.758 | C22: m² | D22: 28 | E22: R$ / m² | F22: Média | G22: =+B22*D22*1.1 -> 48040.546 | H22: SOMAUMA (Argamassa com aditivo cristalizante)
A23: Impermeabilização de peitoril | B23: 1 | C23: vb | D23: 0.8 | E23: R$ / AC | F23: Média | G23: =+D23*DADOS_INICIAIS!E11*1.1 -> 12930.21
A24: Proteção Mecânica | B24: =B20 -> 5142.697 | C24: m² | D24: 28 | E24: R$ / m² | F24: Média | G24: =D24*B24*1.1 -> 158395.07
A25: TOTAL | G25: =SUM(G15:G24) -> 1260169.1
A28: TOTAL IMPERMEABILIZAÇÃO | G28: =G25 -> 1260169.1 | H28: =G28/DADOS_INICIAIS!E11 -> 85.764176

Sheet Instalações
A2: INSTALAÇÕES
A4: INSTALAÇÕES ELÉTRICAS
A6: Descrição | B6: Parâmetro | D6: Valor total
A7: Entrada de Energia | B7: 5 | C7: R$ / AC | D7: =B7*DADOS_INICIAIS!$E$11*1.1 -> 80813.81
A8: Eletrodutos e Eletrocalhas | B8: 23 | C8: R$ / AC | D8: =B8*DADOS_INICIAIS!$E$11*1.1 -> 371743.53
A9: Cabos e Fiações | B9: 40 | C9: R$ / AC | D9: =B9*DADOS_INICIAIS!$E$11*1.1 -> 646510.48
A10: Quadros e Disjuntores | B10: 25 | C10: R$ / AC | D10: =B10*DADOS_INICIAIS!$E$11*1.1 -> 404069.05
A11: Acabamentos Elétricos | B11: 30 | C11: R$ / AC | D11: =B11*DADOS_INICIAIS!$E$11*1.1 -> 484882.86
A12: Equipamentos e Iluminação | B12: 20 | C12: R$ / AC | D12: =B12*DADOS_INICIAIS!$E$11*1.1 -> 323255.24
A13: Mão de Obra para Instalações Elétricas | B13: 60 | C13: R$ / AC | D13: =B13*DADOS_INICIAIS!$E$11*1.1 -> 969765.72
A14: TOTAL | D14: =SUM(D7:D13) -> 3281040.7
A16: INSTALAÇÕES HIDROSSANITÁRIAS
A18: Descrição | B18: Parâmetro | D18: Valor total
A19: Instalações de Água Fria | B19: 25 | C19: R$ / AC | D19: =B19*DADOS_INICIAIS!$E$11*1.1 -> 404069.05
A20: Instalações de Água Quente | B20: 20 | C20: R$ / AC | D20: =B20*DADOS_INICIAIS!$E$11*1.1 -> 323255.24
A21: Instalações de Águas Pluviais | B21: 10 | C21: R$ / AC | D21: =B21*DADOS_INICIAIS!$E$11*1.1 -> 161627.62
A22: Instalações Sanitárias | B22: 15 | C22: R$ / AC | D22: =B22*DADOS_INICIAIS!$E$11*1.1 -> 242441.43
A23: Louças e Metais | B23: 15 | C23: R$ / AC | D23: =B23*DADOS_INICIAIS!$E$11*1.1 -> 242441.43
A24: Mão de Obra para Instalações Hidráulicas | B24: 55 | C24: R$ / AC | D24: =B24*DADOS_INICIAIS!$E$11*1.1 -> 888951.91
A25: TOTAL | D25: =SUM(D19:D24) -> 2262786.7
A27: INSTALAÇÕES PREVENTIVAS E GLP
A29: Descrição | B29: Parâmetro | D29: Valor total
A30: Instalações Preventivas | B30: 18 | C30: R$ / AC | D30: =B30*DADOS_INICIAIS!$E$11*1.1 -> 290929.72
A31: Instalações de GLP | B31: 15 | C31: R$ / AC | D31: =B31*DADOS_INICIAIS!$E$11*1.1 -> 242441.43
A32: Instalações de Proteção e Aterramento - SPDA | B32: 8 | C32: R$ / AC | D32: =B32*DADOS_INICIAIS!$E$11*1.1 -> 129302.1
A33: TOTAL | D33: =SUM(D30:D32) -> 662673.24
A35: TOTAL INSTALAÇÕES | D35: =D14+D25+D33 -> 6206500.6 | E35: =D35/DADOS_INICIAIS!$E$11 -> 422.4

Sheet Instalações Lumis
A1: Obra | B1: LIVE
A2: Empresa | B2: LUMIS
A3: Revisão | B3: R00
A4: ESTIMATIVA DE CUSTOS
A6: Instalações
A8: Área total
D10: Descrição | E10: Térreo
D11: Área (m²) | E11: 14790.93
A13: Sistemas e instalações elétricas
B15: R$/m² | D15: Descrição | E15: Total
B16: 25 | D16: Quadros elétricos e disjuntores | E16: =E$11*$B$16 -> 369773.25
B17: 23 | D17: Eletrodutos e Eletrocalhas | E17: =E11*$B$17 -> 340191.39
B18: 40 | D18: Fios e cabos elétricos | E18: =E11*$B$18 -> 591637.2
B19: 30 | D19: Pontos de tomadas e interruptores | E19: =E11*$B$19 -> 443727.9
B20: 20 | D20: Luminárias, lâmpadas e acessórios | E20: =E11*$B$20 -> 295818.6
D21: total | E21: =SUM(E16:E20) -> 2041148.3
A22: Sistemas e instalações hidrossanitárias e drenagem
B24: MÉDIA/M2 | D24: Descrição | E24: Total
B25: 25 | D25: Instalações de água fria | E25: =E11*$B$25 -> 369773.25
B26: 20 | D26: Instalações de água quente | E26: =E11*$B$26 -> 295818.6
B27: 42.5 | D27: Louças e metais | E27: =$B$27*E11 -> 628614.53
B28: 10 | D28: Instalações de água pluvial | E28: =E11*$B$28 -> 147909.3
B29: 15 | D29: Instalações de esgoto | E29: =E11*$B$29 -> 221863.95
E30: =SUM(E25:E29) -> 1663979.6
A31: Instalações preventivas e GLP
B33: MÉDIA/M2 | D33: Descrição | E33: Total
B34: 10 | D34: Instalações de gás | E34: =$B$34*E11 -> 147909.3
B35: 18 | D35: Instalações do sistema preventivo de Incêndio | E35: =$B$35*E11 -> 266236.74
B36: 8 | D36: Instalações de proteção e Aterramento - SPDA | E36: =$B$36*E11 -> 118327.44
E37: =SUM(E34:E36) -> 532473.48
A38: Mão de Obra
D40: Descrição | E40: Mão de Obra (R$/m²)
D41: Sistemas e instalações elétricas | E41: 55
D42: Sistemas e instalações hidrossanitárias e drenagem | E42: 50
D43: Instalações de gás | E43: 3
D44: Instalações do sistema preventivo de Incêndio | E44: 8
D45: Instalações de proteção e Aterramento - SPDA | E45: 3
A47: Entrada de Energia
C49: MÉDIA/M2 | D49: Ítem | E49: Valor
C50: 8 | D50: Entrada de Energia | E50: =C50*4410.5 -> 35284

Sheet Sistemas Especiais
A2: SISTEMAS ESPECIAIS
A4: CLIMATIZAÇÃO, EXAUSTÃO MECÂNICA E PRESSURIZAÇÃO
A6: Descrição | B6: Quantidade | C6: Preço Unitário | D6: Valor total
A7: Infraestrutura para Instalação de Ar Condicionado | B7: 0 | C7: 1200 | D7: =B7*C7 -> 0
A8: Infraestrutura para Instalação de Ar Condicionado - CASSETE | B8: =DADOS_INICIAIS!E11 -> 14693.42 | C8: 100 | D8: =B8*C8*1.1 -> 1616276.2
A9: Instalação de Ar Condicionado | B9: =Ambientes!J12 -> 12 | C9: 8000 | D9: =B9*C9*1.1 -> 105600
A10: Ventokit | B10: =COUNTIF(Ambientes!G:G,"SIM")-5 -> 133 | C10: 900 | D10: =B10*C10*1.1 -> 131670
A11: Churrasqueiras | B11: =DADOS_INICIAIS!E26 -> 24 | C11: 2600 | D11: =B11*C11*1.1 -> 68640
A12: TOTAL | D12: =SUM(D7:D11) -> 1922186.2
A14: COMUNICAÇÃO
A16: Descrição | B16: Parâmetro | D16: Valor total
A17: CFTV | B17: 2 | C17: R$ / AC | D17: =B17*DADOS_INICIAIS!$E$11*1.1 -> 32325.524
A18: Interfone | B18: 4 | C18: R$ / AC | D18: =B18*DADOS_INICIAIS!$E$11*1.1 -> 64651.048
A19: Controle de acesso | B19: 2 | C19: R$ / AC | D19: =B19*DADOS_INICIAIS!$E$11*1.1 -> 32325.524
A20: TV e internet | B20: 3 | C20: R$ / AC | D20: =B20*DADOS_INICIAIS!$E$11*1.1 -> 48488.286
A21: Automação, telecomunicação e sistemas de segurança | B21: 8 | C21: R$ / AC | D21: =B21*DADOS_INICIAIS!$E$11*1.1 -> 129302.1
A22: TOTAL | D22: =SUM(D17:D21) -> 307092.48
A24: EQUIPAMENTOS
A26: Descrição | B26: Quantidade | C26: Preço Unitário | D26: Valor total
A27: Elevadores | B27: 6 | C27: 210000 | D27: =B27*C27*1.1 -> 1386000 | E27: Proposta Atlas - ABC
A28: Elevador 1 parada | B28: 1 | C28: =C27/4 -> 52500 | D28: =C28*1.1 -> 57750
A29: Grupo de geradores | B29: 1 | C29: 80000 | D29: =B29*C29*1.1 -> 88000
A30: Subestação | B30: 0 | D30: =B30*C30 -> 0
A31: Infra de carro elétrico | B31: =DADOS_INICIAIS!E26 -> 24 | C31: 800 | D31: =B31*C31*1.1 -> 21120 | E31: Cliente informou para considerar 1/apto | J31: 30 | K31: vagas 1º SS
A32: Instalação carro elétrico | B32: =B31 -> 24 | C32: 10000 | D32: =B32*C32*1.1 -> 264000 | E32: Cliente informou para considerar 1/apto | J32: 58 | K32: vagas 2º SS
A33: Sistema de placas fotovoltaicas | B33: 1 | C33: ='Simulador Solar'!A21 -> 1244901.7 | D33: =B33*C33*1.1 -> 1369391.9
A34: Sauna | B34: ='REVESTIMENTO PISO'!F151 -> 5.48 | C34: 3900 | D34: =B34*C34*1.1 -> 23509.2
A35: Lago | B35: 1 | C35: 10000 | D35: =B35*C35*1.1 -> 11000
A36: Equipamentos para Piscina | B36: 33 | C36: =14913.3+15818+1100+5000 -> 36831.3 | D36: =B36*C36*1.1 -> 1336976.2 | E36: Custo Gran Torino + Sistema de aquecimento Sodramar
A37: TOTAL | D37: =SUM(D27:D36) -> 4557747.3
A39: OUTROS SISTEMAS ESPECIAIS
A41: Descrição | B41: Parâmetro | D41: Valor total
A42: Outros sistemas | B42: 30 | C42: R$ / AC | D42: =B42*DADOS_INICIAIS!E11 -> 440802.6
A43: TOTAL | D43: =SUM(D42:D42) -> 440802.6
A45: TOTAL SISTEMAS ESPECIAIS | D45: =D12+D22+D37+D43 -> 7227828.5 | E45: =D45/DADOS_INICIAIS!E11 -> 491.9092

Sheet Simulador Solar
A1: https://www.neosolar.com.br/simulador-solar-calculadora-fotovoltaica
A21: 1244901.7

Sheet Complementares
A2: COMPLEMENTARES
A4: SERVIÇOS COMPLEMENTARES
A6: Descrição | B6: Parâmetro | D6: Quantidade | F6: Valor total
A7: Móveis e decoração | B7: 3100 | C7: R$ / ALI | D7: =DADOS_INICIAIS!E19 -> 343.39 | E7: m² | F7: =D7*B7*1.1 -> 1170959.9
A8: Móveis e decoração jardim duplex e calçadas suspensas | B8: 150 | C8: R$ / ALI | D8: =I8+I9 -> 1361.26 | E8: m² | F8: =D8*B8*1.1 -> 224607.9 | H8: Circulação | I8: =SUMIF('REVESTIMENTO PISO'!D:D,"Circulação",'REVESTIMENTO PISO'!F:F) -> 443.96
A9: Comunicação visual | B9: 12 | C9: R$ / AC | D9: 1 | E9: vb | F9: =DADOS_INICIAIS!$E$11*B9*1.1 -> 193953.14 | H9: Jardim superior | I9: =SUMIF('REVESTIMENTO PISO'!D:D,"JARDIM (SUPERIOR)",'REVESTIMENTO PISO'!F:F) -> 917.3
A10: Paisagismo + mobiliário externo | B10: =C21+150 -> 440.66828 | C10: R$ / ALE | D10: =DADOS_INICIAIS!E20 -> 2661.29 | E10: m² | F10: =D10*B10*1.1 -> 1290020.7
A11: Lago | B11: 1500 | C11: R$ / m² | D11: 52 | E11: m² | F11: =D11*B11*1.1 -> 85800
A12: Ligações definitivas | B12: 5 | C12: R$ / AC | D12: 1 | E12: vb | F12: =DADOS_INICIAIS!$E$11*B12*1.1 -> 80813.81
A13: Desmobilização | B13: 10 | C13: R$ / AC | D13: 1 | E13: vb | F13: =DADOS_INICIAIS!$E$11*B13*1.1 -> 161627.62
A14: Limpeza | B14: 20 | C14: R$ / AC | D14: 1 | E14: vb | F14: =DADOS_INICIAIS!$E$11*B14*1.1 -> 323255.24
A15: TOTAL | F15: =SUM(F7:F14) -> 3531038.3
A17: TOTAL COMPLEMENTARES | F17: =F15 -> 3531038.3 | G17: =F17/DADOS_INICIAIS!E11 -> 240.31426
B20: PAISAGISMO - LIVE LUMIS
B21: CUSTO POR ÁREA DE PAISAGISMO | C21: =520877.56/1792 -> 290.66828 | D21: 2661.29 | E21: =C21*D21 -> 773552.59
B22: CUSTO POR ÁREA CONSTRUÍDA | C22: =520877.56/14888.46 -> 34.985322 | D22: =DADOS_INICIAIS!$E$11 -> 14693.42 | E22: =C22*D22 -> 514054.02

Sheet Canteiro
A1: Obra | B1: xxxx
A2: Empresa | B2: xxxx
A3: Revisão | B3: =#REF! -> #REF! | N3: Número de funcionários | R3: Produtividade média (h/m2)
A4: LEVANTAMENTO QUANTITATIVO | N4: Área construída | O4: 0 | R4: A.C/prazo | S4: =O4/O5 -> #DIV/0!
N5: Prazo da obra | O5: 0 | P5: meses | R5: Pm | S5: 49 | T5: h/m2
A6: Instalações de canteiro | N6: NF | O6: =ROUNDUP((O4*S5)/O5/180,) -> #DIV/0! | P6: funcionários
N7: Pavimentos | O7: 0
A8: Instalações de canteiro | N8: Equipe administrativa | O8: 5 | P8: funcionários
B10: Descrição | C10: Unidade | D10: Quantidade
B11: Produtividade média | C11: m2 / mês | D11: =#REF!/#REF! -> #REF! | N11: Barracão interno | O11: =450+(O4-13000)/1000*16 -> 242
B12: Pm | C12: h/m2 | D12: 49 | N12: Externo | O12: =O11*0.4 -> 96.8
B13: Numero de funcionários | C13: un | D13: =ROUNDUP((D12*#REF!)/#REF!/180,) -> #REF!
B14: Equipe administrativa | C14: un | D14: 5 | O14: =SUM(O11:O13) -> 338.8
B15: Pontos de água e esgoto | C15: un | D15: =ROUNDUP($D$13/20,0) -> #REF! | E15: 20 funcionários/ponto
B16: Bebedouro | C16: un | D16: =ROUNDUP(#REF!/5,0) -> #REF! | E16: 1 / 5 pav. | N16: Área refeitório | O16: 1 | P16: m²/funcionários
B17: Ferramentas | C17: R$ | D17: =800*D13 -> #REF! | E17: 800,00/func. | O17: =O16*O6 -> #DIV/0! | P17: m²
B18: EPI | C18: R$ | D18: =500*D13 -> #REF! | E18: 500,00/func.
B19: Banheiro | C19: un | D19: =ROUNDUP($D$13/20,0) -> #REF! | E19: 1/20 func | N19: Área de vestiário | O19: 1.5 | P19: m²/funcionários
O20: =O19*O6 -> #DIV/0! | P20: m²
A21: Mobiliário de canteiro
B23: Descrição | C23: Unidade | D23: Quantidade | E23: Custo unitário | F23: Custo total
B24: Cadeira | C24: un | D24: =28*1.5 -> 42 | E24: 200 | F24: =D24*E24 -> 8400
B25: Mesa | C25: un | D25: 7 | E25: 1000 | F25: =E25*D25 -> 7000
B26: Ar condicionado | C26: un | D26: 11 | E26: 5000 | F26: =E26*D26 -> 55000
B27: Armário | C27: m | D27: =7*2 -> 14 | E27: 900 | F27: =E27*D27 -> 12600
B28: Escrivaninha | C28: un | D28: =D14 -> 5 | E28: 800 | F28: =E28*D28 -> 4000
B29: TOTAL | F29: =F26+F27+F28+F25+F24 -> 87000
B30: Descrição | C30: Unidade | D30: Quantidade | E30: Custo unitário | F30: Custo total
B31: Computador pessoal | C31: un | D31: =D14 -> 5 | E31: 6000 | F31: =D31*E31 -> 30000 | N31: Área sanitários | O31: =1*ROUNDUP(O6/20,) -> #DIV/0! | P31: m²
B32: Impressora | C32: un | D32: 7 | E32: 2000 | F32: =E32*D32 -> 14000
B33: Roteador | C33: un | D33: 14 | E33: 500 | F33: =E33*D33 -> 7000 | N33: área lavatório | O33: =0.6*ROUNDUP(O6/20,) -> #DIV/0! | P33: m²
B34: TOTAL | F34: =+F31+F32+F33 -> 51000 | N34: Área de chuveiros | O34: =0.8*ROUNDUP(O6/10,) -> #DIV/0! | P34: m²
N36: Escritório | O36: 8 | P36: m²/pessoa
O37: =O36*O8 -> 40 | P37: m²
N39: Almoxarifado | O39: =IF(O4<20000,100,100+((O4-20000)/1000)*5) -> 100 | P39: m2
O41: =O39+O37+O34+O33+O31+O20+O17 -> #DIV/0!
N44: Pontos de água e esgoto | O44: 20 | P44: funcionários/ponto
N45: Pontos de água e esgoto | O45: =ROUNDUP(O6/O44,) -> #DIV/0! | P45: pontos
N48: Bebedouro | O48: 1 | P48: a cada 5 pav.
N49: Total | O49: =ROUNDUP(O7/5,) -> 0 | P49: bebedouros
...

Sheet Bases
A1: Estimativas
B3: Área de Terreno | C3: Área Construída | D3: N° pavimentos | G3: Parâmetros | H3: Área de Terreno | I3: Área Construída | J3: N° pavimentos
A4: =#REF! -> #REF! | B4: =#REF! -> #REF! | C4: =#REF! -> #REF! | D4: =#REF! -> #REF! | G4: OBRA 1 | H4: 0 | I4: 13434.29 | K4: =C4/I4 -> #REF!
G5: OBRA 2 | H5: 0 | I5: 4498.66 | J5: 0
G6: OBRA 3 | H6: 0 | I6: 8366.5 | J6: 0
I8: =G4 -> OBRA 1 | J8: =G4 -> OBRA 1 | K8: =$G$5 -> OBRA 2 | L8: =$G$5 -> OBRA 2 | M8: =G6 -> OBRA 3 | N8: =G6 -> OBRA 3
A9: Descrição | F9: Unidade | G9: Quantidade | H9: Valor (R$) | I9: Valor | J9: Referencia | K9: Valor | L9: Referencia | M9: Valor | N9: Referencia
A10: ESTUDOS | H10: =$C$4*J10 -> #REF! | I10: =#REF! -> #REF! | J10: =I10/$I$4 -> #REF! | K10: =#REF! -> #REF! | L10: =K10/$I$5 -> #REF! | M10: =#REF! -> #REF! | N10: =M10/$I$6 -> #REF!
A11: PROJETOS | H11: =$C$4*J11 -> #REF! | I11: =#REF! -> #REF! | J11: =I11/$I$4 -> #REF! | K11: =#REF! -> #REF! | L11: =K11/$I$5 -> #REF! | M11: =#REF! -> #REF! | N11: =M11/$I$6 -> #REF!
A12: CONSULTORIAS | H12: =$C$4*J12 -> #REF! | I12: =#REF! -> #REF! | J12: =I12/$I$4 -> #REF! | K12: =#REF! -> #REF! | L12: =K12/$I$5 -> #REF! | M12: =#REF! -> #REF! | N12: =M12/$I$6 -> #REF!
A13: ENSAIOS E LAUDOS | H13: =$C$4*J13 -> #REF! | I13: =#REF! -> #REF! | J13: =I13/$I$4 -> #REF! | K13: =#REF! -> #REF! | L13: =K13/$I$5 -> #REF! | M13: =#REF! -> #REF! | N13: =M13/$I$6 -> #REF!
A14: TAXAS
A15: Despesas de Seguros | F15: vb | H15: =J15*$C$4 -> #REF! | I15: =#REF! -> #REF! | J15: =I15/$I$4 -> #REF! | K15: =#REF! -> #REF! | L15: =K15/$I$5 -> #REF! | M15: =#REF! -> #REF! | N15: =M15/$I$6 -> #REF!
A16: Licenciamentos, Taxas, Impostos | F16: vb | H16: =J16*$C$4 -> #REF! | I16: =#REF!-#REF! -> #REF! | J16: =I16/$I$4 -> #REF! | K16: =#REF!-#REF! -> #REF! | L16: =K16/$I$5 -> #REF! | M16: =#REF!-#REF! -> #REF! | N16: =M16/$I$6 -> #REF!
A17: DOCUMENTOS | H17: =J17*C4 -> #REF! | I17: =#REF! -> #REF! | J17: =I17/$I$4 -> #REF! | K17: =#REF! -> #REF! | L17: =K17/$I$5 -> #REF! | M17: =#REF! -> #REF! | N17: =M17/$I$6 -> #REF!
A18: SEGURANÇA DO TRABALHO
