Workbook

Sheet a. COMPARATIVOS OBRAS
A1: COMPARATIVO DE PRAZO DE OBRAS SEMELHANTES
A2: OBRA 1 | D2: OBRA 2 | G2: OBRA 3 | J2: OBRA PARAMÉTRICO
A3: DURAÇÃO | D3: DURAÇÃO | G3: DURAÇÃO | J3: DURAÇÃO
A4: Linha de base: | B4: -- meses | D4: Linha de base: | E4: -- meses | G4: Linha de base: | H4: -- meses | J4: Linha de base: | K4: -- meses
A5: Meta: | B5: -- meses | D5: Meta: | E5: -- meses | G5: Meta: | H5: -- meses | J5: Meta: | K5: -- meses
A6: ESPECIFICAÇÕES DE PROJETO | D6: ESPECIFICAÇÕES DE PROJETO | G6: ESPECIFICAÇÕES DE PROJETO | J6: ESPECIFICAÇÕES DE PROJETO
A7: Área Total | D7: Área Total | G7: Área Total | J7: Área Total
A8: área/pav embasamento = | B8: aprox --- m² | D8: área/pav embasamento = | E8: aprox --- m² | G8: área/pav embasamento = | H8: aprox --- m² | J8: área/pav embasamento = | K8: aprox --- m²
A9: área/pav tipo = | B9: aprox --- m² | D9: área/pav tipo = | E9: aprox --- m² | G9: área/pav tipo = | H9: aprox --- m² | J9: área/pav tipo = | K9: aprox --- m²
A10: Nº PAVIMENTOS | B10: -- | D10: Nº PAVIMENTOS | E10: -- | G10: Nº PAVIMENTOS | H10: -- | J10: Nº PAVIMENTOS | K10: --
A11: ESPECIFICAÇÕES DE PAVIMENTOS | D11: ESPECIFICAÇÕES DE PAVIMENTOS | G11: ESPECIFICAÇÕES DE PAVIMENTOS | J11: ESPECIFICAÇÕES DE PAVIMENTOS
A12: 1º - térreo
A13: 2º ao 4º - 3 pavs garagem
A14: 5º Lazer
A15: 6º - Tipo Dif
A16: 7º ao 20º - Tipo
A17: Técnicos

Sheet b. Fundação
D3: DIMENSIONAMENTO DE PRAZO - FUNDAÇÃO PROFUNDA, BLOCOS E BALDRAMES
B7: Estacas Hélice Contínua | J7: SEM ESTACA -> SAPATAS
C8: Estacas
B9: Etapa | C9: Quantidade | D9: Profundidade (m) | E9: Total (m) | F9: Duração (Dias) | G9: Total (dias) | H9: Meses
B10: Fase 1 | E10: =C10*D10 -> 0 | F10: =ROUNDUP((E10/$D$12),0) -> 0 | G10: =F10*D13 -> 0 | H10: =G10/22 -> 0
B12: Índice (m/dia) | D12: 120
B13: Coeficiente de chuva | D13: 1.2
B16: Etapa | C16: Forma (m²) | D16: Concreto (m³) | E16: Aço (Kg) | F16: Armador | G16: Carpinteiro | H16: Formas (Dias) | I16: Armação (dias) | J16: Concreto (dias) | K16: Duração Total | L16: Meses
B17: Blocos e Baldrames | C17: 1703.95 | D17: 721.67 | E17: 53223.46 | F17: 12 | G17: 12 | H17: =ROUNDUP((C17*$D$22)/(8.8*G17),0) -> 34 | I17: =ROUNDUP((E17*$D$24)/(8.8*F17),0) -> 23 | J17: =ROUNDUP((D17*$D$23)/8.8,0) -> 2 | K17: =I17+J17+H17 -> 59 | L17: =K17/22 -> 2.6818182
K18: =K17*D25 -> 70.8 | L18: =K18/22 -> 3.2181818
B19: Etapa | C19: Forma (m²) | D19: Concreto (m³) | E19: Aço (Kg) | F19: Armador | G19: Carpinteiro | H19: Formas (Dias) | I19: Armação (dias) | J19: Concreto (dias) | K19: Duração Total | L19: Meses
B20: CONTENÇÃO PAREDE DE CONCRETO | C20: 1163.48 | E20: =F22 -> 36341.695 | F20: 10 | G20: 10 | H20: =ROUNDUP((C20*$D$22)/(8.8*G20),0) -> 28 | I20: =ROUNDUP((E20*$D$24)/(8.8*F20),0) -> 19 | J20: =ROUNDUP((D20*$D$23)/8.8,0) -> 0 | K20: =I20+J20+H20 -> 47 | L20: =K20/22 -> 2.1363636
K21: =K20*D25 -> 56.4 | L21: =K21/22 -> 2.5636364
B22: Montagem de formas (Hh/m²): | D22: 2.08 | E22: =C20 -> 1163.48 | F22: =F23*E22/E23 -> 36341.695
B23: Concretagem (h/m³): | D23: 0.013253012 | E23: =C17 -> 1703.95 | F23: =E17 -> 53223.46
B24: RUP Armação (Hh/kg) | D24: 0.044 | E24: =8.8/D22 -> 4.2307692
B25: Coeficiente de chuva | D25: 1.2

Sheet c. Supraestrutura
D3: DIMENSIONAMENTO DE PRAZO - SUPRAESTRUTURA
B7: Pavimento | C7: Área do Pavimento | D7: Forma (m²) | E7: RUP (Hh/m²) | F7: RUP (m²/dia) | G7: Duração | H7: Carpinteiro | I7: Armador | J7: Servente | K7: Total Equipe | O7: cob | Q7: =185.64+118.04 -> 303.68 | R7: =Q7 -> 303.68 | S7: 2594.2 | T7: =S7-R7 -> 2290.52
B8: Cobertura | C8: =12469.72-C9-C10-C11-C12-C13 -> 406.11 | D8: =C8*$C$15 -> 1015.275 | E8: 1.6 | F8: =8.8/E8 -> 5.5 | G8: 12 | H8: =ROUNDUP((D8*E8)/(G8*8.8),0) -> 16 | I8: =ROUNDUP(H8/2,0) -> 8 | J8: =ROUNDUP(H8/4,0) -> 4 | K8: =J8+I8+H8 -> 28 | O8: pav2 | P8: =1469.1-174.91 -> 1294.19 | Q8: =1502.76-126.91 -> 1375.85 | R8: =Q8+P8 -> 2670.04 | S8: 2802.7
B9: Pavimento 2 | C9: 2802.7 | D9: =C9*$C$15 -> 7006.75 | E9: 1.6 | F9: =8.8/E9 -> 5.5 | G9: 50 | H9: =ROUNDUP((D9*E9)/(G9*8.8),0) -> 26 | I9: =ROUNDUP(H9/2,0) -> 13 | J9: =ROUNDUP(H9/4,0) -> 7 | K9: =J9+I9+H9 -> 46 | O9: pav1 | P9: =663.92+286.6+384.68 -> 1335.2 | Q9: =1895.9 -> 1895.9 | R9: =Q9+P9 -> 3231.1 | S9: 3188.34
B10: Pavimento 1 | C10: 3188.34 | D10: =C10*$C$15 -> 7970.85 | E10: 1.6 | F10: =8.8/E10 -> 5.5 | G10: 56 | H10: =ROUNDUP((D10*E10)/(G10*8.8),0) -> 26 | I10: =ROUNDUP(H10/2,0) -> 13 | J10: =ROUNDUP(H10/4,0) -> 7 | K10: =J10+I10+H10 -> 46 | O10: terreo | R10: 4067.92 | S10: 1879.83 | T10: =S10-R10 -> -2188.09
B11: Terreo - residencial | C11: =R10-C12 -> 2693.55 | D11: =C11*$C$15 -> 6733.875 | E11: 1.6 | F11: =8.8/E11 -> 5.5 | G11: 48 | H11: =ROUNDUP((D11*E11)/(G11*8.8),0) -> 26 | I11: =ROUNDUP(H11/2,0) -> 13 | J11: =ROUNDUP(H11/4,0) -> 7 | K11: =J11+I11+H11 -> 46 | O11: sub | R11: 2004.65 | S11: 2001.65
B12: Terreo - garagem | C12: 1374.37 | D12: =C12*$C$15 -> 3435.925 | E12: 2.2 | F12: =8.8/E12 -> 4 | G12: 34 | H12: =ROUNDUP((D12*E12)/(G12*8.8),0) -> 26 | I12: =ROUNDUP(H12/2,0) -> 13 | J12: =ROUNDUP(H12/4,0) -> 7 | K12: =J12+I12+H12 -> 46 | R12: =SUM(R7:R11) -> 12277.39 | S12: =SUM(S7:S11) -> 12466.72
B13: Subsolo | C13: 2004.65 | D13: =C13*$C$15 -> 5011.625 | E13: 2.2 | F13: =8.8/E13 -> 4 | G13: 49 | H13: =ROUNDUP((D13*E13)/(G13*8.8),0) -> 26 | I13: =ROUNDUP(H13/2,0) -> 13 | J13: =ROUNDUP(H13/4,0) -> 7 | K13: =J13+I13+H13 -> 46
C14: =SUM(C8:C13) -> 12469.72
B15: FATOR MULT (X) | C15: 2.5 | F15: Total Dias | G15: =SUM(G8:G13) -> 249 | H15: Total Meses | I15: =G15/22 -> 11.318182
B16: TORRE B | O16: TORRE B | P16: TORRE A | Q16: Total
B17: Pavimento | C17: Área do Pavimento | D17: Forma (m²) | E17: RUP (Hh/m²) | F17: RUP (m²/dia) | G17: Duração | H17: Carpinteiro | I17: Armador | J17: Servente | K17: Total Equipe | N17: cob | P17: =Q23-SUM(O18:P21) -> 512.23 | Q17: =P17 -> 512.23
B18: Cobertura | C18: =O17 -> 0 | D18: =C18*$C$15 -> 0 | E18: 1.6 | F18: =8.8/E18 -> 5.5 | G18: 0 | H18: =ROUNDUP((D18*E18)/(G18*8.8),0) -> #DIV/0! | I18: =ROUNDUP(H18/2,0) -> #DIV/0! | J18: =ROUNDUP(H18/4,0) -> #DIV/0! | K18: =J18+I18+H18 -> #DIV/0! | N18: pav2 | O18: =Q18-P18 -> 1442.84 | P18: =1491.79-131.93 -> 1359.86 | Q18: 2802.7
B19: Pavimento 2 | C19: =O18 -> 1442.84 | D19: =C19*$C$15 -> 3607.1 | E19: 1.6 | F19: =8.8/E19 -> 5.5 | G19: 47 | H19: =ROUNDUP((D19*E19)/(G19*8.8),0) -> 14 | I19: =ROUNDUP(H19/2,0) -> 7 | J19: =ROUNDUP(H19/4,0) -> 4 | K19: =J19+I19+H19 -> 25 | N19: pav1 | O19: =Q19-P19 -> 1540.86 | P19: 1647.38 | Q19: 3188.24
B20: Pavimento 1 | C20: =O19 -> 1540.86 | D20: =C20*$C$15 -> 3852.15 | E20: 1.6 | F20: =8.8/E20 -> 5.5 | G20: 51 | H20: =ROUNDUP((D20*E20)/(G20*8.8),0) -> 14 | I20: =ROUNDUP(H20/2,0) -> 7 | J20: =ROUNDUP(H20/4,0) -> 4 | K20: =J20+I20+H20 -> 25 | N20: terreo | O20: =Q20-P20 -> 2150.92 | P20: 1810.98 | Q20: 3961.9
B21: Terreo - garagem | C21: =O20 -> 2150.92 | D21: =C21*$C$15 -> 5377.3 | E21: 2.01 | F21: =8.8/E21 -> 4.3781095 | G21: 88 | H21: =ROUNDUP((D21*E21)/(G21*8.8),0) -> 14 | I21: =ROUNDUP(H21/2,0) -> 7 | J21: =ROUNDUP(H21/4,0) -> 4 | K21: =J21+I21+H21 -> 25 | N21: sub | O21: =Q21 -> 2004.65 | Q21: 2004.65
B22: Subsolo | C22: =O21 -> 2004.65 | D22: =C22*$C$15 -> 5011.625 | E22: 2.01 | F22: =8.8/E22 -> 4.3781095 | G22: 82 | H22: =ROUNDUP((D22*E22)/(G22*8.8),0) -> 14 | I22: =ROUNDUP(H22/2,0) -> 7 | J22: =ROUNDUP(H22/4,0) -> 4 | K22: =J22+I22+H22 -> 25 | O22: =SUM(O17:O21) -> 7139.27 | P22: =SUM(P17:P21) -> 5330.45 | Q22: =SUM(Q17:Q21) -> 12469.72
F23: Total Dias | G23: =SUM(G18:G22) -> 268 | H23: Total Meses | I23: =G23/22 -> 12.181818 | O23: =O22/Q23 -> 0.57252849 | P23: =P22/Q23 -> 0.42747151 | Q23: 12469.72 | R23: 100
B24: TORRE A | O24: 57 | P24: 43 | Q24: - | R24: X
B25: Pavimento | C25: Área do Pavimento | D25: Forma (m²) | E25: RUP (Hh/m²) | F25: RUP (m²/dia) | G25: Duração | H25: Carpinteiro | I25: Armador | J25: Servente | K25: Total Equipe
B26: Cobertura | C26: =P17 -> 512.23 | D26: =C26*$C$15 -> 1280.575 | E26: 1.6 | F26: =8.8/E26 -> 5.5 | G26: 20 | H26: =ROUNDUP((D26*E26)/(G26*8.8),0) -> 12 | I26: =ROUNDUP(H26/2,0) -> 6 | J26: =ROUNDUP(H26/4,0) -> 3 | K26: =J26+I26+H26 -> 21
B27: Pavimento 2 | C27: =P18 -> 1359.86 | D27: =C27*$C$15 -> 3399.65 | E27: 1.6 | F27: =8.8/E27 -> 5.5 | G27: 52 | H27: =ROUNDUP((D27*E27)/(G27*8.8),0) -> 12 | I27: =ROUNDUP(H27/2,0) -> 6 | J27: =ROUNDUP(H27/4,0) -> 3 | K27: =J27+I27+H27 -> 21
B28: Pavimento 1 | C28: =P19 -> 1647.38 | D28: =C28*$C$15 -> 4118.45 | E28: 1.6 | F28: =8.8/E28 -> 5.5 | G28: 63 | H28: =ROUNDUP((D28*E28)/(G28*8.8),0) -> 12 | I28: =ROUNDUP(H28/2,0) -> 6 | J28: =ROUNDUP(H28/4,0) -> 3 | K28: =J28+I28+H28 -> 21
B29: Terreo - garagem | C29: =P20 -> 1810.98 | D29: =C29*$C$15 -> 4527.45 | E29: 2.2 | F29: =8.8/E29 -> 4 | G29: 95 | H29: =ROUNDUP((D29*E29)/(G29*8.8),0) -> 12 | I29: =ROUNDUP(H29/2,0) -> 6 | J29: =ROUNDUP(H29/4,0) -> 3 | K29: =J29+I29+H29 -> 21
B30: Subsolo | C30: =P21 -> 0 | D30: =C30*$C$15 -> 0 | E30: 2.2 | F30: =8.8/E30 -> 4 | G30: 0 | H30: =ROUNDUP((D30*E30)/(G30*8.8),0) -> #DIV/0! | I30: =ROUNDUP(H30/2,0) -> #DIV/0! | J30: =ROUNDUP(H30/4,0) -> #DIV/0! | K30: =J30+I30+H30 -> #DIV/0!
F31: Total Dias | G31: =SUM(G26:G30) -> 230 | H31: Total Meses | I31: =G31/22 -> 10.454545
B39: RUP
B40: Garagens | C40: 2.2
B41: Lazer | C41: 2.01
B42: Tipo Dif | C42: 1.21
B43: Tipo | C43: 1.17
B44: Técnicos | C44: 1.6

Sheet d. Fachada
B3: DIMENSIONAMENTO DE PRAZO - FACHADA
B6: Serviço | C6: Quant (m²) | D6: RUP | F6: Dias | G6: Profissional | H6: Servente
B7: Chapisco | C7: 3968.0502 | D7: 0.1742 | E7: =8.8/D7 -> 50.516648 | F7: 10 | G7: =ROUNDUP(((($C7*D7)/(F7*8.8))),0) -> 8 | H7: =ROUNDUP(G7/2,0) -> 4
B8: Reboco | C8: =C7 -> 3968.0502 | D8: 0.6328 | E8: =8.8/D8 -> 13.906448 | F8: 36 | G8: =ROUNDUP(((($C8*D8)/(F8*8.8))),0) -> 8 | H8: =ROUNDUP(G8/2,0) -> 4
B9: Concreto aparente (estucamento) | C9: =[1]FACHADA!I11 -> 9921.8458 | D9: 0.129 | E9: =8.8/D9 -> 68.217054 | F9: 19 | G9: =ROUNDUP(((($C9*D9)/(F9*8.8))),0) -> 8 | H9: =ROUNDUP(G9/2,0) -> 4
B10: Selador | C10: =C8 -> 3968.0502 | D10: 0.047 | E10: =8.8/D10 -> 187.23404 | F10: 7 | G10: =ROUNDUP(((($C10*D10)/(F10*8.8))),0) -> 4 | H10: =ROUNDUP(G10/2,0) -> 2
B11: Textura | C11: =C10 -> 3968.0502 | D11: 0.1855 | E11: =8.8/D11 -> 47.439353 | F11: 21 | G11: =ROUNDUP(((($C11*D11)/(F11*8.8))),0) -> 4 | H11: =ROUNDUP(G11/2,0) -> 2
B12: Pastilha Cerâmica (pedra natural) | C12: 451.70282 | D12: 0.945 | E12: =8.8/D12 -> 9.3121693 | F12: 13 | G12: =ROUNDUP(((($C12*D12)/(F12*8.8))),0) -> 4 | H12: =ROUNDUP(G12/2,0) -> 2
B13: Preparação | C13: - | D13: - | F13: =5*4 -> 20 | G13: - | H13: -
B14: Balancim | C14: - | D14: - | F14: =4*4 -> 16 | G14: - | H14: -
D15: Total Dias | F15: =SUM(F7:F14) -> 142 | G15: Total Meses | H15: =F15/22 -> 6.4545455
B16: POR TORRE
B17: Serviço | C17: Quant (m²) | D17: RUP | F17: Dias | G17: Profissional | H17: Servente
B18: Chapisco | C18: =C7/2 -> 1984.0251 | D18: 0.1742 | E18: =8.8/D18 -> 50.516648 | F18: 10 | G18: =ROUNDUP(((($C18*D18)/(F18*8.8))),0) -> 4 | H18: =ROUNDUP(G18/2,0) -> 2
B19: Reboco | C19: =C8/2 -> 1984.0251 | D19: 0.6328 | E19: =8.8/D19 -> 13.906448 | F19: 36 | G19: =ROUNDUP(((($C19*D19)/(F19*8.8))),0) -> 4 | H19: =ROUNDUP(G19/2,0) -> 2
B20: Concreto aparente (estucamento) | C20: =C9/2 -> 4960.9229 | D20: 0.129 | E20: =8.8/D20 -> 68.217054 | F20: 19 | G20: =ROUNDUP(((($C20*D20)/(F20*8.8))),0) -> 4 | H20: =ROUNDUP(G20/2,0) -> 2
B21: Selador | C21: =C10/2 -> 1984.0251 | D21: 0.047 | E21: =8.8/D21 -> 187.23404 | F21: 7 | G21: =ROUNDUP(((($C21*D21)/(F21*8.8))),0) -> 2 | H21: =ROUNDUP(G21/2,0) -> 1
B22: Textura | C22: =C11/2 -> 1984.0251 | D22: 0.1855 | E22: =8.8/D22 -> 47.439353 | F22: 21 | G22: =ROUNDUP(((($C22*D22)/(F22*8.8))),0) -> 2 | H22: =ROUNDUP(G22/2,0) -> 1
B23: Pastilha Cerâmica (pedra natural) | C23: =C12/2 -> 225.85141 | D23: 0.945 | E23: =8.8/D23 -> 9.3121693 | F23: 13 | G23: =ROUNDUP(((($C23*D23)/(F23*8.8))),0) -> 2 | H23: =ROUNDUP(G23/2,0) -> 1
B24: Preparação | C24: - | D24: - | F24: =5*4 -> 20 | G24: - | H24: -
B25: Balancim | C25: - | D25: - | F25: =4*4 -> 16 | G25: - | H25: -
D26: Total Dias | F26: =SUM(F18:F25) -> 142 | G26: Total Meses | H26: =F26/22 -> 6.4545455

Sheet e. ESTIMATIVA PRAZO
B3: ESTIMATIVA DE PRAZO
H5: ESTIMATIVA DE PRAZO | AS5: DIVISÃO DE CUSTOS PARA CURVAS
B6: Serviço | C6: Prazo | G6: SERVIÇOS | H6: M1 | I6: M2 | J6: M3 | K6: M4 | L6: M5 | M6: M6 | N6: M7 | O6: M8 | P6: M9 | Q6: M10 | R6: M11 | S6: M12 | T6: M13 | U6: M14 | V6: M15 | W6: M16 | X6: M17 | Y6: M18 | Z6: M19 | AA6: M20 | AB6: M21 | AC6: M22 | AD6: M23 | AE6: M24 | AF6: M25 | AG6: M26 | AH6: M27 | AI6: M28 | AJ6: M29 | AK6: M30 | AL6: M31 | AM6: M32 | AN6: M33 | AO6: M34 | AP6: M35 | AQ6: M36 | AS6: SERVIÇOS ORÇAMENTO | AT6: SERVIÇO PLANEJAMENTO | AU6: M1 | AV6: M2 | AW6: M3 | AX6: M4 | AY6: M5 | AZ6: M6 | BA6: M7 | BB6: M8 | BC6: M9 | BD6: M10 | BE6: M11 | BF6: M12 | BG6: M13 | BH6: M14 | BI6: M15 | BJ6: M16 | BK6: M17 | BL6: M18 | BM6: M19 | BN6: M20 | BO6: M21 | BP6: M22 | BQ6: M23 | BR6: M24 | BS6: M25 | BT6: M26 | BU6: M27 | BV6: M28 | BW6: M29 | BX6: M30 | BY6: M31 | BZ6: M32 | CA6: M33 | CB6: M34 | CC6: M35 | CD6: M36 | CE6: M37 | CF6: M38 | CG6: M39 | CH6: M40
B7: Iniciais | C7: 1 | D7: ="+/- 1 mês" -> +/- 1 mês | G7: Iniciais (escavação) | H7: 1 | I7: 2 | AS7: MOVIMENTAÇÃO DE TERRA | AT7: Iniciais | AU7: 1
B8: Infra | C8: ='b. Fundação'!H10+'b. Fundação'!L18 -> 3.2181818 | D8: Dimensionamento de Fundações | G8: Contenção + Sapatas | I8: 1 | J8: 2 | K8: 3 | L8: 4 | M8: 5 | N8: 6 | AS8: INFRAESTRUTURA | AT8: Infra | AV8: 1 | AW8: 2 | AX8: 3 | AY8: 4 | AZ8: 5
B9: Supra | C9: ='c. Supraestrutura'!I15 -> 11.318182 | D9: Dimensionamento de Supraestrutura | G9: Supra | O9: 1 | P9: 2 | Q9: 3 | R9: 4 | S9: 5 | T9: 6 | U9: 7 | V9: 8 | W9: 9 | X9: 10 | Y9: 11 | Z9: 12 | AS9: SUPRAESTRUTURA | AT9: Supra | BA9: 1 | BB9: 2 | BC9: 3 | BD9: 4 | BE9: 5 | BF9: 6 | BG9: 7 | BH9: 8 | BI9: 9 | BJ9: 10 | BK9: 11 | BL9: 12 | BM9: 13 | BN9: 14 | BO9: 15 | BP9: 16
B10: Alvenaria (3 meses após supra) + drywall | C10: 3 | D10: ="+/-3 meses após o término da Supraestrutura" -> +/-3 meses após o término da Supraestrutura | G10: Alvenaria + DRYWALL | AA10: 1 | AB10: 2 | AC10: 3 | AE10: 1 | AF10: 2 | AS10: ALVENARIA | AT10: Alvenaria | BE10: 1 | BF10: 2 | BG10: 3 | BH10: 4 | BI10: 5 | BJ10: 6 | BK10: 7 | BL10: 8 | BM10: 9 | BN10: 10 | BO10: 11 | BP10: 12 | BQ10: 13 | BR10: 14 | BS10: 15
B11: Fachada | C11: ='d. Fachada'!H15 -> 6.4545455 | D11: Dimensionamento de fachada | G11: Fachada | AD11: 1 | AE11: 2 | AF11: 3 | AG11: 4 | AH11: 5 | AI11: 6 | AJ11: 7 | AS11: INSTALAÇÕES ELÉTRICAS, HIDRÁULICAS, GLP E PREVENTIVAS | AT11: INSTALAÇÕES ELÉTRICAS, HIDRÁULICAS, GLP E PREVENTIVAS | BF11: 1 | BG11: 2 | BH11: 3 | BI11: 4 | BJ11: 5 | BK11: 6 | BL11: 7 | BM11: 8 | BN11: 9 | BO11: 10 | BP11: 11 | BQ11: 12 | BR11: 13 | BS11: 14 | BT11: 15 | BU11: 16
B12: Acabamentos | C12: 12 | D12: ="+/-12 meses após o término da Alvenaria" -> +/-12 meses após o término da Alvenaria | G12: Acabamentos | AD12: 1 | AE12: 2 | AF12: 3 | AG12: 4 | AH12: 5 | AI12: 6 | AJ12: 7 | AK12: 8 | AL12: 9 | AM12: 10 | AS12: EQUIPAMENTOS E SISTEMAS ESPECIAIS | AT12: EQUIPAMENTOS E SISTEMAS ESPECIAIS | BT12: 1 | BU12: 2 | BV12: 3 | BW12: 4 | BX12: 5 | BY12: 6
B13: Serviços Finais | C13: 5 | D13: ="+/-5 a 6 meses após o término da Fachada" -> +/-5 a 6 meses após o término da Fachada | G13: Serviços Finais | AK13: 1 | AL13: 2 | AM13: 3 | AN13: 4 | AO13: 5 | AS13: IMPERMEABILIZAÇÃO | AT13: IMPERMEABILIZAÇÃO | BI13: 1 | BJ13: 2 | BK13: 3 | BL13: 4 | BM13: 5 | BN13: 6 | BO13: 7 | BP13: 8 | BQ13: 9 | BR13: 10 | BS13: 11 | BT13: 12 | BU13: 13 | BV13: 14 | BW13: 15 | BX13: 16
H14: INFRA | AS14: REVESTIMENTOS INTERNOS EM PISO E PAREDE | AT14: REVESTIMENTOS INTERNOS EM PISO E PAREDE | BG14: 1 | BH14: 2 | BI14: 3 | BJ14: 4 | BK14: 5 | BL14: 6 | BM14: 7 | BN14: 8 | BO14: 9 | BP14: 10 | BQ14: 11 | BR14: 12 | BS14: 13 | BT14: 14 | BU14: 15 | BV14: 16 | BW14: 17
B15: Grua | C15: =C9+1 -> 12.318182 | D15: Prazo de supra + 1 mês | G15: SERVIÇOS | H15: M1 | I15: M2 | J15: M3 | K15: M4 | L15: M5 | M15: M6 | N15: M7 | O15: M8 | P15: M9 | Q15: M10 | R15: M11 | S15: M12 | T15: M13 | U15: M14 | V15: M15 | W15: M16 | X15: M17 | Y15: M18 | Z15: M19 | AA15: M20 | AB15: M21 | AC15: M22 | AD15: M23 | AE15: M24 | AF15: M25 | AG15: M26 | AH15: M27 | AI15: M28 | AJ15: M29 | AK15: M30 | AL15: M31 | AM15: M32 | AN15: M33 | AO15: M34 | AP15: M35 | AQ15: M36 | AS15: REVESTIMENTOS E ACABAMENTOS INTERNOS EM TETO | AT15: REVESTIMENTOS E ACABAMENTOS INTERNOS EM TETO | BK15: 1 | BL15: 2 | BM15: 3 | BN15: 4 | BO15: 5 | BP15: 6 | BQ15: 7 | BR15: 8 | BS15: 9 | BT15: 10 | BU15: 11 | BV15: 12 | BW15: 13 | BX15: 14 | BY15: 15 | BZ15: 16
B16: Balancim | C16: =C11+1 -> 7.4545455 | D16: Prazo de Fachada + 1 mês | G16: Iniciais (escavação) | H16: 1 | I16: 2
B17: Cremalheira | C17: =C9-(('c. Supraestrutura'!G13+'c. Supraestrutura'!G12+'c. Supraestrutura'!G11)/22)+C10+B21 -> 12 | D17: Montada no 3º pavimento de supraestrutura, desmontada após a instalação do elevador da obra | G17: Contenção + Sapatas | I17: 1 | J17: 2 | K17: 3 | L17: 4 | M17: 5 | N17: 6 | AS17: ACABAMENTOS EM PISO E PAREDE | AT17: ACABAMENTOS EM PISO E PAREDE | BJ17: 1 | BK17: 2 | BL17: 3 | BM17: 4 | BN17: 5 | BO17: 6 | BP17: 7 | BQ17: 8 | BR17: 9 | BS17: 10 | BT17: 11 | BU17: 12 | BV17: 13 | BW17: 14 | BX17: 15 | BY17: 16 | BZ17: 17 | CA17: 18
H18: TORRE B | AS18: PINTURA INTERNA | AT18: PINTURA INTERNA | BL18: 1 | BM18: 2 | BN18: 3 | BO18: 4 | BP18: 5 | BQ18: 6 | BR18: 7 | BS18: 8 | BT18: 9 | BU18: 10 | BV18: 11 | BW18: 12 | BX18: 13 | BY18: 14 | BZ18: 15 | CA18: 16 | CB18: 17 | CC18: 18 | CD18: 19 | CE18: 20
B19: Preparação do Fosso do elevador | C19: 30 | G19: Supra | O19: 1 | P19: 2 | Q19: 3 | R19: 4 | S19: 5 | T19: 6 | U19: 7 | V19: 8 | W19: 9 | X19: 10 | Y19: 11 | Z19: 12 | AS19: ESQUADRIAS, VIDROS E FERRAGENS | AT19: ESQUADRIAS, VIDROS E FERRAGENS | BV19: 1 | BW19: 2 | BX19: 3 | BY19: 4 | BZ19: 5 | CA19: 6 | CB19: 7 | CC19: 8 | CD19: 9 | CE19: 10 | CF19: 11
B20: Montagem Elevador | C20: 50 | G20: Alvenaria | AA20: 1 | AB20: 2 | AC20: 3 | AE20: 1 | AF20: 2 | AS20: COBERTURA | AT20: COBERTURA | CC20: 1 | CD20: 2 | CE20: 3 | CF20: 4
B21: =C21/22 -> 3.6363636 | C21: =C19+C20 -> 80 | G21: Fachada | AD21: 1 | AE21: 2 | AF21: 3 | AG21: 4 | AH21: 5 | AI21: 6 | AJ21: 7 | AS21: REVESTIMENTOS E ACABAMENTOS DE FACHADA | AT21: REVESTIMENTOS E ACABAMENTOS DE FACHADA | BT21: 1 | BU21: 2 | BV21: 3 | BW21: 4 | BX21: 5 | BY21: 6 | BZ21: 7 | CA21: 8 | CB21: 9
B22: INDIRETOS MONOLITY | G22: Acabamentos | AD22: 1 | AE22: 2 | AF22: 3 | AG22: 4 | AH22: 5 | AI22: 6 | AJ22: 7 | AK22: 8 | AL22: 9 | AM22: 10 | AN22: 11 | AO22: 12 | AS22: SERVIÇOS COMPLEMENTARES | AT22: Serviços Finais | CC22: 1 | CD22: 2 | CE22: 3 | CF22: 4 | CG22: 5 | CH22: 6
B23: Grua 1 | C23: ='c. Supraestrutura'!I23+1 -> 13.181818 | D23: Prazo de supra + 1 mês | G23: Serviços Finais | AL23: 1 | AM23: 2 | AN23: 3 | AO23: 4 | AP23: 5 | AQ23: 6 | AT23: Acabamentos | BT23: 1 | BU23: 2 | BV23: 3 | BW23: 4 | BX23: 5 | BY23: 6 | BZ23: 7 | CA23: 8 | CB23: 9 | CC23: 10 | CD23: 11 | CE23: 12
B24: Grua 2 | C24: ='c. Supraestrutura'!I31+1 -> 11.454545 | D24: Prazo de supra + 1 mês | H24: TORRE A
B25: Cremalheira 1 | C25: ='c. Supraestrutura'!I23-(('c. Supraestrutura'!G22+'c. Supraestrutura'!G21)/22)+C10+B21 -> 11.090909 | D25: Montagem após a supra do térreo, desmontagem no término do elevador | G25: SERVIÇOS | H25: M1 | I25: M2 | J25: M3 | K25: M4 | L25: M5 | M25: M6 | N25: M7 | O25: M8 | P25: M9 | Q25: M10 | R25: M11 | S25: M12 | T25: M13 | U25: M14 | V25: M15 | W25: M16 | X25: M17 | Y25: M18 | Z25: M19 | AA25: M20 | AB25: M21 | AC25: M22 | AD25: M23 | AE25: M24 | AF25: M25 | AG25: M26 | AH25: M27 | AI25: M28 | AJ25: M29 | AK25: M30 | AL25: M31 | AM25: M32 | AN25: M33 | AO25: M34 | AP25: M35 | AQ25: M36
B26: Cremalheira 2 | C26: ='c. Supraestrutura'!I23-(('c. Supraestrutura'!G29)/22)+C10+B21 -> 14.5 | D26: Montagem após a supra do térreo, desmontagem no término do elevador | G26: Supra | P26: 1 | Q26: 2 | R26: 3 | S26: 4 | T26: 5 | U26: 6 | V26: 7 | W26: 8 | X26: 9 | Y26: 10 | Z26: 11
B27: Balancim 1 | C27: =C16 -> 7.4545455 | D27: Prazo de Fachada + 1 mês | G27: Alvenaria | AA27: 1 | AB27: 2 | AC27: 3 | AE27: 1 | AF27: 2
B28: Balancim 2 | C28: =C16 -> 7.4545455 | D28: Prazo de Fachada + 1 mês | G28: Fachada | AD28: 1 | AE28: 2 | AF28: 3 | AG28: 4 | AH28: 5 | AI28: 6 | AJ28: 7
G29: Acabamentos | AD29: 1 | AE29: 2 | AF29: 3 | AG29: 4 | AH29: 5 | AI29: 6 | AJ29: 7 | AK29: 8 | AL29: 9 | AM29: 10 | AN29: 11 | AO29: 12
G30: Serviços Finais | AL30: 1 | AM30: 2 | AN30: 3 | AO30: 4 | AP30: 5 | AQ30: 6
G32: TOTAL
G33: SERVIÇOS | H33: M1 | I33: M2 | J33: M3 | K33: M4 | L33: M5 | M33: M6 | N33: M7 | O33: M8 | P33: M9 | Q33: M10 | R33: M11 | S33: M12 | T33: M13 | U33: M14 | V33: M15 | W33: M16 | X33: M17 | Y33: M18 | Z33: M19 | AA33: M20 | AB33: M21 | AC33: M22 | AD33: M23 | AE33: M24 | AF33: M25 | AG33: M26 | AH33: M27 | AI33: M28 | AJ33: M29 | AK33: M30 | AL33: M31 | AM33: M32 | AN33: M33 | AO33: M34 | AP33: M35 | AQ33: M36
G34: MOVIMENTAÇÃO DE TERRA | H34: 1 | I34: 2
G35: CONTENÇÃO | I35: 1 | J35: 2 | K35: 3
G36: INFRAESTRUTURA | K36: 1 | L36: 2 | M36: 3 | N36: 4
G37: SUPRAESTRUTURA | O37: 1 | P37: 2 | Q37: 3 | R37: 4 | S37: 5 | T37: 6 | U37: 7 | V37: 8 | W37: 9 | X37: 10 | Y37: 11 | Z37: 12
G38: ALVENARIA + Drywall | R38: 1 | S38: 2 | T38: 3 | U38: 4 | V38: 5 | W38: 6 | X38: 7 | Y38: 8 | Z38: 9 | AA38: 10 | AB38: 11 | AC38: 12 | AD38: 13 | AE38: 14 | AF38: 15 | AG38: 16 | AH38: 17
G39: INSTALAÇÕES ELÉTRICAS, HIDRÁULICAS, GLP E PREVENTIVAS | T39: 1 | U39: 2 | V39: 3 | W39: 4 | X39: 5 | Y39: 6 | Z39: 7 | AA39: 8 | AB39: 9 | AC39: 10 | AD39: 11 | AE39: 12 | AF39: 13 | AG39: 14
G40: EQUIPAMENTOS E SISTEMAS ESPECIAIS | AD40: 1 | AE40: 2 | AF40: 3 | AG40: 4 | AH40: 5 | AI40: 6 | AJ40: 7 | AK40: 8 | AL40: 9 | AM40: 10 | AN40: 11 | AO40: 12 | AP40: 13 | AQ40: 14
G41: IMPERMEABILIZAÇÃO | W41: 2 | X41: 3 | Y41: 4 | Z41: 5 | AA41: 6 | AB41: 7 | AC41: 8 | AD41: 9 | AE41: 10 | AF41: 11 | AG41: 12 | AH41: 13 | AI41: 14
G42: REVESTIMENTOS INTERNOS EM PISO E PAREDE | U42: 1 | V42: 2 | W42: 3 | X42: 4 | Y42: 5 | Z42: 6 | AA42: 7 | AB42: 8 | AC42: 9 | AD42: 10 | AE42: 11 | AF42: 12 | AG42: 13
G43: REVESTIMENTOS E ACABAMENTOS INTERNOS EM TETO | X43: 1 | Y43: 2 | Z43: 3 | AA43: 4 | AB43: 5 | AC43: 6 | AD43: 7 | AE43: 8 | AF43: 9 | AG43: 10 | AH43: 11 | AI43: 12 | AJ43: 13 | AK43: 14
G44: ACABAMENTOS EM PISO E PAREDE | W44: 1 | X44: 2 | Y44: 3 | Z44: 4 | AA44: 5 | AB44: 6 | AC44: 7 | AD44: 8 | AE44: 9 | AF44: 10 | AG44: 11 | AH44: 12 | AI44: 13 | AJ44: 14
...

Sheet f. DISTRIBUIÇÃO DO CUSTO
B2: ETAPA | C2: VALOR ORÇADO | D2: % | G2: M1 | I2: M2 | K2: M3 | M2: M4 | O2: M5 | Q2: M6 | S2: M7 | U2: M8 | W2: M9 | Y2: M10 | AA2: M11 | AC2: M12 | AE2: M13 | AG2: M14 | AI2: M15 | AK2: M16 | AM2: M17 | AO2: M18 | AQ2: M19 | AS2: M20 | AU2: M21 | AW2: M22 | AY2: M23 | BA2: M24 | BC2: M25 | BE2: M26 | BG2: M27 | BI2: M28 | BK2: M29 | BM2: M30 | BO2: M31 | BQ2: M32 | BS2: M33 | BU2: M34 | BW2: M35 | BY2: M36 | CA2: M37 | CC2: M38 | CE2: M39 | CG2: M40
G3: % | H3: R$ | I3: % | J3: R$ | K3: % | L3: R$ | M3: % | N3: R$ | O3: % | P3: R$ | Q3: % | R3: R$ | S3: % | T3: R$ | U3: % | V3: R$ | W3: % | X3: R$ | Y3: % | Z3: R$ | AA3: % | AB3: R$ | AC3: % | AD3: R$ | AE3: % | AF3: R$ | AG3: % | AH3: R$ | AI3: % | AJ3: R$ | AK3: % | AL3: R$ | AM3: % | AN3: R$ | AO3: % | AP3: R$ | AQ3: % | AR3: R$ | AS3: % | AT3: R$ | AU3: % | AV3: R$ | AW3: % | AX3: R$ | AY3: % | AZ3: R$ | BA3: % | BB3: R$ | BC3: % | BD3: R$ | BE3: % | BF3: R$ | BG3: % | BH3: R$ | BI3: % | BJ3: R$ | BK3: % | BL3: R$ | BM3: % | BN3: R$ | BO3: % | BP3: R$ | BQ3: % | BR3: R$ | BS3: % | BT3: R$ | BU3: % | BV3: R$ | BW3: % | BX3: R$ | BY3: % | BZ3: R$ | CA3: % | CB3: R$ | CC3: % | CD3: R$ | CE3: % | CF3: R$ | CG3: % | CH3: R$
B4: GERENCIAMENTO TÉCNICO E ADMINISTRATIVO | C4: 8526873.7 | D4: 0.11402738 | E4: =SUM(G4,I4,K4,M4,O4,Q4,S4,U4,W4,Y4,AA4,AC4,AE4,AG4,AI4,,AK4,AM4,AO4,AQ4,AS4,AU4,AW4,AY4,BA4,BC4,BE4,BG4,BI4,BK4,BM4,BO4,BQ4,BS4,BU4,BW4,BY4,CA4,CC4,CE4,CG4) -> 1 | F4: =H4+J4+L4+N4+P4+R4+T4+V4+X4+Z4+AB4+AD4+AF4+AH4+AJ4+AL4+AN4+AP4+AR4+AT4+AV4+AX4+AZ4+BB4+BD4+BF4+BH4+BJ4+BL4+BN4+BP4+BR4+BT4+BV4+BX4+BZ4 -> 8526873.7 | G4: 0.11 | H4: =$C4*G4 -> 937956.1 | I4: =2%+(79%/35) -> 0.042571429 | J4: =$C4*I4 -> 363001.19 | K4: =2%+(79%/35) -> 0.042571429 | L4: =$C4*K4 -> 363001.19 | M4: =2%+(79%/35) -> 0.042571429 | N4: =$C4*M4 -> 363001.19 | O4: =2%+(79%/35) -> 0.042571429 | P4: =$C4*O4 -> 363001.19 | Q4: =2%+(79%/35) -> 0.042571429 | R4: =$C4*Q4 -> 363001.19 | S4: =(79%/35) -> 0.022571429 | T4: =$C4*S4 -> 192463.72 | U4: =(79%/35) -> 0.022571429 | V4: =$C4*U4 -> 192463.72 | W4: =(79%/35) -> 0.022571429 | X4: =$C4*W4 -> 192463.72 | Y4: =(79%/35) -> 0.022571429 | Z4: =$C4*Y4 -> 192463.72 | AA4: =(79%/35) -> 0.022571429 | AB4: =$C4*AA4 -> 192463.72 | AC4: =(79%/35) -> 0.022571429 | AD4: =$C4*AC4 -> 192463.72 | AE4: =(79%/35) -> 0.022571429 | AF4: =$C4*AE4 -> 192463.72 | AG4: =(79%/35) -> 0.022571429 | AH4: =$C4*AG4 -> 192463.72 | AI4: =(79%/35) -> 0.022571429 | AJ4: =$C4*AI4 -> 192463.72 | AK4: =(79%/35) -> 0.022571429 | AL4: =$C4*AK4 -> 192463.72 | AM4: =(79%/35) -> 0.022571429 | AN4: =$C4*AM4 -> 192463.72 | AO4: =(79%/35) -> 0.022571429 | AP4: =$C4*AO4 -> 192463.72 | AQ4: =(79%/35) -> 0.022571429 | AR4: =$C4*AQ4 -> 192463.72 | AS4: =(79%/35) -> 0.022571429 | AT4: =$C4*AS4 -> 192463.72 | AU4: =(79%/35) -> 0.022571429 | AV4: =$C4*AU4 -> 192463.72 | AW4: =(79%/35) -> 0.022571429 | AX4: =$C4*AW4 -> 192463.72 | AY4: =(79%/35) -> 0.022571429 | AZ4: =$C4*AY4 -> 192463.72 | BA4: =(79%/35) -> 0.022571429 | BB4: =$C4*BA4 -> 192463.72 | BC4: =(79%/35) -> 0.022571429 | BD4: =$C4*BC4 -> 192463.72 | BE4: =(79%/35) -> 0.022571429 | BF4: =$C4*BE4 -> 192463.72 | BG4: =(79%/35) -> 0.022571429 | BH4: =$C4*BG4 -> 192463.72 | BI4: =(79%/35) -> 0.022571429 | BJ4: =$C4*BI4 -> 192463.72 | BK4: =(79%/35) -> 0.022571429 | BL4: =$C4*BK4 -> 192463.72 | BM4: =(79%/35) -> 0.022571429 | BN4: =$C4*BM4 -> 192463.72 | BO4: =(79%/35) -> 0.022571429 | BP4: =$C4*BO4 -> 192463.72 | BQ4: =(79%/35) -> 0.022571429 | BR4: =$C4*BQ4 -> 192463.72 | BS4: =(79%/35) -> 0.022571429 | BT4: =$C4*BS4 -> 192463.72 | BU4: =(79%/35) -> 0.022571429 | BV4: =$C4*BU4 -> 192463.72 | BW4: =(79%/35) -> 0.022571429 | BX4: =$C4*BW4 -> 192463.72 | BY4: =(79%/35) -> 0.022571429 | BZ4: =$C4*BY4 -> 192463.72 | CB4: =$C4*CA4 -> 0 | CD4: =$C4*CC4 -> 0 | CF4: =$C4*CE4 -> 0 | CH4: =$C4*CG4 -> 0
B5: MOVIMENTAÇÃO DE TERRA | C5: 2450076.2 | D5: 0.03276415 | E5: =SUM(G5,I5,K5,M5,O5,Q5,S5,U5,W5,Y5,AA5,AC5,AE5,AG5,AI5,,AK5,AM5,AO5,AQ5,AS5,AU5,AW5,AY5,BA5,BC5,BE5,BG5,BI5,BK5,BM5,BO5,BQ5,BS5,BU5,BW5,BY5,CA5,CC5,CE5,CG5) -> 1 | F5: =H5+J5+L5+N5+P5+R5+T5+V5+X5+Z5+AB5+AD5+AF5+AH5+AJ5+AL5+AN5+AP5+AR5+AT5+AV5+AX5+AZ5+BB5+BD5+BF5+BH5+BJ5+BL5+BN5+BP5+BR5+BT5+BV5+BX5+BZ5 -> 2450076.2 | G5: =100%/4 -> 0.25 | H5: =$C5*G5 -> 612519.04 | I5: =100%/4 -> 0.25 | J5: =$C5*I5 -> 612519.04 | K5: =100%/4 -> 0.25 | L5: =$C5*K5 -> 612519.04 | M5: =100%/4 -> 0.25 | N5: =$C5*M5 -> 612519.04 | P5: =$C5*O5 -> 0 | R5: =$C5*Q5 -> 0 | T5: =$C5*S5 -> 0 | V5: =$C5*U5 -> 0 | X5: =$C5*W5 -> 0 | Z5: =$C5*Y5 -> 0 | AB5: =$C5*AA5 -> 0 | AD5: =$C5*AC5 -> 0 | AF5: =$C5*AE5 -> 0 | AH5: =$C5*AG5 -> 0 | AJ5: =$C5*AI5 -> 0 | AL5: =$C5*AK5 -> 0 | AN5: =$C5*AM5 -> 0 | AP5: =$C5*AO5 -> 0 | AR5: =$C5*AQ5 -> 0 | AT5: =$C5*AS5 -> 0 | AV5: =$C5*AU5 -> 0 | AX5: =$C5*AW5 -> 0 | AZ5: =$C5*AY5 -> 0 | BB5: =$C5*BA5 -> 0 | BD5: =$C5*BC5 -> 0 | BF5: =$C5*BE5 -> 0 | BH5: =$C5*BG5 -> 0 | BJ5: =$C5*BI5 -> 0 | BL5: =$C5*BK5 -> 0 | BN5: =$C5*BM5 -> 0 | BP5: =$C5*BO5 -> 0 | BR5: =$C5*BQ5 -> 0 | BT5: =$C5*BS5 -> 0 | BV5: =$C5*BU5 -> 0 | BX5: =$C5*BW5 -> 0 | BZ5: =$C5*BY5 -> 0 | CB5: =$C5*CA5 -> 0 | CD5: =$C5*CC5 -> 0 | CF5: =$C5*CE5 -> 0 | CH5: =$C5*CG5 -> 0
B6: CONTENÇÃO | C6: 5278318.1 | D6: 0.070585399 | E6: =SUM(G6,I6,K6,M6,O6,Q6,S6,U6,W6,Y6,AA6,AC6,AE6,AG6,AI6,,AK6,AM6,AO6,AQ6,AS6,AU6,AW6,AY6,BA6,BC6,BE6,BG6,BI6,BK6,BM6,BO6,BQ6,BS6,BU6,BW6,BY6,CA6,CC6,CE6,CG6) -> 1 | F6: =H6+J6+L6+N6+P6+R6+T6+V6+X6+Z6+AB6+AD6+AF6+AH6+AJ6+AL6+AN6+AP6+AR6+AT6+AV6+AX6+AZ6+BB6+BD6+BF6+BH6+BJ6+BL6+BN6+BP6+BR6+BT6+BV6+BX6+BZ6 -> 5278318.1 | H6: =$C6*G6 -> 0 | I6: 0.33333333 | J6: =$C6*I6 -> 1759439.4 | K6: 0.33333333 | L6: =$C6*K6 -> 1759439.4 | M6: 0.33333333 | N6: =$C6*M6 -> 1759439.4
B7: INFRAESTRUTURA | C7: 1644604.6 | D7: 0.021992815 | E7: =SUM(G7,I7,K7,M7,O7,Q7,S7,U7,W7,Y7,AA7,AC7,AE7,AG7,AI7,,AK7,AM7,AO7,AQ7,AS7,AU7,AW7,AY7,BA7,BC7,BE7,BG7,BI7,BK7,BM7,BO7,BQ7,BS7,BU7,BW7,BY7,CA7,CC7,CE7,CG7) -> 1 | F7: =H7+J7+L7+N7+P7+R7+T7+V7+X7+Z7+AB7+AD7+AF7+AH7+AJ7+AL7+AN7+AP7+AR7+AT7+AV7+AX7+AZ7+BB7+BD7+BF7+BH7+BJ7+BL7+BN7+BP7+BR7+BT7+BV7+BX7+BZ7 -> 1644604.6 | H7: =$C7*G7 -> 0 | J7: =$C7*I7 -> 0 | L7: =$C7*K7 -> 0 | M7: 0.25 | N7: =$C7*M7 -> 411151.14 | O7: 0.25 | P7: =$C7*O7 -> 411151.14 | Q7: 0.25 | R7: =$C7*Q7 -> 411151.14 | S7: 0.25 | T7: =$C7*S7 -> 411151.14 | V7: =$C7*U7 -> 0 | X7: =$C7*W7 -> 0 | Z7: =$C7*Y7 -> 0 | AB7: =$C7*AA7 -> 0 | AD7: =$C7*AC7 -> 0 | AF7: =$C7*AE7 -> 0 | AH7: =$C7*AG7 -> 0 | AJ7: =$C7*AI7 -> 0 | AL7: =$C7*AK7 -> 0 | AN7: =$C7*AM7 -> 0 | AP7: =$C7*AO7 -> 0 | AR7: =$C7*AQ7 -> 0 | AT7: =$C7*AS7 -> 0 | AV7: =$C7*AU7 -> 0 | AX7: =$C7*AW7 -> 0 | AZ7: =$C7*AY7 -> 0 | BB7: =$C7*BA7 -> 0 | BD7: =$C7*BC7 -> 0 | BF7: =$C7*BE7 -> 0 | BH7: =$C7*BG7 -> 0 | BJ7: =$C7*BI7 -> 0 | BL7: =$C7*BK7 -> 0 | BN7: =$C7*BM7 -> 0 | BP7: =$C7*BO7 -> 0 | BR7: =$C7*BQ7 -> 0 | BT7: =$C7*BS7 -> 0 | BV7: =$C7*BU7 -> 0 | BX7: =$C7*BW7 -> 0 | BZ7: =$C7*BY7 -> 0 | CB7: =$C7*CA7 -> 0 | CD7: =$C7*CC7 -> 0 | CF7: =$C7*CE7 -> 0 | CH7: =$C7*CG7 -> 0
B8: SUPRAESTRUTURA | C8: 13332389 | D8: 0.17829013 | E8: =SUM(G8,I8,K8,M8,O8,Q8,S8,U8,W8,Y8,AA8,AC8,AE8,AG8,AI8,,AK8,AM8,AO8,AQ8,AS8,AU8,AW8,AY8,BA8,BC8,BE8,BG8,BI8,BK8,BM8,BO8,BQ8,BS8,BU8,BW8,BY8,CA8,CC8,CE8,CG8) -> 1 | F8: =H8+J8+L8+N8+P8+R8+T8+V8+X8+Z8+AB8+AD8+AF8+AH8+AJ8+AL8+AN8+AP8+AR8+AT8+AV8+AX8+AZ8+BB8+BD8+BF8+BH8+BJ8+BL8+BN8+BP8+BR8+BT8+BV8+BX8+BZ8 -> 13332389 | H8: =$C8*G8 -> 0 | J8: =$C8*I8 -> 0 | L8: =$C8*K8 -> 0 | N8: =$C8*M8 -> 0 | P8: =$C8*O8 -> 0 | R8: =$C8*Q8 -> 0 | T8: =$C8*S8 -> 0 | U8: 0.0475 | V8: =$C8*U8 -> 633288.48 | W8: 0.086590909 | X8: =$C8*W8 -> 1154463.7 | Y8: 0.086590909 | Z8: =$C8*Y8 -> 1154463.7 | AA8: 0.086590909 | AB8: =$C8*AA8 -> 1154463.7 | AC8: 0.086590909 | AD8: =$C8*AC8 -> 1154463.7 | AE8: 0.086590909 | AF8: =$C8*AE8 -> 1154463.7 | AG8: 0.086590909 | AH8: =$C8*AG8 -> 1154463.7 | AI8: 0.086590909 | AJ8: =$C8*AI8 -> 1154463.7 | AK8: 0.086590909 | AL8: =$C8*AK8 -> 1154463.7 | AM8: 0.086590909 | AN8: =$C8*AM8 -> 1154463.7 | AO8: 0.086590909 | AP8: =$C8*AO8 -> 1154463.7 | AQ8: 0.086590909 | AR8: =$C8*AQ8 -> 1154463.7 | AT8: =$C8*AS8 -> 0 | AV8: =$C8*AU8 -> 0 | AX8: =$C8*AW8 -> 0 | AZ8: =$C8*AY8 -> 0 | BB8: =$C8*BA8 -> 0 | BD8: =$C8*BC8 -> 0 | BF8: =$C8*BE8 -> 0 | BH8: =$C8*BG8 -> 0 | BJ8: =$C8*BI8 -> 0 | BL8: =$C8*BK8 -> 0 | BN8: =$C8*BM8 -> 0 | BP8: =$C8*BO8 -> 0 | BR8: =$C8*BQ8 -> 0 | BT8: =$C8*BS8 -> 0 | BV8: =$C8*BU8 -> 0 | BX8: =$C8*BW8 -> 0 | BZ8: =$C8*BY8 -> 0 | CB8: =$C8*CA8 -> 0 | CD8: =$C8*CC8 -> 0 | CF8: =$C8*CE8 -> 0 | CH8: =$C8*CG8 -> 0
B9: ALVENARIA | C9: 3148673.4 | D9: 0.042106285 | E9: =SUM(G9,I9,K9,M9,O9,Q9,S9,U9,W9,Y9,AA9,AC9,AE9,AG9,AI9,,AK9,AM9,AO9,AQ9,AS9,AU9,AW9,AY9,BA9,BC9,BE9,BG9,BI9,BK9,BM9,BO9,BQ9,BS9,BU9,BW9,BY9,CA9,CC9,CE9,CG9) -> 1 | F9: =H9+J9+L9+N9+P9+R9+T9+V9+X9+Z9+AB9+AD9+AF9+AH9+AJ9+AL9+AN9+AP9+AR9+AT9+AV9+AX9+AZ9+BB9+BD9+BF9+BH9+BJ9+BL9+BN9+BP9+BR9+BT9+BV9+BX9+BZ9 -> 3148673.4 | H9: =$C9*G9 -> 0 | J9: =$C9*I9 -> 0 | L9: =$C9*K9 -> 0 | N9: =$C9*M9 -> 0 | P9: =$C9*O9 -> 0 | R9: =$C9*Q9 -> 0 | T9: =$C9*S9 -> 0 | V9: =$C9*U9 -> 0 | X9: =$C9*W9 -> 0 | Z9: =$C9*Y9 -> 0 | AA9: 0.033529412 | AB9: =$C9*AA9 -> 105573.17 | AC9: 0.060404412 | AD9: =$C9*AC9 -> 190193.76 | AE9: 0.060404412 | AF9: =$C9*AE9 -> 190193.76 | AG9: 0.060404412 | AH9: =$C9*AG9 -> 190193.76 | AI9: 0.060404412 | AJ9: =$C9*AI9 -> 190193.76 | AK9: 0.060404412 | AL9: =$C9*AK9 -> 190193.76 | AM9: 0.060404412 | AN9: =$C9*AM9 -> 190193.76 | AO9: 0.060404412 | AP9: =$C9*AO9 -> 190193.76 | AQ9: 0.060404412 | AR9: =$C9*AQ9 -> 190193.76 | AS9: 0.060404412 | AT9: =$C9*AS9 -> 190193.76 | AU9: 0.060404412 | AV9: =$C9*AU9 -> 190193.76 | AW9: 0.060404412 | AX9: =$C9*AW9 -> 190193.76 | AY9: 0.060404412 | AZ9: =$C9*AY9 -> 190193.76 | BA9: 0.060404412 | BB9: =$C9*BA9 -> 190193.76 | BC9: 0.060404412 | BD9: =$C9*BC9 -> 190193.76 | BE9: 0.060404412 | BF9: =$C9*BE9 -> 190193.76 | BG9: 0.060404412 | BH9: =$C9*BG9 -> 190193.76 | BJ9: =$C9*BI9 -> 0 | BL9: =$C9*BK9 -> 0 | BN9: =$C9*BM9 -> 0 | BP9: =$C9*BO9 -> 0 | BR9: =$C9*BQ9 -> 0 | BT9: =$C9*BS9 -> 0 | BV9: =$C9*BU9 -> 0 | BX9: =$C9*BW9 -> 0 | BZ9: =$C9*BY9 -> 0 | CB9: =$C9*CA9 -> 0 | CD9: =$C9*CC9 -> 0 | CF9: =$C9*CE9 -> 0 | CH9: =$C9*CG9 -> 0
B10: INSTALAÇÕES ELÉTRICAS, HIDRÁULICAS, GLP E PREVENTIVAS | C10: 5267209.7 | D10: 0.070436851 | E10: =SUM(G10,I10,K10,M10,O10,Q10,S10,U10,W10,Y10,AA10,AC10,AE10,AG10,AI10,,AK10,AM10,AO10,AQ10,AS10,AU10,AW10,AY10,BA10,BC10,BE10,BG10,BI10,BK10,BM10,BO10,BQ10,BS10,BU10,BW10,BY10,CA10,CC10,CE10,CG10) -> 1 | F10: =H10+J10+L10+N10+P10+R10+T10+V10+X10+Z10+AB10+AD10+AF10+AH10+AJ10+AL10+AN10+AP10+AR10+AT10+AV10+AX10+AZ10+BB10+BD10+BF10+BH10+BJ10+BL10+BN10+BP10+BR10+BT10+BV10+BX10+BZ10 -> 5267209.7 | H10: =$C10*G10 -> 0 | J10: =$C10*I10 -> 0 | L10: =$C10*K10 -> 0 | N10: =$C10*M10 -> 0 | P10: =$C10*O10 -> 0 | R10: =$C10*Q10 -> 0 | T10: =$C10*S10 -> 0 | V10: =$C10*U10 -> 0 | X10: =$C10*W10 -> 0 | Z10: =$C10*Y10 -> 0 | AB10: =$C10*AA10 -> 0 | AD10: =$C10*AC10 -> 0 | AE10: 0.071428571 | AF10: =$C10*AE10 -> 376229.27 | AG10: 0.071428571 | AH10: =$C10*AG10 -> 376229.27 | AI10: 0.071428571 | AJ10: =$C10*AI10 -> 376229.27 | AK10: 0.071428571 | AL10: =$C10*AK10 -> 376229.27 | AM10: 0.071428571 | AN10: =$C10*AM10 -> 376229.27 | AO10: 0.071428571 | AP10: =$C10*AO10 -> 376229.27 | AQ10: 0.071428571 | AR10: =$C10*AQ10 -> 376229.27 | AS10: 0.071428571 | AT10: =$C10*AS10 -> 376229.27 | AU10: 0.071428571 | AV10: =$C10*AU10 -> 376229.27 | AW10: 0.071428571 | AX10: =$C10*AW10 -> 376229.27 | AY10: 0.071428571 | AZ10: =$C10*AY10 -> 376229.27 | BA10: 0.071428571 | BB10: =$C10*BA10 -> 376229.27 | BC10: 0.071428571 | BD10: =$C10*BC10 -> 376229.27 | BE10: 0.071428571 | BF10: =$C10*BE10 -> 376229.27 | BH10: =$C10*BG10 -> 0 | BJ10: =$C10*BI10 -> 0 | BL10: =$C10*BK10 -> 0 | BN10: =$C10*BM10 -> 0 | BP10: =$C10*BO10 -> 0 | BR10: =$C10*BQ10 -> 0 | BT10: =$C10*BS10 -> 0 | BV10: =$C10*BU10 -> 0 | BX10: =$C10*BW10 -> 0 | BZ10: =$C10*BY10 -> 0 | CB10: =$C10*CA10 -> 0 | CD10: =$C10*CC10 -> 0 | CF10: =$C10*CE10 -> 0 | CH10: =$C10*CG10 -> 0
B11: EQUIPAMENTOS E SISTEMAS ESPECIAIS | C11: 6870035.2 | D11: 0.091870965 | E11: =SUM(G11,I11,K11,M11,O11,Q11,S11,U11,W11,Y11,AA11,AC11,AE11,AG11,AI11,,AK11,AM11,AO11,AQ11,AS11,AU11,AW11,AY11,BA11,BC11,BE11,BG11,BI11,BK11,BM11,BO11,BQ11,BS11,BU11,BW11,BY11,CA11,CC11,CE11,CG11) -> 1 | F11: =H11+J11+L11+N11+P11+R11+T11+V11+X11+Z11+AB11+AD11+AF11+AH11+AJ11+AL11+AN11+AP11+AR11+AT11+AV11+AX11+AZ11+BB11+BD11+BF11+BH11+BJ11+BL11+BN11+BP11+BR11+BT11+BV11+BX11+BZ11 -> 6870035.2 | H11: =$C11*G11 -> 0 | J11: =$C11*I11 -> 0 | L11: =$C11*K11 -> 0 | N11: =$C11*M11 -> 0 | P11: =$C11*O11 -> 0 | R11: =$C11*Q11 -> 0 | T11: =$C11*S11 -> 0 | V11: =$C11*U11 -> 0 | X11: =$C11*W11 -> 0 | Z11: =$C11*Y11 -> 0 | AB11: =$C11*AA11 -> 0 | AD11: =$C11*AC11 -> 0 | AF11: =$C11*AE11 -> 0 | AH11: =$C11*AG11 -> 0 | AJ11: =$C11*AI11 -> 0 | AL11: =$C11*AK11 -> 0 | AN11: =$C11*AM11 -> 0 | AP11: =$C11*AO11 -> 0 | AR11: =$C11*AQ11 -> 0 | AS11: =100%/16 -> 0.0625 | AT11: =$C11*AS11 -> 429377.2 | AU11: =100%/16 -> 0.0625 | AV11: =$C11*AU11 -> 429377.2 | AW11: =100%/16 -> 0.0625 | AX11: =$C11*AW11 -> 429377.2 | AY11: =100%/16 -> 0.0625 | AZ11: =$C11*AY11 -> 429377.2 | BA11: =100%/16 -> 0.0625 | BB11: =$C11*BA11 -> 429377.2 | BC11: =100%/16 -> 0.0625 | BD11: =$C11*BC11 -> 429377.2 | BE11: =100%/16 -> 0.0625 | BF11: =$C11*BE11 -> 429377.2 | BG11: =100%/16 -> 0.0625 | BH11: =$C11*BG11 -> 429377.2 | BI11: =100%/16 -> 0.0625 | BJ11: =$C11*BI11 -> 429377.2 | BK11: =100%/16 -> 0.0625 | BL11: =$C11*BK11 -> 429377.2 | BM11: =100%/16 -> 0.0625 | BN11: =$C11*BM11 -> 429377.2 | BO11: =100%/16 -> 0.0625 | BP11: =$C11*BO11 -> 429377.2 | BQ11: =100%/16 -> 0.0625 | BR11: =$C11*BQ11 -> 429377.2 | BS11: =100%/16 -> 0.0625 | BT11: =$C11*BS11 -> 429377.2 | BU11: =100%/16 -> 0.0625 | BV11: =$C11*BU11 -> 429377.2 | BW11: =100%/16 -> 0.0625 | BX11: =$C11*BW11 -> 429377.2 | BZ11: =$C11*BY11 -> 0 | CB11: =$C11*CA11 -> 0 | CD11: =$C11*CC11 -> 0 | CF11: =$C11*CE11 -> 0 | CH11: =$C11*CG11 -> 0
B12: IMPERMEABILIZAÇÃO | C12: 1100757.3 | D12: 0.014720105 | E12: =SUM(G12,I12,K12,M12,O12,Q12,S12,U12,W12,Y12,AA12,AC12,AE12,AG12,AI12,,AK12,AM12,AO12,AQ12,AS12,AU12,AW12,AY12,BA12,BC12,BE12,BG12,BI12,BK12,BM12,BO12,BQ12,BS12,BU12,BW12,BY12,CA12,CC12,CE12,CG12) -> 1 | F12: =H12+J12+L12+N12+P12+R12+T12+V12+X12+Z12+AB12+AD12+AF12+AH12+AJ12+AL12+AN12+AP12+AR12+AT12+AV12+AX12+AZ12+BB12+BD12+BF12+BH12+BJ12+BL12+BN12+BP12+BR12+BT12+BV12+BX12+BZ12 -> 1100757.3 | H12: =$C12*G12 -> 0 | J12: =$C12*I12 -> 0 | L12: =$C12*K12 -> 0 | N12: =$C12*M12 -> 0 | P12: =$C12*O12 -> 0 | R12: =$C12*Q12 -> 0 | T12: =$C12*S12 -> 0 | V12: =$C12*U12 -> 0 | X12: =$C12*W12 -> 0 | Z12: =$C12*Y12 -> 0 | AB12: =$C12*AA12 -> 0 | AD12: =$C12*AC12 -> 0 | AF12: =$C12*AE12 -> 0 | AH12: =$C12*AG12 -> 0 | AJ12: =$C12*AI12 -> 0 | AK12: 0.076923077 | AL12: =$C12*AK12 -> 84673.642 | AM12: 0.076923077 | AN12: =$C12*AM12 -> 84673.642 | AO12: 0.076923077 | AP12: =$C12*AO12 -> 84673.642 | AQ12: 0.076923077 | AR12: =$C12*AQ12 -> 84673.642 | AS12: 0.076923077 | AT12: =$C12*AS12 -> 84673.642 | AU12: 0.076923077 | AV12: =$C12*AU12 -> 84673.642 | AW12: 0.076923077 | AX12: =$C12*AW12 -> 84673.642 | AY12: 0.076923077 | AZ12: =$C12*AY12 -> 84673.642 | BA12: 0.076923077 | BB12: =$C12*BA12 -> 84673.642 | BC12: 0.076923077 | BD12: =$C12*BC12 -> 84673.642 | BE12: 0.076923077 | BF12: =$C12*BE12 -> 84673.642 | BG12: 0.076923077 | BH12: =$C12*BG12 -> 84673.642 | BI12: 0.076923077 | BJ12: =$C12*BI12 -> 84673.642 | BL12: =$C12*BK12 -> 0 | BN12: =$C12*BM12 -> 0 | BP12: =$C12*BO12 -> 0 | BR12: =$C12*BQ12 -> 0 | BT12: =$C12*BS12 -> 0 | BV12: =$C12*BU12 -> 0 | BX12: =$C12*BW12 -> 0 | BZ12: =$C12*BY12 -> 0 | CB12: =$C12*CA12 -> 0 | CD12: =$C12*CC12 -> 0 | CF12: =$C12*CE12 -> 0 | CH12: =$C12*CG12 -> 0
B13: REVESTIMENTOS INTERNOS EM PISO E PAREDE | C13: 1637724.6 | D13: 0.02190081 | E13: =SUM(G13,I13,K13,M13,O13,Q13,S13,U13,W13,Y13,AA13,AC13,AE13,AG13,AI13,,AK13,AM13,AO13,AQ13,AS13,AU13,AW13,AY13,BA13,BC13,BE13,BG13,BI13,BK13,BM13,BO13,BQ13,BS13,BU13,BW13,BY13,CA13,CC13,CE13,CG13) -> 1 | F13: =H13+J13+L13+N13+P13+R13+T13+V13+X13+Z13+AB13+AD13+AF13+AH13+AJ13+AL13+AN13+AP13+AR13+AT13+AV13+AX13+AZ13+BB13+BD13+BF13+BH13+BJ13+BL13+BN13+BP13+BR13+BT13+BV13+BX13+BZ13 -> 1637724.6 | H13: =$C13*G13 -> 0 | J13: =$C13*I13 -> 0 | L13: =$C13*K13 -> 0 | N13: =$C13*M13 -> 0 | P13: =$C13*O13 -> 0 | R13: =$C13*Q13 -> 0 | T13: =$C13*S13 -> 0 | V13: =$C13*U13 -> 0 | X13: =$C13*W13 -> 0 | Z13: =$C13*Y13 -> 0 | AB13: =$C13*AA13 -> 0 | AD13: =$C13*AC13 -> 0 | AF13: =$C13*AE13 -> 0 | AG13: 0.043846154 | AH13: =$C13*AG13 -> 71807.923 | AI13: 0.079679487 | AJ13: =$C13*AI13 -> 130493.05 | AK13: 0.079679487 | AL13: =$C13*AK13 -> 130493.05 | AM13: 0.079679487 | AN13: =$C13*AM13 -> 130493.05 | AO13: 0.079679487 | AP13: =$C13*AO13 -> 130493.05 | AQ13: 0.079679487 | AR13: =$C13*AQ13 -> 130493.05 | AS13: 0.079679487 | AT13: =$C13*AS13 -> 130493.05 | AU13: 0.079679487 | AV13: =$C13*AU13 -> 130493.05 | AW13: 0.079679487 | AX13: =$C13*AW13 -> 130493.05 | AY13: 0.079679487 | AZ13: =$C13*AY13 -> 130493.05 | BA13: 0.079679487 | BB13: =$C13*BA13 -> 130493.05 | BC13: 0.079679487 | BD13: =$C13*BC13 -> 130493.05 | BE13: 0.079679487 | BF13: =$C13*BE13 -> 130493.05 | BH13: =$C13*BG13 -> 0 | BJ13: =$C13*BI13 -> 0 | BL13: =$C13*BK13 -> 0 | BN13: =$C13*BM13 -> 0 | BP13: =$C13*BO13 -> 0 | BR13: =$C13*BQ13 -> 0 | BT13: =$C13*BS13 -> 0 | BV13: =$C13*BU13 -> 0 | BX13: =$C13*BW13 -> 0 | BZ13: =$C13*BY13 -> 0 | CB13: =$C13*CA13 -> 0 | CD13: =$C13*CC13 -> 0 | CF13: =$C13*CE13 -> 0 | CH13: =$C13*CG13 -> 0
B14: REVESTIMENTOS E ACABAMENTOS INTERNOS EM TETO | C14: 1292981.4 | D14: 0.017290661 | E14: =SUM(G14,I14,K14,M14,O14,Q14,S14,U14,W14,Y14,AA14,AC14,AE14,AG14,AI14,,AK14,AM14,AO14,AQ14,AS14,AU14,AW14,AY14,BA14,BC14,BE14,BG14,BI14,BK14,BM14,BO14,BQ14,BS14,BU14,BW14,BY14,CA14,CC14,CE14,CG14) -> 1 | F14: =H14+J14+L14+N14+P14+R14+T14+V14+X14+Z14+AB14+AD14+AF14+AH14+AJ14+AL14+AN14+AP14+AR14+AT14+AV14+AX14+AZ14+BB14+BD14+BF14+BH14+BJ14+BL14+BN14+BP14+BR14+BT14+BV14+BX14+BZ14 -> 1292981.4 | H14: =$C14*G14 -> 0 | J14: =$C14*I14 -> 0 | L14: =$C14*K14 -> 0 | N14: =$C14*M14 -> 0 | P14: =$C14*O14 -> 0 | R14: =$C14*Q14 -> 0 | T14: =$C14*S14 -> 0 | V14: =$C14*U14 -> 0 | X14: =$C14*W14 -> 0 | Z14: =$C14*Y14 -> 0 | AB14: =$C14*AA14 -> 0 | AD14: =$C14*AC14 -> 0 | AF14: =$C14*AE14 -> 0 | AH14: =$C14*AG14 -> 0 | AJ14: =$C14*AI14 -> 0 | AL14: =$C14*AK14 -> 0 | AM14: 0.040714286 | AN14: =$C14*AM14 -> 52642.815 | AO14: 0.073791209 | AP14: =$C14*AO14 -> 95410.662 | AQ14: 0.073791209 | AR14: =$C14*AQ14 -> 95410.662 | AS14: 0.073791209 | AT14: =$C14*AS14 -> 95410.662 | AU14: 0.073791209 | AV14: =$C14*AU14 -> 95410.662 | AW14: 0.073791209 | AX14: =$C14*AW14 -> 95410.662 | AY14: 0.073791209 | AZ14: =$C14*AY14 -> 95410.662 | BA14: 0.073791209 | BB14: =$C14*BA14 -> 95410.662 | BC14: 0.073791209 | BD14: =$C14*BC14 -> 95410.662 | BE14: 0.073791209 | BF14: =$C14*BE14 -> 95410.662 | BG14: 0.073791209 | BH14: =$C14*BG14 -> 95410.662 | BI14: 0.073791209 | BJ14: =$C14*BI14 -> 95410.662 | BK14: 0.073791209 | BL14: =$C14*BK14 -> 95410.662 | BM14: 0.073791209 | BN14: =$C14*BM14 -> 95410.662 | BP14: =$C14*BO14 -> 0 | BR14: =$C14*BQ14 -> 0 | BT14: =$C14*BS14 -> 0 | BV14: =$C14*BU14 -> 0 | BX14: =$C14*BW14 -> 0 | BZ14: =$C14*BY14 -> 0 | CB14: =$C14*CA14 -> 0 | CD14: =$C14*CC14 -> 0 | CF14: =$C14*CE14 -> 0 | CH14: =$C14*CG14 -> 0
B15: ACABAMENTOS EM PISO E PAREDE | C15: 4169253.4 | D15: 0.055754203 | E15: =SUM(G15,I15,K15,M15,O15,Q15,S15,U15,W15,Y15,AA15,AC15,AE15,AG15,AI15,,AK15,AM15,AO15,AQ15,AS15,AU15,AW15,AY15,BA15,BC15,BE15,BG15,BI15,BK15,BM15,BO15,BQ15,BS15,BU15,BW15,BY15,CA15,CC15,CE15,CG15) -> 1 | F15: =H15+J15+L15+N15+P15+R15+T15+V15+X15+Z15+AB15+AD15+AF15+AH15+AJ15+AL15+AN15+AP15+AR15+AT15+AV15+AX15+AZ15+BB15+BD15+BF15+BH15+BJ15+BL15+BN15+BP15+BR15+BT15+BV15+BX15+BZ15 -> 4169253.4 | H15: =$C15*G15 -> 0 | J15: =$C15*I15 -> 0 | L15: =$C15*K15 -> 0 | N15: =$C15*M15 -> 0 | P15: =$C15*O15 -> 0 | R15: =$C15*Q15 -> 0 | T15: =$C15*S15 -> 0 | V15: =$C15*U15 -> 0 | X15: =$C15*W15 -> 0 | Z15: =$C15*Y15 -> 0 | AB15: =$C15*AA15 -> 0 | AD15: =$C15*AC15 -> 0 | AF15: =$C15*AE15 -> 0 | AH15: =$C15*AG15 -> 0 | AJ15: =$C15*AI15 -> 0 | AK15: 0.040714286 | AL15: =$C15*AK15 -> 169748.18 | AM15: 0.073791209 | AN15: =$C15*AM15 -> 307654.25 | AO15: 0.073791209 | AP15: =$C15*AO15 -> 307654.25 | AQ15: 0.073791209 | AR15: =$C15*AQ15 -> 307654.25 | AS15: 0.073791209 | AT15: =$C15*AS15 -> 307654.25 | AU15: 0.073791209 | AV15: =$C15*AU15 -> 307654.25 | AW15: 0.073791209 | AX15: =$C15*AW15 -> 307654.25 | AY15: 0.073791209 | AZ15: =$C15*AY15 -> 307654.25 | BA15: 0.073791209 | BB15: =$C15*BA15 -> 307654.25 | BC15: 0.073791209 | BD15: =$C15*BC15 -> 307654.25 | BE15: 0.073791209 | BF15: =$C15*BE15 -> 307654.25 | BG15: 0.073791209 | BH15: =$C15*BG15 -> 307654.25 | BI15: 0.073791209 | BJ15: =$C15*BI15 -> 307654.25 | BK15: 0.073791209 | BL15: =$C15*BK15 -> 307654.25 | BN15: =$C15*BM15 -> 0 | BP15: =$C15*BO15 -> 0 | BR15: =$C15*BQ15 -> 0 | BT15: =$C15*BS15 -> 0 | BV15: =$C15*BU15 -> 0 | BX15: =$C15*BW15 -> 0 | BZ15: =$C15*BY15 -> 0 | CB15: =$C15*CA15 -> 0 | CD15: =$C15*CC15 -> 0 | CF15: =$C15*CE15 -> 0 | CH15: =$C15*CG15 -> 0
B16: PINTURA INTERNA | C16: 2000841.4 | D16: 0.026756665 | E16: =SUM(G16,I16,K16,M16,O16,Q16,S16,U16,W16,Y16,AA16,AC16,AE16,AG16,AI16,,AK16,AM16,AO16,AQ16,AS16,AU16,AW16,AY16,BA16,BC16,BE16,BG16,BI16,BK16,BM16,BO16,BQ16,BS16,BU16,BW16,BY16,CA16,CC16,CE16,CG16) -> 1 | F16: =H16+J16+L16+N16+P16+R16+T16+V16+X16+Z16+AB16+AD16+AF16+AH16+AJ16+AL16+AN16+AP16+AR16+AT16+AV16+AX16+AZ16+BB16+BD16+BF16+BH16+BJ16+BL16+BN16+BP16+BR16+BT16+BV16+BX16+BZ16 -> 2000841.4 | H16: =$C16*G16 -> 0 | J16: =$C16*I16 -> 0 | L16: =$C16*K16 -> 0 | N16: =$C16*M16 -> 0 | P16: =$C16*O16 -> 0 | R16: =$C16*Q16 -> 0 | T16: =$C16*S16 -> 0 | V16: =$C16*U16 -> 0 | X16: =$C16*W16 -> 0 | Z16: =$C16*Y16 -> 0 | AB16: =$C16*AA16 -> 0 | AD16: =$C16*AC16 -> 0 | AF16: =$C16*AE16 -> 0 | AH16: =$C16*AG16 -> 0 | AJ16: =$C16*AI16 -> 0 | AL16: =$C16*AK16 -> 0 | AN16: =$C16*AM16 -> 0 | AO16: =100%/19 -> 0.052631579 | AP16: =$C16*AO16 -> 105307.44 | AQ16: =100%/19 -> 0.052631579 | AR16: =$C16*AQ16 -> 105307.44 | AS16: =100%/19 -> 0.052631579 | AT16: =$C16*AS16 -> 105307.44 | AU16: =100%/19 -> 0.052631579 | AV16: =$C16*AU16 -> 105307.44 | AW16: =100%/19 -> 0.052631579 | AX16: =$C16*AW16 -> 105307.44 | AY16: =100%/19 -> 0.052631579 | AZ16: =$C16*AY16 -> 105307.44 | BA16: =100%/19 -> 0.052631579 | BB16: =$C16*BA16 -> 105307.44 | BC16: =100%/19 -> 0.052631579 | BD16: =$C16*BC16 -> 105307.44 | BE16: =100%/19 -> 0.052631579 | BF16: =$C16*BE16 -> 105307.44 | BG16: =100%/19 -> 0.052631579 | BH16: =$C16*BG16 -> 105307.44 | BI16: =100%/19 -> 0.052631579 | BJ16: =$C16*BI16 -> 105307.44 | BK16: =100%/19 -> 0.052631579 | BL16: =$C16*BK16 -> 105307.44 | BM16: =100%/19 -> 0.052631579 | BN16: =$C16*BM16 -> 105307.44 | BO16: =100%/19 -> 0.052631579 | BP16: =$C16*BO16 -> 105307.44 | BQ16: =100%/19 -> 0.052631579 | BR16: =$C16*BQ16 -> 105307.44 | BS16: =100%/19 -> 0.052631579 | BT16: =$C16*BS16 -> 105307.44 | BU16: =100%/19 -> 0.052631579 | BV16: =$C16*BU16 -> 105307.44 | BW16: =100%/19 -> 0.052631579 | BX16: =$C16*BW16 -> 105307.44 | BY16: =100%/19 -> 0.052631579 | BZ16: =$C16*BY16 -> 105307.44 | CB16: =$C16*CA16 -> 0 | CD16: =$C16*CC16 -> 0 | CF16: =$C16*CE16 -> 0 | CH16: =$C16*CG16 -> 0
B17: ESQUADRIAS, VIDROS E FERRAGENS | C17: 9377705.7 | D17: 0.12540531 | E17: =SUM(G17,I17,K17,M17,O17,Q17,S17,U17,W17,Y17,AA17,AC17,AE17,AG17,AI17,,AK17,AM17,AO17,AQ17,AS17,AU17,AW17,AY17,BA17,BC17,BE17,BG17,BI17,BK17,BM17,BO17,BQ17,BS17,BU17,BW17,BY17,CA17,CC17,CE17,CG17) -> 1 | F17: =H17+J17+L17+N17+P17+R17+T17+V17+X17+Z17+AB17+AD17+AF17+AH17+AJ17+AL17+AN17+AP17+AR17+AT17+AV17+AX17+AZ17+BB17+BD17+BF17+BH17+BJ17+BL17+BN17+BP17+BR17+BT17+BV17+BX17+BZ17 -> 9377705.7 | H17: =$C17*G17 -> 0 | J17: =$C17*I17 -> 0 | L17: =$C17*K17 -> 0 | N17: =$C17*M17 -> 0 | P17: =$C17*O17 -> 0 | R17: =$C17*Q17 -> 0 | T17: =$C17*S17 -> 0 | V17: =$C17*U17 -> 0 | X17: =$C17*W17 -> 0 | Z17: =$C17*Y17 -> 0 | AB17: =$C17*AA17 -> 0 | AD17: =$C17*AC17 -> 0 | AF17: =$C17*AE17 -> 0 | AH17: =$C17*AG17 -> 0 | AJ17: =$C17*AI17 -> 0 | AL17: =$C17*AK17 -> 0 | AN17: =$C17*AM17 -> 0 | AP17: =$C17*AO17 -> 0 | AR17: =$C17*AQ17 -> 0 | AT17: =$C17*AS17 -> 0 | AV17: =$C17*AU17 -> 0 | AX17: =$C17*AW17 -> 0 | AZ17: =$C17*AY17 -> 0 | BB17: =$C17*BA17 -> 0 | BD17: =$C17*BC17 -> 0 | BF17: =$C17*BE17 -> 0 | BH17: =$C17*BG17 -> 0 | BI17: 0.125 | BJ17: =$C17*BI17 -> 1172213.2 | BK17: 0.125 | BL17: =$C17*BK17 -> 1172213.2 | BM17: 0.125 | BN17: =$C17*BM17 -> 1172213.2 | BO17: 0.125 | BP17: =$C17*BO17 -> 1172213.2 | BQ17: 0.125 | BR17: =$C17*BQ17 -> 1172213.2 | BS17: 0.125 | BT17: =$C17*BS17 -> 1172213.2 | BU17: 0.125 | BV17: =$C17*BU17 -> 1172213.2 | BW17: 0.125 | BX17: =$C17*BW17 -> 1172213.2 | BZ17: =$C17*BY17 -> 0 | CB17: =$C17*CA17 -> 0 | CD17: =$C17*CC17 -> 0 | CF17: =$C17*CE17 -> 0 | CH17: =$C17*CG17 -> 0
B18: REVESTIMENTOS E ACABAMENTOS DE FACHADA | C18: 3087626.2 | D18: 0.04128992 | E18: =SUM(G18,I18,K18,M18,O18,Q18,S18,U18,W18,Y18,AA18,AC18,AE18,AG18,AI18,,AK18,AM18,AO18,AQ18,AS18,AU18,AW18,AY18,BA18,BC18,BE18,BG18,BI18,BK18,BM18,BO18,BQ18,BS18,BU18,BW18,BY18,CA18,CC18,CE18,CG18) -> 1 | F18: =H18+J18+L18+N18+P18+R18+T18+V18+X18+Z18+AB18+AD18+AF18+AH18+AJ18+AL18+AN18+AP18+AR18+AT18+AV18+AX18+AZ18+BB18+BD18+BF18+BH18+BJ18+BL18+BN18+BP18+BR18+BT18+BV18+BX18+BZ18 -> 3087626.2 | H18: =$C18*G18 -> 0 | J18: =$C18*I18 -> 0 | L18: =$C18*K18 -> 0 | N18: =$C18*M18 -> 0 | P18: =$C18*O18 -> 0 | R18: =$C18*Q18 -> 0 | T18: =$C18*S18 -> 0 | V18: =$C18*U18 -> 0 | X18: =$C18*W18 -> 0 | Z18: =$C18*Y18 -> 0 | AB18: =$C18*AA18 -> 0 | AD18: =$C18*AC18 -> 0 | AF18: =$C18*AE18 -> 0 | AH18: =$C18*AG18 -> 0 | AJ18: =$C18*AI18 -> 0 | AL18: =$C18*AK18 -> 0 | AN18: =$C18*AM18 -> 0 | AP18: =$C18*AO18 -> 0 | AR18: =$C18*AQ18 -> 0 | AT18: =$C18*AS18 -> 0 | AV18: =$C18*AU18 -> 0 | AX18: =$C18*AW18 -> 0 | AY18: 0.14285714 | AZ18: =$C18*AY18 -> 441089.46 | BA18: 0.14285714 | BB18: =$C18*BA18 -> 441089.46 | BC18: 0.14285714 | BD18: =$C18*BC18 -> 441089.46 | BE18: 0.14285714 | BF18: =$C18*BE18 -> 441089.46 | BG18: 0.14285714 | BH18: =$C18*BG18 -> 441089.46 | BI18: 0.14285714 | BJ18: =$C18*BI18 -> 441089.46 | BK18: 0.14285714 | BL18: =$C18*BK18 -> 441089.46 | BN18: =$C18*BM18 -> 0 | BP18: =$C18*BO18 -> 0 | BR18: =$C18*BQ18 -> 0 | BT18: =$C18*BS18 -> 0 | BV18: =$C18*BU18 -> 0 | BX18: =$C18*BW18 -> 0 | BZ18: =$C18*BY18 -> 0 | CB18: =$C18*CA18 -> 0 | CD18: =$C18*CC18 -> 0 | CF18: =$C18*CE18 -> 0 | CH18: =$C18*CG18 -> 0
B19: SERVIÇOS COMPLEMENTARES | C19: 3416073 | D19: 0.045682142 | E19: =SUM(G19,I19,K19,M19,O19,Q19,S19,U19,W19,Y19,AA19,AC19,AE19,AG19,AI19,,AK19,AM19,AO19,AQ19,AS19,AU19,AW19,AY19,BA19,BC19,BE19,BG19,BI19,BK19,BM19,BO19,BQ19,BS19,BU19,BW19,BY19,CA19,CC19,CE19,CG19) -> 1 | F19: =H19+J19+L19+N19+P19+R19+T19+V19+X19+Z19+AB19+AD19+AF19+AH19+AJ19+AL19+AN19+AP19+AR19+AT19+AV19+AX19+AZ19+BB19+BD19+BF19+BH19+BJ19+BL19+BN19+BP19+BR19+BT19+BV19+BX19+BZ19 -> 3416073 | H19: =$C19*G19 -> 0 | J19: =$C19*I19 -> 0 | L19: =$C19*K19 -> 0 | N19: =$C19*M19 -> 0 | P19: =$C19*O19 -> 0 | R19: =$C19*Q19 -> 0 | T19: =$C19*S19 -> 0 | V19: =$C19*U19 -> 0 | X19: =$C19*W19 -> 0 | Z19: =$C19*Y19 -> 0 | AB19: =$C19*AA19 -> 0 | AD19: =$C19*AC19 -> 0 | AF19: =$C19*AE19 -> 0 | AH19: =$C19*AG19 -> 0 | AJ19: =$C19*AI19 -> 0 | AL19: =$C19*AK19 -> 0 | AN19: =$C19*AM19 -> 0 | AP19: =$C19*AO19 -> 0 | AR19: =$C19*AQ19 -> 0 | AT19: =$C19*AS19 -> 0 | AV19: =$C19*AU19 -> 0 | AX19: =$C19*AW19 -> 0 | AZ19: =$C19*AY19 -> 0 | BB19: =$C19*BA19 -> 0 | BD19: =$C19*BC19 -> 0 | BF19: =$C19*BE19 -> 0 | BH19: =$C19*BG19 -> 0 | BJ19: =$C19*BI19 -> 0 | BK19: 0.125 | BL19: =$C19*BK19 -> 427009.13 | BM19: 0.125 | BN19: =$C19*BM19 -> 427009.13 | BO19: 0.125 | BP19: =$C19*BO19 -> 427009.13 | BQ19: 0.125 | BR19: =$C19*BQ19 -> 427009.13 | BS19: 0.125 | BT19: =$C19*BS19 -> 427009.13 | BU19: 0.125 | BV19: =$C19*BU19 -> 427009.13 | BW19: 0.125 | BX19: =$C19*BW19 -> 427009.13 | BY19: 0.125 | BZ19: =$C19*BY19 -> 427009.13 | CB19: =$C19*CA19 -> 0 | CD19: =$C19*CC19 -> 0 | CF19: =$C19*CE19 -> 0 | CH19: =$C19*CG19 -> 0
B20: IMPREVISTOS E CONTINGENCIAS | C20: 2178034.3 | D20: 0.029126214 | E20: =SUM(G20,I20,K20,M20,O20,Q20,S20,U20,W20,Y20,AA20,AC20,AE20,AG20,AI20,,AK20,AM20,AO20,AQ20,AS20,AU20,AW20,AY20,BA20,BC20,BE20,BG20,BI20,BK20,BM20,BO20,BQ20,BS20,BU20,BW20,BY20,CA20,CC20,CE20,CG20) -> 1 | F20: =H20+J20+L20+N20+P20+R20+T20+V20+X20+Z20+AB20+AD20+AF20+AH20+AJ20+AL20+AN20+AP20+AR20+AT20+AV20+AX20+AZ20+BB20+BD20+BF20+BH20+BJ20+BL20+BN20+BP20+BR20+BT20+BV20+BX20+BZ20 -> 2178034.3 | G20: =100%/$B$27 -> 0.027777778 | H20: =$C20*G20 -> 60500.952 | I20: =100%/$B$27 -> 0.027777778 | J20: =$C20*I20 -> 60500.952 | K20: =100%/$B$27 -> 0.027777778 | L20: =$C20*K20 -> 60500.952 | M20: =100%/$B$27 -> 0.027777778 | N20: =$C20*M20 -> 60500.952 | O20: =100%/$B$27 -> 0.027777778 | P20: =$C20*O20 -> 60500.952 | Q20: =100%/$B$27 -> 0.027777778 | R20: =$C20*Q20 -> 60500.952 | S20: =100%/$B$27 -> 0.027777778 | T20: =$C20*S20 -> 60500.952 | U20: =100%/$B$27 -> 0.027777778 | V20: =$C20*U20 -> 60500.952 | W20: =100%/$B$27 -> 0.027777778 | X20: =$C20*W20 -> 60500.952 | Y20: =100%/$B$27 -> 0.027777778 | Z20: =$C20*Y20 -> 60500.952 | AA20: =100%/$B$27 -> 0.027777778 | AB20: =$C20*AA20 -> 60500.952 | AC20: =100%/$B$27 -> 0.027777778 | AD20: =$C20*AC20 -> 60500.952 | AE20: =100%/$B$27 -> 0.027777778 | AF20: =$C20*AE20 -> 60500.952 | AG20: =100%/$B$27 -> 0.027777778 | AH20: =$C20*AG20 -> 60500.952 | AI20: =100%/$B$27 -> 0.027777778 | AJ20: =$C20*AI20 -> 60500.952 | AK20: =100%/$B$27 -> 0.027777778 | AL20: =$C20*AK20 -> 60500.952 | AM20: =100%/$B$27 -> 0.027777778 | AN20: =$C20*AM20 -> 60500.952 | AO20: =100%/$B$27 -> 0.027777778 | AP20: =$C20*AO20 -> 60500.952 | AQ20: =100%/$B$27 -> 0.027777778 | AR20: =$C20*AQ20 -> 60500.952 | AS20: =100%/$B$27 -> 0.027777778 | AT20: =$C20*AS20 -> 60500.952 | AU20: =100%/$B$27 -> 0.027777778 | AV20: =$C20*AU20 -> 60500.952 | AW20: =100%/$B$27 -> 0.027777778 | AX20: =$C20*AW20 -> 60500.952 | AY20: =100%/$B$27 -> 0.027777778 | AZ20: =$C20*AY20 -> 60500.952 | BA20: =100%/$B$27 -> 0.027777778 | BB20: =$C20*BA20 -> 60500.952 | BC20: =100%/$B$27 -> 0.027777778 | BD20: =$C20*BC20 -> 60500.952 | BE20: =100%/$B$27 -> 0.027777778 | BF20: =$C20*BE20 -> 60500.952 | BG20: =100%/$B$27 -> 0.027777778 | BH20: =$C20*BG20 -> 60500.952 | BI20: =100%/$B$27 -> 0.027777778 | BJ20: =$C20*BI20 -> 60500.952 | BK20: =100%/$B$27 -> 0.027777778 | BL20: =$C20*BK20 -> 60500.952 | BM20: =100%/$B$27 -> 0.027777778 | BN20: =$C20*BM20 -> 60500.952 | BO20: =100%/$B$27 -> 0.027777778 | BP20: =$C20*BO20 -> 60500.952 | BQ20: =100%/$B$27 -> 0.027777778 | BR20: =$C20*BQ20 -> 60500.952 | BS20: =100%/$B$27 -> 0.027777778 | BT20: =$C20*BS20 -> 60500.952 | BU20: =100%/$B$27 -> 0.027777778 | BV20: =$C20*BU20 -> 60500.952 | BW20: =100%/$B$27 -> 0.027777778 | BX20: =$C20*BW20 -> 60500.952 | BY20: =100%/$B$27 -> 0.027777778 | BZ20: =$C20*BY20 -> 60500.952 | CB20: =$C20*CA20 -> 0 | CD20: =$C20*CC20 -> 0 | CF20: =$C20*CE20 -> 0 | CH20: =$C20*CG20 -> 0 | CI20: TOTAL OBRA | CJ20: SOMA TOTAL | CK20: VERIFICAÇÃO
B21: TOTAL | C21: 74779177 | D21: 1 | E21: =SUM(H21:CH21) -> 74779177 | H21: =SUM(H4:H20) -> 1610976.1 | J21: =SUM(J4:J20) -> 2795460.6 | L21: =SUM(L4:L20) -> 2795460.6 | N21: =SUM(N4:N20) -> 3206611.7 | P21: =SUM(P4:P20) -> 834653.29 | R21: =SUM(R4:R20) -> 834653.29 | T21: =SUM(T4:T20) -> 664115.82 | V21: =SUM(V4:V20) -> 886253.15 | X21: =SUM(X4:X20) -> 1407428.4 | Z21: =SUM(Z4:Z20) -> 1407428.4 | AB21: =SUM(AB4:AB20) -> 1513001.5 | AD21: =SUM(AD4:AD20) -> 1597622.1 | AF21: =SUM(AF4:AF20) -> 1973851.4 | AH21: =SUM(AH4:AH20) -> 2045659.3 | AJ21: =SUM(AJ4:AJ20) -> 2104344.4 | AL21: =SUM(AL4:AL20) -> 2358766.3 | AN21: =SUM(AN4:AN20) -> 2549315.1 | AP21: =SUM(AP4:AP20) -> 2697390.4 | AR21: =SUM(AR4:AR20) -> 2697390.4 | AT21: =SUM(AT4:AT20) -> 1972304 | AV21: =SUM(AV4:AV20) -> 1972304 | AX21: =SUM(AX4:AX20) -> 1972304 | AZ21: =SUM(AZ4:AZ20) -> 2413393.4 | BB21: =SUM(BB4:BB20) -> 2413393.4 | BD21: =SUM(BD4:BD20) -> 2413393.4 | BF21: =SUM(BF4:BF20) -> 2413393.4 | BH21: =SUM(BH4:BH20) -> 1906671.1 | BJ21: =SUM(BJ4:BJ20) -> 2888690.5 | BL21: =SUM(BL4:BL20) -> 3231026 | BN21: =SUM(BN4:BN20) -> 2482282.3 | BP21: =SUM(BP4:BP20) -> 2386871.7 | BR21: =SUM(BR4:BR20) -> 2386871.7 | BT21: =SUM(BT4:BT20) -> 2386871.7 | BV21: =SUM(BV4:BV20) -> 2386871.7 | BX21: =SUM(BX4:BX20) -> 2386871.7 | BZ21: =SUM(BZ4:BZ20) -> 785281.24 | CB21: =SUM(CB4:CB20) -> 0 | CD21: =SUM(CD4:CD20) -> 0 | CF21: =SUM(CF4:CF20) -> 0 | CH21: =SUM(CH4:CH20) -> 0 | CI21: =C21 -> 74779177 | CJ21: =SUM(H21:CH21) -> 74779177 | CK21: =C21=CJ21 -> TRUE
B22: CUB/SC | E22: =SUM(H22:CH22) -> 1 | H22: =H21/$CI$21 -> 0.021543111 | J22: =J21/$CI$21 -> 0.037382874 | L22: =L21/$CI$21 -> 0.037382874 | N22: =N21/$CI$21 -> 0.042881078 | P22: =P21/$CI$21 -> 0.011161574 | R22: =R21/$CI$21 -> 0.011161574 | T22: =T21/$CI$21 -> 0.008881026 | V22: =V21/$CI$21 -> 0.011851603 | X22: =X21/$CI$21 -> 0.018821126 | Z22: =Z21/$CI$21 -> 0.018821126 | AB22: =AB21/$CI$21 -> 0.020232925 | AD22: =AD21/$CI$21 -> 0.021364532 | AF22: =AF21/$CI$21 -> 0.026395736 | AH22: =AH21/$CI$21 -> 0.027356002 | AJ22: =AJ21/$CI$21 -> 0.028140781 | AL22: =AL21/$CI$21 -> 0.031543089 | AN22: =AN21/$CI$21 -> 0.034091244 | AP22: =AP21/$CI$21 -> 0.036071411 | AR22: =AR21/$CI$21 -> 0.036071411 | AT22: =AT21/$CI$21 -> 0.026375042 | AV22: =AV21/$CI$21 -> 0.026375042 | AX22: =AX21/$CI$21 -> 0.026375042 | AZ22: =AZ21/$CI$21 -> 0.032273602 | BB22: =BB21/$CI$21 -> 0.032273602 | BD22: =BD21/$CI$21 -> 0.032273602 | BF22: =BF21/$CI$21 -> 0.032273602 | BH22: =BH21/$CI$21 -> 0.025497353 | BJ22: =BJ21/$CI$21 -> 0.038629611 | BL22: =BL21/$CI$21 -> 0.043207563 | BN22: =BN21/$CI$21 -> 0.033194833 | BP22: =BP21/$CI$21 -> 0.031918934 | BR22: =BR21/$CI$21 -> 0.031918934 | BT22: =BT21/$CI$21 -> 0.031918934 | BV22: =BV21/$CI$21 -> 0.031918934 | BX22: =BX21/$CI$21 -> 0.031918934 | BZ22: =BZ21/$CI$21 -> 0.010501336 | CB22: =CB21/$CI$21 -> 0 | CD22: =CD21/$CI$21 -> 0 | CF22: =CF21/$CI$21 -> 0 | CH22: =CH21/$CI$21 -> 0 | CJ22: =SUM(H22:CH22) -> 1
C24: ÁREA CONSTRUÍDA | D24: 12469.72
B26: Prazo de obra | C26: Mês | D26: %
B27: 36 | C27: M1 | D27: =H22 -> 0.021543111
C28: M2 | D28: =J22 -> 0.037382874
C29: M3 | D29: =L22 -> 0.037382874
C30: M4 | D30: =N22 -> 0.042881078
C31: M5 | D31: =P22 -> 0.011161574
C32: M6 | D32: =R22 -> 0.011161574
C33: M7 | D33: =T22 -> 0.008881026
C34: M8 | D34: =V22 -> 0.011851603
C35: M9 | D35: =X22 -> 0.018821126
C36: M10 | D36: =Z22 -> 0.018821126
C37: M11 | D37: =AB22 -> 0.020232925
C38: M12 | D38: =AD22 -> 0.021364532
C39: M13 | D39: =AF22 -> 0.026395736
C40: M14 | D40: =AH22 -> 0.027356002
C41: M15 | D41: =AJ22 -> 0.028140781
C42: M16 | D42: =AL22 -> 0.031543089
C43: M17 | D43: =AN22 -> 0.034091244
...
