Workbook
Name \0: #REF!
Name \0: #REF!
Name \a: #REF!
Name \a: #REF!
Name \m: #REF!
Name aa: #REF!
Name aa: #REF!
Name aa: #REF!
Name aa: #REF!
Name aaaa: #REF!
Name aaaa: '[1]M.O.'!#REF!
Name aaaa: #REF!
Name aaaa: #REF!
Name aaaa: #REF!
Name angelo: [2]Geral!#REF!
Name angelo: #REF!
Name angelo: #REF!
Name angelo: #REF!
Name area: #REF!
Name area: #REF!
Name aux: #REF!
Name aux: #REF!
Name aux: #REF!
Name BDA: #REF!
Name BDA: #REF!
Name BDA: #REF!
Name BDI: #REF!
Name BDI: #REF!
Name BDI: #REF!
Name ca: #REF!
Name ca: #REF!
Name ca: #REF!
Name Capa: #REF!
Name Capa: #REF!
Name Capa: #REF!
Name cronograma: #REF!
Name cronograma: #REF!
Name cronograma: #REF!
Name D: #REF!
Name D: #REF!
Name D: #REF!
Name direto: #REF!
Name direto: #REF!
Name direto: #REF!
Name DRE: #REF!
Name DRE: #REF!
Name DRE: #REF!
Name ea: #REF!
Name ea: #REF!
Name ea: #REF!
Name eee: {#N/A,#N/A,FALSE,"ET-CAPA";#N/A,#N/A,FALSE,"ET-PAG1";#N/A,#N/A,FALSE,"ET-PAG2";#N/A,#N/A,FALSE,"ET-PAG3";#N/A,#N/A,FALSE,"ET-PAG4";#N/A,#N/A,FALSE,"ET-PAG5"}
Name eee: {#N/A,#N/A,FALSE,"ET-CAPA";#N/A,#N/A,FALSE,"ET-PAG1";#N/A,#N/A,FALSE,"ET-PAG2";#N/A,#N/A,FALSE,"ET-PAG3";#N/A,#N/A,FALSE,"ET-PAG4";#N/A,#N/A,FALSE,"ET-PAG5"}
Name eee: {#N/A,#N/A,FALSE,"ET-CAPA";#N/A,#N/A,FALSE,"ET-PAG1";#N/A,#N/A,FALSE,"ET-PAG2";#N/A,#N/A,FALSE,"ET-PAG3";#N/A,#N/A,FALSE,"ET-PAG4";#N/A,#N/A,FALSE,"ET-PAG5"}
Name eee: {#N/A,#N/A,FALSE,"ET-CAPA";#N/A,#N/A,FALSE,"ET-PAG1";#N/A,#N/A,FALSE,"ET-PAG2";#N/A,#N/A,FALSE,"ET-PAG3";#N/A,#N/A,FALSE,"ET-PAG4";#N/A,#N/A,FALSE,"ET-PAG5"}
Name eee: {#N/A,#N/A,FALSE,"ET-CAPA";#N/A,#N/A,FALSE,"ET-PAG1";#N/A,#N/A,FALSE,"ET-PAG2";#N/A,#N/A,FALSE,"ET-PAG3";#N/A,#N/A,FALSE,"ET-PAG4";#N/A,#N/A,FALSE,"ET-PAG5"}
Name FFFFFFF: #REF!
Name FFFFFFF: #REF!
Name FFFFFFF: #REF!
Name item_1: #REF!
Name item_1: #REF!

Sheet OBRA
A1: Obra | B1: Monolyt
A2: Empresa | B2: Blue Heaven
A3: Revisão | B3: R03
A4: DADOS OBRA
A6: ARQUITETURA
B8: Descrição | C8: Unidade | D8: Quantidade
B9: ÁREA DO TERRENO | C9: M2 | D9: 7541.68
B10: ÁREA CONSTRUÍDA | C10: M2 | D10: 14693.42
B11: NÚMERO DE UNIDADES HABITACIONAIS | C11: UN | D11: 24
B12: MESES DE OBRA | C12: MÊS | D12: 36
B13: NÚMERO DE PAVIMENTOS | C13: UN | D13: 4

Sheet CANTEIRO
A1: Obra | B1: Monolyt
A2: Empresa | B2: Blue Heaven
A3: Revisão | B3: R02
A4: LEVANTAMENTO QUANTITATIVO
A6: Instalações de canteiro
A8: Instalações de canteiro
B10: Descrição | C10: Unidade | D10: Quantidade
B11: Produtividade média | C11: m2 / mês | D11: =OBRA!D10/OBRA!D12 -> 408.15056
B12: Pm | C12: h/m2 | D12: 45
B13: Numero de funcionários | C13: un | D13: =ROUNDUP((D12*OBRA!D10)/OBRA!D12/180,) -> 103
B14: Equipe administrativa | C14: un | D14: 10
B15: Pontos de água e esgoto | C15: un | D15: =ROUNDUP($D$13/20,0) -> 6 | E15: 20 funcionários/ponto
B16: Bebedouro | C16: un | D16: =ROUNDUP(OBRA!$D$13/5,0) -> 1 | E16: 1 / 5 pav.
B17: Ferramentas | C17: R$ | D17: =800*D13 -> 82400 | E17: 800,00/func.
B18: EPI | C18: R$ | D18: =500*D13 -> 51500 | E18: 500,00/func.
B19: Banheiro | C19: un | D19: =ROUNDUP($D$13/20,0) -> 6 | E19: 1/20 func
A21: Mobiliário de canteiro
B23: Descrição | C23: Unidade | D23: Quantidade | E23: Custo unitário | F23: Custo total
B24: Cadeira | C24: un | D24: =D28*1.5 -> 15 | E24: 200 | F24: =D24*E24 -> 3000
B25: Mesa | C25: un | D25: =2 -> 2 | E25: 1000 | F25: =E25*D25 -> 2000
B26: Ar condicionado | C26: un | D26: =2*2 -> 4 | E26: 5000 | F26: =E26*D26 -> 20000
B27: Armário | C27: m | D27: =7*2*2 -> 28 | E27: 900 | F27: =E27*D27 -> 25200
B28: Escrivaninha | C28: un | D28: =D14 -> 10 | E28: 800 | F28: =E28*D28 -> 8000
B29: TOTAL | F29: =F26+F27+F28+F25+F24 -> 58200
B30: Descrição | C30: Unidade | D30: Quantidade | E30: Custo unitário | F30: Custo total
B31: Computador pessoal | C31: un | D31: =D14 -> 10 | E31: 6000 | F31: =D31*E31 -> 60000
B32: Impressora | C32: un | D32: 2 | E32: 2000 | F32: =E32*D32 -> 4000
B33: Roteador | C33: un | D33: =2*2 -> 4 | E33: 500 | F33: =E33*D33 -> 2000
B34: TOTAL | F34: =+F31+F32+F33 -> 66000

Sheet EPCs
A1: Obra | B1: Monolyt
A2: Empresa | B2: Blue Heaven
A3: Revisão | B3: R02
A4: LEVANTAMENTO QUANTITATIVO
A6: Equipamentos de proteção coletiva
A8: Bandejas de proteção
B10: Descrição | C10: Unidade | D10: Quantidade
B11: Perímetro de projeção torre 1 | C11: m | D11: =155.98+66.7 -> 222.68
B12: Perímetro de projeção torre 2 | C12: m | D12: =185.24+54.18 -> 239.42
B13: Número de montagens de bandeja primária | C13: un | D13: 1
B14: Bandeja de proteção primária | C14: m | D14: =D11+D12 -> 462.1
A16: Guarda - corpo de desforma
B18: Descrição | C18: Unidade | D18: Quantidade
B19: Perímetro de projeção da torre | C19: m | D19: =D11+D12 -> 462.1
B20: Repetições de pavimentos** | C20: un | D20: 3
B21: Proteção de periferia pós desforma torre | C21: m | D21: =(D19*D20) -> 1386.3
A23: Guarda-corpo de vãos
B25: Descrição | C25: Unidade | D25: Quantidade
B26: Comprimento de futuros guarda-copro de alumínio | C26: m | D26: 506.635
B27: Tela fachadeira | C27: m | D27: =D26 -> 506.635
A29: Tela fachadeira
B31: Descrição | C31: Unidade | D31: Quantidade
B32: Area da fachada | C32: m² | D32: =(D11+D12)*11.3 -> 5221.73
B33: Tela fachadeira | C33: m2 | D33: =D32 -> 5221.73
A35: Fechamento removível de vãos em madeira
B37: Descrição | C37: Unidade | D37: Quantidade
B38: Área das portas de elevadores | C38: m2 | D38: =1*2.4 -> 2.4
B39: Quantidade de elevadores | C39: un | D39: 6
B40: Quantidade de portas de elevadores | C40: un | D40: =(2+3+3+3+4+3+3+3) -> 24
B41: Fechamento removível de vãos em madeira | C41: m2 | D41: =D38*D40 -> 57.6
A43: Tapume
B45: Descrição | C45: Unidade | D45: Quantidade
B46: Perímetro de encontro com pavimentação | C46: m | D46: =42.1 -> 42.1
B47: Altura do tapume | C47: m | D47: 2.4
B48: Cobertura para proteção de pedestres | C48: m2 | D48: =D47*D46 -> 101.04

Sheet CUSTOS_INDIRETOS
A1: ORÇAMENTO PARAMÉTRICO - CUSTOS INDIRETOS
A7: Cliente | B7: =OBRA!B2 -> Blue Heaven
A8: Obra | B8: =OBRA!B1 -> Monolyt
A9: Data | B9: 45553
A10: Versão | B10: =OBRA!B3 -> R03
A12: GERENCIAMENTO TÉCNICO
A13: Código | B13: Descrição | C13: Un. | D13: Quantidade orçada | E13: Preço unitário | F13: Preço total
A14: 01 | B14: GERENCIAMENTO TÉCNICO | F14: =F15+F35 -> 1959447.4
A15: 01.001 | B15: ESTUDOS, PROJETOS E CONSULTORIAS | F15: =F16+F17+F33+F34 -> 1346038.8
A16: 01.001.001 | B16: Estudos | F16: 56126.829
A17: 01.001.002 | B17: Projetos | F17: =SUM(F18:F32) -> 1058652
A18: 01.001.002.001 | B18: Terraplenagem | C18: vb | D18: 1 | E18: 7400 | F18: =E18*D18 -> 7400
A19: 01.001.002.002 | B19: Topografia | C19: vb | D19: 1 | E19: 6000 | F19: =E19*D19 -> 6000
A20: 01.001.002.003 | B20: Sondagem | C20: vb | D20: 1 | E20: 8820 | F20: =E20*D20 -> 8820
A21: 01.001.002.004 | B21: Imagens 3D Filme | C21: vb | D21: 1 | E21: 49300 | F21: =E21*D21 -> 49300
A22: 01.001.002.005 | B22: Estudo Geofísico | C22: vb | D22: 1 | E22: 21250 | F22: =E22*D22 -> 21250
A23: 01.001.002.006 | B23: Fundações Contenção | C23: vb | D23: 1 | E23: 14000 | F23: =E23*D23 -> 14000
A24: 01.001.002.007 | B24: Estudo Hidrogeológico | C24: vb | D24: 1 | E24: 10682 | F24: =E24*D24 -> 10682
A25: 01.001.002.008 | B25: Luminotécnico | C25: vb | D25: 1 | E25: 70000 | F25: =E25*D25 -> 70000
A26: 01.001.002.009 | B26: Energia Renovável | C26: vb | D26: 1 | E26: 9000 | F26: =E26*D26 -> 9000
A27: 01.001.002.010 | B27: Drywall | C27: vb | D27: 1 | E27: 27000 | F27: =E27*D27 -> 27000
A28: 01.001.002.011 | B28: Paisagismo | C28: vb | D28: 1 | E28: 125000 | F28: =E28*D28 -> 125000
A29: 01.001.002.012 | B29: Aprovativo | C29: vb | D29: 1 | E29: 10200 | F29: =E29*D29 -> 10200
... A32: 01.001.002.014 | B32: Interiores | C32: vb | D32: 1 | E32: 80000 | F32: =E32*D32 -> 80000
A33: 01.001.003 | B33: Consultorias | F33: 59541.37
A34: 01.001.004 | B34: Ensaios e Laudos | F34: 171718.61
A35: 01.002 | B35: TAXAS E DOCUMENTOS | F35: =SUM(F36:F38) -> 613408.59
A36: 01.002.001 | B36: Seguros | F36: 33456.914
A37: 01.002.002 | B37: Licenciamentos, Taxas, Impostos | F37: 447901.92
A38: 01.002.003 | B38: Documentos | F38: 132049.76
A39: 02 | B39: GERENCIAMENTO ADMINISTRATIVO | F39: =F40+F53+F77 -> 12579413
A40: 02.001 | B40: SEGURANÇA, MEIO AMBIENTE E SAÚDE | F40: =F41+F43+F52 -> 878433
A41: 02.001.001 | B41: Segurança do Trabalho | F41: =F42 -> 316800
A42: 02.001.001.001 | B42: Serviço de segurança do trabalho terceirizado | C42: mes | D42: =OBRA!D12 -> 36 | E42: 8000 | F42: =E42*D42*1.1 -> 316800 | G42: Conforme solicitado em 18/07 via whatsapp
A43: 02.001.002 | B43: Equipamentos de proteção | F43: =SUM(F44:F51) -> 387240.15
A44: 02.001.002.001 | B44: Bandeja de proteção primária | C44: m | D44: =EPCs!D14 -> 462.1 | E44: 402.72 | F44: =E44*D44*1.1 -> 204706.6
A45: 02.001.002.002 | B45: Guarda corpo em laje pós - desforma | C45: m | D45: =EPCs!D21 -> 1386.3 | E45: 13.68 | F45: =E45*D45*1.1 -> 20861.042
A46: 02.001.002.003 | B46: Guarda corpo de vãos | C46: m | D46: =EPCs!D27 -> 506.635 | E46: 13.68 | F46: =E46*D46*1.1 -> 7623.8435
A47: 02.001.002.004 | B47: Fechamento removível de vãos de porta de elevador em madeira | C47: m2 | D47: =EPCs!D41 -> 57.6 | E47: 67.76 | F47: =E47*D47*1.1 -> 4293.2736
A48: 02.001.002.005 | B48: Tela fachadeira | C48: m2 | D48: =EPCs!D33 -> 5221.73 | E48: 6.68 | F48: =E48*D48*1.1 -> 38369.272
...

Sheet GERENCIAMENTO_EXECUTIVO
A1: ORÇAMENTO PARAMÉTRICO - GERENCIAMENTO EXECUTIVO
A7: Cliente | B7: =OBRA!B2 -> Blue Heaven
A8: Obra | B8: =OBRA!B1 -> Monolyt
A9: Data | B9: 45503
A10: Versão | B10: =OBRA!B3 -> R03
A12: GERENCIAMENTO EXECUTIVO
A13: CÓDIGO | B13: ITEM | C13: Quantidade | D13: Unidade | E13: Valor Orçado | F13: Considerações
A14: 1 | B14: GERENCIAMENTO TÉCNICO E ADMINISTRATIVO | E14: =E15 -> 14538860
A15: 1.1 | B15: GERENCIAMENTO TÉCNICO E ADMINISTRATIVO | E15: =E16 -> 14538860
A16: 1.1.1 | B16: Gerenciamento técnico e administrativo | C16: 1 | D16: vb | E16: =CUSTOS_INDIRETOS!F93 -> 14538860 | F16: Conforme aba "custos_indiretos"
A17: 2 | B17: MOVIMENTAÇÃO DE TERRA | E17: =E22+E24+E18 -> 2545063.4
A18: 2.1 | B18: ESCAVAÇÃO VERTICAL DE SUBSOLO | E18: =SUM(E19:E21) -> 1552282
A19: 2.1.1 | B19: Escavação mecanizada | C19: 13424.19 | D19: m³ | E19: 885996.68
A20: 2.1.2 | B20: Reaterro | C20: 248.13756 | D20: m³ | E20: 6823.7829
A21: 2.1.3 | B21: Movimentação de bota-fora | C21: 17128.87 | D21: m² | E21: 659461.53 | F21: 40% empolamento
A22: 2.2 | B22: REBAIXAMENTO DE LENÇOL | E22: =SUM(E23:E23) -> 39600
A23: 2.2.1 | B23: Rebaixamento provisório de lençol | C23: 1 | D23: vb | E23: 39600 | F23: Rebaixameno de lençol provisório considerando período de execução da fundação
A24: 2.3 | B24: MOVIMENTAÇÃO DE VALAS | E24: =SUM(E25:E28) -> 953181.4
A25: 2.3.1 | B25: Escavação mecanizada para blocos e baldrames | C25: 4661.376 | D25: m³ | E25: 257673.24
A26: 2.3.2 | B26: Reaterro para blocos e baldrames | C26: 2796.8256 | D26: m³ | E26: 77301.972
A27: 2.3.3 | B27: Movimentação de bota-fora | C27: 3899.38 | D27: m³ | E27: 171572.57
A28: 2.3.4 | B28: Lastro de concreto magro | C28: 1561.656 | D28: m² | E28: 446633.62
A29: 3 | B29: INFRAESTRUTURA | E29: =E30+E38 -> 5742340
A30: 3.1 | B30: FUNDAÇÃO PROFUNDA | E30: =SUM(E31:E37) -> 2529315.8
A31: 3.1.1 | B31: Estaca Hélice Continua Diâmetro 40 | C31: 820.4 | D31: m | E31: 63170.8
A32: 3.1.2 | B32: Estaca Hélice Continua Diâmetro 50 | C32: 5742.8 | D32: m | E32: 631708
A33: 3.1.3 | B33: Estaca Hélice Continua Diâmetro 60 | C33: 1640.8 | D33: m | E33: 216585.6
A34: 3.1.4 | B34: Armação 6,3mm | C34: 2114.6461 | D34: kg | E34: 18608.886
A35: 3.1.5 | B35: Armação 16mm | C35: 12985.467 | D35: kg | E35: 121414.12
A36: 3.1.6 | B36: Concreto | C36: 1269.2631 | D36: m³ | E36: 1267948.4 | F36: Consideração de concreto com bombeamento + 30% de perda devido a compressão da estaca hélice no solo
A37: 3.1.7 | B37: Mobilização e arrasamento de estacas | C37: 1 | D37: vb | E37: 209880 | F37: Previsão de mobilização de maquinários + arrasamento de estacas
A38: 3.2 | B38: FUNDAÇÃO RASA | E38: =SUM(E39:E42) -> 3213024.3
A39: 3.2.1 | B39: Fabricação, montagem e desmontagem de forma para blocos e baldrames resinado | C39: 2967.1464 | D39: m² | E39: 234997.99 | F39: Forma de madeira serrada sem reutilização
A40: 3.2.2 | B40: Armação | C40: 80815.698 | D40: kg | E40: 711178.14 | F40: Consideração de R$ 8/kg
A41: 3.2.3 | B41: Concreto | C41: 897.9522 | D41: m³ | E41: 720808.68 | F41: Consideração de R$ 729,75/m³ de concreto com bombeamento
A42: 3.2.4 | B42: Mão de obra | C42: 3904.14 | D42: m² | E42: 1546039.4 | F42: Valor estimado por área de projeção do embasamento
A43: 4 | B43: CONTENÇÃO | E43: =E44 -> 1644604.6
A44: 4.2 | B44: PAREDE DE CONCRETO | E44: =SUM(E45:E49) -> 1644604.6
A45: 4.2.1 | B45: Fabricação, montagem e desmontagem de forma - resinado | C45: 2326.96 | D45: m² | E45: 529057.7
A46: 4.2.2 | B46: Concreto | C46: 465.392 | D46: m³ | E46: 373581.79
...

Sheet CREMALHEIRA
