Workbook

Sheet PRAZO
B2: ORÇAMENTO PARAMÉTRICO | ESTIMATIVA DE PRAZO
B4: MEIA PRAIA EMPREENDIMENTOS - 298
B7: SERVIÇOS | C7: M1 | D7: M2 | E7: M3 | F7: M4 | G7: M5 | H7: M6 | I7: M7 | J7: M8 | K7: M9 | L7: M10 | M7: M11 | N7: M12 | O7: M13 | P7: M14 | Q7: M15 | R7: M16 | S7: M17 | T7: M18 | U7: M19 | V7: M20 | W7: M21 | X7: M22 | Y7: M23 | Z7: M24 | AA7: M25 | AB7: M26 | AC7: M27 | AD7: M28 | AE7: M29 | AF7: M30 | AG7: M31 | AH7: M32 | AI7: M33 | AJ7: M34 | AK7: M35 | AL7: M36 | AM7: M37 | AN7: M38 | AO7: M39 | AP7: M40 | AQ7: M41 | AR7: M42 | AS7: M43 | AT7: M44 | AU7: M45 | AV7: M46
B8: MOVIMENTAÇÃO DE TERRA | C8: 1 | D8: 2 | E8: 3
B9: INFRAESTRUTURA | C9: 1 | D9: 2 | E9: 3 | F9: 4 | G9: 5 | H9: 6
B10: SUPRAESTRUTURA | I10: 1 | J10: 2 | K10: 3 | L10: 4 | M10: 5 | N10: 6 | O10: 7 | P10: 8 | Q10: 9 | R10: 10 | S10: 11 | T10: 12 | U10: 13 | V10: 14 | W10: 15 | X10: 16 | Y10: 17 | Z10: 18 | AA10: 19 | AB10: 20 | AC10: 21 | AD10: 22
B11: ALVENARIA | L11: 1 | M11: 2 | N11: 3 | O11: 4 | P11: 5 | Q11: 6 | R11: 7 | S11: 8 | T11: 9 | U11: 10 | V11: 11 | W11: 12 | X11: 13 | Y11: 14 | Z11: 15 | AA11: 16 | AB11: 17 | AC11: 18 | AD11: 19 | AE11: 20 | AF11: 21 | AG11: 22
B12: INSTALAÇÕES ELÉTRICAS, HIDRÁULICAS, GLP E PREVENTIVAS | N12: 1 | O12: 2 | P12: 3 | Q12: 4 | R12: 5 | S12: 6 | T12: 7 | U12: 8 | V12: 9 | W12: 10 | X12: 11 | Y12: 12 | Z12: 13 | AA12: 14 | AB12: 15 | AC12: 16 | AD12: 17 | AE12: 18 | AF12: 19 | AG12: 20 | AH12: 21
B13: EQUIPAMENTOS E SISTEMAS ESPECIAIS | AE13: 1 | AF13: 2 | AG13: 3 | AH13: 4 | AI13: 5 | AJ13: 6 | AK13: 7 | AL13: 8 | AM13: 9 | AN13: 10 | AO13: 11 | AP13: 12
B14: IMPERMEABILIZAÇÃO | P14: 1 | Q14: 2 | R14: 3 | S14: 4 | T14: 5 | U14: 6 | V14: 7 | W14: 8 | X14: 9 | Y14: 10 | Z14: 11 | AA14: 12 | AB14: 13 | AC14: 14 | AD14: 15 | AE14: 16 | AF14: 17 | AG14: 18 | AH14: 19 | AI14: 20 | AJ14: 21
B15: REVESTIMENTOS INTERNOS EM PISO E PAREDE | O15: 1 | P15: 2 | Q15: 3 | R15: 4 | S15: 5 | T15: 6 | U15: 7 | V15: 8 | W15: 9 | X15: 10 | Y15: 11 | Z15: 12 | AA15: 13 | AB15: 14 | AC15: 15 | AD15: 16 | AE15: 17 | AF15: 18 | AG15: 19 | AH15: 20 | AI15: 21
B16: REVESTIMENTOS E ACABAMENTOS INTERNOS EM TETO | R16: 1 | S16: 2 | T16: 3 | U16: 4 | V16: 5 | W16: 6 | X16: 7 | Y16: 8 | Z16: 9 | AA16: 10 | AB16: 11 | AC16: 12 | AD16: 13 | AE16: 14 | AF16: 15 | AG16: 16 | AH16: 17 | AI16: 18 | AJ16: 19 | AK16: 20 | AL16: 21
B17: ACABAMENTOS EM PISO E PAREDE | Q17: 1 | R17: 2 | S17: 3 | T17: 4 | U17: 5 | V17: 6 | W17: 7 | X17: 8 | Y17: 9 | Z17: 10 | AA17: 11 | AB17: 12 | AC17: 13 | AD17: 14 | AE17: 15 | AF17: 16 | AG17: 17 | AH17: 18 | AI17: 19 | AJ17: 20 | AK17: 21 | AL17: 22 | AM17: 23 | AN17: 24
B18: PINTURA INTERNA | S18: 1 | T18: 2 | U18: 3 | V18: 4 | W18: 5 | X18: 6 | Y18: 7 | Z18: 8 | AA18: 9 | AB18: 10 | AC18: 11 | AD18: 12 | AE18: 13 | AF18: 14 | AG18: 15 | AH18: 16 | AI18: 17 | AJ18: 18 | AK18: 19 | AL18: 20 | AM18: 21 | AN18: 22 | AO18: 23 | AP18: 24 | AQ18: 25 | AR18: 26 | AS18: 27 | AT18: 28 | AU18: 29
B19: ESQUADRIAS, VIDROS E FERRAGENS | AI19: 1 | AJ19: 2 | AK19: 3 | AL19: 4 | AM19: 5 | AN19: 6 | AO19: 7 | AP19: 8 | AQ19: 9 | AR19: 10 | AS19: 11 | AT19: 12
B20: COBERTURA | AG20: 1 | AH20: 2 | AI20: 3 | AJ20: 4
B21: REVESTIMENTOS E ACABAMENTOS DE FACHADA | AF21: 1 | AG21: 2 | AH21: 3 | AI21: 4 | AJ21: 5 | AK21: 6 | AL21: 7 | AM21: 8 | AN21: 9 | AO21: 10 | AP21: 11 | AQ21: 12
B22: SERVIÇOS COMPLEMENTARES | AM22: 1 | AN22: 2 | AO22: 3 | AP22: 4 | AQ22: 5 | AR22: 6 | AS22: 7 | AT22: 8 | AU22: 9 | AV22: 10

Sheet DISTRIBUIÇÃO CUSTO
B2: ORÇAMENTO PARAMÉTRICO | DISTRIBUIÇÃO MENSAL DE CUSTOS
B4: MEIA PRAIA EMPREENDIMENTOS - 298
B7: ETAPA | C7: VALOR ORÇADO | D7: % | E7: VALOR / m² | F7: % Distribuído | H7: M1 | J7: M2 | L7: M3 | N7: M4 | P7: M5 | R7: M6 | T7: M7 | V7: M8 | X7: M9 | Z7: M10 | AB7: M11 | AD7: M12 | AF7: M13 | AH7: M14 | AJ7: M15 | AL7: M16 | AN7: M17 | AP7: M18 | AR7: M19 | AT7: M20 | AV7: M21 | AX7: M22 | AZ7: M23 | BB7: M24 | BD7: M25 | BF7: M26 | BH7: M27 | BJ7: M28 | BL7: M29 | BN7: M30 | BP7: M31 | BR7: M32 | BT7: M33 | BV7: M34 | BX7: M35 | BZ7: M36 | CB7: M37 | CD7: M38 | CF7: M39 | CH7: M40 | CJ7: M41 | CL7: M42 | CN7: M43 | CP7: M44 | CR7: M45 | CT7: M46
H8: % | I8: R$ | J8: % | K8: R$ | L8: % | M8: R$ | N8: % | O8: R$ | P8: % | Q8: R$ | R8: % | S8: R$ | T8: % | U8: R$ | V8: % | W8: R$ | X8: % | Y8: R$ | Z8: % | AA8: R$ | AB8: % | AC8: R$ | AD8: % | AE8: R$ | AF8: % | AG8: R$ | AH8: % | AI8: R$ | AJ8: % | AK8: R$ | AL8: % | AM8: R$ | AN8: % | AO8: R$ | AP8: % | AQ8: R$ | AR8: % | AS8: R$ | AT8: % | AU8: R$ | AV8: % | AW8: R$ | AX8: % | AY8: R$ | AZ8: % | BA8: R$ | BB8: % | BC8: R$ | BD8: % | BE8: R$ | BF8: % | BG8: R$ | BH8: % | BI8: R$ | BJ8: % | BK8: R$ | BL8: % | BM8: R$ | BN8: % | BO8: R$ | BP8: % | BQ8: R$ | BR8: % | BS8: R$ | BT8: % | BU8: R$ | BV8: % | BW8: R$ | BX8: % | BY8: R$ | BZ8: % | CA8: R$ | CB8: % | CC8: R$ | CD8: % | CE8: R$ | CF8: % | CG8: R$ | CH8: % | CI8: R$ | CJ8: % | CK8: R$ | CL8: % | CM8: R$ | CN8: % | CO8: R$ | CP8: % | CQ8: R$ | CR8: % | CS8: R$ | CT8: % | CU8: R$
B9: GERENCIAMENTO TÉCNICO E ADMINISTRATIVO | C9: 4306231.3 | D9: =C9/$C$26 -> 0.11470877 | E9: =C9/'DISTRIBUIÇÃO CUSTO'!C$30 -> 405.54618 | F9: =SUM(H9,J9,L9,N9,P9,R9,T9,V9,X9,Z9,AB9,AD9,AF9,AH9,AJ9,AL9,,AN9,AP9,AR9,AT9,AV9,AX9,AZ9,BB9,BD9,BF9,BH9,BJ9,BL9,BN9,BP9,BR9,BT9,BV9,BX9,BZ9,CB9,CD9,CF9,CH9,CJ9,CL9,CN9,CP9,CR9,CT9) -> 1 | H9: =7.2%+(79.21%/46) -> 0.089219565 | I9: =$C9*H9 -> 384200.08 | J9: =3.12%+(79.21%/46) -> 0.048419565 | K9: =$C9*J9 -> 208505.85 | L9: =3.12%+(79.21%/46) -> 0.048419565 | M9: =$C9*L9 -> 208505.85 | N9: =2.45%+(79.21%/46) -> 0.041719565 | O9: =$C9*N9 -> 179654.1 | P9: =2.45%+(79.21%/46) -> 0.041719565 | Q9: =$C9*P9 -> 179654.1 | R9: =2.45%+(79.21%/46) -> 0.041719565 | S9: =$C9*R9 -> 179654.1 | T9: =(79.21%/46) -> 0.017219565 | U9: =$C9*T9 -> 74151.43 | V9: =(79.21%/46) -> 0.017219565 | W9: =$C9*V9 -> 74151.43 | X9: =(79.21%/46) -> 0.017219565 | Y9: =$C9*X9 -> 74151.43 | Z9: =(79.21%/46) -> 0.017219565 | AA9: =$C9*Z9 -> 74151.43 | AB9: =(79.21%/46) -> 0.017219565 | AC9: =$C9*AB9 -> 74151.43 | AD9: =(79.21%/46) -> 0.017219565 | AE9: =$C9*AD9 -> 74151.43 | AF9: =(79.21%/46) -> 0.017219565 | AG9: =$C9*AF9 -> 74151.43 | AH9: =(79.21%/46) -> 0.017219565 | AI9: =$C9*AH9 -> 74151.43 | AJ9: =(79.21%/46) -> 0.017219565 | AK9: =$C9*AJ9 -> 74151.43 | AL9: =(79.21%/46) -> 0.017219565 | AM9: =$C9*AL9 -> 74151.43 | AN9: =(79.21%/46) -> 0.017219565 | AO9: =$C9*AN9 -> 74151.43 | AP9: =(79.21%/46) -> 0.017219565 | AQ9: =$C9*AP9 -> 74151.43 | AR9: =(79.21%/46) -> 0.017219565 | AS9: =$C9*AR9 -> 74151.43 | AT9: =(79.21%/46) -> 0.017219565 | AU9: =$C9*AT9 -> 74151.43 | AV9: =(79.21%/46) -> 0.017219565 | AW9: =$C9*AV9 -> 74151.43 | AX9: =(79.21%/46) -> 0.017219565 | AY9: =$C9*AX9 -> 74151.43 | AZ9: =(79.21%/46) -> 0.017219565 | BA9: =$C9*AZ9 -> 74151.43 | BB9: =(79.21%/46) -> 0.017219565 | BC9: =$C9*BB9 -> 74151.43 | BD9: =(79.21%/46) -> 0.017219565 | BE9: =$C9*BD9 -> 74151.43 | BF9: =(79.21%/46) -> 0.017219565 | BG9: =$C9*BF9 -> 74151.43 | BH9: =(79.21%/46) -> 0.017219565 | BI9: =$C9*BH9 -> 74151.43 | BJ9: =(79.21%/46) -> 0.017219565 | BK9: =$C9*BJ9 -> 74151.43 | BL9: =(79.21%/46) -> 0.017219565 | BM9: =$C9*BL9 -> 74151.43 | BN9: =(79.21%/46) -> 0.017219565 | BO9: =$C9*BN9 -> 74151.43 | BP9: =(79.21%/46) -> 0.017219565 | BQ9: =$C9*BP9 -> 74151.43 | BR9: =(79.21%/46) -> 0.017219565 | BS9: =$C9*BR9 -> 74151.43 | BT9: =(79.21%/46) -> 0.017219565 | BU9: =$C9*BT9 -> 74151.43 | BV9: =(79.21%/46) -> 0.017219565 | BW9: =$C9*BV9 -> 74151.43 | BX9: =(79.21%/46) -> 0.017219565 | BY9: =$C9*BX9 -> 74151.43 | BZ9: =(79.21%/46) -> 0.017219565 | CA9: =$C9*BZ9 -> 74151.43 | CB9: =(79.21%/46) -> 0.017219565 | CC9: =$C9*CB9 -> 74151.43 | CD9: =(79.21%/46) -> 0.017219565 | CE9: =$C9*CD9 -> 74151.43 | CF9: =(79.21%/46) -> 0.017219565 | CG9: =$C9*CF9 -> 74151.43 | CH9: =(79.21%/46) -> 0.017219565 | CI9: =$C9*CH9 -> 74151.43 | CJ9: =(79.21%/46) -> 0.017219565 | CK9: =$C9*CJ9 -> 74151.43 | CL9: =(79.21%/46) -> 0.017219565 | CM9: =$C9*CL9 -> 74151.43 | CN9: =(79.21%/46) -> 0.017219565 | CO9: =$C9*CN9 -> 74151.43 | CP9: =(79.21%/46) -> 0.017219565 | CQ9: =$C9*CP9 -> 74151.43 | CR9: =(79.21%/46) -> 0.017219565 | CS9: =$C9*CR9 -> 74151.43 | CT9: =(79.21%/46) -> 0.017219565 | CU9: =$C9*CT9 -> 74151.43
B10: MOVIMENTAÇÃO DE TERRA | C10: 89379.444 | D10: =C10/$C$26 -> 0.0023808768 | E10: =C10/'DISTRIBUIÇÃO CUSTO'!C$30 -> 8.4174513 | F10: =SUM(H10,J10,L10,N10,P10,R10,T10,V10,X10,Z10,AB10,AD10,AF10,AH10,AJ10,AL10,,AN10,AP10,AR10,AT10,AV10,AX10,AZ10,BB10,BD10,BF10,BH10,BJ10,BL10,BN10,BP10,BR10,BT10,BV10,BX10,BZ10,CB10,CD10,CF10,CH10,CJ10,CL10,CN10,CP10,CR10,CT10) -> 1 | H10: =100%/3 -> 0.33333333 | I10: =$C10*H10 -> 29793.148 | J10: =100%/3 -> 0.33333333 | K10: =$C10*J10 -> 29793.148 | L10: =100%/3 -> 0.33333333 | M10: =$C10*L10 -> 29793.148 | O10: =$C10*N10 -> 0 | Q10: =$C10*P10 -> 0 | S10: =$C10*R10 -> 0 | U10: =$C10*T10 -> 0 | W10: =$C10*V10 -> 0 | Y10: =$C10*X10 -> 0 | AA10: =$C10*Z10 -> 0 | AC10: =$C10*AB10 -> 0 | AE10: =$C10*AD10 -> 0 | AG10: =$C10*AF10 -> 0 | AI10: =$C10*AH10 -> 0 | AK10: =$C10*AJ10 -> 0 | AM10: =$C10*AL10 -> 0 | AO10: =$C10*AN10 -> 0 | AQ10: =$C10*AP10 -> 0 | AS10: =$C10*AR10 -> 0 | AU10: =$C10*AT10 -> 0 | AW10: =$C10*AV10 -> 0 | AY10: =$C10*AX10 -> 0 | BA10: =$C10*AZ10 -> 0 | BC10: =$C10*BB10 -> 0 | BE10: =$C10*BD10 -> 0 | BG10: =$C10*BF10 -> 0 | BI10: =$C10*BH10 -> 0 | BK10: =$C10*BJ10 -> 0 | BM10: =$C10*BL10 -> 0 | BO10: =$C10*BN10 -> 0 | BQ10: =$C10*BP10 -> 0 | BS10: =$C10*BR10 -> 0 | BU10: =$C10*BT10 -> 0 | BW10: =$C10*BV10 -> 0 | BY10: =$C10*BX10 -> 0 | CA10: =$C10*BZ10 -> 0 | CC10: =$C10*CB10 -> 0 | CE10: =$C10*CD10 -> 0 | CG10: =$C10*CF10 -> 0 | CI10: =$C10*CH10 -> 0 | CK10: =$C10*CJ10 -> 0 | CM10: =$C10*CL10 -> 0 | CO10: =$C10*CN10 -> 0 | CQ10: =$C10*CP10 -> 0 | CS10: =$C10*CR10 -> 0 | CU10: =$C10*CT10 -> 0
B11: INFRAESTRUTURA | C11: 1818002.4 | D11: =C11/$C$26 -> 0.048427688 | E11: =C11/'DISTRIBUIÇÃO CUSTO'!C$30 -> 171.21327 | F11: =SUM(H11,J11,L11,N11,P11,R11,T11,V11,X11,Z11,AB11,AD11,AF11,AH11,AJ11,AL11,,AN11,AP11,AR11,AT11,AV11,AX11,AZ11,BB11,BD11,BF11,BH11,BJ11,BL11,BN11,BP11,BR11,BT11,BV11,BX11,BZ11,CB11,CD11,CF11,CH11,CJ11,CL11,CN11,CP11,CR11,CT11) -> 1 | H11: =100%/6 -> 0.16666667 | I11: =$C11*H11 -> 303000.4 | J11: =100%/6 -> 0.16666667 | K11: =$C11*J11 -> 303000.4 | L11: =100%/6 -> 0.16666667 | M11: =$C11*L11 -> 303000.4 | N11: =100%/6 -> 0.16666667 | O11: =$C11*N11 -> 303000.4 | P11: =100%/6 -> 0.16666667 | Q11: =$C11*P11 -> 303000.4 | R11: =100%/6 -> 0.16666667 | S11: =$C11*R11 -> 303000.4 | U11: =$C11*T11 -> 0 | W11: =$C11*V11 -> 0 | Y11: =$C11*X11 -> 0 | AA11: =$C11*Z11 -> 0 | AC11: =$C11*AB11 -> 0 | AE11: =$C11*AD11 -> 0 | AG11: =$C11*AF11 -> 0 | AI11: =$C11*AH11 -> 0 | AK11: =$C11*AJ11 -> 0 | AM11: =$C11*AL11 -> 0 | AO11: =$C11*AN11 -> 0 | AQ11: =$C11*AP11 -> 0 | AS11: =$C11*AR11 -> 0 | AU11: =$C11*AT11 -> 0 | AW11: =$C11*AV11 -> 0 | AY11: =$C11*AX11 -> 0 | BA11: =$C11*AZ11 -> 0 | BC11: =$C11*BB11 -> 0 | BE11: =$C11*BD11 -> 0 | BG11: =$C11*BF11 -> 0 | BI11: =$C11*BH11 -> 0 | BK11: =$C11*BJ11 -> 0 | BM11: =$C11*BL11 -> 0 | BO11: =$C11*BN11 -> 0 | BQ11: =$C11*BP11 -> 0 | BS11: =$C11*BR11 -> 0 | BU11: =$C11*BT11 -> 0 | BW11: =$C11*BV11 -> 0 | BY11: =$C11*BX11 -> 0 | CA11: =$C11*BZ11 -> 0 | CC11: =$C11*CB11 -> 0 | CE11: =$C11*CD11 -> 0 | CG11: =$C11*CF11 -> 0 | CI11: =$C11*CH11 -> 0 | CK11: =$C11*CJ11 -> 0 | CM11: =$C11*CL11 -> 0 | CO11: =$C11*CN11 -> 0 | CQ11: =$C11*CP11 -> 0 | CS11: =$C11*CR11 -> 0 | CU11: =$C11*CT11 -> 0
B12: SUPRAESTRUTURA | C12: 8052236.1 | D12: =C12/$C$26 -> 0.21449431 | E12: =C12/'DISTRIBUIÇÃO CUSTO'!C$30 -> 758.33214 | F12: =SUM(H12,J12,L12,N12,P12,R12,T12,V12,X12,Z12,AB12,AD12,AF12,AH12,AJ12,AL12,,AN12,AP12,AR12,AT12,AV12,AX12,AZ12,BB12,BD12,BF12,BH12,BJ12,BL12,BN12,BP12,BR12,BT12,BV12,BX12,BZ12,CB12,CD12,CF12,CH12,CJ12,CL12,CN12,CP12,CR12,CT12) -> 1 | I12: =$C12*H12 -> 0 | K12: =$C12*J12 -> 0 | M12: =$C12*L12 -> 0 | O12: =$C12*N12 -> 0 | Q12: =$C12*P12 -> 0 | S12: =$C12*R12 -> 0 | T12: =100%/22 -> 0.045454545 | U12: =$C12*T12 -> 366010.73 | V12: =100%/22 -> 0.045454545 | W12: =$C12*V12 -> 366010.73 | X12: =100%/22 -> 0.045454545 | Y12: =$C12*X12 -> 366010.73 | Z12: =100%/22 -> 0.045454545 | AA12: =$C12*Z12 -> 366010.73 | AB12: =100%/22 -> 0.045454545 | AC12: =$C12*AB12 -> 366010.73 | AD12: =100%/22 -> 0.045454545 | AE12: =$C12*AD12 -> 366010.73 | AF12: =100%/22 -> 0.045454545 | AG12: =$C12*AF12 -> 366010.73 | AH12: =100%/22 -> 0.045454545 | AI12: =$C12*AH12 -> 366010.73 | AJ12: =100%/22 -> 0.045454545 | AK12: =$C12*AJ12 -> 366010.73 | AL12: =100%/22 -> 0.045454545 | AM12: =$C12*AL12 -> 366010.73 | AN12: =100%/22 -> 0.045454545 | AO12: =$C12*AN12 -> 366010.73 | AP12: =100%/22 -> 0.045454545 | AQ12: =$C12*AP12 -> 366010.73 | AR12: =100%/22 -> 0.045454545 | AS12: =$C12*AR12 -> 366010.73 | AT12: =100%/22 -> 0.045454545 | AU12: =$C12*AT12 -> 366010.73 | AV12: =100%/22 -> 0.045454545 | AW12: =$C12*AV12 -> 366010.73 | AX12: =100%/22 -> 0.045454545 | AY12: =$C12*AX12 -> 366010.73 | AZ12: =100%/22 -> 0.045454545 | BA12: =$C12*AZ12 -> 366010.73 | BB12: =100%/22 -> 0.045454545 | BC12: =$C12*BB12 -> 366010.73 | BD12: =100%/22 -> 0.045454545 | BE12: =$C12*BD12 -> 366010.73 | BF12: =100%/22 -> 0.045454545 | BG12: =$C12*BF12 -> 366010.73 | BH12: =100%/22 -> 0.045454545 | BI12: =$C12*BH12 -> 366010.73 | BJ12: =100%/22 -> 0.045454545 | BK12: =$C12*BJ12 -> 366010.73 | BM12: =$C12*BL12 -> 0 | BO12: =$C12*BN12 -> 0 | BQ12: =$C12*BP12 -> 0 | BS12: =$C12*BR12 -> 0 | BU12: =$C12*BT12 -> 0 | BW12: =$C12*BV12 -> 0 | BY12: =$C12*BX12 -> 0 | CA12: =$C12*BZ12 -> 0 | CC12: =$C12*CB12 -> 0 | CE12: =$C12*CD12 -> 0 | CG12: =$C12*CF12 -> 0 | CI12: =$C12*CH12 -> 0 | CK12: =$C12*CJ12 -> 0 | CM12: =$C12*CL12 -> 0 | CO12: =$C12*CN12 -> 0 | CQ12: =$C12*CP12 -> 0 | CS12: =$C12*CR12 -> 0 | CU12: =$C12*CT12 -> 0
B13: ALVENARIA | C13: 1549077.4 | D13: =C13/$C$26 -> 0.041264102 | E13: =C13/'DISTRIBUIÇÃO CUSTO'!C$30 -> 145.88683 | F13: =SUM(H13,J13,L13,N13,P13,R13,T13,V13,X13,Z13,AB13,AD13,AF13,AH13,AJ13,AL13,,AN13,AP13,AR13,AT13,AV13,AX13,AZ13,BB13,BD13,BF13,BH13,BJ13,BL13,BN13,BP13,BR13,BT13,BV13,BX13,BZ13,CB13,CD13,CF13,CH13,CJ13,CL13,CN13,CP13,CR13,CT13) -> 1 | I13: =$C13*H13 -> 0 | K13: =$C13*J13 -> 0 | M13: =$C13*L13 -> 0 | O13: =$C13*N13 -> 0 | Q13: =$C13*P13 -> 0 | S13: =$C13*R13 -> 0 | U13: =$C13*T13 -> 0 | W13: =$C13*V13 -> 0 | Y13: =$C13*X13 -> 0 | Z13: =100%/22 -> 0.045454545 | AA13: =$C13*Z13 -> 70412.609 | AB13: =100%/22 -> 0.045454545 | AC13: =$C13*AB13 -> 70412.609 | AD13: =100%/22 -> 0.045454545 | AE13: =$C13*AD13 -> 70412.609 | AF13: =100%/22 -> 0.045454545 | AG13: =$C13*AF13 -> 70412.609 | AH13: =100%/22 -> 0.045454545 | AI13: =$C13*AH13 -> 70412.609 | AJ13: =100%/22 -> 0.045454545 | AK13: =$C13*AJ13 -> 70412.609 | AL13: =100%/22 -> 0.045454545 | AM13: =$C13*AL13 -> 70412.609 | AN13: =100%/22 -> 0.045454545 | AO13: =$C13*AN13 -> 70412.609 | AP13: =100%/22 -> 0.045454545 | AQ13: =$C13*AP13 -> 70412.609 | AR13: =100%/22 -> 0.045454545 | AS13: =$C13*AR13 -> 70412.609 | AT13: =100%/22 -> 0.045454545 | AU13: =$C13*AT13 -> 70412.609 | AV13: =100%/22 -> 0.045454545 | AW13: =$C13*AV13 -> 70412.609 | AX13: =100%/22 -> 0.045454545 | AY13: =$C13*AX13 -> 70412.609 | AZ13: =100%/22 -> 0.045454545 | BA13: =$C13*AZ13 -> 70412.609 | BB13: =100%/22 -> 0.045454545 | BC13: =$C13*BB13 -> 70412.609 | BD13: =100%/22 -> 0.045454545 | BE13: =$C13*BD13 -> 70412.609 | BF13: =100%/22 -> 0.045454545 | BG13: =$C13*BF13 -> 70412.609 | BH13: =100%/22 -> 0.045454545 | BI13: =$C13*BH13 -> 70412.609 | BJ13: =100%/22 -> 0.045454545 | BK13: =$C13*BJ13 -> 70412.609 | BL13: =100%/22 -> 0.045454545 | BM13: =$C13*BL13 -> 70412.609 | BN13: =100%/22 -> 0.045454545 | BO13: =$C13*BN13 -> 70412.609 | BP13: =100%/22 -> 0.045454545 | BQ13: =$C13*BP13 -> 70412.609 | BY13: =$C13*BX13 -> 0 | CA13: =$C13*BZ13 -> 0 | CC13: =$C13*CB13 -> 0 | CE13: =$C13*CD13 -> 0 | CG13: =$C13*CF13 -> 0 | CI13: =$C13*CH13 -> 0 | CK13: =$C13*CJ13 -> 0 | CM13: =$C13*CL13 -> 0 | CO13: =$C13*CN13 -> 0 | CQ13: =$C13*CP13 -> 0 | CS13: =$C13*CR13 -> 0 | CU13: =$C13*CT13 -> 0
B14: INSTALAÇÕES ELÉTRICAS, HIDRÁULICAS, GLP E PREVENTIVAS | C14: 4134785.5 | D14: =C14/$C$26 -> 0.11014182 | E14: =C14/'DISTRIBUIÇÃO CUSTO'!C$30 -> 389.4 | F14: =SUM(H14,J14,L14,N14,P14,R14,T14,V14,X14,Z14,AB14,AD14,AF14,AH14,AJ14,AL14,,AN14,AP14,AR14,AT14,AV14,AX14,AZ14,BB14,BD14,BF14,BH14,BJ14,BL14,BN14,BP14,BR14,BT14,BV14,BX14,BZ14,CB14,CD14,CF14,CH14,CJ14,CL14,CN14,CP14,CR14,CT14) -> 1 | I14: =$C14*H14 -> 0 | K14: =$C14*J14 -> 0 | M14: =$C14*L14 -> 0 | O14: =$C14*N14 -> 0 | Q14: =$C14*P14 -> 0 | S14: =$C14*R14 -> 0 | U14: =$C14*T14 -> 0 | W14: =$C14*V14 -> 0 | Y14: =$C14*X14 -> 0 | AA14: =$C14*Z14 -> 0 | AC14: =$C14*AB14 -> 0 | AD14: =100%/21 -> 0.047619048 | AE14: =$C14*AD14 -> 196894.55 | AF14: =100%/21 -> 0.047619048 | AG14: =$C14*AF14 -> 196894.55 | AH14: =100%/21 -> 0.047619048 | AI14: =$C14*AH14 -> 196894.55 | AJ14: =100%/21 -> 0.047619048 | AK14: =$C14*AJ14 -> 196894.55 | AL14: =100%/21 -> 0.047619048 | AM14: =$C14*AL14 -> 196894.55 | AN14: =100%/21 -> 0.047619048 | AO14: =$C14*AN14 -> 196894.55 | AP14: =100%/21 -> 0.047619048 | AQ14: =$C14*AP14 -> 196894.55 | AR14: =100%/21 -> 0.047619048 | AS14: =$C14*AR14 -> 196894.55 | AT14: =100%/21 -> 0.047619048 | AU14: =$C14*AT14 -> 196894.55 | AV14: =100%/21 -> 0.047619048 | AW14: =$C14*AV14 -> 196894.55 | AX14: =100%/21 -> 0.047619048 | AY14: =$C14*AX14 -> 196894.55 | AZ14: =100%/21 -> 0.047619048 | BA14: =$C14*AZ14 -> 196894.55 | BB14: =100%/21 -> 0.047619048 | BC14: =$C14*BB14 -> 196894.55 | BD14: =100%/21 -> 0.047619048 | BE14: =$C14*BD14 -> 196894.55 | BF14: =100%/21 -> 0.047619048 | BG14: =$C14*BF14 -> 196894.55 | BH14: =100%/21 -> 0.047619048 | BI14: =$C14*BH14 -> 196894.55 | BJ14: =100%/21 -> 0.047619048 | BK14: =$C14*BJ14 -> 196894.55 | BL14: =100%/21 -> 0.047619048 | BM14: =$C14*BL14 -> 196894.55 | BN14: =100%/21 -> 0.047619048 | BO14: =$C14*BN14 -> 196894.55 | BP14: =100%/21 -> 0.047619048 | BQ14: =$C14*BP14 -> 196894.55 | BR14: =100%/21 -> 0.047619048 | BS14: =$C14*BR14 -> 196894.55 | BU14: =$C14*BT14 -> 0 | BW14: =$C14*BV14 -> 0 | BY14: =$C14*BX14 -> 0 | CA14: =$C14*BZ14 -> 0 | CC14: =$C14*CB14 -> 0 | CE14: =$C14*CD14 -> 0 | CG14: =$C14*CF14 -> 0 | CI14: =$C14*CH14 -> 0 | CK14: =$C14*CJ14 -> 0 | CM14: =$C14*CL14 -> 0 | CO14: =$C14*CN14 -> 0 | CQ14: =$C14*CP14 -> 0 | CS14: =$C14*CR14 -> 0 | CU14: =$C14*CT14 -> 0
B15: EQUIPAMENTOS E SISTEMAS ESPECIAIS | C15: 1798783 | D15: =C15/$C$26 -> 0.047915724 | E15: =C15/'DISTRIBUIÇÃO CUSTO'!C$30 -> 169.40325 | F15: =SUM(H15,J15,L15,N15,P15,R15,T15,V15,X15,Z15,AB15,AD15,AF15,AH15,AJ15,AL15,,AN15,AP15,AR15,AT15,AV15,AX15,AZ15,BB15,BD15,BF15,BH15,BJ15,BL15,BN15,BP15,BR15,BT15,BV15,BX15,BZ15,CB15,CD15,CF15,CH15,CJ15,CL15,CN15,CP15,CR15,CT15) -> 1 | I15: =$C15*H15 -> 0 | K15: =$C15*J15 -> 0 | M15: =$C15*L15 -> 0 | O15: =$C15*N15 -> 0 | Q15: =$C15*P15 -> 0 | S15: =$C15*R15 -> 0 | U15: =$C15*T15 -> 0 | W15: =$C15*V15 -> 0 | Y15: =$C15*X15 -> 0 | AA15: =$C15*Z15 -> 0 | AC15: =$C15*AB15 -> 0 | AE15: =$C15*AD15 -> 0 | AG15: =$C15*AF15 -> 0 | AI15: =$C15*AH15 -> 0 | AK15: =$C15*AJ15 -> 0 | AM15: =$C15*AL15 -> 0 | AO15: =$C15*AN15 -> 0 | AQ15: =$C15*AP15 -> 0 | AS15: =$C15*AR15 -> 0 | AU15: =$C15*AT15 -> 0 | AW15: =$C15*AV15 -> 0 | AY15: =$C15*AX15 -> 0 | BA15: =$C15*AZ15 -> 0 | BC15: =$C15*BB15 -> 0 | BE15: =$C15*BD15 -> 0 | BG15: =$C15*BF15 -> 0 | BI15: =$C15*BH15 -> 0 | BK15: =$C15*BJ15 -> 0 | BL15: =100%/12 -> 0.083333333 | BM15: =$C15*BL15 -> 149898.58 | BN15: =100%/12 -> 0.083333333 | BO15: =$C15*BN15 -> 149898.58 | BP15: =100%/12 -> 0.083333333 | BQ15: =$C15*BP15 -> 149898.58 | BR15: =100%/12 -> 0.083333333 | BS15: =$C15*BR15 -> 149898.58 | BT15: =100%/12 -> 0.083333333 | BU15: =$C15*BT15 -> 149898.58 | BV15: =100%/12 -> 0.083333333 | BW15: =$C15*BV15 -> 149898.58 | BX15: =100%/12 -> 0.083333333 | BY15: =$C15*BX15 -> 149898.58 | BZ15: =100%/12 -> 0.083333333 | CA15: =$C15*BZ15 -> 149898.58 | CB15: =100%/12 -> 0.083333333 | CC15: =$C15*CB15 -> 149898.58 | CD15: =100%/12 -> 0.083333333 | CE15: =$C15*CD15 -> 149898.58 | CF15: =100%/12 -> 0.083333333 | CG15: =$C15*CF15 -> 149898.58 | CH15: =100%/12 -> 0.083333333 | CI15: =$C15*CH15 -> 149898.58 | CK15: =$C15*CJ15 -> 0 | CM15: =$C15*CL15 -> 0 | CO15: =$C15*CN15 -> 0 | CQ15: =$C15*CP15 -> 0 | CS15: =$C15*CR15 -> 0 | CU15: =$C15*CT15 -> 0
B16: IMPERMEABILIZAÇÃO | C16: 596836.88 | D16: =C16/$C$26 -> 0.015898456 | E16: =C16/'DISTRIBUIÇÃO CUSTO'!C$30 -> 56.208063 | F16: =SUM(H16,J16,L16,N16,P16,R16,T16,V16,X16,Z16,AB16,AD16,AF16,AH16,AJ16,AL16,,AN16,AP16,AR16,AT16,AV16,AX16,AZ16,BB16,BD16,BF16,BH16,BJ16,BL16,BN16,BP16,BR16,BT16,BV16,BX16,BZ16,CB16,CD16,CF16,CH16,CJ16,CL16,CN16,CP16,CR16,CT16) -> 1 | I16: =$C16*H16 -> 0 | K16: =$C16*J16 -> 0 | M16: =$C16*L16 -> 0 | O16: =$C16*N16 -> 0 | Q16: =$C16*P16 -> 0 | S16: =$C16*R16 -> 0 | U16: =$C16*T16 -> 0 | W16: =$C16*V16 -> 0 | Y16: =$C16*X16 -> 0 | AA16: =$C16*Z16 -> 0 | AC16: =$C16*AB16 -> 0 | AE16: =$C16*AD16 -> 0 | AG16: =$C16*AF16 -> 0 | AH16: =100%/21 -> 0.047619048 | AI16: =$C16*AH16 -> 28420.804 | AJ16: =100%/21 -> 0.047619048 | AK16: =$C16*AJ16 -> 28420.804 | AL16: =100%/21 -> 0.047619048 | AM16: =$C16*AL16 -> 28420.804 | AN16: =100%/21 -> 0.047619048 | AO16: =$C16*AN16 -> 28420.804 | AP16: =100%/21 -> 0.047619048 | AQ16: =$C16*AP16 -> 28420.804 | AR16: =100%/21 -> 0.047619048 | AS16: =$C16*AR16 -> 28420.804 | AT16: =100%/21 -> 0.047619048 | AU16: =$C16*AT16 -> 28420.804 | AV16: =100%/21 -> 0.047619048 | AW16: =$C16*AV16 -> 28420.804 | AX16: =100%/21 -> 0.047619048 | AY16: =$C16*AX16 -> 28420.804 | AZ16: =100%/21 -> 0.047619048 | BA16: =$C16*AZ16 -> 28420.804 | BB16: =100%/21 -> 0.047619048 | BC16: =$C16*BB16 -> 28420.804 | BD16: =100%/21 -> 0.047619048 | BE16: =$C16*BD16 -> 28420.804 | BF16: =100%/21 -> 0.047619048 | BG16: =$C16*BF16 -> 28420.804 | BH16: =100%/21 -> 0.047619048 | BI16: =$C16*BH16 -> 28420.804 | BJ16: =100%/21 -> 0.047619048 | BK16: =$C16*BJ16 -> 28420.804 | BL16: =100%/21 -> 0.047619048 | BM16: =$C16*BL16 -> 28420.804 | BN16: =100%/21 -> 0.047619048 | BO16: =$C16*BN16 -> 28420.804 | BP16: =100%/21 -> 0.047619048 | BQ16: =$C16*BP16 -> 28420.804 | BR16: =100%/21 -> 0.047619048 | BS16: =$C16*BR16 -> 28420.804 | BT16: =100%/21 -> 0.047619048 | BU16: =$C16*BT16 -> 28420.804 | BV16: =100%/21 -> 0.047619048 | BW16: =$C16*BV16 -> 28420.804 | BY16: =$C16*BX16 -> 0 | CA16: =$C16*BZ16 -> 0 | CC16: =$C16*CB16 -> 0 | CE16: =$C16*CD16 -> 0 | CG16: =$C16*CF16 -> 0 | CI16: =$C16*CH16 -> 0 | CK16: =$C16*CJ16 -> 0 | CM16: =$C16*CL16 -> 0 | CO16: =$C16*CN16 -> 0 | CQ16: =$C16*CP16 -> 0 | CS16: =$C16*CR16 -> 0 | CU16: =$C16*CT16 -> 0
B17: REVESTIMENTOS INTERNOS EM PISO E PAREDE | C17: 1820366.9 | D17: =C17/$C$26 -> 0.048490673 | E17: =C17/'DISTRIBUIÇÃO CUSTO'!C$30 -> 171.43595 | F17: =SUM(H17,J17,L17,N17,P17,R17,T17,V17,X17,Z17,AB17,AD17,AF17,AH17,AJ17,AL17,,AN17,AP17,AR17,AT17,AV17,AX17,AZ17,BB17,BD17,BF17,BH17,BJ17,BL17,BN17,BP17,BR17,BT17,BV17,BX17,BZ17,CB17,CD17,CF17,CH17,CJ17,CL17,CN17,CP17,CR17,CT17) -> 1 | I17: =$C17*H17 -> 0 | K17: =$C17*J17 -> 0 | M17: =$C17*L17 -> 0 | O17: =$C17*N17 -> 0 | Q17: =$C17*P17 -> 0 | S17: =$C17*R17 -> 0 | U17: =$C17*T17 -> 0 | W17: =$C17*V17 -> 0 | Y17: =$C17*X17 -> 0 | AA17: =$C17*Z17 -> 0 | AC17: =$C17*AB17 -> 0 | AE17: =$C17*AD17 -> 0 | AF17: =100%/21 -> 0.047619048 | AG17: =$C17*AF17 -> 86684.137 | AH17: =100%/21 -> 0.047619048 | AI17: =$C17*AH17 -> 86684.137 | AJ17: =100%/21 -> 0.047619048 | AK17: =$C17*AJ17 -> 86684.137 | AL17: =100%/21 -> 0.047619048 | AM17: =$C17*AL17 -> 86684.137 | AN17: =100%/21 -> 0.047619048 | AO17: =$C17*AN17 -> 86684.137 | AP17: =100%/21 -> 0.047619048 | AQ17: =$C17*AP17 -> 86684.137 | AR17: =100%/21 -> 0.047619048 | AS17: =$C17*AR17 -> 86684.137 | AT17: =100%/21 -> 0.047619048 | AU17: =$C17*AT17 -> 86684.137 | AV17: =100%/21 -> 0.047619048 | AW17: =$C17*AV17 -> 86684.137 | AX17: =100%/21 -> 0.047619048 | AY17: =$C17*AX17 -> 86684.137 | AZ17: =100%/21 -> 0.047619048 | BA17: =$C17*AZ17 -> 86684.137 | BB17: =100%/21 -> 0.047619048 | BC17: =$C17*BB17 -> 86684.137 | BD17: =100%/21 -> 0.047619048 | BE17: =$C17*BD17 -> 86684.137 | BF17: =100%/21 -> 0.047619048 | BG17: =$C17*BF17 -> 86684.137 | BH17: =100%/21 -> 0.047619048 | BI17: =$C17*BH17 -> 86684.137 | BJ17: =100%/21 -> 0.047619048 | BK17: =$C17*BJ17 -> 86684.137 | BL17: =100%/21 -> 0.047619048 | BM17: =$C17*BL17 -> 86684.137 | BN17: =100%/21 -> 0.047619048 | BO17: =$C17*BN17 -> 86684.137 | BP17: =100%/21 -> 0.047619048 | BQ17: =$C17*BP17 -> 86684.137 | BR17: =100%/21 -> 0.047619048 | BS17: =$C17*BR17 -> 86684.137 | BT17: =100%/21 -> 0.047619048 | BU17: =$C17*BT17 -> 86684.137 | CC17: =$C17*CB17 -> 0 | CE17: =$C17*CD17 -> 0 | CG17: =$C17*CF17 -> 0 | CI17: =$C17*CH17 -> 0 | CK17: =$C17*CJ17 -> 0 | CM17: =$C17*CL17 -> 0 | CO17: =$C17*CN17 -> 0 | CQ17: =$C17*CP17 -> 0 | CS17: =$C17*CR17 -> 0 | CU17: =$C17*CT17 -> 0
B18: REVESTIMENTOS E ACABAMENTOS INTERNOS EM TETO | C18: 710184.99 | D18: =C18/$C$26 -> 0.018917806 | E18: =C18/'DISTRIBUIÇÃO CUSTO'!C$30 -> 66.882801 | F18: =SUM(H18,J18,L18,N18,P18,R18,T18,V18,X18,Z18,AB18,AD18,AF18,AH18,AJ18,AL18,,AN18,AP18,AR18,AT18,AV18,AX18,AZ18,BB18,BD18,BF18,BH18,BJ18,BL18,BN18,BP18,BR18,BT18,BV18,BX18,BZ18,CB18,CD18,CF18,CH18,CJ18,CL18,CN18,CP18,CR18,CT18) -> 1 | I18: =$C18*H18 -> 0 | K18: =$C18*J18 -> 0 | M18: =$C18*L18 -> 0 | O18: =$C18*N18 -> 0 | Q18: =$C18*P18 -> 0 | S18: =$C18*R18 -> 0 | U18: =$C18*T18 -> 0 | W18: =$C18*V18 -> 0 | Y18: =$C18*X18 -> 0 | AA18: =$C18*Z18 -> 0 | AC18: =$C18*AB18 -> 0 | AE18: =$C18*AD18 -> 0 | AG18: =$C18*AF18 -> 0 | AI18: =$C18*AH18 -> 0 | AK18: =$C18*AJ18 -> 0 | AL18: =100%/21 -> 0.047619048 | AM18: =$C18*AL18 -> 33818.333 | AN18: =100%/21 -> 0.047619048 | AO18: =$C18*AN18 -> 33818.333 | AP18: =100%/21 -> 0.047619048 | AQ18: =$C18*AP18 -> 33818.333 | AR18: =100%/21 -> 0.047619048 | AS18: =$C18*AR18 -> 33818.333 | AT18: =100%/21 -> 0.047619048 | AU18: =$C18*AT18 -> 33818.333 | AV18: =100%/21 -> 0.047619048 | AW18: =$C18*AV18 -> 33818.333 | AX18: =100%/21 -> 0.047619048 | AY18: =$C18*AX18 -> 33818.333 | AZ18: =100%/21 -> 0.047619048 | BA18: =$C18*AZ18 -> 33818.333 | BB18: =100%/21 -> 0.047619048 | BC18: =$C18*BB18 -> 33818.333 | BD18: =100%/21 -> 0.047619048 | BE18: =$C18*BD18 -> 33818.333 | BF18: =100%/21 -> 0.047619048 | BG18: =$C18*BF18 -> 33818.333 | BH18: =100%/21 -> 0.047619048 | BI18: =$C18*BH18 -> 33818.333 | BJ18: =100%/21 -> 0.047619048 | BK18: =$C18*BJ18 -> 33818.333 | BL18: =100%/21 -> 0.047619048 | BM18: =$C18*BL18 -> 33818.333 | BN18: =100%/21 -> 0.047619048 | BO18: =$C18*BN18 -> 33818.333 | BP18: =100%/21 -> 0.047619048 | BQ18: =$C18*BP18 -> 33818.333 | BR18: =100%/21 -> 0.047619048 | BS18: =$C18*BR18 -> 33818.333 | BT18: =100%/21 -> 0.047619048 | BU18: =$C18*BT18 -> 33818.333 | BV18: =100%/21 -> 0.047619048 | BW18: =$C18*BV18 -> 33818.333 | BX18: =100%/21 -> 0.047619048 | BY18: =$C18*BX18 -> 33818.333 | BZ18: =100%/21 -> 0.047619048 | CA18: =$C18*BZ18 -> 33818.333 | CI18: =$C18*CH18 -> 0 | CK18: =$C18*CJ18 -> 0 | CM18: =$C18*CL18 -> 0 | CO18: =$C18*CN18 -> 0 | CQ18: =$C18*CP18 -> 0 | CS18: =$C18*CR18 -> 0 | CU18: =$C18*CT18 -> 0
B19: ACABAMENTOS EM PISO E PAREDE | C19: 1725597 | D19: =C19/$C$26 -> 0.045966205 | E19: =C19/'DISTRIBUIÇÃO CUSTO'!C$30 -> 162.51084 | F19: =SUM(H19,J19,L19,N19,P19,R19,T19,V19,X19,Z19,AB19,AD19,AF19,AH19,AJ19,AL19,,AN19,AP19,AR19,AT19,AV19,AX19,AZ19,BB19,BD19,BF19,BH19,BJ19,BL19,BN19,BP19,BR19,BT19,BV19,BX19,BZ19,CB19,CD19,CF19,CH19,CJ19,CL19,CN19,CP19,CR19,CT19) -> 1 | I19: =$C19*H19 -> 0 | K19: =$C19*J19 -> 0 | M19: =$C19*L19 -> 0 | O19: =$C19*N19 -> 0 | Q19: =$C19*P19 -> 0 | S19: =$C19*R19 -> 0 | U19: =$C19*T19 -> 0 | W19: =$C19*V19 -> 0 | Y19: =$C19*X19 -> 0 | AA19: =$C19*Z19 -> 0 | AC19: =$C19*AB19 -> 0 | AE19: =$C19*AD19 -> 0 | AG19: =$C19*AF19 -> 0 | AI19: =$C19*AH19 -> 0 | AJ19: =100%/24 -> 0.041666667 | AK19: =$C19*AJ19 -> 71899.873 | AL19: =100%/24 -> 0.041666667 | AM19: =$C19*AL19 -> 71899.873 | AN19: =100%/24 -> 0.041666667 | AO19: =$C19*AN19 -> 71899.873 | AP19: =100%/24 -> 0.041666667 | AQ19: =$C19*AP19 -> 71899.873 | AR19: =100%/24 -> 0.041666667 | AS19: =$C19*AR19 -> 71899.873 | AT19: =100%/24 -> 0.041666667 | AU19: =$C19*AT19 -> 71899.873 | AV19: =100%/24 -> 0.041666667 | AW19: =$C19*AV19 -> 71899.873 | AX19: =100%/24 -> 0.041666667 | AY19: =$C19*AX19 -> 71899.873 | AZ19: =100%/24 -> 0.041666667 | BA19: =$C19*AZ19 -> 71899.873 | BB19: =100%/24 -> 0.041666667 | BC19: =$C19*BB19 -> 71899.873 | BD19: =100%/24 -> 0.041666667 | BE19: =$C19*BD19 -> 71899.873 | BF19: =100%/24 -> 0.041666667 | BG19: =$C19*BF19 -> 71899.873 | BH19: =100%/24 -> 0.041666667 | BI19: =$C19*BH19 -> 71899.873 | BJ19: =100%/24 -> 0.041666667 | BK19: =$C19*BJ19 -> 71899.873 | BL19: =100%/24 -> 0.041666667 | BM19: =$C19*BL19 -> 71899.873 | BN19: =100%/24 -> 0.041666667 | BO19: =$C19*BN19 -> 71899.873 | BP19: =100%/24 -> 0.041666667 | BQ19: =$C19*BP19 -> 71899.873 | BR19: =100%/24 -> 0.041666667 | BS19: =$C19*BR19 -> 71899.873 | BT19: =100%/24 -> 0.041666667 | BU19: =$C19*BT19 -> 71899.873 | BV19: =100%/24 -> 0.041666667 | BW19: =$C19*BV19 -> 71899.873 | BX19: =100%/24 -> 0.041666667 | BY19: =$C19*BX19 -> 71899.873 | BZ19: =100%/24 -> 0.041666667 | CA19: =$C19*BZ19 -> 71899.873 | CB19: =100%/24 -> 0.041666667 | CC19: =$C19*CB19 -> 71899.873 | CD19: =100%/24 -> 0.041666667 | CE19: =$C19*CD19 -> 71899.873 | CM19: =$C19*CL19 -> 0 | CO19: =$C19*CN19 -> 0 | CQ19: =$C19*CP19 -> 0 | CS19: =$C19*CR19 -> 0 | CU19: =$C19*CT19 -> 0
B20: PINTURA INTERNA | C20: 1897364.8 | D20: =C20/$C$26 -> 0.050541731 | E20: =C20/'DISTRIBUIÇÃO CUSTO'!C$30 -> 178.68734 | F20: =SUM(H20,J20,L20,N20,P20,R20,T20,V20,X20,Z20,AB20,AD20,AF20,AH20,AJ20,AL20,,AN20,AP20,AR20,AT20,AV20,AX20,AZ20,BB20,BD20,BF20,BH20,BJ20,BL20,BN20,BP20,BR20,BT20,BV20,BX20,BZ20,CB20,CD20,CF20,CH20,CJ20,CL20,CN20,CP20,CR20,CT20) -> 1 | I20: =$C20*H20 -> 0 | K20: =$C20*J20 -> 0 | M20: =$C20*L20 -> 0 | O20: =$C20*N20 -> 0 | Q20: =$C20*P20 -> 0 | S20: =$C20*R20 -> 0 | U20: =$C20*T20 -> 0 | W20: =$C20*V20 -> 0 | Y20: =$C20*X20 -> 0 | AA20: =$C20*Z20 -> 0 | AC20: =$C20*AB20 -> 0 | AE20: =$C20*AD20 -> 0 | AG20: =$C20*AF20 -> 0 | AI20: =$C20*AH20 -> 0 | AK20: =$C20*AJ20 -> 0 | AM20: =$C20*AL20 -> 0 | AN20: =100%/29 -> 0.034482759 | AO20: =$C20*AN20 -> 65426.371 | AP20: =100%/29 -> 0.034482759 | AQ20: =$C20*AP20 -> 65426.371 | AR20: =100%/29 -> 0.034482759 | AS20: =$C20*AR20 -> 65426.371 | AT20: =100%/29 -> 0.034482759 | AU20: =$C20*AT20 -> 65426.371 | AV20: =100%/29 -> 0.034482759 | AW20: =$C20*AV20 -> 65426.371 | AX20: =100%/29 -> 0.034482759 | AY20: =$C20*AX20 -> 65426.371 | AZ20: =100%/29 -> 0.034482759 | BA20: =$C20*AZ20 -> 65426.371 | BB20: =100%/29 -> 0.034482759 | BC20: =$C20*BB20 -> 65426.371 | BD20: =100%/29 -> 0.034482759 | BE20: =$C20*BD20 -> 65426.371 | BF20: =100%/29 -> 0.034482759 | BG20: =$C20*BF20 -> 65426.371 | BH20: =100%/29 -> 0.034482759 | BI20: =$C20*BH20 -> 65426.371 | BJ20: =100%/29 -> 0.034482759 | BK20: =$C20*BJ20 -> 65426.371 | BL20: =100%/29 -> 0.034482759 | BM20: =$C20*BL20 -> 65426.371 | BN20: =100%/29 -> 0.034482759 | BO20: =$C20*BN20 -> 65426.371 | BP20: =100%/29 -> 0.034482759 | BQ20: =$C20*BP20 -> 65426.371 | BR20: =100%/29 -> 0.034482759 | BS20: =$C20*BR20 -> 65426.371 | BT20: =100%/29 -> 0.034482759 | BU20: =$C20*BT20 -> 65426.371 | BV20: =100%/29 -> 0.034482759 | BW20: =$C20*BV20 -> 65426.371 | BX20: =100%/29 -> 0.034482759 | BY20: =$C20*BX20 -> 65426.371 | BZ20: =100%/29 -> 0.034482759 | CA20: =$C20*BZ20 -> 65426.371 | CB20: =100%/29 -> 0.034482759 | CC20: =$C20*CB20 -> 65426.371 | CD20: =100%/29 -> 0.034482759 | CE20: =$C20*CD20 -> 65426.371 | CF20: =100%/29 -> 0.034482759 | CG20: =$C20*CF20 -> 65426.371 | CH20: =100%/29 -> 0.034482759 | CI20: =$C20*CH20 -> 65426.371 | CJ20: =100%/29 -> 0.034482759 | CK20: =$C20*CJ20 -> 65426.371 | CL20: =100%/29 -> 0.034482759 | CM20: =$C20*CL20 -> 65426.371 | CN20: =100%/29 -> 0.034482759 | CO20: =$C20*CN20 -> 65426.371 | CP20: =100%/29 -> 0.034482759 | CQ20: =$C20*CP20 -> 65426.371 | CR20: =100%/29 -> 0.034482759 | CS20: =$C20*CR20 -> 65426.371
B21: ESQUADRIAS, VIDROS E FERRAGENS | C21: 4058876.5 | D21: =C21/$C$26 -> 0.10811977 | E21: =C21/'DISTRIBUIÇÃO CUSTO'!C$30 -> 382.25115 | F21: =SUM(H21,J21,L21,N21,P21,R21,T21,V21,X21,Z21,AB21,AD21,AF21,AH21,AJ21,AL21,,AN21,AP21,AR21,AT21,AV21,AX21,AZ21,BB21,BD21,BF21,BH21,BJ21,BL21,BN21,BP21,BR21,BT21,BV21,BX21,BZ21,CB21,CD21,CF21,CH21,CJ21,CL21,CN21,CP21,CR21,CT21) -> 1 | I21: =$C21*H21 -> 0 | K21: =$C21*J21 -> 0 | M21: =$C21*L21 -> 0 | O21: =$C21*N21 -> 0 | Q21: =$C21*P21 -> 0 | S21: =$C21*R21 -> 0 | U21: =$C21*T21 -> 0 | W21: =$C21*V21 -> 0 | Y21: =$C21*X21 -> 0 | AA21: =$C21*Z21 -> 0 | AC21: =$C21*AB21 -> 0 | AE21: =$C21*AD21 -> 0 | AG21: =$C21*AF21 -> 0 | AI21: =$C21*AH21 -> 0 | AK21: =$C21*AJ21 -> 0 | AM21: =$C21*AL21 -> 0 | AO21: =$C21*AN21 -> 0 | AQ21: =$C21*AP21 -> 0 | AS21: =$C21*AR21 -> 0 | AU21: =$C21*AT21 -> 0 | AW21: =$C21*AV21 -> 0 | AY21: =$C21*AX21 -> 0 | BA21: =$C21*AZ21 -> 0 | BC21: =$C21*BB21 -> 0 | BE21: =$C21*BD21 -> 0 | BG21: =$C21*BF21 -> 0 | BI21: =$C21*BH21 -> 0 | BK21: =$C21*BJ21 -> 0 | BM21: =$C21*BL21 -> 0 | BO21: =$C21*BN21 -> 0 | BQ21: =$C21*BP21 -> 0 | BS21: =$C21*BR21 -> 0 | BT21: =100%/12 -> 0.083333333 | BU21: =$C21*BT21 -> 338239.71 | BV21: =100%/12 -> 0.083333333 | BW21: =$C21*BV21 -> 338239.71 | BX21: =100%/12 -> 0.083333333 | BY21: =$C21*BX21 -> 338239.71 | BZ21: =100%/12 -> 0.083333333 | CA21: =$C21*BZ21 -> 338239.71 | CB21: =100%/12 -> 0.083333333 | CC21: =$C21*CB21 -> 338239.71 | CD21: =100%/12 -> 0.083333333 | CE21: =$C21*CD21 -> 338239.71 | CF21: =100%/12 -> 0.083333333 | CG21: =$C21*CF21 -> 338239.71 | CH21: =100%/12 -> 0.083333333 | CI21: =$C21*CH21 -> 338239.71 | CJ21: =100%/12 -> 0.083333333 | CK21: =$C21*CJ21 -> 338239.71 | CL21: =100%/12 -> 0.083333333 | CM21: =$C21*CL21 -> 338239.71 | CN21: =100%/12 -> 0.083333333 | CO21: =$C21*CN21 -> 338239.71 | CP21: =100%/12 -> 0.083333333 | CQ21: =$C21*CP21 -> 338239.71 | CS21: =$C21*CR21 -> 0
B22: COBERTURA | C22: 184819.86 | D22: =C22/$C$26 -> 0.0049232049 | E22: =C22/'DISTRIBUIÇÃO CUSTO'!C$30 -> 17.405704 | F22: =SUM(H22,J22,L22,N22,P22,R22,T22,V22,X22,Z22,AB22,AD22,AF22,AH22,AJ22,AL22,,AN22,AP22,AR22,AT22,AV22,AX22,AZ22,BB22,BD22,BF22,BH22,BJ22,BL22,BN22,BP22,BR22,BT22,BV22,BX22,BZ22,CB22,CD22,CF22,CH22,CJ22,CL22,CN22,CP22,CR22,CT22) -> 1 | I22: =$C22*H22 -> 0 | K22: =$C22*J22 -> 0 | M22: =$C22*L22 -> 0 | O22: =$C22*N22 -> 0 | Q22: =$C22*P22 -> 0 | S22: =$C22*R22 -> 0 | U22: =$C22*T22 -> 0 | W22: =$C22*V22 -> 0 | Y22: =$C22*X22 -> 0 | AA22: =$C22*Z22 -> 0 | AC22: =$C22*AB22 -> 0 | AE22: =$C22*AD22 -> 0 | AG22: =$C22*AF22 -> 0 | AI22: =$C22*AH22 -> 0 | AK22: =$C22*AJ22 -> 0 | AM22: =$C22*AL22 -> 0 | AO22: =$C22*AN22 -> 0 | AQ22: =$C22*AP22 -> 0 | AS22: =$C22*AR22 -> 0 | AU22: =$C22*AT22 -> 0 | AW22: =$C22*AV22 -> 0 | AY22: =$C22*AX22 -> 0 | BA22: =$C22*AZ22 -> 0 | BC22: =$C22*BB22 -> 0 | BE22: =$C22*BD22 -> 0 | BG22: =$C22*BF22 -> 0 | BI22: =$C22*BH22 -> 0 | BK22: =$C22*BJ22 -> 0 | BM22: =$C22*BL22 -> 0 | BO22: =$C22*BN22 -> 0 | BP22: =100%/4 -> 0.25 | BQ22: =$C22*BP22 -> 46204.964 | BR22: =100%/4 -> 0.25 | BS22: =$C22*BR22 -> 46204.964 | BT22: =100%/4 -> 0.25 | BU22: =$C22*BT22 -> 46204.964 | BV22: =100%/4 -> 0.25 | BW22: =$C22*BV22 -> 46204.964 | BY22: =$C22*BX22 -> 0 | CA22: =$C22*BZ22 -> 0 | CC22: =$C22*CB22 -> 0 | CE22: =$C22*CD22 -> 0 | CG22: =$C22*CF22 -> 0 | CI22: =$C22*CH22 -> 0 | CK22: =$C22*CJ22 -> 0 | CM22: =$C22*CL22 -> 0 | CO22: =$C22*CN22 -> 0 | CQ22: =$C22*CP22 -> 0 | CU22: =$C22*CT22 -> 0
B23: REVESTIMENTOS E ACABAMENTOS DE FACHADA | C23: 1847312.6 | D23: =C23/$C$26 -> 0.04920845 | E23: =C23/'DISTRIBUIÇÃO CUSTO'!C$30 -> 173.97361 | F23: =SUM(H23,J23,L23,N23,P23,R23,T23,V23,X23,Z23,AB23,AD23,AF23,AH23,AJ23,AL23,,AN23,AP23,AR23,AT23,AV23,AX23,AZ23,BB23,BD23,BF23,BH23,BJ23,BL23,BN23,BP23,BR23,BT23,BV23,BX23,BZ23,CB23,CD23,CF23,CH23,CJ23,CL23,CN23,CP23,CR23,CT23) -> 1 | I23: =$C23*H23 -> 0 | K23: =$C23*J23 -> 0 | M23: =$C23*L23 -> 0 | O23: =$C23*N23 -> 0 | Q23: =$C23*P23 -> 0 | S23: =$C23*R23 -> 0 | U23: =$C23*T23 -> 0 | W23: =$C23*V23 -> 0 | Y23: =$C23*X23 -> 0 | AA23: =$C23*Z23 -> 0 | AC23: =$C23*AB23 -> 0 | AE23: =$C23*AD23 -> 0 | AG23: =$C23*AF23 -> 0 | AI23: =$C23*AH23 -> 0 | AK23: =$C23*AJ23 -> 0 | AM23: =$C23*AL23 -> 0 | AO23: =$C23*AN23 -> 0 | AQ23: =$C23*AP23 -> 0 | AS23: =$C23*AR23 -> 0 | AU23: =$C23*AT23 -> 0 | AW23: =$C23*AV23 -> 0 | AY23: =$C23*AX23 -> 0 | BA23: =$C23*AZ23 -> 0 | BC23: =$C23*BB23 -> 0 | BE23: =$C23*BD23 -> 0 | BG23: =$C23*BF23 -> 0 | BI23: =$C23*BH23 -> 0 | BK23: =$C23*BJ23 -> 0 | BL23: =100%/13 -> 0.076923077 | BM23: =$C23*BL23 -> 142100.97 | BN23: =100%/13 -> 0.076923077 | BO23: =$C23*BN23 -> 142100.97 | BP23: =100%/13 -> 0.076923077 | BQ23: =$C23*BP23 -> 142100.97 | BR23: =100%/13 -> 0.076923077 | BS23: =$C23*BR23 -> 142100.97 | BT23: =100%/13 -> 0.076923077 | BU23: =$C23*BT23 -> 142100.97 | BV23: =100%/13 -> 0.076923077 | BW23: =$C23*BV23 -> 142100.97 | BX23: =100%/13 -> 0.076923077 | BY23: =$C23*BX23 -> 142100.97 | BZ23: =100%/13 -> 0.076923077 | CA23: =$C23*BZ23 -> 142100.97 | CB23: =100%/13 -> 0.076923077 | CC23: =$C23*CB23 -> 142100.97 | CD23: =100%/13 -> 0.076923077 | CE23: =$C23*CD23 -> 142100.97 | CF23: =100%/13 -> 0.076923077 | CG23: =$C23*CF23 -> 142100.97 | CH23: =100%/13 -> 0.076923077 | CI23: =$C23*CH23 -> 142100.97 | CJ23: =100%/13 -> 0.076923077 | CK23: =$C23*CJ23 -> 142100.97 | CM23: =$C23*CL23 -> 0 | CO23: =$C23*CN23 -> 0 | CQ23: =$C23*CP23 -> 0 | CS23: =$C23*CR23 -> 0 | CU23: =$C23*CT23 -> 0
B24: SERVIÇOS COMPLEMENTARES | C24: 1857288.5 | D24: =C24/$C$26 -> 0.049474186 | E24: =C24/'DISTRIBUIÇÃO CUSTO'!C$30 -> 174.9131 | F24: =SUM(H24,J24,L24,N24,P24,R24,T24,V24,X24,Z24,AB24,AD24,AF24,AH24,AJ24,AL24,,AN24,AP24,AR24,AT24,AV24,AX24,AZ24,BB24,BD24,BF24,BH24,BJ24,BL24,BN24,BP24,BR24,BT24,BV24,BX24,BZ24,CB24,CD24,CF24,CH24,CJ24,CL24,CN24,CP24,CR24,CT24) -> 1 | I24: =$C24*H24 -> 0 | K24: =$C24*J24 -> 0 | M24: =$C24*L24 -> 0 | O24: =$C24*N24 -> 0 | Q24: =$C24*P24 -> 0 | S24: =$C24*R24 -> 0 | U24: =$C24*T24 -> 0 | W24: =$C24*V24 -> 0 | Y24: =$C24*X24 -> 0 | AA24: =$C24*Z24 -> 0 | AC24: =$C24*AB24 -> 0 | AE24: =$C24*AD24 -> 0 | AG24: =$C24*AF24 -> 0 | AI24: =$C24*AH24 -> 0 | AK24: =$C24*AJ24 -> 0 | AM24: =$C24*AL24 -> 0 | AO24: =$C24*AN24 -> 0 | AQ24: =$C24*AP24 -> 0 | AS24: =$C24*AR24 -> 0 | AU24: =$C24*AT24 -> 0 | AW24: =$C24*AV24 -> 0 | AY24: =$C24*AX24 -> 0 | BA24: =$C24*AZ24 -> 0 | BC24: =$C24*BB24 -> 0 | BE24: =$C24*BD24 -> 0 | BG24: =$C24*BF24 -> 0 | BI24: =$C24*BH24 -> 0 | BK24: =$C24*BJ24 -> 0 | BM24: =$C24*BL24 -> 0 | BO24: =$C24*BN24 -> 0 | BQ24: =$C24*BP24 -> 0 | BS24: =$C24*BR24 -> 0 | BU24: =$C24*BT24 -> 0 | BW24: =$C24*BV24 -> 0 | BY24: =$C24*BX24 -> 0 | CA24: =$C24*BZ24 -> 0 | CB24: =100%/10 -> 0.1 | CC24: =$C24*CB24 -> 185728.85 | CD24: =100%/10 -> 0.1 | CE24: =$C24*CD24 -> 185728.85 | CF24: =100%/10 -> 0.1 | CG24: =$C24*CF24 -> 185728.85 | CH24: =100%/10 -> 0.1 | CI24: =$C24*CH24 -> 185728.85 | CJ24: =100%/10 -> 0.1 | CK24: =$C24*CJ24 -> 185728.85 | CL24: =100%/10 -> 0.1 | CM24: =$C24*CL24 -> 185728.85 | CN24: =100%/10 -> 0.1 | CO24: =$C24*CN24 -> 185728.85 | CP24: =100%/10 -> 0.1 | CQ24: =$C24*CP24 -> 185728.85 | CR24: =100%/10 -> 0.1 | CS24: =$C24*CR24 -> 185728.85 | CT24: =100%/10 -> 0.1 | CU24: =$C24*CT24 -> 185728.85
B25: IMPREVISTOS E CONTINGENCIAS | C25: 1093414.3 | D25: =C25/$C$26 -> 0.029126214 | E25: =C25/'DISTRIBUIÇÃO CUSTO'!C$30 -> 102.97403 | F25: =SUM(H25,J25,L25,N25,P25,R25,T25,V25,X25,Z25,AB25,AD25,AF25,AH25,AJ25,AL25,,AN25,AP25,AR25,AT25,AV25,AX25,AZ25,BB25,BD25,BF25,BH25,BJ25,BL25,BN25,BP25,BR25,BT25,BV25,BX25,BZ25,CB25,CD25,CF25,CH25,CJ25,CL25,CN25,CP25,CR25,CT25) -> 1 | H25: =100%/$E$30 -> 0.02173913 | I25: =$C25*H25 -> 23769.876 | J25: =100%/$E$30 -> 0.02173913 | K25: =$C25*J25 -> 23769.876 | L25: =100%/$E$30 -> 0.02173913 | M25: =$C25*L25 -> 23769.876 | N25: =100%/$E$30 -> 0.02173913 | O25: =$C25*N25 -> 23769.876 | P25: =100%/$E$30 -> 0.02173913 | Q25: =$C25*P25 -> 23769.876 | R25: =100%/$E$30 -> 0.02173913 | S25: =$C25*R25 -> 23769.876 | T25: =100%/$E$30 -> 0.02173913 | U25: =$C25*T25 -> 23769.876 | V25: =100%/$E$30 -> 0.02173913 | W25: =$C25*V25 -> 23769.876 | X25: =100%/$E$30 -> 0.02173913 | Y25: =$C25*X25 -> 23769.876 | Z25: =100%/$E$30 -> 0.02173913 | AA25: =$C25*Z25 -> 23769.876 | AB25: =100%/$E$30 -> 0.02173913 | AC25: =$C25*AB25 -> 23769.876 | AD25: =100%/$E$30 -> 0.02173913 | AE25: =$C25*AD25 -> 23769.876 | AF25: =100%/$E$30 -> 0.02173913 | AG25: =$C25*AF25 -> 23769.876 | AH25: =100%/$E$30 -> 0.02173913 | AI25: =$C25*AH25 -> 23769.876 | AJ25: =100%/$E$30 -> 0.02173913 | AK25: =$C25*AJ25 -> 23769.876 | AL25: =100%/$E$30 -> 0.02173913 | AM25: =$C25*AL25 -> 23769.876 | AN25: =100%/$E$30 -> 0.02173913 | AO25: =$C25*AN25 -> 23769.876 | AP25: =100%/$E$30 -> 0.02173913 | AQ25: =$C25*AP25 -> 23769.876 | AR25: =100%/$E$30 -> 0.02173913 | AS25: =$C25*AR25 -> 23769.876 | AT25: =100%/$E$30 -> 0.02173913 | AU25: =$C25*AT25 -> 23769.876 | AV25: =100%/$E$30 -> 0.02173913 | AW25: =$C25*AV25 -> 23769.876 | AX25: =100%/$E$30 -> 0.02173913 | AY25: =$C25*AX25 -> 23769.876 | AZ25: =100%/$E$30 -> 0.02173913 | BA25: =$C25*AZ25 -> 23769.876 | BB25: =100%/$E$30 -> 0.02173913 | BC25: =$C25*BB25 -> 23769.876 | BD25: =100%/$E$30 -> 0.02173913 | BE25: =$C25*BD25 -> 23769.876 | BF25: =100%/$E$30 -> 0.02173913 | BG25: =$C25*BF25 -> 23769.876 | BH25: =100%/$E$30 -> 0.02173913 | BI25: =$C25*BH25 -> 23769.876 | BJ25: =100%/$E$30 -> 0.02173913 | BK25: =$C25*BJ25 -> 23769.876 | BL25: =100%/$E$30 -> 0.02173913 | BM25: =$C25*BL25 -> 23769.876 | BN25: =100%/$E$30 -> 0.02173913 | BO25: =$C25*BN25 -> 23769.876 | BP25: =100%/$E$30 -> 0.02173913 | BQ25: =$C25*BP25 -> 23769.876 | BR25: =100%/$E$30 -> 0.02173913 | BS25: =$C25*BR25 -> 23769.876 | BT25: =100%/$E$30 -> 0.02173913 | BU25: =$C25*BT25 -> 23769.876 | BV25: =100%/$E$30 -> 0.02173913 | BW25: =$C25*BV25 -> 23769.876 | BX25: =100%/$E$30 -> 0.02173913 | BY25: =$C25*BX25 -> 23769.876 | BZ25: =100%/$E$30 -> 0.02173913 | CA25: =$C25*BZ25 -> 23769.876 | CB25: =100%/$E$30 -> 0.02173913 | CC25: =$C25*CB25 -> 23769.876 | CD25: =100%/$E$30 -> 0.02173913 | CE25: =$C25*CD25 -> 23769.876 | CF25: =100%/$E$30 -> 0.02173913 | CG25: =$C25*CF25 -> 23769.876 | CH25: =100%/$E$30 -> 0.02173913 | CI25: =$C25*CH25 -> 23769.876 | CJ25: =100%/$E$30 -> 0.02173913 | CK25: =$C25*CJ25 -> 23769.876 | CL25: =100%/$E$30 -> 0.02173913 | CM25: =$C25*CL25 -> 23769.876 | CN25: =100%/$E$30 -> 0.02173913 | CO25: =$C25*CN25 -> 23769.876 | CP25: =100%/$E$30 -> 0.02173913 | CQ25: =$C25*CP25 -> 23769.876 | CR25: =100%/$E$30 -> 0.02173913 | CS25: =$C25*CR25 -> 23769.876 | CT25: =100%/$E$30 -> 0.02173913 | CU25: =$C25*CT25 -> 23769.876
B26: TOTAL | C26: =SUM(C9:C25) -> 37540557 | D26: =SUM(D9:D25) -> 1 | E26: =SUM(E9:E25) -> 3535.4417 | I26: =SUM(I9:I25) -> 740763.51 | K26: =SUM(K9:K25) -> 565069.27 | M26: =SUM(M9:M25) -> 565069.27 | O26: =SUM(O9:O25) -> 506424.37 | Q26: =SUM(Q9:Q25) -> 506424.37 | S26: =SUM(S9:S25) -> 506424.37 | U26: =SUM(U9:U25) -> 463932.04 | W26: =SUM(W9:W25) -> 463932.04 | Y26: =SUM(Y9:Y25) -> 463932.04 | AA26: =SUM(AA9:AA25) -> 534344.65 | AC26: =SUM(AC9:AC25) -> 534344.65 | AE26: =SUM(AE9:AE25) -> 731239.19 | AG26: =SUM(AG9:AG25) -> 817923.33 | AI26: =SUM(AI9:AI25) -> 846344.13 | AK26: =SUM(AK9:AK25) -> 918244.01 | AM26: =SUM(AM9:AM25) -> 952062.34 | AO26: =SUM(AO9:AO25) -> 1017488.7 | AQ26: =SUM(AQ9:AQ25) -> 1017488.7 | AS26: =SUM(AS9:AS25) -> 1017488.7 | AU26: =SUM(AU9:AU25) -> 1017488.7 | AW26: =SUM(AW9:AW25) -> 1017488.7 | AY26: =SUM(AY9:AY25) -> 1017488.7 | BA26: =SUM(BA9:BA25) -> 1017488.7 | BC26: =SUM(BC9:BC25) -> 1017488.7 | BE26: =SUM(BE9:BE25) -> 1017488.7 | BG26: =SUM(BG9:BG25) -> 1017488.7 | BI26: =SUM(BI9:BI25) -> 1017488.7 | BK26: =SUM(BK9:BK25) -> 1017488.7 | BM26: =SUM(BM9:BM25) -> 943477.53 | BO26: =SUM(BO9:BO25) -> 943477.53 | BQ26: =SUM(BQ9:BQ25) -> 989682.5 | BS26: =SUM(BS9:BS25) -> 919269.89 | BU26: =SUM(BU9:BU25) -> 1060615.1 | BW26: =SUM(BW9:BW25) -> 973930.91 | BY26: =SUM(BY9:BY25) -> 899305.15 | CA26: =SUM(CA9:CA25) -> 899305.15 | CC26: =SUM(CC9:CC25) -> 1051215.7 | CE26: =SUM(CE9:CE25) -> 1051215.7 | CG26: =SUM(CG9:CG25) -> 979315.79 | CI26: =SUM(CI9:CI25) -> 979315.79 | CK26: =SUM(CK9:CK25) -> 829417.21 | CM26: =SUM(CM9:CM25) -> 687316.24 | CO26: =SUM(CO9:CO25) -> 687316.24 | CQ26: =SUM(CQ9:CQ25) -> 687316.24 | CS26: =SUM(CS9:CS25) -> 349076.53 | CU26: =SUM(CU9:CU25) -> 283650.16 | CV26: SOMA TOTAL
B27: CUB/SC | C27: 2725.79 | D27: 45078 | E27: =+E26/C27 -> 1.2970338 | I27: =I26/$C$26 -> 0.019732352 | K27: =K26/$C$26 -> 0.015052234 | M27: =M26/$C$26 -> 0.015052234 | O27: =O26/$C$26 -> 0.01349006 | Q27: =Q26/$C$26 -> 0.01349006 | S27: =S26/$C$26 -> 0.01349006 | U27: =U26/$C$26 -> 0.012358155 | W27: =W26/$C$26 -> 0.012358155 | Y27: =Y26/$C$26 -> 0.012358155 | AA27: =AA26/$C$26 -> 0.014233796 | AC27: =AC26/$C$26 -> 0.014233796 | AE27: =AE26/$C$26 -> 0.019478645 | AG27: =AG26/$C$26 -> 0.021787725 | AI27: =AI26/$C$26 -> 0.022544794 | AK27: =AK26/$C$26 -> 0.024460053 | AM27: =AM26/$C$26 -> 0.025360901 | AO27: =AO26/$C$26 -> 0.027103719 | AQ27: =AQ26/$C$26 -> 0.027103719 | AS27: =AS26/$C$26 -> 0.027103719 | AU27: =AU26/$C$26 -> 0.027103719 | AW27: =AW26/$C$26 -> 0.027103719 | AY27: =AY26/$C$26 -> 0.027103719 | BA27: =BA26/$C$26 -> 0.027103719 | BC27: =BC26/$C$26 -> 0.027103719 | BE27: =BE26/$C$26 -> 0.027103719 | BG27: =BG26/$C$26 -> 0.027103719 | BI27: =BI26/$C$26 -> 0.027103719 | BK27: =BK26/$C$26 -> 0.027103719 | BM27: =BM26/$C$26 -> 0.02513222 | BO27: =BO26/$C$26 -> 0.02513222 | BQ27: =BQ26/$C$26 -> 0.026363021 | BS27: =BS26/$C$26 -> 0.02448738 | BU27: =BU26/$C$26 -> 0.028252512 | BW27: =BW26/$C$26 -> 0.025943432 | BY27: =BY26/$C$26 -> 0.023955562 | CA27: =CA26/$C$26 -> 0.023955562 | CC27: =CC26/$C$26 -> 0.028002133 | CE27: =CE26/$C$26 -> 0.028002133 | CG27: =CG26/$C$26 -> 0.026086874 | CI27: =CI26/$C$26 -> 0.026086874 | CK27: =CK26/$C$26 -> 0.022093897 | CM27: =CM26/$C$26 -> 0.018308632 | CO27: =CO26/$C$26 -> 0.018308632 | CQ27: =CQ26/$C$26 -> 0.018308632 | CS27: =CS26/$C$26 -> 0.0092986507 | CU27: =CU26/$C$26 -> 0.0075558323 | CV27: =SUM(I26:CU26) -> 37540557
C29: ÁREA CONSTRUÍDA | E29: Prazo de obra
C30: 10618.35 | D30: m² | E30: 46
C31: Mês | D31: %
C32: M1 | D32: =I27 -> 0.019732352
C33: M2 | D33: =K27 -> 0.015052234
C34: M3 | D34: =M27 -> 0.015052234
C35: M4 | D35: =O27 -> 0.01349006
C36: M5 | D36: =Q27 -> 0.01349006
C37: M6 | D37: =S27 -> 0.01349006
C38: M7 | D38: =U27 -> 0.012358155
C39: M8 | D39: =W27 -> 0.012358155
C40: M9 | D40: =Y27 -> 0.012358155
C41: M10 | D41: =AA27 -> 0.014233796
C42: M11 | D42: =AC27 -> 0.014233796
C43: M12 | D43: =AE27 -> 0.019478645
C44: M13 | D44: =AG27 -> 0.021787725
C45: M14 | D45: =AI27 -> 0.022544794
...

Sheet CURVA TEÓRICA
B2: CURVA S | % TEÓRICA
B5: MEIA PRAIA EMPREENDIMENTOS - 298
B8: Mês | C8: % AVANÇO | D8: % AVANÇO Acumulado | E8: Valor Planejado | F8: Valor Planejado Acumulado
B9: 1 | C9: ='DISTRIBUIÇÃO CUSTO'!D32 -> 0.019732352 | D9: =C9 -> 0.019732352 | E9: =C9*$F$55 -> 740763.51 | F9: =E9 -> 740763.51
B10: 2 | C10: ='DISTRIBUIÇÃO CUSTO'!D33 -> 0.015052234 | D10: =C10+D9 -> 0.034784587 | E10: =C10*$F$55 -> 565069.27 | F10: =F9+E10 -> 1305832.8
B11: 3 | C11: ='DISTRIBUIÇÃO CUSTO'!D34 -> 0.015052234 | D11: =C11+D10 -> 0.049836821 | E11: =C11*$F$55 -> 565069.27 | F11: =F10+E11 -> 1870902.1
B12: 4 | C12: ='DISTRIBUIÇÃO CUSTO'!D35 -> 0.01349006 | D12: =C12+D11 -> 0.063326881 | E12: =C12*$F$55 -> 506424.37 | F12: =F11+E12 -> 2377326.4
B13: 5 | C13: ='DISTRIBUIÇÃO CUSTO'!D36 -> 0.01349006 | D13: =C13+D12 -> 0.076816942 | E13: =C13*$F$55 -> 506424.37 | F13: =F12+E13 -> 2883750.8
B14: 6 | C14: ='DISTRIBUIÇÃO CUSTO'!D37 -> 0.01349006 | D14: =C14+D13 -> 0.090307002 | E14: =C14*$F$55 -> 506424.37 | F14: =F13+E14 -> 3390175.2
B15: 7 | C15: ='DISTRIBUIÇÃO CUSTO'!D38 -> 0.012358155 | D15: =C15+D14 -> 0.10266516 | E15: =C15*$F$55 -> 463932.04 | F15: =F14+E15 -> 3854107.2
B16: 8 | C16: ='DISTRIBUIÇÃO CUSTO'!D39 -> 0.012358155 | D16: =C16+D15 -> 0.11502331 | E16: =C16*$F$55 -> 463932.04 | F16: =F15+E16 -> 4318039.3
B17: 9 | C17: ='DISTRIBUIÇÃO CUSTO'!D40 -> 0.012358155 | D17: =C17+D16 -> 0.12738147 | E17: =C17*$F$55 -> 463932.04 | F17: =F16+E17 -> 4781971.3
B18: 10 | C18: ='DISTRIBUIÇÃO CUSTO'!D41 -> 0.014233796 | D18: =C18+D17 -> 0.14161526 | E18: =C18*$F$55 -> 534344.65 | F18: =F17+E18 -> 5316315.9
B19: 11 | C19: ='DISTRIBUIÇÃO CUSTO'!D42 -> 0.014233796 | D19: =C19+D18 -> 0.15584906 | E19: =C19*$F$55 -> 534344.65 | F19: =F18+E19 -> 5850660.6
B20: 12 | C20: ='DISTRIBUIÇÃO CUSTO'!D43 -> 0.019478645 | D20: =C20+D19 -> 0.17532771 | E20: =C20*$F$55 -> 731239.19 | F20: =F19+E20 -> 6581899.8
B21: 13 | C21: ='DISTRIBUIÇÃO CUSTO'!D44 -> 0.021787725 | D21: =C21+D20 -> 0.19711543 | E21: =C21*$F$55 -> 817923.33 | F21: =F20+E21 -> 7399823.1
... B54: 46 | C54: ='DISTRIBUIÇÃO CUSTO'!D77 -> 0.0075558323 | D54: =C54+D53 -> 1 | E54: =C54*$F$55 -> 283650.16 | F54: =F53+E54 -> 37540557
E55: Total | F55: ='DISTRIBUIÇÃO CUSTO'!C26 -> 37540557
