Workbook
Name \0: #REF!
Name \0: #REF!
Name \0: #REF!
Name \0: #REF!
Name \0: #REF!
Name \0: #REF!
Name \0: #REF!
Name \a: #REF!
Name \a: #REF!
Name \m: #REF!
Name \m: #REF!
Name aa: #REF!
Name aa: #REF!
Name aaaa: '[1]M.O.'!#REF!
Name aaaa: '[1]M.O.'!#REF!
Name aaaa: '[1]M.O.'!#REF!
Name aaaa: '[1]M.O.'!#REF!
Name aaaa: '[1]M.O.'!#REF!
Name aaaa: '[1]M.O.'!#REF!
Name aaaa: '[1]M.O.'!#REF!
Name angelo: [2]Geral!#REF!
Name angelo: [2]Geral!#REF!
Name angelo: [2]Geral!#REF!
Name angelo: [2]Geral!#REF!
Name angelo: [2]Geral!#REF!
Name angelo: [2]Geral!#REF!
Name angelo: [2]Geral!#REF!
Name area: #REF!
Name aux: #REF!
Name aux: #REF!
Name aux: #REF!
Name aux: #REF!
Name aux: #REF!
Name aux: #REF!
Name aux: #REF!
Name BDA: #REF!
Name BDA: #REF!
Name BDI: #REF!
Name ca: #REF!
Name Capa: #REF!
Name cronograma: #REF!
Name D: #REF!
Name direto: #REF!
Name DRE: #REF!
Name ea: #REF!
Name FFFFFFF: #REF!
Name FFFFFFF: #REF!
Name FFFFFFF: #REF!
Name FFFFFFF: #REF!
Name FFFFFFF: #REF!
Name FFFFFFF: #REF!
Name FFFFFFF: #REF!
Name item_1: #REF!
Name item_1: #REF!
Name item_1: #REF!
Name item_1: #REF!
Name item_1: #REF!
Name item_1: #REF!
Name item_1: #REF!
Name LS: '[1]M.O.'!#REF!

Sheet DADOS_INICIAIS
A1: Obra
A2: Empresa
A3: Revisão | B3: R00
A4: Arquitetura base | B4: PAVTO TIPO R298 -300
A5: DADOS OBRA
B7: Descrição | C7: Identificador | D7: Unidade | E7: Quantidade
B8: ÁREA DO TERRENO | C8: AT | D8: M2 | E8: 820.8
B9: ÁREA TOTAL CONSTRUÍDA | C9: AC | D9: M2 | E9: 10618.35
B10: UNIDADES RESIDENCIAIS | C10: UR | D10: UN | E10: =2*18 -> 36
B11: Dormitórios | C11: dorm | D11: UN | E11: =3*E10 -> 108
B12: Banheiros | C12: ban | D12: UN | E12: =4*E10 -> 144
B13: UNIDADES COMERCIAIS | C13: UC | D13: UN | E13: 5
B14: Churrasqueiras | C14: CHU | D14: UN | E14: ='SISTEMAS ESPECIAIS'!B10 -> 40
B15: NÚMERO TOTAL DE PAVIMENTOS | C15: NP | D15: UN | E15: =18+8 -> 26
B16: NÚMERO DE PAVIMENTOS TIPO | C16: NPT | D16: UN | E16: 18
B17: NÚMERO DE PAVIMENTOS TIPO DIFERENCIADOS | C17: NPD | D17: UN | E17: 2
B18: NÚMERO DE PAVIMENTOS DUPLEX | C18: ND | D18: UN | E18: 0
B19: ÁREA DE PROJEÇÃO DA TORRE | C19: APT | D19: M2 | E19: 353.0516
B20: PERÍMETRO DE PROJEÇÃO DA TORRE | C20: PPT | D20: M | E20: 78.36
B21: ÁREA DE LAZER | C21: AL | D21: M2 | E21: 800
B22: ÁREA DO EMBASAMENTO | C22: AE | D22: M2 | E22: =460.63+578.47*5 -> 3352.98
B23: ÁREA DE SUBSOLOS | C23: S | D23: M2 | E23: 0
B24: NÚMERO DE SUBSOLOS | C24: NS | D24: UN | E24: 0
B25: ÁREA DE PROJEÇÃO DO EMBASAMENTO | C25: APE | D25: M2 | E25: 460.4
B26: PERÍMETRO DE PROJEÇÃO DE EMBAMENTO | C26: PE | D26: M | E26: 90.93
B27: NÚMERO DE PAVIMENTOS DE EMBASAMENTO | C27: NE | D27: UN | E27: 6

Sheet MOVIMENTAÇÃO_DE_TERRA
A2: MOVIMENTAÇÃO DE TERRA
A3: Data | B3: 45480
A4: Arquivo base | B4: -
A6: ESCAVAÇÃO VERTICAL DE SUBSOLO
A8: Descrição | B8: Área de subsolo (m) | C8: Altura do subsolo (m) | D8: Volume total de escavação (m3) | E8: Preço unitário de escavação (R$ / m3) | F8: Valor total | G8: Observação
A9: Escavação | B9: =DADOS_INICIAIS!E23 -> 0 | D9: =C9*B9 -> 0 | E9: 0 | F9: =E9*D9*1.1 -> 0
A10: TOTAL | F10: =SUM(F9:F9) -> 0
A12: REBAIXAMENTO DE LENÇOL FREÁTICO
A14: Descrição | B14: Quantidade (dias) | E14: Preço unitário de rebaixamento (R$ / dias) | F14: Valor total | G14: Observação
A15: Rebaixamento de lençol | B15: 0 | E15: 200 | F15: =B15*E15*1.1 -> 0
A16: TOTAL | F16: =SUM(F15:F15) -> 0
A18: ESCAVAÇÃO E REATERRO DE VALAS
A20: Descrição | B20: Parâmetro | D20: Volume total de escavação (m3) | E20: Preço unitário (R$ / m3) | F20: Valor total | G20: Observação
A21: Escavação mecanizada para blocos e baldrames | B21: 1.3 | C21: m³ / Vol infra | D21: =B21*INFRAESTRUTURA!D29 -> 478.816 | E21: 60 | F21: =E21*D21*1.1 -> 31601.856
A22: Reaterro para blocos e baldrames | B22: 0.6 | C22: m³ / Vol Escavação | D22: =D21-INFRAESTRUTURA!D29 -> 110.496 | E22: 20 | F22: =E22*D22*1.1 -> 2430.912
A23: Movimentação de bota-fora | B23: 1.3 | D23: =(D21-D22)*B23 -> 478.816 | E23: 40 | F23: =E23*D23*1.1 -> 21067.904
A24: Movimentação de terra das estacas | B24: 1 | C24: m³ | D24: =INFRAESTRUTURA!D19 -> 608.71499 | E24: 40 | F24: =E24*D24*1.1 -> 26783.46
A25: TOTAL | F25: =SUM(F21:F24) -> 81884.132
A27: REGULARIZAÇÃO E APILOAMENTO DE FUNDO DE VALAS
A29: Descrição | B29: Parâmetro | D29: Área de lastro (m²) | E29: Preço unitário (R$ / m2) | F29: Valor total | G29: Observação
A30: Lastro de concreto magto e=5cm | B30: 0.8 | C30: m² / APE | D30: =B30*DADOS_INICIAIS!E25 -> 368.32 | E30: =370*0.05 -> 18.5 | F30: =E30*D30*1.1 -> 7495.312 | G30: Definição trazida do Celebration da Passe | H30: =F30/DADOS_INICIAIS!E25 -> 16.28
A31: TOTAL | F31: =SUM(F30:F30) -> 7495.312
A33: TOTAL MOVIMENTAÇÃO DE TERRA | F33: =F10+F16+F25+F31 -> 89379.444 | G33: =F33/DADOS_INICIAIS!E9 -> 8.4174513

Sheet CONTENÇÕES
A3: CONTENÇÃO
A4: Data
A5: Arquivo base
A7: CORTINA DE ESTACAS
A9: Descrição | B9: Parâmetro | D9: Quantidade | F9: Preço unitário | G9: Valor total
A10: Número de Estacas | B10: 0.15 | C10: un / APE | D10: =B10*DADOS_INICIAIS!E25 -> 69.06 | E10: un
A11: Estaca Hélice Continua Diâmetro 40 | B11: 0.1 | D11: =B11*$D$10 -> 6.906 | E11: un
B12: 20 | C12: m/un | D12: =B12*D11 -> 138.12 | E12: m | G12: =F12*D12 -> 0
A13: Estaca Hélice Continua Diâmetro 50 | B13: 0.5 | D13: =B13*$D$10 -> 34.53 | E13: un
B14: 20 | C14: m/un | D14: =B14*D13 -> 690.6 | E14: m | G14: =F14*D14 -> 0
A15: Estaca Hélice Continua Diâmetro 60 | B15: 0.4 | C15: un / APE | D15: =B15*$D$10 -> 27.624 | E15: un
B16: 20 | C16: m/un | D16: =B16*D15 -> 552.48 | E16: m | G16: =F16*D16 -> 0
A17: Concreto | B17: =(PI()*0.4^2)/4*D14+(PI()*0.5^2)/4*D16+(PI()*0.6^2)/4*D12 -> 234.31506 | C17: un / APE | D17: =(PI()*0.4^2)/4*D14+(PI()*0.5^2)/4*D16+(PI()*0.6^2)/4*D12 -> 234.31506 | E17: m³ | G17: =F17*D17 -> 0
A18: Armação 6,3mm | B18: 1.6575131 | C18: kg / m³ | D18: =B18*D17 -> 388.38029 | E18: kg | G18: =F18*D18 -> 0
A19: Armação 16mm | B19: 10.178338 | C19: kg / m³ | D19: =B19*D17 -> 2384.9378 | E19: kg | G19: =F19*D19 -> 0
A20: Mobilização | B20: 1 | C20: vb | D20: 1 | E20: vb | G20: =F20*D20 -> 0
A21: TOTAL | G21: =SUM(G10:G20) -> 0
A23: PAREDE DE CONCRETO
A25: Descrição | B25: Parâmetro | D25: Quantidade | F25: Preço unitário | G25: Valor total
A26: Fabricação, montagem e desmontagem de forma para blocos e baldrames resinado | B26: 2.1 | C26: m² / APE | D26: =B26*DADOS_INICIAIS!E25 -> 966.84 | E26: m² | G26: =F26*D26 -> 0
A27: Concreto | B27: 0.65 | C27: m³ / APE | D27: =B27*DADOS_INICIAIS!E25 -> 299.26 | E27: m³ | G27: =F27*D27 -> 0
A28: Armação | B28: 110 | C28: kg / m³ | D28: =B28*D27 -> 32918.6 | E28: kg | G28: =F28*D28 -> 0
A29: Mão de obra | B29: =SUPRAESTRUTURA!B15*1.5 -> 360 | C29: R$ / APE | D29: =DADOS_INICIAIS!E25 -> 460.4 | E29: m² | F29: =B29 -> 360 | G29: =F29*D29 -> 165744
A30: TOTAL | G30: =SUM(G26:G29) -> 165744
A33: PAREDE DIAFRAGMA
A35: Descrição | B35: Parâmetro | D35: Quantidade | F35: Preço unitário | G35: Valor total
A36: Fabricação, montagem e desmontagem de forma para blocos e baldrames resinado | B36: 2.1 | C36: m² / APE | D36: =B36*DADOS_INICIAIS!E35 -> 0 | E36: m² | G36: =F36*D36 -> 0
A37: Concreto | B37: 0.65 | C37: m³ / APE | D37: =B37*DADOS_INICIAIS!E35 -> 0 | E37: m³ | G37: =F37*D37 -> 0
A38: Armação | B38: 110 | C38: kg / m³ | D38: =B38*D37 -> 0 | E38: kg | G38: =F38*D38 -> 0
A39: Mão de obra | B39: =SUPRAESTRUTURA!B69*1.5 -> 0 | C39: R$ / APE | D39: =DADOS_INICIAIS!E35 -> 0 | E39: m² | F39: =B39 -> 0 | G39: =F39*D39 -> 0
A40: TOTAL | G40: =SUM(G36:G39) -> 0
A46: TOTAL INFRAESTRUTURA | G46: =G21+G30 -> 165744 | H46: =G46/DADOS_INICIAIS!E9 -> 15.609205

Sheet INFRAESTRUTURA
A3: INFRAESTRUTURA
A4: Data | B4: 45480
A5: Arquivo base | B5: -
A7: FUNDAÇÃO PROFUNDA
A9: Descrição | B9: Parâmetro | D9: Quantidade | F9: Preço unitário | G9: Valor total | H9: Observação
A10: Número de Estacas | B10: 0.2 | C10: un / APE | D10: =ROUNDUP(B10*DADOS_INICIAIS!$E$25,0) -> 93 | E10: un | H10: Base obra Trindade Parkside
A11: Estaca Hélice Continua Diâmetro 40 | B11: 0 | D11: =ROUNDUP(B11*$D$10,0) -> 0 | E11: un
B12: 28 | C12: m/un | D12: =B12*D11 -> 0 | E12: m | F12: 70 | G12: =F12*D12*1.1 -> 0
A13: Estaca Hélice Continua Diâmetro 50 | B13: 0.6 | D13: =ROUNDUP(B13*D10,0) -> 56 | E13: un
B14: 28 | C14: m/un | D14: =B14*D13 -> 1568 | E14: m | F14: 90 | G14: =F14*D14*1.1 -> 155232
A15: Estaca Hélice Continua Diâmetro 60 | B15: 0.4 | C15: un / APE | D15: =ROUNDUP(B15*$D$10,0) -> 38 | E15: un
B16: 28 | C16: m/un | D16: =B16*D15 -> 1064 | E16: m | F16: 105 | G16: =F16*D16*1.1 -> 122892
A17: Estaca Hélice Continua Diâmetro 80 | B17: 0 | C17: un / APE | D17: =ROUNDUP(B17*$D$10,0) -> 0 | E17: un
B18: 30 | C18: m/un | D18: =B18*D17 -> 0 | E18: m | F18: 120 | G18: =F18*D18*1.1 -> 0
A19: Concreto (40 Mpa) | B19: 1.3 | C19: perda | D19: =(PI()*((0.4^2)/4)*D12+PI()*((0.5^2)/4)*D14+PI()*((0.6^2)/4)*D16) -> 608.71499 | E19: m³ | F19: =535+45 -> 580 | G19: =F19*D19*B19*1.1 -> 504868.21
A20: Armação | B20: 12 | C20: kg / m³ | D20: =B20*D19 -> 7304.5799 | E20: kg | F20: 7.62 | G20: =F20*D20*1.1 -> 61226.989
A21: Mobilização | B21: 1 | C21: vb | D21: 1 | E21: vb | F21: 12500 | G21: =F21*D21*1.1 -> 13750
A22: Apoio e arrasamento de estacas | D22: =D10 -> 93 | E22: un | F22: 300 | G22: =F22*D22*1 -> 27900
A23: TOTAL | G23: =SUM(G10:G22) -> 885869.2
A25: FUNDAÇÃO RASA
A27: Descrição | B27: Parâmetro | D27: Quantidade | F27: Preço unitário | G27: Valor total | H27: Observação
A28: Fabricação, montagem e desmontagem de forma para blocos e baldrames resinado | B28: 2.1 | C28: m² / APE | D28: =B28*DADOS_INICIAIS!E25 -> 966.84 | E28: m² | F28: 68 | G28: =F28*D28*1.1 -> 72319.632
A29: Concreto (40 Mpa) | B29: 0.8 | C29: m³ / APE | D29: =B29*DADOS_INICIAIS!E25 -> 368.32 | E29: m³ | F29: =535+45 -> 580 | G29: =F29*D29*1.05*1.1 -> 246737.57
A30: Armação | B30: 110 | C30: kg / m³ | D30: =B30*D29 -> 40515.2 | E30: kg | F30: 7.62 | G30: =F30*D30*1.1 -> 339598.41
A31: Piso de concreto armado | B31: 1 | C31: m² / APE | D31: =B31*DADOS_INICIAIS!E25 -> 460.4 | E31: m² | F31: 180 | G31: =F31*D31*1.1 -> 91159.2
A32: Mão de obra | B32: =SUPRAESTRUTURA!B15*1.5 -> 360 | C32: R$ / APE | D32: =DADOS_INICIAIS!E25 -> 460.4 | E32: m² | F32: =B32 -> 360 | G32: =F32*D32*1.1 -> 182318.4
A33: TOTAL | G33: =SUM(G28:G32) -> 932133.21
A36: TOTAL INFRAESTRUTURA | G36: =G23+G33 -> 1818002.4 | H36: =G36/DADOS_INICIAIS!E9 -> 171.21327
H38: =H36/1.1 -> 155.64843

Sheet SUPRAESTRUTURA
A3: SUPRAESTRUTURA
A4: Data | B4: 45480
A5: Arquivo base | B5: -
A7: SUPRAESTRUTURA - LAJE MACIÇA
A9: Descrição | B9: Parâmetro | D9: Quantidade | F9: Preço unitário | G9: Valor total | H9: Observação
A10: Fabricação forma | B10: 3 | C10: Jogos | D10: =(D11/DADOS_INICIAIS!$E$15)*B10 -> 3062.9856 | E10: m² | F10: 110 | G10: =F10*D10*1.1 -> 370621.25
A11: Montagem de forma | B11: 2.5 | C11: m² / AC | D11: =B11*DADOS_INICIAIS!$E$9 -> 26545.875 | E11: m² | F11: 2.5 | G11: =F11*D11*1.1 -> 73001.156
A12: Escoramento | B12: 4 | C12: un / AE | D12: =ROUNDUP(B12*DADOS_INICIAIS!$E$25*B10,0) -> 5525 | E12: un | F12: =17 -> 17 | G12: =F12*D12*1.1 -> 103317.5
A13: Concreto | B13: 0.22 | C13: m³ / AC | D13: =B13*DADOS_INICIAIS!$E$9 -> 2336.037 | E13: m³ | F13: =535+45 -> 580 | G13: =F13*D13*1.05*1.1 -> 1564911.2
A14: Armadura Convencional para Estrutura | B14: 110 | C14: kg / m³ | D14: =D13*B14 -> 256964.07 | E14: kg | F14: 7.62 | G14: =F14*D14*1.1 -> 2153872.8
A15: Mão de obra - estrutura em concreto armado | B15: 240 | C15: R$ / AC | D15: =DADOS_INICIAIS!$E$9 -> 10618.35 | E15: m² | F15: =B15 -> 240 | G15: =F15*D15*1.1 -> 2803244.4
A16: Perfuração de vigas | B16: 5300 | C16: R$ / NP | D16: 1 | E16: vb | F16: =B16*DADOS_INICIAIS!$E$15 -> 137800 | G16: =F16*D16*1.1 -> 151580 | H16: Coeficiente originário do Gran Torino (R$ 160,00/un) | I16: Nova utiliza a verba de 1.500,00 por pav
A17: TOTAL | G17: =SUM(G10:G16) -> 7220548.3 | K17: =4160+1440+1120+2880+4800+91680+4000 -> 110080 | L17: =K17/21 -> 5241.9048
A19: SUPRAESTRUTURA - LAJE CUBETAS
A21: Descrição | B21: Parâmetro | D21: Quantidade | F21: Preço unitário | G21: Valor total | H21: Observação
A22: Fabricação forma | B22: 3 | C22: Jogos | D22: =(D23/DADOS_INICIAIS!$E$15)*B22 -> 3062.9856 | E22: m² | F22: 110 | G22: =F22*D22*1.1 -> 370621.25
A23: Montagem de forma | B23: 2.5 | C23: m² / AC | D23: =B23*DADOS_INICIAIS!$E$9 -> 26545.875 | E23: m² | F23: 2.5 | G23: =F23*D23*1.1 -> 73001.156
A24: Escoramento | B24: 3 | C24: un / APT*NPT | D24: =ROUNDUP(B24*DADOS_INICIAIS!$E$25*B22,0) -> 4144 | E24: un | F24: =17 -> 17 | G24: =F24*D24*1.1 -> 77492.8
A25: Cubetas | B25: 30 | C25: R$ / AC | D25: 1 | E25: vb | F25: =B25*DADOS_INICIAIS!$E$9 -> 318550.5 | G25: =F25*D25*1.1 -> 350405.55
A26: Concreto | B26: 0.25 | C26: m³ / AC | D26: =B26*DADOS_INICIAIS!$E$9 -> 2654.5875 | E26: m³ | F26: =535+45 -> 580 | G26: =F26*D26*1.05*1.1 -> 1778308.2 | H26: =DADOS_INICIAIS!E19*3 -> 1059.1548 | I26: =G25/H26 -> 330.83507
A27: Armadura Convencional para Estrutura | B27: 110 | C27: kg / m³ | D27: =D26*B27 -> 292004.62 | E27: kg | F27: 7.62 | G27: =F27*D27*1.1 -> 2447582.8 | I27: =I26/(24*30) -> 0.45949315
A28: Mão de obra - estrutura em concreto armado | B28: 240 | C28: R$ / AC | D28: =DADOS_INICIAIS!$E$9 -> 10618.35 | E28: m² | F28: =B28 -> 240 | G28: =F28*D28*1.1 -> 2803244.4
A29: Perfuração de vigas | B29: 5300 | C29: R$ / NP | D29: 1 | E29: vb | F29: =B29*DADOS_INICIAIS!$E$15 -> 137800 | G29: =F29*D29*1.1 -> 151580 | H29: Coeficiente originário do Gran Torino (R$ 160,00/un)
A30: TOTAL | G30: =SUM(G22:G29) -> 8052236.1
A32: SUPRAESTRUTURA - LAJE TRELIÇADA
A34: Descrição | B34: Parâmetro | D34: Quantidade | F34: Preço unitário | G34: Valor total | H34: Observação
A35: Fabricação forma | B35: 2 | C35: Jogos | D35: =(D36/DADOS_INICIAIS!$E$15)*B35 -> 0 | E35: m² | F35: 85 | G35: =F35*D35*1.1 -> 0
A36: Montagem de forma | B36: 2.1 | C36: m² / AC | D36: =B36*DADOS_INICIAIS!E38 -> 0 | E36: m² | F36: 1.5 | G36: =F36*D36*1.1 -> 0
A37: Escoramento - Torre | B37: 2 | C37: un / APT*NPT | D37: =B37*DADOS_INICIAIS!E47*DADOS_INICIAIS!E44 -> 0 | E37: un | F37: 17 | G37: =F37*D37*1.1 -> 0
A38: Escoramento - Embasamento | B38: 2 | C38: un / AE | D38: =B38*DADOS_INICIAIS!E50 -> 0 | E38: un | F38: 17 | G38: =F38*D38*1.1 -> 0
A39: Cubetas | B39: 25 | C39: R$ / AC | D39: =B39*DADOS_INICIAIS!E38 -> 0 | E39: m³ | F39: =B39 -> 25 | G39: =F39*D39*1.1 -> 0
A40: Concreto | B40: 0.25 | C40: m³ / AC | D40: =B40*DADOS_INICIAIS!E38 -> 0 | E40: m³ | F40: =575 -> 575 | G40: =F40*D40*1.05*1.1 -> 0
A41: Armadura Convencional para Estrutura | B41: 110 | C41: kg / m³ | D41: =D40*B41 -> 0 | E41: kg | F41: 7.25 | G41: =F41*D41*1.1 -> 0
A42: Mão de obra - estrutura em concreto armado | B42: 240 | C42: R$ / AC | D42: =DADOS_INICIAIS!E38 -> 0 | E42: m² | F42: =B42 -> 240 | G42: =F42*D42*1.1 -> 0
A43: Perfuração de vigas | B43: 5300 | C43: R$ / NP | D43: 1 | E43: vb | F43: =B43*DADOS_INICIAIS!E43 -> 0 | G43: =F43*D43*1.1 -> 0 | H43: Coeficiente originário do Gran Torino (R$ 160,00/un)
A44: TOTAL | G44: =SUM(G35:G43) -> 0
A46: SUPRAESTRUTURA - LAJE PROTENDIDA
A48: Descrição | B48: Parâmetro | D48: Quantidade | F48: Preço unitário | G48: Valor total | H48: Observação
A49: Fabricação forma | B49: 3 | C49: Jogos | D49: =(D50/DADOS_INICIAIS!$E$15)*B49 -> 2572.9079 | E49: m² | F49: 110 | G49: =F49*D49*1.1 -> 311321.85
A50: Montagem de forma | B50: 2.1 | C50: m² / AC | D50: =B50*DADOS_INICIAIS!$E$9 -> 22298.535 | E50: m² | F50: 2.5 | G50: =F50*D50*1.1 -> 61320.971
...

Sheet ALVENARIA
A3: PAREDES E PAINÉIS
A4: Data | B4: 45480
A5: Arquivo base | B5: -
A7: ALVENARIA
A9: Descrição | B9: Parâmetro | D9: Quantidade | F9: Preço unitário | G9: Valor total | H9: Observação
A10: Alvenaria embasamento | B10: 1 | C10: m² / AE | D10: =B10*DADOS_INICIAIS!$E$22 -> 3352.98 | E10: m² | F10: 45 | G10: =F10*D10*1.1 -> 165972.51
A11: Alvenaria lazer | B11: 0.4 | C11: m² / AL | D11: =B11*DADOS_INICIAIS!$E$21 -> 320 | E11: m² | F11: 45 | G11: =F11*D11*1.1 -> 15840
A12: Alvenaria tipo | B12: 1.2 | C12: m² / APT*(NPT+2ND) | D12: =B12*(DADOS_INICIAIS!$E$19*(DADOS_INICIAIS!$E$16+DADOS_INICIAIS!$E$17)) -> 8473.2384 | E12: m² | F12: 45 | G12: =F12*D12*1.1 -> 419425.3
A13: Alvenaria escadas | B13: 0.2 | C13: m² / AC | D13: =B13*DADOS_INICIAIS!$E$9 -> 2123.67 | E13: m² | F13: 70 | G13: =F13*D13*1.05*1.1 -> 171698.72
A14: Alvenaria cobertura / reservatório | B14: 0.4 | C14: m² / APT | D14: =B14*DADOS_INICIAIS!$E$19 -> 141.22064 | E14: m² | F14: 45 | G14: =F14*D14*1.1 -> 6990.4217
A15: Alvenaria refratárias | B15: 1.75 | C15: m² * CHU | D15: =B15*DADOS_INICIAIS!$E$14 -> 70 | E15: un | F15: 210 | G15: =F15*D15*1.1 -> 16170
A16: Serviços complementares | B16: 12.5 | C16: R$ / m² | D16: =D10+D11+D12+D13+D14 -> 14411.109 | E16: m² | F16: =B16 -> 12.5 | G16: =F16*D16*1.1 -> 198152.75
A17: Mão de obra | B17: 35 | C17: R$ / m² | D17: =D10+D11+D12+D13+D14 -> 14411.109 | E17: m² | F17: 35 | G17: =F17*D17*1.1 -> 554827.7
A18: TOTAL | G18: =SUM(G10:G17) -> 1549077.4 | K18: =4160+1440+1120+2880+4800+91680+4000 -> 110080 | L18: =K18/21 -> 5241.9048
A20: ALVENARIA - DRYWALL
A22: Descrição | B22: Parâmetro | D22: Quantidade | F22: Preço unitário | G22: Valor total | H22: Observação
A23: Alvenaria embasamento | B23: 1 | C23: m² / AE | D23: =B23*DADOS_INICIAIS!$E$22 -> 3352.98 | E23: m² | F23: 45 | G23: =F23*D23*1.1 -> 165972.51
A24: Alvenaria lazer | B24: 0.4 | C24: m² / AL | D24: =B24*DADOS_INICIAIS!$E$21 -> 320 | E24: m² | F24: 45 | G24: =F24*D24*1.1 -> 15840
A25: Alvenaria tipo | B25: 1.65 | C25: m² / APT*(NPT+2ND) | D25: =B25*(DADOS_INICIAIS!$E$19*(DADOS_INICIAIS!$E$16+DADOS_INICIAIS!$E$17))*0.4 -> 4660.2811 | E25: m² | F25: 45 | G25: =F25*D25*1.1 -> 230683.92
A26: Drywall tipo | B26: 1.65 | C26: m² / APT*(NPT+2ND) | D26: =B26*(DADOS_INICIAIS!$E$19*(DADOS_INICIAIS!$E$16+DADOS_INICIAIS!$E$17))*0.6 -> 6990.4217 | E26: m² | F26: 220 | G26: =F26*D26*1.1 -> 1691682 | J26: =D26/(D30+D26) -> 0.3942754
A27: Alvenaria escadas | B27: 0.2 | C27: m² / AC | D27: =B27*DADOS_INICIAIS!$E$9 -> 2123.67 | E27: m² | F27: 70 | G27: =F27*D27*1.1 -> 163522.59 | J27: =1-J26 -> 0.6057246
A28: Alvenaria cobertura / reservatório | B28: 0.8 | C28: m² / APT | D28: =B28*DADOS_INICIAIS!$E$19 -> 282.44128 | E28: m³ | F28: 45 | G28: =F28*D28*1.1 -> 13980.843
A29: Alvenaria refratárias | B29: 1.75 | C29: m² * CHU | D29: ='SISTEMAS ESPECIAIS'!B10 -> 40 | E29: un | F29: 210 | G29: =F29*D29*1.1 -> 9240
A30: Serviços complementares | B30: 12.5 | C30: R$ / m² | D30: =D24+D25+D23+D27+D28 -> 10739.372 | E30: m² | F30: =B30 -> 12.5 | G30: =F30*D30*1.1 -> 147666.37
A31: Mão de obra | B31: 35 | C31: R$ / m² | D31: =D24+D25+D23+D27+D28 -> 10739.372 | E31: m² | F31: 35 | G31: =F31*D31*1.1 -> 413465.84
A32: TOTAL | G32: =SUM(G23:G31) -> 2852054.1
A35: TOTAL ALVENARIA | G35: =G18 -> 1549077.4 | H35: =G35/DADOS_INICIAIS!E9 -> 145.88683
G38: =G35/1.1 -> 1408252.2 | H38: =G38/DADOS_INICIAIS!E9 -> 132.62439

Sheet INSTALAÇÕES
A2: INSTALAÇÕES
A4: INSTALAÇÕES ELÉTRICAS
A6: Descrição | B6: Parâmetro | D6: Valor total
A7: Entrada de Energia | B7: 5.5 | C7: R$ / AC | D7: =B7*DADOS_INICIAIS!$E$9*1.1 -> 64241.018
A8: Eletrodutos e Eletrocalhas | B8: 10 | C8: R$ / AC | D8: =B8*DADOS_INICIAIS!$E$9*1.1 -> 116801.85
A9: Cabos e Fiações | B9: 30 | C9: R$ / AC | D9: =B9*DADOS_INICIAIS!$E$9*1.1 -> 350405.55
A10: Quadros e Disjuntores | B10: 15 | C10: R$ / AC | D10: =B10*DADOS_INICIAIS!$E$9*1.1 -> 175202.78
A11: Acabamentos Elétricos | B11: 15 | C11: R$ / AC | D11: =B11*DADOS_INICIAIS!$E$9*1.1 -> 175202.78
A12: Equipamentos e Iluminação | B12: 15 | C12: R$ / AC | D12: =B12*DADOS_INICIAIS!$E$9*1.1 -> 175202.78
A13: Mão de Obra para Instalações Elétricas | B13: 60 | C13: R$ / AC | D13: =B13*DADOS_INICIAIS!$E$9*1.1 -> 700811.1
A14: TOTAL | D14: =SUM(D7:D13) -> 1757867.8
A16: INSTALAÇÕES HIDROSSANITÁRIAS
A18: Descrição | B18: Parâmetro | D18: Valor total
A19: Instalações de Água Fria | B19: 25 | C19: R$ / AC | D19: =B19*DADOS_INICIAIS!$E$9*1.1 -> 292004.62
A20: Instalações de Água Quente | B20: 22 | C20: R$ / AC | D20: =B20*DADOS_INICIAIS!$E$9*1.1 -> 256964.07
A21: Instalações de Águas Pluviais | B21: 10 | C21: R$ / AC | D21: =B21*DADOS_INICIAIS!$E$9*1.1 -> 116801.85
A22: Instalações Sanitárias | B22: 15 | C22: R$ / AC | D22: =B22*DADOS_INICIAIS!$E$9*1.1 -> 175202.78
A23: Louças e Metais | B23: 35.5 | C23: R$ / AC | D23: =B23*DADOS_INICIAIS!$E$9*1.1 -> 414646.57
A24: Mão de Obra para Instalações Hidráulicas | B24: 55 | C24: R$ / AC | D24: =B24*DADOS_INICIAIS!$E$9*1.1 -> 642410.18
A25: TOTAL | D25: =SUM(D19:D24) -> 1898030.1
A27: INSTALAÇÕES PREVENTIVAS E GLP
A29: Descrição | B29: Parâmetro | D29: Valor total
A30: Instalações Preventivas | B30: 20 | C30: R$ / AC | D30: =B30*DADOS_INICIAIS!$E$9*1.1 -> 233603.7
A31: Instalações de GLP | B31: 13 | C31: R$ / AC | D31: =B31*DADOS_INICIAIS!$E$9*1.1 -> 151842.41
A32: Instalações de Proteção e Aterramento - SPDA | B32: 8 | C32: R$ / AC | D32: =B32*DADOS_INICIAIS!$E$9*1.1 -> 93441.48
A33: TOTAL | D33: =SUM(D30:D32) -> 478887.59
A35: TOTAL INSTALAÇÕES | D35: =D14+D25+D33 -> 4134785.5 | E35: =D35/DADOS_INICIAIS!E9 -> 389.4
E37: =E35/1.1 -> 354

Sheet SISTEMAS ESPECIAIS
A2: SISTEMAS ESPECIAIS
A4: CLIMATIZAÇÃO, EXAUSTÃO MECÂNICA E PRESSURIZAÇÃO
A6: Descrição | B6: Quantidade | C6: Preço Unitário | D6: Valor total | G6: TERREO | H6: LAZER 1 | I6: TIPO | J6: LAZER 2
A7: Infraestrutura para Instalação de Ar Condicionado | B7: =G7+H7+I7*18+J7 -> 176 | C7: 1200 | D7: =B7*C7*1.1 -> 232320 | G7: =1+5 -> 6 | H7: =3+2 -> 5 | I7: =(3+1)+(4+1) -> 9 | J7: 3
A8: Instalação de Ar Condicionado | B8: =G8+H8+I8*18+J8 -> 9 | C8: 5000 | D8: =B8*C8*1.1 -> 49500 | G8: =1 -> 1 | H8: =H7 -> 5 | I8: 0 | J8: 3
A9: Ventokit | B9: =G9+H9+I9*18+J9 -> 42 | C9: 900 | D9: =B9*C9*1.1 -> 41580 | G9: 0 | H9: =2+2 -> 4 | I9: =1*2 -> 2 | J9: 2
A10: Churrasqueiras | B10: =G10+H10+I10*18+J10 -> 40 | C10: 2600 | D10: =B10*C10*1.1 -> 114400 | G10: 0 | H10: =1+1 -> 2 | I10: 2 | J10: 2
A11: TOTAL | D11: =SUM(D7:D10) -> 437800
A13: COMUNICAÇÃO
A15: Descrição | B15: Parâmetro | D15: Valor total
A16: CFTV | B16: 2 | C16: R$ / AC | D16: =B16*DADOS_INICIAIS!$E$9*1.1 -> 23360.37
A17: Interfone | B17: 5 | C17: R$ / AC | D17: =B17*DADOS_INICIAIS!$E$9*1.1 -> 58400.925
A18: TV e internet | B18: 3 | C18: R$ / AC | D18: =B18*DADOS_INICIAIS!$E$9*1.1 -> 35040.555
A19: Automação, telecomunicação e sistemas de segurança | B19: 5 | C19: R$ / AC | D19: =B19*DADOS_INICIAIS!$E$9*1.1 -> 58400.925
A20: TOTAL | D20: =SUM(D16:D19) -> 175202.78
A22: EQUIPAMENTOS
A24: Descrição | B24: Quantidade | C24: Preço Unitário | D24: Valor total
A25: Elevadores | B25: 2 | C25: =(768900/2)*0.95 -> 365227.5 | D25: =B25*C25*1.1 -> 803500.5
A26: Grupo de geradores | B26: 1 | C26: 42000 | D26: =B26*C26*1.1 -> 46200
A27: Bombas | B27: 1 | C27: 10000 | D27: =B27*C27*1.1 -> 11000
A28: Infra de carro elétrico | B28: =DADOS_INICIAIS!E10 -> 36 | C28: 560 | D28: =B28*C28*1.1 -> 22176
A29: Equipamento de piscina | B29: 1 | C29: 25000 | D29: =B29*C29*1.1 -> 27500
A30: Sauna | B30: 1 | C30: 8000 | D30: =B30*C30*1.1 -> 8800
A31: Spa | B31: 2 | C31: 15000 | D31: =B31*C31*1.1 -> 33000
A32: TOTAL | D32: =SUM(D25:D31) -> 952176.5
A34: OUTROS SISTEMAS ESPECIAIS
A36: Descrição | B36: Parâmetro | D36: Valor total
A37: Outros sistemas | B37: 20 | C37: R$ / AC | D37: =B37*DADOS_INICIAIS!E9*1.1 -> 233603.7
A38: TOTAL | D38: =SUM(D37:D37) -> 233603.7
A40: TOTAL SISTEMAS ESPECIAIS | D40: =D11+D20+D32+D38 -> 1798783 | E40: =D40/DADOS_INICIAIS!E9 -> 169.40325

Sheet IMPERMEABILIZAÇÃO
A3: IMPERMEABILIZAÇÃO
A4: Data | B4: 45481
A5: Arquivo base | B5: -
A7: ALVENARIA
A9: Descrição | B9: Parâmetro | D9: Quantidade | F9: Preço unitário | G9: Valor total | H9: Observação
A10: Regularização de Superfície | B10: 25 | C10: R$ / m² | D10: =D14+D15 -> 4358.8327 | E10: m² | F10: 8 | G10: =F10*D10*1.1 -> 38357.728 | H10: =G10+G18 -> 105483.75
A11: Poço do elevador | B11: 45 | C11: R$ / m² | D11: =(3.51+(7.5)*1.8)*2 -> 34.02 | E11: m² | F11: =41-F19 -> 13 | G11: =F11*D11*1.1 -> 486.486 | H11: =G11+G12+G19 -> 38757.642
A12: Baldrames | B12: 30 | C12: R$ / m² | D12: =INFRAESTRUTURA!D28 -> 966.84 | E12: m² | F12: =35-F19 -> 7 | G12: =F12*D12*1.1 -> 7444.668 | H12: =G13/I12 -> 201.3825 | I12: =8+50 -> 58
A13: Ralos | B13: 1 | C13: R$ / AC | D13: 1 | E13: vb | F13: =B13*DADOS_INICIAIS!$E$9 -> 10618.35 | G13: =F13*D13*1.1 -> 11680.185 | I13: =8/I12 -> 0.13793103 | J13: =I13*G13 -> 1611.06
A14: Impermeabilizações cimenticias | B14: 0.25 | C14: m² / AC | D14: =B14*DADOS_INICIAIS!E9 -> 2654.5875 | E14: m² | F14: =60-F20 -> 32 | G14: =F14*D14*1.1 -> 93441.48 | H14: =G14+G20 -> 175202.78 | I14: =50/I12 -> 0.86206897 | J14: =I14*G13 -> 10069.125
A15: Impermeabilizações com manta asfaltica | B15: 0.1605 | C15: m² / AC | D15: =B15*DADOS_INICIAIS!E9 -> 1704.2452 | E15: m² | F15: =110-F21 -> 62 | G15: =F15*D15*1.1 -> 116229.52 | H15: =G16/I15 -> 96.001521 | I15: =41+32 -> 73
A16: Impermeabilização de peitoril | B16: 0.6 | C16: R$ / AC | D16: 1 | E16: vb | F16: =B16*DADOS_INICIAIS!$E$9 -> 6371.01 | G16: =F16*D16*1.1 -> 7008.111 | I16: =41/I15 -> 0.56164384 | J16: =I16*G16 -> 3936.0623
A17: Proteção Mecânica | B17: 28 | C17: R$ / m² | D17: =D15 -> 1704.2452 | E17: m² | F17: =28-F22 -> 12 | G17: =F17*D17*1.1 -> 22496.036 | H17: =G15+G21 -> 206213.67 | I17: =32/I15 -> 0.43835616 | J17: =I17*G16 -> 3072.0487
A18: Mão de obra para regularização | D18: =D10 -> 4358.8327 | E18: m² | F18: =22-F10 -> 14 | G18: =F18*D18*1.1 -> 67126.023 | H18: =G17+G22 -> 52490.751
A19: Mão de obra para impermeabilização de poço e baldrames | D19: =D11+D12 -> 1000.86 | E19: m² | F19: 28 | G19: =F19*D19*1.1 -> 30826.488
A20: Mão de obra impermeabilizações cimenticias | D20: =D14 -> 2654.5875 | E20: m² | F20: 28 | G20: =F20*D20*1.1 -> 81761.295
A21: Mão de obra impermeabilizações com manta asfáltica | D21: =D15 -> 1704.2452 | E21: m² | F21: 48 | G21: =F21*D21*1.1 -> 89984.145
A22: Mão de obra para proteção mecânica | D22: =D17 -> 1704.2452 | E22: m² | F22: 16 | G22: =F22*D22*1.1 -> 29994.715
A23: TOTAL | G23: =SUM(G10:G22) -> 596836.88 | K23: =4160+1440+1120+2880+4800+91680+4000 -> 110080 | L23: =K23/21 -> 5241.9048
A25: TOTAL IMPERMEABILIZAÇÃO | G25: =G23 -> 596836.88 | H25: =G25/DADOS_INICIAIS!E9 -> 56.208063
H28: =H25/1.1 -> 51.098239

Sheet Rev. Internos Piso e Parede
A2: ORÇAMENTO PARAMÉTRICO GERENCIAMENTO EXECUTIVO
A7: Cliente
A8: Obra
A9: Data | B9: 45481
A10: Revisão | B10: R00
A12: REVESTIMENTOS INTERNOS EM PISO E PAREDE
A14: Descrição | B14: Quantidade | D14: Parâmetro | F14: Referência | G14: Valor total
A15: Polimento de concreto | B15: ='Acabamentos de Piso e Parede'!B32+'Acabamentos de Piso e Parede'!B36 -> 2594.86 | C15: m² | D15: 16.5 | E15: R$ / m² | F15: Média | G15: =D15*B15*1.1 -> 47096.709
A16: Piso alisado | B16: ='Acabamentos de Piso e Parede'!B34 -> 581.85 | C16: m² | D16: =25-D22 -> 4 | E16: R$ / m² | F16: Média | G16: =D16*B16*1.1 -> 2560.14
A17: Piso ranhurado | B17: ='Acabamentos de Piso e Parede'!B33 -> 415.98 | C17: m² | D17: =28-D23 -> 4 | E17: R$ / m² | F17: Média | G17: =D17*B17*1.1 -> 1830.312
A18: Contrapiso | B18: =6035.33+85 -> 6120.33 | C18: m² | D18: =B18/DADOS_INICIAIS!E9 -> 0.57639181 | E18: m² / AC | F18: Média | G18: =+B18*(65-D24)*1.1 -> 269294.52
A19: Manta acústica | B19: =B18-562.05-85 -> 5473.28 | C19: m² | D19: =B19/DADOS_INICIAIS!E9 -> 0.51545485 | E19: m² / AC | F19: Média | G19: =+B19*25*1.1 -> 150515.2
A20: Chapisco | B20: =DADOS_INICIAIS!E9*'Rev. Internos Piso e Parede'!D20 -> 19113.03 | C20: m² | D20: 1.8 | E20: m² / AC | F20: Média | G20: =+B20*5*1.1-G25*0.1 -> 31536.5
A21: Reboco | B21: =DADOS_INICIAIS!E9*'Rev. Internos Piso e Parede'!D21 -> 19113.03 | C21: m² | D21: 1.8 | E21: m² / AC | F21: Média | G21: =50*B21*1.1-G25*0.9 -> 388950.16
A22: MO piso alisado | B22: =B16 -> 581.85 | C22: m² | D22: 21 | E22: R$ / m² | F22: Média | G22: =D22*B22*1.1 -> 13440.735
A23: Mo piso ranhurado | B23: =B17 -> 415.98 | C23: m² | D23: 24 | E23: R$ / m² | F23: Média | G23: =D23*B23*1.1 -> 10981.872
A24: MO contrapiso | B24: =B18 -> 6120.33 | C24: m² | D24: 25 | E24: R$ / m² | F24: Média | G24: =D24*B24*1.1 -> 168309.08
A25: Mo chapisco e reboco | B25: =B20 -> 19113.03 | C25: m² | D25: 35 | E25: R$ / m² | F25: Média | G25: =D25*B25*1.1 -> 735851.66
A26: TOTAL | G26: =SUM(G15:G25) -> 1820366.9
A29: TOTAL REVESTIMENTOS | G29: =G26 -> 1820366.9 | H29: =G29/DADOS_INICIAIS!E9 -> 171.43595
H31: =H29/1.1 -> 155.85086
B36: =B18/(B15+B16+B17) -> 1.7035508

Sheet TETO
A3: REVESTIMENTOS E ACABAMENTOS DE TETO
A4: Data | B4: 45481
A5: Arquivo base | B5: -
A7: ALVENARIA
A9: Descrição | B9: Parâmetro | D9: Quantidade | F9: Preço unitário | G9: Valor total | H9: Observação
A10: Forro gesso mineral | B10: =D10/DADOS_INICIAIS!$E$9 -> 0.57639181 | C10: m² / AC | D10: ='Rev. Internos Piso e Parede'!B18 -> 6120.33 | E10: m² | F10: 65 | G10: =F10*D10*1.1 -> 437603.6
A11: Negativo | B11: 1.2 | C11: m / FORRO | D11: =(D10)*B11 -> 7344.396 | E11: m² | F11: 22 | G11: =F11*D11*1.1 -> 177734.38
A12: Estucamento | B12: =D12/DADOS_INICIAIS!$E$9 -> 0.3383473 | C12: m² / AC | D12: ='Rev. Internos Piso e Parede'!B15+'Rev. Internos Piso e Parede'!B16+'Rev. Internos Piso e Parede'!B17 -> 3592.69 | E12: m² | F12: =24-F13 -> 3 | G12: =F12*D12*1.1 -> 11855.877
A13: mo estucamento | D13: =D12 -> 3592.69 | E13: m² | F13: =21 -> 21 | G13: =F13*D13*1.1 -> 82991.139
A14: TOTAL | G14: =SUM(G10:G13) -> 710184.99 | K14: =4160+1440+1120+2880+4800+91680+4000 -> 110080 | L14: =K14/21 -> 5241.9048
A16: TOTAL FORRO | G16: =G14 -> 710184.99 | H16: =G16/DADOS_INICIAIS!E9 -> 66.882801
H19: =H16/1.1 -> 60.802547
C20: =461.5-353.75 -> 107.75
C21: =353.75-41.5 -> 312.25

Sheet Acabamentos de Piso e Parede
A2: ORÇAMENTO PARAMÉTRICO GERENCIAMENTO EXECUTIVO
A7: Cliente
A8: Obra
A9: Data | B9: 45481
A10: Revisão | B10: R00
A12: ACABAMENTOS EM PISO E PAREDE
A14: Descrição | B14: Quantidade | D14: Parâmetro | F14: Referência | G14: Valor total | H14: =G19/I14 -> 5840.0925 | I14: =40+20 -> 60
A15: Porcelanato | B15: =B31 -> 6090.33 | C15: m² | D15: =125-D22 -> 77 | E15: R$ / m² | F15: Média | G15: =+D15*B15*1.1 -> 515850.95 | I15: =40/I14 -> 0.66666667 | J15: =I15*G19 -> 233603.7
A16: Piscina | B16: =B37 -> 144.899 | C16: m² | D16: =250-D23 -> 200 | E16: R$ / m² | F16: Média | G16: =+D16*B16*1.1 -> 31877.78 | I16: =20/I14 -> 0.33333333 | J16: =I16*G19 -> 116801.85
A17: Grama sintetica | B17: =B35 -> 30 | C17: m² | D17: 210 | E17: R$ / m² | F17: Média | G17: =+D17*B17*1.1 -> 6930
A18: Paver | B18: =DADOS_INICIAIS!E8-DADOS_INICIAIS!E25 -> 360.4 | C18: m² | D18: =60-D24 -> 42 | E18: R$ / m² | F18: Média | G18: =+D18*B18*1.1 -> 16650.48
A19: Rodapés | B19: 1 | C19: vb | D19: 30 | E19: R$ / AC | F19: Média | G19: =D19*DADOS_INICIAIS!$E$9*1.1 -> 350405.55 | H19: =G20/I19 -> 2511.8677 | I19: =81+12 -> 93
A20: Soleiras e peitoris | B20: 1 | C20: vb | D20: 20 | E20: R$ / AC | F20: Média | G20: =D20*DADOS_INICIAIS!$E$9*1.1 -> 233603.7 | I20: =81/I19 -> 0.87096774 | J20: =I20*G20 -> 203461.29
A21: Revestimentos de Parede | B21: 1 | C21: vb | D21: =50*0.4 -> 20 | E21: R$ / AC | F21: Média | G21: =D21*DADOS_INICIAIS!$E$9*1.1 -> 233603.7 | I21: =12/I19 -> 0.12903226 | J21: =I21*G20 -> 30142.413
A22: MO PORCELANATO | B22: =B15 -> 6090.33 | C22: m² | D22: 48 | E22: R$ / m² | G22: =+D22*B22*1.1 -> 321569.42 | H22: =G21/I22 -> 1229.4932 | I22: =145+45 -> 190
A23: MO PASTILHA | B23: =B16 -> 144.899 | C23: m² | D23: 50 | E23: R$ / m² | G23: =+D23*B23*1.1 -> 7969.445 | I23: =145/I22 -> 0.76315789 | J23: =I23*G21 -> 178276.51
A24: MO PAVER | B24: =B18 -> 360.4 | C24: m² | D24: 18 | E24: R$ / m² | G24: =+D24*B24*1.1 -> 7135.92 | I24: =45/I22 -> 0.23684211 | J24: =I24*G21 -> 55327.192
A25: =20*40 -> 800 | G25: =SUM(G15:G24) -> 1725596.9
A28: TOTAL ACABAMENTOS | G28: =G25 -> 1725596.9 | H28: =G28/DADOS_INICIAIS!E9 -> 162.51084
H30: =H28/1.1 -> 147.73712
A31: PORCELANATO | B31: =6005.33+85 -> 6090.33
A32: CIMENTADO | B32: 2594.86 | F32: =6300-576+461+573 -> 6758
A33: CIMENTADO RANHURADO | B33: 415.98
A34: CIMENTADO ESCADA | B34: 581.85
A35: GRAMA SINTETICA | B35: 30
A36: POLIDO
A37: PASTILHA | B37: 144.899

Sheet PINTURA INTERNA
A3: PINTURA INTERNA
A4: Data | B4: 45481
A5: Arquivo base | B5: -
A7: ALVENARIA
A9: Descrição | B9: Parâmetro | D9: Quantidade | F9: Preço unitário | G9: Valor total | H9: Observação
A10: Pintura piso epoxi | B10: 110 | C10: R$ / m² | D10: ='Rev. Internos Piso e Parede'!B15 -> 2594.86 | E10: m² | F10: =110-F14 -> 70 | G10: =F10*D10*1.1 -> 199804.22 | H10: =ALVENARIA!D16*2-'Rev. Fachada'!B15 -> 22824.45
A11: Pintura acrílica antiderrapante | B11: 65 | C11: R$ / m² | D11: ='Rev. Internos Piso e Parede'!B16 -> 581.85 | E11: m² | F11: =65-28 -> 37 | G11: =F11*D11*1.1 -> 23681.295 | H11: =H10*0.8+TETO!D10 -> 24379.89 | I11: =1+1.5+15+35 -> 52.5
A12: Textura escadas | B12: 22 | C12: R$ / AC | D12: 1 | E12: vb | F12: =B12*DADOS_INICIAIS!$E$9 -> 233603.7 | G12: =F12*D12*1.1 -> 256964.07 | H12: =H10*0.2+TETO!D12 -> 8157.58 | I12: =1-I13 -> 0.33333333 | J12: =I12*G13 -> 428273.45
A13: Pintura Interna | B13: 110 | C13: R$ / AC | D13: 1 | E13: vb | F13: =B13*DADOS_INICIAIS!$E$9 -> 1168018.5 | G13: =F13*D13*1.1 -> 1284820.4 | I13: =35/I11 -> 0.66666667 | J13: =I13*G13 -> 856546.9
A14: MO pintura de piso epoxi | D14: =D10 -> 2594.86 | F14: 40 | G14: =F14*D14*1.1 -> 114173.84 | I14: =1+5+31 -> 37
A15: MO pintura de piso acrilica | D15: =D11 -> 581.85 | F15: =28 -> 28 | G15: =F15*D15*1.1 -> 17920.98 | I15: =1-I16 -> 0.16216216 | J15: =I15*G12 -> 41669.849
A16: TOTAL | G16: =SUM(G10:G15) -> 1897364.8 | I16: =31/I14 -> 0.83783784 | J16: =I16*G12 -> 215294.22 | K16: =4160+1440+1120+2880+4800+91680+4000 -> 110080 | L16: =K16/21 -> 5241.9048
A18: TOTAL IMPERMEABILIZAÇÃO | G18: =G16 -> 1897364.8 | H18: =G18/DADOS_INICIAIS!E9 -> 178.68734
H20: =H18/1.1 -> 162.44304

Sheet ESQUADRIAS
A3: ESQUADRIAS
A4: Data | B4: 45481
A5: Arquivo base | B5: -
A7: ESQUADRIAS
A9: Descrição | B9: Parâmetro | D9: Quantidade | G9: Valor total | H9: Observação
A10: Esquadrias de Alumínio | B10: 0.15 | C10: m² / AC | D10: =B10*DADOS_INICIAIS!E9 -> 1592.7525 | E10: m² | F10: 1250 | G10: =F10*D10*1.1 -> 2190034.7 | H10: =G10/DADOS_INICIAIS!E9 -> 206.25
A11: Pele de vidro | D11: =(29.9+15.2+7.08+5.2)*5.22 -> 299.5236 | E11: m² | F11: 950 | G11: =F11*D11*1.1 -> 313002.16
A12: Portão de alumínio | D12: 1 | E12: un | F12: 18000 | G12: =F12*D12*1.1 -> 19800
A13: Guarda-corpo - vidro | D13: =15*2*DADOS_INICIAIS!E16+DADOS_INICIAIS!E17*DADOS_INICIAIS!E20*0.2 -> 571.344 | E13: m | F13: =750*1.1 -> 825 | G13: =F13*D13*1.1 -> 518494.68
A14: Gradil | D14: =1.95*2*DADOS_INICIAIS!E16*1.1 -> 77.22 | E14: m² | F14: 610 | G14: =F14*D14*1.1 -> 51814.62
A15: Serralherias | B15: 10 | C15: R$ / AC | D15: 1 | E15: vb | F15: =B15*DADOS_INICIAIS!$E$9 -> 106183.5 | G15: =F15*D15*1.1 -> 116801.85
A16: PCF | D16: =2*DADOS_INICIAIS!E15 -> 52 | E16: un | F16: 1750 | G16: =F16*D16*1.1 -> 100100
A17: Corrimão madeira | D17: =((4+5.45*2+3.65*2)*1.2*27) -> 719.28 | E17: m | F17: 65 | G17: =F17*D17*1.1 -> 51428.52
A18: Fechadura Biometrica | D18: =DADOS_INICIAIS!E10 -> 36 | E18: un | F18: 1500 | G18: =F18*D18*1.1 -> 59400
A19: Esquadrias de Madeira | D19: =2+(11*2*18)+2 -> 400 | E19: un | F19: =1450-F20 -> 1300 | G19: =F19*D19*1.1 -> 572000
A20: MO PORTAS DE MADEIRA | D20: =D19 -> 400 | E20: =E19 -> un | F20: 150 | G20: =F20*D20*1.1 -> 66000
A21: TOTAL | G21: =SUM(G10:G19) -> 3992876.5 | K21: =4160+1440+1120+2880+4800+91680+4000 -> 110080 | L21: =K21/21 -> 5241.9048
A23: TOTAL ESQUADRIAS | G23: =G21 -> 3992876.5 | H23: =G23/DADOS_INICIAIS!E9 -> 376.0355

Sheet COBERTURA
A2: COBERTURA
A3: Data | B3: 45481
A4: Arquivo base | B4: -
A6: TELHADO
A8: Descrição | B8: Parâmetro | D8: Quantidade | F8: Preço unitário | G8: Valor total | H8: Observação
A9: Estrutura e telhamento | D9: =353.75-45.46 -> 308.29 | E9: m² | F9: 500 | G9: =F9*D9*1.1 -> 169559.5
A10: Serviços complementares | D10: =D9 -> 308.29 | E10: m² | F10: 45 | G10: =F10*D10*1.1 -> 15260.355
A11: Pergolados | G11: =F11*D11*1.1 -> 0
A12: Passarelas | G12: =F12*D12*1.1 -> 0
A13: TOTAL | G13: =SUM(G9:G12) -> 184819.86
A15: TOTAL COMPLEMENTARES | G15: =G13 -> 184819.86 | H15: =G15/DADOS_INICIAIS!$E$9 -> 17.405704

Sheet Rev. Fachada
A2: ORÇAMENTO PARAMÉTRICO GERENCIAMENTO EXECUTIVO
A7: Cliente
A8: Obra
A9: Data | B9: 45481
A10: Revisão | B10: R00
A12: REVESTIMENTOS ARGAMASSADOS
A14: Descrição | B14: Quantidade | D14: Parâmetro | F14: Referência | G14: Valor total | J14: =G15-J15 -> 164938.63
A15: Chapisco e reboco | B15: =(K18*L18+K19*L19+K20*L20-ESQUADRIAS!D10) -> 5997.7683 | C15: m² | D15: =25+70 -> 95 | E15: R$ / m² | F15: - | G15: =B15*D15*1.1 -> 626766.79 | I15: =70/D15 -> 0.73684211 | J15: =I15*G15 -> 461828.16
A16: TOTAL | G16: =SUM(G15:G15) -> 626766.79
A18: PINTURA | J18: EMBASAMENTO | K18: =DADOS_INICIAIS!E26 -> 90.93 | L18: =16.92+3.24+1.2 -> 21.36
J19: TORRE 1 | K19: =DADOS_INICIAIS!E20 -> 78.36 | L19: =3.6*19+1.2 -> 69.6
A20: Descrição | B20: Quantidade | D20: Parâmetro | F20: Referência | G20: Valor total | J20: RESERV | K20: 27 | L20: =3.6*2 -> 7.2
A21: Textura | B21: =B15 -> 5997.7683 | C21: m² | D21: =70+15 -> 85 | E21: R$ / m² | F21: - | G21: =B21*D21*1.1 -> 560791.34 | I21: =45/D21 -> 0.52941176 | J21: =I21*G21 -> 296889.53 | L21: =K18*L18+K19*L19+K20*L20 -> 7590.5208
A22: TOTAL | G22: =SUM(G21:G21) -> 560791.34 | J22: =G21-J21 -> 263901.81
A24: ACABAMENTOS ESPECIAIS
A26: Descrição | B26: Quantidade | D26: Parâmetro | F26: Referência | G26: Valor total
A27: Acabamentos especiais | B27: =B21 -> 5997.7683 | C27: M² | D27: 100 | E27: R$ / m² | F27: - | G27: =B27*D27*1.1 -> 659754.51
A28: ACM embasmento | B28: =(30.3*2+15.2)*21.36 -> 1619.088 | C28: M² | D28: 450 | E28: R$ / m² | F28: - | G28: =B28*D28*1.1 -> 801448.56
G29: =SUM(G27) -> 659754.51
J30: =25.78*2 -> 51.56
A32: TOTAL FACHADA | G32: =G22+G16+G29 -> 1847312.6 | H32: =G32/DADOS_INICIAIS!E9 -> 173.97361
H33: =H32/1.1 -> 158.15782

Sheet COMPLEMENTARES
A2: COMPLEMENTARES
A3: Data | B3: 45481
A4: Arquivo base | B4: -
A6: SERVIÇOS COMPLEMENTARES
A8: Descrição | B8: Parâmetro | D8: Quantidade | F8: Valor total
A9: Móveis e decoração | B9: 1500 | C9: R$ / AL | D9: =DADOS_INICIAIS!E21 -> 800 | E9: m² | F9: =D9*B9*1.1 -> 1320000
A10: Comunicação visual | B10: 10 | C10: R$ / AC | D10: =B10*DADOS_INICIAIS!$E$9 -> 106183.5 | E10: vb | F10: =D10*1.1 -> 116801.85
A11: Paisagismo | B11: 12 | C11: R$ / AC | D11: =B11*DADOS_INICIAIS!$E$9 -> 127420.2 | E11: vb | F11: =D11*1.1 -> 140162.22
A12: Ligações definitivas | B12: 4 | C12: R$ / AC | D12: =B12*DADOS_INICIAIS!$E$9 -> 42473.4 | E12: vb | F12: =D12*1.1 -> 46720.74
A13: Desmobilização | B13: 5 | C13: R$ / AC | D13: =B13*DADOS_INICIAIS!$E$9 -> 53091.75 | E13: vb | F13: =D13*1.1 -> 58400.925
A14: Limpeza | B14: 15 | C14: R$ / AC | D14: =B14*DADOS_INICIAIS!$E$9 -> 159275.25 | E14: vb | F14: =D14*1.1 -> 175202.78
A15: TOTAL | F15: =SUM(F9:F14) -> 1857288.5
A17: TOTAL COMPLEMENTARES | F17: =F15 -> 1857288.5 | G17: =F17/DADOS_INICIAIS!$E$9 -> 174.9131

Sheet Auxiliar
A2: 2 Portões acesso garagem - Área: 9,2m² x 2 = 18,4m² | B2: 2 | C2: portão | D2: 18.4
A3: 2 portas corta-fogo 1 folha | B3: 2 | C3: pcf
A4: 1 porta de correr alumínio 2 folhas – Área: 3,465m² | B4: 1 | C4: porta alumínio | D4: 3.465
A5: 1 porta de correr alumínio 2 folhas – Área: 1,7325m² | B5: 1 | C5: porta alumínio | D5: 1.7325 | G5: Guarda alumínio | H5: =SUMIF(C:C,G5,D:D) -> 400.5221
A6: 2 portas de abrir alumínio 2 folhas – Área: 2,6376m² x 2 = 5,2752m² | B6: 2 | C6: porta alumínio | D6: 5.2752 | G6: janela | H6: =SUMIF(C:C,G6,D:D) -> 1895.06
A7: 1 porta de abrir alumínio 2 folhas – Área: 4,1916m² | B7: 1 | C7: porta alumínio | D7: 4.1916 | G7: madeira | H7: =SUMIF(C:C,G7,B:B) -> 218
A8: 1 porta pivotante | B8: 1 | C8: pivotante | G8: pcf | H8: =SUMIF(C:C,G8,B:B) -> 60
A9: 19 portas de abrir madeira 1 folha | B9: 19 | C9: madeira | G9: pivotante | H9: =SUMIF(C:C,G9,B:B) -> 1
A10: 3 portas de abrir vidro 1 folha – Área: 2,1m² x 3 = 6,3m² | B10: 3 | C10: porta alumínio | D10: 6.3 | G10: porta alumínio | H10: =SUMIF(C:C,G10,D:D) -> 46.62
A11: 2 portas de abrir vidro 1 folha – Área: 1,89m² x 2 = 3,78m² | B11: 2 | C11: porta alumínio | D11: 3.78 | G11: portão | H11: =SUMIF(C:C,G11,B:B) -> 2
A12: 1 porta de abrir alumínio 1 folha – Área: 2,0076m² | B12: 1 | C12: porta alumínio | D12: 2.0076 | G12: gradil | H12: =SUMIF(C:C,G12,D:D) -> 113.88
A13: Janelas – Área: 3,75 + 4,875 + 2,5 + 1,1 + 1,2 + 5,5402 + 4,4874 = 23,4526m² | C13: janela | D13: 23.4526 | G13: Brise | H13: 109.3146
A14: Muro de vidro – Área: 7,0774 + 5,485 + 3,43 + 4,8138 = 20,8062m² | C14: Guarda alumínio | D14: 20.8062
A15: 8 portas corta-fogo 1 folha | B15: 8 | C15: pcf
A16: Janelas – Area: (1,1 + 1,2 + 28,7391) x 4 = 124,1564m² | C16: janela | D16: 124.1564
A17: 2 portas corta-fogo 1 folha | B17: 2 | C17: pcf
A18: 2 portas de abrir alumínio 1 folha – Área: 1,47m² x 2 = 2,94m² | B18: 2 | C18: porta alumínio | D18: 2.94
A19: 2 portas de abrir vidro 1 folha – Área: 1,89m² x 2 = 3,78m² | B19: 2 | C19: porta alumínio | D19: 3.78
A20: 5 portas de abrir madeira 1 folha | B20: 5 | C20: madeira
A21: 1 janela-porta de correr vidro – Área: 14,7348m² | B21: 1 | C21: janela | D21: 14.7348
A22: Janelas – Área: 1,2894 + 1,2894 + 23,46 + 1,854 + 5,562 + 5,562 + 1,854 + 1,854 + 1,1 + 1,2 = 45,0248m² | C22: janela | D22: 45.0248
A23: Guarda corpo vidro – Área: 7,5299 + 5,7955 + 6,5555 = 19,8809m² | C23: Guarda alumínio | D23: 19.8809
A24: 38 portas corta-fogo 1 folha | B24: 38 | C24: pcf
A25: 171 portas de abrir madeira 1 folha | B25: 171 | C25: madeira
A26: 19 porta de abrir alumínio 1 folha – Área: 1,26m² x 19 = 23,94m² | B26: 19 | C26: porta alumínio | D26: 23.94
A27: 19 janela-porta de correr vidro 5 folhas - Área: 25,4205m² x 19 = 482,9895m² | B27: 19 | C27: janela | D27: 482.9895
A28: 19 janela-porta de correr vidro 5 folhas - Área: 17,8284m² x 19 = 338,7396m² | B28: 19 | C28: janela | D28: 338.7396
A29: Janelas – Área: 1,1 + 1,1 + 1,2 + 1,92 + 0,36 + 2,781 + 2,781 + 1,854 + 1,854 + 5,562 + 5,562 + 1,854 = 27,928m² x 19 = 530,632m² | C29: janela | D29: 530.632
A30: Guarda corpo metálico – Área: 4,745m² x 19 = 90,155m² - Perímetro: 3,65m x 19 = 69,35m | C30: gradil | D30: 90.155
A31: Guarda corpo vidro – Área: 15,645m² x 19 = 297,255m² - Perímetro: 14,9m x 19 = 283,1m | C31: Guarda alumínio | D31: 297.255
A32: 2 portas corta-fogo 1 folha | B32: 2 | C32: pcf
A33: 2 portas de abrir madeira 1 folha | B33: 2 | C33: madeira
A34: 1 porta de abrir alumínio 1 folha – Área: 1,26m² | B34: 1 | C34: porta alumínio | D34: 1.26
A35: 1 janela-porta de correr vidro 3 folhas - Área: 15,21m² | B35: 1 | C35: janela | D35: 15.21
A36: 1 janela-porta de correr vidro 5 folhas - Área: 25,4205m² | B36: 1 | C36: janela | D36: 25.4205
A37: 1 janela-porta de correr vidro 5 folhas - Área: 17,8284m² | B37: 1 | C37: janela | D37: 17.8284
A38: Janelas – Área: 1,1 + 1,2 + 1,1 + 1,92 + 0,36 + 2,781 + 2,781 + 1,854 + 1,854 + 5,562 + 5,562 + 1,854 = 27,928m² | C38: janela | D38: 27.928
A39: Guarda corpo metálico – Área: 4,745m² - Perímetro: 3,65m | C39: gradil | D39: 4.745
A40: Guarda corpo vidro – Área: 15,645m² - Perímetro: 14,9m | C40: Guarda alumínio | D40: 15.645
A41: 2 portas corta-fogo 1 folha | B41: 2 | C41: pcf
...
