Workbook
Name aa: #REF!
Name aa: #REF!
Name aa: #REF!
Name aa: #REF!
Name aa: #REF!
Name aaaa: '[1]M.O.'!#REF!
Name aaaa: '[1]M.O.'!#REF!
Name aaaa: '[1]M.O.'!#REF!
Name aaaa: '[1]M.O.'!#REF!
Name angelo: [2]Geral!#REF!
Name angelo: [2]Geral!#REF!
Name angelo: [2]Geral!#REF!
Name aux: #REF!
Name aux: #REF!
Name aux: #REF!
Name aux: #REF!
Name BDA: #REF!
Name BDA: #REF!
Name BDA: #REF!
Name BDA: #REF!
Name BDI: #REF!
Name BDI: #REF!
Name BDI: #REF!
Name BDI: #REF!
Name ca: #REF!
Name ca: #REF!
Name ca: #REF!
Name ca: #REF!
Name Capa: #REF!
Name Capa: #REF!
Name Capa: #REF!
Name Capa: #REF!
Name cronograma: #REF!
Name cronograma: #REF!
Name cronograma: #REF!
Name cronograma: #REF!
Name D: #REF!
Name D: #REF!
Name D: #REF!
Name D: #REF!
Name direto: #REF!
Name direto: #REF!
Name direto: #REF!
Name direto: #REF!
Name DRE: #REF!
Name DRE: #REF!
Name DRE: #REF!
Name DRE: #REF!
Name ea: #REF!
Name ea: #REF!
Name ea: #REF!
Name ea: #REF!
Name eee: {#N/A,#N/A,FALSE,"ET-CAPA";#N/A,#N/A,FALSE,"ET-PAG1";#N/A,#N/A,FALSE,"ET-PAG2";#N/A,#N/A,FALSE,"ET-PAG3";#N/A,#N/A,FALSE,"ET-PAG4";#N/A,#N/A,FALSE,"ET-PAG5"}
Name eee: {#N/A,#N/A,FALSE,"ET-CAPA";#N/A,#N/A,FALSE,"ET-PAG1";#N/A,#N/A,FALSE,"ET-PAG2";#N/A,#N/A,FALSE,"ET-PAG3";#N/A,#N/A,FALSE,"ET-PAG4";#N/A,#N/A,FALSE,"ET-PAG5"}
Name eee: {#N/A,#N/A,FALSE,"ET-CAPA";#N/A,#N/A,FALSE,"ET-PAG1";#N/A,#N/A,FALSE,"ET-PAG2";#N/A,#N/A,FALSE,"ET-PAG3";#N/A,#N/A,FALSE,"ET-PAG4";#N/A,#N/A,FALSE,"ET-PAG5"}
Name eee: {#N/A,#N/A,FALSE,"ET-CAPA";#N/A,#N/A,FALSE,"ET-PAG1";#N/A,#N/A,FALSE,"ET-PAG2";#N/A,#N/A,FALSE,"ET-PAG3";#N/A,#N/A,FALSE,"ET-PAG4";#N/A,#N/A,FALSE,"ET-PAG5"}
Name FFFFFFF: #REF!
Name FFFFFFF: #REF!
Name item_1: #REF!
Name item_1: #REF!

Sheet OBRA
A1: Obra | B1: Rua 298
A2: Empresa | B2: Meia Praia
A3: Revisão | B3: R01
A4: DADOS OBRA
A6: ARQUITETURA
B8: Descrição | C8: Unidade | D8: Quantidade
B9: ÁREA DO TERRENO | C9: M2 | D9: 820.8
B10: ÁREA CONSTRUÍDA | C10: M2 | D10: 10618.35
B11: NÚMERO DE UNIDADES HABITACIONAIS | C11: UN | D11: 36
B12: MESES DE OBRA | C12: MÊS | D12: 46
B13: NÚMERO DE PAVIMENTOS | C13: UN | D13: 26

Sheet CANTEIRO
A1: Obra | B1: Rua 298
A2: Empresa | B2: Meia Praia
A3: Revisão | B3: =OBRA!B3 -> R01
A4: LEVANTAMENTO QUANTITATIVO
A6: Instalações de canteiro
A8: Instalações de canteiro
B10: Descrição | C10: Unidade | D10: Quantidade
B11: Produtividade média | C11: h/m2 | D11: =OBRA!D10/OBRA!D12 -> 230.8337
B12: Pm | C12: h/m2 | D12: 49
B13: Numero de funcionários | C13: un | D13: 15
B14: Equipe administrativa | C14: un | D14: 5
B15: Pontos de água e esgoto | C15: un | D15: =ROUNDUP($D$13/20,0) -> 1 | E15: 20 funcionários/ponto
B16: Ferramentas | C16: R$ | D16: =800*D13 -> 12000 | E16: 800,00/func.
B17: EPI | C17: R$ | D17: =500*(D13+D14) -> 10000 | E17: 500,00/func.
B18: Banheiro | C18: un | D18: =ROUNDUP($D$13/20,0) -> 1 | E18: 1/20 func
A20: Mobiliário de canteiro
B22: Descrição | C22: Unidade | D22: Quantidade | E22: Custo unitário | F22: Custo total
B23: Cadeira | C23: un | D23: =ROUNDUP(D14*1.5,0) -> 8 | E23: 200 | F23: =D23*E23 -> 1600
B24: Mesa | C24: un | D24: =D14 -> 5 | E24: 1000 | F24: =E24*D24 -> 5000
B25: Ar condicionado | C25: un | D25: 1 | E25: 5000 | F25: =E25*D25 -> 5000
B26: Armário | C26: m | D26: =7 -> 7 | E26: 900 | F26: =E26*D26 -> 6300
B27: Escrivaninha | C27: un | D27: =D14 -> 5 | E27: 800 | F27: =E27*D27 -> 4000
B28: TOTAL | F28: =F25+F26+F27+F24+F23 -> 21900
B29: Descrição | C29: Unidade | D29: Quantidade | E29: Custo unitário | F29: Custo total
B30: Computador pessoal | C30: un | D30: =D14 -> 5 | E30: 6000 | F30: =D30*E30 -> 30000
B31: Impressora | C31: un | D31: 1 | E31: 2000 | F31: =E31*D31 -> 2000
B32: Roteador | C32: un | D32: 2 | E32: 500 | F32: =E32*D32 -> 1000
B33: TOTAL | F33: =+F30+F31+F32 -> 33000

Sheet EPCs
A1: Obra | B1: Rua 298
A2: Empresa | B2: Meia Praia
A3: Revisão | B3: =[3]OBRA!B3 -> R00
A4: LEVANTAMENTO QUANTITATIVO
A6: Equipamentos de proteção coletiva
A8: Bandejas de proteção
B10: Descrição | C10: Unidade | D10: Quantidade
B11: Perímetro de projeção embasamneto | C11: m | D11: 90.93
B12: Perímetro de projeção torre | C12: m | D12: 78.36
B13: Bandeja de proteção primária | C13: m | D13: =D11+D12 -> 169.29
B14: Bandeja de proteção secundária | C14: m | D14: =D12 -> 78.36
A16: Guarda - corpo de desforma
B18: Descrição | C18: Unidade | D18: Quantidade
B19: Perímetro de projeção da torre | C19: m | D19: =D12 -> 78.36
B20: Repetições de pavimentos** | C20: un | D20: 4
B21: Proteção de periferia pós desforma torre | C21: m | D21: =(D19*D20) -> 313.44
A23: Tela fachadeira
B25: Descrição | C25: Unidade | D25: Quantidade
B26: Perimetro da torre | C26: m | D26: =D12 -> 78.36
B27: Altura da torre | C27: m | D27: =16.92+3.24+3.6*20 -> 92.16
B28: Tela fachadeira | C28: m2 | D28: =D26*D27 -> 7221.6576
A30: Tela SLQA
B32: Descrição | C32: Unidade | D32: Quantidade
B33: Perimetro da torre | C33: m | D33: =D19 -> 78.36
B34: Tela SLQA | C34: m | D34: =D33 -> 78.36
A36: Fechamento removível de vãos em madeira
B38: Descrição | C38: Unidade | D38: Quantidade
B39: Área das portas de elevadores | C39: m2 | D39: =0.9*2.4 -> 2.16
B40: Quantidade de elevadores | C40: un | D40: 2
B41: Quantidade de portas de elevadores | C41: un | D41: =D40*OBRA!D13 -> 52
B42: Fechamento removível de vãos em madeira | C42: m2 | D42: =D39*D41 -> 112.32
A44: Tapume
B46: Descrição | C46: Unidade | D46: Quantidade
B47: Perímetro de encontro com pavimentação | C47: m | D47: =30.3*2+16 -> 76.6
B48: Altura do tapume | C48: m | D48: 2.4
B49: Cobertura para proteção de pedestres | C49: m2 | D49: =D48*D47 -> 183.84

Sheet CUSTOS_INDIRETOS
A1: ORÇAMENTO PARAMÉTRICO - CUSTOS INDIRETOS
A7: Cliente | B7: Meia Praia
A8: Obra | B8: Rua 298
A9: Data | B9: 45509
A10: Versão | B10: R01
A12: GERENCIAMENTO TÉCNICO
A13: Código | B13: Descrição | C13: Un. | D13: Quantidade orçada | E13: Preço unitário | F13: Preço total
A14: 01 | B14: GERENCIAMENTO TÉCNICO | F14: =F15+F42 -> 1002197.4
A15: 01.001 | B15: ESTUDOS, PROJETOS E CONSULTORIAS | F15: =SUM(F16:F37) -> 801362.74
A16: 01.001.001 | B16: Estudos | F16: 16907.214
A17: 02.001.001.001 | B17: Levantamento topográfico
A18: 02.001.001.002 | B18: Estudo geológico
A19: 02.001.001.003 | B19: Estudo ambiental
A20: 02.001.001.004 | B20: Sondagem
A21: 02.001.001.005 | B21: Memorial descritivo
A22: 02.001.001.006 | B22: Projeto de canteiro
A23: 01.001.002 | B23: Projetos | F23: 557227.52
A24: 02.001.002.001 | B24: Projeto arquitetônico
A25: 02.001.002.002 | B25: Projeto de terraplanagem
A26: 02.001.002.003 | B26: Projeto de fundações
A27: 02.001.002.004 | B27: Projeto hidrossanitário
A28: 02.001.002.005 | B28: Projeto PPCI e GLP
A29: 02.001.002.006 | B29: Projeto de paisagismo
A30: 02.001.002.007 | B30: Projeto estrutural
A31: 02.001.002.008 | B31: Projeto de elétrico
A32: 02.001.002.009 | B32: Projeto de climatização
A33: 02.001.002.010 | B33: Projeto de interiores
A34: 02.001.002.011 | B34: Projeto de impermeabilização
A35: 01.001.003 | B35: Consultorias | F35: 103081.77
A36: 02.001.003.001 | B36: Planejamento e orçamento
A37: 01.001.004 | B37: Ensaios e Laudos | F37: 124146.24
A38: 02.001.004.001 | B38: Controle tecnológico do concreto
A39: 02.001.004.002 | B39: Ensaio com laudo de desempenho
A40: 02.001.004.003 | B40: Prova de cargas estáticas
A41: 02.001.004.004 | B41: Laudo preventivo de danos à vizinhança
A42: 01.002 | B42: TAXAS E DOCUMENTOS | F42: =SUM(F43:F59) -> 200834.69
A43: 01.002.001 | B43: Seguros | F43: 19919.765
A44: 02.002.001.001 | B44: Seguro de obra
A45: 01.002.002 | B45: Licenciamentos, Taxas, Impostos | F45: 126569.47
A46: 02.002.002.001 | B46: Taxas de alvarás
...

Sheet Gerenciamento Executivo
A1: ORÇAMENTO PARAMÉTRICO
A7: Cliente | B7: Meia Praia
A8: Obra | B8: Rua 298
A9: Data | B9: 45509
A10: Versão | B10: R01
A12: CÓDIGO | B12: ITEM | C12: Quantidade | D12: Unidade | E12: Custo unitário | F12: Valor Orçado | G12: Observações
A13: 1 | B13: GERENCIAMENTO TÉCNICO E ADMINISTRATIVO | F13: =F14 -> 4306231.3
A14: 1.1 | B14: GERENCIAMENTO TÉCNICO E ADMINISTRATIVO | F14: =F15 -> 4306231.3
A15: 1.1.1 | B15: Gerenciamento técnico e administrativo | C15: 1 | D15: vb | E15: =F15/C15 -> 4306231.3 | F15: =CUSTOS_INDIRETOS!F113 -> 4306231.3
A16: 2 | B16: MOVIMENTAÇÃO DE TERRA | F16: =F17 -> 89379.444
A17: 2.1 | B17: MOVIMENTAÇÃO DE VALAS | F17: =SUM(F18:F22) -> 89379.444
A18: 2.1.1 | B18: Escavação mecanizada para blocos e baldrames | C18: 478.816 | D18: m3 | E18: =F18/C18 -> 66 | F18: 31601.856 | G18: Custo previsto para toda a movimentação com maquinário e apoio
A19: 2.1.2 | B19: Reaterro para blocos e baldrames | C19: 110.496 | D19: m3 | E19: =F19/C19 -> 22 | F19: 2430.912
A20: 2.1.3 | B20: Movimentação de bota-fora | C20: 478.816 | D20: m3 | E20: =F20/C20 -> 44 | F20: 21067.904 | G20: Consideração de 30% como fator de empolamento
A21: 2.1.4 | B21: Movimentação de terra das estacas | C21: 608.71499 | D21: m3 | E21: =F21/C21 -> 44 | F21: 26783.46 | G21: 40,00 R$/m³ de material com empolamento
A22: 2.1.5 | B22: Lastro de concreto magto e=5cm | C22: 368.32 | D22: m2 | E22: =F22/C22 -> 20.35 | F22: 7495.312 | G22: 312,00 R$/m³ de concreto magro + R$ 40,00/m³ para bombeamento
A23: 3 | B23: INFRAESTRUTURA | F23: =F24+F31 -> 1818002.4
A24: 3.1 | B24: FUNDAÇÃO PROFUNDA | F24: =SUM(F25:F30) -> 885869.2
A25: 3.1.1 | B25: Estaca Hélice Continua Diâmetro 50 | C25: 1568 | D25: m | E25: =F25/C25 -> 99 | F25: 155232 | G25: 90,00 R$/m incluindo todo o serviço, maquinário e apoio
A26: 3.1.2 | B26: Estaca Hélice Continua Diâmetro 60 | C26: 1064 | D26: m | E26: =F26/C26 -> 115.5 | F26: 122892 | G26: 105,00 R$/m incluindo todo o serviço, maquinário e apoio
A27: 3.1.3 | B27: Concreto (40 Mpa) | C27: 608.71499 | D27: m³ | E27: =F27/C27 -> 829.4 | F27: 504868.21 | G27: 535,00 R$/m³ de concreto + R$ 45,00/m³ para bombeamento (30% de perda)
A28: 3.1.4 | B28: Armação | C28: 7304.5799 | D28: kg | E28: =F28/C28 -> 8.382 | F28: 61226.989 | G28: Custo médio para a bitola de 10mm (CA-50) de R$ 7,62/kg, incluíndo 10% de perda para corte e dobra em obra
A29: 3.1.5 | B29: Mobilização | C29: 1 | D29: vb | E29: =F29/C29 -> 13750 | F29: 13750 | G29: Custo de mobilização e desmobilização de maquinário para estaca hélice contínua
A30: 3.1.6 | B30: Apoio e arrasamento de estacas | C30: 93 | D30: un | E30: =F30/C30 -> 300 | F30: 27900
A31: 3.2 | B31: FUNDAÇÃO RASA | F31: =SUM(F32:F36) -> 932133.21
A32: 3.2.1 | B32: Fabricação, montagem e desmontagem de forma para blocos e baldrames resinado | C32: 966.84 | D32: m² | E32: =F32/C32 -> 74.8 | F32: 72319.632 | G32: Consideração de custo de formas de madeira serrada com utilização única
A33: 3.2.3 | B33: Concreto (40 Mpa) | C33: 368.32 | D33: m³ | E33: =F33/C33 -> 669.9 | F33: 246737.57 | G33: 535,00 R$/m³ de concreto + R$ 45,00/m³ para bombeamento (5% de perda)
A34: 3.2.4 | B34: Armação | C34: 40515.2 | D34: kg | E34: =F34/C34 -> 8.382 | F34: 339598.41 | G34: Custo médio para a bitola de 10mm (CA-50) de R$ 7,62/kg, incluíndo 10% de perda para corte e dobra em obra
A35: 3.2.5 | B35: Piso de concreto armado | C35: 460.4 | D35: m² | E35: =F35/C35 -> 198 | F35: 91159.2 | G35: Custo de material para execução de piso sobre solo
A36: 3.2.6 | B36: Mão de obra | C36: 460.4 | D36: m² | E36: =F36/C36 -> 396 | F36: 182318.4 | G36: Mão de obra prevista para formas, armação, concretagem e apoio de todo o sistema de infraestrutura - R$ 396,00/m² de área de projeção do embasamento
A37: 5 | B37: SUPRAESTRUTURA | F37: =F38+F41+F43+F45+F49 -> 8052236.1
A38: 5.1 | B38: FORMA | F38: =SUM(F39:F40) -> 443622.41
A39: 5.1.1 | B39: Fabricação forma | C39: 3062.9856 | D39: m² | E39: =F39/C39 -> 121 | F39: 370621.25 | G39: Fabricação de 3 jogos referentes ao pavimento tipo com compensado plastificado
A40: 5.1.2 | B40: Montagem de forma | C40: 26545.875 | D40: m² | E40: =F40/C40 -> 2.75 | F40: 73001.156 | G40: Montagem contemplando desmoldante e reposição de pregos das formas fabricadas
A41: 5.2 | B41: ARMADURA | F41: =F42 -> 2447582.8
A42: 5.2.1 | B42: Armadura Convencional para Estrutura | C42: 292004.62 | D42: kg | E42: =F42/C42 -> 8.382 | F42: 2447582.8 | G42: Custo médio para a bitola de 10mm (CA-50) de R$ 7,62/kg, incluíndo 10% de perda para corte e dobra em obra
A43: 5.3 | B43: CONCRETO | F43: =F44 -> 1778308.2
A44: 5.3.1 | B44: Concreto | C44: 2654.5875 | D44: m³ | E44: =F44/C44 -> 669.9 | F44: 1778308.2 | G44: 535,00 R$/m³ de concreto + R$ 45,00/m³ para bombeamento (5% de perda)
A45: 5.4 | B45: COMPLEMENTARES | F45: =SUM(F46:F48) -> 579478.35
A46: 5.4.1 | B46: Locação de escoramento | C46: 4144 | D46: un | E46: =F46/C46 -> 18.7 | F46: 77492.8 | G46: Previsão de custo para manutenção de escoras próprias durante o período estimado de 24 meses
...
