Workbook

Sheet Dados Gerais
A2: ORÇAMENTO PARAMÉTRICO GERENCIAMENTO EXECUTIVO
A7: Documento | B7: CTN_ART-RES Orçamento Paramétrico
A8: Cliente | B8: Neuhaus LTDA
A9: Obra | B9: Origem 3300
A10: Data | B10: 45462 | E10: Revisão | F10: R03 | G10: Status | H10: Finalizado | I10: Responsável | J10: Larissa/Bianca
A12: Descrição | D12: Identificador | E12: Informação
A13: Área do terreno | D13: AT | E13: 1294.4 | H13: m²
A14: Testada do terreno | D14: TT | E14: 97.5 | H14: m
A15: Área total construída | D15: AC | E15: 14516.38 | H15: m²
A16: N° total de pavimentos | D16: NP | E16: 33 | H16: un
A17: N° de pavimentos tipo | D17: NPT | E17: 18 | H17: un
A18: N° de pavimentos tipo diferenciado | D18: NPD | E18: 1 | H18: un
A19: N° de pavimentos duplex | D19: ND | E19: 3 | H19: un
A20: Área de projeção da torre | D20: APT | E20: 325.64 | H20: m²
A21: Perímetro de projeção da torre | D21: PPT | E21: 86.63 | H21: m
A22: Área Lazer | D22: AL | E22: 1284 | H22: m²
A23: Locação da obra | D23: LC | E23: 231.78 | H23: m
A24: Área do embasamento | D24: AE | E24: 5188.25 | H24: m²
... A29: N° de pavimentos de embasamento | D29: NPE | E29: 5 | H29: un

Sheet Resumo
A2: ORÇAMENTO PARAMÉTRICO GERENCIAMENTO EXECUTIVO
A7: Documento | B7: CTN_NHS-ORIGEM 3300 Orçamento Paramétrico
A8: Cliente | B8: Neuhaus LTDA
A9: Obra | B9: Origem 3300
A10: Data | B10: 45462 | C10: Revisão | D10: R03 | E10: Status | F10: Finalizado | G10: Responsável | H10: Larissa/Bianca
A12: MOVIMENTAÇÃO DE TERRA
A14: Descrição | D14: Valor total
A15: ='Movimentação de Terra'!A19 -> REBAIXAMENTO DE LENÇOL | D15: ='Movimentação de Terra'!I23 -> 5500
A16: ='Movimentação de Terra'!A26 -> ESCAVAÇÃO E REATERRO DE VALAS | D16: ='Movimentação de Terra'!I33 -> 299317.12
A17: ='Movimentação de Terra'!A36 -> REGULARIZAÇÃO E APILOAMENTO DE FUNDO DE VALAS | D17: ='Movimentação de Terra'!I40 -> 29580
A18: TOTAL | D18: =SUM(D15:H17) -> 334397.12
A22: INFRAESTRUTURA
A24: Descrição | D24: Valor total
A25: =Infraestrutura!A12 -> FUNDAÇÃO PROFUNDA | D25: =Infraestrutura!I23 -> 1874063.4
A26: =Infraestrutura!A26 -> FUNDAÇÃO RASA | D26: =Infraestrutura!I33 -> 934895.74
A27: TOTAL | D27: =Infraestrutura!I37 -> 2808959.2
A30: SUPRAESTRUTURA
A32: Descrição | D32: Valor total
A33: =+Supraestrutura!A12 -> SUPRAESTRUTURA | D33: =+Supraestrutura!I25 -> 14216001
A34: TOTAL | D34: =SUM(D33:H33) -> 14216001
A37: ALVENARIA
A39: Descrição | D39: Valor total
A40: =+Alvenaria!A12 -> ALVENARIA | D40: =+Alvenaria!I29 -> 3060534.4
A41: TOTAL | D41: =SUM(D40) -> 3060534.4
A44: INSTALAÇÕES
A46: Descrição | D46: Valor total
A47: =+Instalações!A12 -> INSTALAÇÕES ELÉTRICAS | D47: =+Instalações!I22 -> 2448913.3
A48: =+Instalações!A24 -> INSTALAÇÕES HIDRÁULICAS | D48: =+Instalações!I35 -> 2359927.9
A49: =+Instalações!A38 -> INSTALAÇÕES PREVENTIVAS E GLP | D49: =+Instalações!I44 -> 827433.66
A50: TOTAL | D50: =SUM(D47:H49) -> 5636274.9
A53: SISTEMAS ESPECIAIS
A55: Descrição | D55: Valor total
A56: ='Sistemas especiais'!A12 -> CLIMATIZAÇÃO, EXAUSTÃO MECÂNICA E PRESSURIZAÇÃO | D56: ='Sistemas especiais'!I19 -> 637000
A57: ='Sistemas especiais'!A29 -> AUTOMAÇÃO | D57: ='Sistemas especiais'!I33 -> 116131.04
A58: COMUNICAÇÃO | D58: ='Sistemas especiais'!I27 -> 377425.88
A59: ='Sistemas especiais'!A35 -> OUTROS SISTEMAS ESPECIAIS | D59: ='Sistemas especiais'!I39 -> 435491.4
A60: ='Sistemas especiais'!A41 -> EQUIPAMENTOS | D60: ='Sistemas especiais'!I51 -> 2449400
A61: TOTAL | D61: =SUM(D56:H60) -> 4015448.3
A64: IMPERMEABILIZAÇÃO
A66: Descrição | D66: Valor total
...

Sheet Movimentação de Terra
A2: ORÇAMENTO PARAMÉTRICO MOVIMENTAÇÃO DE TERRA
A7: Documento | B7: CTN_ART-RES Orçamento Paramétrico
A8: Cliente | B8: Neuhaus LTDA
A9: Obra | B9: Origem 3300
A10: Data | B10: 45462 | E10: Revisão | F10: R03 | G10: Status | H10: Finalizado | I10: Responsável | J10: Larissa/Bianca
A12: ESCAVAÇÃO
A14: Descrição | D14: Quantidade | F14: Parâmetro | H14: Referência | I14: Valor total
A15: Escavação | D15: =+'[2]Dados Gerais'!E25*3.06 -> 0 | E15: m³ | F15: 28.5 | G15: R$ / m³ | H15: Pedro Chaves | I15: =+D15*F15 -> 0
A16: TOTAL | I16: =SUM(I15:J15) -> 0
A19: REBAIXAMENTO DE LENÇOL
A21: Descrição | D21: Quantidade | F21: Parâmetro | H21: Referência | I21: Valor total
A22: Rebaixamento de Lençol | D22: 10 | E22: dias | F22: 550 | G22: R$ / dia | H22: Média | I22: =F22*D22 -> 5500 | K22: OK
A23: TOTAL | I23: =SUM(I22:J22) -> 5500
A26: ESCAVAÇÃO E REATERRO DE VALAS
A28: Descrição | D28: Quantidade | F28: Parâmetro | H28: Referência | I28: Valor total
A29: Escavação mecanizada para blocos e baldrames | D29: =Infraestrutura!D31*1.3 -> 640.029 | E29: m³ | F29: 1.6 | G29: m³ / AE | H29: Média | I29: =+ROUNDUP((F29*'Dados Gerais'!$E$13*65),0) -> 134618 | K29: OK
A30: Reaterro para blocos e baldrames | D30: =D29-Infraestrutura!D31 -> 147.699 | E30: m³ | F30: 0.7 | G30: m³ / AE | H30: Média | I30: =+ROUNDUP((F30*'Dados Gerais'!$E$13*15),0) -> 13592 | K30: OK
A31: Movimentação de terra das estacas | D31: =Infraestrutura!D21*F31 -> 2931.25 | E31: m³ | F31: 1.75 | G31: m³ / m³ | H31: Média | I31: =+D31*45 -> 131906.25 | K31: OK
A32: Bota-fora de escavação | D32: =(D29-D30)*1.3 -> 640.029 | E32: m³ | F32: 30 | G32: R$ / m³ | H32: Média | I32: =F32*D32 -> 19200.87 | K32: OK
A33: TOTAL | I33: =SUM(I29:J32) -> 299317.12
A36: REGULARIZAÇÃO E APILOAMENTO DE FUNDO DE VALAS
A38: Descrição | D38: Quantidade | F38: Parâmetro | H38: Referência | I38: Valor total
A39: Lastro de concreto magro e= 10cm - Blocos | D39: =+F39*'Dados Gerais'!E27 -> 845.136 | E39: m² | F39: 0.8 | G39: m² / APE | H39: Média | I39: =ROUNDUP((D39*35),0) -> 29580 | K39: OK
A40: TOTAL | I40: =SUM(I39:J39) -> 29580
A42: TOTAL | I42: =SUM(I40+I33+I23) -> 334397.12 | J42: =I40+I33+I23 -> 334397.12 | K42: =J42/'Dados Gerais'!E15 -> 23.035848

Sheet Infraestrutura
A2: ORÇAMENTO PARAMÉTRICO INFRAESTRUTURA
A7: Documento | B7: CTN_ART-RES Orçamento Paramétrico
A8: Cliente | B8: Neuhaus LTDA
A9: Obra | B9: Origem 3300
A10: Data | B10: 45462 | E10: Revisão | F10: R03 | G10: Status | H10: Finalizado | I10: Responsável | J10: Larissa/Bianca
A12: FUNDAÇÃO PROFUNDA
A14: Descrição | D14: Quantidade | F14: Parâmetro | H14: Referência | I14: Valor total
A15: Número de Estacas | D15: 160 | E15: un | F15: 0.15 | G15: un / m² | H15: Média | I15: 0
A16: Estaca Hélice Continua Diâmetro 50 | D16: 19 | E16: un | F16: 19 | G16: % | H16: Média | I16: 0
A17: Estaca Hélice Continua Diâmetro 50 | D17: =ROUNDUP((F17*D16),0) -> 608 | E17: m | F17: 32 | G17: m / un | H17: Média | I17: =+ROUNDUP((D17*110),0) -> 66880
A18: Estaca Hélice Continua Diâmetro 60 | D18: 141 | E18: un | F18: 81 | G18: % | H18: Média | I18: 0
A19: Estaca Hélice Continua Diâmetro 60 | D19: =ROUNDUP((F19*D18),0) -> 4371 | E19: m | F19: 31 | G19: m / un | H19: Média | I19: =+ROUNDUP((D19*115),0)+321.42 -> 502986.42
A20: Armação | D20: 20729 | E20: kg | F20: 12 | G20: kg / m³ | H20: Média | I20: =+ROUNDUP((D20*8.5),0) -> 176197
A21: Concreto | D21: 1675 | E21: m³ | F21: 640 | G21: R$ / m³ | H21: Média | I21: =+ROUNDUP((D21*F21),0) -> 1072000
A22: Arrasamento de Estacas | D22: 160 | E22: un | F22: 350 | G22: R$ / um | H22: Média | I22: =+ROUNDUP((D22*F22),0) -> 56000
A23: TOTAL | I23: =SUM(I15:J22) -> 1874063.4
A26: FUNDAÇÃO RASA
A28: Descrição | D28: Quantidade | F28: Parâmetro | H28: Referência | I28: Valor total
A29: Fabricação, montagem e desmontagem de forma para blocos e baldrames | D29: ='Dados Gerais'!E13*F29 -> 983.744 | E29: m² | F29: 0.76 | G29: m² / AT | H29: Média | I29: =+D29*42.5 -> 41809.12
A30: Armação | D30: =D31*F30 -> 39386.4 | E30: kg | F30: 80 | G30: kg / m³ | H30: Média | I30: =+D30*8.5 -> 334784.4
A31: Concreto | D31: =984.66*F31 -> 492.33 | E31: m³ | F31: 0.5 | G31: m³ / AT | H31: Média | I31: =+D31*380*1.05 -> 196439.67
A32: Mão de obra | D32: 984.66 | E32: m² | F32: 350 | G32: R$ / AT | H32: Média | I32: =+D32*F32*1.05 -> 361862.55 | L32: Considerado área do térreo
A33: ] | I33: =SUM(I29:J32) -> 934895.74
A35: TOTAL | I35: =SUM(I33+I23) -> 2808959.2 | J35: =I33+I26+I17 -> 1001775.7 | K35: =I35/'Dados Gerais'!E15 -> 193.50273
A37: VALOR DO CLIENTE | H37: valor do cliente | I37: 2808959.2 | J37: 2808959.2 | K37: =I37/'Dados Gerais'!E15 -> 193.50273

Sheet Supraestrutura
A2: ORÇAMENTO PARAMÉTRICO SUPRAESTRUTURA
A7: Documento | B7: CTN_ART-RES Orçamento Paramétrico
A8: Cliente | B8: Neuhaus LTDA
A9: Obra | B9: Origem 3300 | M9: Z
A10: Data | B10: 45462 | E10: Revisão | F10: R03 | G10: Status | H10: Finalizado | I10: Responsável | J10: Larissa/Bianca | M10: protensão
M11: 5,00 / m² | N11: material
A12: SUPRAESTRUTURA | M12: 7000 / laje | N12: serviços
M13: 12,30 / kg | N13: aço
A14: Descrição | D14: Quantidade | F14: Parâmetro | H14: Referência | I14: Valor total | M14: 1,83 kg/m² | N14: índice
A15: Fabricação forma - Embasamento | D15: 4196.66 | E15: m² | F15: 25 | G15: % | H15: Média | I15: =+D15*158 -> 663072.28
A16: Fabricação forma - Torre | D16: =D17/3 -> 3109.3933 | E16: m² | F16: 26 | G16: % | H16: Média | I16: =+D16*158 -> 491284.15
A17: Escoramento - Torre | D17: 9328.18 | E17: m² | F17: =I17/D17 -> 26.987931 | G17: R$ / m² | H17: Média | I17: 251748.28
A18: Escoramento - Embasamento | D18: 4193.66 | E18: m² | F18: =I18/D18 -> 97.755691 | G18: R$ / m² | H18: Média | I18: 409954.13
A19: Protensão - lajes torre - cabos | D19: 25941.8 | E19: kg | F19: 2.83 | G19: kg / m² | H19: Média | I19: =+D19*12.3 -> 319084.14
A20: Protensão - lajes torre - serviços | D20: 28 | E20: und | F20: 9000 | G20: und | H20: Média | I20: =+D20*F20 -> 252000
A21: Protensão - vigas torre - cabos | D21: 9364.9 | E21: kg | F21: 2.83 | G21: kg / m² | H21: Média | I21: =+D21*12.3 -> 115188.27
A22: Armadura Convencional para Estrutura | D22: 550544 | E22: kg | F22: 110 | G22: kg / m³ | H22: Média | I22: =+D22*7.2 -> 3963916.8 | K22: alterado para 7,2 conforme orientação do Sandro
A23: Concreto | D23: 5409.36 | E23: m³ | F23: 0.25 | G23: m³ / AC | H23: Média | I23: =+D23*660*1.05 -> 3748686.5
A24: Mão de obra da supraestrutura (incluso montagem de forma) | D24: 14100.96 | E24: m² | F24: 249 | G24: R$ / m² | H24: Média | I24: =+D24*F24+489927.83 -> 4001066.9
A25: TOTAL | I25: =SUM(I15:J24) -> 14216001
A27: TOTAL | I27: =I25 -> 14216001 | J27: =I25+I18+I9 -> 14625956 | K27: =I27/'Dados Gerais'!E15 -> 979.30761
J28: =I26 -> 0
J29: ='[3]ORÇAMENTO RESUMO'!$E$25 -> 18837581
J30: =I27--J29 -> 33053582

Sheet Alvenaria
A2: ORÇAMENTO PARAMÉTRICO ALVENARIA
A7: Documento | B7: CTN_ART-RES Orçamento Paramétrico
A8: Cliente | B8: Neuhaus LTDA
A9: Obra | B9: Origem 3300
A10: Data | B10: 45462 | E10: Revisão | F10: R03 | G10: Status | H10: Finalizado | I10: Responsável | J10: Larissa/Bianca
A12: ALVENARIA
A14: Descrição | D14: Quantidade | F14: Parâmetro | H14: Referência | I14: Valor total
A15: Alvenaria embasamento | D15: 4136.11 | E15: m² | F15: 50 | G15: R$ / APT | H15: Média | I15: =F15*D15 -> 206805.5
A16: Alvenaria lazer | D16: =1550.59*E37 -> 723.12022 | E16: m² | F16: 50 | G16: R$/ APT | H16: Média | I16: =F16*D16 -> 36156.011
A17: Drywall lazer | D17: =1150.59*(E36+E38) -> 614.01044 | E17: m² | F17: 220 | G17: R$ / m² | H17: Média | I17: =F17*D17 -> 135082.3
A18: Alvenaria tipo | D18: =12238.6*0.47 -> 5752.142 | E18: m² | F18: 50 | G18: R$/ APT*NPT | H18: Média | I18: =F18*D18 -> 287607.1
A19: Drywall tipo | D19: =12238.6*E36 -> 6040.443 | E19: m² | F19: 220 | G19: R$ / m² | H19: Média | I19: =F19*D19 -> 1328897.5
A20: Alvenaria dupla tipo | D20: =12238.6*E38 -> 490.66552 | E20: m² | F20: 188 | G20: R$ / m² | H20: Média | I20: =F20*D20 -> 92245.118
A21: Alvenaria tipo diferenciado | D21: =617.87*E37 -> 288.1447 | E21: m² | F21: 50 | G21: R$/ APT*NPD | H21: Média | I21: =F21*D21 -> 14407.235
A22: Drywall Diferenciado | D22: =617.87*E36 -> 304.95388 | E22: m² | F22: 220 | G22: R$ / m² | H22: Média | I22: =F22*D22 -> 67089.853
A23: Alvenaria dupla | D23: =617.87*E38 -> 24.77142 | E23: m² | F23: 188 | G23: R$ / m² | H23: Média | I23: =F23*D23 -> 4657.027
A24: Alvenaria cobertura / reservatório | D24: 307.64 | E24: m² | F24: 50 | G24: R$/ APT | H24: Média | I24: =F24*D24 -> 15382
A25: Bloco de concreto autoclavado | D25: 2096.07 | E25: m² | F25: 60 | G25: R$ / m² | H25: Média | I25: =F25*D25 -> 125764.2
A26: Serviços complementares | D26: =D27+D28 -> 13818.664 | E26: m² | F26: 12.5 | G26: R$ / m² de alv. | H26: Média | I26: =+F26*D26 -> 172733.3
A27: Mão de obra - Bloco Cerâmico | D27: =SUM(D15+D16+D18+D20+D21+D23+D24) -> 11722.594 | E27: m² | F27: 40 | G27: R$ / m² | H27: Média | I27: =+D27*F27 -> 468903.75
A28: Mão de obra - Bloco Concreto | D28: =D25 -> 2096.07 | E28: m² | F28: 50 | G28: R$ / m² | H28: Média | I28: =+D28*F28 -> 104803.5
A29: TOTAL | I29: =SUM(I15:J28) -> 3060534.4
A31: TOTAL | I31: =I29 -> 3060534.4 | J31: =I29+I18+I8 -> 3348141.5 | K31: =I31/'Dados Gerais'!E15 -> 210.83317
D36: =1.08+2.78+4.06+2.75+8.41+3.56+1.06+2.28+2.66+2.66+0.62+2.55 -> 34.47 | E36: =D36/D39 -> 0.4935567
D37: =11.35+7.22+14 -> 32.57 | E37: =D37/D39 -> 0.46635166
D38: =2.8 -> 2.8 | E38: =D38/D39 -> 0.040091638
D39: =SUM(D36:D38) -> 69.84

Sheet Instalações
A2: ORÇAMENTO PARAMÉTRICO INSTALAÇÕES
A7: Documento | B7: CTN_ART-RES Orçamento Paramétrico
A8: Cliente | B8: Neuhaus LTDA
A9: Obra | B9: Origem 3300
A10: Data | B10: 45462 | E10: Revisão | F10: R03 | G10: Status | H10: Finalizado | I10: Responsável | J10: Larissa/Bianca
A12: INSTALAÇÕES ELÉTRICAS
A14: Descrição | D14: Quantidade | F14: Parâmetro | H14: Referência | I14: Valor total
A15: Entrada de Energia | D15: 1 | E15: vb | F15: 5 | G15: R$ / AC | H15: Média | I15: =+F15*'Dados Gerais'!$E$15 -> 72581.9
A16: Eletrodutos e Eletrocalhas | D16: 1 | E16: vb | F16: 12.8 | G16: R$ / AC | H16: Média | I16: =+F16*'Dados Gerais'!$E$15 -> 185809.66
A17: Instalações Embutidas e Aparentes | D17: 1 | E17: vb | F17: 16.9 | G17: R$ / AC | H17: Média | I17: =+F17*'Dados Gerais'!$E$15 -> 245326.82
A18: Cabos e Fiações | D18: 1 | E18: vb | F18: 40 | G18: R$ / AC | H18: Média | I18: =+F18*'Dados Gerais'!$E$15 -> 580655.2
A19: Quadros e Disjuntores | D19: 1 | E19: vb | F19: 20 | G19: R$ / AC | H19: Média | I19: =+F19*'Dados Gerais'!$E$15 -> 290327.6
A20: Equipamentos e Iluminação | D20: 1 | E20: vb | F20: 19 | G20: R$ / AC | H20: Média | I20: =+F20*'Dados Gerais'!$E$15 -> 275811.22
A21: Mão de Obra para Instalações Elétricas | D21: 1 | E21: vb | F21: 55 | G21: R$ / AC | H21: Média | I21: =+F21*'Dados Gerais'!$E$15 -> 798400.9
A22: TOTAL | I22: =SUM(I15:J21) -> 2448913.3
A24: INSTALAÇÕES HIDRÁULICAS
A26: Descrição | D26: Quantidade | F26: Parâmetro | H26: Referência | I26: Valor total
A27: Instalações de Água Fria | D27: 1 | E27: vb | F27: 25 | G27: R$ / AC | H27: Média | I27: =+F27*'Dados Gerais'!$E$15 -> 362909.5
A28: Instalações de Água Quente | D28: 1 | E28: vb | F28: 15 | G28: R$ / AC | H28: Média | I28: =+F28*'Dados Gerais'!$E$15 -> 217745.7
A29: Instalações de Águas Pluviais | D29: 1 | E29: vb | F29: 10 | G29: R$ / AC | H29: Média | I29: =+F29*'Dados Gerais'!$E$15 -> 145163.8
A30: Instalações Sanitárias | D30: 1 | E30: vb | F30: 15 | G30: R$ / AC | H30: Média | I30: =+F30*'Dados Gerais'!$E$15 -> 217745.7
A31: Cisterna | D31: 1 | E31: vb | F31: 0.37 | G31: R$ / AC | H31: Média | I31: =+F31*'Dados Gerais'!$E$15 -> 5371.0606
A32: Sistema de bombas | D32: 1 | E32: vb | F32: 2.2 | G32: R$ / AC | H32: Média | I32: =+F32*'Dados Gerais'!$E$15 -> 31936.036
A33: Louças e Metais | D33: 1 | E33: vb | F33: 45 | G33: R$ / AC | H33: Média | I33: =F33*'Dados Gerais'!E15 -> 653237.1
A34: Mão de Obra para Instalações Hidráulicas | D34: 1 | E34: vb | F34: 50 | G34: R$ / AC | H34: Média | I34: =+F34*'Dados Gerais'!$E$15 -> 725819
A35: TOTAL | I35: =SUM(I27:J34) -> 2359927.9
A38: INSTALAÇÕES PREVENTIVAS E GLP
A40: Descrição | D40: Quantidade | F40: Parâmetro | H40: Referência | I40: Valor total
A41: Instalações Preventivas | D41: 1 | E41: vb | F41: 25 | G41: R$ / AC | H41: Média | I41: =+F41*'Dados Gerais'!$E$15 -> 362909.5
A42: Instalações de SPDA | D42: 1 | E42: vb | F42: 10 | G42: R$ / AC | H42: Média | I42: =+F42*'Dados Gerais'!$E$15 -> 145163.8
A43: Instalações de GLP | D43: 1 | E43: vb | F43: 22 | G43: R$ / AC | H43: Média | I43: =+F43*'Dados Gerais'!$E$15 -> 319360.36
A44: TOTAL | I44: =SUM(I41:J43) -> 827433.66
A46: TOTAL | I46: =I44+I35+I22 -> 5636274.9 | J46: =I44+I37+I28 -> 1045179.4 | K46: =I46/'Dados Gerais'!E15 -> 388.27
J48: 5636274.9 | K48: 1045179.4

Sheet Sistemas especiais
A2: ORÇAMENTO PARAMÉTRICO INSTALAÇÕES
A7: Documento | B7: CTN_ART-RES Orçamento Paramétrico
A8: Cliente | B8: Neuhaus LTDA
A9: Obra | B9: Origem 3300
A10: Data | B10: 45462 | E10: Revisão | F10: R03 | G10: Status | H10: Finalizado | I10: Responsável | K10: Larissa/Bianca
A12: CLIMATIZAÇÃO, EXAUSTÃO MECÂNICA E PRESSURIZAÇÃO
A14: Descrição | D14: Quantidade | F14: Parâmetro | H14: Referência | I14: Valor total
A15: Infraestrutura para Instalação de Ar Condicionado | D15: 226 | E15: pç | F15: 1500 | G15: R$ / ponto | H15: Média | I15: =F15*D15 -> 339000
A16: Máquinas Ar Condicionado área comum | D16: 10 | E16: pç | F16: 6000 | G16: R$ / un | H16: Média | I16: =+D16*F16 -> 60000
A17: Churrasqueiras | D17: 46 | E17: un | F17: 4000 | G17: R$ / un | H17: Média | I17: =+D17*F17 -> 184000
A18: Ventokit | D18: 54 | E18: un | F18: 1000 | G18: R$ / un | H18: Média | I18: =+D18*F18 -> 54000
A19: TOTAL | I19: =SUM(I15:J18) -> 637000
A21: COMUNICAÇÃO
A23: Descrição | D23: Quantidade | F23: Parâmetro | H23: Referência | I23: Valor total
A24: CFTV | D24: 1 | E24: vb | F24: 5 | G24: R$ / AC | H24: Média | I24: =+F24*'Dados Gerais'!E15 -> 72581.9
A25: Interfone | D25: 1 | E25: vb | F25: 9 | G25: R$ / AC | H25: Média | I25: =+F25*'Dados Gerais'!E15 -> 130647.42
A26: TV e internet | D26: 1 | E26: vb | F26: 12 | G26: R$ / AC | H26: Média | I26: =+F26*'Dados Gerais'!E15 -> 174196.56
A27: TOTAL | I27: =SUM(I24:J26) -> 377425.88
A29: AUTOMAÇÃO
A31: Descrição | D31: Quantidade | F31: Parâmetro | H31: Referência | I31: Valor total
A32: Automação, telecomunicação e sistemas de segurança | D32: 1 | E32: vb | F32: 8 | G32: R$ / AC | H32: Média | I32: =F32*'Dados Gerais'!E15 -> 116131.04
A33: TOTAL | I33: =SUM(I32:J32) -> 116131.04
A35: OUTROS SISTEMAS ESPECIAIS
A37: Descrição | D37: Quantidade | F37: Parâmetro | H37: Referência | I37: Valor total
A38: Outros sistemas | D38: 1 | E38: vb | F38: 30 | G38: R$ / AC | H38: Média | I38: =+F38*'Dados Gerais'!E15 -> 435491.4
A39: TOTAL | I39: =SUM(I38:J38) -> 435491.4
A41: EQUIPAMENTOS
A43: Descrição | D43: Quantidade | F43: Parâmetro | H43: Referência | I43: Valor total
A44: Elevador social | D44: 2 | E44: un | F44: 20000 | G44: R$ / NP | H44: Média | I44: =D44*F44*'Dados Gerais'!E16 -> 1320000
A45: Elevador serviço | D45: 1 | E45: un | F45: 20000 | G45: R$ / NP | H45: Média | I45: =D45*F45*'Dados Gerais'!E16 -> 660000
A46: Equipamentos para Piscina | D46: 2 | E46: vb | F46: 120000 | G46: R$ | H46: Média | I46: =+D46*F46 -> 240000
A47: Equipamentos para Sauna | D47: 2 | E47: vb | F47: 20000 | G47: R$ | H47: Média | I47: =+D47*F47 -> 40000
A48: Equipamentos para SPA | D48: 1 | E48: vb | F48: 35000 | G48: R$ | H48: Média | I48: =+D48*F48 -> 35000
A49: Grupo de geradores | D49: 1 | E49: un | F49: 120000 | G49: R$ | H49: Média | I49: =+D49*F49 -> 120000
A50: Infra para carro elétrico | D50: 43 | E50: und | F50: 800 | G50: R$ / und | H50: Média | I50: =F50*D50 -> 34400
A51: TOTAL | I51: =SUM(I44:J50) -> 2449400
A53: TOTAL | I53: =I51+I39+I33+I19+I27 -> 4015448.3 | J53: =I51+I44+I35 -> 3769400 | K53: =I53/'Dados Gerais'!E15 -> 276.61499 | L53: OK

Sheet Impermeabilização
A2: ORÇAMENTO PARAMÉTRICO IMPERMEABILIZAÇÃO
A7: Documento | B7: CTN_ART-RES Orçamento Paramétrico
A8: Cliente | B8: Neuhaus LTDA
A9: Obra | B9: Origem 3300
A10: Data | B10: 45462 | E10: Revisão | F10: R03 | G10: Status | H10: Finalizado | I10: Responsável | J10: Larissa/Bianca
A12: IMPERMEABILIZAÇÃO
A14: Descrição | D14: Quantidade | F14: Parâmetro | H14: Referência | I14: Valor total
A15: Regularização de Superfície | D15: 1 | E15: vb | F15: 9 | G15: R$ / AC | H15: Média | I15: =+F15*'Dados Gerais'!E15 -> 130647.42
A16: Poço do elevador | D16: 30 | E16: m² | F16: 30 | G16: R$ / m² | H16: Média | I16: =+F16*D16 -> 900
A17: Baldrame | D17: =0.7*Infraestrutura!D29 -> 688.6208 | E17: m² | F17: 35 | G17: R$ / m² | H17: Média | I17: =+F17*D17 -> 24101.728
A18: Ralos | D18: 1 | E18: vb | F18: 2.2 | G18: R$ / AC | H18: Média | I18: =+F18*'Dados Gerais'!$E$15 -> 31936.036
A19: Impermeabilizações cimenticias | D19: 1 | E19: vb | F19: 13 | G19: R$ / AC | H19: Média | I19: =+F19*'Dados Gerais'!E15 -> 188712.94
A20: Impermeabilizações com manta asfaltica | D20: 1 | E20: vb | F20: 40 | G20: R$ / AC | H20: Média | I20: =+F20*'Dados Gerais'!E15 -> 580655.2
A21: Impermeabilização de peitoril | D21: 1 | E21: vb | F21: 0.75 | G21: R$ / AC | H21: Média | I21: =+F21*'Dados Gerais'!$E$15 -> 10887.285
A22: Proteção Mecânica | D22: =+D20 -> 1 | E22: vb | F22: 12 | G22: R$ / AC | H22: Média | I22: =+F22*'Dados Gerais'!E15 -> 174196.56
A23: TOTAL | I23: =SUM(I15:J22) -> 1142037.2
A25: TOTAL | I25: =I23 -> 1142037.2 | J25: =I23+I16+I7 -> 1142937.2 | K25: =I25/'Dados Gerais'!E15 -> 78.672311

Sheet Rev. Internos Piso e Parede
A2: ORÇAMENTO PARAMÉTRICO REVESTIMENTOS INTERNOS EM PISO E PAREDE
A7: Documento | B7: CTN_ART-RES Orçamento Paramétrico
A8: Cliente | B8: Neuhaus LTDA
A9: Obra | B9: Origem 3300
A10: Data | B10: 45462 | E10: Revisão | F10: R03 | G10: Status | H10: Finalizado | I10: Responsável | J10: Larissa/Bianca
A12: REVESTIMENTOS INTERNOS EM PISO E PAREDE
A14: Descrição | D14: Quantidade | F14: Parâmetro | H14: Referência | I14: Valor total
A15: Contrapiso | D15: 12921.47 | E15: m² | F15: 40 | G15: R$ / m² | H15: Média | I15: =F15*D15 -> 516858.8
A16: Manta acústica torre | D16: 6369.4 | E16: m² | F16: 15 | G16: R$ / m² | H16: Média | I16: =+F16*D16 -> 95541
A17: Manta acústica lazer | D17: 955.094 | E17: m² | F17: 24 | G17: R$ / m² | H17: Média | I17: =+F17*D17 -> 22922.256
A18: Chapisco | D18: =24141.89*0.47 -> 11346.688 | E18: m² | F18: 2.5 | G18: R$ / m² | H18: Média | I18: =F18*D18 -> 28366.721
A19: Reboco | D19: =D18 -> 11346.688 | E19: m² | F19: 23 | G19: m² / AC | H19: Média | I19: =D19*F19 -> 260973.83 | N19: 41528.14
A20: Estucamento | D20: 1 | E20: vb | F20: 1.3 | G20: R$ / AC | H20: Média | I20: =+F20*'Dados Gerais'!$E$15 -> 18871.294 | N20: =N19/43 -> 965.7707
A21: MO Contrapiso | D21: =D15 -> 12921.47 | E21: m² | F21: 45 | G21: R$ / m² | H21: Média | I21: =F21*D21 -> 581466.15
A22: MO Reboco | D22: =D19 -> 11346.688 | E22: m² | F22: 38 | G22: R$ / m² | H22: Média | I22: =35*D22 -> 397134.09
A23: TOTAL | I23: =SUM(I15:J22) -> 1922134.1
A25: TOTAL | I25: =I23 -> 1922134.1 | J25: =I23+I16+I7 -> 2017675.1 | K25: =I25/'Dados Gerais'!E15 -> 132.4114 | L25: =J25/'Dados Gerais'!E15 -> 138.993

Sheet Acabamentos de Piso e Parede
A2: ORÇAMENTO PARAMÉTRICO ACABAMENTOS EM PISO E PAREDE
A7: Documento | B7: CTN_ART-RES Orçamento Paramétrico
A8: Cliente | B8: Neuhaus LTDA
A9: Obra | B9: Origem 3300
A10: Data | B10: 45462 | E10: Revisão | F10: R03 | G10: Status | H10: Finalizado | I10: Responsável | J10: Larissa/Bianca
A12: ACABAMENTOS EM PISO E PAREDE
A14: Descrição | D14: Quantidade | F14: Parâmetro | H14: Referência | I14: Valor total
A15: Piso porcelanato | D15: 5420.434 | E15: m² | F15: 125 | G15: R$ / m² | H15: Média | I15: =+F15*D15 -> 677554.25
A16: Piso Vinílico - MAT E MDO | D16: 2617.77 | E16: m² | F16: 260 | G16: R$ / m² | H16: Média | I16: =+F16*D16 -> 680620.2
A17: Piso emborrachado | D17: 23.47 | E17: m² | F17: 250 | G17: R$ / m² | H17: Média | I17: =D17*F17 -> 5867.5
A18: Pastilha piscinas | D18: 113 | E18: m² | F18: 145 | G18: R$ / m² | H18: Média | I18: =F18*D18 -> 16385
A19: Piso concreto estampado | D19: 391 | E19: m² | F19: 120 | G19: R$ / m² | H19: Média | I19: =+F19*D19 -> 46920
A20: Piso deck | D20: 91.15 | E20: m² | F20: 500 | G20: RS / m² | H20: Média | I20: =+F20*D20 -> 45575
A21: Rodapés | D21: =682.601/0.1 -> 6826.01 | E21: m | F21: 60 | G21: R$ / m | H21: Média | I21: =+F21*D21 -> 409560.6
A22: Revestimentos de Parede 30x60 | D22: 4715.83 | E22: m² | F22: 90 | G22: R$ / AC | H22: Média | I22: =+F22*D22 -> 424424.7
A23: Soleiras e peitoris | D23: 1 | E23: vb | F23: 12 | G23: R$ / AC | H23: Média | I23: =+F23*'Dados Gerais'!$E$15 -> 174196.56
A24: MO Azulejo | D24: =D22 -> 4715.83 | E24: m² | F24: 45 | G24: R$ / m² | H24: Média | I24: =F24*D24 -> 212212.35
A25: MO Porcelanato | D25: =D15 -> 5420.434 | E25: m² | F25: 40 | G25: R$ / m² | H25: Média | I25: =F25*D25 -> 216817.36
A26: MO Pastilhas | D26: =D18 -> 113 | E26: m² | F26: 45 | G26: R$ / m² | H26: Média | I26: =F26*D26 -> 5085
A27: TOTAL | I27: =SUM(I15:J26) -> 2915218.5
A29: TOTAL | I29: =I27 -> 2915218.5 | J29: =I27+I20+I11 -> 2960793.5 | K29: =I29/'Dados Gerais'!E15 -> 200.82269 | L29: =J29/'Dados Gerais'!E15 -> 203.96225

Sheet Acabamentos de Teto
A2: ORÇAMENTO PARAMÉTRICO REVESTIMENTOS E ACABAMENTOS INTERNOS EM TETO
A7: Documento | B7: CTN_ART-RES Orçamento Paramétrico
A8: Cliente | B8: Neuhaus LTDA
A9: Obra | B9: Origem 3300
A10: Data | B10: 45462 | E10: Revisão | F10: R03 | G10: Status | H10: Finalizado | I10: Responsável | J10: Larissa/Bianca
A12: ACABAMENTOS DE TETO
A14: Descrição | D14: Quantidade | F14: Parâmetro | H14: Referência | I14: Valor total
A15: Forro de Gesso | D15: 6546.19 | E15: m² | F15: 85 | G15: R$ / m² | H15: Média | I15: =+D15*F15 -> 556426.15
A16: Forro vinílico - sacadas | D16: 662.45 | E16: m² | F16: 450 | G16: RS / m² | H16: Média | I16: =+D16*F16 -> 298102.5
A17: Forro ACM - saunas | D17: 13.85 | E17: m² | F17: 300 | G17: RS / m² | H17: Média | I17: =+D17*F17 -> 4155
A18: Negativo | D18: 8065.83 | E18: m | F18: 25 | G18: R$ / m | H18: Média | I18: =+D18*F18 -> 201645.75
A19: Cortineiro | D19: =+F19*'Dados Gerais'!$E$15 -> 1451.638 | E19: m² | F19: 0.1 | G19: m / AC | H19: Média | I19: =D19*30 -> 43549.14
A20: Estucamento | D20: 5078.61 | E20: m² | F20: 33 | G20: R$ / m² | H20: Média | I20: =F20*D20 -> 167594.13
A21: TOTAL | I21: =SUM(I15:J20) -> 1271472.7
A23: TOTAL | I23: =I21 -> 1271472.7 | J23: =I21+I14+I5 -> #VALUE! | K23: =I23/'Dados Gerais'!E15 -> 87.588825

Sheet Pintura Interna
A2: ORÇAMENTO PARAMÉTRICO PINTURA INTERNA
A7: Documento | B7: CTN_ART-RES Orçamento Paramétrico
A8: Cliente | B8: Neuhaus LTDA
A9: Obra | B9: Origem 3300
A10: Data | B10: 45462 | E10: Revisão | F10: R03 | G10: Status | H10: Finalizado | I10: Responsável | J10: Larissa/Bianca
A12: PINTURA INTERNA
A14: Descrição | D14: Quantidade | F14: Parâmetro | H14: Referência | I14: Valor total
A15: Pintura piso epoxi | D15: 2141.16 | E15: m2 | F15: 160 | G15: R$ / m² | H15: Média | I15: =+D15*F15 -> 342585.6
A16: Pintura acrílica escadaria | D16: 3735.02 | E16: m2 | F16: 65 | G16: R$ / m² | H16: Média | I16: =+D16*F16 -> 242776.3
A17: Pintura acrílica paredes | D17: 20946.87 | E17: m2 | F17: =35+20 -> 55 | G17: R$ / m² | H17: Média | I17: =+D17*F17 -> 1152077.8
A18: Textura acrílica paredes | D18: 3735.02 | E18: m2 | F18: =35+12 -> 47 | G18: R$ / m² | H18: Média | I18: =+D18*F18 -> 175545.94
A19: TOTAL | I19: =SUM(I15:J18) -> 1912985.7
A21: TOTAL | I21: =I19 -> 1912985.7 | J21: =I19+I12+I3 -> 1912985.7 | K21: =I21/'Dados Gerais'!E15 -> 131.78118

Sheet Esquadrias
A2: ORÇAMENTO PARAMÉTRICO ESQUADRIAS
A7: Documento | B7: CTN_ART-RES Orçamento Paramétrico
A8: Cliente | B8: Neuhaus LTDA
A9: Obra | B9: Origem 3300
A10: Data | B10: 45462 | E10: Revisão | F10: R03 | G10: Status | H10: Finalizado | I10: Responsável | J10: Larissa/Bianca
A12: ESQUADRIAS
A14: Descrição | D14: Quantidade | F14: Parâmetro | H14: Referência | I14: Valor total
A15: Esquadrias de Alumínio | D15: 1070.93 | E15: m² | F15: 1650 | G15: R$ / m² | H15: Média | I15: =+F15*D15 -> 1767034.5
A16: Esquadrias de vidro | D16: 389.85 | E16: m² | F16: 1000 | G16: R / m² | H16: Média | I16: =+F16*D16 -> 389850
A17: Guarda corpo de alumínio | D17: 720.1 | E17: m² | F17: 2100 | G17: R$ / m² | H17: Média | I17: =+D17*F17 -> 1512210
A18: Brise vertical | D18: 210.62 | E18: m² | F18: 2000 | G18: R$ / m² | H18: Média | I18: =+D18*F18 -> 421240
A19: Serralherias | D19: 1 | E19: vb | F19: 200000 | G19: R$ | H19: Média | I19: =+D19*F19 -> 200000
A20: PCF | D20: 72 | E20: un | F20: 1750 | G20: R$ / un | H20: Média | I20: =+D20*F20 -> 126000
A21: Corrimão | D21: 525.64 | E21: m | F21: 150 | G21: R$ / m | H21: Média | I21: =+D21*F21 -> 78846
A22: Esquadrias Internas de Madeira | D22: 309 | E22: vb | F22: 3000 | G22: R$ / un | H22: Média | I22: =+F22*D22 -> 927000
A23: Fechadura eletrônica | D23: 43 | E23: vb | F23: 2500 | G23: R$ / un | H23: Média | I23: =+F23*D23 -> 107500
A24: Portão de alumínio | D24: 1 | E24: un | F24: 30000 | G24: R$ / un | H24: Média | I24: =+F24*D24 -> 30000
A25: TOTAL | I25: =SUM(I15:J24) -> 5559680.5
A28: TOTAL | I28: =I25 -> 5559680.5 | J28: =I26+I19+I10 -> #VALUE! | K28: =I28/'Dados Gerais'!E15 -> 382.99359

Sheet Rev. Fachada
A2: ORÇAMENTO PARAMÉTRICO REVESTIMENTOS E ACABAMENTOS DE FACHADA
A7: Documento | B7: CTN_ART-RES Orçamento Paramétrico
A8: Cliente | B8: Neuhaus LTDA
A9: Obra | B9: Origem 3300
A10: Data | B10: 45462 | E10: Revisão | F10: R03 | G10: Status | H10: Finalizado | I10: Responsável | J10: Larissa/Bianca
A12: REVESTIMENTOS ARGAMASSADOS
A14: Descrição | D14: Quantidade | F14: Parâmetro | H14: Referência | I14: Valor total
A15: Chapisco e Reboco | D15: 8673.01 | E15: m² | F15: 30 | G15: R$/m² | H15: Média | I15: =+D15*F15 -> 260190.3
A16: Mão de obra | D16: =D15 -> 8673.01 | E16: m² | F16: 70 | G16: R$/m² | H16: Média | I16: =+D16*F16 -> 607110.7
A17: TOTAL | I17: =SUM(I15:J16) -> 867301
O19: =P22*O21 -> 2682.49
A20: PINTURA
L21: =I23*M21 -> 780570.9 | M21: 0.6 | O21: 1 | P21: 10198.14
A22: Descrição | D22: Quantidade | F22: Parâmetro | H22: Referência | I22: Valor total | L22: =I23*M22 -> 520380.6 | M22: 0.4 | P22: 2682.49
A23: Textura STO / Pintura | D23: 8673.01 | E23: m² | F23: 150 | G23: R$ / m² | H23: Média | I23: =F23*D23 -> 1300951.5 | L23: projetada na cor preta | P23: =P22/P21 -> 0.26303718
A24: TOTAL | I24: =SUM(I23:J23) -> 1300951.5
A26: REVESTIMENTOS ESPECIAIS
A28: Descrição | D28: Quantidade | F28: Parâmetro | H28: Referência | I28: Valor total
A29: Detalhes | D29: 1 | E29: vb | F29: 100000 | G29: vb | H29: Média | I29: =+F29 -> 100000
A30: Tijolinho | D30: 514.04 | E30: m² | F30: 220 | G30: vb | H30: Média | I30: =+F30*D30 -> 113088.8
A31: Pele de vidro | D31: 290.99 | E31: m² | F31: 1000 | G31: R$ / m² | H31: Média | I31: =+D31*F31 -> 290990
I32: =SUM(I29:J31) -> 504078.8
A34: TOTAL | I34: =I32+I24+I17 -> 2672331.3 | J34: =I32+I25+I16 -> 1111189.5 | K34: =I34/'Dados Gerais'!E15 -> 184.09075

Sheet Complementares
A2: ORÇAMENTO PARAMÉTRICO EQUIPAMENTOS
A7: Documento | B7: CTN_ART-RES Orçamento Paramétrico
A8: Cliente | B8: Neuhaus LTDA
A9: Obra | B9: Origem 3300
A10: Data | B10: 45462 | E10: Revisão | F10: R03 | G10: Status | H10: Finalizado | I10: Responsável | K10: Larissa/Bianca
A12: SERVIÇOS COMPLEMENTARES | M12: =M14-M13 -> 319.71
M13: 229.44
A14: Descrição | D14: Quantidade | F14: Parâmetro | H14: Referência | I14: Valor total | M14: 549.15 | O14: 252.6
A15: Móveis e decoração | D15: 1 | E15: vb | F15: 2400 | G15: R$ / AL | H15: Média | I15: =D15*F15*'Dados Gerais'!$E$22 -> 3081600 | M15: 320000 | N15: BOTANICO | O15: 340701.44 | P15: ZAHA
A16: Comunicação visual | D16: 1 | E16: vb | F16: 10 | G16: R$ / AC | H16: Média | I16: =D16*F16*'Dados Gerais'!$E$15 -> 145163.8 | M16: =M15/M12 -> 1000.9071 | O16: =O15/O14 -> 1348.7785
A17: Paisagismo | D17: 1 | E17: vb | F17: 65 | G17: R$ / AC | H17: Média | I17: 580655.2 | M17: 117000 | N17: BOTANICO | O17: 4955.66 | P17: ZAHA
A18: Limpeza | D18: 1 | E18: vb | F18: 15 | G18: R$ / AC | H18: Média | I18: =D18*F18*'Dados Gerais'!$E$15 -> 217745.7 | M18: 3123.4
A19: Desmobilização | D19: 1 | E19: vb | F19: 5 | G19: R$ / AC | H19: Média | I19: =D19*F19*'[4]Dados Gerais'!$E$15 -> 470446.55 | M19: =M17/M18 -> 37.459179
A20: Ligações definitivas | D20: 1 | E20: vb | F20: 15 | G20: R$ / AC | H20: Média | I20: =D20*F20*'Dados Gerais'!E15 -> 217745.7
A21: TOTAL | I21: =SUM(I15:J20) -> 4713357
A23: TOTAL | I23: =I21+I13+I6 -> 4713357 | J23: =I21+I14+I5 -> #VALUE! | K23: =I23/'Dados Gerais'!E15 -> 324.69231
