Workbook
Name \0: #REF!
Name \a: #REF!
Name \m: #REF!
Name aa: #REF!
Name aaaa: [1]M.O.!#REF!
Name angelo: [2]Geral!#REF!
Name aux: #REF!
Name BDA: #REF!
Name BDI: #REF!
Name ca: #REF!
Name Capa: #REF!
Name cronograma: #REF!
Name D: #REF!
Name direto: #REF!
Name DRE: #REF!
Name ea: #REF!
Name FFFFFFF: #REF!
Name item_1: #REF!
Name LS: [1]M.O.!#REF!
Name MENU: #REF!
Name MENU1: #REF!
Name MENU2: #REF!
Name MENU3: #REF!
Name MENU4: #REF!
Name MENU5: #REF!
Name MENU6: #REF!
Name mo: #REF!
Name OAE: #REF!
Name PAV: #REF!
Name pr: #REF!
Name PRE: #REF!
Name Print_Area_MI: #REF!
Name qe: #REF!
Name qee: #REF!
Name reforsu: #REF!
Name ren: #REF!
Name REV: #REF!
Name sa: #REF!
Name SEG: #REF!
Name SIH: #REF!
Name SIV: #REF!
Name ss: #REF!
Name susref: #REF!
Name tania: #REF!
Name tc: #REF!
Name TOT: #REF!
Name Total: #REF!
Name TRP: #REF!
Name xxxx: #REF!

Sheet CUSTOS INDIRETOS
A1: ORÇAMENTO PARAMÉTRICO - CUSTOS INDIRETOS
A7: Cliente | B7: =[3]OBRA!B2 -> Neuhaus
A8: Obra | B8: =[3]OBRA!B1 -> Origem 3300
A9: Data | B9: 45462
A10: Versão | B10: R03
A12: GERENCIAMENTO TÉCNICO
A13: Código | B13: Descrição | C13: Un. | D13: Quantidade orçada | E13: Preço unitário | F13: Preço total | G13: observação
A14: 01 | B14: GERENCIAMENTO TÉCNICO | F14: =SUM(F20+F15) -> 1276327.1
A15: 01.001 | B15: ESTUDOS, PROJETOS E CONSULTORIAS | F15: =SUM(F16:F19) -> 584595.64
A16: 01.001.001 | B16: Estudos | F16: 28641.924
A17: 01.001.002 | B17: Projetos | F17: 466942.45
A18: 01.001.003 | B18: Consultorias | F18: 63138.444
A19: 01.001.004 | B19: Ensaios e Laudos | F19: 25872.825
A20: 01.002 | B20: TAXAS E DOCUMENTOS | F20: =SUM(F21:F23) -> 691731.43
A21: 01.002.001 | B21: Seguros | F21: 94382.854
A22: 01.002.002 | B22: Licenciamentos, Taxas, Impostos | F22: 529878.77
A23: 01.002.003 | B23: Documentos | F23: 67469.811
A24: 02 | B24: GERENCIAMENTO ADMINISTRATIVO | F24: =SUM(F25+F38+F61) -> 6238585.7
A25: 02.001 | B25: SEGURANÇA, MEIO AMBIENTE E SAÚDE | F25: =SUM(F26+F28+F37) -> 1052775.2
A26: 02.001.001 | B26: Segurança do Trabalho | F26: 168000
A27: 02.001.001.001 | B27: Serviço de segurança do trabalho terceirizado | C27: mes | D27: 48 | E27: 3500 | F27: 168000
A28: 02.001.002 | B28: Equipamentos de proteção | F28: 795976.47
A29: 02.001.002.001 | B29: Bandeja de proteção primária | C29: m | D29: 301.68 | E29: 350 | F29: 105588
A30: 02.001.002.002 | B30: Bandeja de proteção secundária | C30: m | D30: 779.67 | E30: 300 | F30: 233901
A31: 02.001.002.003 | B31: Guarda corpo em laje pós - desforma | C31: m | D31: 754.2 | E31: 49 | F31: 36955.8
A32: 02.001.002.004 | B32: Fechamento removível de vãos de porta de elevador em madeira | C32: m2 | D32: 638.55 | E32: 50 | F32: 31927.5
A33: 02.001.002.005 | B33: Varal de segurança com cabo de aço (linha de vida) | C33: m | D33: 754.2 | E33: 244 | F33: 184024.8
A34: 02.001.002.006 | B34: Sinalização com placa indicativa fixada na estrutura | C34: vb | D34: 1 | E34: 15968.018 | F34: 15968.018
A35: 02.001.002.007 | B35: Tela fachadeira reforçada com impressão digital | C35: m2 | D35: 9974.09 | E35: 15 | F35: 149611.35
A36: 02.001.002.008 | B36: Equipamentos de proteção individual | C36: vb | D36: 1 | E36: 38000 | F36: 38000
A37: 02.001.003 | B37: Meio Ambiente | F37: 88798.778
A38: 02.002 | B38: ADMINISTRAÇÃO E CANTEIRO DE OBRA | F38: =SUM(F39+F49+F60+F52) -> 3331912.5
A39: 02.002.001 | B39: Equipe de Gestão e Apoio | F39: =SUM(F40:F48) -> 2461893.1 | G39: falta adicionar o tecnico de segurança
A40: 02.002.001.001 | B40: Engenheiro civil | C40: mes | D40: 48 | E40: 12000 | F40: 576000
A41: 02.002.001.002 | B41: Almoxarife | C41: mes | D41: 48 | E41: 4254.448 | F41: 204213.5
A42: 02.002.001.003 | B42: Mestre de obras | C42: mes | D42: 48 | E42: 8369.792 | F42: 401750.02
A43: 02.002.001.004 | B43: Estagiário | C43: mes | D43: 48 | E43: 3000 | F43: 144000
A44: 02.002.001.005 | B44: Serviço de vigilância 24h | C44: mes | D44: 48 | E44: 5086.84 | F44: 244168.32 | G44: será contratado uma pessoa, ou somente empresa de vigilãncia?
A45: 02.002.001.006 | B45: Operador de grua | C45: mes | D45: 22 | E45: 7800 | F45: 171600
A46: 02.002.001.007 | B46: Servente para segurança | C46: mes | D46: 48 | E46: 3812.48 | F46: 182999.04
...

Sheet ORÇAMENTO RESUMO
A1: CÓDIGO | B1: ITEM | C1: Quantidade | D1: Unidade | E1: Valor Orçado | F1: Considerações
A2: 1 | B2: GERENCIAMENTO TÉCNICO E ADMINISTRATIVO | E2: ='CUSTOS INDIRETOS'!F81 -> 7514912.8 | F2: =E2/$E$187 -> 0.11527965
A3: 1.1 | B3: GERENCIAMENTO TÉCNICO E ADMINISTRATIVO | E3: =E2 -> 7514912.8
A4: 1.1.1 | B4: Gerenciamento técnico e administrativo | C4: 1 | D4: vb | E4: =E3 -> 7514912.8
A5: 2 | B5: MOVIMENTAÇÃO DE TERRA | E5: =E6 -> 334397.12 | F5: =E5/$E$187 -> 0.0051296913
A6: 2.1 | B6: MOVIMENTAÇÃO DE TERRA | E6: =SUM(E7:E12) -> 334397.12
A7: 2.1.1 | B7: Rebaixamento de lençol freático | C7: 10 | D7: dias | E7: ='[4]Movimentação de Terra'!$I$22 -> 5500
A8: 2.1.2 | B8: Escavação mecanizada para blocos e baldrames | C8: 512.02 | D8: m3 | E8: ='[4]Movimentação de Terra'!$I$29 -> 134618
A9: 2.1.3 | B9: Reaterro para blocos e baldrames | C9: 118.16 | D9: m3 | E9: ='[4]Movimentação de Terra'!$I$30 -> 13592
A10: 2.1.4 | B10: Movimentação de terra (30% de empolamento) | C10: 3014.01 | D10: m3 | E10: ='[4]Movimentação de Terra'!$I$31 -> 131906.25
A11: 2.1.5 | B11: Bota-fora da escavação | C11: 640.03 | D11: m3 | E11: ='[4]Movimentação de Terra'!$I$32 -> 19200.87
A12: 2.1.6 | B12: Lastro de concreto magro e= 10cm - Blocos | C12: 1035.52 | D12: m2 | E12: ='[4]Movimentação de Terra'!$I$39 -> 29580
A13: 3 | B13: INFRAESTRUTURA | E13: =E14+E20 -> 2808959.2 | F13: =E13/$E$187 -> 0.043089765
A14: 3.1 | B14: FUNDAÇÃO PROFUNDA | E14: =SUM(E15:E19) -> 1874063.4
A15: 3.1.1 | B15: Estaca hélice contínua diâmetro 50cm | C15: 608 | D15: m | E15: =[4]Infraestrutura!$I$17 -> 66880 | F15: 19 estacas com 32 metros de profundidade
A16: 3.1.2 | B16: Estaca hélice contínua diâmetro 60cm | C16: 4371 | D16: m | E16: =[4]Infraestrutura!$I$19 -> 502986.42 | F16: 141 estacas com 32 metros de profundidade
A17: 3.1.3 | B17: Armação | C17: 20729 | D17: kg | E17: =[4]Infraestrutura!$I$20 -> 176197 | F17: Consideração de R$ 8,50/kg
A18: 3.1.4 | B18: Concreto | C18: 1675 | D18: m3 | E18: =[4]Infraestrutura!$I$21 -> 1072000 | F18: Consideração de R$ 640,00/m³ com 10% de perda
A19: 3.1.5 | B19: Arrasamento de estacas | C19: 160 | D19: und | E19: =[4]Infraestrutura!$I$22 -> 56000
A20: 3.2 | B20: FUNDAÇÃO RASA | E20: =SUM(E21:E24) -> 934895.74
A21: 3.2.1 | B21: Fabricação, montagem e desmontagem de forma para blocos e baldrames | C21: 983.74 | D21: m² | E21: =[4]Infraestrutura!$I$29 -> 41809.12
A22: 3.2.2 | B22: Armação | C22: 39386.4 | D22: kg | E22: =[4]Infraestrutura!$I$30 -> 334784.4 | F22: Consideração de R$ 8,50/kg
A23: 3.2.3 | B23: Concreto | C23: 492.33 | D23: m³ | E23: =[4]Infraestrutura!$I$31 -> 196439.67 | F23: Consideração de R$ 640,00/m³ com 5% de perda
A24: 3.2.5 | B24: Mão de obra infraestrutura | C24: 984.66 | D24: vb | E24: =[4]Infraestrutura!$I$32 -> 361862.55 | F24: Consideração de área do térreo
A25: 5 | B25: SUPRAESTRUTURA | E25: =E26+E30+E33+E36+E38 -> 18837581 | F25: =E25/$E$187 -> 0.28897072
A26: 5.1 | B26: FORMA | E26: =E27+E28+E29 -> 5572992.1
A27: 5.1.1 | B27: Fabricação forma | C27: 14500 | D27: m² | E27: {=[5]Supraestrutura!$I$15:$J$15} -> 4970913.8 | F27: #REF! | G27: 158 reais o m2 da forma esta de acordo, porem se usarmos a metragem total de area do empreendimento já da um valor grande pois não estamos levando em conta as repetições . consideraria 5000 m2 de forma para o embasamento, pois 2 jogos fazer toda o embasamento. E para a torre 3 mil m2 de forma, por serão 3 jogos de formas com 2 jogos, levando em consideração 500m2 de area de laje. | H27: 1264000
A28: 5.1.2 | B28: Montagem de forma | C28: 36290.95 | D28: m² | E28: {=[5]Supraestrutura!$I$16:$J$16} -> 489927.82 | F28: #REF! | G28: mover verba para m.o. de supraestrutura | H28: excluir
A29: 5.1.3 | B29: Protensão | C29: 9117.92 | D29: m² | E29: =[5]Supraestrutura!$I$19 -> 112150.42 | F29: Consideração todas as lajes da torre | G29: desconsiderar este item.... Já incluso no fabricaçao de forma | H29: excluir
A30: 5.2 | B30: ESCORAMENTO | E30: =E31+E32 -> 638866.85
A31: 5.2.1 | B31: Escoramento - Torre | C31: 9117.92 | D31: m² | E31: =[4]Supraestrutura!$I$17 -> 322383.6 | F31: rever quantidade | G31: considerar 21 reais o m2
A32: 5.2.2 | B32: Escoramento - Embasamento | C32: 5188.25 | D32: m² | E32: =[4]Supraestrutura!$I$18 -> 316483.25 | F32: rever quantidade | G32: considerar 48 reais o m2 | J32: 3822.31
A33: 5.3 | B33: ARMADURA | E33: =E34+E35 -> 5113896.4 | J33: 484
A34: 5.3.1 | B34: Armadura Convencional para Estrutura | C34: 550544 | D34: kg | E34: =[5]Supraestrutura!$I$23 -> 4679624 | F34: Consideração de R$ 9,00/kg | G34: considerar 7,20 o kg do aço com arame e espaçadores | J34: =J33/J32 -> 0.126625
A35: 5.3.2 | B35: Cabos para protensão | C35: =25941.8+9364.9 -> 35306.7 | D35: kg | E35: =[6]Supraestrutura!$I$20+[6]Supraestrutura!$I$22 -> 434272.41 | F35: Consideração de 1,83 kg/m² de laje e 12,30/kg | G35: ok, verificaer somente quantidade | J35: =J32/J33 -> 7.8973347
A36: 5.4 | B36: CONCRETO | E36: =E37 -> 3748686.5
A37: 5.4.1 | B37: Concreto | C37: 5409.36 | D37: m³ | E37: =[5]Supraestrutura!$I$24 -> 3748686.5 | F37: Consideração de R$ 640,00/m³ com 5% de perda | G37: ok
A38: 5.5 | B38: MÃO DE OBRA | E38: =E39+E40 -> 3763139
A39: 5.5.1 | B39: Mão de obra supraestrutura | C39: 14516.38 | D39: m² | E39: =[6]Supraestrutura!$I$25 -> 3511139 | F39: Valor estimado com base na área construída | G39: ok
A40: 5.5.2 | B40: Serviços de protensão | C40: 28 | D40: und | E40: =[4]Supraestrutura!$I$21 -> 252000 | F40: Valor estimado por laje da torre | G40: ok
...
