Workbook

Sheet Dados Gerais
A2: ORÇAMENTO PARAMÉTRICO GERENCIAMENTO EXECUTIVO
A7: Documento | B7: CTN-BRS-139 - Gerenciamento executivo_R00
A8: Cliente | B8: Brasin
A9: Obra | B9: 139
A10: Data | B10: 45006 | E10: Revisão | F10: R00 | G10: Status | H10: Em andamento | I10: Responsável
A12: Descrição | D12: Identificador | E12: Informação
A13: Área do terreno | D13: AT | E13: 774.6 | H13: m²
A14: Testada do terreno | D14: TT | H14: m
A15: Área total construída | D15: AC | E15: 16727.83 | H15: m²
A16: N° total de pavimentos | D16: NP | E16: 43 | H16: un
A17: N° de pavimentos tipo | D17: NPT | E17: 32 | H17: un
A18: N° de pavimentos tipo diferenciado | D18: NPD | E18: 1 | H18: un
A19: N° de pavimentos duplex | D19: ND | E19: 1 | H19: un | K19: unidades | L19: 40
A20: Área de projeção da torre | D20: APT | E20: 383.13 | H20: m²
A21: Perímetro de projeção da torre | D21: PPT | E21: 88.89 | H21: m | K21: 50 meses
A22: Área Lazer | D22: AL | E22: =871.23+285.53 -> 1156.76 | H22: m² | K22: 12 | L22: fundação | M22: pode reduzir pra 10
A23: Locação da obra | D23: LC | E23: 130.3026 | H23: m | K23: 26 | L23: estrutura | M23: complexa
A24: Área do embasamento | D24: AE | E24: =764.54+783.23+805.3*3+818.66+871.23 -> 5653.56 | H24: m² | K24: 1 | L24: grua
A25: Área de subsolos | D25: AS | E25: 0 | H25: m² | K25: 12 | L25: acabamentos
A26: N° de subsolos | D26: NS | E26: 0 | H26: un | K26: =SUM(K22:K25) -> 51
A27: Área de projeção do embasamento | D27: APE | E27: 764.54 | H27: m²
A28: Perímetro de projeção embasamento | D28: PPE | E28: 130.3026 | H28: m
A29: N° de pavimentos de embasamento | D29: NPE | E29: 6 | H29: un

Sheet Resumo
A2: ORÇAMENTO PARAMÉTRICO GERENCIAMENTO EXECUTIVO
A7: Documento | B7: CTN_R21-HOL - Gerenciamento executivo_R00
A8: Cliente | B8: R21
A9: Obra | B9: Holmes Residence | E9: UC | F9: 01 | G9: Status | H9: Concluido
A10: Data | B10: 44938 | E10: Revisão | F10: R00 | G10: Resp. | H10: Kelen
A12: MOVIMENTAÇÃO DE TERRA
A14: Descrição | D14: Valor total
A15: =+'Movimentação de Terra'!A19 -> REBAIXAMENTO DE LENÇOL | D15: =+'Movimentação de Terra'!I23 -> 30581.6
A16: =+'Movimentação de Terra'!A33 -> ESCAVAÇÃO E REATERRO DE VALAS | D16: =+'Movimentação de Terra'!I39 -> 146651.81
A17: =+'Movimentação de Terra'!A42 -> REGULARIZAÇÃO E APILOAMENTO DE FUNDO DE VALAS | D17: =+'Movimentação de Terra'!I46 -> 3059
A18: =+'Movimentação de Terra'!A42 -> REGULARIZAÇÃO E APILOAMENTO DE FUNDO DE VALAS | D18: =+'Movimentação de Terra'!I46 -> 3059
A19: TOTAL | D19: =SUM(D15:H18) -> 183351.41
A23: INFRAESTRUTURA
A25: Descrição | D25: Valor total
A26: =+Infraestrutura!A12 -> FUNDAÇÃO PROFUNDA | D26: =+Infraestrutura!I31 -> 3139502.4
A27: =+Infraestrutura!A34 -> FUNDAÇÃO RASA | D27: =+Infraestrutura!I42 -> 897111.24
A28: TOTAL | D28: =SUM(D26:H27) -> 4036613.6
A31: SUPRAESTRUTURA
A33: Descrição | D33: Valor total
A34: =+Supraestrutura!A12 -> SUPRAESTRUTURA | D34: =+Supraestrutura!I27 -> 12902695
A35: TOTAL | D35: =SUM(D34:H34) -> 12902695
A38: ALVENARIA
A40: Descrição | D40: Valor total
A41: =+Alvenaria!A12 -> ALVENARIA | D41: =+Alvenaria!I24 -> 2845234.7
A42: TOTAL | D42: =SUM(D41) -> 2845234.7
A45: INSTALAÇÕES
A47: Descrição | D47: Valor total
A48: =+#REF! -> #REF! | D48: =+#REF! -> #REF!
A49: =+#REF! -> #REF! | D49: =+#REF! -> #REF!
A50: =+#REF! -> #REF! | D50: =+#REF! -> #REF!
A51: TOTAL | D51: =SUM(D48:H50) -> #REF!
A54: IMPERMEABILIZAÇÃO
A56: Descrição | D56: Valor total
A57: =+Impermeabilização!A12 -> IMPERMEABILIZAÇÃO | D57: =+Impermeabilização!I23 -> 1396052
A58: TOTAL | D58: =SUM(D57) -> 1396052
A61: REVESTIMENTOS INTERNOS EM PISO E PAREDE
A63: Descrição | D63: Valor total
A64: =+'Rev. Internos Piso e Parede'!A12 -> REVESTIMENTOS INTERNOS EM PISO E PAREDE | D64: =+'Rev. Internos Piso e Parede'!I21 -> 2856393.8
A65: TOTAL | D65: =SUM(D64) -> 2856393.8
A68: REVESTIMENTOS E ACABAMENTOS INTERNOS EM TETO
...

Sheet Movimentação de Terra
A2: ORÇAMENTO PARAMÉTRICO MOVIMENTAÇÃO DE TERRA
A7: Documento | B7: ='Dados Gerais'!B7 -> CTN-BRS-139 - Gerenciamento executivo_R00
A8: Cliente | B8: ='Dados Gerais'!B8 -> Brasin
A9: Obra | B9: ='Dados Gerais'!B9 -> 139 | G9: UC | H9: 00 | I9: Status | J9: Em andamento
A10: Data | B10: ='Dados Gerais'!B10 -> 45006 | G10: Revisão | H10: R00 | I10: Resp.
A12: ESCAVAÇÃO
A14: Descrição | D14: Quantidade | F14: Parâmetro | H14: Referência | I14: Valor total
A15: Escavação | D15: =+'Dados Gerais'!E25*3.06 -> 0 | E15: m³ | F15: 28.5 | G15: R$ / m³ | H15: Pedro Chaves | I15: =+D15*F15 -> 0
A16: TOTAL | I16: =SUM(I15:J15) -> 0
A19: REBAIXAMENTO DE LENÇOL
A21: Descrição | D21: Quantidade | F21: Parâmetro | H21: Referência | I21: Valor total
A22: Rebaixamento de Lençol | D22: 0 | E22: - | F22: 40 | G22: R$ / APE | H22: Média | I22: =F22*'Dados Gerais'!E27 -> 30581.6 | P22: 421.3 | Q22: M2
A23: TOTAL | I23: =SUM(I22:J22) -> 30581.6 | P23: 1180 | Q23: M3
P24: =P23/P22 -> 2.8008545
A26: DETONAÇÃO DE ROCHAS | M26: Terreno rochoso
A28: Descrição | D28: Quantidade | F28: Parâmetro | H28: Referência | I28: Valor total
A29: Detonação de rochas | D29: =F29*'Dados Gerais'!E27 -> 1911.35 | E29: m³ | F29: 2.5 | G29: m³ / APE | H29: Média | I29: =320*D29 -> 611632
A30: TOTAL | I30: =SUM(I29:J29) -> 611632
A33: ESCAVAÇÃO E REATERRO DE VALAS
M34: Detonação de rochas
A35: Descrição | D35: Quantidade | F35: Parâmetro | H35: Referência | I35: Valor total
A36: Escavação mecanizada para blocos e baldrames | D36: =F36*'Dados Gerais'!E27 -> 382.27 | E36: m³ | F36: 0.5 | G36: m³ / APE | H36: Média | I36: =+ROUNDUP((D36*70),0) -> 26759
A37: Reaterro para blocos e baldrames | D37: =F37*D36 -> 76.454 | E37: m³ | F37: 0.2 | G37: m³ / APE | H37: Média | I37: =+ROUNDUP((D37*25),0) -> 1912
A38: Movimentação de terra das estacas | D38: =+Infraestrutura!D30*F38+D36-D37 -> 1310.8979 | E38: m³ | F38: 1 | G38: m³ / m³ | H38: Média | I38: =+D38*90 -> 117980.81
A39: TOTAL | I39: =SUM(I36:J38) -> 146651.81
A42: REGULARIZAÇÃO E APILOAMENTO DE FUNDO DE VALAS
A44: Descrição | D44: Quantidade | F44: Parâmetro | H44: Referência | I44: Valor total
A45: Lastro de concreto magro e= 10cm - Blocos | D45: =F45*'Dados Gerais'!E27 -> 382.27 | E45: m² | F45: 0.5 | G45: m² / APE | H45: Média | I45: =ROUNDUP((D45*8),0) -> 3059
A46: TOTAL | I46: =SUM(I45:J45) -> 3059
A49: TOTAL MOVIMENTAÇÃO DE TERRA | I49: =I23+I30+I39+I46 -> 791924.41 | K49: =I49/'Dados Gerais'!E15 -> 47.34173

Sheet Infraestrutura
A2: ORÇAMENTO PARAMÉTRICO INFRAESTRUTURA
A7: Documento | B7: ='Dados Gerais'!B7 -> CTN-BRS-139 - Gerenciamento executivo_R00
A8: Cliente | B8: ='Dados Gerais'!B8 -> Brasin
A9: Obra | B9: ='Dados Gerais'!B9 -> 139 | G9: UC | H9: 00 | I9: Status | J9: Em andamento
A10: Data | B10: ='Dados Gerais'!B10 -> 45006 | G10: Revisão | H10: R00 | I10: Resp.
A12: FUNDAÇÃO PROFUNDA
A14: Descrição | D14: Quantidade | F14: Parâmetro | H14: Referência | I14: Valor total
A15: Número de Estacas raiz | D15: =ROUNDUP((F15*'Dados Gerais'!E27/2),0) -> 85 | E15: un | F15: 0.22 | G15: un / m² | H15: Média | I15: 0
A16: Estaca Raiz Diâmetro 40 | D16: =ROUNDUP(($D$15*(F16/100)),0) -> 11 | E16: un | F16: 12 | G16: % | H16: Média | I16: 0
A17: Estaca Raiz Diâmetro 40 | D17: =ROUNDUP((F17*D16),0) -> 330 | E17: m | F17: 30 | G17: m / un | H17: Média | I17: =+ROUNDUP((D17*800),0) -> 264000
A18: Estaca Raiz Diâmetro 45 | D18: =ROUNDUP(($D$15*(F18/100)),0) -> 15 | E18: un | F18: 17 | G18: % | H18: Média | I18: 0
A19: Estaca Raiz Diâmetro 45 | D19: =ROUNDUP((F19*D18),0) -> 450 | E19: m | F19: 30 | G19: m / un | H19: Média | I19: =+ROUNDUP((D19*800),0) -> 360000
A20: Estaca Raiz Diâmetro 50 | D20: =ROUNDUP(($D$15*(F20/100)),0) -> 61 | E20: un | F20: 71 | G20: % | H20: Média | I20: 0
A21: Estaca Raiz Diâmetro 50 | D21: =ROUNDUP((F21*D20),0) -> 1830 | E21: m | F21: 30 | G21: m / un | H21: Média | I21: =+ROUNDUP((D21*800),0) -> 1464000
A22: Número de Estacas helice | D22: =D15 -> 85 | E22: un | F22: 0.22 | G22: un / m² | H22: Média | I22: 0
A23: Estaca Helice Diâmetro 50 | D23: =ROUNDUP(($D$22*(F23/100)),0) -> 11 | E23: un | F23: 12 | G23: % | H23: Média | I23: 0
A24: Estaca Helice Diâmetro 50 | D24: =ROUNDUP((F24*D23),0) -> 330 | E24: m | F24: 30 | G24: m / un | H24: Média | I24: =+ROUNDUP((D24*75),0) -> 24750
A25: Estaca Helice Diâmetro 60 | D25: =ROUNDUP(($D$22*(F25/100)),0) -> 15 | E25: un | F25: 17 | G25: % | H25: Média | I25: 0
A26: Estaca Helice Diâmetro 60 | D26: =ROUNDUP((F26*D25),0) -> 450 | E26: m | F26: 30 | G26: m / un | H26: Média | I26: =+ROUNDUP((D26*80),0) -> 36000
A27: Estaca Helice Diâmetro 70 | D27: =ROUNDUP(($D$22*(F27/100)),0) -> 15 | E27: un | F27: 17 | G27: % | H27: Média | I27: 0
A28: Estaca Helice Diâmetro 70 | D28: =ROUNDUP((F28*D27),0) -> 450 | E28: m | F28: 30 | G28: m / un | H28: Média | I28: =+ROUNDUP((D28*90),0) -> 40500
A29: Armação | D29: =ROUNDUP(((D30)*F29),0) -> 24555 | E29: kg | F29: 24.43 | G29: kg / m³ | H29: Média | I29: =+ROUNDUP((D29*8),0) -> 196440
A30: Concreto | D30: =(PI()*((0.4^2)/4)*D17+PI()*((0.45^2)/4)*D19+PI()*((0.5^2)/4)*D21)*1.2+(PI()*((0.5^2)/4)*D24+PI()*((0.6^2)/4)*D26+PI()*((0.7^2)/4)*D28)*1.2 -> 1005.0819 | E30: m³ | F30: =580+45 -> 625 | G30: R$ / m³ | H30: Média | I30: =+ROUNDUP((D30*F30),0)*1.2 -> 753812.4
A31: TOTAL | I31: =SUM(I15:J30) -> 3139502.4 | N31: =I31/'Dados Gerais'!E15 -> 187.68139
A34: FUNDAÇÃO RASA
A36: Descrição | D36: Quantidade | F36: Parâmetro | H36: Referência | I36: Valor total
A37: Fabricação, montagem e desmontagem de forma para blocos e baldrames | D37: ='Dados Gerais'!E27*Infraestrutura!F37 -> 573.405 | E37: m² | F37: 0.75 | G37: m² / AT | H37: Média | I37: =+D37*33.7 -> 19323.749
A38: Armação | D38: =D39*F38 -> 30581.6 | E38: kg | F38: 80 | G38: kg / m³ | H38: Média | I38: =+D38*8 -> 244652.8
A39: Concreto | D39: =F39*'Dados Gerais'!E27 -> 382.27 | E39: m³ | F39: 0.5 | G39: m³ / AT | H39: Média | I39: =+D39*(580+45)*1.05 -> 250864.69
A40: Piso de concreto armado | D40: ='Dados Gerais'!E27 -> 764.54 | E40: m² | F40: 350 | G40: R$ / m² | H40: Média | I40: =F40*D40 -> 267589
A41: Mão de obra | D41: =D37 -> 573.405 | E41: m² | F41: 200 | G41: R$ / AT | H41: Média | I41: =+D41*F41 -> 114681
A42: TOTAL | I42: =SUM(I37:J41) -> 897111.24
A45: TOTAL INFRAESTRUTURA | I45: =I31+I42 -> 4036613.6 | K45: =I45/'Dados Gerais'!E15 -> 241.31125

Sheet Supraestrutura
A2: ORÇAMENTO PARAMÉTRICO SUPRAESTRUTURA
A7: Documento | B7: ='Dados Gerais'!B7 -> CTN-BRS-139 - Gerenciamento executivo_R00
A8: Cliente | B8: ='Dados Gerais'!B8 -> Brasin
A9: Obra | B9: ='Dados Gerais'!B9 -> 139 | G9: UC | H9: 00 | I9: Status | J9: Em andamento
A10: Data | B10: ='Dados Gerais'!B10 -> 45006 | G10: Revisão | H10: R00 | I10: Resp.
A12: SUPRAESTRUTURA
A14: Descrição | D14: Quantidade | F14: Parâmetro | H14: Referência | I14: Valor total
A15: Fabricação forma | D15: =+D16*F15/100 -> 12545.873 | E15: m² | F15: 30 | G15: % | H15: Média | I15: =+D15*95 -> 1191857.9 | M15: concreto 40 MPA
A16: Montagem de forma | D16: =+'Dados Gerais'!$E$15*F16 -> 41819.575 | E16: m² | F16: 2.5 | G16: m² / AC | H16: Média | I16: =+D16*4.5 -> 188188.09 | M16: Laje protendida
A17: Pilares circulares - 1.25 | D17: 4 | E17: un | F17: =2*PI()*(1.25/2)*17.27 -> 67.819131 | G17: m² / un | H17: Média | I17: =+D17*F17*131 -> 35537.225 | M17: Pilares circulares
A18: Pilares circulares - 1.00 | D18: 4 | E18: un | F18: =2*PI()*(1/2)*17.27 -> 54.255305 | G18: m² / un | H18: Média | I18: =+D18*F18*126 -> 27344.674
A19: Pilares circulares - 0.8 | D19: 3 | E19: un | F19: =2*PI()*(0.8/2)*17.27 -> 43.404244 | G19: m² / un | H19: Média | I19: =+D19*F19*121 -> 15755.741
A20: Escoramento - Torre | D20: =+'Dados Gerais'!E20*'Dados Gerais'!E17 -> 12260.16 | E20: m² | F20: 57 | G20: R$ / m² | H20: Média | I20: =+D20*F20 -> 698829.12
A21: Escoramento - Embasamento | D21: =+'Dados Gerais'!E24 -> 5653.56 | E21: m² | F21: 57 | G21: R$ / m² | H21: Média | I21: =+D21*F21 -> 322252.92
A22: Armadura Convencional para Estrutura | D22: =(D24)*F22 -> 355466.39 | E22: kg | F22: 85 | G22: kg / m³ | H22: Média | I22: =+D22*8 -> 2843731.1
A23: Protensão | D23: =(D24)*F23 -> 70173.247 | E23: kg | F23: 16.78 | G23: kg / m³ | H23: Média | I23: =+D23*(11.95+11.4) -> 1638545.3
A24: Concreto | D24: =(+'Dados Gerais'!E15)*Supraestrutura!$F$24 -> 4181.9575 | E24: m³ | F24: 0.25 | G24: m³ / AC | H24: Média | I24: =+D24*(580+45)*1.05 -> 2744409.6
A25: Mão de obra - laje inclinada | D25: =(14.87*9.66)/2 -> 71.8221 | E25: m² | F25: 250 | G25: R$ / m² | H25: Média | I25: =+D25*F25 -> 17955.525
A26: Mão de obra - estrutura em concreto armado | D26: ='Dados Gerais'!E15 -> 16727.83 | E26: m² | F26: 190 | G26: R$ / m² | H26: Média | I26: =+D26*F26 -> 3178287.7
A27: TOTAL | I27: =SUM(I15:J26) -> 12902695
A30: TOTAL SUPRAESTRUTURA | I30: =I27 -> 12902695 | K30: =I30/'Dados Gerais'!E15 -> 771.33106
A33: Lumis
A34: 62240 | B34: kg de cordoalha | D34: 14888.46 | E34: area | F34: =A34/D34 -> 4.1804189
D35: 3709.58 | E35: concreto | F35: =A34/D35 -> 16.77818

Sheet Alvenaria
A2: ORÇAMENTO PARAMÉTRICO ALVENARIA
A7: Documento | B7: ='Dados Gerais'!B7 -> CTN-BRS-139 - Gerenciamento executivo_R00
A8: Cliente | B8: ='Dados Gerais'!B8 -> Brasin
A9: Obra | B9: ='Dados Gerais'!B9 -> 139 | G9: UC | H9: 00 | I9: Status | J9: Em andamento
A10: Data | B10: ='Dados Gerais'!B10 -> 45006 | G10: Revisão | H10: R00 | I10: Resp.
A12: ALVENARIA
A14: Descrição | D14: Quantidade | F14: Parâmetro | H14: Referência | I14: Valor total
A15: Alvenaria embasamento | D15: =F15*'Dados Gerais'!E24 -> 3392.136 | E15: m² | F15: 0.6 | G15: m² / AE | H15: Média | I15: =+D15*43.5 -> 147557.92
A16: Alvenaria lazer | D16: =F16*'Dados Gerais'!E22 -> 867.57 | E16: m² | F16: 0.75 | G16: m² / AL | H16: Média | I16: =+D16*43.5 -> 37739.295
A17: Alvenaria tipo - externo | D17: =F17*'Dados Gerais'!E17*'Dados Gerais'!E20 -> 2452.032 | E17: m² | F17: 0.2 | G17: m² / APT*NPT | H17: Média | I17: =+D17*43.5 -> 106663.39
A18: Alvenaria tipo - Interno | D18: =F18*'Dados Gerais'!E17*'Dados Gerais'!E20 -> 18390.24 | E18: m² | F18: 1.5 | G18: m² / APT*NPT | H18: Média | I18: =+D18*43.5 -> 799975.44
A19: Alvenaria tipo diferenciado | D19: =F19*'Dados Gerais'!E18*'Dados Gerais'!E20 -> 574.695 | E19: m² | F19: 1.5 | G19: m² / APT*NPD | H19: Média | I19: =+D19*43.5 -> 24999.232
A20: Alvenaria escadas - sical | D20: =F20*'Dados Gerais'!E15 -> 3345.566 | E20: m² | F20: 0.2 | G20: m² / AC | H20: Média | I20: =+D20*55 -> 184006.13 | N20: Alvenaria para isolamento acustico em geradores e subestação
A21: Alvenaria cobertura / reservatório | D21: =F21*'Dados Gerais'!E20 -> 306.504 | E21: m² | F21: 0.8 | G21: m² / APT | H21: Média | I21: =+D21*43.5 -> 13332.924 | N21: Bloco sical nas escadas
A22: Serviços complementares | D22: =D15+D16+D17+D18+D19+D20+D21 -> 29328.743 | E22: m² | F22: 8.2 | G22: R$ / m² | H22: Média | I22: =+D22*F22 -> 240495.69
A23: Mão de obra | D23: =D16+D17+D18+D19+D20+D21+D15 -> 29328.743 | E23: m² | F23: 44 | G23: R$ / m² | H23: Média | I23: =+D23*F23 -> 1290464.7
A24: TOTAL | I24: =SUM(I15:J23) -> 2845234.7
A27: TOTAL ALVENARIA | I27: =I24 -> 2845234.7 | K27: =I27/'Dados Gerais'!E15 -> 170.08989

Sheet Instalações
A2: ORÇAMENTO PARAMÉTRICO INSTALAÇÕES
A7: Documento | B7: ='Dados Gerais'!B7 -> CTN-BRS-139 - Gerenciamento executivo_R00
A8: Cliente | B8: ='Dados Gerais'!B8 -> Brasin
A9: Obra | B9: ='Dados Gerais'!B9 -> 139 | G9: UC | H9: 00 | I9: Status | J9: Em andamento
A10: Data | B10: ='Dados Gerais'!B10 -> 45006 | G10: Revisão | H10: R00 | I10: Resp. | M10: 8285.73
A12: INSTALAÇÕES ELÉTRICAS | M12: MARIO LAGO
A14: Descrição | D14: Quantidade | F14: Parâmetro | H14: Referência | I14: Valor total
A15: Entrada de Energia | D15: 1 | E15: vb | F15: 5.5 | G15: R$ / AC | H15: Média | I15: =+F15*'Dados Gerais'!$E$15 -> 92003.065 | L15: =7688.76 -> 7688.76 | M15: =L15/$M$10 -> 0.92795203
A16: Eletrodutos e Eletrocalhas | D16: 1 | E16: vb | F16: 10 | G16: R$ / AC | H16: Média | I16: =+F16*'Dados Gerais'!$E$15 -> 167278.3 | L16: =81009.14 -> 81009.14 | M16: =L16/$M$10 -> 9.7769466 | P16: =5790898.24/M10 -> 698.90019
A17: Instalações Embutidas e Aparentes | D17: 1 | E17: vb | F17: 15 | G17: R$ / AC | H17: Média | I17: =+F17*'Dados Gerais'!$E$15 -> 250917.45
A18: Cabos e Fiações | D18: 1 | E18: vb | F18: 30 | G18: R$ / AC | H18: Média | I18: =+F18*'Dados Gerais'!$E$15 -> 501834.9 | L18: 123189.9 | M18: =L18/$M$10 -> 14.867718
A19: Quadros e Disjuntores | D19: 1 | E19: vb | F19: 15 | G19: R$ / AC | H19: Média | I19: =+F19*'Dados Gerais'!$E$15 -> 250917.45 | L19: 82781.1 | M19: =L19/$M$10 -> 9.9908035
A20: Acabamentos Elétricos | D20: 1 | E20: vb | F20: 15 | G20: R$ / AC | H20: Média | I20: =+F20*'Dados Gerais'!$E$15 -> 250917.45 | L20: 36466.82 | M20: =L20/$M$10 -> 4.4011596
A21: Equipamentos e Iluminação | D21: 1 | E21: vb | F21: 15 | G21: R$ / AC | H21: Média | I21: =+F21*'Dados Gerais'!$E$15 -> 250917.45 | L21: 7695.09 | M21: =L21/$M$10 -> 0.928716
A22: Mão de Obra para Instalações Elétricas | D22: 1 | E22: vb | F22: 45 | G22: R$ / AC | H22: Média | I22: =+F22*'Dados Gerais'!$E$15 -> 752752.35 | M22: 29.86
A23: TOTAL | I23: =SUM(I15:J22) -> 2517538.4
A25: INSTALAÇÕES HIDROSSANITÁRIAS
F26: cpvc
A27: Descrição | D27: Quantidade | F27: Parâmetro | H27: Referência | I27: Valor total
A28: Instalações de Água Fria | D28: 1 | E28: vb | F28: 28 | G28: R$ / AC | H28: Média | I28: =+F28*'Dados Gerais'!$E$15 -> 468379.24 | L28: =63808.43+51048.04+67434.12 -> 182290.59 | M28: =L28/$M$10 -> 22.000547
A29: Instalações de Água Quente | D29: 1 | E29: vb | F29: 28 | G29: R$ / AC | H29: Média | I29: =+F29*'Dados Gerais'!$E$15 -> 468379.24 | M29: =L29/$M$10 -> 0
A30: Instalações de Águas Pluviais | D30: 1 | E30: vb | F30: 10 | G30: R$ / AC | H30: Média | I30: =+F30*'Dados Gerais'!$E$15 -> 167278.3 | M30: =L30/$M$10 -> 0
A31: Instalações Sanitárias | D31: 1 | E31: vb | F31: 16 | G31: R$ / AC | H31: Média | I31: =+F31*'Dados Gerais'!$E$15 -> 267645.28 | L31: =56503.57+70171 -> 126674.57 | M31: =L31/$M$10 -> 15.288281
A32: Suportes | D32: 1 | E32: vb | F32: 0 | G32: R$ / AC | H32: Média | I32: =+F32*'Dados Gerais'!$E$15 -> 0 | M32: =L32/$M$10 -> 0
A33: Louças e Metais | D33: 1 | E33: vb | F33: 30 | G33: R$ / AC | H33: Média | I33: =+F33*'Dados Gerais'!$E$15+7500*4*2 -> 561834.9 | L33: 160586 | M33: =L33/$M$10 -> 19.381032
A34: Mão de Obra para Instalações Hidráulicas | D34: 1 | E34: vb | F34: 45 | G34: R$ / AC | H34: Média | I34: =+F34*'Dados Gerais'!$E$15 -> 752752.35 | M34: 45
A35: TOTAL | I35: =SUM(I28:J34) -> 2686269.3
A38: INSTALAÇÕES PREVENTIVAS E GLP
A40: Descrição | D40: Quantidade | F40: Parâmetro | H40: Referência | I40: Valor total
A41: Instalações Preventivas | D41: 1 | E41: vb | F41: 15 | G41: R$ / AC | H41: Média | I41: =+F41*'Dados Gerais'!$E$15 -> 250917.45 | L41: 152457.19 | M41: =L41/$M$10 -> 18.399971 | N41: =M41-4 -> 14.399971
A42: Instalações de GLP | D42: 1 | E42: vb | F42: 8 | G42: R$ / AC | H42: Média | I42: =+F42*'Dados Gerais'!$E$15 -> 133822.64 | L42: 97678.62 | M42: =L42/$M$10 -> 11.788777 | N42: =M42-4 -> 7.7887766
A43: Instalações de Proteção e Aterramento - SPDA | D43: 1 | E43: vb | F43: 10 | G43: R$ / AC | H43: Média | I43: =+F43*'Dados Gerais'!$E$15 -> 167278.3 | L43: 115723.28 | M43: =L43/$M$10 -> 13.966576 | N43: =M43-4 -> 9.9665763
A44: Mão de Obra | D44: 1 | E44: vb | F44: 12 | G44: R$ / AC | H44: Média | I44: =+F44*'Dados Gerais'!$E$15 -> 200733.96
A45: TOTAL | I45: =SUM(I41:J44) -> 752752.35
A48: TOTAL INSTALAÇÕES | I48: =I23+I35+I45 -> 5956560.1 | K48: =I48/'Dados Gerais'!E15 -> 356.08684

Sheet Sistemas especiais
A2: ORÇAMENTO PARAMÉTRICO INSTALAÇÕES
A7: Documento | B7: ='Dados Gerais'!B7 -> CTN-BRS-139 - Gerenciamento executivo_R00
A8: Cliente | B8: ='Dados Gerais'!B8 -> Brasin
A9: Obra | B9: ='Dados Gerais'!B9 -> 139 | G9: UC | H9: 00 | I9: Status | J9: Em andamento
A10: Data | B10: ='Dados Gerais'!B10 -> 45006 | G10: Revisão | H10: R00 | I10: Resp.
A12: CLIMATIZAÇÃO, EXAUSTÃO MECÂNICA E PRESSURIZAÇÃO
A14: Descrição | D14: Quantidade | F14: Parâmetro | H14: Referência | I14: Valor total
A15: Infraestrutura para Instalação de Ar Condicionado | D15: 202 | E15: un | F15: 1500 | G15: R$ / un | H15: Média | I15: =F15*D15 -> 303000 | M15: terreo | N15: 5 | O15: 8
A16: Instalação de Ar Condicionado | D16: 8 | E16: un | F16: 5000 | G16: R$ / un | H16: Média | I16: =F16*D16 -> 40000 | M16: Lazer | N16: 5 | O16: 6
A17: Ventokit | D17: 57 | E17: un | F17: 900 | G17: R$ / un | H17: Média | I17: =+D17*F17 -> 51300 | M17: tipo 1 | N17: =4*2*6 -> 48 | O17: =2*6 -> 12
A18: Churrasqueiras | D18: =40+3 -> 43 | E18: un | F18: 2000 | G18: R$ / un | H18: Média | I18: =+D18*F18 -> 86000 | M18: dif | N18: 5 | O18: 1
A19: TOTAL | I19: =SUM(I15:J18) -> 480300 | M19: Tipo 2 | N19: =N18*26 -> 130 | O19: =O18*26 -> 26
M20: duplex | N20: =5+1 -> 6 | O20: 2
A21: COMUNICAÇÃO | M21: Rooftop | N21: 3 | O21: 2
A23: Descrição | D23: Quantidade | F23: Parâmetro | H23: Referência | I23: Valor total
A24: CFTV | D24: 1 | E24: vb | F24: 1.5 | G24: R$ / AC | H24: Média | I24: =+F24*'Dados Gerais'!$E$15 -> 25091.745 | L24: 22475.5 | M24: =L24/14888.46 -> 1.509592
A25: Interfone | D25: 1 | E25: vb | F25: 7 | G25: R$ / AC | H25: Média | I25: =+F25*'Dados Gerais'!$E$15 -> 117094.81 | L25: 98085 | M25: =L25/14888.46 -> 6.5879883
A26: TV e internet | D26: 1 | E26: vb | F26: 5 | G26: R$ / AC | H26: Média | I26: =+F26*'Dados Gerais'!$E$15 -> 83639.15 | L26: 67516.5 | M26: =L26/14888.46 -> 4.5348209 | N26: =SUM(N15:N21) -> 202 | O26: =SUM(O15:O21) -> 57
A27: TOTAL | I27: =SUM(I24:J26) -> 225825.71
A29: OUTROS SISTEMAS ESPECIAIS
A31: Descrição | D31: Quantidade | F31: Parâmetro | H31: Referência | I31: Valor total
A32: Outros sistemas | D32: 1 | E32: vb | F32: 20 | G32: R$ / AC | H32: Média | I32: =+F32*'Dados Gerais'!E15 -> 334556.6
A33: TOTAL | I33: =SUM(I32:J32) -> 334556.6
A36: EQUIPAMENTOS
A38: Descrição | D38: Quantidade | F38: Parâmetro | H38: Referência | I38: Valor total
A39: Elevadores | D39: 3 | E39: un | F39: 16000 | G39: R$ / NP | H39: Média | I39: =D39*F39*'Dados Gerais'!E16 -> 2064000
A40: Grupo de geradores | D40: 1 | E40: un | F40: =91000*1.2 -> 109200 | G40: R$ | H40: Média | I40: =+D40*F40 -> 109200
A41: Subestação | D41: 1 | E41: un | F41: =1.2*180000 -> 216000 | G41: R$ | H41: Média | I41: =+D41*F41 -> 216000
A42: Sauna | D42: 1 | E42: un | F42: 15000 | G42: R$ | H42: Média | I42: =+D42*F42 -> 15000
A43: Carro elétrico | D43: 43 | E43: un | F43: 550 | G43: R$ | H43: Média | I43: =+D43*F43 -> 23650
A44: Hidromassagem | D44: 1 | E44: un | F44: 12630 | G44: R$ | H44: Média | I44: =+D44*F44 -> 12630
A45: Sistema de aquecimento | D45: 1 | E45: vb | F45: =40000+75000 -> 115000 | G45: R$ | H45: Média | I45: =+D45*F45 -> 115000
A46: Equipamentos para Piscina | D46: 1 | E46: vb | F46: 250000 | G46: R$ | H46: Média | I46: =+D46*F46 -> 250000
A47: TOTAL | I47: =SUM(I39:J46) -> 2805480
A50: TOTAL SISTEMAS ESPECIAIS | I50: =I19+I33+I47+I27 -> 3846162.3 | K50: =I50/'Dados Gerais'!E15 -> 229.92596

Sheet Impermeabilização
A2: ORÇAMENTO PARAMÉTRICO IMPERMEABILIZAÇÃO
A7: Documento | B7: ='Dados Gerais'!B7 -> CTN-BRS-139 - Gerenciamento executivo_R00
A8: Cliente | B8: ='Dados Gerais'!B8 -> Brasin
A9: Obra | B9: ='Dados Gerais'!B9 -> 139 | G9: UC | H9: 00 | I9: Status | J9: Em andamento
A10: Data | B10: ='Dados Gerais'!B10 -> 45006 | G10: Revisão | H10: R00 | I10: Resp.
A12: IMPERMEABILIZAÇÃO
A14: Descrição | D14: Quantidade | F14: Parâmetro | H14: Referência | I14: Valor total
A15: Regularização de Superfície | D15: =D20 -> 5854.7405 | E15: m² | F15: 15 | G15: R$ / m² | H15: Média | I15: =+D15*F15 -> 87821.107
A16: Poço do elevador | D16: =3*3.35+3*(7.23*1.2) -> 36.078 | E16: m² | F16: 45 | G16: R$ / m² | H16: Média | I16: =+D16*F16 -> 1623.51
A17: Baldrames | D17: =0.7*Infraestrutura!D37 -> 401.3835 | E17: m² | F17: 40 | G17: R$ / m² | H17: Média | I17: =+D17*F17 -> 16055.34
A18: Ralos | D18: 1 | E18: vb | F18: 1 | G18: R$ / AC | H18: Média | I18: =+F18*'Dados Gerais'!$E$15 -> 16727.83
A19: Impermeabilizações cimenticias | D19: =+F19*'Dados Gerais'!$E$15 -> 1672.783 | E19: m² | F19: 0.1 | G19: m² / AC | H19: Média | I19: =+D19*60 -> 100366.98
A20: Impermeabilizações com manta asfaltica | D20: =+F20*'Dados Gerais'!$E$15 -> 5854.7405 | E20: m² | F20: 0.35 | G20: m² / AC | H20: Média | I20: =+D20*160 -> 936758.48
A21: Impermeabilização de peitoril | D21: 1 | E21: vb | F21: 0.15 | G21: R$ / AC | H21: Média | I21: =+F21*'Dados Gerais'!$E$15 -> 2509.1745
A22: Proteção Mecânica | D22: =+D20 -> 5854.7405 | E22: m² | F22: 40 | G22: R$ / m² | H22: Média | I22: =F22*D22 -> 234189.62
A23: TOTAL | I23: =SUM(I15:J22) -> 1396052
A26: TOTAL IMPERMEABILIZAÇÃO | I26: =I23 -> 1396052 | K26: =I26/'Dados Gerais'!E15 -> 83.456853

Sheet Acabamentos de Teto
A2: ORÇAMENTO PARAMÉTRICO REVESTIMENTOS E ACABAMENTOS INTERNOS EM TETO
A7: Documento | B7: ='Dados Gerais'!B7 -> CTN-BRS-139 - Gerenciamento executivo_R00
A8: Cliente | B8: ='Dados Gerais'!B8 -> Brasin
A9: Obra | B9: ='Dados Gerais'!B9 -> 139 | G9: UC | H9: 00 | I9: Status | J9: Em andamento
A10: Data | B10: ='Dados Gerais'!B10 -> 45006 | G10: Revisão | H10: R00 | I10: Resp.
A12: ACABAMENTOS DE TETO - OPÇÃO FORRO MINERAL
A14: Descrição | D14: Quantidade | F14: Parâmetro | H14: Referência | I14: Valor total
A15: Forro em placa mineral | D15: =+'Dados Gerais'!E15*F15 -> 11947.27 | E15: m² | F15: =1-F18 -> 0.71421517 | G15: m² / AC | H15: Média | I15: =+D15*60 -> 716836.2 | M15: Gesso acartonado ST e RU
A16: Negativo | D16: =+F16*'Dados Gerais'!$E$15 -> 11947.27 | E16: m | F16: =1-F18 -> 0.71421517 | G16: m / AC | H16: Média | I16: =+D16*22 -> 262839.94 | M16: Comparação com gesso mineral
A17: Cortineiro | D17: =305.4+(11+3.42)*2*6+(4.1+8.1+6+6.45+1.78+3)*27+(4+11.72+6.5+1.72+3+2*1.5)+(5.73+2.2+13.9+4.86)+(7.4+0.5+7.3+3) -> 1347.88 | E17: m | F17: =D17/'Dados Gerais'!E15 -> 0.080577098 | G17: m / AC | H17: Média | I17: =+D17*96 -> 129396.48 | M17: Escadas, areas tecnicas e haragens sm forro
A18: Estucamento | D18: ='Dados Gerais'!E27+'Rev. Internos Piso e Parede'!D15 -> 4780.56 | E18: m² | F18: =D18/'Dados Gerais'!E15 -> 0.28578483 | G18: R$ / AC | H18: Média | I18: =D18*20 -> 95611.2 | M18: Cortineiros 15/20cm
A19: TOTAL | I19: =SUM(I15:J18) -> 1204683.8 | M19: Negativo
A21: ACABAMENTOS DE TETO - OPÇÃO ACARTONADO
A23: Descrição | D23: Quantidade | F23: Parâmetro | H23: Referência | I23: Valor total
A24: Forro acartonado ST e RU | D24: =+'Dados Gerais'!E15*F24 -> 11947.27 | E24: m² | F24: =1-F27 -> 0.71421517 | G24: m² / AC | H24: Média | I24: =+D24*100 -> 1194727
A25: Negativo | D25: =+F25*'Dados Gerais'!$E$15 -> 11947.27 | E25: m | F25: =1-F27 -> 0.71421517 | G25: m / AC | H25: Média | I25: =+D25*22 -> 262839.94
A26: Cortineiro | D26: =305.4+(11+3.42)*2*6+(4.1+8.1+6+6.45+1.78+3)*27+(4+11.72+6.5+1.72+3+2*1.5)+(5.73+2.2+13.9+4.86)+(7.4+0.5+7.3+3) -> 1347.88 | E26: m | F26: =D26/'Dados Gerais'!E15 -> 0.080577098 | G26: m / AC | H26: Média | I26: =+D26*96 -> 129396.48
A27: Estucamento | D27: ='Dados Gerais'!E27+'Rev. Internos Piso e Parede'!D15 -> 4780.56 | E27: m² | F27: =D27/'Dados Gerais'!E15 -> 0.28578483 | G27: R$ / AC | H27: Média | I27: =D27*20 -> 95611.2
A28: TOTAL | I28: =SUM(I24:J27) -> 1682574.6
I31: DIFERENÇA | J31: =I28-I19 -> 477890.8

Sheet Rev. Internos Piso e Parede
A2: ORÇAMENTO PARAMÉTRICO REVESTIMENTOS INTERNOS EM PISO E PAREDE
A7: Documento | B7: ='Dados Gerais'!B7 -> CTN-BRS-139 - Gerenciamento executivo_R00
A8: Cliente | B8: ='Dados Gerais'!B8 -> Brasin
A9: Obra | B9: ='Dados Gerais'!B9 -> 139 | G9: UC | H9: 00 | I9: Status | J9: Em andamento
A10: Data | B10: ='Dados Gerais'!B10 -> 45006 | G10: Revisão | H10: R00 | I10: Resp.
A12: REVESTIMENTOS INTERNOS EM PISO E PAREDE
A14: Descrição | D14: Quantidade | F14: Parâmetro | H14: Referência | I14: Valor total
A15: Piso de concreto polido | D15: ='Dados Gerais'!E24-'Dados Gerais'!E27-873 -> 4016.02 | E15: m² | F15: 80 | G15: R$ / m² | H15: Média | I15: =F15*D15 -> 321281.6 | M15: Contrapiso com argamassa usinada 5cm
A16: Contrapiso | D16: =+'Dados Gerais'!$E$15-'Dados Gerais'!E27-D15 -> 11947.27 | E16: m² | F16: =D16/'Dados Gerais'!E15 -> 0.71421517 | G16: m² / AC | H16: Média | I16: =+D16*65 -> 776572.55 | M16: Manta acustica em apartamentos
A17: Manta acústica | D17: =D16-'Dados Gerais'!E22 -> 10790.51 | E17: m² | F17: =D17/'Dados Gerais'!E15 -> 0.64506335 | G17: m² / AC | H17: Média | I17: =+D17*25 -> 269762.75 | M17: Reboco com massa estabilizada
A18: Chapisco | D18: =+'Dados Gerais'!$E$15*'Rev. Internos Piso e Parede'!F18 -> 26764.528 | E18: m² | F18: 1.6 | G18: m² / AC | H18: Média | I18: =+D18*5 -> 133822.64 | M18: Chapisco rodado em obra
A19: Reboco | D19: =+'Dados Gerais'!$E$15*'Rev. Internos Piso e Parede'!F19 -> 26764.528 | E19: m² | F19: 1.6 | G19: m² / AC | H19: Média | I19: =50*D19 -> 1338226.4
A20: Estucamento | D20: 1 | E20: vb | F20: 1 | G20: R$ / AC | H20: Média | I20: =+F20*'Dados Gerais'!$E$15 -> 16727.83
A21: TOTAL | I21: =SUM(I15:J20) -> 2856393.8
A24: TOTAL IMPERMEABILIZAÇÃO | I24: =I21 -> 2856393.8 | K24: =I24/'Dados Gerais'!E15 -> 170.75698

Sheet Acabamentos de Piso e Parede
A2: ORÇAMENTO PARAMÉTRICO ACABAMENTOS EM PISO E PAREDE
A7: Documento | B7: ='Dados Gerais'!B7 -> CTN-BRS-139 - Gerenciamento executivo_R00
A8: Cliente | B8: ='Dados Gerais'!B8 -> Brasin
A9: Obra | B9: ='Dados Gerais'!B9 -> 139 | G9: UC | H9: 00 | I9: Status | J9: Em andamento
A10: Data | B10: ='Dados Gerais'!B10 -> 45006 | G10: Revisão | H10: R00 | I10: Resp.
A12: ACABAMENTOS EM PISO E PAREDE - OPÇÃO 1
A14: Descrição | D14: Quantidade | F14: Parâmetro | H14: Referência | I14: Valor total | M14: Garagem com piso polido e tinta epoxi
A15: Porcelanato 90x90 | D15: =E33+E38+E49+E50+E51+E53+E54+E55+E63*6+E69+E76*27+E81+E86+E64*6+E70+E77*27+E82+E87 -> 6065 | E15: m² | F15: =80+48 -> 128 | G15: R$ / m² | H15: Média | I15: =+F15*D15 -> 776320 | M15: Contrapiso e revestimento ceramico
A16: Porcelanato 80x80 | D16: =E34+E35+E36+E37+E39+E40+E41 -> 174.93 | E16: m² | F16: 105 | G16: R$ / m² | H16: Média | I16: =+F16*D16 -> 18367.65
A17: Cerâmica 45x45 | D17: =E34+E35 -> 49.85 | E17: m² | F17: 75 | G17: R$ / m² | H17: Média | I17: =+F17*D17 -> 3738.75
A18: Vinílico | D18: =E52+E65*6+E71+E78*27 -> 3053.75 | E18: m² | F18: =250 -> 250 | G18: R$ / m² | H18: Média | I18: =+F18*D18 -> 763437.5
A19: Concreto estampado | D19: =E45*5+315.93 -> 714.53 | E19: m² | F19: 17 | G19: R$ / m² | H19: Média | I19: =+F19*D19 -> 12147.01 | M19: Sauna revestida com porcelanato em paredes
A20: Granito | D20: =E59+E88+E72 -> 688.91 | E20: m² | F20: 105 | G20: R$ / m² | H20: Média | I20: =+F20*D20 -> 72335.55 | M20: Muro da área de lazer será revestido com 80x80
A21: Piscina | D21: =E58+E57+14.38*0.5+(19.84+10.31+2.04+11.6+7.46)*1.5-51.81+50 -> 146.845 | E21: m² | F21: 230 | G21: R$ / m² | H21: Média | I21: =+F21*D21 -> 33774.35 | M21: Rodapé em poliestireno, com exceção de algumas aplicações em pedras
A22: Deck de Garapeira | D22: 51.81 | E22: m² | F22: 230 | G22: R$ / m² | H22: Média | I22: =+F22*D22 -> 11916.3
A23: Pedra portuguesa | D23: =E56 -> 63.12 | E23: m² | F23: 145 | G23: R$ / m² | H23: Média | I23: =+F23*D23 -> 9152.4
A24: Rodapés | D24: 1 | E24: vb | F24: 50 | G24: R$ / AC | H24: Média | I24: =+F24*'Dados Gerais'!$E$15 -> 836391.5
A25: Revestimentos de Parede muro - Pedra portuguesa | D25: ='Dados Gerais'!E28*2 -> 260.6052 | E25: m² | F25: 145 | G25: R$ / m² | H25: Média | I25: =F25*D25 -> 37787.754
A26: Revestimentos de Parede | D26: 1 | E26: vb | F26: 40 | G26: R$ / AC | H26: Média | I26: =+F26*'Dados Gerais'!$E$15 -> 669113.2
A27: TOTAL | I27: =SUM(I15:J26) -> 3244482
A30: TOTAL IMPERMEABILIZAÇÃO | I30: =I27 -> 3244482 | K30: =I30/'Dados Gerais'!E15 -> 193.95713
D32: TERREO
D33: Salas comerciais | E33: =397.35+47.48 -> 444.83 | F33: porcelanato 90x90 | J33: Escada | K33: =(13.91+5.35)*43 -> 828.18 | L33: pintura acrilica
D34: Lixeira, glp | E34: =0.76+4.56 -> 5.32 | F34: ceramica
D35: Subestação e gerador | E35: =28.57+11.67+4.29 -> 44.53 | F35: ceramica
D36: Bicicletários, box, banbhistas | E36: 108 | F36: porcelanato 80x80
D37: Portaria | E37: =5.46 -> 5.46 | F37: porcelanato 80x80
D38: Hall | E38: 32.2 | F38: porcelanato 90x90
D39: Pet wah | E39: 4.03 | F39: porcelanato 80x80
D40: Servidores | E40: =2.85+2.94 -> 5.79 | F40: porcelanato 80x80
D41: Lavabo | E41: 1.8 | F41: porcelanato 80x80
D43: G1
D44: escadas | E44: =(13.91+5.35) -> 19.26
D45: rampa | E45: 79.72
D46: gaargem | E46: =873-E44-E45 -> 774.02 | F46: cerâmica ou pintura
D48: LZER
D49: estar e salão de festas | E49: =75+72.9 -> 147.9 | F49: porcelanato 90x90
D50: lavabos e circulação | E50: =2+1.68+1.85+3.21+2.38+2.73+5.05 -> 18.9 | F50: porcelanato 90x90
D51: hall | E51: =15.02 -> 15.02 | F51: porcelanato 90x90
D52: academia | E52: 42.59 | F52: vinilico
...

Sheet Pintura Interna
A2: ORÇAMENTO PARAMÉTRICO PINTURA INTERNA
A7: Documento | B7: ='Dados Gerais'!B7 -> CTN-BRS-139 - Gerenciamento executivo_R00
A8: Cliente | B8: ='Dados Gerais'!B8 -> Brasin
A9: Obra | B9: ='Dados Gerais'!B9 -> 139 | G9: UC | H9: 00 | I9: Status | J9: Em andamento
A10: Data | B10: ='Dados Gerais'!B10 -> 45006 | G10: Revisão | H10: R00 | I10: Resp.
A12: PINTURA INTERNA - OPÇÃO 1
A14: Descrição | D14: Quantidade | F14: Parâmetro | H14: Referência | I14: Valor total
A15: Pintura piso acrílica | D15: ='Acabamentos de Piso e Parede'!K33 -> 828.18 | E15: m2 | F15: 6 | G15: R$ / m² | H15: Média | I15: =D15*F15 -> 4969.08
A16: Pintura piso epoxi | D16: ='Acabamentos de Piso e Parede'!E46*5 -> 3870.1 | E16: m2 | F16: 70 | G16: R$ / m² | H16: Média | I16: =D16*F16 -> 270907
A17: Pintura Interna | D17: 1 | E17: vb | F17: 90 | G17: R$ / AC | H17: Média | I17: =+F17*'Dados Gerais'!$E$15 -> 1505504.7
A18: TOTAL | I18: =SUM(I16:J17) -> 1776411.7
A20: TOTAL IMPERMEABILIZAÇÃO | I20: =I18 -> 1776411.7 | K20: =I20/'Dados Gerais'!E15 -> 106.19499

Sheet Esquadrias
A2: ORÇAMENTO PARAMÉTRICO ESQUADRIAS
A7: Documento | B7: ='Dados Gerais'!B7 -> CTN-BRS-139 - Gerenciamento executivo_R00
A8: Cliente | B8: ='Dados Gerais'!B8 -> Brasin
A9: Obra | B9: ='Dados Gerais'!B9 -> 139 | G9: UC | H9: 00 | I9: Status | J9: Em andamento
A10: Data | B10: ='Dados Gerais'!B10 -> 45006 | G10: Revisão | H10: R00 | I10: Resp.
A12: ESQUADRIAS
A14: Descrição | D14: Quantidade | F14: Parâmetro | H14: Referência | I14: Valor total | M14: Linha gold
A15: Esquadrias de Alumínio | D15: 134.86 | E15: m² | F15: 1200 | G15: R$ / m² | H15: Média | I15: =F15*D15 -> 161832 | M15: Persiama integrada
A16: Janelas com persiana integrada | D16: 289.8 | E16: m² | F16: 1600 | G16: R$ / m² | H16: Média | I16: =F16*D16 -> 463680
A17: Pele de vidro | D17: 4350.4 | E17: m² | F17: 1000 | G17: R$ / m² | H17: Média | I17: =F17*D17 -> 4350400
A18: PCF | D18: 103 | E18: un | F18: 1750 | G18: R$ / un | H18: Média | I18: =F18*D18 -> 180250 | M18: Portas de madeira
A19: Serralherias | D19: 1 | E19: vb | F19: 400000 | G19: R$ | H19: Média | I19: =+D19*F19 -> 400000 | M19: Fechadura eletronica
A20: Guarda-corpo - vidro | D20: =28.16+1122.92 -> 1151.08 | E20: m² | F20: 1000 | G20: R$ / m² | H20: Média | I20: =+F20*D20 -> 1151080 | M20: Pele de vidro na fachada
A21: Gradis | D21: =340.58 -> 340.58 | E21: m² | F21: 1000 | G21: R$ / m² | H21: Média | I21: =+F21*D21 -> 340580
A22: Brises | D22: 146.81 | E22: m² | F22: 2000 | G22: R$ / m² | H22: Média | I22: =+F22*D22 -> 293620
A23: Portão de alumínio | D23: 1 | E23: un | F23: 16000 | G23: R$ / un | H23: Média | I23: =+F23*D23 -> 16000 | M23: Brise nas áreas de garagem, pendente definição de material de brises, a princípio está projetado como metálico.
A24: Fechadura biométrica | D24: 40 | E24: un | F24: 1300 | G24: R$ / un | H24: Média | I24: =F24*D24 -> 52000
A25: Esquadrias de Madeira | D25: 453 | E25: un | F25: 2200 | G25: R$ / un | H25: Média | I25: =F25*D25 -> 996600
A26: TOTAL | I26: =SUM(I15:J25) -> 8406042
A29: TOTAL PINTURA | I29: =I26 -> 8406042 | K29: =I29/'Dados Gerais'!E15 -> 502.51838
D34: 11735.92
D35: =D15+D16+D17+D22 -> 4921.87
D36: =D34-D35 -> 6814.05

Sheet Auxiliar
A2: 2 Portões acesso garagem - Área: 9,2m² x 2 = 18,4m² | B2: 2 | C2: portão | D2: 18.4
A3: 2 portas corta-fogo 1 folha | B3: 2 | C3: pcf
A4: 1 porta de correr alumínio 2 folhas – Área: 3,465m² | B4: 1 | C4: porta alumínio | D4: 3.465
A5: 1 porta de correr alumínio 2 folhas – Área: 1,7325m² | B5: 1 | C5: porta alumínio | D5: 1.7325 | G5: Guarda alumínio | H5: =SUMIF(C:C,G5,D:D) -> 400.5221
A6: 2 portas de abrir alumínio 2 folhas – Área: 2,6376m² x 2 = 5,2752m² | B6: 2 | C6: porta alumínio | D6: 5.2752 | G6: janela | H6: =SUMIF(C:C,G6,D:D) -> 1895.06
A7: 1 porta de abrir alumínio 2 folhas – Área: 4,1916m² | B7: 1 | C7: porta alumínio | D7: 4.1916 | G7: madeira | H7: =SUMIF(C:C,G7,B:B) -> 218
A8: 1 porta pivotante | B8: 1 | C8: pivotante | G8: pcf | H8: =SUMIF(C:C,G8,B:B) -> 60
A9: 19 portas de abrir madeira 1 folha | B9: 19 | C9: madeira | G9: pivotante | H9: =SUMIF(C:C,G9,B:B) -> 1
A10: 3 portas de abrir vidro 1 folha – Área: 2,1m² x 3 = 6,3m² | B10: 3 | C10: porta alumínio | D10: 6.3 | G10: porta alumínio | H10: =SUMIF(C:C,G10,D:D) -> 46.62
A11: 2 portas de abrir vidro 1 folha – Área: 1,89m² x 2 = 3,78m² | B11: 2 | C11: porta alumínio | D11: 3.78 | G11: portão | H11: =SUMIF(C:C,G11,B:B) -> 2
A12: 1 porta de abrir alumínio 1 folha – Área: 2,0076m² | B12: 1 | C12: porta alumínio | D12: 2.0076 | G12: gradil | H12: =SUMIF(C:C,G12,D:D) -> 113.88
A13: Janelas – Área: 3,75 + 4,875 + 2,5 + 1,1 + 1,2 + 5,5402 + 4,4874 = 23,4526m² | C13: janela | D13: 23.4526 | G13: Brise | H13: 109.3146
A14: Muro de vidro – Área: 7,0774 + 5,485 + 3,43 + 4,8138 = 20,8062m² | C14: Guarda alumínio | D14: 20.8062
A15: 8 portas corta-fogo 1 folha | B15: 8 | C15: pcf
A16: Janelas – Area: (1,1 + 1,2 + 28,7391) x 4 = 124,1564m² | C16: janela | D16: 124.1564
A17: 2 portas corta-fogo 1 folha | B17: 2 | C17: pcf
A18: 2 portas de abrir alumínio 1 folha – Área: 1,47m² x 2 = 2,94m² | B18: 2 | C18: porta alumínio | D18: 2.94
A19: 2 portas de abrir vidro 1 folha – Área: 1,89m² x 2 = 3,78m² | B19: 2 | C19: porta alumínio | D19: 3.78
A20: 5 portas de abrir madeira 1 folha | B20: 5 | C20: madeira
A21: 1 janela-porta de correr vidro – Área: 14,7348m² | B21: 1 | C21: janela | D21: 14.7348
A22: Janelas – Área: 1,2894 + 1,2894 + 23,46 + 1,854 + 5,562 + 5,562 + 1,854 + 1,854 + 1,1 + 1,2 = 45,0248m² | C22: janela | D22: 45.0248
A23: Guarda corpo vidro – Área: 7,5299 + 5,7955 + 6,5555 = 19,8809m² | C23: Guarda alumínio | D23: 19.8809
A24: 38 portas corta-fogo 1 folha | B24: 38 | C24: pcf
A25: 171 portas de abrir madeira 1 folha | B25: 171 | C25: madeira
A26: 19 porta de abrir alumínio 1 folha – Área: 1,26m² x 19 = 23,94m² | B26: 19 | C26: porta alumínio | D26: 23.94
A27: 19 janela-porta de correr vidro 5 folhas - Área: 25,4205m² x 19 = 482,9895m² | B27: 19 | C27: janela | D27: 482.9895
A28: 19 janela-porta de correr vidro 5 folhas - Área: 17,8284m² x 19 = 338,7396m² | B28: 19 | C28: janela | D28: 338.7396
A29: Janelas – Área: 1,1 + 1,1 + 1,2 + 1,92 + 0,36 + 2,781 + 2,781 + 1,854 + 1,854 + 5,562 + 5,562 + 1,854 = 27,928m² x 19 = 530,632m² | C29: janela | D29: 530.632
A30: Guarda corpo metálico – Área: 4,745m² x 19 = 90,155m² - Perímetro: 3,65m x 19 = 69,35m | C30: gradil | D30: 90.155
A31: Guarda corpo vidro – Área: 15,645m² x 19 = 297,255m² - Perímetro: 14,9m x 19 = 283,1m | C31: Guarda alumínio | D31: 297.255
A32: 2 portas corta-fogo 1 folha | B32: 2 | C32: pcf
A33: 2 portas de abrir madeira 1 folha | B33: 2 | C33: madeira
A34: 1 porta de abrir alumínio 1 folha – Área: 1,26m² | B34: 1 | C34: porta alumínio | D34: 1.26
A35: 1 janela-porta de correr vidro 3 folhas - Área: 15,21m² | B35: 1 | C35: janela | D35: 15.21
A36: 1 janela-porta de correr vidro 5 folhas - Área: 25,4205m² | B36: 1 | C36: janela | D36: 25.4205
A37: 1 janela-porta de correr vidro 5 folhas - Área: 17,8284m² | B37: 1 | C37: janela | D37: 17.8284
A38: Janelas – Área: 1,1 + 1,2 + 1,1 + 1,92 + 0,36 + 2,781 + 2,781 + 1,854 + 1,854 + 5,562 + 5,562 + 1,854 = 27,928m² | C38: janela | D38: 27.928
A39: Guarda corpo metálico – Área: 4,745m² - Perímetro: 3,65m | C39: gradil | D39: 4.745
A40: Guarda corpo vidro – Área: 15,645m² - Perímetro: 14,9m | C40: Guarda alumínio | D40: 15.645
A41: 2 portas corta-fogo 1 folha | B41: 2 | C41: pcf
...

Sheet Cobertura
A2: ORÇAMENTO PARAMÉTRICO COBERTURA
A7: Documento | B7: ='Dados Gerais'!B7 -> CTN-BRS-139 - Gerenciamento executivo_R00
A8: Cliente | B8: ='Dados Gerais'!B8 -> Brasin
A9: Obra | B9: ='Dados Gerais'!B9 -> 139 | G9: UC | H9: 00 | I9: Status | J9: Em andamento
A10: Data | B10: ='Dados Gerais'!B10 -> 45006 | G10: Revisão | H10: R00 | I10: Resp.
A12: COBERTURA
A14: Descrição | D14: Quantidade | F14: Parâmetro | H14: Referência | I14: Valor total
A15: Cobertura | D15: 0 | E15: m² | F15: 260 | G15: R$ / m² | H15: - | I15: =+F15*D15 -> 0
A16: TOTAL | I16: =SUM(I15:J15) -> 0
B18: Área
A19: Ático | B19: 15 | J19: =I16 -> 0 | K19: =J19/'[1]Dados Gerais'!E15 -> 0

Sheet Rev. Fachada
A2: ORÇAMENTO PARAMÉTRICO REVESTIMENTOS E ACABAMENTOS DE FACHADA
A7: Documento | B7: ='Dados Gerais'!B7 -> CTN-BRS-139 - Gerenciamento executivo_R00
A8: Cliente | B8: ='Dados Gerais'!B8 -> Brasin
A9: Obra | B9: ='Dados Gerais'!B9 -> 139 | G9: UC | H9: 00 | I9: Status | J9: Em andamento
A10: Data | B10: ='Dados Gerais'!B10 -> 45006 | G10: Revisão | H10: R00 | I10: Resp.
A12: REVESTIMENTOS ARGAMASSADOS
A14: Descrição | D14: Quantidade | F14: Parâmetro | H14: Referência | I14: Valor total
A15: Chapisco e reboco | D15: ='[2]EPC''s'!$D$42 -> 11735.918 | E15: m² | F15: 55 | G15: R$ / m² | H15: - | I15: =D15*F15 -> 645475.5
A16: TOTAL | I16: =SUM(I15:J15) -> 645475.5
A18: PINTURA
M19: =22957.279-146.813-330.47-10.48-15.182 -> 22454.334
A20: Descrição | D20: Quantidade | F20: Parâmetro | H20: Referência | I20: Valor total
A21: Textura - micro pedras e resina | D21: =D15-D27-D28 -> 11243.874 | E21: m² | F21: =(321.24/1.3)+30 -> 277.10769 | G21: R$ / m² | H21: - | I21: =+D21*F21 -> 3115764
A22: TOTAL | I22: =SUM(I21) -> 3115764 | M22: FACHADA 1 | N22: =(20.51+13.74)*0.94+(20.51+13.74)*0.5*2+19.91*0.5*2+19.91*2.32*2+0.8*19.91 -> 194.6654
M23: FACHADA 2 | N23: =(18.42+13.86)*0.94+(18.42+13.86)*0.5*2+23.16*0.5*2+23.16*1.42+23.16*1.9+3.4*23.16 -> 241.4184
A24: REVESTIMENTOS ESPECIAIS | M24: FACHADA 3 | N24: =(18.42+13.86)*0.94+(18.42+13.86)*0.5*2+65.17*0.5*2+65.17*1.42+3.4*(137.27-72.58) -> 440.2806
A26: Descrição | D26: Quantidade | F26: Parâmetro | H26: Referência | I26: Valor total
A27: Pastilha | D27: =56.914+253.717+25.93 -> 336.561 | E27: m² | F27: 210 | G27: R$ / m² | H27: Média | I27: =F27*D27 -> 70677.81
A28: Concreto aparente | D28: =55.784+19.119+16.713+18.676+29.1+16.091 -> 155.483 | E28: m² | F28: 160 | G28: R$ / m² | H28: Média | I28: =F28*D28 -> 24877.28
A29: ACM | D29: =N22+N23+N24 -> 876.3644 | E29: m² | F29: 700 | G29: R$ / m² | H29: Média | I29: =F29*D29 -> 613455.08
I30: =SUM(I27:J29) -> 709010.17
A33: TOTAL FACHADA | I33: =I30+I22+I16 -> 4470249.7 | K33: =I33/'Dados Gerais'!E15 -> 267.23429

Sheet Complementares
A2: ORÇAMENTO PARAMÉTRICO EQUIPAMENTOS
A7: Documento | B7: ='Dados Gerais'!B7 -> CTN-BRS-139 - Gerenciamento executivo_R00
A8: Cliente | B8: ='Dados Gerais'!B8 -> Brasin
A9: Obra | B9: ='Dados Gerais'!B9 -> 139 | G9: UC | H9: 00 | I9: Status | J9: Em andamento
A10: Data | B10: ='Dados Gerais'!B10 -> 45006 | G10: Revisão | H10: R00 | I10: Resp.
A12: SERVIÇOS COMPLEMENTARES
A14: Descrição | D14: Quantidade | F14: Parâmetro | H14: Referência | I14: Valor total
A15: Móveis e decoração | D15: 1 | E15: vb | F15: 2400 | G15: R$ / AL | H15: Média | I15: =D15*F15*'Dados Gerais'!$E$22 -> 2776224
A16: Comunicação visual | D16: 1 | E16: vb | F16: 10 | G16: R$ / AC | H16: Média | I16: =D16*F16*'Dados Gerais'!$E$15 -> 167278.3
A17: Paisagismo | D17: 1 | E17: vb | F17: 17 | G17: R$ / AC | H17: Média | I17: =D17*F17*'Dados Gerais'!$E$15 -> 284373.11
A18: Limpeza | D18: 1 | E18: vb | F18: 15 | G18: R$ / AC | H18: Média | I18: =D18*F18*'Dados Gerais'!$E$15 -> 250917.45
A19: TOTAL | I19: =SUM(I15:J18) -> 3478792.9
A22: TOTAL ACABAMENTOS | I22: =I19 -> 3478792.9 | K22: =I22/'Dados Gerais'!E15 -> 207.96438
