Workbook
Name \0: #REF!
Name \0: #REF!
Name \0: #REF!
Name \0: #REF!
Name \0: #REF!
Name \0: #REF!
Name \0: #REF!
Name \0: #REF!
Name \0: #REF!
Name \1: #REF!
Name \1: #REF!
Name \a: #REF!
Name \a: #REF!
Name \a: #REF!
Name \b: #REF!
Name \b: #REF!
Name \c: #REF!
Name \c: #REF!
Name \d: #REF!
Name \d: #REF!
Name \e: #REF!
Name \e: #REF!
Name \i: #REF!
Name \i: #REF!
Name \J: #REF!
Name \J: #REF!
Name \k: #REF!
Name \k: #REF!
Name \l: #N/A
Name \m: #REF!
Name \m: #REF!
Name \m: #REF!
Name \o: #REF!
Name \o: #REF!
Name \p: #REF!
Name \p: #REF!
Name \r: #REF!
Name \r: #REF!
Name \T: #REF!
Name \T: #REF!
Name \z: #REF!
Name \z: #REF!
Name ______ACR10: #REF!
Name ______ACR10: #REF!
Name ______ACR15: #REF!
Name ______ACR15: #REF!
Name ______acr20: #REF!
Name ______acr20: #REF!
Name ______acr5: #REF!
Name ______acr5: #REF!
Name ______ARQ1: #REF!
Name ______ARQ1: #REF!
Name ______QT100: #REF!
Name ______QT100: #REF!
Name ______QT2: #REF!
Name ______QT2: #REF!
Name ______QT3: #REF!
Name ______QT3: #REF!
Name ______QT4: #REF!
Name ______QT4: #REF!

Sheet DADOS_INICIAIS
A1: Obra | B1: Connect
A2: Empresa | B2: Passe
A3: Revisão | B3: R00
A4: Arquitetura base | B4: PAS_CNC_ARQ_EP_R08
A5: DADOS OBRA
B7: Descrição | C7: Identificador | D7: Unidade | F7: Quantidade
B8: ÁREA DO TERRENO | C8: AT | D8: M2 | F8: 9027.79
B9: ÁREA TOTAL CONSTRUÍDA | C9: AC | D9: M2 | F9: 73831.22
B10: 3º SUBSOLO | D10: M2 | E10: 4679.95
B11: 2º SUBSOLO | D11: M2 | E11: 4528.14
B12: 1º SUBSOLO | D12: M2 | E12: 4528.14
B13: TERREO | D13: M2 | E13: 5529.88
B14: MEZANINO | D14: M2 | E14: 2740.07
B15: SOBRELOJA | D15: M2 | E15: 4855.85
B16: LAZER | D16: M2 | E16: 5014.3
B17: TIPO (X22) | D17: M2 | E17: =618.71*22 -> 13611.62 | F17: =682.92*22 -> 15024.24
B18: LAZER SUPERIOR | D18: M2 | E18: 1554.82
B19: BARRILETE 1 | D19: M2 | E19: =76.57*2 -> 153.14
B20: TIPO 2 (X16) | D20: M2 | F20: =682.92*16 -> 10926.72
B21: BARRILETE 2 | D21: M2 | F21: =111.98*2 -> 223.96
B22: UNIDADES RESIDENCIAIS | C22: UR | D22: UN | F22: 596 | G22: =F9-F34-F33 -> 50078.89
B23: Dormitórios | C23: dorm | D23: UN | F23: =480+90*2+30*3 -> 750
B24: Banheiros | C24: ban | D24: UN
B25: UNIDADES COMERCIAIS | C25: UC | D25: UN | F25: 2
B26: Churrasqueiras | C26: CHU | D26: UN
B27: NÚMERO TOTAL DE PAVIMENTOS | C27: NP | D27: UN | F27: 42
B28: NÚMERO DE PAVIMENTOS TIPO | C28: NPT | D28: UN | F28: =22+16 -> 38
B29: NÚMERO DE PAVIMENTOS TIPO DIFERENCIADOS | C29: NPD | D29: UN | F29: 1 | G29: LAZER SUPERIOR
B30: NÚMERO DE PAVIMENTOS DUPLEX | C30: ND | D30: UN | F30: 0
B31: ÁREA DE PROJEÇÃO DA TORRE | C31: APT | D31: M2 | E31: 669.946 | F31: 690.612
B32: PERÍMETRO DE PROJEÇÃO DA TORRE | C32: PPT | D32: M | E32: 112.63 | F32: 116.82
B33: ÁREA DE LAZER | C33: AL | D33: M2 | F33: =5014.3-956.89+1554.82 -> 5612.23
B34: ÁREA DO EMBASAMENTO | C34: AE | D34: M2 | F34: =E13+E14+E15+E16 -> 18140.1
B35: ÁREA DE SUBSOLOS | C35: S | D35: M2 | F35: =E10+E11+E12 -> 13736.23
B36: NÚMERO DE SUBSOLOS | C36: NS | D36: UN | F36: 3
B37: ÁREA DE PROJEÇÃO DO EMBASAMENTO | C37: APE | D37: M2 | F37: =E10 -> 4679.95 | G37: =F37/F9 -> 0.063387142
B38: PERÍMETRO DE PROJEÇÃO DE EMBAMENTO | C38: PE | D38: M | F38: 349.8
B39: NÚMERO DE PAVIMENTOS DE EMBASAMENTO | C39: NE | D39: UN | F39: 4

Sheet AREAS
B3: FASE | C3: Identificador | D3: Unidade | E3: FASE 1 | F3: FASE 2 | G3: FASE 3 - TORRE 1 | H3: FASE 4 - TORRE 2 | I3: Quantidade
B4: ÁREA DO TERRENO | C4: AT | D4: M2 | I4: 9830.25
B5: ÁREA TOTAL CONSTRUÍDA | C5: AC | D5: M2 | E5: =E6 -> 4116.32 | F5: =SUM(F6:F18) -> 3791.55 | G5: =SUM(G6:G18) -> 38610.175 | H5: =SUM(H6:H18) -> 34203.985 | I5: =G5+H5+F5+E5 -> 80722.03
B6: MALL 1 | D6: M2 | E6: =7907.87-F7 -> 4116.32
B7: MALL 2 | D7: M2 | F7: =3298.91+492.64 -> 3791.55
B8: 2º SUBSOLO | D8: M2 | G8: 6194.79
B9: 1º SUBSOLO | D9: M2 | G9: 6239.85
B10: TERREO | D10: M2 | G10: =3933.19+800.4 -> 4733.59
B11: MEZANINO | D11: M2 | G11: 1651.8
B12: SOBRELOJA | D12: M2 | G12: =3933.19/2 -> 1966.595 | H12: =G12 -> 1966.595
B13: LAZER | D13: M2 | G13: =4031.41/2 -> 2015.705 | H13: =G13 -> 2015.705
B14: TIPO 1/LAZER | D14: M2 | G14: =1717.77/2 -> 858.885 | H14: =G14 -> 858.885
B15: TIPO (X22) | D15: M2 | G15: 14749.96 | H15: =(28360.59/(22+18))*22 -> 15598.325
B16: BARRILETE 1 /LAZER SUPERIOR | D16: M2 | G16: =131.41+67.59 -> 199 | H16: 753.61
B17: TIPO 2 (X18) | D17: M2 | H17: =(28360.59/(22+18))*18 -> 12762.266
B18: BARRILETE 2 | D18: M2 | H18: =159+89.6 -> 248.6
B19: UNIDADES RESIDENCIAIS | C19: UR | D19: UN | E19: 0 | F19: 0 | G19: =22*10 -> 220 | H19: 382
B20: Dormitórios | C20: dorm | D20: UN
B21: Banheiros | C21: ban | D21: UN
B22: UNIDADES COMERCIAIS | C22: UC | D22: UN | E22: 15
B23: Churrasqueiras | C23: CHU | D23: UN
B24: NÚMERO TOTAL DE PAVIMENTOS | C24: NP | D24: UN | E24: 3 | F24: 3 | G24: 29 | H24: 43
B25: NÚMERO DE PAVIMENTOS TIPO | C25: NPT | D25: UN | G25: 22 | H25: 40
B26: NÚMERO DE PAVIMENTOS TIPO DIFERENCIADOS | C26: NPD | D26: UN | G26: 4 | H26: 3
B27: NÚMERO DE PAVIMENTOS DUPLEX | C27: ND | D27: UN
B28: ÁREA DE PROJEÇÃO DA TORRE | C28: APT | D28: M2 | G28: 683.1 | H28: 695.35
B29: PERÍMETRO DE PROJEÇÃO DA TORRE | C29: PPT | D29: M | G29: 112.63 | H29: 116.82
B30: ÁREA DE LAZER | C30: AL | D30: M2 | G30: =G13+G16 -> 2214.705 | H30: =H13+H16 -> 2769.315
B31: ÁREA DO EMBASAMENTO | C31: AE | D31: M2 | E31: =E7 -> 0 | G31: =G10+G11+G12+G13 -> 10367.69 | H31: =H12+H13 -> 3982.3
B32: ÁREA DE SUBSOLOS | C32: S | D32: M2 | G32: =G8+G9 -> 12434.64
B33: NÚMERO DE SUBSOLOS | C33: NS | D33: UN | G33: 2
B34: ÁREA DE PROJEÇÃO DO EMBASAMENTO | C34: APE | D34: M2 | G34: =G8 -> 6194.79
B35: PERÍMETRO DE PROJEÇÃO DE EMBAMENTO | C35: PE | D35: M | G35: 349.8
B36: NÚMERO DE PAVIMENTOS DE EMBASAMENTO | C36: NE | D36: UN | G36: 4

Sheet MOVIMENTAÇÃO_DE_TERRA
A2: MOVIMENTAÇÃO DE TERRA
A3: Data | B3: 45643
A4: Arquivo base | B4: -
A6: ESCAVAÇÃO VERTICAL DE SUBSOLO
A8: Descrição | B8: Área de subsolo (m²) | C8: Altura do subsolo (m) | D8: Volume total de escavação (m3) | E8: Preço unitário de escavação (R$ / m3) | F8: Valor total | G8: Observação
A9: Escavação | B9: =AREAS!G8 -> 6194.79 | C9: 6.76 | D9: =C9*B9 -> 41876.78 | E9: 2.66 | F9: =E9*D9*1.1 -> 122531.46
A10: Movimentação de bota-fora | B10: 1.3 | D10: =B10*D9 -> 54439.815 | E10: 20 | F10: =E10*D10*1.1 -> 1197675.9
A11: TOTAL | F11: =SUM(F9:F10) -> 1320207.4
A13: REBAIXAMENTO DE LENÇOL FREÁTICO
A15: Descrição | B15: Quantidade (dias) | E15: Preço unitário de rebaixamento (R$ / dias) | F15: Valor total | G15: Observação
A16: Rebaixamento de lençol | B16: 0 | E16: 200 | F16: =B16*E16*1.1 -> 0
A17: TOTAL | F17: =SUM(F16:F16) -> 0
A19: ESCAVAÇÃO E REATERRO DE VALAS
A21: Descrição | B21: Parâmetro | D21: Volume total de escavação (m3) | E21: Preço unitário (R$ / m3) | F21: Valor total | G21: Observação
A22: Escavação mecanizada para blocos e baldrames | B22: 1.3 | C22: m³ / Vol infra | D22: =B22*INFRAESTRUTURA!D23 -> 2433.574 | E22: 60 | F22: =E22*D22*1.1 -> 160615.88
A23: Reaterro para blocos e baldrames | B23: 0.6 | C23: m³ / Vol Escavação | D23: =D22-INFRAESTRUTURA!D23 -> 561.594 | E23: 20 | F23: =E23*D23*1.1 -> 12355.068
A24: Movimentação de bota-fora | B24: 1.3 | D24: =(D22-D23)*B24 -> 2433.574 | E24: 20 | F24: =E24*D24*1.1 -> 53538.628
A25: Movimentação de terra das estacas | B25: 1.3 | C25: m³ | D25: =INFRAESTRUTURA!D13*B25 -> 6432.411 | E25: 20 | F25: =E25*D25*1.1 -> 141513.04
A26: TOTAL | F26: =SUM(F22:F25) -> 368022.62
A28: REGULARIZAÇÃO E APILOAMENTO DE FUNDO DE VALAS
A30: Descrição | B30: Parâmetro | D30: Área de lastro (m²) | E30: Preço unitário (R$ / m2) | F30: Valor total | G30: Observação
A31: Lastro de concreto magto e=5cm | B31: 0.8 | C31: m² / APE | D31: =B31*DADOS_INICIAIS!F37 -> 3743.96 | E31: =370*0.05 -> 18.5 | F31: =E31*D31*1.1 -> 76189.586 | H31: =F31/DADOS_INICIAIS!F37 -> 16.28
A32: TOTAL | F32: =SUM(F31:F31) -> 76189.586
A34: TOTAL MOVIMENTAÇÃO DE TERRA | F34: =F11+F17+F26+F32 -> 1764419.6 | G34: =F34/(AREAS!H5+AREAS!G5) -> 24.23182

Sheet CONTENÇÕES
A3: CONTENÇÃO
A4: Data
A5: Arquivo base
A7: CORTINA DE ESTACAS
A9: Descrição | B9: Parâmetro | D9: Quantidade | F9: Preço unitário | G9: Valor total
A10: Número de Estacas | B10: 0.15 | C10: un / APE | D10: =B10*DADOS_INICIAIS!F37 -> 701.9925 | E10: un
A11: Estaca Hélice Continua Diâmetro 40 | B11: 0.1 | D11: =B11*$D$10 -> 70.19925 | E11: un
B12: 20 | C12: m/un | D12: =B12*D11 -> 1403.985 | E12: m | G12: =F12*D12 -> 0
A13: Estaca Hélice Continua Diâmetro 50 | B13: 0.5 | D13: =B13*$D$10 -> 350.99625 | E13: un
B14: 20 | C14: m/un | D14: =B14*D13 -> 7019.925 | E14: m | G14: =F14*D14 -> 0
A15: Estaca Hélice Continua Diâmetro 60 | B15: 0.4 | C15: un / APE | D15: =B15*$D$10 -> 280.797 | E15: un
B16: 20 | C16: m/un | D16: =B16*D15 -> 5615.94 | E16: m | G16: =F16*D16 -> 0
A17: Concreto | B17: =(PI()*0.4^2)/4*D14+(PI()*0.5^2)/4*D16+(PI()*0.6^2)/4*D12 -> 2381.8044 | C17: un / APE | D17: =(PI()*0.4^2)/4*D14+(PI()*0.5^2)/4*D16+(PI()*0.6^2)/4*D12 -> 2381.8044 | E17: m³ | G17: =F17*D17 -> 0
A18: Armação 6,3mm | B18: 1.6575131 | C18: kg / m³ | D18: =B18*D17 -> 3947.8721 | E18: kg | G18: =F18*D18 -> 0
A19: Armação 16mm | B19: 10.178338 | C19: kg / m³ | D19: =B19*D17 -> 24242.81 | E19: kg | G19: =F19*D19 -> 0
A20: Mobilização | B20: 1 | C20: vb | D20: 1 | E20: vb | G20: =F20*D20 -> 0
A21: TOTAL | G21: =SUM(G10:G20) -> 0
A23: PAREDE DE CONCRETO
A25: Descrição | B25: Parâmetro | D25: Quantidade | F25: Preço unitário | G25: Valor total
A26: Fabricação, montagem e desmontagem de forma para blocos e baldrames resinado | B26: 2.1 | C26: m² / APE | D26: =B26*DADOS_INICIAIS!F37 -> 9827.895 | E26: m² | G26: =F26*D26 -> 0
A27: Concreto | B27: 0.65 | C27: m³ / APE | D27: =B27*DADOS_INICIAIS!F37 -> 3041.9675 | E27: m³ | G27: =F27*D27 -> 0
A28: Armação | B28: 110 | C28: kg / m³ | D28: =B28*D27 -> 334616.43 | E28: kg | G28: =F28*D28 -> 0
A29: Mão de obra | B29: =SUPRAESTRUTURA!B16*1.5 -> 315 | C29: R$ / APE | D29: =DADOS_INICIAIS!F37 -> 4679.95 | E29: m² | F29: =B29 -> 315 | G29: =F29*D29 -> 1474184.2
A30: TOTAL | G30: =SUM(G26:G29) -> 1474184.2
A33: PAREDE DIAFRAGMA
A35: Descrição | B35: Parâmetro | D35: Quantidade | F35: Preço unitário | G35: Valor total
A36: Fabricação, montagem e desmontagem de forma para blocos e baldrames resinado | B36: 2.1 | C36: m² / APE | D36: =B36*DADOS_INICIAIS!F47 -> 0 | E36: m² | G36: =F36*D36 -> 0
A37: Concreto | B37: 0.65 | C37: m³ / APE | D37: =B37*DADOS_INICIAIS!F47 -> 0 | E37: m³ | G37: =F37*D37 -> 0
A38: Armação | B38: 110 | C38: kg / m³ | D38: =B38*D37 -> 0 | E38: kg | G38: =F38*D38 -> 0
A39: Mão de obra | B39: =SUPRAESTRUTURA!B87*1.5 -> 0 | C39: R$ / APE | D39: =DADOS_INICIAIS!F47 -> 0 | E39: m² | F39: =B39 -> 0 | G39: =F39*D39 -> 0
A40: TOTAL | G40: =SUM(G36:G39) -> 0
A46: TOTAL INFRAESTRUTURA | G46: =G21+G30 -> 1474184.2 | H46: =G46/DADOS_INICIAIS!F9 -> 19.96695

Sheet INFRAESTRUTURA
A3: INFRAESTRUTURA
A4: Data | B4: 45456
A5: Arquivo base | B5: -
A7: FUNDAÇÃO PROFUNDA
A9: Descrição | B9: Parâmetro | D9: Quantidade | F9: Preço unitário | G9: Valor total | H9: Observação
A10: Número de Estacas | B10: 0.0508 | C10: un / APE | D10: =ROUND(B10*AREAS!G34,0) -> 315 | E10: un | H10: Quantitativos trazidos de preliminar de fundação
A11: Estaca Escavada Diâmetro 100 | B11: 0 | D11: =D10 -> 315 | E11: un
B12: 20 | C12: m/un | D12: =B12*D11 -> 6300 | E12: m | F12: 500 | G12: =F12*D12*1.1 -> 3465000
A13: Concreto (40 Mpa) | B13: 1.2 | C13: perda | D13: =PI()*((1^2)/4)*D12 -> 4948.0084 | E13: m³ | F13: 520 | G13: =F13*D13*B13*1.1 -> 3396313
A14: Armação | B14: 27.5 | C14: kg / m³ | D14: =B14*D13 -> 136070.23 | E14: kg | F14: 7.62 | G14: =F14*D14*1.1 -> 1140540.7
A15: Mobilização | B15: 1 | C15: vb | D15: 1 | E15: vb | F15: 14500 | G15: =F15*D15*1.1 -> 15950
A16: Apoio e arrasamento de estacas | D16: =D10 -> 315 | E16: un | F16: 300 | G16: =F16*D16*1 -> 94500
A17: TOTAL | G17: =SUM(G12:G16) -> 8112303.7
A19: FUNDAÇÃO RASA
A21: Descrição | B21: Parâmetro | D21: Quantidade | F21: Preço unitário | G21: Valor total | H21: Observação
A22: Fabricação, montagem e desmontagem de forma para blocos e baldrames resinado | B22: 0.5 | C22: m² / APE | D22: =B22*DADOS_INICIAIS!F37 -> 2339.975 | E22: m² | F22: 68 | G22: =F22*D22*1.1 -> 175030.13 | H22: Definição de índice pelo Celebration
A23: Concreto (40 Mpa) | B23: 0.4 | C23: m³ / APE | D23: =B23*DADOS_INICIAIS!F37 -> 1871.98 | E23: m³ | F23: =514+44 -> 558 | G23: =F23*D23*1.05*1.1 -> 1206472.4 | H23: Definição de resitência trazida do Celebration da Passe
A24: Armação | B24: 90 | C24: kg / m³ | D24: =B24*D23 -> 168478.2 | E24: kg | F24: 7.62 | G24: =F24*D24*1.1 -> 1412184.3
A25: Mão de obra | B25: =SUPRAESTRUTURA!B16*1.5 -> 315 | C25: R$ / APE | D25: =DADOS_INICIAIS!F37 -> 4679.95 | E25: m² | F25: =B25 -> 315 | G25: =F25*D25*1.1 -> 1621602.7
A26: TOTAL | G26: =SUM(G22:G25) -> 4415289.5
A29: TOTAL INFRAESTRUTURA | G29: =G17+G26 -> 12527593 | H29: =G29/DADOS_INICIAIS!F9 -> 169.6788

Sheet CONTENÇÕES (2)
A3: CONTENÇÃO
A5: CORTINA DE ESTACAS
A7: Descrição | B7: Parâmetro | D7: Quantidade | F7: Preço unitário | G7: Valor total
A8: Número de Estacas | B8: 0.15 | C8: un / APE | D8: =B8*[4]DADOS_INICIAIS!F23 -> 303.6465 | E8: un
A9: Estaca Hélice Continua Diâmetro 40 | B9: 0.1 | D9: =B9*$D$8 -> 30.36465 | E9: un
B10: 20 | C10: m/un | D10: =B10*D9 -> 607.293 | E10: m | G10: =F10*D10 -> 0
A11: Estaca Hélice Continua Diâmetro 50 | B11: 0.5 | D11: =B11*$D$8 -> 151.82325 | E11: un
B12: 20 | C12: m/un | D12: =B12*D11 -> 3036.465 | E12: m | G12: =F12*D12 -> 0
A13: Estaca Hélice Continua Diâmetro 60 | B13: 0.4 | C13: un / APE | D13: =B13*$D$8 -> 121.4586 | E13: un
B14: 20 | C14: m/un | D14: =B14*D13 -> 2429.172 | E14: m | G14: =F14*D14 -> 0
A15: Concreto | B15: =(PI()*0.4^2)/4*D12+(PI()*0.5^2)/4*D14+(PI()*0.6^2)/4*D10 -> 1030.2483 | C15: un / APE | D15: =(PI()*0.4^2)/4*D12+(PI()*0.5^2)/4*D14+(PI()*0.6^2)/4*D10 -> 1030.2483 | E15: m³ | G15: =F15*D15 -> 0
A16: Armação 6,3mm | B16: 1.6575131 | C16: kg / m³ | D16: =B16*D15 -> 1707.6501 | E16: kg | G16: =F16*D16 -> 0
A17: Armação 16mm | B17: 10.178338 | C17: kg / m³ | D17: =B17*D15 -> 10486.215 | E17: kg | G17: =F17*D17 -> 0
A18: Mobilização | B18: 1 | C18: vb | D18: 1 | E18: vb | G18: =F18*D18 -> 0
A19: TOTAL | G19: =SUM(G8:G18) -> 0
A21: PAREDE DE CONCRETO
A23: Descrição | B23: Parâmetro | D23: Quantidade | F23: Preço unitário | G23: Valor total
A24: Área de Contenção | D24: =354.45*MOVIMENTAÇÃO_DE_TERRA!C9 -> 2396.082 | E24: m2 | H24: quantitativo de modelo (ambos subsolos)
A25: Fabricação, montagem e desmontagem de forma - resinado | B25: 2 | C25: m² | D25: =B25*D24 -> 4792.164 | E25: m² | F25: =206.56+0.130939 -> 206.69094 | G25: =F25*D25*1.1 -> 1089546.6
A26: Concreto | B26: 0.4 | C26: m | D26: =D24*B26 -> 958.4328 | E26: m³ | F26: =(514+44)*1.05 -> 585.9 | G26: =F26*D26*1.1 -> 617700.36 | H26: Custo Viva 4
A27: Armação | B27: 110 | C27: kg / m³ | D27: =B27*D26 -> 105427.61 | E27: kg | F27: 8 | G27: =F27*D27*1.1 -> 927762.95 | H27: Custo Viva 4
A28: Estrutura - drenagem | D28: 354.45 | E28: m | F28: 260 | G28: =F28*D28 -> 92157
A29: Mão de obra | B29: - | D29: =D24 -> 2396.082 | E29: m² | F29: 190 | G29: =F29*D29*1.1 -> 500781.14
A30: TOTAL | G30: =SUM(G25:G29) -> 3227948
A32: PERFIS METALICOS
A34: Descrição | B34: Parâmetro | D34: Quantidade | F34: Preço unitário | G34: Valor total | H34: Observação
A35: Perímetro de contenção | D35: 354.45 | E35: m | G35: =F35*D35*1.05 -> 0
A36: Perfis metálicos | B36: 360 | C36: kg/m | D36: =B36*D35 -> 127602 | E36: kg | F36: 10.42 | G36: =F36*D36*1.1 -> 1462574.1
A37: Chapa W250x38,5 | B37: =ROUND(D35/0.8,0) -> 443 | C37: un | D37: =38.5*0.1*B37 -> 1705.55 | E37: kg | F37: 12 | G37: =F37*D37*1.1 -> 22513.26
A38: Ancoragem CA-50 16mm | B38: 1.578 | C38: kg/m | D38: =(3*0.05*2+3*0.1)*B37 -> 265.8 | E38: m | F38: =6.5+0.35+0.1 -> 6.95 | G38: =F38*D38*B38*1.1 -> 3206.5607
A39: Placa dupla de concreto Pré-moldado | B39: =MOVIMENTAÇÃO_DE_TERRA!C9 -> 6.76 | C39: altura | D39: =D35*MOVIMENTAÇÃO_DE_TERRA!C9 -> 2396.082 | E39: m² | F39: 200 | G39: =F39*D39*1.1 -> 527138.04
A40: Forma | D40: =D35*0.4*2 -> 283.56 | E40: m² | F40: 68 | G40: =F40*D40*1.1 -> 21210.288 | I40: viga de coroamento 40x40
A41: Concreto (40 Mpa) | B41: 0.4 | C41: largura | D41: =D35*0.4*0.4 -> 56.712 | E41: m³ | F41: =(514+44)*1.05 -> 585.9 | G41: =F41*D41*1.05*1.1 -> 38377.833
A42: Armação | B42: 40 | C42: kg / m³ | D42: =B42*D41 -> 2268.48 | E42: kg | F42: 7.62 | G42: =F42*D42*1.1 -> 19014.399
A43: Cravação de perfis metálicos | D43: =B37*12 -> 5316 | E43: m | F43: 60 | G43: =F43*D43*1.1 -> 350856
A44: Estrutura - drenagem | D44: =D35 -> 354.45 | E44: m | F44: 260 | G44: =F44*D44 -> 92157
A45: Mão de obra contenção | D45: =D39 -> 2396.082 | E45: m² | F45: 790 | G45: =F45*D45*1.1 -> 2082195.3
A46: TOTAL | G46: =SUM(G36:G45) -> 4619242.8
A50: TOTAL CONTENÇÃO | G50: =G46 -> 4619242.8 | H50: =G50/AREAS!G5 -> 119.63796
B53: ATALAIA | C53: MONOLYT
...

Sheet SUPRAESTRUTURA
A3: SUPRAESTRUTURA
A4: Data | B4: 45456
A5: Arquivo base | B5: -
K6: LAJE MACIÇA | M6: LAJE NERVURADA | O6: VARIAÇÃO CUBETA-NERVURA | Q6: CARTESIAN (MACIÇA) | R6: CLIENTE (MACIÇA) | S6: VARIAÇÃO CUBETA-NERVURA | T6: PROJEÇÃO NERVURADA
A7: SUPRAESTRUTURA - LAJE NERVURADA - FASE 3 | J7: AREA | K7: 2384.4 | M7: 2384.4 | P7: AREA | Q7: 1 | R7: 1 | T7: 1
J8: CONCRETO | K8: 333.8 | L8: =K8/K7 -> 0.13999329 | M8: 240.8 | N8: =M8/M7 -> 0.10098977 | O8: =N8/L8 -> 0.72139005 | P8: CONCRETO | Q8: 0.22 | R8: 0.36 | S8: 0.72139005 | T8: =R8*O8 -> 0.25970042
A9: Descrição | B9: Parâmetro | D9: Quantidade | F9: Preço unitário | G9: Valor total | H9: Observação | J9: AÇO | K9: 29254 | L9: =K9/K8 -> 87.639305 | M9: 16595 | N9: =M9/M8 -> 68.916113 | O9: =N9/L9 -> 0.78636079 | P9: AÇO | Q9: 120 | R9: 115 | S9: 0.78636079 | T9: =R9*O9 -> 90.431491
A10: Fabricação forma | B10: 3 | C10: Jogos | D10: =(D11/AREAS!G24)*B10 -> 8585.791 | E10: m² | F10: 110 | G10: =F10*D10 -> 944437.01 | J10: FORMA | K10: 2414.2 | L10: =K10/K7 -> 1.0124979 | M10: 55.32 | N10: =M10/M7 -> 0.023200805 | O10: =N10/L10 -> 0.022914423 | P10: FORMA | Q10: 2.5 | R10: 2.2 | S10: 0.022914423 | T10: =R10-R10*O10 -> 2.1495883
A11: Montagem de forma | B11: =T10 -> 2.1495883 | C11: m² / AC | D11: =B11*AREAS!G5 -> 82995.979 | E11: m² | F11: 2.5 | G11: =F11*D11 -> 207489.95
A12: Escoramento | B12: 4 | C12: un / AE | D12: =AREAS!G5-AREAS!G8 -> 32415.385 | E12: m² | F12: 25 | G12: =F12*D12*1.1 -> 891423.09
A13: Concreto | B13: =T8 -> 0.25970042 | C13: m³ / AC | D13: =B13*AREAS!G5 -> 10027.079 | E13: m³ | F13: =514+44 -> 558 | G13: =F13*D13*1.05 -> 5874865.4
A14: Armadura Convencional para Estrutura | B14: =T9 -> 90.431491 | C14: kg / m³ | D14: =D13*B14 -> 906763.67 | E14: kg | F14: 7.62 | G14: =F14*D14 -> 6909539.2
A15: Locação de cubetas | D15: =AREAS!G5-AREAS!G8 -> 32415.385 | E15: M2 | F15: =71.8/2 -> 35.9 | G15: =F15*D15 -> 1163712.3
A16: Mão de obra - estrutura em concreto armado | B16: 210 | C16: R$ / AC | D16: =AREAS!G5 -> 38610.175 | E16: m² | F16: 210 | G16: =F16*D16*1.1 -> 8918950.4
A17: Perfuração de vigas | B17: 1500 | C17: R$ / NP | D17: 1 | E17: vb | F17: =B17*AREAS!G28 -> 1024650 | G17: =F17*D17*1.1 -> 1127115 | H17: Coeficiente originário do Gran Torino (R$ 160,00/un) | I17: Nova utiliza a verba de 1.500,00 por pav
A18: TOTAL | G18: =SUM(G10:G17) -> 26037532 | K18: =4160+1440+1120+2880+4800+91680+4000 -> 110080 | M18: =K18/21 -> 5241.9048
A19: SUPRAESTRUTURA - LAJE NERVURADA - FASE 4
A21: Descrição | B21: Parâmetro | D21: Quantidade | F21: Preço unitário | G21: Valor total | H21: Observação
A22: Fabricação forma | B22: 3 | C22: Jogos | D22: =(D23/AREAS!H24)*B22 -> 5129.6152 | E22: m² | F22: 110 | G22: =F22*D22 -> 564257.67
A23: Montagem de forma | B23: =B11 -> 2.1495883 | C23: m² / AC | D23: =B23*AREAS!H5 -> 73524.485 | E23: m² | F23: 2.5 | G23: =F23*D23 -> 183811.21
A24: Escoramento | B24: 4 | C24: un / AE | D24: =AREAS!H5 -> 34203.985 | E24: m² | F24: 25 | G24: =F24*D24*1.1 -> 940609.59
A25: Concreto | B25: =B13 -> 0.25970042 | C25: m³ / AC | D25: =B25*AREAS!H5 -> 8882.7893 | E25: m³ | F25: =F13 -> 558 | G25: =F25*D25*1.05 -> 5204426.2
A26: Armadura Convencional para Estrutura | B26: =B14 -> 90.431491 | C26: kg / m³ | D26: =D25*B26 -> 803283.87 | E26: kg | F26: 7.62 | G26: =F26*D26 -> 6121023.1
A27: Locação de cubetas | D27: =AREAS!H5 -> 34203.985 | E27: m² | F27: =71.8/2 -> 35.9 | G27: =F27*D27*1.1 -> 1350715.4
A28: Mão de obra - estrutura em concreto armado | B28: 210 | C28: R$ / AC | D28: =AREAS!H5 -> 34203.985 | E28: m² | F28: 210 | G28: =F28*D28*1.1 -> 7901120.5
A29: Perfuração de vigas | B29: 1500 | C29: R$ / NP | D29: 1 | E29: vb | F29: =B29*AREAS!H28 -> 1043025 | G29: =F29*D29*1.1 -> 1147327.5 | H29: Coeficiente originário do Gran Torino (R$ 160,00/un)
A30: TOTAL | G30: =SUM(G22:G29) -> 23413291
A32: SUPRAESTRUTURA - LAJE CUBETAS PROTENDIDAS
A34: Descrição | B34: Parâmetro | D34: Quantidade | F34: Preço unitário | G34: Valor total | H34: Observação
A35: Fabricação forma | B35: 2 | C35: Jogos | D35: =(D36/DADOS_INICIAIS!$F$27)*B35 -> 7383.122 | E35: m² | F35: 110 | G35: =F35*D35*1.1 -> 893357.76
A36: Montagem de forma | B36: 2.1 | C36: m² / AC | D36: =B36*DADOS_INICIAIS!$F$9 -> 155045.56 | E36: m² | F36: 2.5 | G36: =F36*D36*1.1 -> 426375.3
A37: Escoramento | B37: 3 | C37: un / APT*NPT | D37: =ROUNDUP(B37*DADOS_INICIAIS!$F$37*B35,0) -> 28080 | E37: un | F37: =17 -> 17 | G37: =F37*D37*1.1 -> 525096
A38: Cubetas | B38: 25 | C38: R$ / AC | D38: 1 | E38: vb | F38: =B38*DADOS_INICIAIS!$F$9 -> 1845780.5 | G38: =F38*D38*1.1 -> 2030358.6
A39: Protensão - lajes - materiais | B39: =12.3*0.8 -> 9.84 | C39: RS / m² | D39: =(DADOS_INICIAIS!$F$28+DADOS_INICIAIS!$F$29)*DADOS_INICIAIS!$F$31+DADOS_INICIAIS!$F$34 -> 45073.968 | E39: m² | F39: =B39 -> 9.84 | G39: =F39*D39*1.1 -> 487880.63
A40: Protensão - lajes - cabos | B40: =2.83*0.8 -> 2.264 | C40: kg / m² | D40: =B40*D39 -> 102047.46 | E40: kg | F40: 12.3 | G40: =F40*D40*1.1 -> 1380702.2
A41: Protensão - lajes - serviços | B41: 9000 | C41: und / pav | D41: =DADOS_INICIAIS!F27 -> 42 | E41: pav | F41: =B41 -> 9000 | G41: =F41*D41*1.1 -> 415800
A42: Concreto | B42: 0.18 | C42: m³ / AC | D42: =B42*DADOS_INICIAIS!$F$9 -> 13289.62 | E42: m³ | F42: =535+45 -> 580 | G42: =F42*D42*1.05*1.1 -> 8902716.2
A43: Cristalizante (reservatorios) | B43: 0.2 | D43: =B43*D42 -> 2657.9239 | E43: m³ | F43: =1.22*F42-F42 -> 127.6 | G43: =F43*D43*1.05*1.1 -> 391719.51
A44: Armadura Convencional para Estrutura | B44: 110 | C44: kg / m³ | D44: =D42*B44-D40 -> 1359810.7 | E44: kg | F44: 7.62 | G44: =F44*D44*1.1 -> 11397933
A45: Mão de obra - estrutura em concreto armado | B45: 240 | C45: R$ / AC | D45: =DADOS_INICIAIS!$F$9 -> 73831.22 | E45: m² | F45: =B45 -> 240 | G45: =F45*D45*1.1 -> 19491442
...

Sheet ALVENARIA
A3: PAREDES E PAINÉIS
A4: Data | B4: 45457
A5: Arquivo base | B5: -
A7: ALVENARIA - FASE 3
A9: Descrição | B9: Parâmetro | D9: Quantidade | F9: Preço unitário | G9: Valor total | H9: Observação
A10: Alvenaria embasamento | B10: 1 | C10: m² / AE | D10: =B10*AREAS!G31 -> 10367.69 | E10: m² | F10: 45 | G10: =F10*D10*1.1 -> 513200.66
A11: Alvenaria lazer | B11: 0.4 | C11: m² / AL | D11: =B11*AREAS!G30 -> 885.882 | E11: m² | F11: 45 | G11: =F11*D11*1.1 -> 43851.159
A12: Alvenaria tipo | B12: 1.65 | C12: m² / APT*(NPT+2ND) | D12: =B12*(AREAS!G15)*0.3 -> 7301.2302 | E12: m² | F12: 45 | G12: =F12*D12*1.1 -> 361410.89
A13: Drywall tipo | B13: 1.65 | C13: m² / APT*(NPT+2ND) | D13: =B13*(AREAS!G15)*0.7 -> 17036.204 | E13: m² | F13: 220 | G13: =F13*D13*1.1 -> 4122761.3
A14: Alvenaria escadas | B14: 0.2 | C14: m² / AC | D14: =B14*AREAS!G5 -> 7722.035 | E14: m² | F14: 70 | G14: =F14*D14*1.05*1.1 -> 624326.53 | H14: =D14*2 -> 15444.07
A15: Alvenaria cobertura / reservatório | B15: 0.8 | C15: m² / APT | D15: =B15*AREAS!#REF! -> #REF! | E15: m² | F15: 45 | G15: =F15*D15*1.1 -> #REF!
A16: Alvenaria refratárias | B16: 1.75 | C16: m² * CHU | D16: =B16*'SISTEMAS ESPECIAIS 3'!B11 -> 313.25 | E16: m² | F16: 210 | G16: =F16*D16*1.1 -> 72360.75
A17: Serviços complementares | B17: 12.5 | C17: R$ / m² | D17: =D10+D11+D12+D14+D15 -> #REF! | E17: m² | F17: =B17 -> 12.5 | G17: =F17*D17*1.1 -> #REF!
A18: Mão de obra | B18: 35 | C18: R$ / m² | D18: =D10+D11+D12+D14+D15 -> #REF! | E18: m² | F18: 35 | G18: =F18*D18*1.1 -> #REF!
A19: TOTAL | G19: =SUM(G10:G18) -> #REF! | K19: =4160+1440+1120+2880+4800+91680+4000 -> 110080 | L19: =K19/21 -> 5241.9048
A20: ALVENARIA - FASE4
A22: Descrição | B22: Parâmetro | D22: Quantidade | F22: Preço unitário | G22: Valor total | H22: Observação
A23: Alvenaria embasamento | B23: 1 | C23: m² / AE | E23: m² | F23: 45 | G23: =F23*D23*1.1 -> 0
A24: Alvenaria lazer | B24: 0.4 | C24: m² / AL | D24: =B24*AREAS!H30 -> 1107.726 | E24: m² | F24: 45 | G24: =F24*D24*1.1 -> 54832.437
A25: Alvenaria tipo | B25: 1.65 | C25: m² / APT*(NPT+2ND) | D25: =B25*(AREAS!H15+AREAS!H17)*0.3 -> 14038.492 | E25: m² | F25: 45 | G25: =F25*D25*1.1 -> 694905.36
A26: Drywall tipo | B26: 1.65 | C26: m² / APT*(NPT+2ND) | D26: =B26*(AREAS!H15+AREAS!H17)*0.7 -> 32756.481 | E26: m² | F26: 220 | G26: =F26*D26*1.1 -> 7927068.5
A27: Alvenaria escadas | B27: 0.2 | C27: m² / AC | D27: =B27*AREAS!H5 -> 6840.797 | E27: m² | F27: 70 | G27: =F27*D27*1.05*1.1 -> 553078.44
A28: Alvenaria cobertura / reservatório | B28: 0.8 | C28: m² / APT | D28: =B28*AREAS!H18 -> 198.88 | E28: m² | F28: 45 | G28: =F28*D28*1.1 -> 9844.56
A29: Alvenaria refratárias | B29: 1.75 | C29: m² * CHU | D29: =B29*'SISTEMAS ESPECIAIS 4'!B10 -> 565.25 | E29: m² | F29: 210 | G29: =F29*D29*1.1 -> 130572.75
A30: Serviços complementares | B30: 12.5 | C30: R$ / m² | D30: =D23+D24+D25+D27+D28 -> 22185.895 | E30: m² | F30: =B30 -> 12.5 | G30: =F30*D30*1.1 -> 305056.06
A31: Mão de obra | B31: 35 | C31: R$ / m² | D31: =D23+D24+D25+D27+D28 -> 22185.895 | E31: m² | F31: 35 | G31: =F31*D31*1.1 -> 854156.96
A32: TOTAL | G32: =SUM(G23:G31) -> 10529515 | K32: =4160+1440+1120+2880+4800+91680+4000 -> 110080 | L32: =K32/21 -> 5241.9048
A34: ALVENARIA - DRTWALL
A36: Descrição | B36: Parâmetro | D36: Quantidade | F36: Preço unitário | G36: Valor total | H36: Observação
A37: Alvenaria embasamento | B37: 1 | C37: m² / AE | D37: =B37*DADOS_INICIAIS!$F$34 -> 18140.1 | E37: m² | F37: 45 | G37: =F37*D37*1.1 -> 897934.95
A38: Alvenaria lazer | B38: 0.4 | C38: m² / AL | D38: =B38*DADOS_INICIAIS!$F$33 -> 2244.892 | E38: m² | F38: 45 | G38: =F38*D38*1.1 -> 111122.15
A39: Alvenaria tipo | B39: 1.62 | C39: m² / APT*(NPT+2ND) | D39: =B39*(DADOS_INICIAIS!$F$31*(DADOS_INICIAIS!$F$28+DADOS_INICIAIS!$F$29))*0.3 -> 13089.86 | E39: un | F39: 45 | G39: =F39*D39*1.1 -> 647948.06
A40: Drywall tipo | B40: 1.65 | C40: m² / APT*(NPT+2ND) | D40: =B40*(DADOS_INICIAIS!$F$31*(DADOS_INICIAIS!$F$28+DADOS_INICIAIS!$F$29))*0.7 -> 31108.618 | F40: 220 | G40: =F40*D40*1.1 -> 7528285.4 | J40: =D40/(D45+D40) -> 0.38933367
A41: Alvenaria escadas | B41: 0.2 | C41: m² / AC | D41: =B41*DADOS_INICIAIS!$F$9 -> 14766.244 | E41: un | F41: 70 | G41: =F41*D41*1.1 -> 1137000.8 | J41: =1-J40 -> 0.61066633
A42: Alvenaria cobertura / reservatório | B42: 0.8 | C42: m² / APT | D42: =B42*DADOS_INICIAIS!$F$31 -> 552.4896 | E42: m³ | F42: 45 | G42: =F42*D42*1.1 -> 27348.235
A43: Alvenaria refratárias | B43: 1.75 | C43: m² * CHU | D43: ='SISTEMAS ESPECIAIS 4'!B10 -> 323 | E43: un | F43: 210
A44: Churrasqueiras pré-moldadas | D44: =D43 -> 323 | E44: un | F44: 1800 | G44: =F44*D44*1.1 -> 639540
A45: Serviços complementares | B45: 12.5 | C45: R$ / m² | D45: =D38+D39+D37+D41+D42 -> 48793.585 | E45: kg | F45: =B45 -> 12.5 | G45: =F45*D45*1.1 -> 670911.8
A46: Mão de obra | B46: 35 | C46: R$ / m² | D46: =D38+D39+D37+D41+D42 -> 48793.585 | E46: m² | F46: 35 | G46: =F46*D46*1.1 -> 1878553
A47: TOTAL | G47: =SUM(G37:G46) -> 13538644
...

Sheet INSTALAÇÕES
A2: INSTALAÇÕES
A4: INSTALAÇÕES ELÉTRICAS
D5: FASE 3 | E5: FASE 4
A6: Descrição | B6: Parâmetro | D6: Valor total | E6: Valor total
A7: Entrada de Energia | B7: 30 | C7: R$ / AC | D7: =B7*AREAS!$G$5*1.1 -> 1274135.8 | E7: =B7*AREAS!$H$5*1.1 -> 1128731.5
A8: Eletrodutos e Eletrocalhas | B8: 15 | C8: R$ / AC | D8: =B8*AREAS!$G$5*1.1 -> 637067.89 | E8: =B8*AREAS!$H$5*1.1 -> 564365.75
A9: Cabos e Fiações | B9: 35 | C9: R$ / AC | D9: =B9*AREAS!$G$5*1.1 -> 1486491.7 | E9: =B9*AREAS!$H$5*1.1 -> 1316853.4
A10: Quadros e Disjuntores | B10: 15 | C10: R$ / AC | D10: =B10*AREAS!$G$5*1.1 -> 637067.89 | E10: =B10*AREAS!$H$5*1.1 -> 564365.75
A11: Acabamentos Elétricos | B11: 15 | C11: R$ / AC | D11: =B11*AREAS!$G$5*1.1 -> 637067.89 | E11: =B11*AREAS!$H$5*1.1 -> 564365.75
A12: Equipamentos e Iluminação | B12: 5 | C12: R$ / AC | D12: =B12*AREAS!$G$5*1.1 -> 212355.96 | E12: =B12*AREAS!$H$5*1.1 -> 188121.92
A13: Mão de Obra para Instalações Elétricas | B13: 60 | C13: R$ / AC | D13: =B13*AREAS!$G$5*1.1 -> 2548271.6 | E13: =B13*AREAS!$H$5*1.1 -> 2257463
A14: TOTAL | D14: =SUM(D7:D13) -> 7432458.7 | E14: =SUM(E7:E13) -> 6584267.1
A16: INSTALAÇÕES HIDROSSANITÁRIAS
A18: Descrição | B18: Parâmetro | D18: Valor total | E18: Valor total
A19: Instalações de Água Fria | B19: 20 | C19: R$ / AC | D19: =B19*AREAS!$G$5*1.1 -> 849423.85 | E19: =B19*AREAS!$H$5*1.1 -> 752487.67
A20: Instalações de Água Quente | B20: 18 | C20: R$ / AC | D20: =B20*AREAS!$G$5*1.1 -> 764481.47 | E20: =B20*AREAS!$H$5*1.1 -> 677238.9
A21: Instalações de Águas Pluviais | B21: 10 | C21: R$ / AC | D21: =B21*AREAS!$G$5*1.1 -> 424711.93 | E21: =B21*AREAS!$H$5*1.1 -> 376243.84
A22: Instalações Sanitárias | B22: 15 | C22: R$ / AC | D22: =B22*AREAS!$G$5*1.1 -> 637067.89 | E22: =B22*AREAS!$H$5*1.1 -> 564365.75
A23: Louças e Metais (bacias sanitárias) | B23: 50 | C23: R$ / AC | D23: =B23*AREAS!$G$5*1.1 -> 2123559.6 | E23: =B23*AREAS!$H$5*1.1 -> 1881219.2
A24: Mão de Obra para Instalações Hidráulicas | B24: 55 | C24: R$ / AC | D24: =B24*AREAS!$G$5*1.1 -> 2335915.6 | E24: =B24*AREAS!$H$5*1.1 -> 2069341.1
A25: TOTAL | D25: =SUM(D19:D24) -> 7135160.3 | E25: =SUM(E19:E24) -> 6320896.4
A27: INSTALAÇÕES PREVENTIVAS E GLP
A29: Descrição | B29: Parâmetro | D29: Valor total | E29: Valor total
A30: Instalações Preventivas | B30: 9.5 | C30: R$ / AC | D30: =B30*AREAS!$G$5*1.1 -> 403476.33 | E30: =B30*AREAS!$H$5*1.1 -> 357431.64
A31: Instalações de GLP | B31: 5 | C31: R$ / AC | D31: =B31*AREAS!$G$5*1.1 -> 212355.96 | E31: =B31*AREAS!$H$5*1.1 -> 188121.92
A32: Instalações de Proteção e Aterramento - SPDA | B32: 3 | C32: R$ / AC | D32: =B32*AREAS!$G$5*1.1 -> 127413.58 | E32: =B32*AREAS!$H$5*1.1 -> 112873.15
A33: Mão de Obra | B33: 12 | C33: R$ / AC | D33: =B33*AREAS!$G$5*1.1 -> 509654.31 | E33: =B33*AREAS!$H$5*1.1 -> 451492.6
A34: TOTAL | D34: =SUM(D30:D33) -> 1252900.2 | E34: =SUM(E30:E33) -> 1109919.3
A36: TOTAL INSTALAÇÕES | D36: =D14+D25+D34 -> 15820519 | E36: =D36/(AREAS!G5) -> 409.75 | F36: FASE 3
D37: =E14+E25+E34 -> 14015083 | E37: =D37/AREAS!H5 -> 409.75 | F37: FASE 4
E38: =E36/1.1 -> 372.5

Sheet SISTEMAS ESPECIAIS 3
A2: SISTEMAS ESPECIAIS
A4: CLIMATIZAÇÃO, EXAUSTÃO MECÂNICA E PRESSURIZAÇÃO
A6: Descrição | B6: Quantidade | C6: Preço Unitário | D6: Valor total | G6: TERREO | H6: MEZANINO | I6: LAZER 1 | J6: TORRE 1 | K6: LAZER SUP01
A7: Infraestrutura para Instalação de Ar Condicionado | B7: =SUM(G7:K7) -> 518 | C7: 1500 | D7: =B7*C7*1.1 -> 854700 | E7: 2323200 | G7: =9+1+1+1+5+2 -> 19 | H7: 1 | I7: 5 | J7: =22*22 -> 484 | K7: =9 -> 9
A8: Instalação de Ar Condicionado | B8: =SUM(G8:M8) -> 34 | C8: 5000 | D8: =B8*C8*1.1 -> 187000 | G8: =G7 -> 19 | H8: =H7 -> 1 | I8: =I7 -> 5 | K8: =K7 -> 9
A9: Exaustão de subsolos | B9: =AREAS!G8+AREAS!G9 -> 12434.64 | C9: 78 | D9: =B9*C9*1.1 -> 1066892.1
A10: Ventokit | B10: =SUM(G10:M10) -> 67 | C10: 900 | D10: =B10*C10*1.1 -> 66330 | G10: =3+2+1+4 -> 10 | H10: 1 | I10: =2+7 -> 9 | J10: =2*22 -> 44 | K10: =3 -> 3
A11: Churrasqueiras | B11: =SUM(G11:M11) -> 179 | C11: 2600 | D11: =B11*C11*1.1 -> 511940 | I11: 3 | J11: =8*22 -> 176
A12: TOTAL | D12: =SUM(D7:D11) -> 2686862.1
A14: COMUNICAÇÃO
A16: Descrição | B16: Parâmetro | D16: Valor total
A17: CFTV | B17: 2 | C17: R$ / AC | D17: =B17*AREAS!$G$5*1.1 -> 84942.385
A18: Interfone | B18: 5 | C18: R$ / AC | D18: =B18*AREAS!$G$5*1.1 -> 212355.96
A19: TV e internet | B19: 3 | C19: R$ / AC | D19: =B19*AREAS!$G$5*1.1 -> 127413.58
A20: Automação, telecomunicação e sistemas de segurança | B20: 5 | C20: R$ / AC | D20: =B20*AREAS!$G$5*1.1 -> 212355.96
A21: TOTAL | D21: =SUM(D17:D20) -> 637067.89
A23: EQUIPAMENTOS
A25: Descrição | B25: Quantidade | C25: Preço Unitário | D25: Valor total
A26: Elevadores | B26: 5 | C26: =486310*1.5 -> 729465 | D26: =B26*C26*1.1 -> 4012057.5 | E26: 29 paradas
A27: Grupo de geradores | B27: 1 | C27: 300000 | D27: =B27*C27*1.1 -> 330000
A28: Subestação | B28: 1 | C28: 245000 | D28: =B28*C28*1.1 -> 269500
A29: Escada pressurizada | B29: 0 | C29: =50*DADOS_INICIAIS!F9 -> 3691561 | D29: =B29*C29*1.1 -> 0
A30: Bombas | B30: 1 | C30: =(440422.6/42000)*AREAS!G5 -> 404876.04 | D30: =B30*C30*1.1 -> 445363.64 | E30: subsolo
A31: Trataamento de esgoto | B31: 0 | C31: 110000 | D31: =B31*C31*1.1 -> 0
A32: Infra de carro elétrico | B32: 0 | C32: 547 | D32: =B32*C32*1.1 -> 0
A33: Equipamento d ecarro eletrico | B33: 0 | C33: 10500 | D33: =B33*C33*1.1 -> 0
A34: Equipamentos SPA | B34: 1 | C34: 12630 | D34: =B34*C34*1.1 -> 13893
A35: Equipamentos para Sauna SECA | B35: 1 | C35: 4500 | D35: =B35*C35*1.1 -> 4950
A36: Equipamentos para Sauna UMIDA | B36: 0 | C36: 5000 | D36: =B36*C36*1.1 -> 0
A37: Equipamentos para Piscina INTERNA | B37: 1 | C37: 80000 | D37: =B37*C37*1.1 -> 88000
A38: Equipamentos para Piscina PARTY | B38: 1 | C38: 26000 | D38: =B38*C38*1.1 -> 28600
A39: Equipamentos para Piscina EXTERNA | B39: 1 | C39: =250000/4 -> 62500 | D39: =B39*C39*1.1 -> 68750
A40: TOTAL | D40: =SUM(D26:D39) -> 5261114.1
A42: OUTROS SISTEMAS ESPECIAIS
A44: Descrição | B44: Parâmetro | D44: Valor total
A45: Outros sistemas | B45: 30 | C45: R$ / AC | D45: =B45*AREAS!G5*1.1 -> 1274135.8
A46: TOTAL | D46: =SUM(D45:D45) -> 1274135.8
A48: TOTAL SISTEMAS ESPECIAIS | D48: =D12+D21+D40+D46 -> 9859179.9 | E48: =D48/AREAS!G5 -> 255.35186

Sheet SISTEMAS ESPECIAIS 4
A2: SISTEMAS ESPECIAIS
A4: CLIMATIZAÇÃO, EXAUSTÃO MECÂNICA E PRESSURIZAÇÃO
A6: Descrição | B6: Quantidade | C6: Preço Unitário | D6: Valor total | G6: LAZER | H6: TORRE 2 | I6: LAZER SUP02
A7: Infraestrutura para Instalação de Ar Condicionado | B7: =SUM(G7:I7) -> 890 | C7: 1500 | D7: =B7*C7*1.1 -> 1468500 | E7: 2323200 | G7: 4 | H7: =22*22+22*18 -> 880 | I7: =6 -> 6
A8: Instalação de Ar Condicionado | B8: =SUM(G8:K8) -> 10 | C8: 5000 | D8: =B8*C8*1.1 -> 55000 | G8: =G7 -> 4 | I8: =I7 -> 6
A9: Ventokit | B9: =SUM(G9:K9) -> 65 | C9: 900 | D9: =B9*C9*1.1 -> 64350 | G9: =7+2+5 -> 14 | H9: =2*22+2*1 -> 46 | I9: =2+3 -> 5
A10: Churrasqueiras | B10: =SUM(G10:K10) -> 323 | C10: 2600 | D10: =B10*C10*1.1 -> 923780 | G10: 2 | H10: =8*22+8*18 -> 320 | I10: =1 -> 1
A11: TOTAL | D11: =SUM(D7:D10) -> 2511630
A13: COMUNICAÇÃO
A15: Descrição | B15: Parâmetro | D15: Valor total
A16: CFTV | B16: 2 | C16: R$ / AC | D16: =B16*AREAS!$H$5*1.1 -> 75248.767
A17: Interfone | B17: 5 | C17: R$ / AC | D17: =B17*AREAS!$H$5*1.1 -> 188121.92
A18: TV e internet | B18: 3 | C18: R$ / AC | D18: =B18*AREAS!$H$5*1.1 -> 112873.15
A19: Automação, telecomunicação e sistemas de segurança | B19: 5 | C19: R$ / AC | D19: =B19*AREAS!$H$5*1.1 -> 188121.92
A20: TOTAL | D20: =SUM(D16:D19) -> 564365.75
A22: EQUIPAMENTOS
A24: Descrição | B24: Quantidade | C24: Preço Unitário | D24: Valor total
A25: Elevadores | B25: 6 | C25: =813912.09*1.5 -> 1220868.1 | D25: =B25*C25*1.1 -> 8057729.7 | E25: 43 paradas
A26: Grupo de geradores | B26: 0 | C26: 80000 | D26: =B26*C26*1.1 -> 0
A27: Subestação | B27: 1 | C27: 245000 | D27: =B27*C27*1.1 -> 269500
A28: Escada pressurizada | B28: 0 | C28: =50*DADOS_INICIAIS!F9 -> 3691561 | D28: =B28*C28*1.1 -> 0
A29: Bombas | B29: 1 | C29: =(440422.6/42000)*AREAS!H5 -> 358671.62 | D29: =B29*C29*1.1 -> 394538.78
A30: Trataamento de esgoto | B30: 0 | C30: 110000 | D30: =B30*C30*1.1 -> 0
A31: Infra de carro elétrico | B31: 0 | C31: 547 | D31: =B31*C31*1.1 -> 0
A32: Equipamento d ecarro eletrico | B32: 0 | C32: 10500 | D32: =B32*C32*1.1 -> 0
A33: Equipamentos SPA | B33: 1 | C33: 12630 | D33: =B33*C33*1.1 -> 13893
A34: Equipamentos para Sauna SECA | B34: 1 | C34: 4500 | D34: =B34*C34*1.1 -> 4950
A35: Equipamentos para Sauna UMIDA | B35: 1 | C35: 5000 | D35: =B35*C35*1.1 -> 5500
A36: Equipamentos para Piscina INTERNA | B36: 1 | C36: 80000 | D36: =B36*C36*1.1 -> 88000
A37: Equipamentos para Piscina PARTY | B37: 1 | C37: 26000 | D37: =B37*C37*1.1 -> 28600
A38: Equipamentos para Piscina EXTERNA | B38: 1 | C38: =250000/4 -> 62500 | D38: =B38*C38*1.1 -> 68750
A39: TOTAL | D39: =SUM(D25:D38) -> 8931461.5
A41: OUTROS SISTEMAS ESPECIAIS
A43: Descrição | B43: Parâmetro | D43: Valor total
A44: Outros sistemas | B44: 30 | C44: R$ / AC | D44: =B44*AREAS!H5*1.1 -> 1128731.5
A45: TOTAL | D45: =SUM(D44:D44) -> 1128731.5
A47: TOTAL SISTEMAS ESPECIAIS | D47: =D11+D20+D39+D45 -> 13136189 | E47: =D47/AREAS!H5 -> 384.05434

Sheet IMPERMEABILIZAÇÃO
A3: IMPERMEABILIZAÇÃO
A4: Data | B4: 45457
A5: Arquivo base | B5: -
A7: IMPERM - FASE 3
A9: Descrição | B9: Parâmetro | D9: Quantidade | F9: Preço unitário | G9: Valor total | H9: Observação
A10: Regularização de Superfície | B10: 25 | C10: R$ / m² | D10: =D15+D16 -> 21235.596 | E10: m² | F10: 22 | G10: =F10*D10*1.1 -> 513901.43
A11: Poço do elevador | B11: 45 | C11: R$ / m² | D11: =((3.61)+(1.9+2.2)*2*1.8)*5 -> 91.85 | E11: m² | F11: 41 | G11: =F11*D11*1.1 -> 4142.435
A12: Baldrames | B12: 30 | C12: R$ / m² | D12: =INFRAESTRUTURA!D22 -> 2339.975 | E12: m² | F12: 35 | G12: =F12*D12*1.1 -> 90089.038
A13: Ralos | B13: 1 | C13: R$ / AC | D13: 1 | E13: vb | F13: =B13*AREAS!G5 -> 38610.175 | G13: =F13*D13*1.1 -> 42471.193
A14: Tratamento de frisos | B14: 0.15 | C14: m²/m | D14: 0 | E14: m | F14: 60 | G14: =D14*B14*F14*1.1 -> 0
A15: Impermeabilizações cimenticias | B15: 0.4 | C15: m² / AC | D15: =B15*AREAS!G5 -> 15444.07 | E15: m² | F15: 60 | G15: =F15*D15 -> 926644.2
A16: Impermeabilizações com manta asfaltica | B16: 0.15 | C16: m² / AC | D16: =B16*AREAS!G5 -> 5791.5262 | E16: m² | F16: 110 | G16: =F16*D16*1.1 -> 700774.68
A17: Impermeabilização de peitoril | B17: 0.6 | C17: R$ / AC | D17: 1 | E17: vb | F17: =B17*AREAS!G5 -> 23166.105 | G17: =F17*D17*1.1 -> 25482.716
A18: Cristalização elementos aparentes | D18: =SUPRAESTRUTURA!D13*0.1 -> 1002.7079 | F18: 60 | G18: =F18*D18*1.1 -> 66178.719
A19: Proteção Mecânica | B19: 28 | C19: R$ / m² | D19: =D16 -> 5791.5262 | E19: m² | F19: 28 | G19: =F19*D19*1.1 -> 178379.01
A20: Junta de dilatação | D20: =48.12*5 -> 240.6 | E20: m | F20: =225+45 -> 270 | G20: =F20*D20*1.1 -> 71458.2
A21: TOTAL | G21: =SUM(G10:G20) -> 2619521.6 | K21: =4160+1440+1120+2880+4800+91680+4000 -> 110080 | L21: =K21/21 -> 5241.9048
A23: TOTAL IMPERMEABILIZAÇÃO | G23: =G21 -> 2619521.6 | H23: =G23/AREAS!G5 -> 67.84537
H26: =H23/1.1 -> 61.677609
A27: IMPERM - FASE 4
A29: Descrição | B29: Parâmetro | D29: Quantidade | F29: Preço unitário | G29: Valor total | H29: Observação
A30: Regularização de Superfície | B30: 25 | C30: R$ / m² | D30: =D34+D35 -> 18812.192 | E30: m² | F30: 22 | G30: =F30*D30*1.1 -> 455255.04
A31: Poço do elevador | B31: 45 | C31: R$ / m² | D31: =((3.61)+(1.9+2.2)*2*1.8)*6 -> 110.22 | E31: m² | F31: 41 | G31: =F31*D31*1.1 -> 4970.922
A32: Baldrames | B32: 30 | C32: R$ / m² | D32: 0 | E32: m² | F32: 35 | G32: =F32*D32*1.1 -> 0
A33: Ralos | B33: 1 | C33: R$ / AC | D33: 1 | E33: vb | F33: =B33*AREAS!H5 -> 34203.985 | G33: =F33*D33*1.1 -> 37624.384
A34: Impermeabilizações cimenticias | B34: 0.4 | C34: m² / AC | D34: =B34*AREAS!H5 -> 13681.594 | E34: m² | F34: 60 | G34: =F34*D34 -> 820895.64
A35: Impermeabilizações com manta asfaltica | B35: 0.15 | C35: m² / AC | D35: =B35*AREAS!H5 -> 5130.5977 | E35: m² | F35: 110 | G35: =F35*D35*1.1 -> 620802.33
A36: Impermeabilização de peitoril | B36: 0.6 | C36: R$ / AC | D36: 1 | E36: vb | F36: =B36*AREAS!H5 -> 20522.391 | G36: =F36*D36*1.1 -> 22574.63
A37: Cristalização elementos aparentes | D37: =SUPRAESTRUTURA!D25*0.2 -> 1776.5579 | F37: 60 | G37: =F37*D37*1.1 -> 117252.82
A38: Proteção Mecânica | B38: 28 | C38: R$ / m² | D38: =D35 -> 5130.5977 | E38: m² | F38: 28 | G38: =F38*D38*1.1 -> 158022.41
A39: TOTAL | G39: =SUM(G30:G38) -> 2237398.2 | K39: =4160+1440+1120+2880+4800+91680+4000 -> 110080 | L39: =K39/21 -> 5241.9048
A41: TOTAL IMPERMEABILIZAÇÃO | G41: =G39 -> 2237398.2 | H41: =G41/AREAS!H5 -> 65.413377

Sheet AMBIENTES
A1: Obra
A2: Empresa
A3: Revisão
A4: Data
A5: LEVANTAMENTO QUANTITATIVO
A7: REVESTIMENTOS E ACABAMENTOS DE PISO
B9: LEVANTAMENTO DE PROJETO | K9: CONTRAPISO
B10: Pavimento | C10: Local | D10: Piso | E10: Teto | F10: Área (m²) | G10: Contrapiso (Sim/Não) | H10: Repetição | I10: Total | K10: Revestimento | L10: Área total
B11: SUBSOLO 2 | C11: Garagem | D11: Polido | E11: Estucamento | F11: =AREAS!G8*0.9 -> 5575.311 | G11: Não | H11: 1 | I11: =F11*H11 -> 5575.311 | K11: Contrapiso | L11: =SUMIF(G:G,"Sim",I:I) -> 1960.231 | M11: =L11/[5]AREAS!E6 -> 0.24788356
B12: SUBSOLO1 | C12: Garagem | D12: Polido | E12: Estucamneto | F12: =AREAS!G9*0.9 -> 5615.865 | G12: Não | H12: 1 | I12: =F12*H12 -> 5615.865 | K12: Manta acústica | L12: =SUMIFS(I:I,G:G,"Sim",C:C,"*APT*") -> 0
B13: TÉRREO | C13: Garagem | D13: Polido | E13: Estucamneto | F13: =1720.58+112.82+80.04+175.15+84.06 -> 2172.65 | G13: Não | H13: 1 | I13: =F13*H13 -> 2172.65
B14: TÉRREO | C14: Rampa | D14: Polido ranhurado | E14: Estucamneto | F14: =(110.66+78+78)*1.2 -> 319.992 | G14: Não | H14: 1 | I14: =F14*H14 -> 319.992 | K14: PISO
B15: TÉRREO | C15: Lixo e rt | D15: Drenante | F15: 43.88 | G15: Não | H15: 1 | I15: =F15*H15 -> 43.88 | K15: Material | L15: Área total
B16: TÉRREO | C16: RT | D16: Cimentado | E16: Estucamneto | F16: =7.27+7.89+19.86+17.36+18.42+12.04+38.38 -> 121.22 | G16: Não | H16: 1 | I16: =F16*H16 -> 121.22 | K16: Porcelanato | L16: =SUMIF(D:D,K16,I:I) -> 1228.611
A17: =IF(C16="*&APTO&*","OK","") | B17: TÉRREO | C17: ESCADAS E ANTECAMARAS | D17: Porcelanato | E17: Estucamneto | F17: =12.561+19.16+12.29+11.77+8.28+12.5+11.18+15.64 -> 103.381 | G17: Sim | H17: 1 | I17: =F17*H17 -> 103.381 | K17: Calçada | L17: =SUMIF(D:D,K17,I:I) -> 0
B18: TÉRREO | C18: serviço | D18: Porcelanato | E18: Gesso | F18: =20.68+10.41+18.45+40.19+4.53+3.55+11.88+3.76+2.9+7.47+2.88+2.88 -> 129.58 | G18: Sim | H18: 1 | I18: =F18*H18 -> 129.58 | K18: Polido | L18: =SUMIF(D:D,K18,I:I) -> 18715.146
B19: TÉRREO | C19: Hall | D19: Porcelanato 120x120 | E19: Gesso | F19: =47.53+661.48+22.61 -> 731.62 | G19: Sim | H19: 1 | I19: =F19*H19 -> 731.62 | K19: Cimentado | L19: =SUMIF(D:D,K19,I:I) -> 195.955
B20: TÉRREO | C20: Areas comuns | D20: Porcelanato | E20: Gesso | F20: =9.92+7.04+4.09+4+16.82+17.8+18.16+6.75+3.15+12.51+3.15+12.66+116.63+37.54+21.45+3.68+3.68+41.16+7.36 -> 347.55 | G20: Sim | H20: 1 | I20: =F20*H20 -> 347.55 | K20: Polido ranhurado | L20: =SUMIF(D:D,K20,I:I) -> 319.992
B21: TÉRREO | C21: Aesso pedestres | D21: Porcelanato | F21: =20.33+202.91 -> 223.24 | G21: Sim | H21: 1 | I21: =F21*H21 -> 223.24 | K21: Porcelanato 120x120 | L21: =SUMIF(D:D,K21,I:I) -> 731.62
B22: TÉRREO | C22: Aesso pedestres | D22: Cimentado | F22: =63.43+11.305 -> 74.735 | G22: Não | H22: 1 | I22: =F22*H22 -> 74.735
B23: PAV 1 (MEZANINO) | C23: Garagem | D23: Polido | E23: Estucamneto | F23: =1669.82+114.1 -> 1783.92 | G23: Não | H23: 1 | I23: =F23*H23 -> 1783.92 | L23: =SUMIF(D:D,K23,I:I) -> 0
B24: PAV 1 (MEZANINO) | C24: Escada | D24: Porcelanato | E24: Estucamneto | F24: =13.08+13.08+12.6+12.04+14.17+21+1+6.52 -> 93.49 | G24: Sim | H24: 1 | I24: =F24*H24 -> 93.49 | L24: =SUMIF(D:D,K24,I:I) -> 0
B25: PAV 1 (MEZANINO) | C25: Hall | D25: Porcelanato | E25: Gesso | F25: 21.94 | G25: Sim | H25: 1 | I25: =F25*H25 -> 21.94 | L25: =SUMIF(D:D,K25,I:I) -> 0
B26: PAV 1 (MEZANINO) | C26: Areas comuns | D26: Porcelanato | E26: Gesso | F26: =34.79+20.66 -> 55.45 | G26: Sim | H26: 1 | I26: =F26*H26 -> 55.45 | K26: TETO
B27: PAV 1 (MEZANINO) | C27: Areas tecnicas | D27: Porcelanato | E27: Estucamneto | F27: =9.53+70.95 -> 80.48 | G27: Sim | H27: 1 | I27: =F27*H27 -> 80.48 | K27: Material | L27: Área total
B28: SOBRELOJA | C28: Garagem | D28: Polido | E28: Estucamneto | F28: =3567.4 -> 3567.4 | G28: Não | H28: 1 | I28: =F28*H28 -> 3567.4 | K28: Gesso | L28: =SUMIF(E:E,K28,I:I) -> 1366
B29: SOBRELOJA | C29: Escada | D29: Porcelanato | E29: Estucamneto | F29: =13.08+13.08+12.6+12.04+6.52+14.17+22.15 -> 93.64 | G29: Sim | H29: 1 | I29: =F29*H29 -> 93.64 | K29: Estucamento | L29: =SUMIF(E:E,K29,I:I) -> 5575.311
B30: SOBRELOJA | C30: Areas comuns | D30: Porcelanato | E30: Gesso | F30: =79.86 -> 79.86 | G30: Sim | H30: 1 | I30: =F30*H30 -> 79.86 | L30: =SUMIF(E:E,K30,I:I) -> 0
B31: LAZER - 1 | G31: Sim | H31: 1 | I31: =F31*H31 -> 0 | L31: =SUMIF(E:E,K31,I:I) -> 0
B32: LAZER - 1 | G32: Sim | H32: 1 | I32: =F32*H32 -> 0 | L32: =SUMIF(E:E,K32,I:I) -> 0
B33: LAZER - 1 | G33: Sim | H33: 1 | I33: =F33*H33 -> 0 | L33: =SUMIF(E:E,K33,I:I) -> 0
B34: LAZER - 1 | G34: Não | H34: 1 | I34: =F34*H34 -> 0 | L34: =SUMIF(E:E,K34,I:I) -> 0
B35: LAZER - 1 | G35: Não | H35: 1 | I35: =F35*H35 -> 0 | L35: =SUMIF(E:E,K35,I:I) -> 0
B36: LAZER - 1 | G36: Sim | H36: 1 | I36: =F36*H36 -> 0 | L36: =SUMIF(E:E,K36,I:I) -> 0
B37: LAZER - 1 | G37: Não | H37: 1 | I37: =F37*H37 -> 0 | L37: =SUMIF(E:E,K37,I:I) -> 0
B38: LAZER - 1 | G38: Não | H38: 1 | I38: =F38*H38 -> 0

Sheet Rev. Internos Piso e Parede
A2: ORÇAMENTO PARAMÉTRICO GERENCIAMENTO EXECUTIVO
A7: Cliente | B7: Amalfi
A8: Obra | B8: San Felicce
A9: Data | B9: 45397
A10: Revisão | B10: R00
A12: REVESTIMENTOS INTERNOS EM PISO E PAREDE - FASE 3
J13: =SUM(G15:G18) -> 2019626.2
A14: Descrição | B14: Quantidade | D14: Parâmetro | F14: Referência | G14: Valor total | J14: =G20+G21 -> 2896535.3
A15: Polimento de concreto | B15: =AMBIENTES!L18-AMBIENTES!F28/2 -> 16931.446 | C15: m² | D15: 16.5 | E15: R$ / m² | F15: Média | G15: =D15*B15*1.1 -> 307305.74
A16: Piso alisado | B16: =AMBIENTES!L19+AMBIENTES!L20 -> 515.947 | C16: m² | D16: 25 | E16: R$ / m² | F16: Média | G16: =D16*B16*1.1 -> 14188.542
A17: Contrapiso | B17: =AREAS!G5*0.9-'Rev. Internos Piso e Parede'!B15-'Rev. Internos Piso e Parede'!B16 -> 17301.765 | C17: m² | D17: =B17/AREAS!G5 -> 0.44811412 | E17: m² / AC | F17: Média | G17: =+B17*65*1.1 -> 1237076.2
A18: Manta acústica | B18: =AREAS!G13+AREAS!G15 -> 16765.665 | C18: m² | D18: =B18/AREAS!G5 -> 0.43422919 | E18: m² / AC | F18: Média | G18: =+B18*25*1.1 -> 461055.79
A19: Manta lazer | B19: =AREAS!G16 -> 199 | C19: m² | D19: =B19/AREAS!G5 -> 0.0051540818 | E19: m² / AC | F19: Média | G19: =+B19*50*1.1 -> 10945
A20: Chapisco | B20: =AREAS!G5*'Rev. Internos Piso e Parede'!D20*0.62 -> 47876.617 | C20: m² | D20: 2 | E20: m² / AC | F20: Média | G20: =+B20*5*1.1 -> 263321.39
A21: Reboco | B21: =B20 -> 47876.617 | C21: m² | D21: 2 | E21: m² / AC | F21: Média | G21: =50*B21*1.1 -> 2633213.9
A22: Estucamento | B22: 1 | C22: vb | D22: 1 | E22: R$ / AC | F22: Média | G22: =D22*AREAS!G5*1.1 -> 42471.193
A23: TOTAL | G23: =SUM(G15:G22) -> 4969577.8
A26: TOTAL REVESTIMENTOS | G26: =G23 -> 4969577.8 | H26: =G26/AREAS!G5 -> 128.71161
H28: =H26/1.1 -> 117.01055
B30: =ALVENARIA!D18*2-'Rev. Fachada'!B15 -> #REF!
A31: REVESTIMENTOS INTERNOS EM PISO E PAREDE - FASE 4
A33: Descrição | B33: Quantidade | D33: Parâmetro | F33: Referência | G33: Valor total
A34: Polimento de concreto | B34: =AMBIENTES!F28/2 -> 1783.7 | C34: m² | D34: 16.5 | E34: R$ / m² | F34: Média | G34: =D34*B34*1.1 -> 32374.155
A35: Piso alisado | B35: 0 | C35: m² | D35: 25 | E35: R$ / m² | F35: Média | G35: =D35*B35*1.1 -> 0
A36: Contrapiso | B36: =AREAS!H5*0.9-'Rev. Internos Piso e Parede'!B34-'Rev. Internos Piso e Parede'!B35 -> 28999.887 | C36: m² | D36: =B36/AREAS!H5 -> 0.84785111 | E36: m² / AC | F36: Média | G36: =+B36*65*1.1 -> 2073491.9
A37: Manta acústica | B37: =AREAS!H13+AREAS!H15+AREAS!H17 -> 30376.295 | C37: m² | D37: =B37/AREAS!H5 -> 0.88809228 | E37: m² / AC | F37: Média | G37: =+B37*25*1.1 -> 835348.11
A38: Manta lazer | B38: =AREAS!H16 -> 753.61 | C38: m² | D38: =B38/AREAS!H6 -> #DIV/0! | E38: m² / AC | F38: Média | G38: =+B38*50*1.1 -> 41448.55
A39: Chapisco | B39: =AREAS!H5*'Rev. Internos Piso e Parede'!D39*0.62 -> 42412.941 | C39: m² | D39: 2 | E39: m² / AC | F39: Média | G39: =+B39*5*1.1 -> 233271.18
A40: Reboco | B40: =B39 -> 42412.941 | C40: m² | D40: 2 | E40: m² / AC | F40: Média | G40: =50*B40*1.1 -> 2332711.8
A41: Estucamento | B41: 1 | C41: vb | D41: 1 | E41: m² / AC | F41: Média | G41: =D41*AREAS!H5*1.1 -> 37624.384
A42: TOTAL | G42: =SUM(G34:G41) -> 5586270
A45: TOTAL REVESTIMENTOS | G45: =G42 -> 5586270 | H45: =G45/AREAS!H5 -> 163.3222

Sheet TETO
A3: REVESTIMENTOS E ACABAMENTOS DE TETO
A4: Data | B4: 45457
A5: Arquivo base | B5: -
A7: FORRO - FASE 3
A9: Descrição | B9: Parâmetro | D9: Quantidade | F9: Preço unitário | G9: Valor total | H9: Observação
A10: Forro acartonado | B10: 0.55 | C10: m² / AC | D10: =AREAS!G5*TETO!B10-'Rev. Internos Piso e Parede'!B15-'Rev. Internos Piso e Parede'!B16 -> 3788.2033 | E10: m² | F10: 120 | G10: =F10*D10*1.1 -> 500042.83
A11: Negativo | B11: 1.2 | C11: m / FORRO | D11: =D10*B11 -> 4545.8439 | E11: m² | F11: 22 | G11: =F11*D11*1.1 -> 110009.42
A12: Estucamento | B12: 0.35 | C12: m² / AC | D12: =B12*AREAS!G5 -> 13513.561 | E12: m² | F12: 24 | G12: =F12*D12*1.1 -> 356758.02
A13: TOTAL | G13: =SUM(G10:G12) -> 966810.27 | K13: =4160+1440+1120+2880+4800+91680+4000 -> 110080 | L13: =K13/21 -> 5241.9048
A15: TOTAL IMPERMEABILIZAÇÃO | G15: =G13 -> 966810.27 | H15: =G15/AREAS!G5 -> 25.040297
A18: FORRO - FASE 4
A20: Descrição | B20: Parâmetro | D20: Quantidade | F20: Preço unitário | G20: Valor total | H20: Observação
A21: Forro acartonado | B21: 0.8 | C21: m² / AC | D21: =AREAS!H5*TETO!B21-'Rev. Internos Piso e Parede'!B34 -> 25579.488 | E21: m² | F21: 120 | G21: =F21*D21*1.1 -> 3376492.4
A22: Negativo | B22: 1.2 | C22: m / FORRO | D22: =D21*B22 -> 30695.386 | E22: m² | F22: 22 | G22: =F22*D22*1.1 -> 742828.33
A23: Estucamento | B23: 0.1 | C23: m² / AC | D23: =B23*AREAS!H5 -> 3420.3985 | E23: m² | F23: 24 | G23: =F23*D23*1.1 -> 90298.52
A24: TOTAL | G24: =SUM(G21:G23) -> 4209619.3 | K24: =4160+1440+1120+2880+4800+91680+4000 -> 110080 | L24: =K24/21 -> 5241.9048
A26: TOTAL IMPERMEABILIZAÇÃO | G26: =G24 -> 4209619.3 | H26: =G26/AREAS!H5 -> 123.07394

Sheet Acabamentos de Piso e Parede
A2: ORÇAMENTO PARAMÉTRICO GERENCIAMENTO EXECUTIVO
A7: Cliente | B7: Amalfi
A8: Obra | B8: San Felicce
A9: Data | B9: 45397
A10: Revisão | B10: R00
A12: ACABAMENTOS EM PISO E PAREDE - FASE 3
A14: Descrição | B14: Quantidade | D14: Parâmetro | F14: Referência | G14: Valor total
A15: Porcelanato | B15: ='Rev. Internos Piso e Parede'!B17-B21-B16 -> 16550.775 | C15: m² | D15: 125 | E15: R$ / m² | F15: Média | G15: =+D15*B15*1.1 -> 2275731.5
A16: Porcelanato 120x120 | B16: =AMBIENTES!L21 -> 731.62 | C16: m² | D16: 228 | E16: R$ / m² | F16: Média | G16: =+D16*B16*1.1 -> 183490.3
A17: Piso vinilico | C17: m² | D17: 150 | E17: R$ / m² | F17: Média | G17: =+D17*B17*1.1 -> 0
A18: Emborrachado | C18: m² | D18: 350 | E18: R$ / m² | F18: Média | G18: =+D18*B18*1.1 -> 0
A19: Carpete | B19: 0 | C19: m² | D19: 350 | E19: R$ / m² | F19: Média | G19: =+D19*B19*1.1 -> 0
A20: Piscina | C20: m² | D20: 300 | E20: R$ / m² | F20: Média | G20: =+D20*B20*1.1 -> 0
A21: Deck | B21: =19.37 -> 19.37 | C21: m² | D21: 450 | E21: R$ / m² | F21: Média | G21: =+D21*B21*1.1 -> 9588.15
A22: Cimentado quadras | B22: =195.3 -> 195.3 | C22: m² | D22: 25 | E22: R$ / m² | F22: Média | G22: =+D22*B22*1.1 -> 5370.75
A23: Paver | C23: m² | D23: 60 | E23: R$ / m² | F23: Média | G23: =+D23*B23*1.1 -> 0
A24: Ladrilho hidaraulico | C24: m² | D24: 180 | E24: R$ / m² | F24: Média | G24: =+D24*B24*1.1 -> 0
A25: Rodapés | B25: 1 | C25: vb | D25: 30 | E25: R$ / AC | F25: Média | G25: =D25*AREAS!$G$5*1.1 -> 1274135.8
A26: Soleiras e peitoris | B26: 1 | C26: vb | D26: 20 | E26: R$ / AC | F26: Média | G26: =D26*AREAS!$G$5*1.1 -> 849423.85
A27: Revestimentos de Parede | B27: 1 | C27: vb | D27: 35 | E27: R$ / AC | F27: Média | G27: =D27*AREAS!$G$5*1.1 -> 1486491.7
A28: =20*40 -> 800 | G28: =SUM(G15:G27) -> 6084232.1
A31: TOTAL ACABAMENTOS | G31: =G28 -> 6084232.1 | H31: =G31/AREAS!$G$5 -> 157.58105
H33: =H31/1.1 -> 143.2555
A34: ACABAMENTOS EM PISO E PAREDE - FASE 4
A36: Descrição | B36: Quantidade | D36: Parâmetro | F36: Referência | G36: Valor total
A37: Porcelanato | B37: ='Rev. Internos Piso e Parede'!B36-'Acabamentos de Piso e Parede'!B43 -> 28940.617 | C37: m² | D37: 125 | E37: R$ / m² | F37: Média | G37: =+D37*B37*1.1 -> 3979334.8
A38: Cerâmico | C38: m² | D38: 98 | E38: R$ / m² | F38: Média | G38: =+D38*B38*1.1 -> 0
A39: Piso vinilico | C39: m² | D39: 150 | E39: R$ / m² | F39: Média | G39: =+D39*B39*1.1 -> 0
A40: Emborrachado | C40: m² | D40: 350 | E40: R$ / m² | F40: Média | G40: =+D40*B40*1.1 -> 0
A41: Carpete | B41: 0 | C41: m² | D41: 350 | E41: R$ / m² | F41: Média | G41: =+D41*B41*1.1 -> 0
A42: Piscina | C42: m² | D42: 300 | E42: R$ / m² | F42: Média | G42: =+D42*B42*1.1 -> 0
A43: Deck | B43: =59.27 -> 59.27 | C43: m² | D43: 450 | E43: R$ / m² | F43: Média | G43: =+D43*B43*1.1 -> 29338.65
A44: Cimentado quadras | B44: =110.67 -> 110.67 | C44: m² | D44: 25 | E44: R$ / m² | F44: Média | G44: =+D44*B44*1.1 -> 3043.425
A45: Paver | C45: m² | D45: 60 | E45: R$ / m² | F45: Média | G45: =+D45*B45*1.1 -> 0
A46: Ladrilho hidaraulico | C46: m² | D46: 180 | E46: R$ / m² | F46: Média | G46: =+D46*B46*1.1 -> 0
A47: Rodapés | B47: 1 | C47: vb | D47: 30 | E47: R$ / AC | F47: Média | G47: =D47*AREAS!$H$5*1.1 -> 1128731.5
A48: Soleiras e peitoris | B48: 1 | C48: vb | D48: 20 | E48: R$ / AC | F48: Média | G48: =D48*AREAS!$H$5*1.1 -> 752487.67
A49: Revestimentos de Parede | B49: 1 | C49: vb | D49: 65 | E49: R$ / AC | F49: Média | G49: =D49*AREAS!$H$5*1.1 -> 2445584.9
A50: =20*40 -> 800 | G50: =SUM(G37:G49) -> 8338520.9
A53: TOTAL ACABAMENTOS | G53: =G50 -> 8338520.9 | H53: =G53/AREAS!$H$5 -> 243.788
...

Sheet PINTURA INTERNA
A3: PINTURA INTERNA
A4: Data | B4: 45457
A5: Arquivo base | B5: -
A7: PINTURA - FASE 3
A9: Descrição | B9: Parâmetro | D9: Quantidade | F9: Preço unitário | G9: Valor total | H9: Observação
A10: Pintura piso epoxi | B10: 25 | C10: R$ / m² | D10: ='Rev. Internos Piso e Parede'!B15+'Rev. Internos Piso e Parede'!B16 -> 17447.393 | E10: m² | F10: 110 | G10: =F10*D10*1.1 -> 2111134.6
A11: Textura escadas | B11: 20 | C11: R$ / AC | D11: 1 | E11: vb | F11: =B11*AREAS!$G$5 -> 772203.5 | G11: =F11*D11*1.1 -> 849423.85 | H11: =ALVENARIA!H14*28 -> 432433.96
A12: Pintura Interna | B12: 50 | C12: R$ / AC | D12: 1 | E12: vb | F12: =B12*AREAS!$G$5 -> 1930508.8 | G12: =F12*D12*1.05*1.1 -> 2229737.6 | H12: ='Rev. Internos Piso e Parede'!B20*43 -> 2058694.5
A13: TOTAL | G13: =SUM(G10:G12) -> 5190296 | K13: =4160+1440+1120+2880+4800+91680+4000 -> 110080 | L13: =K13/21 -> 5241.9048
A15: TOTAL IMPERMEABILIZAÇÃO | G15: =G13 -> 5190296 | H15: =G15/AREAS!$G$5 -> 134.42819
H17: =H15/1.1 -> 122.20745
A19: PINTURA - FASE 4
A21: Descrição | B21: Parâmetro | D21: Quantidade | F21: Preço unitário | G21: Valor total | H21: Observação
A22: Pintura piso epoxi | B22: 25 | C22: R$ / m² | D22: ='Rev. Internos Piso e Parede'!B34 -> 1783.7 | E22: m² | F22: 110 | G22: =F22*D22*1.1 -> 215827.7
A23: Textura escadas | B23: 20 | C23: R$ / AC | D23: 1 | E23: vb | F23: =B23*AREAS!$H$5 -> 684079.7 | G23: =F23*D23*1.1 -> 752487.67
A24: Pintura Interna | B24: 70 | C24: R$ / AC | D24: 1 | E24: vb | F24: =B24*AREAS!$H$5 -> 2394279 | G24: =F24*D24*1.05*1.1 -> 2765392.2 | H24: ='Rev. Internos Piso e Parede'!B40*43 -> 1823756.5
A25: TOTAL | G25: =SUM(G22:G24) -> 3733707.6
A27: TOTAL IMPERMEABILIZAÇÃO | G27: =G25 -> 3733707.6 | H27: =G27/AREAS!$H$5 -> 109.16002

Sheet ESQUADRIAS
A3: ESQUADRIAS
A4: Data | B4: 45460
A5: Arquivo base | B5: -
A7: ESQUADRIAS - FASE 3
A9: Descrição | B9: Parâmetro | D9: Quantidade | F9: Preço unitário | G9: Valor total | H9: Observação
A10: Esquadrias de Alumínio | B10: 0.12 | C10: m² / AC | D10: =B10*AREAS!G5 -> 4633.221 | E10: m² | F10: 1100 | G10: =F10*D10*1.1 -> 5606197.4 | H10: =G10/DADOS_INICIAIS!F9 -> 75.932612
A11: Pele de vidro | D11: =98.3+204.7*2 -> 507.7 | E11: m² | F11: 1000 | G11: =F11*D11*1.1 -> 558470
A12: Portão de alumínio | D12: 2 | E12: un | F12: 18000 | G12: =F12*D12*1.1 -> 39600
A13: Guarda-corpo - vidro | D13: =88.98*3+66.65*20+20.25*2 -> 1640.44 | E13: m | F13: =950*1.1 -> 1045 | G13: =F13*D13*1.1 -> 1885685.8
A14: Gradil | E14: m | F14: =680*1.1 -> 748 | G14: =F14*D14*1.1 -> 0
A15: Corrimão inox | E15: m | F15: 150 | G15: =F15*D15*1.1 -> 0
A16: Serralherias | B16: 10 | C16: R$ / AC | D16: 1 | E16: vb | F16: =B16*AREAS!G5 -> 386101.75 | G16: =F16*D16*1.1 -> 424711.93
A17: PCF | D17: =1*2+2+7+2+2*22+1 -> 58 | E17: un | F17: 1750 | G17: =F17*D17*1.1 -> 111650
A18: Corrimão metálico | D18: =((3.68*2+2.43*2+2.65+0.15)*(22+6+2))*1.2 -> 540.72 | E18: m | F18: 120 | G18: =F18*D18*1.1 -> 71375.04
A19: Fechadura biométrica | D19: =AREAS!G19 -> 220 | E19: un | F19: 1400 | G19: =F19*D19*1.1 -> 338800
A20: Esquadrias de Madeira | D20: =43*22+3+13+6 -> 968 | E20: un | F20: 1200 | G20: =F20*D20*1.1 -> 1277760
A21: TOTAL | G21: =SUM(G10:G20) -> 10314250 | K21: =4160+1440+1120+2880+4800+91680+4000 -> 110080 | L21: =K21/21 -> 5241.9048
A23: TOTAL ESQUADRIAS | G23: =G21 -> 10314250 | H23: =G23/AREAS!G5 -> 267.13814
A25: ESQUADRIAS - FASE 4
A27: Descrição | B27: Parâmetro | D27: Quantidade | F27: Preço unitário | G27: Valor total | H27: Observação
A28: Esquadrias de Alumínio | B28: 0.25 | C28: m² / AC | D28: =B28*AREAS!H5 -> 8550.9963 | E28: m² | F28: 1100 | G28: =F28*D28*1.1 -> 10346705 | H28: =G28/DADOS_INICIAIS!F27 -> 246350.13
A29: Pele de vidro | D29: =98.3+147.3*2 -> 392.9 | E29: m² | F29: 1000 | G29: =F29*D29*1.1 -> 432190
A30: Portão de alumínio | E30: un | F30: 18000 | G30: =F30*D30*1.1 -> 0
A31: Guarda-corpo - vidro | D31: =74.08*(20+18) -> 2815.04 | E31: m | F31: =950*1.1 -> 1045 | G31: =F31*D31*1.1 -> 3235888.5
A32: Gradil | E32: m | F32: =680*1.1 -> 748 | G32: =F32*D32*1.1 -> 0
A33: Corrimão inox | E33: m | F33: 150 | G33: =F33*D33*1.1 -> 0
A34: Serralherias | B34: 10 | C34: R$ / AC | D34: 1 | E34: vb | F34: =B34*AREAS!H5 -> 342039.85 | G34: =F34*D34*1.1 -> 376243.84
A35: PCF | D35: =2*2+4*2+4+4+4*22+4+4*18+2 -> 186 | E35: un | F35: 1750 | G35: =F35*D35*1.1 -> 358050
A36: Corrimão metálico | D36: =((4.43+3.04*2+2.26+1.76*2+0.68*2)*(22+6+1+8+1))*1.2 -> 804.84 | E36: m | F36: 120 | G36: =F36*D36*1.1 -> 106238.88
A37: Fechadura biométrica | D37: =AREAS!H19 -> 382 | E37: un | F37: 1400 | G37: =F37*D37*1.1 -> 588280
A38: Esquadrias de Madeira | D38: =43*22+43*18+5+12+31 -> 1768 | E38: un | F38: 1200 | G38: =F38*D38*1.1 -> 2333760
A39: TOTAL | G39: =SUM(G28:G38) -> 17777357
A41: TOTAL ESQUADRIAS | G41: =G39 -> 17777357 | H41: =G41/AREAS!H5 -> 519.74519

Sheet COBERTURA
A2: COBERTURA
A3: Data | B3: 45460
A4: Arquivo base | B4: -
A6: TELHADO
A8: Descrição | B8: Parâmetro | D8: Quantidade | F8: Preço unitário | G8: Valor total | H8: Observação
A9: Estrutura e telhamento | E9: m² | F9: 500 | G9: =F9*D9*1.1 -> 0
A10: Serviços complementares | E10: m² | F10: 45 | G10: =F10*D10*1.1 -> 0
A11: Pergolados - 3 | D11: =17.64+18.25+19 -> 54.89 | E11: m² | F11: 350 | G11: =F11*D11*1.1 -> 21132.65
A12: Pergolados - 4 | D12: =19+6.5*3+7.08*3 -> 59.74 | E12: m² | F12: 290 | G12: =F12*D12*1.1 -> 19057.06
A13: Passarelas - 4 | D13: 130.47 | E13: m² | F13: 3800 | G13: =F13*D13*1.1 -> 545364.6
A14: Moldura ACM metálica | D14: ='Rev. Fachada'!B29+'Rev. Fachada'!B54 -> 247.56 | E14: m² | F14: 52.5 | G14: =F14*D14*1.1 -> 14296.59
A15: TOTAL | G15: =SUM(G9:G14) -> 599850.9
A17: TOTAL COMPLEMENTARES | G17: =G15 -> 599850.9 | H17: =G17/DADOS_INICIAIS!$F$9 -> 8.124624

Sheet Rev. Fachada
A2: ORÇAMENTO PARAMÉTRICO GERENCIAMENTO EXECUTIVO
A7: Cliente | B7: Passe
A8: Obra | B8: Connect
A9: Data | B9: 45460
A10: Revisão | B10: R00
A11: FACHADA FASE 3
A12: REVESTIMENTOS ARGAMASSADOS
A14: Descrição | B14: Quantidade | D14: Parâmetro | F14: Referência | G14: Valor total
