Workbook
Name \0: #REF!
Name \0: #REF!
Name \0: #REF!
Name \0: #REF!
Name \0: #REF!
Name \0: #REF!
Name \0: #REF!
Name \1: #REF!
Name \a: #REF!
Name \a: #REF!
Name \b: #REF!
Name \c: #REF!
Name \d: #REF!
Name \e: #REF!
Name \i: #REF!
Name \J: #REF!
Name \k: #REF!
Name \l: #N/A
Name \m: #REF!
Name \m: #REF!
Name \o: #REF!
Name \p: #REF!
Name \r: #REF!
Name \T: #REF!
Name \z: #REF!
Name ______ACR10: #REF!
Name ______ACR15: #REF!
Name ______acr20: #REF!
Name ______acr5: #REF!
Name ______ARQ1: #REF!
Name ______QT100: #REF!
Name ______QT2: #REF!
Name ______QT3: #REF!
Name ______QT4: #REF!
Name ______QT50: #REF!
Name ______QT75: #REF!
Name _____ACR10: #REF!
Name _____ACR15: #REF!
Name _____acr20: #REF!
Name _____acr5: #REF!
Name _____ARQ1: #REF!
Name _____QT100: #REF!
Name _____QT2: #REF!
Name _____QT3: #REF!
Name _____QT4: #REF!
Name _____QT50: #REF!
Name _____QT75: #REF!
Name ___ACR10: #REF!
Name ___ACR15: #REF!
Name ___acr20: #REF!
Name ___acr5: #REF!
Name ___ARQ1: #REF!
Name ___QT100: #REF!
Name ___QT2: #REF!
Name ___QT3: #REF!
Name ___QT4: #REF!
Name ___QT50: #REF!
Name ___QT75: #REF!
Name __ACR10: #REF!
Name __ACR15: #REF!

Sheet DADOS_INICIAIS
A1: Obra | B1: Connect
A2: Empresa | B2: Passe
A3: Revisão | B3: R00
A4: Arquitetura base | B4: PAS_CNC_ARQ_EP_R08
A5: DADOS OBRA
B7: Descrição | C7: Identificador | D7: Unidade | F7: Quantidade
B8: ÁREA DO TERRENO | C8: AT | D8: M2 | F8: 9027.79
B9: ÁREA TOTAL CONSTRUÍDA | C9: AC | D9: M2 | F9: 73831.22
B10: 3º SUBSOLO | D10: M2 | E10: 4679.95
B11: 2º SUBSOLO | D11: M2 | E11: 4528.14
B12: 1º SUBSOLO | D12: M2 | E12: 4528.14
B13: TERREO | D13: M2 | E13: 5529.88
B14: MEZANINO | D14: M2 | E14: 2740.07
B15: SOBRELOJA | D15: M2 | E15: 4855.85
B16: LAZER | D16: M2 | E16: 5014.3
B17: TIPO (X22) | D17: M2 | E17: =618.71*22 -> 13611.62 | F17: =682.92*22 -> 15024.24
B18: LAZER SUPERIOR | D18: M2 | E18: 1554.82
B19: BARRILETE 1 | D19: M2 | E19: =76.57*2 -> 153.14
B20: TIPO 2 (X16) | D20: M2 | F20: =682.92*16 -> 10926.72
B21: BARRILETE 2 | D21: M2 | F21: =111.98*2 -> 223.96
B22: UNIDADES RESIDENCIAIS | C22: UR | D22: UN | F22: 596 | G22: =F9-F34-F33 -> 50078.89
B23: Dormitórios | C23: dorm | D23: UN | F23: =480+90*2+30*3 -> 750
B24: Banheiros | C24: ban | D24: UN
B25: UNIDADES COMERCIAIS | C25: UC | D25: UN | F25: 2
B26: Churrasqueiras | C26: CHU | D26: UN
B27: NÚMERO TOTAL DE PAVIMENTOS | C27: NP | D27: UN | F27: 42
B28: NÚMERO DE PAVIMENTOS TIPO | C28: NPT | D28: UN | F28: =22+16 -> 38
B29: NÚMERO DE PAVIMENTOS TIPO DIFERENCIADOS | C29: NPD | D29: UN | F29: 1 | G29: LAZER SUPERIOR
B30: NÚMERO DE PAVIMENTOS DUPLEX | C30: ND | D30: UN | F30: 0
B31: ÁREA DE PROJEÇÃO DA TORRE | C31: APT | D31: M2 | E31: 669.946 | F31: 690.612
B32: PERÍMETRO DE PROJEÇÃO DA TORRE | C32: PPT | D32: M | E32: 112.63 | F32: 116.82
B33: ÁREA DE LAZER | C33: AL | D33: M2 | F33: =5014.3-956.89+1554.82 -> 5612.23
B34: ÁREA DO EMBASAMENTO | C34: AE | D34: M2 | F34: =E13+E14+E15+E16 -> 18140.1
B35: ÁREA DE SUBSOLOS | C35: S | D35: M2 | F35: =E10+E11+E12 -> 13736.23
B36: NÚMERO DE SUBSOLOS | C36: NS | D36: UN | F36: 3
B37: ÁREA DE PROJEÇÃO DO EMBASAMENTO | C37: APE | D37: M2 | F37: =E10 -> 4679.95 | G37: =F37/F9 -> 0.063387142
B38: PERÍMETRO DE PROJEÇÃO DE EMBAMENTO | C38: PE | D38: M | F38: 349.8
B39: NÚMERO DE PAVIMENTOS DE EMBASAMENTO | C39: NE | D39: UN | F39: 4

Sheet AREAS
B3: FASE | C3: Identificador | D3: Unidade | E3: FASE 1 | F3: FASE 2 | G3: FASE 3 | H3: FASE 4 | I3: Quantidade
B4: ÁREA DO TERRENO | C4: AT | D4: M2 | I4: 9821.77
B5: ÁREA TOTAL CONSTRUÍDA | C5: AC | D5: M2 | E5: =E6 -> 7907.87 | G5: =SUM(G6:G18) -> 41187.085 | H5: =SUM(H6:H18) -> 32985.595 | I5: =E5+G5+H5 -> 82080.55
B6: MALL 1 | D6: M2 | E6: =7907.87 -> 7907.87
B7: MALL 2 | D7: M2
B8: 2º SUBSOLO | D8: M2 | G8: 6200.52
B9: 1º SUBSOLO | D9: M2 | G9: 6027.62
B10: TERREO | D10: M2 | G10: 6094.47
B11: MEZANINO | D11: M2 | G11: 3047.1
B12: SOBRELOJA | D12: M2 | G12: =4888.74/2 -> 2444.37 | H12: =G12 -> 2444.37
B13: LAZER | D13: M2 | G13: =4081.93/2 -> 2040.965 | H13: =G13 -> 2040.965
B14: TIPO (X22) | D14: M2 | G14: =623.83+627.62+631.03+634.26+638.35+641.69+645.05+648.44+651.67+655.18+658.44+662.44+665.81+669.25+671.62+676.07+679.55+683.1*5 -> 14495.8 | H14: =74172.68-SUM(G8:G16)-H12-H13-H15-H16-H17-H18 -> 15235.88
B15: LAZER SUPERIOR | D15: M2 | G15: =683.1 -> 683.1 | H15: =1579.52-G15 -> 896.42
B16: BARRILETE 1 | D16: M2 | G16: =76.57*2 -> 153.14 | H16: 0
B17: TIPO 2 (X18) | D17: M2 | H17: =695.35*9+688.78+680.06+671.27+663.59+655.56+645.28+638.72+626.22+616.37 -> 12144
B18: BARRILETE 2 | D18: M2 | H18: =111.98*2 -> 223.96
B19: UNIDADES RESIDENCIAIS | C19: UR | D19: UN | E19: 0 | F19: 0 | G19: =22*10 -> 220 | H19: 382
B20: Dormitórios | C20: dorm | D20: UN
B21: Banheiros | C21: ban | D21: UN
B22: UNIDADES COMERCIAIS | C22: UC | D22: UN | E22: 15
B23: Churrasqueiras | C23: CHU | D23: UN
B24: NÚMERO TOTAL DE PAVIMENTOS | C24: NP | D24: UN | E24: 3 | F24: 3 | G24: 29 | H24: 43
B25: NÚMERO DE PAVIMENTOS TIPO | C25: NPT | D25: UN | G25: 22 | H25: 40
B26: NÚMERO DE PAVIMENTOS TIPO DIFERENCIADOS | C26: NPD | D26: UN | G26: 4 | H26: 3
B27: NÚMERO DE PAVIMENTOS DUPLEX | C27: ND | D27: UN
B28: ÁREA DE PROJEÇÃO DA TORRE | C28: APT | D28: M2 | E28: =INFRAESTRUTURA!D8+INFRAESTRUTURA!D20 -> 4232.4 | G28: 683.1 | H28: 695.35
B29: PERÍMETRO DE PROJEÇÃO DA TORRE | C29: PPT | D29: M | E29: 259.5 | G29: 112.63 | H29: 116.82
B30: ÁREA DE LAZER | C30: AL | D30: M2 | G30: =G13+G15 -> 2724.065 | H30: =H13+H15 -> 2937.385
B31: ÁREA DO EMBASAMENTO | C31: AE | D31: M2 | E31: =E6 -> 7907.87 | G31: =G10+G11+G12+G13 -> 13626.905 | H31: =H12+H13 -> 4485.335
B32: ÁREA DE SUBSOLOS | C32: S | D32: M2 | G32: =G8+G9 -> 12228.14
B33: NÚMERO DE SUBSOLOS | C33: NS | D33: UN | G33: 2
B34: ÁREA DE PROJEÇÃO DO EMBASAMENTO | C34: APE | D34: M2 | E34: 4232.97 | G34: =G8 -> 6200.52
B35: PERÍMETRO DE PROJEÇÃO DE EMBAMENTO | C35: PE | D35: M | G35: 349.8
B36: NÚMERO DE PAVIMENTOS DE EMBASAMENTO | C36: NE | D36: UN | G36: 4

Sheet MOVIMENTAÇÃO_DE_TERRA
A2: MOVIMENTAÇÃO DE TERRA
A3: Data | B3: 45643
A4: Arquivo base | B4: -
A6: ESCAVAÇÃO VERTICAL DE SUBSOLO
A8: Descrição | B8: Área de subsolo (m) | C8: Altura do subsolo (m) | D8: Volume total de escavação (m3) | E8: Preço unitário de escavação (R$ / m3) | F8: Valor total | G8: Observação
A9: Escavação | B9: 0 | D9: =C9*B9 -> 0 | E9: 0 | F9: =E9*D9*1.1 -> 0
A10: TOTAL | F10: =SUM(F9:F9) -> 0
A12: REBAIXAMENTO DE LENÇOL FREÁTICO
A14: Descrição | B14: Quantidade (dias) | E14: Preço unitário de rebaixamento (R$ / dias) | F14: Valor total | G14: Observação
A15: Rebaixamento de lençol | B15: 0 | E15: 200 | F15: =B15*E15*1.1 -> 0
A16: TOTAL | F16: =SUM(F15:F15) -> 0
A18: ESCAVAÇÃO E REATERRO DE VALAS
A20: Descrição | B20: Parâmetro | D20: Volume total de escavação (m3) | E20: Preço unitário (R$ / m3) | F20: Valor total | G20: Observação
A21: Escavação mecanizada para blocos e baldrames | B21: 1.3 | C21: m³ / Vol infra | D21: =B21*INFRAESTRUTURA!D35 -> 275.106 | E21: 60 | F21: =E21*D21*1.1 -> 18156.996
A22: Reaterro para blocos e baldrames | B22: 0.6 | C22: m³ / Vol Escavação | D22: =D21-INFRAESTRUTURA!D35 -> 63.486 | E22: 20 | F22: =E22*D22*1.1 -> 1396.692
A23: Movimentação de bota-fora | B23: 1.3 | D23: =(D21-D22)*B23 -> 275.106 | E23: 20 | F23: =E23*D23*1.1 -> 6052.332
A24: Movimentação de terra das estacas | B24: 1 | C24: m³ | D24: =INFRAESTRUTURA!D13 -> 518 | E24: 20 | F24: =E24*D24*1.1 -> 11396
A25: TOTAL | F25: =SUM(F21:F24) -> 37002.02
A27: REGULARIZAÇÃO E APILOAMENTO DE FUNDO DE VALAS
A29: Descrição | B29: Parâmetro | D29: Área de lastro (m²) | E29: Preço unitário (R$ / m2) | F29: Valor total | G29: Observação
A30: Lastro de concreto magto e=5cm | B30: 0.8 | C30: m² / APE | D30: =B30*DADOS_INICIAIS!F37 -> 3743.96 | E30: =370*0.05 -> 18.5 | F30: =E30*D30*1.1 -> 76189.586 | H30: =F30/DADOS_INICIAIS!F37 -> 16.28
A31: TOTAL | F31: =SUM(F30:F30) -> 76189.586
A33: TOTAL MOVIMENTAÇÃO DE TERRA | F33: =F10+F16+F25+F31 -> 113191.61 | G33: =F33/AREAS!E6 -> 14.313792 | H33: MALL

Sheet CONTENÇÕES
A3: CONTENÇÃO
A4: Data
A5: Arquivo base
A7: CORTINA DE ESTACAS
A9: Descrição | B9: Parâmetro | D9: Quantidade | F9: Preço unitário | G9: Valor total
A10: Número de Estacas | B10: 0.15 | C10: un / APE | D10: =B10*DADOS_INICIAIS!F37 -> 701.9925 | E10: un
A11: Estaca Hélice Continua Diâmetro 40 | B11: 0.1 | D11: =B11*$D$10 -> 70.19925 | E11: un
B12: 20 | C12: m/un | D12: =B12*D11 -> 1403.985 | E12: m | G12: =F12*D12 -> 0
A13: Estaca Hélice Continua Diâmetro 50 | B13: 0.5 | D13: =B13*$D$10 -> 350.99625 | E13: un
B14: 20 | C14: m/un | D14: =B14*D13 -> 7019.925 | E14: m | G14: =F14*D14 -> 0
A15: Estaca Hélice Continua Diâmetro 60 | B15: 0.4 | C15: un / APE | D15: =B15*$D$10 -> 280.797 | E15: un
B16: 20 | C16: m/un | D16: =B16*D15 -> 5615.94 | E16: m | G16: =F16*D16 -> 0
A17: Concreto | B17: =(PI()*0.4^2)/4*D14+(PI()*0.5^2)/4*D16+(PI()*0.6^2)/4*D12 -> 2381.8044 | C17: un / APE | D17: =(PI()*0.4^2)/4*D14+(PI()*0.5^2)/4*D16+(PI()*0.6^2)/4*D12 -> 2381.8044 | E17: m³ | G17: =F17*D17 -> 0
A18: Armação 6,3mm | B18: 1.6575131 | C18: kg / m³ | D18: =B18*D17 -> 3947.8721 | E18: kg | G18: =F18*D18 -> 0
A19: Armação 16mm | B19: 10.178338 | C19: kg / m³ | D19: =B19*D17 -> 24242.81 | E19: kg | G19: =F19*D19 -> 0
A20: Mobilização | B20: 1 | C20: vb | D20: 1 | E20: vb | G20: =F20*D20 -> 0
A21: TOTAL | G21: =SUM(G10:G20) -> 0
A23: PAREDE DE CONCRETO
A25: Descrição | B25: Parâmetro | D25: Quantidade | F25: Preço unitário | G25: Valor total
A26: Fabricação, montagem e desmontagem de forma para blocos e baldrames resinado | B26: 2.1 | C26: m² / APE | D26: =B26*DADOS_INICIAIS!F37 -> 9827.895 | E26: m² | G26: =F26*D26 -> 0
A27: Concreto | B27: 0.65 | C27: m³ / APE | D27: =B27*DADOS_INICIAIS!F37 -> 3041.9675 | E27: m³ | G27: =F27*D27 -> 0
A28: Armação | B28: 110 | C28: kg / m³ | D28: =B28*D27 -> 334616.43 | E28: kg | G28: =F28*D28 -> 0
A29: Mão de obra | B29: =SUPRAESTRUTURA!B15*1.5 -> 315 | C29: R$ / APE | D29: =DADOS_INICIAIS!F37 -> 4679.95 | E29: m² | F29: =B29 -> 315 | G29: =F29*D29 -> 1474184.2
A30: TOTAL | G30: =SUM(G26:G29) -> 1474184.2
A33: PAREDE DIAFRAGMA
A35: Descrição | B35: Parâmetro | D35: Quantidade | F35: Preço unitário | G35: Valor total
A36: Fabricação, montagem e desmontagem de forma para blocos e baldrames resinado | B36: 2.1 | C36: m² / APE | D36: =B36*DADOS_INICIAIS!F47 -> 0 | E36: m² | G36: =F36*D36 -> 0
A37: Concreto | B37: 0.65 | C37: m³ / APE | D37: =B37*DADOS_INICIAIS!F47 -> 0 | E37: m³ | G37: =F37*D37 -> 0
A38: Armação | B38: 110 | C38: kg / m³ | D38: =B38*D37 -> 0 | E38: kg | G38: =F38*D38 -> 0
A39: Mão de obra | B39: =SUPRAESTRUTURA!B74*1.5 -> 0 | C39: R$ / APE | D39: =DADOS_INICIAIS!F47 -> 0 | E39: m² | F39: =B39 -> 0 | G39: =F39*D39 -> 0
A40: TOTAL | G40: =SUM(G36:G39) -> 0
A46: TOTAL INFRAESTRUTURA | G46: =G21+G30 -> 1474184.2 | H46: =G46/DADOS_INICIAIS!F9 -> 19.96695

Sheet INFRAESTRUTURA
A3: INFRAESTRUTURA
A4: Data | B4: 45643
A5: Arquivo base | B5: WAV-FUN-EX-00001-MALL-IMPL-R01
E6: =D10+D22 -> 266 | F6: =E6/D10 -> 1.7051282
A7: FUNDAÇÃO PROFUNDA
D8: 2483
A9: Descrição | B9: Parâmetro | D9: Quantidade | F9: Preço unitário | G9: Valor total | H9: Observação
A10: Número de Estacas | B10: =D10/AREAS!$E$34 -> 0.036853557 | C10: un / APE | D10: =D11 -> 156 | E10: un | H10: Quantitativos trazidos de preliminar de fundação
A11: Estaca Escavada Diâmetro 50 | B11: 1 | D11: 156 | E11: un
B12: =D12/D11 -> 16.893462 | C12: m/un | D12: =45*6.34+16*14.34+54*20.34+42*24.34 -> 2635.38 | E12: m | F12: 75 | G12: =F12*D12*1.1 -> 217418.85
A13: Concreto (25 Mpa) | B13: 1.1 | C13: perda | D13: 518 | E13: m³ | F13: =510+44 -> 554 | G13: =F13*D13*B13*1.1 -> 347236.12
A14: Armação | B14: =D14/D13 -> 7.3285714 | C14: kg / m³ | D14: 3796.2 | E14: kg | F14: 7.62 | G14: =F14*D14*1.1 -> 31819.748
A15: Mobilização | B15: 1 | C15: vb | D15: 1 | E15: vb | F15: 14500 | G15: =F15*D15*1.1 -> 15950
A16: Apoio e arrasamento de estacas | D16: =D10 -> 156 | E16: un | F16: 300 | G16: =F16*D16*1 -> 46800
A17: TOTAL | G17: =SUM(G10:G16) -> 659224.72
A19: FUNDAÇÃO PROFUNDA
D20: 1749.4
A21: Descrição | B21: Parâmetro | D21: Quantidade | F21: Preço unitário | G21: Valor total | H21: Observação
A22: Número de Estacas | B22: =D22/AREAS!$E$34 -> 0.025986482 | C22: un / APE | D22: =ROUND((D10/$D$8)*$D$20,0) -> 110 | E22: un | H22: Quantitativos trazidos de preliminar de fundação
A23: Estaca Escavada Diâmetro 50 | B23: 1 | D23: =D22 -> 110 | E23: un
B24: =B12 -> 16.893462 | C24: m/un | D24: =B24*D23 -> 1858.2808 | E24: m | F24: 75 | G24: =F24*D24*1.1 -> 153308.16
A25: Concreto (25 Mpa) | B25: 1.2 | C25: perda | D25: =(D13/$D$8)*$D$20 -> 364.95739 | E25: m³ | F25: =510+44 -> 554 | G25: =F25*D25*B25*1.1 -> 266886.04
A26: Armação | B26: =D26/D25 -> 7.3285714 | C26: kg / m³ | D26: =(D14/$D$8)*$D$20 -> 2674.6163 | E26: kg | F26: 7.62 | G26: =F26*D26*1.1 -> 22418.634
A27: Mobilização | B27: 1 | C27: vb | D27: 0 | E27: vb | F27: 14500 | G27: =F27*D27*1.1 -> 0
A28: Apoio e arrasamento de estacas | D28: =D22 -> 110 | E28: un | F28: 300 | G28: =F28*D28*1 -> 33000
A29: TOTAL | G29: =SUM(G22:G28) -> 475612.84
A31: FUNDAÇÃO RASA
A33: Descrição | B33: Parâmetro | D33: Quantidade | F33: Preço unitário | G33: Valor total | H33: Observação
A34: Fabricação, montagem e desmontagem de forma para blocos e baldrames resinado | B34: 0.2 | C34: m² / APE | D34: =B34*AREAS!E28 -> 846.48 | E34: m² | F34: 68 | G34: =F34*D34*1.1 -> 63316.704
A35: Concreto (40 Mpa) | B35: 0.05 | C35: m³ / APE | D35: =B35*AREAS!E28 -> 211.62 | E35: m³ | F35: =514+44 -> 558 | G35: =F35*D35*1.05*1.1 -> 136386.97
A36: Armação | B36: 60 | C36: kg / m³ | D36: =B36*D35 -> 12697.2 | E36: kg | F36: 7.62 | G36: =F36*D36*1.1 -> 106427.93
A37: Mão de obra | B37: =SUPRAESTRUTURA!B15*1.5 -> 315 | C37: R$ / APE | D37: =AREAS!E28 -> 4232.4 | E37: m² | F37: =B37 -> 315 | G37: =F37*D37*1.1 -> 1466526.6
A38: TOTAL | G38: =SUM(G34:G37) -> 1772658.2
A41: TOTAL INFRAESTRUTURA | G41: =G17+G38+G29 -> 2907495.8 | H41: =G41/AREAS!E6 -> 367.67116
D44: =0.8*4*0.8*(D22+D10) -> 680.96
D45: =0.8*0.8*0.8*(D22+D10) -> 136.192

Sheet SUPRAESTRUTURA
A3: SUPRAESTRUTURA
A4: Data | B4: 45643
A5: Arquivo base | B5: -
A7: SUPRAESTRUTURA - LAJE MACIÇA
A9: Descrição | B9: Parâmetro | D9: Quantidade | F9: Preço unitário | G9: Valor total | H9: Observação
A10: Fabricação forma | B10: 2 | C10: Jogos | D10: =(D11/AREAS!E24)*B10 -> 8239.92 | E10: m² | F10: 110 | G10: =F10*D10*1.1 -> 997030.32
A11: Montagem de forma | B11: 2.5 | C11: m² / AC | D11: =(935+1934+1341+2243+775)*1.71 -> 12359.88 | E11: m² | F11: 2.5 | G11: =F11*D11*1.1 -> 33989.67 | H11: Qauntitativo de projeto acrescido 71% para fase 2
A12: Escoramento | B12: 4 | C12: un / AE | D12: =ROUNDUP(B12*AREAS!E28*B10,0) -> 33860 | E12: un | F12: =17 -> 17 | G12: =F12*D12*1.1 -> 633182
A13: Concreto | B13: 0.2 | C13: m³ / AC | D13: =(105.5+224+513+327+102.5)*1.71 -> 2175.12 | E13: m³ | F13: =514+44 -> 558 | G13: =F13*D13*1.05*1.1 -> 1401843.1 | H13: Qauntitativo de projeto acrescido 71% para fase 2
A14: Armadura Convencional para Estrutura | B14: 90 | C14: kg / m³ | D14: =D13*B14 -> 195760.8 | E14: kg | F14: 7.62 | G14: =F14*D14*1.1 -> 1640867
A15: Mão de obra - estrutura em concreto armado | B15: 210 | C15: R$ / AC | D15: =AREAS!E6 -> 7907.87 | E15: m² | F15: 210 | G15: =F15*D15*1.1 -> 1826718
A16: Perfuração de vigas | B16: 1500 | C16: R$ / NP | D16: 1 | E16: vb | F16: =B16*AREAS!E24 -> 4500 | G16: =F16*D16*1.1 -> 4950 | H16: Coeficiente originário do Gran Torino (R$ 160,00/un) | I16: Nova utiliza a verba de 1.500,00 por pav
A17: TOTAL | G17: =SUM(G10:G16) -> 6538580.1 | K17: =4160+1440+1120+2880+4800+91680+4000 -> 110080 | L17: =K17/21 -> 5241.9048
A19: SUPRAESTRUTURA - LAJE CUBETAS PROTENDIDAS
A21: Descrição | B21: Parâmetro | D21: Quantidade | F21: Preço unitário | G21: Valor total | H21: Observação
A22: Fabricação forma | B22: 2 | C22: Jogos | D22: =(D23/DADOS_INICIAIS!$F$27)*B22 -> 7383.122 | E22: m² | F22: 110 | G22: =F22*D22*1.1 -> 893357.76
A23: Montagem de forma | B23: 2.1 | C23: m² / AC | D23: =B23*DADOS_INICIAIS!$F$9 -> 155045.56 | E23: m² | F23: 2.5 | G23: =F23*D23*1.1 -> 426375.3
A24: Escoramento | B24: 3 | C24: un / APT*NPT | D24: =ROUNDUP(B24*DADOS_INICIAIS!$F$37*B22,0) -> 28080 | E24: un | F24: =17 -> 17 | G24: =F24*D24*1.1 -> 525096
A25: Cubetas | B25: 25 | C25: R$ / AC | D25: 1 | E25: vb | F25: =B25*DADOS_INICIAIS!$F$9 -> 1845780.5 | G25: =F25*D25*1.1 -> 2030358.6
A26: Protensão - lajes - materiais | B26: =12.3*0.8 -> 9.84 | C26: RS / m² | D26: =(DADOS_INICIAIS!$F$28+DADOS_INICIAIS!$F$29)*DADOS_INICIAIS!$F$31+DADOS_INICIAIS!$F$34 -> 45073.968 | E26: m² | F26: =B26 -> 9.84 | G26: =F26*D26*1.1 -> 487880.63
A27: Protensão - lajes - cabos | B27: =2.83*0.8 -> 2.264 | C27: kg / m² | D27: =B27*D26 -> 102047.46 | E27: kg | F27: 12.3 | G27: =F27*D27*1.1 -> 1380702.2
A28: Protensão - lajes - serviços | B28: 9000 | C28: und / pav | D28: =DADOS_INICIAIS!F27 -> 42 | E28: pav | F28: =B28 -> 9000 | G28: =F28*D28*1.1 -> 415800
A29: Concreto | B29: 0.18 | C29: m³ / AC | D29: =B29*DADOS_INICIAIS!$F$9 -> 13289.62 | E29: m³ | F29: =535+45 -> 580 | G29: =F29*D29*1.05*1.1 -> 8902716.2
A30: Cristalizante (reservatorios) | B30: 0.2 | D30: =B30*D29 -> 2657.9239 | E30: m³ | F30: =1.22*F29-F29 -> 127.6 | G30: =F30*D30*1.05*1.1 -> 391719.51
A31: Armadura Convencional para Estrutura | B31: 110 | C31: kg / m³ | D31: =D29*B31-D27 -> 1359810.7 | E31: kg | F31: 7.62 | G31: =F31*D31*1.1 -> 11397933
A32: Mão de obra - estrutura em concreto armado | B32: 240 | C32: R$ / AC | D32: =DADOS_INICIAIS!$F$9 -> 73831.22 | E32: m² | F32: =B32 -> 240 | G32: =F32*D32*1.1 -> 19491442
A33: Perfuração de vigas | B33: 5300 | C33: R$ / NP | D33: 1 | E33: vb | F33: =B33*DADOS_INICIAIS!$F$27 -> 222600 | G33: =F33*D33*1.1 -> 244860 | H33: Coeficiente originário do Gran Torino (R$ 160,00/un)
A34: TOTAL | G34: =SUM(G22:G33) -> 46588241
A36: SUPRAESTRUTURA - LAJE TRELIÇADA
A38: Descrição | B38: Parâmetro | D38: Quantidade | F38: Preço unitário | G38: Valor total | H38: Observação
A39: Fabricação forma | B39: 2 | C39: Jogos | D39: =(D40/DADOS_INICIAIS!$F$27)*B39 -> 0 | E39: m² | F39: 85 | G39: =F39*D39*1.1 -> 0
A40: Montagem de forma | B40: 2.1 | C40: m² / AC | D40: =B40*DADOS_INICIAIS!F50 -> 0 | E40: m² | F40: 1.5 | G40: =F40*D40*1.1 -> 0
A41: Escoramento - Torre | B41: 2 | C41: un / APT*NPT | D41: =B41*DADOS_INICIAIS!F59*DADOS_INICIAIS!F56 -> 0 | E41: un | F41: 17 | G41: =F41*D41*1.1 -> 0
A42: Escoramento - Embasamento | B42: 2 | C42: un / AE | D42: =B42*DADOS_INICIAIS!F62 -> 0 | E42: un | F42: 17 | G42: =F42*D42*1.1 -> 0
A43: Cubetas | B43: 25 | C43: R$ / AC | D43: =B43*DADOS_INICIAIS!F50 -> 0 | E43: m³ | F43: =B43 -> 25 | G43: =F43*D43*1.1 -> 0
A44: Concreto | B44: 0.25 | C44: m³ / AC | D44: =B44*DADOS_INICIAIS!F50 -> 0 | E44: m³ | F44: =575 -> 575 | G44: =F44*D44*1.05*1.1 -> 0
A45: Armadura Convencional para Estrutura | B45: 110 | C45: kg / m³ | D45: =D44*B45 -> 0 | E45: kg | F45: 7.25 | G45: =F45*D45*1.1 -> 0
A46: Mão de obra - estrutura em concreto armado | B46: 240 | C46: R$ / AC | D46: =DADOS_INICIAIS!F50 -> 0 | E46: m² | F46: =B46 -> 240 | G46: =F46*D46*1.1 -> 0
A47: Perfuração de vigas | B47: 5300 | C47: R$ / NP | D47: 1 | E47: vb | F47: =B47*DADOS_INICIAIS!F55 -> 0 | G47: =F47*D47*1.1 -> 0 | H47: Coeficiente originário do Gran Torino (R$ 160,00/un)
A48: TOTAL | G48: =SUM(G39:G47) -> 0
...

Sheet ALVENARIA
A3: PAREDES E PAINÉIS
A4: Data | B4: 45457
A5: Arquivo base | B5: -
A7: ALVENARIA
A9: Descrição | B9: Parâmetro | D9: Quantidade | F9: Preço unitário | G9: Valor total | H9: Observação
A10: Alvenaria embasamento | B10: 0.5 | C10: m² / AE | D10: =B10*AREAS!E6*(1.33) -> 5258.7335 | E10: m² | F10: 45 | G10: =F10*D10*1.1 -> 260307.31
A11: Alvenaria escadas | B11: 0.2 | C11: m² / AC | D11: =559.33*1.67 -> 934.0811 | E11: m² | F11: 70 | G11: =F11*D11*1.05*1.1 -> 75520.457
A12: Alvenaria refratárias | B12: 1.75 | C12: m² * CHU | D12: =B12*DADOS_INICIAIS!$F$26 -> 0 | E12: un | F12: 210 | G12: =F12*D12*1.1 -> 0
A13: Serviços complementares | B13: 12.5 | C13: R$ / m² | D13: =D10+D11 -> 6192.8147 | E13: m² | F13: =B13 -> 12.5 | G13: =F13*D13*1.1 -> 85151.201
A14: Mão de obra | B14: 35 | C14: R$ / m² | D14: =D10+D11 -> 6192.8147 | E14: m² | F14: 35 | G14: =F14*D14*1.1 -> 238423.36
A15: TOTAL | G15: =SUM(G10:G14) -> 659402.33 | K15: =4160+1440+1120+2880+4800+91680+4000 -> 110080 | L15: =K15/21 -> 5241.9048
A17: ALVENARIA - DRTWALL
A19: Descrição | B19: Parâmetro | D19: Quantidade | F19: Preço unitário | G19: Valor total | H19: Observação
A20: Alvenaria embasamento | B20: 1 | C20: m² / AE | D20: =B20*DADOS_INICIAIS!$F$34 -> 18140.1 | E20: m² | F20: 45 | G20: =F20*D20*1.1 -> 897934.95
A21: Alvenaria lazer | B21: 0.4 | C21: m² / AL | D21: =B21*DADOS_INICIAIS!$F$33 -> 2244.892 | E21: m² | F21: 45 | G21: =F21*D21*1.1 -> 111122.15
A22: Alvenaria tipo | B22: 1.62 | C22: m² / APT*(NPT+2ND) | D22: =B22*(DADOS_INICIAIS!$F$31*(DADOS_INICIAIS!$F$28+DADOS_INICIAIS!$F$29))*0.3 -> 13089.86 | E22: un | F22: 45 | G22: =F22*D22*1.1 -> 647948.06
A23: Drywall tipo | B23: 1.65 | C23: m² / APT*(NPT+2ND) | D23: =B23*(DADOS_INICIAIS!$F$31*(DADOS_INICIAIS!$F$28+DADOS_INICIAIS!$F$29))*0.7 -> 31108.618 | F23: 220 | G23: =F23*D23*1.1 -> 7528285.4 | J23: =D23/(D28+D23) -> 0.38933367
A24: Alvenaria escadas | B24: 0.2 | C24: m² / AC | D24: =B24*DADOS_INICIAIS!$F$9 -> 14766.244 | E24: un | F24: 70 | G24: =F24*D24*1.1 -> 1137000.8 | J24: =1-J23 -> 0.61066633
A25: Alvenaria cobertura / reservatório | B25: 0.8 | C25: m² / APT | D25: =B25*DADOS_INICIAIS!$F$31 -> 552.4896 | E25: m³ | F25: 45 | G25: =F25*D25*1.1 -> 27348.235
A26: Alvenaria refratárias | B26: 1.75 | C26: m² * CHU | D26: ='SISTEMAS ESPECIAIS'!B10 -> 0 | E26: un | F26: 210
A27: Churrasqueiras pré-moldadas | D27: =D26 -> 0 | E27: un | F27: 1800 | G27: =F27*D27*1.1 -> 0
A28: Serviços complementares | B28: 12.5 | C28: R$ / m² | D28: =D21+D22+D20+D24+D25 -> 48793.585 | E28: kg | F28: =B28 -> 12.5 | G28: =F28*D28*1.1 -> 670911.8
A29: Mão de obra | B29: 35 | C29: R$ / m² | D29: =D21+D22+D20+D24+D25 -> 48793.585 | E29: m² | F29: 35 | G29: =F29*D29*1.1 -> 1878553
A30: TOTAL | G30: =SUM(G20:G29) -> 12899104
A33: TOTAL ALVENARIA | G33: =G15 -> 659402.33 | H33: =G33/AREAS!E6 -> 83.385581
D36: =D14*2 -> 12385.629 | G36: =G33/1.1 -> 599456.67 | H36: =G36/DADOS_INICIAIS!F9 -> 8.1192843
A38: 1496.49
C42: 4139 | D42: =C42/INFRAESTRUTURA!D8 -> 1.6669352

Sheet INSTALAÇÕES
A2: INSTALAÇÕES
A4: INSTALAÇÕES ELÉTRICAS
A6: Descrição | B6: Parâmetro | D6: Valor total
A7: Entrada de Energia | B7: 30 | C7: R$ / AC | D7: =B7*AREAS!$E$6*1.1 -> 260959.71
A8: Eletrodutos e Eletrocalhas | B8: 15 | C8: R$ / AC | D8: =B8*AREAS!$E$6*1.1 -> 130479.86
A9: Cabos e Fiações | B9: 35 | C9: R$ / AC | D9: =B9*AREAS!$E$6*1.1 -> 304453
A10: Quadros e Disjuntores | B10: 6 | C10: R$ / AC | D10: =B10*AREAS!$E$6*1.1 -> 52191.942
A11: Acabamentos Elétricos | B11: 8 | C11: R$ / AC
A12: Equipamentos e Iluminação | B12: 2 | C12: R$ / AC | D12: =B12*AREAS!$E$6*1.1 -> 17397.314
A13: Mão de Obra para Instalações Elétricas | B13: 60 | C13: R$ / AC | D13: =B13*AREAS!$E$6*1.1 -> 521919.42
A14: TOTAL | D14: =SUM(D7:D13) -> 1287401.2
A16: INSTALAÇÕES HIDROSSANITÁRIAS
A18: Descrição | B18: Parâmetro | D18: Valor total
A19: Instalações de Água Fria | B19: 20 | C19: R$ / AC | D19: =B19*AREAS!$E$6*1.1 -> 173973.14
A20: Instalações de Água Quente | B20: 10 | C20: R$ / AC | D20: =B20*AREAS!$E$6*1.1 -> 86986.57
A21: Instalações de Águas Pluviais | B21: 10 | C21: R$ / AC | D21: =B21*AREAS!$E$6*1.1 -> 86986.57
A22: Instalações Sanitárias | B22: 15 | C22: R$ / AC | D22: =B22*AREAS!$E$6*1.1 -> 130479.86
A23: Louças e Metais | B23: 50 | C23: R$ / AC | D23: =B23*AREAS!$E$6*1.1 -> 434932.85
A24: Mão de Obra para Instalações Hidráulicas | B24: 55 | C24: R$ / AC | D24: =B24*AREAS!$E$6*1.1 -> 478426.14
A25: TOTAL | D25: =SUM(D19:D24) -> 1391785.1
A27: INSTALAÇÕES PREVENTIVAS E GLP
A29: Descrição | B29: Parâmetro | D29: Valor total
A30: Instalações Preventivas | B30: 9.5 | C30: R$ / AC | D30: =B30*AREAS!$E$6*1.1 -> 82637.242
A31: Instalações de GLP | B31: 2 | C31: R$ / AC | D31: =B31*AREAS!$E$6*1.1 -> 17397.314
A32: Instalações de Proteção e Aterramento - SPDA | B32: 4 | C32: R$ / AC | D32: =B32*AREAS!$E$6*1.1 -> 34794.628
A33: Mão de obra | B33: 12 | D33: =B33*AREAS!$E$6*1.1 -> 104383.88
A34: TOTAL | D34: =SUM(D30:D33) -> 239213.07
A36: TOTAL INSTALAÇÕES | D36: =D14+D25+D34 -> 2918399.4 | E36: =D36/AREAS!$E$6 -> 369.05
E38: =E36/1.1 -> 335.5

Sheet SISTEMAS ESPECIAIS
A2: SISTEMAS ESPECIAIS
A4: CLIMATIZAÇÃO, EXAUSTÃO MECÂNICA E PRESSURIZAÇÃO
A6: Descrição | B6: Quantidade | C6: Preço Unitário | D6: Valor total | G6: TERREO | H6: 1 PV | I6: 2 PAV | J6: 3PAV | K6: COB
A7: Infraestrutura para Instalação de Ar Condicionado | B7: =SUM(G7:J7) -> 35 | C7: 1500 | D7: =B7*C7*1.1 -> 57750 | G7: =17+8 -> 25 | H7: 0 | I7: =2+2+3+3 -> 10
A8: Instalação de Ar Condicionado | B8: =SUM(G8:O8) -> 35 | C8: 5000 | D8: =B8*C8*1.1 -> 192500 | G8: =G7 -> 25 | H8: =H7 -> 0 | I8: =I7 -> 10
A9: Ventokit | B9: =SUM(G9:O9) -> 31 | C9: 900 | D9: =B9*C9*1.1 -> 30690 | G9: =6+11 -> 17 | I9: =7+7 -> 14
A10: Churrasqueiras | B10: 0 | C10: 2600 | D10: =B10*C10*1.1 -> 0
A11: TOTAL | D11: =SUM(D7:D10) -> 280940
A13: COMUNICAÇÃO
A15: Descrição | B15: Parâmetro | D15: Valor total
A16: CFTV | B16: 5 | C16: R$ / AC | D16: =B16*AREAS!$E$6*1.1 -> 43493.285
A17: Interfone | B17: 0 | C17: R$ / AC | D17: =B17*AREAS!$E$6*1.1 -> 0
A18: TV e internet | B18: 4 | C18: R$ / AC | D18: =B18*AREAS!$E$6*1.1 -> 34794.628
A19: Automação, telecomunicação e sistemas de segurança | B19: 10 | C19: R$ / AC | D19: =B19*AREAS!$E$6*1.1 -> 86986.57
A20: TOTAL | D20: =SUM(D16:D19) -> 165274.48
A22: EQUIPAMENTOS
A24: Descrição | B24: Quantidade | C24: Preço Unitário | D24: Valor total
A25: Elevadores | B25: 4 | C25: 151569.28 | D25: =B25*C25*1.1 -> 666904.83 | E25: 4 PARADAS
A26: Grupo de geradores | B26: 0 | C26: 80000 | D26: =B26*C26*1.1 -> 0
A27: Subestação | B27: 1 | C27: 350000 | D27: =B27*C27*1.1 -> 385000
A28: Escada pressurizada | B28: 0 | C28: =50*DADOS_INICIAIS!F9 -> 3691561 | D28: =B28*C28*1.1 -> 0
A29: Bombas | B29: 1 | C29: 4500 | D29: =B29*C29*1.1 -> 4950
A30: Trataamento de esgoto | B30: 0 | C30: 110000 | D30: =B30*C30*1.1 -> 0
A31: Infra de carro elétrico | B31: 0 | C31: 547 | D31: =B31*C31*1.1 -> 0
A32: Equipamento d ecarro eletrico | B32: 0 | C32: 10500 | D32: =B32*C32*1.1 -> 0
A33: Equipamentos para Sauna | B33: 0 | C33: 8500 | D33: =B33*C33*1.1 -> 0
A34: Equipamentos para Espelho dagua | B34: 1 | C34: 25000 | D34: =B34*C34*1.1 -> 27500
A35: Equipamentos para Chafariz | B35: =2+4 -> 6 | C35: 12000 | D35: =B35*C35*1.1 -> 79200
A36: Equipamentos para Piscina | B36: 0 | C36: 25000 | D36: =B36*C36*1.1 -> 0
A37: TOTAL | D37: =SUM(D25:D36) -> 1163554.8
A39: OUTROS SISTEMAS ESPECIAIS
A41: Descrição | B41: Parâmetro | D41: Valor total
A42: Outros sistemas | B42: 30 | C42: R$ / AC | D42: =B42*AREAS!E6*1.1 -> 260959.71
A43: TOTAL | D43: =SUM(D42:D42) -> 260959.71
A45: TOTAL SISTEMAS ESPECIAIS | D45: =D11+D20+D37+D43 -> 1870729 | E45: =D45/AREAS!E6 -> 236.56548

Sheet IMPERMEABILIZAÇÃO
A3: IMPERMEABILIZAÇÃO
A4: Data | B4: 45457
A5: Arquivo base | B5: -
A7: ALVENARIA
A9: Descrição | B9: Parâmetro | D9: Quantidade | F9: Preço unitário | G9: Valor total | H9: Observação
A10: Regularização de Superfície | B10: 25 | C10: R$ / m² | D10: =D15+D16 -> 953.639 | E10: m² | F10: 22 | G10: =F10*D10*1.1 -> 23078.064
A11: Poço do elevador | B11: 45 | C11: R$ / m² | D11: =((2.15*2.15)+(2.15+2.15)*2*1.8)*4 -> 80.41 | E11: m² | F11: 41 | G11: =F11*D11*1.1 -> 3626.491
A12: Baldrames | B12: 30 | C12: R$ / m² | D12: =INFRAESTRUTURA!D34 -> 846.48 | E12: m² | F12: 35 | G12: =F12*D12*1.1 -> 32589.48
A13: Ralos | B13: 0.25 | C13: R$ / AC | D13: 1 | E13: vb | F13: =B13*AREAS!E6 -> 1976.9675 | G13: =F13*D13*1.1 -> 2174.6643
A14: Tratamento de frisos | B14: 0.15 | C14: m²/m | E14: m | F14: 60 | G14: =D14*B14*F14*1.1 -> 0
A15: Impermeabilizações cimenticias | B15: 0.3 | C15: m² / AC | D15: =(16.02*2+40.71+31.48*2)*1.2 -> 162.852 | E15: m² | F15: 60 | G15: =F15*D15 -> 9771.12
A16: Impermeabilizações com manta asfaltica | B16: 0.1 | C16: m² / AC | D16: =B16*AREAS!E6 -> 790.787 | E16: m² | F16: 110 | G16: =F16*D16*1.1 -> 95685.227
A17: Impermeabilização de peitoril | B17: 0.6 | C17: R$ / AC | D17: 1 | E17: vb | F17: =B17*AREAS!E6 -> 4744.722 | G17: =F17*D17*1.1 -> 5219.1942
A18: Cristalização elementos aparentes | D18: =SUPRAESTRUTURA!D13*0.4 -> 870.048 | E18: m3 | F18: 60 | G18: =F18*D18*1.1 -> 57423.168
A19: Proteção Mecânica | B19: 28 | C19: R$ / m² | D19: =D16 -> 790.787 | E19: m² | F19: 28 | G19: =F19*D19*1.1 -> 24356.24
A20: TOTAL | G20: =SUM(G10:G19) -> 253923.65 | K20: =4160+1440+1120+2880+4800+91680+4000 -> 110080 | L20: =K20/21 -> 5241.9048
A22: TOTAL IMPERMEABILIZAÇÃO | G22: =G20 -> 253923.65 | H22: =G22/AREAS!E6 -> 32.110246
H25: =H22/1.1 -> 29.191132

Sheet AMBIENTES
A1: Obra
A2: Empresa
A3: Revisão
A4: Data
A5: LEVANTAMENTO QUANTITATIVO
A7: REVESTIMENTOS E ACABAMENTOS DE PISO
B9: LEVANTAMENTO DE PROJETO | K9: CONTRAPISO
B10: Pavimento | C10: Local | D10: Piso | E10: Teto | F10: Área (m²) | G10: Contrapiso (Sim/Não) | H10: Repetição | I10: Total | K10: Revestimento | L10: Área total
B11: TÉRREO | C11: Interno lojas - fase 1 | D11: Porcelanato | E11: Gesso | F11: 1077.0758 | G11: Sim | H11: 1 | I11: =F11*H11 -> 1077.0758 | K11: Contrapiso | L11: =SUMIF(G:G,"Sim",I:I) -> 8639.8201 | M11: =L11/AREAS!E6 -> 1.0925597
B12: TÉRREO | C12: Interno tecnicos - fase 1 | D12: Porcelanato | E12: Gesso | F12: 405.2659 | G12: Sim | H12: 1 | I12: =F12*H12 -> 405.2659 | K12: Manta acústica | L12: =SUMIFS(I:I,G:G,"Sim",C:C,"*APT*") -> 0
B13: TÉRREO | C13: Escadas - fase 1 | D13: Porcelanato | F13: =(1.2*0.22*18+1.2*0.18*19)*2+(1.2*0.22*35+1.2*0.18*36)+2.73*2 -> 40.188 | G13: Sim | H13: 1 | I13: =F13*H13 -> 40.188
B14: TÉRREO | C14: Externo - fase 1 | D14: Porcelanato | E14: Gesso | F14: 996.3604 | G14: Sim | H14: 1 | I14: =F14*H14 -> 996.3604 | K14: PISO
B15: TÉRREO | C15: Calçada garden | D15: Calçada | F15: 2360.4381 | G15: Não | H15: 1 | I15: =F15*H15 -> 2360.4381 | K15: Material | L15: Área total
B16: TÉRREO | C16: Interno lojas - fase 2 | D16: Porcelanato | E16: Gesso | F16: =101.93+27.4+31.4*3+85.26+71.53+31.4*3+27.4*2+106.46+40.54+20.34+20.34+40.54+16.04*2+3.15 -> 792.77 | G16: Sim | H16: 1 | I16: =F16*H16 -> 792.77 | K16: Porcelanato | L16: =SUMIF(D:D,K16,I:I) -> 8639.8201
A17: =IF(C16="*&APTO&*","OK","") | B17: TÉRREO | C17: Interno tecnicos - fase 2 | D17: Porcelanato | E17: Gesso | F17: =93.12+77.28+16 -> 186.4 | G17: Sim | H17: 1 | I17: =F17*H17 -> 186.4 | K17: Calçada | L17: =SUMIF(D:D,K17,I:I) -> 2360.4381
B18: TÉRREO | C18: Escadas - fase 2 | D18: Porcelanato | F18: =(1.2*0.22*18+1.2*0.18*19+2.4*1.2)*4+(1.2*0.22*16+1.2*0.18*17+1.2*1.2*4)*2+(1.2*0.22*18+1.2*0.18*19+2+1.2*1.2) -> 86.552 | G18: Sim | H18: 1 | I18: =F18*H18 -> 86.552 | K18: Polido | L18: =SUMIF(D:D,K18,I:I) -> 1477
B19: TÉRREO | C19: Externo - fase 2 | D19: Porcelanato | E19: Gesso | F19: 426.43 | G19: Sim | H19: 1 | I19: =F19*H19 -> 426.43 | L19: =SUMIF(D:D,K19,I:I) -> 0
B20: TÉRREO | C20: Interno circ - fase 2 | D20: Porcelanato | E20: Gesso | F20: 182.3 | G20: Sim | H20: 1 | I20: =F20*H20 -> 182.3 | L20: =SUMIF(D:D,K20,I:I) -> 0
B21: TÉRREO | C21: Estacionamento | D21: Polido | F21: 1477 | G21: Não | H21: 1 | I21: =F21*H21 -> 1477 | L21: =SUMIF(D:D,K21,I:I) -> 0
B22: PAV 1 (MEZANINO) | C22: Interno lojas - fase 1 | D22: Porcelanato | E22: Gesso | F22: 592.01 | G22: Sim | H22: 1 | I22: =F22*H22 -> 592.01 | L22: =SUMIF(D:D,K22,I:I) -> 0
B23: PAV 1 (MEZANINO) | C23: Interno tecnicos - fase 1 | D23: Porcelanato | E23: Gesso | F23: 265.03 | G23: Sim | H23: 1 | I23: =F23*H23 -> 265.03 | L23: =SUMIF(D:D,K23,I:I) -> 0
B24: PAV 1 (MEZANINO) | C24: Escadas - fase 1 | D24: Porcelanato | F24: =(1.2*0.22*18+1.2*0.18*19)*2+(1.2*0.22*35+1.2*0.18*36)+2.73*2 -> 40.188 | G24: Sim | H24: 1 | I24: =F24*H24 -> 40.188 | K24: TETO
B25: PAV 1 (MEZANINO) | C25: Interno lojas - fase 2 | D25: Porcelanato | E25: Gesso | F25: =49.64+23.6*2+27.4+48.79 -> 173.03 | G25: Sim | H25: 1 | I25: =F25*H25 -> 173.03 | K25: Material | L25: Área total
B26: PAV 1 (MEZANINO) | C26: Interno tecnicos - fase 2 | D26: Porcelanato | E26: Gesso | F26: =39.36*2 -> 78.72 | G26: Sim | H26: 1 | I26: =F26*H26 -> 78.72 | K26: Gesso | L26: =SUMIF(E:E,K26,I:I) -> 8171.1721
B27: PAV 1 (MEZANINO) | C27: Interno circ - fase 2 | D27: Porcelanato | E27: Gesso | F27: 182.3 | G27: Sim | H27: 1 | I27: =F27*H27 -> 182.3 | K27: Estucamento | L27: =SUMIF(E:E,K27,I:I) -> 0
B28: PAV 1 (MEZANINO) | C28: Escadas - fase 2 | D28: Porcelanato | F28: =(1.2*0.22*18+1.2*0.18*19+2.4*1.2)*2+(1.2*0.22*16+1.2*0.18*17+1.2*1.2*4)*2+(1.2*0.22*18+1.2*0.18*19+2+1.2*1.2) -> 63.08 | G28: Sim | H28: 1 | I28: =F28*H28 -> 63.08 | L28: =SUMIF(E:E,K28,I:I) -> 0
B29: PAV 2 (SOBRELOJA) | C29: Interno lojas - fase 1 | D29: Porcelanato | E29: Gesso | F29: 1744.6 | G29: Sim | H29: 1 | I29: =F29*H29 -> 1744.6 | L29: =SUMIF(E:E,K29,I:I) -> 0
B30: PAV 2 (SOBRELOJA) | C30: Interno circ - fase 1 | D30: Porcelanato | F30: 128.74 | G30: Sim | H30: 1 | I30: =F30*H30 -> 128.74 | L30: =SUMIF(E:E,K30,I:I) -> 0
B31: PAV 2 (SOBRELOJA) | C31: Interno lojas - fase 2 | D31: Porcelanato | E31: Gesso | F31: 1068.88 | G31: Sim | H31: 1 | I31: =F31*H31 -> 1068.88 | L31: =SUMIF(E:E,K31,I:I) -> 0
B32: PAV 2 (SOBRELOJA) | C32: Escadas - fase 2 | D32: Porcelanato | F32: =(1.2*0.22*18+1.2*0.18*19+2.4*1.2)*2+(1.2*0.22*16+1.2*0.18*17+1.2*1.2*4)*2+(1.2*0.22*18+1.2*0.18*19+2+1.2*1.2) -> 63.08 | G32: Sim | H32: 1 | I32: =F32*H32 -> 63.08 | L32: =SUMIF(E:E,K32,I:I) -> 0
B33: PAV 3 | C33: Concreto - fase 1 | F33: 2042.13 | G33: Não | H33: 1 | I33: =F33*H33 -> 2042.13 | L33: =SUMIF(E:E,K33,I:I) -> 0
B34: PAV 3 | C34: Telhado - fase 1 | F34: 917.6 | G34: Não | H34: 1 | I34: =F34*H34 -> 917.6 | L34: =SUMIF(E:E,K34,I:I) -> 0
B35: PAV 3 | C35: Pavimentos tec - fase 2 | D35: Porcelanato | F35: =23.41*2 -> 46.82 | G35: Sim | H35: 1 | I35: =F35*H35 -> 46.82 | L35: =SUMIF(E:E,K35,I:I) -> 0
B36: PAV 3 | C36: Telhado - fase 2 | F36: =1.985*2 -> 3.97 | G36: Não | H36: 1 | I36: =F36*H36 -> 3.97 | L36: =SUMIF(E:E,K36,I:I) -> 0
B37: COB | C37: Telhado - fase 2 | F37: =25.08*2 -> 50.16 | G37: Não | H37: 1 | I37: =F37*H37 -> 50.16

Sheet Rev. Internos Piso e Parede
A2: ORÇAMENTO PARAMÉTRICO GERENCIAMENTO EXECUTIVO
A7: Cliente | B7: Amalfi
A8: Obra | B8: San Felicce
A9: Data | B9: 45397
A10: Revisão | B10: R00
A12: REVESTIMENTOS INTERNOS EM PISO E PAREDE
J13: =SUM(G15:G18) -> 716428.57
A14: Descrição | B14: Quantidade | D14: Parâmetro | F14: Referência | G14: Valor total | J14: =G19+G20 -> 705964.17
A15: Polimento de concreto | B15: =AMBIENTES!L18 -> 1477 | C15: m² | D15: =(16.5+550*0.1)*1.3 -> 92.95 | E15: R$ / m² | F15: Média | G15: =D15*B15*1.1 -> 151015.87
A16: Piso alisado | B16: 0 | C16: m² | D16: 25 | E16: R$ / m² | F16: Média | G16: =D16*B16*1.1 -> 0
A17: Contrapiso | B17: =AREAS!E6 -> 7907.87 | C17: m² | D17: =B17/DADOS_INICIAIS!F9 -> 0.1071074 | E17: m² / AC | F17: Média | G17: =+B17*65*1.1 -> 565412.71
A18: Manta acústica | B18: =AMBIENTES!L12 -> 0 | C18: m² | D18: =B18/DADOS_INICIAIS!F9 -> 0 | E18: m² / AC | F18: Média | G18: =+B18*25*1.1 -> 0
A19: Chapisco | B19: =ALVENARIA!D14*2-'Rev. Fachada'!B15 -> 11668.829 | C19: m² | D19: 2 | E19: m² / AC | F19: Média | G19: =+B19*5*1.1 -> 64178.561
A20: Reboco | B20: =B19 -> 11668.829 | C20: m² | D20: 2 | E20: m² / AC | F20: Média | G20: =50*B20*1.1 -> 641785.61
A21: TOTAL | G21: =SUM(G15:G20) -> 1422392.7
A24: TOTAL REVESTIMENTOS | G24: =G21 -> 1422392.7 | H24: =G24/AREAS!E6 -> 179.87053
H26: =H24/1.1 -> 163.51866
B27: =B19+'Rev. Fachada'!B15 -> 12385.629

Sheet TETO
A3: REVESTIMENTOS E ACABAMENTOS DE TETO
A4: Data | B4: 45457
A5: Arquivo base | B5: -
A7: ALVENARIA
A9: Descrição | B9: Parâmetro | D9: Quantidade | F9: Preço unitário | G9: Valor total | H9: Observação
A10: Forro acartonado | B10: 0.8 | C10: m² / AC | D10: =AREAS!$E$6*TETO!B10*0.6 -> 3795.7776 | E10: m² | F10: 120
A11: Negativo | B11: 1.2 | C11: m / FORRO | D11: =D10*B11 -> 4554.9331 | E11: m² | F11: 22
A12: Forro madeira | C12: m² / AC | D12: =AREAS!$E$6*TETO!B10*0.4 -> 2530.5184 | E12: m² | F12: 579
A13: Estucamento | B13: 0.1 | C13: m² / AC | D13: =AREAS!$E$6*TETO!B13 -> 790.787 | E13: m² | F13: 24 | G13: =F13*D13*1.1 -> 20876.777
A14: Chapisco e reboco | B14: =1-B10-B13 -> 0.1 | C14: m² / AC | D14: 0 | E14: m² | F14: 91 | G14: =F14*D14*1.05*1.1 -> 0
A15: TOTAL | G15: =SUM(G10:G14) -> 20876.777 | K15: =4160+1440+1120+2880+4800+91680+4000 -> 110080 | L15: =K15/21 -> 5241.9048
A17: TOTAL IMPERMEABILIZAÇÃO | G17: =G15 -> 20876.777 | H17: =G17/AREAS!E6 -> 2.64
H20: =H17/1.1 -> 2.4

Sheet Acabamentos de Piso e Parede
A2: ORÇAMENTO PARAMÉTRICO GERENCIAMENTO EXECUTIVO
A7: Cliente | B7: Amalfi
A8: Obra | B8: San Felicce
A9: Data | B9: 45397
A10: Revisão | B10: R00
A12: ACABAMENTOS EM PISO E PAREDE
A14: Descrição | B14: Quantidade | D14: Parâmetro | F14: Referência | G14: Valor total
A15: Porcelanato | B15: =AMBIENTES!L16 -> 8639.8201 | C15: m² | D15: 125 | E15: R$ / m² | F15: Média
A16: Cerâmico | C16: m² | D16: 98 | E16: R$ / m² | F16: Média | G16: =+D16*B16*1.1 -> 0
A17: Piso vinilico | C17: m² | D17: 150 | E17: R$ / m² | F17: Média | G17: =+D17*B17*1.1 -> 0
A18: Emborrachado | C18: m² | D18: 350 | E18: R$ / m² | F18: Média | G18: =+D18*B18*1.1 -> 0
A19: Carpete | C19: m² | D19: 350 | E19: R$ / m² | F19: Média | G19: =+D19*B19*1.1 -> 0
A20: Piscina | C20: m² | D20: 300 | E20: R$ / m² | F20: Média | G20: =+D20*B20*1.1 -> 0
A21: Deck | B21: =68.87*2+40.57 -> 178.31 | C21: m² | D21: 450 | E21: R$ / m² | F21: Média | G21: =+D21*B21*1.1 -> 88263.45
A22: Paver | B22: =AMBIENTES!L17 -> 2360.4381 | C22: m² | D22: 60 | E22: R$ / m² | F22: Média | G22: =+D22*B22*1.1 -> 155788.91
A23: Ladrilho hidaraulico | C23: m² | D23: 180 | E23: R$ / m² | F23: Média | G23: =+D23*B23*1.1 -> 0
A24: Rodapés | B24: 1 | C24: vb | D24: 30 | E24: R$ / AC | F24: Média
A25: Soleiras e peitoris | B25: 1 | C25: vb | D25: 20 | E25: R$ / AC | F25: Média
A26: Revestimentos de Parede | C26: vb | D26: 30 | E26: R$ / AC | F26: Média | G26: =D26*DADOS_INICIAIS!$F$9*1.1*B26 -> 0
A27: =20*40 -> 800 | G27: =SUM(G15:G26) -> 244052.36
A30: TOTAL ACABAMENTOS | G30: =G27 -> 244052.36 | H30: =G30/AREAS!E6 -> 30.86196
H32: =H30/1.1 -> 28.056327
A33: PORCELANATO | B33: 2612.64
A34: CERAMICA | B34: 29.99
A35: CARPETE | B35: 181.54
A36: PISO ALISADO | B36: 6243.04
A37: VINILICO | B37: 4526.15
A38: PISO RANHURADO | B38: 280.79
A39: PAVER | B39: 134.39
A40: DECK | B40: 58.41
A41: PASTILHA | B41: 54.76
A42: PISO ALISADO ESCADA | B42: 448.72
A43: EMBORRACHADO | B43: 138.18

Sheet PINTURA INTERNA
A3: PINTURA INTERNA
A4: Data | B4: 45457
A5: Arquivo base | B5: -
A7: ALVENARIA
A9: Descrição | B9: Parâmetro | D9: Quantidade | F9: Preço unitário | G9: Valor total | H9: Observação
A10: Pintura piso epoxi | B10: 25 | C10: R$ / m² | D10: ='Rev. Internos Piso e Parede'!B15 -> 1477 | E10: m² | F10: 110
A11: Pintura acrílica antiderrapante | B11: 45 | C11: R$ / m² | D11: ='Rev. Internos Piso e Parede'!B16 -> 0 | E11: m² | F11: 65 | G11: =F11*D11*1.1 -> 0
A12: Textura escadas | B12: 15 | C12: R$ / AC | D12: =ALVENARIA!D11*2 -> 1868.1622 | E12: m² | F12: =1.2+6.87+20 -> 28.07 | G12: =F12*D12*1.1 -> 57683.244
A13: Pintura Interna | B13: 50 | C13: R$ / AC | D13: ='Rev. Internos Piso e Parede'!B20-'PINTURA INTERNA'!D12 -> 9800.6671 | E13: m² | F13: =1.2+3.2+6.74+32 -> 43.14 | G13: =F13*D13*1.1 -> 465080.86
A14: TOTAL | G14: =SUM(G10:G13) -> 522764.1 | K14: =4160+1440+1120+2880+4800+91680+4000 -> 110080 | L14: =K14/21 -> 5241.9048
A16: TOTAL IMPERMEABILIZAÇÃO | G16: =G14 -> 522764.1 | H16: =G16/AREAS!E6 -> 66.106815
H18: =H16/1.1 -> 60.097105

Sheet ESQUADRIAS
A3: ESQUADRIAS
A4: Data | B4: 45460
A5: Arquivo base | B5: -
A7: ESQUADRIAS
A9: Descrição | B9: Parâmetro | D9: Quantidade | F9: Preço unitário | G9: Valor total | H9: Observação
A10: Esquadrias de Alumínio | B10: 0.15 | C10: m² / AC | E10: m² | F10: 1100 | G10: =F10*D10*1.1 -> 0 | H10: =G10/DADOS_INICIAIS!F9 -> 0
A11: Pele de vidro | D11: =D32 -> 2871.7831 | E11: m² | F11: 1100 | G11: =F11*D11*1.1 -> 3474857.6
A12: Brise de madeira | D12: =E32 -> 551.24 | E12: m² | F12: 1500 | G12: =F12*D12*1.1 -> 909546
A13: Portão de alumínio | D13: 0 | E13: un | F13: 18000 | G13: =F13*D13*1.1 -> 0
A14: Guarda-corpo - vidro | D14: =(2.16*4*2*3+(3.48*4+1.08*4)*2*3+2.16*4*2*3+(3.72*2+2.52*2+2.4)*2)+(4.82+5)*2+(3.66*2+5.3)*3+5.41*2+4.72*2+40.7*2 -> 402.04 | E14: m | F14: =950*1.1 -> 1045 | G14: =F14*D14*1.1 -> 462144.98
A15: Gradil | E15: m | F15: =680*1.1 -> 748 | G15: =F15*D15*1.1 -> 0
A16: Corrimão inox | E16: m | F16: 150 | G16: =F16*D16*1.1 -> 0
A17: Serralherias | B17: 10 | C17: R$ / AC | D17: 1 | E17: vb | F17: =B17*AREAS!E6 -> 79078.7 | G17: =F17*D17*1.1 -> 86986.57
A18: PCF | D18: 6 | E18: un | F18: 1750 | G18: =F18*D18*1.1 -> 11550
A19: Corrimão metálico | D19: =((3.97+2.95)*4)*1.1 -> 30.448 | E19: m | F19: 120 | G19: =F19*D19*1.1 -> 4019.136
A20: Fechadura biométrica | F20: 1400 | G20: =F20*D20*1.1 -> 0
A21: Poras aluminio | D21: =10+1+1+3+6+2+7+7 -> 37 | E21: un | F21: 850 | G21: =F21*D21*1.1 -> 34595
A22: Esquadrias de Madeira | D22: =6+1+2+3+2+2+2+2+3+2 -> 25 | E22: un | F22: 1200 | G22: =F22*D22*1.1 -> 33000
A23: TOTAL | G23: =SUM(G10:G22) -> 5016699.2 | K23: =4160+1440+1120+2880+4800+91680+4000 -> 110080 | L23: =K23/21 -> 5241.9048
A25: TOTAL ESQUADRIAS | G25: =G23 -> 5016699.2 | H25: =G25/AREAS!E6 -> 634.39324
C27: PELE DE VIDO | D27: area | E27: BRISE
B28: TERREO -2 | C28: =57.14*2+22.5 -> 136.78 | D28: =C28*6.22 -> 850.7716
B29: TERREO -1 | D29: =16.97+94.95+752.7875+96.26+75.8068 -> 1036.7743 | E29: =146.42*2 -> 292.84
B30: SOBRELOJS -2 | C30: =29.94*2 -> 59.88 | D30: =C30*7.14 -> 427.5432
B31: SOBRELOJS -1 | D31: =495.794+2.54+58.36 -> 556.694 | E31: =129.2*2 -> 258.4
D32: =SUM(D28:D31) -> 2871.7831 | E32: =SUM(E28:E31) -> 551.24

Sheet COBERTURA
A2: COBERTURA
A3: Data | B3: 45460
A4: Arquivo base | B4: -
A6: TELHADO
A8: Descrição | B8: Parâmetro | D8: Quantidade | F8: Preço unitário | G8: Valor total | H8: Observação
A9: Estrutura e telhamento | D9: =AMBIENTES!F34+AMBIENTES!F36+AMBIENTES!F37 -> 971.73 | E9: m² | F9: 500 | G9: =F9*D9*1.1 -> 534451.5
A10: Serviços complementares | D10: =D9 -> 971.73 | E10: m² | F10: 45 | G10: =F10*D10*1.1 -> 48100.635
A11: Pergolados metalicos | D11: =132.31*2 -> 264.62 | E11: m² | F11: 350 | G11: =F11*D11*1.1 -> 101878.7
A12: Pergolados madeira | D12: =17.44*4 -> 69.76 | E12: m² | F12: 280 | G12: =F12*D12*1.1 -> 21486.08
A13: Passarelas | G13: =F13*D13*1.1 -> 0
A14: Estrutura metálica cobertura | D14: 365 | E14: m2 | F14: 800 | G14: =F14*D14*1.1 -> 321200
A15: Moldura ACM metálica | D15: =520+AREAS!E29+147*2 -> 1073.5 | E15: m | F15: 52.5 | G15: =F15*D15*1.1 -> 61994.625
A16: TOTAL | G16: =SUM(G9:G14) -> 1027116.9
A18: TOTAL COMPLEMENTARES | G18: =G16 -> 1027116.9 | H18: =G18/AREAS!E6 -> 129.88541

Sheet Rev. Fachada
A2: ORÇAMENTO PARAMÉTRICO GERENCIAMENTO EXECUTIVO
A7: Cliente | B7: Passe
A8: Obra | B8: Connect
A9: Data | B9: 45460
A10: Revisão | B10: R00
A12: REVESTIMENTOS ARGAMASSADOS
A14: Descrição | B14: Quantidade | D14: Parâmetro | F14: Referência | G14: Valor total
A15: Chapisco e reboco | B15: =K19*L19 -> 716.8 | C15: m² | D15: =25+70 -> 95 | E15: R$ / m² | F15: - | G15: =B15*D15*1.1 -> 74905.6
A16: Chapisco e reboco molduras | B16: =($K$20*9+$K$21*5+$K$22)*0.7 -> 0 | C16: m² | D16: =25+70 -> 95 | E16: R$ / m² | G16: =B16*D16*1.1 -> 0
A17: TOTAL | G17: =SUM(G15:G16) -> 74905.6
A19: PINTURA | J19: EMBASAMENTO | K19: =31.7+39.98 -> 71.68 | L19: 10
A21: Descrição | B21: Quantidade | D21: Parâmetro | F21: Referência | G21: Valor total
A22: Textura | B22: =B15 -> 716.8 | C22: m² | D22: =70+15 -> 85 | E22: R$ / m² | F22: - | G22: =B22*D22*1.1 -> 67020.8
A23: Textura molduras | B23: =($K$20*9+$K$21*5+$K$22)*0.7 -> 0 | C23: m² | D23: =70+15 -> 85 | E23: R$ / m² | G23: =B23*D23*1.1 -> 0
A24: TOTAL | G24: =SUM(G22:G23) -> 67020.8
A26: ACABAMENTOS ESPECIAIS
A28: Descrição | B28: Quantidade | D28: Parâmetro | F28: Referência | G28: Valor total
A29: Molduras ACM | B29: =COBERTURA!D15 -> 1073.5 | C29: M | D29: 150 | E29: R$ / m² | F29: - | G29: =B29*D29*1.1 -> 177127.5
A30: Molduras ACM | B30: =COBERTURA!D14 -> 365 | C30: M2 | D30: 650 | E30: R$ / m² | F30: - | G30: =B30*D30*1.1 -> 260975
G31: =SUM(G29:G30) -> 438102.5
J32: =25.78*2 -> 51.56
A34: TOTAL FACHADA | G34: =G24+G17+G31 -> 580028.9 | H34: =G34/AREAS!E6 -> 73.34831
H35: =H34/1.1 -> 66.680282

Sheet COMPLEMENTARES
A2: COMPLEMENTARES
A3: Data | B3: 45460
A4: Arquivo base | B4: -
A6: SERVIÇOS COMPLEMENTARES
A8: Descrição | B8: Parâmetro | D8: Quantidade | F8: Valor total
A9: Móveis e decoração | B9: 2100 | C9: R$ / AL | D9: =AREAS!E6*0.1 -> 790.787 | E9: m² | F9: =D9*B9*1.1 -> 1826718
A10: Comunicação visual | B10: 10 | C10: R$ / AC | D10: =B10*AREAS!E6 -> 79078.7 | E10: R$ | F10: =D10*1.1 -> 86986.57
A11: Paisagismo | B11: 15 | C11: R$ / AC | D11: =B11*(AREAS!$E$6+2373) -> 154213.05 | E11: R$ | F11: =D11*1.1 -> 169634.36
A12: Irrigação, iluminação e mobiliário externo | B12: 23 | C12: R$ / AC | D12: =B12*(AREAS!$E$6+2373) -> 236460.01 | E12: R$ | F12: =D12*1.1 -> 260106.01
A13: Playground | B13: =172734.56/111.47 -> 1549.6058 | C13: R$ / m2 | D13: 62.72 | E13: m2 | F13: =D13*B13*1.1 -> 106910.4
A14: Ligações definitivas | B14: 4 | C14: R$ / AC | D14: =B14*AREAS!$E$6 -> 31631.48 | E14: R$ | F14: =D14*1.1 -> 34794.628
A15: Desmobilização | B15: 3.5 | C15: R$ / AC | D15: =B15*AREAS!$E$6 -> 27677.545 | E15: R$ | F15: =D15*1.1 -> 30445.3
A16: Limpeza | B16: 15 | C16: R$ / AC | D16: =B16*AREAS!$E$6 -> 118618.05 | E16: R$ | F16: =D16*1.1 -> 130479.86
A17: TOTAL | F17: =SUM(F9:F16) -> 2646075.1
A19: TOTAL COMPLEMENTARES | F19: =F17 -> 2646075.1 | G19: =F19/AREAS!E6 -> 334.61287

Sheet Auxiliar
A2: 2 Portões acesso garagem - Área: 9,2m² x 2 = 18,4m² | B2: 2 | C2: portão | D2: 18.4
A3: 2 portas corta-fogo 1 folha | B3: 2 | C3: pcf
A4: 1 porta de correr alumínio 2 folhas – Área: 3,465m² | B4: 1 | C4: porta alumínio | D4: 3.465
A5: 1 porta de correr alumínio 2 folhas – Área: 1,7325m² | B5: 1 | C5: porta alumínio | D5: 1.7325 | G5: Guarda alumínio | H5: =SUMIF(C:C,G5,D:D) -> 400.5221
A6: 2 portas de abrir alumínio 2 folhas – Área: 2,6376m² x 2 = 5,2752m² | B6: 2 | C6: porta alumínio | D6: 5.2752 | G6: janela | H6: =SUMIF(C:C,G6,D:D) -> 1895.06
A7: 1 porta de abrir alumínio 2 folhas – Área: 4,1916m² | B7: 1 | C7: porta alumínio | D7: 4.1916 | G7: madeira | H7: =SUMIF(C:C,G7,B:B) -> 218
A8: 1 porta pivotante | B8: 1 | C8: pivotante | G8: pcf | H8: =SUMIF(C:C,G8,B:B) -> 60
A9: 19 portas de abrir madeira 1 folha | B9: 19 | C9: madeira | G9: pivotante | H9: =SUMIF(C:C,G9,B:B) -> 1
A10: 3 portas de abrir vidro 1 folha – Área: 2,1m² x 3 = 6,3m² | B10: 3 | C10: porta alumínio | D10: 6.3 | G10: porta alumínio | H10: =SUMIF(C:C,G10,D:D) -> 46.62
A11: 2 portas de abrir vidro 1 folha – Área: 1,89m² x 2 = 3,78m² | B11: 2 | C11: porta alumínio | D11: 3.78 | G11: portão | H11: =SUMIF(C:C,G11,B:B) -> 2
A12: 1 porta de abrir alumínio 1 folha – Área: 2,0076m² | B12: 1 | C12: porta alumínio | D12: 2.0076 | G12: gradil | H12: =SUMIF(C:C,G12,D:D) -> 113.88
A13: Janelas – Área: 3,75 + 4,875 + 2,5 + 1,1 + 1,2 + 5,5402 + 4,4874 = 23,4526m² | C13: janela | D13: 23.4526 | G13: Brise | H13: 109.3146
A14: Muro de vidro – Área: 7,0774 + 5,485 + 3,43 + 4,8138 = 20,8062m² | C14: Guarda alumínio | D14: 20.8062
A15: 8 portas corta-fogo 1 folha | B15: 8 | C15: pcf
A16: Janelas – Area: (1,1 + 1,2 + 28,7391) x 4 = 124,1564m² | C16: janela | D16: 124.1564
A17: 2 portas corta-fogo 1 folha | B17: 2 | C17: pcf
A18: 2 portas de abrir alumínio 1 folha – Área: 1,47m² x 2 = 2,94m² | B18: 2 | C18: porta alumínio | D18: 2.94
A19: 2 portas de abrir vidro 1 folha – Área: 1,89m² x 2 = 3,78m² | B19: 2 | C19: porta alumínio | D19: 3.78
A20: 5 portas de abrir madeira 1 folha | B20: 5 | C20: madeira
A21: 1 janela-porta de correr vidro – Área: 14,7348m² | B21: 1 | C21: janela | D21: 14.7348
A22: Janelas – Área: 1,2894 + 1,2894 + 23,46 + 1,854 + 5,562 + 5,562 + 1,854 + 1,854 + 1,1 + 1,2 = 45,0248m² | C22: janela | D22: 45.0248
A23: Guarda corpo vidro – Área: 7,5299 + 5,7955 + 6,5555 = 19,8809m² | C23: Guarda alumínio | D23: 19.8809
A24: 38 portas corta-fogo 1 folha | B24: 38 | C24: pcf
A25: 171 portas de abrir madeira 1 folha | B25: 171 | C25: madeira
A26: 19 porta de abrir alumínio 1 folha – Área: 1,26m² x 19 = 23,94m² | B26: 19 | C26: porta alumínio | D26: 23.94
A27: 19 janela-porta de correr vidro 5 folhas - Área: 25,4205m² x 19 = 482,9895m² | B27: 19 | C27: janela | D27: 482.9895
A28: 19 janela-porta de correr vidro 5 folhas - Área: 17,8284m² x 19 = 338,7396m² | B28: 19 | C28: janela | D28: 338.7396
A29: Janelas – Área: 1,1 + 1,1 + 1,2 + 1,92 + 0,36 + 2,781 + 2,781 + 1,854 + 1,854 + 5,562 + 5,562 + 1,854 = 27,928m² x 19 = 530,632m² | C29: janela | D29: 530.632
A30: Guarda corpo metálico – Área: 4,745m² x 19 = 90,155m² - Perímetro: 3,65m x 19 = 69,35m | C30: gradil | D30: 90.155
A31: Guarda corpo vidro – Área: 15,645m² x 19 = 297,255m² - Perímetro: 14,9m x 19 = 283,1m | C31: Guarda alumínio | D31: 297.255
A32: 2 portas corta-fogo 1 folha | B32: 2 | C32: pcf
A33: 2 portas de abrir madeira 1 folha | B33: 2 | C33: madeira
A34: 1 porta de abrir alumínio 1 folha – Área: 1,26m² | B34: 1 | C34: porta alumínio | D34: 1.26
A35: 1 janela-porta de correr vidro 3 folhas - Área: 15,21m² | B35: 1 | C35: janela | D35: 15.21
A36: 1 janela-porta de correr vidro 5 folhas - Área: 25,4205m² | B36: 1 | C36: janela | D36: 25.4205
A37: 1 janela-porta de correr vidro 5 folhas - Área: 17,8284m² | B37: 1 | C37: janela | D37: 17.8284
A38: Janelas – Área: 1,1 + 1,2 + 1,1 + 1,92 + 0,36 + 2,781 + 2,781 + 1,854 + 1,854 + 5,562 + 5,562 + 1,854 = 27,928m² | C38: janela | D38: 27.928
A39: Guarda corpo metálico – Área: 4,745m² - Perímetro: 3,65m | C39: gradil | D39: 4.745
A40: Guarda corpo vidro – Área: 15,645m² - Perímetro: 14,9m | C40: Guarda alumínio | D40: 15.645
A41: 2 portas corta-fogo 1 folha | B41: 2 | C41: pcf
...
