Workbook
Name \0: #REF!
Name \0: #REF!
Name \0: #REF!
Name \0: #REF!
Name \0: #REF!
Name \0: #REF!
Name \1: #REF!
Name \1: #REF!
Name \1: #REF!
Name \1: #REF!
Name \1: #REF!
Name \a: #REF!
Name \a: #REF!
Name \a: #REF!
Name \a: #REF!
Name \a: #REF!
Name \a: #REF!
Name \b: #REF!
Name \b: #REF!
Name \b: #REF!
Name \b: #REF!
Name \b: #REF!
Name \c: #REF!
Name \c: #REF!
Name \c: #REF!
Name \c: #REF!
Name \c: #REF!
Name \d: #REF!
Name \d: #REF!
Name \d: #REF!
Name \d: #REF!
Name \d: #REF!
Name \e: #REF!
Name \e: #REF!
Name \e: #REF!
Name \e: #REF!
Name \e: #REF!
Name \i: #REF!
Name \i: #REF!
Name \i: #REF!
Name \i: #REF!
Name \i: #REF!
Name \J: #REF!
Name \J: #REF!
Name \J: #REF!
Name \J: #REF!
Name \J: #REF!
Name \k: #REF!
Name \k: #REF!
Name \k: #REF!
Name \k: #REF!
Name \k: #REF!
Name \l: #N/A
Name \m: #REF!
Name \m: #REF!
Name \m: #REF!
Name \m: #REF!
Name \m: #REF!
Name \m: #REF!
Name \o: #REF!

Sheet PROJETOS
B1: Projeto | C1: ='Obra '!D1 -> Caio Prado
B2: Empresa | C2: ='Obra '!D2 -> Indepy
B3: Revisão | C3: ='Obra '!D3 -> R00 - Larissa
A5: INFRAESTRUTURA
A6: PAVIMENTO | B6: DISCIPLINA
B7: ARQUITETURA | C7: FUNDAÇÕES | D7: OBSERVAÇÃO
A8: Fundação Profunda | C8: BRS_RDT_FUN_EX_001_R03
A20: Caminho: | B20: https://qicloud.com.br/root/caroline.nunes@cartesianengenharia.com#Obras/BRS-MOD_REDENTOR/Estrutura/04%20-%20PROJETO%20EXECUTIVO/PDF
A22: INSTALAÇÕES ELETRICAS
A23: PAVIMENTO | B23: DISCIPLINA
B24: ARQUITETURA | C24: ELETRICA | D24: OBSERVAÇÃO
A25: GERAL
A26: ='Obra '!$B$17 -> Subsolo
A27: ='Obra '!$B$18 -> Térreo
A28: ='Obra '!$B$19 -> 1º Pavimento - HMP
A29: ='Obra '!$B$20 -> 2º Pavimento - HMP
A30: ='Obra '!$B$21 -> 3º Pavimento - R2V / HMP
A31: ='Obra '!$B$22 -> 5º/ 7º/ 9º E 11º Pavimento - R2V
A32: ='Obra '!$B$23 -> 4º/ 6º/ 8º/ 10º E 12º Pavimento - R2V
A33: ='Obra '!$B$24 -> 13º Pavimento - LAZER
A34: ='Obra '!$B$25 -> 14º E 16º Pavimento - R2V
A35: ='Obra '!$B$26 -> 15º E 17º Pavimento - R2V
A36: ='Obra '!$B$27 -> 18º Pavimento - LAZER
A37: Caminho: | B37: 2.Projetos em andamento/Empresa/Obra/Escopo/Extração de quantitativos/Projetos Considerados

Sheet Obra 
C1: Projeto | D1: Caio Prado | E1: ENDEREÇO DA OBRA: | F1: R. Caio Prado, 207 - Consolação, São Paulo - SP, 01303-001
C2: Empresa | D2: Indepy | E2: CNPJ:
C3: Revisão | D3: R00 - Larissa | E3: ARQUIVO:
A4: QUADRO DE ÁREAS
B6: Descrição | C6: Unidade | E6: Quantidade | G6: Imagens
B7: MESES DE OBRA | C7: MÊS | E7: 36
B8: ÁREA DO TERRENO | C8: M² | E8: 981.06
B9: ÁREA CONSTRUÍDA | C9: M² | E9: 6938.39
B10: NÚMERO DE UNIDADES HABITACIONAIS | C10: UN | E10: 135
B11: NÚMERO DE UNIDADES COMERCIAIS | C11: UN | E11: 1
B12: ÁREA PRIVATIVA | C12: M² | E12: =SUM(E66:E115) -> 4392.6
B13: NÚMERO DE PAVIMENTOS | C13: UN | E13: 23
B14: ÁREA DE LAZER | C14: M² | E14: =MOBILIÁRIO!C7 -> 1901.04
B15: TOTAL DORMITÓRIOS | C15: UN | E15: 135
B17: Subsolo | C17: M² | E17: 243.84
B18: Térreo | C18: M² | E18: 615.57 | F18: =E18*0.6 -> 369.342
B19: 1º Pavimento - HMP | C19: M² | E19: 380.61
B20: 2º Pavimento - HMP | C20: M² | E20: 478.98
B21: 3º Pavimento - R2V / HMP | C21: M² | E21: 412.99
B22: 5º/ 7º/ 9º E 11º Pavimento - R2V | C22: M² | E22: 1651.96
B23: 4º/ 6º/ 8º/ 10º E 12º Pavimento - R2V | C23: M² | E23: 1806.8
B24: 13º Pavimento - LAZER | C24: M² | E24: 294.68 | F24: =E24*0.9 -> 265.212
B25: 14º E 16º Pavimento - R2V | C25: M² | E25: 445.2
B26: 15º E 17º Pavimento - R2V | C26: M² | E26: 389.26
B27: 18º Pavimento - LAZER | C27: M² | E27: 82.25 | F27: =E27*0.9 -> 74.025
B28: BARRILETE | C28: M² | E28: 67.2
B29: CX D'ÁGUA | C29: M² | E29: 69.05 | F29: =59.88+3.11+78.87+47.22+27.7+5.97+2.985+1.84 -> 227.575
B30: TOPO | C30: M²
B35: CARTESIAN | G35: CARTESIAN
B36: ETAPA | C36: VALOR ORÇADO | D36: % | E36: VALOR / m² | G36: ETAPA | H36: VALOR ORÇADO | I36: % | J36: VALOR / m²
B37: GERENCIAMENTO TÉCNICO E ADMISTRATIVO | D37: =C37/C$60 -> 0 | E37: =C37/$E$9 -> 0 | G37: PAREDES E PAINÉIS | H37: =C42 -> 1994418.8 | I37: =H37/H$48 -> 0.12034852 | J37: =H37/$E$9 -> 287.44691
B38: MOVIMENTAÇÃO DE TERRA | C38: =SUMIFS(Ger_Executivo!N:N,Ger_Executivo!J:J,B38,Ger_Executivo!H:H,Ger_Executivo!$H$8) -> 0 | D38: =C38/C$60 -> 0 | E38: =C38/$E$9 -> 0 | G38: IMPERMEABILIZAÇÃO E TRATAMENTOS | H38: =C43 -> 703992.08 | I38: =H38/H$48 -> 0.042480748 | J38: =H38/$E$9 -> 101.46332
B39: INFRAESTRUTURA | C39: =SUMIFS(Ger_Executivo!N:N,Ger_Executivo!J:J,B39,Ger_Executivo!H:H,Ger_Executivo!$H$8) -> 0 | D39: =C39/C$60 -> 0 | E39: =C39/$E$9 -> 0 | G39: REVESTIMENTOS INTERNOS DE PAREDE | H39: =C51 -> 1323971.4 | I39: =H39/H$48 -> 0.079891944 | J39: =H39/$E$9 -> 190.81825
B40: CONTENÇÃO | C40: =SUMIFS(Ger_Executivo!N:N,Ger_Executivo!J:J,B40,Ger_Executivo!H:H,Ger_Executivo!$H$8) -> 0 | D40: =C40/C$60 -> 0 | E40: =C40/$E$9 -> 0 | G40: REVESTIMENTOS E ACABAMENTOS INTERNOS EM TETO | H40: =C52 -> 695689.43 | I40: =H40/H$48 -> 0.041979744 | J40: =H40/$E$9 -> 100.26669
B41: SUPRAESTRUTURA | C41: =SUMIFS(Ger_Executivo!N:N,Ger_Executivo!J:J,B41,Ger_Executivo!H:H,Ger_Executivo!$H$8) -> 0 | D41: =C41/C$60 -> 0 | E41: =C41/$E$9 -> 0 | G41: PISOS E PAVIMENTAÇÕES | H41: =C53 -> 1461780 | I41: =H41/H$48 -> 0.088207681 | J41: =H41/$E$9 -> 210.68
B42: PAREDES E PAINÉIS | C42: =SUMIFS(Ger_Executivo!N:N,Ger_Executivo!J:J,B42,Ger_Executivo!H:H,Ger_Executivo!$H$8) -> 1994418.8 | D42: =C42/C$60 -> 0.11798874 | E42: =C42/$E$9 -> 287.44691 | G42: SISTEMAS DE PINTURA INTERNA | H42: =C54 -> 1340430.3 | I42: =H42/H$48 -> 0.080885116 | J42: =H42/$E$9 -> 193.19039
B43: IMPERMEABILIZAÇÃO E TRATAMENTOS | C43: =SUMIFS(Ger_Executivo!N:N,Ger_Executivo!J:J,B43,Ger_Executivo!H:H,Ger_Executivo!$H$8) -> 703992.08 | D43: =C43/C$60 -> 0.041647792 | E43: =C43/$E$9 -> 101.46332 | G43: ESQUADRIAS, VIDROS E FERRAGENS | H43: =C55 -> 3691455.8 | I43: =H43/H$48 -> 0.22275223 | J43: =H43/$E$9 -> 532.03348
B44: SISTEMAS E INSTALAÇÕES ELÉTRICAS | C44: =SUMIFS(Ger_Executivo!N:N,Ger_Executivo!J:J,B44,Ger_Executivo!H:H,Ger_Executivo!$H$8) -> 0 | D44: =C44/C$60 -> 0 | E44: =C44/$E$9 -> 0 | G44: LOUÇAS E METAIS | H44: =C56 -> 326798.11 | I44: =H44/H$48 -> 0.019719864 | J44: =H44/$E$9 -> 47.099992
B45: SISTEMAS E INSTALAÇÕES HIDROSSANITÁRIAS E DRENAGEM | C45: =SUMIFS(Ger_Executivo!N:N,Ger_Executivo!J:J,B45,Ger_Executivo!H:H,Ger_Executivo!$H$8) -> 0 | D45: =C45/C$60 -> 0 | E45: =C45/$E$9 -> 0 | G45: REVESTIMENTOS E ACABAMENTOS EM FACHADA | H45: =C57 -> 1898087.7 | I45: =H45/H$48 -> 0.11453564 | J45: =H45/$E$9 -> 273.56313
B46: INSTALAÇÕES PREVENTIVAS | C46: =SUMIFS(Ger_Executivo!N:N,Ger_Executivo!J:J,B46,Ger_Executivo!H:H,Ger_Executivo!$H$8) -> 0 | D46: =C46/C$60 -> 0 | E46: =C46/$E$9 -> 0 | G46: SERVIÇOS COMPLEMENTARES E FINAIS | H46: =C58 -> 3135402.8 | I46: =H46/H$48 -> 0.18919852 | J46: =H46/$E$9 -> 451.89198
...

Sheet EAP Análise
A1: ETAPA | B1: VALOR ORÇADO | C1: % | D1: VALOR / m²
A2: GERENCIAMENTO TÉCNICO E ADMINISTRATIVO | C2: =B2/$B$28 -> 0 | D2: =B2/'Obra '!$E$9 -> 0 | E2: ='[4]MÉDIAS CARTESIAN'!$C13-B2 -> 2406266.6
A3: MOVIMENTAÇÃO DE TERRA | B3: =SUMIF(Ger_Executivo!Q:Q,A3,Ger_Executivo!N:N) -> 0 | C3: =B3/$B$28 -> 0 | D3: =B3/'Obra '!$E$9 -> 0 | E3: ='[4]MÉDIAS CARTESIAN'!$C14-B3 -> 303296.04
A4: INFRAESTRUTURA | B4: =SUMIF(Ger_Executivo!Q:Q,A4,Ger_Executivo!N:N) -> 0 | C4: =B4/$B$28 -> 0 | D4: =B4/'Obra '!$E$9 -> 0 | E4: ='[4]MÉDIAS CARTESIAN'!$C15-B4 -> 1290666.1
A5: CONTENÇÃO | B5: =SUMIF(Ger_Executivo!Q:Q,A5,Ger_Executivo!N:N) -> 0 | C5: =B5/$B$28 -> 0 | D5: =B5/'Obra '!$E$9 -> 0 | E5: ='[4]MÉDIAS CARTESIAN'!$C18-B5 -> 168316.36
A6: SUPRAESTRUTURA | B6: =SUMIF(Ger_Executivo!Q:Q,A6,Ger_Executivo!N:N) -> 0 | C6: =B6/$B$28 -> 0 | D6: =B6/'Obra '!$E$9 -> 0 | E6: ='[4]MÉDIAS CARTESIAN'!$C19-B6 -> 3502945.8
A7: ALVENARIA | B7: =SUMIF(Ger_Executivo!Q:Q,A7,Ger_Executivo!N:N) -> 1994418.8 | C7: =B7/$B$28 -> 0.11798874 | D7: =B7/'Obra '!$E$9 -> 287.44691 | E7: ='[4]MÉDIAS CARTESIAN'!$C20-B7 -> -720693.13
A8: INSTALAÇÕES ELÉTRICAS, HIDRÁULICAS, GLP E PREVENTIVAS | B8: =SUMIF(Ger_Executivo!Q:Q,A8,Ger_Executivo!N:N) -> 0 | C8: =B8/$B$28 -> 0 | D8: =B8/'Obra '!$E$9 -> 0 | E8: ='[4]MÉDIAS CARTESIAN'!$C25+'[4]MÉDIAS CARTESIAN'!$C$24+'[4]MÉDIAS CARTESIAN'!$C$23+'[4]MÉDIAS CARTESIAN'!$C$22+'[4]MÉDIAS CARTESIAN'!$C$21-B8 -> 1861372.5
A9: CLIMATIZAÇÃO, EXAUSTÃO MECÂNICA E PRESSURIZAÇÃO | B9: =SUMIF(Ger_Executivo!Q:Q,A9,Ger_Executivo!N:N) -> 0 | C9: =B9/$B$28 -> 0 | D9: =B9/'Obra '!$E$9 -> 0 | E9: ='[4]MÉDIAS CARTESIAN'!$C26-B9 -> 623694.81
A10: EQUIPAMENTOS E SISTEMAS ESPECIAIS | B10: =SUMIF(Ger_Executivo!Q:Q,A10,Ger_Executivo!N:N) -> 0 | C10: =B10/$B$28 -> 0 | D10: =B10/'Obra '!$E$9 -> 0 | E10: ='[4]MÉDIAS CARTESIAN'!$C27-B10 -> 504732.66
A11: INSTALAÇÕES ESPECIAIS | B11: =SUMIF(Ger_Executivo!Q:Q,A11,Ger_Executivo!N:N) -> 0 | C11: =B11/$B$28 -> 0 | D11: =B11/'Obra '!$E$9 -> 0 | E11: ='[4]MÉDIAS CARTESIAN'!$C28-B11 -> 323409.52
A12: REVESTIMENTOS ARGAMASSADOS PISO | B12: =SUMIF(Ger_Executivo!Q:Q,A12,Ger_Executivo!N:N) -> 669260.84 | C12: =B12/$B$28 -> 0.039593111 | D12: =B12/'Obra '!$E$9 -> 96.457657 | E12: ='[4]MÉDIAS CARTESIAN'!$C29-B12 -> -215508.1
A13: REVESTIMENTOS ARGAMASSADOS PAREDE | B13: =SUMIF(Ger_Executivo!Q:Q,A13,Ger_Executivo!N:N) -> 428169.71 | C13: =B13/$B$28 -> 0.025330289 | D13: =B13/'Obra '!$E$9 -> 61.710239 | E13: ='[4]MÉDIAS CARTESIAN'!$C30-B13 -> -129346.75
A14: REVESTIMENTOS ARGAMASSADOS TETO | B14: =SUMIF(Ger_Executivo!Q:Q,A14,Ger_Executivo!N:N) -> 11353.315 | C14: =B14/$B$28 -> 0.000671656 | D14: =B14/'Obra '!$E$9 -> 1.636304 | E14: ='[4]MÉDIAS CARTESIAN'!$C31-B14 -> 54584.25
A15: IMPERMEABILIZAÇÃO | B15: =SUMIF(Ger_Executivo!Q:Q,A15,Ger_Executivo!N:N) -> 703992.08 | C15: =B15/$B$28 -> 0.041647792 | D15: =B15/'Obra '!$E$9 -> 101.46332 | E15: ='[4]MÉDIAS CARTESIAN'!$C32-B15 -> -115353.88
A16: ACABAMENTOS INTERNOS EM PAREDE | B16: =SUMIF(Ger_Executivo!Q:Q,A16,Ger_Executivo!N:N) -> 895801.7 | C16: =B16/$B$28 -> 0.052995146 | D16: =B16/'Obra '!$E$9 -> 129.10801 | E16: ='[4]MÉDIAS CARTESIAN'!$C33-B16 -> -501510.48
A17: ACABAMENTOS EM PISOS E PAVIMENTAÇÕES | B17: =SUMIF(Ger_Executivo!Q:Q,A17,Ger_Executivo!N:N) -> 792519.18 | C17: =B17/$B$28 -> 0.046885008 | D17: =B17/'Obra '!$E$9 -> 114.22235 | E17: ='[4]MÉDIAS CARTESIAN'!$C34-B17 -> 205885.82
A18: ACABAMENTOS INTERNOS EM TETO | B18: =SUMIF(Ger_Executivo!Q:Q,A18,Ger_Executivo!N:N) -> 684336.12 | C18: =B18/$B$28 -> 0.040484956 | D18: =B18/'Obra '!$E$9 -> 98.630391 | E18: ='[4]MÉDIAS CARTESIAN'!$C35-B18 -> -204418.8
A19: PINTURA INTERNA | B19: =SUMIF(Ger_Executivo!Q:Q,A19,Ger_Executivo!N:N) -> 1340430.3 | C19: =B19/$B$28 -> 0.079299133 | D19: =B19/'Obra '!$E$9 -> 193.19039 | E19: ='[4]MÉDIAS CARTESIAN'!$C36-B19 -> -515533.57
A20: PINTURA DE FACHADA | B20: =SUMIF(Ger_Executivo!Q:Q,A20,Ger_Executivo!N:N) -> 715371.88 | C20: =B20/$B$28 -> 0.042321015 | D20: =B20/'Obra '!$E$9 -> 103.10344 | E20: ='[4]MÉDIAS CARTESIAN'!$C37-B20 -> -143553.59
... A27: IMPREVISTOS | B27: =SUMIF(Ger_Executivo!Q:Q,A27,Ger_Executivo!N:N) -> 331440.53 | C27: =B27/$B$28 -> 0.019607843 | D27: =B27/'Obra '!$E$9 -> 47.769083 | E27: ='[4]MÉDIAS CARTESIAN'!$C44-B27 -> 61216.986
A28: TOTAL | B28: =SUM(B2:B27) -> 16903467 | C28: =SUM(C2:C27) -> 1 | D28: =SUM(D2:D27) -> 2436.2232
A29: CUB/SC | B29: ='Obra '!C61 -> 2481.34 | C29: ='Obra '!D61 -> 45931 | D29: =ROUNDUP(+D28/B29,2)&" CUB" -> 0,99 CUB
A33: ALVENARIA
A34: ALVENARIA | B34: =8065.3318*2 -> 16130.664
A35: DRYWALL | B35: =2807.94+822.07 -> 3630.01
B36: =B34+B35 -> 19760.674
A38: ARGAMASSADO INTERNO
A39: EST INT | B39: 253.75
A40: CHAP INT | B40: 2077.54
A41: REB INT | B41: 66.91
A42: MASSA GESSO INTERNO | B42: 12478.29 | C42: Tem itens aqui com estrutura, portanto, uma parte fica e argamassado e outra fica em alvenaria ali emcima
B43: =SUM(B39:B42) -> 14876.49
A44: ARGAMASSADO EXTERNO
A45: REB EXT | B45: 6418.996
A46: EST EXT | B46: 576.58
B47: =B45+B46 -> 6995.576 | C47: =B47+B43 -> 21872.066
A48: ACABAMENTO INTERNO
A49: PINT INT | B49: 16892.104
A50: ACAB INT | B50: 3346.4578
...

Sheet CPU
A1: Repetição | B1: Tipo | C1: Descrição | D1: Descrição | E1: Und | F1: Quantidade | G1: Custo unit. | H1: Custo Total. | I1: Observações
A2: =COUNTIFS($D$2:$D$3085,D2,$B$2:$B$3085,B2) -> 1 | B2: Etapa | D2: INSTALAÇÕES PROVISÓRIAS | G2: =IF(B2="insumo",_xlfn.XLOOKUP($D2,Insumos!$B$1:$B$764,Insumos!$D$1:$D$764),"") | H2: {=_xlfn.IFS(B2="Serviço",SUMIFS(H3:$H$3085,C3:$C$3085,$C2),B2="Insumo",F2*G2,B2="Etapa","")}
A3: =COUNTIFS($D$2:$D$3085,D3,$B$2:$B$3085,B3) -> 1 | B3: Serviço | C3: =IF(B3="serviço",D3,C2) -> Central de aço | D3: Central de aço | E3: M2 | G3: =IF(B3="insumo",_xlfn.XLOOKUP($D3,Insumos!$B$1:$B$764,Insumos!$D$1:$D$764),"") | H3: {=_xlfn.IFS(B3="Serviço",SUMIFS(H4:$H$3085,C4:$C$3085,$C3),B3="Insumo",F3*G3,B3="Etapa","")} -> 118.1045 | I3: Sim
A4: =COUNTIFS($D$2:$D$3085,D4,$B$2:$B$3085,B4) -> 3 | B4: Insumo | C4: =IF(B4="serviço",D4,C3) -> Central de aço | D4: LONA PLASTICA 120 MICRAS 4X100M PRETA | E4: =_xlfn.XLOOKUP(D4,Insumos!$B$1:$B$764,Insumos!$C$1:$C$764) -> M2 | F4: 1 | G4: =IF(B4="insumo",_xlfn.XLOOKUP($D4,Insumos!$B$1:$B$764,Insumos!$D$1:$D$764),"") -> 1.25 | H4: {=_xlfn.IFS(B4="Serviço",SUMIFS(H5:$H$3085,C5:$C$3085,$C4),B4="Insumo",F4*G4,B4="Etapa","")} -> 1.25
A5: =COUNTIFS($D$2:$D$3085,D5,$B$2:$B$3085,B5) -> 3 | B5: Insumo | C5: =IF(B5="serviço",D5,C4) -> Central de aço | D5: TELHA METALICA GALVANIZADA TRAPEZOIDAL 0,43MM NBR 14514 | E5: =_xlfn.XLOOKUP(D5,Insumos!$B$1:$B$764,Insumos!$C$1:$C$764) -> M2 | F5: 1 | G5: =IF(B5="insumo",_xlfn.XLOOKUP($D5,Insumos!$B$1:$B$764,Insumos!$D$1:$D$764),"") -> 31 | H5: {=_xlfn.IFS(B5="Serviço",SUMIFS(H6:$H$3085,C6:$C$3085,$C5),B5="Insumo",F5*G5,B5="Etapa","")} -> 31
A6: =COUNTIFS($D$2:$D$3085,D6,$B$2:$B$3085,B6) -> 9 | B6: Insumo | C6: =IF(B6="serviço",D6,C5) -> Central de aço | D6: Concreto Usinado bombeável 20MPa Convencional | E6: =_xlfn.XLOOKUP(D6,Insumos!$B$1:$B$764,Insumos!$C$1:$C$764) -> M3 | F6: 0.074 | G6: =IF(B6="insumo",_xlfn.XLOOKUP($D6,Insumos!$B$1:$B$764,Insumos!$D$1:$D$764),"") -> 490 | H6: {=_xlfn.IFS(B6="Serviço",SUMIFS(H7:$H$3085,C7:$C$3085,$C6),B6="Insumo",F6*G6,B6="Etapa","")} -> 36.26
A7: =COUNTIFS($D$2:$D$3085,D7,$B$2:$B$3085,B7) -> 3 | B7: Insumo | C7: =IF(B7="serviço",D7,C6) -> Central de aço | D7: PREGO GALVANIZADO LISO S/CABECA 17X21 NBR 6627 | E7: =_xlfn.XLOOKUP(D7,Insumos!$B$1:$B$764,Insumos!$C$1:$C$764) -> KG | F7: 0.15 | G7: =IF(B7="insumo",_xlfn.XLOOKUP($D7,Insumos!$B$1:$B$764,Insumos!$D$1:$D$764),"") -> 10.03 | H7: {=_xlfn.IFS(B7="Serviço",SUMIFS(H8:$H$3085,C8:$C$3085,$C7),B7="Insumo",F7*G7,B7="Etapa","")} -> 1.5045
A8: =COUNTIFS($D$2:$D$3085,D8,$B$2:$B$3085,B8) -> 3 | B8: Insumo | C8: =IF(B8="serviço",D8,C7) -> Central de aço | D8: BLOCO CONCRETO ESTRUTURAL 03MPA 14X19X39CM NBR 6136 | E8: =_xlfn.XLOOKUP(D8,Insumos!$B$1:$B$764,Insumos!$C$1:$C$764) -> UN | F8: 9 | G8: =IF(B8="insumo",_xlfn.XLOOKUP($D8,Insumos!$B$1:$B$764,Insumos!$D$1:$D$764),"") -> 2.95 | H8: {=_xlfn.IFS(B8="Serviço",SUMIFS(H9:$H$3085,C9:$C$3085,$C8),B8="Insumo",F8*G8,B8="Etapa","")} -> 26.55
A9: =COUNTIFS($D$2:$D$3085,D9,$B$2:$B$3085,B9) -> 3 | B9: Insumo | C9: =IF(B9="serviço",D9,C8) -> Central de aço | D9: ARGAMASSA ENSACADA P/ASSENTAMENTO BLOCO 04MPA NBR 13281 | E9: =_xlfn.XLOOKUP(D9,Insumos!$B$1:$B$764,Insumos!$C$1:$C$764) -> KG | F9: 24 | G9: =IF(B9="insumo",_xlfn.XLOOKUP($D9,Insumos!$B$1:$B$764,Insumos!$D$1:$D$764),"") -> 0.46 | H9: {=_xlfn.IFS(B9="Serviço",SUMIFS(H10:$H$3085,C10:$C$3085,$C9),B9="Insumo",F9*G9,B9="Etapa","")} -> 11.04
A10: =COUNTIFS($D$2:$D$3085,D10,$B$2:$B$3085,B10) -> 3 | B10: Insumo | C10: =IF(B10="serviço",D10,C9) -> Central de aço | D10: SERVICO EMP. - INST. PROVISORIA - CONFECCAO BAIA P/MATERIAL | E10: =_xlfn.XLOOKUP(D10,Insumos!$B$1:$B$764,Insumos!$C$1:$C$764) -> M2 | F10: 1 | G10: =IF(B10="insumo",_xlfn.XLOOKUP($D10,Insumos!$B$1:$B$764,Insumos!$D$1:$D$764),"") -> 10.5 | H10: {=_xlfn.IFS(B10="Serviço",SUMIFS(H11:$H$3085,C11:$C$3085,$C10),B10="Insumo",F10*G10,B10="Etapa","")} -> 10.5
A11: =COUNTIFS($D$2:$D$3085,D11,$B$2:$B$3085,B11) -> 1 | B11: Serviço | C11: =IF(B11="serviço",D11,C10) -> Central de fôrmas | D11: Central de fôrmas | E11: M2 | G11: =IF(B11="insumo",_xlfn.XLOOKUP($D11,Insumos!$B$1:$B$764,Insumos!$D$1:$D$764),"") | H11: {=_xlfn.IFS(B11="Serviço",SUMIFS(H12:$H$3085,C12:$C$3085,$C11),B11="Insumo",F11*G11,B11="Etapa","")} -> 118.1045 | I11: Sim
A12: =COUNTIFS($D$2:$D$3085,D12,$B$2:$B$3085,B12) -> 3 | B12: Insumo | C12: =IF(B12="serviço",D12,C11) -> Central de fôrmas | D12: LONA PLASTICA 120 MICRAS 4X100M PRETA | E12: =_xlfn.XLOOKUP(D12,Insumos!$B$1:$B$764,Insumos!$C$1:$C$764) -> M2 | F12: 1 | G12: =IF(B12="insumo",_xlfn.XLOOKUP($D12,Insumos!$B$1:$B$764,Insumos!$D$1:$D$764),"") -> 1.25 | H12: {=_xlfn.IFS(B12="Serviço",SUMIFS(H13:$H$3085,C13:$C$3085,$C12),B12="Insumo",F12*G12,B12="Etapa","")} -> 1.25
A13: =COUNTIFS($D$2:$D$3085,D13,$B$2:$B$3085,B13) -> 3 | B13: Insumo | C13: =IF(B13="serviço",D13,C12) -> Central de fôrmas | D13: TELHA METALICA GALVANIZADA TRAPEZOIDAL 0,43MM NBR 14514 | E13: =_xlfn.XLOOKUP(D13,Insumos!$B$1:$B$764,Insumos!$C$1:$C$764) -> M2 | F13: 1 | G13: =IF(B13="insumo",_xlfn.XLOOKUP($D13,Insumos!$B$1:$B$764,Insumos!$D$1:$D$764),"") -> 31 | H13: {=_xlfn.IFS(B13="Serviço",SUMIFS(H14:$H$3085,C14:$C$3085,$C13),B13="Insumo",F13*G13,B13="Etapa","")} -> 31
A14: =COUNTIFS($D$2:$D$3085,D14,$B$2:$B$3085,B14) -> 9 | B14: Insumo | C14: =IF(B14="serviço",D14,C13) -> Central de fôrmas | D14: Concreto Usinado bombeável 20MPa Convencional | E14: =_xlfn.XLOOKUP(D14,Insumos!$B$1:$B$764,Insumos!$C$1:$C$764) -> M3 | F14: 0.074 | G14: =IF(B14="insumo",_xlfn.XLOOKUP($D14,Insumos!$B$1:$B$764,Insumos!$D$1:$D$764),"") -> 490 | H14: {=_xlfn.IFS(B14="Serviço",SUMIFS(H15:$H$3085,C15:$C$3085,$C14),B14="Insumo",F14*G14,B14="Etapa","")} -> 36.26
A15: =COUNTIFS($D$2:$D$3085,D15,$B$2:$B$3085,B15) -> 3 | B15: Insumo | C15: =IF(B15="serviço",D15,C14) -> Central de fôrmas | D15: PREGO GALVANIZADO LISO S/CABECA 17X21 NBR 6627 | E15: =_xlfn.XLOOKUP(D15,Insumos!$B$1:$B$764,Insumos!$C$1:$C$764) -> KG | F15: 0.15 | G15: =IF(B15="insumo",_xlfn.XLOOKUP($D15,Insumos!$B$1:$B$764,Insumos!$D$1:$D$764),"") -> 10.03 | H15: {=_xlfn.IFS(B15="Serviço",SUMIFS(H16:$H$3085,C16:$C$3085,$C15),B15="Insumo",F15*G15,B15="Etapa","")} -> 1.5045
A16: =COUNTIFS($D$2:$D$3085,D16,$B$2:$B$3085,B16) -> 3 | B16: Insumo | C16: =IF(B16="serviço",D16,C15) -> Central de fôrmas | D16: BLOCO CONCRETO ESTRUTURAL 03MPA 14X19X39CM NBR 6136 | E16: =_xlfn.XLOOKUP(D16,Insumos!$B$1:$B$764,Insumos!$C$1:$C$764) -> UN | F16: 9 | G16: =IF(B16="insumo",_xlfn.XLOOKUP($D16,Insumos!$B$1:$B$764,Insumos!$D$1:$D$764),"") -> 2.95 | H16: {=_xlfn.IFS(B16="Serviço",SUMIFS(H17:$H$3085,C17:$C$3085,$C16),B16="Insumo",F16*G16,B16="Etapa","")} -> 26.55
A17: =COUNTIFS($D$2:$D$3085,D17,$B$2:$B$3085,B17) -> 3 | B17: Insumo | C17: =IF(B17="serviço",D17,C16) -> Central de fôrmas | D17: ARGAMASSA ENSACADA P/ASSENTAMENTO BLOCO 04MPA NBR 13281 | E17: =_xlfn.XLOOKUP(D17,Insumos!$B$1:$B$764,Insumos!$C$1:$C$764) -> KG | F17: 24 | G17: =IF(B17="insumo",_xlfn.XLOOKUP($D17,Insumos!$B$1:$B$764,Insumos!$D$1:$D$764),"") -> 0.46 | H17: {=_xlfn.IFS(B17="Serviço",SUMIFS(H18:$H$3085,C18:$C$3085,$C17),B17="Insumo",F17*G17,B17="Etapa","")} -> 11.04
A18: =COUNTIFS($D$2:$D$3085,D18,$B$2:$B$3085,B18) -> 3 | B18: Insumo | C18: =IF(B18="serviço",D18,C17) -> Central de fôrmas | D18: SERVICO EMP. - INST. PROVISORIA - CONFECCAO BAIA P/MATERIAL | E18: =_xlfn.XLOOKUP(D18,Insumos!$B$1:$B$764,Insumos!$C$1:$C$764) -> M2 | F18: 1 | G18: =IF(B18="insumo",_xlfn.XLOOKUP($D18,Insumos!$B$1:$B$764,Insumos!$D$1:$D$764),"") -> 10.5 | H18: {=_xlfn.IFS(B18="Serviço",SUMIFS(H19:$H$3085,C19:$C$3085,$C18),B18="Insumo",F18*G18,B18="Etapa","")} -> 10.5
A19: =COUNTIFS($D$2:$D$3085,D19,$B$2:$B$3085,B19) -> 1 | B19: Serviço | C19: =IF(B19="serviço",D19,C18) -> Central de Argamassa | D19: Central de Argamassa | E19: M2 | G19: =IF(B19="insumo",_xlfn.XLOOKUP($D19,Insumos!$B$1:$B$764,Insumos!$D$1:$D$764),"") | H19: {=_xlfn.IFS(B19="Serviço",SUMIFS(H20:$H$3085,C20:$C$3085,$C19),B19="Insumo",F19*G19,B19="Etapa","")} -> 118.1045 | I19: Sim
A20: =COUNTIFS($D$2:$D$3085,D20,$B$2:$B$3085,B20) -> 3 | B20: Insumo | C20: =IF(B20="serviço",D20,C19) -> Central de Argamassa | D20: LONA PLASTICA 120 MICRAS 4X100M PRETA | E20: =_xlfn.XLOOKUP(D20,Insumos!$B$1:$B$764,Insumos!$C$1:$C$764) -> M2 | F20: 1 | G20: =IF(B20="insumo",_xlfn.XLOOKUP($D20,Insumos!$B$1:$B$764,Insumos!$D$1:$D$764),"") -> 1.25 | H20: {=_xlfn.IFS(B20="Serviço",SUMIFS(H21:$H$3085,C21:$C$3085,$C20),B20="Insumo",F20*G20,B20="Etapa","")} -> 1.25
A21: =COUNTIFS($D$2:$D$3085,D21,$B$2:$B$3085,B21) -> 3 | B21: Insumo | C21: =IF(B21="serviço",D21,C20) -> Central de Argamassa | D21: TELHA METALICA GALVANIZADA TRAPEZOIDAL 0,43MM NBR 14514 | E21: =_xlfn.XLOOKUP(D21,Insumos!$B$1:$B$764,Insumos!$C$1:$C$764) -> M2 | F21: 1 | G21: =IF(B21="insumo",_xlfn.XLOOKUP($D21,Insumos!$B$1:$B$764,Insumos!$D$1:$D$764),"") -> 31 | H21: {=_xlfn.IFS(B21="Serviço",SUMIFS(H22:$H$3085,C22:$C$3085,$C21),B21="Insumo",F21*G21,B21="Etapa","")} -> 31
A22: =COUNTIFS($D$2:$D$3085,D22,$B$2:$B$3085,B22) -> 9 | B22: Insumo | C22: =IF(B22="serviço",D22,C21) -> Central de Argamassa | D22: Concreto Usinado bombeável 20MPa Convencional | E22: =_xlfn.XLOOKUP(D22,Insumos!$B$1:$B$764,Insumos!$C$1:$C$764) -> M3 | F22: 0.074 | G22: =IF(B22="insumo",_xlfn.XLOOKUP($D22,Insumos!$B$1:$B$764,Insumos!$D$1:$D$764),"") -> 490 | H22: {=_xlfn.IFS(B22="Serviço",SUMIFS(H23:$H$3085,C23:$C$3085,$C22),B22="Insumo",F22*G22,B22="Etapa","")} -> 36.26
A23: =COUNTIFS($D$2:$D$3085,D23,$B$2:$B$3085,B23) -> 3 | B23: Insumo | C23: =IF(B23="serviço",D23,C22) -> Central de Argamassa | D23: PREGO GALVANIZADO LISO S/CABECA 17X21 NBR 6627 | E23: =_xlfn.XLOOKUP(D23,Insumos!$B$1:$B$764,Insumos!$C$1:$C$764) -> KG | F23: 0.15 | G23: =IF(B23="insumo",_xlfn.XLOOKUP($D23,Insumos!$B$1:$B$764,Insumos!$D$1:$D$764),"") -> 10.03 | H23: {=_xlfn.IFS(B23="Serviço",SUMIFS(H24:$H$3085,C24:$C$3085,$C23),B23="Insumo",F23*G23,B23="Etapa","")} -> 1.5045
A24: =COUNTIFS($D$2:$D$3085,D24,$B$2:$B$3085,B24) -> 3 | B24: Insumo | C24: =IF(B24="serviço",D24,C23) -> Central de Argamassa | D24: BLOCO CONCRETO ESTRUTURAL 03MPA 14X19X39CM NBR 6136 | E24: =_xlfn.XLOOKUP(D24,Insumos!$B$1:$B$764,Insumos!$C$1:$C$764) -> UN | F24: 9 | G24: =IF(B24="insumo",_xlfn.XLOOKUP($D24,Insumos!$B$1:$B$764,Insumos!$D$1:$D$764),"") -> 2.95 | H24: {=_xlfn.IFS(B24="Serviço",SUMIFS(H25:$H$3085,C25:$C$3085,$C24),B24="Insumo",F24*G24,B24="Etapa","")} -> 26.55
A25: =COUNTIFS($D$2:$D$3085,D25,$B$2:$B$3085,B25) -> 3 | B25: Insumo | C25: =IF(B25="serviço",D25,C24) -> Central de Argamassa | D25: ARGAMASSA ENSACADA P/ASSENTAMENTO BLOCO 04MPA NBR 13281 | E25: =_xlfn.XLOOKUP(D25,Insumos!$B$1:$B$764,Insumos!$C$1:$C$764) -> KG | F25: 24 | G25: =IF(B25="insumo",_xlfn.XLOOKUP($D25,Insumos!$B$1:$B$764,Insumos!$D$1:$D$764),"") -> 0.46 | H25: {=_xlfn.IFS(B25="Serviço",SUMIFS(H26:$H$3085,C26:$C$3085,$C25),B25="Insumo",F25*G25,B25="Etapa","")} -> 11.04
A26: =COUNTIFS($D$2:$D$3085,D26,$B$2:$B$3085,B26) -> 3 | B26: Insumo | C26: =IF(B26="serviço",D26,C25) -> Central de Argamassa | D26: SERVICO EMP. - INST. PROVISORIA - CONFECCAO BAIA P/MATERIAL | E26: =_xlfn.XLOOKUP(D26,Insumos!$B$1:$B$764,Insumos!$C$1:$C$764) -> M2 | F26: 1 | G26: =IF(B26="insumo",_xlfn.XLOOKUP($D26,Insumos!$B$1:$B$764,Insumos!$D$1:$D$764),"") -> 10.5 | H26: {=_xlfn.IFS(B26="Serviço",SUMIFS(H27:$H$3085,C27:$C$3085,$C26),B26="Insumo",F26*G26,B26="Etapa","")} -> 10.5
A27: =COUNTIFS($D$2:$D$3085,D27,$B$2:$B$3085,B27) -> 1 | B27: Serviço | C27: =IF(B27="serviço",D27,C26) -> Armazenamento de cerâmicas* | D27: Armazenamento de cerâmicas* | E27: M2 | G27: =IF(B27="insumo",_xlfn.XLOOKUP($D27,Insumos!$B$1:$B$764,Insumos!$D$1:$D$764),"") | H27: {=_xlfn.IFS(B27="Serviço",SUMIFS(H28:$H$3085,C28:$C$3085,$C27),B27="Insumo",F27*G27,B27="Etapa","")} -> 376.71489 | I27: Sim
A28: =COUNTIFS($D$2:$D$3085,D28,$B$2:$B$3085,B28) -> 11 | B28: Insumo | C28: =IF(B28="serviço",D28,C27) -> Armazenamento de cerâmicas* | D28: MADEIRA PINUS/SIMILAR - TABUA PINUS 200X20MM NBR 11700 | E28: =_xlfn.XLOOKUP(D28,Insumos!$B$1:$B$764,Insumos!$C$1:$C$764) -> M2 | F28: 0.591 | G28: =IF(B28="insumo",_xlfn.XLOOKUP($D28,Insumos!$B$1:$B$764,Insumos!$D$1:$D$764),"") -> 46.5 | H28: {=_xlfn.IFS(B28="Serviço",SUMIFS(H29:$H$3085,C29:$C$3085,$C28),B28="Insumo",F28*G28,B28="Etapa","")} -> 27.4815
A29: =COUNTIFS($D$2:$D$3085,D29,$B$2:$B$3085,B29) -> 10 | B29: Insumo | C29: =IF(B29="serviço",D29,C28) -> Armazenamento de cerâmicas* | D29: COMPENSADO MADEIRA TIPO RESINADO COLA FENOLICA 2440X1220X10MM | E29: =_xlfn.XLOOKUP(D29,Insumos!$B$1:$B$764,Insumos!$C$1:$C$764) -> UN | F29: 0.404 | G29: =IF(B29="insumo",_xlfn.XLOOKUP($D29,Insumos!$B$1:$B$764,Insumos!$D$1:$D$764),"") -> 58.46 | H29: {=_xlfn.IFS(B29="Serviço",SUMIFS(H30:$H$3085,C30:$C$3085,$C29),B29="Insumo",F29*G29,B29="Etapa","")} -> 23.61784
A30: =COUNTIFS($D$2:$D$3085,D30,$B$2:$B$3085,B30) -> 24 | B30: Insumo | C30: =IF(B30="serviço",D30,C29) -> Armazenamento de cerâmicas* | D30: MADEIRA PINUS/SIMILAR - PONTALETE 75X75MM NBR 11700/15696 | E30: =_xlfn.XLOOKUP(D30,Insumos!$B$1:$B$764,Insumos!$C$1:$C$764) -> M | F30: 4.39 | G30: =IF(B30="insumo",_xlfn.XLOOKUP($D30,Insumos!$B$1:$B$764,Insumos!$D$1:$D$764),"") -> 7 | H30: {=_xlfn.IFS(B30="Serviço",SUMIFS(H31:$H$3085,C31:$C$3085,$C30),B30="Insumo",F30*G30,B30="Etapa","")} -> 30.73
A31: =COUNTIFS($D$2:$D$3085,D31,$B$2:$B$3085,B31) -> 11 | B31: Insumo | C31: =IF(B31="serviço",D31,C30) -> Armazenamento de cerâmicas* | D31: MADEIRA PINUS/SIMILAR - SARRAFO PINUS 50X20MM NBR 11700/15696 | E31: =_xlfn.XLOOKUP(D31,Insumos!$B$1:$B$764,Insumos!$C$1:$C$764) -> M2 | F31: 0.15 | G31: =IF(B31="insumo",_xlfn.XLOOKUP($D31,Insumos!$B$1:$B$764,Insumos!$D$1:$D$764),"") -> 46.5 | H31: {=_xlfn.IFS(B31="Serviço",SUMIFS(H32:$H$3085,C32:$C$3085,$C31),B31="Insumo",F31*G31,B31="Etapa","")} -> 6.975
A32: =COUNTIFS($D$2:$D$3085,D32,$B$2:$B$3085,B32) -> 10 | B32: Insumo | C32: =IF(B32="serviço",D32,C31) -> Armazenamento de cerâmicas* | D32: MADEIRA PINUS/SIMILAR - SARRAFO PINUS 50X10MM NBR 11700 | E32: =_xlfn.XLOOKUP(D32,Insumos!$B$1:$B$764,Insumos!$C$1:$C$764) -> M | F32: 1 | G32: =IF(B32="insumo",_xlfn.XLOOKUP($D32,Insumos!$B$1:$B$764,Insumos!$D$1:$D$764),"") -> 2 | H32: {=_xlfn.IFS(B32="Serviço",SUMIFS(H33:$H$3085,C33:$C$3085,$C32),B32="Insumo",F32*G32,B32="Etapa","")} -> 2
A33: =COUNTIFS($D$2:$D$3085,D33,$B$2:$B$3085,B33) -> 36 | B33: Insumo | C33: =IF(B33="serviço",D33,C32) -> Armazenamento de cerâmicas* | D33: PREGO DE ACO POLIDO COM CABECA 17 X 21 (2 X 11) | E33: =_xlfn.XLOOKUP(D33,Insumos!$B$1:$B$764,Insumos!$C$1:$C$764) -> KG | F33: 1 | G33: =IF(B33="insumo",_xlfn.XLOOKUP($D33,Insumos!$B$1:$B$764,Insumos!$D$1:$D$764),"") -> 18.13 | H33: {=_xlfn.IFS(B33="Serviço",SUMIFS(H34:$H$3085,C34:$C$3085,$C33),B33="Insumo",F33*G33,B33="Etapa","")} -> 18.13
A34: =COUNTIFS($D$2:$D$3085,D34,$B$2:$B$3085,B34) -> 10 | B34: Insumo | C34: =IF(B34="serviço",D34,C33) -> Armazenamento de cerâmicas* | D34: EXTINTOR INCENDIO PO QUIMICO 06KG CLASSE ABC (COMPLETO) NBR 15808 | E34: =_xlfn.XLOOKUP(D34,Insumos!$B$1:$B$764,Insumos!$C$1:$C$764) -> UN | F34: 0.015 | G34: =IF(B34="insumo",_xlfn.XLOOKUP($D34,Insumos!$B$1:$B$764,Insumos!$D$1:$D$764),"") -> 185.37 | H34: {=_xlfn.IFS(B34="Serviço",SUMIFS(H35:$H$3085,C35:$C$3085,$C34),B34="Insumo",F34*G34,B34="Etapa","")} -> 2.78055
A35: =COUNTIFS($D$2:$D$3085,D35,$B$2:$B$3085,B35) -> 10 | B35: Insumo | C35: =IF(B35="serviço",D35,C34) -> Armazenamento de cerâmicas* | D35: MATERIAL PARA INSTALAÇÃO ELÉTRICA | E35: =_xlfn.XLOOKUP(D35,Insumos!$B$1:$B$764,Insumos!$C$1:$C$764) -> VB | F35: 1 | G35: =IF(B35="insumo",_xlfn.XLOOKUP($D35,Insumos!$B$1:$B$764,Insumos!$D$1:$D$764),"") -> 215 | H35: {=_xlfn.IFS(B35="Serviço",SUMIFS(H36:$H$3085,C36:$C$3085,$C35),B35="Insumo",F35*G35,B35="Etapa","")} -> 215
A36: =COUNTIFS($D$2:$D$3085,D36,$B$2:$B$3085,B36) -> 10 | B36: Insumo | C36: =IF(B36="serviço",D36,C35) -> Armazenamento de cerâmicas* | D36: SERVICO INSTALAÇÃO BARRACAO ALMOXARIFADO | E36: =_xlfn.XLOOKUP(D36,Insumos!$B$1:$B$764,Insumos!$C$1:$C$764) -> M2 | F36: 1 | G36: =IF(B36="insumo",_xlfn.XLOOKUP($D36,Insumos!$B$1:$B$764,Insumos!$D$1:$D$764),"") -> 50 | H36: {=_xlfn.IFS(B36="Serviço",SUMIFS(H37:$H$3085,C37:$C$3085,$C36),B36="Insumo",F36*G36,B36="Etapa","")} -> 50
A37: =COUNTIFS($D$2:$D$3085,D37,$B$2:$B$3085,B37) -> 1 | B37: Serviço | C37: =IF(B37="serviço",D37,C36) -> Armazenamento de placas degesso* | D37: Armazenamento de placas degesso* | E37: M2 | G37: =IF(B37="insumo",_xlfn.XLOOKUP($D37,Insumos!$B$1:$B$764,Insumos!$D$1:$D$764),"") | H37: {=_xlfn.IFS(B37="Serviço",SUMIFS(H38:$H$3085,C38:$C$3085,$C37),B37="Insumo",F37*G37,B37="Etapa","")} -> 376.71489 | I37: Sim
A38: =COUNTIFS($D$2:$D$3085,D38,$B$2:$B$3085,B38) -> 11 | B38: Insumo | C38: =IF(B38="serviço",D38,C37) -> Armazenamento de placas degesso* | D38: MADEIRA PINUS/SIMILAR - TABUA PINUS 200X20MM NBR 11700 | E38: =_xlfn.XLOOKUP(D38,Insumos!$B$1:$B$764,Insumos!$C$1:$C$764) -> M2 | F38: 0.591 | G38: =IF(B38="insumo",_xlfn.XLOOKUP($D38,Insumos!$B$1:$B$764,Insumos!$D$1:$D$764),"") -> 46.5 | H38: {=_xlfn.IFS(B38="Serviço",SUMIFS(H39:$H$3085,C39:$C$3085,$C38),B38="Insumo",F38*G38,B38="Etapa","")} -> 27.4815
A39: =COUNTIFS($D$2:$D$3085,D39,$B$2:$B$3085,B39) -> 10 | B39: Insumo | C39: =IF(B39="serviço",D39,C38) -> Armazenamento de placas degesso* | D39: COMPENSADO MADEIRA TIPO RESINADO COLA FENOLICA 2440X1220X10MM | E39: =_xlfn.XLOOKUP(D39,Insumos!$B$1:$B$764,Insumos!$C$1:$C$764) -> UN | F39: 0.404 | G39: =IF(B39="insumo",_xlfn.XLOOKUP($D39,Insumos!$B$1:$B$764,Insumos!$D$1:$D$764),"") -> 58.46 | H39: {=_xlfn.IFS(B39="Serviço",SUMIFS(H40:$H$3085,C40:$C$3085,$C39),B39="Insumo",F39*G39,B39="Etapa","")} -> 23.61784
A40: =COUNTIFS($D$2:$D$3085,D40,$B$2:$B$3085,B40) -> 24 | B40: Insumo | C40: =IF(B40="serviço",D40,C39) -> Armazenamento de placas degesso* | D40: MADEIRA PINUS/SIMILAR - PONTALETE 75X75MM NBR 11700/15696 | E40: =_xlfn.XLOOKUP(D40,Insumos!$B$1:$B$764,Insumos!$C$1:$C$764) -> M | F40: 4.39 | G40: =IF(B40="insumo",_xlfn.XLOOKUP($D40,Insumos!$B$1:$B$764,Insumos!$D$1:$D$764),"") -> 7 | H40: {=_xlfn.IFS(B40="Serviço",SUMIFS(H41:$H$3085,C41:$C$3085,$C40),B40="Insumo",F40*G40,B40="Etapa","")} -> 30.73
...

Sheet Insumos
A1: Repetição | B1: Descrição | C1: Und | D1: 1 | E1: Custo Unitário | F1: Grupo insumo | G1: Sub Grupo | H1: Observações | I1: Grupo Sienge
A2: =COUNTIFS($B$2:$B$764,B2) -> 1 | B2: Arame Galvanizado | C2: KG | D2: =E2*$D$1 -> 13.69 | E2: 13.69 | F2: Aço | G2: Arame | I2: Armadura
A3: =COUNTIFS($B$2:$B$764,B3) -> 1 | B3: Arame Recozido BWG 18 | C3: KG | D3: =E3*$D$1 -> 16.71 | E3: 16.71 | F3: Aço | G3: Arame | I3: Armadura
A4: =COUNTIFS($B$2:$B$764,B4) -> 1 | B4: Barras de transferencia lisa 12,5mm 50 cm | C4: pc | D4: =E4*$D$1 -> 3.82 | E4: 3.82 | F4: Aço | G4: Barra de Aço CA50 / CA60 | I4: Armadura
A5: =COUNTIFS($B$2:$B$764,B5) -> 1 | B5: Monocordoalha engraxada CP - 190 RB (12,7mm) | C5: KG | D5: =E5*$D$1 -> 15.5 | E5: 15.5 | F5: Aço | G5: Barra de Aço CA50 / CA60 | I5: Armadura
A6: =COUNTIFS($B$2:$B$764,B6) -> 1 | B6: Armação aço Média para estaca (Corte e Dobra em Obra) | C6: KG | D6: =E6*$D$1 -> 7.6873385 | E6: 7.6873385 | F6: Aço | G6: Barra de Aço CA50 / CA60 | I6: Armadura
A7: =COUNTIFS($B$2:$B$764,B7) -> 1 | B7: Armação aço Média para estaca (Corte e Dobra em Indústria) | C7: KG | D7: =E7*$D$1 -> 8.2873385 | E7: 8.2873385 | F7: Aço | G7: Barra de Aço CA50 / CA60 | I7: Armadura
A8: =COUNTIFS($B$2:$B$764,B8) -> 1 | B8: CORTE E DOBRA ARMADO ESTACA Ø50CM 5F 16,0 4MTS ESP75 PS20 | C8: KG | D8: =E8*$D$1 -> 302.922 | E8: 302.922 | F8: Aço | G8: Barra de Aço CA50 / CA60 | I8: Armadura
A9: =COUNTIFS($B$2:$B$764,B9) -> 1 | B9: CORTE E DOBRA ARMADO ESTACA Ø60CM 5F 20,0 4MTS ESP75 PS20 | C9: KG | D9: =E9*$D$1 -> 466.337 | E9: 466.337 | F9: Aço | G9: Barra de Aço CA50 / CA60 | I9: Armadura
A10: =COUNTIFS($B$2:$B$764,B10) -> 1 | B10: CORTE E DOBRA ARMADO ESTACA Ø60CM 7F 20,0 6MTS ESP75 PS20 | C10: KG | D10: =E10*$D$1 -> 937.639 | E10: 937.639 | F10: Aço | G10: Barra de Aço CA50 / CA60 | I10: Armadura
A11: =COUNTIFS($B$2:$B$764,B11) -> 1 | B11: CORTE E DOBRA ARMADO ESTACA Ø60CM 9F 20,0 8MTS ESP75 PS20 | C11: KG | D11: =E11*$D$1 -> 1609.666 | E11: 1609.666 | F11: Aço | G11: Barra de Aço CA50 / CA60 | I11: Armadura
A12: =COUNTIFS($B$2:$B$764,B12) -> 1 | B12: Aço CA50 10,0 mm | C12: KG | D12: =E12*$D$1 -> 5.76 | E12: 5.76 | F12: Aço | G12: Barra de Aço CA50 / CA60 | I12: Armadura
A13: =COUNTIFS($B$2:$B$764,B13) -> 1 | B13: Aço CA50 12,5 mm | C13: KG | D13: =E13*$D$1 -> 5.59 | E13: 5.59 | F13: Aço | G13: Barra de Aço CA50 / CA60 | I13: Armadura
... A24: =COUNTIFS($B$2:$B$764,B24) -> 1 | B24: TELA ACO CARBONO CA60 M.150X150MM F.04,2MM 245X600CM Q92 (21,8KG/UN) | C24: KG | D24: =E24*$D$1 -> 4.88 | E24: 4.88 | F24: Aço | G24: Tela de Aço CA60 | I24: Armadura
A25: =COUNTIFS($B$2:$B$764,B25) -> 1 | B25: TELA ACO CARBONO CA60 M.100X100MM F.04,2MM 245X600CM Q113 (26,46KG/UN) | C25: KG | D25: =E25*$D$1 -> 8.537037 | E25: =225.89/26.46 -> 8.537037 | F25: Aço | G25: Tela de Aço CA60 | I25: Armadura
A26: =COUNTIFS($B$2:$B$764,B26) -> 1 | B26: TELA ACO CARBONO CA60 M.100X100MM F.04,2MM 245X600CM Q138 (32,34KG/UN) | C26: KG | D26: =E26*$D$1 -> 9.1447124 | E26: 9.1447124 | F26: Aço | G26: Tela de Aço CA60 | I26: Armadura
A27: =COUNTIFS($B$2:$B$764,B27) -> 1 | B27: TELA DE ACO SOLDADA GALVANIZADA/ZINCADA PARA ALVENARIA, FIO D = *1,20 A 1,70* MM, MALHA 15 X 15 MM, (C X L) *50 X 17,5* CM | C27: UN | D27: =E27*$D$1 -> 2.5 | E27: 2.5 | F27: Aço | G27: Tela de Aço Carbono | I27: Armadura
A28: =COUNTIFS($B$2:$B$764,B28) -> 1 | B28: Tela de arame galvanizada, hexagonal, fio 0,56 mm (24 bwg), malha 1/2", h = 1 m | C28: M2 | D28: =E28*$D$1 -> 14.27 | E28: 14.27 | F28: Aço | G28: Tela de Aço Carbono | I28: Armadura
A29: =COUNTIFS($B$2:$B$764,B29) -> 1 | B29: TIJOLO REFRATÁRIO 5 X 11,5 X 23 CM | C29: UN | D29: =E29*$D$1 -> 7 | E29: 7 | F29: Alvenaria | G29: Alvenaria Refratária | I29: Pintura
A30: =COUNTIFS($B$2:$B$764,B30) -> 1 | B30: TIJOLO REFRATÁRIO 2,5 X 11,5 X 23 CM | C30: UN | D30: =E30*$D$1 -> 5.95 | E30: 5.95 | F30: Alvenaria | G30: Alvenaria Refratária | I30: Pintura
A31: =COUNTIFS($B$2:$B$764,B31) -> 1 | B31: BLOCO CONCRETO ESTRUTURAL 03MPA 14X19X39CM NBR 6136 | C31: UN | D31: =E31*$D$1 -> 2.95 | E31: 2.95 | F31: Alvenaria | G31: Alvenaria Estrutural | I31: Elementos de Vedação (Cerâmica)
A32: =COUNTIFS($B$2:$B$764,B32) -> 1 | B32: BLOCO CONCRETO ESTRUTURAL 04MPA 14X19X04CM NBR 6136 | C32: UN | D32: =E32*$D$1 -> 4.1861538 | E32: 4.1861538 | F32: Alvenaria | G32: Alvenaria Estrutural | I32: Elementos de Vedação (Cerâmica)
A33: =COUNTIFS($B$2:$B$764,B33) -> 1 | B33: BLOCO CONCRETO ESTRUTURAL 04MPA 14X19X09CM NBR 6136 | C33: UN | D33: =E33*$D$1 -> 3.9889744 | E33: 3.9889744 | F33: Alvenaria | G33: Alvenaria Estrutural | I33: Elementos de Vedação (Cerâmica)
A34: =COUNTIFS($B$2:$B$764,B34) -> 1 | B34: BLOCO CONCRETO ESTRUTURAL 04MPA 14X19X14CM NBR 6136 | C34: UN | D34: =E34*$D$1 -> 1.376 | E34: 1.376 | F34: Alvenaria | G34: Alvenaria Estrutural | I34: Elementos de Vedação (Cerâmica)
A35: =COUNTIFS($B$2:$B$764,B35) -> 1 | B35: BLOCO CONCRETO ESTRUTURAL 04MPA 11,5X19X29CM NBR 6136 | C35: UN | D35: =E35*$D$1 -> 1.998 | E35: 1.998 | F35: Alvenaria | G35: Alvenaria Estrutural | I35: Elementos de Vedação (Cerâmica)
A36: =COUNTIFS($B$2:$B$764,B36) -> 1 | B36: BLOCO CONCRETO ESTRUTURAL 04MPA 14X19X29CM NBR 6136 | C36: UN | D36: =E36*$D$1 -> 1.998 | E36: 1.998 | F36: Alvenaria | G36: Alvenaria Estrutural | I36: Elementos de Vedação (Cerâmica)
A37: =COUNTIFS($B$2:$B$764,B37) -> 1 | B37: BLOCO CONCRETO ESTRUTURAL 04MPA 14X19X44CM NBR 6136 | C37: UN | D37: =E37*$D$1 -> 4.02 | E37: 4.02 | F37: Alvenaria | G37: Alvenaria Estrutural | I37: Elementos de Vedação (Cerâmica)
... A83: =COUNTIFS($B$2:$B$764,B83) -> 1 | B83: Argamassa ACIII | C83: KG | D83: =E83*$D$1 -> 2.55 | E83: 2.55 | F83: Argamassa | G83: Argamassa de Assentamento de Revestimentos | I83: Argamassa
A84: =COUNTIFS($B$2:$B$764,B84) -> 1 | B84: MASSA JUNTA DRYWALL | C84: KG | D84: =E84*$D$1 -> 5.5 | E84: =33/6 -> 5.5 | F84: Argamassa | G84: Argamassa de Assentamento de Revestimentos | I84: Argamassa
A85: =COUNTIFS($B$2:$B$764,B85) -> 1 | B85: ARGAMASSA COLANTE AC II | C85: KG | D85: =E85*$D$1 -> 1.36 | E85: 1.36 | F85: Argamassa | G85: Argamassa de Assentamento de Revestimentos | I85: Argamassa
A86: =COUNTIFS($B$2:$B$764,B86) -> 1 | B86: Argamassa industrializada para Para Chapisco Colante | C86: KG | D86: =E86*$D$1 -> 2.295 | E86: 2.295 | F86: Argamassa | G86: Argamassa Diversas | I86: Argamassa
A87: =COUNTIFS($B$2:$B$764,B87) -> 1 | B87: Massa Dundun Para Assentamento De Tijolos E Blocos | C87: KG | D87: =E87*$D$1 -> 19.116 | E87: 19.116 | F87: Argamassa | G87: Argamassa Diversas | I87: Argamassa
A88: =COUNTIFS($B$2:$B$764,B88) -> 1 | B88: ARGAMASSA REFRATÁRIA | C88: M3 | D88: =E88*$D$1 -> 1.75 | E88: 1.75 | F88: Argamassa | G88: Argamassa Diversas | I88: Argamassa
A89: =COUNTIFS($B$2:$B$764,B89) -> 1 | B89: Argamassa Usinada para emboço/massa única | C89: M3 | D89: =E89*$D$1 -> 605.66 | E89: 605.66 | F89: Argamassa | G89: Argamassa Diversas | I89: Argamassa
A90: =COUNTIFS($B$2:$B$764,B90) -> 1 | B90: Argamassa usninada para contrapiso | C90: M3 | D90: =E90*$D$1 -> 550 | E90: 550 | F90: Argamassa | G90: Argamassa Diversas | I90: Argamassa
A91: =COUNTIFS($B$2:$B$764,B91) -> 1 | B91: Argila expandida | C91: KG | D91: =E91*$D$1 -> 2.945 | E91: 2.945 | F91: Argamassa | G91: Argamassa Diversas | I91: Argamassa
A92: =COUNTIFS($B$2:$B$764,B92) -> 1 | B92: ARGAMASSA ESTABILIZADA PARA ASSENTAMENTO | C92: M3 | D92: =E92*$D$1 -> 425 | E92: 425 | F92: Argamassa | G92: Argamassa Usinada | I92: Argamassa
A93: =COUNTIFS($B$2:$B$764,B93) -> 1 | B93: ARGAMASSA ESTABILIZADA PARA CHAPISCO | C93: M3 | D93: =E93*$D$1 -> 480 | E93: 480 | F93: Argamassa | G93: Argamassa Usinada | I93: Argamassa
A94: =COUNTIFS($B$2:$B$764,B94) -> 1 | B94: ARGAMASSA INDUSTRIALIZADA MULTIUSO, PARA REVESTIMENTO INTERNO E EXTERNO E ASSENTAMENTO DE BLOCOS DIVERSOS | C94: M3 | D94: =E94*$D$1 -> 425 | E94: 425 | F94: Argamassa | G94: Argamassa Usinada | I94: Argamassa
A95: =COUNTIFS($B$2:$B$764,B95) -> 1 | B95: PISO INTERTRAVADO CONCRETO SEXTAVADO 35MPA 30X30X06CM NATURAL | C95: M2 | D95: =E95*$D$1 -> 75.9 | E95: 75.9 | F95: Artefatos de concreto | G95: Artefatos de concreto | I95: Concretos
...

Sheet Ger_Executivo
G4: PROJETO: | I4: ='Obra '!D1 -> Caio Prado | O4: REVISÃO: | P4: DATA
G5: EMPRESA: | I5: ='Obra '!D2 -> Indepy | O5: R00 | P5: 45980
A6: Unidade Construtiva | B6: Célula Construtiva | C6: Etapa | D6: Subetapa | E6: Serviço | G6: GERENCIAMENTO EXECUTIVO
A7: 0 | B7: 0 | C7: 0 | D7: 0 | E7: 0 | G7: Atalho | H7: NIVEL | I7: Item | J7: Descrição | K7: Unidade | L7: Quant. | M7: Preço un | N7: Total | O7: Considerações | P7: Situação
A8: =IF($H8="UNIDADE CONSTRUTIVA",OFFSET(A8,-1,0)+1,LARGE(A$3:A7,1)) -> 0 | B8: =IF(H8="UNIDADE CONSTRUTIVA",0,IF(H8="CÉLULA CONSTRUTIVA",OFFSET(B8,-1,0)+1,OFFSET(B8,-1,0))) -> 1 | C8: =IF(H8="CÉLULA CONSTRUTIVA",0,IF(H8="ETAPA",OFFSET(C8,-1,0)+1,OFFSET(C8,-1,0))) -> 0 | D8: =IF(H8="ETAPA",0,IF(H8="SUBETAPA",OFFSET(D8,-1,0)+1,OFFSET(D8,-1,0))) -> 0 | E8: =IF(H8="Subetapa",0,IF(H8="serviço",OFFSET(E8,-1,0)+1,OFFSET(E8,-1,0))) -> 0 | H8: CÉLULA CONSTRUTIVA | I8: =IF(H8="Unidade Construtiva",TEXT(A8,"00"),IF(H8="Célula Construtiva",TEXT(B8,"00"),IF(H8="Etapa",CONCATENATE(TEXT(B8,"00"),".",TEXT(C8,"000")),IF(H8="Subetapa",CONCATENATE(TEXT(B8,"00"),".",TEXT(C8,"000"),".",TEXT(D8,"000")),IF(H8="Serviço",CONCATENATE(TEXT(B8,"00"),".",TEXT(C8,"000"),".",TEXT(D8,"000"),".",TEXT(E8,"000")),""))))) -> 01 | J8: MOVIMENTAÇÃO DE TERRA | K8: PEGAR CONTENÇÃO TBM | N8: =IF(H8="Serviço",M8*L8,IF(H8="CÉLULA CONSTRUTIVA",SUMIFS($N$8:$N$452,$B$8:$B$452,B8,$H$8:$H$452,"Serviço"),IF(H8="ETAPA",SUMIFS($N$8:$N$452,$B$8:$B$452,B8,$C$8:$C$452,C8,$H$8:$H$452,"Serviço"),IF(H8="SUBETAPA",SUMIFS($N$8:$N$452,$B$8:$B$452,B8,$C$8:$C$452,C8,$D$8:$D$452,D8,$H$8:$H$452,"Serviço"),0)))) -> 0 | O8: =N8/'Obra '!$E$9 -> 0 | Q8: MOVIMENTAÇÃO DE TERRA
A9: =IF($H9="UNIDADE CONSTRUTIVA",OFFSET(A9,-1,0)+1,LARGE(A$3:A8,1)) -> 0 | B9: =IF(H9="UNIDADE CONSTRUTIVA",0,IF(H9="CÉLULA CONSTRUTIVA",OFFSET(B9,-1,0)+1,OFFSET(B9,-1,0))) -> 1 | C9: =IF(H9="CÉLULA CONSTRUTIVA",0,IF(H9="ETAPA",OFFSET(C9,-1,0)+1,OFFSET(C9,-1,0))) -> 1 | D9: =IF(H9="ETAPA",0,IF(H9="SUBETAPA",OFFSET(D9,-1,0)+1,OFFSET(D9,-1,0))) -> 0 | E9: =IF(H9="Subetapa",0,IF(H9="serviço",OFFSET(E9,-1,0)+1,OFFSET(E9,-1,0))) -> 0 | H9: ETAPA | I9: =IF(H9="Unidade Construtiva",TEXT(A9,"00"),IF(H9="Célula Construtiva",TEXT(B9,"00"),IF(H9="Etapa",CONCATENATE(TEXT(B9,"00"),".",TEXT(C9,"000")),IF(H9="Subetapa",CONCATENATE(TEXT(B9,"00"),".",TEXT(C9,"000"),".",TEXT(D9,"000")),IF(H9="Serviço",CONCATENATE(TEXT(B9,"00"),".",TEXT(C9,"000"),".",TEXT(D9,"000"),".",TEXT(E9,"000")),""))))) -> 01.001 | J9: MOVIMENTAÇÃO DE TERRA | N9: =IF(H9="Serviço",M9*L9,IF(H9="CÉLULA CONSTRUTIVA",SUMIFS($N$8:$N$452,$B$8:$B$452,B9,$H$8:$H$452,"Serviço"),IF(H9="ETAPA",SUMIFS($N$8:$N$452,$B$8:$B$452,B9,$C$8:$C$452,C9,$H$8:$H$452,"Serviço"),IF(H9="SUBETAPA",SUMIFS($N$8:$N$452,$B$8:$B$452,B9,$C$8:$C$452,C9,$D$8:$D$452,D9,$H$8:$H$452,"Serviço"),0)))) -> 0 | O9: =N9/'Obra '!$E$9 -> 0
A10: =IF($H10="UNIDADE CONSTRUTIVA",OFFSET(A10,-1,0)+1,LARGE(A$3:A9,1)) -> 0 | B10: =IF(H10="UNIDADE CONSTRUTIVA",0,IF(H10="CÉLULA CONSTRUTIVA",OFFSET(B10,-1,0)+1,OFFSET(B10,-1,0))) -> 1 | C10: =IF(H10="CÉLULA CONSTRUTIVA",0,IF(H10="ETAPA",OFFSET(C10,-1,0)+1,OFFSET(C10,-1,0))) -> 1 | D10: =IF(H10="ETAPA",0,IF(H10="SUBETAPA",OFFSET(D10,-1,0)+1,OFFSET(D10,-1,0))) -> 1 | E10: =IF(H10="Subetapa",0,IF(H10="serviço",OFFSET(E10,-1,0)+1,OFFSET(E10,-1,0))) -> 0 | H10: SUBETAPA | I10: =IF(H10="Unidade Construtiva",TEXT(A10,"00"),IF(H10="Célula Construtiva",TEXT(B10,"00"),IF(H10="Etapa",CONCATENATE(TEXT(B10,"00"),".",TEXT(C10,"000")),IF(H10="Subetapa",CONCATENATE(TEXT(B10,"00"),".",TEXT(C10,"000"),".",TEXT(D10,"000")),IF(H10="Serviço",CONCATENATE(TEXT(B10,"00"),".",TEXT(C10,"000"),".",TEXT(D10,"000"),".",TEXT(E10,"000")),""))))) -> 01.001.001 | J10: Corte e aterro | N10: =IF(H10="Serviço",M10*L10,IF(H10="CÉLULA CONSTRUTIVA",SUMIFS($N$8:$N$452,$B$8:$B$452,B10,$H$8:$H$452,"Serviço"),IF(H10="ETAPA",SUMIFS($N$8:$N$452,$B$8:$B$452,B10,$C$8:$C$452,C10,$H$8:$H$452,"Serviço"),IF(H10="SUBETAPA",SUMIFS($N$8:$N$452,$B$8:$B$452,B10,$C$8:$C$452,C10,$D$8:$D$452,D10,$H$8:$H$452,"Serviço"),0)))) -> 0 | O10: =N10/'Obra '!$E$9 -> 0
A11: =IF($H11="UNIDADE CONSTRUTIVA",OFFSET(A11,-1,0)+1,LARGE(A$3:A10,1)) -> 0 | B11: =IF(H11="UNIDADE CONSTRUTIVA",0,IF(H11="CÉLULA CONSTRUTIVA",OFFSET(B11,-1,0)+1,OFFSET(B11,-1,0))) -> 1 | C11: =IF(H11="CÉLULA CONSTRUTIVA",0,IF(H11="ETAPA",OFFSET(C11,-1,0)+1,OFFSET(C11,-1,0))) -> 1 | D11: =IF(H11="ETAPA",0,IF(H11="SUBETAPA",OFFSET(D11,-1,0)+1,OFFSET(D11,-1,0))) -> 1 | E11: =IF(H11="Subetapa",0,IF(H11="serviço",OFFSET(E11,-1,0)+1,OFFSET(E11,-1,0))) -> 1 | H11: SERVIÇO | I11: =IF(H11="Unidade Construtiva",TEXT(A11,"00"),IF(H11="Célula Construtiva",TEXT(B11,"00"),IF(H11="Etapa",CONCATENATE(TEXT(B11,"00"),".",TEXT(C11,"000")),IF(H11="Subetapa",CONCATENATE(TEXT(B11,"00"),".",TEXT(C11,"000"),".",TEXT(D11,"000")),IF(H11="Serviço",CONCATENATE(TEXT(B11,"00"),".",TEXT(C11,"000"),".",TEXT(D11,"000"),".",TEXT(E11,"000")),""))))) -> 01.001.001.001 | J11: Terraplanagem - Corte e Desaterro Solo | K11: m3 | M11: =_xlfn.XLOOKUP($J11,CPU!$D$1:$D$3085,CPU!$H$1:$H$3085) -> 2.7132 | N11: =IF(H11="Serviço",M11*L11,IF(H11="CÉLULA CONSTRUTIVA",SUMIFS($N$111:$N$554,$B$111:$B$554,B11,$H$111:$H$554,"Serviço"),IF(H11="ETAPA",SUMIFS($N$111:$N$554,$B$111:$B$554,B11,$C$111:$C$554,C11,$H$111:$H$554,"Serviço"),IF(H11="SUBETAPA",SUMIFS($N$111:$N$554,$B$111:$B$554,B11,$C$111:$C$554,C11,$D$111:$D$554,D11,$H$111:$H$554,"Serviço"),0)))) -> 0 | O11: Corte do subsolo | P11: Finalizado
A12: =IF($H12="UNIDADE CONSTRUTIVA",OFFSET(A12,-1,0)+1,LARGE(A$3:A11,1)) -> 0 | B12: =IF(H12="UNIDADE CONSTRUTIVA",0,IF(H12="CÉLULA CONSTRUTIVA",OFFSET(B12,-1,0)+1,OFFSET(B12,-1,0))) -> 1 | C12: =IF(H12="CÉLULA CONSTRUTIVA",0,IF(H12="ETAPA",OFFSET(C12,-1,0)+1,OFFSET(C12,-1,0))) -> 1 | D12: =IF(H12="ETAPA",0,IF(H12="SUBETAPA",OFFSET(D12,-1,0)+1,OFFSET(D12,-1,0))) -> 1 | E12: =IF(H12="Subetapa",0,IF(H12="serviço",OFFSET(E12,-1,0)+1,OFFSET(E12,-1,0))) -> 2 | H12: SERVIÇO | I12: =IF(H12="Unidade Construtiva",TEXT(A12,"00"),IF(H12="Célula Construtiva",TEXT(B12,"00"),IF(H12="Etapa",CONCATENATE(TEXT(B12,"00"),".",TEXT(C12,"000")),IF(H12="Subetapa",CONCATENATE(TEXT(B12,"00"),".",TEXT(C12,"000"),".",TEXT(D12,"000")),IF(H12="Serviço",CONCATENATE(TEXT(B12,"00"),".",TEXT(C12,"000"),".",TEXT(D12,"000"),".",TEXT(E12,"000")),""))))) -> 01.001.001.002 | J12: Terraplanagem - Aterro material de 1º categoria | K12: m3 | M12: =_xlfn.XLOOKUP($J12,CPU!$D$1:$D$3085,CPU!$H$1:$H$3085) -> 9.2718 | N12: =IF(H12="Serviço",M12*L12,IF(H12="CÉLULA CONSTRUTIVA",SUMIFS($N$111:$N$554,$B$111:$B$554,B12,$H$111:$H$554,"Serviço"),IF(H12="ETAPA",SUMIFS($N$111:$N$554,$B$111:$B$554,B12,$C$111:$C$554,C12,$H$111:$H$554,"Serviço"),IF(H12="SUBETAPA",SUMIFS($N$111:$N$554,$B$111:$B$554,B12,$C$111:$C$554,C12,$D$111:$D$554,D12,$H$111:$H$554,"Serviço"),0)))) -> 0 | O12: Aterro do subsolo | P12: Finalizado
A13: =IF($H13="UNIDADE CONSTRUTIVA",OFFSET(A13,-1,0)+1,LARGE(A$3:A12,1)) -> 0 | B13: =IF(H13="UNIDADE CONSTRUTIVA",0,IF(H13="CÉLULA CONSTRUTIVA",OFFSET(B13,-1,0)+1,OFFSET(B13,-1,0))) -> 1 | C13: =IF(H13="CÉLULA CONSTRUTIVA",0,IF(H13="ETAPA",OFFSET(C13,-1,0)+1,OFFSET(C13,-1,0))) -> 1 | D13: =IF(H13="ETAPA",0,IF(H13="SUBETAPA",OFFSET(D13,-1,0)+1,OFFSET(D13,-1,0))) -> 2 | E13: =IF(H13="Subetapa",0,IF(H13="serviço",OFFSET(E13,-1,0)+1,OFFSET(E13,-1,0))) -> 0 | H13: SUBETAPA | I13: =IF(H13="Unidade Construtiva",TEXT(A13,"00"),IF(H13="Célula Construtiva",TEXT(B13,"00"),IF(H13="Etapa",CONCATENATE(TEXT(B13,"00"),".",TEXT(C13,"000")),IF(H13="Subetapa",CONCATENATE(TEXT(B13,"00"),".",TEXT(C13,"000"),".",TEXT(D13,"000")),IF(H13="Serviço",CONCATENATE(TEXT(B13,"00"),".",TEXT(C13,"000"),".",TEXT(D13,"000"),".",TEXT(E13,"000")),""))))) -> 01.001.002 | J13: Escavação e Reaterro de Valas | N13: =IF(H13="Serviço",M13*L13,IF(H13="CÉLULA CONSTRUTIVA",SUMIFS($N$8:$N$452,$B$8:$B$452,B13,$H$8:$H$452,"Serviço"),IF(H13="ETAPA",SUMIFS($N$8:$N$452,$B$8:$B$452,B13,$C$8:$C$452,C13,$H$8:$H$452,"Serviço"),IF(H13="SUBETAPA",SUMIFS($N$8:$N$452,$B$8:$B$452,B13,$C$8:$C$452,C13,$D$8:$D$452,D13,$H$8:$H$452,"Serviço"),0)))) -> 0 | O13: =N13/'Obra '!$E$9 -> 0
A14: =IF($H14="UNIDADE CONSTRUTIVA",OFFSET(A14,-1,0)+1,LARGE(A$3:A13,1)) -> 0 | B14: =IF(H14="UNIDADE CONSTRUTIVA",0,IF(H14="CÉLULA CONSTRUTIVA",OFFSET(B14,-1,0)+1,OFFSET(B14,-1,0))) -> 1 | C14: =IF(H14="CÉLULA CONSTRUTIVA",0,IF(H14="ETAPA",OFFSET(C14,-1,0)+1,OFFSET(C14,-1,0))) -> 1 | D14: =IF(H14="ETAPA",0,IF(H14="SUBETAPA",OFFSET(D14,-1,0)+1,OFFSET(D14,-1,0))) -> 2 | E14: =IF(H14="Subetapa",0,IF(H14="serviço",OFFSET(E14,-1,0)+1,OFFSET(E14,-1,0))) -> 1 | H14: SERVIÇO | I14: =IF(H14="Unidade Construtiva",TEXT(A14,"00"),IF(H14="Célula Construtiva",TEXT(B14,"00"),IF(H14="Etapa",CONCATENATE(TEXT(B14,"00"),".",TEXT(C14,"000")),IF(H14="Subetapa",CONCATENATE(TEXT(B14,"00"),".",TEXT(C14,"000"),".",TEXT(D14,"000")),IF(H14="Serviço",CONCATENATE(TEXT(B14,"00"),".",TEXT(C14,"000"),".",TEXT(D14,"000"),".",TEXT(E14,"000")),""))))) -> 01.001.002.001 | J14: Escavação mecanizada para estacas de fundação, com retroescavadeira | K14: m3 | M14: =_xlfn.XLOOKUP($J14,CPU!$D$1:$D$3085,CPU!$H$1:$H$3085) -> 36.36 | N14: =IF(H14="Serviço",M14*L14,IF(H14="CÉLULA CONSTRUTIVA",SUMIFS($N$8:$N$452,$B$8:$B$452,B14,$H$8:$H$452,"Serviço"),IF(H14="ETAPA",SUMIFS($N$8:$N$452,$B$8:$B$452,B14,$C$8:$C$452,C14,$H$8:$H$452,"Serviço"),IF(H14="SUBETAPA",SUMIFS($N$8:$N$452,$B$8:$B$452,B14,$C$8:$C$452,C14,$D$8:$D$452,D14,$H$8:$H$452,"Serviço"),0)))) -> 0 | O14: Considerado estacas e contenção, conforme repassado pelo projetista | P14: Finalizado
A15: =IF($H15="UNIDADE CONSTRUTIVA",OFFSET(A15,-1,0)+1,LARGE(A$3:A14,1)) -> 0 | B15: =IF(H15="UNIDADE CONSTRUTIVA",0,IF(H15="CÉLULA CONSTRUTIVA",OFFSET(B15,-1,0)+1,OFFSET(B15,-1,0))) -> 1 | C15: =IF(H15="CÉLULA CONSTRUTIVA",0,IF(H15="ETAPA",OFFSET(C15,-1,0)+1,OFFSET(C15,-1,0))) -> 1 | D15: =IF(H15="ETAPA",0,IF(H15="SUBETAPA",OFFSET(D15,-1,0)+1,OFFSET(D15,-1,0))) -> 2 | E15: =IF(H15="Subetapa",0,IF(H15="serviço",OFFSET(E15,-1,0)+1,OFFSET(E15,-1,0))) -> 2 | H15: SERVIÇO | I15: =IF(H15="Unidade Construtiva",TEXT(A15,"00"),IF(H15="Célula Construtiva",TEXT(B15,"00"),IF(H15="Etapa",CONCATENATE(TEXT(B15,"00"),".",TEXT(C15,"000")),IF(H15="Subetapa",CONCATENATE(TEXT(B15,"00"),".",TEXT(C15,"000"),".",TEXT(D15,"000")),IF(H15="Serviço",CONCATENATE(TEXT(B15,"00"),".",TEXT(C15,"000"),".",TEXT(D15,"000"),".",TEXT(E15,"000")),""))))) -> 01.001.002.002 | J15: Escavação mecanizada para blocos de fundação, vigas de fundação e poço de elevador, com retroescavadeira | K15: m3 | M15: =_xlfn.XLOOKUP($J15,CPU!$D$1:$D$3085,CPU!$H$1:$H$3085) -> 36.36 | N15: =IF(H15="Serviço",M15*L15,IF(H15="CÉLULA CONSTRUTIVA",SUMIFS($N$8:$N$452,$B$8:$B$452,B15,$H$8:$H$452,"Serviço"),IF(H15="ETAPA",SUMIFS($N$8:$N$452,$B$8:$B$452,B15,$C$8:$C$452,C15,$H$8:$H$452,"Serviço"),IF(H15="SUBETAPA",SUMIFS($N$8:$N$452,$B$8:$B$452,B15,$C$8:$C$452,C15,$D$8:$D$452,D15,$H$8:$H$452,"Serviço"),0)))) -> 0 | O15: Considerado estimativa de blocos, vigas de fundação e pilares, devido a ausencia de projeto | P15: Finalizado
A16: =IF($H16="UNIDADE CONSTRUTIVA",OFFSET(A16,-1,0)+1,LARGE(A$3:A15,1)) -> 0 | B16: =IF(H16="UNIDADE CONSTRUTIVA",0,IF(H16="CÉLULA CONSTRUTIVA",OFFSET(B16,-1,0)+1,OFFSET(B16,-1,0))) -> 1 | C16: =IF(H16="CÉLULA CONSTRUTIVA",0,IF(H16="ETAPA",OFFSET(C16,-1,0)+1,OFFSET(C16,-1,0))) -> 1 | D16: =IF(H16="ETAPA",0,IF(H16="SUBETAPA",OFFSET(D16,-1,0)+1,OFFSET(D16,-1,0))) -> 2 | E16: =IF(H16="Subetapa",0,IF(H16="serviço",OFFSET(E16,-1,0)+1,OFFSET(E16,-1,0))) -> 3 | H16: SERVIÇO | I16: =IF(H16="Unidade Construtiva",TEXT(A16,"00"),IF(H16="Célula Construtiva",TEXT(B16,"00"),IF(H16="Etapa",CONCATENATE(TEXT(B16,"00"),".",TEXT(C16,"000")),IF(H16="Subetapa",CONCATENATE(TEXT(B16,"00"),".",TEXT(C16,"000"),".",TEXT(D16,"000")),IF(H16="Serviço",CONCATENATE(TEXT(B16,"00"),".",TEXT(C16,"000"),".",TEXT(D16,"000"),".",TEXT(E16,"000")),""))))) -> 01.001.002.003 | J16: Reaterro mecanizado de valas para blocos e vigas de fundação, com retroescavadeira | K16: m3 | M16: =_xlfn.XLOOKUP($J16,CPU!$D$1:$D$3085,CPU!$H$1:$H$3085) -> 14.55 | N16: =IF(H16="Serviço",M16*L16,IF(H16="CÉLULA CONSTRUTIVA",SUMIFS($N$8:$N$452,$B$8:$B$452,B16,$H$8:$H$452,"Serviço"),IF(H16="ETAPA",SUMIFS($N$8:$N$452,$B$8:$B$452,B16,$C$8:$C$452,C16,$H$8:$H$452,"Serviço"),IF(H16="SUBETAPA",SUMIFS($N$8:$N$452,$B$8:$B$452,B16,$C$8:$C$452,C16,$D$8:$D$452,D16,$H$8:$H$452,"Serviço"),0)))) -> 0 | P16: Finalizado
A17: =IF($H17="UNIDADE CONSTRUTIVA",OFFSET(A17,-1,0)+1,LARGE(A$3:A16,1)) -> 0 | B17: =IF(H17="UNIDADE CONSTRUTIVA",0,IF(H17="CÉLULA CONSTRUTIVA",OFFSET(B17,-1,0)+1,OFFSET(B17,-1,0))) -> 1 | C17: =IF(H17="CÉLULA CONSTRUTIVA",0,IF(H17="ETAPA",OFFSET(C17,-1,0)+1,OFFSET(C17,-1,0))) -> 1 | D17: =IF(H17="ETAPA",0,IF(H17="SUBETAPA",OFFSET(D17,-1,0)+1,OFFSET(D17,-1,0))) -> 3 | E17: =IF(H17="Subetapa",0,IF(H17="serviço",OFFSET(E17,-1,0)+1,OFFSET(E17,-1,0))) -> 0 | H17: SUBETAPA | I17: =IF(H17="Unidade Construtiva",TEXT(A17,"00"),IF(H17="Célula Construtiva",TEXT(B17,"00"),IF(H17="Etapa",CONCATENATE(TEXT(B17,"00"),".",TEXT(C17,"000")),IF(H17="Subetapa",CONCATENATE(TEXT(B17,"00"),".",TEXT(C17,"000"),".",TEXT(D17,"000")),IF(H17="Serviço",CONCATENATE(TEXT(B17,"00"),".",TEXT(C17,"000"),".",TEXT(D17,"000"),".",TEXT(E17,"000")),""))))) -> 01.001.003 | J17: Lastro de estrutura de concreto | N17: =IF(H17="Serviço",M17*L17,IF(H17="CÉLULA CONSTRUTIVA",SUMIFS($N$8:$N$452,$B$8:$B$452,B17,$H$8:$H$452,"Serviço"),IF(H17="ETAPA",SUMIFS($N$8:$N$452,$B$8:$B$452,B17,$C$8:$C$452,C17,$H$8:$H$452,"Serviço"),IF(H17="SUBETAPA",SUMIFS($N$8:$N$452,$B$8:$B$452,B17,$C$8:$C$452,C17,$D$8:$D$452,D17,$H$8:$H$452,"Serviço"),0)))) -> 0 | O17: =N17/'Obra '!$E$9 -> 0
A18: =IF($H18="UNIDADE CONSTRUTIVA",OFFSET(A18,-1,0)+1,LARGE(A$3:A17,1)) -> 0 | B18: =IF(H18="UNIDADE CONSTRUTIVA",0,IF(H18="CÉLULA CONSTRUTIVA",OFFSET(B18,-1,0)+1,OFFSET(B18,-1,0))) -> 1 | C18: =IF(H18="CÉLULA CONSTRUTIVA",0,IF(H18="ETAPA",OFFSET(C18,-1,0)+1,OFFSET(C18,-1,0))) -> 1 | D18: =IF(H18="ETAPA",0,IF(H18="SUBETAPA",OFFSET(D18,-1,0)+1,OFFSET(D18,-1,0))) -> 3 | E18: =IF(H18="Subetapa",0,IF(H18="serviço",OFFSET(E18,-1,0)+1,OFFSET(E18,-1,0))) -> 1 | H18: SERVIÇO | I18: =IF(H18="Unidade Construtiva",TEXT(A18,"00"),IF(H18="Célula Construtiva",TEXT(B18,"00"),IF(H18="Etapa",CONCATENATE(TEXT(B18,"00"),".",TEXT(C18,"000")),IF(H18="Subetapa",CONCATENATE(TEXT(B18,"00"),".",TEXT(C18,"000"),".",TEXT(D18,"000")),IF(H18="Serviço",CONCATENATE(TEXT(B18,"00"),".",TEXT(C18,"000"),".",TEXT(D18,"000"),".",TEXT(E18,"000")),""))))) -> 01.001.003.001 | J18: Lastro de Concreto Magro, Aplicado em Blocos de Fundação | K18: m3 | M18: =_xlfn.XLOOKUP($J18,CPU!$D$1:$D$3085,CPU!$H$1:$H$3085) -> 518.794 | N18: =IF(H18="Serviço",M18*L18,IF(H18="CÉLULA CONSTRUTIVA",SUMIFS($N$8:$N$452,$B$8:$B$452,B18,$H$8:$H$452,"Serviço"),IF(H18="ETAPA",SUMIFS($N$8:$N$452,$B$8:$B$452,B18,$C$8:$C$452,C18,$H$8:$H$452,"Serviço"),IF(H18="SUBETAPA",SUMIFS($N$8:$N$452,$B$8:$B$452,B18,$C$8:$C$452,C18,$D$8:$D$452,D18,$H$8:$H$452,"Serviço"),0)))) -> 0 | O18: Quantidades referentes ao levantamento cartesiano, com base nnos projetos e adicionado o levantado pelo projetista nas áres de piso armado | P18: Finalizado
A19: =IF($H19="UNIDADE CONSTRUTIVA",OFFSET(A19,-1,0)+1,LARGE(A$3:A18,1)) -> 0 | B19: =IF(H19="UNIDADE CONSTRUTIVA",0,IF(H19="CÉLULA CONSTRUTIVA",OFFSET(B19,-1,0)+1,OFFSET(B19,-1,0))) -> 1 | C19: =IF(H19="CÉLULA CONSTRUTIVA",0,IF(H19="ETAPA",OFFSET(C19,-1,0)+1,OFFSET(C19,-1,0))) -> 1 | D19: =IF(H19="ETAPA",0,IF(H19="SUBETAPA",OFFSET(D19,-1,0)+1,OFFSET(D19,-1,0))) -> 4 | E19: =IF(H19="Subetapa",0,IF(H19="serviço",OFFSET(E19,-1,0)+1,OFFSET(E19,-1,0))) -> 0 | H19: SUBETAPA | I19: =IF(H19="Unidade Construtiva",TEXT(A19,"00"),IF(H19="Célula Construtiva",TEXT(B19,"00"),IF(H19="Etapa",CONCATENATE(TEXT(B19,"00"),".",TEXT(C19,"000")),IF(H19="Subetapa",CONCATENATE(TEXT(B19,"00"),".",TEXT(C19,"000"),".",TEXT(D19,"000")),IF(H19="Serviço",CONCATENATE(TEXT(B19,"00"),".",TEXT(C19,"000"),".",TEXT(D19,"000"),".",TEXT(E19,"000")),""))))) -> 01.001.004 | J19: Movimentação de bota - fora | N19: =IF(H19="Serviço",M19*L19,IF(H19="CÉLULA CONSTRUTIVA",SUMIFS($N$8:$N$452,$B$8:$B$452,B19,$H$8:$H$452,"Serviço"),IF(H19="ETAPA",SUMIFS($N$8:$N$452,$B$8:$B$452,B19,$C$8:$C$452,C19,$H$8:$H$452,"Serviço"),IF(H19="SUBETAPA",SUMIFS($N$8:$N$452,$B$8:$B$452,B19,$C$8:$C$452,C19,$D$8:$D$452,D19,$H$8:$H$452,"Serviço"),0)))) -> 0 | O19: =N19/'Obra '!$E$9 -> 0
A20: =IF($H20="UNIDADE CONSTRUTIVA",OFFSET(A20,-1,0)+1,LARGE(A$3:A19,1)) -> 0 | B20: =IF(H20="UNIDADE CONSTRUTIVA",0,IF(H20="CÉLULA CONSTRUTIVA",OFFSET(B20,-1,0)+1,OFFSET(B20,-1,0))) -> 1 | C20: =IF(H20="CÉLULA CONSTRUTIVA",0,IF(H20="ETAPA",OFFSET(C20,-1,0)+1,OFFSET(C20,-1,0))) -> 1 | D20: =IF(H20="ETAPA",0,IF(H20="SUBETAPA",OFFSET(D20,-1,0)+1,OFFSET(D20,-1,0))) -> 4 | E20: =IF(H20="Subetapa",0,IF(H20="serviço",OFFSET(E20,-1,0)+1,OFFSET(E20,-1,0))) -> 1 | H20: SERVIÇO | I20: =IF(H20="Unidade Construtiva",TEXT(A20,"00"),IF(H20="Célula Construtiva",TEXT(B20,"00"),IF(H20="Etapa",CONCATENATE(TEXT(B20,"00"),".",TEXT(C20,"000")),IF(H20="Subetapa",CONCATENATE(TEXT(B20,"00"),".",TEXT(C20,"000"),".",TEXT(D20,"000")),IF(H20="Serviço",CONCATENATE(TEXT(B20,"00"),".",TEXT(C20,"000"),".",TEXT(D20,"000"),".",TEXT(E20,"000")),""))))) -> 01.001.004.001 | J20: Movimentação de terra para bota-fora - Escavação Vertical Terraplenagem | K20: m3 | M20: =_xlfn.XLOOKUP($J20,CPU!$D$1:$D$3085,CPU!$H$1:$H$3085) -> 45.45 | N20: =IF(H20="Serviço",M20*L20,IF(H20="CÉLULA CONSTRUTIVA",SUMIFS($N$8:$N$452,$B$8:$B$452,B20,$H$8:$H$452,"Serviço"),IF(H20="ETAPA",SUMIFS($N$8:$N$452,$B$8:$B$452,B20,$C$8:$C$452,C20,$H$8:$H$452,"Serviço"),IF(H20="SUBETAPA",SUMIFS($N$8:$N$452,$B$8:$B$452,B20,$C$8:$C$452,C20,$D$8:$D$452,D20,$H$8:$H$452,"Serviço"),0)))) -> 0 | O20: Bota fora do subsolo | P20: Finalizado
A21: =IF($H21="UNIDADE CONSTRUTIVA",OFFSET(A21,-1,0)+1,LARGE(A$3:A20,1)) -> 0 | B21: =IF(H21="UNIDADE CONSTRUTIVA",0,IF(H21="CÉLULA CONSTRUTIVA",OFFSET(B21,-1,0)+1,OFFSET(B21,-1,0))) -> 1 | C21: =IF(H21="CÉLULA CONSTRUTIVA",0,IF(H21="ETAPA",OFFSET(C21,-1,0)+1,OFFSET(C21,-1,0))) -> 1 | D21: =IF(H21="ETAPA",0,IF(H21="SUBETAPA",OFFSET(D21,-1,0)+1,OFFSET(D21,-1,0))) -> 4 | E21: =IF(H21="Subetapa",0,IF(H21="serviço",OFFSET(E21,-1,0)+1,OFFSET(E21,-1,0))) -> 2 | H21: SERVIÇO | I21: =IF(H21="Unidade Construtiva",TEXT(A21,"00"),IF(H21="Célula Construtiva",TEXT(B21,"00"),IF(H21="Etapa",CONCATENATE(TEXT(B21,"00"),".",TEXT(C21,"000")),IF(H21="Subetapa",CONCATENATE(TEXT(B21,"00"),".",TEXT(C21,"000"),".",TEXT(D21,"000")),IF(H21="Serviço",CONCATENATE(TEXT(B21,"00"),".",TEXT(C21,"000"),".",TEXT(D21,"000"),".",TEXT(E21,"000")),""))))) -> 01.001.004.002 | J21: Movimentação de terra para bota-fora - Escavação de Valas | K21: m3 | M21: =_xlfn.XLOOKUP($J21,CPU!$D$1:$D$3085,CPU!$H$1:$H$3085) -> 45.45 | N21: =IF(H21="Serviço",M21*L21,IF(H21="CÉLULA CONSTRUTIVA",SUMIFS($N$8:$N$452,$B$8:$B$452,B21,$H$8:$H$452,"Serviço"),IF(H21="ETAPA",SUMIFS($N$8:$N$452,$B$8:$B$452,B21,$C$8:$C$452,C21,$H$8:$H$452,"Serviço"),IF(H21="SUBETAPA",SUMIFS($N$8:$N$452,$B$8:$B$452,B21,$C$8:$C$452,C21,$D$8:$D$452,D21,$H$8:$H$452,"Serviço"),0)))) -> 0 | P21: Finalizado
A22: =IF($H22="UNIDADE CONSTRUTIVA",OFFSET(A22,-1,0)+1,LARGE(A$3:A21,1)) -> 0 | B22: =IF(H22="UNIDADE CONSTRUTIVA",0,IF(H22="CÉLULA CONSTRUTIVA",OFFSET(B22,-1,0)+1,OFFSET(B22,-1,0))) -> 1 | C22: =IF(H22="CÉLULA CONSTRUTIVA",0,IF(H22="ETAPA",OFFSET(C22,-1,0)+1,OFFSET(C22,-1,0))) -> 1 | D22: =IF(H22="ETAPA",0,IF(H22="SUBETAPA",OFFSET(D22,-1,0)+1,OFFSET(D22,-1,0))) -> 4 | E22: =IF(H22="Subetapa",0,IF(H22="serviço",OFFSET(E22,-1,0)+1,OFFSET(E22,-1,0))) -> 3 | H22: SERVIÇO | I22: =IF(H22="Unidade Construtiva",TEXT(A22,"00"),IF(H22="Célula Construtiva",TEXT(B22,"00"),IF(H22="Etapa",CONCATENATE(TEXT(B22,"00"),".",TEXT(C22,"000")),IF(H22="Subetapa",CONCATENATE(TEXT(B22,"00"),".",TEXT(C22,"000"),".",TEXT(D22,"000")),IF(H22="Serviço",CONCATENATE(TEXT(B22,"00"),".",TEXT(C22,"000"),".",TEXT(D22,"000"),".",TEXT(E22,"000")),""))))) -> 01.001.004.003 | J22: Movimentação de terra para bota-fora - Estacas | K22: m3 | M22: =_xlfn.XLOOKUP($J22,CPU!$D$1:$D$3085,CPU!$H$1:$H$3085) -> 68.18 | N22: =IF(H22="Serviço",M22*L22,IF(H22="CÉLULA CONSTRUTIVA",SUMIFS($N$8:$N$452,$B$8:$B$452,B22,$H$8:$H$452,"Serviço"),IF(H22="ETAPA",SUMIFS($N$8:$N$452,$B$8:$B$452,B22,$C$8:$C$452,C22,$H$8:$H$452,"Serviço"),IF(H22="SUBETAPA",SUMIFS($N$8:$N$452,$B$8:$B$452,B22,$C$8:$C$452,C22,$D$8:$D$452,D22,$H$8:$H$452,"Serviço"),0)))) -> 0 | O22: Considerado estacas e contenção, conforme repassado pelo projetista | P22: Finalizado
A23: =IF($H23="UNIDADE CONSTRUTIVA",OFFSET(A23,-1,0)+1,LARGE(A$3:A22,1)) -> 0 | B23: =IF(H23="UNIDADE CONSTRUTIVA",0,IF(H23="CÉLULA CONSTRUTIVA",OFFSET(B23,-1,0)+1,OFFSET(B23,-1,0))) -> 2 | C23: =IF(H23="CÉLULA CONSTRUTIVA",0,IF(H23="ETAPA",OFFSET(C23,-1,0)+1,OFFSET(C23,-1,0))) -> 0 | D23: =IF(H23="ETAPA",0,IF(H23="SUBETAPA",OFFSET(D23,-1,0)+1,OFFSET(D23,-1,0))) -> 4 | E23: =IF(H23="Subetapa",0,IF(H23="serviço",OFFSET(E23,-1,0)+1,OFFSET(E23,-1,0))) -> 3 | H23: CÉLULA CONSTRUTIVA | I23: =IF(H23="Unidade Construtiva",TEXT(A23,"00"),IF(H23="Célula Construtiva",TEXT(B23,"00"),IF(H23="Etapa",CONCATENATE(TEXT(B23,"00"),".",TEXT(C23,"000")),IF(H23="Subetapa",CONCATENATE(TEXT(B23,"00"),".",TEXT(C23,"000"),".",TEXT(D23,"000")),IF(H23="Serviço",CONCATENATE(TEXT(B23,"00"),".",TEXT(C23,"000"),".",TEXT(D23,"000"),".",TEXT(E23,"000")),""))))) -> 02 | J23: INFRAESTRUTURA | N23: =IF(H23="Serviço",M23*L23,IF(H23="CÉLULA CONSTRUTIVA",SUMIFS($N$8:$N$452,$B$8:$B$452,B23,$H$8:$H$452,"Serviço"),IF(H23="ETAPA",SUMIFS($N$8:$N$452,$B$8:$B$452,B23,$C$8:$C$452,C23,$H$8:$H$452,"Serviço"),IF(H23="SUBETAPA",SUMIFS($N$8:$N$452,$B$8:$B$452,B23,$C$8:$C$452,C23,$D$8:$D$452,D23,$H$8:$H$452,"Serviço"),0)))) -> 0 | O23: =N23/'Obra '!$E$9 -> 0 | Q23: INFRAESTRUTURA
