Workbook
Name aa: #REF!
Name aa: #REF!
Name aa: #REF!
Name aa: #REF!
Name aaaa: '[1]M.O.'!#REF!
Name aaaa: '[1]M.O.'!#REF!
Name aaaa: '[1]M.O.'!#REF!
Name aaaa: '[1]M.O.'!#REF!
Name angelo: [2]Geral!#REF!
Name angelo: [2]Geral!#REF!
Name angelo: [2]Geral!#REF!
Name area: #REF!
Name aux: #REF!
Name aux: #REF!
Name aux: #REF!
Name BDA: #REF!
Name BDA: #REF!
Name BDA: #REF!
Name BDI: #REF!
Name BDI: #REF!
Name ca: #REF!
Name ca: #REF!
Name Capa: #REF!
Name Capa: #REF!
Name cronograma: #REF!
Name cronograma: #REF!
Name D: #REF!
Name D: #REF!
Name direto: #REF!
Name direto: #REF!
Name DRE: #REF!
Name DRE: #REF!
Name ea: #REF!
Name ea: #REF!
Name eee: {#N/A,#N/A,FALSE,"ET-CAPA";#N/A,#N/A,FALSE,"ET-PAG1";#N/A,#N/A,FALSE,"ET-PAG2";#N/A,#N/A,FALSE,"ET-PAG3";#N/A,#N/A,FALSE,"ET-PAG4";#N/A,#N/A,FALSE,"ET-PAG5"}
Name eee: {#N/A,#N/A,FALSE,"ET-CAPA";#N/A,#N/A,FALSE,"ET-PAG1";#N/A,#N/A,FALSE,"ET-PAG2";#N/A,#N/A,FALSE,"ET-PAG3";#N/A,#N/A,FALSE,"ET-PAG4";#N/A,#N/A,FALSE,"ET-PAG5"}
Name eee: {#N/A,#N/A,FALSE,"ET-CAPA";#N/A,#N/A,FALSE,"ET-PAG1";#N/A,#N/A,FALSE,"ET-PAG2";#N/A,#N/A,FALSE,"ET-PAG3";#N/A,#N/A,FALSE,"ET-PAG4";#N/A,#N/A,FALSE,"ET-PAG5"}
Name eee: {#N/A,#N/A,FALSE,"ET-CAPA";#N/A,#N/A,FALSE,"ET-PAG1";#N/A,#N/A,FALSE,"ET-PAG2";#N/A,#N/A,FALSE,"ET-PAG3";#N/A,#N/A,FALSE,"ET-PAG4";#N/A,#N/A,FALSE,"ET-PAG5"}
Name FFFFFFF: #REF!
Name FFFFFFF: #REF!
Name item_1: #REF!
Name item_1: #REF!
Name LS: '[1]M.O.'!#REF!
Name LS: '[1]M.O.'!#REF!
Name MENU: #REF!
Name MENU: #REF!
Name MENU: #REF!
Name MENU: #REF!
Name MENU1: #REF!
Name MENU1: #REF!
Name MENU1: #REF!
Name MENU2: #REF!
Name MENU2: #REF!
Name MENU2: #REF!
Name MENU3: #REF!
Name MENU3: #REF!
Name MENU4: #REF!
Name MENU4: #REF!
Name MENU5: #REF!
Name MENU5: #REF!

Sheet OBRA
A1: Obra | B1: Viva Perequê Residencial
A2: Empresa | B2: Ferazzo e Correa Incorporadora
A3: Revisão | B3: R00
A4: DADOS OBRA
A6: ARQUITETURA
B8: Descrição | C8: Unidade | D8: Quantidade
B9: ÁREA DO TERRENO | C9: M2 | D9: 600
B10: ÁREA CONSTRUÍDA | C10: M2 | D10: 5576.17
B11: NÚMERO DE UNIDADES HABITACIONAIS | C11: UN | D11: 34
B12: MESES DE OBRA | C12: MÊS | D12: 35
B13: NÚMERO DE PAVIMENTOS | C13: UN | D13: 15

Sheet CANTEIRO
A1: Obra | B1: =OBRA!B1 -> Viva Perequê Residencial
A2: Empresa | B2: =OBRA!B2 -> Ferazzo e Correa Incorporadora
A3: Revisão | B3: =OBRA!B3 -> R00
A4: LEVANTAMENTO QUANTITATIVO
A6: Instalações de canteiro
A8: Instalações de canteiro
B10: Descrição | C10: Unidade | D10: Quantidade
B11: Produtividade média | C11: m2 / mês | D11: =OBRA!D10/OBRA!D12 -> 159.31914
B12: Pm | C12: h/m2 | D12: 49
B13: Numero de funcionários | C13: un | D13: =ROUNDUP((D12*OBRA!D10)/OBRA!D12/180,) -> 44
B14: Equipe administrativa | C14: un | D14: 5
B15: Pontos de água e esgoto | C15: un | D15: =ROUNDUP($D$13/20,0) -> 3 | E15: 20 funcionários/ponto
B16: Bebedouro | C16: un | D16: =ROUNDUP(OBRA!$D$13/5,0) -> 3 | E16: 1 / 5 pav.
B17: Ferramentas | C17: R$ | D17: =800*D13 -> 35200 | E17: 800,00/func.
B18: EPI | C18: R$ | D18: =500*(D13+D14) -> 24500 | E18: 500,00/func.
B19: Banheiro | C19: un | D19: =ROUNDUP($D$13/20,0) -> 3 | E19: 1/20 func
A21: Mobiliário de canteiro
B23: Descrição | C23: Unidade | D23: Quantidade | E23: Custo unitário | F23: Custo total
B24: Cadeira | C24: un | D24: =ROUNDUP(D14*1.5,0) -> 8 | E24: 200 | F24: =D24*E24 -> 1600
B25: Mesa | C25: un | D25: 1 | E25: 1000 | F25: =E25*D25 -> 1000
B26: Ar condicionado | C26: un | D26: 1 | E26: 5000 | F26: =E26*D26 -> 5000
B27: Armário | C27: m | D27: 4 | E27: 900 | F27: =E27*D27 -> 3600
B28: Escrivaninha | C28: un | D28: =D14 -> 5 | E28: 800 | F28: =E28*D28 -> 4000
B29: TOTAL | F29: =F26+F27+F28+F25+F24 -> 15200
B30: Descrição | C30: Unidade | D30: Quantidade | E30: Custo unitário | F30: Custo total
B31: Computador pessoal | C31: un | D31: 1 | E31: 6000 | F31: =D31*E31 -> 6000
B32: Impressora | C32: un | D32: 1 | E32: 2000 | F32: =E32*D32 -> 2000
B33: Roteador | C33: un | D33: 2 | E33: 500 | F33: =E33*D33 -> 1000
B34: TOTAL | F34: =+F31+F32+F33 -> 9000

Sheet BASES
A1: Estimativas
B3: Área de Terreno | C3: Área Construída | D3: N° pavimentos | G3: Parâmetros | H3: Área de Terreno | I3: Área Construída | J3: index
A4: =OBRA!B1 -> Viva Perequê Residencial | B4: =OBRA!D9 -> 600 | C4: =OBRA!D10 -> 5576.17 | D4: =OBRA!D13 -> 15 | G4: One Palace | H4: 0 | I4: 11653.22 | J4: 1.1207102 | K4: =C4/I4 -> 0.47850894
G5: Gran Torino | H5: 0 | I5: 12518.96 | J5: 1.0003264
G6: Marine | I6: 4498.68 | J6: =[4]ORÇAMENTO_EXECUTIVO!$B$20/[5]ORÇAMENTO_EXECUTIVO!$B$20 -> 1.0781743
G7: For Season | H7: 0 | I7: 6348.51 | J7: =[4]ORÇAMENTO_EXECUTIVO!$B$20/[6]Obra!$C$48 -> 1.0436493
G8: Mirador de alicante | H8: 0 | I8: 10661.12 | J8: 0
I10: =G4 -> One Palace | J10: =G4 -> One Palace | K10: =$G$5 -> Gran Torino | L10: =$G$5 -> Gran Torino | M10: =G8 -> Mirador de alicante | N10: =G8 -> Mirador de alicante | O10: =G6 -> Marine | P10: =G6 -> Marine | Q10: =G7 -> For Season | R10: =G7 -> For Season
A11: Descrição | F11: Unidade | G11: Quantidade | H11: Valor (R$) | I11: Valor | J11: Referencia | K11: Valor | L11: Referencia | M11: Valor | N11: Referencia | P11: Referencia | R11: Referencia
A12: ESTUDOS | H12: =$C$4*MEDIAN(P12,R12) -> 41032.304 | I12: 18555 | J12: =I12/$I$4 -> 1.5922638 | K12: 155511.79 | L12: =K12/$I$5 -> 12.422101 | M12: 14588.85 | N12: =M12/$I$8 -> 1.3684163 | O12: 40433.9 | P12: =O12/$I$6*$J$6 -> 9.6905742 | Q12: 30575.83 | R12: =Q12/$I$7*$J$7 -> 5.0264463
A13: PROJETOS | H13: =$C$4*MEDIAN(P13,R13) -> 233264.68 | I13: 303558.38 | J13: =I13/$I$4 -> 26.049313 | K13: 380354.48 | L13: =K13/$I$5 -> 30.382275 | M13: 559472 | N13: =M13/$I$8 -> 52.477788 | O13: 166779.75 | P13: =O13/$I$6*$J$6 -> 39.971201 | Q13: 265788.02 | R13: =Q13/$I$7*$J$7 -> 43.693637
A14: CONSULTORIAS | H14: =$C$4*MEDIAN(P14,R14) -> 95590.319 | I14: 176584.42 | J14: =I14/$I$4 -> 15.153273 | K14: 121532.68 | L14: =K14/$I$5 -> 9.7078895 | M14: 92050.41 | N14: =M14/$I$8 -> 8.6342157 | O14: 73726.05 | P14: =O14/$I$6*$J$6 -> 17.669524 | Q14: 101073.6 | R14: =Q14/$I$7*$J$7 -> 16.615772
A15: ENSAIOS E LAUDOS | H15: =$C$4*MEDIAN(P15,R15) -> 28743.232 | I15: 169172.85 | J15: =I15/$I$4 -> 14.517262 | K15: 146367.54 | L15: =K15/$I$5 -> 11.691669 | M15: 64357.54 | N15: =M15/$I$8 -> 6.0366584 | O15: 23350 | P15: =O15/$I$6*$J$6 -> 5.5961683 | Q15: 28670 | R15: =Q15/$I$7*$J$7 -> 4.7131415
A16: TAXAS | P16: =O16/$I$6*$J$6 -> 0 | R16: =Q16/$I$7*$J$7 -> 0
A17: Despesas de Seguros | F17: vb | H17: =$C$4*MEDIAN(P17,R17) -> 13876.595 | I17: 25000 | J17: =I17/$I$4 -> 2.1453298 | K17: 21531.34 | L17: =K17/$I$5 -> 1.7198985 | M17: 20000 | N17: =M17/$I$8 -> 1.8759755 | O17: 13004.64 | P17: =O17/$I$6*$J$6 -> 3.1167517 | Q17: 11316.52 | R17: =Q17/$I$7*$J$7 -> 1.8603544
A18: Licenciamentos, Taxas, Impostos | F18: vb | H18: =$C$4*MEDIAN(P18,R18) -> 80829.993 | I18: =163905-I17 -> 138905 | J18: =I18/$I$4 -> 11.919881 | K18: =97233.83-K17 -> 75702.49 | L18: =K18/$I$5 -> 6.0470271 | M18: =369811.66-M17 -> 349811.66 | N18: =M18/$I$8 -> 32.811905 | O18: 62028.71 | P18: =O18/$I$6*$J$6 -> 14.866086 | Q18: 85923.09 | R18: =Q18/$I$7*$J$7 -> 14.125137
A19: DOCUMENTOS | H19: =R19*$C$4 -> 49979.658 | I19: 0 | J19: =I19/$I$4 -> 0 | L19: =K19/$I$5 -> 0 | M19: 54564.35 | N19: =M19/$I$8 -> 5.1180692 | O19: 8250 | P19: =O19/$I$6*$J$6 -> 1.9772329 | Q19: 54522.34 | R19: =Q19/$I$7*$J$7 -> 8.9630801
A20: SEGURANÇA DO TRABALHO | P20: =O20/$I$6*$J$6 -> 0 | R20: =Q20/$I$7*$J$7 -> 0
A21: Serviço segurança do trabalho terceirizado | F21: mês | H21: 2500 | I21: 651.72 | J21: =I21/$I$4 -> 0.055926173 | K21: 1500 | L21: =K21/$I$5 -> 0.11981826 | M21: 3590.2439 | N21: =M21/$I$8 -> 0.33676048 | O21: 1000 | P21: =O21/$I$6*$J$6 -> 0.23966459 | Q21: 660 | R21: =Q21/$I$7*$J$7 -> 0.10849925
A22: Placas de Sinalização de Obra | F22: vb | H22: =R22*$C$4 -> 3361.8403 | I22: 6000 | J22: =I22/$I$4 -> 0.51487915 | K22: 2630 | L22: =K22/$I$5 -> 0.21008135 | M22: 2665.18 | N22: =M22/$I$8 -> 0.24999062 | P22: =O22/$I$6*$J$6 -> 0 | Q22: 3667.4 | R22: =Q22/$I$7*$J$7 -> 0.60289415
A23: MEIO AMBIENTE | SAÚDE OCUPACIONAL | H23: =P23*C4 -> 69760.629 | I23: 37750 | J23: =I23/$I$4 -> 3.239448 | K23: 0 | L23: =K23/$I$5 -> 0 | M23: 80563.98 | N23: =M23/$I$8 -> 7.5568027 | O23: 52200 | P23: =O23/$I$6*$J$6 -> 12.510492 | Q23: 162569.88 | R23: =Q23/$I$7*$J$7 -> 26.725318
A24: EQUIPE | P24: =O24/$I$6*$J$6 -> 0 | R24: =Q24/$I$7*$J$7 -> 0
A25: Engenheiro Civil | F25: mês | H25: 8000 | I25: 5000 | K25: 8000 | M25: 7000 | P25: =O25/$I$6*$J$6 -> 0 | R25: =Q25/$I$7*$J$7 -> 0
A26: Mestre Geral | F26: mês | H26: 6500 | M26: 6500 | P26: =O26/$I$6*$J$6 -> 0 | R26: =Q26/$I$7*$J$7 -> 0
A27: Almoxarife | F27: mês | H27: 3000 | I27: 3000 | K27: 2500 | M27: 3000 | P27: =O27/$I$6*$J$6 -> 0 | R27: =Q27/$I$7*$J$7 -> 0
A28: Auxiliar de Engenharia | F28: mês | H28: 2500 | I28: 3000 | K28: 5200 | P28: =O28/$I$6*$J$6 -> 0 | R28: =Q28/$I$7*$J$7 -> 0
A29: Estagiário de Engenharia | F29: mês | H29: 1500 | I29: 700 | K29: 2000 | P29: =O29/$I$6*$J$6 -> 0 | R29: =Q29/$I$7*$J$7 -> 0
A30: Operador de Guincho | F30: mês | H30: 4500 | K30: 3500 | M30: 3500 | P30: =O30/$I$6*$J$6 -> 0 | R30: =Q30/$I$7*$J$7 -> 0
A31: Equipe de apoio | F31: mês | H31: 10500 | K31: 10500 | M31: 21073.49 | P31: =O31/$I$6*$J$6 -> 0 | R31: =Q31/$I$7*$J$7 -> 0
A32: Serviço de vigilância | F32: vb | H32: 2500 | I32: 1700 | J32: =I32/$I$4 -> 0.14588243 | L32: =K32/$I$5 -> 0 | N32: =M32/$I$8 -> 0 | P32: =O32/$I$6*$J$6 -> 0 | R32: =Q32/$I$7*$J$7 -> 0
A33: CANTEIRO DE OBRA | P33: =O33/$I$6*$J$6 -> 0 | R33: =Q33/$I$7*$J$7 -> 0
A34: Limpeza da camada vegetal | F34: m2 | H34: =3.5*B4 -> 2100 | I34: 3.5 | J34: =I34/$I$4 -> 0.00030034617 | K34: 2808.43 | L34: =K34/$I$5 -> 0.22433413 | M34: 1782.45 | N34: =M34/$I$8 -> 0.16719163 | P34: =O34/$I$6*$J$6 -> 0 | R34: =Q34/$I$7*$J$7 -> 0
A35: Demolições | I35: 13820 | J35: =I35/$I$4 -> 1.1859383 | K35: 30701.25 | L35: =K35/$I$5 -> 2.4523802 | M35: 26145 | N35: =M35/$I$8 -> 2.452369 | P35: =O35/$I$6*$J$6 -> 0 | R35: =Q35/$I$7*$J$7 -> 0
A36: Locação da obra | F36: m | J36: =I36/$I$4 -> 0 | L36: =K36/$I$5 -> 0 | N36: =M36/$I$8 -> 0 | P36: =O36/$I$6*$J$6 -> 0 | R36: =Q36/$I$7*$J$7 -> 0
A37: Instalações Provisórias: Redes de Água Fria, Esgoto e Drenagem | F37: vb | H37: =$C$4*MEDIAN(P37,R37) -> 5904.7027 | I37: 11000 | J37: =I37/$I$4 -> 0.94394511 | K37: 15023.39 | L37: =K37/$I$5 -> 1.200051 | M37: 12793.88 | N37: =M37/$I$8 -> 1.2000503 | O37: 5400 | P37: =O37/$I$6*$J$6 -> 1.2941888 | Q37: 5010.23 | R37: =Q37/$I$7*$J$7 -> 0.82364573
A38: Instalações Provisórias: Redes Elétrica, Comunicação e Dados | F38: vb | H38: =$C$4*MEDIAN(P38,R38) -> 5665.2433 | I38: 15000 | J38: =I38/$I$4 -> 1.2871979 | K38: 13149.18 | L38: =K38/$I$5 -> 1.0503412 | M38: 11197.81 | N38: =M38/$I$8 -> 1.0503409 | O38: 4730 | P38: =O38/$I$6*$J$6 -> 1.1336135 | Q38: 5464.56 | R38: =Q38/$I$7*$J$7 -> 0.89833431
A39: Locação de banheiro químico | F39: mês | H39: =$C$4*MEDIAN(P39,R39) -> 0 | I39: 600 | J39: =I39/$I$4 -> 0.051487915 | K39: 900 | L39: =K39/$I$5 -> 0.071890956 | M39: 950 | N39: =M39/$I$8 -> 0.089108837 | P39: =O39/$I$6*$J$6 -> 0 | R39: =Q39/$I$7*$J$7 -> 0
A40: Galpão provisório | F40: vb | H40: =$C$4*MEDIAN(P40,R40) -> 112431.93 | I40: 20000 | J40: =I40/$I$4 -> 1.7162638 | K40: 70106.18 | L40: =K40/$I$5 -> 5.6000003 | M40: 142198.69 | N40: =M40/$I$8 -> 13.338063 | O40: 58511 | P40: =O40/$I$6*$J$6 -> 14.023015 | Q40: 160000 | R40: =Q40/$I$7*$J$7 -> 26.302848
A41: Despesas de Consumo e manutenção | F41: vb | H41: =$C$4*MEDIAN(P41,R41) -> 276101.51 | I41: 314850 | J41: =I41/$I$4 -> 27.018283 | K41: 277199.2 | L41: =K41/$I$5 -> 22.14235 | M41: 279687.37 | N41: =M41/$I$8 -> 26.234333 | O41: 250022.86 | P41: =O41/$I$6*$J$6 -> 59.921627 | Q41: 237890.34 | R41: =Q41/$I$7*$J$7 -> 39.107459

Sheet EPCs
A1: Obra | B1: =OBRA!B1 -> Viva Perequê Residencial
A2: Empresa | B2: =OBRA!B2 -> Ferazzo e Correa Incorporadora
A3: Revisão | B3: =OBRA!B3 -> R00
A4: LEVANTAMENTO QUANTITATIVO
A6: Equipamentos de proteção coletiva
A8: Bandejas de proteção
B10: Descrição | C10: Unidade | D10: Quantidade
B11: Perímetro de projeção embasamneto | C11: m | D11: =[7]DADOS_INICIAIS!$E$26 -> 93.06
B12: Perímetro de projeção torre | C12: m | D12: =[7]DADOS_INICIAIS!$E$20 -> 73.29
B13: Bandeja de proteção primária | C13: m | D13: =D11+(25-3.7)*2+(24-3.7*2) -> 152.26
B14: Bandeja de proteção secundária | C14: m | D14: =D12 -> 73.29
A16: Guarda - corpo de desforma
B18: Descrição | C18: Unidade | D18: Quantidade
B19: Perímetro de projeção da torre + vão do elevador | C19: m | D19: =D12+4.15 -> 77.44
B20: Repetições de pavimentos** | C20: un | D20: 4
B21: Proteção de periferia pós desforma torre | C21: m | D21: =(D19*D20) -> 309.76
A23: Tela fachadeira
B25: Descrição | C25: Unidade | D25: Quantidade
B26: Perimetro da torre | C26: m | D26: =D12 -> 73.29
B27: Altura da torre | C27: m | D27: =45.9-4.14 -> 41.76
B28: Tela fachadeira | C28: m2 | D28: =D26*D27 -> 3060.5904
A30: Fechamento removível de vãos em madeira
B32: Descrição | C32: Unidade | D32: Quantidade
B33: Área das portas de elevadores | C33: m2 | D33: =1*2.2 -> 2.2
B34: Quantidade de elevadores | C34: un | D34: 2
B35: Quantidade de portas de elevadores | C35: un | D35: =D34*OBRA!D13 -> 30
B36: Fechamento removível de vãos em madeira | C36: m2 | D36: =D33*D35 -> 66
A38: Tapume
B40: Descrição | C40: Unidade | D40: Quantidade
B41: Perímetro de encontro com pavimentação | C41: m | D41: 24
B42: Altura do tapume | C42: m | D42: 2.4
B43: Cobertura para proteção de pedestres | C43: m2 | D43: =D42*D41 -> 57.6

Sheet CUSTOS_INDIRETOS
A1: ORÇAMENTO PARAMÉTRICO - CUSTOS INDIRETOS
A7: Cliente | B7: =OBRA!B2 -> Ferazzo e Correa Incorporadora
A8: Obra | B8: =OBRA!B1 -> Viva Perequê Residencial
A9: Data | B9: 45741
A10: Versão | B10: =OBRA!B3 -> R00
A12: GERENCIAMENTO TÉCNICO
A13: Código | B13: Descrição | C13: Un. | D13: Quantidade orçada | E13: Preço unitário | F13: Preço total
A14: 01 | B14: GERENCIAMENTO TÉCNICO | F14: =F15+F20 -> 597648.46
A15: 01.001 | B15: ESTUDOS, PROJETOS E CONSULTORIAS | F15: =SUM(F16:F19) -> 438493.59
A16: 01.001.001 | B16: Estudos | F16: =BASES!H12*1.1 -> 45135.534
A17: 01.001.002 | B17: Projetos | F17: =BASES!H13*1.1 -> 256591.15
A18: 01.001.003 | B18: Consultorias | F18: =BASES!H14*1.1 -> 105149.35
A19: 01.001.004 | B19: Ensaios e Laudos | F19: =BASES!H15*1.1 -> 31617.555
A20: 01.002 | B20: TAXAS E DOCUMENTOS | F20: =SUM(F21:F23) -> 159154.87
A21: 01.002.001 | B21: Seguros | F21: =BASES!H17*1.1 -> 15264.254
A22: 01.002.002 | B22: Licenciamentos, Taxas, Impostos | F22: =BASES!H18*1.1 -> 88912.993
A23: 01.002.003 | B23: Documentos | F23: =BASES!H19*1.1 -> 54977.624
A24: 02 | B24: GERENCIAMENTO ADMINISTRATIVO | F24: =F25+F39+F58 -> 2256611.7
A25: 02.001 | B25: SEGURANÇA, MEIO AMBIENTE E SAÚDE | F25: =F26+F28+F38 -> 357994.3
A26: 02.001.001 | B26: Segurança do Trabalho | F26: =F27 -> 87500
A27: 02.001.001.001 | B27: Serviço de segurança do trabalho terceirizado | C27: mes | D27: =OBRA!D12 -> 35 | E27: =BASES!H21 -> 2500 | F27: =E27*D27 -> 87500
A28: 02.001.002 | B28: Equipamentos de proteção | F28: =SUM(F29:F37) -> 200733.67
A29: 02.001.002.001 | B29: Bandeja de proteção primária | C29: m | D29: =EPCs!D13 -> 152.26 | E29: 294.33 | F29: =E29*D29 -> 44814.686
A30: 02.001.002.002 | B30: Bandeja de proteção secundária | C30: m | D30: =EPCs!D14 -> 73.29 | E30: 210.06 | F30: =E30*D30 -> 15395.297
A31: 02.001.002.003 | B31: Guarda corpo em laje pós - desforma | C31: m | D31: =EPCs!D21 -> 309.76 | E31: 17.89 | F31: =E31*D31 -> 5541.6064
A32: 02.001.002.004 | B32: Fechamento removível de vãos de porta de elevador em madeira | C32: m2 | D32: =EPCs!D36 -> 66 | E32: 47.3 | F32: =E32*D32 -> 3121.8
A33: 02.001.002.005 | B33: Varal de segurança com cabo de aço | C33: m | D33: =D31 -> 309.76 | E33: 244 | F33: =E33*D33 -> 75581.44
A34: 02.001.002.006 | B34: Tela fachadeira reforçada com impressão digital | C34: m2 | D34: =EPCs!D28 -> 3060.5904 | E34: 8.5 | F34: =E34*D34 -> 26015.018
A35: 02.001.002.007 | B35: Sinalização com placa indicativa fixada na estrutura | C35: vb | D35: 1 | E35: =BASES!H22*1.1 -> 3698.0243 | F35: =E35*D35 -> 3698.0243
A36: 02.001.002.008 | B36: Equipamentos de proteção individual | C36: vb | D36: 1 | E36: =CANTEIRO!D18 -> 24500 | F36: =E36*D36 -> 24500
A37: 02.001.002.009 | B37: Gurada-corpo de vãos com régua de pinus 2,5x15cm | C37: m | D37: =[7]ESQUADRIAS!$D$14/1.1+[7]ESQUADRIAS!$D$15/1.1 -> 134.31727 | E37: 15.38 | F37: =E37*D37 -> 2065.7997
A38: 02.001.003 | B38: Meio Ambiente | F38: =BASES!H23 -> 69760.629
A39: 02.002 | B39: ADMINISTRAÇÃO E CANTEIRO DE OBRA | F39: =F40+F46+F48+F57 -> 1512161.4
A40: 02.002.001 | B40: Equipe de Gestão e Apoio | F40: =SUM(F41:F45) -> 992480
A41: 02.002.001.001 | B41: Engenheiro Civil | C41: mes | D41: =OBRA!$D$12 -> 35 | E41: 8500 | F41: =E41*D41 -> 297500
A42: 02.002.001.002 | B42: Mestre Geral | C42: mes | D42: =OBRA!$D$12 -> 35 | E42: 8000 | F42: =E42*D42 -> 280000
A43: 02.002.001.005 | B43: Estagiário de Engenharia | C43: mes | D43: =OBRA!$D$12 -> 35 | E43: 2200 | F43: =E43*D43 -> 77000
A44: 02.002.001.006 | B44: Operador de Guincho | C44: mes | D44: =D61 -> 15 | E44: =BASES!H30 -> 4500 | F44: =E44*D44 -> 67500
A45: 02.002.001.007 | B45: Equipe de apoio | C45: mes | D45: =OBRA!$D$12 -> 35 | E45: =2100*1.84*2 -> 7728 | F45: =E45*D45 -> 270480 | G45: 2 seventes (84% de encargos)
A46: 02.002.002 | B46: Operação Inicial do Canteiro | F46: =SUM(F47) -> 7500
...
