Workbook
Name \0: #REF!
Name \0: #REF!
Name \0: #REF!
Name \0: #REF!
Name \0: #REF!
Name \0: #REF!
Name \0: #REF!
Name \1: #REF!
Name \a: #REF!
Name \a: #REF!
Name \b: #REF!
Name \c: #REF!
Name \d: #REF!
Name \e: #REF!
Name \i: #REF!
Name \J: #REF!
Name \k: #REF!
Name \l: #N/A
Name \m: #REF!
Name \m: #REF!
Name \o: #REF!
Name \p: #REF!
Name \r: #REF!
Name \T: #REF!
Name \z: #REF!
Name ______ACR10: #REF!
Name ______ACR15: #REF!
Name ______acr20: #REF!
Name ______acr5: #REF!
Name ______ARQ1: #REF!
Name ______QT100: #REF!
Name ______QT2: #REF!
Name ______QT3: #REF!
Name ______QT4: #REF!
Name ______QT50: #REF!
Name ______QT75: #REF!
Name _____ACR10: #REF!
Name _____ACR15: #REF!
Name _____acr20: #REF!
Name _____acr5: #REF!
Name _____ARQ1: #REF!
Name _____QT100: #REF!
Name _____QT2: #REF!
Name _____QT3: #REF!
Name _____QT4: #REF!
Name _____QT50: #REF!
Name _____QT75: #REF!
Name ___ACR10: #REF!
Name ___ACR15: #REF!
Name ___acr20: #REF!
Name ___acr5: #REF!
Name ___ARQ1: #REF!
Name ___QT100: #REF!
Name ___QT2: #REF!
Name ___QT3: #REF!
Name ___QT4: #REF!
Name ___QT50: #REF!
Name ___QT75: #REF!
Name __ACR10: #REF!
Name __ACR15: #REF!

Sheet DADOS_INICIAIS
A1: Obra | B1: Viva Perequê Residencial
A2: Empresa | B2: Ferazzo e Correa Incorporadora
A3: Revisão | B3: R00
A4: Arquitetura base | B4: 01 - Implantação e Situação - R1
A5: DADOS OBRA
B7: Descrição | C7: Identificador | D7: Unidade | E7: Quantidade
B8: ÁREA DO TERRENO | C8: AT | D8: M2 | E8: 600
B9: ÁREA TOTAL CONSTRUÍDA | C9: AC | D9: M2 | E9: 5576.17
B10: UNIDADES RESIDENCIAIS | C10: UR | D10: UN | E10: =4*8+2+2 -> 36
B11: Dormitórios | C11: dorm | D11: UN
B12: Banheiros | C12: ban | D12: UN
B13: UNIDADES COMERCIAIS | C13: UC | D13: UN
B14: Churrasqueiras | C14: CHU | D14: UN | E14: ='SISTEMAS ESPECIAIS'!B10 -> 40
B15: NÚMERO TOTAL DE PAVIMENTOS | C15: NP | D15: UN | E15: 15
B16: NÚMERO DE PAVIMENTOS TIPO | C16: NPT | D16: UN | E16: 8
B17: NÚMERO DE PAVIMENTOS TIPO DIFERENCIADOS | C17: NPD | D17: UN | E17: 1
B18: NÚMERO DE PAVIMENTOS DUPLEX | C18: ND | D18: UN | E18: 0
B19: ÁREA DE PROJEÇÃO DA TORRE | C19: APT | D19: M2 | E19: 312.08
B20: PERÍMETRO DE PROJEÇÃO DA TORRE | C20: PPT | D20: M | E20: 73.29
B21: ÁREA DE LAZER | C21: AL | D21: M2 | E21: =537.71-107.3*2 -> 323.11
B22: ÁREA DO EMBASAMENTO | C22: AE | D22: M2 | E22: =502.69+537.71*3 -> 2115.82
B23: ÁREA DE SUBSOLOS | C23: S | D23: M2
B24: NÚMERO DE SUBSOLOS | C24: NS | D24: UN
B25: ÁREA DE PROJEÇÃO DO EMBASAMENTO | C25: APE | D25: M2 | E25: =537.71 -> 537.71
B26: PERÍMETRO DE PROJEÇÃO DE EMBAMENTO | C26: PE | D26: M | E26: 93.06
B27: NÚMERO DE PAVIMENTOS DE EMBASAMENTO | C27: NE | D27: UN | E27: 4
B29: ETAPA | C29: VALOR ORÇADO | D29: % | E29: VALOR / m²
B30: GERENCIAMENTO TÉCNICO E ADMINISTRATIVO | C30: =[4]CUSTOS_INDIRETOS!$F$71 -> 2854260.2 | D30: =C30/C$47 -> 0.12397491 | E30: =C30/$E$9 -> 511.86749
B31: MOVIMENTAÇÃO DE TERRA | C31: =MOVIMENTAÇÃO_DE_TERRA!F34 -> 67840.8 | D31: =C31/C$47 -> 0.0029466679 | E31: =C31/$E$9 -> 12.1662
B32: INFRAESTRUTURA | C32: =INFRAESTRUTURA!G35 -> 1034699.6 | D32: =C32/C$47 -> 0.044942219 | E32: =C32/$E$9 -> 185.5574
B33: SUPRAESTRUTURA | C33: =SUPRAESTRUTURA!G62 -> 4305290.3 | D33: =C33/C$47 -> 0.18700046 | E33: =C33/$E$9 -> 772.08735
B34: ALVENARIA | C34: =ALVENARIA!G32 -> 895755.06 | D34: =C34/C$47 -> 0.038907157 | E34: =C34/$E$9 -> 160.63984
B35: INSTALAÇÕES ELÉTRICAS, HIDRÁULICAS, GLP E PREVENTIVAS | C35: =INSTALAÇÕES!D35 -> 1887533.5 | D35: =C35/C$47 -> 0.081985097 | E35: =C35/$E$9 -> 338.5
B36: EQUIPAMENTOS E SISTEMAS ESPECIAIS | C36: ='SISTEMAS ESPECIAIS'!D43 -> 1161762.3 | D36: =C36/C$47 -> 0.050461193 | E36: =C36/$E$9 -> 208.34413
B37: IMPERMEABILIZAÇÃO | C37: =IMPERMEABILIZAÇÃO!G21 -> 295473.31 | D37: =C37/C$47 -> 0.012833895 | E37: =C37/$E$9 -> 52.988576
B38: REVESTIMENTOS INTERNOS EM PISO E PAREDE | C38: ='Rev. Internos Piso e Parede'!G28 -> 1007134.2 | D38: =C38/C$47 -> 0.043744915 | E38: =C38/$E$9 -> 180.61397
B39: REVESTIMENTOS E ACABAMENTOS INTERNOS EM TETO | C39: =TETO!G16 -> 412383.44 | D39: =C39/C$47 -> 0.017911892 | E39: =C39/$E$9 -> 73.954604
B40: ACABAMENTOS EM PISO E PAREDE | C40: ='Acabamentos de Piso e Parede'!G31 -> 1270508.2 | D40: =C40/C$47 -> 0.055184576 | E40: =C40/$E$9 -> 227.84603
B41: PINTURA INTERNA | C41: ='PINTURA INTERNA'!G19 -> 906892.25 | D41: =C41/C$47 -> 0.039390902 | E41: =C41/$E$9 -> 162.63712
B42: ESQUADRIAS, VIDROS E FERRAGENS | C42: =ESQUADRIAS!G25 -> 3267860 | D42: =C42/C$47 -> 0.14193963 | E42: =C42/$E$9 -> 586.04023
...

Sheet MOVIMENTAÇÃO_DE_TERRA
A2: MOVIMENTAÇÃO DE TERRA
A3: Data | B3: 45727
A4: Arquivo base | B4: -
A6: ESCAVAÇÃO VERTICAL DE SUBSOLO
A8: Descrição | B8: Área de subsolo (m2) | C8: Altura do subsolo (m) | D8: Volume total de escavação (m3) | E8: Preço unitário de escavação (R$ / m3) | F8: Valor total | G8: Observação
A9: Escavação | B9: 0 | C9: 6 | D9: =(C9*B9) -> 0 | E9: 2.66 | F9: =E9*D9*1.1 -> 0
A10: Movimentação de bota-fora | D10: =D9*1.3 -> 0 | E10: 45.45 | F10: =E10*D10*1.1 -> 0 | G10: 30% de empolamento
A11: TOTAL | F11: =SUM(F9:F10) -> 0
A13: REBAIXAMENTO DE LENÇOL FREÁTICO
A15: Descrição | B15: Quantidade (dias) | E15: Preço unitário de rebaixamento (R$ / dias) | F15: Valor total | G15: Observação
A16: Rebaixamento de lençol | B16: 0 | E16: 200 | F16: =B16*E16*1.1 -> 0 | G16: Sem rebaixamento
A17: TOTAL | F17: =SUM(F16:F16) -> 0
A19: ESCAVAÇÃO E REATERRO DE VALAS
A21: Descrição | B21: Parâmetro | D21: Volume total de escavação (m3) | E21: Preço unitário (R$ / m3) | F21: Valor total | G21: Observação
A22: Escavação mecanizada para blocos e baldrames | B22: 1.3 | C22: m³ / Vol infra | D22: =B22*INFRAESTRUTURA!D29 -> 314.56035 | E22: 36.36 | F22: =E22*D22*1.1 -> 12581.156
A23: Reaterro para blocos e baldrames | B23: 0.6 | C23: m³ / Vol Escavação | D23: =D22-INFRAESTRUTURA!D29 -> 72.59085 | E23: 14.55 | F23: =E23*D23*1.1 -> 1161.8166
A24: Movimentação de bota-fora | B24: 1.3 | D24: =(D22-D23)*B24 -> 314.56035 | E24: 45.45 | F24: =E24*D24*1.1 -> 15726.445
A25: Movimentação de terra das estacas | B25: 1 | C25: m³ | D25: =INFRAESTRUTURA!D19 -> 278.18803 | E25: 68.18 | F25: =E25*D25*1.1 -> 20863.546
A26: TOTAL | F26: =SUM(F22:F25) -> 50332.963
A28: REGULARIZAÇÃO E APILOAMENTO DE FUNDO DE VALAS
A30: Descrição | B30: Parâmetro | D30: Área de lastro (m²) | E30: Preço unitário (R$ / m2) | F30: Valor total | G30: Observação
A31: Lastro de concreto magto e=10cm | B31: 0.8 | C31: m² / APE | D31: =B31*DADOS_INICIAIS!E25 -> 430.168 | E31: =370*0.1 -> 37 | F31: =E31*D31*1.1 -> 17507.838 | H31: =F31/DADOS_INICIAIS!E25 -> 32.56
A32: TOTAL | F32: =SUM(F31:F31) -> 17507.838
A34: TOTAL MOVIMENTAÇÃO DE TERRA | F34: =F11+F17+F26+F32 -> 67840.8 | G34: =F34/DADOS_INICIAIS!E9 -> 12.1662
F35: =F34/DADOS_INICIAIS!E25 -> 126.16615

Sheet CONTENÇÕES
A3: CONTENÇÃO
A4: Data
A5: Arquivo base
A7: CORTINA DE ESTACAS
A9: Descrição | B9: Parâmetro | D9: Quantidade | F9: Preço unitário | G9: Valor total
A10: Número de Estacas | B10: 0.15 | C10: un / APE | D10: =B10*DADOS_INICIAIS!E25 -> 80.6565 | E10: un
A11: Estaca Hélice Continua Diâmetro 40 | B11: 0.1 | D11: =B11*$D$10 -> 8.06565 | E11: un
B12: 20 | C12: m/un | D12: =B12*D11 -> 161.313 | E12: m | G12: =F12*D12 -> 0
A13: Estaca Hélice Continua Diâmetro 50 | B13: 0.5 | D13: =B13*$D$10 -> 40.32825 | E13: un
B14: 20 | C14: m/un | D14: =B14*D13 -> 806.565 | E14: m | G14: =F14*D14 -> 0
A15: Estaca Hélice Continua Diâmetro 60 | B15: 0.4 | C15: un / APE | D15: =B15*$D$10 -> 32.2626 | E15: un
B16: 20 | C16: m/un | D16: =B16*D15 -> 645.252 | E16: m | G16: =F16*D16 -> 0
A17: Concreto | B17: =(PI()*0.4^2)/4*D14+(PI()*0.5^2)/4*D16+(PI()*0.6^2)/4*D12 -> 273.66106 | C17: un / APE | D17: =(PI()*0.4^2)/4*D14+(PI()*0.5^2)/4*D16+(PI()*0.6^2)/4*D12 -> 273.66106 | E17: m³ | G17: =F17*D17 -> 0
A18: Armação 6,3mm | B18: 1.6575131 | C18: kg / m³ | D18: =B18*D17 -> 453.59679 | E18: kg | G18: =F18*D18 -> 0
A19: Armação 16mm | B19: 10.178338 | C19: kg / m³ | D19: =B19*D17 -> 2785.4146 | E19: kg | G19: =F19*D19 -> 0
A20: Mobilização | B20: 1 | C20: vb | D20: 1 | E20: vb | G20: =F20*D20 -> 0
A21: TOTAL | G21: =SUM(G10:G20) -> 0
A23: PAREDE DE CONCRETO
A25: Descrição | B25: Parâmetro | D25: Quantidade | F25: Preço unitário | G25: Valor total
A26: Fabricação, montagem e desmontagem de forma para blocos e baldrames resinado | B26: 2.1 | C26: m² / APE | D26: =B26*DADOS_INICIAIS!E25 -> 1129.191 | E26: m² | G26: =F26*D26 -> 0
A27: Concreto | B27: 0.65 | C27: m³ / APE | D27: =B27*DADOS_INICIAIS!E25 -> 349.5115 | E27: m³ | G27: =F27*D27 -> 0
A28: Armação | B28: 110 | C28: kg / m³ | D28: =B28*D27 -> 38446.265 | E28: kg | G28: =F28*D28 -> 0
A29: Mão de obra | B29: =SUPRAESTRUTURA!B15*1.5 -> 360 | C29: R$ / APE | D29: =DADOS_INICIAIS!E25 -> 537.71 | E29: m² | F29: =B29 -> 360 | G29: =F29*D29 -> 193575.6
A30: TOTAL | G30: =SUM(G26:G29) -> 193575.6
A33: PAREDE DIAFRAGMA
A35: Descrição | B35: Parâmetro | D35: Quantidade | F35: Preço unitário | G35: Valor total
A36: Fabricação, montagem e desmontagem de forma para blocos e baldrames resinado | B36: 2.1 | C36: m² / APE | D36: =B36*DADOS_INICIAIS!E35 -> 710.85 | E36: m² | G36: =F36*D36 -> 0
A37: Concreto | B37: 0.65 | C37: m³ / APE | D37: =B37*DADOS_INICIAIS!E35 -> 220.025 | E37: m³ | G37: =F37*D37 -> 0
A38: Armação | B38: 110 | C38: kg / m³ | D38: =B38*D37 -> 24202.75 | E38: kg | G38: =F38*D38 -> 0
A39: Mão de obra | B39: =SUPRAESTRUTURA!B69*1.5 -> 0 | C39: R$ / APE | D39: =DADOS_INICIAIS!E35 -> 338.5 | E39: m² | F39: =B39 -> 0 | G39: =F39*D39 -> 0
A40: TOTAL | G40: =SUM(G36:G39) -> 0
A46: TOTAL INFRAESTRUTURA | G46: =G21+G30 -> 193575.6 | H46: =G46/DADOS_INICIAIS!E9 -> 34.714795

Sheet INFRAESTRUTURA
A3: INFRAESTRUTURA
A4: Data | B4: 45727
A5: Arquivo base | B5: -
A7: FUNDAÇÃO PROFUNDA
A9: Descrição | B9: Parâmetro | D9: Quantidade | F9: Preço unitário | G9: Valor total | H9: Observação
A10: Número de Estacas | B10: 0.12 | C10: un / APE | D10: =ROUNDUP(B10*DADOS_INICIAIS!$E$25,0) -> 65 | E10: un
A11: Estaca Hélice Continua Diâmetro 40 | B11: 0.2 | D11: =ROUNDUP(B11*$D$10,0) -> 13 | E11: un
B12: 22 | C12: m/un | D12: =B12*D11 -> 286 | E12: m | F12: 70 | G12: =F12*D12*1.1 -> 22022
A13: Estaca Hélice Continua Diâmetro 50 | B13: 0.7 | D13: =ROUNDUP(B13*D10,0) -> 46 | E13: un
B14: 22 | C14: m/un | D14: =B14*D13 -> 1012 | E14: m | F14: 90 | G14: =F14*D14*1.1 -> 100188
A15: Estaca Hélice Continua Diâmetro 60 | B15: 0.1 | C15: un / APE | D15: =ROUNDUP(B15*$D$10,0) -> 7 | E15: un
B16: 22 | C16: m/un | D16: =B16*D15 -> 154 | E16: m | F16: 105 | G16: =F16*D16*1.1 -> 17787
A17: Estaca Hélice Continua Diâmetro 80 | B17: 0 | C17: un / APE | D17: =ROUNDUP(B17*$D$10,0) -> 0 | E17: un
C18: m/un | D18: =B18*D17 -> 0 | E18: m | F18: 120 | G18: =F18*D18*1.1 -> 0
A19: Concreto (40 Mpa) | B19: 1.3 | C19: perda | D19: =(PI()*((0.4^2)/4)*D12+PI()*((0.5^2)/4)*D14+PI()*((0.6^2)/4)*D16) -> 278.18803 | E19: m³ | F19: =(535+45+(1.67*0.6))*B19 -> 755.3026 | G19: =F19*D19*1.1 -> 231127.76
A20: Armação | B20: 13 | C20: kg / m³ | D20: =B20*D19 -> 3616.4444 | E20: kg | F20: 7.62 | G20: =F20*D20*1.1 -> 30313.037
A21: Mobilização | B21: 1 | C21: vb | D21: 1 | E21: vb | F21: 15000 | G21: =F21*D21*1.1 -> 16500
A22: Apoio e arrasamento de estacas | D22: =D10 -> 65 | E22: un | F22: 300 | G22: =F22*D22*1 -> 19500
A23: TOTAL | G23: =SUM(G10:G22) -> 437437.79
G24: =G23/981.89 -> 445.5059
A25: FUNDAÇÃO RASA
A27: Descrição | B27: Parâmetro | D27: Quantidade | F27: Preço unitário | G27: Valor total | H27: Observação
A28: Fabricação, montagem e desmontagem de forma para blocos e baldrames resinado | B28: 0.98 | C28: m² / APE | D28: =B28*DADOS_INICIAIS!E25 -> 526.9558 | E28: m² | F28: 68 | G28: =F28*D28*1.1 -> 39416.294
A29: Concreto (40 Mpa) | B29: 0.45 | C29: m³ / APE | D29: =B29*DADOS_INICIAIS!E25 -> 241.9695 | E29: m³ | F29: =(535+45+(1.67*0.6))*1.05 -> 610.0521 | G29: =F29*D29*1.1 -> 162375.4
A30: Armação | B30: 90 | C30: kg / m³ | D30: =B30*D29 -> 21777.255 | E30: kg | F30: 7.62 | G30: =F30*D30*1.1 -> 182536.95
A31: Mão de obra | B31: =SUPRAESTRUTURA!B15*1.5 -> 360 | C31: R$ / APE | D31: =DADOS_INICIAIS!E25 -> 537.71 | E31: m² | F31: =B31 -> 360 | G31: =F31*D31*1.1 -> 212933.16
A32: TOTAL | G32: =SUM(G28:G31) -> 597261.81
A35: TOTAL INFRAESTRUTURA | G35: =G23+G32 -> 1034699.6 | H35: =G35/DADOS_INICIAIS!E9 -> 185.5574
H37: =H35/1.1 -> 168.68854
B38: concreto | C38: =0.1 -> 0.1 | D38: =C38*F29 -> 61.00521
B39: aço | C39: =C38*120 -> 12 | D39: =C39*F30 -> 91.44
B40: mo | C40: 1 | D40: =C40*20 -> 20

Sheet CONTENÇÃO
A3: INFRAESTRUTURA
A4: Data | B4: 45719
A5: Arquivo base | B5: -
A7: CORTINA DE ESTACAS
A9: Descrição | B9: Parâmetro | D9: Quantidade | F9: Preço unitário | G9: Valor total | H9: Observação
A10: Número de Estacas | E10: un | H10: Base obra Trindade Parkside
A11: Estaca Hélice Continua Diâmetro 40 | E11: un
E12: m | F12: 70 | G12: =F12*D12*1.1 -> 0
A13: Estaca Hélice Continua Diâmetro 50 | E13: un
E14: m | F14: 90 | G14: =F14*D14*1.1 -> 0
A15: Estaca Hélice Continua Diâmetro 60 | E15: un
E16: m | F16: 105 | G16: =F16*D16*1.1 -> 0
A17: Estaca Hélice Continua Diâmetro 80 | E17: un
E18: m | F18: 120 | G18: =F18*D18*1.1 -> 0
A19: Concreto (40 Mpa) | E19: m³ | F19: =535+45 -> 580 | G19: =F19*D19*B19*1.1 -> 0
A20: Armação | E20: kg | F20: 7.62 | G20: =F20*D20*1.1 -> 0
A21: Mobilização | E21: vb | F21: 12500 | G21: =F21*D21*1.1 -> 0
A22: Apoio e arrasamento de estacas | E22: un | F22: 300 | G22: =F22*D22*1 -> 0
A23: TOTAL | G23: =SUM(G10:G22) -> 0
A25: PAREDE DE CONCRETO
A27: Descrição | B27: Parâmetro | D27: Quantidade | F27: Preço unitário | G27: Valor total | H27: Observação
A28: Comprimento do muro | D28: =DADOS_INICIAIS!E26 -> 93.06 | E28: m | H28: =D28*D29 -> 837.54
A29: Altura do muro | D29: =6+3 -> 9 | E29: m
A30: Execução de mureta guia | D30: =D28 -> 93.06 | E30: m | F30: 710 | G30: =F30*D30*1.1 -> 72679.86
A31: Serviço especializado parede diafragma | D31: =D28*D29 -> 837.54 | E31: m² | F31: 270 | G31: =F31*D31 -> 226135.8
A32: Mobilização para parede diagragma | D32: 1 | E32: vb | F32: 18000 | G32: =F32 -> 18000
A33: Armação | B33: 112 | C33: kg / m³ | D33: =B33*D34 -> 28141.344 | E33: kg | F33: 7.62 | G33: =F33*D33 -> 214437.04
A34: Concreto (30 Mpa) COM CRISTALIZANTE | B34: 0.3 | C34: espessura | D34: =B34*D29*D28 -> 251.262 | E34: m³ | F34: =(535*1.22+45+(1.67*0.6))*1.05 -> 733.6371 | G34: =F34*D34*1.05 -> 193551.88
A35: Tratamento em juntas de concretagem com fita hidroexpansiva | D35: =ROUNDUP(D28/1.25,0)*6 -> 450 | E35: m | F35: 41.5 | G35: =F35*D35*1.1 -> 20542.5
A36: TOTAL | G36: =SUM(G28:G35) -> 745347.08
A39: TOTAL CONTENÇÃO | G39: =G23+G36 -> 745347.08 | H39: =G39/DADOS_INICIAIS!E9 -> 133.66649
H41: =H39/1.1 -> 121.51499

Sheet SUPRAESTRUTURA
A3: SUPRAESTRUTURA
A4: Data | B4: 45472
A5: Arquivo base | B5: -
A7: SUPRAESTRUTURA - LAJE MACIÇA
A9: Descrição | B9: Parâmetro | D9: Quantidade | F9: Preço unitário | G9: Valor total | H9: Observação
A10: Fabricação forma | B10: 3 | C10: Jogos | D10: =(D11/DADOS_INICIAIS!$E$15)*B10 -> 2788.085 | E10: m² | F10: 110 | G10: =F10*D10*1.1 -> 337358.28
A11: Montagem de forma | B11: 2.5 | C11: m² / AC | D11: =B11*DADOS_INICIAIS!$E$9 -> 13940.425 | E11: m² | F11: 2.5 | G11: =F11*D11*1.1 -> 38336.169
A12: Escoramento | B12: 4 | C12: un / AE | D12: =ROUNDUP(B12*DADOS_INICIAIS!$E$25*B10,0) -> 6453 | E12: un | F12: =17 -> 17 | G12: =F12*D12*1.1 -> 120671.1
A13: Concreto | B13: 0.22 | C13: m³ / AC | D13: =B13*DADOS_INICIAIS!$E$9 -> 1226.7574 | E13: m³ | F13: =(535+45+(1.67*0.6))*1.05 -> 610.0521 | G13: =F13*D13*1.05*1.1 -> 864385.75
A14: Armadura Convencional para Estrutura | B14: 110 | C14: kg / m³ | D14: =D13*B14 -> 134943.31 | E14: kg | F14: 7.62 | G14: =F14*D14*1.1 -> 1131094.9
A15: Mão de obra - estrutura em concreto armado | B15: 240 | C15: R$ / AC | D15: =DADOS_INICIAIS!$E$9 -> 5576.17 | E15: m² | F15: =B15 -> 240 | G15: =F15*D15*1.1 -> 1472108.9
A16: Perfuração de vigas | B16: 5300 | C16: R$ / NP | D16: 1 | E16: vb | F16: =B16*DADOS_INICIAIS!$E$15 -> 79500 | G16: =F16*D16*1.1 -> 87450 | H16: Coeficiente originário do Gran Torino (R$ 160,00/un) | I16: Nova utiliza a verba de 1.500,00 por pav
A17: TOTAL | G17: =SUM(G10:G16) -> 4051405 | K17: =4160+1440+1120+2880+4800+91680+4000 -> 110080 | L17: =K17/21 -> 5241.9048
A19: SUPRAESTRUTURA - LAJE CUBETAS
A21: Descrição | B21: Parâmetro | D21: Quantidade | F21: Preço unitário | G21: Valor total | H21: Observação
A22: Fabricação forma | B22: 3 | C22: Jogos | D22: =(D23/DADOS_INICIAIS!$E$15)*B22 -> 2341.9914 | E22: m² | F22: 110 | G22: =F22*D22*1.1 -> 283380.96
A23: Montagem de forma | B23: 2.1 | C23: m² / AC | D23: =B23*DADOS_INICIAIS!$E$9 -> 11709.957 | E23: m² | F23: 2.5 | G23: =F23*D23*1.1 -> 32202.382
A24: Locação de escoramento metálico | C24: um/m² | D24: 13 | E24: mês | F24: =18300*0.8 -> 14640 | G24: =F24*D24*1.1 -> 209352 | H24: =G24/DADOS_INICIAIS!E9 -> 37.544049
A25: Cubetas | D25: 13 | E25: mês | F25: =H25*0.38*30 -> 10681.8 | G25: =F25*D25*1.1 -> 152749.74 | H25: =ROUNDUP(DADOS_INICIAIS!E19*B22,0) -> 937 | I25: =F25/DADOS_INICIAIS!E9 -> 1.9156159
A26: Concreto | B26: 0.28 | C26: m³ / AC | D26: =B26*DADOS_INICIAIS!$E$9 -> 1561.3276 | E26: m³ | F26: =(535+45+(1.67*0.6))*1.05 -> 610.0521 | G26: =F26*D26*1.1 -> 1047740.3 | H26: Indice Atlantia
A27: Armadura Convencional para Estrutura | B27: 75 | C27: kg / m³ | D27: =D26*B27 -> 117099.57 | E27: kg | F27: 5.95 | G27: =F27*D27*1.1 -> 766416.69 | H27: Indice Atlantia
A28: Mão de obra - estrutura em concreto armado | C28: R$ / AC | D28: =DADOS_INICIAIS!$E$9 -> 5576.17 | E28: m² | F28: 290 | G28: =F28*D28*1.1 -> 1778798.2
A29: Perfuração de vigas | B29: 2100 | C29: R$ / NP | D29: 1 | E29: vb | F29: =B29*DADOS_INICIAIS!$E$15 -> 31500 | G29: =F29*D29*1.1 -> 34650 | H29: Coeficiente originário do Gran Torino (R$ 160,00/un)
A30: TOTAL | G30: =SUM(G22:G29) -> 4305290.3
A32: SUPRAESTRUTURA - LAJE TRELIÇADA
A34: Descrição | B34: Parâmetro | D34: Quantidade | F34: Preço unitário | G34: Valor total | H34: Observação
A35: Fabricação forma | B35: 2 | C35: Jogos | D35: =(D36/DADOS_INICIAIS!$E$15)*B35 -> 50.571911 | E35: m² | F35: 85 | G35: =F35*D35*1.1 -> 4728.4737
A36: Montagem de forma | B36: 2.1 | C36: m² / AC | D36: =B36*DADOS_INICIAIS!E38 -> 379.28933 | E36: m² | F36: 1.5 | G36: =F36*D36*1.1 -> 625.8274
A37: Escoramento - Torre | B37: 2 | C37: un / APT*NPT | D37: =B37*DADOS_INICIAIS!E44*DADOS_INICIAIS!E42 -> 327518.37 | E37: un | F37: 17 | G37: =F37*D37*1.1 -> 6124593.5
A38: Escoramento - Embasamento | B38: 2 | C38: un / AE | D38: =B38*DADOS_INICIAIS!E46 -> 210.69505 | E38: un | F38: 17 | G38: =F38*D38*1.1 -> 3939.9974
A39: Cubetas | B39: 25 | C39: R$ / AC | D39: =B39*DADOS_INICIAIS!E38 -> 4515.3492 | E39: m³ | F39: =B39 -> 25 | G39: =F39*D39*1.1 -> 124172.1
A40: Concreto | B40: 0.25 | C40: m³ / AC | D40: =B40*DADOS_INICIAIS!E38 -> 45.153492 | E40: m³ | F40: =575 -> 575 | G40: =F40*D40*1.05*1.1 -> 29987.563
A41: Armadura Convencional para Estrutura | B41: 110 | C41: kg / m³ | D41: =D40*B41 -> 4966.8841 | E41: kg | F41: 7.25 | G41: =F41*D41*1.1 -> 39610.901
A42: Mão de obra - estrutura em concreto armado | B42: 240 | C42: R$ / AC | D42: =DADOS_INICIAIS!E38 -> 180.61397 | E42: m² | F42: =B42 -> 240 | G42: =F42*D42*1.1 -> 47682.088
A43: Perfuração de vigas | B43: 5300 | C43: R$ / NP | D43: 1 | E43: vb | F43: =B43*DADOS_INICIAIS!E41 -> 861976.75 | G43: =F43*D43*1.1 -> 948174.43 | H43: Coeficiente originário do Gran Torino (R$ 160,00/un)
A44: TOTAL | G44: =SUM(G35:G43) -> 7323514.8
A46: SUPRAESTRUTURA - LAJE PROTENDIDA
A48: Descrição | B48: Parâmetro | D48: Quantidade | F48: Preço unitário | G48: Valor total | H48: Observação
A49: Fabricação forma | B49: 3 | C49: Jogos | D49: =(D50/DADOS_INICIAIS!$E$15)*B49 -> 2341.9914 | E49: m² | F49: 110 | G49: =F49*D49*1.1 -> 283380.96
A50: Montagem de forma | B50: 2.1 | C50: m² / AC | D50: =B50*DADOS_INICIAIS!$E$9 -> 11709.957 | E50: m² | F50: 2.5 | G50: =F50*D50*1.1 -> 32202.382
...

Sheet ALVENARIA
A3: PAREDES E PAINÉIS
A4: Data | B4: 45469
A5: Arquivo base | B5: -
A7: ALVENARIA
A9: Descrição | B9: Parâmetro | D9: Quantidade | F9: Preço unitário | G9: Valor total | H9: Observação
A10: Alvenaria | B10: 1.2 | C10: m² / AC | D10: =B10*DADOS_INICIAIS!$E$9 -> 6691.404 | E10: m² | F10: 45 | G10: =F10*D10*1.1 -> 331224.5 | I10: =(D10+#REF!+#REF!+#REF!+#REF!)/DADOS_INICIAIS!E9 -> #REF!
A11: Alvenaria silico calcario | B11: 0.2 | C11: m² / AC | D11: =B11*DADOS_INICIAIS!$E$9 -> 1115.234 | E11: m² | F11: 70 | G11: =F11*D11*1.1 -> 85873.018 | I11: =(D11+#REF!+#REF!+#REF!+#REF!)/DADOS_INICIAIS!E10 -> #REF!
A12: Alvenaria refratárias | B12: 1.75 | C12: m² * CHU | D12: =B12*DADOS_INICIAIS!$E$14 -> 70 | E12: m² | F12: 210 | G12: =F12*D12*1.1 -> 16170
A13: Serviços complementares | B13: 12.5 | C13: R$ / m² | D13: =D10 -> 6691.404 | E13: m² | F13: 22 | G13: =F13*D13*1.1 -> 161931.98
A14: Mão de obra | B14: 35 | C14: R$ / m² | D14: =D10+D11 -> 7806.638 | E14: m² | F14: 35 | G14: =F14*D14*1.1 -> 300555.56
A15: TOTAL | G15: =SUM(G10:G14) -> 895755.06 | K15: =4160+1440+1120+2880+4800+91680+4000 -> 110080 | L15: =K15/21 -> 5241.9048
A17: ALVENARIA - DRYWALL | G17: =G14/D14 -> 38.5
A19: Descrição | B19: Parâmetro | D19: Quantidade | F19: Preço unitário | G19: Valor total | H19: Observação
A20: Alvenaria embasamento | B20: 1 | C20: m² / AE | D20: =B20*DADOS_INICIAIS!$E$22 -> 2115.82 | E20: m² | F20: 45 | G20: =F20*D20*1.1 -> 104733.09
A21: Alvenaria lazer | B21: 0.4 | C21: m² / AL | D21: =B21*DADOS_INICIAIS!$E$21 -> 129.244 | E21: m² | F21: 45 | G21: =F21*D21*1.1 -> 6397.578
A22: Alvenaria tipo | B22: 1.65 | C22: m² / APT*(NPT+2ND) | D22: =B22*(DADOS_INICIAIS!$E$19*(DADOS_INICIAIS!$E$16+DADOS_INICIAIS!$E$17))*0.4 -> 1853.7552 | E22: m² | F22: 45 | G22: =F22*D22*1.1 -> 91760.882
A23: Drywall tipo | B23: 1.65 | C23: m² / APT*(NPT+2ND) | D23: =B23*(DADOS_INICIAIS!$E$19*(DADOS_INICIAIS!$E$16+DADOS_INICIAIS!$E$17))*0.6 -> 2780.6328 | E23: m² | F23: 220 | G23: =F23*D23*1.1 -> 672913.14 | J23: =D23/(D27+D23) -> 0.33727738
A24: Alvenaria escadas | B24: 0.2 | C24: m² / AC | D24: =B24*DADOS_INICIAIS!$E$9 -> 1115.234 | E24: m² | F24: 70 | G24: =F24*D24*1.1 -> 85873.018 | J24: =1-J23 -> 0.66272262
A25: Alvenaria cobertura / reservatório | B25: 0.8 | C25: m² / APT | D25: =B25*DADOS_INICIAIS!$E$19 -> 249.664 | E25: m³ | F25: 45 | G25: =F25*D25*1.1 -> 12358.368
A26: Alvenaria refratárias | B26: 1.75 | C26: m² * CHU | D26: ='SISTEMAS ESPECIAIS'!B10 -> 40 | E26: un | F26: 210 | G26: =F26*D26*1.1 -> 9240
A27: Serviços complementares | B27: 12.5 | C27: R$ / m² | D27: =D21+D22+D20+D24+D25 -> 5463.7172 | E27: m² | F27: =B27 -> 12.5 | G27: =F27*D27*1.1 -> 75126.111
A28: Mão de obra | B28: 35 | C28: R$ / m² | D28: =D21+D22+D20+D24+D25 -> 5463.7172 | E28: m² | F28: 35 | G28: =F28*D28*1.1 -> 210353.11
A29: TOTAL | G29: =SUM(G20:G28) -> 1268755.3
A32: TOTAL ALVENARIA | G32: =G15 -> 895755.06 | H32: =G32/DADOS_INICIAIS!E9 -> 160.63984
C35: =24000/(568+874+1996+1144) -> 5.2378874 | G35: =G32/1.1 -> 814322.78 | H35: =G35/DADOS_INICIAIS!E9 -> 146.03622

Sheet INSTALAÇÕES
A2: INSTALAÇÕES
A4: INSTALAÇÕES ELÉTRICAS
A6: Descrição | B6: Parâmetro | D6: Valor total
A7: Entrada de Energia | B7: 5 | C7: R$ / AC | D7: =B7*DADOS_INICIAIS!$E$9 -> 27880.85
A8: Eletrodutos e Eletrocalhas | B8: 12 | C8: R$ / AC | D8: =B8*DADOS_INICIAIS!$E$9 -> 66914.04
A9: Cabos e Fiações | B9: 25 | C9: R$ / AC | D9: =B9*DADOS_INICIAIS!$E$9 -> 139404.25
A10: Quadros e Disjuntores | B10: 12 | C10: R$ / AC | D10: =B10*DADOS_INICIAIS!$E$9 -> 66914.04
A11: Acabamentos Elétricos | B11: 10 | C11: R$ / AC | D11: =B11*DADOS_INICIAIS!$E$9 -> 55761.7
A12: Equipamentos e Iluminação | B12: 5 | C12: R$ / AC | D12: =B12*DADOS_INICIAIS!$E$9 -> 27880.85
A13: Mão de Obra para Instalações Elétricas | B13: 70 | C13: R$ / AC | D13: =B13*DADOS_INICIAIS!$E$9 -> 390331.9 | E13: =D13/DADOS_INICIAIS!$E$9 -> 70
A14: TOTAL | D14: =SUM(D7:D13) -> 775087.63
A16: INSTALAÇÕES HIDROSSANITÁRIAS
A18: Descrição | B18: Parâmetro | D18: Valor total
A19: Instalações de Água Fria | B19: 20 | C19: R$ / AC | D19: =B19*DADOS_INICIAIS!$E$9 -> 111523.4
A20: Instalações de Água Quente | B20: 15 | C20: R$ / AC | D20: =B20*DADOS_INICIAIS!$E$9 -> 83642.55
A21: Instalações de Águas Pluviais | B21: 12 | C21: R$ / AC | D21: =B21*DADOS_INICIAIS!$E$9 -> 66914.04
A22: Instalações Sanitárias | B22: 16 | C22: R$ / AC | D22: =B22*DADOS_INICIAIS!$E$9 -> 89218.72
A23: Louças e Metais | B23: 45 | C23: R$ / AC | D23: =B23*DADOS_INICIAIS!$E$9 -> 250927.65
A24: Mão de Obra para Instalações Hidráulicas | B24: 55 | C24: R$ / AC | D24: =B24*DADOS_INICIAIS!$E$9 -> 306689.35 | E24: =D24/DADOS_INICIAIS!$E$9 -> 55
A25: TOTAL | D25: =SUM(D19:D24) -> 908915.71
A27: INSTALAÇÕES PREVENTIVAS E GLP
A29: Descrição | B29: Parâmetro | D29: Valor total
A30: Instalações Preventivas | B30: 15 | C30: R$ / AC | D30: =B30*DADOS_INICIAIS!$E$9 -> 83642.55
A31: Instalações de GLP | B31: 15 | C31: R$ / AC | D31: =B31*DADOS_INICIAIS!$E$9 -> 83642.55
A32: Instalações de Proteção e Aterramento - SPDA | B32: 6.5 | C32: R$ / AC | D32: =B32*DADOS_INICIAIS!$E$9 -> 36245.105
A33: TOTAL | D33: =SUM(D30:D32) -> 203530.21
A35: TOTAL INSTALAÇÕES | D35: =D14+D25+D33 -> 1887533.5 | E35: =D35/DADOS_INICIAIS!E9 -> 338.5
E37: =E35/1.1 -> 307.72727

Sheet SISTEMAS ESPECIAIS
A2: SISTEMAS ESPECIAIS
A4: CLIMATIZAÇÃO, EXAUSTÃO MECÂNICA E PRESSURIZAÇÃO
A6: Descrição | B6: Quantidade | C6: Preço Unitário | D6: Valor total | G6: TERREO | H6: LAZER | I6: TIPO 8 | J6: TIPO 1 | K6: COBERTURA
A7: Infraestrutura para Instalação de Ar Condicionado | B7: =SUM(G7:M7) -> 121 | C7: 1200 | D7: =B7*C7*1.1 -> 159720 | G7: =3*2+2 -> 8 | H7: =4+3*2 -> 10 | I7: =(3*2+3*2)*8 -> 96 | J7: =3+4 -> 7
A8: Instalação de Ar Condicionado | B8: =SUM(G8:M8) -> 6 | C8: 5000 | D8: =B8*C8*1.1 -> 33000 | G8: 2 | H8: =4 -> 4 | I8: 0 | J8: 0
A9: Ventokit | B9: =SUM(G9:M9) -> 24 | C9: 900 | D9: =B9*C9*1.1 -> 23760 | G9: 4 | H9: =1+1*2 -> 3 | I9: =1*2*8 -> 16 | J9: 1
A10: Churrasqueiras | B10: =SUM(G10:M10) -> 40 | C10: 3500 | D10: =B10*C10*1.1 -> 154000 | G10: 0 | H10: =2+2*2 -> 6 | I10: =4*8 -> 32 | J10: =2 -> 2
A11: Pressurização de escada | B11: =DADOS_INICIAIS!E9 -> 5576.17 | C11: 11
A12: TOTAL | D12: =SUM(D7:D11) -> 370480
A14: COMUNICAÇÃO
A16: Descrição | B16: Parâmetro | D16: Valor total
A17: CFTV | B17: 2 | C17: R$ / AC | D17: =B17*DADOS_INICIAIS!$E$9*1.05 -> 11709.957
A18: Interfone | B18: 4 | C18: R$ / AC | D18: =B18*DADOS_INICIAIS!$E$9*1.05 -> 23419.914
A19: TV e internet | B19: 6 | C19: R$ / AC | D19: =B19*DADOS_INICIAIS!$E$9*1.05 -> 35129.871
A20: Automação, telecomunicação e sistemas de segurança | B20: 5.5 | C20: R$ / AC
A21: TOTAL | D21: =SUM(D17:D20) -> 70259.742
A23: EQUIPAMENTOS
A25: Descrição | B25: Quantidade | C25: Preço Unitário | D25: Valor total
A26: Elevadores | B26: 2 | C26: =17750*DADOS_INICIAIS!E15 -> 266250 | D26: =B26*C26*1.1 -> 585750
A27: Plataforma elevatória | C27: 42750 | D27: =B27*C27*1.1 -> 0 | E27: inox
A28: Grupo de geradores | B28: 1 | C28: 19800 | D28: =B28*C28*1.05 -> 20790
A29: Bombas | B29: 1 | D29: =B29*C29*1.1 -> 0
A30: Infra de carro elétrico | B30: 1 | C30: 590 | D30: =B30*C30 -> 590 | E30: vaga pne
A31: Equipamento de piscina | B31: 1 | C31: 27500 | D31: =B31*C31*1.1 -> 30250
A32: Equipamento de sauna | B32: 1 | C32: 7980
A33: Equipamento de spa | B33: 2 | C33: =19700/2 -> 9850
A34: Sistema de placas solares | C34: 1150 | D34: =B34*C34*1.1 -> 0
A35: TOTAL | D35: =SUM(D26:D34) -> 637380
A37: OUTROS SISTEMAS ESPECIAIS
A39: Descrição | B39: Parâmetro | D39: Valor total
A40: Outros sistemas | B40: 15 | C40: R$ / AC | D40: =B40*DADOS_INICIAIS!E9 -> 83642.55
A41: TOTAL | D41: =SUM(D40:D40) -> 83642.55
A43: TOTAL SISTEMAS ESPECIAIS | D43: =D12+D21+D35+D41 -> 1161762.3 | E43: =D43/DADOS_INICIAIS!E9 -> 208.34413

Sheet IMPERMEABILIZAÇÃO
A3: IMPERMEABILIZAÇÃO
A4: Data | B4: 45471
A5: Arquivo base | B5: -
A7: IMPERMEABILIZAÇÃO
A9: Descrição | B9: Parâmetro | D9: Quantidade | F9: Preço unitário | G9: Valor total | H9: Observação
A10: Regularização de Superfície | B10: 25 | C10: R$ / m² | D10: =D15+D16+D17 -> 1999.1982 | E10: m² | F10: =5+20 -> 25 | G10: =F10*D10*1.1 -> 54977.95
A11: Proteção Mecânica | B11: 28 | C11: R$ / m² | D11: =D17+D16 -> 326.3472 | E11: m² | F11: 28 | G11: =F11*D11*1.1 -> 10051.494
A12: Poço do elevador | B12: 45 | C12: R$ / m² | D12: =(1.8*1.8*2)+(1.8*4)*1.8*2 -> 32.4 | E12: m² | F12: 41 | G12: =F12*D12*1.1 -> 1461.24
A13: Baldrames | B13: 30 | C13: R$ / m² | D13: =INFRAESTRUTURA!D28 -> 526.9558 | E13: m² | F13: 45 | G13: =F13*D13*1.1 -> 26084.312
A14: Ralos | B14: 2 | C14: R$ / AC | D14: 1 | E14: vb | F14: =B14*DADOS_INICIAIS!$E$9 -> 11152.34 | G14: =F14*D14*1.1 -> 12267.574 | H14: =G14/I14 -> #DIV/0!
A15: Impermeabilizações cimenticias | B15: 0.3 | C15: m² / AC | D15: =B15*DADOS_INICIAIS!E9 -> 1672.851 | E15: m² | F15: =40+30 -> 70 | G15: =F15*D15*1.1 -> 128809.53
A16: Impermeabilizações com manta asfaltica | B16: =D16/DADOS_INICIAIS!E9 -> 0.049558604 | C16: m² / AC | D16: ='PISO E TETO'!I64+'PISO E TETO'!I38+'PISO E TETO'!I41+'PISO E TETO'!I42+'PISO E TETO'!I43 -> 276.3472 | E16: m² | F16: 150 | G16: =F16*D16*1.1 -> 45597.288 | H16: Terraços e áreas externas
A17: Impermeabilizações com manta asfalticafloreiras | C17: m² / AC | D17: 50 | E17: m² | F17: 150 | G17: =F17*D17*1.1 -> 8250
A18: Impermeabilização de peitoril | B18: 1.3 | C18: R$ / AC | D18: 1 | E18: vb | F18: =B18*DADOS_INICIAIS!$E$9 -> 7249.021 | G18: =F18*D18*1.1 -> 7973.9231 | H18: =G18/I18 -> #DIV/0!
A19: TOTAL | G19: =SUM(G10:G18) -> 295473.31 | K19: =4160+1440+1120+2880+4800+91680+4000 -> 110080 | L19: =K19/21 -> 5241.9048
A21: TOTAL IMPERMEABILIZAÇÃO | G21: =G19 -> 295473.31 | H21: =G21/DADOS_INICIAIS!E9 -> 52.988576
H24: =H21/1.1 -> 48.171433
C25: =3.36*(141*2+10) -> 981.12 | E25: =((3.03+4.23+2.8)*2+(3.15+3.06+3.75)*2)*8+(4.1+1.05+2+4.4+17.13+22.88+3.25+4.25+4.1)+(3.42+3.84+3.25)*2 -> 404.5
C26: =1.5*2.1*(141*2+10) -> 919.8 | E26: =E25*1.3 -> 525.85
C27: =C25+C26 -> 1900.92 | D27: só banheiro
C28: =4*1.5*56 -> 336 | D28: cozinha
A31: IMPERMEABILIZAÇÃO
A33: Descrição | B33: Parâmetro | D33: Quantidade | F33: Preço unitário | G33: Valor total | H33: Observação
A34: Regularização de Superfície | B34: 25 | C34: R$ / m² | D34: 6235.376 | E34: m² | F34: =5+20 -> 25 | G34: =F34*D34*1.1 -> 171472.84
A35: Poço do elevador | B35: 45 | C35: R$ / m² | D35: 37.806 | E35: m² | F35: =41 -> 41 | G35: =F35*D35*1.1 -> 1705.0506
A36: Baldrames | B36: 30 | C36: R$ / m² | D36: 1131.0624 | E36: m² | F36: =15+38 -> 53 | G36: =F36*D36*1.1 -> 65940.938
A37: Ralos | B37: 1 | C37: R$ / AC | D37: 1 | E37: vb | F37: =B37*DADOS_INICIAIS!$E$9 -> 5576.17 | G37: =F37*D37*1.1 -> 6133.787 | H37: =G37/I37 -> #DIV/0!
A38: Impermeabilizações cimenticias | B38: 0.3 | C38: m² / AC | D38: 3944.334 | E38: m² | F38: =40+30 -> 70 | G38: =F38*D38*1.1 -> 303713.72
A39: Impermeabilizações com manta asfaltica | B39: =D39/DADOS_INICIAIS!E33 -> 2.9673353 | C39: m² / AC | D39: 2291.042 | E39: m² | F39: =50+48 -> 98 | G39: =F39*D39*1.1 -> 246974.33
A40: Impermeabilizações com manta asfalticafloreiras | C40: m² / AC | E40: m² | F40: =50+48 -> 98 | G40: =F40*D40*1.1 -> 0
A41: Impermeabilização de peitoril | B41: 1.2 | C41: R$ / AC | D41: 1 | E41: vb | F41: =B41*DADOS_INICIAIS!$E$9 -> 6691.404 | G41: =F41*D41*1.1 -> 7360.5444 | H41: =G41/I41 -> #DIV/0!
A42: Proteção Mecânica | B42: 28 | C42: R$ / m² | D42: 2291.042 | E42: m² | F42: =35+22 -> 57 | G42: =F42*D42*1.1 -> 143648.33
A43: TOTAL | G43: =SUM(G34:G42) -> 946949.54 | K43: =4160+1440+1120+2880+4800+91680+4000 -> 110080 | L43: =K43/21 -> 5241.9048

Sheet PISO E TETO
A1: Obra | B1: =DADOS_INICIAIS!B1 -> Viva Perequê Residencial
A2: Empresa | B2: =DADOS_INICIAIS!B2 -> Ferazzo e Correa Incorporadora
A3: Revisão | B3: R00
A4: Data | B4: 45825
A5: LEVANTAMENTO QUANTITATIVO
A7: REVESTIMENTOS E ACABAMENTOS DE PISO E TETO
B9: LEVANTAMENTO DE PROJETO | L9: CONTRAPISO
B10: Pavimento | C10: Ambiente | D10: Área (m²) | E10: Material | F10: Contrapiso (Sim/Não) | G10: Forro | H10: Repetição | I10: Total | L10: Revestimento | M10: Área total
B11: TERREO | C11: SALA 01 | D11: 197.13 | E11: PORCELANATO | F11: Sim | G11: Gesso | H11: 1 | I11: =H11*Table_2[[#This Row],[Área (m²)]] -> 197.13 | L11: Contrapiso | M11: =SUMIF(F:F,"Sim",I:I) -> 3430.988
B12: TERREO | C12: SALA 02 | D12: 102.85 | E12: PORCELANATO | F12: Sim | G12: Gesso | H12: 1 | I12: =H12*Table_2[[#This Row],[Área (m²)]] -> 102.85 | L12: Manta acústica | M12: =SUMIF(F31:F57,"Sim",I31:I57) -> 3071.638
B13: TERREO | C13: LAVABO SALAS | D13: =3.36+3.36+2.34+2.34 -> 11.4 | E13: PORCELANATO | F13: Sim | G13: Gesso | H13: 1 | I13: =H13*Table_2[[#This Row],[Área (m²)]] -> 11.4 | L13: FORRO
B14: TERREO | C14: LIXEIRA | D14: 4.07 | E14: PORCELANATO | F14: Sim | G14: Estucamento | H14: 1 | I14: =H14*Table_2[[#This Row],[Área (m²)]] -> 4.07 | L14: Revestimento | M14: Área total
B15: TERREO | C15: CENTRAL DE GÁS | D15: 3.74 | E15: CIMENTADO | F15: Não | G15: Estucamento | H15: 1 | I15: =H15*Table_2[[#This Row],[Área (m²)]] -> 3.74 | L15: Estucamento | M15: =SUMIF(G:G,L15,I:I) -> 2546.7505
B16: TERREO | C16: HALL DE ENTRADA | D16: 38.28 | E16: PORCELANATO | F16: Sim | G16: Gesso | H16: 1 | I16: =H16*Table_2[[#This Row],[Área (m²)]] -> 38.28 | L16: Gesso | M16: =SUMIF(G:G,L16,I:I) -> 3155.42
B17: TERREO | C17: S TECNICA | D17: 4.32 | E17: CIMENTADO | F17: Não | G17: Estucamento | H17: 1 | I17: =H17*Table_2[[#This Row],[Área (m²)]] -> 4.32 | L17: - | M17: =SUMIF(G:G,L17,I:I) -> 650.8552
B18: TERREO | C18: ANTECAMARA | D18: 3.54 | E18: CIMENTADO | F18: Não | G18: Estucamento | H18: 1 | I18: =H18*Table_2[[#This Row],[Área (m²)]] -> 3.54
B19: TERREO | C19: ESCADA | D19: =15.95+1.35*22*0.18 -> 21.296 | E19: CIMENTADO | F19: Não | G19: Estucamento | H19: 1 | I19: =H19*Table_2[[#This Row],[Área (m²)]] -> 21.296
B20: TERREO | C20: RAMPA | D20: =102.62*1.2+3.8*4*1.0315+6*4*1.1783 -> 167.102 | E20: LADRILHO HIDRAULICO | F20: Não | G20: Estucamento | H20: 1 | I20: =H20*Table_2[[#This Row],[Área (m²)]] -> 167.102
B21: TERREO | C21: PASSEIO/ACESSO FRENTE coberto | D21: =24*1.5 -> 36 | E21: Paver | F21: Não | G21: Gesso | H21: 1 | I21: =H21*Table_2[[#This Row],[Área (m²)]] -> 36 | L21: ACABAMENTOS
B22: TERREO | C22: PASSEIO/ACESSO FRENTE | D22: =24*(4-1.5) -> 60 | E22: Paver | F22: Não | G22: - | H22: 1 | I22: =H22*Table_2[[#This Row],[Área (m²)]] -> 60 | L22: Material | M22: Área total
B23: G1/G2 | C23: GARAGEM | D23: =346.34+12.5*10 -> 471.34 | E23: POLIDO | F23: Não | G23: Estucamento | H23: 2 | I23: =H23*Table_2[[#This Row],[Área (m²)]] -> 942.68 | L23: PORCELANATO | M23: =SUMIF(E:E,L23,I:I) -> 2367.21
B24: G1/G2 | C24: ANTECAMARA | D24: 4.61 | E24: CIMENTADO | F24: Não | G24: Estucamento | H24: 2 | I24: =H24*Table_2[[#This Row],[Área (m²)]] -> 9.22 | L24: CIMENTADO | M24: =SUMIF(E:E,L24,I:I) -> 598.196
B25: G1/G2 | C25: ESCADA | D25: =15.95+1.35*22*0.18 -> 21.296 | E25: CIMENTADO | F25: Não | G25: Estucamento | H25: 2 | I25: =H25*Table_2[[#This Row],[Área (m²)]] -> 42.592 | L25: LADRILHO HIDRAULICO | M25: =SUMIF(E:E,L25,I:I) -> 676.56452
B26: G1/G2 | C26: RAMPA | D26: =3.69*4.1*1.0813+(12.2+15.7)*4.1*1.2+3.8*4.1*1.0394 -> 169.82084 | E26: LADRILHO HIDRAULICO | F26: Não | G26: Estucamento | H26: 2 | I26: =H26*Table_2[[#This Row],[Área (m²)]] -> 339.64168 | L26: Paver | M26: =SUMIF(E:E,L26,I:I) -> 96
B27: G3 | C27: GARAGEM | D27: =346.34+12.5+12*12+21.6 -> 524.44 | E27: POLIDO | F27: Não | G27: Estucamento | H27: 1 | I27: =H27*Table_2[[#This Row],[Área (m²)]] -> 524.44 | L27: POLIDO | M27: =SUMIF(E:E,L27,I:I) -> 1467.12
B28: G3 | C28: ANTECAMARA | D28: 4.61 | E28: CIMENTADO | F28: Não | G28: Estucamento | H28: 1 | I28: =H28*Table_2[[#This Row],[Área (m²)]] -> 4.61 | L28: VINILICO | M28: =SUMIF(E:E,L28,I:I) -> 914.94
B29: G3 | C29: ESCADA | D29: =17.02+1.35*16*0.18 -> 20.908 | E29: CIMENTADO | F29: Não | G29: Estucamento | H29: 1 | I29: =H29*Table_2[[#This Row],[Área (m²)]] -> 20.908 | L29: PASTILHA | M29: =SUMIF(E:E,L29,I:I) -> 72.12
B30: G3 | C30: RAMPA | D30: =3.69*4.1*1.0813+(12.2+15.7)*4.1*1.2+3.8*4.1*1.0394 -> 169.82084 | E30: LADRILHO HIDRAULICO | F30: Não | G30: Estucamento | H30: 1 | I30: =H30*Table_2[[#This Row],[Área (m²)]] -> 169.82084 | L30: - | M30: =SUMIF(E:E,L30,I:I) -> 84.1572
B31: DIF / LAZER | C31: ANTECAMARA | D31: 4.61 | E31: CIMENTADO | F31: Não | G31: Estucamento | H31: 1 | I31: =H31*Table_2[[#This Row],[Área (m²)]] -> 4.61 | L31: GRAMA SINTETICA | M31: =SUMIF(E:E,L31,I:I) -> 30
B32: DIF / LAZER | C32: ESCADA | D32: =15.9+1.35*20*0.18 -> 20.76 | E32: CIMENTADO | F32: Não | G32: Estucamento | H32: 1 | I32: =H32*Table_2[[#This Row],[Área (m²)]] -> 20.76 | L32: DECK | M32: =SUMIF(E:E,L32,I:I) -> 46.718
B33: DIF / LAZER | C33: CIRCULAÇÃO | D33: 22.05 | E33: PORCELANATO | F33: Sim | G33: Gesso | H33: 1 | I33: =H33*Table_2[[#This Row],[Área (m²)]] -> 22.05
B34: DIF / LAZER | C34: SALÃO DE FESTAS | D34: 53.87 | E34: PORCELANATO | F34: Sim | G34: Gesso | H34: 1 | I34: =H34*Table_2[[#This Row],[Área (m²)]] -> 53.87
B35: DIF / LAZER | C35: PUB | D35: 22.91 | E35: VINILICO | F35: Sim | G35: Gesso | H35: 1 | I35: =H35*Table_2[[#This Row],[Área (m²)]] -> 22.91
B36: DIF / LAZER | C36: ACADEMIA | D36: 16.52 | E36: VINILICO | F36: Sim | G36: Gesso | H36: 1 | I36: =H36*Table_2[[#This Row],[Área (m²)]] -> 16.52
B37: DIF / LAZER | C37: LAVABO | D37: =2.4+3.82 -> 6.22 | E37: PORCELANATO | F37: Sim | G37: Gesso | H37: 1 | I37: =H37*Table_2[[#This Row],[Área (m²)]] -> 6.22
B38: DIF / LAZER | C38: LAZER EXTERNO | D38: 103.6 | E38: PORCELANATO | F38: Sim | G38: - | H38: 1 | I38: =H38*Table_2[[#This Row],[Área (m²)]] -> 103.6
B39: DIF / LAZER | C39: PLAYGROUND | D39: =30 -> 30 | E39: GRAMA SINTETICA | F39: Sim | G39: - | H39: 1 | I39: =H39*Table_2[[#This Row],[Área (m²)]] -> 30
B40: DIF / LAZER | C40: DECK | D40: =(24-10.84)*3.55 -> 46.718 | E40: DECK | F40: Sim | G40: - | H40: 1 | I40: =H40*Table_2[[#This Row],[Área (m²)]] -> 46.718
B41: DIF / LAZER | C41: PRAINHA | D41: =10.8 -> 10.8 | E41: PASTILHA | F41: Sim | G41: - | H41: 1 | I41: =H41*Table_2[[#This Row],[Área (m²)]] -> 10.8
B42: DIF / LAZER | C42: PISCINA | D42: =11.21+16.54+(3.55*2+4.79*2+2.85*2)*1.5 -> 61.32 | E42: PASTILHA | F42: Sim | G42: - | H42: 1 | I42: =H42*Table_2[[#This Row],[Área (m²)]] -> 61.32
...

Sheet Rev. Internos Piso e Parede
A2: ORÇAMENTO PARAMÉTRICO GERENCIAMENTO EXECUTIVO
A7: Cliente
A8: Obra
A9: Data | B9: 45471
A10: Revisão | B10: R00
A12: REVESTIMENTOS INTERNOS EM PISO E PAREDE
A14: Descrição | B14: Quantidade | D14: Parâmetro | F14: Referência | G14: Valor total
A15: Polimento de concreto | B15: ='PISO E TETO'!M27 -> 1467.12 | C15: m² | D15: 50 | E15: R$ / m² | F15: Média | G15: =D15*B15*1.1 -> 80691.6 | H15: =G15/B15 -> 55 | I15: =172.7*B15 -> 253371.62
A16: Piso alisado | B16: ='PISO E TETO'!M24 -> 598.196 | C16: m² | D16: 25 | E16: R$ / m² | F16: Média | G16: =D16*B16*1.1 -> 16450.39
A17: Piso ranhurado | C17: m² | D17: =28 -> 28 | E17: R$ / m² | F17: Média | G17: =D17*B17*1.1 -> 0
A18: Contrapiso | B18: ='PISO E TETO'!M11 -> 3430.988 | C18: m² | D18: 32 | E18: m² / AC | F18: Média | G18: =B18*D18*1.1 -> 120770.78
A19: Manta acústica | B19: ='PISO E TETO'!M12 -> 3071.638 | C19: m² | D19: 26 | E19: m² / AC | F19: Média | G19: =B19*D19*1.1 -> 87848.847 | J19: =G19/B19 -> 28.6 | K19: =G19/DADOS_INICIAIS!E9 -> 15.754334
A20: Mao de obra contrapiso | B20: =B18 -> 3430.988 | C20: m² | D20: 35 | E20: R$ / m² | F20: Média | G20: =B20*D20*1.1 -> 132093.04
A21: Chapisco | B21: =ALVENARIA!D13*2-'Rev. Fachada'!B15 -> 9367.2754 | C21: m² | D21: 2.9 | E21: R$ / m² | F21: Média | G21: =B21*D21*1.1 -> 29881.608
A22: Reboco | B22: =B21 -> 9367.2754 | C22: m² | D22: 16 | E22: R$ / m² | F22: Média | G22: =B22*D22*1.1 -> 164864.05
A23: Estucamento | B23: =0.15*DADOS_INICIAIS!E9 -> 836.4255 | C23: m² | D23: =4.3+22 -> 26.3 | E23: R$ / m² | F23: Média | G23: =B23*D23*1.1 -> 24197.79
A24: Mao de obra argamassado | B24: =B22 -> 9367.2754 | D24: 34 | E24: R$ / m² | F24: Média | G24: =B24*D24*1.1 -> 350336.1
A25: TOTAL | G25: =SUM(G15:G24) -> 1007134.2
A28: TOTAL REVESTIMENTOS | G28: =G25 -> 1007134.2 | H28: =G28/DADOS_INICIAIS!E9 -> 180.61397

Sheet TETO
A3: REVESTIMENTOS E ACABAMENTOS DE TETO
A4: Data | B4: 45471
A5: Arquivo base | B5: -
A7: GESSO
A9: Descrição | B9: Parâmetro | D9: Quantidade | F9: Preço unitário | G9: Valor total | H9: Observação
A10: Forro gesso mineral | B10: =D10/DADOS_INICIAIS!E9 -> 0.56587586 | C10: m² / AC | D10: ='PISO E TETO'!M16 -> 3155.42 | E10: m² | F10: 65 | G10: =F10*D10*1.1 -> 225612.53
A11: Negativo | B11: 1.2 | C11: m / FORRO | D11: =(D10)*B11 -> 3786.504 | E11: m | F11: 25 | G11: =F11*D11*1.1 -> 104128.86
A12: Estucamento | B12: =D12/DADOS_INICIAIS!E9 -> 0.45672039 | C12: m² / AC | D12: ='PISO E TETO'!M15 -> 2546.7505 | E12: m² | F12: 7.5 | G12: =F12*D12*1.1 -> 21010.692
A13: MO Estucamento | D13: =D12 -> 2546.7505 | F13: 22 | G13: =F13*D13*1.1 -> 61631.363
A14: TOTAL | G14: =SUM(G10:G13) -> 412383.44 | H14: =G14/DADOS_INICIAIS!$E$9 -> 73.954604 | K14: =4160+1440+1120+2880+4800+91680+4000 -> 110080 | L14: =K14/21 -> 5241.9048
A16: TOTAL FORRO | G16: =G14 -> 412383.44 | H16: =G16/DADOS_INICIAIS!E9 -> 73.954604
G18: =#REF!/DADOS_INICIAIS!E9 -> #REF!
H19: =H16/1.1 -> 67.231458

Sheet Acabamentos de Piso e Parede
A2: ORÇAMENTO PARAMÉTRICO GERENCIAMENTO EXECUTIVO
A7: Cliente
A8: Obra
A9: Data | B9: 45471
A10: Revisão | B10: R00
A12: ACABAMENTOS EM PISO E PAREDE
A14: Descrição | B14: Quantidade | D14: Parâmetro | F14: Referência | G14: Valor total
A15: Porcelanato | B15: ='PISO E TETO'!M23 -> 2367.21 | C15: m² | D15: 170 | E15: R$ / m² | F15: Média | G15: =+D15*B15*1.1 -> 442668.27
A16: Porcelanato AC | C16: m² | D16: 150 | E16: R$ / m² | F16: Média | G16: =+D16*B16*1.1 -> 0
A17: Porcelanato AP | C17: m² | D17: 85 | E17: R$ / m² | F17: Média | G17: =+D17*B17*1.1 -> 0
A18: Ceramica | C18: m² | D18: 60 | E18: R$ / m² | F18: Média | G18: =+D18*B18*1.1 -> 0
A19: Piscina | B19: ='PISO E TETO'!M29 -> 72.12 | C19: m² | D19: =290+50 -> 340 | E19: R$ / m² | F19: Média | G19: =+D19*B19*1.1 -> 26972.88
A20: Paver | B20: ='PISO E TETO'!M26 -> 96 | C20: m² | D20: 150 | E20: R$ / m² | F20: Média | G20: =+D20*B20*1.1 -> 15840
A21: Vinilico | B21: ='PISO E TETO'!M28 -> 914.94 | C21: m² | D21: 210 | E21: R$ / m² | F21: Média | G21: =+D21*B21*1.1 -> 211351.14
A22: Ladrilho hidraulico | B22: ='PISO E TETO'!M25 -> 676.56452 | C22: m² | D22: 81 | E22: R$ / m² | F22: Média | G22: =+D22*B22*1.1 -> 60281.899
A23: Deck | B23: ='PISO E TETO'!M32 -> 46.718 | C23: m² | D23: =768+40 -> 808 | E23: R$ / m² | F23: Média | G23: =+D23*B23*1.1 -> 41522.958
A24: Grama sintetica | B24: ='PISO E TETO'!M31 -> 30 | C24: m² | D24: 210 | E24: R$ / m² | F24: Média | G24: =+D24*B24*1.1 -> 6930
A25: Madeira sauna | C25: m² | D25: =985.2 -> 985.2 | E25: R$ / m² | F25: Média | G25: =+D25*B25*1.1 -> 0
A26: Rodapés | B26: 1 | C26: vb | D26: 18 | E26: R$ / AC | F26: Média | G26: =D26*DADOS_INICIAIS!$E$9*1.1 -> 110408.17
A27: Soleiras | B27: 1 | C27: vb | D27: 5 | E27: R$ / AC | F27: Média | G27: =D27*DADOS_INICIAIS!$E$9*1.1 -> 30668.935
A28: Peitoris | B28: 1 | C28: vb | D28: 12 | E28: R$ / AC | F28: Média | G28: =D28*DADOS_INICIAIS!$E$9*1.1 -> 73605.444
A29: Revestimentos de Parede | B29: =0.24*DADOS_INICIAIS!E9 -> 1338.2808 | C29: m² | D29: 170 | E29: R$ / AC | F29: Média | G29: =D29*B29*1.1 -> 250258.51 | H29: banheiros
A30: Mao de obra acabamentos
G31: =SUM(G15:G30) -> 1270508.2 | I31: =G31/DADOS_INICIAIS!E9 -> 227.84603

Sheet PINTURA INTERNA
A3: PINTURA INTERNA
A4: Data | B4: 45457
A5: Arquivo base | B5: -
A7: PINTURA INTERNA
A9: Descrição | B9: Parâmetro | D9: Quantidade | F9: Preço unitário | G9: Valor total | H9: Observação
A10: Pintura piso epoxi | B10: 110 | C10: R$ / m² | D10: ='Rev. Internos Piso e Parede'!B15 -> 1467.12 | E10: m² | F10: =80+30 -> 110 | G10: =F10*D10*1.1 -> 177521.52 | H10: Vagas e bicicleta
A11: Pintura piso resina | B11: 110 | C11: R$ / m² | E11: m² | F11: 30 | G11: =F11*D11*1.1 -> 0
A12: Pintura acrílica antiderrapante | B12: 65 | C12: R$ / m² | D12: ='Rev. Internos Piso e Parede'!B16 -> 598.196 | E12: m² | G12: =F12*D12*1.1 -> 0
A13: Textura escadas | B13: 25 | C13: R$ / AC | D13: ='Rev. Internos Piso e Parede'!B23 -> 836.4255 | E13: m² | F13: =6+28 -> 34 | G13: =F13*D13*1.1 -> 31282.314 | H13: =H10*0.2+TETO!D12 -> #VALUE!
A14: Textura Teto | B14: 25 | C14: R$ / AC | D14: =TETO!D12 -> 2546.7505 | E14: m² | F14: =F13 -> 34 | G14: =F14*D14*1.1 -> 95248.469 | H14: =H12*0.2+TETO!D14 -> 0
A15: Pintura Interna Tetos | B15: =90*0.9 -> 81 | C15: R$ / AC | D15: =TETO!D10 -> 3155.42 | E15: m² | F15: =21+28 -> 49 | G15: =F15*D15*1.1 -> 170077.14
A16: Pintura Interna | B16: =90*0.9 -> 81 | C16: R$ / AC | D16: ='Rev. Internos Piso e Parede'!B22-'Acabamentos de Piso e Parede'!B29 -> 8028.9946 | E16: m² | F16: =F15 -> 49 | G16: =F16*D16*1.1 -> 432762.81
A17: TOTAL | G17: =SUM(G10:G16) -> 906892.25 | K17: =4160+1440+1120+2880+4800+91680+4000 -> 110080 | L17: =K17/21 -> 5241.9048
A19: PINTURA INTERNA | G19: =G17 -> 906892.25 | H19: =G19/DADOS_INICIAIS!E9 -> 162.63712
H21: =H19/1.1 -> 147.85193

Sheet ESQUADRIAS
A3: ESQUADRIAS
A4: Data | B4: 45460
A5: Arquivo base | B5: -
A7: ESQUADRIAS
A9: Descrição | B9: Parâmetro | D9: Quantidade | G9: Valor total | H9: Observação
A10: Esquadrias de PVC | B10: 0.14 | C10: m² / AC | D10: =B10*DADOS_INICIAIS!E9 -> 780.6638 | E10: m² | F10: 1650 | G10: =F10*D10*1.1 -> 1416904.8 | I10: =G10/D10 -> 1815 | K10: J3 | L10: =64+3 -> 67 | M10: =1.6*1.2 -> 1.92 | N10: =L10*M10 -> 128.64
A11: Pele de vidro | B11: 0.08 | C11: m² / AC | D11: =4.24*2.6+3*2.6+2.95*2.6*2 -> 34.164 | E11: m² | F11: 1100 | G11: =F11*D11*1.1 -> 41338.44 | K11: J9 | L11: =48+5 -> 53 | M11: =0.8*0.8 -> 0.64 | N11: =L11*M11 -> 33.92
A12: Esquadrias de PVC arredondadas | D12: =8.2*(13.5-4.14)+7.36*(13.5-4.14)+3*(52.12-45.9)+24*2.6 -> 226.7016 | E12: m² | F12: 3252.9159 | G12: =F12*D12*1.1 -> 811185.37 | K12: J4 | L12: 2 | M12: =1.5*1.2 -> 1.8 | N12: =L12*M12 -> 3.6
A13: Portão de alumínio | D13: 1 | E13: un | F13: 16000 | G13: =F13*D13*1.1 -> 17600 | K13: J6 | L13: =2+1 -> 3 | M13: =1.2*1.2 -> 1.44 | N13: =L13*M13 -> 4.32
A14: Guarda-corpo - vidro | D14: =((6.28+1.45)+(7.5+1.46))*1.1+(22.5-6.3-3-0.3)*1.1 -> 32.549 | E14: m² | F14: =F16 -> 2442.6667 | G14: =F14*D14*1.1 -> 87456.993 | K14: J10 | L14: 5 | M14: =0.7*0.5 -> 0.35 | N14: =L14*M14 -> 1.75
A15: Gradil area tecnica | D15: =(2.1+0.6*2)*4*8+(3.6+0.6*2)*2 -> 115.2 | E15: m² | F15: =890/1.1 -> 809.09091 | G15: =F15*D15*1.1 -> 102528 | N15: =SUM(N10:N14) -> 172.23
A16: Gradil fachada | D16: =8.2+7.36+(2.3+3+3.05*2)*8+5.5+3.2+3.9 -> 119.36 | E16: m | F16: =3053.33333333333*0.8 -> 2442.6667 | G16: =F16*D16*1.1 -> 320712.36 | N16: =SUM(N11:N15) -> 215.82
A17: Serralherias | B17: 2 | C17: R$ / AC | D17: 1 | E17: vb | F17: =B17*DADOS_INICIAIS!$E$9 -> 11152.34 | G17: =F17*D17*1.1 -> 12267.574 | K17: PORTAS | L17: =5+1+2 -> 8 | M17: =1*2.1 -> 2.1 | N17: =L17*M17 -> 16.8
A18: PCF | D18: =2*DADOS_INICIAIS!E15 -> 30 | E18: un | F18: 1750 | G18: =F18*D18*1.1 -> 57750 | N18: =(2.6*2.3+2.6*3+2.6*3.05*2)*8+5.5*2.6+3.2*2.6+3.9*2.6 -> 269.88
A19: Corrimão madeira | D19: =(4.12*2+4.75*2)*1.2*DADOS_INICIAIS!E15 -> 319.32 | E19: m | F19: 85 | G19: =F19*D19*1.1 -> 29856.42
A20: Corrimão comercial | E20: m | F20: 650 | G20: =F20*D20*1.1 -> 0
A21: Fechadura Biometrica | D21: =DADOS_INICIAIS!E10 -> 36 | E21: un | F21: 1250 | G21: =F21*D21*1.1 -> 49500
A22: Esquadrias de Madeira | D22: =5+1+6+7+4+32+64+80+2+7+3+3+2 -> 216 | E22: un | F22: 1350 | G22: =F22*D22*1.1 -> 320760
A23: TOTAL | G23: =SUM(G10:G22) -> 3267860 | K23: =4160+1440+1120+2880+4800+91680+4000 -> 110080 | L23: =K23/21 -> 5241.9048
A25: TOTAL ESQUADRIAS | G25: =G23 -> 3267860 | H25: =G25/DADOS_INICIAIS!E9 -> 586.04023
B29: G1 | C29: G2 | D29: G3 | E29: TIPO DIF | F29: TIPO (X21) | G29: ROOFTOP
A30: BRISE TEC | E30: =2.5+(2.5+0.65) -> 5.65 | G30: =22.16+1.25+1.35 -> 24.76 | H30: =SUM(B30:G30) -> 30.41
A31: GC SACADA | B31: 12.52 | C31: 12.52 | D31: =10.19 -> 10.19 | E31: =7.33+6.24 -> 13.57 | F31: =E31*21 -> 284.97 | G31: =E31 -> 13.57 | H31: =SUM(B31:G31) -> 347.34

Sheet COBERTURA
A2: COBERTURA
A3: Data | B3: 45543
A4: Arquivo base | B4: -
A6: TELHADO
A8: Descrição | B8: Parâmetro | D8: Quantidade | F8: Preço unitário | G8: Valor total | H8: Observação
A9: Estrutura e telhamento | D9: ='PISO E TETO'!D62 -> 199.2 | E9: m² | F9: 131.04 | G9: =F9*D9*1.1 -> 28713.485
A10: Telhamento Shingle | D10: =D9*(1+3.35) -> 866.52 | E10: m² | F10: 197.99 | G10: =F10*D10*1.1 -> 188718.52
A11: Serviços complementares | D11: =D9 -> 199.2 | E11: m² | F11: 90 | G11: =F11*D11*1.1 -> 19720.8
A12: Mo ocbertura | D12: =D9 -> 199.2 | E12: m² | F12: 643.851 | G12: =F12*D12 -> 128255.12
A13: Pergolados | D13: =(10.26-1.85)*2.7+3.55*3.1 -> 33.712 | E13: m² | F13: 450 | G13: =F13*D13*1.1 -> 16687.44
A14: TOTAL | G14: =SUM(G9:G13) -> 382095.37
A16: TOTAL COMPLEMENTARES | G16: =G14 -> 382095.37 | H16: =G16/DADOS_INICIAIS!$E$9 -> 68.522905

Sheet Rev. Fachada
A2: ORÇAMENTO PARAMÉTRICO GERENCIAMENTO EXECUTIVO
A7: Cliente
A8: Obra
A9: Data | B9: 45543
A10: Revisão | B10: R00
A12: REVESTIMENTOS ARGAMASSADOS
A14: Descrição | B14: Quantidade | D14: Parâmetro | F14: Referência | G14: Valor total
A15: Chapisco e reboco | B15: =L31 -> 4015.5326 | C15: m² | D15: 25 | E15: R$ / m² | F15: - | G15: =B15*D15*1.1 -> 110427.15
A16: Tratamento | B16: =K24*(DADOS_INICIAIS!E15-DADOS_INICIAIS!E27)+K22*DADOS_INICIAIS!E27 -> 1178.43 | C16: m | D16: 5 | E16: R$ / m² | F16: - | G16: =B16*D16*1.1 -> 6481.365
A17: Mão de obra | B17: =B15 -> 4015.5326 | C17: m² | D17: 65 | E17: R$ / m² | F17: - | G17: =B17*D17*1.1 -> 287110.58
A18: Revestimento torre frisado | B18: =M24 -> 2461.0782 | C18: m² | D18: =D15*1.4 -> 35 | E18: R$ / m² | F18: - | G18: =B18*D18*1.1 -> 94751.511
A19: mo Revestimento torre frisado | B19: =B18 -> 2461.0782 | C19: m² | D19: =D17*2 -> 130 | E19: R$ / m² | F19: - | G19: =B19*D19*1.1 -> 351934.18
A20: TOTAL | G20: =SUM(G15:G19) -> 850704.79
A22: PINTURA | J22: EMBASAMENTO | K22: =DADOS_INICIAIS!E26 -> 93.06 | L22: 15.13
A24: Descrição | B24: Quantidade | D24: Parâmetro | F24: Referência | G24: Valor total | J24: TORRE | K24: =DADOS_INICIAIS!E20 -> 73.29 | L24: 33.58 | M24: =L24*K24 -> 2461.0782
A25: Textura | B25: =B15-B27 -> 1554.4544 | C25: m² | D25: 28 | E25: R$ / m² | F25: - | G25: =B25*D25*1.1 -> 47877.197 | H25: =G25/B25 -> 30.8 | J25: RESERV | K25: =4.12*2+11.06*2 -> 30.36 | L25: 6.03
A26: Mo Tetxura | B26: =B25 -> 1554.4544 | C26: m² | D26: 52 | E26: R$ / m² | F26: - | G26: =B26*D26*1.1 -> 88914.794 | H26: =G26/B26 -> 57.2
A27: Textura frisos | B27: =M24 -> 2461.0782 | C27: m² | D27: 9.6 | E27: R$ / m² | F27: - | G27: =B27*D27*1.1 -> 25988.986 | H27: =G27/B27 -> 10.56
A28: Mo Tetxura frisos | B28: =B27 -> 2461.0782 | C28: m² | D28: 80 | E28: R$ / m² | F28: - | G28: =B28*D28*1.1 -> 216574.88 | H28: =G28/B28 -> 88
A29: Pintura molduras | B29: =B36*0.4*3*1.5 -> 837.756 | C29: m² | D29: 12 | E29: R$ / m² | F29: - | G29: =B29*D29*1.1 -> 11058.379 | H29: =G29/B29 -> 13.2
A30: Mo Pintura molduras | B30: =B29 -> 837.756 | C30: m² | D30: 200 | E30: R$ / m² | F30: - | G30: =B30*D30*1.1 -> 184306.32 | H30: =G30/B30 -> 220
A31: TOTAL | G31: =SUM(G25:G30) -> 574720.56 | L31: =K22*L22+K24*L24+K25*L25*0.8+K23*L23 -> 4015.5326
A33: ACABAMENTOS ESPECIAIS
A35: Descrição | B35: Quantidade | D35: Parâmetro | F35: Referência | G35: Valor total
A36: Molduras EPS | B36: =SUM(A44:A48) -> 465.42 | C36: m | D36: 250 | E36: R$ / m | F36: - | G36: =B36*D36*1.1 -> 127990.5
A37: Detalhes unitarios | B37: 2 | C37: um | D37: 2160 | E37: R$ / un | F37: - | G37: =B37*D37*1.1 -> 4752 | H37: =G37/B37 -> 2376
G38: =SUM(G36:G37) -> 132742.5
J39: =25.78*2 -> 51.56
A41: TOTAL FACHADA | G41: =G31+G20+G38 -> 1558167.8 | H41: =G41/DADOS_INICIAIS!E9 -> 279.43335
B42: =0.07*DADOS_INICIAIS!$E$9 -> 390.3319 | H42: =H41/1.1 -> 254.03032
A44: =3*K24 -> 219.87
A45: =3*L24 -> 100.74
A46: =6*L22 -> 90.78 | C46: =B16*4 -> 4713.72 | D46: 45 | E46: =D46*C46 -> 212117.4
A47: =24*2 -> 48 | E47: =E46*0.4 -> 84846.96 | H47: INDICE | I47: 0.25 | J47: TODO COM MOLDURA
A48: =L25 -> 6.03 | E48: =E46+E47 -> 296964.36 | H48: INDICE | I48: 0.1 | J48: APENAS EMBASAMENTO E COBERTURA
C49: =0.25*DADOS_INICIAIS!E9 -> 1394.0425 | D49: 245 | E49: =D49*C49 -> 341540.41

Sheet COMPLEMENTARES
A2: COMPLEMENTARES
A3: Data | B3: 45460
A4: Arquivo base | B4: -
A6: SERVIÇOS COMPLEMENTARES
A8: Descrição | B8: Parâmetro | D8: Quantidade | F8: Valor total
A9: Móveis e decoração | B9: 2100 | C9: R$ / AL | D9: =DADOS_INICIAIS!E21 -> 323.11 | E9: m² | F9: =D9*B9*1.1 -> 746384.1
A10: Comunicação visual | B10: 10 | C10: R$ / AC | D10: =B10*DADOS_INICIAIS!$E$9 -> 55761.7 | E10: vb | F10: =D10*1.1 -> 61337.87
A11: Paisagismo | B11: 25 | C11: R$ / AC | D11: =B11*DADOS_INICIAIS!$E$9 -> 139404.25 | E11: vb | F11: =D11*1.1 -> 153344.68
A12: Ligações definitivas | B12: 4 | C12: R$ / AC | D12: =B12*DADOS_INICIAIS!$E$9 -> 22304.68 | E12: vb | F12: =D12*1.1 -> 24535.148
A13: Desmobilização | B13: 3.5 | C13: R$ / AC | D13: =B13*DADOS_INICIAIS!$E$9 -> 19516.595 | E13: vb | F13: =D13 -> 19516.595
A14: Limpeza | B14: 20 | C14: R$ / AC | D14: =B14*DADOS_INICIAIS!$E$9 -> 111523.4 | E14: vb | F14: =D14*1.1 -> 122675.74
A15: TOTAL | F15: =SUM(F9:F14) -> 1127794.1
A17: TOTAL COMPLEMENTARES | F17: =F15 -> 1127794.1 | G17: =F17/DADOS_INICIAIS!$E$9 -> 202.25247

Sheet Auxiliar
A2: 2 Portões acesso garagem - Área: 9,2m² x 2 = 18,4m² | B2: 2 | C2: portão | D2: 18.4
A3: 2 portas corta-fogo 1 folha | B3: 2 | C3: pcf
A4: 1 porta de correr alumínio 2 folhas – Área: 3,465m² | B4: 1 | C4: porta alumínio | D4: 3.465
A5: 1 porta de correr alumínio 2 folhas – Área: 1,7325m² | B5: 1 | C5: porta alumínio | D5: 1.7325 | G5: Guarda alumínio | H5: =SUMIF(C:C,G5,D:D) -> 400.5221
A6: 2 portas de abrir alumínio 2 folhas – Área: 2,6376m² x 2 = 5,2752m² | B6: 2 | C6: porta alumínio | D6: 5.2752 | G6: janela | H6: =SUMIF(C:C,G6,D:D) -> 1895.06
A7: 1 porta de abrir alumínio 2 folhas – Área: 4,1916m² | B7: 1 | C7: porta alumínio | D7: 4.1916 | G7: madeira | H7: =SUMIF(C:C,G7,B:B) -> 218
A8: 1 porta pivotante | B8: 1 | C8: pivotante | G8: pcf | H8: =SUMIF(C:C,G8,B:B) -> 60
A9: 19 portas de abrir madeira 1 folha | B9: 19 | C9: madeira | G9: pivotante | H9: =SUMIF(C:C,G9,B:B) -> 1
A10: 3 portas de abrir vidro 1 folha – Área: 2,1m² x 3 = 6,3m² | B10: 3 | C10: porta alumínio | D10: 6.3 | G10: porta alumínio | H10: =SUMIF(C:C,G10,D:D) -> 46.62
A11: 2 portas de abrir vidro 1 folha – Área: 1,89m² x 2 = 3,78m² | B11: 2 | C11: porta alumínio | D11: 3.78 | G11: portão | H11: =SUMIF(C:C,G11,B:B) -> 2
A12: 1 porta de abrir alumínio 1 folha – Área: 2,0076m² | B12: 1 | C12: porta alumínio | D12: 2.0076 | G12: gradil | H12: =SUMIF(C:C,G12,D:D) -> 113.88
A13: Janelas – Área: 3,75 + 4,875 + 2,5 + 1,1 + 1,2 + 5,5402 + 4,4874 = 23,4526m² | C13: janela | D13: 23.4526 | G13: Brise | H13: 109.3146
A14: Muro de vidro – Área: 7,0774 + 5,485 + 3,43 + 4,8138 = 20,8062m² | C14: Guarda alumínio | D14: 20.8062
A15: 8 portas corta-fogo 1 folha | B15: 8 | C15: pcf
A16: Janelas – Area: (1,1 + 1,2 + 28,7391) x 4 = 124,1564m² | C16: janela | D16: 124.1564
A17: 2 portas corta-fogo 1 folha | B17: 2 | C17: pcf
A18: 2 portas de abrir alumínio 1 folha – Área: 1,47m² x 2 = 2,94m² | B18: 2 | C18: porta alumínio | D18: 2.94
A19: 2 portas de abrir vidro 1 folha – Área: 1,89m² x 2 = 3,78m² | B19: 2 | C19: porta alumínio | D19: 3.78
A20: 5 portas de abrir madeira 1 folha | B20: 5 | C20: madeira
A21: 1 janela-porta de correr vidro – Área: 14,7348m² | B21: 1 | C21: janela | D21: 14.7348
A22: Janelas – Área: 1,2894 + 1,2894 + 23,46 + 1,854 + 5,562 + 5,562 + 1,854 + 1,854 + 1,1 + 1,2 = 45,0248m² | C22: janela | D22: 45.0248
A23: Guarda corpo vidro – Área: 7,5299 + 5,7955 + 6,5555 = 19,8809m² | C23: Guarda alumínio | D23: 19.8809
A24: 38 portas corta-fogo 1 folha | B24: 38 | C24: pcf
A25: 171 portas de abrir madeira 1 folha | B25: 171 | C25: madeira
A26: 19 porta de abrir alumínio 1 folha – Área: 1,26m² x 19 = 23,94m² | B26: 19 | C26: porta alumínio | D26: 23.94
A27: 19 janela-porta de correr vidro 5 folhas - Área: 25,4205m² x 19 = 482,9895m² | B27: 19 | C27: janela | D27: 482.9895
A28: 19 janela-porta de correr vidro 5 folhas - Área: 17,8284m² x 19 = 338,7396m² | B28: 19 | C28: janela | D28: 338.7396
A29: Janelas – Área: 1,1 + 1,1 + 1,2 + 1,92 + 0,36 + 2,781 + 2,781 + 1,854 + 1,854 + 5,562 + 5,562 + 1,854 = 27,928m² x 19 = 530,632m² | C29: janela | D29: 530.632
A30: Guarda corpo metálico – Área: 4,745m² x 19 = 90,155m² - Perímetro: 3,65m x 19 = 69,35m | C30: gradil | D30: 90.155
A31: Guarda corpo vidro – Área: 15,645m² x 19 = 297,255m² - Perímetro: 14,9m x 19 = 283,1m | C31: Guarda alumínio | D31: 297.255
A32: 2 portas corta-fogo 1 folha | B32: 2 | C32: pcf
A33: 2 portas de abrir madeira 1 folha | B33: 2 | C33: madeira
A34: 1 porta de abrir alumínio 1 folha – Área: 1,26m² | B34: 1 | C34: porta alumínio | D34: 1.26
A35: 1 janela-porta de correr vidro 3 folhas - Área: 15,21m² | B35: 1 | C35: janela | D35: 15.21
A36: 1 janela-porta de correr vidro 5 folhas - Área: 25,4205m² | B36: 1 | C36: janela | D36: 25.4205
A37: 1 janela-porta de correr vidro 5 folhas - Área: 17,8284m² | B37: 1 | C37: janela | D37: 17.8284
A38: Janelas – Área: 1,1 + 1,2 + 1,1 + 1,92 + 0,36 + 2,781 + 2,781 + 1,854 + 1,854 + 5,562 + 5,562 + 1,854 = 27,928m² | C38: janela | D38: 27.928
A39: Guarda corpo metálico – Área: 4,745m² - Perímetro: 3,65m | C39: gradil | D39: 4.745
A40: Guarda corpo vidro – Área: 15,645m² - Perímetro: 14,9m | C40: Guarda alumínio | D40: 15.645
A41: 2 portas corta-fogo 1 folha | B41: 2 | C41: pcf
...
