Workbook
Name \0: #REF!
Name \0: #REF!
Name \0: #REF!
Name \0: #REF!
Name \0: #REF!
Name \0: #REF!
Name \0: #REF!
Name \0: #REF!
Name \a: #REF!
Name \a: #REF!
Name \a: #REF!
Name \m: #REF!
Name \m: #REF!
Name \m: #REF!
Name _akhnsdkjsdb: #REF!
Name aa: #REF!
Name aa: #REF!
Name aa: #REF!
Name aa: #REF!
Name aa: #REF!
Name aa: #REF!
Name aa: #REF!
Name aa: #REF!
Name aaaa: #REF!
Name aaaa: #REF!
Name aaaa: #REF!
Name aaaa: #REF!
Name aaaa: #REF!
Name aaaa: #REF!
Name aaaa: #REF!
Name aaaa: #REF!
Name angelo: #REF!
Name angelo: #REF!
Name angelo: #REF!
Name angelo: #REF!
Name angelo: #REF!
Name angelo: #REF!
Name angelo: #REF!
Name area: #REF!
Name area: #REF!
Name area: #REF!
Name area: #REF!
Name area: #REF!
Name Areaimpresso: #REF!
Name Areaimpresso: #REF!
Name Areaimpresso: #REF!
Name Areaimpresso: #REF!
Name Areaimpresso: #REF!
Name aux: #REF!
Name aux: #REF!
Name aux: #REF!
Name BDA: #REF!
Name BDA: #REF!
Name BDA: #REF!
Name BDI: #REF!
Name ca: #REF!
Name Capa: #REF!
Name Composição: BASES!$I$72
Name cronograma: #REF!
Name cronograma: #REF!

Sheet EQUIPA FACHADA
A1: Obra | B1: ATALAIA
A2: Empresa | B2: GMF
A3: Revisão | B3: R00
A4: QUANTIFICAÇÃO
A6: Fachada
A8: Geral
B10: Opção | C10: Tempo de locação (mês) | D10: Ancoragens (un) | E10: Custo unitário locação (R$) | F10: Locação (R$) | G10: Custo unitário ancoragens (R$) | H10: Custo ancoragens (R$) | I10: Custo total (R$) | J10: Custo mensal (R$/mes)
B11: FCHADA SIMPLES (1 BALANCIM) | C11: 11.5 | D11: =4+4+5+5+6+6+6+7 -> 43 | E11: 1850 | F11: =C11*E11*1 -> 21275 | G11: 450 | H11: =G11*D11 -> 19350 | I11: =H11+F11+600+120 -> 41345 | J11: =I11/C11 -> 3595.2174
B12: *consideração de balancim com 4 metros
A14: Geral
B16: Opção | C16: Tempo de locação (mês) | D16: Custo unitário locação (R$) | E16: Locação (R$) | F16: Custo total (R$) | G16: Custo mensal (R$/mes)
B17: FCHADA SIMPLES (3 metros andaime) | C17: 2.5 | D17: 365 | E17: =C17*D17*1 -> 912.5 | F17: =E17+E18 -> 2100 | G17: =F17/5 -> 420
B18: FCHADA SIMPLES (7 metros andaime) | C18: =2.5 -> 2.5 | D18: 475 | E18: =C18*D18*1 -> 1187.5
B19: *consideração de balancim com 4 metros

Sheet OBRA
A1: Obra | B1: Viva Perequê Residencial
A2: Empresa | B2: Ferazzo e Correa Incorporadora
A3: Revisão | B3: R00
A4: DADOS OBRA
A6: ARQUITETURA
B8: Descrição | C8: Unidade | D8: Quantidade
B9: ÁREA DO TERRENO | C9: M2 | D9: 600
B10: ÁREA CONSTRUÍDA | C10: M2 | D10: 5576.17
B11: NÚMERO DE UNIDADES HABITACIONAIS | C11: UN | D11: 34
B12: MESES DE OBRA | C12: MÊS | D12: 35
B13: NÚMERO DE PAVIMENTOS | C13: UN | D13: 15

Sheet EPC's
A1: Obra | B1: =OBRA!B1 -> Viva Perequê Residencial
A2: Empresa | B2: =OBRA!B2 -> Ferazzo e Correa Incorporadora
A3: Revisão | B3: R00
A4: LEVANTAMENTO QUANTITATIVO
A6: Equipamentos de proteção coletiva
A8: Bandejas de proteção
B10: Descrição | C10: Unidade | D10: Quantidade
B11: Perímetro de projeção embasamento | C11: m | D11: =[9]DADOS_INICIAIS!$E$26 -> 93.06
B12: Perímetro de projeção torre | C12: m | D12: =[9]DADOS_INICIAIS!$E$20 -> 73.29
B13: Bandeja de proteção primária | C13: m | D13: =D11+(25-3.7)*2+(24-3.7*2) -> 152.26
B14: Bandeja de proteção secundária | C14: m | D14: =D12 -> 73.29
A16: Guarda - corpo de desforma
B18: Descrição | C18: Unidade | D18: Quantidade
B19: Perímetro de projeção da torre + vão do elevador | C19: m | D19: =#REF!+((1.75+1.75+1.75+1.75)*2) -> #REF!
B20: Repetições de pavimentos** | C20: un | D20: 19 | E20: (3 TIPOS + COBERTURA COM APRT)
B21: Proteção de periferia pós desforma torre | C21: m | D21: =(D19*D20) -> #REF!
A23: Tela fachadeira
B25: Descrição | C25: Unidade | D25: Quantidade
B26: Perímetro de projeção torre | C26: m | D26: =D19 -> #REF!
B27: Altura de cobrimento da tela | C27: m² | D27: 66.88
B28: Tela fachadeira | C28: m2 | D28: =D26*D27 -> #REF!
A29: Tela SLQA
B31: Descrição | C31: Unidade | D31: Quantidade
B32: Perímetro de projeção torre | C32: m | D32: =D19 -> #REF!
B33: Altura de cobrimento da tela | C33: m | D33: =D27-60.4 -> 6.48 | E33: ALTURA DOS 3 ULTIMOS PAVS
B34: Tela fachadeira | C34: m2 | D34: =D32*D33 -> #REF!
A36: Fechamento removível de vãos em madeira
B38: Descrição | C38: Unidade | D38: Quantidade
B39: Área das portas de elevadores | C39: m2 | D39: =11*1.935 -> 21.285
B40: Quantidade de elevadores | C40: un | D40: 2
B41: Quantidade de portas de elevadores | C41: un | D41: =D40*19 -> 38
B42: Fechamento removível de vãos em madeira | C42: m2 | D42: =D39*D41 -> 808.83
B43: Área das portas de aptos | C43: m2
B44: Quantidade de aptos | C44: un
B45: Quantidade de portas de aptos | C45: un
B46: =BASES!A77 -> Fechamento removível de vãos de porta de entrada dos aptos. em madeira | C46: m2 | D46: =(0.9*2.17)*(6+(4*6)+(4*6)+(4*2)+5) -> 130.851
B47: =BASES!A78 -> Fechamento removível de abertura no piso do elevador em madeira | C47: m2 | D47: =(D40*D41)*3.06 -> 232.56
A48: Guarda - corpo de vãos
B50: Descrição | C50: Unidade | D50: Quantidade
B51: Perímetro de vãos | C51: m | D51: =(1.59*28)+(1.95*17)+(5.13*28)+(1.6*11)+(3.32*15)+23.99+10.4 -> 323.1
...

Sheet CANTEIRO
A1: Obra | B1: =OBRA!B1 -> Viva Perequê Residencial
A2: Empresa | B2: =OBRA!B2 -> Ferazzo e Correa Incorporadora
A3: Revisão | B3: R00 | N3: Número de funcionários | R3: Produtividade média (h/m2)
A4: LEVANTAMENTO QUANTITATIVO | N4: Área construída | O4: =OBRA!D10 -> 5576.17 | R4: A.C/prazo | S4: =O4/O5 -> 159.31914
N5: Prazo da obra | O5: =OBRA!D12 -> 35 | P5: meses | R5: Pm | S5: 49 | T5: h/m2
A6: Instalações de canteiro | N6: NF | O6: =ROUNDUP((O4*S5)/O5/180,) -> 44 | P6: funcionários
N7: Pavimentos | O7: 9
A8: Instalações de canteiro | N8: Equipe administrativa | O8: 4 | P8: funcionários
B10: Descrição | C10: Unidade | D10: Quantidade
B11: Produtividade média | C11: h/m2 | D11: =OBRA!D10/OBRA!D12 -> 159.31914 | N11: Barracão interno | O11: =450+(O4-13000)/1000*16 -> 331.21872
B12: Pm | C12: h/m2 | D12: 49 | N12: Externo | O12: =O11*0.4 -> 132.48749
B13: Numero de funcionários | C13: un | D13: =ROUNDUP((D12*OBRA!D10)/OBRA!D12/180,) -> 44
B14: Equipe administrativa | C14: un | D14: 4 | O14: =SUM(O11:O13) -> 463.70621
B15: Pontos de água e esgoto | C15: un | D15: 3 | E15: 20 funcionários/ponto
B16: Bebedouro | C16: un | D16: =ROUNDUP(OBRA!$D$13/5,0) -> 3 | E16: 1 / 5 pav. | N16: Área refeitório | O16: 1 | P16: m²/funcionários
B17: Ferramentas | C17: R$ | D17: =800*(D13+D14) -> 38400 | E17: 800,00/func. | O17: =O16*O6 -> 44 | P17: m²
B18: EPI | C18: R$ | D18: =500*(D13+D14) -> 24000 | E18: 500,00/func. | H18: https://www.sienge.com.br/blog/dimensione-o-canteiro-de-obras-corretamente/
B19: Banheiro | C19: un | D19: =ROUNDUP(($D$13+D14)/20,0) -> 3 | E19: 1/20 func | N19: Área de vestiário | O19: 1.5 | P19: m²/funcionários
O20: =O19*O6 -> 66 | P20: m²
A21: Mobiliário de canteiro
B23: Descrição | C23: Unidade | D23: Quantidade | E23: Custo unitário | F23: Custo total
B24: Cadeira | C24: un | D24: =ROUNDUP(D25*1.5,0) -> 62 | E24: 200 | F24: =D24*E24 -> 12400
B25: Mesa | C25: un | D25: 41 | E25: 1000 | F25: =E25*D25 -> 41000
B26: Ar condicionado | C26: un | D26: 6 | E26: 5000 | F26: =E26*D26 -> 30000
B27: Armário | C27: m | D27: 13 | E27: 900 | F27: =E27*D27 -> 11700
B28: Cadeira | C28: un | D28: =ROUNDUP(D29*1.5,0) -> 48 | E28: 200 | F28: =D28*E28 -> 9600
B29: Escrivaninha | C29: un | D29: 32 | E29: 800 | F29: =E29*D29 -> 25600
B30: TOTAL | F30: =F26+F27+F29+F25+F24 -> 120700
B31: Descrição | C31: Unidade | D31: Quantidade | E31: Custo unitário | F31: Custo total
B32: Computador pessoal | C32: un | D32: 6 | E32: 6000 | F32: =D32*E32 -> 36000 | N32: Área sanitários | O32: =1*ROUNDUP(O6/20,) -> 3 | P32: m²
B33: Impressora | C33: un | D33: 1 | E33: 2000 | F33: =E33*D33 -> 2000
B34: Roteador | C34: un | D34: 6 | E34: 500 | F34: =E34*D34 -> 3000 | N34: área lavatório | O34: =0.6*ROUNDUP(O6/20,) -> 1.8 | P34: m²
B35: TOTAL | F35: =+F32+F33+F34 -> 41000 | N35: Área de chuveiros | O35: =0.8*ROUNDUP(O6/10,) -> 4 | P35: m²
N37: Escritório | O37: 8 | P37: m²/pessoa
O38: =O37*O8 -> 32 | P38: m²
N40: Almoxarifado | O40: =IF(O4<20000,100,100+((O4-20000)/1000)*5) -> 100 | P40: m2
O42: =O40+O38+O35+O34+O32+O20+O17 -> 250.8
N45: Pontos de água e esgoto | O45: 20 | P45: funcionários/ponto
N46: Pontos de água e esgoto | O46: =ROUNDUP(O6/O45,) -> 3 | P46: pontos
N49: Bebedouro | O49: 1 | P49: a cada 5 pav.
...

Sheet RESPOSTAS
A2: Carimbo de data/hora
A4: Endereço de e-mail
A5: Cliente
A6: Obra
A7: Responsável pelo questionário
A8: Data de preenchimento do formulário
A9: Memorial descritivo
A10: Levantamento topográfico
A11: Estudo geológico
A12: Estudo ambiental
A13: Sondagem do terreno
A14: Projeto de canteiro
... A16: Legalização de incorporação
A17: Projeto arquitetônico legal | C17: (legal e executivo)
A18: Projeto arquitetônico executivo
A19: Projeto arquitetônico interiores/ambientação
A20: Projeto arquitetônico de fachada
A21: Projeto técnico de fachada
A22: Projeto de terraplanagem
A23: Projeto de fundação
A24: Projeto estrutural em concreto armado | C24: (já com fundação)
A25: Projeto de estrutura metálica
A26: Projeto de alvenaria estrutural
A27: Projeto elétrico | C27: (elétrico / comunicação / telefonia)
A28: Projeto comunicação e dados
A29: Projeto de telefonia
A30: Projeto luminotécnico
A31: Projeto de automação | C31: (automação / segurança / cftv )
A32: Projeto hidrossanitário | C32: (hidráulico e sanitário)
A33: Projeto de drenagem
A34: Projeto pluvial
A35: Projeto de irrigação
A36: Projeto preventivo (PPCI - Plano de Prevenção e Proteção Contra Incêndios)
A37: Projeto de climatização | C37: (climatização e exaustão)
A38: Projeto de exaustão
A39: Projeto de gás
A40: Projeto de segurança
A41: Projeto de impermeabilização
A42: Projeto de esquadrias
A43: Projeto de forro
...

Sheet COMPOSIÇÃO
F2: UNIDADE | G2: QUANT. | H2: PREÇO
D3: SERVIÇO | E3: Bandeja primaria - 1 montagem | F3: =BASES!E41 -> vb | G3: =BASES!F41 -> 1 | H3: =(G4*H4)+(G6*H6)+(G9*H9)+(G5*H5)+(G7*H7)+(G8*H8) -> 524.26322
D4: COMPOSIÇÃO | E4: Prego de aço polido com cabeça 17x21 | F4: kg | G4: 0.1238 | H4: 14.65
E5: tabua pinus 3a construção 2,5x30 cm | F5: m | G5: 3.903005 | H5: 21.3
E6: Suporte de plataforma de proteção primaria principal perfil em u em aço de 3 mm 2500x800x40x75x40 mm com caibro e pino de fixação | F6: UNIDADE | G6: 0.4 | H6: 218
E7: Chapa/painel de madeira compensada plastificada ( madeirite plastificado) para forma de concreto, de 2200 x 1100 mm, e = 14 mm | F7: m² | G7: 4.0201 | H7: 57.28
E8: Tábua Pinus 2,5x15 cm | F8: m | G8: 1.831333 | H8: 11.96
E9: Aço CA-50 Ø 16,00 mm - Vergalhão | F9: kg | G9: 1.3676 | H9: 73.078
F32: UNIDADE | G32: QUANT. | H32: PREÇO
D33: SERVIÇO | E33: =BASES!A77 -> Fechamento removível de vãos de porta de entrada dos aptos. em madeira | F33: M² | G33: =BASES!F77 -> 130.851 | H33: =(G34*H34)+(G35*H35) -> 6.14475
D34: COMPOSIÇÃO | E34: Prego de aço polido com cabeça 17x21 | F34: KG | G34: 0.015 | H34: 14.65
E35: Sarrafo 2,5x7,5 em pinus | F35: M | G35: 1.975 | H35: 3
F39: UNIDADE | G39: QUANT. | H39: PREÇO
D40: SERVIÇO | E40: =BASES!A75 -> Guarda-corpo de laje após desforma - Escora metálica, travessões e tela | F40: =BASES!E75 -> m | G40: =BASES!F75 -> #REF! | H40: =(G41*H41)+(G43*H43)+(G44*H44)+(G42*H42) -> 36.92914
D41: COMPOSIÇÃO | E41: TELA PLASTICA TECIDA LISTRADA BRANCA E LARANJA, TIPO GUARDA CORPO, EM POLIETILENO MONOFILADO, ROLO 1,20 X 50 M (L X C) | F41: M | G41: 0.55 | H41: 2.73
E42: TABUA APARELHADA *2,5 X 15* CM, EM MACARANDUBA/MASSARANDUBA, ANGELIM OU EQUIVALENTE DA REGIAO | F42: M² | G42: 0.233 | H42: 144.68
E43: LOCACAO DE ESCORA METALICA TELESCOPICA, COM ALTURA REGULAVEL DE *1,80* A *3,20* M, COM CAPACIDADE DE CARGA DE NO MINIMO 1000 KGF (10 KN), INCLUSO TRIPE E FORCADO | F43: UNXMES | G43: 0.1 | H43: 16
E44: Prego de aço polido com cabeça 17x21 | F44: KG | G44: 0.008 | H44: 14.65
F47: UNIDADE | G47: QUANT. | H47: PREÇO
D48: SERVIÇO | E48: TOTEM EM MADEIRA COM PLACA INDICATIVA POSICIONADA NO TERRENO | F48: =BASES!#REF! -> #REF! | G48: =BASES!F87 -> 1 | H48: =(G49*H49)+(G51*H51)+(G52*H52)+(G50*H50) -> 360.9236
D49: COMPOSIÇÃO | E49: CHAPA/PAINEL DE MADEIRA COMPENSADA RESINADA (MADEIRITE RESINADO ROSA) PARA FORMA DE CONCRETO, DE 2200 x 1100 MM, E = 14 MMROLO 1,20 X 50 M (L X C) | F49: M² | G49: 5.9392 | H49: 57.28
E50: PLACA DE SINALIZACAO DE SEGURANCA, FOTOLUMINESCENTE, EM PVC *2* MM ANTI-CHAMAS (SIMBOLOS, CORES E PICTOGRAMAS CONFORME NBR 13434) | F50: M² | G50: 1 | H50: 12
E51: GRAMPO PARA GRAMPEADOR PNEUMATICO 13 X 16 MM | F51: UNIDADE | G51: 0.011 | H51: =1113.63/18000 -> 0.061868333
E52: Prego de aço polido com cabeça 17x21 | F52: KG | G52: 0.5956 | H52: 14.65
F55: UNIDADE | G55: QUANT. | H55: PREÇO
D56: SERVIÇO | E56: =BASES!A125 -> Tapume de TELHA METÁLICA TRAPEZOIDAL | F56: =BASES!E125 -> m2 | G56: =BASES!F125 -> 220 | H56: =(G57*H57)+(G60*H60)+(G61*H61)+(G58*H58)+(G59*H59) -> 132.54723
D57: COMPOSIÇÃO | E57: Prego de aço 18x27 com cabeça | F57: kg | G57: 0.0428 | H57: 12.12
E58: Tábua de madeira 2,5x30 | F58: m | G58: 1 | H58: 21.3
E59: Telha aço zincado trapezoidal | F59: m² | G59: 1.05 | H59: 97
E60: vigota 7,5x7,5 cm | F60: m | G60: 1.2273 | H60: 6.89
E61: Concreto magro 150 kg cim/m³ | F61: m³ | G61: 0.0012 | H61: 352

Sheet BASES
A1: ="ORÇAMENTO EXECUTIVO - "&UPPER(OBRA!B1) -> ORÇAMENTO EXECUTIVO - VIVA PEREQUÊ RESIDENCIAL
L2: Área Const. | M2: =NOUVE!B9 -> 5438.9 | N2: Área Const. | O2: =VANCOUVER!B6 -> 5554.12 | P2: Área Const. | Q2: ='VILLA LOBOS'!B7 -> 6001.7 | R2: Área Const. | S2: ='GRAN TOWER'!B8 -> 6245.48 | T2: Área Const. | U2: =[3]OBRA!D10 -> 6348.51
A3: Empresa: | B3: =OBRA!B2 -> Ferazzo e Correa Incorporadora | L3: Data base | M3: =NOUVE!B10 -> 44805 | N3: Data base | O3: =VANCOUVER!B7 -> 44621 | P3: Data base | Q3: ='VILLA LOBOS'!B8 -> 45108 | R3: Data base | S3: ='GRAN TOWER'!B9 -> 45383 | T3: Data base | U3: =[3]OBRA!D14 -> 45413
A4: Obra: | B4: =OBRA!B1 -> Viva Perequê Residencial | L4: cub | M4: =NOUVE!B11 -> 2623.42 | N4: cub | O4: =VANCOUVER!B8 -> 2444.3 | P4: cub | Q4: ='VILLA LOBOS'!B9 -> 2747.9 | R4: cub | S4: ='GRAN TOWER'!B10 -> 2757.56 | T4: cub | U4: 2755.41 | W4: MABREM - GRAN TORINO | X4: =U4/[4]ORÇAMENTO_EXECUTIVO!$B$19 -> 0.99922033
A5: Revisão | L5: Index | M5: =($U$4/M4) -> 1.0503122 | N5: Index | O5: =($U$4/O4) -> 1.1272798 | P5: Index | Q5: =($U$4/Q4) -> 1.002733 | R5: Index | S5: =($U$4/S4) -> 0.99922033 | T5: Index | W5: GMF - ATALAIA | X5: =U4/[5]ORÇAMENTO_EXECUTIVO!$F$22 -> 0.99922033
A6: Data: | B6: 45441 | L6: Á. Terreno | M6: =NOUVE!B8 -> 0 | N6: Á. Terreno | O6: =VANCOUVER!B5 -> 0 | P6: Á. Terreno | Q6: ='VILLA LOBOS'!B6 -> 553.46 | R6: Á. Terreno | S6: ='GRAN TOWER'!B7 -> 859.95 | T6: Á. Terreno | U6: =[3]OBRA!D9 -> 624 | W6: AS RAMOS - PAESSAGIO | X6: =U4/[6]BASES!$Q$4 -> 1.0278159
L7: HOLZE | N7: =VANCOUVER!B4 -> PASS-E | P7: ='[3]VILLA LOBOS'!B5 -> MACOM | R7: ='GRAN TOWER'!B5 -> GRANDEZZA | T7: =B3 -> Ferazzo e Correa Incorporadora
A8: DESPESAS INDIRETAS | L8: =NOUVE!B5 -> NOUVE 354 | N8: =VANCOUVER!B3 -> VANCOUVER | P8: ='[3]VILLA LOBOS'!B4 -> VILLA LOBOS | R8: ='GRAN TOWER'!B4 -> GRAN TOWER | T8: =B4 -> Viva Perequê Residencial
A9: Descrição | E9: Unidade | F9: Quantidade | G9: Valor (R$) | H9: Total | I9: Consideração | J9: Status | L9: Valor | M9: Referencia | N9: Valor | O9: Referencia | P9: Valor | Q9: Referencia | R9: Valor | S9: Referencia | T9: m² | U9: Total
A10: TERRENO
A11: Memorial descritivo | E11: vb | F11: 1 | G11: =U11 -> 6867.9583 | H11: =F11*G11 -> 6867.9583 | I11: Média | J11: Lançado Sienge | L11: =NOUVE!E19 -> 0 | M11: =(L11*$M$5)/$M$2 -> 0 | O11: =(N11*$O$5)/$O$2 -> 0 | P11: ='VILLA LOBOS'!E16 -> 6449 | Q11: =(P11*$Q$5)/$Q$2 -> 1.0774656 | R11: ='GRAN TOWER'!E17 -> 6789 | S11: =(R11*$S$5)/$S$2 -> 1.0861786 | T11: =(Q11+S11)/2 -> 1.0818221 | U11: =T11*$U$2 -> 6867.9583
A12: Estudo ambiental | E12: vb | F12: 1 | G12: 3866.34 | H12: =F12*G12 -> 3866.34 | I12: Informado no Formulário | J12: Lançado Sienge | L12: =NOUVE!E21 -> 3600 | M12: =(L12*$M$5)/$M$2 -> 0.69520011 | N12: =VANCOUVER!E15 -> 5100 | O12: =(N12*$O$5)/$O$2 -> 1.0351103 | P12: ='VILLA LOBOS'!E19 -> 3794 | Q12: =(P12*$Q$5)/$Q$2 -> 0.6338819 | R12: ='VILLA LOBOS'!G19 -> 0 | S12: =(R12*$S$5)/$S$2 -> 0 | T12: =(Q12+M12+O12)/3 -> 0.78806411 | U12: =T12*$U$2 -> 5003.0329
A13: Levantamento topográfico | E13: vb | F13: 1 | G13: 900 | H13: =F13*G13 -> 900 | I13: Informado no Formulário | J13: Lançado Sienge | L13: =NOUVE!E20 -> 1021 | M13: =(L13*$M$5)/$M$2 -> 0.19716648 | N13: =VANCOUVER!E14 -> 400 | O13: =(N13*$O$5)/$O$2 -> 0.081185123 | P13: ='VILLA LOBOS'!E17 -> 1200 | Q13: =(P13*$Q$5)/$Q$2 -> 0.20048979 | R13: ='VILLA LOBOS'!G17 -> 0 | S13: =(R13*$S$5)/$S$2 -> 0 | T13: =(Q13+M13+O13)/3 -> 0.1596138 | U13: =T13*$U$2 -> 1013.3098
A14: Estudo geológico | E14: vb | F14: 1 | G14: =U14 -> 5459.9107 | H14: =F14*G14 -> 5459.9107 | I14: Média | J14: Lançado Sienge | M14: =(L14*$M$5)/$M$2 -> 0 | O14: =(N14*$O$5)/$O$2 -> 0 | P14: ='VILLA LOBOS'!E18 -> 3794 | Q14: =(P14*$Q$5)/$Q$2 -> 0.6338819 | R14: ='GRAN TOWER'!E19 -> 6789 | S14: =(R14*$S$5)/$S$2 -> 1.0861786 | T14: =(Q14+S14)/2 -> 0.86003025 | U14: =T14*$U$2 -> 5459.9107
A15: Sondagem do terreno | E15: vb | F15: 1 | G15: 6586 | H15: =F15*G15 -> 6586 | I15: Informado no Formulário | J15: Lançado Sienge | L15: =NOUVE!E22 -> 8204 | M15: =(L15*$M$5)/$M$2 -> 1.5842838 | N15: =VANCOUVER!E16 -> 4369.97 | O15: =(N15*$O$5)/$O$2 -> 0.88694138 | P15: ='VILLA LOBOS'!E20 -> 9000 | Q15: =(P15*$Q$5)/$Q$2 -> 1.5036735 | R15: ='VILLA LOBOS'!G20 -> 0 | S15: =(R15*$S$5)/$S$2 -> 0 | T15: =(Q15+M15+O15)/3 -> 1.3249662 | U15: =T15*$U$2 -> 8411.5613
A16: =RESPOSTAS!A14 -> Projeto de canteiro | E16: vb | F16: 1 | G16: =U16 -> 6895.6158 | H16: =F16*G16 -> 6895.6158 | I16: Média | J16: Lançado Sienge | L16: =NOUVE!E23 -> 0 | M16: =(L16*$M$5)/$M$2 -> 0 | O16: =(N16*$O$5)/$O$2 -> 0 | Q16: =(P16*$Q$5)/$Q$2 -> 0 | R16: ='GRAN TOWER'!E22 -> 6789 | S16: =(R16*$S$5)/$S$2 -> 1.0861786 | T16: =S16 -> 1.0861786 | U16: =T16*$U$2 -> 6895.6158 | X16: =$W$4 -> MABREM - GRAN TORINO | Y16: =( 3600*$X$5)/[4]ORÇAMENTO_EXECUTIVO!$G$2 -> 0.28733962
A17: =RESPOSTAS!A16 -> Legalização de incorporação | E17: vb | F17: 1 | G17: 14611.4 | H17: =F17*G17 -> 14611.4 | I17: Informado no Formulário | J17: Lançado Sienge | M17: =(L17*$M$5)/$M$2 -> 0 | N17: =VANCOUVER!E18 -> 8000 | O17: =(N17*$O$5)/$O$2 -> 1.6237025 | P17: ='VILLA LOBOS'!E22 -> 11291 | Q17: =(P17*$Q$5)/$Q$2 -> 1.8864419 | R17: ='VILLA LOBOS'!G22 -> 0 | S17: =(R17*$S$5)/$S$2 -> 0 | T17: =(Q17+O17)/2 -> 1.7550722 | U17: =T17*$U$2 -> 11142.093 | V17: =W5 -> GMF - ATALAIA | W17: =(12000*$X$5)/[5]ORÇAMENTO_EXECUTIVO!$N$4 -> 1.6260308 | Z17: =$W$4 -> MABREM - GRAN TORINO | AA17: =( 12000*$X$5)/[4]ORÇAMENTO_EXECUTIVO!$G$2 -> 0.95779872
A18: PROJETOS
A19: Projeto arquitetôico executivo | E19: vb | F19: 1 | G19: 80000 | H19: =F19*G19 -> 80000 | I19: Informado no Formulário | J19: Lançado Sienge | M19: =(L19*$M$5)/$M$2 -> 0 | N19: =VANCOUVER!E20+VANCOUVER!E21 -> 62064.16 | O19: =(N19*$O$5)/$O$2 -> 12.596716 | P19: ='VILLA LOBOS'!E24 -> 25629 | Q19: =(P19*$Q$5)/$Q$2 -> 4.2819608 | R19: ='VILLA LOBOS'!G24 -> 0 | S19: =(R19*$S$5)/$S$2 -> 0 | T19: =(Q19+O19)/2 -> 8.4393385 | U19: =T19*$U$2 -> 53577.225
A20: Projeto arquitetôico legal + executivo + elétrico+ comunicação + telefonia+luminotécnico+hidrosanitario+drenagem+pluvial+gás | E20: vb | F20: 1 | I20: Informado no Formulário | J20: Lançado Sienge | L20: =NOUVE!E25 -> 100000 | M20: =(L20*$M$5)/$M$2 -> 19.311114 | N20: =VANCOUVER!E19 -> 20297.38 | O20: =(N20*$O$5)/$O$2 -> 4.1196132 | P20: ='VILLA LOBOS'!E23 -> 22991 | Q20: =(P20*$Q$5)/$Q$2 -> 3.8412174 | R20: ='VILLA LOBOS'!G23 -> 0 | S20: =(R20*$S$5)/$S$2 -> 0 | T20: =(Q20+M20+O20)/3 -> 9.0906483 | U20: =T20*$U$2 -> 57712.071
A21: Projeto fachada | E21: vb | F21: 1 | G21: =U21 -> 2721.4845 | H21: =F21*G21 -> 2721.4845 | I21: Média | J21: Lançado Sienge | M21: =(L21*$M$5)/$M$2 -> 0 | N21: =VANCOUVER!E22 -> 2500 | O21: =(N21*$O$5)/$O$2 -> 0.50740702 | Q21: =(P21*$Q$5)/$Q$2 -> 0 | R21: ='GRAN TOWER'!E28 -> 2187.34 | S21: =(R21*$S$5)/$S$2 -> 0.34995462 | T21: =(O21+S21)/2 -> 0.42868082 | U21: =T21*$U$2 -> 2721.4845
A22: Projeto de interiores - interiores | E22: vb | F22: 1 | G22: =U22 -> 68955.142 | H22: =F22*G22 -> 68955.142 | I22: Média | J22: Lançado Sienge | M22: =(L22*$M$5)/$M$2 -> 0 | O22: =(N22*$O$5)/$O$2 -> 0 | Q22: =(P22*$Q$5)/$Q$2 -> 0 | R22: ='GRAN TOWER'!E27 -> 67889 | S22: =(R22*$S$5)/$S$2 -> 10.861626 | T22: =S22 -> 10.861626 | U22: =T22*$U$2 -> 68955.142
A23: Projeto fundação | E23: vb | F23: 1 | G23: =U23 -> 14739.662 | H23: =F23*G23 -> 14739.662 | I23: Informado no Formulário | J23: Lançado Sienge | L23: =NOUVE!E26 -> 11200 | M23: =(L23*$M$5)/$M$2 -> 2.1628448 | N23: =VANCOUVER!E23 -> 12222.23 | O23: =(N23*$O$5)/$O$2 -> 2.4806581 | Q23: =(P23*$Q$5)/$Q$2 -> 0 | S23: =(R23*$S$5)/$S$2 -> 0 | T23: =(M23+O23)/2 -> 2.3217515 | U23: =T23*$U$2 -> 14739.662
A24: Projeto terraplanagem | E24: vb | F24: 1 | G24: =U24 -> 0 | H24: =F24*G24 -> 0 | I24: Informado no Formulário | J24: Lançado Sienge | M24: =(L24*$M$5)/$M$2 -> 0 | O24: =(N24*$O$5)/$O$2 -> 0 | Q24: =(P24*$Q$5)/$Q$2 -> 0 | S24: =(R24*$S$5)/$S$2 -> 0 | T24: =(M24+O24)/2 -> 0 | U24: =T24*$U$2 -> 0
A25: Projeto estrutural | E25: vb | F25: 1 | G25: =U25 -> 72163.128 | H25: =F25*G25 -> 72163.128 | I25: Informado no Formulário | J25: Lançado Sienge | L25: =NOUVE!E27 -> 52450 | M25: =(L25*$M$5)/$M$2 -> 10.128679 | N25: =VANCOUVER!E24 -> 48634.64 | O25: =(N25*$O$5)/$O$2 -> 9.8710231 | P25: ='VILLA LOBOS'!E28 -> 84400 | Q25: =(P25*$Q$5)/$Q$2 -> 14.101115 | R25: ='VILLA LOBOS'!G28 -> 0 | S25: =(R25*$S$5)/$S$2 -> 0 | T25: =(Q25+M25+O25)/3 -> 11.366939 | U25: =T25*$U$2 -> 72163.128
A26: Projeto estrutura metálica | E26: vb | F26: 1 | G26: =U26 -> 30471.126 | H26: =F26*G26 -> 30471.126 | I26: Média | J26: Lançado Sienge | L26: =NOUVE!E28 -> 0 | M26: =(L26*$M$5)/$M$2 -> 0 | O26: =(N26*$O$5)/$O$2 -> 0 | Q26: =(P26*$Q$5)/$Q$2 -> 0 | R26: ='GRAN TOWER'!E31 -> 30000 | S26: =(R26*$S$5)/$S$2 -> 4.7997287 | T26: =S26 -> 4.7997287 | U26: =T26*$U$2 -> 30471.126
A27: Projeto de alvenaria estrutural | E27: vb | F27: 1 | G27: 1385000 | H27: =F27*G27 -> 1385000 | I27: Informado no Formulário | J27: Lançado Sienge | L27: =NOUVE!E29 -> 0 | M27: =(L27*$M$5)/$M$2 -> 0 | O27: =(N27*$O$5)/$O$2 -> 0 | Q27: =(P27*$Q$5)/$Q$2 -> 0 | S27: =(R27*$S$5)/$S$2 -> 0 | T27: =(Q27+M27+O27)/3 -> 0 | U27: =T27*$U$2 -> 0
A28: Projeto automação | E28: vb | F28: 1 | G28: =U28 -> 2031.4084 | H28: =F28*G28 -> 2031.4084 | I28: Média | J28: Lançado Sienge | M28: =(L28*$M$5)/$M$2 -> 0 | O28: =(N28*$O$5)/$O$2 -> 0 | Q28: =(P28*$Q$5)/$Q$2 -> 0 | R28: ='GRAN TOWER'!E33 -> 2000 | S28: =(R28*$S$5)/$S$2 -> 0.31998191 | T28: =S28 -> 0.31998191 | U28: =T28*$U$2 -> 2031.4084
A29: Projeto irrigação | E29: vb | F29: 1 | G29: =U29 -> 0 | H29: =F29*G29 -> 0 | I29: Média | J29: Pendente | M29: =(L29*$M$5)/$M$2 -> 0 | O29: =(N29*$O$5)/$O$2 -> 0 | Q29: =(P29*$Q$5)/$Q$2 -> 0 | S29: =(R29*$S$5)/$S$2 -> 0 | U29: =T29*$U$2 -> 0
A30: Projeto paisagismo | E30: vb | F30: 1 | G30: =U30 -> 3990.4104 | H30: =F30*G30 -> 3990.4104 | I30: Média | J30: Lançado Sienge | M30: =(L30*$M$5)/$M$2 -> 0 | N30: =VANCOUVER!E28 -> 5000 | O30: =(N30*$O$5)/$O$2 -> 1.014814 | Q30: =(P30*$Q$5)/$Q$2 -> 0 | R30: ='GRAN TOWER'!E39 -> 1514.48 | S30: =(R30*$S$5)/$S$2 -> 0.24230311 | T30: =(O30+S30)/2 -> 0.62855857 | U30: =T30*$U$2 -> 3990.4104
A31: Projeto preventivo | E31: vb | F31: 1 | G31: =U31 -> 8226.7037 | H31: =F31*G31 -> 8226.7037 | I31: Informado no Formulário | J31: Lançado Sienge | M31: =(L31*$M$5)/$M$2 -> 0 | N31: =VANCOUVER!E27 -> 8850 | O31: =(N31*$O$5)/$O$2 -> 1.7962209 | Q31: =(P31*$Q$5)/$Q$2 -> 0 | R31: ='GRAN TOWER'!E35 -> 4972 | S31: =(R31*$S$5)/$S$2 -> 0.79547504 | T31: =(O31+S31)/2 -> 1.2958479 | U31: =T31*$U$2 -> 8226.7037
A32: Projeto comunicação visual | E32: vb | F32: 1 | G32: =U32 -> 5154.0457 | H32: =F32*G32 -> 5154.0457 | I32: Média | J32: Lançado Sienge | M32: =(L32*$M$5)/$M$2 -> 0 | N32: =VANCOUVER!E29 -> 4000 | O32: =(N32*$O$5)/$O$2 -> 0.81185123 | Q32: =(P32*$Q$5)/$Q$2 -> 0 | S32: =(R32*$S$5)/$S$2 -> 0 | T32: =O32 -> 0.81185123 | U32: =T32*$U$2 -> 5154.0457
A33: Projeto de climatização | E33: vb | F33: 1 | G33: =U33 -> 5477.6928 | H33: =F33*G33 -> 5477.6928 | I33: Média | J33: Lançado Sienge | M33: =(L33*$M$5)/$M$2 -> 0 | O33: =(N33*$O$5)/$O$2 -> 0 | P33: ='VILLA LOBOS'!E26 -> 3000 | Q33: =(P33*$Q$5)/$Q$2 -> 0.50122448 | R33: ='GRAN TOWER'!E36 -> 7653.17 | S33: =(R33*$S$5)/$S$2 -> 1.224438 | T33: =(Q33+S33)/2 -> 0.86283124 | U33: =T33*$U$2 -> 5477.6928
A34: Projeto de exaustão | E34: vb | F34: 1 | G34: =U34 -> 3182.0287 | H34: =F34*G34 -> 3182.0287 | I34: Média | J34: Lançado Sienge | M34: =(L34*$M$5)/$M$2 -> 0 | O34: =(N34*$O$5)/$O$2 -> 0 | P34: ='VILLA LOBOS'!E27 -> 3000 | Q34: =(P34*$Q$5)/$Q$2 -> 0.50122448 | R34: ='VILLA LOBOS'!G27 -> 0 | S34: =(R34*$S$5)/$S$2 -> 0 | T34: =Q34 -> 0.50122448 | U34: =T34*$U$2 -> 3182.0287
A35: Projeto de impermeabilização | E35: vb | F35: 1 | G35: =U35 -> 29119.213 | H35: =F35*G35 -> 29119.213 | I35: Média | J35: Lançado Sienge | M35: =(L35*$M$5)/$M$2 -> 0 | O35: =(N35*$O$5)/$O$2 -> 0 | Q35: =(P35*$Q$5)/$Q$2 -> 0 | R35: ='GRAN TOWER'!E37 -> 28668.99 | S35: =(R35*$S$5)/$S$2 -> 4.5867792 | T35: =S35 -> 4.5867792 | U35: =T35*$U$2 -> 29119.213
A36: Projeto de acústico | E36: vb | F36: 1 | G36: =U36 -> 0 | H36: =F36*G36 -> 0 | I36: Média | J36: Pendente | M36: =(L36*$M$5)/$M$2 -> 0 | O36: =(N36*$O$5)/$O$2 -> 0 | Q36: =(P36*$Q$5)/$Q$2 -> 0 | S36: =(R36*$S$5)/$S$2 -> 0 | U36: =T36*$U$2 -> 0
A37: Projeto de esquadrias | E37: vb | F37: 1 | G37: =U37 -> 0 | H37: =F37*G37 -> 0 | I37: Média | J37: Pendente | M37: =(L37*$M$5)/$M$2 -> 0 | O37: =(N37*$O$5)/$O$2 -> 0 | Q37: =(P37*$Q$5)/$Q$2 -> 0 | R37: ='VILLA LOBOS'!G30 -> 0 | S37: =(R37*$S$5)/$S$2 -> 0 | T37: =Q37 -> 0 | U37: =T37*$U$2 -> 0
A38: Projeto de forro | E38: vb | F38: 1 | G38: =U38 -> 0 | H38: =F38*G38 -> 0 | I38: Média | J38: Pendente | M38: =(L38*$M$5)/$M$2 -> 0 | O38: =(N38*$O$5)/$O$2 -> 0 | Q38: =(P38*$Q$5)/$Q$2 -> 0 | S38: =(R38*$S$5)/$S$2 -> 0 | U38: =T38*$U$2 -> 0
A39: Projeto de sonorização | E39: vb | F39: 1 | G39: =U39 -> 0 | H39: =F39*G39 -> 0 | I39: Média | J39: Pendente | M39: =(L39*$M$5)/$M$2 -> 0 | O39: =(N39*$O$5)/$O$2 -> 0 | Q39: =(P39*$Q$5)/$Q$2 -> 0 | S39: =(R39*$S$5)/$S$2 -> 0 | U39: =T39*$U$2 -> 0
A40: Projeto de piscina | E40: vb | F40: 1 | G40: =U40 -> 2582.0521 | H40: =F40*G40 -> 2582.0521 | I40: Média | J40: Lançado Sienge | M40: =(L40*$M$5)/$M$2 -> 0 | O40: =(N40*$O$5)/$O$2 -> 0 | Q40: =(P40*$Q$5)/$Q$2 -> 0 | R40: ='GRAN TOWER'!E38 -> 2542.13 | S40: =(R40*$S$5)/$S$2 -> 0.40671781 | T40: =S40 -> 0.40671781 | U40: =T40*$U$2 -> 2582.0521
...

Sheet NOUVE
A5: Obra | B5: NOUVE 354
A6: CONSTRUTORA | B6: HOUZE
A7: Endereço da obra
A8: AREA TERRENO
A9: Unidade construtiva M² | B9: 5438.9
A10: ANO | B10: 44805
A11: CUB | B11: 2623.42
A15: Código | B15: Descrição | C15: Un. | D15: Quantidade orçada | E15: Preço unitário | F15: Preço total
A16: 01 | B16: ESTUDOS, PROJETOS E CONSULTORIAS | F16: 236049.5
A17: 01.001 | B17: ESTUDOS, PROJETOS E CONSULTORIAS | F17: 236049.5
A18: 01.001.001 | B18: Estudos | F18: 12825
A19: 01.001.001.001 | B19: Memorial descritivo | C19: vb | D19: 0 | E19: 0 | F19: 0
A20: 01.001.001.002 | B20: Levantamento Topográfico | C20: vb | D20: 1 | E20: 1021 | F20: 1021
A21: 01.001.001.003 | B21: Estudo ambiental | C21: vb | D21: 1 | E21: 3600 | F21: 3600
A22: 01.001.001.004 | B22: Sondagem do terreno | C22: vb | D22: 1 | E22: 8204 | F22: 8204
A23: 01.001.001.005 | B23: Projeto de canteiro | C23: vb | D23: 0 | E23: 0 | F23: 0
A24: 01.001.002 | B24: Projetos | F24: 163650
A25: 01.001.002.001 | B25: Projeto Arquitetônico legal | C25: vb | D25: 1 | E25: 100000 | F25: 100000
A26: 01.001.002.002 | B26: Projeto Fundações | C26: vb | D26: 1 | E26: 11200 | F26: 11200
A27: 01.001.002.003 | B27: Projeto Estrutural | C27: vb | D27: 1 | E27: 52450 | F27: 52450
A28: 01.001.002.004 | B28: Projeto de automação | C28: vb | D28: 0 | E28: 0 | F28: 0
A29: 01.001.002.005 | B29: Projeto de climatização, exaustão e acústico | C29: vb | D29: 0 | E29: 0 | F29: 0
A30: 01.001.002.006 | B30: Projeto de impermeabilização | C30: vb | D30: 0 | E30: 0 | F30: 0
A31: 01.001.003 | B31: Consultorias | F31: 27500
A32: 01.001.003.001 | B32: Orçamento e planejamento | C32: vb | D32: 1 | E32: 27500 | F32: 27500
A33: 01.001.004 | B33: Ensaios e Laudos | F33: 32074.5
A34: 01.001.004.001 | B34: Controle Tecnologico de Concreto | C34: m3 | D34: 2138.3 | E34: 15 | F34: 32074.5
A35: 02 | B35: TAXAS, DOCUMENTOS | F35: 659910.95
A36: 02.001 | B36: TAXAS, DOCUMENTOS | F36: 659910.95
A37: 02.001.001 | B37: Taxas e Documentos | F37: 659910.95
A38: 02.001.001.001 | B38: Despesas de Seguros | C38: vb | D38: 1 | E38: 10000 | F38: 10000
A39: 02.001.001.002 | B39: Aprovação e legalização ambiental | C39: vb | D39: 1 | E39: 7000 | F39: 7000
A40: 02.001.001.003 | B40: Aprovação e legalização prefeitura | C40: vb | D40: 1 | E40: 12500 | F40: 12500
A41: 02.001.001.004 | B41: Aprovação e legalização água e esgoto | C41: vb | D41: 1 | E41: 5000 | F41: 5000
A42: 02.001.001.005 | B42: Aprovação e legalização elétrico | C42: vb | D42: 1 | E42: 3537.26 | F42: 3537.26
A43: 02.001.001.006 | B43: Aprovação e legalização Bombeiros | C43: vb | D43: 1 | E43: 4000 | F43: 4000
A44: 02.001.001.007 | B44: Taxas de ART | C44: vb | D44: 1 | E44: 1414.9 | F44: 1414.9
A45: 02.001.001.008 | B45: Taxas de Alvará | C45: vb | D45: 1 | E45: 51458.79 | F45: 51458.79
A46: 02.001.001.009 | B46: Outorga | C46: vb | D46: 1 | E46: 500000 | F46: 500000
A47: 02.001.001.010 | B47: Despesas de cartório / taxas gerais | C47: vb | D47: 1 | E47: 25000 | F47: 25000
...

Sheet VANCOUVER
A3: Obra | B3: VANCOUVER
A4: CONSTRUTORA | B4: PASS-E
A5: AREA TERRENO
A6: Unidade construtiva M² | B6: 5554.12
A7: ANO | B7: 44621
A8: CUB | B8: 2444.3
A10: Código | B10: Descrição | C10: Un. | D10: Quantidade orçada | E10: Preço unitário | F10: Preço total
A11: 01 | B11: ESTUDOS, PROJETOS E CONSULTORIAS | F11: 289667
A12: 01.001 | B12: ESTUDOS, PROJETOS E CONSULTORIAS | F12: 289667
A13: 01.001.001 | B13: Estudos | F13: 9869.97
A14: 01.001.001.001 | B14: Levantamento topográfico | C14: vb | D14: 1 | E14: 400 | F14: 400
A15: 01.001.001.002 | B15: Estudo ambiental | C15: vb | D15: 1 | E15: 5100 | F15: 5100
A16: 01.001.001.003 | B16: Sondagem do terreno | C16: vb | D16: 1 | E16: 4369.97 | F16: 4369.97
A17: 01.001.002 | B17: Projetos | F17: 225779.59
A18: 01.001.002.001 | B18: Legalização de incorporação* | C18: vb | D18: 1 | E18: 8000 | F18: 8000
A19: 01.001.002.002 | B19: Projeto arquitetônico legal* | C19: vb | D19: 1 | E19: 20297.38 | F19: 20297.38
A20: 01.001.002.003 | B20: Projeto arquitetônico | C20: vb | D20: 1 | E20: 44464.16 | F20: 44464.16
A21: 01.001.002.004 | B21: Projeto arquitetônico interiores/ambientação* | C21: vb | D21: 1 | E21: 17600 | F21: 17600
A22: 01.001.002.005 | B22: Projeto técnico de fachada* | C22: vb | D22: 1 | E22: 2500 | F22: 2500
A23: 01.001.002.006 | B23: Projeto de fundação* | C23: vb | D23: 1 | E23: 12222.23 | F23: 12222.23
A24: 01.001.002.007 | B24: Projeto estrutural em concreto armado* | C24: vb | D24: 1 | E24: 48634.64 | F24: 48634.64
A25: 01.001.002.008 | B25: Projeto elétrico* | C25: vb | D25: 1 | E25: 6605.59 | F25: 6605.59
A26: 01.001.002.009 | B26: Projeto hidrossanitário* | C26: vb | D26: 1 | E26: 6605.59 | F26: 6605.59
A27: 01.001.002.010 | B27: Projeto preventivo* | C27: vb | D27: 1 | E27: 8850 | F27: 8850
A28: 01.001.002.011 | B28: Projeto de paisagismo | C28: vb | D28: 1 | E28: 5000 | F28: 5000
A29: 01.001.002.012 | B29: Projeto de comunicação visual | C29: vb | D29: 1 | E29: 4000 | F29: 4000
A30: 01.001.002.013 | B30: Modelagem BIM de complementares | C30: vb | D30: 1 | E30: 41000 | F30: 41000
A31: 01.001.003 | B31: Consultorias | F31: 32741.36
A32: 01.001.003.001 | B32: Orçamento e planejamento* | C32: vb | D32: 1 | E32: 11941.36 | F32: 11941.36
A33: 01.001.003.002 | B33: Auditoria de qualidade* | C33: vb | D33: 1 | E33: 8000 | F33: 8000
A34: 01.001.003.003 | B34: Consultorias técnicas diversas | C34: vb | D34: 1 | E34: 12800 | F34: 12800
A35: 01.001.004 | B35: Ensaios e Laudos | F35: 21276.08
A36: 01.001.004.001 | B36: Controle tecnológico de concreto | C36: m3 | D36: 1436.81 | E36: 7.5 | F36: 10776.08
A37: 01.001.004.002 | B37: Laudo preventivo de danos à vizinhança | C37: vb | D37: 1 | E37: 1500 | F37: 1500
A38: 01.001.004.003 | B38: Ensaio/Laudo desempenho - NBR 15575 | C38: vb | D38: 1 | E38: 9000 | F38: 9000
A39: 02 | B39: TAXAS, DOCUMENTOS | F39: 68286.31
A40: 02.001 | B40: TAXAS, DOCUMENTOS | F40: 68286.31
A41: 02.001.001 | B41: Taxas e Documentos | F41: 68286.31
A42: 02.001.001.001 | B42: Despesas de seguro* | C42: vb | D42: 1 | E42: 9600 | F42: 9600
A43: 02.001.001.002 | B43: Aprovação e legalização prefeitura* | C43: vb | D43: 1 | E43: 20297.38 | F43: 20297.38
...

Sheet VILLA LOBOS
A4: Obra | B4: VILLA LOBOS
A5: CONSTRUTORA | B5: MACOM
A6: AREA TERRENO | B6: 553.46
A7: Unidade construtiva M² | B7: 6001.7
A8: ANO | B8: 45108
A9: CUB | B9: 2747.9
A12: Código | B12: Descrição | C12: Un. | D12: Quantidade orçada | E12: Preço unitário | F12: Preço total
A13: 1 | B13: SERVIÇOS TÉCNICOS | F13: 521607.16
A14: 1001 | B14: ESTUDOS, PROJETOS E CONSULTORIAS | F14: 365146.91
A15: 1001001 | B15: Estudos | F15: 24237
A16: 1001001001 | B16: MEMORIAL DESCRITIVO | C16: vb | D16: 1 | E16: 6449 | F16: 6449
A17: 1001001002 | B17: LEVANTAMENTO TOPOGRÁFICO | C17: vb | D17: 1 | E17: 1200 | F17: 1200
A18: 1001001003 | B18: ESTUDO GEOLÓGICO | C18: vb | D18: 1 | E18: 3794 | F18: 3794
A19: 1001001004 | B19: ESTUDO AMBIENTAL | C19: vb | D19: 1 | E19: 3794 | F19: 3794
A20: 1001001005 | B20: SONDAGEM DO TERRENO | C20: vb | D20: 1 | E20: 9000 | F20: 9000
A21: 1001002 | B21: Projetos | F21: 268414.21
A22: 1001002001 | B22: LEGALIZAÇÃO DE INCORPORAÇÃO | C22: vb | D22: 1 | E22: 11291 | F22: 11291
A23: 1001002002 | B23: PROJETO ARQUITETÔNICO LEGAL | C23: vb | D23: 1 | E23: 22991 | F23: 22991
A24: 1001002003 | B24: PROJETO ARQUITETÔNICO EXECUTIVO | C24: vb | D24: 1 | E24: 25629 | F24: 25629
A25: 1001002004 | B25: PROJETO DE TERRAPLANAGEM | C25: vb | D25: 1 | E25: 54300 | F25: 54300
A26: 1001002005 | B26: PROJETO DE CLIMATIZAÇÃO | C26: vb | D26: 1 | E26: 3000 | F26: 3000
A27: 1001002006 | B27: PROJETO DE ASPIRAÇÃO CENTRAL | C27: vb | D27: 1 | E27: 3000 | F27: 3000
A28: 1001002007 | B28: PROJETO ESTRUTURAL EM CONCRETO ARMADO | C28: vb | D28: 1 | E28: 84400 | F28: 84400
A29: 1001002008 | B29: PROJETOS COMPLEMENTARES | C29: vb | D29: 1 | E29: 45800 | F29: 45800
A30: 1001002009 | B30: COMPATIBILIZAÇÃO DE PROJETOS BIM | C30: vb | D30: 1 | E30: 18003.21 | F30: 18003.21
A31: 1001003 | B31: Consultorias | F31: 42149.7
A32: 1001003001 | B32: ORÇAMENTO E PLANEJAMENTO | C32: vb | D32: 1 | E32: 42149.7 | F32: 42149.7
A33: 1001004 | B33: Ensaios e laudos | F33: 30346
A34: 1001004001 | B34: CONTROLE TECNOLÓGICO DO CONCRETO | C34: vb | D34: 1 | E34: 30346 | F34: 30346
A35: 1002 | B35: CONSUMOS, TAXAS E DOCUMENTOS | F35: 156460.25
A36: 1002001 | B36: Licenciamentos, taxas, impostos, aprovações e seguros | F36: 93852.46
A37: 1002001001 | B37: DESPESAS DE SEGURO DE OBRA | C37: vb | D37: 1 | E37: 9825.24 | F37: 9825.24
A38: 1002001002 | B38: DESPESAS DE CARTÓRIO, LICENÇAS, CERTIDÕES E JURÍDICAS | C38: vb | D38: 1 | E38: 3454 | F38: 3454
A39: 1002001003 | B39: APROVAÇÃO E LEGALIZAÇÃO AMBIENTAL | C39: vb | D39: 1 | E39: 4563 | F39: 4563
A40: 1002001004 | B40: APROVAÇÃO E LEGALIZAÇÃO DE PREFEITURA | C40: vb | D40: 1 | E40: 26658 | F40: 26658
A41: 1002001005 | B41: APROVAÇÃO E LEGALIZAÇÃO DE ÁGUA E ESGOTO | C41: vb | D41: 1 | E41: 4599 | F41: 4599
A42: 1002001006 | B42: APROVAÇÃO E LEGALIZAÇÃO ELÉTRICO | C42: vb | D42: 1 | E42: 4599 | F42: 4599
A43: 1002001007 | B43: APROVAÇÃO E LEGALIZAÇÃO BOMBEIROS | C43: vb | D43: 1 | E43: 4932 | F43: 4932
A44: 1002001008 | B44: TAXAS DE ART | C44: vb | D44: 1 | E44: 1897 | F44: 1897
A45: 1002001009 | B45: TAXAS DE ALVARÁ | C45: vb | D45: 1 | E45: 12999.52 | F45: 12999.52
...

Sheet GRAN TOWER
A4: Obra | B4: GRAN TOWER
A5: CONSTRUTORA | B5: GRANDEZZA
A6: Endereço da obra | B6: Av. Itapocoroy esq. com RuaAlfredo Brunetti (Lt. 18, 19A e 19B) CEP: 88385-000 Armação - Penha,SC
A7: AREA TERRENO | B7: 859.95
A8: Unidade construtiva M² | B8: 6245.48
A9: ANO | B9: 45383
A10: CUB | B10: 2757.56
A13: Código | B13: Descrição | C13: Un. | D13: Quantidade orçada | E13: Preço unitário | F13: Preço total
A14: 1 | B14: SERVIÇOS TÉCNICOS | F14: 704184.6
A15: 1001 | B15: ESTUDOS, PROJETOS E CONSULTORIAS | F15: 511004.81
A16: 1001001 | B16: Estudos | F16: 65491
A17: 1001001001 | B17: Memorial descritivo | C17: vb | D17: 1 | E17: 6789 | F17: 6789
A18: 1001001002 | B18: Levantamento topográfico | C18: vb | D18: 1 | E18: 6789 | F18: 6789
A19: 1001001003 | B19: Estudo geológico | C19: vb | D19: 1 | E19: 6789 | F19: 6789
A20: 1001001004 | B20: Estudo ambiental | C20: vb | D20: 1 | E20: 16158 | F20: 16158
A21: 1001001005 | B21: Sondagem do terreno | C21: vb | D21: 1 | E21: 22177 | F21: 22177
A22: 1001001006 | B22: Projeto de canteiro | C22: vb | D22: 1 | E22: 6789 | F22: 6789
A23: 1001002 | B23: Projetos | F23: 408226.81
A24: 1001002001 | B24: Legalização de incorporação | C24: vb | D24: 1 | E24: 11611.7 | F24: 11611.7
A25: 1001002002 | B25: Projeto arquitetônico legal | C25: vb | D25: 1 | E25: 79546 | F25: 79546
A26: 1001002003 | B26: Projeto arquitetônico executivo | C26: vb | D26: 1 | E26: 50000 | F26: 50000
A27: 1001002004 | B27: Projeto arquitetônico interiores | C27: vb | D27: 1 | E27: 67889 | F27: 67889
A28: 1001002005 | B28: Projeto arquitetônico de fachada | C28: vb | D28: 1 | E28: 2187.34 | F28: 2187.34
A29: 1001002006 | B29: Projeto de fundação | C29: vb | D29: 1 | E29: 3729 | F29: 3729
A30: 1001002007 | B30: Projeto estrutural de concreto armado | C30: vb | D30: 1 | E30: 41587 | F30: 41587
A31: 1001002008 | B31: Projeto de estrutura metálica | C31: vb | D31: 1 | E31: 30000 | F31: 30000
A32: 1001002009 | B32: Projeto elétrico | C32: vb | D32: 1 | E32: 33310 | F32: 33310
A33: 1001002010 | B33: Projeto de automação | C33: vb | D33: 1 | E33: 2000 | F33: 2000
A34: 1001002011 | B34: Projeto hidrossanitário | C34: vb | D34: 1 | E34: 41016 | F34: 41016
A35: 1001002012 | B35: Projeto preventivo | C35: vb | D35: 1 | E35: 4972 | F35: 4972
... A39: 1001002016 | B39: Projeto de paisagismo | C39: vb | D39: 1 | E39: 1514.48 | F39: 1514.48
A40: 1001003 | B40: Consultorias | F40: 37287
A41: 1001003001 | B41: Consultoria técnica de legalização | C41: vb | D41: 1 | E41: 37287 | F41: 37287
A42: 1001004 | B42: Ensaios | F42: 0
A43: 1002 | B43: TAXAS E DOCUMENTOS | F43: 193179.79
A44: 1002001 | B44: Licenciamentos, Taxas, Impostos, Aprovações e Seguros | F44: 193179.79
A45: 1002001001 | B45: Despesas de seguro de obra | C45: vb | D45: 1 | E45: 37287 | F45: 37287
A46: 1002001002 | B46: Aprovação e legalização ambiental | C46: vb | D46: 1 | E46: 4972 | F46: 4972
A47: 1002001003 | B47: Aprovação e legalização prefeitura | C47: vb | D47: 1 | E47: 8883 | F47: 8883
A48: 1002001004 | B48: Aprovação e legalização água e esgoto | C48: vb | D48: 1 | E48: 1134 | F48: 1134
...
