Workbook
Name \0: #REF!
Name \0: #REF!
Name \0: #REF!
Name \0: #REF!
Name \0: #REF!
Name \0: #REF!
Name \0: #REF!
Name \0: #REF!
Name \0: #REF!
Name \0: #REF!
Name \0: #REF!
Name \0: #REF!
Name \0: #REF!
Name \0: #REF!
Name \0: #REF!
Name \0: #REF!
Name \0: #REF!
Name \0: #REF!
Name \0: #REF!
Name \a: #REF!
Name \a: #REF!
Name \a: #REF!
Name \a: #REF!
Name \a: #REF!
Name \a: #REF!
Name \a: #REF!
Name \a: #REF!
Name \a: #REF!
Name \a: #REF!
Name \a: #REF!
Name \a: #REF!
Name \a: #REF!
Name \a: #REF!
Name \a: #REF!
Name \a: #REF!
Name \a: #REF!
Name \a: #REF!
Name \a: #REF!
Name \m: #REF!
Name \m: #REF!
Name \m: #REF!
Name \m: #REF!
Name \m: #REF!
Name \m: #REF!
Name \m: #REF!
Name \m: #REF!
Name \m: #REF!
Name \m: #REF!
Name \m: #REF!
Name \m: #REF!
Name \m: #REF!
Name \m: #REF!
Name \m: #REF!
Name \m: #REF!
Name \m: #REF!
Name \m: #REF!
Name aa: #REF!
Name aa: #REF!
Name aa: #REF!
Name aa: #REF!

Sheet Resumo
A1: ETAPA | B1: R02 | E1: R03 | H1: DIFERENÇA
B2: VALOR ORÇADO | C2: % | D2: VALOR/M² | E2: VALOR ORÇADO | F2: % | G2: VALOR/M² | H2: VALOR ORÇADO | I2: VALOR/M² | K2: ÁREA CONSTRUÍDA | L2: 10722.5 | M2: M²
A3: ='CUSTOS DIRETOS'!A3 -> 1.1. GERENCIAMENTO TÉCNICO E ADMINISTRATIVO | B3: 2786052.3 | C3: =B3/$B$25 -> 0.095597832 | D3: =B3/$L$2 -> 259.83235 | E3: =SUMIF('CUSTOS DIRETOS'!$A$3:$A$352,A3,'CUSTOS DIRETOS'!$E$3:$E$352) -> 2786052.3 | F3: =E3/$E$25 -> 0.092272313 | G3: =E3/$L$2 -> 259.83235 | H3: =E3-B3 -> 0 | I3: =G3-D3 -> 0
A4: 1.2.1. MOVIMENTAÇÃO DE TERRA | B4: 110350.11 | C4: =B4/$B$25 -> 0.003786444 | D4: =B4/$L$2 -> 10.291453 | E4: =SUMIF('CUSTOS DIRETOS'!$A$3:$A$352,A4,'CUSTOS DIRETOS'!$E$3:$E$352) -> 110350.11 | F4: =E4/$E$25 -> 0.0036547267 | G4: =E4/$L$2 -> 10.291453 | H4: =E4-B4 -> 0 | I4: =G4-D4 -> 0
A5: ='CUSTOS DIRETOS'!A42 -> 1.2.2. INFRAESTRUTURA | B5: 2370948.9 | C5: =B5/$B$25 -> 0.081354383 | D5: =B5/$L$2 -> 221.11904 | E5: =SUMIF('CUSTOS DIRETOS'!$A$3:$A$352,A5,'CUSTOS DIRETOS'!$E$3:$E$352) -> 2370948.9 | F5: =E5/$E$25 -> 0.078524345 | G5: =E5/$L$2 -> 221.11904 | H5: =E5-B5 -> 0 | I5: =G5-D5 -> 0
A6: ='CUSTOS DIRETOS'!A69 -> 1.2.3. SUPRAESTRUTURA | B6: 5880203.6 | C6: =B6/$B$25 -> 0.20176746 | D6: =B6/$L$2 -> 548.39857 | E6: =SUMIF('CUSTOS DIRETOS'!$A$3:$A$352,A6,'CUSTOS DIRETOS'!$E$3:$E$352) -> 5880203.6 | F6: =E6/$E$25 -> 0.19474867 | G6: =E6/$L$2 -> 548.39857 | H6: =E6-B6 -> 0 | I6: =G6-D6 -> 0
A7: ='CUSTOS DIRETOS'!A103 -> 1.2.4. PAREDES E PAINÉIS | B7: 1469000.4 | C7: =B7/$B$25 -> 0.050405821 | D7: =B7/$L$2 -> 137.00167 | E7: =SUMIF('CUSTOS DIRETOS'!$A$3:$A$352,A7,'CUSTOS DIRETOS'!$E$3:$E$352) -> 1669970.1 | F7: =E7/$E$25 -> 0.055308366 | G7: =E7/$L$2 -> 155.74447 | H7: =E7-B7 -> 200969.66 | I7: =G7-D7 -> 18.742799 | J7: aumento na quantidade de alvenaria
A8: ='CUSTOS DIRETOS'!A118 -> 1.2.5. IMPERMEABILIZAÇÃO E TRATAMENTOS | B8: 717784.17 | C8: =B8/$B$25 -> 0.024629333 | D8: =B8/$L$2 -> 66.941867 | E8: =SUMIF('CUSTOS DIRETOS'!$A$3:$A$352,A8,'CUSTOS DIRETOS'!$E$3:$E$352) -> 717784.17 | F8: =E8/$E$25 -> 0.023772563 | G8: =E8/$L$2 -> 66.941867 | H8: =E8-B8 -> 0 | I8: =G8-D8 -> 0
A9: ='CUSTOS DIRETOS'!A137 -> 1.2.6. SISTEMAS E INSTALAÇÕES HIDROSSANITÁRIAS E DRENAGEM | B9: 933172.45 | C9: =B9/$B$25 -> 0.032019952 | D9: =B9/$L$2 -> 87.029372 | E9: =SUMIF('CUSTOS DIRETOS'!$A$3:$A$352,A9,'CUSTOS DIRETOS'!$E$3:$E$352) -> 933172.45 | F9: =E9/$E$25 -> 0.030906088 | G9: =E9/$L$2 -> 87.029372 | H9: =E9-B9 -> 0 | I9: =G9-D9 -> 0
A10: ='CUSTOS DIRETOS'!A151 -> 1.2.7. SISTEMAS E INSTALAÇÕES ELÉTRICAS | B10: 1092655.5 | C10: =B10/$B$25 -> 0.037492295 | D10: =B10/$L$2 -> 101.90305 | E10: =SUMIF('CUSTOS DIRETOS'!$A$3:$A$352,A10,'CUSTOS DIRETOS'!$E$3:$E$352) -> 1092655.5 | F10: =E10/$E$25 -> 0.036188067 | G10: =E10/$L$2 -> 101.90305 | H10: =E10-B10 -> 0 | I10: =G10-D10 -> 0
A11: ='CUSTOS DIRETOS'!A167 -> 1.2.8. INSTALAÇÕES PREVENTIVAS | B11: 255923.68 | C11: =B11/$B$25 -> 0.0087815109 | D11: =B11/$L$2 -> 23.867911 | E11: =SUMIF('CUSTOS DIRETOS'!$A$3:$A$352,A11,'CUSTOS DIRETOS'!$E$3:$E$352) -> 255923.68 | F11: =E11/$E$25 -> 0.0084760324 | G11: =E11/$L$2 -> 23.867911 | H11: =E11-B11 -> 0 | I11: =G11-D11 -> 0
A12: ='CUSTOS DIRETOS'!A177 -> 1.2.9. INSTALAÇÃO DE GÁS | B12: 149949.8 | C12: =B12/$B$25 -> 0.0051452285 | D12: =B12/$L$2 -> 13.984593 | E12: =SUMIF('CUSTOS DIRETOS'!$A$3:$A$352,A12,'CUSTOS DIRETOS'!$E$3:$E$352) -> 149949.8 | F12: =E12/$E$25 -> 0.0049662437 | G12: =E12/$L$2 -> 13.984593 | H12: =E12-B12 -> 0 | I12: =G12-D12 -> 0
A13: ='CUSTOS DIRETOS'!A181 -> 1.2.10. INSTALAÇÕES DE COMUNICAÇÕES | B13: 151300.45 | C13: =B13/$B$25 -> 0.0051915735 | D13: =B13/$L$2 -> 14.110558 | E13: =SUMIF('CUSTOS DIRETOS'!$A$3:$A$352,A13,'CUSTOS DIRETOS'!$E$3:$E$352) -> 151300.45 | F13: =E13/$E$25 -> 0.0050109766 | G13: =E13/$L$2 -> 14.110558 | H13: =E13-B13 -> 0 | I13: =G13-D13 -> 0
A14: ='CUSTOS DIRETOS'!A187 -> 1.2.11. EQUIPAMENTOS E SISTEMA ESPECIAIS | B14: 1034052 | C14: =B14/$B$25 -> 0.035481433 | D14: =B14/$L$2 -> 96.437584 | E14: =SUMIF('CUSTOS DIRETOS'!$A$3:$A$352,A14,'CUSTOS DIRETOS'!$E$3:$E$352) -> 1034052 | F14: =E14/$E$25 -> 0.034247156 | G14: =E14/$L$2 -> 96.437584 | H14: =E14-B14 -> 0 | I14: =G14-D14 -> 0
A15: ='CUSTOS DIRETOS'!A197 -> 1.2.12. CLIMATIZAÇÃO E EXAUSTÃO | B15: 269762.89 | C15: =B15/$B$25 -> 0.0092563758 | D15: =B15/$L$2 -> 25.158581 | E15: =SUMIF('CUSTOS DIRETOS'!$A$3:$A$352,A15,'CUSTOS DIRETOS'!$E$3:$E$352) -> 269762.89 | F15: =E15/$E$25 -> 0.0089343784 | G15: =E15/$L$2 -> 25.158581 | H15: =E15-B15 -> 0 | I15: =G15-D15 -> 0
A16: ='CUSTOS DIRETOS'!A205 -> 1.2.13. REVESTIMENTOS INTERNOS DE PAREDE | B16: 2033021.2 | C16: =B16/$B$25 -> 0.069759068 | D16: =B16/$L$2 -> 189.60328 | E16: =SUMIF('CUSTOS DIRETOS'!$A$3:$A$352,A16,'CUSTOS DIRETOS'!$E$3:$E$352) -> 2179759.2 | F16: =E16/$E$25 -> 0.072192262 | G16: =E16/$L$2 -> 203.28833 | H16: =E16-B16 -> 146737.99 | I16: =G16-D16 -> 13.685054 | J16: aumento da área de chapisco e reboco das novas alvenarias porém havia duplicação do reboco externo que foi corrigido]
A17: ='CUSTOS DIRETOS'!A222 -> 1.2.14. REVESTIMENTOS E ACABAMENTOS INTERNOS EM TETO | B17: 568584.16 | C17: =B17/$B$25 -> 0.019509832 | D17: =B17/$L$2 -> 53.027201 | E17: =SUMIF('CUSTOS DIRETOS'!$A$3:$A$352,A17,'CUSTOS DIRETOS'!$E$3:$E$352) -> 568584.16 | F17: =E17/$E$25 -> 0.018831152 | G17: =E17/$L$2 -> 53.027201 | H17: =E17-B17 -> 0 | I17: =G17-D17 -> 0
A18: ='CUSTOS DIRETOS'!A227 -> 1.2.15. PISOS E PAVIMENTAÇÕES | B18: 2316031.9 | C18: =B18/$B$25 -> 0.079470017 | D18: =B18/$L$2 -> 215.99738 | E18: =SUMIF('CUSTOS DIRETOS'!$A$3:$A$352,A18,'CUSTOS DIRETOS'!$E$3:$E$352) -> 2316031.9 | F18: =E18/$E$25 -> 0.07670553 | G18: =E18/$L$2 -> 215.99738 | H18: =E18-B18 -> 0 | I18: =G18-D18 -> 0
A19: ='CUSTOS DIRETOS'!A253 -> 1.2.16. SISTEMAS DE PINTURA INTERNA | B19: 1570798.2 | C19: =B19/$B$25 -> 0.053898809 | D19: =B19/$L$2 -> 146.49552 | E19: =SUMIF('CUSTOS DIRETOS'!$A$3:$A$352,A19,'CUSTOS DIRETOS'!$E$3:$E$352) -> 2128847.1 | F19: =E19/$E$25 -> 0.070506085 | G19: =E19/$L$2 -> 198.54018 | H19: =E19-B19 -> 558048.86 | I19: =G19-D19 -> 52.04466 | J19: aumento na quantidade de alvenaria
A20: ='CUSTOS DIRETOS'!A275 -> 1.2.17. ESQUADRIAS, VIDROS E FERRAGENS | B20: 2263600.2 | C20: =B20/$B$25 -> 0.077670928 | D20: =B20/$L$2 -> 211.1075 | E20: =SUMIF('CUSTOS DIRETOS'!$A$3:$A$352,A20,'CUSTOS DIRETOS'!$E$3:$E$352) -> 2263600.2 | F20: =E20/$E$25 -> 0.074969024 | G20: =E20/$L$2 -> 211.1075 | H20: =E20-B20 -> 0 | I20: =G20-D20 -> 0
A21: ='CUSTOS DIRETOS'!A300 -> 1.2.18. LOUÇAS E METAIS | B21: 351077.93 | C21: =B21/$B$25 -> 0.012046539 | D21: =B21/$L$2 -> 32.742171 | E21: =SUMIF('CUSTOS DIRETOS'!$A$3:$A$352,A21,'CUSTOS DIRETOS'!$E$3:$E$352) -> 351077.93 | F21: =E21/$E$25 -> 0.011627482 | G21: =E21/$L$2 -> 32.742171 | H21: =E21-B21 -> 0 | I21: =G21-D21 -> 0
A22: ='CUSTOS DIRETOS'!A308 -> 1.2.19. REVESTIMENTO E ACABAMENTOS EM FACHADA | B22: 1072274.3 | C22: =B22/$B$25 -> 0.036792954 | D22: =B22/$L$2 -> 100.00226 | E22: =SUMIF('CUSTOS DIRETOS'!$A$3:$A$352,A22,'CUSTOS DIRETOS'!$E$3:$E$352) -> 1201333.9 | F22: =E22/$E$25 -> 0.039787428 | G22: =E22/$L$2 -> 112.0386 | H22: =E22-B22 -> 129059.62 | I22: =G22-D22 -> 12.036337 | J22: aumento na quantidade de alvenaria
A23: ='CUSTOS DIRETOS'!A329 -> 1.2.20. SERVIÇOS COMPLEMENTARES E FINAIS | B23: 1316232.1 | C23: =B23/$B$25 -> 0.045163882 | D23: =B23/$L$2 -> 122.75422 | E23: =SUMIF('CUSTOS DIRETOS'!$A$3:$A$352,A23,'CUSTOS DIRETOS'!$E$3:$E$352) -> 1316232.1 | F23: =E23/$E$25 -> 0.043592786 | G23: =E23/$L$2 -> 122.75422 | H23: =E23-B23 -> 0 | I23: =G23-D23 -> 0
A24: ='CUSTOS DIRETOS'!A352 -> 1.2.21. IMPREVISTOS E CONTINGÊNCIAS | B24: 430691.64 | C24: =B24/$B$25 -> 0.014778325 | D24: =B24/$L$2 -> 40.167092 | E24: =E30 -> 446213.89 | F24: =E24/$E$25 -> 0.014778325 | G24: =E24/$L$2 -> 41.614725 | H24: =E24-B24 -> 15522.242 | I24: =G24-D24 -> 1.4476327
A25: TOTAL | B25: =SUM(B3:B24) -> 29143468 | C25: =SUM(C3:C24) -> 1 | D25: =SUM(D3:D24) -> 2717.9732 | E25: =SUM(E3:E24) -> 30193806 | F25: =SUM(F3:F24) -> 1 | G25: =SUM(G3:G24) -> 2815.9297 | H25: =SUM(H3:H24) -> 1050338.4 | I25: =SUM(I3:I24) -> 97.956483
A26: CUB | B26: 2752.67 | C26: DEZ/23 | D26: =ROUNDDOWN(D25/B26,2)&" CUB" -> 0,98 CUB | G26: =ROUNDDOWN(G25/B26,2)&" CUB" -> 1,02 CUB | H26: =H25/B25 -> 0.036040268 | I26: =ROUNDDOWN(I25/B26,2)&" CUB" -> 0,03 CUB
E29: =SUM(E3:E23) -> 29747592
E30: =E29*1.5% -> 446213.89

Sheet CUSTOS DIRETOS
A1: Etapa | B1: Quant. | C1: Unidade | D1: Valor Unitário | E1: Valor Total
A2: 1. West Village SPE | E2: =SUM(E3,E32) -> 30193806
A3: 1.1. GERENCIAMENTO TÉCNICO E ADMINISTRATIVO | E3: ='CUSTOS INDIRETOS'!E4 -> 2786052.3
A4: 1.1.1. SERVIÇOS TÉCNICOS | E4: 0
A5: 1.1.1.1. ESTUDOS, PROJETOS E CONSULTORIAS | E5: 0
A6: 1.1.1.1.1. ESTUDOS | E6: 0
A7: 1.1.1.1.2. PROJETOS | E7: 0
A8: 1.1.1.1.3. CONSULTORIAS | E8: 0
A9: 1.1.1.1.4. ENSAIOS | E9: 0
A10: 1.1.1.2. TAXAS E DOCUMENTOS | E10: 0
A11: 1.1.1.2.1. LICENCIAMENTOS, TAXAS, IMPOSTOS, APROVAÇÕES E SEGUROS | E11: 0
A12: 1.1.1.2.2. DOCUMENTOS | E12: 0
A13: 1.1.2. SERVIÇOS INICIAIS | E13: 0
A14: 1.1.2.1. SEGURANÇA, MEIO AMBIENTE E SAÚDE | E14: 0
A15: 1.1.2.1.1. SEGURANÇA DO TRABALHO | E15: 0
... A31: 1.1.3.1.3. BALANCINS E ANDAIMES | E31: 0
A32: 1.2. GERENCIAMENTO EXECUTIVO | E32: =SUM(E33,E42,E69,E103,E118,E137,E151,E167,E177,E181,E187,E197,E205,E222,E227,E253,E275,E300,E308,E329,E352) -> 27407754
A33: 1.2.1. MOVIMENTAÇÃO DE TERRA | E33: =E34 -> 110350.11
A34: 1.2.1.1. MOVIMENTAÇÃO DE TERRA | E34: =SUM(E35,E38,E40) -> 110350.11
A35: 1.2.1.1.1. ESCAVAÇÃO E REATERRO DE VALAS | E35: =SUM(E36:E37) -> 75830.02
A36: Escavação mecanizada para blocos e baldrames | B36: =ESCAVAÇÕES!D19 -> 1010.6474 | C36: m3 | D36: 69.21 | E36: 69947.09 | F36: QUANT. ESCAVAÇÕES
A37: Reaterro mecanizado para blocos e baldrames com retroescavadeira | B37: =ESCAVAÇÕES!E19 -> 431.29909 | C37: m3 | D37: 13.64 | E37: 5882.93 | F37: QUANT. ESCAVAÇÕES
A38: 1.2.1.1.2. LASTRO DE ESTRUTURA DE CONCRETO | E38: =SUM(E39) -> 1051.49
A39: Lastro de concreto magro, aplicado em blocos e baldrames, espessura 10cm | B39: =ESCAVAÇÕES!H19 -> 37.337076 | C39: m2 | D39: 28.16 | E39: 1051.49 | F39: QUANT. ESCAVAÇÕES
A40: 1.2.1.1.3. MOVIMENTAÇÃO DE BOTA-FORA | E40: =SUM(E41) -> 33468.6
A41: Movimentação de terra para bota-fora de escavação de blocos e baldrames | B41: =ESCAVAÇÕES!F19 -> 557.81145 | C41: m3 | D41: 60 | E41: 33468.6 | F41: QUANT. ESCAVAÇÕES
A42: 1.2.2. INFRAESTRUTURA | E42: =SUM(E43,E54) -> 2370948.9
A43: 1.2.2.1. FUNDAÇÃO PROFUNDA | E43: =SUM(E44,E47,E50,E52) -> 1279618.1
A44: 1.2.2.1.1. PERFURAÇÃO | E44: =SUM(E45:E46) -> 468060
A45: Perfuração de estacas em hélice contínuadiâmetro 50cm | B45: 1827 | C45: m | D45: 100 | E45: 182700 | F45: QUANT. ESTACAS
A46: Perfuração de estacas em hélice contínua diâmetro 60cm | B46: 2378 | C46: m | D46: 120 | E46: 285360 | F46: QUANT. ESTACAS
A47: 1.2.2.1.2. ARMADURA | E47: =SUM(E48:E49) -> 65595.16
A48: Armação aço CA-50, diâmetro 6,3mm para infraestrutura, corte e dobra em obra | B48: 1453 | C48: kg | D48: 6.12 | E48: =B48*D48 -> 8892.36 | F48: QUANT. ESTACAS | G48: Alterados preços de aço e arame recozido de acordo com valores passados pela Kirchner
A49: Armação aço CA-50, diâmetro 16,0mm para (+) | B49: 9205 | C49: kg | D49: 6.16 | E49: =B49*D49 -> 56702.8 | F49: QUANT. ESTACAS | G49: Alterados preços de aço e arame recozido de acordo com valores passados pela Kirchner
A50: 1.2.2.1.3. CONCRETO | E50: =SUM(E51) -> 730012.9
A51: Concreto usinado bombeável para estacas fck 40MPa, com bombeamento | B51: 1237.31 | C51: m3 | D51: 590 | E51: =B51*D51 -> 730012.9 | F51: QUANT. ESTACAS | G51: Alterado valor de concreto para R$500 + R$40 bombeamento, considerando o desperdício na composição
A52: 1.2.2.1.4. MÃO DE OBRA | E52: =SUM(E53) -> 15950
A53: Arrasamento mecanizado de estacas (MÃO D (+) | B53: 145 | C53: un | D53: 110 | E53: =B53*D53 -> 15950 | F53: QUANT. ESTACAS
A54: 1.2.2.2. FUNDAÇÃO RASA | E54: =SUM(E55,E57,E65,E67) -> 1091330.8
A55: 1.2.2.2.1. FORMA | E55: =SUM(E56) -> 196335.24
...

Sheet CUSTOS INDIRETOS
A1: Etapa | B1: Quant. | C1: Unidade | D1: Valor Unitário | E1: Valor Total
A3: 1. West Village SPE | E3: ='CUSTOS DIRETOS'!E2 -> 30193806
A4: 1.1. GERENCIAMENTO TÉCNICO E ADMINISTRATIVO | E4: =SUM(E5,E38,E83) -> 2786052.3
A5: 1.1.1. SERVIÇOS TÉCNICOS | E5: =SUM(E6,E25) -> 800277.37
A6: 1.1.1.1. ESTUDOS, PROJETOS E CONSULTORIAS | E6: =SUM(E7,E11,E20,E22) -> 540822.79
A7: 1.1.1.1.1. ESTUDOS | E7: =SUM(E8:E10) -> 19900
A8: Levantamento topográfico (COMPOSIÇÃO) | B8: 1 | C8: vb | D8: 7400 | E8: =B8*D8 -> 7400 | F8: Formulário de custos indiretos
A9: Sondagem do terreno (COMPOSIÇÃO) | B9: 1 | C9: vb | D9: 9500 | E9: =B9*D9 -> 9500 | F9: Formulário de custos indiretos
A10: Estudo ambiental (COMPOSIÇÃO) | B10: 1 | C10: vb | D10: 3000 | E10: =B10*D10 -> 3000 | F10: Formulário de custos indiretos
A11: 1.1.1.1.2. PROJETOS | E11: =SUM(E12:E19) -> 466031.66
A12: Projeto Arquitetônico (COMPOSIÇÃO) | B12: 1 | C12: vb | D12: 160000 | E12: =B12*D12 -> 160000 | F12: Formulário de custos indiretos
A13: Projeto Estrutural (COMPOSIÇÃO) | B13: 1 | C13: vb | D13: 117000 | E13: =B13*D13 -> 117000 | F13: Formulário de custos indiretos
A14: Projeto Elétrico (COMPOSIÇÃO) | B14: 1 | C14: vb | D14: 16000 | E14: =B14*D14 -> 16000 | F14: Formulário de custos indiretos
A15: Projeto Hidrossanitário (COMPOSIÇÃO) | B15: 1 | C15: vb | D15: 21500 | E15: =B15*D15 -> 21500 | F15: Formulário de custos indiretos
A16: Projeto Preventivo (COMPOSIÇÃO) | B16: 1 | C16: vb | D16: 23479.71 | E16: =B16*D16 -> 23479.71 | F16: Valor estimado por índices históricos
A17: Projeto Arquitetônico Executivo | B17: 1 | C17: vb | D17: 89165.06 | E17: =B17*D17 -> 89165.06 | F17: Valor estimado por índices históricos
A18: Projeto Interiores/ Ambientação | B18: 1 | C18: vb | D18: 33450 | E18: =B18*D18 -> 33450 | F18: Formulário de custos indiretos
A19: Projeto Telefonia | B19: 1 | C19: vb | D19: 5436.89 | E19: =B19*D19 -> 5436.89 | F19: Valor estimado por índices históricos
A20: 1.1.1.1.3. CONSULTORIAS | E20: =SUM(E21) -> 24972.29
A21: Consultoria de Orçamento e Planejamento | B21: 1 | C21: vb | D21: 24972.29 | E21: =D21*B21 -> 24972.29 | F21: Valor estimado por índices históricos
A22: 1.1.1.1.4. ENSAIOS | E22: =SUM(E23:E24) -> 29918.842
A23: Laudo preventivo de danos a vizinhança ( (+) | B23: 1 | C23: vb | D23: 11102.4 | E23: =B23*D23 -> 11102.4 | F23: Valor estimado por índices históricos
A24: Controle tecnológico de concreto (COMPOS (+) | B24: 1 | C24: vb | D24: =SUM('CUSTOS DIRETOS'!B51,'CUSTOS DIRETOS'!B66,'CUSTOS DIRETOS'!B89,'CUSTOS DIRETOS'!B93*0.1)*4.25 -> 18816.442 | E24: =B24*D24 -> 18816.442 | F24: Valor estimado por índices históricos
A25: 1.1.1.2. TAXAS E DOCUMENTOS | E25: =SUM(E26,E35) -> 259454.58
A26: 1.1.1.2.1. LICENCIAMENTOS, TAXAS, IMPOSTOS, APROVAÇÕES E SEGUROS | E26: =SUM(E27:E34) -> 241395.49
A27: Despesas cartoriais e jurídicas (COMPOSI (+) | B27: 1 | C27: vb | D27: 50000 | E27: =B27*D27 -> 50000 | F27: Valor estimado por índices históricos
A28: Taxas de ART (COMPOSIÇÃO) | B28: 1 | C28: vb | D28: 2594.62 | E28: =B28*D28 -> 2594.62 | F28: Valor estimado por índices históricos
A29: IPTU (COMPOSIÇÃO) | B29: 1 | C29: vb | D29: 26706.76 | E29: =B29*D29 -> 26706.76 | F29: Valor estimado por índices históricos
A30: Taxas de alvarás (+) | B30: 1 | C30: vb | D30: 23117.71 | E30: =B30*D30 -> 23117.71 | F30: Formulário de custos indiretos
A31: Taxa de aprovação ambiental (COMPOSIÇÃO) | B31: 1 | C31: vb | D31: =0.1*Resumo!L2 -> 1072.25 | E31: =B31*D31 -> 1072.25 | F31: Valor estimado por índices históricos
A32: Despesas de seguros (COMPOSIÇÃO) | B32: 1 | C32: vb | D32: =2850.95*7 -> 19956.65 | E32: =B32*D32 -> 19956.65 | F32: Formulário de custos indiretos
A33: Incorporação (COMPOSIÇÃO) | B33: 1 | C33: vb | D33: =4*Resumo!L2 -> 42890 | E33: =B33*D33 -> 42890 | F33: Valor estimado por índices históricos
A34: Taxa de aprovação de projetos | B34: 1 | C34: vb | D34: =7*Resumo!L2 -> 75057.5 | E34: =B34*D34 -> 75057.5 | F34: Valor estimado por índices históricos
A35: 1.1.1.2.2. DOCUMENTOS | E35: =SUM(E36:E37) -> 18059.09
A36: Laudo técnico de vistoria de entrega (CO (+) | B36: 1 | C36: vb | D36: 6264.34 | E36: =B36*D36 -> 6264.34 | F36: Valor estimado por índices históricos
A37: Certidão INSS | B37: 1 | C37: vb | D37: =1.1*Resumo!L2 -> 11794.75 | E37: =B37*D37 -> 11794.75 | F37: Valor estimado por índices históricos
A38: 1.1.2. SERVIÇOS INICIAIS | E38: =SUM(E39,E57,E79) -> 1288278.5
A39: 1.1.2.1. SEGURANÇA, MEIO AMBIENTE E SAÚDE | E39: =SUM(E40,E44,E54) -> 641275.51
A40: 1.1.2.1.1. SEGURANÇA DO TRABALHO | E40: =SUM(E41:E43) -> 156497.8
A41: Serviço de segurança do trabalho terceir (+) | B41: 35 | C41: mes | D41: 3337.8 | E41: =B41*D41 -> 116823 | F41: Valor estimado por índices históricos
...

Sheet CUSTOS DISPONIBILIZADOS

Sheet ESCAVAÇÕES
A1: Obra | B1: ='[7]RESUMO INFRA'!B1 -> WEST VILLAGE
A2: Empresa | B2: ='[7]RESUMO INFRA'!B2 -> KIRCHNER
A3: Revisão | B3: ='[7]RESUMO INFRA'!B3 -> 0
A4: QUANTIFICAÇÃO
A6: Quantitativo escavação
A9: RESUMO
B11: LOCAL | D11: Volume de escavação (m³) | E11: Volume de reaterro (m³) | F11: Volume de bota-fora (m³) | G11: Apiloamento de Vala (m²) | H11: Volume de lastro (m³)
C12: BLOCOS | D12: =SUM([7]BLOCOS_FUNDAÇÃO!AD30,[7]BLOCOS_FUNDAÇÃO!AF66) -> 406.40948 | E12: =SUM([7]BLOCOS_FUNDAÇÃO!AE30,[7]BLOCOS_FUNDAÇÃO!AG66) -> 94.42517 | F12: =SUM([7]BLOCOS_FUNDAÇÃO!AF30,[7]BLOCOS_FUNDAÇÃO!AH66) -> 311.98431 | G12: =SUM([7]BLOCOS_FUNDAÇÃO!AG30,[7]BLOCOS_FUNDAÇÃO!AI66) -> 217.8856 | H12: =SUM([7]BLOCOS_FUNDAÇÃO!AH30,[7]BLOCOS_FUNDAÇÃO!AJ66) -> 21.78856
C13: BALDRAMES | D13: ='[7]VIGAS - TÉRREO (BALDRAME)'!K71 -> 181.31761 | E13: ='[7]VIGAS - TÉRREO (BALDRAME)'!L71 -> 83.13489 | F13: ='[7]VIGAS - TÉRREO (BALDRAME)'!M71 -> 98.18272 | G13: ='[7]VIGAS - TÉRREO (BALDRAME)'!N71 -> 108.56386 | H13: ='[7]VIGAS - TÉRREO (BALDRAME)'!O71 -> 10.856386
C14: RESER. INFERIOR 01 | D14: ='[7]ESCAVAÇÃO - RESER. INFERIOR'!AD16 -> 125.1354 | E14: ='[7]ESCAVAÇÃO - RESER. INFERIOR'!AE16 -> 80.416638 | F14: ='[7]ESCAVAÇÃO - RESER. INFERIOR'!AF16 -> 44.718762 | G14: ='[7]ESCAVAÇÃO - RESER. INFERIOR'!AG16 -> 17.6754 | H14: ='[7]ESCAVAÇÃO - RESER. INFERIOR'!AH16 -> 1.76754
C15: RESER. INFERIOR 02 | D15: ='[7]ESCAVAÇÃO - RESER. INFERIOR'!AD17 -> 111.23006 | E15: ='[7]ESCAVAÇÃO - RESER. INFERIOR'!AE17 -> 72.910937 | F15: ='[7]ESCAVAÇÃO - RESER. INFERIOR'!AF17 -> 38.319127 | G15: ='[7]ESCAVAÇÃO - RESER. INFERIOR'!AG17 -> 15.1459 | H15: ='[7]ESCAVAÇÃO - RESER. INFERIOR'!AH17 -> 1.51459
C16: ='[7]ESCAVAÇÃO - RESER. INFERIOR'!C18 -> RESER. RETARDADO | D16: ='[7]ESCAVAÇÃO - RESER. INFERIOR'!AD18 -> 31.233897 | E16: ='[7]ESCAVAÇÃO - RESER. INFERIOR'!AE18 -> 18.840897 | F16: ='[7]ESCAVAÇÃO - RESER. INFERIOR'!AF18 -> 12.393 | G16: ='[7]ESCAVAÇÃO - RESER. INFERIOR'!AG18 -> 8.1 | H16: ='[7]ESCAVAÇÃO - RESER. INFERIOR'!AH18 -> 0.81
C17: ='[7]ESCAVAÇÃO - RESER. INFERIOR'!C19 -> RESER. PLUVIAL | D17: ='[7]ESCAVAÇÃO - RESER. INFERIOR'!AD19 -> 26.065167 | E17: ='[7]ESCAVAÇÃO - RESER. INFERIOR'!AE19 -> 16.885167 | F17: ='[7]ESCAVAÇÃO - RESER. INFERIOR'!AF19 -> 9.18 | G17: ='[7]ESCAVAÇÃO - RESER. INFERIOR'!AG19 -> 6 | H17: ='[7]ESCAVAÇÃO - RESER. INFERIOR'!AH19 -> 0.6
C18: TRATAMENTO DE ESGOTO | D18: ='[7]ESCAVAÇÃO - TRATAMENTO DE ESGOT'!J22 -> 129.25582 | E18: ='[7]ESCAVAÇÃO - TRATAMENTO DE ESGOT'!K22 -> 64.685393 | F18: ='[7]ESCAVAÇÃO - TRATAMENTO DE ESGOT'!L22 -> 43.033536
B19: TOTAL | D19: =SUM(D12:D18) -> 1010.6474 | E19: =SUM(E12:E18) -> 431.29909 | F19: =SUM(F12:F18) -> 557.81145 | G19: =SUM(G12:G17) -> 373.37076 | H19: =SUM(H12:H17) -> 37.337076

Sheet ESTACAS
A1: Obra | B1: WEST VILLAGE
A2: Empresa | B2: KIRCHNER
A3: Revisão | B3: R00
A4: QUANTIFICAÇÃO
A6: Quantitativo estacas
B9: LOCAL | C9: TIPO | D9: Quantidade | E9: Profundidade(m) | F9: Profundidade total (m) | G9: Concreto 40 Mpa + 20% (m³)
B10: 1139 - LOCAÇÃO DAS ESTACAS - R1. dwg | C10: Diâmetro 50cm | D10: 63 | E10: 29 | F10: =E10*D10 -> 1827 | G10: =PI()*(0.25^2)*F10*1.2 -> 430.47673
B11: 1139 - LOCAÇÃO DAS ESTACAS - R1. dwg | C11: Diâmetro 60cm | D11: 82 | E11: 29 | F11: =E11*D11 -> 2378 | G11: =PI()*(0.3^2)*F11*1.2 -> 806.83639
D12: =SUM(D10:D11) -> 145 | F12: =E12*D12 -> 0 | G12: =PI()*(0.35^2)*F12 -> 0
E13: TOTAL | F13: =SUM(F10:F12) -> 4205 | G13: =SUM(G10:G12) -> 1237.3131
B15: Aço | C15: Diâmetro | D15: Peso (kg)
B16: CA50 | C16: 6.3 | D16: 1453
B17: CA50 | C17: 16 | D17: 9205
C18: TOTAL | D18: =SUM(D16:D17) -> 10658

Sheet BALDRAMES
A1: Obra | B1: =[8]ARQUIVOS_BASE!B1 -> WEST VILLAGE
A2: Empresa | B2: =[8]ARQUIVOS_BASE!B2 -> KIRCHNER
A3: Revisão | B3: =[8]ARQUIVOS_BASE!B3 -> 0
A4: RESUMO DE QUANTITATIVO
A6: Quantitativo de Infraestrutura
A8: BLOCOS/ BALDRAME/ LAJE DE PISO/ RESERV. INFERIOR
B10: ELEMENTO | D10: FCK DE CONCRETO (MPa) | E10: VOLUME DE CONCRETO (m³) | F10: ÁREA DE FORMA (m²) | G10: Ø5,00 (kg) | H10: Ø6,30 (kg) | I10: Ø8,00 (kg) | J10: Ø10,00 (kg) | K10: Ø12,50 (kg) | L10: Ø16,00 (kg) | M10: Ø20,00 (kg) | N10: Ø25,00 (kg) | O10: KG DE AÇO (kg) | P10: TAXA DE AÇO (kg/m³)
B11: BLOCOS | D11: 35 | E11: =SUM([7]BLOCOS_FUNDAÇÃO!AE66,[7]BLOCOS_FUNDAÇÃO!L30) -> 311.98431 | F11: =SUM([7]BLOCOS_FUNDAÇÃO!K30,[7]BLOCOS_FUNDAÇÃO!AD66) -> 426.44216 | G11: 216 | H11: 527 | I11: 18 | J11: 3519 | K11: 6091 | L11: 966 | M11: 16892 | N11: 0 | O11: =SUM(G11:N11) -> 28229 | P11: =O11/E11 -> 90.482114
B12: BALDRAME | C12: L1 - TÉRREO | D12: 35 | E12: ='[7]VIGAS - TÉRREO (BALDRAME)'!J71 -> 80.785957 | F12: ='[7]VIGAS - TÉRREO (BALDRAME)'!I71 -> 804.43436 | G12: 275 | H12: 642 | I12: 1436 | J12: 602 | K12: 1797 | L12: 2234 | M12: 510 | N12: 0 | O12: =SUM(G12:N12) -> 7496 | P12: =O12/E12 -> 92.788404
B13: LAJE DE PISO | C13: L1 - TÉRREO | D13: 35 | E13: ='[7]LAJES_RESER. INFERIOR'!J7 -> 128.7 | F13: ='[7]LAJES_RESER. INFERIOR'!G7 -> 780 | G13: 0 | H13: 2545 | I13: 1839 | J13: 702 | K13: 0 | L13: 0 | M13: 0 | N13: 0 | O13: =SUM(G13:N13) -> 5086 | P13: =O13/E13 -> 39.51826
B14: RES. INFERIOR | D14: 35 | E14: =SUM('[7]VIGAS - RESER. INFERIOR'!J32,'[7]LAJES_RESER. INFERIOR'!J17) -> 40.270146 | F14: =SUM('[7]VIGAS - RESER. INFERIOR'!I32,'[7]LAJES_RESER. INFERIOR'!I17) -> 391.95044 | G14: 8 | H14: =17+140 -> 157 | I14: =1132+1103 -> 2235 | J14: =1693+73 -> 1766 | K14: =26 -> 26 | L14: =1037 -> 1037 | M14: 0 | N14: 0 | O14: =SUM(G14:N14) -> 5229 | P14: =O14/E14 -> 129.84805
B15: TOTAL | E15: =SUM(E11:E14) -> 561.74041 | F15: =SUM(F11:F14) -> 2402.827 | G15: =SUM(G11:G14) -> 499 | H15: =SUM(H11:H14) -> 3871 | I15: =SUM(I11:I14) -> 5528 | J15: =SUM(J11:J14) -> 6589 | K15: =SUM(K11:K14) -> 7914 | L15: =SUM(L11:L14) -> 4237 | ... O15: =SUM(O11:O14) -> 46040 | P15: =O15/E15 -> 81.959565

Sheet SUPRAESTRUTURA
A1: Obra | B1: =[8]ARQUIVOS_BASE!B1 -> WEST VILLAGE
A2: Empresa | B2: =[8]ARQUIVOS_BASE!B2 -> KIRCHNER
A3: Revisão | B3: =[8]ARQUIVOS_BASE!B3 -> 0
A4: RESUMO DE QUANTITATIVO
A6: Quantitativo de Supraestrutura
A8: VIGAS
B10: ELEMENTO | C10: PAVIMENTO | D10: FCK DE CONCRETO (MPa) | E10: VOLUME DE CONCRETO (m³) | F10: ÁREA DE FORMA (m²) | G10: Ø5,00 (kg) | H10: Ø6,30 (kg) | I10: Ø8,00 (kg) | J10: Ø10,00 (kg) | K10: Ø12,50 (kg) | L10: Ø16,00 (kg) | M10: Ø20,00 (kg) | N10: Ø25,00 (kg) | O10: KG DE AÇO (kg) | P10: TAXA DE AÇO (kg/m³)
B11: VIGAS | C11: L2 - MEZ G1 | D11: 35 | E11: ='[8]VIGAS - MEZ G1'!J51 -> 91.341087 | F11: ='[8]VIGAS - MEZ G1'!I51 -> 631.07026 | G11: 248 | H11: 514 | I11: 375 | J11: 675 | K11: 2217 | L11: 1899 | M11: 5501 | N11: 0 | O11: =SUM(G11:N11) -> 11429 | P11: =O11/E11 -> 125.12441
B12: VIGAS | C12: L3 - G2 | D12: 35 | E12: ='[8]VIGAS - G2'!J35 -> 18.49273 | F12: ='[8]VIGAS - G2'!I35 -> 279.89302 | G12: =156 -> 156 | H12: 310 | I12: 29 | J12: 208 | K12: 246 | L12: 502 | M12: 615 | N12: 0 | O12: =SUM(G12:N12) -> 2066 | P12: =O12/E12 -> 111.71958
B13: VIGAS | C13: L4 - MEZ G3 | D13: 35 | E13: ='[8]VIGAS - G3'!J35 -> 19.156573 | F13: ='[8]VIGAS - G3'!I35 -> 290.32429 | G13: 174 | H13: 309 | I13: 38 | J13: 188 | K13: 193 | L13: 475 | M13: 832 | N13: 0 | O13: =SUM(G13:N13) -> 2209 | P13: =O13/E13 -> 115.3129
B14: VIGAS | C14: L5 - LAZER | D14: 35 | E14: ='[8]VIGAS - LAZER'!J65 -> 222.09438 | F14: ='[8]VIGAS - LAZER'!I65 -> 976.36124 | G14: 211 | H14: 362 | I14: 2196 | J14: 1938 | K14: 5683 | L14: 10626 | M14: 2099 | N14: 0 | O14: =SUM(G14:N14) -> 23115 | P14: =O14/E14 -> 104.07738
B15: VIGAS | C15: L6 TIPO | D15: 35 | E15: ='[8]VIGAS - PAV TIPO'!J23 -> 11.799368 | F15: ='[8]VIGAS - PAV TIPO'!I23 -> 183.41024 | G15: 109 | H15: 207 | I15: 49 | J15: 32 | K15: 161 | L15: 513 | M15: 565 | N15: 0 | O15: =SUM(G15:N15) -> 1636 | P15: =O15/E15 -> 138.65149
B16: VIGAS | C16: L7 A L11 TIPO | D16: 35 | E16: =5*E15 -> 58.99684 | F16: ='[8]VIGAS - PAV TIPO'!I23*5 -> 917.0512 | G16: =106*5 -> 530 | H16: =5*207 -> 1035 | I16: =5*49 -> 245 | J16: =5*32 -> 160 | K16: =5*161 -> 805 | L16: =5*535 -> 2675 | M16: =5*565 -> 2825 | N16: 0 | O16: =SUM(G16:N16) -> 8275 | P16: =O16/E16 -> 140.26175
B17: VIGAS | C17: L12 A L16 TIPO | D17: 35 | E17: =5*E15 -> 58.99684 | F17: ='[8]VIGAS - PAV TIPO'!I23*5 -> 917.0512 | G17: =5*106 -> 530 | H17: =5*207 -> 1035 | I17: =5*44 -> 220 | J17: =5*55 -> 275 | K17: =5*151 -> 755 | L17: =5*477 -> 2385 | M17: =5*504 -> 2520 | N17: 0 | O17: =SUM(G17:N17) -> 7720 | P17: =O17/E17 -> 130.85447
B18: VIGAS | C18: L17 A L20 TIPO | D18: 35 | E18: =4*E15 -> 47.197472 | F18: =4*'[8]VIGAS - PAV TIPO'!I23 -> 733.64096 | G18: =4*105 -> 420 | H18: =4*207 -> 828 | I18: =4*25 -> 100 | J18: =4*86 -> 344 | K18: =4*141 -> 564 | L18: =4*619 -> 2476 | M18: 0 | N18: 0 | O18: =SUM(G18:N18) -> 4732 | P18: =O18/E18 -> 100.25961
B19: VIGAS | C19: L21 - TELHADO | D19: 35 | E19: ='[8]VIGAS - TELHADO'!J23 -> 11.812108 | F19: ='[8]VIGAS - TELHADO'!I23 -> 183.61044 | G19: 109 | H19: 207 | I19: 24 | J19: 142 | K19: 291 | L19: 140 | M19: 0 | N19: 0 | O19: =SUM(G19:N19) -> 913 | P19: =O19/E19 -> 77.29357
B20: VIGAS | C20: L22 - MÁQUINAS | D20: 35 | E20: ='[8]VIGAS - CASA DE MAQ'!J10 -> 0.742 | F20: ='[8]VIGAS - CASA DE MAQ'!I10 -> 12.084 | G20: 6 | H20: 0 | I20: 5 | J20: 29 | K20: 0 | L20: 0 | M20: 0 | N20: 0 | O20: =SUM(G20:N20) -> 40 | P20: =O20/E20 -> 53.908356
B21: VIGAS | C21: TOTAL | E21: =SUM(E11:E20) -> 540.6294 | F21: =SUM(F11:F20) -> 5124.4969 | G21: =SUM(G11:G20) -> 2493 | H21: =SUM(H11:H20) -> 4807 | I21: =SUM(I11:I20) -> 3281 | J21: =SUM(J11:J20) -> 3991 | K21: =SUM(K11:K20) -> 10915 | L21: =SUM(L11:L20) -> 21691 | ... O21: =SUM(O11:O20) -> 62135 | P21: =O21/E21 -> 114.93086
A23: PILARES
B25: ELEMENTO | C25: PAVIMENTO | D25: FCK DE CONCRETO (MPa) | E25: VOLUME DE CONCRETO (m³) | F25: ÁREA DE FORMA (m²) | G25: Ø5,00 (kg) | H25: Ø6,30 (kg) | I25: Ø8,00 (kg) | J25: Ø10,00 (kg) | K25: Ø12,50 (kg) | L25: Ø16,00 (kg) | M25: Ø20,00 (kg) | N25: Ø25,00 (kg) | O25: KG DE AÇO (kg) | P25: TAXA DE AÇO (kg/m³)
B26: PILARES | C26: L1 - TÉRREO | D26: 35 | E26: 0 | O26: =SUM(G26:N26) -> 0
B27: PILARES | C27: L2 - MEZ G1 | D27: 35 | E27: ='[8]PILARES - MEZ G1'!J53 -> 57.48336 | F27: ='[8]PILARES - MEZ G1'!I53 -> 497.1384 | G27: 425 | H27: 1093 | I27: 0 | J27: 0 | K27: 740 | L27: 1926 | M27: 6793 | N27: 0 | O27: =SUM(G27:N27) -> 10977 | P27: =O27/E27 -> 190.95961
B28: PILARES | C28: L3 - G2 | D28: 35 | E28: ='[8]PILARES - MEZ G2'!J53 -> 40.76928 | F28: ='[8]PILARES - MEZ G2'!I53 -> 361.5552 | G28: 277 | H28: 766 | I28: 0 | J28: 0 | K28: 836 | L28: 2665 | M28: 2989 | N28: 0 | O28: =SUM(G28:N28) -> 7533 | P28: =O28/E28 -> 184.77147
B29: PILARES | C29: L4 - MEZ G3 | D29: 35 | E29: ='[8]PILARES - MEZ G3'!J51 -> 40.76928 | F29: ='[8]PILARES - MEZ G3'!I51 -> 361.5552 | G29: 277 | H29: 667 | I29: 0 | J29: 0 | K29: 1401 | L29: 1402 | M29: 2693 | N29: 0 | O29: =SUM(G29:N29) -> 6440 | P29: =O29/E29 -> 157.96207
B30: PILARES | C30: L5 - LAZER | D30: 35 | E30: ='[8]PILARES - LAZER '!J51 -> 55.70136 | F30: ='[8]PILARES - LAZER '!I51 -> 491.7528 | G30: 369 | H30: 913 | I30: 0 | J30: 0 | K30: 1454 | L30: 1475 | M30: 2629 | N30: 0 | O30: =SUM(G30:N30) -> 6840 | P30: =O30/E30 -> 122.79772
B31: PILARES | C31: L6 TIPO | D31: 35 | E31: ='[8]PILARES - L6 TIPO 01'!J36 -> 33.21504 | F31: ='[8]PILARES - L6 TIPO 01'!I36 -> 281.124 | G31: 531 | H31: 87 | I31: 0 | J31: 0 | K31: 670 | L31: 1389 | M31: 2240 | N31: 0 | O31: =SUM(G31:N31) -> 4917 | P31: =O31/E31 -> 148.03535
B32: PILARES | C32: L7 TIPO | D32: 35 | E32: ='[8]PILARES - L7 A L21 TIPO'!J35 -> 29.71872 | F32: ='[8]PILARES - L7 A L21 TIPO'!I35 -> 246.636 | G32: =416 -> 416 | H32: =29 -> 29 | I32: 0 | J32: 0 | K32: =709 -> 709 | L32: =1187 -> 1187 | M32: =513 -> 513 | N32: 0 | O32: =SUM(G32:N32) -> 2854 | P32: =O32/E32 -> 96.033746
B33: PILARES | C33: L8 TIPO | D33: 35 | E33: =E32 -> 29.71872 | F33: =F32 -> 246.636 | G33: 415 | H33: 29 | I33: 0 | J33: 0 | K33: 894 | L33: 1212 | M33: 0 | N33: 0 | O33: =SUM(G33:N33) -> 2550 | P33: =O33/E33 -> 85.804503
B34: PILARES | C34: L9 TIPO | D34: 35 | E34: =E32 -> 29.71872 | F34: =F32 -> 246.636 | G34: 414 | H34: 29 | I34: 0 | J34: 0 | K34: 1187 | L34: 732 | M34: 0 | N34: 0 | O34: =SUM(G34:N34) -> 2362 | P34: =O34/E34 -> 79.478524
B35: PILARES | C35: L10 TIPO | D35: 35 | E35: =E32 -> 29.71872 | F35: =F32 -> 246.636 | G35: 413 | H35: 29 | I35: 0 | J35: 0 | K35: 1279 | L35: 581 | M35: 0 | N35: 0 | O35: =SUM(G35:N35) -> 2302 | P35: =O35/E35 -> 77.459594
B36: PILARES | C36: L11 TIPO | D36: 35 | E36: =E32 -> 29.71872 | F36: =F32 -> 246.636 | G36: 413 | H36: 29 | I36: 0 | J36: 0 | K36: 1372 | L36: 429 | M36: 0 | N36: 0 | O36: =SUM(G36:N36) -> 2243 | P36: =O36/E36 -> 75.474314
B37: PILARES | C37: L12 A L20 TIPO | D37: 35 | E37: =E32*9 -> 267.46848 | F37: =F32*9 -> 2219.724 | G37: =401*9 -> 3609 | H37: =9*29 -> 261 | I37: 0 | J37: 0 | K37: =9*1479 -> 13311 | L37: =9*126 -> 1134 | M37: 0 | N37: 0 | O37: =SUM(G37:N37) -> 18315 | P37: =O37/E37 -> 68.475358
B38: PILARES | C38: L21 - TELHADO | D38: 35 | E38: =E32 -> 29.71872 | F38: =F32 -> 246.636 | G38: 401 | H38: 29 | I38: 0 | J38: 0 | K38: 1330 | L38: 126 | M38: 0 | N38: 0 | O38: =SUM(G38:N38) -> 1886 | P38: =O38/E38 -> 63.461683
B39: PILARES | C39: L22 - MÁQUINAS L23/ L24 - RESERVATÓRIO SUPERIOR | D39: 35 | E39: ='[8]PILARES - L22 L23 L24'!J35 -> 19.95056 | F39: ='[8]PILARES - L22 L23 L24'!I35 -> 168.448 | G39: 271 | H39: 67 | I39: 0 | J39: 0 | K39: 941 | L39: 223 | M39: 0 | N39: 0 | O39: =SUM(G39:N39) -> 1502 | P39: =O39/E39 -> 75.286107
C40: TOTAL | D40: 35 | E40: =SUM(E26:E39) -> 693.66968 | F40: =SUM(F26:F39) -> 5861.1136 | G40: =SUM(G26:G39) -> 8231 | H40: =SUM(H26:H39) -> 4028 | I40: =SUM(I26:I39) -> 0 | J40: =SUM(J26:J39) -> 0 | K40: =SUM(K26:K39) -> 26124 | L40: =SUM(L26:L39) -> 14481 | ... O40: =SUM(O26:O39) -> 70721 | P40: =O40/E40 -> 101.95198
A42: LAJES
B44: ELEMENTO | C44: PAVIMENTO | D44: FCK DE CONCRETO (MPa) | E44: VOLUME DE CONCRETO (m³) | F44: ÁREA DE FORMA (m²) | G44: Ø5,00 (kg) | H44: Ø6,30 (kg) | I44: Ø8,00 (kg) | J44: Ø10,00 (kg) | K44: Ø12,50 (kg) | L44: Ø16,00 (kg) | M44: Ø20,00 (kg) | N44: Ø25,00 (kg) | O44: KG DE AÇO (kg) | P44: TAXA DE AÇO (kg/m³)
B45: LAJE | C45: L2 - MEZ G1 | D45: 35 | E45: 87 | F45: =[8]LAJES_FORMAS!G13 -> 91.83 | G45: 0 | H45: 92 | I45: 1045 | J45: 1371 | K45: 1374 | L45: 0 | M45: 0 | N45: 0 | O45: =SUM(G45:N45) -> 3882 | P45: =O45/E45 -> 44.62069
B46: LAJE | C46: L3 - G2 | D46: 35 | E46: 98 | F46: =[8]LAJES_FORMAS!G18 -> 140.32 | G46: 0 | H46: 62 | I46: 1157 | J46: 715 | K46: 2756 | L46: 77 | M46: 0 | N46: 0 | O46: =SUM(G46:N46) -> 4767 | P46: =O46/E46 -> 48.642857
B47: LAJE | C47: L4 - MEZ G3 | D47: 35 | E47: 98 | F47: =[8]LAJES_FORMAS!G23 -> 140.42 | G47: 0 | H47: 62 | I47: 1157 | J47: 715 | K47: 2756 | L47: 77 | M47: 0 | N47: 0 | O47: =SUM(G47:N47) -> 4767 | P47: =O47/E47 -> 48.642857
...

Sheet ESCORAMENTO
A1: PLANILHA DE ESCORAMENTO
A3: CLIENTE | B3: KIRCHNER
A4: OBRA | B4: WEST VILLAGE
A5: REVISÃO | B5: R00
A6: DATA | B6: 45274
A8: PAVIMENTO | B8: ÁREA | C8: R$ | D8: R$ | E8: INÍCIO | F8: FIM | I8: ESCORAMENTO (PARA 1 MÊS)
C9: ESCOR. / m2 | D9: DIA / m2 | G9: DIAS CORRIDOS | H9: DIFERENÇA ENTRE PAVIMENTOS | I9: 1 | J9: 0.75 | K9: 0.5 | L9: 0.25 | M9: TRAV/MÊS / M2 | N9: TRAV.
A10: Garagem 01 | B10: 825.55 | C10: =(20640)/B10 -> 25.001514 | D10: =C10/30 -> 0.8333838 | G10: 31 | H10: 0 | I10: =(B10+7)*G10*D10 -> 21508.844 | J10: 0
A11: Garagem 02 | B11: 825.55 | C11: =(20640)/B11 -> 25.001514 | D11: =C11/30 -> 0.8333838 | G11: 20 | H11: =E11-F10 -> 0 | I11: =(B11+7)*G11*D11 -> 13876.674 | J11: =(B10*D10*0.75)*7 -> 3612 | K11: =(B10*D10*0.5)*7 -> 2408 | L11: =(B10*D10*0.25)*7 -> 1204 | N11: =(M11*($G11)*B10)/30 -> 0
A12: Garagem 03 | B12: 825.55 | C12: =(20640)/B12 -> 25.001514 | D12: =C12/30 -> 0.8333838 | G12: 20 | H12: =E12-F10 -> 0 | I12: =(B12+7)*G12*D12 -> 13876.674 | J12: =(B11*D11*0.75)*7 -> 3612 | K12: =(B11*D11*0.5)*7 -> 2408 | L12: =(B11*D11*0.25)*7 -> 1204 | N12: =(M12*($G12)*B11)/30 -> 0
A13: Lazer | B13: 827.3 | C13: =(20640)/B13 -> 24.948628 | D13: =C13/30 -> 0.83162094 | G13: 37 | H13: =E13-F11 -> 0 | I13: =(B13+7)*G13*D13 -> 25671.39 | J13: =(B12*D12*0.75)*7 -> 3612 | K13: =(B12*D12*0.5)*7 -> 2408 | L13: =(B12*D12*0.25)*7 -> 1204
A14: Tipo 1 | B14: 439.35 | C14: =(11200)/B14 -> 25.492204 | D14: =C14/30 -> 0.84974015 | G14: 15 | H14: =E14-F12 -> 0 | I14: =(B14+7)*G14*D14 -> 5689.2227 | J14: =(B13*D13*0.75)*7 -> 3612 | K14: =(B13*D13*0.5)*7 -> 2408 | L14: =(B13*D13*0.25)*7 -> 1204 | N14: =(M14*($G14)*B13)/30 -> 0
A15: Tipo 2 | B15: 439.35 | C15: =(11200)/B15 -> 25.492204 | D15: =C15/30 -> 0.84974015 | G15: 12 | H15: =E15-F13 -> 0 | I15: =(B15+7)*G15*D15 -> 4551.3782 | J15: =(B14*D14*0.75)*7 -> 1960 | K15: =(B14*D14*0.5)*7 -> 1306.6667 | L15: =(B14*D14*0.25+B15*D15*0.25)*7 -> 1306.6667 | N15: =(M15*($G15)*B14)/30 -> 0
A16: Tipo 3 | B16: 439.35 | C16: =(11200)/B16 -> 25.492204 | D16: =C16/30 -> 0.84974015 | G16: 11 | H16: =E16-F14 -> 0 | I16: =(B16+7)*G16*D16 -> 4172.0967 | J16: =(B15*D15*0.75)*7 -> 1960 | K16: =(B15*D15*0.5)*7 -> 1306.6667 | L16: =(B15*D15*0.25+B16*D16*0.25)*7 -> 1306.6667 | N16: =(M16*($G16)*B15)/30 -> 0
A17: Tipo 4 | B17: 439.35 | C17: =(11200)/B17 -> 25.492204 | D17: =C17/30 -> 0.84974015 | G17: 11 | H17: =E17-F15 -> 0 | I17: =(B17+7)*G17*D17 -> 4172.0967 | J17: =(B16*D16*0.75)*7 -> 1960 | K17: =(B16*D16*0.5)*7 -> 1306.6667 | L17: =(B16*D16*0.25+B17*D17*0.25)*7 -> 1306.6667 | N17: =(M17*($G17)*B16)/30 -> 0
A18: Tipo 5 | B18: 439.35 | C18: =(11200)/B18 -> 25.492204 | D18: =C18/30 -> 0.84974015 | G18: 11 | H18: =E18-F16 -> 0 | I18: =(B18+7)*G18*D18 -> 4172.0967 | J18: =(B17*D17*0.75)*7 -> 1960 | K18: =(B17*D17*0.5)*7 -> 1306.6667 | L18: =(B17*D17*0.25+B18*D18*0.25)*7 -> 1306.6667 | N18: =(M18*($G18)*B17)/30 -> 0
A19: Tipo 6 | B19: 439.35 | C19: =(11200)/B19 -> 25.492204 | D19: =C19/30 -> 0.84974015 | G19: 11 | H19: =E19-F17 -> 0 | I19: =(B19+7)*G19*D19 -> 4172.0967 | J19: =(B18*D18*0.75)*7 -> 1960 | K19: =(B18*D18*0.5)*7 -> 1306.6667 | L19: =(B18*D18*0.25+B19*D19*0.25)*7 -> 1306.6667 | N19: =(M19*($G19)*B18)/30 -> 0
A20: Tipo 7 | B20: 439.35 | C20: =(11200)/B20 -> 25.492204 | D20: =C20/30 -> 0.84974015 | G20: 11 | H20: =E20-F18 -> 0 | I20: =(B20+7)*G20*D20 -> 4172.0967 | J20: =(B19*D19*0.75)*7 -> 1960 | K20: =(B19*D19*0.5)*7 -> 1306.6667 | L20: =(B19*D19*0.25+B20*D20*0.25)*7 -> 1306.6667 | N20: =(M20*($G20)*B19)/30 -> 0
A21: Tipo 8 | B21: 439.35 | C21: =(11200)/B21 -> 25.492204 | D21: =C21/30 -> 0.84974015 | G21: 11 | H21: =E21-F19 -> 0 | I21: =(B21+7)*G21*D21 -> 4172.0967 | J21: =(B20*D20*0.75)*7 -> 1960 | K21: =(B20*D20*0.5)*7 -> 1306.6667 | L21: =(B20*D20*0.25+B21*D21*0.25)*7 -> 1306.6667 | N21: =(M21*($G21)*B20)/30 -> 0
A22: Tipo 9 | B22: 439.35 | C22: =(11200)/B22 -> 25.492204 | D22: =C22/30 -> 0.84974015 | G22: 11 | H22: =E22-F20 -> 0 | I22: =(B22+7)*G22*D22 -> 4172.0967 | J22: =(B21*D21*0.75)*7 -> 1960 | K22: =(B21*D21*0.5)*7 -> 1306.6667 | L22: =(B21*D21*0.25+B22*D22*0.25)*7 -> 1306.6667 | N22: =(M22*($G22)*B21)/30 -> 0
A23: Tipo 10 | B23: 439.35 | C23: =(11200)/B23 -> 25.492204 | D23: =C23/30 -> 0.84974015 | G23: 11 | H23: =E23-F21 -> 0 | I23: =(B23+7)*G23*D23 -> 4172.0967 | J23: =(B22*D22*0.75)*7 -> 1960 | K23: =(B22*D22*0.5)*7 -> 1306.6667 | L23: =(B22*D22*0.25+B23*D23*0.25)*7 -> 1306.6667 | N23: =(M23*($G23)*B22)/30 -> 0
A24: Tipo 11 | B24: 439.35 | C24: =(11200)/B24 -> 25.492204 | D24: =C24/30 -> 0.84974015 | G24: 11 | H24: =E24-F22 -> 0 | I24: =(B24+7)*G24*D24 -> 4172.0967 | J24: =(B23*D23*0.75)*7 -> 1960 | K24: =(B23*D23*0.5)*7 -> 1306.6667 | L24: =(B23*D23*0.25+B24*D24*0.25)*7 -> 1306.6667 | N24: =(M24*($G24)*B23)/30 -> 0
A25: Tipo 12 | B25: 439.35 | C25: =(11200)/B25 -> 25.492204 | D25: =C25/30 -> 0.84974015 | G25: 11 | H25: =E25-F23 -> 0 | I25: =(B25+7)*G25*D25 -> 4172.0967 | J25: =(B24*D24*0.75)*7 -> 1960 | K25: =(B24*D24*0.5)*7 -> 1306.6667 | L25: =(B24*D24*0.25+B25*D25*0.25)*7 -> 1306.6667
A26: Tipo 13 | B26: 439.35 | C26: =(11200)/B26 -> 25.492204 | D26: =C26/30 -> 0.84974015 | G26: 11 | H26: =E26-F24 -> 0 | I26: =(B26+7)*G26*D26 -> 4172.0967 | J26: =(B25*D25*0.75)*7 -> 1960 | K26: =(B25*D25*0.5)*7 -> 1306.6667 | L26: =(B25*D25*0.25+B26*D26*0.25)*7 -> 1306.6667
A27: Tipo 14 | B27: 439.35 | C27: =(11200)/B27 -> 25.492204 | D27: =C27/30 -> 0.84974015 | G27: 11 | H27: =E27-F25 -> 0 | I27: =(B27+7)*G27*D27 -> 4172.0967 | J27: =(B26*D26*0.75)*7 -> 1960 | K27: =(B26*D26*0.5)*7 -> 1306.6667 | L27: =(B26*D26*0.25+B27*D27*0.25)*7 -> 1306.6667
A28: Tipo 15 | B28: 439.35 | C28: =(11200)/B28 -> 25.492204 | D28: =C28/30 -> 0.84974015 | G28: 11 | H28: =E28-F26 -> 0 | I28: =(B28+7)*G28*D28 -> 4172.0967 | J28: =(B27*D27*0.75)*7 -> 1960 | K28: =(B27*D27*0.5)*7 -> 1306.6667 | L28: =(B27*D27*0.25+B28*D28*0.25)*7 -> 1306.6667
A29: Casa de máquinas | B29: 39.9 | C29: =(60*16)/B29 -> 24.06015 | D29: =C29/30 -> 0.80200501 | G29: 14 | H29: =E29-F27 -> 0 | I29: =(B29+7)*G29*D29 -> 526.59649 | J29: =(B28*D28*0.75)*7 -> 1960 | K29: =(B28*D28*0.5)*7 -> 1306.6667 | L29: =(B28*D28*0.25+B29*D29*0.25)*7 -> 709.33333
A30: Reservatórios | B30: 19.2 | C30: =(30*16)/B30 -> 25 | D30: =C30/30 -> 0.83333333 | G30: 10 | H30: =E30-F28 -> 0 | I30: =(B30+7)*G30*D30 -> 218.33333 | J30: =(B29*D29*0.75)*7 -> 168 | K30: =(B29*D29*0.5)*7 -> 112 | L30: =(B29*D29*0.25+B30*D30*0.25)*7 -> 84
J31: =(B30*D30*0.75)*7 -> 84 | K31: =(B30*D30*0.5)*7 -> 56 | L31: =(B30*D30*0.25+B31*D31*0.25)*7 -> 28
K32: =A31*C31*F32*0.25 -> 0 | L32: =B23*D24*G32*0.25 -> 0
B34: =SUM(B10:B30) -> 9953.3 | I34: =SUM(I10:I32) -> 140156.37 | J34: =SUM(J11:J32) -> 44100 | K34: =SUM(K11:K32) -> 29400 | L34: =SUM(L11:L32) -> 23930.667 | N34: =SUM(N10:N32) -> 0
J36: PREÇO DO CIMBRAMENTO POR M2 | N36: =SUM(N34+I34+J34+L34+K34)/B34 -> 23.870177
J37: FRETE DE IDA | N37: 720
J38: FRETE DE VOLTA | N38: 720
J39: FRETE / M2 | N39: =(N37+N38)/B34 -> 0.14467564
J40: TOTAL / M2 | N40: =N39+N36 -> 24.014853
N41: =N40/10 -> 2.4014853 | O41: TOTAL/M²/MÊS
N44: =N40*B34 -> 239027.04

Sheet ALVENARIA
A1: Obra | B1: =[8]ARQUIVOS_BASE!B1 -> WEST VILLAGE
A2: Empresa | B2: =[8]ARQUIVOS_BASE!B2 -> KIRCHNER
A3: Revisão | B3: R03
A4: RESUMO DE QUANTITATIVO
A6: Quantitativo de alvenaria
A8: ALVENARIA INTERNA
B10: PAVIMENTO | C10: ÁREA DE PAREDE INTERNA (m2) | G10: ÁREA DE REBOCO E CHAPISCO EM ALVENARIA | H10: ENCUNHAMENTO (m)
C11: 20CM | D11: 15 CM | E11: ESCADA | F11: CHURRASQUEIRA
B12: TÉRREO | C12: 7.88 | D12: 539.91654 | E12: 55.178221 | F12: 0 | G12: =((C12+D12+E12)*2)+F12+C26+D26 -> 1514.9526 | H12: ='[9]KIRCHNER LEVANT TÉRREO'!$C$12+'[9]KIRCHNER LEVANT TÉRREO'!$D$12+'[9]KIRCHNER LEVANT TÉRREO'!$E$12+'[9]KIRCHNER LEVANT TÉRREO'!$F$12 -> 207.4206
B13: G1 | C13: 14.8044 | D13: 55.104746 | E13: 29.830661 | F13: 0 | G13: =((C13+D13+E13)*2)+F13+C27+D27 -> 412.28861 | H13: ='[9]KIRCHNER LEVANT GARAGEM'!$C$12+'[9]KIRCHNER LEVANT GARAGEM'!$D$12+'[9]KIRCHNER LEVANT GARAGEM'!$E$12+'[9]KIRCHNER LEVANT GARAGEM'!$F$12 -> 56.622907
B14: G2 | C14: 14.8044 | D14: 55.104746 | E14: 29.830661 | F14: 0 | G14: =((C14+D14+E14)*2)+F14+C28+D28 -> 412.28861 | H14: =H13 -> 56.622907
B15: G3 | C15: 20.8884 | D15: 73.373911 | E15: 42.866549 | F15: 0 | G15: =((C15+D15+E15)*2)+F15+C29+D29 -> 549.58472 | H15: ='[9]KIRCHNER LEVANT TÉRREO'!$C$12+'[9]KIRCHNER LEVANT TÉRREO'!$D$12+'[9]KIRCHNER LEVANT TÉRREO'!$E$12+'[9]KIRCHNER LEVANT TÉRREO'!$F$12 -> 207.4206
B16: LAZER | C16: 42.5866 | D16: 225.33254 | E16: 37.436291 | F16: 19.972 | G16: =((C16+D16+E16)*2)+F16+C30+D30 -> 935.85225 | H16: ='[9]KIRCHNER LEVANT LAZER'!$C$12+'[9]KIRCHNER LEVANT LAZER'!$D$12+'[9]KIRCHNER LEVANT LAZER'!$E$12+'[9]KIRCHNER LEVANT LAZER'!$F$12 -> 122.45317
B17: PAV. TIPO (15X) | C17: 1823.1735 | D17: 6248.4764 | E17: 593.02733 | F17: 674.64 | G17: =((C17+D17+E17)*2)+F17+C31+D31 -> 20331.822 | H17: =('[9]KIRCHNER LEVANT TIPO'!$C$12+'[9]KIRCHNER LEVANT TIPO'!$D$12+'[9]KIRCHNER LEVANT TIPO'!$E$12+'[9]KIRCHNER LEVANT TIPO'!$F$12)*15 -> 3852.8116
B18: CASA DE MÁQUINAS | C18: 8.772 | D18: 39.45 | E18: 63.295915 | F18: 0 | G18: =((C18+D18+E18)*2)+F18+C32+D32 -> 529.15476 | H18: ='[9]KIRCHNER LEVANT CASA MAQUINAS'!$C$12+'[9]KIRCHNER LEVANT CASA MAQUINAS'!$D$12+'[9]KIRCHNER LEVANT CASA MAQUINAS'!$E$12 -> 30.25694
B19: RESERVATÓRIO | C19: 0 | D19: 0 | E19: 0 | F19: 0 | G19: =((C19+D19+E19)*2)+F19+C33+D33 -> 16.938 | H19: 0
B20: TOTAL | C20: =SUM(C12:C19) -> 1932.9093 | D20: =SUM(D12:D19) -> 7236.7588 | E20: =SUM(E12:E19) -> 851.46563 | F20: =SUM(F12:F19) -> 694.612 | G20: =SUM(G12:G19) -> 24702.882 | H20: =SUM(H12:H19) -> 4533.6087
A22: ALVENARIA EXTERNA
B24: PAVIMENTO | C24: ÁREA DE PAREDE EXTERNA (m2) | E24: ÁREA DE REBOCO E CHAPISCO EM ALVENARIA | F24: ENCUNHAMENTO (m)
C25: 20CM | D25: 15 CM
B26: TÉRREO | C26: 0 | D26: 309.00304 | E26: =D26+C26 -> 309.00304 | F26: ='[9]KIRCHNER LEVANT TÉRREO'!$C$19 -> 106.4812
B27: G1 | C27: 15.548 | D27: 197.261 | E27: =D27+C27 -> 212.809 | F27: ='[9]KIRCHNER LEVANT GARAGEM'!$C$19+'[9]KIRCHNER LEVANT GARAGEM'!$D$19 -> 104.74
B28: G2 | C28: 15.548 | D28: 197.261 | E28: =D28+C28 -> 212.809 | F28: =F27 -> 104.74
B29: G3 | C29: 20.8884 | D29: 254.4386 | E29: =D29+C29 -> 275.327 | F29: ='[9]KIRCHNER LEVANT GARAGEM 3'!$C$19+'[9]KIRCHNER LEVANT GARAGEM 3'!$D$19 -> 104.74
B30: LAZER | C30: 20.0032 | D30: 285.1662 | E30: =D30+C30 -> 305.1694 | F30: ='[9]KIRCHNER LEVANT LAZER'!$C$19+'[9]KIRCHNER LEVANT LAZER'!$D$19 -> 141.99
B31: PAV. TIPO (15X) | C31: 71.1 | D31: 2256.7281 | E31: =D31+C31 -> 2327.8281 | F31: =('[9]KIRCHNER LEVANT TIPO'!$C$19+'[9]KIRCHNER LEVANT TIPO'!$D$19)*15 -> 1351.573
B32: CASA DE MÁQUINAS | C32: 19.745 | D32: 286.37393 | E32: =D32+C32 -> 306.11893 | F32: ='[9]KIRCHNER LEVANT CASA MAQUINAS'!$C$19+'[9]KIRCHNER LEVANT CASA MAQUINAS'!$D$19 -> 135.03002
B33: RESERVATÓRIO | C33: 5.6 | D33: 11.338 | E33: =D33+C33 -> 16.938 | F33: ='[9]KIRCHNER LEVANT RESERVATORIO'!$C$19+'[9]KIRCHNER LEVANT RESERVATORIO'!$D$19 -> 16.85
B34: TOTAL | C34: =SUM(C26:C33) -> 168.4326 | D34: =SUM(D26:D33) -> 3797.5698 | E34: =SUM(E26:E33) -> 3966.0024 | F34: =SUM(F26:F33) -> 2066.1442
A36: TOTAL
B38: PAVIMENTO | C38: ÁREA DE PAREDE (m2) | G38: ENCUNHAMENTO (m) | H38: ÁREA DE REBOCO E CHAPISCO EM ALVENARIA
C39: 20CM | D39: 15 CM | E39: ESCADA | F39: CHURRASQUEIRA
B40: TÉRREO | C40: =C12+C26 -> 7.88 | D40: =D12+D26 -> 848.91958 | E40: =E12 -> 55.178221 | F40: =F12 -> 0 | G40: =F26+H12 -> 313.9018 | H40: =G12+E26 -> 1823.9556
B41: G1 | C41: =C13+C27 -> 30.3524 | D41: =D13+D27 -> 252.36575 | E41: =E13 -> 29.830661 | F41: =F13 -> 0 | G41: =F27+H13 -> 161.36291 | H41: =G13+E27 -> 625.09761
B42: G2 | C42: =C14+C28 -> 30.3524 | D42: =D14+D28 -> 252.36575 | E42: =E14 -> 29.830661 | F42: =F14 -> 0 | G42: =F28+H14 -> 161.36291 | H42: =G14+E28 -> 625.09761
B43: G3 | C43: =C15+C29 -> 41.7768 | D43: =D15+D29 -> 327.81251 | E43: =E15 -> 42.866549 | F43: =F15 -> 0 | G43: =F29+H15 -> 312.1606 | H43: =G15+E29 -> 824.91172
B44: LAZER | C44: =C16+C30 -> 62.5898 | D44: =D16+D30 -> 510.49874 | E44: =E16 -> 37.436291 | F44: =F16 -> 19.972 | G44: =F30+H16 -> 264.44317 | H44: =G16+E30 -> 1241.0217
B45: PAV. TIPO (15X) | C45: =C17+C31 -> 1894.2735 | D45: =D17+D31 -> 8505.2044 | E45: =E17 -> 593.02733 | F45: =F17 -> 674.64 | G45: =F31+H17 -> 5204.3846 | H45: =G17+E31 -> 22659.65
B46: CASA DE MÁQUINAS | C46: =C18+C32 -> 28.517 | D46: =D18+D32 -> 325.82393 | E46: =E18 -> 63.295915 | F46: =F18 -> 0 | G46: =F32+H18 -> 165.28696 | H46: =G18+E32 -> 835.27369
B47: RESERVATÓRIO | C47: =C19+C33 -> 5.6 | D47: =D19+D33 -> 11.338 | E47: =E19 -> 0 | F47: =F19 -> 0 | G47: =F33+H19 -> 16.85 | H47: =G19+E33 -> 33.876
...

Sheet Verga e contra
A1: Obra | B1: West village
A2: Empresa | B2: Kirchner
A3: Revisão
A4: LEVANTAMENTO QUANTITATIVO
A6: Verga e contraverga
A8: Verga e contraverga - Garagem 1
B10: Elemento | C10: Unidade | D10: Quantidade
B11: Verga/contraverga de concreto, moldada in loco | C11: m | D11: 17.07
A13: Verga e contraverga - Garagem 2
B15: Elemento | C15: Unidade | D15: Quantidade
B16: Verga/contraverga de concreto, moldada in loco | C16: m | D16: 17.07
A18: Verga e contraverga - Garagem 3
B20: Elemento | C20: Unidade | D20: Quantidade
B21: Verga/contraverga de concreto, moldada in loco | C21: m | D21: 17.07
A23: Verga e contraverga - Nivel 1
B25: Elemento | C25: Unidade | D25: Quantidade
B26: Verga/contraverga de concreto, moldada in loco | C26: m | D26: 185.78
A28: Verga e contraverga - Lazer
B30: Elemento | C30: Unidade | D30: Quantidade
B31: Verga/contraverga de concreto, moldada in loco | C31: m | D31: 67.39
A33: Verga e contraverga - Tipo 1
B35: Elemento | C35: Unidade | D35: Quantidade
B36: Verga/contraverga de concreto, moldada in loco | C36: m | D36: 3498.42
A38: Verga e contraverga - Cobertura
B40: Elemento | C40: Unidade | D40: Quantidade
B41: Verga/contraverga de concreto, moldada in loco | C41: m | D41: 21.18
A43: Verga e contraverga - Total
B45: Elemento | C45: Unidade | D45: Quantidade
B46: Verga/contraverga de concreto, moldada in loco | C46: m | D46: =SUMIF(B$8:B$41,B46,D$8:D$41) -> 3823.98

Sheet REVESTIMENTOS
A1: Obra | B1: =[8]ARQUIVOS_BASE!B1 -> WEST VILLAGE
A2: Empresa | B2: =[8]ARQUIVOS_BASE!B2 -> KIRCHNER
A3: Revisão | B3: R03
A4: RESUMO DE QUANTITATIVO
A6: Quantitativo de Revestimento em alvenaria
A8: REVESTIMENTOS INTERNOS
B10: PAVIMENTO | C10: ÁREA DE REBOCO E CHAPISCO EM ALVENARIA | D10: ÁREA DE REBOCO E CHAPISCO EM ESTRUTURA | E10: ÁREA DE REBOCO E CHAPISCO | F10: ÁREA DE PAREDE AZULEJO BANHEIRO (m²) | G10: AREA DE PINTURA (m²)
B11: TÉRREO | C11: =ALVENARIA!G12 -> 1514.9526 | D11: ='ARGAMASSADO EM ESTRUTURA'!J11:J12 -> 561.8615 | E11: =D11+C11 -> 2076.8141 | F11: 0 | G11: =E11-F11 -> 2076.8141
B12: G1 | C12: =ALVENARIA!G13 -> 412.28861 | D12: ='ARGAMASSADO EM ESTRUTURA'!J13 -> 475.0208 | E12: =D12+C12 -> 887.30941 | F12: 0 | G12: =E12-F12 -> 887.30941
B13: G2 | C13: =ALVENARIA!G14 -> 412.28861 | D13: ='ARGAMASSADO EM ESTRUTURA'!J15 -> 475.0208 | E13: =D13+C13 -> 887.30941 | F13: 0 | G13: =E13-F13 -> 887.30941
B14: G3 | C14: =ALVENARIA!G15 -> 549.58472 | D14: ='ARGAMASSADO EM ESTRUTURA'!J17 -> 328.74 | E14: =D14+C14 -> 878.32472 | F14: 0 | G14: =E14-F14 -> 878.32472
B15: LAZER | C15: =ALVENARIA!G16 -> 935.85225 | D15: ='ARGAMASSADO EM ESTRUTURA'!J21 -> 175.7262 | E15: =D15+C15 -> 1111.5785 | F15: 46.1552 | G15: =E15-F15 -> 1065.4233
B16: PAV. TIPO (15X) | C16: =ALVENARIA!G17 -> 20331.822 | D16: ='ARGAMASSADO EM ESTRUTURA'!J23 -> 1982.268 | E16: =D16+C16 -> 22314.09 | F16: 3525.522 | G16: =E16-F16 -> 18788.568
B17: CASA DE MÁQUINAS | C17: =ALVENARIA!G18 -> 529.15476 | D17: 0 | E17: =D17+C17 -> 529.15476 | F17: 0 | G17: =E17-F17 -> 529.15476
B18: RESERVATÓRIO | C18: =ALVENARIA!G19 -> 16.938 | D18: 0 | E18: =D18+C18 -> 16.938 | F18: 0 | G18: =E18-F18 -> 16.938
B19: TOTAL | C19: =SUM(C11:C18) -> 24702.882 | D19: =SUM(D11:D18) -> 3998.6373 | E19: =SUM(E11:E18) -> 28701.519 | F19: =SUM(F11:F18) -> 3571.6772 | G19: =SUM(G11:G18) -> 25129.842
A21: REVESTIMENTOS EXTERNOS
B23: PAVIMENTO | C23: ÁREA DE REBOCO E CHAPISCO EM ALVENARIA | D23: ÁREA DE REBOCO E CHAPISCO EM ESTRUTURA | E23: ÁREA DE REBOCO E CHAPISCO
B24: TÉRREO | C24: =ALVENARIA!E26 -> 309.00304 | D24: 285.796 | E24: =D24+C24 -> 594.79904
B25: G1 | C25: =ALVENARIA!E27 -> 212.809 | D25: 313.272 | E25: =D25+C25 -> 526.081
B26: G2 | C26: =ALVENARIA!E28 -> 212.809 | D26: 313.272 | E26: =D26+C26 -> 526.081
B27: G3 | C27: =ALVENARIA!E29 -> 275.327 | D27: 236.98 | E27: =D27+C27 -> 512.307
B28: LAZER | C28: =ALVENARIA!E30 -> 305.1694 | D28: 117.033 | E28: =D28+C28 -> 422.2024
B29: PAV. TIPO (15X) | C29: =ALVENARIA!E31 -> 2327.8281 | D29: 1638.315 | E29: =D29+C29 -> 3966.1431
B30: CASA DE MÁQUINAS | C30: =ALVENARIA!E32 -> 306.11893 | D30: 57.6726 | E30: =D30+C30 -> 363.79153
B31: RESERVATÓRIO | C31: =ALVENARIA!E33 -> 16.938 | D31: 68.4864 | E31: =D31+C31 -> 85.4244
B32: DETALHES DA FACHADA EXTERNA | C32: 0 | D32: =243.134+576.54 -> 819.674 | E32: =D32+C32 -> 819.674
B33: TOTAL | C33: =SUM(C24:C32) -> 3966.0024 | D33: =SUM(D24:D32) -> 3850.501 | E33: =SUM(E24:E32) -> 7816.5034

Sheet ARGAMASSADO EM ESTRUTURA
A1: Obra | B1: =[8]ARQUIVOS_BASE!B1 -> WEST VILLAGE
A2: Empresa | B2: =[8]ARQUIVOS_BASE!B2 -> KIRCHNER
A3: Revisão | B3: =[8]ARQUIVOS_BASE!B3 -> 0
A4: RESUMO DE QUANTITATIVO
A6: Quantitativo de Acabamento Argamassado - Estrutura
A8: REVESTIMENTO ARGAMASSADO EM ESTRUTURA INTERNO
B10: PAVIMENTO | C10: PERÍMETRO DE PILARES (m) | D10: ALTURA DE PILARES (m) | E10: ÁREA TOTAL PILARES INTERNO (m2) | F10: PERÍMETRO DE VIGAS (m) | G10: ALTURA DE VIGAS DE BORDA (m) | H10: ÁREA TOTAL DE VIGAS m2) | I10: ÁREA TOTAL DE REV. ARGAMASSADO EM ESTRUTURA - INTERNO (m2) | J10: ÁREA DE REBOCO E CHAPISCO EM ESTRUTURA | K10: ÁREA DE TEXTURA EM ESTRUTURA | L10: ÁREA DE EMASSAMENTO E PINTURA EM ESTRUTURA
B11: TÉRREO | C11: =(16*0.74)+(2*1.9)+(4*3.1)+3.2 -> 31.24 | D11: 3.52 | E11: =D11*C11 -> 109.9648 | F11: =(20+39+20)*2 -> 158 | G11: 0.7 | H11: =G11*F11 -> 110.6 | I11: =SUM(E11,H11,H12,E12) -> 561.8615 | J11: =I11 -> 561.8615 | K11: =J11 -> 561.8615
C12: =(8*3)+(2*3.6)+(4*3.4)+(2*1.2)+1.05+(2*2.85)+0.455 -> 54.405 | D12: 4.14 | E12: =D12*C12 -> 225.2367 | F12: =(16.95+1.5+4.5+1.5+17)*2 -> 82.9 | G12: 1.4 | H12: =G12*F12 -> 116.06
B13: G1 | C13: =(16*0.74)+(4*1.2)+(2*1.4) -> 19.44 | D13: 2.26 | E13: =D13*C13 -> 43.9344 | F13: =(F11+38)*2 -> 392 | G13: 0.7 | H13: =G13*F13 -> 274.4 | I13: =SUM(H13,E13,E14) -> 475.0208 | J13: =I13 -> 475.0208 | K13: =I13 -> 475.0208
C14: =C12 -> 54.405 | D14: 2.88 | E14: =D14*C14 -> 156.6864
B15: G2 | C15: =C13 -> 19.44 | D15: =D13 -> 2.26 | E15: =D15*C15 -> 43.9344 | F15: =F13 -> 392 | G15: 0.7 | H15: =G15*F15 -> 274.4 | I15: =SUM(H15,E15,E16) -> 475.0208 | J15: =I15 -> 475.0208 | K15: =I15 -> 475.0208
C16: =C14 -> 54.405 | D16: =D14 -> 2.88 | E16: =D16*C16 -> 156.6864
B17: G3 | C17: =4*0.7 -> 2.8 | D17: 2.6 | E17: =D17*C17 -> 7.28 | F17: =(10.75+5.5+10.49+10.75+22.54+21.49)*2 -> 163.04 | G17: 0.6 | H17: =F17*G17 -> 97.824 | I17: =SUM(H17:H20,E17:E19) -> 328.74 | J17: =I17 -> 328.74 | K17: =I17 -> 328.74
C18: =(6*3)+(4*3.1)+(2*3.3) -> 37 | D18: 2.48 | E18: =D18*C18 -> 91.76 | F18: =2*22.75 -> 45.5 | G18: 0.7 | H18: =F18*G18 -> 31.85
C19: =(0.6)+(11*0.7)+(4*1.2)+(2*1.4) -> 15.9 | D19: 2.99 | E19: =D19*C19 -> 47.541 | F19: =2*5.7 -> 11.4 | G19: 0.75 | H19: =F19*G19 -> 8.55
E20: =D20*C20 -> 0 | F20: =(11+4.15)*2 -> 30.3 | G20: 1.45 | H20: =F20*G20 -> 43.935
B21: LAZER | C21: =(6*1.5)+(2*2.4)+1.6+2.6+0.6+1.55+1.55 -> 21.7 | D21: 2.73 | E21: =D21*C21 -> 59.241 | G21: 0.7 | H21: =F21*G21 -> 0 | I21: =SUM(H21,E21,E22) -> 175.7262 | J21: =I21 -> 175.7262 | L21: =I21 -> 175.7262
C22: =(3*1.15)+(4*1.5)+(2*1.2)+(2*3)+(2*3.1)+(2*2.85)+(2*0.455)+1+(2.4) -> 34.06 | D22: 3.42 | E22: =D22*C22 -> 116.4852
B23: PAV. TIPO (15X) | C23: =C21 -> 21.7 | D23: 2.37 | E23: =D23*C23 -> 51.429 | G23: 0.7 | H23: =F23*G23 -> 0 | I23: =SUM(H23,E23:E24)*15 -> 1982.268 | J23: =I23 -> 1982.268 | L23: =I23 -> 1982.268
C24: =C22 -> 34.06 | D24: 2.37 | E24: =D24*C24 -> 80.7222
B25: CASA DE MÁQUINAS | E25: =D25*C25 -> 0
E26: =SUM(E11:E25) -> 1190.9015 | F26: =SUM(F11:F25) -> 1275.14 | G26: =SUM(G11:G25) -> 8.4 | H26: =SUM(H11:H25) -> 957.619 | I26: =SUM(I11:I25) -> 3998.6373 | J26: =SUM(J11:J25) -> 3998.6373 | K26: =SUM(K11:K25) -> 1840.6431 | L26: =SUM(L11:L25) -> 2157.9942 | M26: =SUM(M11:M25) -> 0
A29: REVESTIMENTO ARGAMASSADO EM ESTRUTURA EXTERNO
B31: PAVIMENTO | C31: PERÍMETRO DE PILARES (m) | D31: ALTURA DE PILARES (m) | E31: ÁREA TOTAL PILARES EXTERNOS (m2) | F31: PERÍMETRO DE VIGAS (m) | G31: ALTURA DE VIGAS DE BORDA (m) | H31: ÁREA TOTAL DE VIGAS m2) | I31: ÁREA DE BLOCOS DE FACHADA m2 | J31: ÁREA TOTAL DE VER. ARGAMASSADO EM ESTRUTURA - EXTERNO (m2) | K31: ÁREA DE REBOCO E CHAPISCO EM ESTRUTURA | L31: ÁREA DE TEXTURA EM ESTRUTURA | M31: ÁREA DE EMASSAMENTO E PINTURA EM ESTRUTURA
B32: TÉRREO | C32: =(16*0.6)+(6*1.2) -> 16.8 | D32: 3.52 | E32: =D32*C32 -> 59.136 | F32: =F11 -> 158 | G32: 0.7 | H32: =F32*G32 -> 110.6 | J32: =SUM(H32,H33,E32) -> 285.796 | K32: =J32 -> 285.796
F33: =F12 -> 82.9 | G33: 1.4 | H33: =G33*F33 -> 116.06
B34: G1 | C34: =(16*0.6)+(4*1.2)+(2*1.4) -> 17.2 | D34: 2.26 | E34: =D34*C34 -> 38.872 | F34: =F13 -> 392 | G34: =G13 -> 0.7 | H34: =G34*F34 -> 274.4 | J34: =SUM(H34,E34) -> 313.272 | K34: =J34 -> 313.272
B36: G2 | C36: =C34 -> 17.2 | D36: =D34 -> 2.26 | E36: =D36*C36 -> 38.872 | F36: =F15 -> 392 | G36: =G15 -> 0.7 | H36: =G36*F36 -> 274.4 | J36: =SUM(H36,E36) -> 313.272 | K36: =J36 -> 313.272
B38: G3 | C38: =(0.6)+(11*0.7)+(4*1.2)+(2*1.4) -> 15.9 | D38: 2.99 | E38: =D38*C38 -> 47.541 | F38: =F17 -> 163.04 | G38: =G17 -> 0.6 | H38: =F38*G38 -> 97.824 | J38: =SUM(H38:H41,E38:E39) -> 236.98 | K38: =J38 -> 236.98
C39: =C17 -> 2.8 | D39: 2.6 | E39: =D39*C39 -> 7.28 | F39: =F18 -> 45.5 | G39: =G18 -> 0.7 | H39: =F39*G39 -> 31.85
F40: =F19 -> 11.4 | G40: =G19 -> 0.75 | H40: =F40*G40 -> 8.55
F41: =F20 -> 30.3 | G41: =G20 -> 1.45 | H41: =F41*G41 -> 43.935
B42: LAZER | C42: =C21 -> 21.7 | D42: 2.73 | E42: =D42*C42 -> 59.241 | F42: 82.56 | G42: 0.7 | H42: =F42*G42 -> 57.792 | J42: =SUM(H42,E42) -> 117.033 | K42: =J42 -> 117.033
B43: PAV. TIPO (15X) | C43: =C42 -> 21.7 | D43: 2.37 | E43: =D43*C43 -> 51.429 | F43: 82.56 | G43: 0.7 | H43: =F43*G43 -> 57.792 | J43: =SUM(H43,E43)*15 -> 1638.315 | K43: =J43 -> 1638.315
B44: CASA DE MÁQUINAS | C44: 11.04 | D44: 3.59 | E44: =D44*C44 -> 39.6336 | F44: =0.87+5.57+0.87+2.03+0.6+2.6+0.25+7.5+0.25+2.6+0.6+2.03 -> 25.77 | G44: 0.7 | H44: =F44*G44 -> 18.039 | J44: =SUM(H44,E44) -> 57.6726 | K44: =J44 -> 57.6726
B45: RESERVATÓRIO | F45: 18.56 | G45: 3.69 | H45: =F45*G45 -> 68.4864 | J45: =SUM(H45,E45) -> 68.4864
E46: =SUM(E32:E44) -> 342.0046 | H46: =SUM(H32:H45) -> 1159.7284 | I46: ='[10]REV. FACHADA'!D16 -> 576.54 | J46: =SUM(J32:J45) -> 3030.827 | K46: =SUM(K32:K44) -> 2962.3406 | L46: =SUM(L32:L44) -> 0 | M46: =SUM(M32:M44) -> 0 | N46: =SUM(N32:N44) -> 0 | O46: =N46/D46 -> #DIV/0!

Sheet CHURRASQUEIRA
A1: Obra | B1: West Village
A2: Empresa | B2: Kirchner
A3: Revisão | B3: R03
A4: LEVANTAMENTO QUANTITATIVO
A6: Churrasqueira
A8: Churrasqueira - área unitária
B10: LAZER = 2 | C10: Unidade | D10: Quantidade
B11: Perímetro | C11: m | D11: =1.1+1.1+0.7+0.7 -> 3.6
B12: Altura | C12: m | D12: 1.2
B13: Área piso | C13: m² | D13: =(1.1*0.7) -> 0.77
B14: Área boca | C14: m² | D14: =(0.6*0.6) -> 0.36
B15: Área de refratário | C15: m² | D15: =D11*D12+D13-D14 -> 4.73
B16: Apartamentos =6*15 = 90 | C16: Unidade | D16: Quantidade
B17: Perímetro | C17: m | D17: =((0.6+0.7)*2) -> 2.6
B18: Altura | C18: m | D18: 1.2
B19: Área piso | C19: m² | D19: =(0.6*0.7) -> 0.42
B20: Área boca | C20: m² | D20: =(0.6*0.6) -> 0.36
B21: Área de refratário | C21: m² | D21: =D17*D18+D19-D20 -> 3.18
A23: Churrasqueira - total
B25: Descrição | C25: Quantidade | D25: Área (m²)
B26: LAZER | C26: 2 | D26: =D15*C26 -> 9.46
B27: APARTAMENTOS | C27: =6*15 -> 90 | D27: =C27*D21 -> 286.2
B29: Descrição | C29: Tamanho | D29: Área (m²)
B30: LAZER | C30: 5 cm | D30: =D26 -> 9.46
B31: APARTAMENTOS | C31: 5 cm | D31: =D27 -> 286.2

Sheet IMPER
B1: IMPERMEABILIZAÇÃO - KIRCHNER
E5: 1 | F5: 3 | G5: 1 | H5: 15 | I5: 1
B6: COZINHAS | D6: TOTAL | E6: TÉRREO | F6: GARAGEM (X3) | G6: LAZER | H6: tipo (x15) | I6: TELHADO
B7: Altura parede | C7: m | E7: 0.4 | F7: 0.4 | G7: 0.4 | H7: 0.4 | I7: 0.4
B8: Paredes - perimetro | C8: m | D8: =SUMPRODUCT(E8:I8,E5:I5) -> 276.58 | G8: =3.15+3.88 -> 7.03 | H8: =2.67+3+3+3+3.15+3.15 -> 17.97 | I8: 0
B9: Área parede | C9: m2 | D9: =SUMPRODUCT(E9:I9,E5:I5) -> 110.632 | E9: =E8*E7 -> 0 | F9: =F8*F7 -> 0 | G9: =G8*G7 -> 2.812 | H9: =H8*H7 -> 7.188 | I9: =I8*I7 -> 0
B10: Piso | C10: m2 | D10: =SUMPRODUCT(E10:I10,E5:I5) -> 276.58 | E10: =1*E8 -> 0 | F10: =1*F8 -> 0 | G10: =1*G8 -> 7.03 | H10: =1*H8 -> 17.97 | I10: =1*I8 -> 0
B11: IMPERMEABILIZANTE EM COZINHA | H11: m2 | I11: =SUM(D9:D10) -> 387.212
B12: * CONSIDERADO 1 METRO A FRENTE DA PAREDE
E13: 1 | F13: 3 | G13: 1 | H13: 15 | I13: 1
B14: BANHEIROS | D14: TOTAL | E14: TÉRREO | F14: GARAGEM (X3) | G14: =G6 -> LAZER | H14: =H6 -> tipo (x15) | I14: =I6 -> TELHADO
A15: BOX BANHEIRO | B15: Altura parede | C15: m | E15: 1.5 | F15: 1.5 | G15: 1.5 | H15: 1.5 | I15: 1.5
B16: Paredes - perimetro | C16: m | D16: =SUMPRODUCT(E16:I16,E13:I13) -> 399.14 | E16: 0 | G16: =(1.3*1)+(0.9*2)+1.57+ 1.36+1.36+2.35 -> 9.74 | H16: =(((1.2)+(1.18*2))*2)+((1.2)+(0.88*2)*6)+((1.1)+0.88)+1.08+0.92+((0.95*2)+1.2) -> 25.96
B17: Área parede | C17: m2 | D17: =SUMPRODUCT(E17:I17,E13:I13) -> 598.71 | E17: =E16*E15 -> 0 | F17: =F16*F15 -> 0 | G17: =G16*G15 -> 14.61 | H17: =H16*H15 -> 38.94 | I17: =I16*I15 -> 0
B18: Piso | C18: m2 | D18: =SUMPRODUCT(E18:I18,E13:I13) -> 188.234 | G18: =1.14+3.05 -> 4.19 | H18: =(1.2*1.18)+((1.2*0.88)*6)+(1.1*0.88)+(0.95*1.2)+(1.08*0.92)+(1.18*1.2) -> 12.2696
A19: BANHEIRO | B19: Altura parede | C19: m | E19: 0.4 | F19: 0.4 | G19: 0.4 | H19: 0.4 | I19: 0.4
B20: Paredes - perimetro | C20: m | D20: =SUMPRODUCT(E20:I20,E13:I13) -> 554.1 | E20: 0 | G20: =(1.3*1)+(1.45*2) -> 4.2 | H20: =1.95+1.95+1.2+1.6+1.6+1.2+0.8+1.7+1.96+0.75+1.6+1.6+1.2+1.58+1.58+1.2+1.58+1.58+1.58+1.58+1.2+1.2+1.6+1.6+1.2+0.78+1.91+0.94+0.82+1.6+1.6+1.2+1.94+1.94+1.2-13.86 -> 36.66
B21: Área parede | C21: m2 | D21: =SUMPRODUCT(E21:I21,E13:I13) -> 221.64 | E21: =E20*E19 -> 0 | F21: =F20*F19 -> 0 | G21: =G20*G19 -> 1.68 | H21: =H20*H19 -> 14.664 | I21: =I20*I19 -> 0
B22: Piso | C22: m2 | D22: =SUMPRODUCT(E22:I22,E13:I13) -> 573.99 | E22: 0 | G22: =1.89 -> 1.89 | H22: =3.78+3+3.23+3.06+3+3+3+3+3.78+3.06+3+3.23-I18 -> 38.14
B23: IMPERMEABILIZANTE EM BOX BANHEIRO | H23: m2 | I23: =SUM(D17:D18) -> 786.944
B24: IMPERMEABILIZANTE EM BANHEIRO | H24: m2 | I24: =SUM(D21:D22) -> 795.63 | K24: =SUM(I24,I23,I33,I11,I50) -> 2866.276
B25: *ÁREA PISO DE BANHEIRO, JÁ FOI DESCONTADA DA ÁREA DO BOX
B26: *ÁREA DE DUCHA FOI CONSIDERADA EM BOX DE BANHEIRO
E27: 1 | F27: 3 | G27: 1 | H27: 15 | I27: 1
B28: SACADAS | D28: TOTAL | E28: TÉRREO | F28: GARAGEM (X3) | G28: =G6 -> LAZER | H28: =H6 -> tipo (x15) | I28: =I6 -> TELHADO
B29: Altura parede | C29: m | E29: 0.4 | F29: 0.4 | G29: 0.4 | H29: 0.4 | I29: 0.4
B30: Paredes - perimetro | C30: m | D30: =SUMPRODUCT(E30:I30,E27:I27) -> 388.35 | H30: =0.57+0.2+2.52+2.1+2.1+0.2+2.65+1.94+0.76+2.65+1.94+0.76+2.1+2.1+0.15+2.4+0.75 -> 25.89 | I30: 0
B31: Área parede | C31: m2 | D31: =SUMPRODUCT(E31:I31,E27:I27) -> 155.34 | E31: =E30*E29 -> 0 | F31: =F30*F29 -> 0 | G31: =G30*G29 -> 0 | H31: =H30*H29 -> 10.356 | I31: =I30*I29 -> 0
B32: Piso | C32: m2 | D32: =SUMPRODUCT(E32:I32,E27:I27) -> 489 | H32: =6.05+5.65+4.6+4.6+6.05+5.65 -> 32.6 | I32: 0
